<robot name="compact_apartment_dryer">
  <material name="warm_white_enamel">
    <color rgba="0.94 0.95 0.93 1" />
    </material>
  <material name="soft_gray_trim">
    <color rgba="0.72 0.74 0.74 1" />
    </material>
  <material name="black_rubber_gasket">
    <color rgba="0.02 0.022 0.024 1" />
    </material>
  <material name="brushed_drum_metal">
    <color rgba="0.66 0.68 0.67 1" />
    </material>
  <material name="shadowed_interior">
    <color rgba="0.09 0.095 0.1 1" />
    </material>
  <material name="smoked_porthole_glass">
    <color rgba="0.45 0.62 0.72 0.38" />
    </material>
  <material name="charcoal_handle">
    <color rgba="0.035 0.035 0.038 1" />
    </material>
  <link name="body">
    <visual name="rear_panel">
      <origin xyz="0 0.2675 0.38" rpy="0 0 0" />
      <geometry>
        <box size="0.62 0.025 0.76" />
        </geometry>
      <material name="warm_white_enamel">
        <color rgba="0.94 0.95 0.93 1" />
        </material>
      </visual>
    <visual name="side_panel_0">
      <origin xyz="-0.2975 0 0.38" rpy="0 0 0" />
      <geometry>
        <box size="0.025 0.56 0.76" />
        </geometry>
      <material name="warm_white_enamel">
        <color rgba="0.94 0.95 0.93 1" />
        </material>
      </visual>
    <visual name="side_panel_1">
      <origin xyz="0.2975 0 0.38" rpy="0 0 0" />
      <geometry>
        <box size="0.025 0.56 0.76" />
        </geometry>
      <material name="warm_white_enamel">
        <color rgba="0.94 0.95 0.93 1" />
        </material>
      </visual>
    <visual name="top_panel">
      <origin xyz="0 0 0.7475" rpy="0 0 0" />
      <geometry>
        <box size="0.62 0.56 0.025" />
        </geometry>
      <material name="warm_white_enamel">
        <color rgba="0.94 0.95 0.93 1" />
        </material>
      </visual>
    <visual name="bottom_panel">
      <origin xyz="0 0 0.0125" rpy="0 0 0" />
      <geometry>
        <box size="0.62 0.56 0.025" />
        </geometry>
      <material name="warm_white_enamel">
        <color rgba="0.94 0.95 0.93 1" />
        </material>
      </visual>
    <visual name="front_stile_0">
      <origin xyz="-0.2775 -0.2675 0.38" rpy="0 0 0" />
      <geometry>
        <box size="0.065 0.025 0.76" />
        </geometry>
      <material name="warm_white_enamel">
        <color rgba="0.94 0.95 0.93 1" />
        </material>
      </visual>
    <visual name="front_stile_1">
      <origin xyz="0.2775 -0.2675 0.38" rpy="0 0 0" />
      <geometry>
        <box size="0.065 0.025 0.76" />
        </geometry>
      <material name="warm_white_enamel">
        <color rgba="0.94 0.95 0.93 1" />
        </material>
      </visual>
    <visual name="front_top_rail">
      <origin xyz="0 -0.2675 0.6825" rpy="0 0 0" />
      <geometry>
        <box size="0.62 0.025 0.155" />
        </geometry>
      <material name="warm_white_enamel">
        <color rgba="0.94 0.95 0.93 1" />
        </material>
      </visual>
    <visual name="front_bottom_rail">
      <origin xyz="0 -0.2675 0.0775" rpy="0 0 0" />
      <geometry>
        <box size="0.62 0.025 0.155" />
        </geometry>
      <material name="warm_white_enamel">
        <color rgba="0.94 0.95 0.93 1" />
        </material>
      </visual>
    <visual name="porthole_bezel">
      <origin xyz="0 -0.284 0.38" rpy="1.5708 0 0" />
      <geometry>
        <mesh filename="assets/meshes/body_porthole_bezel.obj" />
        </geometry>
      <material name="soft_gray_trim">
        <color rgba="0.72 0.74 0.74 1" />
        </material>
      </visual>
    <visual name="axle_spoke_x">
      <origin xyz="0 -0.27 0.38" rpy="0 0 0" />
      <geometry>
        <box size="0.45 0.006 0.012" />
        </geometry>
      <material name="soft_gray_trim">
        <color rgba="0.72 0.74 0.74 1" />
        </material>
      </visual>
    <visual name="axle_spoke_z">
      <origin xyz="0 -0.27 0.38" rpy="0 0 0" />
      <geometry>
        <box size="0.012 0.006 0.45" />
        </geometry>
      <material name="soft_gray_trim">
        <color rgba="0.72 0.74 0.74 1" />
        </material>
      </visual>
    <visual name="axle_bearing">
      <origin xyz="0 -0.262 0.38" rpy="1.5708 0 0" />
      <geometry>
        <cylinder radius="0.035" length="0.012" />
        </geometry>
      <material name="soft_gray_trim">
        <color rgba="0.72 0.74 0.74 1" />
        </material>
      </visual>
    <visual name="hinge_leaf_0">
      <origin xyz="-0.275 -0.2945 0.235" rpy="0 0 0" />
      <geometry>
        <box size="0.032 0.033 0.115" />
        </geometry>
      <material name="soft_gray_trim">
        <color rgba="0.72 0.74 0.74 1" />
        </material>
      </visual>
    <visual name="hinge_leaf_1">
      <origin xyz="-0.275 -0.2945 0.525" rpy="0 0 0" />
      <geometry>
        <box size="0.032 0.033 0.115" />
        </geometry>
      <material name="soft_gray_trim">
        <color rgba="0.72 0.74 0.74 1" />
        </material>
      </visual>
    <collision name="rear_panel">
      <origin xyz="0 0.2675 0.38" rpy="0 0 0" />
      <geometry>
        <box size="0.62 0.025 0.76" />
        </geometry>
      </collision>
    <collision name="side_panel_0">
      <origin xyz="-0.2975 0 0.38" rpy="0 0 0" />
      <geometry>
        <box size="0.025 0.56 0.76" />
        </geometry>
      </collision>
    <collision name="side_panel_1">
      <origin xyz="0.2975 0 0.38" rpy="0 0 0" />
      <geometry>
        <box size="0.025 0.56 0.76" />
        </geometry>
      </collision>
    <collision name="top_panel">
      <origin xyz="0 0 0.7475" rpy="0 0 0" />
      <geometry>
        <box size="0.62 0.56 0.025" />
        </geometry>
      </collision>
    <collision name="bottom_panel">
      <origin xyz="0 0 0.0125" rpy="0 0 0" />
      <geometry>
        <box size="0.62 0.56 0.025" />
        </geometry>
      </collision>
    <collision name="front_stile_0">
      <origin xyz="-0.2775 -0.2675 0.38" rpy="0 0 0" />
      <geometry>
        <box size="0.065 0.025 0.76" />
        </geometry>
      </collision>
    <collision name="front_stile_1">
      <origin xyz="0.2775 -0.2675 0.38" rpy="0 0 0" />
      <geometry>
        <box size="0.065 0.025 0.76" />
        </geometry>
      </collision>
    <collision name="front_top_rail">
      <origin xyz="0 -0.2675 0.6825" rpy="0 0 0" />
      <geometry>
        <box size="0.62 0.025 0.155" />
        </geometry>
      </collision>
    <collision name="front_bottom_rail">
      <origin xyz="0 -0.2675 0.0775" rpy="0 0 0" />
      <geometry>
        <box size="0.62 0.025 0.155" />
        </geometry>
      </collision>
    <collision name="porthole_bezel">
      <origin xyz="0 -0.284 0.38" rpy="1.5708 0 0" />
      <geometry>
        <mesh filename="assets/meshes/body_porthole_bezel.obj" />
        </geometry>
      </collision>
    <collision name="axle_spoke_x">
      <origin xyz="0 -0.27 0.38" rpy="0 0 0" />
      <geometry>
        <box size="0.45 0.006 0.012" />
        </geometry>
      </collision>
    <collision name="axle_spoke_z">
      <origin xyz="0 -0.27 0.38" rpy="0 0 0" />
      <geometry>
        <box size="0.012 0.006 0.45" />
        </geometry>
      </collision>
    <collision name="axle_bearing">
      <origin xyz="0 -0.262 0.38" rpy="1.5708 0 0" />
      <geometry>
        <cylinder radius="0.035" length="0.012" />
        </geometry>
      </collision>
    <collision name="hinge_leaf_0">
      <origin xyz="-0.275 -0.2945 0.235" rpy="0 0 0" />
      <geometry>
        <box size="0.032 0.033 0.115" />
        </geometry>
      </collision>
    <collision name="hinge_leaf_1">
      <origin xyz="-0.275 -0.2945 0.525" rpy="0 0 0" />
      <geometry>
        <box size="0.032 0.033 0.115" />
        </geometry>
      </collision>
    </link>
  <link name="drum">
    <visual name="drum_shell">
      <origin xyz="0 0 0" rpy="1.5708 0 0" />
      <geometry>
        <cylinder radius="0.205" length="0.34" />
        </geometry>
      <material name="brushed_drum_metal">
        <color rgba="0.66 0.68 0.67 1" />
        </material>
      </visual>
    <visual name="drum_hub">
      <origin xyz="0 -0.182 0" rpy="1.5708 0 0" />
      <geometry>
        <cylinder radius="0.03" length="0.03" />
        </geometry>
      <material name="soft_gray_trim">
        <color rgba="0.72 0.74 0.74 1" />
        </material>
      </visual>
    <visual name="tumbling_fin_0">
      <origin xyz="0.122 0 0" rpy="0 -0 0" />
      <geometry>
        <box size="0.03 0.285 0.018" />
        </geometry>
      <material name="soft_gray_trim">
        <color rgba="0.72 0.74 0.74 1" />
        </material>
      </visual>
    <visual name="tumbling_fin_1">
      <origin xyz="-0.061 0 0.105655" rpy="0 -2.0944 0" />
      <geometry>
        <box size="0.03 0.285 0.018" />
        </geometry>
      <material name="soft_gray_trim">
        <color rgba="0.72 0.74 0.74 1" />
        </material>
      </visual>
    <visual name="tumbling_fin_2">
      <origin xyz="-0.061 0 -0.105655" rpy="0 -4.18879 0" />
      <geometry>
        <box size="0.03 0.285 0.018" />
        </geometry>
      <material name="soft_gray_trim">
        <color rgba="0.72 0.74 0.74 1" />
        </material>
      </visual>
    <collision name="drum_shell">
      <origin xyz="0 0 0" rpy="1.5708 0 0" />
      <geometry>
        <cylinder radius="0.205" length="0.34" />
        </geometry>
      </collision>
    <collision name="drum_hub">
      <origin xyz="0 -0.182 0" rpy="1.5708 0 0" />
      <geometry>
        <cylinder radius="0.03" length="0.03" />
        </geometry>
      </collision>
    <collision name="tumbling_fin_0">
      <origin xyz="0.122 0 0" rpy="0 -0 0" />
      <geometry>
        <box size="0.03 0.285 0.018" />
        </geometry>
      </collision>
    <collision name="tumbling_fin_1">
      <origin xyz="-0.061 0 0.105655" rpy="0 -2.0944 0" />
      <geometry>
        <box size="0.03 0.285 0.018" />
        </geometry>
      </collision>
    <collision name="tumbling_fin_2">
      <origin xyz="-0.061 0 -0.105655" rpy="0 -4.18879 0" />
      <geometry>
        <box size="0.03 0.285 0.018" />
        </geometry>
      </collision>
    </link>
  <link name="door">
    <visual name="door_ring">
      <origin xyz="0.255 0 0" rpy="1.5708 0 0" />
      <geometry>
        <mesh filename="assets/meshes/door_outer_ring.obj" />
        </geometry>
      <material name="warm_white_enamel">
        <color rgba="0.94 0.95 0.93 1" />
        </material>
      </visual>
    <visual name="rubber_gasket">
      <origin xyz="0.255 -0.003 0" rpy="1.5708 0 0" />
      <geometry>
        <mesh filename="assets/meshes/door_inner_gasket.obj" />
        </geometry>
      <material name="black_rubber_gasket">
        <color rgba="0.02 0.022 0.024 1" />
        </material>
      </visual>
    <visual name="glass_window">
      <origin xyz="0.255 -0.006 0" rpy="1.5708 0 0" />
      <geometry>
        <cylinder radius="0.177" length="0.01" />
        </geometry>
      <material name="smoked_porthole_glass">
        <color rgba="0.45 0.62 0.72 0.38" />
        </material>
      </visual>
    <visual name="hinge_barrel_0">
      <origin xyz="0 0 -0.135" rpy="0 0 0" />
      <geometry>
        <cylinder radius="0.016" length="0.115" />
        </geometry>
      <material name="soft_gray_trim">
        <color rgba="0.72 0.74 0.74 1" />
        </material>
      </visual>
    <visual name="hinge_barrel_1">
      <origin xyz="0 0 0.135" rpy="0 0 0" />
      <geometry>
        <cylinder radius="0.016" length="0.115" />
        </geometry>
      <material name="soft_gray_trim">
        <color rgba="0.72 0.74 0.74 1" />
        </material>
      </visual>
    <visual name="hinge_bridge">
      <origin xyz="0.012 0.002 0" rpy="0 0 0" />
      <geometry>
        <box size="0.04 0.018 0.265" />
        </geometry>
      <material name="warm_white_enamel">
        <color rgba="0.94 0.95 0.93 1" />
        </material>
      </visual>
    <collision name="door_ring">
      <origin xyz="0.255 0 0" rpy="1.5708 0 0" />
      <geometry>
        <mesh filename="assets/meshes/door_outer_ring.obj" />
        </geometry>
      </collision>
    <collision name="rubber_gasket">
      <origin xyz="0.255 -0.003 0" rpy="1.5708 0 0" />
      <geometry>
        <mesh filename="assets/meshes/door_inner_gasket.obj" />
        </geometry>
      </collision>
    <collision name="glass_window">
      <origin xyz="0.255 -0.006 0" rpy="1.5708 0 0" />
      <geometry>
        <cylinder radius="0.177" length="0.01" />
        </geometry>
      </collision>
    <collision name="hinge_barrel_0">
      <origin xyz="0 0 -0.135" rpy="0 0 0" />
      <geometry>
        <cylinder radius="0.016" length="0.115" />
        </geometry>
      </collision>
    <collision name="hinge_barrel_1">
      <origin xyz="0 0 0.135" rpy="0 0 0" />
      <geometry>
        <cylinder radius="0.016" length="0.115" />
        </geometry>
      </collision>
    <collision name="hinge_bridge">
      <origin xyz="0.012 0.002 0" rpy="0 0 0" />
      <geometry>
        <box size="0.04 0.018 0.265" />
        </geometry>
      </collision>
    </link>
  <link name="latch_handle">
    <visual name="latch_base">
      <origin xyz="0 0.003 0" rpy="1.5708 0 0" />
      <geometry>
        <cylinder radius="0.025" length="0.026" />
        </geometry>
      <material name="charcoal_handle">
        <color rgba="0.035 0.035 0.038 1" />
        </material>
      </visual>
    <visual name="latch_grip">
      <origin xyz="0 -0.02 0" rpy="0 0 0" />
      <geometry>
        <box size="0.036 0.026 0.145" />
        </geometry>
      <material name="charcoal_handle">
        <color rgba="0.035 0.035 0.038 1" />
        </material>
      </visual>
    <visual name="latch_neck">
      <origin xyz="0 -0.012 0" rpy="1.5708 0 0" />
      <geometry>
        <cylinder radius="0.017" length="0.03" />
        </geometry>
      <material name="charcoal_handle">
        <color rgba="0.035 0.035 0.038 1" />
        </material>
      </visual>
    <collision name="latch_base">
      <origin xyz="0 0.003 0" rpy="1.5708 0 0" />
      <geometry>
        <cylinder radius="0.025" length="0.026" />
        </geometry>
      </collision>
    <collision name="latch_grip">
      <origin xyz="0 -0.02 0" rpy="0 0 0" />
      <geometry>
        <box size="0.036 0.026 0.145" />
        </geometry>
      </collision>
    <collision name="latch_neck">
      <origin xyz="0 -0.012 0" rpy="1.5708 0 0" />
      <geometry>
        <cylinder radius="0.017" length="0.03" />
        </geometry>
      </collision>
    </link>
  <joint name="body_to_drum" type="continuous">
    <origin xyz="0 -0.07 0.38" rpy="0 0 0" />
    <parent link="body" />
    <child link="drum" />
    <axis xyz="0 1 0" />
    <limit effort="35" velocity="10" />
    </joint>
  <joint name="body_to_door" type="revolute">
    <origin xyz="-0.255 -0.326 0.38" rpy="0 0 0" />
    <parent link="body" />
    <child link="door" />
    <axis xyz="0 0 -1" />
    <limit effort="12" velocity="1.4" lower="0" upper="1.8" />
    </joint>
  <joint name="door_to_latch" type="revolute">
    <origin xyz="0.493 -0.026 0" rpy="0 0 0" />
    <parent link="door" />
    <child link="latch_handle" />
    <axis xyz="0 1 0" />
    <limit effort="1.5" velocity="3" lower="-0.35" upper="0.35" />
    </joint>
  </robot>
