<robot name="portal_gantry_z_slide">
  <material name="powder_coated_frame">
    <color rgba="0.16 0.2 0.24 1" />
    </material>
  <material name="bright_linear_rail">
    <color rgba="0.72 0.74 0.72 1" />
    </material>
  <material name="dark_fasteners">
    <color rgba="0.03 0.035 0.04 1" />
    </material>
  <material name="safety_orange_carriage">
    <color rgba="0.95 0.42 0.08 1" />
    </material>
  <material name="black_bearing_rubber">
    <color rgba="0.01 0.01 0.012 1" />
    </material>
  <material name="blue_z_slide">
    <color rgba="0.05 0.17 0.34 1" />
    </material>
  <material name="machined_tool_plate">
    <color rgba="0.62 0.64 0.62 1" />
    </material>
  <link name="frame">
    <visual name="foot_0">
      <origin xyz="-1.05 0 0.0275" rpy="0 0 0" />
      <geometry>
        <box size="0.3 0.5 0.055" />
        </geometry>
      <material name="powder_coated_frame">
        <color rgba="0.16 0.2 0.24 1" />
        </material>
      </visual>
    <visual name="foot_1">
      <origin xyz="1.05 0 0.0275" rpy="0 0 0" />
      <geometry>
        <box size="0.3 0.5 0.055" />
        </geometry>
      <material name="powder_coated_frame">
        <color rgba="0.16 0.2 0.24 1" />
        </material>
      </visual>
    <visual name="upright_0">
      <origin xyz="-1.05 0 0.745" rpy="0 0 0" />
      <geometry>
        <box size="0.13 0.18 1.43" />
        </geometry>
      <material name="powder_coated_frame">
        <color rgba="0.16 0.2 0.24 1" />
        </material>
      </visual>
    <visual name="upright_1">
      <origin xyz="1.05 0 0.745" rpy="0 0 0" />
      <geometry>
        <box size="0.13 0.18 1.43" />
        </geometry>
      <material name="powder_coated_frame">
        <color rgba="0.16 0.2 0.24 1" />
        </material>
      </visual>
    <visual name="top_beam">
      <origin xyz="0 0 1.485" rpy="0 0 0" />
      <geometry>
        <box size="2.32 0.2 0.16" />
        </geometry>
      <material name="powder_coated_frame">
        <color rgba="0.16 0.2 0.24 1" />
        </material>
      </visual>
    <visual name="front_linear_rail">
      <origin xyz="0 -0.074 1.385" rpy="0 0 0" />
      <geometry>
        <box size="1.86 0.032 0.03" />
        </geometry>
      <material name="bright_linear_rail">
        <color rgba="0.72 0.74 0.72 1" />
        </material>
      </visual>
    <visual name="rear_linear_rail">
      <origin xyz="0 0.074 1.385" rpy="0 0 0" />
      <geometry>
        <box size="1.86 0.032 0.03" />
        </geometry>
      <material name="bright_linear_rail">
        <color rgba="0.72 0.74 0.72 1" />
        </material>
      </visual>
    <visual name="knee_front_0">
      <origin xyz="-1.05 -0.105 1.275" rpy="0 0.35 0" />
      <geometry>
        <box size="0.18 0.03 0.3" />
        </geometry>
      <material name="powder_coated_frame">
        <color rgba="0.16 0.2 0.24 1" />
        </material>
      </visual>
    <visual name="knee_rear_0">
      <origin xyz="-1.05 0.105 1.275" rpy="0 0.35 0" />
      <geometry>
        <box size="0.18 0.03 0.3" />
        </geometry>
      <material name="powder_coated_frame">
        <color rgba="0.16 0.2 0.24 1" />
        </material>
      </visual>
    <visual name="anchor_0_0_0">
      <origin xyz="-1.12 -0.17 0.058" rpy="0 0 0" />
      <geometry>
        <cylinder radius="0.018" length="0.014" />
        </geometry>
      <material name="dark_fasteners">
        <color rgba="0.03 0.035 0.04 1" />
        </material>
      </visual>
    <visual name="anchor_0_0_1">
      <origin xyz="-0.98 -0.17 0.058" rpy="0 0 0" />
      <geometry>
        <cylinder radius="0.018" length="0.014" />
        </geometry>
      <material name="dark_fasteners">
        <color rgba="0.03 0.035 0.04 1" />
        </material>
      </visual>
    <visual name="anchor_0_1_0">
      <origin xyz="-1.12 0.17 0.058" rpy="0 0 0" />
      <geometry>
        <cylinder radius="0.018" length="0.014" />
        </geometry>
      <material name="dark_fasteners">
        <color rgba="0.03 0.035 0.04 1" />
        </material>
      </visual>
    <visual name="anchor_0_1_1">
      <origin xyz="-0.98 0.17 0.058" rpy="0 0 0" />
      <geometry>
        <cylinder radius="0.018" length="0.014" />
        </geometry>
      <material name="dark_fasteners">
        <color rgba="0.03 0.035 0.04 1" />
        </material>
      </visual>
    <visual name="knee_front_1">
      <origin xyz="1.05 -0.105 1.275" rpy="0 -0.35 0" />
      <geometry>
        <box size="0.18 0.03 0.3" />
        </geometry>
      <material name="powder_coated_frame">
        <color rgba="0.16 0.2 0.24 1" />
        </material>
      </visual>
    <visual name="knee_rear_1">
      <origin xyz="1.05 0.105 1.275" rpy="0 -0.35 0" />
      <geometry>
        <box size="0.18 0.03 0.3" />
        </geometry>
      <material name="powder_coated_frame">
        <color rgba="0.16 0.2 0.24 1" />
        </material>
      </visual>
    <visual name="anchor_1_0_0">
      <origin xyz="0.98 -0.17 0.058" rpy="0 0 0" />
      <geometry>
        <cylinder radius="0.018" length="0.014" />
        </geometry>
      <material name="dark_fasteners">
        <color rgba="0.03 0.035 0.04 1" />
        </material>
      </visual>
    <visual name="anchor_1_0_1">
      <origin xyz="1.12 -0.17 0.058" rpy="0 0 0" />
      <geometry>
        <cylinder radius="0.018" length="0.014" />
        </geometry>
      <material name="dark_fasteners">
        <color rgba="0.03 0.035 0.04 1" />
        </material>
      </visual>
    <visual name="anchor_1_1_0">
      <origin xyz="0.98 0.17 0.058" rpy="0 0 0" />
      <geometry>
        <cylinder radius="0.018" length="0.014" />
        </geometry>
      <material name="dark_fasteners">
        <color rgba="0.03 0.035 0.04 1" />
        </material>
      </visual>
    <visual name="anchor_1_1_1">
      <origin xyz="1.12 0.17 0.058" rpy="0 0 0" />
      <geometry>
        <cylinder radius="0.018" length="0.014" />
        </geometry>
      <material name="dark_fasteners">
        <color rgba="0.03 0.035 0.04 1" />
        </material>
      </visual>
    <collision name="foot_0">
      <origin xyz="-1.05 0 0.0275" rpy="0 0 0" />
      <geometry>
        <box size="0.3 0.5 0.055" />
        </geometry>
      </collision>
    <collision name="foot_1">
      <origin xyz="1.05 0 0.0275" rpy="0 0 0" />
      <geometry>
        <box size="0.3 0.5 0.055" />
        </geometry>
      </collision>
    <collision name="upright_0">
      <origin xyz="-1.05 0 0.745" rpy="0 0 0" />
      <geometry>
        <box size="0.13 0.18 1.43" />
        </geometry>
      </collision>
    <collision name="upright_1">
      <origin xyz="1.05 0 0.745" rpy="0 0 0" />
      <geometry>
        <box size="0.13 0.18 1.43" />
        </geometry>
      </collision>
    <collision name="top_beam">
      <origin xyz="0 0 1.485" rpy="0 0 0" />
      <geometry>
        <box size="2.32 0.2 0.16" />
        </geometry>
      </collision>
    <collision name="front_linear_rail">
      <origin xyz="0 -0.074 1.385" rpy="0 0 0" />
      <geometry>
        <box size="1.86 0.032 0.03" />
        </geometry>
      </collision>
    <collision name="rear_linear_rail">
      <origin xyz="0 0.074 1.385" rpy="0 0 0" />
      <geometry>
        <box size="1.86 0.032 0.03" />
        </geometry>
      </collision>
    <collision name="knee_front_0">
      <origin xyz="-1.05 -0.105 1.275" rpy="0 0.35 0" />
      <geometry>
        <box size="0.18 0.03 0.3" />
        </geometry>
      </collision>
    <collision name="knee_rear_0">
      <origin xyz="-1.05 0.105 1.275" rpy="0 0.35 0" />
      <geometry>
        <box size="0.18 0.03 0.3" />
        </geometry>
      </collision>
    <collision name="anchor_0_0_0">
      <origin xyz="-1.12 -0.17 0.058" rpy="0 0 0" />
      <geometry>
        <cylinder radius="0.018" length="0.014" />
        </geometry>
      </collision>
    <collision name="anchor_0_0_1">
      <origin xyz="-0.98 -0.17 0.058" rpy="0 0 0" />
      <geometry>
        <cylinder radius="0.018" length="0.014" />
        </geometry>
      </collision>
    <collision name="anchor_0_1_0">
      <origin xyz="-1.12 0.17 0.058" rpy="0 0 0" />
      <geometry>
        <cylinder radius="0.018" length="0.014" />
        </geometry>
      </collision>
    <collision name="anchor_0_1_1">
      <origin xyz="-0.98 0.17 0.058" rpy="0 0 0" />
      <geometry>
        <cylinder radius="0.018" length="0.014" />
        </geometry>
      </collision>
    <collision name="knee_front_1">
      <origin xyz="1.05 -0.105 1.275" rpy="0 -0.35 0" />
      <geometry>
        <box size="0.18 0.03 0.3" />
        </geometry>
      </collision>
    <collision name="knee_rear_1">
      <origin xyz="1.05 0.105 1.275" rpy="0 -0.35 0" />
      <geometry>
        <box size="0.18 0.03 0.3" />
        </geometry>
      </collision>
    <collision name="anchor_1_0_0">
      <origin xyz="0.98 -0.17 0.058" rpy="0 0 0" />
      <geometry>
        <cylinder radius="0.018" length="0.014" />
        </geometry>
      </collision>
    <collision name="anchor_1_0_1">
      <origin xyz="1.12 -0.17 0.058" rpy="0 0 0" />
      <geometry>
        <cylinder radius="0.018" length="0.014" />
        </geometry>
      </collision>
    <collision name="anchor_1_1_0">
      <origin xyz="0.98 0.17 0.058" rpy="0 0 0" />
      <geometry>
        <cylinder radius="0.018" length="0.014" />
        </geometry>
      </collision>
    <collision name="anchor_1_1_1">
      <origin xyz="1.12 0.17 0.058" rpy="0 0 0" />
      <geometry>
        <cylinder radius="0.018" length="0.014" />
        </geometry>
      </collision>
    </link>
  <link name="beam_carriage">
    <visual name="carriage_block">
      <origin xyz="0 0 -0.035" rpy="0 0 0" />
      <geometry>
        <box size="0.42 0.23 0.08" />
        </geometry>
      <material name="safety_orange_carriage">
        <color rgba="0.95 0.42 0.08 1" />
        </material>
      </visual>
    <visual name="lower_saddle">
      <origin xyz="0 0 -0.062" rpy="0 0 0" />
      <geometry>
        <box size="0.34 0.16 0.035" />
        </geometry>
      <material name="safety_orange_carriage">
        <color rgba="0.95 0.42 0.08 1" />
        </material>
      </visual>
    <visual name="roller_0_0">
      <origin xyz="-0.13 -0.074 0.005" rpy="1.5708 0 0" />
      <geometry>
        <cylinder radius="0.025" length="0.036" />
        </geometry>
      <material name="black_bearing_rubber">
        <color rgba="0.01 0.01 0.012 1" />
        </material>
      </visual>
    <visual name="roller_hub_0_0">
      <origin xyz="-0.13 -0.074 0.005" rpy="1.5708 0 0" />
      <geometry>
        <cylinder radius="0.014" length="0.042" />
        </geometry>
      <material name="bright_linear_rail">
        <color rgba="0.72 0.74 0.72 1" />
        </material>
      </visual>
    <visual name="roller_0_1">
      <origin xyz="-0.13 0.074 0.005" rpy="1.5708 0 0" />
      <geometry>
        <cylinder radius="0.025" length="0.036" />
        </geometry>
      <material name="black_bearing_rubber">
        <color rgba="0.01 0.01 0.012 1" />
        </material>
      </visual>
    <visual name="roller_hub_0_1">
      <origin xyz="-0.13 0.074 0.005" rpy="1.5708 0 0" />
      <geometry>
        <cylinder radius="0.014" length="0.042" />
        </geometry>
      <material name="bright_linear_rail">
        <color rgba="0.72 0.74 0.72 1" />
        </material>
      </visual>
    <visual name="roller_1_0">
      <origin xyz="0.13 -0.074 0.005" rpy="1.5708 0 0" />
      <geometry>
        <cylinder radius="0.025" length="0.036" />
        </geometry>
      <material name="black_bearing_rubber">
        <color rgba="0.01 0.01 0.012 1" />
        </material>
      </visual>
    <visual name="roller_hub_1_0">
      <origin xyz="0.13 -0.074 0.005" rpy="1.5708 0 0" />
      <geometry>
        <cylinder radius="0.014" length="0.042" />
        </geometry>
      <material name="bright_linear_rail">
        <color rgba="0.72 0.74 0.72 1" />
        </material>
      </visual>
    <visual name="roller_1_1">
      <origin xyz="0.13 0.074 0.005" rpy="1.5708 0 0" />
      <geometry>
        <cylinder radius="0.025" length="0.036" />
        </geometry>
      <material name="black_bearing_rubber">
        <color rgba="0.01 0.01 0.012 1" />
        </material>
      </visual>
    <visual name="roller_hub_1_1">
      <origin xyz="0.13 0.074 0.005" rpy="1.5708 0 0" />
      <geometry>
        <cylinder radius="0.014" length="0.042" />
        </geometry>
      <material name="bright_linear_rail">
        <color rgba="0.72 0.74 0.72 1" />
        </material>
      </visual>
    <visual name="guide_0">
      <origin xyz="-0.095 0 -0.26" rpy="0 0 0" />
      <geometry>
        <box size="0.03 0.14 0.42" />
        </geometry>
      <material name="safety_orange_carriage">
        <color rgba="0.95 0.42 0.08 1" />
        </material>
      </visual>
    <visual name="guide_1">
      <origin xyz="0.095 0 -0.26" rpy="0 0 0" />
      <geometry>
        <box size="0.03 0.14 0.42" />
        </geometry>
      <material name="safety_orange_carriage">
        <color rgba="0.95 0.42 0.08 1" />
        </material>
      </visual>
    <visual name="guide_backstrap">
      <origin xyz="0 0.0875 -0.27" rpy="0 0 0" />
      <geometry>
        <box size="0.22 0.035 0.34" />
        </geometry>
      <material name="safety_orange_carriage">
        <color rgba="0.95 0.42 0.08 1" />
        </material>
      </visual>
    <collision name="carriage_block">
      <origin xyz="0 0 -0.035" rpy="0 0 0" />
      <geometry>
        <box size="0.42 0.23 0.08" />
        </geometry>
      </collision>
    <collision name="lower_saddle">
      <origin xyz="0 0 -0.062" rpy="0 0 0" />
      <geometry>
        <box size="0.34 0.16 0.035" />
        </geometry>
      </collision>
    <collision name="roller_0_0">
      <origin xyz="-0.13 -0.074 0.005" rpy="1.5708 0 0" />
      <geometry>
        <cylinder radius="0.025" length="0.036" />
        </geometry>
      </collision>
    <collision name="roller_hub_0_0">
      <origin xyz="-0.13 -0.074 0.005" rpy="1.5708 0 0" />
      <geometry>
        <cylinder radius="0.014" length="0.042" />
        </geometry>
      </collision>
    <collision name="roller_0_1">
      <origin xyz="-0.13 0.074 0.005" rpy="1.5708 0 0" />
      <geometry>
        <cylinder radius="0.025" length="0.036" />
        </geometry>
      </collision>
    <collision name="roller_hub_0_1">
      <origin xyz="-0.13 0.074 0.005" rpy="1.5708 0 0" />
      <geometry>
        <cylinder radius="0.014" length="0.042" />
        </geometry>
      </collision>
    <collision name="roller_1_0">
      <origin xyz="0.13 -0.074 0.005" rpy="1.5708 0 0" />
      <geometry>
        <cylinder radius="0.025" length="0.036" />
        </geometry>
      </collision>
    <collision name="roller_hub_1_0">
      <origin xyz="0.13 -0.074 0.005" rpy="1.5708 0 0" />
      <geometry>
        <cylinder radius="0.014" length="0.042" />
        </geometry>
      </collision>
    <collision name="roller_1_1">
      <origin xyz="0.13 0.074 0.005" rpy="1.5708 0 0" />
      <geometry>
        <cylinder radius="0.025" length="0.036" />
        </geometry>
      </collision>
    <collision name="roller_hub_1_1">
      <origin xyz="0.13 0.074 0.005" rpy="1.5708 0 0" />
      <geometry>
        <cylinder radius="0.014" length="0.042" />
        </geometry>
      </collision>
    <collision name="guide_0">
      <origin xyz="-0.095 0 -0.26" rpy="0 0 0" />
      <geometry>
        <box size="0.03 0.14 0.42" />
        </geometry>
      </collision>
    <collision name="guide_1">
      <origin xyz="0.095 0 -0.26" rpy="0 0 0" />
      <geometry>
        <box size="0.03 0.14 0.42" />
        </geometry>
      </collision>
    <collision name="guide_backstrap">
      <origin xyz="0 0.0875 -0.27" rpy="0 0 0" />
      <geometry>
        <box size="0.22 0.035 0.34" />
        </geometry>
      </collision>
    </link>
  <link name="z_slide">
    <visual name="slide_plate">
      <origin xyz="0 0 -0.23" rpy="0 0 0" />
      <geometry>
        <box size="0.11 0.075 0.46" />
        </geometry>
      <material name="blue_z_slide">
        <color rgba="0.05 0.17 0.34 1" />
        </material>
      </visual>
    <visual name="bearing_shoe_0_0">
      <origin xyz="-0.0675 0 -0.125" rpy="0 0 0" />
      <geometry>
        <box size="0.025 0.09 0.07" />
        </geometry>
      <material name="bright_linear_rail">
        <color rgba="0.72 0.74 0.72 1" />
        </material>
      </visual>
    <visual name="bearing_shoe_0_1">
      <origin xyz="-0.0675 0 -0.315" rpy="0 0 0" />
      <geometry>
        <box size="0.025 0.09 0.07" />
        </geometry>
      <material name="bright_linear_rail">
        <color rgba="0.72 0.74 0.72 1" />
        </material>
      </visual>
    <visual name="bearing_shoe_1_0">
      <origin xyz="0.0675 0 -0.125" rpy="0 0 0" />
      <geometry>
        <box size="0.025 0.09 0.07" />
        </geometry>
      <material name="bright_linear_rail">
        <color rgba="0.72 0.74 0.72 1" />
        </material>
      </visual>
    <visual name="bearing_shoe_1_1">
      <origin xyz="0.0675 0 -0.315" rpy="0 0 0" />
      <geometry>
        <box size="0.025 0.09 0.07" />
        </geometry>
      <material name="bright_linear_rail">
        <color rgba="0.72 0.74 0.72 1" />
        </material>
      </visual>
    <visual name="tool_mount">
      <origin xyz="0 0 -0.485" rpy="0 0 0" />
      <geometry>
        <box size="0.2 0.13 0.05" />
        </geometry>
      <material name="machined_tool_plate">
        <color rgba="0.62 0.64 0.62 1" />
        </material>
      </visual>
    <visual name="lead_screw">
      <origin xyz="0 -0.0555 -0.235" rpy="0 0 0" />
      <geometry>
        <cylinder radius="0.018" length="0.3" />
        </geometry>
      <material name="bright_linear_rail">
        <color rgba="0.72 0.74 0.72 1" />
        </material>
      </visual>
    <collision name="slide_plate">
      <origin xyz="0 0 -0.23" rpy="0 0 0" />
      <geometry>
        <box size="0.11 0.075 0.46" />
        </geometry>
      </collision>
    <collision name="bearing_shoe_0_0">
      <origin xyz="-0.0675 0 -0.125" rpy="0 0 0" />
      <geometry>
        <box size="0.025 0.09 0.07" />
        </geometry>
      </collision>
    <collision name="bearing_shoe_0_1">
      <origin xyz="-0.0675 0 -0.315" rpy="0 0 0" />
      <geometry>
        <box size="0.025 0.09 0.07" />
        </geometry>
      </collision>
    <collision name="bearing_shoe_1_0">
      <origin xyz="0.0675 0 -0.125" rpy="0 0 0" />
      <geometry>
        <box size="0.025 0.09 0.07" />
        </geometry>
      </collision>
    <collision name="bearing_shoe_1_1">
      <origin xyz="0.0675 0 -0.315" rpy="0 0 0" />
      <geometry>
        <box size="0.025 0.09 0.07" />
        </geometry>
      </collision>
    <collision name="tool_mount">
      <origin xyz="0 0 -0.485" rpy="0 0 0" />
      <geometry>
        <box size="0.2 0.13 0.05" />
        </geometry>
      </collision>
    <collision name="lead_screw">
      <origin xyz="0 -0.0555 -0.235" rpy="0 0 0" />
      <geometry>
        <cylinder radius="0.018" length="0.3" />
        </geometry>
      </collision>
    </link>
  <joint name="frame_to_carriage" type="prismatic">
    <origin xyz="0 0 1.34" rpy="0 0 0" />
    <parent link="frame" />
    <child link="beam_carriage" />
    <axis xyz="1 0 0" />
    <limit effort="350" velocity="0.65" lower="-0.55" upper="0.55" />
    </joint>
  <joint name="carriage_to_z_slide" type="prismatic">
    <origin xyz="0 0 -0.08" rpy="0 0 0" />
    <parent link="beam_carriage" />
    <child link="z_slide" />
    <axis xyz="0 0 -1" />
    <limit effort="220" velocity="0.35" lower="0" upper="0.22" />
    </joint>
  </robot>
