<robot name="recessed_wall_safe">
  <material name="gunmetal">
    <color rgba="0.13 0.15 0.16 1" />
    </material>
  <material name="dark_steel">
    <color rgba="0.06 0.07 0.075 1" />
    </material>
  <material name="satin_steel">
    <color rgba="0.62 0.64 0.62 1" />
    </material>
  <material name="black_dial">
    <color rgba="0.015 0.015 0.018 1" />
    </material>
  <material name="white_mark">
    <color rgba="0.92 0.9 0.84 1" />
    </material>
  <material name="green_felt">
    <color rgba="0.05 0.28 0.13 1" />
    </material>
  <material name="tray_paint">
    <color rgba="0.26 0.25 0.23 1" />
    </material>
  <material name="painted_wall">
    <color rgba="0.78 0.74 0.66 1" />
    </material>
  <link name="body">
    <visual name="wall_left">
      <origin xyz="-0.365 -0.15 0" rpy="0 0 0" />
      <geometry>
        <box size="0.17 0.024 0.9" />
        </geometry>
      <material name="painted_wall">
        <color rgba="0.78 0.74 0.66 1" />
        </material>
      </visual>
    <visual name="wall_right">
      <origin xyz="0.365 -0.15 0" rpy="0 0 0" />
      <geometry>
        <box size="0.17 0.024 0.9" />
        </geometry>
      <material name="painted_wall">
        <color rgba="0.78 0.74 0.66 1" />
        </material>
      </visual>
    <visual name="wall_top">
      <origin xyz="0 -0.15 0.365" rpy="0 0 0" />
      <geometry>
        <box size="0.56 0.024 0.17" />
        </geometry>
      <material name="painted_wall">
        <color rgba="0.78 0.74 0.66 1" />
        </material>
      </visual>
    <visual name="wall_bottom">
      <origin xyz="0 -0.15 -0.365" rpy="0 0 0" />
      <geometry>
        <box size="0.56 0.024 0.17" />
        </geometry>
      <material name="painted_wall">
        <color rgba="0.78 0.74 0.66 1" />
        </material>
      </visual>
    <visual name="left_wall">
      <origin xyz="-0.22 0 0" rpy="0 0 0" />
      <geometry>
        <box size="0.04 0.22 0.44" />
        </geometry>
      <material name="gunmetal">
        <color rgba="0.13 0.15 0.16 1" />
        </material>
      </visual>
    <visual name="right_wall">
      <origin xyz="0.22 0 0" rpy="0 0 0" />
      <geometry>
        <box size="0.04 0.22 0.44" />
        </geometry>
      <material name="gunmetal">
        <color rgba="0.13 0.15 0.16 1" />
        </material>
      </visual>
    <visual name="top_wall">
      <origin xyz="0 0 0.22" rpy="0 0 0" />
      <geometry>
        <box size="0.48 0.22 0.04" />
        </geometry>
      <material name="gunmetal">
        <color rgba="0.13 0.15 0.16 1" />
        </material>
      </visual>
    <visual name="bottom_wall">
      <origin xyz="0 0 -0.22" rpy="0 0 0" />
      <geometry>
        <box size="0.48 0.22 0.04" />
        </geometry>
      <material name="gunmetal">
        <color rgba="0.13 0.15 0.16 1" />
        </material>
      </visual>
    <visual name="back_wall">
      <origin xyz="0 0.111 0" rpy="0 0 0" />
      <geometry>
        <box size="0.44 0.018 0.44" />
        </geometry>
      <material name="dark_steel">
        <color rgba="0.06 0.07 0.075 1" />
        </material>
      </visual>
    <visual name="frame_left">
      <origin xyz="-0.24 -0.126 0" rpy="0 0 0" />
      <geometry>
        <box size="0.08 0.036 0.52" />
        </geometry>
      <material name="dark_steel">
        <color rgba="0.06 0.07 0.075 1" />
        </material>
      </visual>
    <visual name="frame_right">
      <origin xyz="0.24 -0.126 0" rpy="0 0 0" />
      <geometry>
        <box size="0.08 0.036 0.52" />
        </geometry>
      <material name="dark_steel">
        <color rgba="0.06 0.07 0.075 1" />
        </material>
      </visual>
    <visual name="frame_top">
      <origin xyz="0 -0.126 0.24" rpy="0 0 0" />
      <geometry>
        <box size="0.56 0.036 0.08" />
        </geometry>
      <material name="dark_steel">
        <color rgba="0.06 0.07 0.075 1" />
        </material>
      </visual>
    <visual name="frame_bottom">
      <origin xyz="0 -0.126 -0.24" rpy="0 0 0" />
      <geometry>
        <box size="0.56 0.036 0.08" />
        </geometry>
      <material name="dark_steel">
        <color rgba="0.06 0.07 0.075 1" />
        </material>
      </visual>
    <visual name="left_runner">
      <origin xyz="-0.1885 -0.015 -0.115" rpy="0 0 0" />
      <geometry>
        <box size="0.025 0.12 0.018" />
        </geometry>
      <material name="satin_steel">
        <color rgba="0.62 0.64 0.62 1" />
        </material>
      </visual>
    <visual name="right_runner">
      <origin xyz="0.1885 -0.015 -0.115" rpy="0 0 0" />
      <geometry>
        <box size="0.025 0.12 0.018" />
        </geometry>
      <material name="satin_steel">
        <color rgba="0.62 0.64 0.62 1" />
        </material>
      </visual>
    <visual name="body_hinge_barrel_0">
      <origin xyz="0.205 -0.165 -0.145" rpy="0 0 0" />
      <geometry>
        <cylinder radius="0.012" length="0.07" />
        </geometry>
      <material name="satin_steel">
        <color rgba="0.62 0.64 0.62 1" />
        </material>
      </visual>
    <visual name="body_hinge_barrel_1">
      <origin xyz="0.205 -0.165 0.055" rpy="0 0 0" />
      <geometry>
        <cylinder radius="0.012" length="0.07" />
        </geometry>
      <material name="satin_steel">
        <color rgba="0.62 0.64 0.62 1" />
        </material>
      </visual>
    <visual name="body_hinge_leaf_0">
      <origin xyz="0.23 -0.147 -0.145" rpy="0 0 0" />
      <geometry>
        <box size="0.05 0.012 0.055" />
        </geometry>
      <material name="satin_steel">
        <color rgba="0.62 0.64 0.62 1" />
        </material>
      </visual>
    <visual name="body_hinge_leaf_1">
      <origin xyz="0.23 -0.147 0.055" rpy="0 0 0" />
      <geometry>
        <box size="0.05 0.012 0.055" />
        </geometry>
      <material name="satin_steel">
        <color rgba="0.62 0.64 0.62 1" />
        </material>
      </visual>
    <collision name="wall_left">
      <origin xyz="-0.365 -0.15 0" rpy="0 0 0" />
      <geometry>
        <box size="0.17 0.024 0.9" />
        </geometry>
      </collision>
    <collision name="wall_right">
      <origin xyz="0.365 -0.15 0" rpy="0 0 0" />
      <geometry>
        <box size="0.17 0.024 0.9" />
        </geometry>
      </collision>
    <collision name="wall_top">
      <origin xyz="0 -0.15 0.365" rpy="0 0 0" />
      <geometry>
        <box size="0.56 0.024 0.17" />
        </geometry>
      </collision>
    <collision name="wall_bottom">
      <origin xyz="0 -0.15 -0.365" rpy="0 0 0" />
      <geometry>
        <box size="0.56 0.024 0.17" />
        </geometry>
      </collision>
    <collision name="left_wall">
      <origin xyz="-0.22 0 0" rpy="0 0 0" />
      <geometry>
        <box size="0.04 0.22 0.44" />
        </geometry>
      </collision>
    <collision name="right_wall">
      <origin xyz="0.22 0 0" rpy="0 0 0" />
      <geometry>
        <box size="0.04 0.22 0.44" />
        </geometry>
      </collision>
    <collision name="top_wall">
      <origin xyz="0 0 0.22" rpy="0 0 0" />
      <geometry>
        <box size="0.48 0.22 0.04" />
        </geometry>
      </collision>
    <collision name="bottom_wall">
      <origin xyz="0 0 -0.22" rpy="0 0 0" />
      <geometry>
        <box size="0.48 0.22 0.04" />
        </geometry>
      </collision>
    <collision name="back_wall">
      <origin xyz="0 0.111 0" rpy="0 0 0" />
      <geometry>
        <box size="0.44 0.018 0.44" />
        </geometry>
      </collision>
    <collision name="frame_left">
      <origin xyz="-0.24 -0.126 0" rpy="0 0 0" />
      <geometry>
        <box size="0.08 0.036 0.52" />
        </geometry>
      </collision>
    <collision name="frame_right">
      <origin xyz="0.24 -0.126 0" rpy="0 0 0" />
      <geometry>
        <box size="0.08 0.036 0.52" />
        </geometry>
      </collision>
    <collision name="frame_top">
      <origin xyz="0 -0.126 0.24" rpy="0 0 0" />
      <geometry>
        <box size="0.56 0.036 0.08" />
        </geometry>
      </collision>
    <collision name="frame_bottom">
      <origin xyz="0 -0.126 -0.24" rpy="0 0 0" />
      <geometry>
        <box size="0.56 0.036 0.08" />
        </geometry>
      </collision>
    <collision name="left_runner">
      <origin xyz="-0.1885 -0.015 -0.115" rpy="0 0 0" />
      <geometry>
        <box size="0.025 0.12 0.018" />
        </geometry>
      </collision>
    <collision name="right_runner">
      <origin xyz="0.1885 -0.015 -0.115" rpy="0 0 0" />
      <geometry>
        <box size="0.025 0.12 0.018" />
        </geometry>
      </collision>
    <collision name="body_hinge_barrel_0">
      <origin xyz="0.205 -0.165 -0.145" rpy="0 0 0" />
      <geometry>
        <cylinder radius="0.012" length="0.07" />
        </geometry>
      </collision>
    <collision name="body_hinge_barrel_1">
      <origin xyz="0.205 -0.165 0.055" rpy="0 0 0" />
      <geometry>
        <cylinder radius="0.012" length="0.07" />
        </geometry>
      </collision>
    <collision name="body_hinge_leaf_0">
      <origin xyz="0.23 -0.147 -0.145" rpy="0 0 0" />
      <geometry>
        <box size="0.05 0.012 0.055" />
        </geometry>
      </collision>
    <collision name="body_hinge_leaf_1">
      <origin xyz="0.23 -0.147 0.055" rpy="0 0 0" />
      <geometry>
        <box size="0.05 0.012 0.055" />
        </geometry>
      </collision>
    </link>
  <link name="door">
    <visual name="door_slab">
      <origin xyz="-0.185 0.035 0" rpy="0 0 0" />
      <geometry>
        <box size="0.36 0.05 0.36" />
        </geometry>
      <material name="dark_steel">
        <color rgba="0.06 0.07 0.075 1" />
        </material>
      </visual>
    <visual name="recessed_face">
      <origin xyz="-0.185 0.0075 0" rpy="0 0 0" />
      <geometry>
        <box size="0.285 0.006 0.285" />
        </geometry>
      <material name="gunmetal">
        <color rgba="0.13 0.15 0.16 1" />
        </material>
      </visual>
    <visual name="dial_index">
      <origin xyz="-0.185 0.003 0.126" rpy="0 0 0" />
      <geometry>
        <box size="0.07 0.004 0.01" />
        </geometry>
      <material name="white_mark">
        <color rgba="0.92 0.9 0.84 1" />
        </material>
      </visual>
    <visual name="door_hinge_barrel_0">
      <origin xyz="0 0 -0.055" rpy="0 0 0" />
      <geometry>
        <cylinder radius="0.012" length="0.07" />
        </geometry>
      <material name="satin_steel">
        <color rgba="0.62 0.64 0.62 1" />
        </material>
      </visual>
    <visual name="door_hinge_barrel_1">
      <origin xyz="0 0 0.145" rpy="0 0 0" />
      <geometry>
        <cylinder radius="0.012" length="0.07" />
        </geometry>
      <material name="satin_steel">
        <color rgba="0.62 0.64 0.62 1" />
        </material>
      </visual>
    <visual name="door_hinge_leaf_0">
      <origin xyz="-0.018 0.006 -0.055" rpy="0 0 0" />
      <geometry>
        <box size="0.046 0.012 0.055" />
        </geometry>
      <material name="satin_steel">
        <color rgba="0.62 0.64 0.62 1" />
        </material>
      </visual>
    <visual name="door_hinge_leaf_1">
      <origin xyz="-0.018 0.006 0.145" rpy="0 0 0" />
      <geometry>
        <box size="0.046 0.012 0.055" />
        </geometry>
      <material name="satin_steel">
        <color rgba="0.62 0.64 0.62 1" />
        </material>
      </visual>
    <collision name="door_slab">
      <origin xyz="-0.185 0.035 0" rpy="0 0 0" />
      <geometry>
        <box size="0.36 0.05 0.36" />
        </geometry>
      </collision>
    <collision name="recessed_face">
      <origin xyz="-0.185 0.0075 0" rpy="0 0 0" />
      <geometry>
        <box size="0.285 0.006 0.285" />
        </geometry>
      </collision>
    <collision name="dial_index">
      <origin xyz="-0.185 0.003 0.126" rpy="0 0 0" />
      <geometry>
        <box size="0.07 0.004 0.01" />
        </geometry>
      </collision>
    <collision name="door_hinge_barrel_0">
      <origin xyz="0 0 -0.055" rpy="0 0 0" />
      <geometry>
        <cylinder radius="0.012" length="0.07" />
        </geometry>
      </collision>
    <collision name="door_hinge_barrel_1">
      <origin xyz="0 0 0.145" rpy="0 0 0" />
      <geometry>
        <cylinder radius="0.012" length="0.07" />
        </geometry>
      </collision>
    <collision name="door_hinge_leaf_0">
      <origin xyz="-0.018 0.006 -0.055" rpy="0 0 0" />
      <geometry>
        <box size="0.046 0.012 0.055" />
        </geometry>
      </collision>
    <collision name="door_hinge_leaf_1">
      <origin xyz="-0.018 0.006 0.145" rpy="0 0 0" />
      <geometry>
        <box size="0.046 0.012 0.055" />
        </geometry>
      </collision>
    </link>
  <link name="dial">
    <visual name="dial_shaft">
      <origin xyz="0 -0.004 0" rpy="1.5708 0 0" />
      <geometry>
        <cylinder radius="0.018" length="0.008" />
        </geometry>
      <material name="satin_steel">
        <color rgba="0.62 0.64 0.62 1" />
        </material>
      </visual>
    <visual name="dial_cap">
      <origin xyz="0 -0.018 0" rpy="1.5708 0 0" />
      <geometry>
        <mesh filename="assets/meshes/combination_dial.obj" />
        </geometry>
      <material name="black_dial">
        <color rgba="0.015 0.015 0.018 1" />
        </material>
      </visual>
    <collision name="dial_shaft">
      <origin xyz="0 -0.004 0" rpy="1.5708 0 0" />
      <geometry>
        <cylinder radius="0.018" length="0.008" />
        </geometry>
      </collision>
    <collision name="dial_cap">
      <origin xyz="0 -0.018 0" rpy="1.5708 0 0" />
      <geometry>
        <mesh filename="assets/meshes/combination_dial.obj" />
        </geometry>
      </collision>
    </link>
  <link name="handle">
    <visual name="handle_hub">
      <origin xyz="0 -0.015 0" rpy="1.5708 0 0" />
      <geometry>
        <cylinder radius="0.025" length="0.03" />
        </geometry>
      <material name="satin_steel">
        <color rgba="0.62 0.64 0.62 1" />
        </material>
      </visual>
    <visual name="spoke_0">
      <origin xyz="2.20436e-18 -0.029 0.036" rpy="0 -1.5708 0" />
      <geometry>
        <box size="0.075 0.012 0.012" />
        </geometry>
      <material name="satin_steel">
        <color rgba="0.62 0.64 0.62 1" />
        </material>
      </visual>
    <visual name="spoke_knob_0">
      <origin xyz="4.46996e-18 -0.029 0.073" rpy="0 0 0" />
      <geometry>
        <sphere radius="0.013" />
        </geometry>
      <material name="satin_steel">
        <color rgba="0.62 0.64 0.62 1" />
        </material>
      </visual>
    <visual name="spoke_1">
      <origin xyz="-0.0311769 -0.029 -0.018" rpy="0 -3.66519 0" />
      <geometry>
        <box size="0.075 0.012 0.012" />
        </geometry>
      <material name="satin_steel">
        <color rgba="0.62 0.64 0.62 1" />
        </material>
      </visual>
    <visual name="spoke_knob_1">
      <origin xyz="-0.0632199 -0.029 -0.0365" rpy="0 0 0" />
      <geometry>
        <sphere radius="0.013" />
        </geometry>
      <material name="satin_steel">
        <color rgba="0.62 0.64 0.62 1" />
        </material>
      </visual>
    <visual name="spoke_2">
      <origin xyz="0.0311769 -0.029 -0.018" rpy="0 -5.75959 0" />
      <geometry>
        <box size="0.075 0.012 0.012" />
        </geometry>
      <material name="satin_steel">
        <color rgba="0.62 0.64 0.62 1" />
        </material>
      </visual>
    <visual name="spoke_knob_2">
      <origin xyz="0.0632199 -0.029 -0.0365" rpy="0 0 0" />
      <geometry>
        <sphere radius="0.013" />
        </geometry>
      <material name="satin_steel">
        <color rgba="0.62 0.64 0.62 1" />
        </material>
      </visual>
    <collision name="handle_hub">
      <origin xyz="0 -0.015 0" rpy="1.5708 0 0" />
      <geometry>
        <cylinder radius="0.025" length="0.03" />
        </geometry>
      </collision>
    <collision name="spoke_0">
      <origin xyz="2.20436e-18 -0.029 0.036" rpy="0 -1.5708 0" />
      <geometry>
        <box size="0.075 0.012 0.012" />
        </geometry>
      </collision>
    <collision name="spoke_knob_0">
      <origin xyz="4.46996e-18 -0.029 0.073" rpy="0 0 0" />
      <geometry>
        <sphere radius="0.013" />
        </geometry>
      </collision>
    <collision name="spoke_1">
      <origin xyz="-0.0311769 -0.029 -0.018" rpy="0 -3.66519 0" />
      <geometry>
        <box size="0.075 0.012 0.012" />
        </geometry>
      </collision>
    <collision name="spoke_knob_1">
      <origin xyz="-0.0632199 -0.029 -0.0365" rpy="0 0 0" />
      <geometry>
        <sphere radius="0.013" />
        </geometry>
      </collision>
    <collision name="spoke_2">
      <origin xyz="0.0311769 -0.029 -0.018" rpy="0 -5.75959 0" />
      <geometry>
        <box size="0.075 0.012 0.012" />
        </geometry>
      </collision>
    <collision name="spoke_knob_2">
      <origin xyz="0.0632199 -0.029 -0.0365" rpy="0 0 0" />
      <geometry>
        <sphere radius="0.013" />
        </geometry>
      </collision>
    </link>
  <link name="tray">
    <visual name="tray_floor">
      <geometry>
        <box size="0.36 0.13 0.012" />
        </geometry>
      <material name="tray_paint">
        <color rgba="0.26 0.25 0.23 1" />
        </material>
      </visual>
    <visual name="left_lip">
      <origin xyz="-0.174 0 0.014" rpy="0 0 0" />
      <geometry>
        <box size="0.012 0.13 0.04" />
        </geometry>
      <material name="tray_paint">
        <color rgba="0.26 0.25 0.23 1" />
        </material>
      </visual>
    <visual name="right_lip">
      <origin xyz="0.174 0 0.014" rpy="0 0 0" />
      <geometry>
        <box size="0.012 0.13 0.04" />
        </geometry>
      <material name="tray_paint">
        <color rgba="0.26 0.25 0.23 1" />
        </material>
      </visual>
    <visual name="front_lip">
      <origin xyz="0 -0.059 0.014" rpy="0 0 0" />
      <geometry>
        <box size="0.36 0.012 0.04" />
        </geometry>
      <material name="tray_paint">
        <color rgba="0.26 0.25 0.23 1" />
        </material>
      </visual>
    <visual name="rear_lip">
      <origin xyz="0 0.059 0.014" rpy="0 0 0" />
      <geometry>
        <box size="0.36 0.012 0.04" />
        </geometry>
      <material name="tray_paint">
        <color rgba="0.26 0.25 0.23 1" />
        </material>
      </visual>
    <visual name="felt_pad">
      <origin xyz="0 0 0.0075" rpy="0 0 0" />
      <geometry>
        <box size="0.305 0.08 0.003" />
        </geometry>
      <material name="green_felt">
        <color rgba="0.05 0.28 0.13 1" />
        </material>
      </visual>
    <collision name="tray_floor">
      <geometry>
        <box size="0.36 0.13 0.012" />
        </geometry>
      </collision>
    <collision name="left_lip">
      <origin xyz="-0.174 0 0.014" rpy="0 0 0" />
      <geometry>
        <box size="0.012 0.13 0.04" />
        </geometry>
      </collision>
    <collision name="right_lip">
      <origin xyz="0.174 0 0.014" rpy="0 0 0" />
      <geometry>
        <box size="0.012 0.13 0.04" />
        </geometry>
      </collision>
    <collision name="front_lip">
      <origin xyz="0 -0.059 0.014" rpy="0 0 0" />
      <geometry>
        <box size="0.36 0.012 0.04" />
        </geometry>
      </collision>
    <collision name="rear_lip">
      <origin xyz="0 0.059 0.014" rpy="0 0 0" />
      <geometry>
        <box size="0.36 0.012 0.04" />
        </geometry>
      </collision>
    <collision name="felt_pad">
      <origin xyz="0 0 0.0075" rpy="0 0 0" />
      <geometry>
        <box size="0.305 0.08 0.003" />
        </geometry>
      </collision>
    </link>
  <joint name="body_to_door" type="revolute">
    <origin xyz="0.205 -0.165 0" rpy="0 0 0" />
    <parent link="body" />
    <child link="door" />
    <axis xyz="0 0 1" />
    <limit effort="80" velocity="1.2" lower="0" upper="1.75" />
    </joint>
  <joint name="door_to_dial" type="continuous">
    <origin xyz="-0.185 0.0045 0.07" rpy="0 0 0" />
    <parent link="door" />
    <child link="dial" />
    <axis xyz="0 -1 0" />
    <limit effort="1.2" velocity="6" />
    </joint>
  <joint name="door_to_handle" type="revolute">
    <origin xyz="-0.185 0.0045 -0.085" rpy="0 0 0" />
    <parent link="door" />
    <child link="handle" />
    <axis xyz="0 -1 0" />
    <limit effort="12" velocity="2.5" lower="-1.05" upper="1.05" />
    </joint>
  <joint name="body_to_tray" type="prismatic">
    <origin xyz="0 -0.015 -0.1" rpy="0 0 0" />
    <parent link="body" />
    <child link="tray" />
    <axis xyz="0 -1 0" />
    <limit effort="25" velocity="0.25" lower="0" upper="0.1" />
    </joint>
  </robot>
