<robot name="modern_rice_cooker">
  <material name="warm_white_porcelain">
    <color rgba="0.92 0.9 0.84 1" />
    </material>
  <material name="satin_warm_gray">
    <color rgba="0.72 0.72 0.68 1" />
    </material>
  <material name="charcoal_glass">
    <color rgba="0.025 0.03 0.035 1" />
    </material>
  <material name="dark_rubber">
    <color rgba="0.015 0.014 0.013 1" />
    </material>
  <material name="soft_touch_gray">
    <color rgba="0.45 0.47 0.48 1" />
    </material>
  <material name="latch_white">
    <color rgba="0.86 0.86 0.82 1" />
    </material>
  <material name="brushed_steel">
    <color rgba="0.7 0.72 0.72 1" />
    </material>
  <material name="vent_black">
    <color rgba="0.02 0.02 0.018 1" />
    </material>
  <link name="body">
    <visual name="oval_shell">
      <geometry>
        <mesh filename="assets/meshes/oval_housing_shell.obj" />
        </geometry>
      <material name="warm_white_porcelain">
        <color rgba="0.92 0.9 0.84 1" />
        </material>
      </visual>
    <visual name="lower_plinth">
      <origin xyz="0 0 0.02" rpy="0 0 0" />
      <geometry>
        <mesh filename="assets/meshes/lower_plinth.obj" />
        </geometry>
      <material name="dark_rubber">
        <color rgba="0.015 0.014 0.013 1" />
        </material>
      </visual>
    <visual name="inner_pot">
      <geometry>
        <mesh filename="assets/meshes/inner_cooking_pot.obj" />
        </geometry>
      <material name="brushed_steel">
        <color rgba="0.7 0.72 0.72 1" />
        </material>
      </visual>
    <visual name="pot_shadow">
      <origin xyz="0 0 0.222" rpy="0 0 0" />
      <geometry>
        <cylinder radius="0.146" length="0.004" />
        </geometry>
      <material name="charcoal_glass">
        <color rgba="0.025 0.03 0.035 1" />
        </material>
      </visual>
    <visual name="control_panel">
      <origin xyz="0 -0.184 0.136" rpy="0 0 0" />
      <geometry>
        <mesh filename="assets/meshes/front_control_panel.obj" />
        </geometry>
      <material name="charcoal_glass">
        <color rgba="0.025 0.03 0.035 1" />
        </material>
      </visual>
    <visual name="display_slot">
      <origin xyz="0 -0.194 0.194" rpy="0 0 0" />
      <geometry>
        <box size="0.21 0.01 0.006" />
        </geometry>
      <material name="soft_touch_gray">
        <color rgba="0.45 0.47 0.48 1" />
        </material>
      </visual>
    <visual name="front_foot_0">
      <origin xyz="-0.145 -0.11 0.018" rpy="0 0 0" />
      <geometry>
        <cylinder radius="0.024" length="0.018" />
        </geometry>
      <material name="dark_rubber">
        <color rgba="0.015 0.014 0.013 1" />
        </material>
      </visual>
    <visual name="front_foot_1">
      <origin xyz="0.145 -0.11 0.018" rpy="0 0 0" />
      <geometry>
        <cylinder radius="0.024" length="0.018" />
        </geometry>
      <material name="dark_rubber">
        <color rgba="0.015 0.014 0.013 1" />
        </material>
      </visual>
    <visual name="rear_foot_0">
      <origin xyz="-0.145 0.11 0.018" rpy="0 0 0" />
      <geometry>
        <cylinder radius="0.024" length="0.018" />
        </geometry>
      <material name="dark_rubber">
        <color rgba="0.015 0.014 0.013 1" />
        </material>
      </visual>
    <visual name="rear_foot_1">
      <origin xyz="0.145 0.11 0.018" rpy="0 0 0" />
      <geometry>
        <cylinder radius="0.024" length="0.018" />
        </geometry>
      <material name="dark_rubber">
        <color rgba="0.015 0.014 0.013 1" />
        </material>
      </visual>
    <visual name="hinge_knuckle_0">
      <origin xyz="-0.155 0.166 0.27" rpy="0 1.5708 0" />
      <geometry>
        <cylinder radius="0.016" length="0.052" />
        </geometry>
      <material name="satin_warm_gray">
        <color rgba="0.72 0.72 0.68 1" />
        </material>
      </visual>
    <visual name="hinge_boss_0">
      <origin xyz="-0.155 0.156 0.25" rpy="0 0 0" />
      <geometry>
        <box size="0.05 0.03 0.04" />
        </geometry>
      <material name="warm_white_porcelain">
        <color rgba="0.92 0.9 0.84 1" />
        </material>
      </visual>
    <visual name="hinge_knuckle_1">
      <origin xyz="0.155 0.166 0.27" rpy="0 1.5708 0" />
      <geometry>
        <cylinder radius="0.016" length="0.052" />
        </geometry>
      <material name="satin_warm_gray">
        <color rgba="0.72 0.72 0.68 1" />
        </material>
      </visual>
    <visual name="hinge_boss_1">
      <origin xyz="0.155 0.156 0.25" rpy="0 0 0" />
      <geometry>
        <box size="0.05 0.03 0.04" />
        </geometry>
      <material name="warm_white_porcelain">
        <color rgba="0.92 0.9 0.84 1" />
        </material>
      </visual>
    <collision name="oval_shell">
      <geometry>
        <mesh filename="assets/meshes/oval_housing_shell.obj" />
        </geometry>
      </collision>
    <collision name="lower_plinth">
      <origin xyz="0 0 0.02" rpy="0 0 0" />
      <geometry>
        <mesh filename="assets/meshes/lower_plinth.obj" />
        </geometry>
      </collision>
    <collision name="inner_pot">
      <geometry>
        <mesh filename="assets/meshes/inner_cooking_pot.obj" />
        </geometry>
      </collision>
    <collision name="pot_shadow">
      <origin xyz="0 0 0.222" rpy="0 0 0" />
      <geometry>
        <cylinder radius="0.146" length="0.004" />
        </geometry>
      </collision>
    <collision name="control_panel">
      <origin xyz="0 -0.184 0.136" rpy="0 0 0" />
      <geometry>
        <mesh filename="assets/meshes/front_control_panel.obj" />
        </geometry>
      </collision>
    <collision name="display_slot">
      <origin xyz="0 -0.194 0.194" rpy="0 0 0" />
      <geometry>
        <box size="0.21 0.01 0.006" />
        </geometry>
      </collision>
    <collision name="front_foot_0">
      <origin xyz="-0.145 -0.11 0.018" rpy="0 0 0" />
      <geometry>
        <cylinder radius="0.024" length="0.018" />
        </geometry>
      </collision>
    <collision name="front_foot_1">
      <origin xyz="0.145 -0.11 0.018" rpy="0 0 0" />
      <geometry>
        <cylinder radius="0.024" length="0.018" />
        </geometry>
      </collision>
    <collision name="rear_foot_0">
      <origin xyz="-0.145 0.11 0.018" rpy="0 0 0" />
      <geometry>
        <cylinder radius="0.024" length="0.018" />
        </geometry>
      </collision>
    <collision name="rear_foot_1">
      <origin xyz="0.145 0.11 0.018" rpy="0 0 0" />
      <geometry>
        <cylinder radius="0.024" length="0.018" />
        </geometry>
      </collision>
    <collision name="hinge_knuckle_0">
      <origin xyz="-0.155 0.166 0.27" rpy="0 1.5708 0" />
      <geometry>
        <cylinder radius="0.016" length="0.052" />
        </geometry>
      </collision>
    <collision name="hinge_boss_0">
      <origin xyz="-0.155 0.156 0.25" rpy="0 0 0" />
      <geometry>
        <box size="0.05 0.03 0.04" />
        </geometry>
      </collision>
    <collision name="hinge_knuckle_1">
      <origin xyz="0.155 0.166 0.27" rpy="0 1.5708 0" />
      <geometry>
        <cylinder radius="0.016" length="0.052" />
        </geometry>
      </collision>
    <collision name="hinge_boss_1">
      <origin xyz="0.155 0.156 0.25" rpy="0 0 0" />
      <geometry>
        <box size="0.05 0.03 0.04" />
        </geometry>
      </collision>
    </link>
  <link name="lid">
    <visual name="lid_crown">
      <geometry>
        <mesh filename="assets/meshes/lid_crown.obj" />
        </geometry>
      <material name="satin_warm_gray">
        <color rgba="0.72 0.72 0.68 1" />
        </material>
      </visual>
    <visual name="hinge_barrel">
      <origin xyz="0 0 0" rpy="0 1.5708 0" />
      <geometry>
        <cylinder radius="0.0135" length="0.235" />
        </geometry>
      <material name="satin_warm_gray">
        <color rgba="0.72 0.72 0.68 1" />
        </material>
      </visual>
    <visual name="handle_recess">
      <origin xyz="0 -0.178 0.055" rpy="0 0 0" />
      <geometry>
        <mesh filename="assets/meshes/handle_recess.obj" />
        </geometry>
      <material name="soft_touch_gray">
        <color rgba="0.45 0.47 0.48 1" />
        </material>
      </visual>
    <visual name="hinge_strap">
      <origin xyz="0 -0.012 0.006" rpy="0 0 0" />
      <geometry>
        <box size="0.185 0.03 0.012" />
        </geometry>
      <material name="satin_warm_gray">
        <color rgba="0.72 0.72 0.68 1" />
        </material>
      </visual>
    <visual name="steam_vent">
      <origin xyz="0.105 -0.065 0.048" rpy="0 0 0" />
      <geometry>
        <cylinder radius="0.022" length="0.01" />
        </geometry>
      <material name="vent_black">
        <color rgba="0.02 0.02 0.018 1" />
        </material>
      </visual>
    <visual name="vent_slit_0">
      <origin xyz="0.095 -0.065 0.054" rpy="0 0 0" />
      <geometry>
        <box size="0.004 0.024 0.002" />
        </geometry>
      <material name="satin_warm_gray">
        <color rgba="0.72 0.72 0.68 1" />
        </material>
      </visual>
    <visual name="vent_slit_1">
      <origin xyz="0.105 -0.065 0.054" rpy="0 0 0" />
      <geometry>
        <box size="0.004 0.024 0.002" />
        </geometry>
      <material name="satin_warm_gray">
        <color rgba="0.72 0.72 0.68 1" />
        </material>
      </visual>
    <visual name="vent_slit_2">
      <origin xyz="0.115 -0.065 0.054" rpy="0 0 0" />
      <geometry>
        <box size="0.004 0.024 0.002" />
        </geometry>
      <material name="satin_warm_gray">
        <color rgba="0.72 0.72 0.68 1" />
        </material>
      </visual>
    <collision name="lid_crown">
      <geometry>
        <mesh filename="assets/meshes/lid_crown.obj" />
        </geometry>
      </collision>
    <collision name="hinge_barrel">
      <origin xyz="0 0 0" rpy="0 1.5708 0" />
      <geometry>
        <cylinder radius="0.0135" length="0.235" />
        </geometry>
      </collision>
    <collision name="handle_recess">
      <origin xyz="0 -0.178 0.055" rpy="0 0 0" />
      <geometry>
        <mesh filename="assets/meshes/handle_recess.obj" />
        </geometry>
      </collision>
    <collision name="hinge_strap">
      <origin xyz="0 -0.012 0.006" rpy="0 0 0" />
      <geometry>
        <box size="0.185 0.03 0.012" />
        </geometry>
      </collision>
    <collision name="steam_vent">
      <origin xyz="0.105 -0.065 0.048" rpy="0 0 0" />
      <geometry>
        <cylinder radius="0.022" length="0.01" />
        </geometry>
      </collision>
    <collision name="vent_slit_0">
      <origin xyz="0.095 -0.065 0.054" rpy="0 0 0" />
      <geometry>
        <box size="0.004 0.024 0.002" />
        </geometry>
      </collision>
    <collision name="vent_slit_1">
      <origin xyz="0.105 -0.065 0.054" rpy="0 0 0" />
      <geometry>
        <box size="0.004 0.024 0.002" />
        </geometry>
      </collision>
    <collision name="vent_slit_2">
      <origin xyz="0.115 -0.065 0.054" rpy="0 0 0" />
      <geometry>
        <box size="0.004 0.024 0.002" />
        </geometry>
      </collision>
    </link>
  <link name="latch_button">
    <visual name="button_cap">
      <geometry>
        <mesh filename="assets/meshes/latch_button_cap.obj" />
        </geometry>
      <material name="latch_white">
        <color rgba="0.86 0.86 0.82 1" />
        </material>
      </visual>
    <collision name="button_cap">
      <geometry>
        <mesh filename="assets/meshes/latch_button_cap.obj" />
        </geometry>
      </collision>
    </link>
  <link name="menu_button_0">
    <visual name="button_cap">
      <geometry>
        <mesh filename="assets/meshes/menu_button_0_cap.obj" />
        </geometry>
      <material name="soft_touch_gray">
        <color rgba="0.45 0.47 0.48 1" />
        </material>
      </visual>
    <visual name="button_mark">
      <origin xyz="0 -0.008 0" rpy="0 0 0" />
      <geometry>
        <box size="0.035 0.002 0.004" />
        </geometry>
      <material name="charcoal_glass">
        <color rgba="0.025 0.03 0.035 1" />
        </material>
      </visual>
    <collision name="button_cap">
      <geometry>
        <mesh filename="assets/meshes/menu_button_0_cap.obj" />
        </geometry>
      </collision>
    <collision name="button_mark">
      <origin xyz="0 -0.008 0" rpy="0 0 0" />
      <geometry>
        <box size="0.035 0.002 0.004" />
        </geometry>
      </collision>
    </link>
  <link name="menu_button_1">
    <visual name="button_cap">
      <geometry>
        <mesh filename="assets/meshes/menu_button_1_cap.obj" />
        </geometry>
      <material name="soft_touch_gray">
        <color rgba="0.45 0.47 0.48 1" />
        </material>
      </visual>
    <visual name="button_mark">
      <origin xyz="0 -0.008 0" rpy="0 0 0" />
      <geometry>
        <box size="0.004 0.002 0.02" />
        </geometry>
      <material name="charcoal_glass">
        <color rgba="0.025 0.03 0.035 1" />
        </material>
      </visual>
    <collision name="button_cap">
      <geometry>
        <mesh filename="assets/meshes/menu_button_1_cap.obj" />
        </geometry>
      </collision>
    <collision name="button_mark">
      <origin xyz="0 -0.008 0" rpy="0 0 0" />
      <geometry>
        <box size="0.004 0.002 0.02" />
        </geometry>
      </collision>
    </link>
  <joint name="body_to_lid" type="revolute">
    <origin xyz="0 0.166 0.27" rpy="0 0 0" />
    <parent link="body" />
    <child link="lid" />
    <axis xyz="-1 0 0" />
    <limit effort="4" velocity="2" lower="0" upper="1.22" />
    </joint>
  <joint name="body_to_latch_button" type="prismatic">
    <origin xyz="0 -0.198 0.172" rpy="0 0 0" />
    <parent link="body" />
    <child link="latch_button" />
    <axis xyz="0 1 0" />
    <limit effort="8" velocity="0.12" lower="0" upper="0.012" />
    </joint>
  <joint name="body_to_menu_button_0" type="prismatic">
    <origin xyz="-0.055 -0.197 0.108" rpy="0 0 0" />
    <parent link="body" />
    <child link="menu_button_0" />
    <axis xyz="0 1 0" />
    <limit effort="3" velocity="0.1" lower="0" upper="0.007" />
    </joint>
  <joint name="body_to_menu_button_1" type="prismatic">
    <origin xyz="0.055 -0.197 0.108" rpy="0 0 0" />
    <parent link="body" />
    <child link="menu_button_1" />
    <axis xyz="0 1 0" />
    <limit effort="3" velocity="0.1" lower="0" upper="0.007" />
    </joint>
  </robot>
