<robot name="three_wheel_folding_kick_scooter">
  <material name="powder_coated_blue">
    <color rgba="0.05 0.3 0.78 1" />
    </material>
  <material name="grit_black">
    <color rgba="0.015 0.015 0.014 1" />
    </material>
  <material name="matte_rubber_black">
    <color rgba="0.03 0.03 0.032 1" />
    </material>
  <material name="brushed_aluminum">
    <color rgba="0.74 0.76 0.75 1" />
    </material>
  <material name="white_plastic_rim">
    <color rgba="0.92 0.94 0.9 1" />
    </material>
  <material name="dark_hinge_pin">
    <color rgba="0.1 0.105 0.11 1" />
    </material>
  <link name="deck">
    <visual name="deck_center">
      <origin xyz="0 0 0.1125" rpy="0 0 0" />
      <geometry>
        <box size="0.47 0.19 0.035" />
        </geometry>
      <material name="powder_coated_blue">
        <color rgba="0.05 0.3 0.78 1" />
        </material>
      </visual>
    <visual name="rear_round">
      <origin xyz="-0.235 0 0.1125" rpy="0 0 0" />
      <geometry>
        <cylinder radius="0.095" length="0.035" />
        </geometry>
      <material name="powder_coated_blue">
        <color rgba="0.05 0.3 0.78 1" />
        </material>
      </visual>
    <visual name="front_round">
      <origin xyz="0.235 0 0.1125" rpy="0 0 0" />
      <geometry>
        <cylinder radius="0.095" length="0.035" />
        </geometry>
      <material name="powder_coated_blue">
        <color rgba="0.05 0.3 0.78 1" />
        </material>
      </visual>
    <visual name="grip_center">
      <origin xyz="0 0 0.131" rpy="0 0 0" />
      <geometry>
        <box size="0.37 0.15 0.003" />
        </geometry>
      <material name="grit_black">
        <color rgba="0.015 0.015 0.014 1" />
        </material>
      </visual>
    <visual name="grip_rear_round">
      <origin xyz="-0.185 0 0.131" rpy="0 0 0" />
      <geometry>
        <cylinder radius="0.075" length="0.003" />
        </geometry>
      <material name="grit_black">
        <color rgba="0.015 0.015 0.014 1" />
        </material>
      </visual>
    <visual name="grip_front_round">
      <origin xyz="0.185 0 0.131" rpy="0 0 0" />
      <geometry>
        <cylinder radius="0.075" length="0.003" />
        </geometry>
      <material name="grit_black">
        <color rgba="0.015 0.015 0.014 1" />
        </material>
      </visual>
    <visual name="side_rail_0">
      <origin xyz="0 -0.083 0.0945" rpy="0 0 0" />
      <geometry>
        <box size="0.53 0.014 0.014" />
        </geometry>
      <material name="brushed_aluminum">
        <color rgba="0.74 0.76 0.75 1" />
        </material>
      </visual>
    <visual name="side_rail_1">
      <origin xyz="0 0.083 0.0945" rpy="0 0 0" />
      <geometry>
        <box size="0.53 0.014 0.014" />
        </geometry>
      <material name="brushed_aluminum">
        <color rgba="0.74 0.76 0.75 1" />
        </material>
      </visual>
    <visual name="rear_fork_0">
      <origin xyz="-0.375 -0.04 0.0825" rpy="0 0 0" />
      <geometry>
        <box size="0.12 0.012 0.055" />
        </geometry>
      <material name="brushed_aluminum">
        <color rgba="0.74 0.76 0.75 1" />
        </material>
      </visual>
    <visual name="rear_fork_1">
      <origin xyz="-0.375 0.04 0.0825" rpy="0 0 0" />
      <geometry>
        <box size="0.12 0.012 0.055" />
        </geometry>
      <material name="brushed_aluminum">
        <color rgba="0.74 0.76 0.75 1" />
        </material>
      </visual>
    <visual name="rear_axle_pin">
      <origin xyz="-0.405 0 0.07" rpy="1.5708 0 0" />
      <geometry>
        <cylinder radius="0.008" length="0.105" />
        </geometry>
      <material name="dark_hinge_pin">
        <color rgba="0.1 0.105 0.11 1" />
        </material>
      </visual>
    <visual name="rear_brake_fender">
      <origin xyz="-0.395 0 0.154" rpy="0 0 0" />
      <geometry>
        <box size="0.105 0.062 0.006" />
        </geometry>
      <material name="powder_coated_blue">
        <color rgba="0.05 0.3 0.78 1" />
        </material>
      </visual>
    <visual name="rear_fender_strut_0">
      <origin xyz="-0.365 -0.032 0.132" rpy="0 0 0" />
      <geometry>
        <box size="0.016 0.006 0.046" />
        </geometry>
      <material name="brushed_aluminum">
        <color rgba="0.74 0.76 0.75 1" />
        </material>
      </visual>
    <visual name="rear_fender_strut_1">
      <origin xyz="-0.365 0.032 0.132" rpy="0 0 0" />
      <geometry>
        <box size="0.016 0.006 0.046" />
        </geometry>
      <material name="brushed_aluminum">
        <color rgba="0.74 0.76 0.75 1" />
        </material>
      </visual>
    <visual name="hinge_cheek_0">
      <origin xyz="0.245 -0.06 0.155" rpy="0 0 0" />
      <geometry>
        <box size="0.08 0.016 0.07" />
        </geometry>
      <material name="brushed_aluminum">
        <color rgba="0.74 0.76 0.75 1" />
        </material>
      </visual>
    <visual name="hinge_cheek_1">
      <origin xyz="0.245 0.06 0.155" rpy="0 0 0" />
      <geometry>
        <box size="0.08 0.016 0.07" />
        </geometry>
      <material name="brushed_aluminum">
        <color rgba="0.74 0.76 0.75 1" />
        </material>
      </visual>
    <visual name="hinge_pin">
      <origin xyz="0.245 0 0.155" rpy="1.5708 0 0" />
      <geometry>
        <cylinder radius="0.009" length="0.15" />
        </geometry>
      <material name="dark_hinge_pin">
        <color rgba="0.1 0.105 0.11 1" />
        </material>
      </visual>
    <collision name="deck_center">
      <origin xyz="0 0 0.1125" rpy="0 0 0" />
      <geometry>
        <box size="0.47 0.19 0.035" />
        </geometry>
      </collision>
    <collision name="rear_round">
      <origin xyz="-0.235 0 0.1125" rpy="0 0 0" />
      <geometry>
        <cylinder radius="0.095" length="0.035" />
        </geometry>
      </collision>
    <collision name="front_round">
      <origin xyz="0.235 0 0.1125" rpy="0 0 0" />
      <geometry>
        <cylinder radius="0.095" length="0.035" />
        </geometry>
      </collision>
    <collision name="grip_center">
      <origin xyz="0 0 0.131" rpy="0 0 0" />
      <geometry>
        <box size="0.37 0.15 0.003" />
        </geometry>
      </collision>
    <collision name="grip_rear_round">
      <origin xyz="-0.185 0 0.131" rpy="0 0 0" />
      <geometry>
        <cylinder radius="0.075" length="0.003" />
        </geometry>
      </collision>
    <collision name="grip_front_round">
      <origin xyz="0.185 0 0.131" rpy="0 0 0" />
      <geometry>
        <cylinder radius="0.075" length="0.003" />
        </geometry>
      </collision>
    <collision name="side_rail_0">
      <origin xyz="0 -0.083 0.0945" rpy="0 0 0" />
      <geometry>
        <box size="0.53 0.014 0.014" />
        </geometry>
      </collision>
    <collision name="side_rail_1">
      <origin xyz="0 0.083 0.0945" rpy="0 0 0" />
      <geometry>
        <box size="0.53 0.014 0.014" />
        </geometry>
      </collision>
    <collision name="rear_fork_0">
      <origin xyz="-0.375 -0.04 0.0825" rpy="0 0 0" />
      <geometry>
        <box size="0.12 0.012 0.055" />
        </geometry>
      </collision>
    <collision name="rear_fork_1">
      <origin xyz="-0.375 0.04 0.0825" rpy="0 0 0" />
      <geometry>
        <box size="0.12 0.012 0.055" />
        </geometry>
      </collision>
    <collision name="rear_axle_pin">
      <origin xyz="-0.405 0 0.07" rpy="1.5708 0 0" />
      <geometry>
        <cylinder radius="0.008" length="0.105" />
        </geometry>
      </collision>
    <collision name="rear_brake_fender">
      <origin xyz="-0.395 0 0.154" rpy="0 0 0" />
      <geometry>
        <box size="0.105 0.062 0.006" />
        </geometry>
      </collision>
    <collision name="rear_fender_strut_0">
      <origin xyz="-0.365 -0.032 0.132" rpy="0 0 0" />
      <geometry>
        <box size="0.016 0.006 0.046" />
        </geometry>
      </collision>
    <collision name="rear_fender_strut_1">
      <origin xyz="-0.365 0.032 0.132" rpy="0 0 0" />
      <geometry>
        <box size="0.016 0.006 0.046" />
        </geometry>
      </collision>
    <collision name="hinge_cheek_0">
      <origin xyz="0.245 -0.06 0.155" rpy="0 0 0" />
      <geometry>
        <box size="0.08 0.016 0.07" />
        </geometry>
      </collision>
    <collision name="hinge_cheek_1">
      <origin xyz="0.245 0.06 0.155" rpy="0 0 0" />
      <geometry>
        <box size="0.08 0.016 0.07" />
        </geometry>
      </collision>
    <collision name="hinge_pin">
      <origin xyz="0.245 0 0.155" rpy="1.5708 0 0" />
      <geometry>
        <cylinder radius="0.009" length="0.15" />
        </geometry>
      </collision>
    </link>
  <link name="front_fork">
    <visual name="front_mount">
      <origin xyz="0.013 0 0" rpy="0 0 0" />
      <geometry>
        <box size="0.026 0.105 0.06" />
        </geometry>
      <material name="brushed_aluminum">
        <color rgba="0.74 0.76 0.75 1" />
        </material>
      </visual>
    <visual name="fork_stem">
      <origin xyz="0.042 0 0.0475" rpy="0 0.526943 0" />
      <geometry>
        <cylinder radius="0.014" length="0.0636318" />
        </geometry>
      <material name="brushed_aluminum">
        <color rgba="0.74 0.76 0.75 1" />
        </material>
      </visual>
    <visual name="fork_arm_0">
      <origin xyz="0.083 -0.048 0.0725" rpy="0 1.61696 -1.09062" />
      <geometry>
        <cylinder radius="0.009" length="0.108356" />
        </geometry>
      <material name="brushed_aluminum">
        <color rgba="0.74 0.76 0.75 1" />
        </material>
      </visual>
    <visual name="fork_arm_1">
      <origin xyz="0.083 0.048 0.0725" rpy="0 1.61696 1.09062" />
      <geometry>
        <cylinder radius="0.009" length="0.108356" />
        </geometry>
      <material name="brushed_aluminum">
        <color rgba="0.74 0.76 0.75 1" />
        </material>
      </visual>
    <visual name="fork_center_web">
      <origin xyz="0.084 0 0.0575" rpy="0 2.16322 0" />
      <geometry>
        <cylinder radius="0.01" length="0.0626817" />
        </geometry>
      <material name="brushed_aluminum">
        <color rgba="0.74 0.76 0.75 1" />
        </material>
      </visual>
    <visual name="front_lug_0">
      <origin xyz="0.11 -0.096 -0.005" rpy="0 0 0" />
      <geometry>
        <box size="0.04 0.012 0.15" />
        </geometry>
      <material name="brushed_aluminum">
        <color rgba="0.74 0.76 0.75 1" />
        </material>
      </visual>
    <visual name="front_lug_1">
      <origin xyz="0.11 0.096 -0.005" rpy="0 0 0" />
      <geometry>
        <box size="0.04 0.012 0.15" />
        </geometry>
      <material name="brushed_aluminum">
        <color rgba="0.74 0.76 0.75 1" />
        </material>
      </visual>
    <visual name="front_center_lug">
      <origin xyz="0.11 0 -0.005" rpy="0 0 0" />
      <geometry>
        <box size="0.04 0.018 0.15" />
        </geometry>
      <material name="brushed_aluminum">
        <color rgba="0.74 0.76 0.75 1" />
        </material>
      </visual>
    <visual name="front_axle_pin_0">
      <origin xyz="0.105 -0.065 -0.0425" rpy="1.5708 0 0" />
      <geometry>
        <cylinder radius="0.008" length="0.145" />
        </geometry>
      <material name="dark_hinge_pin">
        <color rgba="0.1 0.105 0.11 1" />
        </material>
      </visual>
    <visual name="front_axle_pin_1">
      <origin xyz="0.105 0.065 -0.0425" rpy="1.5708 0 0" />
      <geometry>
        <cylinder radius="0.008" length="0.145" />
        </geometry>
      <material name="dark_hinge_pin">
        <color rgba="0.1 0.105 0.11 1" />
        </material>
      </visual>
    <collision name="front_mount">
      <origin xyz="0.013 0 0" rpy="0 0 0" />
      <geometry>
        <box size="0.026 0.105 0.06" />
        </geometry>
      </collision>
    <collision name="fork_stem">
      <origin xyz="0.042 0 0.0475" rpy="0 0.526943 0" />
      <geometry>
        <cylinder radius="0.014" length="0.0636318" />
        </geometry>
      </collision>
    <collision name="fork_arm_0">
      <origin xyz="0.083 -0.048 0.0725" rpy="0 1.61696 -1.09062" />
      <geometry>
        <cylinder radius="0.009" length="0.108356" />
        </geometry>
      </collision>
    <collision name="fork_arm_1">
      <origin xyz="0.083 0.048 0.0725" rpy="0 1.61696 1.09062" />
      <geometry>
        <cylinder radius="0.009" length="0.108356" />
        </geometry>
      </collision>
    <collision name="fork_center_web">
      <origin xyz="0.084 0 0.0575" rpy="0 2.16322 0" />
      <geometry>
        <cylinder radius="0.01" length="0.0626817" />
        </geometry>
      </collision>
    <collision name="front_lug_0">
      <origin xyz="0.11 -0.096 -0.005" rpy="0 0 0" />
      <geometry>
        <box size="0.04 0.012 0.15" />
        </geometry>
      </collision>
    <collision name="front_lug_1">
      <origin xyz="0.11 0.096 -0.005" rpy="0 0 0" />
      <geometry>
        <box size="0.04 0.012 0.15" />
        </geometry>
      </collision>
    <collision name="front_center_lug">
      <origin xyz="0.11 0 -0.005" rpy="0 0 0" />
      <geometry>
        <box size="0.04 0.018 0.15" />
        </geometry>
      </collision>
    <collision name="front_axle_pin_0">
      <origin xyz="0.105 -0.065 -0.0425" rpy="1.5708 0 0" />
      <geometry>
        <cylinder radius="0.008" length="0.145" />
        </geometry>
      </collision>
    <collision name="front_axle_pin_1">
      <origin xyz="0.105 0.065 -0.0425" rpy="1.5708 0 0" />
      <geometry>
        <cylinder radius="0.008" length="0.145" />
        </geometry>
      </collision>
    </link>
  <link name="handlebar_stem">
    <visual name="folding_barrel">
      <origin xyz="0 0 0" rpy="1.5708 0 0" />
      <geometry>
        <cylinder radius="0.025" length="0.07" />
        </geometry>
      <material name="brushed_aluminum">
        <color rgba="0.74 0.76 0.75 1" />
        </material>
      </visual>
    <visual name="upright_tube">
      <origin xyz="0 0 0.4075" rpy="0 0 0" />
      <geometry>
        <cylinder radius="0.016" length="0.705" />
        </geometry>
      <material name="brushed_aluminum">
        <color rgba="0.74 0.76 0.75 1" />
        </material>
      </visual>
    <visual name="handlebar">
      <origin xyz="0 0 0.76" rpy="0 1.5708 1.5708" />
      <geometry>
        <cylinder radius="0.014" length="0.47" />
        </geometry>
      <material name="brushed_aluminum">
        <color rgba="0.74 0.76 0.75 1" />
        </material>
      </visual>
    <visual name="grip_0">
      <origin xyz="0 -0.2725 0.76" rpy="0 1.5708 1.5708" />
      <geometry>
        <cylinder radius="0.018" length="0.075" />
        </geometry>
      <material name="matte_rubber_black">
        <color rgba="0.03 0.03 0.032 1" />
        </material>
      </visual>
    <visual name="grip_1">
      <origin xyz="0 0.2725 0.76" rpy="0 1.5708 1.5708" />
      <geometry>
        <cylinder radius="0.018" length="0.075" />
        </geometry>
      <material name="matte_rubber_black">
        <color rgba="0.03 0.03 0.032 1" />
        </material>
      </visual>
    <visual name="lower_clamp">
      <origin xyz="0 0 0.04" rpy="0 0 0" />
      <geometry>
        <box size="0.035 0.05 0.03" />
        </geometry>
      <material name="brushed_aluminum">
        <color rgba="0.74 0.76 0.75 1" />
        </material>
      </visual>
    <collision name="folding_barrel">
      <origin xyz="0 0 0" rpy="1.5708 0 0" />
      <geometry>
        <cylinder radius="0.025" length="0.07" />
        </geometry>
      </collision>
    <collision name="upright_tube">
      <origin xyz="0 0 0.4075" rpy="0 0 0" />
      <geometry>
        <cylinder radius="0.016" length="0.705" />
        </geometry>
      </collision>
    <collision name="handlebar">
      <origin xyz="0 0 0.76" rpy="0 1.5708 1.5708" />
      <geometry>
        <cylinder radius="0.014" length="0.47" />
        </geometry>
      </collision>
    <collision name="grip_0">
      <origin xyz="0 -0.2725 0.76" rpy="0 1.5708 1.5708" />
      <geometry>
        <cylinder radius="0.018" length="0.075" />
        </geometry>
      </collision>
    <collision name="grip_1">
      <origin xyz="0 0.2725 0.76" rpy="0 1.5708 1.5708" />
      <geometry>
        <cylinder radius="0.018" length="0.075" />
        </geometry>
      </collision>
    <collision name="lower_clamp">
      <origin xyz="0 0 0.04" rpy="0 0 0" />
      <geometry>
        <box size="0.035 0.05 0.03" />
        </geometry>
      </collision>
    </link>
  <link name="front_wheel_0">
    <visual name="rim">
      <origin xyz="0 0 0" rpy="0 0 1.5708" />
      <geometry>
        <mesh filename="assets/meshes/scooter_plastic_wheel.obj" />
        </geometry>
      <material name="white_plastic_rim">
        <color rgba="0.92 0.94 0.9 1" />
        </material>
      </visual>
    <visual name="tire">
      <origin xyz="0 0 0" rpy="0 0 1.5708" />
      <geometry>
        <mesh filename="assets/meshes/scooter_black_tire.obj" />
        </geometry>
      <material name="matte_rubber_black">
        <color rgba="0.03 0.03 0.032 1" />
        </material>
      </visual>
    <collision name="rim">
      <origin xyz="0 0 0" rpy="0 0 1.5708" />
      <geometry>
        <mesh filename="assets/meshes/scooter_plastic_wheel.obj" />
        </geometry>
      </collision>
    <collision name="tire">
      <origin xyz="0 0 0" rpy="0 0 1.5708" />
      <geometry>
        <mesh filename="assets/meshes/scooter_black_tire.obj" />
        </geometry>
      </collision>
    </link>
  <link name="front_wheel_1">
    <visual name="rim">
      <origin xyz="0 0 0" rpy="0 0 1.5708" />
      <geometry>
        <mesh filename="assets/meshes/scooter_plastic_wheel.obj" />
        </geometry>
      <material name="white_plastic_rim">
        <color rgba="0.92 0.94 0.9 1" />
        </material>
      </visual>
    <visual name="tire">
      <origin xyz="0 0 0" rpy="0 0 1.5708" />
      <geometry>
        <mesh filename="assets/meshes/scooter_black_tire.obj" />
        </geometry>
      <material name="matte_rubber_black">
        <color rgba="0.03 0.03 0.032 1" />
        </material>
      </visual>
    <collision name="rim">
      <origin xyz="0 0 0" rpy="0 0 1.5708" />
      <geometry>
        <mesh filename="assets/meshes/scooter_plastic_wheel.obj" />
        </geometry>
      </collision>
    <collision name="tire">
      <origin xyz="0 0 0" rpy="0 0 1.5708" />
      <geometry>
        <mesh filename="assets/meshes/scooter_black_tire.obj" />
        </geometry>
      </collision>
    </link>
  <link name="rear_wheel">
    <visual name="rim">
      <origin xyz="0 0 0" rpy="0 0 1.5708" />
      <geometry>
        <mesh filename="assets/meshes/scooter_plastic_wheel.obj" />
        </geometry>
      <material name="white_plastic_rim">
        <color rgba="0.92 0.94 0.9 1" />
        </material>
      </visual>
    <visual name="tire">
      <origin xyz="0 0 0" rpy="0 0 1.5708" />
      <geometry>
        <mesh filename="assets/meshes/scooter_black_tire.obj" />
        </geometry>
      <material name="matte_rubber_black">
        <color rgba="0.03 0.03 0.032 1" />
        </material>
      </visual>
    <collision name="rim">
      <origin xyz="0 0 0" rpy="0 0 1.5708" />
      <geometry>
        <mesh filename="assets/meshes/scooter_plastic_wheel.obj" />
        </geometry>
      </collision>
    <collision name="tire">
      <origin xyz="0 0 0" rpy="0 0 1.5708" />
      <geometry>
        <mesh filename="assets/meshes/scooter_black_tire.obj" />
        </geometry>
      </collision>
    </link>
  <joint name="deck_to_front_fork" type="fixed">
    <origin xyz="0.33 0 0.1125" rpy="0 0 0" />
    <parent link="deck" />
    <child link="front_fork" />
    </joint>
  <joint name="deck_to_stem" type="revolute">
    <origin xyz="0.245 0 0.155" rpy="0 0 0" />
    <parent link="deck" />
    <child link="handlebar_stem" />
    <axis xyz="0 -1 0" />
    <limit effort="20" velocity="1.5" lower="0" upper="1.5" />
    </joint>
  <joint name="front_axle_0" type="continuous">
    <origin xyz="0.105 -0.065 -0.0425" rpy="0 0 0" />
    <parent link="front_fork" />
    <child link="front_wheel_0" />
    <axis xyz="0 1 0" />
    <limit effort="3" velocity="30" />
    </joint>
  <joint name="front_axle_1" type="continuous">
    <origin xyz="0.105 0.065 -0.0425" rpy="0 0 0" />
    <parent link="front_fork" />
    <child link="front_wheel_1" />
    <axis xyz="0 1 0" />
    <limit effort="3" velocity="30" />
    </joint>
  <joint name="rear_axle" type="continuous">
    <origin xyz="-0.405 0 0.07" rpy="0 0 0" />
    <parent link="deck" />
    <child link="rear_wheel" />
    <axis xyz="0 1 0" />
    <limit effort="3" velocity="30" />
    </joint>
  </robot>
