<robot name="cross_slide_milling_vise">
  <material name="dark_cast_iron">
    <color rgba="0.12 0.13 0.14 1" />
    </material>
  <material name="machined_steel">
    <color rgba="0.63 0.64 0.61 1" />
    </material>
  <material name="hardened_jaw_steel">
    <color rgba="0.46 0.48 0.49 1" />
    </material>
  <material name="black_oxide">
    <color rgba="0.02 0.022 0.025 1" />
    </material>
  <material name="oiled_slot">
    <color rgba="0.005 0.006 0.007 1" />
    </material>
  <link name="base">
    <visual name="base_block">
      <origin xyz="0 0 0.04" rpy="0 0 0" />
      <geometry>
        <box size="0.62 0.34 0.08" />
        </geometry>
      <material name="dark_cast_iron">
        <color rgba="0.12 0.13 0.14 1" />
        </material>
      </visual>
    <visual name="rear_x_way">
      <origin xyz="0 0.135 0.087" rpy="0 0 0" />
      <geometry>
        <box size="0.54 0.03 0.018" />
        </geometry>
      <material name="machined_steel">
        <color rgba="0.63 0.64 0.61 1" />
        </material>
      </visual>
    <visual name="front_x_way">
      <origin xyz="0 -0.135 0.087" rpy="0 0 0" />
      <geometry>
        <box size="0.54 0.03 0.018" />
        </geometry>
      <material name="machined_steel">
        <color rgba="0.63 0.64 0.61 1" />
        </material>
      </visual>
    <visual name="recessed_t_slot">
      <origin xyz="0.01 0 0.078" rpy="0 0 0" />
      <geometry>
        <box size="0.5 0.034 0.004" />
        </geometry>
      <material name="oiled_slot">
        <color rgba="0.005 0.006 0.007 1" />
        </material>
      </visual>
    <visual name="fixed_lower_jaw">
      <origin xyz="-0.245 0 0.1305" rpy="0 0 0" />
      <geometry>
        <box size="0.055 0.25 0.105" />
        </geometry>
      <material name="dark_cast_iron">
        <color rgba="0.12 0.13 0.14 1" />
        </material>
      </visual>
    <visual name="fixed_lower_plate">
      <origin xyz="-0.2145 0 0.136" rpy="0 0 0" />
      <geometry>
        <box size="0.006 0.22 0.072" />
        </geometry>
      <material name="hardened_jaw_steel">
        <color rgba="0.46 0.48 0.49 1" />
        </material>
      </visual>
    <visual name="fixed_lower_tooth_0">
      <origin xyz="-0.21 0 0.112" rpy="0 0 0" />
      <geometry>
        <box size="0.004 0.205 0.004" />
        </geometry>
      <material name="machined_steel">
        <color rgba="0.63 0.64 0.61 1" />
        </material>
      </visual>
    <visual name="fixed_lower_tooth_1">
      <origin xyz="-0.21 0 0.136" rpy="0 0 0" />
      <geometry>
        <box size="0.004 0.205 0.004" />
        </geometry>
      <material name="machined_steel">
        <color rgba="0.63 0.64 0.61 1" />
        </material>
      </visual>
    <visual name="fixed_lower_tooth_2">
      <origin xyz="-0.21 0 0.16" rpy="0 0 0" />
      <geometry>
        <box size="0.004 0.205 0.004" />
        </geometry>
      <material name="machined_steel">
        <color rgba="0.63 0.64 0.61 1" />
        </material>
      </visual>
    <visual name="x_screw_left_bearing">
      <origin xyz="-0.285 -0.171 0.082" rpy="0 0 0" />
      <geometry>
        <box size="0.042 0.04 0.055" />
        </geometry>
      <material name="dark_cast_iron">
        <color rgba="0.12 0.13 0.14 1" />
        </material>
      </visual>
    <visual name="x_screw_right_bearing">
      <origin xyz="0.285 -0.171 0.082" rpy="0 0 0" />
      <geometry>
        <box size="0.042 0.04 0.055" />
        </geometry>
      <material name="dark_cast_iron">
        <color rgba="0.12 0.13 0.14 1" />
        </material>
      </visual>
    <visual name="x_lead_screw">
      <origin xyz="0 -0.198 0.095" rpy="0 1.5708 0" />
      <geometry>
        <cylinder radius="0.007" length="0.7" />
        </geometry>
      <material name="machined_steel">
        <color rgba="0.63 0.64 0.61 1" />
        </material>
      </visual>
    <visual name="x_handwheel">
      <origin xyz="0.338 -0.198 0.095" rpy="0 1.5708 0" />
      <geometry>
        <cylinder radius="0.036" length="0.012" />
        </geometry>
      <material name="black_oxide">
        <color rgba="0.02 0.022 0.025 1" />
        </material>
      </visual>
    <visual name="x_wheel_spoke">
      <origin xyz="0.346 -0.198 0.119" rpy="0 0 0" />
      <geometry>
        <box size="0.01 0.007 0.06" />
        </geometry>
      <material name="black_oxide">
        <color rgba="0.02 0.022 0.025 1" />
        </material>
      </visual>
    <visual name="x_crank_knob">
      <origin xyz="0.358 -0.198 0.149" rpy="0 1.5708 0" />
      <geometry>
        <cylinder radius="0.008" length="0.032" />
        </geometry>
      <material name="machined_steel">
        <color rgba="0.63 0.64 0.61 1" />
        </material>
      </visual>
    <collision name="base_block">
      <origin xyz="0 0 0.04" rpy="0 0 0" />
      <geometry>
        <box size="0.62 0.34 0.08" />
        </geometry>
      </collision>
    <collision name="rear_x_way">
      <origin xyz="0 0.135 0.087" rpy="0 0 0" />
      <geometry>
        <box size="0.54 0.03 0.018" />
        </geometry>
      </collision>
    <collision name="front_x_way">
      <origin xyz="0 -0.135 0.087" rpy="0 0 0" />
      <geometry>
        <box size="0.54 0.03 0.018" />
        </geometry>
      </collision>
    <collision name="recessed_t_slot">
      <origin xyz="0.01 0 0.078" rpy="0 0 0" />
      <geometry>
        <box size="0.5 0.034 0.004" />
        </geometry>
      </collision>
    <collision name="fixed_lower_jaw">
      <origin xyz="-0.245 0 0.1305" rpy="0 0 0" />
      <geometry>
        <box size="0.055 0.25 0.105" />
        </geometry>
      </collision>
    <collision name="fixed_lower_plate">
      <origin xyz="-0.2145 0 0.136" rpy="0 0 0" />
      <geometry>
        <box size="0.006 0.22 0.072" />
        </geometry>
      </collision>
    <collision name="fixed_lower_tooth_0">
      <origin xyz="-0.21 0 0.112" rpy="0 0 0" />
      <geometry>
        <box size="0.004 0.205 0.004" />
        </geometry>
      </collision>
    <collision name="fixed_lower_tooth_1">
      <origin xyz="-0.21 0 0.136" rpy="0 0 0" />
      <geometry>
        <box size="0.004 0.205 0.004" />
        </geometry>
      </collision>
    <collision name="fixed_lower_tooth_2">
      <origin xyz="-0.21 0 0.16" rpy="0 0 0" />
      <geometry>
        <box size="0.004 0.205 0.004" />
        </geometry>
      </collision>
    <collision name="x_screw_left_bearing">
      <origin xyz="-0.285 -0.171 0.082" rpy="0 0 0" />
      <geometry>
        <box size="0.042 0.04 0.055" />
        </geometry>
      </collision>
    <collision name="x_screw_right_bearing">
      <origin xyz="0.285 -0.171 0.082" rpy="0 0 0" />
      <geometry>
        <box size="0.042 0.04 0.055" />
        </geometry>
      </collision>
    <collision name="x_lead_screw">
      <origin xyz="0 -0.198 0.095" rpy="0 1.5708 0" />
      <geometry>
        <cylinder radius="0.007" length="0.7" />
        </geometry>
      </collision>
    <collision name="x_handwheel">
      <origin xyz="0.338 -0.198 0.095" rpy="0 1.5708 0" />
      <geometry>
        <cylinder radius="0.036" length="0.012" />
        </geometry>
      </collision>
    <collision name="x_wheel_spoke">
      <origin xyz="0.346 -0.198 0.119" rpy="0 0 0" />
      <geometry>
        <box size="0.01 0.007 0.06" />
        </geometry>
      </collision>
    <collision name="x_crank_knob">
      <origin xyz="0.358 -0.198 0.149" rpy="0 1.5708 0" />
      <geometry>
        <cylinder radius="0.008" length="0.032" />
        </geometry>
      </collision>
    </link>
  <link name="lower_jaw">
    <visual name="lower_saddle">
      <origin xyz="0 0 0.0225" rpy="0 0 0" />
      <geometry>
        <box size="0.32 0.2 0.045" />
        </geometry>
      <material name="dark_cast_iron">
        <color rgba="0.12 0.13 0.14 1" />
        </material>
      </visual>
    <visual name="moving_lower_jaw">
      <origin xyz="-0.135 0 0.088" rpy="0 0 0" />
      <geometry>
        <box size="0.048 0.22 0.09" />
        </geometry>
      <material name="dark_cast_iron">
        <color rgba="0.12 0.13 0.14 1" />
        </material>
      </visual>
    <visual name="moving_lower_plate">
      <origin xyz="-0.162 0 0.092" rpy="0 0 0" />
      <geometry>
        <box size="0.006 0.2 0.066" />
        </geometry>
      <material name="hardened_jaw_steel">
        <color rgba="0.46 0.48 0.49 1" />
        </material>
      </visual>
    <visual name="moving_lower_tooth_0">
      <origin xyz="-0.166 0 0.07" rpy="0 0 0" />
      <geometry>
        <box size="0.004 0.188 0.004" />
        </geometry>
      <material name="machined_steel">
        <color rgba="0.63 0.64 0.61 1" />
        </material>
      </visual>
    <visual name="moving_lower_tooth_1">
      <origin xyz="-0.166 0 0.092" rpy="0 0 0" />
      <geometry>
        <box size="0.004 0.188 0.004" />
        </geometry>
      <material name="machined_steel">
        <color rgba="0.63 0.64 0.61 1" />
        </material>
      </visual>
    <visual name="moving_lower_tooth_2">
      <origin xyz="-0.166 0 0.114" rpy="0 0 0" />
      <geometry>
        <box size="0.004 0.188 0.004" />
        </geometry>
      <material name="machined_steel">
        <color rgba="0.63 0.64 0.61 1" />
        </material>
      </visual>
    <visual name="left_y_way">
      <origin xyz="-0.115 0 0.052" rpy="0 0 0" />
      <geometry>
        <box size="0.028 0.19 0.018" />
        </geometry>
      <material name="machined_steel">
        <color rgba="0.63 0.64 0.61 1" />
        </material>
      </visual>
    <visual name="right_y_way">
      <origin xyz="0.115 0 0.052" rpy="0 0 0" />
      <geometry>
        <box size="0.028 0.19 0.018" />
        </geometry>
      <material name="machined_steel">
        <color rgba="0.63 0.64 0.61 1" />
        </material>
      </visual>
    <visual name="fixed_upper_jaw">
      <origin xyz="0 -0.085 0.078" rpy="0 0 0" />
      <geometry>
        <box size="0.16 0.035 0.07" />
        </geometry>
      <material name="dark_cast_iron">
        <color rgba="0.12 0.13 0.14 1" />
        </material>
      </visual>
    <visual name="fixed_upper_plate">
      <origin xyz="0 -0.066 0.08" rpy="0 0 0" />
      <geometry>
        <box size="0.145 0.006 0.052" />
        </geometry>
      <material name="hardened_jaw_steel">
        <color rgba="0.46 0.48 0.49 1" />
        </material>
      </visual>
    <visual name="y_screw_bearing">
      <origin xyz="0.167 0 0.08" rpy="0 0 0" />
      <geometry>
        <box size="0.045 0.06 0.075" />
        </geometry>
      <material name="dark_cast_iron">
        <color rgba="0.12 0.13 0.14 1" />
        </material>
      </visual>
    <visual name="y_lead_screw">
      <origin xyz="0.187 0 0.11" rpy="-1.5708 0 0" />
      <geometry>
        <cylinder radius="0.006" length="0.37" />
        </geometry>
      <material name="machined_steel">
        <color rgba="0.63 0.64 0.61 1" />
        </material>
      </visual>
    <visual name="y_handwheel">
      <origin xyz="0.187 0.178 0.11" rpy="-1.5708 0 0" />
      <geometry>
        <cylinder radius="0.029" length="0.01" />
        </geometry>
      <material name="black_oxide">
        <color rgba="0.02 0.022 0.025 1" />
        </material>
      </visual>
    <visual name="y_wheel_spoke">
      <origin xyz="0.187 0.184 0.13" rpy="0 0 0" />
      <geometry>
        <box size="0.006 0.01 0.05" />
        </geometry>
      <material name="black_oxide">
        <color rgba="0.02 0.022 0.025 1" />
        </material>
      </visual>
    <collision name="lower_saddle">
      <origin xyz="0 0 0.0225" rpy="0 0 0" />
      <geometry>
        <box size="0.32 0.2 0.045" />
        </geometry>
      </collision>
    <collision name="moving_lower_jaw">
      <origin xyz="-0.135 0 0.088" rpy="0 0 0" />
      <geometry>
        <box size="0.048 0.22 0.09" />
        </geometry>
      </collision>
    <collision name="moving_lower_plate">
      <origin xyz="-0.162 0 0.092" rpy="0 0 0" />
      <geometry>
        <box size="0.006 0.2 0.066" />
        </geometry>
      </collision>
    <collision name="moving_lower_tooth_0">
      <origin xyz="-0.166 0 0.07" rpy="0 0 0" />
      <geometry>
        <box size="0.004 0.188 0.004" />
        </geometry>
      </collision>
    <collision name="moving_lower_tooth_1">
      <origin xyz="-0.166 0 0.092" rpy="0 0 0" />
      <geometry>
        <box size="0.004 0.188 0.004" />
        </geometry>
      </collision>
    <collision name="moving_lower_tooth_2">
      <origin xyz="-0.166 0 0.114" rpy="0 0 0" />
      <geometry>
        <box size="0.004 0.188 0.004" />
        </geometry>
      </collision>
    <collision name="left_y_way">
      <origin xyz="-0.115 0 0.052" rpy="0 0 0" />
      <geometry>
        <box size="0.028 0.19 0.018" />
        </geometry>
      </collision>
    <collision name="right_y_way">
      <origin xyz="0.115 0 0.052" rpy="0 0 0" />
      <geometry>
        <box size="0.028 0.19 0.018" />
        </geometry>
      </collision>
    <collision name="fixed_upper_jaw">
      <origin xyz="0 -0.085 0.078" rpy="0 0 0" />
      <geometry>
        <box size="0.16 0.035 0.07" />
        </geometry>
      </collision>
    <collision name="fixed_upper_plate">
      <origin xyz="0 -0.066 0.08" rpy="0 0 0" />
      <geometry>
        <box size="0.145 0.006 0.052" />
        </geometry>
      </collision>
    <collision name="y_screw_bearing">
      <origin xyz="0.167 0 0.08" rpy="0 0 0" />
      <geometry>
        <box size="0.045 0.06 0.075" />
        </geometry>
      </collision>
    <collision name="y_lead_screw">
      <origin xyz="0.187 0 0.11" rpy="-1.5708 0 0" />
      <geometry>
        <cylinder radius="0.006" length="0.37" />
        </geometry>
      </collision>
    <collision name="y_handwheel">
      <origin xyz="0.187 0.178 0.11" rpy="-1.5708 0 0" />
      <geometry>
        <cylinder radius="0.029" length="0.01" />
        </geometry>
      </collision>
    <collision name="y_wheel_spoke">
      <origin xyz="0.187 0.184 0.13" rpy="0 0 0" />
      <geometry>
        <box size="0.006 0.01 0.05" />
        </geometry>
      </collision>
    </link>
  <link name="upper_jaw">
    <visual name="upper_table">
      <origin xyz="0 0.055 0.0175" rpy="0 0 0" />
      <geometry>
        <box size="0.18 0.15 0.035" />
        </geometry>
      <material name="dark_cast_iron">
        <color rgba="0.12 0.13 0.14 1" />
        </material>
      </visual>
    <visual name="moving_upper_jaw">
      <origin xyz="0 0.035 0.068" rpy="0 0 0" />
      <geometry>
        <box size="0.16 0.04 0.07" />
        </geometry>
      <material name="dark_cast_iron">
        <color rgba="0.12 0.13 0.14 1" />
        </material>
      </visual>
    <visual name="moving_upper_plate">
      <origin xyz="0 0.012 0.07" rpy="0 0 0" />
      <geometry>
        <box size="0.145 0.006 0.052" />
        </geometry>
      <material name="hardened_jaw_steel">
        <color rgba="0.46 0.48 0.49 1" />
        </material>
      </visual>
    <visual name="upper_tooth_0">
      <origin xyz="-0.048 0.008 0.071" rpy="0 0 0" />
      <geometry>
        <box size="0.005 0.004 0.046" />
        </geometry>
      <material name="machined_steel">
        <color rgba="0.63 0.64 0.61 1" />
        </material>
      </visual>
    <visual name="upper_tooth_1">
      <origin xyz="0 0.008 0.071" rpy="0 0 0" />
      <geometry>
        <box size="0.005 0.004 0.046" />
        </geometry>
      <material name="machined_steel">
        <color rgba="0.63 0.64 0.61 1" />
        </material>
      </visual>
    <visual name="upper_tooth_2">
      <origin xyz="0.048 0.008 0.071" rpy="0 0 0" />
      <geometry>
        <box size="0.005 0.004 0.046" />
        </geometry>
      <material name="machined_steel">
        <color rgba="0.63 0.64 0.61 1" />
        </material>
      </visual>
    <collision name="upper_table">
      <origin xyz="0 0.055 0.0175" rpy="0 0 0" />
      <geometry>
        <box size="0.18 0.15 0.035" />
        </geometry>
      </collision>
    <collision name="moving_upper_jaw">
      <origin xyz="0 0.035 0.068" rpy="0 0 0" />
      <geometry>
        <box size="0.16 0.04 0.07" />
        </geometry>
      </collision>
    <collision name="moving_upper_plate">
      <origin xyz="0 0.012 0.07" rpy="0 0 0" />
      <geometry>
        <box size="0.145 0.006 0.052" />
        </geometry>
      </collision>
    <collision name="upper_tooth_0">
      <origin xyz="-0.048 0.008 0.071" rpy="0 0 0" />
      <geometry>
        <box size="0.005 0.004 0.046" />
        </geometry>
      </collision>
    <collision name="upper_tooth_1">
      <origin xyz="0 0.008 0.071" rpy="0 0 0" />
      <geometry>
        <box size="0.005 0.004 0.046" />
        </geometry>
      </collision>
    <collision name="upper_tooth_2">
      <origin xyz="0.048 0.008 0.071" rpy="0 0 0" />
      <geometry>
        <box size="0.005 0.004 0.046" />
        </geometry>
      </collision>
    </link>
  <joint name="x_cross_slide" type="prismatic">
    <origin xyz="0 0 0.08" rpy="0 0 0" />
    <parent link="base" />
    <child link="lower_jaw" />
    <axis xyz="1 0 0" />
    <limit effort="250" velocity="0.1" lower="0" upper="0.12" />
    </joint>
  <joint name="y_upper_slide" type="prismatic">
    <origin xyz="0 0 0.045" rpy="0 0 0" />
    <parent link="lower_jaw" />
    <child link="upper_jaw" />
    <axis xyz="0 1 0" />
    <limit effort="180" velocity="0.08" lower="-0.075" upper="0.06" />
    </joint>
  </robot>
