<robot name="retrofit_windshield_wiper">
  <material name="satin_black">
    <color rgba="0.015 0.017 0.016 1" />
    </material>
  <material name="aged_rubber">
    <color rgba="0.002 0.002 0.002 1" />
    </material>
  <material name="cadmium_steel">
    <color rgba="0.55 0.52 0.45 1" />
    </material>
  <material name="cast_aluminum">
    <color rgba="0.48 0.5 0.49 1" />
    </material>
  <material name="brass_bushings">
    <color rgba="0.72 0.56 0.22 1" />
    </material>
  <material name="smoky_glass">
    <color rgba="0.22 0.4 0.52 0.34" />
    </material>
  <material name="black_gasket">
    <color rgba="0.01 0.01 0.009 1" />
    </material>
  <material name="red_service_paint">
    <color rgba="0.55 0.07 0.035 1" />
    </material>
  <link name="cowl_frame">
    <visual name="cowl_tray">
      <origin xyz="0 0 0.014" rpy="0 0 0" />
      <geometry>
        <box size="1.4 0.2 0.028" />
        </geometry>
      <material name="satin_black">
        <color rgba="0.015 0.017 0.016 1" />
        </material>
      </visual>
    <visual name="front_lip">
      <origin xyz="0 -0.185 0.015" rpy="0 0 0" />
      <geometry>
        <box size="1.4 0.02 0.03" />
        </geometry>
      <material name="satin_black">
        <color rgba="0.015 0.017 0.016 1" />
        </material>
      </visual>
    <visual name="front_bridge">
      <origin xyz="0 -0.139 0.014" rpy="0 0 0" />
      <geometry>
        <box size="0.72 0.095 0.012" />
        </geometry>
      <material name="satin_black">
        <color rgba="0.015 0.017 0.016 1" />
        </material>
      </visual>
    <visual name="rear_riser">
      <origin xyz="0 0.096 0.074" rpy="0 0 0" />
      <geometry>
        <box size="1.4 0.02 0.12" />
        </geometry>
      <material name="satin_black">
        <color rgba="0.015 0.017 0.016 1" />
        </material>
      </visual>
    <visual name="glass_gasket">
      <origin xyz="0 0.266 0.136" rpy="0 0 0" />
      <geometry>
        <box size="0.72 0.352 0.018" />
        </geometry>
      <material name="black_gasket">
        <color rgba="0.01 0.01 0.009 1" />
        </material>
      </visual>
    <visual name="side_gasket_0">
      <origin xyz="-0.585 0.426 0.136" rpy="0 0 0" />
      <geometry>
        <box size="0.17 0.04 0.018" />
        </geometry>
      <material name="black_gasket">
        <color rgba="0.01 0.01 0.009 1" />
        </material>
      </visual>
    <visual name="side_gasket_1">
      <origin xyz="0.585 0.426 0.136" rpy="0 0 0" />
      <geometry>
        <box size="0.17 0.04 0.018" />
        </geometry>
      <material name="black_gasket">
        <color rgba="0.01 0.01 0.009 1" />
        </material>
      </visual>
    <visual name="windshield_lower">
      <origin xyz="0 0.426 0.355" rpy="0 0 0" />
      <geometry>
        <box size="1.34 0.01 0.42" />
        </geometry>
      <material name="smoky_glass">
        <color rgba="0.22 0.4 0.52 0.34" />
        </material>
      </visual>
    <visual name="motor_pedestal">
      <origin xyz="0 -0.008 0.058" rpy="0 0 0" />
      <geometry>
        <box size="0.26 0.12 0.06" />
        </geometry>
      <material name="cast_aluminum">
        <color rgba="0.48 0.5 0.49 1" />
        </material>
      </visual>
    <visual name="gear_cover">
      <origin xyz="0 0.025 0.118" rpy="0 0 0" />
      <geometry>
        <cylinder radius="0.078" length="0.04" />
        </geometry>
      <material name="cast_aluminum">
        <color rgba="0.48 0.5 0.49 1" />
        </material>
      </visual>
    <visual name="motor_can">
      <origin xyz="0 -0.07 0.094" rpy="1.5708 0 0" />
      <geometry>
        <cylinder radius="0.055" length="0.12" />
        </geometry>
      <material name="satin_black">
        <color rgba="0.015 0.017 0.016 1" />
        </material>
      </visual>
    <visual name="motor_endcap">
      <origin xyz="0 -0.132 0.094" rpy="1.5708 0 0" />
      <geometry>
        <cylinder radius="0.058" length="0.012" />
        </geometry>
      <material name="cast_aluminum">
        <color rgba="0.48 0.5 0.49 1" />
        </material>
      </visual>
    <visual name="cross_tube">
      <origin xyz="0 0.085 0.094" rpy="0 1.5708 0" />
      <geometry>
        <cylinder radius="0.018" length="0.96" />
        </geometry>
      <material name="cadmium_steel">
        <color rgba="0.55 0.52 0.45 1" />
        </material>
      </visual>
    <visual name="reinforcing_strap_0">
      <origin xyz="-0.16 0.005 0.08" rpy="0 0 -0.22" />
      <geometry>
        <box size="0.18 0.034 0.035" />
        </geometry>
      <material name="cadmium_steel">
        <color rgba="0.55 0.52 0.45 1" />
        </material>
      </visual>
    <visual name="reinforcing_strap_1">
      <origin xyz="0.16 0.005 0.08" rpy="0 0 0.22" />
      <geometry>
        <box size="0.18 0.034 0.035" />
        </geometry>
      <material name="cadmium_steel">
        <color rgba="0.55 0.52 0.45 1" />
        </material>
      </visual>
    <visual name="hatch_plinth_0">
      <origin xyz="-0.31 -0.151 0.05" rpy="0 0 0" />
      <geometry>
        <box size="0.34 0.096 0.028" />
        </geometry>
      <material name="satin_black">
        <color rgba="0.015 0.017 0.016 1" />
        </material>
      </visual>
    <visual name="hatch_post_0">
      <origin xyz="-0.25 -0.139 0.028" rpy="0 0 0" />
      <geometry>
        <box size="0.04 0.05 0.056" />
        </geometry>
      <material name="satin_black">
        <color rgba="0.015 0.017 0.016 1" />
        </material>
      </visual>
    <visual name="hatch_front_rail_0">
      <origin xyz="-0.31 -0.188 0.066" rpy="0 0 0" />
      <geometry>
        <box size="0.32 0.014 0.018" />
        </geometry>
      <material name="cadmium_steel">
        <color rgba="0.55 0.52 0.45 1" />
        </material>
      </visual>
    <visual name="hatch_hinge_rail_0">
      <origin xyz="-0.31 -0.113 0.051" rpy="0 0 0" />
      <geometry>
        <box size="0.32 0.014 0.018" />
        </geometry>
      <material name="cadmium_steel">
        <color rgba="0.55 0.52 0.45 1" />
        </material>
      </visual>
    <visual name="hatch_side_rail_0a">
      <origin xyz="-0.47 -0.151 0.066" rpy="0 0 0" />
      <geometry>
        <box size="0.014 0.088 0.018" />
        </geometry>
      <material name="cadmium_steel">
        <color rgba="0.55 0.52 0.45 1" />
        </material>
      </visual>
    <visual name="hatch_side_rail_0b">
      <origin xyz="-0.15 -0.151 0.066" rpy="0 0 0" />
      <geometry>
        <box size="0.014 0.088 0.018" />
        </geometry>
      <material name="cadmium_steel">
        <color rgba="0.55 0.52 0.45 1" />
        </material>
      </visual>
    <visual name="hatch_knuckle_0a">
      <origin xyz="-0.43 -0.113 0.076" rpy="0 1.5708 0" />
      <geometry>
        <cylinder radius="0.006" length="0.068" />
        </geometry>
      <material name="cadmium_steel">
        <color rgba="0.55 0.52 0.45 1" />
        </material>
      </visual>
    <visual name="hatch_knuckle_0b">
      <origin xyz="-0.19 -0.113 0.076" rpy="0 1.5708 0" />
      <geometry>
        <cylinder radius="0.006" length="0.068" />
        </geometry>
      <material name="cadmium_steel">
        <color rgba="0.55 0.52 0.45 1" />
        </material>
      </visual>
    <visual name="hatch_frame_bolt_0_-0.115">
      <origin xyz="-0.425 -0.178 0.078" rpy="0 0 0" />
      <geometry>
        <cylinder radius="0.01" length="0.006" />
        </geometry>
      <material name="cadmium_steel">
        <color rgba="0.55 0.52 0.45 1" />
        </material>
      </visual>
    <visual name="hatch_frame_bolt_0_0.115">
      <origin xyz="-0.195 -0.178 0.078" rpy="0 0 0" />
      <geometry>
        <cylinder radius="0.01" length="0.006" />
        </geometry>
      <material name="cadmium_steel">
        <color rgba="0.55 0.52 0.45 1" />
        </material>
      </visual>
    <visual name="hatch_plinth_1">
      <origin xyz="0.31 -0.151 0.05" rpy="0 0 0" />
      <geometry>
        <box size="0.34 0.096 0.028" />
        </geometry>
      <material name="satin_black">
        <color rgba="0.015 0.017 0.016 1" />
        </material>
      </visual>
    <visual name="hatch_post_1">
      <origin xyz="0.25 -0.139 0.028" rpy="0 0 0" />
      <geometry>
        <box size="0.04 0.05 0.056" />
        </geometry>
      <material name="satin_black">
        <color rgba="0.015 0.017 0.016 1" />
        </material>
      </visual>
    <visual name="hatch_front_rail_1">
      <origin xyz="0.31 -0.188 0.066" rpy="0 0 0" />
      <geometry>
        <box size="0.32 0.014 0.018" />
        </geometry>
      <material name="cadmium_steel">
        <color rgba="0.55 0.52 0.45 1" />
        </material>
      </visual>
    <visual name="hatch_hinge_rail_1">
      <origin xyz="0.31 -0.113 0.051" rpy="0 0 0" />
      <geometry>
        <box size="0.32 0.014 0.018" />
        </geometry>
      <material name="cadmium_steel">
        <color rgba="0.55 0.52 0.45 1" />
        </material>
      </visual>
    <visual name="hatch_side_rail_1a">
      <origin xyz="0.15 -0.151 0.066" rpy="0 0 0" />
      <geometry>
        <box size="0.014 0.088 0.018" />
        </geometry>
      <material name="cadmium_steel">
        <color rgba="0.55 0.52 0.45 1" />
        </material>
      </visual>
    <visual name="hatch_side_rail_1b">
      <origin xyz="0.47 -0.151 0.066" rpy="0 0 0" />
      <geometry>
        <box size="0.014 0.088 0.018" />
        </geometry>
      <material name="cadmium_steel">
        <color rgba="0.55 0.52 0.45 1" />
        </material>
      </visual>
    <visual name="hatch_knuckle_1a">
      <origin xyz="0.19 -0.113 0.076" rpy="0 1.5708 0" />
      <geometry>
        <cylinder radius="0.006" length="0.068" />
        </geometry>
      <material name="cadmium_steel">
        <color rgba="0.55 0.52 0.45 1" />
        </material>
      </visual>
    <visual name="hatch_knuckle_1b">
      <origin xyz="0.43 -0.113 0.076" rpy="0 1.5708 0" />
      <geometry>
        <cylinder radius="0.006" length="0.068" />
        </geometry>
      <material name="cadmium_steel">
        <color rgba="0.55 0.52 0.45 1" />
        </material>
      </visual>
    <visual name="hatch_frame_bolt_1_-0.115">
      <origin xyz="0.195 -0.178 0.078" rpy="0 0 0" />
      <geometry>
        <cylinder radius="0.01" length="0.006" />
        </geometry>
      <material name="cadmium_steel">
        <color rgba="0.55 0.52 0.45 1" />
        </material>
      </visual>
    <visual name="hatch_frame_bolt_1_0.115">
      <origin xyz="0.425 -0.178 0.078" rpy="0 0 0" />
      <geometry>
        <cylinder radius="0.01" length="0.006" />
        </geometry>
      <material name="cadmium_steel">
        <color rgba="0.55 0.52 0.45 1" />
        </material>
      </visual>
    <visual name="spindle_pedestal_0">
      <origin xyz="-0.48 0.025 0.058" rpy="0 0 0" />
      <geometry>
        <box size="0.16 0.11 0.06" />
        </geometry>
      <material name="cast_aluminum">
        <color rgba="0.48 0.5 0.49 1" />
        </material>
      </visual>
    <visual name="spindle_adapter_0">
      <origin xyz="-0.48 0.025 0.093" rpy="0 0 0" />
      <geometry>
        <box size="0.205 0.135 0.012" />
        </geometry>
      <material name="cadmium_steel">
        <color rgba="0.55 0.52 0.45 1" />
        </material>
      </visual>
    <visual name="bearing_sleeve_0">
      <origin xyz="-0.48 0.025 0.139" rpy="0 0 0" />
      <geometry>
        <cylinder radius="0.04" length="0.095" />
        </geometry>
      <material name="brass_bushings">
        <color rgba="0.72 0.56 0.22 1" />
        </material>
      </visual>
    <visual name="gusset_0a">
      <origin xyz="-0.542 0.075 0.078" rpy="0 0 -0.2" />
      <geometry>
        <box size="0.03 0.12 0.04" />
        </geometry>
      <material name="cadmium_steel">
        <color rgba="0.55 0.52 0.45 1" />
        </material>
      </visual>
    <visual name="gusset_0b">
      <origin xyz="-0.418 0.075 0.078" rpy="0 0 0.2" />
      <geometry>
        <box size="0.03 0.12 0.04" />
        </geometry>
      <material name="cadmium_steel">
        <color rgba="0.55 0.52 0.45 1" />
        </material>
      </visual>
    <visual name="adapter_bolt_0_-0.07_-0.045">
      <origin xyz="-0.55 -0.02 0.102" rpy="0 0 0" />
      <geometry>
        <cylinder radius="0.01" length="0.007" />
        </geometry>
      <material name="cadmium_steel">
        <color rgba="0.55 0.52 0.45 1" />
        </material>
      </visual>
    <visual name="adapter_bolt_0_-0.07_0.045">
      <origin xyz="-0.55 0.07 0.102" rpy="0 0 0" />
      <geometry>
        <cylinder radius="0.01" length="0.007" />
        </geometry>
      <material name="cadmium_steel">
        <color rgba="0.55 0.52 0.45 1" />
        </material>
      </visual>
    <visual name="adapter_bolt_0_0.07_-0.045">
      <origin xyz="-0.41 -0.02 0.102" rpy="0 0 0" />
      <geometry>
        <cylinder radius="0.01" length="0.007" />
        </geometry>
      <material name="cadmium_steel">
        <color rgba="0.55 0.52 0.45 1" />
        </material>
      </visual>
    <visual name="adapter_bolt_0_0.07_0.045">
      <origin xyz="-0.41 0.07 0.102" rpy="0 0 0" />
      <geometry>
        <cylinder radius="0.01" length="0.007" />
        </geometry>
      <material name="cadmium_steel">
        <color rgba="0.55 0.52 0.45 1" />
        </material>
      </visual>
    <visual name="spindle_pedestal_1">
      <origin xyz="0.48 0.025 0.058" rpy="0 0 0" />
      <geometry>
        <box size="0.16 0.11 0.06" />
        </geometry>
      <material name="cast_aluminum">
        <color rgba="0.48 0.5 0.49 1" />
        </material>
      </visual>
    <visual name="spindle_adapter_1">
      <origin xyz="0.48 0.025 0.093" rpy="0 0 0" />
      <geometry>
        <box size="0.205 0.135 0.012" />
        </geometry>
      <material name="cadmium_steel">
        <color rgba="0.55 0.52 0.45 1" />
        </material>
      </visual>
    <visual name="bearing_sleeve_1">
      <origin xyz="0.48 0.025 0.139" rpy="0 0 0" />
      <geometry>
        <cylinder radius="0.04" length="0.095" />
        </geometry>
      <material name="brass_bushings">
        <color rgba="0.72 0.56 0.22 1" />
        </material>
      </visual>
    <visual name="gusset_1a">
      <origin xyz="0.418 0.075 0.078" rpy="0 0 -0.2" />
      <geometry>
        <box size="0.03 0.12 0.04" />
        </geometry>
      <material name="cadmium_steel">
        <color rgba="0.55 0.52 0.45 1" />
        </material>
      </visual>
    <visual name="gusset_1b">
      <origin xyz="0.542 0.075 0.078" rpy="0 0 0.2" />
      <geometry>
        <box size="0.03 0.12 0.04" />
        </geometry>
      <material name="cadmium_steel">
        <color rgba="0.55 0.52 0.45 1" />
        </material>
      </visual>
    <visual name="adapter_bolt_1_-0.07_-0.045">
      <origin xyz="0.41 -0.02 0.102" rpy="0 0 0" />
      <geometry>
        <cylinder radius="0.01" length="0.007" />
        </geometry>
      <material name="cadmium_steel">
        <color rgba="0.55 0.52 0.45 1" />
        </material>
      </visual>
    <visual name="adapter_bolt_1_-0.07_0.045">
      <origin xyz="0.41 0.07 0.102" rpy="0 0 0" />
      <geometry>
        <cylinder radius="0.01" length="0.007" />
        </geometry>
      <material name="cadmium_steel">
        <color rgba="0.55 0.52 0.45 1" />
        </material>
      </visual>
    <visual name="adapter_bolt_1_0.07_-0.045">
      <origin xyz="0.55 -0.02 0.102" rpy="0 0 0" />
      <geometry>
        <cylinder radius="0.01" length="0.007" />
        </geometry>
      <material name="cadmium_steel">
        <color rgba="0.55 0.52 0.45 1" />
        </material>
      </visual>
    <visual name="adapter_bolt_1_0.07_0.045">
      <origin xyz="0.55 0.07 0.102" rpy="0 0 0" />
      <geometry>
        <cylinder radius="0.01" length="0.007" />
        </geometry>
      <material name="cadmium_steel">
        <color rgba="0.55 0.52 0.45 1" />
        </material>
      </visual>
    <collision name="cowl_tray">
      <origin xyz="0 0 0.014" rpy="0 0 0" />
      <geometry>
        <box size="1.4 0.2 0.028" />
        </geometry>
      </collision>
    <collision name="front_lip">
      <origin xyz="0 -0.185 0.015" rpy="0 0 0" />
      <geometry>
        <box size="1.4 0.02 0.03" />
        </geometry>
      </collision>
    <collision name="front_bridge">
      <origin xyz="0 -0.139 0.014" rpy="0 0 0" />
      <geometry>
        <box size="0.72 0.095 0.012" />
        </geometry>
      </collision>
    <collision name="rear_riser">
      <origin xyz="0 0.096 0.074" rpy="0 0 0" />
      <geometry>
        <box size="1.4 0.02 0.12" />
        </geometry>
      </collision>
    <collision name="glass_gasket">
      <origin xyz="0 0.266 0.136" rpy="0 0 0" />
      <geometry>
        <box size="0.72 0.352 0.018" />
        </geometry>
      </collision>
    <collision name="side_gasket_0">
      <origin xyz="-0.585 0.426 0.136" rpy="0 0 0" />
      <geometry>
        <box size="0.17 0.04 0.018" />
        </geometry>
      </collision>
    <collision name="side_gasket_1">
      <origin xyz="0.585 0.426 0.136" rpy="0 0 0" />
      <geometry>
        <box size="0.17 0.04 0.018" />
        </geometry>
      </collision>
    <collision name="windshield_lower">
      <origin xyz="0 0.426 0.355" rpy="0 0 0" />
      <geometry>
        <box size="1.34 0.01 0.42" />
        </geometry>
      </collision>
    <collision name="motor_pedestal">
      <origin xyz="0 -0.008 0.058" rpy="0 0 0" />
      <geometry>
        <box size="0.26 0.12 0.06" />
        </geometry>
      </collision>
    <collision name="gear_cover">
      <origin xyz="0 0.025 0.118" rpy="0 0 0" />
      <geometry>
        <cylinder radius="0.078" length="0.04" />
        </geometry>
      </collision>
    <collision name="motor_can">
      <origin xyz="0 -0.07 0.094" rpy="1.5708 0 0" />
      <geometry>
        <cylinder radius="0.055" length="0.12" />
        </geometry>
      </collision>
    <collision name="motor_endcap">
      <origin xyz="0 -0.132 0.094" rpy="1.5708 0 0" />
      <geometry>
        <cylinder radius="0.058" length="0.012" />
        </geometry>
      </collision>
    <collision name="cross_tube">
      <origin xyz="0 0.085 0.094" rpy="0 1.5708 0" />
      <geometry>
        <cylinder radius="0.018" length="0.96" />
        </geometry>
      </collision>
    <collision name="reinforcing_strap_0">
      <origin xyz="-0.16 0.005 0.08" rpy="0 0 -0.22" />
      <geometry>
        <box size="0.18 0.034 0.035" />
        </geometry>
      </collision>
    <collision name="reinforcing_strap_1">
      <origin xyz="0.16 0.005 0.08" rpy="0 0 0.22" />
      <geometry>
        <box size="0.18 0.034 0.035" />
        </geometry>
      </collision>
    <collision name="hatch_plinth_0">
      <origin xyz="-0.31 -0.151 0.05" rpy="0 0 0" />
      <geometry>
        <box size="0.34 0.096 0.028" />
        </geometry>
      </collision>
    <collision name="hatch_post_0">
      <origin xyz="-0.25 -0.139 0.028" rpy="0 0 0" />
      <geometry>
        <box size="0.04 0.05 0.056" />
        </geometry>
      </collision>
    <collision name="hatch_front_rail_0">
      <origin xyz="-0.31 -0.188 0.066" rpy="0 0 0" />
      <geometry>
        <box size="0.32 0.014 0.018" />
        </geometry>
      </collision>
    <collision name="hatch_hinge_rail_0">
      <origin xyz="-0.31 -0.113 0.051" rpy="0 0 0" />
      <geometry>
        <box size="0.32 0.014 0.018" />
        </geometry>
      </collision>
    <collision name="hatch_side_rail_0a">
      <origin xyz="-0.47 -0.151 0.066" rpy="0 0 0" />
      <geometry>
        <box size="0.014 0.088 0.018" />
        </geometry>
      </collision>
    <collision name="hatch_side_rail_0b">
      <origin xyz="-0.15 -0.151 0.066" rpy="0 0 0" />
      <geometry>
        <box size="0.014 0.088 0.018" />
        </geometry>
      </collision>
    <collision name="hatch_knuckle_0a">
      <origin xyz="-0.43 -0.113 0.076" rpy="0 1.5708 0" />
      <geometry>
        <cylinder radius="0.006" length="0.068" />
        </geometry>
      </collision>
    <collision name="hatch_knuckle_0b">
      <origin xyz="-0.19 -0.113 0.076" rpy="0 1.5708 0" />
      <geometry>
        <cylinder radius="0.006" length="0.068" />
        </geometry>
      </collision>
    <collision name="hatch_frame_bolt_0_-0.115">
      <origin xyz="-0.425 -0.178 0.078" rpy="0 0 0" />
      <geometry>
        <cylinder radius="0.01" length="0.006" />
        </geometry>
      </collision>
    <collision name="hatch_frame_bolt_0_0.115">
      <origin xyz="-0.195 -0.178 0.078" rpy="0 0 0" />
      <geometry>
        <cylinder radius="0.01" length="0.006" />
        </geometry>
      </collision>
    <collision name="hatch_plinth_1">
      <origin xyz="0.31 -0.151 0.05" rpy="0 0 0" />
      <geometry>
        <box size="0.34 0.096 0.028" />
        </geometry>
      </collision>
    <collision name="hatch_post_1">
      <origin xyz="0.25 -0.139 0.028" rpy="0 0 0" />
      <geometry>
        <box size="0.04 0.05 0.056" />
        </geometry>
      </collision>
    <collision name="hatch_front_rail_1">
      <origin xyz="0.31 -0.188 0.066" rpy="0 0 0" />
      <geometry>
        <box size="0.32 0.014 0.018" />
        </geometry>
      </collision>
    <collision name="hatch_hinge_rail_1">
      <origin xyz="0.31 -0.113 0.051" rpy="0 0 0" />
      <geometry>
        <box size="0.32 0.014 0.018" />
        </geometry>
      </collision>
    <collision name="hatch_side_rail_1a">
      <origin xyz="0.15 -0.151 0.066" rpy="0 0 0" />
      <geometry>
        <box size="0.014 0.088 0.018" />
        </geometry>
      </collision>
    <collision name="hatch_side_rail_1b">
      <origin xyz="0.47 -0.151 0.066" rpy="0 0 0" />
      <geometry>
        <box size="0.014 0.088 0.018" />
        </geometry>
      </collision>
    <collision name="hatch_knuckle_1a">
      <origin xyz="0.19 -0.113 0.076" rpy="0 1.5708 0" />
      <geometry>
        <cylinder radius="0.006" length="0.068" />
        </geometry>
      </collision>
    <collision name="hatch_knuckle_1b">
      <origin xyz="0.43 -0.113 0.076" rpy="0 1.5708 0" />
      <geometry>
        <cylinder radius="0.006" length="0.068" />
        </geometry>
      </collision>
    <collision name="hatch_frame_bolt_1_-0.115">
      <origin xyz="0.195 -0.178 0.078" rpy="0 0 0" />
      <geometry>
        <cylinder radius="0.01" length="0.006" />
        </geometry>
      </collision>
    <collision name="hatch_frame_bolt_1_0.115">
      <origin xyz="0.425 -0.178 0.078" rpy="0 0 0" />
      <geometry>
        <cylinder radius="0.01" length="0.006" />
        </geometry>
      </collision>
    <collision name="spindle_pedestal_0">
      <origin xyz="-0.48 0.025 0.058" rpy="0 0 0" />
      <geometry>
        <box size="0.16 0.11 0.06" />
        </geometry>
      </collision>
    <collision name="spindle_adapter_0">
      <origin xyz="-0.48 0.025 0.093" rpy="0 0 0" />
      <geometry>
        <box size="0.205 0.135 0.012" />
        </geometry>
      </collision>
    <collision name="bearing_sleeve_0">
      <origin xyz="-0.48 0.025 0.139" rpy="0 0 0" />
      <geometry>
        <cylinder radius="0.04" length="0.095" />
        </geometry>
      </collision>
    <collision name="gusset_0a">
      <origin xyz="-0.542 0.075 0.078" rpy="0 0 -0.2" />
      <geometry>
        <box size="0.03 0.12 0.04" />
        </geometry>
      </collision>
    <collision name="gusset_0b">
      <origin xyz="-0.418 0.075 0.078" rpy="0 0 0.2" />
      <geometry>
        <box size="0.03 0.12 0.04" />
        </geometry>
      </collision>
    <collision name="adapter_bolt_0_-0.07_-0.045">
      <origin xyz="-0.55 -0.02 0.102" rpy="0 0 0" />
      <geometry>
        <cylinder radius="0.01" length="0.007" />
        </geometry>
      </collision>
    <collision name="adapter_bolt_0_-0.07_0.045">
      <origin xyz="-0.55 0.07 0.102" rpy="0 0 0" />
      <geometry>
        <cylinder radius="0.01" length="0.007" />
        </geometry>
      </collision>
    <collision name="adapter_bolt_0_0.07_-0.045">
      <origin xyz="-0.41 -0.02 0.102" rpy="0 0 0" />
      <geometry>
        <cylinder radius="0.01" length="0.007" />
        </geometry>
      </collision>
    <collision name="adapter_bolt_0_0.07_0.045">
      <origin xyz="-0.41 0.07 0.102" rpy="0 0 0" />
      <geometry>
        <cylinder radius="0.01" length="0.007" />
        </geometry>
      </collision>
    <collision name="spindle_pedestal_1">
      <origin xyz="0.48 0.025 0.058" rpy="0 0 0" />
      <geometry>
        <box size="0.16 0.11 0.06" />
        </geometry>
      </collision>
    <collision name="spindle_adapter_1">
      <origin xyz="0.48 0.025 0.093" rpy="0 0 0" />
      <geometry>
        <box size="0.205 0.135 0.012" />
        </geometry>
      </collision>
    <collision name="bearing_sleeve_1">
      <origin xyz="0.48 0.025 0.139" rpy="0 0 0" />
      <geometry>
        <cylinder radius="0.04" length="0.095" />
        </geometry>
      </collision>
    <collision name="gusset_1a">
      <origin xyz="0.418 0.075 0.078" rpy="0 0 -0.2" />
      <geometry>
        <box size="0.03 0.12 0.04" />
        </geometry>
      </collision>
    <collision name="gusset_1b">
      <origin xyz="0.542 0.075 0.078" rpy="0 0 0.2" />
      <geometry>
        <box size="0.03 0.12 0.04" />
        </geometry>
      </collision>
    <collision name="adapter_bolt_1_-0.07_-0.045">
      <origin xyz="0.41 -0.02 0.102" rpy="0 0 0" />
      <geometry>
        <cylinder radius="0.01" length="0.007" />
        </geometry>
      </collision>
    <collision name="adapter_bolt_1_-0.07_0.045">
      <origin xyz="0.41 0.07 0.102" rpy="0 0 0" />
      <geometry>
        <cylinder radius="0.01" length="0.007" />
        </geometry>
      </collision>
    <collision name="adapter_bolt_1_0.07_-0.045">
      <origin xyz="0.55 -0.02 0.102" rpy="0 0 0" />
      <geometry>
        <cylinder radius="0.01" length="0.007" />
        </geometry>
      </collision>
    <collision name="adapter_bolt_1_0.07_0.045">
      <origin xyz="0.55 0.07 0.102" rpy="0 0 0" />
      <geometry>
        <cylinder radius="0.01" length="0.007" />
        </geometry>
      </collision>
    </link>
  <link name="motor_crank">
    <visual name="crank_hub">
      <origin xyz="0 0 0.014" rpy="0 0 0" />
      <geometry>
        <cylinder radius="0.028" length="0.026" />
        </geometry>
      <material name="cadmium_steel">
        <color rgba="0.55 0.52 0.45 1" />
        </material>
      </visual>
    <visual name="crank_arm">
      <origin xyz="0.084 0 0.03" rpy="0 0 0" />
      <geometry>
        <box size="0.168 0.03 0.012" />
        </geometry>
      <material name="cadmium_steel">
        <color rgba="0.55 0.52 0.45 1" />
        </material>
      </visual>
    <visual name="crank_pin">
      <origin xyz="0.16 0 0.055" rpy="0 0 0" />
      <geometry>
        <cylinder radius="0.013" length="0.04" />
        </geometry>
      <material name="cadmium_steel">
        <color rgba="0.55 0.52 0.45 1" />
        </material>
      </visual>
    <visual name="counterweight">
      <origin xyz="-0.06 0 0.031" rpy="0 0 0" />
      <geometry>
        <cylinder radius="0.018" length="0.01" />
        </geometry>
      <material name="cast_aluminum">
        <color rgba="0.48 0.5 0.49 1" />
        </material>
      </visual>
    <visual name="weight_web">
      <origin xyz="-0.03 0 0.031" rpy="0 0 0" />
      <geometry>
        <box size="0.056 0.018 0.01" />
        </geometry>
      <material name="cast_aluminum">
        <color rgba="0.48 0.5 0.49 1" />
        </material>
      </visual>
    <visual name="hub_nut">
      <origin xyz="0 0 0.031" rpy="0 0 0" />
      <geometry>
        <cylinder radius="0.017" length="0.006" />
        </geometry>
      <material name="brass_bushings">
        <color rgba="0.72 0.56 0.22 1" />
        </material>
      </visual>
    <collision name="crank_hub">
      <origin xyz="0 0 0.014" rpy="0 0 0" />
      <geometry>
        <cylinder radius="0.028" length="0.026" />
        </geometry>
      </collision>
    <collision name="crank_arm">
      <origin xyz="0.084 0 0.03" rpy="0 0 0" />
      <geometry>
        <box size="0.168 0.03 0.012" />
        </geometry>
      </collision>
    <collision name="crank_pin">
      <origin xyz="0.16 0 0.055" rpy="0 0 0" />
      <geometry>
        <cylinder radius="0.013" length="0.04" />
        </geometry>
      </collision>
    <collision name="counterweight">
      <origin xyz="-0.06 0 0.031" rpy="0 0 0" />
      <geometry>
        <cylinder radius="0.018" length="0.01" />
        </geometry>
      </collision>
    <collision name="weight_web">
      <origin xyz="-0.03 0 0.031" rpy="0 0 0" />
      <geometry>
        <box size="0.056 0.018 0.01" />
        </geometry>
      </collision>
    <collision name="hub_nut">
      <origin xyz="0 0 0.031" rpy="0 0 0" />
      <geometry>
        <cylinder radius="0.017" length="0.006" />
        </geometry>
      </collision>
    </link>
  <link name="drive_link">
    <visual name="drive_bar">
      <origin xyz="0.203961 0 0" rpy="0 0 0" />
      <geometry>
        <box size="0.355922 0.02 0.01" />
        </geometry>
      <material name="cadmium_steel">
        <color rgba="0.55 0.52 0.45 1" />
        </material>
      </visual>
    <visual name="crank_eye">
      <geometry>
        <cylinder radius="0.03" length="0.012" />
        </geometry>
      <material name="cadmium_steel">
        <color rgba="0.55 0.52 0.45 1" />
        </material>
      </visual>
    <visual name="spindle_eye">
      <origin xyz="0.407922 0 0" rpy="0 0 0" />
      <geometry>
        <cylinder radius="0.03" length="0.012" />
        </geometry>
      <material name="cadmium_steel">
        <color rgba="0.55 0.52 0.45 1" />
        </material>
      </visual>
    <visual name="paint_mark">
      <origin xyz="0.203961 0 0.011" rpy="0 0 0" />
      <geometry>
        <box size="0.06 0.014 0.017" />
        </geometry>
      <material name="red_service_paint">
        <color rgba="0.55 0.07 0.035 1" />
        </material>
      </visual>
    <collision name="drive_bar">
      <origin xyz="0.203961 0 0" rpy="0 0 0" />
      <geometry>
        <box size="0.355922 0.02 0.01" />
        </geometry>
      </collision>
    <collision name="crank_eye">
      <geometry>
        <cylinder radius="0.03" length="0.012" />
        </geometry>
      </collision>
    <collision name="spindle_eye">
      <origin xyz="0.407922 0 0" rpy="0 0 0" />
      <geometry>
        <cylinder radius="0.03" length="0.012" />
        </geometry>
      </collision>
    <collision name="paint_mark">
      <origin xyz="0.203961 0 0.011" rpy="0 0 0" />
      <geometry>
        <box size="0.06 0.014 0.017" />
        </geometry>
      </collision>
    </link>
  <link name="wiper_carrier_0">
    <visual name="spindle_shaft">
      <origin xyz="0 0 -0.055" rpy="0 0 0" />
      <geometry>
        <cylinder radius="0.016" length="0.24" />
        </geometry>
      <material name="cadmium_steel">
        <color rgba="0.55 0.52 0.45 1" />
        </material>
      </visual>
    <visual name="arm_adapter">
      <origin xyz="0 0 0.052" rpy="0 0 0" />
      <geometry>
        <box size="0.09 0.06 0.025" />
        </geometry>
      <material name="cast_aluminum">
        <color rgba="0.48 0.5 0.49 1" />
        </material>
      </visual>
    <visual name="stamped_arm">
      <origin xyz="0 0.18 0.061" rpy="0 0 0" />
      <geometry>
        <box size="0.03 0.36 0.012" />
        </geometry>
      <material name="satin_black">
        <color rgba="0.015 0.017 0.016 1" />
        </material>
      </visual>
    <visual name="arm_rivet_0">
      <origin xyz="0 0.105 0.07" rpy="0 0 0" />
      <geometry>
        <cylinder radius="0.009" length="0.006" />
        </geometry>
      <material name="cadmium_steel">
        <color rgba="0.55 0.52 0.45 1" />
        </material>
      </visual>
    <visual name="arm_rivet_1">
      <origin xyz="0 0.25 0.07" rpy="0 0 0" />
      <geometry>
        <cylinder radius="0.009" length="0.006" />
        </geometry>
      <material name="cadmium_steel">
        <color rgba="0.55 0.52 0.45 1" />
        </material>
      </visual>
    <visual name="blade_saddle">
      <origin xyz="0 0.36 0.054" rpy="0 0 0" />
      <geometry>
        <box size="0.085 0.055 0.026" />
        </geometry>
      <material name="cast_aluminum">
        <color rgba="0.48 0.5 0.49 1" />
        </material>
      </visual>
    <visual name="blade_backing">
      <origin xyz="0 0.38 0.05" rpy="0 0 0" />
      <geometry>
        <box size="0.44 0.02 0.018" />
        </geometry>
      <material name="cadmium_steel">
        <color rgba="0.55 0.52 0.45 1" />
        </material>
      </visual>
    <visual name="rubber_blade">
      <origin xyz="0 0.391 0.031" rpy="0 0 0" />
      <geometry>
        <box size="0.46 0.012 0.035" />
        </geometry>
      <material name="aged_rubber">
        <color rgba="0.002 0.002 0.002 1" />
        </material>
      </visual>
    <visual name="bellcrank_arm">
      <origin xyz="0.025 -0.07 -0.155" rpy="0 0 0" />
      <geometry>
        <box size="0.08 0.22 0.008" />
        </geometry>
      <material name="cadmium_steel">
        <color rgba="0.55 0.52 0.45 1" />
        </material>
      </visual>
    <visual name="tie_pin">
      <origin xyz="0.055 -0.15 -0.155" rpy="0 0 0" />
      <geometry>
        <cylinder radius="0.01" length="0.05" />
        </geometry>
      <material name="cadmium_steel">
        <color rgba="0.55 0.52 0.45 1" />
        </material>
      </visual>
    <collision name="spindle_shaft">
      <origin xyz="0 0 -0.055" rpy="0 0 0" />
      <geometry>
        <cylinder radius="0.016" length="0.24" />
        </geometry>
      </collision>
    <collision name="arm_adapter">
      <origin xyz="0 0 0.052" rpy="0 0 0" />
      <geometry>
        <box size="0.09 0.06 0.025" />
        </geometry>
      </collision>
    <collision name="stamped_arm">
      <origin xyz="0 0.18 0.061" rpy="0 0 0" />
      <geometry>
        <box size="0.03 0.36 0.012" />
        </geometry>
      </collision>
    <collision name="arm_rivet_0">
      <origin xyz="0 0.105 0.07" rpy="0 0 0" />
      <geometry>
        <cylinder radius="0.009" length="0.006" />
        </geometry>
      </collision>
    <collision name="arm_rivet_1">
      <origin xyz="0 0.25 0.07" rpy="0 0 0" />
      <geometry>
        <cylinder radius="0.009" length="0.006" />
        </geometry>
      </collision>
    <collision name="blade_saddle">
      <origin xyz="0 0.36 0.054" rpy="0 0 0" />
      <geometry>
        <box size="0.085 0.055 0.026" />
        </geometry>
      </collision>
    <collision name="blade_backing">
      <origin xyz="0 0.38 0.05" rpy="0 0 0" />
      <geometry>
        <box size="0.44 0.02 0.018" />
        </geometry>
      </collision>
    <collision name="rubber_blade">
      <origin xyz="0 0.391 0.031" rpy="0 0 0" />
      <geometry>
        <box size="0.46 0.012 0.035" />
        </geometry>
      </collision>
    <collision name="bellcrank_arm">
      <origin xyz="0.025 -0.07 -0.155" rpy="0 0 0" />
      <geometry>
        <box size="0.08 0.22 0.008" />
        </geometry>
      </collision>
    <collision name="tie_pin">
      <origin xyz="0.055 -0.15 -0.155" rpy="0 0 0" />
      <geometry>
        <cylinder radius="0.01" length="0.05" />
        </geometry>
      </collision>
    </link>
  <link name="wiper_carrier_1">
    <visual name="spindle_shaft">
      <origin xyz="0 0 -0.055" rpy="0 0 0" />
      <geometry>
        <cylinder radius="0.016" length="0.24" />
        </geometry>
      <material name="cadmium_steel">
        <color rgba="0.55 0.52 0.45 1" />
        </material>
      </visual>
    <visual name="arm_adapter">
      <origin xyz="0 0 0.052" rpy="0 0 0" />
      <geometry>
        <box size="0.09 0.06 0.025" />
        </geometry>
      <material name="cast_aluminum">
        <color rgba="0.48 0.5 0.49 1" />
        </material>
      </visual>
    <visual name="stamped_arm">
      <origin xyz="0 0.18 0.061" rpy="0 0 0" />
      <geometry>
        <box size="0.03 0.36 0.012" />
        </geometry>
      <material name="satin_black">
        <color rgba="0.015 0.017 0.016 1" />
        </material>
      </visual>
    <visual name="arm_rivet_0">
      <origin xyz="0 0.105 0.07" rpy="0 0 0" />
      <geometry>
        <cylinder radius="0.009" length="0.006" />
        </geometry>
      <material name="cadmium_steel">
        <color rgba="0.55 0.52 0.45 1" />
        </material>
      </visual>
    <visual name="arm_rivet_1">
      <origin xyz="0 0.25 0.07" rpy="0 0 0" />
      <geometry>
        <cylinder radius="0.009" length="0.006" />
        </geometry>
      <material name="cadmium_steel">
        <color rgba="0.55 0.52 0.45 1" />
        </material>
      </visual>
    <visual name="blade_saddle">
      <origin xyz="0 0.36 0.054" rpy="0 0 0" />
      <geometry>
        <box size="0.085 0.055 0.026" />
        </geometry>
      <material name="cast_aluminum">
        <color rgba="0.48 0.5 0.49 1" />
        </material>
      </visual>
    <visual name="blade_backing">
      <origin xyz="0 0.38 0.05" rpy="0 0 0" />
      <geometry>
        <box size="0.44 0.02 0.018" />
        </geometry>
      <material name="cadmium_steel">
        <color rgba="0.55 0.52 0.45 1" />
        </material>
      </visual>
    <visual name="rubber_blade">
      <origin xyz="0 0.391 0.031" rpy="0 0 0" />
      <geometry>
        <box size="0.46 0.012 0.035" />
        </geometry>
      <material name="aged_rubber">
        <color rgba="0.002 0.002 0.002 1" />
        </material>
      </visual>
    <visual name="bellcrank_arm">
      <origin xyz="-0.025 -0.07 -0.155" rpy="0 0 0" />
      <geometry>
        <box size="0.08 0.22 0.008" />
        </geometry>
      <material name="cadmium_steel">
        <color rgba="0.55 0.52 0.45 1" />
        </material>
      </visual>
    <visual name="tie_pin">
      <origin xyz="-0.055 -0.15 -0.155" rpy="0 0 0" />
      <geometry>
        <cylinder radius="0.01" length="0.05" />
        </geometry>
      <material name="cadmium_steel">
        <color rgba="0.55 0.52 0.45 1" />
        </material>
      </visual>
    <visual name="drive_bellcrank">
      <origin xyz="0.04 -0.04 0.055" rpy="0 0 0" />
      <geometry>
        <box size="0.12 0.09 0.01" />
        </geometry>
      <material name="cadmium_steel">
        <color rgba="0.55 0.52 0.45 1" />
        </material>
      </visual>
    <visual name="drive_pin">
      <origin xyz="0.08 -0.08 0.055" rpy="0 0 0" />
      <geometry>
        <cylinder radius="0.01" length="0.04" />
        </geometry>
      <material name="cadmium_steel">
        <color rgba="0.55 0.52 0.45 1" />
        </material>
      </visual>
    <collision name="spindle_shaft">
      <origin xyz="0 0 -0.055" rpy="0 0 0" />
      <geometry>
        <cylinder radius="0.016" length="0.24" />
        </geometry>
      </collision>
    <collision name="arm_adapter">
      <origin xyz="0 0 0.052" rpy="0 0 0" />
      <geometry>
        <box size="0.09 0.06 0.025" />
        </geometry>
      </collision>
    <collision name="stamped_arm">
      <origin xyz="0 0.18 0.061" rpy="0 0 0" />
      <geometry>
        <box size="0.03 0.36 0.012" />
        </geometry>
      </collision>
    <collision name="arm_rivet_0">
      <origin xyz="0 0.105 0.07" rpy="0 0 0" />
      <geometry>
        <cylinder radius="0.009" length="0.006" />
        </geometry>
      </collision>
    <collision name="arm_rivet_1">
      <origin xyz="0 0.25 0.07" rpy="0 0 0" />
      <geometry>
        <cylinder radius="0.009" length="0.006" />
        </geometry>
      </collision>
    <collision name="blade_saddle">
      <origin xyz="0 0.36 0.054" rpy="0 0 0" />
      <geometry>
        <box size="0.085 0.055 0.026" />
        </geometry>
      </collision>
    <collision name="blade_backing">
      <origin xyz="0 0.38 0.05" rpy="0 0 0" />
      <geometry>
        <box size="0.44 0.02 0.018" />
        </geometry>
      </collision>
    <collision name="rubber_blade">
      <origin xyz="0 0.391 0.031" rpy="0 0 0" />
      <geometry>
        <box size="0.46 0.012 0.035" />
        </geometry>
      </collision>
    <collision name="bellcrank_arm">
      <origin xyz="-0.025 -0.07 -0.155" rpy="0 0 0" />
      <geometry>
        <box size="0.08 0.22 0.008" />
        </geometry>
      </collision>
    <collision name="tie_pin">
      <origin xyz="-0.055 -0.15 -0.155" rpy="0 0 0" />
      <geometry>
        <cylinder radius="0.01" length="0.05" />
        </geometry>
      </collision>
    <collision name="drive_bellcrank">
      <origin xyz="0.04 -0.04 0.055" rpy="0 0 0" />
      <geometry>
        <box size="0.12 0.09 0.01" />
        </geometry>
      </collision>
    <collision name="drive_pin">
      <origin xyz="0.08 -0.08 0.055" rpy="0 0 0" />
      <geometry>
        <cylinder radius="0.01" length="0.04" />
        </geometry>
      </collision>
    </link>
  <link name="tie_rod">
    <visual name="tie_bar">
      <origin xyz="0.425 0 0" rpy="0 0 0" />
      <geometry>
        <box size="0.806 0.018 0.01" />
        </geometry>
      <material name="cadmium_steel">
        <color rgba="0.55 0.52 0.45 1" />
        </material>
      </visual>
    <visual name="left_eye">
      <geometry>
        <cylinder radius="0.028" length="0.012" />
        </geometry>
      <material name="cadmium_steel">
        <color rgba="0.55 0.52 0.45 1" />
        </material>
      </visual>
    <visual name="right_eye">
      <origin xyz="0.85 0 0" rpy="0 0 0" />
      <geometry>
        <cylinder radius="0.028" length="0.012" />
        </geometry>
      <material name="cadmium_steel">
        <color rgba="0.55 0.52 0.45 1" />
        </material>
      </visual>
    <collision name="tie_bar">
      <origin xyz="0.425 0 0" rpy="0 0 0" />
      <geometry>
        <box size="0.806 0.018 0.01" />
        </geometry>
      </collision>
    <collision name="left_eye">
      <geometry>
        <cylinder radius="0.028" length="0.012" />
        </geometry>
      </collision>
    <collision name="right_eye">
      <origin xyz="0.85 0 0" rpy="0 0 0" />
      <geometry>
        <cylinder radius="0.028" length="0.012" />
        </geometry>
      </collision>
    </link>
  <link name="service_hatch_0">
    <visual name="hatch_panel">
      <origin xyz="0 -0.065 0.004" rpy="0 0 0" />
      <geometry>
        <box size="0.205 0.096 0.008" />
        </geometry>
      <material name="satin_black">
        <color rgba="0.015 0.017 0.016 1" />
        </material>
      </visual>
    <visual name="hinge_leaf">
      <origin xyz="0 -0.012 0.005" rpy="0 0 0" />
      <geometry>
        <box size="0.13 0.024 0.004" />
        </geometry>
      <material name="cadmium_steel">
        <color rgba="0.55 0.52 0.45 1" />
        </material>
      </visual>
    <visual name="service_label">
      <origin xyz="0 -0.088 0.013" rpy="0 0 0" />
      <geometry>
        <box size="0.23 0.012 0.01" />
        </geometry>
      <material name="red_service_paint">
        <color rgba="0.55 0.07 0.035 1" />
        </material>
      </visual>
    <visual name="hatch_barrel">
      <origin xyz="0 0 0.005" rpy="0 1.5708 0" />
      <geometry>
        <cylinder radius="0.006" length="0.13" />
        </geometry>
      <material name="cadmium_steel">
        <color rgba="0.55 0.52 0.45 1" />
        </material>
      </visual>
    <visual name="hatch_screw_0">
      <origin xyz="-0.095 -0.03 0.011" rpy="0 0 0" />
      <geometry>
        <cylinder radius="0.01" length="0.006" />
        </geometry>
      <material name="cadmium_steel">
        <color rgba="0.55 0.52 0.45 1" />
        </material>
      </visual>
    <visual name="hatch_screw_1">
      <origin xyz="0.095 -0.03 0.011" rpy="0 0 0" />
      <geometry>
        <cylinder radius="0.01" length="0.006" />
        </geometry>
      <material name="cadmium_steel">
        <color rgba="0.55 0.52 0.45 1" />
        </material>
      </visual>
    <visual name="pull_tab">
      <origin xyz="0 -0.069 0.013" rpy="0 0 0" />
      <geometry>
        <box size="0.055 0.01 0.01" />
        </geometry>
      <material name="cadmium_steel">
        <color rgba="0.55 0.52 0.45 1" />
        </material>
      </visual>
    <collision name="hatch_panel">
      <origin xyz="0 -0.065 0.004" rpy="0 0 0" />
      <geometry>
        <box size="0.205 0.096 0.008" />
        </geometry>
      </collision>
    <collision name="hinge_leaf">
      <origin xyz="0 -0.012 0.005" rpy="0 0 0" />
      <geometry>
        <box size="0.13 0.024 0.004" />
        </geometry>
      </collision>
    <collision name="service_label">
      <origin xyz="0 -0.088 0.013" rpy="0 0 0" />
      <geometry>
        <box size="0.23 0.012 0.01" />
        </geometry>
      </collision>
    <collision name="hatch_barrel">
      <origin xyz="0 0 0.005" rpy="0 1.5708 0" />
      <geometry>
        <cylinder radius="0.006" length="0.13" />
        </geometry>
      </collision>
    <collision name="hatch_screw_0">
      <origin xyz="-0.095 -0.03 0.011" rpy="0 0 0" />
      <geometry>
        <cylinder radius="0.01" length="0.006" />
        </geometry>
      </collision>
    <collision name="hatch_screw_1">
      <origin xyz="0.095 -0.03 0.011" rpy="0 0 0" />
      <geometry>
        <cylinder radius="0.01" length="0.006" />
        </geometry>
      </collision>
    <collision name="pull_tab">
      <origin xyz="0 -0.069 0.013" rpy="0 0 0" />
      <geometry>
        <box size="0.055 0.01 0.01" />
        </geometry>
      </collision>
    </link>
  <link name="service_hatch_1">
    <visual name="hatch_panel">
      <origin xyz="0 -0.065 0.004" rpy="0 0 0" />
      <geometry>
        <box size="0.205 0.096 0.008" />
        </geometry>
      <material name="satin_black">
        <color rgba="0.015 0.017 0.016 1" />
        </material>
      </visual>
    <visual name="hinge_leaf">
      <origin xyz="0 -0.012 0.005" rpy="0 0 0" />
      <geometry>
        <box size="0.13 0.024 0.004" />
        </geometry>
      <material name="cadmium_steel">
        <color rgba="0.55 0.52 0.45 1" />
        </material>
      </visual>
    <visual name="service_label">
      <origin xyz="0 -0.088 0.013" rpy="0 0 0" />
      <geometry>
        <box size="0.23 0.012 0.01" />
        </geometry>
      <material name="red_service_paint">
        <color rgba="0.55 0.07 0.035 1" />
        </material>
      </visual>
    <visual name="hatch_barrel">
      <origin xyz="0 0 0.005" rpy="0 1.5708 0" />
      <geometry>
        <cylinder radius="0.006" length="0.13" />
        </geometry>
      <material name="cadmium_steel">
        <color rgba="0.55 0.52 0.45 1" />
        </material>
      </visual>
    <visual name="hatch_screw_0">
      <origin xyz="-0.095 -0.03 0.011" rpy="0 0 0" />
      <geometry>
        <cylinder radius="0.01" length="0.006" />
        </geometry>
      <material name="cadmium_steel">
        <color rgba="0.55 0.52 0.45 1" />
        </material>
      </visual>
    <visual name="hatch_screw_1">
      <origin xyz="0.095 -0.03 0.011" rpy="0 0 0" />
      <geometry>
        <cylinder radius="0.01" length="0.006" />
        </geometry>
      <material name="cadmium_steel">
        <color rgba="0.55 0.52 0.45 1" />
        </material>
      </visual>
    <visual name="pull_tab">
      <origin xyz="0 -0.069 0.013" rpy="0 0 0" />
      <geometry>
        <box size="0.055 0.01 0.01" />
        </geometry>
      <material name="cadmium_steel">
        <color rgba="0.55 0.52 0.45 1" />
        </material>
      </visual>
    <collision name="hatch_panel">
      <origin xyz="0 -0.065 0.004" rpy="0 0 0" />
      <geometry>
        <box size="0.205 0.096 0.008" />
        </geometry>
      </collision>
    <collision name="hinge_leaf">
      <origin xyz="0 -0.012 0.005" rpy="0 0 0" />
      <geometry>
        <box size="0.13 0.024 0.004" />
        </geometry>
      </collision>
    <collision name="service_label">
      <origin xyz="0 -0.088 0.013" rpy="0 0 0" />
      <geometry>
        <box size="0.23 0.012 0.01" />
        </geometry>
      </collision>
    <collision name="hatch_barrel">
      <origin xyz="0 0 0.005" rpy="0 1.5708 0" />
      <geometry>
        <cylinder radius="0.006" length="0.13" />
        </geometry>
      </collision>
    <collision name="hatch_screw_0">
      <origin xyz="-0.095 -0.03 0.011" rpy="0 0 0" />
      <geometry>
        <cylinder radius="0.01" length="0.006" />
        </geometry>
      </collision>
    <collision name="hatch_screw_1">
      <origin xyz="0.095 -0.03 0.011" rpy="0 0 0" />
      <geometry>
        <cylinder radius="0.01" length="0.006" />
        </geometry>
      </collision>
    <collision name="pull_tab">
      <origin xyz="0 -0.069 0.013" rpy="0 0 0" />
      <geometry>
        <box size="0.055 0.01 0.01" />
        </geometry>
      </collision>
    </link>
  <joint name="motor_to_crank" type="revolute">
    <origin xyz="0 0.025 0.146" rpy="0 0 0" />
    <parent link="cowl_frame" />
    <child link="motor_crank" />
    <axis xyz="0 0 1" />
    <limit effort="18" velocity="4" lower="-0.65" upper="0.65" />
    </joint>
  <joint name="crank_to_drive_link" type="revolute">
    <origin xyz="0.16 0 0.055" rpy="0 0 -0.197396" />
    <parent link="motor_crank" />
    <child link="drive_link" />
    <axis xyz="0 0 1" />
    <limit effort="8" velocity="4" lower="-0.95" upper="0.95" />
    </joint>
  <joint name="frame_to_wiper_0" type="revolute">
    <origin xyz="-0.48 0.025 0.154" rpy="0 0 0" />
    <parent link="cowl_frame" />
    <child link="wiper_carrier_0" />
    <axis xyz="0 0 1" />
    <limit effort="12" velocity="3" lower="-0.55" upper="0.55" />
    <mimic joint="motor_to_crank" multiplier="0.8" />
    </joint>
  <joint name="frame_to_wiper_1" type="revolute">
    <origin xyz="0.48 0.025 0.154" rpy="0 0 0" />
    <parent link="cowl_frame" />
    <child link="wiper_carrier_1" />
    <axis xyz="0 0 1" />
    <limit effort="12" velocity="3" lower="-0.55" upper="0.55" />
    <mimic joint="motor_to_crank" multiplier="0.8" />
    </joint>
  <joint name="wiper_to_tie_rod" type="revolute">
    <origin xyz="0.055 -0.15 -0.155" rpy="0 0 0" />
    <parent link="wiper_carrier_0" />
    <child link="tie_rod" />
    <axis xyz="0 0 1" />
    <limit effort="6" velocity="3" lower="-0.75" upper="0.75" />
    </joint>
  <joint name="frame_to_hatch_0" type="revolute">
    <origin xyz="-0.31 -0.113 0.071" rpy="0 0 0" />
    <parent link="cowl_frame" />
    <child link="service_hatch_0" />
    <axis xyz="-1 0 0" />
    <limit effort="3" velocity="1" lower="0" upper="1.05" />
    </joint>
  <joint name="frame_to_hatch_1" type="revolute">
    <origin xyz="0.31 -0.113 0.071" rpy="0 0 0" />
    <parent link="cowl_frame" />
    <child link="service_hatch_1" />
    <axis xyz="-1 0 0" />
    <limit effort="3" velocity="1" lower="0" upper="1.05" />
    </joint>
  </robot>
