<robot name="pit_orchestra_stand">
  <link name="base">
    <visual name="weighted_puck">
      <origin xyz="0 0 0.0175" rpy="0 0 0" />
      <geometry>
        <cylinder radius="0.18" length="0.035" />
        </geometry>
      <material name="satin_black">
        <color rgba="0.015 0.015 0.014 1" />
        </material>
      </visual>
    <visual name="top_weight_plate">
      <origin xyz="0 0 0.038" rpy="0 0 0" />
      <geometry>
        <cylinder radius="0.115" length="0.008" />
        </geometry>
      <material name="dark_graphite">
        <color rgba="0.08 0.085 0.085 1" />
        </material>
      </visual>
    <visual name="lower_collar">
      <origin xyz="0 0 0.052" rpy="0 0 0" />
      <geometry>
        <cylinder radius="0.035" length="0.032" />
        </geometry>
      <material name="satin_black">
        <color rgba="0.015 0.015 0.014 1" />
        </material>
      </visual>
    <visual name="outer_sleeve">
      <origin xyz="0 0 0.04" rpy="0 0 0" />
      <geometry>
        <mesh filename="assets/meshes/outer_sleeve.obj" />
        </geometry>
      <material name="brushed_steel">
        <color rgba="0.55 0.56 0.53 1" />
        </material>
      </visual>
    <visual name="upper_collar">
      <origin xyz="0 0 0.338" rpy="0 0 0" />
      <geometry>
        <cylinder radius="0.03" length="0.02" />
        </geometry>
      <material name="satin_black">
        <color rgba="0.015 0.015 0.014 1" />
        </material>
      </visual>
    <collision name="weighted_puck">
      <origin xyz="0 0 0.0175" rpy="0 0 0" />
      <geometry>
        <cylinder radius="0.18" length="0.035" />
        </geometry>
      </collision>
    <collision name="top_weight_plate">
      <origin xyz="0 0 0.038" rpy="0 0 0" />
      <geometry>
        <cylinder radius="0.115" length="0.008" />
        </geometry>
      </collision>
    <collision name="lower_collar">
      <origin xyz="0 0 0.052" rpy="0 0 0" />
      <geometry>
        <cylinder radius="0.035" length="0.032" />
        </geometry>
      </collision>
    <collision name="outer_sleeve">
      <origin xyz="0 0 0.04" rpy="0 0 0" />
      <geometry>
        <mesh filename="assets/meshes/outer_sleeve.obj" />
        </geometry>
      </collision>
    <collision name="upper_collar">
      <origin xyz="0 0 0.338" rpy="0 0 0" />
      <geometry>
        <cylinder radius="0.03" length="0.02" />
        </geometry>
      </collision>
    </link>
  <link name="mast">
    <visual name="inner_tube">
      <origin xyz="0 0 0.045" rpy="0 0 0" />
      <geometry>
        <cylinder radius="0.012" length="0.61" />
        </geometry>
      <material name="brushed_steel">
        <color rgba="0.55 0.56 0.53 1" />
        </material>
      </visual>
    <visual name="head_arm">
      <origin xyz="0 -0.0225 0.36" rpy="0 0 0" />
      <geometry>
        <box size="0.12 0.045 0.026" />
        </geometry>
      <material name="satin_black">
        <color rgba="0.015 0.015 0.014 1" />
        </material>
      </visual>
    <visual name="yoke_ear_0">
      <origin xyz="-0.047 -0.054 0.36" rpy="0 0 0" />
      <geometry>
        <box size="0.026 0.025 0.02" />
        </geometry>
      <material name="satin_black">
        <color rgba="0.015 0.015 0.014 1" />
        </material>
      </visual>
    <visual name="yoke_ear_1">
      <origin xyz="0.047 -0.054 0.36" rpy="0 0 0" />
      <geometry>
        <box size="0.026 0.025 0.02" />
        </geometry>
      <material name="satin_black">
        <color rgba="0.015 0.015 0.014 1" />
        </material>
      </visual>
    <visual name="hinge_knuckle_0">
      <origin xyz="-0.047 -0.065 0.36" rpy="0 1.5708 0" />
      <geometry>
        <cylinder radius="0.012" length="0.026" />
        </geometry>
      <material name="satin_black">
        <color rgba="0.015 0.015 0.014 1" />
        </material>
      </visual>
    <visual name="hinge_knuckle_1">
      <origin xyz="0.047 -0.065 0.36" rpy="0 1.5708 0" />
      <geometry>
        <cylinder radius="0.012" length="0.026" />
        </geometry>
      <material name="satin_black">
        <color rgba="0.015 0.015 0.014 1" />
        </material>
      </visual>
    <visual name="hinge_pin">
      <origin xyz="0 -0.065 0.36" rpy="0 1.5708 0" />
      <geometry>
        <cylinder radius="0.004" length="0.12" />
        </geometry>
      <material name="brushed_steel">
        <color rgba="0.55 0.56 0.53 1" />
        </material>
      </visual>
    <collision name="inner_tube">
      <origin xyz="0 0 0.045" rpy="0 0 0" />
      <geometry>
        <cylinder radius="0.012" length="0.61" />
        </geometry>
      </collision>
    <collision name="head_arm">
      <origin xyz="0 -0.0225 0.36" rpy="0 0 0" />
      <geometry>
        <box size="0.12 0.045 0.026" />
        </geometry>
      </collision>
    <collision name="yoke_ear_0">
      <origin xyz="-0.047 -0.054 0.36" rpy="0 0 0" />
      <geometry>
        <box size="0.026 0.025 0.02" />
        </geometry>
      </collision>
    <collision name="yoke_ear_1">
      <origin xyz="0.047 -0.054 0.36" rpy="0 0 0" />
      <geometry>
        <box size="0.026 0.025 0.02" />
        </geometry>
      </collision>
    <collision name="hinge_knuckle_0">
      <origin xyz="-0.047 -0.065 0.36" rpy="0 1.5708 0" />
      <geometry>
        <cylinder radius="0.012" length="0.026" />
        </geometry>
      </collision>
    <collision name="hinge_knuckle_1">
      <origin xyz="0.047 -0.065 0.36" rpy="0 1.5708 0" />
      <geometry>
        <cylinder radius="0.012" length="0.026" />
        </geometry>
      </collision>
    <collision name="hinge_pin">
      <origin xyz="0 -0.065 0.36" rpy="0 1.5708 0" />
      <geometry>
        <cylinder radius="0.004" length="0.12" />
        </geometry>
      </collision>
    </link>
  <link name="desk">
    <visual name="center_knuckle">
      <origin xyz="0 0 0" rpy="0 1.5708 0" />
      <geometry>
        <cylinder radius="0.01" length="0.06" />
        </geometry>
      <material name="satin_black">
        <color rgba="0.015 0.015 0.014 1" />
        </material>
      </visual>
    <visual name="hinge_leaf">
      <origin xyz="0 -0.012 0.016" rpy="0 0 0" />
      <geometry>
        <box size="0.05 0.01 0.03" />
        </geometry>
      <material name="satin_black">
        <color rgba="0.015 0.015 0.014 1" />
        </material>
      </visual>
    <visual name="panel">
      <origin xyz="0 -0.018 0.19" rpy="0 0 0" />
      <geometry>
        <mesh filename="assets/meshes/desk_panel.obj" />
        </geometry>
      <material name="satin_black">
        <color rgba="0.015 0.015 0.014 1" />
        </material>
      </visual>
    <visual name="lower_tray">
      <origin xyz="0 -0.045 0.027" rpy="0 0 0" />
      <geometry>
        <box size="0.56 0.06 0.028" />
        </geometry>
      <material name="satin_black">
        <color rgba="0.015 0.015 0.014 1" />
        </material>
      </visual>
    <visual name="front_lip">
      <origin xyz="0 -0.077 0.045" rpy="0 0 0" />
      <geometry>
        <box size="0.56 0.01 0.055" />
        </geometry>
      <material name="worn_black_edge">
        <color rgba="0.025 0.023 0.021 1" />
        </material>
      </visual>
    <visual name="side_rail_0">
      <origin xyz="-0.292 -0.021 0.185" rpy="0 0 0" />
      <geometry>
        <box size="0.018 0.018 0.265" />
        </geometry>
      <material name="worn_black_edge">
        <color rgba="0.025 0.023 0.021 1" />
        </material>
      </visual>
    <visual name="side_rail_1">
      <origin xyz="0.292 -0.021 0.185" rpy="0 0 0" />
      <geometry>
        <box size="0.018 0.018 0.265" />
        </geometry>
      <material name="worn_black_edge">
        <color rgba="0.025 0.023 0.021 1" />
        </material>
      </visual>
    <collision name="center_knuckle">
      <origin xyz="0 0 0" rpy="0 1.5708 0" />
      <geometry>
        <cylinder radius="0.01" length="0.06" />
        </geometry>
      </collision>
    <collision name="hinge_leaf">
      <origin xyz="0 -0.012 0.016" rpy="0 0 0" />
      <geometry>
        <box size="0.05 0.01 0.03" />
        </geometry>
      </collision>
    <collision name="panel">
      <origin xyz="0 -0.018 0.19" rpy="0 0 0" />
      <geometry>
        <mesh filename="assets/meshes/desk_panel.obj" />
        </geometry>
      </collision>
    <collision name="lower_tray">
      <origin xyz="0 -0.045 0.027" rpy="0 0 0" />
      <geometry>
        <box size="0.56 0.06 0.028" />
        </geometry>
      </collision>
    <collision name="front_lip">
      <origin xyz="0 -0.077 0.045" rpy="0 0 0" />
      <geometry>
        <box size="0.56 0.01 0.055" />
        </geometry>
      </collision>
    <collision name="side_rail_0">
      <origin xyz="-0.292 -0.021 0.185" rpy="0 0 0" />
      <geometry>
        <box size="0.018 0.018 0.265" />
        </geometry>
      </collision>
    <collision name="side_rail_1">
      <origin xyz="0.292 -0.021 0.185" rpy="0 0 0" />
      <geometry>
        <box size="0.018 0.018 0.265" />
        </geometry>
      </collision>
    </link>
  <link name="retainer_0">
    <visual name="pivot_pin">
      <origin xyz="0 0 0" rpy="1.5708 0 0" />
      <geometry>
        <cylinder radius="0.006" length="0.02" />
        </geometry>
      <material name="brushed_steel">
        <color rgba="0.55 0.56 0.53 1" />
        </material>
      </visual>
    <visual name="wire_arm">
      <geometry>
        <mesh filename="assets/meshes/retainer_arm_0.obj" />
        </geometry>
      <material name="brushed_steel">
        <color rgba="0.55 0.56 0.53 1" />
        </material>
      </visual>
    <visual name="page_pad">
      <origin xyz="0 -0.004 0.116" rpy="0 0 0" />
      <geometry>
        <box size="0.034 0.005 0.012" />
        </geometry>
      <material name="dark_graphite">
        <color rgba="0.08 0.085 0.085 1" />
        </material>
      </visual>
    <collision name="pivot_pin">
      <origin xyz="0 0 0" rpy="1.5708 0 0" />
      <geometry>
        <cylinder radius="0.006" length="0.02" />
        </geometry>
      </collision>
    <collision name="wire_arm">
      <geometry>
        <mesh filename="assets/meshes/retainer_arm_0.obj" />
        </geometry>
      </collision>
    <collision name="page_pad">
      <origin xyz="0 -0.004 0.116" rpy="0 0 0" />
      <geometry>
        <box size="0.034 0.005 0.012" />
        </geometry>
      </collision>
    </link>
  <link name="retainer_1">
    <visual name="pivot_pin">
      <origin xyz="0 0 0" rpy="1.5708 0 0" />
      <geometry>
        <cylinder radius="0.006" length="0.02" />
        </geometry>
      <material name="brushed_steel">
        <color rgba="0.55 0.56 0.53 1" />
        </material>
      </visual>
    <visual name="wire_arm">
      <geometry>
        <mesh filename="assets/meshes/retainer_arm_1.obj" />
        </geometry>
      <material name="brushed_steel">
        <color rgba="0.55 0.56 0.53 1" />
        </material>
      </visual>
    <visual name="page_pad">
      <origin xyz="0 -0.004 0.116" rpy="0 0 0" />
      <geometry>
        <box size="0.034 0.005 0.012" />
        </geometry>
      <material name="dark_graphite">
        <color rgba="0.08 0.085 0.085 1" />
        </material>
      </visual>
    <collision name="pivot_pin">
      <origin xyz="0 0 0" rpy="1.5708 0 0" />
      <geometry>
        <cylinder radius="0.006" length="0.02" />
        </geometry>
      </collision>
    <collision name="wire_arm">
      <geometry>
        <mesh filename="assets/meshes/retainer_arm_1.obj" />
        </geometry>
      </collision>
    <collision name="page_pad">
      <origin xyz="0 -0.004 0.116" rpy="0 0 0" />
      <geometry>
        <box size="0.034 0.005 0.012" />
        </geometry>
      </collision>
    </link>
  <joint name="mast_slide" type="prismatic">
    <origin xyz="0 0 0.34" rpy="0 0 0" />
    <parent link="base" />
    <child link="mast" />
    <axis xyz="0 0 1" />
    <limit effort="80" velocity="0.2" lower="0" upper="0.16" />
    </joint>
  <joint name="desk_tilt" type="revolute">
    <origin xyz="0 -0.065 0.36" rpy="0 0 0" />
    <parent link="mast" />
    <child link="desk" />
    <axis xyz="1 0 0" />
    <limit effort="12" velocity="1" lower="-0.3" upper="0.7" />
    </joint>
  <joint name="retainer_pivot_0" type="revolute">
    <origin xyz="-0.185 -0.079 0.075" rpy="0 0 0" />
    <parent link="desk" />
    <child link="retainer_0" />
    <axis xyz="0 1 0" />
    <limit effort="0.8" velocity="3" lower="-1.05" upper="1.05" />
    </joint>
  <joint name="retainer_pivot_1" type="revolute">
    <origin xyz="0.185 -0.079 0.075" rpy="0 0 0" />
    <parent link="desk" />
    <child link="retainer_1" />
    <axis xyz="0 1 0" />
    <limit effort="0.8" velocity="3" lower="-1.05" upper="1.05" />
    </joint>
  </robot>
