<robot name="laboratory_axis_stage">
  <material name="cast_aluminum">
    <color rgba="0.62 0.64 0.65 1" />
    </material>
  <material name="dark_burnished_steel">
    <color rgba="0.05 0.055 0.06 1" />
    </material>
  <material name="ground_steel">
    <color rgba="0.74 0.76 0.77 1" />
    </material>
  <material name="black_anodized_cover">
    <color rgba="0.015 0.017 0.02 1" />
    </material>
  <material name="muted_axis_label">
    <color rgba="0.06 0.16 0.32 1" />
    </material>
  <link name="base">
    <visual name="base_plate">
      <origin xyz="0 0 0.0275" rpy="0 0 0" />
      <geometry>
        <box size="1.08 0.46 0.055" />
        </geometry>
      <material name="cast_aluminum">
        <color rgba="0.62 0.64 0.65 1" />
        </material>
      </visual>
    <visual name="base_rail_0">
      <origin xyz="0 -0.16 0.066" rpy="0 0 0" />
      <geometry>
        <box size="0.98 0.035 0.022" />
        </geometry>
      <material name="dark_burnished_steel">
        <color rgba="0.05 0.055 0.06 1" />
        </material>
      </visual>
    <visual name="base_rail_1">
      <origin xyz="0 0.16 0.066" rpy="0 0 0" />
      <geometry>
        <box size="0.98 0.035 0.022" />
        </geometry>
      <material name="dark_burnished_steel">
        <color rgba="0.05 0.055 0.06 1" />
        </material>
      </visual>
    <visual name="x_stop_0_0">
      <origin xyz="-0.505 -0.16 0.08" rpy="0 0 0" />
      <geometry>
        <box size="0.045 0.115 0.05" />
        </geometry>
      <material name="black_anodized_cover">
        <color rgba="0.015 0.017 0.02 1" />
        </material>
      </visual>
    <visual name="x_stop_1_0">
      <origin xyz="-0.505 0.16 0.08" rpy="0 0 0" />
      <geometry>
        <box size="0.045 0.115 0.05" />
        </geometry>
      <material name="black_anodized_cover">
        <color rgba="0.015 0.017 0.02 1" />
        </material>
      </visual>
    <visual name="x_stop_0_1">
      <origin xyz="0.505 -0.16 0.08" rpy="0 0 0" />
      <geometry>
        <box size="0.045 0.115 0.05" />
        </geometry>
      <material name="black_anodized_cover">
        <color rgba="0.015 0.017 0.02 1" />
        </material>
      </visual>
    <visual name="x_stop_1_1">
      <origin xyz="0.505 0.16 0.08" rpy="0 0 0" />
      <geometry>
        <box size="0.045 0.115 0.05" />
        </geometry>
      <material name="black_anodized_cover">
        <color rgba="0.015 0.017 0.02 1" />
        </material>
      </visual>
    <visual name="machined_center_face">
      <origin xyz="0 0 0.058" rpy="0 0 0" />
      <geometry>
        <box size="0.86 0.02 0.006" />
        </geometry>
      <material name="ground_steel">
        <color rgba="0.74 0.76 0.77 1" />
        </material>
      </visual>
    <collision name="base_plate">
      <origin xyz="0 0 0.0275" rpy="0 0 0" />
      <geometry>
        <box size="1.08 0.46 0.055" />
        </geometry>
      </collision>
    <collision name="base_rail_0">
      <origin xyz="0 -0.16 0.066" rpy="0 0 0" />
      <geometry>
        <box size="0.98 0.035 0.022" />
        </geometry>
      </collision>
    <collision name="base_rail_1">
      <origin xyz="0 0.16 0.066" rpy="0 0 0" />
      <geometry>
        <box size="0.98 0.035 0.022" />
        </geometry>
      </collision>
    <collision name="x_stop_0_0">
      <origin xyz="-0.505 -0.16 0.08" rpy="0 0 0" />
      <geometry>
        <box size="0.045 0.115 0.05" />
        </geometry>
      </collision>
    <collision name="x_stop_1_0">
      <origin xyz="-0.505 0.16 0.08" rpy="0 0 0" />
      <geometry>
        <box size="0.045 0.115 0.05" />
        </geometry>
      </collision>
    <collision name="x_stop_0_1">
      <origin xyz="0.505 -0.16 0.08" rpy="0 0 0" />
      <geometry>
        <box size="0.045 0.115 0.05" />
        </geometry>
      </collision>
    <collision name="x_stop_1_1">
      <origin xyz="0.505 0.16 0.08" rpy="0 0 0" />
      <geometry>
        <box size="0.045 0.115 0.05" />
        </geometry>
      </collision>
    <collision name="machined_center_face">
      <origin xyz="0 0 0.058" rpy="0 0 0" />
      <geometry>
        <box size="0.86 0.02 0.006" />
        </geometry>
      </collision>
    </link>
  <link name="bridge_saddle">
    <visual name="x_bearing_0">
      <origin xyz="0 -0.16 0.0225" rpy="0 0 0" />
      <geometry>
        <box size="0.18 0.08 0.045" />
        </geometry>
      <material name="cast_aluminum">
        <color rgba="0.62 0.64 0.65 1" />
        </material>
      </visual>
    <visual name="x_bearing_cap_0">
      <origin xyz="0 -0.16 0.049" rpy="0 0 0" />
      <geometry>
        <box size="0.155 0.052 0.008" />
        </geometry>
      <material name="ground_steel">
        <color rgba="0.74 0.76 0.77 1" />
        </material>
      </visual>
    <visual name="x_bearing_1">
      <origin xyz="0 0.16 0.0225" rpy="0 0 0" />
      <geometry>
        <box size="0.18 0.08 0.045" />
        </geometry>
      <material name="cast_aluminum">
        <color rgba="0.62 0.64 0.65 1" />
        </material>
      </visual>
    <visual name="x_bearing_cap_1">
      <origin xyz="0 0.16 0.049" rpy="0 0 0" />
      <geometry>
        <box size="0.155 0.052 0.008" />
        </geometry>
      <material name="ground_steel">
        <color rgba="0.74 0.76 0.77 1" />
        </material>
      </visual>
    <visual name="bridge_bed">
      <origin xyz="0 0 0.0625" rpy="0 0 0" />
      <geometry>
        <box size="0.28 0.41 0.035" />
        </geometry>
      <material name="cast_aluminum">
        <color rgba="0.62 0.64 0.65 1" />
        </material>
      </visual>
    <visual name="raised_y_deck">
      <origin xyz="0 0 0.09" rpy="0 0 0" />
      <geometry>
        <box size="0.22 0.36 0.02" />
        </geometry>
      <material name="cast_aluminum">
        <color rgba="0.62 0.64 0.65 1" />
        </material>
      </visual>
    <visual name="y_rail_0">
      <origin xyz="-0.105 0 0.111" rpy="0 0 0" />
      <geometry>
        <box size="0.022 0.465 0.022" />
        </geometry>
      <material name="dark_burnished_steel">
        <color rgba="0.05 0.055 0.06 1" />
        </material>
      </visual>
    <visual name="y_rail_1">
      <origin xyz="0.105 0 0.111" rpy="0 0 0" />
      <geometry>
        <box size="0.022 0.465 0.022" />
        </geometry>
      <material name="dark_burnished_steel">
        <color rgba="0.05 0.055 0.06 1" />
        </material>
      </visual>
    <visual name="y_stop_0">
      <origin xyz="0 -0.245 0.1275" rpy="0 0 0" />
      <geometry>
        <box size="0.21 0.025 0.055" />
        </geometry>
      <material name="black_anodized_cover">
        <color rgba="0.015 0.017 0.02 1" />
        </material>
      </visual>
    <visual name="y_stop_1">
      <origin xyz="0 0.245 0.1275" rpy="0 0 0" />
      <geometry>
        <box size="0.21 0.025 0.055" />
        </geometry>
      <material name="black_anodized_cover">
        <color rgba="0.015 0.017 0.02 1" />
        </material>
      </visual>
    <visual name="y_axis_scale">
      <origin xyz="0 0 0.103" rpy="0 0 0" />
      <geometry>
        <box size="0.055 0.3 0.006" />
        </geometry>
      <material name="muted_axis_label">
        <color rgba="0.06 0.16 0.32 1" />
        </material>
      </visual>
    <collision name="x_bearing_0">
      <origin xyz="0 -0.16 0.0225" rpy="0 0 0" />
      <geometry>
        <box size="0.18 0.08 0.045" />
        </geometry>
      </collision>
    <collision name="x_bearing_cap_0">
      <origin xyz="0 -0.16 0.049" rpy="0 0 0" />
      <geometry>
        <box size="0.155 0.052 0.008" />
        </geometry>
      </collision>
    <collision name="x_bearing_1">
      <origin xyz="0 0.16 0.0225" rpy="0 0 0" />
      <geometry>
        <box size="0.18 0.08 0.045" />
        </geometry>
      </collision>
    <collision name="x_bearing_cap_1">
      <origin xyz="0 0.16 0.049" rpy="0 0 0" />
      <geometry>
        <box size="0.155 0.052 0.008" />
        </geometry>
      </collision>
    <collision name="bridge_bed">
      <origin xyz="0 0 0.0625" rpy="0 0 0" />
      <geometry>
        <box size="0.28 0.41 0.035" />
        </geometry>
      </collision>
    <collision name="raised_y_deck">
      <origin xyz="0 0 0.09" rpy="0 0 0" />
      <geometry>
        <box size="0.22 0.36 0.02" />
        </geometry>
      </collision>
    <collision name="y_rail_0">
      <origin xyz="-0.105 0 0.111" rpy="0 0 0" />
      <geometry>
        <box size="0.022 0.465 0.022" />
        </geometry>
      </collision>
    <collision name="y_rail_1">
      <origin xyz="0.105 0 0.111" rpy="0 0 0" />
      <geometry>
        <box size="0.022 0.465 0.022" />
        </geometry>
      </collision>
    <collision name="y_stop_0">
      <origin xyz="0 -0.245 0.1275" rpy="0 0 0" />
      <geometry>
        <box size="0.21 0.025 0.055" />
        </geometry>
      </collision>
    <collision name="y_stop_1">
      <origin xyz="0 0.245 0.1275" rpy="0 0 0" />
      <geometry>
        <box size="0.21 0.025 0.055" />
        </geometry>
      </collision>
    <collision name="y_axis_scale">
      <origin xyz="0 0 0.103" rpy="0 0 0" />
      <geometry>
        <box size="0.055 0.3 0.006" />
        </geometry>
      </collision>
    </link>
  <link name="cross_carriage">
    <visual name="y_bearing_0">
      <origin xyz="-0.105 0 0.02" rpy="0 0 0" />
      <geometry>
        <box size="0.065 0.13 0.04" />
        </geometry>
      <material name="cast_aluminum">
        <color rgba="0.62 0.64 0.65 1" />
        </material>
      </visual>
    <visual name="y_bearing_cap_0">
      <origin xyz="-0.105 0 0.043" rpy="0 0 0" />
      <geometry>
        <box size="0.05 0.1 0.006" />
        </geometry>
      <material name="ground_steel">
        <color rgba="0.74 0.76 0.77 1" />
        </material>
      </visual>
    <visual name="z_saddle_side_0">
      <origin xyz="-0.105 0 0.055" rpy="0 0 0" />
      <geometry>
        <box size="0.075 0.19 0.03" />
        </geometry>
      <material name="cast_aluminum">
        <color rgba="0.62 0.64 0.65 1" />
        </material>
      </visual>
    <visual name="y_bearing_1">
      <origin xyz="0.105 0 0.02" rpy="0 0 0" />
      <geometry>
        <box size="0.065 0.13 0.04" />
        </geometry>
      <material name="cast_aluminum">
        <color rgba="0.62 0.64 0.65 1" />
        </material>
      </visual>
    <visual name="y_bearing_cap_1">
      <origin xyz="0.105 0 0.043" rpy="0 0 0" />
      <geometry>
        <box size="0.05 0.1 0.006" />
        </geometry>
      <material name="ground_steel">
        <color rgba="0.74 0.76 0.77 1" />
        </material>
      </visual>
    <visual name="z_saddle_side_1">
      <origin xyz="0.105 0 0.055" rpy="0 0 0" />
      <geometry>
        <box size="0.075 0.19 0.03" />
        </geometry>
      <material name="cast_aluminum">
        <color rgba="0.62 0.64 0.65 1" />
        </material>
      </visual>
    <visual name="z_saddle_crossbar_0">
      <origin xyz="0 -0.08 0.055" rpy="0 0 0" />
      <geometry>
        <box size="0.205 0.035 0.03" />
        </geometry>
      <material name="cast_aluminum">
        <color rgba="0.62 0.64 0.65 1" />
        </material>
      </visual>
    <visual name="z_saddle_crossbar_1">
      <origin xyz="0 0.08 0.055" rpy="0 0 0" />
      <geometry>
        <box size="0.205 0.035 0.03" />
        </geometry>
      <material name="cast_aluminum">
        <color rgba="0.62 0.64 0.65 1" />
        </material>
      </visual>
    <visual name="z_guide_column_0">
      <origin xyz="-0.062 0 0.22" rpy="0 0 0" />
      <geometry>
        <box size="0.032 0.11 0.3" />
        </geometry>
      <material name="cast_aluminum">
        <color rgba="0.62 0.64 0.65 1" />
        </material>
      </visual>
    <visual name="z_guide_column_1">
      <origin xyz="0.062 0 0.22" rpy="0 0 0" />
      <geometry>
        <box size="0.032 0.11 0.3" />
        </geometry>
      <material name="cast_aluminum">
        <color rgba="0.62 0.64 0.65 1" />
        </material>
      </visual>
    <visual name="z_back_cover">
      <origin xyz="0 0.06 0.22" rpy="0 0 0" />
      <geometry>
        <box size="0.15 0.025 0.3" />
        </geometry>
      <material name="black_anodized_cover">
        <color rgba="0.015 0.017 0.02 1" />
        </material>
      </visual>
    <visual name="left_guide_face">
      <origin xyz="-0.043 0 0.22" rpy="0 0 0" />
      <geometry>
        <box size="0.006 0.08 0.26" />
        </geometry>
      <material name="ground_steel">
        <color rgba="0.74 0.76 0.77 1" />
        </material>
      </visual>
    <visual name="right_guide_face">
      <origin xyz="0.043 0 0.22" rpy="0 0 0" />
      <geometry>
        <box size="0.006 0.08 0.26" />
        </geometry>
      <material name="ground_steel">
        <color rgba="0.74 0.76 0.77 1" />
        </material>
      </visual>
    <visual name="front_ram_cover">
      <origin xyz="0 -0.065 0.3875" rpy="0 0 0" />
      <geometry>
        <box size="0.17 0.03 0.035" />
        </geometry>
      <material name="black_anodized_cover">
        <color rgba="0.015 0.017 0.02 1" />
        </material>
      </visual>
    <visual name="rear_ram_cover">
      <origin xyz="0 0.065 0.3875" rpy="0 0 0" />
      <geometry>
        <box size="0.17 0.03 0.035" />
        </geometry>
      <material name="black_anodized_cover">
        <color rgba="0.015 0.017 0.02 1" />
        </material>
      </visual>
    <collision name="y_bearing_0">
      <origin xyz="-0.105 0 0.02" rpy="0 0 0" />
      <geometry>
        <box size="0.065 0.13 0.04" />
        </geometry>
      </collision>
    <collision name="y_bearing_cap_0">
      <origin xyz="-0.105 0 0.043" rpy="0 0 0" />
      <geometry>
        <box size="0.05 0.1 0.006" />
        </geometry>
      </collision>
    <collision name="z_saddle_side_0">
      <origin xyz="-0.105 0 0.055" rpy="0 0 0" />
      <geometry>
        <box size="0.075 0.19 0.03" />
        </geometry>
      </collision>
    <collision name="y_bearing_1">
      <origin xyz="0.105 0 0.02" rpy="0 0 0" />
      <geometry>
        <box size="0.065 0.13 0.04" />
        </geometry>
      </collision>
    <collision name="y_bearing_cap_1">
      <origin xyz="0.105 0 0.043" rpy="0 0 0" />
      <geometry>
        <box size="0.05 0.1 0.006" />
        </geometry>
      </collision>
    <collision name="z_saddle_side_1">
      <origin xyz="0.105 0 0.055" rpy="0 0 0" />
      <geometry>
        <box size="0.075 0.19 0.03" />
        </geometry>
      </collision>
    <collision name="z_saddle_crossbar_0">
      <origin xyz="0 -0.08 0.055" rpy="0 0 0" />
      <geometry>
        <box size="0.205 0.035 0.03" />
        </geometry>
      </collision>
    <collision name="z_saddle_crossbar_1">
      <origin xyz="0 0.08 0.055" rpy="0 0 0" />
      <geometry>
        <box size="0.205 0.035 0.03" />
        </geometry>
      </collision>
    <collision name="z_guide_column_0">
      <origin xyz="-0.062 0 0.22" rpy="0 0 0" />
      <geometry>
        <box size="0.032 0.11 0.3" />
        </geometry>
      </collision>
    <collision name="z_guide_column_1">
      <origin xyz="0.062 0 0.22" rpy="0 0 0" />
      <geometry>
        <box size="0.032 0.11 0.3" />
        </geometry>
      </collision>
    <collision name="z_back_cover">
      <origin xyz="0 0.06 0.22" rpy="0 0 0" />
      <geometry>
        <box size="0.15 0.025 0.3" />
        </geometry>
      </collision>
    <collision name="left_guide_face">
      <origin xyz="-0.043 0 0.22" rpy="0 0 0" />
      <geometry>
        <box size="0.006 0.08 0.26" />
        </geometry>
      </collision>
    <collision name="right_guide_face">
      <origin xyz="0.043 0 0.22" rpy="0 0 0" />
      <geometry>
        <box size="0.006 0.08 0.26" />
        </geometry>
      </collision>
    <collision name="front_ram_cover">
      <origin xyz="0 -0.065 0.3875" rpy="0 0 0" />
      <geometry>
        <box size="0.17 0.03 0.035" />
        </geometry>
      </collision>
    <collision name="rear_ram_cover">
      <origin xyz="0 0.065 0.3875" rpy="0 0 0" />
      <geometry>
        <box size="0.17 0.03 0.035" />
        </geometry>
      </collision>
    </link>
  <link name="z_ram">
    <visual name="ram_body">
      <origin xyz="0 0 -0.1625" rpy="0 0 0" />
      <geometry>
        <box size="0.08 0.055 0.325" />
        </geometry>
      <material name="ground_steel">
        <color rgba="0.74 0.76 0.77 1" />
        </material>
      </visual>
    <visual name="ram_front_cover">
      <origin xyz="0 -0.033 -0.175" rpy="0 0 0" />
      <geometry>
        <box size="0.052 0.006 0.3" />
        </geometry>
      <material name="black_anodized_cover">
        <color rgba="0.015 0.017 0.02 1" />
        </material>
      </visual>
    <visual name="mounting_flange">
      <origin xyz="0 0 -0.3375" rpy="0 0 0" />
      <geometry>
        <box size="0.13 0.1 0.025" />
        </geometry>
      <material name="cast_aluminum">
        <color rgba="0.62 0.64 0.65 1" />
        </material>
      </visual>
    <visual name="flange_bolt_0_0">
      <origin xyz="-0.043 -0.03 -0.3515" rpy="0 0 0" />
      <geometry>
        <cylinder radius="0.008" length="0.005" />
        </geometry>
      <material name="dark_burnished_steel">
        <color rgba="0.05 0.055 0.06 1" />
        </material>
      </visual>
    <visual name="flange_bolt_0_1">
      <origin xyz="-0.043 0.03 -0.3515" rpy="0 0 0" />
      <geometry>
        <cylinder radius="0.008" length="0.005" />
        </geometry>
      <material name="dark_burnished_steel">
        <color rgba="0.05 0.055 0.06 1" />
        </material>
      </visual>
    <visual name="flange_bolt_1_0">
      <origin xyz="0.043 -0.03 -0.3515" rpy="0 0 0" />
      <geometry>
        <cylinder radius="0.008" length="0.005" />
        </geometry>
      <material name="dark_burnished_steel">
        <color rgba="0.05 0.055 0.06 1" />
        </material>
      </visual>
    <visual name="flange_bolt_1_1">
      <origin xyz="0.043 0.03 -0.3515" rpy="0 0 0" />
      <geometry>
        <cylinder radius="0.008" length="0.005" />
        </geometry>
      <material name="dark_burnished_steel">
        <color rgba="0.05 0.055 0.06 1" />
        </material>
      </visual>
    <collision name="ram_body">
      <origin xyz="0 0 -0.1625" rpy="0 0 0" />
      <geometry>
        <box size="0.08 0.055 0.325" />
        </geometry>
      </collision>
    <collision name="ram_front_cover">
      <origin xyz="0 -0.033 -0.175" rpy="0 0 0" />
      <geometry>
        <box size="0.052 0.006 0.3" />
        </geometry>
      </collision>
    <collision name="mounting_flange">
      <origin xyz="0 0 -0.3375" rpy="0 0 0" />
      <geometry>
        <box size="0.13 0.1 0.025" />
        </geometry>
      </collision>
    <collision name="flange_bolt_0_0">
      <origin xyz="-0.043 -0.03 -0.3515" rpy="0 0 0" />
      <geometry>
        <cylinder radius="0.008" length="0.005" />
        </geometry>
      </collision>
    <collision name="flange_bolt_0_1">
      <origin xyz="-0.043 0.03 -0.3515" rpy="0 0 0" />
      <geometry>
        <cylinder radius="0.008" length="0.005" />
        </geometry>
      </collision>
    <collision name="flange_bolt_1_0">
      <origin xyz="0.043 -0.03 -0.3515" rpy="0 0 0" />
      <geometry>
        <cylinder radius="0.008" length="0.005" />
        </geometry>
      </collision>
    <collision name="flange_bolt_1_1">
      <origin xyz="0.043 0.03 -0.3515" rpy="0 0 0" />
      <geometry>
        <cylinder radius="0.008" length="0.005" />
        </geometry>
      </collision>
    </link>
  <joint name="base_to_bridge" type="prismatic">
    <origin xyz="-0.28 0 0.077" rpy="0 0 0" />
    <parent link="base" />
    <child link="bridge_saddle" />
    <axis xyz="1 0 0" />
    <limit effort="260" velocity="0.45" lower="0" upper="0.56" />
    </joint>
  <joint name="bridge_to_cross" type="prismatic">
    <origin xyz="0 -0.135 0.122" rpy="0 0 0" />
    <parent link="bridge_saddle" />
    <child link="cross_carriage" />
    <axis xyz="0 1 0" />
    <limit effort="180" velocity="0.35" lower="0" upper="0.27" />
    </joint>
  <joint name="cross_to_ram" type="prismatic">
    <origin xyz="0 0 0.365" rpy="0 0 0" />
    <parent link="cross_carriage" />
    <child link="z_ram" />
    <axis xyz="0 0 -1" />
    <limit effort="120" velocity="0.18" lower="0" upper="0.12" />
    </joint>
  </robot>
