<robot name="folding_kick_scooter">
  <link name="deck">
    <visual name="deck_center">
      <origin xyz="-0.005 0 0.115" rpy="0 0 0" />
      <geometry>
        <box size="0.62 0.105 0.026" />
        </geometry>
      <material name="brushed_aluminum">
        <color rgba="0.7 0.72 0.74 1" />
        </material>
      </visual>
    <visual name="rear_round_cap">
      <origin xyz="-0.315 0 0.115" rpy="0 0 0" />
      <geometry>
        <cylinder radius="0.0525" length="0.026" />
        </geometry>
      <material name="brushed_aluminum">
        <color rgba="0.7 0.72 0.74 1" />
        </material>
      </visual>
    <visual name="front_round_cap">
      <origin xyz="0.305 0 0.115" rpy="0 0 0" />
      <geometry>
        <cylinder radius="0.0525" length="0.026" />
        </geometry>
      <material name="brushed_aluminum">
        <color rgba="0.7 0.72 0.74 1" />
        </material>
      </visual>
    <visual name="grip_strip">
      <origin xyz="-0.035 0 0.1295" rpy="0 0 0" />
      <geometry>
        <box size="0.54 0.083 0.004" />
        </geometry>
      <material name="grip_tape">
        <color rgba="0.015 0.017 0.018 1" />
        </material>
      </visual>
    <visual name="side_rail_0">
      <origin xyz="-0.01 0.057 0.117" rpy="0 0 0" />
      <geometry>
        <box size="0.58 0.01 0.018" />
        </geometry>
      <material name="dark_powder_coat">
        <color rgba="0.05 0.055 0.06 1" />
        </material>
      </visual>
    <visual name="side_rail_1">
      <origin xyz="-0.01 -0.057 0.117" rpy="0 0 0" />
      <geometry>
        <box size="0.58 0.01 0.018" />
        </geometry>
      <material name="dark_powder_coat">
        <color rgba="0.05 0.055 0.06 1" />
        </material>
      </visual>
    <visual name="rear_fork_leg_0">
      <origin xyz="-0.445 0.038 0.1" rpy="0 0 0" />
      <geometry>
        <box size="0.09 0.012 0.08" />
        </geometry>
      <material name="dark_powder_coat">
        <color rgba="0.05 0.055 0.06 1" />
        </material>
      </visual>
    <visual name="rear_fork_leg_1">
      <origin xyz="-0.445 -0.038 0.1" rpy="0 0 0" />
      <geometry>
        <box size="0.09 0.012 0.08" />
        </geometry>
      <material name="dark_powder_coat">
        <color rgba="0.05 0.055 0.06 1" />
        </material>
      </visual>
    <visual name="rear_side_stay_0">
      <origin xyz="-0.39 0.038 0.128" rpy="0 0 0" />
      <geometry>
        <box size="0.105 0.012 0.018" />
        </geometry>
      <material name="dark_powder_coat">
        <color rgba="0.05 0.055 0.06 1" />
        </material>
      </visual>
    <visual name="rear_side_stay_1">
      <origin xyz="-0.39 -0.038 0.128" rpy="0 0 0" />
      <geometry>
        <box size="0.105 0.012 0.018" />
        </geometry>
      <material name="dark_powder_coat">
        <color rgba="0.05 0.055 0.06 1" />
        </material>
      </visual>
    <visual name="rear_axle">
      <origin xyz="-0.46 0 0.075" rpy="1.5708 0 0" />
      <geometry>
        <cylinder radius="0.008" length="0.102" />
        </geometry>
      <material name="dark_powder_coat">
        <color rgba="0.05 0.055 0.06 1" />
        </material>
      </visual>
    <visual name="hinge_base_plate">
      <origin xyz="0.335 0 0.136" rpy="0 0 0" />
      <geometry>
        <box size="0.075 0.105 0.02" />
        </geometry>
      <material name="dark_powder_coat">
        <color rgba="0.05 0.055 0.06 1" />
        </material>
      </visual>
    <visual name="hinge_cheek_0">
      <origin xyz="0.35 0.04 0.151" rpy="0 0 0" />
      <geometry>
        <box size="0.05 0.026 0.05" />
        </geometry>
      <material name="dark_powder_coat">
        <color rgba="0.05 0.055 0.06 1" />
        </material>
      </visual>
    <visual name="fixed_hinge_knuckle_0">
      <origin xyz="0.35 0.04 0.16" rpy="1.5708 0 0" />
      <geometry>
        <cylinder radius="0.018" length="0.032" />
        </geometry>
      <material name="dark_powder_coat">
        <color rgba="0.05 0.055 0.06 1" />
        </material>
      </visual>
    <visual name="hinge_cheek_1">
      <origin xyz="0.35 -0.04 0.151" rpy="0 0 0" />
      <geometry>
        <box size="0.05 0.026 0.05" />
        </geometry>
      <material name="dark_powder_coat">
        <color rgba="0.05 0.055 0.06 1" />
        </material>
      </visual>
    <visual name="fixed_hinge_knuckle_1">
      <origin xyz="0.35 -0.04 0.16" rpy="1.5708 0 0" />
      <geometry>
        <cylinder radius="0.018" length="0.032" />
        </geometry>
      <material name="dark_powder_coat">
        <color rgba="0.05 0.055 0.06 1" />
        </material>
      </visual>
    <collision name="deck_center">
      <origin xyz="-0.005 0 0.115" rpy="0 0 0" />
      <geometry>
        <box size="0.62 0.105 0.026" />
        </geometry>
      </collision>
    <collision name="rear_round_cap">
      <origin xyz="-0.315 0 0.115" rpy="0 0 0" />
      <geometry>
        <cylinder radius="0.0525" length="0.026" />
        </geometry>
      </collision>
    <collision name="front_round_cap">
      <origin xyz="0.305 0 0.115" rpy="0 0 0" />
      <geometry>
        <cylinder radius="0.0525" length="0.026" />
        </geometry>
      </collision>
    <collision name="grip_strip">
      <origin xyz="-0.035 0 0.1295" rpy="0 0 0" />
      <geometry>
        <box size="0.54 0.083 0.004" />
        </geometry>
      </collision>
    <collision name="side_rail_0">
      <origin xyz="-0.01 0.057 0.117" rpy="0 0 0" />
      <geometry>
        <box size="0.58 0.01 0.018" />
        </geometry>
      </collision>
    <collision name="side_rail_1">
      <origin xyz="-0.01 -0.057 0.117" rpy="0 0 0" />
      <geometry>
        <box size="0.58 0.01 0.018" />
        </geometry>
      </collision>
    <collision name="rear_fork_leg_0">
      <origin xyz="-0.445 0.038 0.1" rpy="0 0 0" />
      <geometry>
        <box size="0.09 0.012 0.08" />
        </geometry>
      </collision>
    <collision name="rear_fork_leg_1">
      <origin xyz="-0.445 -0.038 0.1" rpy="0 0 0" />
      <geometry>
        <box size="0.09 0.012 0.08" />
        </geometry>
      </collision>
    <collision name="rear_side_stay_0">
      <origin xyz="-0.39 0.038 0.128" rpy="0 0 0" />
      <geometry>
        <box size="0.105 0.012 0.018" />
        </geometry>
      </collision>
    <collision name="rear_side_stay_1">
      <origin xyz="-0.39 -0.038 0.128" rpy="0 0 0" />
      <geometry>
        <box size="0.105 0.012 0.018" />
        </geometry>
      </collision>
    <collision name="rear_axle">
      <origin xyz="-0.46 0 0.075" rpy="1.5708 0 0" />
      <geometry>
        <cylinder radius="0.008" length="0.102" />
        </geometry>
      </collision>
    <collision name="hinge_base_plate">
      <origin xyz="0.335 0 0.136" rpy="0 0 0" />
      <geometry>
        <box size="0.075 0.105 0.02" />
        </geometry>
      </collision>
    <collision name="hinge_cheek_0">
      <origin xyz="0.35 0.04 0.151" rpy="0 0 0" />
      <geometry>
        <box size="0.05 0.026 0.05" />
        </geometry>
      </collision>
    <collision name="fixed_hinge_knuckle_0">
      <origin xyz="0.35 0.04 0.16" rpy="1.5708 0 0" />
      <geometry>
        <cylinder radius="0.018" length="0.032" />
        </geometry>
      </collision>
    <collision name="hinge_cheek_1">
      <origin xyz="0.35 -0.04 0.151" rpy="0 0 0" />
      <geometry>
        <box size="0.05 0.026 0.05" />
        </geometry>
      </collision>
    <collision name="fixed_hinge_knuckle_1">
      <origin xyz="0.35 -0.04 0.16" rpy="1.5708 0 0" />
      <geometry>
        <cylinder radius="0.018" length="0.032" />
        </geometry>
      </collision>
    </link>
  <link name="stem">
    <visual name="folding_hinge_knuckle">
      <origin xyz="0 0 0" rpy="1.5708 0 0" />
      <geometry>
        <cylinder radius="0.0165" length="0.043" />
        </geometry>
      <material name="brushed_aluminum">
        <color rgba="0.7 0.72 0.74 1" />
        </material>
      </visual>
    <visual name="hinge_lug">
      <origin xyz="0.018 0 0.024" rpy="0 0 0" />
      <geometry>
        <box size="0.055 0.04 0.055" />
        </geometry>
      <material name="brushed_aluminum">
        <color rgba="0.7 0.72 0.74 1" />
        </material>
      </visual>
    <visual name="folding_release_catch">
      <origin xyz="0.047 0 0.016" rpy="0 0 0" />
      <geometry>
        <box size="0.018 0.032 0.03" />
        </geometry>
      <material name="red_release_catch">
        <color rgba="0.8 0.04 0.025 1" />
        </material>
      </visual>
    <visual name="stem_socket">
      <origin xyz="0.018 0 0.055" rpy="0 0 0" />
      <geometry>
        <box size="0.048 0.034 0.018" />
        </geometry>
      <material name="brushed_aluminum">
        <color rgba="0.7 0.72 0.74 1" />
        </material>
      </visual>
    <visual name="main_stem_tube">
      <origin xyz="-0.0348858 0 0.436302" rpy="0 -0.139626 0" />
      <geometry>
        <cylinder radius="0.018" length="0.76" />
        </geometry>
      <material name="brushed_aluminum">
        <color rgba="0.7 0.72 0.74 1" />
        </material>
      </visual>
    <visual name="lower_clamp_collar">
      <origin xyz="0.00319198 0 0.165365" rpy="0 -0.139626 0" />
      <geometry>
        <cylinder radius="0.022" length="0.06" />
        </geometry>
      <material name="dark_powder_coat">
        <color rgba="0.05 0.055 0.06 1" />
        </material>
      </visual>
    <visual name="upper_clamp_collar">
      <origin xyz="-0.0539247 0 0.571771" rpy="0 -0.139626 0" />
      <geometry>
        <cylinder radius="0.02" length="0.05" />
        </geometry>
      <material name="dark_powder_coat">
        <color rgba="0.05 0.055 0.06 1" />
        </material>
      </visual>
    <visual name="handlebar_crossbar">
      <origin xyz="-0.0877716 0 0.822604" rpy="1.5708 0 0" />
      <geometry>
        <cylinder radius="0.014" length="0.46" />
        </geometry>
      <material name="brushed_aluminum">
        <color rgba="0.7 0.72 0.74 1" />
        </material>
      </visual>
    <visual name="grip_0">
      <origin xyz="-0.0877716 0.287 0.822604" rpy="1.5708 0 0" />
      <geometry>
        <cylinder radius="0.018" length="0.115" />
        </geometry>
      <material name="black_rubber">
        <color rgba="0.01 0.01 0.01 1" />
        </material>
      </visual>
    <visual name="grip_1">
      <origin xyz="-0.0877716 -0.287 0.822604" rpy="1.5708 0 0" />
      <geometry>
        <cylinder radius="0.018" length="0.115" />
        </geometry>
      <material name="black_rubber">
        <color rgba="0.01 0.01 0.01 1" />
        </material>
      </visual>
    <visual name="front_fork_crown">
      <origin xyz="0.08 0 0.017" rpy="0 0 0" />
      <geometry>
        <box size="0.1 0.092 0.022" />
        </geometry>
      <material name="brushed_aluminum">
        <color rgba="0.7 0.72 0.74 1" />
        </material>
      </visual>
    <visual name="front_fork_leg_0">
      <origin xyz="0.11 0.038 -0.057" rpy="0 0 0" />
      <geometry>
        <box size="0.028 0.011 0.128" />
        </geometry>
      <material name="brushed_aluminum">
        <color rgba="0.7 0.72 0.74 1" />
        </material>
      </visual>
    <visual name="front_fork_leg_1">
      <origin xyz="0.11 -0.038 -0.057" rpy="0 0 0" />
      <geometry>
        <box size="0.028 0.011 0.128" />
        </geometry>
      <material name="brushed_aluminum">
        <color rgba="0.7 0.72 0.74 1" />
        </material>
      </visual>
    <visual name="front_axle">
      <origin xyz="0.11 0 -0.085" rpy="1.5708 0 0" />
      <geometry>
        <cylinder radius="0.008" length="0.102" />
        </geometry>
      <material name="dark_powder_coat">
        <color rgba="0.05 0.055 0.06 1" />
        </material>
      </visual>
    <collision name="folding_hinge_knuckle">
      <origin xyz="0 0 0" rpy="1.5708 0 0" />
      <geometry>
        <cylinder radius="0.0165" length="0.043" />
        </geometry>
      </collision>
    <collision name="hinge_lug">
      <origin xyz="0.018 0 0.024" rpy="0 0 0" />
      <geometry>
        <box size="0.055 0.04 0.055" />
        </geometry>
      </collision>
    <collision name="folding_release_catch">
      <origin xyz="0.047 0 0.016" rpy="0 0 0" />
      <geometry>
        <box size="0.018 0.032 0.03" />
        </geometry>
      </collision>
    <collision name="stem_socket">
      <origin xyz="0.018 0 0.055" rpy="0 0 0" />
      <geometry>
        <box size="0.048 0.034 0.018" />
        </geometry>
      </collision>
    <collision name="main_stem_tube">
      <origin xyz="-0.0348858 0 0.436302" rpy="0 -0.139626 0" />
      <geometry>
        <cylinder radius="0.018" length="0.76" />
        </geometry>
      </collision>
    <collision name="lower_clamp_collar">
      <origin xyz="0.00319198 0 0.165365" rpy="0 -0.139626 0" />
      <geometry>
        <cylinder radius="0.022" length="0.06" />
        </geometry>
      </collision>
    <collision name="upper_clamp_collar">
      <origin xyz="-0.0539247 0 0.571771" rpy="0 -0.139626 0" />
      <geometry>
        <cylinder radius="0.02" length="0.05" />
        </geometry>
      </collision>
    <collision name="handlebar_crossbar">
      <origin xyz="-0.0877716 0 0.822604" rpy="1.5708 0 0" />
      <geometry>
        <cylinder radius="0.014" length="0.46" />
        </geometry>
      </collision>
    <collision name="grip_0">
      <origin xyz="-0.0877716 0.287 0.822604" rpy="1.5708 0 0" />
      <geometry>
        <cylinder radius="0.018" length="0.115" />
        </geometry>
      </collision>
    <collision name="grip_1">
      <origin xyz="-0.0877716 -0.287 0.822604" rpy="1.5708 0 0" />
      <geometry>
        <cylinder radius="0.018" length="0.115" />
        </geometry>
      </collision>
    <collision name="front_fork_crown">
      <origin xyz="0.08 0 0.017" rpy="0 0 0" />
      <geometry>
        <box size="0.1 0.092 0.022" />
        </geometry>
      </collision>
    <collision name="front_fork_leg_0">
      <origin xyz="0.11 0.038 -0.057" rpy="0 0 0" />
      <geometry>
        <box size="0.028 0.011 0.128" />
        </geometry>
      </collision>
    <collision name="front_fork_leg_1">
      <origin xyz="0.11 -0.038 -0.057" rpy="0 0 0" />
      <geometry>
        <box size="0.028 0.011 0.128" />
        </geometry>
      </collision>
    <collision name="front_axle">
      <origin xyz="0.11 0 -0.085" rpy="1.5708 0 0" />
      <geometry>
        <cylinder radius="0.008" length="0.102" />
        </geometry>
      </collision>
    </link>
  <link name="rear_wheel">
    <visual name="rear_tire">
      <origin xyz="0 0 0" rpy="0 0 1.5708" />
      <geometry>
        <mesh filename="assets/meshes/scooter_polyurethane_tire.obj" />
        </geometry>
      <material name="black_rubber">
        <color rgba="0.01 0.01 0.01 1" />
        </material>
      </visual>
    <visual name="rear_wheel_core">
      <origin xyz="0 0 0" rpy="0 0 1.5708" />
      <geometry>
        <mesh filename="assets/meshes/scooter_polyurethane_wheel_core.obj" />
        </geometry>
      <material name="brushed_aluminum">
        <color rgba="0.7 0.72 0.74 1" />
        </material>
      </visual>
    <collision name="rear_tire">
      <origin xyz="0 0 0" rpy="0 0 1.5708" />
      <geometry>
        <mesh filename="assets/meshes/scooter_polyurethane_tire.obj" />
        </geometry>
      </collision>
    <collision name="rear_wheel_core">
      <origin xyz="0 0 0" rpy="0 0 1.5708" />
      <geometry>
        <mesh filename="assets/meshes/scooter_polyurethane_wheel_core.obj" />
        </geometry>
      </collision>
    </link>
  <link name="front_wheel">
    <visual name="front_tire">
      <origin xyz="0 0 0" rpy="0 0 1.5708" />
      <geometry>
        <mesh filename="assets/meshes/scooter_polyurethane_tire.obj" />
        </geometry>
      <material name="black_rubber">
        <color rgba="0.01 0.01 0.01 1" />
        </material>
      </visual>
    <visual name="front_wheel_core">
      <origin xyz="0 0 0" rpy="0 0 1.5708" />
      <geometry>
        <mesh filename="assets/meshes/scooter_polyurethane_wheel_core.obj" />
        </geometry>
      <material name="brushed_aluminum">
        <color rgba="0.7 0.72 0.74 1" />
        </material>
      </visual>
    <collision name="front_tire">
      <origin xyz="0 0 0" rpy="0 0 1.5708" />
      <geometry>
        <mesh filename="assets/meshes/scooter_polyurethane_tire.obj" />
        </geometry>
      </collision>
    <collision name="front_wheel_core">
      <origin xyz="0 0 0" rpy="0 0 1.5708" />
      <geometry>
        <mesh filename="assets/meshes/scooter_polyurethane_wheel_core.obj" />
        </geometry>
      </collision>
    </link>
  <joint name="deck_to_stem" type="revolute">
    <origin xyz="0.35 0 0.16" rpy="0 0 0" />
    <parent link="deck" />
    <child link="stem" />
    <axis xyz="0 -1 0" />
    <limit effort="35" velocity="2" lower="-1.39626" upper="1.5708" />
    </joint>
  <joint name="deck_to_rear_wheel" type="continuous">
    <origin xyz="-0.46 0 0.075" rpy="0 0 0" />
    <parent link="deck" />
    <child link="rear_wheel" />
    <axis xyz="0 1 0" />
    <limit effort="2" velocity="45" />
    </joint>
  <joint name="stem_to_front_wheel" type="continuous">
    <origin xyz="0.11 0 -0.085" rpy="0 0 0" />
    <parent link="stem" />
    <child link="front_wheel" />
    <axis xyz="0 1 0" />
    <limit effort="2" velocity="45" />
    </joint>
  </robot>
