<robot name="gear_assemblies_study">
  <material name="shot_blasted_frame">
    <color rgba="0.33 0.35 0.35 1" />
    </material>
  <material name="black_oxide">
    <color rgba="0.055 0.06 0.062 1" />
    </material>
  <material name="ground_shaft_steel">
    <color rgba="0.7 0.72 0.7 1" />
    </material>
  <material name="oiled_machined_steel">
    <color rgba="0.48 0.47 0.42 1" />
    </material>
  <material name="bronze_wear_surfaces">
    <color rgba="0.74 0.54 0.28 1" />
    </material>
  <material name="brushed_cover_plate">
    <color rgba="0.42 0.46 0.47 1" />
    </material>
  <material name="dark_split_lines">
    <color rgba="0.015 0.016 0.017 1" />
    </material>
  <link name="frame">
    <visual name="ground_base">
      <origin xyz="-0.1 0 0.02" rpy="0 0 0" />
      <geometry>
        <box size="1.36 0.74 0.04" />
        </geometry>
      <material name="shot_blasted_frame">
        <color rgba="0.33 0.35 0.35 1" />
        </material>
      </visual>
    <visual name="near_lower_rail">
      <origin xyz="-0.1 -0.34 0.085" rpy="0 0 0" />
      <geometry>
        <box size="1.27 0.045 0.09" />
        </geometry>
      <material name="shot_blasted_frame">
        <color rgba="0.33 0.35 0.35 1" />
        </material>
      </visual>
    <visual name="far_lower_rail">
      <origin xyz="-0.1 0.34 0.085" rpy="0 0 0" />
      <geometry>
        <box size="1.27 0.045 0.09" />
        </geometry>
      <material name="shot_blasted_frame">
        <color rgba="0.33 0.35 0.35 1" />
        </material>
      </visual>
    <visual name="near_upper_rail">
      <origin xyz="-0.1 -0.34 0.535" rpy="0 0 0" />
      <geometry>
        <box size="1.27 0.03 0.05" />
        </geometry>
      <material name="shot_blasted_frame">
        <color rgba="0.33 0.35 0.35 1" />
        </material>
      </visual>
    <visual name="far_upper_rail">
      <origin xyz="-0.1 0.34 0.535" rpy="0 0 0" />
      <geometry>
        <box size="1.27 0.03 0.05" />
        </geometry>
      <material name="shot_blasted_frame">
        <color rgba="0.33 0.35 0.35 1" />
        </material>
      </visual>
    <visual name="near_post_0">
      <origin xyz="-0.62 -0.34 0.287" rpy="0 0 0" />
      <geometry>
        <box size="0.04 0.045 0.495" />
        </geometry>
      <material name="shot_blasted_frame">
        <color rgba="0.33 0.35 0.35 1" />
        </material>
      </visual>
    <visual name="far_post_0">
      <origin xyz="-0.62 0.34 0.287" rpy="0 0 0" />
      <geometry>
        <box size="0.04 0.045 0.495" />
        </geometry>
      <material name="shot_blasted_frame">
        <color rgba="0.33 0.35 0.35 1" />
        </material>
      </visual>
    <visual name="near_post_1">
      <origin xyz="-0.36 -0.34 0.287" rpy="0 0 0" />
      <geometry>
        <box size="0.04 0.045 0.495" />
        </geometry>
      <material name="shot_blasted_frame">
        <color rgba="0.33 0.35 0.35 1" />
        </material>
      </visual>
    <visual name="far_post_1">
      <origin xyz="-0.36 0.34 0.287" rpy="0 0 0" />
      <geometry>
        <box size="0.04 0.045 0.495" />
        </geometry>
      <material name="shot_blasted_frame">
        <color rgba="0.33 0.35 0.35 1" />
        </material>
      </visual>
    <visual name="near_post_2">
      <origin xyz="-0.1 -0.34 0.287" rpy="0 0 0" />
      <geometry>
        <box size="0.04 0.045 0.495" />
        </geometry>
      <material name="shot_blasted_frame">
        <color rgba="0.33 0.35 0.35 1" />
        </material>
      </visual>
    <visual name="far_post_2">
      <origin xyz="-0.1 0.34 0.287" rpy="0 0 0" />
      <geometry>
        <box size="0.04 0.045 0.495" />
        </geometry>
      <material name="shot_blasted_frame">
        <color rgba="0.33 0.35 0.35 1" />
        </material>
      </visual>
    <visual name="near_post_3">
      <origin xyz="0.13 -0.34 0.287" rpy="0 0 0" />
      <geometry>
        <box size="0.04 0.045 0.495" />
        </geometry>
      <material name="shot_blasted_frame">
        <color rgba="0.33 0.35 0.35 1" />
        </material>
      </visual>
    <visual name="far_post_3">
      <origin xyz="0.13 0.34 0.287" rpy="0 0 0" />
      <geometry>
        <box size="0.04 0.045 0.495" />
        </geometry>
      <material name="shot_blasted_frame">
        <color rgba="0.33 0.35 0.35 1" />
        </material>
      </visual>
    <visual name="near_post_4">
      <origin xyz="0.39 -0.34 0.287" rpy="0 0 0" />
      <geometry>
        <box size="0.04 0.045 0.495" />
        </geometry>
      <material name="shot_blasted_frame">
        <color rgba="0.33 0.35 0.35 1" />
        </material>
      </visual>
    <visual name="far_post_4">
      <origin xyz="0.39 0.34 0.287" rpy="0 0 0" />
      <geometry>
        <box size="0.04 0.045 0.495" />
        </geometry>
      <material name="shot_blasted_frame">
        <color rgba="0.33 0.35 0.35 1" />
        </material>
      </visual>
    <visual name="cross_tie_0">
      <origin xyz="-0.6 0 0.07" rpy="0 0 0" />
      <geometry>
        <box size="0.045 0.6 0.06" />
        </geometry>
      <material name="shot_blasted_frame">
        <color rgba="0.33 0.35 0.35 1" />
        </material>
      </visual>
    <visual name="cross_tie_1">
      <origin xyz="-0.22 0 0.07" rpy="0 0 0" />
      <geometry>
        <box size="0.045 0.6 0.06" />
        </geometry>
      <material name="shot_blasted_frame">
        <color rgba="0.33 0.35 0.35 1" />
        </material>
      </visual>
    <visual name="cross_tie_2">
      <origin xyz="0.17 0 0.07" rpy="0 0 0" />
      <geometry>
        <box size="0.045 0.6 0.06" />
        </geometry>
      <material name="shot_blasted_frame">
        <color rgba="0.33 0.35 0.35 1" />
        </material>
      </visual>
    <visual name="cross_tie_3">
      <origin xyz="0.44 0 0.07" rpy="0 0 0" />
      <geometry>
        <box size="0.045 0.6 0.06" />
        </geometry>
      <material name="shot_blasted_frame">
        <color rgba="0.33 0.35 0.35 1" />
        </material>
      </visual>
    <visual name="spur_cover_top_guide">
      <origin xyz="-0.28 -0.37 0.445" rpy="0 0 0" />
      <geometry>
        <box size="0.47 0.025 0.026" />
        </geometry>
      <material name="shot_blasted_frame">
        <color rgba="0.33 0.35 0.35 1" />
        </material>
      </visual>
    <visual name="spur_cover_bottom_guide">
      <origin xyz="-0.28 -0.37 0.23" rpy="0 0 0" />
      <geometry>
        <box size="0.47 0.025 0.026" />
        </geometry>
      <material name="shot_blasted_frame">
        <color rgba="0.33 0.35 0.35 1" />
        </material>
      </visual>
    <visual name="bevel_cover_top_guide">
      <origin xyz="0.17 -0.37 0.445" rpy="0 0 0" />
      <geometry>
        <box size="0.31 0.025 0.026" />
        </geometry>
      <material name="shot_blasted_frame">
        <color rgba="0.33 0.35 0.35 1" />
        </material>
      </visual>
    <visual name="bevel_cover_bottom_guide">
      <origin xyz="0.17 -0.37 0.23" rpy="0 0 0" />
      <geometry>
        <box size="0.31 0.025 0.026" />
        </geometry>
      <material name="shot_blasted_frame">
        <color rgba="0.33 0.35 0.35 1" />
        </material>
      </visual>
    <visual name="input_pedestal_0">
      <origin xyz="-0.42 -0.25 0.169" rpy="0 0 0" />
      <geometry>
        <box size="0.105 0.06 0.258" />
        </geometry>
      <material name="shot_blasted_frame">
        <color rgba="0.33 0.35 0.35 1" />
        </material>
      </visual>
    <visual name="input_bearing_0_ring">
      <origin xyz="-0.42 -0.25 0.34" rpy="-1.5708 0 0" />
      <geometry>
        <mesh filename="assets/meshes/split_bearing_ring.obj" />
        </geometry>
      <material name="bronze_wear_surfaces">
        <color rgba="0.74 0.54 0.28 1" />
        </material>
      </visual>
    <visual name="input_bearing_0_cap">
      <origin xyz="-0.42 -0.25 0.395" rpy="0 0 0" />
      <geometry>
        <box size="0.122 0.06 0.034" />
        </geometry>
      <material name="shot_blasted_frame">
        <color rgba="0.33 0.35 0.35 1" />
        </material>
      </visual>
    <visual name="input_bearing_0_split_line">
      <origin xyz="-0.42 -0.279 0.378" rpy="0 0 0" />
      <geometry>
        <box size="0.12 0.006 0.01" />
        </geometry>
      <material name="dark_split_lines">
        <color rgba="0.015 0.016 0.017 1" />
        </material>
      </visual>
    <visual name="input_bearing_0_bolt_0">
      <origin xyz="-0.456 -0.25 0.419" rpy="0 0 0" />
      <geometry>
        <cylinder radius="0.006" length="0.014" />
        </geometry>
      <material name="black_oxide">
        <color rgba="0.055 0.06 0.062 1" />
        </material>
      </visual>
    <visual name="input_bearing_0_bolt_1">
      <origin xyz="-0.384 -0.25 0.419" rpy="0 0 0" />
      <geometry>
        <cylinder radius="0.006" length="0.014" />
        </geometry>
      <material name="black_oxide">
        <color rgba="0.055 0.06 0.062 1" />
        </material>
      </visual>
    <visual name="input_pedestal_1">
      <origin xyz="-0.42 0.25 0.169" rpy="0 0 0" />
      <geometry>
        <box size="0.105 0.06 0.258" />
        </geometry>
      <material name="shot_blasted_frame">
        <color rgba="0.33 0.35 0.35 1" />
        </material>
      </visual>
    <visual name="input_bearing_1_ring">
      <origin xyz="-0.42 0.25 0.34" rpy="-1.5708 0 0" />
      <geometry>
        <mesh filename="assets/meshes/split_bearing_ring.obj" />
        </geometry>
      <material name="bronze_wear_surfaces">
        <color rgba="0.74 0.54 0.28 1" />
        </material>
      </visual>
    <visual name="input_bearing_1_cap">
      <origin xyz="-0.42 0.25 0.395" rpy="0 0 0" />
      <geometry>
        <box size="0.122 0.06 0.034" />
        </geometry>
      <material name="shot_blasted_frame">
        <color rgba="0.33 0.35 0.35 1" />
        </material>
      </visual>
    <visual name="input_bearing_1_split_line">
      <origin xyz="-0.42 0.221 0.378" rpy="0 0 0" />
      <geometry>
        <box size="0.12 0.006 0.01" />
        </geometry>
      <material name="dark_split_lines">
        <color rgba="0.015 0.016 0.017 1" />
        </material>
      </visual>
    <visual name="input_bearing_1_bolt_0">
      <origin xyz="-0.456 0.25 0.419" rpy="0 0 0" />
      <geometry>
        <cylinder radius="0.006" length="0.014" />
        </geometry>
      <material name="black_oxide">
        <color rgba="0.055 0.06 0.062 1" />
        </material>
      </visual>
    <visual name="input_bearing_1_bolt_1">
      <origin xyz="-0.384 0.25 0.419" rpy="0 0 0" />
      <geometry>
        <cylinder radius="0.006" length="0.014" />
        </geometry>
      <material name="black_oxide">
        <color rgba="0.055 0.06 0.062 1" />
        </material>
      </visual>
    <visual name="compound_pedestal_0">
      <origin xyz="-0.1 -0.25 0.169" rpy="0 0 0" />
      <geometry>
        <box size="0.105 0.06 0.258" />
        </geometry>
      <material name="shot_blasted_frame">
        <color rgba="0.33 0.35 0.35 1" />
        </material>
      </visual>
    <visual name="compound_bearing_0_ring">
      <origin xyz="-0.1 -0.25 0.34" rpy="-1.5708 0 0" />
      <geometry>
        <mesh filename="assets/meshes/split_bearing_ring.obj" />
        </geometry>
      <material name="bronze_wear_surfaces">
        <color rgba="0.74 0.54 0.28 1" />
        </material>
      </visual>
    <visual name="compound_bearing_0_cap">
      <origin xyz="-0.1 -0.25 0.395" rpy="0 0 0" />
      <geometry>
        <box size="0.122 0.06 0.034" />
        </geometry>
      <material name="shot_blasted_frame">
        <color rgba="0.33 0.35 0.35 1" />
        </material>
      </visual>
    <visual name="compound_bearing_0_split_line">
      <origin xyz="-0.1 -0.279 0.378" rpy="0 0 0" />
      <geometry>
        <box size="0.12 0.006 0.01" />
        </geometry>
      <material name="dark_split_lines">
        <color rgba="0.015 0.016 0.017 1" />
        </material>
      </visual>
    <visual name="compound_bearing_0_bolt_0">
      <origin xyz="-0.136 -0.25 0.419" rpy="0 0 0" />
      <geometry>
        <cylinder radius="0.006" length="0.014" />
        </geometry>
      <material name="black_oxide">
        <color rgba="0.055 0.06 0.062 1" />
        </material>
      </visual>
    <visual name="compound_bearing_0_bolt_1">
      <origin xyz="-0.064 -0.25 0.419" rpy="0 0 0" />
      <geometry>
        <cylinder radius="0.006" length="0.014" />
        </geometry>
      <material name="black_oxide">
        <color rgba="0.055 0.06 0.062 1" />
        </material>
      </visual>
    <visual name="compound_pedestal_1">
      <origin xyz="-0.1 0.25 0.169" rpy="0 0 0" />
      <geometry>
        <box size="0.105 0.06 0.258" />
        </geometry>
      <material name="shot_blasted_frame">
        <color rgba="0.33 0.35 0.35 1" />
        </material>
      </visual>
    <visual name="compound_bearing_1_ring">
      <origin xyz="-0.1 0.25 0.34" rpy="-1.5708 0 0" />
      <geometry>
        <mesh filename="assets/meshes/split_bearing_ring.obj" />
        </geometry>
      <material name="bronze_wear_surfaces">
        <color rgba="0.74 0.54 0.28 1" />
        </material>
      </visual>
    <visual name="compound_bearing_1_cap">
      <origin xyz="-0.1 0.25 0.395" rpy="0 0 0" />
      <geometry>
        <box size="0.122 0.06 0.034" />
        </geometry>
      <material name="shot_blasted_frame">
        <color rgba="0.33 0.35 0.35 1" />
        </material>
      </visual>
    <visual name="compound_bearing_1_split_line">
      <origin xyz="-0.1 0.221 0.378" rpy="0 0 0" />
      <geometry>
        <box size="0.12 0.006 0.01" />
        </geometry>
      <material name="dark_split_lines">
        <color rgba="0.015 0.016 0.017 1" />
        </material>
      </visual>
    <visual name="compound_bearing_1_bolt_0">
      <origin xyz="-0.136 0.25 0.419" rpy="0 0 0" />
      <geometry>
        <cylinder radius="0.006" length="0.014" />
        </geometry>
      <material name="black_oxide">
        <color rgba="0.055 0.06 0.062 1" />
        </material>
      </visual>
    <visual name="compound_bearing_1_bolt_1">
      <origin xyz="-0.064 0.25 0.419" rpy="0 0 0" />
      <geometry>
        <cylinder radius="0.006" length="0.014" />
        </geometry>
      <material name="black_oxide">
        <color rgba="0.055 0.06 0.062 1" />
        </material>
      </visual>
    <visual name="transfer_pedestal_0">
      <origin xyz="0.145 -0.25 0.169" rpy="0 0 0" />
      <geometry>
        <box size="0.105 0.06 0.258" />
        </geometry>
      <material name="shot_blasted_frame">
        <color rgba="0.33 0.35 0.35 1" />
        </material>
      </visual>
    <visual name="transfer_bearing_0_ring">
      <origin xyz="0.145 -0.25 0.34" rpy="-1.5708 0 0" />
      <geometry>
        <mesh filename="assets/meshes/split_bearing_ring.obj" />
        </geometry>
      <material name="bronze_wear_surfaces">
        <color rgba="0.74 0.54 0.28 1" />
        </material>
      </visual>
    <visual name="transfer_bearing_0_cap">
      <origin xyz="0.145 -0.25 0.395" rpy="0 0 0" />
      <geometry>
        <box size="0.122 0.06 0.034" />
        </geometry>
      <material name="shot_blasted_frame">
        <color rgba="0.33 0.35 0.35 1" />
        </material>
      </visual>
    <visual name="transfer_bearing_0_split_line">
      <origin xyz="0.145 -0.279 0.378" rpy="0 0 0" />
      <geometry>
        <box size="0.12 0.006 0.01" />
        </geometry>
      <material name="dark_split_lines">
        <color rgba="0.015 0.016 0.017 1" />
        </material>
      </visual>
    <visual name="transfer_bearing_0_bolt_0">
      <origin xyz="0.109 -0.25 0.419" rpy="0 0 0" />
      <geometry>
        <cylinder radius="0.006" length="0.014" />
        </geometry>
      <material name="black_oxide">
        <color rgba="0.055 0.06 0.062 1" />
        </material>
      </visual>
    <visual name="transfer_bearing_0_bolt_1">
      <origin xyz="0.181 -0.25 0.419" rpy="0 0 0" />
      <geometry>
        <cylinder radius="0.006" length="0.014" />
        </geometry>
      <material name="black_oxide">
        <color rgba="0.055 0.06 0.062 1" />
        </material>
      </visual>
    <visual name="transfer_pedestal_1">
      <origin xyz="0.145 0.035 0.169" rpy="0 0 0" />
      <geometry>
        <box size="0.105 0.06 0.258" />
        </geometry>
      <material name="shot_blasted_frame">
        <color rgba="0.33 0.35 0.35 1" />
        </material>
      </visual>
    <visual name="transfer_bearing_1_ring">
      <origin xyz="0.145 0.035 0.34" rpy="-1.5708 0 0" />
      <geometry>
        <mesh filename="assets/meshes/split_bearing_ring.obj" />
        </geometry>
      <material name="bronze_wear_surfaces">
        <color rgba="0.74 0.54 0.28 1" />
        </material>
      </visual>
    <visual name="transfer_bearing_1_cap">
      <origin xyz="0.145 0.035 0.395" rpy="0 0 0" />
      <geometry>
        <box size="0.122 0.06 0.034" />
        </geometry>
      <material name="shot_blasted_frame">
        <color rgba="0.33 0.35 0.35 1" />
        </material>
      </visual>
    <visual name="transfer_bearing_1_split_line">
      <origin xyz="0.145 0.006 0.378" rpy="0 0 0" />
      <geometry>
        <box size="0.12 0.006 0.01" />
        </geometry>
      <material name="dark_split_lines">
        <color rgba="0.015 0.016 0.017 1" />
        </material>
      </visual>
    <visual name="transfer_bearing_1_bolt_0">
      <origin xyz="0.109 0.035 0.419" rpy="0 0 0" />
      <geometry>
        <cylinder radius="0.006" length="0.014" />
        </geometry>
      <material name="black_oxide">
        <color rgba="0.055 0.06 0.062 1" />
        </material>
      </visual>
    <visual name="transfer_bearing_1_bolt_1">
      <origin xyz="0.181 0.035 0.419" rpy="0 0 0" />
      <geometry>
        <cylinder radius="0.006" length="0.014" />
        </geometry>
      <material name="black_oxide">
        <color rgba="0.055 0.06 0.062 1" />
        </material>
      </visual>
    <visual name="output_thrust_pedestal">
      <origin xyz="0.145 0.245 0.092" rpy="0 0 0" />
      <geometry>
        <box size="0.145 0.145 0.105" />
        </geometry>
      <material name="shot_blasted_frame">
        <color rgba="0.33 0.35 0.35 1" />
        </material>
      </visual>
    <visual name="output_lower_bearing_ring">
      <origin xyz="0.145 0.245 0.185" rpy="0 0 0" />
      <geometry>
        <mesh filename="assets/meshes/split_bearing_ring.obj" />
        </geometry>
      <material name="bronze_wear_surfaces">
        <color rgba="0.74 0.54 0.28 1" />
        </material>
      </visual>
    <visual name="output_bearing_sleeve">
      <origin xyz="0.145 0.245 0.238" rpy="0 0 0" />
      <geometry>
        <cylinder radius="0.028" length="0.115" />
        </geometry>
      <material name="bronze_wear_surfaces">
        <color rgba="0.74 0.54 0.28 1" />
        </material>
      </visual>
    <visual name="output_bearing_bridge">
      <origin xyz="0.145 0.245 0.238" rpy="0 0 0" />
      <geometry>
        <box size="0.165 0.165 0.03" />
        </geometry>
      <material name="shot_blasted_frame">
        <color rgba="0.33 0.35 0.35 1" />
        </material>
      </visual>
    <visual name="output_cap_near_lip">
      <origin xyz="0.145 0.181 0.238" rpy="0 0 0" />
      <geometry>
        <box size="0.165 0.032 0.028" />
        </geometry>
      <material name="shot_blasted_frame">
        <color rgba="0.33 0.35 0.35 1" />
        </material>
      </visual>
    <visual name="output_cap_far_lip">
      <origin xyz="0.145 0.309 0.238" rpy="0 0 0" />
      <geometry>
        <box size="0.165 0.032 0.028" />
        </geometry>
      <material name="shot_blasted_frame">
        <color rgba="0.33 0.35 0.35 1" />
        </material>
      </visual>
    <visual name="output_cap_side_0">
      <origin xyz="0.079 0.245 0.238" rpy="0 0 0" />
      <geometry>
        <box size="0.032 0.096 0.028" />
        </geometry>
      <material name="shot_blasted_frame">
        <color rgba="0.33 0.35 0.35 1" />
        </material>
      </visual>
    <visual name="output_cap_side_1">
      <origin xyz="0.211 0.245 0.238" rpy="0 0 0" />
      <geometry>
        <box size="0.032 0.096 0.028" />
        </geometry>
      <material name="shot_blasted_frame">
        <color rgba="0.33 0.35 0.35 1" />
        </material>
      </visual>
    <visual name="output_split_line">
      <origin xyz="0.145 0.165 0.238" rpy="0 0 0" />
      <geometry>
        <box size="0.145 0.006 0.01" />
        </geometry>
      <material name="dark_split_lines">
        <color rgba="0.015 0.016 0.017 1" />
        </material>
      </visual>
    <visual name="output_torque_web">
      <origin xyz="0.145 0.365 0.323" rpy="0 0 0" />
      <geometry>
        <box size="0.085 0.075 0.386" />
        </geometry>
      <material name="shot_blasted_frame">
        <color rgba="0.33 0.35 0.35 1" />
        </material>
      </visual>
    <visual name="torque_arm_clevis">
      <origin xyz="0.145 0.46 0.186" rpy="0 0 1.5708" />
      <geometry>
        <mesh filename="assets/meshes/torque_arm_clevis.obj" />
        </geometry>
      <material name="shot_blasted_frame">
        <color rgba="0.33 0.35 0.35 1" />
        </material>
      </visual>
    <visual name="output_cap_bolt_0_-0.05">
      <origin xyz="0.095 0.195 0.26" rpy="0 0 0" />
      <geometry>
        <cylinder radius="0.006" length="0.016" />
        </geometry>
      <material name="black_oxide">
        <color rgba="0.055 0.06 0.062 1" />
        </material>
      </visual>
    <visual name="output_cap_bolt_0_+0.05">
      <origin xyz="0.095 0.295 0.26" rpy="0 0 0" />
      <geometry>
        <cylinder radius="0.006" length="0.016" />
        </geometry>
      <material name="black_oxide">
        <color rgba="0.055 0.06 0.062 1" />
        </material>
      </visual>
    <visual name="output_cap_bolt_1_-0.05">
      <origin xyz="0.195 0.195 0.26" rpy="0 0 0" />
      <geometry>
        <cylinder radius="0.006" length="0.016" />
        </geometry>
      <material name="black_oxide">
        <color rgba="0.055 0.06 0.062 1" />
        </material>
      </visual>
    <visual name="output_cap_bolt_1_+0.05">
      <origin xyz="0.195 0.295 0.26" rpy="0 0 0" />
      <geometry>
        <cylinder radius="0.006" length="0.016" />
        </geometry>
      <material name="black_oxide">
        <color rgba="0.055 0.06 0.062 1" />
        </material>
      </visual>
    <collision name="ground_base">
      <origin xyz="-0.1 0 0.02" rpy="0 0 0" />
      <geometry>
        <box size="1.36 0.74 0.04" />
        </geometry>
      </collision>
    <collision name="near_lower_rail">
      <origin xyz="-0.1 -0.34 0.085" rpy="0 0 0" />
      <geometry>
        <box size="1.27 0.045 0.09" />
        </geometry>
      </collision>
    <collision name="far_lower_rail">
      <origin xyz="-0.1 0.34 0.085" rpy="0 0 0" />
      <geometry>
        <box size="1.27 0.045 0.09" />
        </geometry>
      </collision>
    <collision name="near_upper_rail">
      <origin xyz="-0.1 -0.34 0.535" rpy="0 0 0" />
      <geometry>
        <box size="1.27 0.03 0.05" />
        </geometry>
      </collision>
    <collision name="far_upper_rail">
      <origin xyz="-0.1 0.34 0.535" rpy="0 0 0" />
      <geometry>
        <box size="1.27 0.03 0.05" />
        </geometry>
      </collision>
    <collision name="near_post_0">
      <origin xyz="-0.62 -0.34 0.287" rpy="0 0 0" />
      <geometry>
        <box size="0.04 0.045 0.495" />
        </geometry>
      </collision>
    <collision name="far_post_0">
      <origin xyz="-0.62 0.34 0.287" rpy="0 0 0" />
      <geometry>
        <box size="0.04 0.045 0.495" />
        </geometry>
      </collision>
    <collision name="near_post_1">
      <origin xyz="-0.36 -0.34 0.287" rpy="0 0 0" />
      <geometry>
        <box size="0.04 0.045 0.495" />
        </geometry>
      </collision>
    <collision name="far_post_1">
      <origin xyz="-0.36 0.34 0.287" rpy="0 0 0" />
      <geometry>
        <box size="0.04 0.045 0.495" />
        </geometry>
      </collision>
    <collision name="near_post_2">
      <origin xyz="-0.1 -0.34 0.287" rpy="0 0 0" />
      <geometry>
        <box size="0.04 0.045 0.495" />
        </geometry>
      </collision>
    <collision name="far_post_2">
      <origin xyz="-0.1 0.34 0.287" rpy="0 0 0" />
      <geometry>
        <box size="0.04 0.045 0.495" />
        </geometry>
      </collision>
    <collision name="near_post_3">
      <origin xyz="0.13 -0.34 0.287" rpy="0 0 0" />
      <geometry>
        <box size="0.04 0.045 0.495" />
        </geometry>
      </collision>
    <collision name="far_post_3">
      <origin xyz="0.13 0.34 0.287" rpy="0 0 0" />
      <geometry>
        <box size="0.04 0.045 0.495" />
        </geometry>
      </collision>
    <collision name="near_post_4">
      <origin xyz="0.39 -0.34 0.287" rpy="0 0 0" />
      <geometry>
        <box size="0.04 0.045 0.495" />
        </geometry>
      </collision>
    <collision name="far_post_4">
      <origin xyz="0.39 0.34 0.287" rpy="0 0 0" />
      <geometry>
        <box size="0.04 0.045 0.495" />
        </geometry>
      </collision>
    <collision name="cross_tie_0">
      <origin xyz="-0.6 0 0.07" rpy="0 0 0" />
      <geometry>
        <box size="0.045 0.6 0.06" />
        </geometry>
      </collision>
    <collision name="cross_tie_1">
      <origin xyz="-0.22 0 0.07" rpy="0 0 0" />
      <geometry>
        <box size="0.045 0.6 0.06" />
        </geometry>
      </collision>
    <collision name="cross_tie_2">
      <origin xyz="0.17 0 0.07" rpy="0 0 0" />
      <geometry>
        <box size="0.045 0.6 0.06" />
        </geometry>
      </collision>
    <collision name="cross_tie_3">
      <origin xyz="0.44 0 0.07" rpy="0 0 0" />
      <geometry>
        <box size="0.045 0.6 0.06" />
        </geometry>
      </collision>
    <collision name="spur_cover_top_guide">
      <origin xyz="-0.28 -0.37 0.445" rpy="0 0 0" />
      <geometry>
        <box size="0.47 0.025 0.026" />
        </geometry>
      </collision>
    <collision name="spur_cover_bottom_guide">
      <origin xyz="-0.28 -0.37 0.23" rpy="0 0 0" />
      <geometry>
        <box size="0.47 0.025 0.026" />
        </geometry>
      </collision>
    <collision name="bevel_cover_top_guide">
      <origin xyz="0.17 -0.37 0.445" rpy="0 0 0" />
      <geometry>
        <box size="0.31 0.025 0.026" />
        </geometry>
      </collision>
    <collision name="bevel_cover_bottom_guide">
      <origin xyz="0.17 -0.37 0.23" rpy="0 0 0" />
      <geometry>
        <box size="0.31 0.025 0.026" />
        </geometry>
      </collision>
    <collision name="input_pedestal_0">
      <origin xyz="-0.42 -0.25 0.169" rpy="0 0 0" />
      <geometry>
        <box size="0.105 0.06 0.258" />
        </geometry>
      </collision>
    <collision name="input_bearing_0_ring">
      <origin xyz="-0.42 -0.25 0.34" rpy="-1.5708 0 0" />
      <geometry>
        <mesh filename="assets/meshes/split_bearing_ring.obj" />
        </geometry>
      </collision>
    <collision name="input_bearing_0_cap">
      <origin xyz="-0.42 -0.25 0.395" rpy="0 0 0" />
      <geometry>
        <box size="0.122 0.06 0.034" />
        </geometry>
      </collision>
    <collision name="input_bearing_0_split_line">
      <origin xyz="-0.42 -0.279 0.378" rpy="0 0 0" />
      <geometry>
        <box size="0.12 0.006 0.01" />
        </geometry>
      </collision>
    <collision name="input_bearing_0_bolt_0">
      <origin xyz="-0.456 -0.25 0.419" rpy="0 0 0" />
      <geometry>
        <cylinder radius="0.006" length="0.014" />
        </geometry>
      </collision>
    <collision name="input_bearing_0_bolt_1">
      <origin xyz="-0.384 -0.25 0.419" rpy="0 0 0" />
      <geometry>
        <cylinder radius="0.006" length="0.014" />
        </geometry>
      </collision>
    <collision name="input_pedestal_1">
      <origin xyz="-0.42 0.25 0.169" rpy="0 0 0" />
      <geometry>
        <box size="0.105 0.06 0.258" />
        </geometry>
      </collision>
    <collision name="input_bearing_1_ring">
      <origin xyz="-0.42 0.25 0.34" rpy="-1.5708 0 0" />
      <geometry>
        <mesh filename="assets/meshes/split_bearing_ring.obj" />
        </geometry>
      </collision>
    <collision name="input_bearing_1_cap">
      <origin xyz="-0.42 0.25 0.395" rpy="0 0 0" />
      <geometry>
        <box size="0.122 0.06 0.034" />
        </geometry>
      </collision>
    <collision name="input_bearing_1_split_line">
      <origin xyz="-0.42 0.221 0.378" rpy="0 0 0" />
      <geometry>
        <box size="0.12 0.006 0.01" />
        </geometry>
      </collision>
    <collision name="input_bearing_1_bolt_0">
      <origin xyz="-0.456 0.25 0.419" rpy="0 0 0" />
      <geometry>
        <cylinder radius="0.006" length="0.014" />
        </geometry>
      </collision>
    <collision name="input_bearing_1_bolt_1">
      <origin xyz="-0.384 0.25 0.419" rpy="0 0 0" />
      <geometry>
        <cylinder radius="0.006" length="0.014" />
        </geometry>
      </collision>
    <collision name="compound_pedestal_0">
      <origin xyz="-0.1 -0.25 0.169" rpy="0 0 0" />
      <geometry>
        <box size="0.105 0.06 0.258" />
        </geometry>
      </collision>
    <collision name="compound_bearing_0_ring">
      <origin xyz="-0.1 -0.25 0.34" rpy="-1.5708 0 0" />
      <geometry>
        <mesh filename="assets/meshes/split_bearing_ring.obj" />
        </geometry>
      </collision>
    <collision name="compound_bearing_0_cap">
      <origin xyz="-0.1 -0.25 0.395" rpy="0 0 0" />
      <geometry>
        <box size="0.122 0.06 0.034" />
        </geometry>
      </collision>
    <collision name="compound_bearing_0_split_line">
      <origin xyz="-0.1 -0.279 0.378" rpy="0 0 0" />
      <geometry>
        <box size="0.12 0.006 0.01" />
        </geometry>
      </collision>
    <collision name="compound_bearing_0_bolt_0">
      <origin xyz="-0.136 -0.25 0.419" rpy="0 0 0" />
      <geometry>
        <cylinder radius="0.006" length="0.014" />
        </geometry>
      </collision>
    <collision name="compound_bearing_0_bolt_1">
      <origin xyz="-0.064 -0.25 0.419" rpy="0 0 0" />
      <geometry>
        <cylinder radius="0.006" length="0.014" />
        </geometry>
      </collision>
    <collision name="compound_pedestal_1">
      <origin xyz="-0.1 0.25 0.169" rpy="0 0 0" />
      <geometry>
        <box size="0.105 0.06 0.258" />
        </geometry>
      </collision>
    <collision name="compound_bearing_1_ring">
      <origin xyz="-0.1 0.25 0.34" rpy="-1.5708 0 0" />
      <geometry>
        <mesh filename="assets/meshes/split_bearing_ring.obj" />
        </geometry>
      </collision>
    <collision name="compound_bearing_1_cap">
      <origin xyz="-0.1 0.25 0.395" rpy="0 0 0" />
      <geometry>
        <box size="0.122 0.06 0.034" />
        </geometry>
      </collision>
    <collision name="compound_bearing_1_split_line">
      <origin xyz="-0.1 0.221 0.378" rpy="0 0 0" />
      <geometry>
        <box size="0.12 0.006 0.01" />
        </geometry>
      </collision>
    <collision name="compound_bearing_1_bolt_0">
      <origin xyz="-0.136 0.25 0.419" rpy="0 0 0" />
      <geometry>
        <cylinder radius="0.006" length="0.014" />
        </geometry>
      </collision>
    <collision name="compound_bearing_1_bolt_1">
      <origin xyz="-0.064 0.25 0.419" rpy="0 0 0" />
      <geometry>
        <cylinder radius="0.006" length="0.014" />
        </geometry>
      </collision>
    <collision name="transfer_pedestal_0">
      <origin xyz="0.145 -0.25 0.169" rpy="0 0 0" />
      <geometry>
        <box size="0.105 0.06 0.258" />
        </geometry>
      </collision>
    <collision name="transfer_bearing_0_ring">
      <origin xyz="0.145 -0.25 0.34" rpy="-1.5708 0 0" />
      <geometry>
        <mesh filename="assets/meshes/split_bearing_ring.obj" />
        </geometry>
      </collision>
    <collision name="transfer_bearing_0_cap">
      <origin xyz="0.145 -0.25 0.395" rpy="0 0 0" />
      <geometry>
        <box size="0.122 0.06 0.034" />
        </geometry>
      </collision>
    <collision name="transfer_bearing_0_split_line">
      <origin xyz="0.145 -0.279 0.378" rpy="0 0 0" />
      <geometry>
        <box size="0.12 0.006 0.01" />
        </geometry>
      </collision>
    <collision name="transfer_bearing_0_bolt_0">
      <origin xyz="0.109 -0.25 0.419" rpy="0 0 0" />
      <geometry>
        <cylinder radius="0.006" length="0.014" />
        </geometry>
      </collision>
    <collision name="transfer_bearing_0_bolt_1">
      <origin xyz="0.181 -0.25 0.419" rpy="0 0 0" />
      <geometry>
        <cylinder radius="0.006" length="0.014" />
        </geometry>
      </collision>
    <collision name="transfer_pedestal_1">
      <origin xyz="0.145 0.035 0.169" rpy="0 0 0" />
      <geometry>
        <box size="0.105 0.06 0.258" />
        </geometry>
      </collision>
    <collision name="transfer_bearing_1_ring">
      <origin xyz="0.145 0.035 0.34" rpy="-1.5708 0 0" />
      <geometry>
        <mesh filename="assets/meshes/split_bearing_ring.obj" />
        </geometry>
      </collision>
    <collision name="transfer_bearing_1_cap">
      <origin xyz="0.145 0.035 0.395" rpy="0 0 0" />
      <geometry>
        <box size="0.122 0.06 0.034" />
        </geometry>
      </collision>
    <collision name="transfer_bearing_1_split_line">
      <origin xyz="0.145 0.006 0.378" rpy="0 0 0" />
      <geometry>
        <box size="0.12 0.006 0.01" />
        </geometry>
      </collision>
    <collision name="transfer_bearing_1_bolt_0">
      <origin xyz="0.109 0.035 0.419" rpy="0 0 0" />
      <geometry>
        <cylinder radius="0.006" length="0.014" />
        </geometry>
      </collision>
    <collision name="transfer_bearing_1_bolt_1">
      <origin xyz="0.181 0.035 0.419" rpy="0 0 0" />
      <geometry>
        <cylinder radius="0.006" length="0.014" />
        </geometry>
      </collision>
    <collision name="output_thrust_pedestal">
      <origin xyz="0.145 0.245 0.092" rpy="0 0 0" />
      <geometry>
        <box size="0.145 0.145 0.105" />
        </geometry>
      </collision>
    <collision name="output_lower_bearing_ring">
      <origin xyz="0.145 0.245 0.185" rpy="0 0 0" />
      <geometry>
        <mesh filename="assets/meshes/split_bearing_ring.obj" />
        </geometry>
      </collision>
    <collision name="output_bearing_sleeve">
      <origin xyz="0.145 0.245 0.238" rpy="0 0 0" />
      <geometry>
        <cylinder radius="0.028" length="0.115" />
        </geometry>
      </collision>
    <collision name="output_bearing_bridge">
      <origin xyz="0.145 0.245 0.238" rpy="0 0 0" />
      <geometry>
        <box size="0.165 0.165 0.03" />
        </geometry>
      </collision>
    <collision name="output_cap_near_lip">
      <origin xyz="0.145 0.181 0.238" rpy="0 0 0" />
      <geometry>
        <box size="0.165 0.032 0.028" />
        </geometry>
      </collision>
    <collision name="output_cap_far_lip">
      <origin xyz="0.145 0.309 0.238" rpy="0 0 0" />
      <geometry>
        <box size="0.165 0.032 0.028" />
        </geometry>
      </collision>
    <collision name="output_cap_side_0">
      <origin xyz="0.079 0.245 0.238" rpy="0 0 0" />
      <geometry>
        <box size="0.032 0.096 0.028" />
        </geometry>
      </collision>
    <collision name="output_cap_side_1">
      <origin xyz="0.211 0.245 0.238" rpy="0 0 0" />
      <geometry>
        <box size="0.032 0.096 0.028" />
        </geometry>
      </collision>
    <collision name="output_split_line">
      <origin xyz="0.145 0.165 0.238" rpy="0 0 0" />
      <geometry>
        <box size="0.145 0.006 0.01" />
        </geometry>
      </collision>
    <collision name="output_torque_web">
      <origin xyz="0.145 0.365 0.323" rpy="0 0 0" />
      <geometry>
        <box size="0.085 0.075 0.386" />
        </geometry>
      </collision>
    <collision name="torque_arm_clevis">
      <origin xyz="0.145 0.46 0.186" rpy="0 0 1.5708" />
      <geometry>
        <mesh filename="assets/meshes/torque_arm_clevis.obj" />
        </geometry>
      </collision>
    <collision name="output_cap_bolt_0_-0.05">
      <origin xyz="0.095 0.195 0.26" rpy="0 0 0" />
      <geometry>
        <cylinder radius="0.006" length="0.016" />
        </geometry>
      </collision>
    <collision name="output_cap_bolt_0_+0.05">
      <origin xyz="0.095 0.295 0.26" rpy="0 0 0" />
      <geometry>
        <cylinder radius="0.006" length="0.016" />
        </geometry>
      </collision>
    <collision name="output_cap_bolt_1_-0.05">
      <origin xyz="0.195 0.195 0.26" rpy="0 0 0" />
      <geometry>
        <cylinder radius="0.006" length="0.016" />
        </geometry>
      </collision>
    <collision name="output_cap_bolt_1_+0.05">
      <origin xyz="0.195 0.295 0.26" rpy="0 0 0" />
      <geometry>
        <cylinder radius="0.006" length="0.016" />
        </geometry>
      </collision>
    </link>
  <link name="input_shaft">
    <visual name="shaft">
      <origin xyz="0 0 0" rpy="-1.5708 0 0" />
      <geometry>
        <cylinder radius="0.018" length="0.59" />
        </geometry>
      <material name="ground_shaft_steel">
        <color rgba="0.7 0.72 0.7 1" />
        </material>
      </visual>
    <visual name="input_spur">
      <origin xyz="0 0 0" rpy="-1.5708 0 0" />
      <geometry>
        <mesh filename="assets/meshes/input_30t_spur.obj" />
        </geometry>
      <material name="oiled_machined_steel">
        <color rgba="0.48 0.47 0.42 1" />
        </material>
      </visual>
    <visual name="input_key">
      <origin xyz="0 0 0.033" rpy="0 0 0" />
      <geometry>
        <box size="0.014 0.088 0.01" />
        </geometry>
      <material name="black_oxide">
        <color rgba="0.055 0.06 0.062 1" />
        </material>
      </visual>
    <visual name="input_coupler_stub">
      <origin xyz="0 -0.325 0" rpy="-1.5708 0 0" />
      <geometry>
        <cylinder radius="0.024" length="0.06" />
        </geometry>
      <material name="ground_shaft_steel">
        <color rgba="0.7 0.72 0.7 1" />
        </material>
      </visual>
    <collision name="shaft">
      <origin xyz="0 0 0" rpy="-1.5708 0 0" />
      <geometry>
        <cylinder radius="0.018" length="0.59" />
        </geometry>
      </collision>
    <collision name="input_spur">
      <origin xyz="0 0 0" rpy="-1.5708 0 0" />
      <geometry>
        <mesh filename="assets/meshes/input_30t_spur.obj" />
        </geometry>
      </collision>
    <collision name="input_key">
      <origin xyz="0 0 0.033" rpy="0 0 0" />
      <geometry>
        <box size="0.014 0.088 0.01" />
        </geometry>
      </collision>
    <collision name="input_coupler_stub">
      <origin xyz="0 -0.325 0" rpy="-1.5708 0 0" />
      <geometry>
        <cylinder radius="0.024" length="0.06" />
        </geometry>
      </collision>
    </link>
  <link name="compound_shaft">
    <visual name="shaft">
      <origin xyz="0 0 0" rpy="-1.5708 0 0" />
      <geometry>
        <cylinder radius="0.018" length="0.59" />
        </geometry>
      <material name="ground_shaft_steel">
        <color rgba="0.7 0.72 0.7 1" />
        </material>
      </visual>
    <visual name="large_spur">
      <origin xyz="0 0 0" rpy="-1.5708 0 0.0747998" />
      <geometry>
        <mesh filename="assets/meshes/compound_42t_spur.obj" />
        </geometry>
      <material name="oiled_machined_steel">
        <color rgba="0.48 0.47 0.42 1" />
        </material>
      </visual>
    <visual name="pinion_spur">
      <origin xyz="0 -0.095 0" rpy="-1.5708 0 0" />
      <geometry>
        <mesh filename="assets/meshes/compound_18t_pinion.obj" />
        </geometry>
      <material name="oiled_machined_steel">
        <color rgba="0.48 0.47 0.42 1" />
        </material>
      </visual>
    <visual name="compound_key">
      <origin xyz="0 -0.045 0.033" rpy="0 0 0" />
      <geometry>
        <box size="0.014 0.175 0.01" />
        </geometry>
      <material name="black_oxide">
        <color rgba="0.055 0.06 0.062 1" />
        </material>
      </visual>
    <collision name="shaft">
      <origin xyz="0 0 0" rpy="-1.5708 0 0" />
      <geometry>
        <cylinder radius="0.018" length="0.59" />
        </geometry>
      </collision>
    <collision name="large_spur">
      <origin xyz="0 0 0" rpy="-1.5708 0 0.0747998" />
      <geometry>
        <mesh filename="assets/meshes/compound_42t_spur.obj" />
        </geometry>
      </collision>
    <collision name="pinion_spur">
      <origin xyz="0 -0.095 0" rpy="-1.5708 0 0" />
      <geometry>
        <mesh filename="assets/meshes/compound_18t_pinion.obj" />
        </geometry>
      </collision>
    <collision name="compound_key">
      <origin xyz="0 -0.045 0.033" rpy="0 0 0" />
      <geometry>
        <box size="0.014 0.175 0.01" />
        </geometry>
      </collision>
    </link>
  <link name="transfer_shaft">
    <visual name="shaft">
      <origin xyz="0 -0.09 0" rpy="-1.5708 0 0" />
      <geometry>
        <cylinder radius="0.018" length="0.43" />
        </geometry>
      <material name="ground_shaft_steel">
        <color rgba="0.7 0.72 0.7 1" />
        </material>
      </visual>
    <visual name="transfer_spur">
      <origin xyz="0 -0.095 0" rpy="-1.5708 0 0.0872665" />
      <geometry>
        <mesh filename="assets/meshes/transfer_36t_spur.obj" />
        </geometry>
      <material name="oiled_machined_steel">
        <color rgba="0.48 0.47 0.42 1" />
        </material>
      </visual>
    <visual name="bevel_pinion">
      <origin xyz="0 0.09 0" rpy="-1.5708 0 0" />
      <geometry>
        <mesh filename="assets/meshes/bevel_pinion_18t.obj" />
        </geometry>
      <material name="oiled_machined_steel">
        <color rgba="0.48 0.47 0.42 1" />
        </material>
      </visual>
    <visual name="transfer_key">
      <origin xyz="0 -0.01 0.033" rpy="0 0 0" />
      <geometry>
        <box size="0.014 0.182 0.01" />
        </geometry>
      <material name="black_oxide">
        <color rgba="0.055 0.06 0.062 1" />
        </material>
      </visual>
    <collision name="shaft">
      <origin xyz="0 -0.09 0" rpy="-1.5708 0 0" />
      <geometry>
        <cylinder radius="0.018" length="0.43" />
        </geometry>
      </collision>
    <collision name="transfer_spur">
      <origin xyz="0 -0.095 0" rpy="-1.5708 0 0.0872665" />
      <geometry>
        <mesh filename="assets/meshes/transfer_36t_spur.obj" />
        </geometry>
      </collision>
    <collision name="bevel_pinion">
      <origin xyz="0 0.09 0" rpy="-1.5708 0 0" />
      <geometry>
        <mesh filename="assets/meshes/bevel_pinion_18t.obj" />
        </geometry>
      </collision>
    <collision name="transfer_key">
      <origin xyz="0 -0.01 0.033" rpy="0 0 0" />
      <geometry>
        <box size="0.014 0.182 0.01" />
        </geometry>
      </collision>
    </link>
  <link name="output_shaft">
    <visual name="shaft">
      <origin xyz="0 0 0.13" rpy="0 0 0" />
      <geometry>
        <cylinder radius="0.0186" length="0.56" />
        </geometry>
      <material name="ground_shaft_steel">
        <color rgba="0.7 0.72 0.7 1" />
        </material>
      </visual>
    <visual name="bevel_gear">
      <geometry>
        <mesh filename="assets/meshes/bevel_output_28t.obj" />
        </geometry>
      <material name="oiled_machined_steel">
        <color rgba="0.48 0.47 0.42 1" />
        </material>
      </visual>
    <visual name="keyed_output_hub">
      <origin xyz="0 0 0.275" rpy="0 0 0" />
      <geometry>
        <cylinder radius="0.046" length="0.058" />
        </geometry>
      <material name="ground_shaft_steel">
        <color rgba="0.7 0.72 0.7 1" />
        </material>
      </visual>
    <visual name="output_key">
      <origin xyz="0.044 0 0.275" rpy="0 0 0" />
      <geometry>
        <box size="0.014 0.01 0.11" />
        </geometry>
      <material name="black_oxide">
        <color rgba="0.055 0.06 0.062 1" />
        </material>
      </visual>
    <visual name="output_flange">
      <origin xyz="0 0 0.392" rpy="0 0 0" />
      <geometry>
        <cylinder radius="0.072" length="0.016" />
        </geometry>
      <material name="ground_shaft_steel">
        <color rgba="0.7 0.72 0.7 1" />
        </material>
      </visual>
    <visual name="flange_bolt_0">
      <origin xyz="0.049 0 0.407" rpy="0 0 0" />
      <geometry>
        <cylinder radius="0.006" length="0.022" />
        </geometry>
      <material name="black_oxide">
        <color rgba="0.055 0.06 0.062 1" />
        </material>
      </visual>
    <visual name="flange_bolt_1">
      <origin xyz="3.00038e-18 0.049 0.407" rpy="0 0 0" />
      <geometry>
        <cylinder radius="0.006" length="0.022" />
        </geometry>
      <material name="black_oxide">
        <color rgba="0.055 0.06 0.062 1" />
        </material>
      </visual>
    <visual name="flange_bolt_2">
      <origin xyz="-0.049 6.00077e-18 0.407" rpy="0 0 0" />
      <geometry>
        <cylinder radius="0.006" length="0.022" />
        </geometry>
      <material name="black_oxide">
        <color rgba="0.055 0.06 0.062 1" />
        </material>
      </visual>
    <visual name="flange_bolt_3">
      <origin xyz="-9.00115e-18 -0.049 0.407" rpy="0 0 0" />
      <geometry>
        <cylinder radius="0.006" length="0.022" />
        </geometry>
      <material name="black_oxide">
        <color rgba="0.055 0.06 0.062 1" />
        </material>
      </visual>
    <collision name="shaft">
      <origin xyz="0 0 0.13" rpy="0 0 0" />
      <geometry>
        <cylinder radius="0.0186" length="0.56" />
        </geometry>
      </collision>
    <collision name="bevel_gear">
      <geometry>
        <mesh filename="assets/meshes/bevel_output_28t.obj" />
        </geometry>
      </collision>
    <collision name="keyed_output_hub">
      <origin xyz="0 0 0.275" rpy="0 0 0" />
      <geometry>
        <cylinder radius="0.046" length="0.058" />
        </geometry>
      </collision>
    <collision name="output_key">
      <origin xyz="0.044 0 0.275" rpy="0 0 0" />
      <geometry>
        <box size="0.014 0.01 0.11" />
        </geometry>
      </collision>
    <collision name="output_flange">
      <origin xyz="0 0 0.392" rpy="0 0 0" />
      <geometry>
        <cylinder radius="0.072" length="0.016" />
        </geometry>
      </collision>
    <collision name="flange_bolt_0">
      <origin xyz="0.049 0 0.407" rpy="0 0 0" />
      <geometry>
        <cylinder radius="0.006" length="0.022" />
        </geometry>
      </collision>
    <collision name="flange_bolt_1">
      <origin xyz="3.00038e-18 0.049 0.407" rpy="0 0 0" />
      <geometry>
        <cylinder radius="0.006" length="0.022" />
        </geometry>
      </collision>
    <collision name="flange_bolt_2">
      <origin xyz="-0.049 6.00077e-18 0.407" rpy="0 0 0" />
      <geometry>
        <cylinder radius="0.006" length="0.022" />
        </geometry>
      </collision>
    <collision name="flange_bolt_3">
      <origin xyz="-9.00115e-18 -0.049 0.407" rpy="0 0 0" />
      <geometry>
        <cylinder radius="0.006" length="0.022" />
        </geometry>
      </collision>
    </link>
  <link name="spur_cover">
    <visual name="cover_plate">
      <geometry>
        <box size="0.465 0.012 0.205" />
        </geometry>
      <material name="brushed_cover_plate">
        <color rgba="0.42 0.46 0.47 1" />
        </material>
      </visual>
    <visual name="upper_slide_tongue">
      <origin xyz="0 0.01 0.088" rpy="0 0 0" />
      <geometry>
        <box size="0.43 0.01 0.012" />
        </geometry>
      <material name="black_oxide">
        <color rgba="0.055 0.06 0.062 1" />
        </material>
      </visual>
    <visual name="lower_slide_tongue">
      <origin xyz="0 0.01 -0.088" rpy="0 0 0" />
      <geometry>
        <box size="0.43 0.01 0.012" />
        </geometry>
      <material name="black_oxide">
        <color rgba="0.055 0.06 0.062 1" />
        </material>
      </visual>
    <visual name="pull_handle">
      <origin xyz="0 -0.014 0" rpy="0 0 0" />
      <geometry>
        <box size="0.15 0.018 0.018" />
        </geometry>
      <material name="black_oxide">
        <color rgba="0.055 0.06 0.062 1" />
        </material>
      </visual>
    <visual name="cover_bolt_top_0">
      <origin xyz="-0.19 -0.006 0.075" rpy="-1.5708 0 0" />
      <geometry>
        <cylinder radius="0.005" length="0.014" />
        </geometry>
      <material name="black_oxide">
        <color rgba="0.055 0.06 0.062 1" />
        </material>
      </visual>
    <visual name="cover_bolt_bottom_0">
      <origin xyz="-0.19 -0.006 -0.075" rpy="-1.5708 0 0" />
      <geometry>
        <cylinder radius="0.005" length="0.014" />
        </geometry>
      <material name="black_oxide">
        <color rgba="0.055 0.06 0.062 1" />
        </material>
      </visual>
    <visual name="cover_bolt_top_1">
      <origin xyz="-0.095 -0.006 0.075" rpy="-1.5708 0 0" />
      <geometry>
        <cylinder radius="0.005" length="0.014" />
        </geometry>
      <material name="black_oxide">
        <color rgba="0.055 0.06 0.062 1" />
        </material>
      </visual>
    <visual name="cover_bolt_bottom_1">
      <origin xyz="-0.095 -0.006 -0.075" rpy="-1.5708 0 0" />
      <geometry>
        <cylinder radius="0.005" length="0.014" />
        </geometry>
      <material name="black_oxide">
        <color rgba="0.055 0.06 0.062 1" />
        </material>
      </visual>
    <visual name="cover_bolt_top_2">
      <origin xyz="0.095 -0.006 0.075" rpy="-1.5708 0 0" />
      <geometry>
        <cylinder radius="0.005" length="0.014" />
        </geometry>
      <material name="black_oxide">
        <color rgba="0.055 0.06 0.062 1" />
        </material>
      </visual>
    <visual name="cover_bolt_bottom_2">
      <origin xyz="0.095 -0.006 -0.075" rpy="-1.5708 0 0" />
      <geometry>
        <cylinder radius="0.005" length="0.014" />
        </geometry>
      <material name="black_oxide">
        <color rgba="0.055 0.06 0.062 1" />
        </material>
      </visual>
    <visual name="cover_bolt_top_3">
      <origin xyz="0.19 -0.006 0.075" rpy="-1.5708 0 0" />
      <geometry>
        <cylinder radius="0.005" length="0.014" />
        </geometry>
      <material name="black_oxide">
        <color rgba="0.055 0.06 0.062 1" />
        </material>
      </visual>
    <visual name="cover_bolt_bottom_3">
      <origin xyz="0.19 -0.006 -0.075" rpy="-1.5708 0 0" />
      <geometry>
        <cylinder radius="0.005" length="0.014" />
        </geometry>
      <material name="black_oxide">
        <color rgba="0.055 0.06 0.062 1" />
        </material>
      </visual>
    <collision name="cover_plate">
      <geometry>
        <box size="0.465 0.012 0.205" />
        </geometry>
      </collision>
    <collision name="upper_slide_tongue">
      <origin xyz="0 0.01 0.088" rpy="0 0 0" />
      <geometry>
        <box size="0.43 0.01 0.012" />
        </geometry>
      </collision>
    <collision name="lower_slide_tongue">
      <origin xyz="0 0.01 -0.088" rpy="0 0 0" />
      <geometry>
        <box size="0.43 0.01 0.012" />
        </geometry>
      </collision>
    <collision name="pull_handle">
      <origin xyz="0 -0.014 0" rpy="0 0 0" />
      <geometry>
        <box size="0.15 0.018 0.018" />
        </geometry>
      </collision>
    <collision name="cover_bolt_top_0">
      <origin xyz="-0.19 -0.006 0.075" rpy="-1.5708 0 0" />
      <geometry>
        <cylinder radius="0.005" length="0.014" />
        </geometry>
      </collision>
    <collision name="cover_bolt_bottom_0">
      <origin xyz="-0.19 -0.006 -0.075" rpy="-1.5708 0 0" />
      <geometry>
        <cylinder radius="0.005" length="0.014" />
        </geometry>
      </collision>
    <collision name="cover_bolt_top_1">
      <origin xyz="-0.095 -0.006 0.075" rpy="-1.5708 0 0" />
      <geometry>
        <cylinder radius="0.005" length="0.014" />
        </geometry>
      </collision>
    <collision name="cover_bolt_bottom_1">
      <origin xyz="-0.095 -0.006 -0.075" rpy="-1.5708 0 0" />
      <geometry>
        <cylinder radius="0.005" length="0.014" />
        </geometry>
      </collision>
    <collision name="cover_bolt_top_2">
      <origin xyz="0.095 -0.006 0.075" rpy="-1.5708 0 0" />
      <geometry>
        <cylinder radius="0.005" length="0.014" />
        </geometry>
      </collision>
    <collision name="cover_bolt_bottom_2">
      <origin xyz="0.095 -0.006 -0.075" rpy="-1.5708 0 0" />
      <geometry>
        <cylinder radius="0.005" length="0.014" />
        </geometry>
      </collision>
    <collision name="cover_bolt_top_3">
      <origin xyz="0.19 -0.006 0.075" rpy="-1.5708 0 0" />
      <geometry>
        <cylinder radius="0.005" length="0.014" />
        </geometry>
      </collision>
    <collision name="cover_bolt_bottom_3">
      <origin xyz="0.19 -0.006 -0.075" rpy="-1.5708 0 0" />
      <geometry>
        <cylinder radius="0.005" length="0.014" />
        </geometry>
      </collision>
    </link>
  <link name="bevel_cover">
    <visual name="cover_plate">
      <geometry>
        <box size="0.305 0.012 0.205" />
        </geometry>
      <material name="brushed_cover_plate">
        <color rgba="0.42 0.46 0.47 1" />
        </material>
      </visual>
    <visual name="upper_slide_tongue">
      <origin xyz="0 0.01 0.088" rpy="0 0 0" />
      <geometry>
        <box size="0.27 0.01 0.012" />
        </geometry>
      <material name="black_oxide">
        <color rgba="0.055 0.06 0.062 1" />
        </material>
      </visual>
    <visual name="lower_slide_tongue">
      <origin xyz="0 0.01 -0.088" rpy="0 0 0" />
      <geometry>
        <box size="0.27 0.01 0.012" />
        </geometry>
      <material name="black_oxide">
        <color rgba="0.055 0.06 0.062 1" />
        </material>
      </visual>
    <visual name="pull_handle">
      <origin xyz="0 -0.014 0" rpy="0 0 0" />
      <geometry>
        <box size="0.105 0.018 0.018" />
        </geometry>
      <material name="black_oxide">
        <color rgba="0.055 0.06 0.062 1" />
        </material>
      </visual>
    <visual name="cover_bolt_top_0">
      <origin xyz="-0.115 -0.006 0.075" rpy="-1.5708 0 0" />
      <geometry>
        <cylinder radius="0.005" length="0.014" />
        </geometry>
      <material name="black_oxide">
        <color rgba="0.055 0.06 0.062 1" />
        </material>
      </visual>
    <visual name="cover_bolt_bottom_0">
      <origin xyz="-0.115 -0.006 -0.075" rpy="-1.5708 0 0" />
      <geometry>
        <cylinder radius="0.005" length="0.014" />
        </geometry>
      <material name="black_oxide">
        <color rgba="0.055 0.06 0.062 1" />
        </material>
      </visual>
    <visual name="cover_bolt_top_1">
      <origin xyz="0 -0.006 0.075" rpy="-1.5708 0 0" />
      <geometry>
        <cylinder radius="0.005" length="0.014" />
        </geometry>
      <material name="black_oxide">
        <color rgba="0.055 0.06 0.062 1" />
        </material>
      </visual>
    <visual name="cover_bolt_bottom_1">
      <origin xyz="0 -0.006 -0.075" rpy="-1.5708 0 0" />
      <geometry>
        <cylinder radius="0.005" length="0.014" />
        </geometry>
      <material name="black_oxide">
        <color rgba="0.055 0.06 0.062 1" />
        </material>
      </visual>
    <visual name="cover_bolt_top_2">
      <origin xyz="0.115 -0.006 0.075" rpy="-1.5708 0 0" />
      <geometry>
        <cylinder radius="0.005" length="0.014" />
        </geometry>
      <material name="black_oxide">
        <color rgba="0.055 0.06 0.062 1" />
        </material>
      </visual>
    <visual name="cover_bolt_bottom_2">
      <origin xyz="0.115 -0.006 -0.075" rpy="-1.5708 0 0" />
      <geometry>
        <cylinder radius="0.005" length="0.014" />
        </geometry>
      <material name="black_oxide">
        <color rgba="0.055 0.06 0.062 1" />
        </material>
      </visual>
    <collision name="cover_plate">
      <geometry>
        <box size="0.305 0.012 0.205" />
        </geometry>
      </collision>
    <collision name="upper_slide_tongue">
      <origin xyz="0 0.01 0.088" rpy="0 0 0" />
      <geometry>
        <box size="0.27 0.01 0.012" />
        </geometry>
      </collision>
    <collision name="lower_slide_tongue">
      <origin xyz="0 0.01 -0.088" rpy="0 0 0" />
      <geometry>
        <box size="0.27 0.01 0.012" />
        </geometry>
      </collision>
    <collision name="pull_handle">
      <origin xyz="0 -0.014 0" rpy="0 0 0" />
      <geometry>
        <box size="0.105 0.018 0.018" />
        </geometry>
      </collision>
    <collision name="cover_bolt_top_0">
      <origin xyz="-0.115 -0.006 0.075" rpy="-1.5708 0 0" />
      <geometry>
        <cylinder radius="0.005" length="0.014" />
        </geometry>
      </collision>
    <collision name="cover_bolt_bottom_0">
      <origin xyz="-0.115 -0.006 -0.075" rpy="-1.5708 0 0" />
      <geometry>
        <cylinder radius="0.005" length="0.014" />
        </geometry>
      </collision>
    <collision name="cover_bolt_top_1">
      <origin xyz="0 -0.006 0.075" rpy="-1.5708 0 0" />
      <geometry>
        <cylinder radius="0.005" length="0.014" />
        </geometry>
      </collision>
    <collision name="cover_bolt_bottom_1">
      <origin xyz="0 -0.006 -0.075" rpy="-1.5708 0 0" />
      <geometry>
        <cylinder radius="0.005" length="0.014" />
        </geometry>
      </collision>
    <collision name="cover_bolt_top_2">
      <origin xyz="0.115 -0.006 0.075" rpy="-1.5708 0 0" />
      <geometry>
        <cylinder radius="0.005" length="0.014" />
        </geometry>
      </collision>
    <collision name="cover_bolt_bottom_2">
      <origin xyz="0.115 -0.006 -0.075" rpy="-1.5708 0 0" />
      <geometry>
        <cylinder radius="0.005" length="0.014" />
        </geometry>
      </collision>
    </link>
  <joint name="frame_to_input_shaft" type="continuous">
    <origin xyz="-0.42 0 0.34" rpy="0 0 0" />
    <parent link="frame" />
    <child link="input_shaft" />
    <axis xyz="0 1 0" />
    <limit effort="55" velocity="18" />
    </joint>
  <joint name="frame_to_compound_shaft" type="continuous">
    <origin xyz="-0.1 0 0.34" rpy="0 0 0" />
    <parent link="frame" />
    <child link="compound_shaft" />
    <axis xyz="0 1 0" />
    <limit effort="90" velocity="12" />
    <mimic joint="frame_to_input_shaft" multiplier="-0.714286" />
    </joint>
  <joint name="frame_to_transfer_shaft" type="continuous">
    <origin xyz="0.145 0 0.34" rpy="0 0 0" />
    <parent link="frame" />
    <child link="transfer_shaft" />
    <axis xyz="0 1 0" />
    <limit effort="120" velocity="9" />
    <mimic joint="frame_to_compound_shaft" multiplier="-0.5" />
    </joint>
  <joint name="frame_to_output_shaft" type="continuous">
    <origin xyz="0.145 0.245 0.34" rpy="0 0 0" />
    <parent link="frame" />
    <child link="output_shaft" />
    <axis xyz="0 0 1" />
    <limit effort="150" velocity="7" />
    <mimic joint="frame_to_transfer_shaft" multiplier="-0.642857" />
    </joint>
  <joint name="frame_to_spur_cover" type="prismatic">
    <origin xyz="-0.28 -0.388 0.338" rpy="0 0 0" />
    <parent link="frame" />
    <child link="spur_cover" />
    <axis xyz="0 -1 0" />
    <limit effort="35" velocity="0.15" lower="0" upper="0.09" />
    </joint>
  <joint name="frame_to_bevel_cover" type="prismatic">
    <origin xyz="0.17 -0.388 0.338" rpy="0 0 0" />
    <parent link="frame" />
    <child link="bevel_cover" />
    <axis xyz="0 -1 0" />
    <limit effort="30" velocity="0.15" lower="0" upper="0.08" />
    </joint>
  </robot>
