<robot name="vertical_mast_side_arm">
  <material name="anodized_dark_mast">
    <color rgba="0.18 0.2 0.22 1" />
    </material>
  <material name="black_guide_rails">
    <color rgba="0.035 0.035 0.04 1" />
    </material>
  <material name="satin_carriage">
    <color rgba="0.72 0.74 0.73 1" />
    </material>
  <material name="blue_upper_link">
    <color rgba="0.08 0.22 0.55 1" />
    </material>
  <material name="orange_forearm_link">
    <color rgba="0.88 0.36 0.08 1" />
    </material>
  <material name="dark_pivot_pins">
    <color rgba="0.02 0.02 0.025 1" />
    </material>
  <link name="mast">
    <visual name="floor_plate">
      <origin xyz="0 0 0.0175" rpy="0 0 0" />
      <geometry>
        <box size="0.3 0.24 0.035" />
        </geometry>
      <material name="anodized_dark_mast">
        <color rgba="0.18 0.2 0.22 1" />
        </material>
      </visual>
    <visual name="upright_box">
      <origin xyz="0 0 0.585" rpy="0 0 0" />
      <geometry>
        <box size="0.06 0.06 1.1" />
        </geometry>
      <material name="anodized_dark_mast">
        <color rgba="0.18 0.2 0.22 1" />
        </material>
      </visual>
    <visual name="front_rail">
      <origin xyz="0 -0.036 0.585" rpy="0 0 0" />
      <geometry>
        <box size="0.086 0.012 1.02" />
        </geometry>
      <material name="black_guide_rails">
        <color rgba="0.035 0.035 0.04 1" />
        </material>
      </visual>
    <visual name="rear_rail">
      <origin xyz="0 0.036 0.585" rpy="0 0 0" />
      <geometry>
        <box size="0.086 0.012 1.02" />
        </geometry>
      <material name="black_guide_rails">
        <color rgba="0.035 0.035 0.04 1" />
        </material>
      </visual>
    <visual name="top_stop">
      <origin xyz="0 0 1.155" rpy="0 0 0" />
      <geometry>
        <box size="0.092 0.092 0.04" />
        </geometry>
      <material name="anodized_dark_mast">
        <color rgba="0.18 0.2 0.22 1" />
        </material>
      </visual>
    <visual name="lower_stop">
      <origin xyz="0 0 0.145" rpy="0 0 0" />
      <geometry>
        <box size="0.116 0.116 0.05" />
        </geometry>
      <material name="anodized_dark_mast">
        <color rgba="0.18 0.2 0.22 1" />
        </material>
      </visual>
    <collision name="floor_plate">
      <origin xyz="0 0 0.0175" rpy="0 0 0" />
      <geometry>
        <box size="0.3 0.24 0.035" />
        </geometry>
      </collision>
    <collision name="upright_box">
      <origin xyz="0 0 0.585" rpy="0 0 0" />
      <geometry>
        <box size="0.06 0.06 1.1" />
        </geometry>
      </collision>
    <collision name="front_rail">
      <origin xyz="0 -0.036 0.585" rpy="0 0 0" />
      <geometry>
        <box size="0.086 0.012 1.02" />
        </geometry>
      </collision>
    <collision name="rear_rail">
      <origin xyz="0 0.036 0.585" rpy="0 0 0" />
      <geometry>
        <box size="0.086 0.012 1.02" />
        </geometry>
      </collision>
    <collision name="top_stop">
      <origin xyz="0 0 1.155" rpy="0 0 0" />
      <geometry>
        <box size="0.092 0.092 0.04" />
        </geometry>
      </collision>
    <collision name="lower_stop">
      <origin xyz="0 0 0.145" rpy="0 0 0" />
      <geometry>
        <box size="0.116 0.116 0.05" />
        </geometry>
      </collision>
    </link>
  <link name="carriage">
    <visual name="rear_sleeve_plate">
      <origin xyz="0 0.054 0" rpy="0 0 0" />
      <geometry>
        <box size="0.14 0.024 0.12" />
        </geometry>
      <material name="satin_carriage">
        <color rgba="0.72 0.74 0.73 1" />
        </material>
      </visual>
    <visual name="front_sleeve_plate">
      <origin xyz="0 -0.054 0" rpy="0 0 0" />
      <geometry>
        <box size="0.14 0.024 0.12" />
        </geometry>
      <material name="satin_carriage">
        <color rgba="0.72 0.74 0.73 1" />
        </material>
      </visual>
    <visual name="side_sleeve_plate">
      <origin xyz="0.058 0 0" rpy="0 0 0" />
      <geometry>
        <box size="0.024 0.13 0.12" />
        </geometry>
      <material name="satin_carriage">
        <color rgba="0.72 0.74 0.73 1" />
        </material>
      </visual>
    <visual name="opposite_sleeve_plate">
      <origin xyz="-0.058 0 0" rpy="0 0 0" />
      <geometry>
        <box size="0.024 0.13 0.12" />
        </geometry>
      <material name="satin_carriage">
        <color rgba="0.72 0.74 0.73 1" />
        </material>
      </visual>
    <visual name="root_boss">
      <origin xyz="0.095 0 0" rpy="0 0 0" />
      <geometry>
        <box size="0.06 0.11 0.07" />
        </geometry>
      <material name="satin_carriage">
        <color rgba="0.72 0.74 0.73 1" />
        </material>
      </visual>
    <visual name="root_fork_plate_0">
      <origin xyz="0.165 0.051 0" rpy="0 0 0" />
      <geometry>
        <box size="0.09 0.018 0.12" />
        </geometry>
      <material name="satin_carriage">
        <color rgba="0.72 0.74 0.73 1" />
        </material>
      </visual>
    <visual name="root_fork_plate_1">
      <origin xyz="0.165 -0.051 0" rpy="0 0 0" />
      <geometry>
        <box size="0.09 0.018 0.12" />
        </geometry>
      <material name="satin_carriage">
        <color rgba="0.72 0.74 0.73 1" />
        </material>
      </visual>
    <visual name="root_pin_cap_0">
      <origin xyz="0.17 0.064 0" rpy="1.5708 0 0" />
      <geometry>
        <cylinder radius="0.034" length="0.008" />
        </geometry>
      <material name="dark_pivot_pins">
        <color rgba="0.02 0.02 0.025 1" />
        </material>
      </visual>
    <visual name="root_pin_cap_1">
      <origin xyz="0.17 -0.064 0" rpy="1.5708 0 0" />
      <geometry>
        <cylinder radius="0.034" length="0.008" />
        </geometry>
      <material name="dark_pivot_pins">
        <color rgba="0.02 0.02 0.025 1" />
        </material>
      </visual>
    <collision name="rear_sleeve_plate">
      <origin xyz="0 0.054 0" rpy="0 0 0" />
      <geometry>
        <box size="0.14 0.024 0.12" />
        </geometry>
      </collision>
    <collision name="front_sleeve_plate">
      <origin xyz="0 -0.054 0" rpy="0 0 0" />
      <geometry>
        <box size="0.14 0.024 0.12" />
        </geometry>
      </collision>
    <collision name="side_sleeve_plate">
      <origin xyz="0.058 0 0" rpy="0 0 0" />
      <geometry>
        <box size="0.024 0.13 0.12" />
        </geometry>
      </collision>
    <collision name="opposite_sleeve_plate">
      <origin xyz="-0.058 0 0" rpy="0 0 0" />
      <geometry>
        <box size="0.024 0.13 0.12" />
        </geometry>
      </collision>
    <collision name="root_boss">
      <origin xyz="0.095 0 0" rpy="0 0 0" />
      <geometry>
        <box size="0.06 0.11 0.07" />
        </geometry>
      </collision>
    <collision name="root_fork_plate_0">
      <origin xyz="0.165 0.051 0" rpy="0 0 0" />
      <geometry>
        <box size="0.09 0.018 0.12" />
        </geometry>
      </collision>
    <collision name="root_fork_plate_1">
      <origin xyz="0.165 -0.051 0" rpy="0 0 0" />
      <geometry>
        <box size="0.09 0.018 0.12" />
        </geometry>
      </collision>
    <collision name="root_pin_cap_0">
      <origin xyz="0.17 0.064 0" rpy="1.5708 0 0" />
      <geometry>
        <cylinder radius="0.034" length="0.008" />
        </geometry>
      </collision>
    <collision name="root_pin_cap_1">
      <origin xyz="0.17 -0.064 0" rpy="1.5708 0 0" />
      <geometry>
        <cylinder radius="0.034" length="0.008" />
        </geometry>
      </collision>
    </link>
  <link name="upper_link">
    <visual name="shoulder_barrel">
      <origin xyz="0 0 0" rpy="1.5708 0 0" />
      <geometry>
        <cylinder radius="0.034" length="0.112" />
        </geometry>
      <material name="dark_pivot_pins">
        <color rgba="0.02 0.02 0.025 1" />
        </material>
      </visual>
    <visual name="upper_beam">
      <origin xyz="0.17 0 0" rpy="0 0 0" />
      <geometry>
        <box size="0.31 0.036 0.034" />
        </geometry>
      <material name="blue_upper_link">
        <color rgba="0.08 0.22 0.55 1" />
        </material>
      </visual>
    <visual name="elbow_bridge">
      <origin xyz="0.315 0 0" rpy="0 0 0" />
      <geometry>
        <box size="0.07 0.095 0.035" />
        </geometry>
      <material name="blue_upper_link">
        <color rgba="0.08 0.22 0.55 1" />
        </material>
      </visual>
    <visual name="elbow_fork_plate_0">
      <origin xyz="0.38 0.048 0" rpy="0 0 0" />
      <geometry>
        <box size="0.1 0.018 0.105" />
        </geometry>
      <material name="blue_upper_link">
        <color rgba="0.08 0.22 0.55 1" />
        </material>
      </visual>
    <visual name="elbow_fork_plate_1">
      <origin xyz="0.38 -0.048 0" rpy="0 0 0" />
      <geometry>
        <box size="0.1 0.018 0.105" />
        </geometry>
      <material name="blue_upper_link">
        <color rgba="0.08 0.22 0.55 1" />
        </material>
      </visual>
    <visual name="elbow_pin_cap_0">
      <origin xyz="0.38 0.061 0" rpy="1.5708 0 0" />
      <geometry>
        <cylinder radius="0.03" length="0.008" />
        </geometry>
      <material name="dark_pivot_pins">
        <color rgba="0.02 0.02 0.025 1" />
        </material>
      </visual>
    <visual name="elbow_pin_cap_1">
      <origin xyz="0.38 -0.061 0" rpy="1.5708 0 0" />
      <geometry>
        <cylinder radius="0.03" length="0.008" />
        </geometry>
      <material name="dark_pivot_pins">
        <color rgba="0.02 0.02 0.025 1" />
        </material>
      </visual>
    <collision name="shoulder_barrel">
      <origin xyz="0 0 0" rpy="1.5708 0 0" />
      <geometry>
        <cylinder radius="0.034" length="0.112" />
        </geometry>
      </collision>
    <collision name="upper_beam">
      <origin xyz="0.17 0 0" rpy="0 0 0" />
      <geometry>
        <box size="0.31 0.036 0.034" />
        </geometry>
      </collision>
    <collision name="elbow_bridge">
      <origin xyz="0.315 0 0" rpy="0 0 0" />
      <geometry>
        <box size="0.07 0.095 0.035" />
        </geometry>
      </collision>
    <collision name="elbow_fork_plate_0">
      <origin xyz="0.38 0.048 0" rpy="0 0 0" />
      <geometry>
        <box size="0.1 0.018 0.105" />
        </geometry>
      </collision>
    <collision name="elbow_fork_plate_1">
      <origin xyz="0.38 -0.048 0" rpy="0 0 0" />
      <geometry>
        <box size="0.1 0.018 0.105" />
        </geometry>
      </collision>
    <collision name="elbow_pin_cap_0">
      <origin xyz="0.38 0.061 0" rpy="1.5708 0 0" />
      <geometry>
        <cylinder radius="0.03" length="0.008" />
        </geometry>
      </collision>
    <collision name="elbow_pin_cap_1">
      <origin xyz="0.38 -0.061 0" rpy="1.5708 0 0" />
      <geometry>
        <cylinder radius="0.03" length="0.008" />
        </geometry>
      </collision>
    </link>
  <link name="forearm_link">
    <visual name="elbow_barrel">
      <origin xyz="0 0 0" rpy="1.5708 0 0" />
      <geometry>
        <cylinder radius="0.028" length="0.104" />
        </geometry>
      <material name="dark_pivot_pins">
        <color rgba="0.02 0.02 0.025 1" />
        </material>
      </visual>
    <visual name="forearm_beam">
      <origin xyz="0.155 0 0" rpy="0 0 0" />
      <geometry>
        <box size="0.27 0.034 0.03" />
        </geometry>
      <material name="orange_forearm_link">
        <color rgba="0.88 0.36 0.08 1" />
        </material>
      </visual>
    <visual name="wrist_block">
      <origin xyz="0.3 0 0" rpy="0 0 0" />
      <geometry>
        <box size="0.06 0.052 0.042" />
        </geometry>
      <material name="orange_forearm_link">
        <color rgba="0.88 0.36 0.08 1" />
        </material>
      </visual>
    <visual name="tool_socket">
      <origin xyz="0.335 0 0" rpy="0 1.5708 0" />
      <geometry>
        <cylinder radius="0.026" length="0.045" />
        </geometry>
      <material name="dark_pivot_pins">
        <color rgba="0.02 0.02 0.025 1" />
        </material>
      </visual>
    <collision name="elbow_barrel">
      <origin xyz="0 0 0" rpy="1.5708 0 0" />
      <geometry>
        <cylinder radius="0.028" length="0.104" />
        </geometry>
      </collision>
    <collision name="forearm_beam">
      <origin xyz="0.155 0 0" rpy="0 0 0" />
      <geometry>
        <box size="0.27 0.034 0.03" />
        </geometry>
      </collision>
    <collision name="wrist_block">
      <origin xyz="0.3 0 0" rpy="0 0 0" />
      <geometry>
        <box size="0.06 0.052 0.042" />
        </geometry>
      </collision>
    <collision name="tool_socket">
      <origin xyz="0.335 0 0" rpy="0 1.5708 0" />
      <geometry>
        <cylinder radius="0.026" length="0.045" />
        </geometry>
      </collision>
    </link>
  <joint name="mast_to_carriage" type="prismatic">
    <origin xyz="0 0 0.32" rpy="0 0 0" />
    <parent link="mast" />
    <child link="carriage" />
    <axis xyz="0 0 1" />
    <limit effort="160" velocity="0.35" lower="0" upper="0.62" />
    </joint>
  <joint name="carriage_to_upper" type="revolute">
    <origin xyz="0.17 0 0" rpy="0 0 0" />
    <parent link="carriage" />
    <child link="upper_link" />
    <axis xyz="0 -1 0" />
    <limit effort="45" velocity="1.8" lower="-0.75" upper="1.25" />
    </joint>
  <joint name="upper_to_forearm" type="revolute">
    <origin xyz="0.38 0 0" rpy="0 0 0" />
    <parent link="upper_link" />
    <child link="forearm_link" />
    <axis xyz="0 -1 0" />
    <limit effort="28" velocity="2.2" lower="-1.55" upper="1.4" />
    </joint>
  </robot>
