<robot name="stunt_kick_scooter">
  <material name="brushed_aluminum">
    <color rgba="0.72 0.74 0.72 1" />
    </material>
  <material name="anodized_blue">
    <color rgba="0.03 0.18 0.75 1" />
    </material>
  <material name="matte_black">
    <color rgba="0.01 0.01 0.012 1" />
    </material>
  <material name="dark_rubber">
    <color rgba="0.006 0.006 0.005 1" />
    </material>
  <material name="textured_grip">
    <color rgba="0.025 0.025 0.022 1" />
    </material>
  <material name="dark_hardware">
    <color rgba="0.08 0.08 0.085 1" />
    </material>
  <link name="deck">
    <visual name="deck_shell">
      <origin xyz="0 0 0.13" rpy="0 0 0" />
      <geometry>
        <box size="0.52 0.11 0.035" />
        </geometry>
      <material name="anodized_blue">
        <color rgba="0.03 0.18 0.75 1" />
        </material>
      </visual>
    <visual name="front_round_end">
      <origin xyz="0.26 0 0.13" rpy="0 0 0" />
      <geometry>
        <cylinder radius="0.055" length="0.035" />
        </geometry>
      <material name="anodized_blue">
        <color rgba="0.03 0.18 0.75 1" />
        </material>
      </visual>
    <visual name="rear_round_end">
      <origin xyz="-0.26 0 0.13" rpy="0 0 0" />
      <geometry>
        <cylinder radius="0.055" length="0.035" />
        </geometry>
      <material name="anodized_blue">
        <color rgba="0.03 0.18 0.75 1" />
        </material>
      </visual>
    <visual name="grip_tape">
      <origin xyz="-0.01 0 0.1495" rpy="0 0 0" />
      <geometry>
        <box size="0.445 0.078 0.004" />
        </geometry>
      <material name="textured_grip">
        <color rgba="0.025 0.025 0.022 1" />
        </material>
      </visual>
    <visual name="front_side_boss_0">
      <origin xyz="0.305 0.054 0.145" rpy="0 0 0" />
      <geometry>
        <box size="0.09 0.01 0.02" />
        </geometry>
      <material name="anodized_blue">
        <color rgba="0.03 0.18 0.75 1" />
        </material>
      </visual>
    <visual name="front_side_boss_1">
      <origin xyz="0.305 -0.054 0.145" rpy="0 0 0" />
      <geometry>
        <box size="0.09 0.01 0.02" />
        </geometry>
      <material name="anodized_blue">
        <color rgba="0.03 0.18 0.75 1" />
        </material>
      </visual>
    <visual name="steering_bearing_cheek_0">
      <origin xyz="0.34 0.02 0.184" rpy="0 0 0" />
      <geometry>
        <box size="0.07 0.01 0.075" />
        </geometry>
      <material name="brushed_aluminum">
        <color rgba="0.72 0.74 0.72 1" />
        </material>
      </visual>
    <visual name="steering_bearing_cheek_1">
      <origin xyz="0.34 -0.02 0.184" rpy="0 0 0" />
      <geometry>
        <box size="0.07 0.01 0.075" />
        </geometry>
      <material name="brushed_aluminum">
        <color rgba="0.72 0.74 0.72 1" />
        </material>
      </visual>
    <visual name="rear_dropout_0">
      <origin xyz="-0.31 0.036 0.086" rpy="0 0 0" />
      <geometry>
        <box size="0.072 0.012 0.07" />
        </geometry>
      <material name="brushed_aluminum">
        <color rgba="0.72 0.74 0.72 1" />
        </material>
      </visual>
    <visual name="rear_dropout_1">
      <origin xyz="-0.31 -0.036 0.086" rpy="0 0 0" />
      <geometry>
        <box size="0.072 0.012 0.07" />
        </geometry>
      <material name="brushed_aluminum">
        <color rgba="0.72 0.74 0.72 1" />
        </material>
      </visual>
    <visual name="rear_bridge">
      <origin xyz="-0.292 0 0.116" rpy="0 0 0" />
      <geometry>
        <box size="0.05 0.07 0.01" />
        </geometry>
      <material name="brushed_aluminum">
        <color rgba="0.72 0.74 0.72 1" />
        </material>
      </visual>
    <visual name="kickstand_hinge_bridge">
      <origin xyz="0.055 -0.065 0.109" rpy="0 0 0" />
      <geometry>
        <box size="0.06 0.03 0.007" />
        </geometry>
      <material name="dark_hardware">
        <color rgba="0.08 0.08 0.085 1" />
        </material>
      </visual>
    <visual name="kickstand_hinge_tab_0">
      <origin xyz="0.033 -0.068 0.094" rpy="0 0 0" />
      <geometry>
        <box size="0.01 0.017 0.035" />
        </geometry>
      <material name="dark_hardware">
        <color rgba="0.08 0.08 0.085 1" />
        </material>
      </visual>
    <visual name="kickstand_hinge_tab_1">
      <origin xyz="0.077 -0.068 0.094" rpy="0 0 0" />
      <geometry>
        <box size="0.01 0.017 0.035" />
        </geometry>
      <material name="dark_hardware">
        <color rgba="0.08 0.08 0.085 1" />
        </material>
      </visual>
    <collision name="deck_shell">
      <origin xyz="0 0 0.13" rpy="0 0 0" />
      <geometry>
        <box size="0.52 0.11 0.035" />
        </geometry>
      </collision>
    <collision name="front_round_end">
      <origin xyz="0.26 0 0.13" rpy="0 0 0" />
      <geometry>
        <cylinder radius="0.055" length="0.035" />
        </geometry>
      </collision>
    <collision name="rear_round_end">
      <origin xyz="-0.26 0 0.13" rpy="0 0 0" />
      <geometry>
        <cylinder radius="0.055" length="0.035" />
        </geometry>
      </collision>
    <collision name="grip_tape">
      <origin xyz="-0.01 0 0.1495" rpy="0 0 0" />
      <geometry>
        <box size="0.445 0.078 0.004" />
        </geometry>
      </collision>
    <collision name="front_side_boss_0">
      <origin xyz="0.305 0.054 0.145" rpy="0 0 0" />
      <geometry>
        <box size="0.09 0.01 0.02" />
        </geometry>
      </collision>
    <collision name="front_side_boss_1">
      <origin xyz="0.305 -0.054 0.145" rpy="0 0 0" />
      <geometry>
        <box size="0.09 0.01 0.02" />
        </geometry>
      </collision>
    <collision name="steering_bearing_cheek_0">
      <origin xyz="0.34 0.02 0.184" rpy="0 0 0" />
      <geometry>
        <box size="0.07 0.01 0.075" />
        </geometry>
      </collision>
    <collision name="steering_bearing_cheek_1">
      <origin xyz="0.34 -0.02 0.184" rpy="0 0 0" />
      <geometry>
        <box size="0.07 0.01 0.075" />
        </geometry>
      </collision>
    <collision name="rear_dropout_0">
      <origin xyz="-0.31 0.036 0.086" rpy="0 0 0" />
      <geometry>
        <box size="0.072 0.012 0.07" />
        </geometry>
      </collision>
    <collision name="rear_dropout_1">
      <origin xyz="-0.31 -0.036 0.086" rpy="0 0 0" />
      <geometry>
        <box size="0.072 0.012 0.07" />
        </geometry>
      </collision>
    <collision name="rear_bridge">
      <origin xyz="-0.292 0 0.116" rpy="0 0 0" />
      <geometry>
        <box size="0.05 0.07 0.01" />
        </geometry>
      </collision>
    <collision name="kickstand_hinge_bridge">
      <origin xyz="0.055 -0.065 0.109" rpy="0 0 0" />
      <geometry>
        <box size="0.06 0.03 0.007" />
        </geometry>
      </collision>
    <collision name="kickstand_hinge_tab_0">
      <origin xyz="0.033 -0.068 0.094" rpy="0 0 0" />
      <geometry>
        <box size="0.01 0.017 0.035" />
        </geometry>
      </collision>
    <collision name="kickstand_hinge_tab_1">
      <origin xyz="0.077 -0.068 0.094" rpy="0 0 0" />
      <geometry>
        <box size="0.01 0.017 0.035" />
        </geometry>
      </collision>
    </link>
  <link name="front_steerer">
    <visual name="fixed_bar_stem">
      <origin xyz="0 0 0.3725" rpy="0 0 0" />
      <geometry>
        <cylinder radius="0.015" length="0.755" />
        </geometry>
      <material name="brushed_aluminum">
        <color rgba="0.72 0.74 0.72 1" />
        </material>
      </visual>
    <visual name="crossbar">
      <origin xyz="0 0 0.74" rpy="-1.5708 0 0" />
      <geometry>
        <cylinder radius="0.013" length="0.37" />
        </geometry>
      <material name="brushed_aluminum">
        <color rgba="0.72 0.74 0.72 1" />
        </material>
      </visual>
    <visual name="grip_0">
      <origin xyz="0 0.237 0.74" rpy="-1.5708 0 0" />
      <geometry>
        <cylinder radius="0.017" length="0.105" />
        </geometry>
      <material name="dark_rubber">
        <color rgba="0.006 0.006 0.005 1" />
        </material>
      </visual>
    <visual name="grip_1">
      <origin xyz="0 -0.237 0.74" rpy="-1.5708 0 0" />
      <geometry>
        <cylinder radius="0.017" length="0.105" />
        </geometry>
      <material name="dark_rubber">
        <color rgba="0.006 0.006 0.005 1" />
        </material>
      </visual>
    <visual name="fork_crown">
      <origin xyz="0.02 0 -0.0125" rpy="0 0 0" />
      <geometry>
        <box size="0.055 0.086 0.018" />
        </geometry>
      <material name="anodized_blue">
        <color rgba="0.03 0.18 0.75 1" />
        </material>
      </visual>
    <visual name="fork_leg_0">
      <origin xyz="0.025 0.035 -0.0675" rpy="0 0 0" />
      <geometry>
        <cylinder radius="0.008" length="0.105" />
        </geometry>
      <material name="brushed_aluminum">
        <color rgba="0.72 0.74 0.72 1" />
        </material>
      </visual>
    <visual name="fork_leg_1">
      <origin xyz="0.025 -0.035 -0.0675" rpy="0 0 0" />
      <geometry>
        <cylinder radius="0.008" length="0.105" />
        </geometry>
      <material name="brushed_aluminum">
        <color rgba="0.72 0.74 0.72 1" />
        </material>
      </visual>
    <visual name="front_axle_lug_0">
      <origin xyz="0.025 0.035 -0.0925" rpy="0 0 0" />
      <geometry>
        <box size="0.03 0.012 0.024" />
        </geometry>
      <material name="dark_hardware">
        <color rgba="0.08 0.08 0.085 1" />
        </material>
      </visual>
    <visual name="front_axle_lug_1">
      <origin xyz="0.025 -0.035 -0.0925" rpy="0 0 0" />
      <geometry>
        <box size="0.03 0.012 0.024" />
        </geometry>
      <material name="dark_hardware">
        <color rgba="0.08 0.08 0.085 1" />
        </material>
      </visual>
    <collision name="fixed_bar_stem">
      <origin xyz="0 0 0.3725" rpy="0 0 0" />
      <geometry>
        <cylinder radius="0.015" length="0.755" />
        </geometry>
      </collision>
    <collision name="crossbar">
      <origin xyz="0 0 0.74" rpy="-1.5708 0 0" />
      <geometry>
        <cylinder radius="0.013" length="0.37" />
        </geometry>
      </collision>
    <collision name="grip_0">
      <origin xyz="0 0.237 0.74" rpy="-1.5708 0 0" />
      <geometry>
        <cylinder radius="0.017" length="0.105" />
        </geometry>
      </collision>
    <collision name="grip_1">
      <origin xyz="0 -0.237 0.74" rpy="-1.5708 0 0" />
      <geometry>
        <cylinder radius="0.017" length="0.105" />
        </geometry>
      </collision>
    <collision name="fork_crown">
      <origin xyz="0.02 0 -0.0125" rpy="0 0 0" />
      <geometry>
        <box size="0.055 0.086 0.018" />
        </geometry>
      </collision>
    <collision name="fork_leg_0">
      <origin xyz="0.025 0.035 -0.0675" rpy="0 0 0" />
      <geometry>
        <cylinder radius="0.008" length="0.105" />
        </geometry>
      </collision>
    <collision name="fork_leg_1">
      <origin xyz="0.025 -0.035 -0.0675" rpy="0 0 0" />
      <geometry>
        <cylinder radius="0.008" length="0.105" />
        </geometry>
      </collision>
    <collision name="front_axle_lug_0">
      <origin xyz="0.025 0.035 -0.0925" rpy="0 0 0" />
      <geometry>
        <box size="0.03 0.012 0.024" />
        </geometry>
      </collision>
    <collision name="front_axle_lug_1">
      <origin xyz="0.025 -0.035 -0.0925" rpy="0 0 0" />
      <geometry>
        <box size="0.03 0.012 0.024" />
        </geometry>
      </collision>
    </link>
  <link name="front_wheel">
    <visual name="tire">
      <origin xyz="0 0 0" rpy="0 0 1.5708" />
      <geometry>
        <mesh filename="assets/meshes/scooter_tire.obj" />
        </geometry>
      <material name="dark_rubber">
        <color rgba="0.006 0.006 0.005 1" />
        </material>
      </visual>
    <visual name="wheel_core">
      <origin xyz="0 0 0" rpy="0 0 1.5708" />
      <geometry>
        <mesh filename="assets/meshes/scooter_wheel_core.obj" />
        </geometry>
      <material name="brushed_aluminum">
        <color rgba="0.72 0.74 0.72 1" />
        </material>
      </visual>
    <visual name="axle_spacer">
      <origin xyz="0 0 0" rpy="-1.5708 0 0" />
      <geometry>
        <cylinder radius="0.0055" length="0.058" />
        </geometry>
      <material name="dark_hardware">
        <color rgba="0.08 0.08 0.085 1" />
        </material>
      </visual>
    <collision name="tire">
      <origin xyz="0 0 0" rpy="0 0 1.5708" />
      <geometry>
        <mesh filename="assets/meshes/scooter_tire.obj" />
        </geometry>
      </collision>
    <collision name="wheel_core">
      <origin xyz="0 0 0" rpy="0 0 1.5708" />
      <geometry>
        <mesh filename="assets/meshes/scooter_wheel_core.obj" />
        </geometry>
      </collision>
    <collision name="axle_spacer">
      <origin xyz="0 0 0" rpy="-1.5708 0 0" />
      <geometry>
        <cylinder radius="0.0055" length="0.058" />
        </geometry>
      </collision>
    </link>
  <link name="rear_wheel">
    <visual name="tire">
      <origin xyz="0 0 0" rpy="0 0 1.5708" />
      <geometry>
        <mesh filename="assets/meshes/scooter_tire.obj" />
        </geometry>
      <material name="dark_rubber">
        <color rgba="0.006 0.006 0.005 1" />
        </material>
      </visual>
    <visual name="wheel_core">
      <origin xyz="0 0 0" rpy="0 0 1.5708" />
      <geometry>
        <mesh filename="assets/meshes/scooter_wheel_core.obj" />
        </geometry>
      <material name="brushed_aluminum">
        <color rgba="0.72 0.74 0.72 1" />
        </material>
      </visual>
    <visual name="axle_spacer">
      <origin xyz="0 0 0" rpy="-1.5708 0 0" />
      <geometry>
        <cylinder radius="0.0055" length="0.06" />
        </geometry>
      <material name="dark_hardware">
        <color rgba="0.08 0.08 0.085 1" />
        </material>
      </visual>
    <collision name="tire">
      <origin xyz="0 0 0" rpy="0 0 1.5708" />
      <geometry>
        <mesh filename="assets/meshes/scooter_tire.obj" />
        </geometry>
      </collision>
    <collision name="wheel_core">
      <origin xyz="0 0 0" rpy="0 0 1.5708" />
      <geometry>
        <mesh filename="assets/meshes/scooter_wheel_core.obj" />
        </geometry>
      </collision>
    <collision name="axle_spacer">
      <origin xyz="0 0 0" rpy="-1.5708 0 0" />
      <geometry>
        <cylinder radius="0.0055" length="0.06" />
        </geometry>
      </collision>
    </link>
  <link name="kickstand">
    <visual name="hinge_pin">
      <origin xyz="0 0 0" rpy="0 1.5708 0" />
      <geometry>
        <cylinder radius="0.007" length="0.034" />
        </geometry>
      <material name="dark_hardware">
        <color rgba="0.08 0.08 0.085 1" />
        </material>
      </visual>
    <visual name="folding_leg">
      <origin xyz="0 -0.061 0" rpy="-1.5708 0 0" />
      <geometry>
        <cylinder radius="0.0065" length="0.118" />
        </geometry>
      <material name="brushed_aluminum">
        <color rgba="0.72 0.74 0.72 1" />
        </material>
      </visual>
    <visual name="rubber_foot">
      <origin xyz="0 -0.126 0" rpy="0 0 0" />
      <geometry>
        <sphere radius="0.014" />
        </geometry>
      <material name="dark_rubber">
        <color rgba="0.006 0.006 0.005 1" />
        </material>
      </visual>
    <collision name="hinge_pin">
      <origin xyz="0 0 0" rpy="0 1.5708 0" />
      <geometry>
        <cylinder radius="0.007" length="0.034" />
        </geometry>
      </collision>
    <collision name="folding_leg">
      <origin xyz="0 -0.061 0" rpy="-1.5708 0 0" />
      <geometry>
        <cylinder radius="0.0065" length="0.118" />
        </geometry>
      </collision>
    <collision name="rubber_foot">
      <origin xyz="0 -0.126 0" rpy="0 0 0" />
      <geometry>
        <sphere radius="0.014" />
        </geometry>
      </collision>
    </link>
  <joint name="steering_yaw" type="revolute">
    <origin xyz="0.34 0 0.1475" rpy="0 0 0" />
    <parent link="deck" />
    <child link="front_steerer" />
    <axis xyz="0 0 1" />
    <limit effort="12" velocity="4" lower="-0.75" upper="0.75" />
    </joint>
  <joint name="front_wheel_spin" type="continuous">
    <origin xyz="0.025 0 -0.0925" rpy="0 0 0" />
    <parent link="front_steerer" />
    <child link="front_wheel" />
    <axis xyz="0 1 0" />
    <limit effort="4" velocity="30" />
    </joint>
  <joint name="rear_wheel_spin" type="continuous">
    <origin xyz="-0.31 0 0.055" rpy="0 0 0" />
    <parent link="deck" />
    <child link="rear_wheel" />
    <axis xyz="0 1 0" />
    <limit effort="4" velocity="30" />
    </joint>
  <joint name="kickstand_hinge" type="revolute">
    <origin xyz="0.055 -0.068 0.094" rpy="0 0 0" />
    <parent link="deck" />
    <child link="kickstand" />
    <axis xyz="1 0 0" />
    <limit effort="3" velocity="2" lower="0" upper="1.1" />
    </joint>
  </robot>
