<robot name="twin_pad_linear_slider">
  <material name="dark_anodized_aluminum">
    <color rgba="0.05 0.055 0.06 1" />
    </material>
  <material name="brushed_steel">
    <color rgba="0.62 0.64 0.62 1" />
    </material>
  <material name="bearing_bronze">
    <color rgba="0.76 0.52 0.22 1" />
    </material>
  <material name="carriage_aluminum">
    <color rgba="0.78 0.8 0.82 1" />
    </material>
  <material name="black_oxide">
    <color rgba="0.015 0.015 0.014 1" />
    </material>
  <material name="blue_top_pad">
    <color rgba="0.02 0.16 0.62 1" />
    </material>
  <link name="rail_body">
    <visual name="base_plate">
      <origin xyz="0 0 0.015" rpy="0 0 0" />
      <geometry>
        <box size="0.78 0.2 0.03" />
        </geometry>
      <material name="dark_anodized_aluminum" />
      </visual>
    <visual name="guide_rail_0">
      <origin xyz="0 -0.052 0.0475" rpy="0 0 0" />
      <geometry>
        <box size="0.7 0.032 0.035" />
        </geometry>
      <material name="dark_anodized_aluminum" />
      </visual>
    <visual name="guide_face_0">
      <origin xyz="0 -0.034 0.05" rpy="0 0 0" />
      <geometry>
        <box size="0.68 0.004 0.03" />
        </geometry>
      <material name="brushed_steel" />
      </visual>
    <visual name="guide_rail_1">
      <origin xyz="0 0.052 0.0475" rpy="0 0 0" />
      <geometry>
        <box size="0.7 0.032 0.035" />
        </geometry>
      <material name="dark_anodized_aluminum" />
      </visual>
    <visual name="guide_face_1">
      <origin xyz="0 0.034 0.05" rpy="0 0 0" />
      <geometry>
        <box size="0.68 0.004 0.03" />
        </geometry>
      <material name="brushed_steel" />
      </visual>
    <visual name="end_stop_0">
      <origin xyz="-0.365 0 0.065" rpy="0 0 0" />
      <geometry>
        <box size="0.025 0.18 0.07" />
        </geometry>
      <material name="dark_anodized_aluminum" />
      </visual>
    <visual name="end_stop_1">
      <origin xyz="0.365 0 0.065" rpy="0 0 0" />
      <geometry>
        <box size="0.025 0.18 0.07" />
        </geometry>
      <material name="dark_anodized_aluminum" />
      </visual>
    <visual name="rail_screw_0">
      <origin xyz="-0.3 -0.075 0.0325" rpy="0 0 0" />
      <geometry>
        <cylinder radius="0.007" length="0.005" />
        </geometry>
      <material name="black_oxide" />
      </visual>
    <visual name="rail_screw_1">
      <origin xyz="-0.3 0.075 0.0325" rpy="0 0 0" />
      <geometry>
        <cylinder radius="0.007" length="0.005" />
        </geometry>
      <material name="black_oxide" />
      </visual>
    <visual name="rail_screw_2">
      <origin xyz="0.3 -0.075 0.0325" rpy="0 0 0" />
      <geometry>
        <cylinder radius="0.007" length="0.005" />
        </geometry>
      <material name="black_oxide" />
      </visual>
    <visual name="rail_screw_3">
      <origin xyz="0.3 0.075 0.0325" rpy="0 0 0" />
      <geometry>
        <cylinder radius="0.007" length="0.005" />
        </geometry>
      <material name="black_oxide" />
      </visual>
    <collision name="base_plate">
      <origin xyz="0 0 0.015" rpy="0 0 0" />
      <geometry>
        <box size="0.78 0.2 0.03" />
        </geometry>
      </collision>
    <collision name="guide_rail_0">
      <origin xyz="0 -0.052 0.0475" rpy="0 0 0" />
      <geometry>
        <box size="0.7 0.032 0.035" />
        </geometry>
      </collision>
    <collision name="guide_face_0">
      <origin xyz="0 -0.034 0.05" rpy="0 0 0" />
      <geometry>
        <box size="0.68 0.004 0.03" />
        </geometry>
      </collision>
    <collision name="guide_rail_1">
      <origin xyz="0 0.052 0.0475" rpy="0 0 0" />
      <geometry>
        <box size="0.7 0.032 0.035" />
        </geometry>
      </collision>
    <collision name="guide_face_1">
      <origin xyz="0 0.034 0.05" rpy="0 0 0" />
      <geometry>
        <box size="0.68 0.004 0.03" />
        </geometry>
      </collision>
    <collision name="end_stop_0">
      <origin xyz="-0.365 0 0.065" rpy="0 0 0" />
      <geometry>
        <box size="0.025 0.18 0.07" />
        </geometry>
      </collision>
    <collision name="end_stop_1">
      <origin xyz="0.365 0 0.065" rpy="0 0 0" />
      <geometry>
        <box size="0.025 0.18 0.07" />
        </geometry>
      </collision>
    <collision name="rail_screw_0">
      <origin xyz="-0.3 -0.075 0.0325" rpy="0 0 0" />
      <geometry>
        <cylinder radius="0.007" length="0.005" />
        </geometry>
      </collision>
    <collision name="rail_screw_1">
      <origin xyz="-0.3 0.075 0.0325" rpy="0 0 0" />
      <geometry>
        <cylinder radius="0.007" length="0.005" />
        </geometry>
      </collision>
    <collision name="rail_screw_2">
      <origin xyz="0.3 -0.075 0.0325" rpy="0 0 0" />
      <geometry>
        <cylinder radius="0.007" length="0.005" />
        </geometry>
      </collision>
    <collision name="rail_screw_3">
      <origin xyz="0.3 0.075 0.0325" rpy="0 0 0" />
      <geometry>
        <cylinder radius="0.007" length="0.005" />
        </geometry>
      </collision>
    </link>
  <link name="carriage">
    <visual name="bridge">
      <origin xyz="0 0 0.089" rpy="0 0 0" />
      <geometry>
        <box size="0.22 0.15 0.034" />
        </geometry>
      <material name="carriage_aluminum" />
      </visual>
    <visual name="center_tongue">
      <origin xyz="0 0 0.055" rpy="0 0 0" />
      <geometry>
        <box size="0.195 0.05 0.045" />
        </geometry>
      <material name="carriage_aluminum" />
      </visual>
    <visual name="bearing_pad_0">
      <origin xyz="0 -0.029 0.05" rpy="0 0 0" />
      <geometry>
        <box size="0.17 0.012 0.03" />
        </geometry>
      <material name="bearing_bronze" />
      </visual>
    <visual name="bearing_pad_1">
      <origin xyz="0 0.029 0.05" rpy="0 0 0" />
      <geometry>
        <box size="0.17 0.012 0.03" />
        </geometry>
      <material name="bearing_bronze" />
      </visual>
    <visual name="top_pad">
      <origin xyz="0 0 0.113" rpy="0 0 0" />
      <geometry>
        <box size="0.145 0.095 0.014" />
        </geometry>
      <material name="blue_top_pad" />
      </visual>
    <visual name="pad_screw_0">
      <origin xyz="-0.055 -0.03 0.1215" rpy="0 0 0" />
      <geometry>
        <cylinder radius="0.007" length="0.004" />
        </geometry>
      <material name="black_oxide" />
      </visual>
    <visual name="pad_screw_1">
      <origin xyz="-0.055 0.03 0.1215" rpy="0 0 0" />
      <geometry>
        <cylinder radius="0.007" length="0.004" />
        </geometry>
      <material name="black_oxide" />
      </visual>
    <visual name="pad_screw_2">
      <origin xyz="0.055 -0.03 0.1215" rpy="0 0 0" />
      <geometry>
        <cylinder radius="0.007" length="0.004" />
        </geometry>
      <material name="black_oxide" />
      </visual>
    <visual name="pad_screw_3">
      <origin xyz="0.055 0.03 0.1215" rpy="0 0 0" />
      <geometry>
        <cylinder radius="0.007" length="0.004" />
        </geometry>
      <material name="black_oxide" />
      </visual>
    <collision name="bridge">
      <origin xyz="0 0 0.089" rpy="0 0 0" />
      <geometry>
        <box size="0.22 0.15 0.034" />
        </geometry>
      </collision>
    <collision name="center_tongue">
      <origin xyz="0 0 0.055" rpy="0 0 0" />
      <geometry>
        <box size="0.195 0.05 0.045" />
        </geometry>
      </collision>
    <collision name="bearing_pad_0">
      <origin xyz="0 -0.029 0.05" rpy="0 0 0" />
      <geometry>
        <box size="0.17 0.012 0.03" />
        </geometry>
      </collision>
    <collision name="bearing_pad_1">
      <origin xyz="0 0.029 0.05" rpy="0 0 0" />
      <geometry>
        <box size="0.17 0.012 0.03" />
        </geometry>
      </collision>
    <collision name="top_pad">
      <origin xyz="0 0 0.113" rpy="0 0 0" />
      <geometry>
        <box size="0.145 0.095 0.014" />
        </geometry>
      </collision>
    <collision name="pad_screw_0">
      <origin xyz="-0.055 -0.03 0.1215" rpy="0 0 0" />
      <geometry>
        <cylinder radius="0.007" length="0.004" />
        </geometry>
      </collision>
    <collision name="pad_screw_1">
      <origin xyz="-0.055 0.03 0.1215" rpy="0 0 0" />
      <geometry>
        <cylinder radius="0.007" length="0.004" />
        </geometry>
      </collision>
    <collision name="pad_screw_2">
      <origin xyz="0.055 -0.03 0.1215" rpy="0 0 0" />
      <geometry>
        <cylinder radius="0.007" length="0.004" />
        </geometry>
      </collision>
    <collision name="pad_screw_3">
      <origin xyz="0.055 0.03 0.1215" rpy="0 0 0" />
      <geometry>
        <cylinder radius="0.007" length="0.004" />
        </geometry>
      </collision>
    </link>
  <joint name="rail_to_carriage" type="prismatic">
    <origin xyz="-0.2 0 0" rpy="0 0 0" />
    <parent link="rail_body" />
    <child link="carriage" />
    <axis xyz="1 0 0" />
    <limit effort="120" velocity="0.35" lower="0" upper="0.4" />
    <dynamics damping="3" friction="1.5" />
    </joint>
  </robot>
