<robot name="compact_dorm_microwave">
  <link name="cabinet">
    <visual name="top_shell">
      <origin xyz="0 0 0.2425" rpy="0 0 0" />
      <geometry>
        <box size="0.45 0.34 0.035" />
        </geometry>
      <material name="warm_white_enamel">
        <color rgba="0.86 0.84 0.78 1" />
        </material>
      </visual>
    <visual name="bottom_shell">
      <origin xyz="0 0 0.0175" rpy="0 0 0" />
      <geometry>
        <box size="0.45 0.34 0.035" />
        </geometry>
      <material name="warm_white_enamel">
        <color rgba="0.86 0.84 0.78 1" />
        </material>
      </visual>
    <visual name="side_shell_0">
      <origin xyz="-0.2075 0 0.13" rpy="0 0 0" />
      <geometry>
        <box size="0.035 0.34 0.26" />
        </geometry>
      <material name="warm_white_enamel">
        <color rgba="0.86 0.84 0.78 1" />
        </material>
      </visual>
    <visual name="side_shell_1">
      <origin xyz="0.2075 0 0.13" rpy="0 0 0" />
      <geometry>
        <box size="0.035 0.34 0.26" />
        </geometry>
      <material name="warm_white_enamel">
        <color rgba="0.86 0.84 0.78 1" />
        </material>
      </visual>
    <visual name="rear_shell">
      <origin xyz="0 0.1575 0.13" rpy="0 0 0" />
      <geometry>
        <box size="0.45 0.025 0.26" />
        </geometry>
      <material name="warm_white_enamel">
        <color rgba="0.86 0.84 0.78 1" />
        </material>
      </visual>
    <visual name="front_lintel">
      <origin xyz="-0.045 -0.16 0.244" rpy="0 0 0" />
      <geometry>
        <box size="0.335 0.02 0.032" />
        </geometry>
      <material name="warm_white_enamel">
        <color rgba="0.86 0.84 0.78 1" />
        </material>
      </visual>
    <visual name="front_sill">
      <origin xyz="-0.045 -0.16 0.016" rpy="0 0 0" />
      <geometry>
        <box size="0.335 0.02 0.032" />
        </geometry>
      <material name="warm_white_enamel">
        <color rgba="0.86 0.84 0.78 1" />
        </material>
      </visual>
    <visual name="hinge_jamb">
      <origin xyz="-0.209 -0.16 0.13" rpy="0 0 0" />
      <geometry>
        <box size="0.032 0.02 0.21" />
        </geometry>
      <material name="warm_white_enamel">
        <color rgba="0.86 0.84 0.78 1" />
        </material>
      </visual>
    <visual name="fixed_hinge_leaf_0">
      <origin xyz="-0.205 -0.17 0.197" rpy="0 0 0" />
      <geometry>
        <box size="0.016 0.01 0.07" />
        </geometry>
      <material name="brushed_silver">
        <color rgba="0.62 0.61 0.57 1" />
        </material>
      </visual>
    <visual name="fixed_hinge_leaf_1">
      <origin xyz="-0.205 -0.17 0.063" rpy="0 0 0" />
      <geometry>
        <box size="0.016 0.01 0.07" />
        </geometry>
      <material name="brushed_silver">
        <color rgba="0.62 0.61 0.57 1" />
        </material>
      </visual>
    <visual name="control_strip">
      <origin xyz="0.1625 -0.157 0.13" rpy="0 0 0" />
      <geometry>
        <box size="0.105 0.026 0.22" />
        </geometry>
      <material name="warm_white_enamel">
        <color rgba="0.86 0.84 0.78 1" />
        </material>
      </visual>
    <visual name="dark_cavity_back">
      <origin xyz="-0.045 0.125 0.135" rpy="0 0 0" />
      <geometry>
        <box size="0.296 0.01 0.168" />
        </geometry>
      <material name="oven_shadow_black">
        <color rgba="0.015 0.015 0.014 1" />
        </material>
      </visual>
    <visual name="dark_cavity_floor">
      <origin xyz="-0.045 -0.035 0.041" rpy="0 0 0" />
      <geometry>
        <box size="0.296 0.23 0.012" />
        </geometry>
      <material name="oven_shadow_black">
        <color rgba="0.015 0.015 0.014 1" />
        </material>
      </visual>
    <visual name="glass_turntable">
      <origin xyz="-0.045 -0.045 0.0505" rpy="0 0 0" />
      <geometry>
        <cylinder radius="0.105" length="0.007" />
        </geometry>
      <material name="smoky_window_glass">
        <color rgba="0.08 0.12 0.15 0.72" />
        </material>
      </visual>
    <visual name="side_vent_0">
      <origin xyz="0.226 0.025 0.085" rpy="0 0 0" />
      <geometry>
        <box size="0.003 0.105 0.006" />
        </geometry>
      <material name="oven_shadow_black">
        <color rgba="0.015 0.015 0.014 1" />
        </material>
      </visual>
    <visual name="side_vent_1">
      <origin xyz="0.226 0.025 0.108" rpy="0 0 0" />
      <geometry>
        <box size="0.003 0.105 0.006" />
        </geometry>
      <material name="oven_shadow_black">
        <color rgba="0.015 0.015 0.014 1" />
        </material>
      </visual>
    <visual name="side_vent_2">
      <origin xyz="0.226 0.025 0.131" rpy="0 0 0" />
      <geometry>
        <box size="0.003 0.105 0.006" />
        </geometry>
      <material name="oven_shadow_black">
        <color rgba="0.015 0.015 0.014 1" />
        </material>
      </visual>
    <visual name="side_vent_3">
      <origin xyz="0.226 0.025 0.154" rpy="0 0 0" />
      <geometry>
        <box size="0.003 0.105 0.006" />
        </geometry>
      <material name="oven_shadow_black">
        <color rgba="0.015 0.015 0.014 1" />
        </material>
      </visual>
    <visual name="side_vent_4">
      <origin xyz="0.226 0.025 0.177" rpy="0 0 0" />
      <geometry>
        <box size="0.003 0.105 0.006" />
        </geometry>
      <material name="oven_shadow_black">
        <color rgba="0.015 0.015 0.014 1" />
        </material>
      </visual>
    <collision name="top_shell">
      <origin xyz="0 0 0.2425" rpy="0 0 0" />
      <geometry>
        <box size="0.45 0.34 0.035" />
        </geometry>
      </collision>
    <collision name="bottom_shell">
      <origin xyz="0 0 0.0175" rpy="0 0 0" />
      <geometry>
        <box size="0.45 0.34 0.035" />
        </geometry>
      </collision>
    <collision name="side_shell_0">
      <origin xyz="-0.2075 0 0.13" rpy="0 0 0" />
      <geometry>
        <box size="0.035 0.34 0.26" />
        </geometry>
      </collision>
    <collision name="side_shell_1">
      <origin xyz="0.2075 0 0.13" rpy="0 0 0" />
      <geometry>
        <box size="0.035 0.34 0.26" />
        </geometry>
      </collision>
    <collision name="rear_shell">
      <origin xyz="0 0.1575 0.13" rpy="0 0 0" />
      <geometry>
        <box size="0.45 0.025 0.26" />
        </geometry>
      </collision>
    <collision name="front_lintel">
      <origin xyz="-0.045 -0.16 0.244" rpy="0 0 0" />
      <geometry>
        <box size="0.335 0.02 0.032" />
        </geometry>
      </collision>
    <collision name="front_sill">
      <origin xyz="-0.045 -0.16 0.016" rpy="0 0 0" />
      <geometry>
        <box size="0.335 0.02 0.032" />
        </geometry>
      </collision>
    <collision name="hinge_jamb">
      <origin xyz="-0.209 -0.16 0.13" rpy="0 0 0" />
      <geometry>
        <box size="0.032 0.02 0.21" />
        </geometry>
      </collision>
    <collision name="fixed_hinge_leaf_0">
      <origin xyz="-0.205 -0.17 0.197" rpy="0 0 0" />
      <geometry>
        <box size="0.016 0.01 0.07" />
        </geometry>
      </collision>
    <collision name="fixed_hinge_leaf_1">
      <origin xyz="-0.205 -0.17 0.063" rpy="0 0 0" />
      <geometry>
        <box size="0.016 0.01 0.07" />
        </geometry>
      </collision>
    <collision name="control_strip">
      <origin xyz="0.1625 -0.157 0.13" rpy="0 0 0" />
      <geometry>
        <box size="0.105 0.026 0.22" />
        </geometry>
      </collision>
    <collision name="dark_cavity_back">
      <origin xyz="-0.045 0.125 0.135" rpy="0 0 0" />
      <geometry>
        <box size="0.296 0.01 0.168" />
        </geometry>
      </collision>
    <collision name="dark_cavity_floor">
      <origin xyz="-0.045 -0.035 0.041" rpy="0 0 0" />
      <geometry>
        <box size="0.296 0.23 0.012" />
        </geometry>
      </collision>
    <collision name="glass_turntable">
      <origin xyz="-0.045 -0.045 0.0505" rpy="0 0 0" />
      <geometry>
        <cylinder radius="0.105" length="0.007" />
        </geometry>
      </collision>
    <collision name="side_vent_0">
      <origin xyz="0.226 0.025 0.085" rpy="0 0 0" />
      <geometry>
        <box size="0.003 0.105 0.006" />
        </geometry>
      </collision>
    <collision name="side_vent_1">
      <origin xyz="0.226 0.025 0.108" rpy="0 0 0" />
      <geometry>
        <box size="0.003 0.105 0.006" />
        </geometry>
      </collision>
    <collision name="side_vent_2">
      <origin xyz="0.226 0.025 0.131" rpy="0 0 0" />
      <geometry>
        <box size="0.003 0.105 0.006" />
        </geometry>
      </collision>
    <collision name="side_vent_3">
      <origin xyz="0.226 0.025 0.154" rpy="0 0 0" />
      <geometry>
        <box size="0.003 0.105 0.006" />
        </geometry>
      </collision>
    <collision name="side_vent_4">
      <origin xyz="0.226 0.025 0.177" rpy="0 0 0" />
      <geometry>
        <box size="0.003 0.105 0.006" />
        </geometry>
      </collision>
    </link>
  <link name="door">
    <visual name="door_panel">
      <origin xyz="0.16 0 0" rpy="0 0 0" />
      <geometry>
        <box size="0.315 0.02 0.215" />
        </geometry>
      <material name="charcoal_plastic">
        <color rgba="0.05 0.055 0.06 1" />
        </material>
      </visual>
    <visual name="window_pane">
      <origin xyz="0.142 -0.012 0.006" rpy="0 0 0" />
      <geometry>
        <box size="0.208 0.004 0.128" />
        </geometry>
      <material name="smoky_window_glass">
        <color rgba="0.08 0.12 0.15 0.72" />
        </material>
      </visual>
    <visual name="pull_lip">
      <origin xyz="0.292 -0.017 0" rpy="0 0 0" />
      <geometry>
        <box size="0.018 0.014 0.16" />
        </geometry>
      <material name="brushed_silver">
        <color rgba="0.62 0.61 0.57 1" />
        </material>
      </visual>
    <visual name="hinge_barrel_0">
      <origin xyz="0 0 0.067" rpy="0 0 0" />
      <geometry>
        <cylinder radius="0.01" length="0.07" />
        </geometry>
      <material name="brushed_silver">
        <color rgba="0.62 0.61 0.57 1" />
        </material>
      </visual>
    <visual name="hinge_barrel_1">
      <origin xyz="0 0 -0.067" rpy="0 0 0" />
      <geometry>
        <cylinder radius="0.01" length="0.07" />
        </geometry>
      <material name="brushed_silver">
        <color rgba="0.62 0.61 0.57 1" />
        </material>
      </visual>
    <collision name="door_panel">
      <origin xyz="0.16 0 0" rpy="0 0 0" />
      <geometry>
        <box size="0.315 0.02 0.215" />
        </geometry>
      </collision>
    <collision name="window_pane">
      <origin xyz="0.142 -0.012 0.006" rpy="0 0 0" />
      <geometry>
        <box size="0.208 0.004 0.128" />
        </geometry>
      </collision>
    <collision name="pull_lip">
      <origin xyz="0.292 -0.017 0" rpy="0 0 0" />
      <geometry>
        <box size="0.018 0.014 0.16" />
        </geometry>
      </collision>
    <collision name="hinge_barrel_0">
      <origin xyz="0 0 0.067" rpy="0 0 0" />
      <geometry>
        <cylinder radius="0.01" length="0.07" />
        </geometry>
      </collision>
    <collision name="hinge_barrel_1">
      <origin xyz="0 0 -0.067" rpy="0 0 0" />
      <geometry>
        <cylinder radius="0.01" length="0.07" />
        </geometry>
      </collision>
    </link>
  <link name="knob">
    <visual name="shaft">
      <origin xyz="0 0 0.008" rpy="0 0 0" />
      <geometry>
        <cylinder radius="0.015" length="0.016" />
        </geometry>
      <material name="charcoal_plastic">
        <color rgba="0.05 0.055 0.06 1" />
        </material>
      </visual>
    <visual name="dial_cap">
      <origin xyz="0 0 0.026" rpy="0 0 0" />
      <geometry>
        <cylinder radius="0.039" length="0.02" />
        </geometry>
      <material name="brushed_silver">
        <color rgba="0.62 0.61 0.57 1" />
        </material>
      </visual>
    <visual name="pointer_mark">
      <origin xyz="0 0.019 0.038" rpy="0 0 0" />
      <geometry>
        <box size="0.006 0.026 0.004" />
        </geometry>
      <material name="printed_black">
        <color rgba="0 0 0 1" />
        </material>
      </visual>
    <collision name="shaft">
      <origin xyz="0 0 0.008" rpy="0 0 0" />
      <geometry>
        <cylinder radius="0.015" length="0.016" />
        </geometry>
      </collision>
    <collision name="dial_cap">
      <origin xyz="0 0 0.026" rpy="0 0 0" />
      <geometry>
        <cylinder radius="0.039" length="0.02" />
        </geometry>
      </collision>
    <collision name="pointer_mark">
      <origin xyz="0 0.019 0.038" rpy="0 0 0" />
      <geometry>
        <box size="0.006 0.026 0.004" />
        </geometry>
      </collision>
    </link>
  <joint name="door_hinge" type="revolute">
    <origin xyz="-0.205 -0.185 0.13" rpy="0 0 0" />
    <parent link="cabinet" />
    <child link="door" />
    <axis xyz="0 0 -1" />
    <limit effort="4" velocity="1.4" lower="0" upper="1.92" />
    </joint>
  <joint name="knob_shaft" type="revolute">
    <origin xyz="0.1625 -0.17 0.145" rpy="1.5708 0 0" />
    <parent link="cabinet" />
    <child link="knob" />
    <axis xyz="0 0 1" />
    <limit effort="0.5" velocity="6" lower="0" upper="5.2" />
    </joint>
  </robot>
