<robot name="driver_side_sun_visor">
  <material name="warm_grey_headliner">
    <color rgba="0.72 0.69 0.63 1" />
    </material>
  <material name="molded_beige_fabric">
    <color rgba="0.78 0.72 0.62 1" />
    </material>
  <material name="slightly_lighter_extender">
    <color rgba="0.84 0.79 0.69 1" />
    </material>
  <material name="grey_plastic_hardware">
    <color rgba="0.47 0.47 0.45 1" />
    </material>
  <material name="dark_hinge_pin">
    <color rgba="0.08 0.08 0.08 1" />
    </material>
  <material name="recess_shadow">
    <color rgba="0.1 0.09 0.08 1" />
    </material>
  <link name="roof_hardware">
    <inertial>
      <origin xyz="0.005 0.01 -0.01" rpy="0 0 0" />
      <mass value="0.22" />
      <inertia ixx="0.000183333" ixy="0" ixz="0" iyy="0.0060225" iyz="0" izz="0.00607383" />
      </inertial>
    <visual name="headliner_patch">
      <origin xyz="0.005 0.018 0.006" rpy="0 0 0" />
      <geometry>
        <box size="0.57 0.07 0.012" />
        </geometry>
      <material name="warm_grey_headliner">
        <color rgba="0.72 0.69 0.63 1" />
        </material>
      </visual>
    <visual name="bracket_base">
      <origin xyz="-0.225 0.004 -0.004" rpy="0 0 0" />
      <geometry>
        <box size="0.07 0.052 0.014" />
        </geometry>
      <material name="grey_plastic_hardware">
        <color rgba="0.47 0.47 0.45 1" />
        </material>
      </visual>
    <visual name="bracket_cheek_0">
      <origin xyz="-0.225 -0.02 -0.025" rpy="0 0 0" />
      <geometry>
        <box size="0.038 0.006 0.038" />
        </geometry>
      <material name="grey_plastic_hardware">
        <color rgba="0.47 0.47 0.45 1" />
        </material>
      </visual>
    <visual name="bracket_cheek_1">
      <origin xyz="-0.225 0.02 -0.025" rpy="0 0 0" />
      <geometry>
        <box size="0.038 0.006 0.038" />
        </geometry>
      <material name="grey_plastic_hardware">
        <color rgba="0.47 0.47 0.45 1" />
        </material>
      </visual>
    <visual name="bracket_socket">
      <origin xyz="-0.225 0 -0.02" rpy="1.5708 0 0" />
      <geometry>
        <cylinder radius="0.01" length="0.044" />
        </geometry>
      <material name="dark_hinge_pin">
        <color rgba="0.08 0.08 0.08 1" />
        </material>
      </visual>
    <visual name="clip_base">
      <origin xyz="0.225 0 -0.004" rpy="0 0 0" />
      <geometry>
        <box size="0.046 0.046 0.012" />
        </geometry>
      <material name="grey_plastic_hardware">
        <color rgba="0.47 0.47 0.45 1" />
        </material>
      </visual>
    <visual name="clip_jaw_0">
      <origin xyz="0.225 -0.018 -0.022" rpy="0 0 0" />
      <geometry>
        <box size="0.024 0.006 0.028" />
        </geometry>
      <material name="grey_plastic_hardware">
        <color rgba="0.47 0.47 0.45 1" />
        </material>
      </visual>
    <visual name="clip_jaw_1">
      <origin xyz="0.225 0.018 -0.022" rpy="0 0 0" />
      <geometry>
        <box size="0.024 0.006 0.028" />
        </geometry>
      <material name="grey_plastic_hardware">
        <color rgba="0.47 0.47 0.45 1" />
        </material>
      </visual>
    <visual name="clip_lip_0">
      <origin xyz="0.225 -0.012 -0.036" rpy="0 0 0" />
      <geometry>
        <box size="0.024 0.006 0.01" />
        </geometry>
      <material name="grey_plastic_hardware">
        <color rgba="0.47 0.47 0.45 1" />
        </material>
      </visual>
    <visual name="clip_lip_1">
      <origin xyz="0.225 0.012 -0.036" rpy="0 0 0" />
      <geometry>
        <box size="0.024 0.006 0.01" />
        </geometry>
      <material name="grey_plastic_hardware">
        <color rgba="0.47 0.47 0.45 1" />
        </material>
      </visual>
    <collision name="headliner_patch">
      <origin xyz="0.005 0.018 0.006" rpy="0 0 0" />
      <geometry>
        <box size="0.57 0.07 0.012" />
        </geometry>
      </collision>
    <collision name="bracket_base">
      <origin xyz="-0.225 0.004 -0.004" rpy="0 0 0" />
      <geometry>
        <box size="0.07 0.052 0.014" />
        </geometry>
      </collision>
    <collision name="bracket_cheek_0">
      <origin xyz="-0.225 -0.02 -0.025" rpy="0 0 0" />
      <geometry>
        <box size="0.038 0.006 0.038" />
        </geometry>
      </collision>
    <collision name="bracket_cheek_1">
      <origin xyz="-0.225 0.02 -0.025" rpy="0 0 0" />
      <geometry>
        <box size="0.038 0.006 0.038" />
        </geometry>
      </collision>
    <collision name="bracket_socket">
      <origin xyz="-0.225 0 -0.02" rpy="1.5708 0 0" />
      <geometry>
        <cylinder radius="0.01" length="0.044" />
        </geometry>
      </collision>
    <collision name="clip_base">
      <origin xyz="0.225 0 -0.004" rpy="0 0 0" />
      <geometry>
        <box size="0.046 0.046 0.012" />
        </geometry>
      </collision>
    <collision name="clip_jaw_0">
      <origin xyz="0.225 -0.018 -0.022" rpy="0 0 0" />
      <geometry>
        <box size="0.024 0.006 0.028" />
        </geometry>
      </collision>
    <collision name="clip_jaw_1">
      <origin xyz="0.225 0.018 -0.022" rpy="0 0 0" />
      <geometry>
        <box size="0.024 0.006 0.028" />
        </geometry>
      </collision>
    <collision name="clip_lip_0">
      <origin xyz="0.225 -0.012 -0.036" rpy="0 0 0" />
      <geometry>
        <box size="0.024 0.006 0.01" />
        </geometry>
      </collision>
    <collision name="clip_lip_1">
      <origin xyz="0.225 0.012 -0.036" rpy="0 0 0" />
      <geometry>
        <box size="0.024 0.006 0.01" />
        </geometry>
      </collision>
    </link>
  <link name="hinge_rod">
    <inertial>
      <origin xyz="0.231 0 0" rpy="0 1.5708 0" />
      <mass value="0.06" />
      <inertia ixx="0.00106776" ixy="0" ixz="0" iyy="0.00106776" iyz="0" izz="1.08e-06" />
      </inertial>
    <visual name="steel_rod">
      <origin xyz="0.231 0 0" rpy="0 1.5708 0" />
      <geometry>
        <cylinder radius="0.0052" length="0.462" />
        </geometry>
      <material name="dark_hinge_pin">
        <color rgba="0.08 0.08 0.08 1" />
        </material>
      </visual>
    <visual name="clip_pin">
      <origin xyz="0.454 0 0" rpy="0 1.5708 0" />
      <geometry>
        <cylinder radius="0.0085" length="0.018" />
        </geometry>
      <material name="grey_plastic_hardware">
        <color rgba="0.47 0.47 0.45 1" />
        </material>
      </visual>
    <collision name="steel_rod">
      <origin xyz="0.231 0 0" rpy="0 1.5708 0" />
      <geometry>
        <cylinder radius="0.0052" length="0.462" />
        </geometry>
      </collision>
    <collision name="clip_pin">
      <origin xyz="0.454 0 0" rpy="0 1.5708 0" />
      <geometry>
        <cylinder radius="0.0085" length="0.018" />
        </geometry>
      </collision>
    </link>
  <link name="visor_panel">
    <inertial>
      <origin xyz="0.235 -0.096 -0.036" rpy="0 0 0" />
      <mass value="0.34" />
      <inertia ixx="0.000837987" ixy="0" ixz="0" iyy="0.00562986" iyz="0" izz="0.00642954" />
      </inertial>
    <visual name="panel_body">
      <origin xyz="0.235 -0.096 -0.036" rpy="0 0 0" />
      <geometry>
        <mesh filename="assets/meshes/visor_padded_panel.obj" />
        </geometry>
      <material name="molded_beige_fabric">
        <color rgba="0.78 0.72 0.62 1" />
        </material>
      </visual>
    <visual name="sleeve_upper_shadow">
      <origin xyz="0.31 -0.04 -0.036" rpy="0 0 0" />
      <geometry>
        <box size="0.226 0.004 0.016" />
        </geometry>
      <material name="recess_shadow">
        <color rgba="0.1 0.09 0.08 1" />
        </material>
      </visual>
    <visual name="sleeve_lower_shadow">
      <origin xyz="0.31 -0.152 -0.036" rpy="0 0 0" />
      <geometry>
        <box size="0.226 0.004 0.016" />
        </geometry>
      <material name="recess_shadow">
        <color rgba="0.1 0.09 0.08 1" />
        </material>
      </visual>
    <visual name="hinge_leaf_0">
      <origin xyz="0.058 -0.01 -0.035" rpy="0 0 0" />
      <geometry>
        <box size="0.085 0.014 0.018" />
        </geometry>
      <material name="grey_plastic_hardware">
        <color rgba="0.47 0.47 0.45 1" />
        </material>
      </visual>
    <visual name="hinge_leaf_1">
      <origin xyz="0.172 -0.01 -0.035" rpy="0 0 0" />
      <geometry>
        <box size="0.085 0.014 0.018" />
        </geometry>
      <material name="grey_plastic_hardware">
        <color rgba="0.47 0.47 0.45 1" />
        </material>
      </visual>
    <visual name="free_end_keeper">
      <origin xyz="0.452 -0.01 -0.035" rpy="0 0 0" />
      <geometry>
        <box size="0.02 0.012 0.018" />
        </geometry>
      <material name="grey_plastic_hardware">
        <color rgba="0.47 0.47 0.45 1" />
        </material>
      </visual>
    <collision name="panel_body">
      <origin xyz="0.235 -0.096 -0.036" rpy="0 0 0" />
      <geometry>
        <mesh filename="assets/meshes/visor_padded_panel.obj" />
        </geometry>
      </collision>
    <collision name="sleeve_upper_shadow">
      <origin xyz="0.31 -0.04 -0.036" rpy="0 0 0" />
      <geometry>
        <box size="0.226 0.004 0.016" />
        </geometry>
      </collision>
    <collision name="sleeve_lower_shadow">
      <origin xyz="0.31 -0.152 -0.036" rpy="0 0 0" />
      <geometry>
        <box size="0.226 0.004 0.016" />
        </geometry>
      </collision>
    <collision name="hinge_leaf_0">
      <origin xyz="0.058 -0.01 -0.035" rpy="0 0 0" />
      <geometry>
        <box size="0.085 0.014 0.018" />
        </geometry>
      </collision>
    <collision name="hinge_leaf_1">
      <origin xyz="0.172 -0.01 -0.035" rpy="0 0 0" />
      <geometry>
        <box size="0.085 0.014 0.018" />
        </geometry>
      </collision>
    <collision name="free_end_keeper">
      <origin xyz="0.452 -0.01 -0.035" rpy="0 0 0" />
      <geometry>
        <box size="0.02 0.012 0.018" />
        </geometry>
      </collision>
    </link>
  <link name="extender">
    <inertial>
      <mass value="0.09" />
      <inertia ixx="6.735e-05" ixy="0" ixz="0" iyy="0.00027183" iyz="0" izz="0.00033702" />
      </inertial>
    <visual name="extender_panel">
      <geometry>
        <mesh filename="assets/meshes/visor_sliding_extender.obj" />
        </geometry>
      <material name="slightly_lighter_extender">
        <color rgba="0.84 0.79 0.69 1" />
        </material>
      </visual>
    <visual name="upper_guide_rail">
      <origin xyz="0 0.05 0" rpy="0 0 0" />
      <geometry>
        <box size="0.184 0.006 0.01" />
        </geometry>
      <material name="grey_plastic_hardware">
        <color rgba="0.47 0.47 0.45 1" />
        </material>
      </visual>
    <visual name="lower_guide_rail">
      <origin xyz="0 -0.05 0" rpy="0 0 0" />
      <geometry>
        <box size="0.184 0.006 0.01" />
        </geometry>
      <material name="grey_plastic_hardware">
        <color rgba="0.47 0.47 0.45 1" />
        </material>
      </visual>
    <visual name="upper_rubbing_pad">
      <origin xyz="0 0.054 0" rpy="0 0 0" />
      <geometry>
        <box size="0.006 0.002 0.004" />
        </geometry>
      <material name="grey_plastic_hardware">
        <color rgba="0.47 0.47 0.45 1" />
        </material>
      </visual>
    <visual name="lower_rubbing_pad">
      <origin xyz="0 -0.054 0" rpy="0 0 0" />
      <geometry>
        <box size="0.006 0.002 0.004" />
        </geometry>
      <material name="grey_plastic_hardware">
        <color rgba="0.47 0.47 0.45 1" />
        </material>
      </visual>
    <visual name="pull_grip">
      <origin xyz="0.084 0 -0.009" rpy="0 0 0" />
      <geometry>
        <box size="0.018 0.06 0.006" />
        </geometry>
      <material name="grey_plastic_hardware">
        <color rgba="0.47 0.47 0.45 1" />
        </material>
      </visual>
    <collision name="extender_panel">
      <geometry>
        <mesh filename="assets/meshes/visor_sliding_extender.obj" />
        </geometry>
      </collision>
    <collision name="upper_guide_rail">
      <origin xyz="0 0.05 0" rpy="0 0 0" />
      <geometry>
        <box size="0.184 0.006 0.01" />
        </geometry>
      </collision>
    <collision name="lower_guide_rail">
      <origin xyz="0 -0.05 0" rpy="0 0 0" />
      <geometry>
        <box size="0.184 0.006 0.01" />
        </geometry>
      </collision>
    <collision name="upper_rubbing_pad">
      <origin xyz="0 0.054 0" rpy="0 0 0" />
      <geometry>
        <box size="0.006 0.002 0.004" />
        </geometry>
      </collision>
    <collision name="lower_rubbing_pad">
      <origin xyz="0 -0.054 0" rpy="0 0 0" />
      <geometry>
        <box size="0.006 0.002 0.004" />
        </geometry>
      </collision>
    <collision name="pull_grip">
      <origin xyz="0.084 0 -0.009" rpy="0 0 0" />
      <geometry>
        <box size="0.018 0.06 0.006" />
        </geometry>
      </collision>
    </link>
  <joint name="bracket_pivot" type="revolute">
    <origin xyz="-0.225 0 -0.02" rpy="0 0 0" />
    <parent link="roof_hardware" />
    <child link="hinge_rod" />
    <axis xyz="0 0 1" />
    <limit effort="4" velocity="1.2" lower="-1.15" upper="1.15" />
    </joint>
  <joint name="main_hinge" type="revolute">
    <parent link="hinge_rod" />
    <child link="visor_panel" />
    <axis xyz="1 0 0" />
    <limit effort="3" velocity="1.5" lower="0" upper="1.45" />
    </joint>
  <joint name="extender_slide" type="prismatic">
    <origin xyz="0.31 -0.096 -0.036" rpy="0 0 0" />
    <parent link="visor_panel" />
    <child link="extender" />
    <axis xyz="1 0 0" />
    <limit effort="12" velocity="0.35" lower="0" upper="0.12" />
    </joint>
  </robot>
