<robot name="flat_incline_utility_weight_bench">
  <material name="matte_black_powdercoat">
    <color rgba="0.045 0.047 0.05 1" />
    </material>
  <material name="dark_pin_steel">
    <color rgba="0.22 0.23 0.24 1" />
    </material>
  <material name="brushed_hinge_steel">
    <color rgba="0.6 0.61 0.62 1" />
    </material>
  <material name="black_textured_vinyl">
    <color rgba="0.025 0.024 0.023 1" />
    </material>
  <material name="stitched_seam_grey">
    <color rgba="0.28 0.28 0.27 1" />
    </material>
  <material name="black_rubber">
    <color rgba="0.01 0.01 0.01 1" />
    </material>
  <link name="frame">
    <inertial>
      <origin xyz="-0.06 0 0.22" rpy="0 0 0" />
      <mass value="18" />
      <inertia ixx="0.6078" ixy="0" ixz="0" iyy="2.4504" iyz="0" izz="2.4774" />
      </inertial>
    <visual name="rectangular_base">
      <origin xyz="-0.075 0 0.048" rpy="0 0 0" />
      <geometry>
        <box size="1.18 0.42 0.026" />
        </geometry>
      <material name="matte_black_powdercoat">
        <color rgba="0.045 0.047 0.05 1" />
        </material>
      </visual>
    <visual name="side_rail_0">
      <origin xyz="-0.075 0.18 0.084" rpy="0 0 0" />
      <geometry>
        <box size="1.16 0.05 0.06" />
        </geometry>
      <material name="matte_black_powdercoat">
        <color rgba="0.045 0.047 0.05 1" />
        </material>
      </visual>
    <visual name="side_rail_1">
      <origin xyz="-0.075 -0.18 0.084" rpy="0 0 0" />
      <geometry>
        <box size="1.16 0.05 0.06" />
        </geometry>
      <material name="matte_black_powdercoat">
        <color rgba="0.045 0.047 0.05 1" />
        </material>
      </visual>
    <visual name="front_crossmember">
      <origin xyz="0.5 0 0.087" rpy="0 0 0" />
      <geometry>
        <box size="0.055 0.43 0.058" />
        </geometry>
      <material name="matte_black_powdercoat">
        <color rgba="0.045 0.047 0.05 1" />
        </material>
      </visual>
    <visual name="rear_crossmember">
      <origin xyz="-0.645 0 0.087" rpy="0 0 0" />
      <geometry>
        <box size="0.055 0.43 0.058" />
        </geometry>
      <material name="matte_black_powdercoat">
        <color rgba="0.045 0.047 0.05 1" />
        </material>
      </visual>
    <visual name="middle_crossmember">
      <origin xyz="-0.07 0 0.087" rpy="0 0 0" />
      <geometry>
        <box size="0.055 0.43 0.058" />
        </geometry>
      <material name="matte_black_powdercoat">
        <color rgba="0.045 0.047 0.05 1" />
        </material>
      </visual>
    <visual name="front_upright_0">
      <origin xyz="0.37 0.145 0.225" rpy="0 0 0" />
      <geometry>
        <box size="0.05 0.05 0.335" />
        </geometry>
      <material name="matte_black_powdercoat">
        <color rgba="0.045 0.047 0.05 1" />
        </material>
      </visual>
    <visual name="front_upright_1">
      <origin xyz="0.37 -0.145 0.225" rpy="0 0 0" />
      <geometry>
        <box size="0.05 0.05 0.335" />
        </geometry>
      <material name="matte_black_powdercoat">
        <color rgba="0.045 0.047 0.05 1" />
        </material>
      </visual>
    <visual name="front_outer_upright_0">
      <origin xyz="0.37 0.205 0.255" rpy="0 0 0" />
      <geometry>
        <box size="0.055 0.025 0.33" />
        </geometry>
      <material name="matte_black_powdercoat">
        <color rgba="0.045 0.047 0.05 1" />
        </material>
      </visual>
    <visual name="front_outer_upright_1">
      <origin xyz="0.37 -0.205 0.255" rpy="0 0 0" />
      <geometry>
        <box size="0.055 0.025 0.33" />
        </geometry>
      <material name="matte_black_powdercoat">
        <color rgba="0.045 0.047 0.05 1" />
        </material>
      </visual>
    <visual name="front_hinge_bridge">
      <origin xyz="0.37 0 0.37" rpy="0 0 0" />
      <geometry>
        <box size="0.075 0.37 0.035" />
        </geometry>
      <material name="matte_black_powdercoat">
        <color rgba="0.045 0.047 0.05 1" />
        </material>
      </visual>
    <visual name="seat_hinge_pin">
      <origin xyz="0.37 0 0.42" rpy="1.5708 0 0" />
      <geometry>
        <cylinder radius="0.014" length="0.39" />
        </geometry>
      <material name="brushed_hinge_steel">
        <color rgba="0.6 0.61 0.62 1" />
        </material>
      </visual>
    <visual name="junction_upright_0">
      <origin xyz="-0.06 0.152 0.23" rpy="0 0 0" />
      <geometry>
        <box size="0.05 0.05 0.35" />
        </geometry>
      <material name="matte_black_powdercoat">
        <color rgba="0.045 0.047 0.05 1" />
        </material>
      </visual>
    <visual name="junction_upright_1">
      <origin xyz="-0.06 -0.152 0.23" rpy="0 0 0" />
      <geometry>
        <box size="0.05 0.05 0.35" />
        </geometry>
      <material name="matte_black_powdercoat">
        <color rgba="0.045 0.047 0.05 1" />
        </material>
      </visual>
    <visual name="backrest_hinge_bridge">
      <origin xyz="-0.06 0 0.389" rpy="0 0 0" />
      <geometry>
        <box size="0.08 0.37 0.034" />
        </geometry>
      <material name="matte_black_powdercoat">
        <color rgba="0.045 0.047 0.05 1" />
        </material>
      </visual>
    <visual name="backrest_hinge_pin">
      <origin xyz="-0.06 0 0.42" rpy="1.5708 0 0" />
      <geometry>
        <cylinder radius="0.014" length="0.39" />
        </geometry>
      <material name="brushed_hinge_steel">
        <color rgba="0.6 0.61 0.62 1" />
        </material>
      </visual>
    <visual name="rear_pivot_bridge">
      <origin xyz="-0.625 0 0.087" rpy="0 0 0" />
      <geometry>
        <box size="0.23 0.05 0.04" />
        </geometry>
      <material name="matte_black_powdercoat">
        <color rgba="0.045 0.047 0.05 1" />
        </material>
      </visual>
    <visual name="rear_pivot_lug_0">
      <origin xyz="-0.625 0.05 0.142" rpy="0 0 0" />
      <geometry>
        <box size="0.06 0.03 0.09" />
        </geometry>
      <material name="matte_black_powdercoat">
        <color rgba="0.045 0.047 0.05 1" />
        </material>
      </visual>
    <visual name="rear_pivot_lug_1">
      <origin xyz="-0.625 -0.05 0.142" rpy="0 0 0" />
      <geometry>
        <box size="0.06 0.03 0.09" />
        </geometry>
      <material name="matte_black_powdercoat">
        <color rgba="0.045 0.047 0.05 1" />
        </material>
      </visual>
    <visual name="rear_support_pin">
      <origin xyz="-0.625 0 0.142" rpy="1.5708 0 0" />
      <geometry>
        <cylinder radius="0.012" length="0.145" />
        </geometry>
      <material name="brushed_hinge_steel">
        <color rgba="0.6 0.61 0.62 1" />
        </material>
      </visual>
    <visual name="incline_ladder_rail">
      <origin xyz="-0.36 0.058 0.255" rpy="0 -0.36 0" />
      <geometry>
        <box size="0.36 0.034 0.035" />
        </geometry>
      <material name="dark_pin_steel">
        <color rgba="0.22 0.23 0.24 1" />
        </material>
      </visual>
    <visual name="ladder_stanchion_0_0">
      <origin xyz="-0.5 0.058 0.17" rpy="0 0 0" />
      <geometry>
        <box size="0.04 0.084 0.23" />
        </geometry>
      <material name="matte_black_powdercoat">
        <color rgba="0.045 0.047 0.05 1" />
        </material>
      </visual>
    <visual name="ladder_stanchion_0_1">
      <origin xyz="-0.5 -0.058 0.17" rpy="0 0 0" />
      <geometry>
        <box size="0.04 0.084 0.23" />
        </geometry>
      <material name="matte_black_powdercoat">
        <color rgba="0.045 0.047 0.05 1" />
        </material>
      </visual>
    <visual name="ladder_stanchion_1_0">
      <origin xyz="-0.235 0.058 0.218" rpy="0 0 0" />
      <geometry>
        <box size="0.04 0.084 0.325" />
        </geometry>
      <material name="matte_black_powdercoat">
        <color rgba="0.045 0.047 0.05 1" />
        </material>
      </visual>
    <visual name="ladder_stanchion_1_1">
      <origin xyz="-0.235 -0.058 0.218" rpy="0 0 0" />
      <geometry>
        <box size="0.04 0.084 0.325" />
        </geometry>
      <material name="matte_black_powdercoat">
        <color rgba="0.045 0.047 0.05 1" />
        </material>
      </visual>
    <visual name="ladder_tooth_0">
      <origin xyz="-0.495 0.08 0.307" rpy="0 0 0" />
      <geometry>
        <box size="0.034 0.07 0.06" />
        </geometry>
      <material name="brushed_hinge_steel">
        <color rgba="0.6 0.61 0.62 1" />
        </material>
      </visual>
    <visual name="ladder_tooth_1">
      <origin xyz="-0.42 0.08 0.331" rpy="0 0 0" />
      <geometry>
        <box size="0.034 0.07 0.06" />
        </geometry>
      <material name="brushed_hinge_steel">
        <color rgba="0.6 0.61 0.62 1" />
        </material>
      </visual>
    <visual name="ladder_tooth_2">
      <origin xyz="-0.345 0.08 0.355" rpy="0 0 0" />
      <geometry>
        <box size="0.034 0.07 0.06" />
        </geometry>
      <material name="brushed_hinge_steel">
        <color rgba="0.6 0.61 0.62 1" />
        </material>
      </visual>
    <visual name="ladder_tooth_3">
      <origin xyz="-0.27 0.08 0.379" rpy="0 0 0" />
      <geometry>
        <box size="0.034 0.07 0.06" />
        </geometry>
      <material name="brushed_hinge_steel">
        <color rgba="0.6 0.61 0.62 1" />
        </material>
      </visual>
    <visual name="ladder_tooth_spine">
      <origin xyz="-0.38 0.092 0.33" rpy="0 0 0" />
      <geometry>
        <box size="0.3 0.016 0.03" />
        </geometry>
      <material name="dark_pin_steel">
        <color rgba="0.22 0.23 0.24 1" />
        </material>
      </visual>
    <visual name="front_handle">
      <geometry>
        <mesh filename="assets/meshes/front_carry_handle.obj" />
        </geometry>
      <material name="matte_black_powdercoat">
        <color rgba="0.045 0.047 0.05 1" />
        </material>
      </visual>
    <visual name="handle_mount_0">
      <origin xyz="0.502 0.105 0.087" rpy="0 0 0" />
      <geometry>
        <box size="0.07 0.04 0.085" />
        </geometry>
      <material name="matte_black_powdercoat">
        <color rgba="0.045 0.047 0.05 1" />
        </material>
      </visual>
    <visual name="handle_mount_1">
      <origin xyz="0.502 -0.105 0.087" rpy="0 0 0" />
      <geometry>
        <box size="0.07 0.04 0.085" />
        </geometry>
      <material name="matte_black_powdercoat">
        <color rgba="0.045 0.047 0.05 1" />
        </material>
      </visual>
    <visual name="wheel_mount_0">
      <origin xyz="0.555 0.242 0.078" rpy="0 0 0" />
      <geometry>
        <box size="0.095 0.04 0.07" />
        </geometry>
      <material name="matte_black_powdercoat">
        <color rgba="0.045 0.047 0.05 1" />
        </material>
      </visual>
    <visual name="wheel_bracket_web_0">
      <origin xyz="0.555 0.213 0.078" rpy="0 0 0" />
      <geometry>
        <box size="0.08 0.03 0.055" />
        </geometry>
      <material name="matte_black_powdercoat">
        <color rgba="0.045 0.047 0.05 1" />
        </material>
      </visual>
    <visual name="axle_stub_0">
      <origin xyz="0.585 0.25 0.055" rpy="1.5708 0 0" />
      <geometry>
        <cylinder radius="0.01" length="0.07" />
        </geometry>
      <material name="brushed_hinge_steel">
        <color rgba="0.6 0.61 0.62 1" />
        </material>
      </visual>
    <visual name="wheel_mount_1">
      <origin xyz="0.555 -0.242 0.078" rpy="0 0 0" />
      <geometry>
        <box size="0.095 0.04 0.07" />
        </geometry>
      <material name="matte_black_powdercoat">
        <color rgba="0.045 0.047 0.05 1" />
        </material>
      </visual>
    <visual name="wheel_bracket_web_1">
      <origin xyz="0.555 -0.213 0.078" rpy="0 0 0" />
      <geometry>
        <box size="0.08 0.03 0.055" />
        </geometry>
      <material name="matte_black_powdercoat">
        <color rgba="0.045 0.047 0.05 1" />
        </material>
      </visual>
    <visual name="axle_stub_1">
      <origin xyz="0.585 -0.25 0.055" rpy="1.5708 0 0" />
      <geometry>
        <cylinder radius="0.01" length="0.07" />
        </geometry>
      <material name="brushed_hinge_steel">
        <color rgba="0.6 0.61 0.62 1" />
        </material>
      </visual>
    <collision name="rectangular_base">
      <origin xyz="-0.075 0 0.048" rpy="0 0 0" />
      <geometry>
        <box size="1.18 0.42 0.026" />
        </geometry>
      </collision>
    <collision name="side_rail_0">
      <origin xyz="-0.075 0.18 0.084" rpy="0 0 0" />
      <geometry>
        <box size="1.16 0.05 0.06" />
        </geometry>
      </collision>
    <collision name="side_rail_1">
      <origin xyz="-0.075 -0.18 0.084" rpy="0 0 0" />
      <geometry>
        <box size="1.16 0.05 0.06" />
        </geometry>
      </collision>
    <collision name="front_crossmember">
      <origin xyz="0.5 0 0.087" rpy="0 0 0" />
      <geometry>
        <box size="0.055 0.43 0.058" />
        </geometry>
      </collision>
    <collision name="rear_crossmember">
      <origin xyz="-0.645 0 0.087" rpy="0 0 0" />
      <geometry>
        <box size="0.055 0.43 0.058" />
        </geometry>
      </collision>
    <collision name="middle_crossmember">
      <origin xyz="-0.07 0 0.087" rpy="0 0 0" />
      <geometry>
        <box size="0.055 0.43 0.058" />
        </geometry>
      </collision>
    <collision name="front_upright_0">
      <origin xyz="0.37 0.145 0.225" rpy="0 0 0" />
      <geometry>
        <box size="0.05 0.05 0.335" />
        </geometry>
      </collision>
    <collision name="front_upright_1">
      <origin xyz="0.37 -0.145 0.225" rpy="0 0 0" />
      <geometry>
        <box size="0.05 0.05 0.335" />
        </geometry>
      </collision>
    <collision name="front_outer_upright_0">
      <origin xyz="0.37 0.205 0.255" rpy="0 0 0" />
      <geometry>
        <box size="0.055 0.025 0.33" />
        </geometry>
      </collision>
    <collision name="front_outer_upright_1">
      <origin xyz="0.37 -0.205 0.255" rpy="0 0 0" />
      <geometry>
        <box size="0.055 0.025 0.33" />
        </geometry>
      </collision>
    <collision name="front_hinge_bridge">
      <origin xyz="0.37 0 0.37" rpy="0 0 0" />
      <geometry>
        <box size="0.075 0.37 0.035" />
        </geometry>
      </collision>
    <collision name="seat_hinge_pin">
      <origin xyz="0.37 0 0.42" rpy="1.5708 0 0" />
      <geometry>
        <cylinder radius="0.014" length="0.39" />
        </geometry>
      </collision>
    <collision name="junction_upright_0">
      <origin xyz="-0.06 0.152 0.23" rpy="0 0 0" />
      <geometry>
        <box size="0.05 0.05 0.35" />
        </geometry>
      </collision>
    <collision name="junction_upright_1">
      <origin xyz="-0.06 -0.152 0.23" rpy="0 0 0" />
      <geometry>
        <box size="0.05 0.05 0.35" />
        </geometry>
      </collision>
    <collision name="backrest_hinge_bridge">
      <origin xyz="-0.06 0 0.389" rpy="0 0 0" />
      <geometry>
        <box size="0.08 0.37 0.034" />
        </geometry>
      </collision>
    <collision name="backrest_hinge_pin">
      <origin xyz="-0.06 0 0.42" rpy="1.5708 0 0" />
      <geometry>
        <cylinder radius="0.014" length="0.39" />
        </geometry>
      </collision>
    <collision name="rear_pivot_bridge">
      <origin xyz="-0.625 0 0.087" rpy="0 0 0" />
      <geometry>
        <box size="0.23 0.05 0.04" />
        </geometry>
      </collision>
    <collision name="rear_pivot_lug_0">
      <origin xyz="-0.625 0.05 0.142" rpy="0 0 0" />
      <geometry>
        <box size="0.06 0.03 0.09" />
        </geometry>
      </collision>
    <collision name="rear_pivot_lug_1">
      <origin xyz="-0.625 -0.05 0.142" rpy="0 0 0" />
      <geometry>
        <box size="0.06 0.03 0.09" />
        </geometry>
      </collision>
    <collision name="rear_support_pin">
      <origin xyz="-0.625 0 0.142" rpy="1.5708 0 0" />
      <geometry>
        <cylinder radius="0.012" length="0.145" />
        </geometry>
      </collision>
    <collision name="incline_ladder_rail">
      <origin xyz="-0.36 0.058 0.255" rpy="0 -0.36 0" />
      <geometry>
        <box size="0.36 0.034 0.035" />
        </geometry>
      </collision>
    <collision name="ladder_stanchion_0_0">
      <origin xyz="-0.5 0.058 0.17" rpy="0 0 0" />
      <geometry>
        <box size="0.04 0.084 0.23" />
        </geometry>
      </collision>
    <collision name="ladder_stanchion_0_1">
      <origin xyz="-0.5 -0.058 0.17" rpy="0 0 0" />
      <geometry>
        <box size="0.04 0.084 0.23" />
        </geometry>
      </collision>
    <collision name="ladder_stanchion_1_0">
      <origin xyz="-0.235 0.058 0.218" rpy="0 0 0" />
      <geometry>
        <box size="0.04 0.084 0.325" />
        </geometry>
      </collision>
    <collision name="ladder_stanchion_1_1">
      <origin xyz="-0.235 -0.058 0.218" rpy="0 0 0" />
      <geometry>
        <box size="0.04 0.084 0.325" />
        </geometry>
      </collision>
    <collision name="ladder_tooth_0">
      <origin xyz="-0.495 0.08 0.307" rpy="0 0 0" />
      <geometry>
        <box size="0.034 0.07 0.06" />
        </geometry>
      </collision>
    <collision name="ladder_tooth_1">
      <origin xyz="-0.42 0.08 0.331" rpy="0 0 0" />
      <geometry>
        <box size="0.034 0.07 0.06" />
        </geometry>
      </collision>
    <collision name="ladder_tooth_2">
      <origin xyz="-0.345 0.08 0.355" rpy="0 0 0" />
      <geometry>
        <box size="0.034 0.07 0.06" />
        </geometry>
      </collision>
    <collision name="ladder_tooth_3">
      <origin xyz="-0.27 0.08 0.379" rpy="0 0 0" />
      <geometry>
        <box size="0.034 0.07 0.06" />
        </geometry>
      </collision>
    <collision name="ladder_tooth_spine">
      <origin xyz="-0.38 0.092 0.33" rpy="0 0 0" />
      <geometry>
        <box size="0.3 0.016 0.03" />
        </geometry>
      </collision>
    <collision name="front_handle">
      <geometry>
        <mesh filename="assets/meshes/front_carry_handle.obj" />
        </geometry>
      </collision>
    <collision name="handle_mount_0">
      <origin xyz="0.502 0.105 0.087" rpy="0 0 0" />
      <geometry>
        <box size="0.07 0.04 0.085" />
        </geometry>
      </collision>
    <collision name="handle_mount_1">
      <origin xyz="0.502 -0.105 0.087" rpy="0 0 0" />
      <geometry>
        <box size="0.07 0.04 0.085" />
        </geometry>
      </collision>
    <collision name="wheel_mount_0">
      <origin xyz="0.555 0.242 0.078" rpy="0 0 0" />
      <geometry>
        <box size="0.095 0.04 0.07" />
        </geometry>
      </collision>
    <collision name="wheel_bracket_web_0">
      <origin xyz="0.555 0.213 0.078" rpy="0 0 0" />
      <geometry>
        <box size="0.08 0.03 0.055" />
        </geometry>
      </collision>
    <collision name="axle_stub_0">
      <origin xyz="0.585 0.25 0.055" rpy="1.5708 0 0" />
      <geometry>
        <cylinder radius="0.01" length="0.07" />
        </geometry>
      </collision>
    <collision name="wheel_mount_1">
      <origin xyz="0.555 -0.242 0.078" rpy="0 0 0" />
      <geometry>
        <box size="0.095 0.04 0.07" />
        </geometry>
      </collision>
    <collision name="wheel_bracket_web_1">
      <origin xyz="0.555 -0.213 0.078" rpy="0 0 0" />
      <geometry>
        <box size="0.08 0.03 0.055" />
        </geometry>
      </collision>
    <collision name="axle_stub_1">
      <origin xyz="0.585 -0.25 0.055" rpy="1.5708 0 0" />
      <geometry>
        <cylinder radius="0.01" length="0.07" />
        </geometry>
      </collision>
    </link>
  <link name="backrest">
    <inertial>
      <origin xyz="-0.38 0 0.05" rpy="0 0 0" />
      <mass value="5" />
      <inertia ixx="0.0480417" ixy="0" ixz="0" iyy="0.256167" iyz="0" izz="0.298875" />
      </inertial>
    <visual name="back_pad">
      <origin xyz="-0.385 0 0.015" rpy="0 0 0" />
      <geometry>
        <mesh filename="assets/meshes/backrest_pad_rounded.obj" />
        </geometry>
      <material name="black_textured_vinyl">
        <color rgba="0.025 0.024 0.023 1" />
        </material>
      </visual>
    <visual name="back_seam_0">
      <origin xyz="-0.39 0.132 0.085" rpy="0 0 0" />
      <geometry>
        <box size="0.7 0.01 0.006" />
        </geometry>
      <material name="stitched_seam_grey">
        <color rgba="0.28 0.28 0.27 1" />
        </material>
      </visual>
    <visual name="back_seam_1">
      <origin xyz="-0.39 -0.132 0.085" rpy="0 0 0" />
      <geometry>
        <box size="0.7 0.01 0.006" />
        </geometry>
      <material name="stitched_seam_grey">
        <color rgba="0.28 0.28 0.27 1" />
        </material>
      </visual>
    <visual name="back_hinge_barrel">
      <origin xyz="0 0 0" rpy="1.5708 0 0" />
      <geometry>
        <cylinder radius="0.018" length="0.34" />
        </geometry>
      <material name="brushed_hinge_steel">
        <color rgba="0.6 0.61 0.62 1" />
        </material>
      </visual>
    <visual name="back_under_rail">
      <origin xyz="-0.39 0 0.014" rpy="0 0 0" />
      <geometry>
        <box size="0.58 0.05 0.026" />
        </geometry>
      <material name="dark_pin_steel">
        <color rgba="0.22 0.23 0.24 1" />
        </material>
      </visual>
    <collision name="back_pad">
      <origin xyz="-0.385 0 0.015" rpy="0 0 0" />
      <geometry>
        <mesh filename="assets/meshes/backrest_pad_rounded.obj" />
        </geometry>
      </collision>
    <collision name="back_seam_0">
      <origin xyz="-0.39 0.132 0.085" rpy="0 0 0" />
      <geometry>
        <box size="0.7 0.01 0.006" />
        </geometry>
      </collision>
    <collision name="back_seam_1">
      <origin xyz="-0.39 -0.132 0.085" rpy="0 0 0" />
      <geometry>
        <box size="0.7 0.01 0.006" />
        </geometry>
      </collision>
    <collision name="back_hinge_barrel">
      <origin xyz="0 0 0" rpy="1.5708 0 0" />
      <geometry>
        <cylinder radius="0.018" length="0.34" />
        </geometry>
      </collision>
    <collision name="back_under_rail">
      <origin xyz="-0.39 0 0.014" rpy="0 0 0" />
      <geometry>
        <box size="0.58 0.05 0.026" />
        </geometry>
      </collision>
    </link>
  <link name="seat">
    <inertial>
      <origin xyz="-0.2 0 0.05" rpy="0 0 0" />
      <mass value="3.4" />
      <inertia ixx="0.0326683" ixy="0" ixz="0" iyy="0.0517933" iyz="0" izz="0.080835" />
      </inertial>
    <visual name="seat_pad">
      <origin xyz="-0.2 0 0.015" rpy="0 0 0" />
      <geometry>
        <mesh filename="assets/meshes/seat_pad_rounded.obj" />
        </geometry>
      <material name="black_textured_vinyl">
        <color rgba="0.025 0.024 0.023 1" />
        </material>
      </visual>
    <visual name="seat_seam_0">
      <origin xyz="-0.2 0.13 0.085" rpy="0 0 0" />
      <geometry>
        <box size="0.31 0.01 0.006" />
        </geometry>
      <material name="stitched_seam_grey">
        <color rgba="0.28 0.28 0.27 1" />
        </material>
      </visual>
    <visual name="seat_seam_1">
      <origin xyz="-0.2 -0.13 0.085" rpy="0 0 0" />
      <geometry>
        <box size="0.31 0.01 0.006" />
        </geometry>
      <material name="stitched_seam_grey">
        <color rgba="0.28 0.28 0.27 1" />
        </material>
      </visual>
    <visual name="seat_hinge_barrel">
      <origin xyz="0 0 0" rpy="1.5708 0 0" />
      <geometry>
        <cylinder radius="0.018" length="0.335" />
        </geometry>
      <material name="brushed_hinge_steel">
        <color rgba="0.6 0.61 0.62 1" />
        </material>
      </visual>
    <visual name="seat_under_rail">
      <origin xyz="-0.19 0 0.007" rpy="0 0 0" />
      <geometry>
        <box size="0.32 0.05 0.026" />
        </geometry>
      <material name="dark_pin_steel">
        <color rgba="0.22 0.23 0.24 1" />
        </material>
      </visual>
    <collision name="seat_pad">
      <origin xyz="-0.2 0 0.015" rpy="0 0 0" />
      <geometry>
        <mesh filename="assets/meshes/seat_pad_rounded.obj" />
        </geometry>
      </collision>
    <collision name="seat_seam_0">
      <origin xyz="-0.2 0.13 0.085" rpy="0 0 0" />
      <geometry>
        <box size="0.31 0.01 0.006" />
        </geometry>
      </collision>
    <collision name="seat_seam_1">
      <origin xyz="-0.2 -0.13 0.085" rpy="0 0 0" />
      <geometry>
        <box size="0.31 0.01 0.006" />
        </geometry>
      </collision>
    <collision name="seat_hinge_barrel">
      <origin xyz="0 0 0" rpy="1.5708 0 0" />
      <geometry>
        <cylinder radius="0.018" length="0.335" />
        </geometry>
      </collision>
    <collision name="seat_under_rail">
      <origin xyz="-0.19 0 0.007" rpy="0 0 0" />
      <geometry>
        <box size="0.32 0.05 0.026" />
        </geometry>
      </collision>
    </link>
  <link name="rear_support_arm">
    <inertial>
      <origin xyz="0.16 0 0.15" rpy="0 0 0" />
      <mass value="1.3" />
      <inertia ixx="0.0168567" ixy="0" ixz="0" iyy="0.0265633" iyz="0" izz="0.0183733" />
      </inertial>
    <visual name="arm_tube">
      <geometry>
        <mesh filename="assets/meshes/rear_prop_arm_tube.obj" />
        </geometry>
      <material name="matte_black_powdercoat">
        <color rgba="0.045 0.047 0.05 1" />
        </material>
      </visual>
    <visual name="lower_bushing">
      <origin xyz="0 0 0" rpy="1.5708 0 0" />
      <geometry>
        <cylinder radius="0.024" length="0.06" />
        </geometry>
      <material name="brushed_hinge_steel">
        <color rgba="0.6 0.61 0.62 1" />
        </material>
      </visual>
    <visual name="upper_roller">
      <origin xyz="0.32 0 0.205" rpy="1.5708 0 0" />
      <geometry>
        <cylinder radius="0.018" length="0.155" />
        </geometry>
      <material name="brushed_hinge_steel">
        <color rgba="0.6 0.61 0.62 1" />
        </material>
      </visual>
    <collision name="arm_tube">
      <geometry>
        <mesh filename="assets/meshes/rear_prop_arm_tube.obj" />
        </geometry>
      </collision>
    <collision name="lower_bushing">
      <origin xyz="0 0 0" rpy="1.5708 0 0" />
      <geometry>
        <cylinder radius="0.024" length="0.06" />
        </geometry>
      </collision>
    <collision name="upper_roller">
      <origin xyz="0.32 0 0.205" rpy="1.5708 0 0" />
      <geometry>
        <cylinder radius="0.018" length="0.155" />
        </geometry>
      </collision>
    </link>
  <link name="wheel_0">
    <inertial>
      <origin xyz="0 0 0" rpy="0 0 1.5708" />
      <mass value="0.36" />
      <inertia ixx="0.00033573" ixy="0" ixz="0" iyy="0.00033573" iyz="0" izz="0.0005445" />
      </inertial>
    <visual name="tire">
      <origin xyz="0 0 0" rpy="0 0 1.5708" />
      <geometry>
        <mesh filename="assets/meshes/front_transport_wheel_tire.obj" />
        </geometry>
      <material name="black_rubber">
        <color rgba="0.01 0.01 0.01 1" />
        </material>
      </visual>
    <visual name="rim">
      <origin xyz="0 0 0" rpy="0 0 1.5708" />
      <geometry>
        <mesh filename="assets/meshes/front_transport_wheel_rim.obj" />
        </geometry>
      <material name="brushed_hinge_steel">
        <color rgba="0.6 0.61 0.62 1" />
        </material>
      </visual>
    <visual name="hub_sleeve">
      <origin xyz="0 0 0" rpy="1.5708 0 0" />
      <geometry>
        <cylinder radius="0.012" length="0.055" />
        </geometry>
      <material name="dark_pin_steel">
        <color rgba="0.22 0.23 0.24 1" />
        </material>
      </visual>
    <collision name="tire">
      <origin xyz="0 0 0" rpy="0 0 1.5708" />
      <geometry>
        <mesh filename="assets/meshes/front_transport_wheel_tire.obj" />
        </geometry>
      </collision>
    <collision name="rim">
      <origin xyz="0 0 0" rpy="0 0 1.5708" />
      <geometry>
        <mesh filename="assets/meshes/front_transport_wheel_rim.obj" />
        </geometry>
      </collision>
    <collision name="hub_sleeve">
      <origin xyz="0 0 0" rpy="1.5708 0 0" />
      <geometry>
        <cylinder radius="0.012" length="0.055" />
        </geometry>
      </collision>
    </link>
  <link name="wheel_1">
    <inertial>
      <origin xyz="0 0 0" rpy="0 0 1.5708" />
      <mass value="0.36" />
      <inertia ixx="0.00033573" ixy="0" ixz="0" iyy="0.00033573" iyz="0" izz="0.0005445" />
      </inertial>
    <visual name="tire">
      <origin xyz="0 0 0" rpy="0 0 1.5708" />
      <geometry>
        <mesh filename="assets/meshes/front_transport_wheel_tire.obj" />
        </geometry>
      <material name="black_rubber">
        <color rgba="0.01 0.01 0.01 1" />
        </material>
      </visual>
    <visual name="rim">
      <origin xyz="0 0 0" rpy="0 0 1.5708" />
      <geometry>
        <mesh filename="assets/meshes/front_transport_wheel_rim.obj" />
        </geometry>
      <material name="brushed_hinge_steel">
        <color rgba="0.6 0.61 0.62 1" />
        </material>
      </visual>
    <visual name="hub_sleeve">
      <origin xyz="0 0 0" rpy="1.5708 0 0" />
      <geometry>
        <cylinder radius="0.012" length="0.055" />
        </geometry>
      <material name="dark_pin_steel">
        <color rgba="0.22 0.23 0.24 1" />
        </material>
      </visual>
    <collision name="tire">
      <origin xyz="0 0 0" rpy="0 0 1.5708" />
      <geometry>
        <mesh filename="assets/meshes/front_transport_wheel_tire.obj" />
        </geometry>
      </collision>
    <collision name="rim">
      <origin xyz="0 0 0" rpy="0 0 1.5708" />
      <geometry>
        <mesh filename="assets/meshes/front_transport_wheel_rim.obj" />
        </geometry>
      </collision>
    <collision name="hub_sleeve">
      <origin xyz="0 0 0" rpy="1.5708 0 0" />
      <geometry>
        <cylinder radius="0.012" length="0.055" />
        </geometry>
      </collision>
    </link>
  <joint name="backrest_hinge" type="revolute">
    <origin xyz="-0.06 0 0.42" rpy="0 0 0" />
    <parent link="frame" />
    <child link="backrest" />
    <axis xyz="0 1 0" />
    <limit effort="70" velocity="1.2" lower="0" upper="1.05" />
    </joint>
  <joint name="seat_hinge" type="revolute">
    <origin xyz="0.37 0 0.42" rpy="0 0 0" />
    <parent link="frame" />
    <child link="seat" />
    <axis xyz="0 1 0" />
    <limit effort="45" velocity="1.1" lower="0" upper="0.42" />
    </joint>
  <joint name="rear_support_pivot" type="revolute">
    <origin xyz="-0.625 0 0.142" rpy="0 0 0" />
    <parent link="frame" />
    <child link="rear_support_arm" />
    <axis xyz="0 -1 0" />
    <limit effort="35" velocity="1.4" lower="-0.35" upper="0.65" />
    </joint>
  <joint name="wheel_spin_0" type="continuous">
    <origin xyz="0.585 0.292 0.055" rpy="0 0 0" />
    <parent link="frame" />
    <child link="wheel_0" />
    <axis xyz="0 1 0" />
    <limit effort="4" velocity="20" />
    </joint>
  <joint name="wheel_spin_1" type="continuous">
    <origin xyz="0.585 -0.292 0.055" rpy="0 0 0" />
    <parent link="frame" />
    <child link="wheel_1" />
    <axis xyz="0 1 0" />
    <limit effort="4" velocity="20" />
    </joint>
  </robot>
