<robot name="toy_coupe_opening_hood">
  <material name="body_red">
    <color rgba="0.82 0.06 0.035 1" />
    </material>
  <material name="dark_red">
    <color rgba="0.56 0.03 0.025 1" />
    </material>
  <material name="seam_black">
    <color rgba="0.015 0.015 0.017 1" />
    </material>
  <material name="black_rubber">
    <color rgba="0.02 0.02 0.022 1" />
    </material>
  <material name="bright_zinc">
    <color rgba="0.78 0.78 0.74 1" />
    </material>
  <material name="smoked_blue_glass">
    <color rgba="0.16 0.33 0.47 0.72" />
    </material>
  <material name="chrome">
    <color rgba="0.88 0.86 0.78 1" />
    </material>
  <link name="body">
    <visual name="lower_body_shell">
      <geometry>
        <mesh filename="assets/meshes/lower_body_shell.obj" />
        </geometry>
      <material name="body_red">
        <color rgba="0.82 0.06 0.035 1" />
        </material>
      </visual>
    <visual name="trunk_deck">
      <origin xyz="-0.058 0 0.047" rpy="0 0 0" />
      <geometry>
        <box size="0.056 0.058 0.012" />
        </geometry>
      <material name="body_red">
        <color rgba="0.82 0.06 0.035 1" />
        </material>
      </visual>
    <visual name="trunk_cross_seam">
      <origin xyz="-0.057 0 0.0534" rpy="0 0 0" />
      <geometry>
        <box size="0.05 0.001 0.001" />
        </geometry>
      <material name="seam_black">
        <color rgba="0.015 0.015 0.017 1" />
        </material>
      </visual>
    <visual name="trunk_seam_left">
      <origin xyz="-0.082 0.014 0.0534" rpy="0 0 0" />
      <geometry>
        <box size="0.001 0.022 0.001" />
        </geometry>
      <material name="seam_black">
        <color rgba="0.015 0.015 0.017 1" />
        </material>
      </visual>
    <visual name="trunk_seam_right">
      <origin xyz="-0.082 -0.014 0.0534" rpy="0 0 0" />
      <geometry>
        <box size="0.001 0.022 0.001" />
        </geometry>
      <material name="seam_black">
        <color rgba="0.015 0.015 0.017 1" />
        </material>
      </visual>
    <visual name="front_fender_left">
      <origin xyz="0.05 0.033 0.041" rpy="0 0 0" />
      <geometry>
        <box size="0.078 0.01 0.014" />
        </geometry>
      <material name="body_red">
        <color rgba="0.82 0.06 0.035 1" />
        </material>
      </visual>
    <visual name="rear_fender_left">
      <origin xyz="-0.065 0.034 0.041" rpy="0 0 0" />
      <geometry>
        <box size="0.066 0.011 0.015" />
        </geometry>
      <material name="body_red">
        <color rgba="0.82 0.06 0.035 1" />
        </material>
      </visual>
    <visual name="a_pillar_left">
      <origin xyz="0.028 0.038 0.0405" rpy="0 0 0" />
      <geometry>
        <box size="0.004 0.005 0.025" />
        </geometry>
      <material name="dark_red">
        <color rgba="0.56 0.03 0.025 1" />
        </material>
      </visual>
    <visual name="front_fender_right">
      <origin xyz="0.05 -0.033 0.041" rpy="0 0 0" />
      <geometry>
        <box size="0.078 0.01 0.014" />
        </geometry>
      <material name="body_red">
        <color rgba="0.82 0.06 0.035 1" />
        </material>
      </visual>
    <visual name="rear_fender_right">
      <origin xyz="-0.065 -0.034 0.041" rpy="0 0 0" />
      <geometry>
        <box size="0.066 0.011 0.015" />
        </geometry>
      <material name="body_red">
        <color rgba="0.82 0.06 0.035 1" />
        </material>
      </visual>
    <visual name="a_pillar_right">
      <origin xyz="0.028 -0.038 0.0405" rpy="0 0 0" />
      <geometry>
        <box size="0.004 0.005 0.025" />
        </geometry>
      <material name="dark_red">
        <color rgba="0.56 0.03 0.025 1" />
        </material>
      </visual>
    <visual name="roof_pillars">
      <geometry>
        <mesh filename="assets/meshes/roof_pillars.obj" />
        </geometry>
      <material name="body_red">
        <color rgba="0.82 0.06 0.035 1" />
        </material>
      </visual>
    <visual name="roof_skin">
      <origin xyz="-0.016 0 0.0715" rpy="0 0 0" />
      <geometry>
        <box size="0.032 0.047 0.0012" />
        </geometry>
      <material name="body_red">
        <color rgba="0.82 0.06 0.035 1" />
        </material>
      </visual>
    <visual name="windshield">
      <origin xyz="0.017 0 0.0585" rpy="0 -0.55 0" />
      <geometry>
        <box size="0.021 0.038 0.001" />
        </geometry>
      <material name="smoked_blue_glass">
        <color rgba="0.16 0.33 0.47 0.72" />
        </material>
      </visual>
    <visual name="rear_window">
      <origin xyz="-0.049 0 0.0578" rpy="0 0.55 0" />
      <geometry>
        <box size="0.02 0.038 0.001" />
        </geometry>
      <material name="smoked_blue_glass">
        <color rgba="0.16 0.33 0.47 0.72" />
        </material>
      </visual>
    <visual name="left_quarter_window">
      <origin xyz="-0.016 0.0258 0.058" rpy="0 0 0" />
      <geometry>
        <box size="0.034 0.001 0.011" />
        </geometry>
      <material name="smoked_blue_glass">
        <color rgba="0.16 0.33 0.47 0.72" />
        </material>
      </visual>
    <visual name="right_quarter_window">
      <origin xyz="-0.016 -0.0258 0.058" rpy="0 0 0" />
      <geometry>
        <box size="0.034 0.001 0.011" />
        </geometry>
      <material name="smoked_blue_glass">
        <color rgba="0.16 0.33 0.47 0.72" />
        </material>
      </visual>
    <visual name="front_bumper">
      <origin xyz="0.092 0 0.034" rpy="0 0 0" />
      <geometry>
        <box size="0.034 0.074 0.005" />
        </geometry>
      <material name="chrome">
        <color rgba="0.88 0.86 0.78 1" />
        </material>
      </visual>
    <visual name="rear_bumper">
      <origin xyz="-0.093 0 0.035" rpy="0 0 0" />
      <geometry>
        <box size="0.032 0.07 0.005" />
        </geometry>
      <material name="chrome">
        <color rgba="0.88 0.86 0.78 1" />
        </material>
      </visual>
    <visual name="hood_cowl">
      <origin xyz="0.025 0 0.047" rpy="0 0 0" />
      <geometry>
        <box size="0.007 0.056 0.003" />
        </geometry>
      <material name="dark_red">
        <color rgba="0.56 0.03 0.025 1" />
        </material>
      </visual>
    <visual name="hood_hinge_leaf_left">
      <origin xyz="0.0255 0.014 0.0495" rpy="0 0 0" />
      <geometry>
        <box size="0.006 0.005 0.003" />
        </geometry>
      <material name="seam_black">
        <color rgba="0.015 0.015 0.017 1" />
        </material>
      </visual>
    <visual name="hood_hinge_knuckle_left">
      <origin xyz="0.0255 0.014 0.0508" rpy="-1.5708 0 0" />
      <geometry>
        <cylinder radius="0.00135" length="0.007" />
        </geometry>
      <material name="seam_black">
        <color rgba="0.015 0.015 0.017 1" />
        </material>
      </visual>
    <visual name="hood_hinge_leaf_right">
      <origin xyz="0.0255 -0.014 0.0495" rpy="0 0 0" />
      <geometry>
        <box size="0.006 0.005 0.003" />
        </geometry>
      <material name="seam_black">
        <color rgba="0.015 0.015 0.017 1" />
        </material>
      </visual>
    <visual name="hood_hinge_knuckle_right">
      <origin xyz="0.0255 -0.014 0.0508" rpy="-1.5708 0 0" />
      <geometry>
        <cylinder radius="0.00135" length="0.007" />
        </geometry>
      <material name="seam_black">
        <color rgba="0.015 0.015 0.017 1" />
        </material>
      </visual>
    <visual name="front_axle">
      <origin xyz="0.06 0 0.0175" rpy="-1.5708 0 0" />
      <geometry>
        <cylinder radius="0.0025" length="0.0944" />
        </geometry>
      <material name="chrome">
        <color rgba="0.88 0.86 0.78 1" />
        </material>
      </visual>
    <visual name="rear_axle">
      <origin xyz="-0.066 0 0.0175" rpy="-1.5708 0 0" />
      <geometry>
        <cylinder radius="0.0025" length="0.0944" />
        </geometry>
      <material name="chrome">
        <color rgba="0.88 0.86 0.78 1" />
        </material>
      </visual>
    <visual name="front_axle_socket_left">
      <origin xyz="0.06 0.0385 0.025" rpy="0 0 0" />
      <geometry>
        <box size="0.01 0.007 0.018" />
        </geometry>
      <material name="seam_black">
        <color rgba="0.015 0.015 0.017 1" />
        </material>
      </visual>
    <visual name="front_axle_socket_right">
      <origin xyz="0.06 -0.0385 0.025" rpy="0 0 0" />
      <geometry>
        <box size="0.01 0.007 0.018" />
        </geometry>
      <material name="seam_black">
        <color rgba="0.015 0.015 0.017 1" />
        </material>
      </visual>
    <visual name="rear_axle_socket_left">
      <origin xyz="-0.066 0.0385 0.025" rpy="0 0 0" />
      <geometry>
        <box size="0.01 0.007 0.018" />
        </geometry>
      <material name="seam_black">
        <color rgba="0.015 0.015 0.017 1" />
        </material>
      </visual>
    <visual name="rear_axle_socket_right">
      <origin xyz="-0.066 -0.0385 0.025" rpy="0 0 0" />
      <geometry>
        <box size="0.01 0.007 0.018" />
        </geometry>
      <material name="seam_black">
        <color rgba="0.015 0.015 0.017 1" />
        </material>
      </visual>
    <collision name="lower_body_shell">
      <geometry>
        <mesh filename="assets/meshes/lower_body_shell.obj" />
        </geometry>
      </collision>
    <collision name="trunk_deck">
      <origin xyz="-0.058 0 0.047" rpy="0 0 0" />
      <geometry>
        <box size="0.056 0.058 0.012" />
        </geometry>
      </collision>
    <collision name="trunk_cross_seam">
      <origin xyz="-0.057 0 0.0534" rpy="0 0 0" />
      <geometry>
        <box size="0.05 0.001 0.001" />
        </geometry>
      </collision>
    <collision name="trunk_seam_left">
      <origin xyz="-0.082 0.014 0.0534" rpy="0 0 0" />
      <geometry>
        <box size="0.001 0.022 0.001" />
        </geometry>
      </collision>
    <collision name="trunk_seam_right">
      <origin xyz="-0.082 -0.014 0.0534" rpy="0 0 0" />
      <geometry>
        <box size="0.001 0.022 0.001" />
        </geometry>
      </collision>
    <collision name="front_fender_left">
      <origin xyz="0.05 0.033 0.041" rpy="0 0 0" />
      <geometry>
        <box size="0.078 0.01 0.014" />
        </geometry>
      </collision>
    <collision name="rear_fender_left">
      <origin xyz="-0.065 0.034 0.041" rpy="0 0 0" />
      <geometry>
        <box size="0.066 0.011 0.015" />
        </geometry>
      </collision>
    <collision name="a_pillar_left">
      <origin xyz="0.028 0.038 0.0405" rpy="0 0 0" />
      <geometry>
        <box size="0.004 0.005 0.025" />
        </geometry>
      </collision>
    <collision name="front_fender_right">
      <origin xyz="0.05 -0.033 0.041" rpy="0 0 0" />
      <geometry>
        <box size="0.078 0.01 0.014" />
        </geometry>
      </collision>
    <collision name="rear_fender_right">
      <origin xyz="-0.065 -0.034 0.041" rpy="0 0 0" />
      <geometry>
        <box size="0.066 0.011 0.015" />
        </geometry>
      </collision>
    <collision name="a_pillar_right">
      <origin xyz="0.028 -0.038 0.0405" rpy="0 0 0" />
      <geometry>
        <box size="0.004 0.005 0.025" />
        </geometry>
      </collision>
    <collision name="roof_pillars">
      <geometry>
        <mesh filename="assets/meshes/roof_pillars.obj" />
        </geometry>
      </collision>
    <collision name="roof_skin">
      <origin xyz="-0.016 0 0.0715" rpy="0 0 0" />
      <geometry>
        <box size="0.032 0.047 0.0012" />
        </geometry>
      </collision>
    <collision name="windshield">
      <origin xyz="0.017 0 0.0585" rpy="0 -0.55 0" />
      <geometry>
        <box size="0.021 0.038 0.001" />
        </geometry>
      </collision>
    <collision name="rear_window">
      <origin xyz="-0.049 0 0.0578" rpy="0 0.55 0" />
      <geometry>
        <box size="0.02 0.038 0.001" />
        </geometry>
      </collision>
    <collision name="left_quarter_window">
      <origin xyz="-0.016 0.0258 0.058" rpy="0 0 0" />
      <geometry>
        <box size="0.034 0.001 0.011" />
        </geometry>
      </collision>
    <collision name="right_quarter_window">
      <origin xyz="-0.016 -0.0258 0.058" rpy="0 0 0" />
      <geometry>
        <box size="0.034 0.001 0.011" />
        </geometry>
      </collision>
    <collision name="front_bumper">
      <origin xyz="0.092 0 0.034" rpy="0 0 0" />
      <geometry>
        <box size="0.034 0.074 0.005" />
        </geometry>
      </collision>
    <collision name="rear_bumper">
      <origin xyz="-0.093 0 0.035" rpy="0 0 0" />
      <geometry>
        <box size="0.032 0.07 0.005" />
        </geometry>
      </collision>
    <collision name="hood_cowl">
      <origin xyz="0.025 0 0.047" rpy="0 0 0" />
      <geometry>
        <box size="0.007 0.056 0.003" />
        </geometry>
      </collision>
    <collision name="hood_hinge_leaf_left">
      <origin xyz="0.0255 0.014 0.0495" rpy="0 0 0" />
      <geometry>
        <box size="0.006 0.005 0.003" />
        </geometry>
      </collision>
    <collision name="hood_hinge_knuckle_left">
      <origin xyz="0.0255 0.014 0.0508" rpy="-1.5708 0 0" />
      <geometry>
        <cylinder radius="0.00135" length="0.007" />
        </geometry>
      </collision>
    <collision name="hood_hinge_leaf_right">
      <origin xyz="0.0255 -0.014 0.0495" rpy="0 0 0" />
      <geometry>
        <box size="0.006 0.005 0.003" />
        </geometry>
      </collision>
    <collision name="hood_hinge_knuckle_right">
      <origin xyz="0.0255 -0.014 0.0508" rpy="-1.5708 0 0" />
      <geometry>
        <cylinder radius="0.00135" length="0.007" />
        </geometry>
      </collision>
    <collision name="front_axle">
      <origin xyz="0.06 0 0.0175" rpy="-1.5708 0 0" />
      <geometry>
        <cylinder radius="0.0025" length="0.0944" />
        </geometry>
      </collision>
    <collision name="rear_axle">
      <origin xyz="-0.066 0 0.0175" rpy="-1.5708 0 0" />
      <geometry>
        <cylinder radius="0.0025" length="0.0944" />
        </geometry>
      </collision>
    <collision name="front_axle_socket_left">
      <origin xyz="0.06 0.0385 0.025" rpy="0 0 0" />
      <geometry>
        <box size="0.01 0.007 0.018" />
        </geometry>
      </collision>
    <collision name="front_axle_socket_right">
      <origin xyz="0.06 -0.0385 0.025" rpy="0 0 0" />
      <geometry>
        <box size="0.01 0.007 0.018" />
        </geometry>
      </collision>
    <collision name="rear_axle_socket_left">
      <origin xyz="-0.066 0.0385 0.025" rpy="0 0 0" />
      <geometry>
        <box size="0.01 0.007 0.018" />
        </geometry>
      </collision>
    <collision name="rear_axle_socket_right">
      <origin xyz="-0.066 -0.0385 0.025" rpy="0 0 0" />
      <geometry>
        <box size="0.01 0.007 0.018" />
        </geometry>
      </collision>
    </link>
  <link name="hood">
    <visual name="hood_skin">
      <origin xyz="0.032 0 0.0016" rpy="0 0 0" />
      <geometry>
        <mesh filename="assets/meshes/hood_skin.obj" />
        </geometry>
      <material name="body_red">
        <color rgba="0.82 0.06 0.035 1" />
        </material>
      </visual>
    <visual name="left_hood_gap">
      <origin xyz="0.032 0.0262 0.0034" rpy="0 0 0" />
      <geometry>
        <box size="0.05888 0.001 0.0008" />
        </geometry>
      <material name="seam_black">
        <color rgba="0.015 0.015 0.017 1" />
        </material>
      </visual>
    <visual name="right_hood_gap">
      <origin xyz="0.032 -0.0262 0.0034" rpy="0 0 0" />
      <geometry>
        <box size="0.05888 0.001 0.0008" />
        </geometry>
      <material name="seam_black">
        <color rgba="0.015 0.015 0.017 1" />
        </material>
      </visual>
    <visual name="hood_hinge_barrel">
      <origin xyz="0.0005 0 0.0018" rpy="-1.5708 0 0" />
      <geometry>
        <cylinder radius="0.00145" length="0.021" />
        </geometry>
      <material name="seam_black">
        <color rgba="0.015 0.015 0.017 1" />
        </material>
      </visual>
    <collision name="hood_skin">
      <origin xyz="0.032 0 0.0016" rpy="0 0 0" />
      <geometry>
        <mesh filename="assets/meshes/hood_skin.obj" />
        </geometry>
      </collision>
    <collision name="left_hood_gap">
      <origin xyz="0.032 0.0262 0.0034" rpy="0 0 0" />
      <geometry>
        <box size="0.05888 0.001 0.0008" />
        </geometry>
      </collision>
    <collision name="right_hood_gap">
      <origin xyz="0.032 -0.0262 0.0034" rpy="0 0 0" />
      <geometry>
        <box size="0.05888 0.001 0.0008" />
        </geometry>
      </collision>
    <collision name="hood_hinge_barrel">
      <origin xyz="0.0005 0 0.0018" rpy="-1.5708 0 0" />
      <geometry>
        <cylinder radius="0.00145" length="0.021" />
        </geometry>
      </collision>
    </link>
  <link name="left_door">
    <visual name="door_panel">
      <origin xyz="-0.027 0 0.013" rpy="0 0 0" />
      <geometry>
        <box size="0.054 0.0024 0.026" />
        </geometry>
      <material name="body_red">
        <color rgba="0.82 0.06 0.035 1" />
        </material>
      </visual>
    <visual name="upper_cut">
      <origin xyz="-0.027 0.0012 0.025" rpy="0 0 0" />
      <geometry>
        <box size="0.0513 0.0012 0.0011" />
        </geometry>
      <material name="seam_black">
        <color rgba="0.015 0.015 0.017 1" />
        </material>
      </visual>
    <visual name="lower_cut">
      <origin xyz="-0.027 0.0012 0.001" rpy="0 0 0" />
      <geometry>
        <box size="0.04968 0.0012 0.001" />
        </geometry>
      <material name="seam_black">
        <color rgba="0.015 0.015 0.017 1" />
        </material>
      </visual>
    <visual name="front_cut">
      <origin xyz="-0.001 0.0012 0.013" rpy="0 0 0" />
      <geometry>
        <box size="0.001 0.0012 0.02392" />
        </geometry>
      <material name="seam_black">
        <color rgba="0.015 0.015 0.017 1" />
        </material>
      </visual>
    <visual name="rear_cut">
      <origin xyz="-0.053 0.0012 0.013" rpy="0 0 0" />
      <geometry>
        <box size="0.001 0.0012 0.02132" />
        </geometry>
      <material name="seam_black">
        <color rgba="0.015 0.015 0.017 1" />
        </material>
      </visual>
    <visual name="side_window">
      <origin xyz="-0.02052 0.0012 0.0182" rpy="0 0 0" />
      <geometry>
        <box size="0.02484 0.0012 0.01" />
        </geometry>
      <material name="smoked_blue_glass">
        <color rgba="0.16 0.33 0.47 0.72" />
        </material>
      </visual>
    <visual name="door_handle">
      <origin xyz="-0.03672 0.0012 0.01248" rpy="0 0 0" />
      <geometry>
        <box size="0.006 0.0012 0.0012" />
        </geometry>
      <material name="seam_black">
        <color rgba="0.015 0.015 0.017 1" />
        </material>
      </visual>
    <visual name="hinge_barrel">
      <origin xyz="0.0012 -0.00015 0.013" rpy="0 0 0" />
      <geometry>
        <cylinder radius="0.0016" length="0.0208" />
        </geometry>
      <material name="seam_black">
        <color rgba="0.015 0.015 0.017 1" />
        </material>
      </visual>
    <collision name="door_panel">
      <origin xyz="-0.027 0 0.013" rpy="0 0 0" />
      <geometry>
        <box size="0.054 0.0024 0.026" />
        </geometry>
      </collision>
    <collision name="upper_cut">
      <origin xyz="-0.027 0.0012 0.025" rpy="0 0 0" />
      <geometry>
        <box size="0.0513 0.0012 0.0011" />
        </geometry>
      </collision>
    <collision name="lower_cut">
      <origin xyz="-0.027 0.0012 0.001" rpy="0 0 0" />
      <geometry>
        <box size="0.04968 0.0012 0.001" />
        </geometry>
      </collision>
    <collision name="front_cut">
      <origin xyz="-0.001 0.0012 0.013" rpy="0 0 0" />
      <geometry>
        <box size="0.001 0.0012 0.02392" />
        </geometry>
      </collision>
    <collision name="rear_cut">
      <origin xyz="-0.053 0.0012 0.013" rpy="0 0 0" />
      <geometry>
        <box size="0.001 0.0012 0.02132" />
        </geometry>
      </collision>
    <collision name="side_window">
      <origin xyz="-0.02052 0.0012 0.0182" rpy="0 0 0" />
      <geometry>
        <box size="0.02484 0.0012 0.01" />
        </geometry>
      </collision>
    <collision name="door_handle">
      <origin xyz="-0.03672 0.0012 0.01248" rpy="0 0 0" />
      <geometry>
        <box size="0.006 0.0012 0.0012" />
        </geometry>
      </collision>
    <collision name="hinge_barrel">
      <origin xyz="0.0012 -0.00015 0.013" rpy="0 0 0" />
      <geometry>
        <cylinder radius="0.0016" length="0.0208" />
        </geometry>
      </collision>
    </link>
  <link name="right_door">
    <visual name="door_panel">
      <origin xyz="-0.027 0 0.013" rpy="0 0 0" />
      <geometry>
        <box size="0.054 0.0024 0.026" />
        </geometry>
      <material name="body_red">
        <color rgba="0.82 0.06 0.035 1" />
        </material>
      </visual>
    <visual name="upper_cut">
      <origin xyz="-0.027 -0.0012 0.025" rpy="0 0 0" />
      <geometry>
        <box size="0.0513 0.0012 0.0011" />
        </geometry>
      <material name="seam_black">
        <color rgba="0.015 0.015 0.017 1" />
        </material>
      </visual>
    <visual name="lower_cut">
      <origin xyz="-0.027 -0.0012 0.001" rpy="0 0 0" />
      <geometry>
        <box size="0.04968 0.0012 0.001" />
        </geometry>
      <material name="seam_black">
        <color rgba="0.015 0.015 0.017 1" />
        </material>
      </visual>
    <visual name="front_cut">
      <origin xyz="-0.001 -0.0012 0.013" rpy="0 0 0" />
      <geometry>
        <box size="0.001 0.0012 0.02392" />
        </geometry>
      <material name="seam_black">
        <color rgba="0.015 0.015 0.017 1" />
        </material>
      </visual>
    <visual name="rear_cut">
      <origin xyz="-0.053 -0.0012 0.013" rpy="0 0 0" />
      <geometry>
        <box size="0.001 0.0012 0.02132" />
        </geometry>
      <material name="seam_black">
        <color rgba="0.015 0.015 0.017 1" />
        </material>
      </visual>
    <visual name="side_window">
      <origin xyz="-0.02052 -0.0012 0.0182" rpy="0 0 0" />
      <geometry>
        <box size="0.02484 0.0012 0.01" />
        </geometry>
      <material name="smoked_blue_glass">
        <color rgba="0.16 0.33 0.47 0.72" />
        </material>
      </visual>
    <visual name="door_handle">
      <origin xyz="-0.03672 -0.0012 0.01248" rpy="0 0 0" />
      <geometry>
        <box size="0.006 0.0012 0.0012" />
        </geometry>
      <material name="seam_black">
        <color rgba="0.015 0.015 0.017 1" />
        </material>
      </visual>
    <visual name="hinge_barrel">
      <origin xyz="0.0012 0.00015 0.013" rpy="0 0 0" />
      <geometry>
        <cylinder radius="0.0016" length="0.0208" />
        </geometry>
      <material name="seam_black">
        <color rgba="0.015 0.015 0.017 1" />
        </material>
      </visual>
    <collision name="door_panel">
      <origin xyz="-0.027 0 0.013" rpy="0 0 0" />
      <geometry>
        <box size="0.054 0.0024 0.026" />
        </geometry>
      </collision>
    <collision name="upper_cut">
      <origin xyz="-0.027 -0.0012 0.025" rpy="0 0 0" />
      <geometry>
        <box size="0.0513 0.0012 0.0011" />
        </geometry>
      </collision>
    <collision name="lower_cut">
      <origin xyz="-0.027 -0.0012 0.001" rpy="0 0 0" />
      <geometry>
        <box size="0.04968 0.0012 0.001" />
        </geometry>
      </collision>
    <collision name="front_cut">
      <origin xyz="-0.001 -0.0012 0.013" rpy="0 0 0" />
      <geometry>
        <box size="0.001 0.0012 0.02392" />
        </geometry>
      </collision>
    <collision name="rear_cut">
      <origin xyz="-0.053 -0.0012 0.013" rpy="0 0 0" />
      <geometry>
        <box size="0.001 0.0012 0.02132" />
        </geometry>
      </collision>
    <collision name="side_window">
      <origin xyz="-0.02052 -0.0012 0.0182" rpy="0 0 0" />
      <geometry>
        <box size="0.02484 0.0012 0.01" />
        </geometry>
      </collision>
    <collision name="door_handle">
      <origin xyz="-0.03672 -0.0012 0.01248" rpy="0 0 0" />
      <geometry>
        <box size="0.006 0.0012 0.0012" />
        </geometry>
      </collision>
    <collision name="hinge_barrel">
      <origin xyz="0.0012 0.00015 0.013" rpy="0 0 0" />
      <geometry>
        <cylinder radius="0.0016" length="0.0208" />
        </geometry>
      </collision>
    </link>
  <link name="front_left_wheel">
    <visual name="tire">
      <origin xyz="0 0 0" rpy="0 0 1.5708" />
      <geometry>
        <mesh filename="assets/meshes/front_left_tire.obj" />
        </geometry>
      <material name="black_rubber">
        <color rgba="0.02 0.02 0.022 1" />
        </material>
      </visual>
    <visual name="rim">
      <origin xyz="0 0 0" rpy="0 0 1.5708" />
      <geometry>
        <mesh filename="assets/meshes/front_left_rim.obj" />
        </geometry>
      <material name="bright_zinc">
        <color rgba="0.78 0.78 0.74 1" />
        </material>
      </visual>
    <visual name="hub_cap">
      <origin xyz="0 0 0" rpy="0 0 1.5708" />
      <geometry>
        <cylinder radius="0.0031" length="0.01104" />
        </geometry>
      <material name="bright_zinc">
        <color rgba="0.78 0.78 0.74 1" />
        </material>
      </visual>
    <collision name="tire">
      <origin xyz="0 0 0" rpy="0 0 1.5708" />
      <geometry>
        <mesh filename="assets/meshes/front_left_tire.obj" />
        </geometry>
      </collision>
    <collision name="rim">
      <origin xyz="0 0 0" rpy="0 0 1.5708" />
      <geometry>
        <mesh filename="assets/meshes/front_left_rim.obj" />
        </geometry>
      </collision>
    <collision name="hub_cap">
      <origin xyz="0 0 0" rpy="0 0 1.5708" />
      <geometry>
        <cylinder radius="0.0031" length="0.01104" />
        </geometry>
      </collision>
    </link>
  <link name="front_right_wheel">
    <visual name="tire">
      <origin xyz="0 0 0" rpy="0 0 -1.5708" />
      <geometry>
        <mesh filename="assets/meshes/front_right_tire.obj" />
        </geometry>
      <material name="black_rubber">
        <color rgba="0.02 0.02 0.022 1" />
        </material>
      </visual>
    <visual name="rim">
      <origin xyz="0 0 0" rpy="0 0 -1.5708" />
      <geometry>
        <mesh filename="assets/meshes/front_right_rim.obj" />
        </geometry>
      <material name="bright_zinc">
        <color rgba="0.78 0.78 0.74 1" />
        </material>
      </visual>
    <visual name="hub_cap">
      <origin xyz="0 0 0" rpy="0 0 -1.5708" />
      <geometry>
        <cylinder radius="0.0031" length="0.01104" />
        </geometry>
      <material name="bright_zinc">
        <color rgba="0.78 0.78 0.74 1" />
        </material>
      </visual>
    <collision name="tire">
      <origin xyz="0 0 0" rpy="0 0 -1.5708" />
      <geometry>
        <mesh filename="assets/meshes/front_right_tire.obj" />
        </geometry>
      </collision>
    <collision name="rim">
      <origin xyz="0 0 0" rpy="0 0 -1.5708" />
      <geometry>
        <mesh filename="assets/meshes/front_right_rim.obj" />
        </geometry>
      </collision>
    <collision name="hub_cap">
      <origin xyz="0 0 0" rpy="0 0 -1.5708" />
      <geometry>
        <cylinder radius="0.0031" length="0.01104" />
        </geometry>
      </collision>
    </link>
  <link name="rear_left_wheel">
    <visual name="tire">
      <origin xyz="0 0 0" rpy="0 0 1.5708" />
      <geometry>
        <mesh filename="assets/meshes/rear_left_tire.obj" />
        </geometry>
      <material name="black_rubber">
        <color rgba="0.02 0.02 0.022 1" />
        </material>
      </visual>
    <visual name="rim">
      <origin xyz="0 0 0" rpy="0 0 1.5708" />
      <geometry>
        <mesh filename="assets/meshes/rear_left_rim.obj" />
        </geometry>
      <material name="bright_zinc">
        <color rgba="0.78 0.78 0.74 1" />
        </material>
      </visual>
    <visual name="hub_cap">
      <origin xyz="0 0 0" rpy="0 0 1.5708" />
      <geometry>
        <cylinder radius="0.0031" length="0.01104" />
        </geometry>
      <material name="bright_zinc">
        <color rgba="0.78 0.78 0.74 1" />
        </material>
      </visual>
    <collision name="tire">
      <origin xyz="0 0 0" rpy="0 0 1.5708" />
      <geometry>
        <mesh filename="assets/meshes/rear_left_tire.obj" />
        </geometry>
      </collision>
    <collision name="rim">
      <origin xyz="0 0 0" rpy="0 0 1.5708" />
      <geometry>
        <mesh filename="assets/meshes/rear_left_rim.obj" />
        </geometry>
      </collision>
    <collision name="hub_cap">
      <origin xyz="0 0 0" rpy="0 0 1.5708" />
      <geometry>
        <cylinder radius="0.0031" length="0.01104" />
        </geometry>
      </collision>
    </link>
  <link name="rear_right_wheel">
    <visual name="tire">
      <origin xyz="0 0 0" rpy="0 0 -1.5708" />
      <geometry>
        <mesh filename="assets/meshes/rear_right_tire.obj" />
        </geometry>
      <material name="black_rubber">
        <color rgba="0.02 0.02 0.022 1" />
        </material>
      </visual>
    <visual name="rim">
      <origin xyz="0 0 0" rpy="0 0 -1.5708" />
      <geometry>
        <mesh filename="assets/meshes/rear_right_rim.obj" />
        </geometry>
      <material name="bright_zinc">
        <color rgba="0.78 0.78 0.74 1" />
        </material>
      </visual>
    <visual name="hub_cap">
      <origin xyz="0 0 0" rpy="0 0 -1.5708" />
      <geometry>
        <cylinder radius="0.0031" length="0.01104" />
        </geometry>
      <material name="bright_zinc">
        <color rgba="0.78 0.78 0.74 1" />
        </material>
      </visual>
    <collision name="tire">
      <origin xyz="0 0 0" rpy="0 0 -1.5708" />
      <geometry>
        <mesh filename="assets/meshes/rear_right_tire.obj" />
        </geometry>
      </collision>
    <collision name="rim">
      <origin xyz="0 0 0" rpy="0 0 -1.5708" />
      <geometry>
        <mesh filename="assets/meshes/rear_right_rim.obj" />
        </geometry>
      </collision>
    <collision name="hub_cap">
      <origin xyz="0 0 0" rpy="0 0 -1.5708" />
      <geometry>
        <cylinder radius="0.0031" length="0.01104" />
        </geometry>
      </collision>
    </link>
  <joint name="hood_hinge" type="revolute">
    <origin xyz="0.025 0 0.049" rpy="0 0 0" />
    <parent link="body" />
    <child link="hood" />
    <axis xyz="0 -1 0" />
    <limit effort="0.8" velocity="2" lower="0" upper="1.12" />
    </joint>
  <joint name="left_door_hinge" type="revolute">
    <origin xyz="0.026 0.0415 0.0275" rpy="0 0 0" />
    <parent link="body" />
    <child link="left_door" />
    <axis xyz="0 0 -1" />
    <limit effort="0.6" velocity="2" lower="0" upper="1.15" />
    </joint>
  <joint name="right_door_hinge" type="revolute">
    <origin xyz="0.026 -0.0415 0.0275" rpy="0 0 0" />
    <parent link="body" />
    <child link="right_door" />
    <axis xyz="0 0 1" />
    <limit effort="0.6" velocity="2" lower="0" upper="1.15" />
    </joint>
  <joint name="front_left_wheel_spin" type="continuous">
    <origin xyz="0.06 0.052 0.0175" rpy="0 0 0" />
    <parent link="body" />
    <child link="front_left_wheel" />
    <axis xyz="0 1 0" />
    <limit effort="0.25" velocity="30" />
    </joint>
  <joint name="front_right_wheel_spin" type="continuous">
    <origin xyz="0.06 -0.052 0.0175" rpy="0 0 0" />
    <parent link="body" />
    <child link="front_right_wheel" />
    <axis xyz="0 1 0" />
    <limit effort="0.25" velocity="30" />
    </joint>
  <joint name="rear_left_wheel_spin" type="continuous">
    <origin xyz="-0.066 0.052 0.0175" rpy="0 0 0" />
    <parent link="body" />
    <child link="rear_left_wheel" />
    <axis xyz="0 1 0" />
    <limit effort="0.25" velocity="30" />
    </joint>
  <joint name="rear_right_wheel_spin" type="continuous">
    <origin xyz="-0.066 -0.052 0.0175" rpy="0 0 0" />
    <parent link="body" />
    <child link="rear_right_wheel" />
    <axis xyz="0 1 0" />
    <limit effort="0.25" velocity="30" />
    </joint>
  </robot>
