<robot name="satellite_pedestal_dish">
  <material name="galvanized_steel">
    <color rgba="0.58 0.61 0.62 1" />
    </material>
  <material name="dark_powder_coat">
    <color rgba="0.08 0.09 0.09 1" />
    </material>
  <material name="matte_white_reflector">
    <color rgba="0.88 0.88 0.84 1" />
    </material>
  <material name="black_rubber">
    <color rgba="0.02 0.02 0.018 1" />
    </material>
  <material name="feed_gray">
    <color rgba="0.34 0.36 0.37 1" />
    </material>
  <link name="pedestal">
    <visual name="base_foot">
      <origin xyz="0 0 0.06" rpy="0 0 0" />
      <geometry>
        <cylinder radius="0.55" length="0.12" />
        </geometry>
      <material name="black_rubber">
        <color rgba="0.02 0.02 0.018 1" />
        </material>
      </visual>
    <visual name="pedestal_column">
      <origin xyz="0 0 0.72" rpy="0 0 0" />
      <geometry>
        <cylinder radius="0.17" length="1.2" />
        </geometry>
      <material name="galvanized_steel">
        <color rgba="0.58 0.61 0.62 1" />
        </material>
      </visual>
    <visual name="fixed_turntable">
      <origin xyz="0 0 1.38" rpy="0 0 0" />
      <geometry>
        <cylinder radius="0.34" length="0.12" />
        </geometry>
      <material name="dark_powder_coat">
        <color rgba="0.08 0.09 0.09 1" />
        </material>
      </visual>
    <collision name="base_foot">
      <origin xyz="0 0 0.06" rpy="0 0 0" />
      <geometry>
        <cylinder radius="0.55" length="0.12" />
        </geometry>
      </collision>
    <collision name="pedestal_column">
      <origin xyz="0 0 0.72" rpy="0 0 0" />
      <geometry>
        <cylinder radius="0.17" length="1.2" />
        </geometry>
      </collision>
    <collision name="fixed_turntable">
      <origin xyz="0 0 1.38" rpy="0 0 0" />
      <geometry>
        <cylinder radius="0.34" length="0.12" />
        </geometry>
      </collision>
    </link>
  <link name="yaw_head">
    <visual name="rotating_turntable">
      <origin xyz="0 0 0.06" rpy="0 0 0" />
      <geometry>
        <cylinder radius="0.38" length="0.12" />
        </geometry>
      <material name="dark_powder_coat">
        <color rgba="0.08 0.09 0.09 1" />
        </material>
      </visual>
    <visual name="azimuth_neck">
      <origin xyz="0 0 0.23" rpy="0 0 0" />
      <geometry>
        <cylinder radius="0.13" length="0.22" />
        </geometry>
      <material name="galvanized_steel">
        <color rgba="0.58 0.61 0.62 1" />
        </material>
      </visual>
    <visual name="yoke_base">
      <origin xyz="-0.34 0 0.37" rpy="0 0 0" />
      <geometry>
        <box size="0.3 1.85 0.08" />
        </geometry>
      <material name="dark_powder_coat">
        <color rgba="0.08 0.09 0.09 1" />
        </material>
      </visual>
    <visual name="azimuth_saddle">
      <origin xyz="-0.205 0 0.32" rpy="0 0 0" />
      <geometry>
        <box size="0.22 0.28 0.1" />
        </geometry>
      <material name="dark_powder_coat">
        <color rgba="0.08 0.09 0.09 1" />
        </material>
      </visual>
    <visual name="yoke_post_0">
      <origin xyz="-0.34 -0.82 0.66" rpy="0 0 0" />
      <geometry>
        <box size="0.16 0.1 0.58" />
        </geometry>
      <material name="dark_powder_coat">
        <color rgba="0.08 0.09 0.09 1" />
        </material>
      </visual>
    <visual name="lower_lug_0">
      <origin xyz="-0.13 -0.82 0.6" rpy="0 0 0" />
      <geometry>
        <box size="0.42 0.1 0.12" />
        </geometry>
      <material name="dark_powder_coat">
        <color rgba="0.08 0.09 0.09 1" />
        </material>
      </visual>
    <visual name="upper_lug_0">
      <origin xyz="-0.13 -0.82 0.96" rpy="0 0 0" />
      <geometry>
        <box size="0.42 0.1 0.12" />
        </geometry>
      <material name="dark_powder_coat">
        <color rgba="0.08 0.09 0.09 1" />
        </material>
      </visual>
    <visual name="bearing_ring_0">
      <origin xyz="0 -0.82 0.78" rpy="0 0 0" />
      <geometry>
        <mesh filename="assets/meshes/bearing_ring_0_mesh.obj" />
        </geometry>
      <material name="dark_powder_coat">
        <color rgba="0.08 0.09 0.09 1" />
        </material>
      </visual>
    <visual name="yoke_post_1">
      <origin xyz="-0.34 0.82 0.66" rpy="0 0 0" />
      <geometry>
        <box size="0.16 0.1 0.58" />
        </geometry>
      <material name="dark_powder_coat">
        <color rgba="0.08 0.09 0.09 1" />
        </material>
      </visual>
    <visual name="lower_lug_1">
      <origin xyz="-0.13 0.82 0.6" rpy="0 0 0" />
      <geometry>
        <box size="0.42 0.1 0.12" />
        </geometry>
      <material name="dark_powder_coat">
        <color rgba="0.08 0.09 0.09 1" />
        </material>
      </visual>
    <visual name="upper_lug_1">
      <origin xyz="-0.13 0.82 0.96" rpy="0 0 0" />
      <geometry>
        <box size="0.42 0.1 0.12" />
        </geometry>
      <material name="dark_powder_coat">
        <color rgba="0.08 0.09 0.09 1" />
        </material>
      </visual>
    <visual name="bearing_ring_1">
      <origin xyz="0 0.82 0.78" rpy="0 0 0" />
      <geometry>
        <mesh filename="assets/meshes/bearing_ring_1_mesh.obj" />
        </geometry>
      <material name="dark_powder_coat">
        <color rgba="0.08 0.09 0.09 1" />
        </material>
      </visual>
    <visual name="rear_cross_tube">
      <origin xyz="-0.18 0 0.88" rpy="-1.5708 0 0" />
      <geometry>
        <cylinder radius="0.026" length="1.66" />
        </geometry>
      <material name="dark_powder_coat">
        <color rgba="0.08 0.09 0.09 1" />
        </material>
      </visual>
    <collision name="rotating_turntable">
      <origin xyz="0 0 0.06" rpy="0 0 0" />
      <geometry>
        <cylinder radius="0.38" length="0.12" />
        </geometry>
      </collision>
    <collision name="azimuth_neck">
      <origin xyz="0 0 0.23" rpy="0 0 0" />
      <geometry>
        <cylinder radius="0.13" length="0.22" />
        </geometry>
      </collision>
    <collision name="yoke_base">
      <origin xyz="-0.34 0 0.37" rpy="0 0 0" />
      <geometry>
        <box size="0.3 1.85 0.08" />
        </geometry>
      </collision>
    <collision name="azimuth_saddle">
      <origin xyz="-0.205 0 0.32" rpy="0 0 0" />
      <geometry>
        <box size="0.22 0.28 0.1" />
        </geometry>
      </collision>
    <collision name="yoke_post_0">
      <origin xyz="-0.34 -0.82 0.66" rpy="0 0 0" />
      <geometry>
        <box size="0.16 0.1 0.58" />
        </geometry>
      </collision>
    <collision name="lower_lug_0">
      <origin xyz="-0.13 -0.82 0.6" rpy="0 0 0" />
      <geometry>
        <box size="0.42 0.1 0.12" />
        </geometry>
      </collision>
    <collision name="upper_lug_0">
      <origin xyz="-0.13 -0.82 0.96" rpy="0 0 0" />
      <geometry>
        <box size="0.42 0.1 0.12" />
        </geometry>
      </collision>
    <collision name="bearing_ring_0">
      <origin xyz="0 -0.82 0.78" rpy="0 0 0" />
      <geometry>
        <mesh filename="assets/meshes/bearing_ring_0_mesh.obj" />
        </geometry>
      </collision>
    <collision name="yoke_post_1">
      <origin xyz="-0.34 0.82 0.66" rpy="0 0 0" />
      <geometry>
        <box size="0.16 0.1 0.58" />
        </geometry>
      </collision>
    <collision name="lower_lug_1">
      <origin xyz="-0.13 0.82 0.6" rpy="0 0 0" />
      <geometry>
        <box size="0.42 0.1 0.12" />
        </geometry>
      </collision>
    <collision name="upper_lug_1">
      <origin xyz="-0.13 0.82 0.96" rpy="0 0 0" />
      <geometry>
        <box size="0.42 0.1 0.12" />
        </geometry>
      </collision>
    <collision name="bearing_ring_1">
      <origin xyz="0 0.82 0.78" rpy="0 0 0" />
      <geometry>
        <mesh filename="assets/meshes/bearing_ring_1_mesh.obj" />
        </geometry>
      </collision>
    <collision name="rear_cross_tube">
      <origin xyz="-0.18 0 0.88" rpy="-1.5708 0 0" />
      <geometry>
        <cylinder radius="0.026" length="1.66" />
        </geometry>
      </collision>
    </link>
  <link name="dish_frame">
    <visual name="reflector_shell">
      <geometry>
        <mesh filename="assets/meshes/parabolic_reflector.obj" />
        </geometry>
      <material name="matte_white_reflector">
        <color rgba="0.88 0.88 0.84 1" />
        </material>
      </visual>
    <visual name="rear_support_frame">
      <geometry>
        <mesh filename="assets/meshes/rear_support_frame.obj" />
        </geometry>
      <material name="dark_powder_coat">
        <color rgba="0.08 0.09 0.09 1" />
        </material>
      </visual>
    <visual name="trunnion_shaft">
      <origin xyz="0 0 0" rpy="-1.5708 0 0" />
      <geometry>
        <cylinder radius="0.081" length="1.74" />
        </geometry>
      <material name="galvanized_steel">
        <color rgba="0.58 0.61 0.62 1" />
        </material>
      </visual>
    <visual name="rear_hub">
      <origin xyz="-0.015 0 0" rpy="0 1.5708 0" />
      <geometry>
        <cylinder radius="0.09" length="0.065" />
        </geometry>
      <material name="dark_powder_coat">
        <color rgba="0.08 0.09 0.09 1" />
        </material>
      </visual>
    <visual name="feed_arm">
      <geometry>
        <mesh filename="assets/meshes/feed_arm_mesh.obj" />
        </geometry>
      <material name="galvanized_steel">
        <color rgba="0.58 0.61 0.62 1" />
        </material>
      </visual>
    <visual name="feed_horn">
      <origin xyz="0.47 0 0" rpy="0 1.5708 0" />
      <geometry>
        <cylinder radius="0.06" length="0.14" />
        </geometry>
      <material name="feed_gray">
        <color rgba="0.34 0.36 0.37 1" />
        </material>
      </visual>
    <visual name="feed_arm_boss">
      <origin xyz="0.41 0 -0.08" rpy="0 0 0" />
      <geometry>
        <sphere radius="0.025" />
        </geometry>
      <material name="feed_gray">
        <color rgba="0.34 0.36 0.37 1" />
        </material>
      </visual>
    <collision name="reflector_shell">
      <geometry>
        <mesh filename="assets/meshes/parabolic_reflector.obj" />
        </geometry>
      </collision>
    <collision name="rear_support_frame">
      <geometry>
        <mesh filename="assets/meshes/rear_support_frame.obj" />
        </geometry>
      </collision>
    <collision name="trunnion_shaft">
      <origin xyz="0 0 0" rpy="-1.5708 0 0" />
      <geometry>
        <cylinder radius="0.081" length="1.74" />
        </geometry>
      </collision>
    <collision name="rear_hub">
      <origin xyz="-0.015 0 0" rpy="0 1.5708 0" />
      <geometry>
        <cylinder radius="0.09" length="0.065" />
        </geometry>
      </collision>
    <collision name="feed_arm">
      <geometry>
        <mesh filename="assets/meshes/feed_arm_mesh.obj" />
        </geometry>
      </collision>
    <collision name="feed_horn">
      <origin xyz="0.47 0 0" rpy="0 1.5708 0" />
      <geometry>
        <cylinder radius="0.06" length="0.14" />
        </geometry>
      </collision>
    <collision name="feed_arm_boss">
      <origin xyz="0.41 0 -0.08" rpy="0 0 0" />
      <geometry>
        <sphere radius="0.025" />
        </geometry>
      </collision>
    </link>
  <joint name="azimuth_axis" type="continuous">
    <origin xyz="0 0 1.44" rpy="0 0 0" />
    <parent link="pedestal" />
    <child link="yaw_head" />
    <axis xyz="0 0 1" />
    <limit effort="450" velocity="0.45" />
    </joint>
  <joint name="elevation_axis" type="revolute">
    <origin xyz="0 0 0.78" rpy="0 -0.174533 0" />
    <parent link="yaw_head" />
    <child link="dish_frame" />
    <axis xyz="0 -1 0" />
    <limit effort="320" velocity="0.35" lower="0" upper="1.22173" />
    </joint>
  </robot>
