<robot name="gothic_belfry_tower">
  <material name="weathered_limestone">
    <color rgba="0.55 0.56 0.53 1" />
    </material>
  <material name="shadowed_recess">
    <color rgba="0.045 0.047 0.05 1" />
    </material>
  <material name="pale_slate">
    <color rgba="0.34 0.38 0.41 1" />
    </material>
  <material name="aged_bell_bronze">
    <color rgba="0.6 0.43 0.2 1" />
    </material>
  <material name="dark_oak_timber">
    <color rgba="0.28 0.16 0.08 1" />
    </material>
  <material name="blackened_iron">
    <color rgba="0.08 0.075 0.07 1" />
    </material>
  <link name="tower">
    <visual name="plinth">
      <origin xyz="0 0 0.17" rpy="0 0 0" />
      <geometry>
        <box size="4.15 4.15 0.34" />
        </geometry>
      <material name="weathered_limestone">
        <color rgba="0.55 0.56 0.53 1" />
        </material>
      </visual>
    <visual name="lower_tower">
      <origin xyz="0 0 1.58" rpy="0 0 0" />
      <geometry>
        <box size="3.45 3.45 2.52" />
        </geometry>
      <material name="weathered_limestone">
        <color rgba="0.55 0.56 0.53 1" />
        </material>
      </visual>
    <visual name="belfry_sill">
      <origin xyz="0 0 2.92" rpy="0 0 0" />
      <geometry>
        <box size="3.68 3.68 0.28" />
        </geometry>
      <material name="weathered_limestone">
        <color rgba="0.55 0.56 0.53 1" />
        </material>
      </visual>
    <visual name="corner_pier_-1_-1">
      <origin xyz="-1.42 -1.42 4.08" rpy="0 0 0" />
      <geometry>
        <box size="0.64 0.64 2.35" />
        </geometry>
      <material name="weathered_limestone">
        <color rgba="0.55 0.56 0.53 1" />
        </material>
      </visual>
    <visual name="corner_pier_-1_+1">
      <origin xyz="-1.42 1.42 4.08" rpy="0 0 0" />
      <geometry>
        <box size="0.64 0.64 2.35" />
        </geometry>
      <material name="weathered_limestone">
        <color rgba="0.55 0.56 0.53 1" />
        </material>
      </visual>
    <visual name="corner_pier_+1_-1">
      <origin xyz="1.42 -1.42 4.08" rpy="0 0 0" />
      <geometry>
        <box size="0.64 0.64 2.35" />
        </geometry>
      <material name="weathered_limestone">
        <color rgba="0.55 0.56 0.53 1" />
        </material>
      </visual>
    <visual name="corner_pier_+1_+1">
      <origin xyz="1.42 1.42 4.08" rpy="0 0 0" />
      <geometry>
        <box size="0.64 0.64 2.35" />
        </geometry>
      <material name="weathered_limestone">
        <color rgba="0.55 0.56 0.53 1" />
        </material>
      </visual>
    <visual name="front_cornice">
      <origin xyz="0 -1.6 5.3" rpy="0 0 0" />
      <geometry>
        <box size="3.68 0.48 0.38" />
        </geometry>
      <material name="weathered_limestone">
        <color rgba="0.55 0.56 0.53 1" />
        </material>
      </visual>
    <visual name="rear_cornice">
      <origin xyz="0 1.6 5.3" rpy="0 0 0" />
      <geometry>
        <box size="3.68 0.48 0.38" />
        </geometry>
      <material name="weathered_limestone">
        <color rgba="0.55 0.56 0.53 1" />
        </material>
      </visual>
    <visual name="west_cornice">
      <origin xyz="-1.6 0 5.3" rpy="0 0 0" />
      <geometry>
        <box size="0.48 3.68 0.38" />
        </geometry>
      <material name="weathered_limestone">
        <color rgba="0.55 0.56 0.53 1" />
        </material>
      </visual>
    <visual name="east_cornice">
      <origin xyz="1.6 0 5.3" rpy="0 0 0" />
      <geometry>
        <box size="0.48 3.68 0.38" />
        </geometry>
      <material name="weathered_limestone">
        <color rgba="0.55 0.56 0.53 1" />
        </material>
      </visual>
    <visual name="drum_base_slab">
      <origin xyz="0 0 5.48" rpy="0 0 0" />
      <geometry>
        <box size="3.05 3.05 0.2" />
        </geometry>
      <material name="weathered_limestone">
        <color rgba="0.55 0.56 0.53 1" />
        </material>
      </visual>
    <visual name="front_belfry_shadow">
      <origin xyz="0 -1.745 3.83" rpy="0 0 0" />
      <geometry>
        <box size="1.04 0.04 1.46" />
        </geometry>
      <material name="shadowed_recess">
        <color rgba="0.045 0.047 0.05 1" />
        </material>
      </visual>
    <visual name="front_lancet_frame">
      <origin xyz="0 -1.735 2.98" rpy="1.5708 0 0" />
      <geometry>
        <mesh filename="assets/meshes/lancet_arch_frame.obj" />
        </geometry>
      <material name="weathered_limestone">
        <color rgba="0.55 0.56 0.53 1" />
        </material>
      </visual>
    <visual name="front_louver_0">
      <origin xyz="0 -1.795 3.48" rpy="0.12 0 0" />
      <geometry>
        <box size="1.1 0.07 0.075" />
        </geometry>
      <material name="dark_oak_timber">
        <color rgba="0.28 0.16 0.08 1" />
        </material>
      </visual>
    <visual name="front_louver_1">
      <origin xyz="0 -1.795 3.76" rpy="0.12 0 0" />
      <geometry>
        <box size="1.1 0.07 0.075" />
        </geometry>
      <material name="dark_oak_timber">
        <color rgba="0.28 0.16 0.08 1" />
        </material>
      </visual>
    <visual name="front_louver_2">
      <origin xyz="0 -1.795 4.04" rpy="0.12 0 0" />
      <geometry>
        <box size="1.1 0.07 0.075" />
        </geometry>
      <material name="dark_oak_timber">
        <color rgba="0.28 0.16 0.08 1" />
        </material>
      </visual>
    <visual name="rear_belfry_shadow">
      <origin xyz="0 1.745 3.83" rpy="0 0 0" />
      <geometry>
        <box size="1.04 0.04 1.46" />
        </geometry>
      <material name="shadowed_recess">
        <color rgba="0.045 0.047 0.05 1" />
        </material>
      </visual>
    <visual name="rear_lancet_frame">
      <origin xyz="0 1.735 2.98" rpy="1.5708 0 3.14159" />
      <geometry>
        <mesh filename="assets/meshes/lancet_arch_frame.obj" />
        </geometry>
      <material name="weathered_limestone">
        <color rgba="0.55 0.56 0.53 1" />
        </material>
      </visual>
    <visual name="rear_louver_0">
      <origin xyz="0 1.795 3.48" rpy="-0.12 0 0" />
      <geometry>
        <box size="1.1 0.07 0.075" />
        </geometry>
      <material name="dark_oak_timber">
        <color rgba="0.28 0.16 0.08 1" />
        </material>
      </visual>
    <visual name="rear_louver_1">
      <origin xyz="0 1.795 3.76" rpy="-0.12 0 0" />
      <geometry>
        <box size="1.1 0.07 0.075" />
        </geometry>
      <material name="dark_oak_timber">
        <color rgba="0.28 0.16 0.08 1" />
        </material>
      </visual>
    <visual name="rear_louver_2">
      <origin xyz="0 1.795 4.04" rpy="-0.12 0 0" />
      <geometry>
        <box size="1.1 0.07 0.075" />
        </geometry>
      <material name="dark_oak_timber">
        <color rgba="0.28 0.16 0.08 1" />
        </material>
      </visual>
    <visual name="east_belfry_shadow">
      <origin xyz="1.745 0 3.83" rpy="0 0 0" />
      <geometry>
        <box size="0.04 1.04 1.46" />
        </geometry>
      <material name="shadowed_recess">
        <color rgba="0.045 0.047 0.05 1" />
        </material>
      </visual>
    <visual name="east_lancet_frame">
      <origin xyz="1.735 0 2.98" rpy="1.5708 0 1.5708" />
      <geometry>
        <mesh filename="assets/meshes/lancet_arch_frame.obj" />
        </geometry>
      <material name="weathered_limestone">
        <color rgba="0.55 0.56 0.53 1" />
        </material>
      </visual>
    <visual name="east_louver_0">
      <origin xyz="1.795 0 3.48" rpy="0 -0.12 0" />
      <geometry>
        <box size="0.07 1.1 0.075" />
        </geometry>
      <material name="dark_oak_timber">
        <color rgba="0.28 0.16 0.08 1" />
        </material>
      </visual>
    <visual name="east_louver_1">
      <origin xyz="1.795 0 3.76" rpy="0 -0.12 0" />
      <geometry>
        <box size="0.07 1.1 0.075" />
        </geometry>
      <material name="dark_oak_timber">
        <color rgba="0.28 0.16 0.08 1" />
        </material>
      </visual>
    <visual name="east_louver_2">
      <origin xyz="1.795 0 4.04" rpy="0 -0.12 0" />
      <geometry>
        <box size="0.07 1.1 0.075" />
        </geometry>
      <material name="dark_oak_timber">
        <color rgba="0.28 0.16 0.08 1" />
        </material>
      </visual>
    <visual name="west_belfry_shadow">
      <origin xyz="-1.745 0 3.83" rpy="0 0 0" />
      <geometry>
        <box size="0.04 1.04 1.46" />
        </geometry>
      <material name="shadowed_recess">
        <color rgba="0.045 0.047 0.05 1" />
        </material>
      </visual>
    <visual name="west_lancet_frame">
      <origin xyz="-1.735 0 2.98" rpy="1.5708 0 -1.5708" />
      <geometry>
        <mesh filename="assets/meshes/lancet_arch_frame.obj" />
        </geometry>
      <material name="weathered_limestone">
        <color rgba="0.55 0.56 0.53 1" />
        </material>
      </visual>
    <visual name="west_louver_0">
      <origin xyz="-1.795 0 3.48" rpy="0 0.12 0" />
      <geometry>
        <box size="0.07 1.1 0.075" />
        </geometry>
      <material name="dark_oak_timber">
        <color rgba="0.28 0.16 0.08 1" />
        </material>
      </visual>
    <visual name="west_louver_1">
      <origin xyz="-1.795 0 3.76" rpy="0 0.12 0" />
      <geometry>
        <box size="0.07 1.1 0.075" />
        </geometry>
      <material name="dark_oak_timber">
        <color rgba="0.28 0.16 0.08 1" />
        </material>
      </visual>
    <visual name="west_louver_2">
      <origin xyz="-1.795 0 4.04" rpy="0 0.12 0" />
      <geometry>
        <box size="0.07 1.1 0.075" />
        </geometry>
      <material name="dark_oak_timber">
        <color rgba="0.28 0.16 0.08 1" />
        </material>
      </visual>
    <visual name="front_crossbeam">
      <origin xyz="0 -1 4.72" rpy="0 0 0" />
      <geometry>
        <box size="2.95 0.24 0.24" />
        </geometry>
      <material name="dark_oak_timber">
        <color rgba="0.28 0.16 0.08 1" />
        </material>
      </visual>
    <visual name="rear_crossbeam">
      <origin xyz="0 1 4.72" rpy="0 0 0" />
      <geometry>
        <box size="2.95 0.24 0.24" />
        </geometry>
      <material name="dark_oak_timber">
        <color rgba="0.28 0.16 0.08 1" />
        </material>
      </visual>
    <visual name="bearing_neg_y_0">
      <origin xyz="-0.62 -0.79 4.72" rpy="0 0 0" />
      <geometry>
        <box size="0.38 0.22 0.34" />
        </geometry>
      <material name="blackened_iron">
        <color rgba="0.08 0.075 0.07 1" />
        </material>
      </visual>
    <visual name="bearing_pos_y_0">
      <origin xyz="-0.62 0.79 4.72" rpy="0 0 0" />
      <geometry>
        <box size="0.38 0.22 0.34" />
        </geometry>
      <material name="blackened_iron">
        <color rgba="0.08 0.075 0.07 1" />
        </material>
      </visual>
    <visual name="bearing_neg_y_1">
      <origin xyz="0.62 -0.79 4.72" rpy="0 0 0" />
      <geometry>
        <box size="0.38 0.22 0.34" />
        </geometry>
      <material name="blackened_iron">
        <color rgba="0.08 0.075 0.07 1" />
        </material>
      </visual>
    <visual name="bearing_pos_y_1">
      <origin xyz="0.62 0.79 4.72" rpy="0 0 0" />
      <geometry>
        <box size="0.38 0.22 0.34" />
        </geometry>
      <material name="blackened_iron">
        <color rgba="0.08 0.075 0.07 1" />
        </material>
      </visual>
    <visual name="octagonal_drum">
      <origin xyz="0 0 5.95" rpy="0 0 0.392699" />
      <geometry>
        <mesh filename="assets/meshes/octagonal_drum.obj" />
        </geometry>
      <material name="weathered_limestone">
        <color rgba="0.55 0.56 0.53 1" />
        </material>
      </visual>
    <visual name="drum_rib_0">
      <origin xyz="1.18 0 5.95" rpy="0 0 0" />
      <geometry>
        <box size="0.16 0.24 1.22" />
        </geometry>
      <material name="weathered_limestone">
        <color rgba="0.55 0.56 0.53 1" />
        </material>
      </visual>
    <visual name="drum_rib_1">
      <origin xyz="0.834386 0.834386 5.95" rpy="0 0 0.785398" />
      <geometry>
        <box size="0.16 0.24 1.22" />
        </geometry>
      <material name="weathered_limestone">
        <color rgba="0.55 0.56 0.53 1" />
        </material>
      </visual>
    <visual name="drum_rib_2">
      <origin xyz="7.22542e-17 1.18 5.95" rpy="0 0 1.5708" />
      <geometry>
        <box size="0.16 0.24 1.22" />
        </geometry>
      <material name="weathered_limestone">
        <color rgba="0.55 0.56 0.53 1" />
        </material>
      </visual>
    <visual name="drum_rib_3">
      <origin xyz="-0.834386 0.834386 5.95" rpy="0 0 2.35619" />
      <geometry>
        <box size="0.16 0.24 1.22" />
        </geometry>
      <material name="weathered_limestone">
        <color rgba="0.55 0.56 0.53 1" />
        </material>
      </visual>
    <visual name="drum_rib_4">
      <origin xyz="-1.18 1.44508e-16 5.95" rpy="0 0 3.14159" />
      <geometry>
        <box size="0.16 0.24 1.22" />
        </geometry>
      <material name="weathered_limestone">
        <color rgba="0.55 0.56 0.53 1" />
        </material>
      </visual>
    <visual name="drum_rib_5">
      <origin xyz="-0.834386 -0.834386 5.95" rpy="0 0 3.92699" />
      <geometry>
        <box size="0.16 0.24 1.22" />
        </geometry>
      <material name="weathered_limestone">
        <color rgba="0.55 0.56 0.53 1" />
        </material>
      </visual>
    <visual name="drum_rib_6">
      <origin xyz="-2.16762e-16 -1.18 5.95" rpy="0 0 4.71239" />
      <geometry>
        <box size="0.16 0.24 1.22" />
        </geometry>
      <material name="weathered_limestone">
        <color rgba="0.55 0.56 0.53 1" />
        </material>
      </visual>
    <visual name="drum_rib_7">
      <origin xyz="0.834386 -0.834386 5.95" rpy="0 0 5.49779" />
      <geometry>
        <box size="0.16 0.24 1.22" />
        </geometry>
      <material name="weathered_limestone">
        <color rgba="0.55 0.56 0.53 1" />
        </material>
      </visual>
    <visual name="pointed_spire">
      <origin xyz="0 0 7.84" rpy="0 0 0.392699" />
      <geometry>
        <mesh filename="assets/meshes/octagonal_spire.obj" />
        </geometry>
      <material name="pale_slate">
        <color rgba="0.34 0.38 0.41 1" />
        </material>
      </visual>
    <visual name="spire_ribs">
      <geometry>
        <mesh filename="assets/meshes/spire_ribs.obj" />
        </geometry>
      <material name="weathered_limestone">
        <color rgba="0.55 0.56 0.53 1" />
        </material>
      </visual>
    <collision name="plinth">
      <origin xyz="0 0 0.17" rpy="0 0 0" />
      <geometry>
        <box size="4.15 4.15 0.34" />
        </geometry>
      </collision>
    <collision name="lower_tower">
      <origin xyz="0 0 1.58" rpy="0 0 0" />
      <geometry>
        <box size="3.45 3.45 2.52" />
        </geometry>
      </collision>
    <collision name="belfry_sill">
      <origin xyz="0 0 2.92" rpy="0 0 0" />
      <geometry>
        <box size="3.68 3.68 0.28" />
        </geometry>
      </collision>
    <collision name="corner_pier_-1_-1">
      <origin xyz="-1.42 -1.42 4.08" rpy="0 0 0" />
      <geometry>
        <box size="0.64 0.64 2.35" />
        </geometry>
      </collision>
    <collision name="corner_pier_-1_+1">
      <origin xyz="-1.42 1.42 4.08" rpy="0 0 0" />
      <geometry>
        <box size="0.64 0.64 2.35" />
        </geometry>
      </collision>
    <collision name="corner_pier_+1_-1">
      <origin xyz="1.42 -1.42 4.08" rpy="0 0 0" />
      <geometry>
        <box size="0.64 0.64 2.35" />
        </geometry>
      </collision>
    <collision name="corner_pier_+1_+1">
      <origin xyz="1.42 1.42 4.08" rpy="0 0 0" />
      <geometry>
        <box size="0.64 0.64 2.35" />
        </geometry>
      </collision>
    <collision name="front_cornice">
      <origin xyz="0 -1.6 5.3" rpy="0 0 0" />
      <geometry>
        <box size="3.68 0.48 0.38" />
        </geometry>
      </collision>
    <collision name="rear_cornice">
      <origin xyz="0 1.6 5.3" rpy="0 0 0" />
      <geometry>
        <box size="3.68 0.48 0.38" />
        </geometry>
      </collision>
    <collision name="west_cornice">
      <origin xyz="-1.6 0 5.3" rpy="0 0 0" />
      <geometry>
        <box size="0.48 3.68 0.38" />
        </geometry>
      </collision>
    <collision name="east_cornice">
      <origin xyz="1.6 0 5.3" rpy="0 0 0" />
      <geometry>
        <box size="0.48 3.68 0.38" />
        </geometry>
      </collision>
    <collision name="drum_base_slab">
      <origin xyz="0 0 5.48" rpy="0 0 0" />
      <geometry>
        <box size="3.05 3.05 0.2" />
        </geometry>
      </collision>
    <collision name="front_belfry_shadow">
      <origin xyz="0 -1.745 3.83" rpy="0 0 0" />
      <geometry>
        <box size="1.04 0.04 1.46" />
        </geometry>
      </collision>
    <collision name="front_lancet_frame">
      <origin xyz="0 -1.735 2.98" rpy="1.5708 0 0" />
      <geometry>
        <mesh filename="assets/meshes/lancet_arch_frame.obj" />
        </geometry>
      </collision>
    <collision name="front_louver_0">
      <origin xyz="0 -1.795 3.48" rpy="0.12 0 0" />
      <geometry>
        <box size="1.1 0.07 0.075" />
        </geometry>
      </collision>
    <collision name="front_louver_1">
      <origin xyz="0 -1.795 3.76" rpy="0.12 0 0" />
      <geometry>
        <box size="1.1 0.07 0.075" />
        </geometry>
      </collision>
    <collision name="front_louver_2">
      <origin xyz="0 -1.795 4.04" rpy="0.12 0 0" />
      <geometry>
        <box size="1.1 0.07 0.075" />
        </geometry>
      </collision>
    <collision name="rear_belfry_shadow">
      <origin xyz="0 1.745 3.83" rpy="0 0 0" />
      <geometry>
        <box size="1.04 0.04 1.46" />
        </geometry>
      </collision>
    <collision name="rear_lancet_frame">
      <origin xyz="0 1.735 2.98" rpy="1.5708 0 3.14159" />
      <geometry>
        <mesh filename="assets/meshes/lancet_arch_frame.obj" />
        </geometry>
      </collision>
    <collision name="rear_louver_0">
      <origin xyz="0 1.795 3.48" rpy="-0.12 0 0" />
      <geometry>
        <box size="1.1 0.07 0.075" />
        </geometry>
      </collision>
    <collision name="rear_louver_1">
      <origin xyz="0 1.795 3.76" rpy="-0.12 0 0" />
      <geometry>
        <box size="1.1 0.07 0.075" />
        </geometry>
      </collision>
    <collision name="rear_louver_2">
      <origin xyz="0 1.795 4.04" rpy="-0.12 0 0" />
      <geometry>
        <box size="1.1 0.07 0.075" />
        </geometry>
      </collision>
    <collision name="east_belfry_shadow">
      <origin xyz="1.745 0 3.83" rpy="0 0 0" />
      <geometry>
        <box size="0.04 1.04 1.46" />
        </geometry>
      </collision>
    <collision name="east_lancet_frame">
      <origin xyz="1.735 0 2.98" rpy="1.5708 0 1.5708" />
      <geometry>
        <mesh filename="assets/meshes/lancet_arch_frame.obj" />
        </geometry>
      </collision>
    <collision name="east_louver_0">
      <origin xyz="1.795 0 3.48" rpy="0 -0.12 0" />
      <geometry>
        <box size="0.07 1.1 0.075" />
        </geometry>
      </collision>
    <collision name="east_louver_1">
      <origin xyz="1.795 0 3.76" rpy="0 -0.12 0" />
      <geometry>
        <box size="0.07 1.1 0.075" />
        </geometry>
      </collision>
    <collision name="east_louver_2">
      <origin xyz="1.795 0 4.04" rpy="0 -0.12 0" />
      <geometry>
        <box size="0.07 1.1 0.075" />
        </geometry>
      </collision>
    <collision name="west_belfry_shadow">
      <origin xyz="-1.745 0 3.83" rpy="0 0 0" />
      <geometry>
        <box size="0.04 1.04 1.46" />
        </geometry>
      </collision>
    <collision name="west_lancet_frame">
      <origin xyz="-1.735 0 2.98" rpy="1.5708 0 -1.5708" />
      <geometry>
        <mesh filename="assets/meshes/lancet_arch_frame.obj" />
        </geometry>
      </collision>
    <collision name="west_louver_0">
      <origin xyz="-1.795 0 3.48" rpy="0 0.12 0" />
      <geometry>
        <box size="0.07 1.1 0.075" />
        </geometry>
      </collision>
    <collision name="west_louver_1">
      <origin xyz="-1.795 0 3.76" rpy="0 0.12 0" />
      <geometry>
        <box size="0.07 1.1 0.075" />
        </geometry>
      </collision>
    <collision name="west_louver_2">
      <origin xyz="-1.795 0 4.04" rpy="0 0.12 0" />
      <geometry>
        <box size="0.07 1.1 0.075" />
        </geometry>
      </collision>
    <collision name="front_crossbeam">
      <origin xyz="0 -1 4.72" rpy="0 0 0" />
      <geometry>
        <box size="2.95 0.24 0.24" />
        </geometry>
      </collision>
    <collision name="rear_crossbeam">
      <origin xyz="0 1 4.72" rpy="0 0 0" />
      <geometry>
        <box size="2.95 0.24 0.24" />
        </geometry>
      </collision>
    <collision name="bearing_neg_y_0">
      <origin xyz="-0.62 -0.79 4.72" rpy="0 0 0" />
      <geometry>
        <box size="0.38 0.22 0.34" />
        </geometry>
      </collision>
    <collision name="bearing_pos_y_0">
      <origin xyz="-0.62 0.79 4.72" rpy="0 0 0" />
      <geometry>
        <box size="0.38 0.22 0.34" />
        </geometry>
      </collision>
    <collision name="bearing_neg_y_1">
      <origin xyz="0.62 -0.79 4.72" rpy="0 0 0" />
      <geometry>
        <box size="0.38 0.22 0.34" />
        </geometry>
      </collision>
    <collision name="bearing_pos_y_1">
      <origin xyz="0.62 0.79 4.72" rpy="0 0 0" />
      <geometry>
        <box size="0.38 0.22 0.34" />
        </geometry>
      </collision>
    <collision name="octagonal_drum">
      <origin xyz="0 0 5.95" rpy="0 0 0.392699" />
      <geometry>
        <mesh filename="assets/meshes/octagonal_drum.obj" />
        </geometry>
      </collision>
    <collision name="drum_rib_0">
      <origin xyz="1.18 0 5.95" rpy="0 0 0" />
      <geometry>
        <box size="0.16 0.24 1.22" />
        </geometry>
      </collision>
    <collision name="drum_rib_1">
      <origin xyz="0.834386 0.834386 5.95" rpy="0 0 0.785398" />
      <geometry>
        <box size="0.16 0.24 1.22" />
        </geometry>
      </collision>
    <collision name="drum_rib_2">
      <origin xyz="7.22542e-17 1.18 5.95" rpy="0 0 1.5708" />
      <geometry>
        <box size="0.16 0.24 1.22" />
        </geometry>
      </collision>
    <collision name="drum_rib_3">
      <origin xyz="-0.834386 0.834386 5.95" rpy="0 0 2.35619" />
      <geometry>
        <box size="0.16 0.24 1.22" />
        </geometry>
      </collision>
    <collision name="drum_rib_4">
      <origin xyz="-1.18 1.44508e-16 5.95" rpy="0 0 3.14159" />
      <geometry>
        <box size="0.16 0.24 1.22" />
        </geometry>
      </collision>
    <collision name="drum_rib_5">
      <origin xyz="-0.834386 -0.834386 5.95" rpy="0 0 3.92699" />
      <geometry>
        <box size="0.16 0.24 1.22" />
        </geometry>
      </collision>
    <collision name="drum_rib_6">
      <origin xyz="-2.16762e-16 -1.18 5.95" rpy="0 0 4.71239" />
      <geometry>
        <box size="0.16 0.24 1.22" />
        </geometry>
      </collision>
    <collision name="drum_rib_7">
      <origin xyz="0.834386 -0.834386 5.95" rpy="0 0 5.49779" />
      <geometry>
        <box size="0.16 0.24 1.22" />
        </geometry>
      </collision>
    <collision name="pointed_spire">
      <origin xyz="0 0 7.84" rpy="0 0 0.392699" />
      <geometry>
        <mesh filename="assets/meshes/octagonal_spire.obj" />
        </geometry>
      </collision>
    <collision name="spire_ribs">
      <geometry>
        <mesh filename="assets/meshes/spire_ribs.obj" />
        </geometry>
      </collision>
    </link>
  <link name="bell_0">
    <visual name="timber_yoke">
      <origin xyz="0 0 -0.03" rpy="0 0 0" />
      <geometry>
        <box size="0.58 0.68 0.22" />
        </geometry>
      <material name="dark_oak_timber">
        <color rgba="0.28 0.16 0.08 1" />
        </material>
      </visual>
    <visual name="axle_pin">
      <origin xyz="0 0 0" rpy="1.5708 0 0" />
      <geometry>
        <cylinder radius="0.045" length="1.28" />
        </geometry>
      <material name="blackened_iron">
        <color rgba="0.08 0.075 0.07 1" />
        </material>
      </visual>
    <visual name="strap_0">
      <origin xyz="-0.18 0 -0.35" rpy="0 0 0" />
      <geometry>
        <box size="0.075 0.06 0.52" />
        </geometry>
      <material name="blackened_iron">
        <color rgba="0.08 0.075 0.07 1" />
        </material>
      </visual>
    <visual name="strap_1">
      <origin xyz="0.18 0 -0.35" rpy="0 0 0" />
      <geometry>
        <box size="0.075 0.06 0.52" />
        </geometry>
      <material name="blackened_iron">
        <color rgba="0.08 0.075 0.07 1" />
        </material>
      </visual>
    <visual name="bell_crown">
      <origin xyz="0 0 -0.35" rpy="0 0 0" />
      <geometry>
        <cylinder radius="0.2" length="0.16" />
        </geometry>
      <material name="aged_bell_bronze">
        <color rgba="0.6 0.43 0.2 1" />
        </material>
      </visual>
    <visual name="clapper_hanger">
      <origin xyz="0 0 -0.58" rpy="1.5708 0 0" />
      <geometry>
        <cylinder radius="0.04" length="0.28" />
        </geometry>
      <material name="blackened_iron">
        <color rgba="0.08 0.075 0.07 1" />
        </material>
      </visual>
    <visual name="clapper_link">
      <origin xyz="0 0 -0.485" rpy="0 0 0" />
      <geometry>
        <box size="0.06 0.06 0.12" />
        </geometry>
      <material name="blackened_iron">
        <color rgba="0.08 0.075 0.07 1" />
        </material>
      </visual>
    <visual name="bell_shell">
      <geometry>
        <mesh filename="assets/meshes/bell_0_bronze_shell.obj" />
        </geometry>
      <material name="aged_bell_bronze">
        <color rgba="0.6 0.43 0.2 1" />
        </material>
      </visual>
    <collision name="timber_yoke">
      <origin xyz="0 0 -0.03" rpy="0 0 0" />
      <geometry>
        <box size="0.58 0.68 0.22" />
        </geometry>
      </collision>
    <collision name="axle_pin">
      <origin xyz="0 0 0" rpy="1.5708 0 0" />
      <geometry>
        <cylinder radius="0.045" length="1.28" />
        </geometry>
      </collision>
    <collision name="strap_0">
      <origin xyz="-0.18 0 -0.35" rpy="0 0 0" />
      <geometry>
        <box size="0.075 0.06 0.52" />
        </geometry>
      </collision>
    <collision name="strap_1">
      <origin xyz="0.18 0 -0.35" rpy="0 0 0" />
      <geometry>
        <box size="0.075 0.06 0.52" />
        </geometry>
      </collision>
    <collision name="bell_crown">
      <origin xyz="0 0 -0.35" rpy="0 0 0" />
      <geometry>
        <cylinder radius="0.2" length="0.16" />
        </geometry>
      </collision>
    <collision name="clapper_hanger">
      <origin xyz="0 0 -0.58" rpy="1.5708 0 0" />
      <geometry>
        <cylinder radius="0.04" length="0.28" />
        </geometry>
      </collision>
    <collision name="clapper_link">
      <origin xyz="0 0 -0.485" rpy="0 0 0" />
      <geometry>
        <box size="0.06 0.06 0.12" />
        </geometry>
      </collision>
    <collision name="bell_shell">
      <geometry>
        <mesh filename="assets/meshes/bell_0_bronze_shell.obj" />
        </geometry>
      </collision>
    </link>
  <link name="clapper_0">
    <visual name="clapper_pin">
      <origin xyz="0 0 0" rpy="1.5708 0 0" />
      <geometry>
        <cylinder radius="0.028" length="0.34" />
        </geometry>
      <material name="blackened_iron">
        <color rgba="0.08 0.075 0.07 1" />
        </material>
      </visual>
    <visual name="clevis_side_0">
      <origin xyz="0 0.158 -0.04" rpy="0 0 0" />
      <geometry>
        <box size="0.04 0.025 0.08" />
        </geometry>
      <material name="blackened_iron">
        <color rgba="0.08 0.075 0.07 1" />
        </material>
      </visual>
    <visual name="clevis_side_1">
      <origin xyz="0 -0.158 -0.04" rpy="0 0 0" />
      <geometry>
        <box size="0.04 0.025 0.08" />
        </geometry>
      <material name="blackened_iron">
        <color rgba="0.08 0.075 0.07 1" />
        </material>
      </visual>
    <visual name="clevis_crossbar">
      <origin xyz="0 0 -0.08" rpy="1.5708 0 0" />
      <geometry>
        <cylinder radius="0.018" length="0.316" />
        </geometry>
      <material name="blackened_iron">
        <color rgba="0.08 0.075 0.07 1" />
        </material>
      </visual>
    <visual name="clapper_rod">
      <origin xyz="0 0 -0.35" rpy="0 0 0" />
      <geometry>
        <cylinder radius="0.026" length="0.54" />
        </geometry>
      <material name="blackened_iron">
        <color rgba="0.08 0.075 0.07 1" />
        </material>
      </visual>
    <visual name="clapper_ball">
      <origin xyz="0 0 -0.69" rpy="0 0 0" />
      <geometry>
        <sphere radius="0.13" />
        </geometry>
      <material name="blackened_iron">
        <color rgba="0.08 0.075 0.07 1" />
        </material>
      </visual>
    <collision name="clapper_pin">
      <origin xyz="0 0 0" rpy="1.5708 0 0" />
      <geometry>
        <cylinder radius="0.028" length="0.34" />
        </geometry>
      </collision>
    <collision name="clevis_side_0">
      <origin xyz="0 0.158 -0.04" rpy="0 0 0" />
      <geometry>
        <box size="0.04 0.025 0.08" />
        </geometry>
      </collision>
    <collision name="clevis_side_1">
      <origin xyz="0 -0.158 -0.04" rpy="0 0 0" />
      <geometry>
        <box size="0.04 0.025 0.08" />
        </geometry>
      </collision>
    <collision name="clevis_crossbar">
      <origin xyz="0 0 -0.08" rpy="1.5708 0 0" />
      <geometry>
        <cylinder radius="0.018" length="0.316" />
        </geometry>
      </collision>
    <collision name="clapper_rod">
      <origin xyz="0 0 -0.35" rpy="0 0 0" />
      <geometry>
        <cylinder radius="0.026" length="0.54" />
        </geometry>
      </collision>
    <collision name="clapper_ball">
      <origin xyz="0 0 -0.69" rpy="0 0 0" />
      <geometry>
        <sphere radius="0.13" />
        </geometry>
      </collision>
    </link>
  <link name="bell_1">
    <visual name="timber_yoke">
      <origin xyz="0 0 -0.03" rpy="0 0 0" />
      <geometry>
        <box size="0.58 0.68 0.22" />
        </geometry>
      <material name="dark_oak_timber">
        <color rgba="0.28 0.16 0.08 1" />
        </material>
      </visual>
    <visual name="axle_pin">
      <origin xyz="0 0 0" rpy="1.5708 0 0" />
      <geometry>
        <cylinder radius="0.045" length="1.28" />
        </geometry>
      <material name="blackened_iron">
        <color rgba="0.08 0.075 0.07 1" />
        </material>
      </visual>
    <visual name="strap_0">
      <origin xyz="-0.18 0 -0.35" rpy="0 0 0" />
      <geometry>
        <box size="0.075 0.06 0.52" />
        </geometry>
      <material name="blackened_iron">
        <color rgba="0.08 0.075 0.07 1" />
        </material>
      </visual>
    <visual name="strap_1">
      <origin xyz="0.18 0 -0.35" rpy="0 0 0" />
      <geometry>
        <box size="0.075 0.06 0.52" />
        </geometry>
      <material name="blackened_iron">
        <color rgba="0.08 0.075 0.07 1" />
        </material>
      </visual>
    <visual name="bell_crown">
      <origin xyz="0 0 -0.35" rpy="0 0 0" />
      <geometry>
        <cylinder radius="0.2" length="0.16" />
        </geometry>
      <material name="aged_bell_bronze">
        <color rgba="0.6 0.43 0.2 1" />
        </material>
      </visual>
    <visual name="clapper_hanger">
      <origin xyz="0 0 -0.58" rpy="1.5708 0 0" />
      <geometry>
        <cylinder radius="0.04" length="0.28" />
        </geometry>
      <material name="blackened_iron">
        <color rgba="0.08 0.075 0.07 1" />
        </material>
      </visual>
    <visual name="clapper_link">
      <origin xyz="0 0 -0.485" rpy="0 0 0" />
      <geometry>
        <box size="0.06 0.06 0.12" />
        </geometry>
      <material name="blackened_iron">
        <color rgba="0.08 0.075 0.07 1" />
        </material>
      </visual>
    <visual name="bell_shell">
      <geometry>
        <mesh filename="assets/meshes/bell_1_bronze_shell.obj" />
        </geometry>
      <material name="aged_bell_bronze">
        <color rgba="0.6 0.43 0.2 1" />
        </material>
      </visual>
    <collision name="timber_yoke">
      <origin xyz="0 0 -0.03" rpy="0 0 0" />
      <geometry>
        <box size="0.58 0.68 0.22" />
        </geometry>
      </collision>
    <collision name="axle_pin">
      <origin xyz="0 0 0" rpy="1.5708 0 0" />
      <geometry>
        <cylinder radius="0.045" length="1.28" />
        </geometry>
      </collision>
    <collision name="strap_0">
      <origin xyz="-0.18 0 -0.35" rpy="0 0 0" />
      <geometry>
        <box size="0.075 0.06 0.52" />
        </geometry>
      </collision>
    <collision name="strap_1">
      <origin xyz="0.18 0 -0.35" rpy="0 0 0" />
      <geometry>
        <box size="0.075 0.06 0.52" />
        </geometry>
      </collision>
    <collision name="bell_crown">
      <origin xyz="0 0 -0.35" rpy="0 0 0" />
      <geometry>
        <cylinder radius="0.2" length="0.16" />
        </geometry>
      </collision>
    <collision name="clapper_hanger">
      <origin xyz="0 0 -0.58" rpy="1.5708 0 0" />
      <geometry>
        <cylinder radius="0.04" length="0.28" />
        </geometry>
      </collision>
    <collision name="clapper_link">
      <origin xyz="0 0 -0.485" rpy="0 0 0" />
      <geometry>
        <box size="0.06 0.06 0.12" />
        </geometry>
      </collision>
    <collision name="bell_shell">
      <geometry>
        <mesh filename="assets/meshes/bell_1_bronze_shell.obj" />
        </geometry>
      </collision>
    </link>
  <link name="clapper_1">
    <visual name="clapper_pin">
      <origin xyz="0 0 0" rpy="1.5708 0 0" />
      <geometry>
        <cylinder radius="0.028" length="0.34" />
        </geometry>
      <material name="blackened_iron">
        <color rgba="0.08 0.075 0.07 1" />
        </material>
      </visual>
    <visual name="clevis_side_0">
      <origin xyz="0 0.158 -0.04" rpy="0 0 0" />
      <geometry>
        <box size="0.04 0.025 0.08" />
        </geometry>
      <material name="blackened_iron">
        <color rgba="0.08 0.075 0.07 1" />
        </material>
      </visual>
    <visual name="clevis_side_1">
      <origin xyz="0 -0.158 -0.04" rpy="0 0 0" />
      <geometry>
        <box size="0.04 0.025 0.08" />
        </geometry>
      <material name="blackened_iron">
        <color rgba="0.08 0.075 0.07 1" />
        </material>
      </visual>
    <visual name="clevis_crossbar">
      <origin xyz="0 0 -0.08" rpy="1.5708 0 0" />
      <geometry>
        <cylinder radius="0.018" length="0.316" />
        </geometry>
      <material name="blackened_iron">
        <color rgba="0.08 0.075 0.07 1" />
        </material>
      </visual>
    <visual name="clapper_rod">
      <origin xyz="0 0 -0.35" rpy="0 0 0" />
      <geometry>
        <cylinder radius="0.026" length="0.54" />
        </geometry>
      <material name="blackened_iron">
        <color rgba="0.08 0.075 0.07 1" />
        </material>
      </visual>
    <visual name="clapper_ball">
      <origin xyz="0 0 -0.69" rpy="0 0 0" />
      <geometry>
        <sphere radius="0.13" />
        </geometry>
      <material name="blackened_iron">
        <color rgba="0.08 0.075 0.07 1" />
        </material>
      </visual>
    <collision name="clapper_pin">
      <origin xyz="0 0 0" rpy="1.5708 0 0" />
      <geometry>
        <cylinder radius="0.028" length="0.34" />
        </geometry>
      </collision>
    <collision name="clevis_side_0">
      <origin xyz="0 0.158 -0.04" rpy="0 0 0" />
      <geometry>
        <box size="0.04 0.025 0.08" />
        </geometry>
      </collision>
    <collision name="clevis_side_1">
      <origin xyz="0 -0.158 -0.04" rpy="0 0 0" />
      <geometry>
        <box size="0.04 0.025 0.08" />
        </geometry>
      </collision>
    <collision name="clevis_crossbar">
      <origin xyz="0 0 -0.08" rpy="1.5708 0 0" />
      <geometry>
        <cylinder radius="0.018" length="0.316" />
        </geometry>
      </collision>
    <collision name="clapper_rod">
      <origin xyz="0 0 -0.35" rpy="0 0 0" />
      <geometry>
        <cylinder radius="0.026" length="0.54" />
        </geometry>
      </collision>
    <collision name="clapper_ball">
      <origin xyz="0 0 -0.69" rpy="0 0 0" />
      <geometry>
        <sphere radius="0.13" />
        </geometry>
      </collision>
    </link>
  <joint name="tower_to_bell_0" type="revolute">
    <origin xyz="-0.62 0 4.72" rpy="0 0 0" />
    <parent link="tower" />
    <child link="bell_0" />
    <axis xyz="0 1 0" />
    <limit effort="900" velocity="1.2" lower="-0.52" upper="0.52" />
    </joint>
  <joint name="bell_0_to_clapper_0" type="revolute">
    <origin xyz="0 0 -0.58" rpy="0 0 0" />
    <parent link="bell_0" />
    <child link="clapper_0" />
    <axis xyz="0 1 0" />
    <limit effort="12" velocity="2.4" lower="-0.72" upper="0.72" />
    </joint>
  <joint name="tower_to_bell_1" type="revolute">
    <origin xyz="0.62 0 4.72" rpy="0 0 0" />
    <parent link="tower" />
    <child link="bell_1" />
    <axis xyz="0 1 0" />
    <limit effort="900" velocity="1.2" lower="-0.52" upper="0.52" />
    </joint>
  <joint name="bell_1_to_clapper_1" type="revolute">
    <origin xyz="0 0 -0.58" rpy="0 0 0" />
    <parent link="bell_1" />
    <child link="clapper_1" />
    <axis xyz="0 1 0" />
    <limit effort="12" velocity="2.4" lower="-0.72" upper="0.72" />
    </joint>
  </robot>
