<robot name="toy_boxy_suv">
  <material name="toy_red">
    <color rgba="0.82 0.05 0.035 1" />
    </material>
  <material name="dark_red_plastic">
    <color rgba="0.5 0.02 0.02 1" />
    </material>
  <material name="soft_black_rubber">
    <color rgba="0.015 0.015 0.014 1" />
    </material>
  <material name="smoked_window">
    <color rgba="0.02 0.04 0.055 1" />
    </material>
  <material name="silver_plastic">
    <color rgba="0.72 0.72 0.68 1" />
    </material>
  <link name="body">
    <visual name="lower_shell">
      <origin xyz="0 0 0.098" rpy="0 0 0" />
      <geometry>
        <box size="0.33 0.128 0.048" />
        </geometry>
      <material name="toy_red">
        <color rgba="0.82 0.05 0.035 1" />
        </material>
      </visual>
    <visual name="cabin_block">
      <origin xyz="0.01 0 0.136" rpy="0 0 0" />
      <geometry>
        <box size="0.152 0.118 0.052" />
        </geometry>
      <material name="toy_red">
        <color rgba="0.82 0.05 0.035 1" />
        </material>
      </visual>
    <visual name="flat_roof">
      <origin xyz="0.01 0 0.168" rpy="0 0 0" />
      <geometry>
        <box size="0.156 0.124 0.012" />
        </geometry>
      <material name="dark_red_plastic">
        <color rgba="0.5 0.02 0.02 1" />
        </material>
      </visual>
    <visual name="hood_deck">
      <origin xyz="0.108 0 0.127" rpy="0 0 0" />
      <geometry>
        <box size="0.094 0.124 0.014" />
        </geometry>
      <material name="toy_red">
        <color rgba="0.82 0.05 0.035 1" />
        </material>
      </visual>
    <visual name="rear_body_deck">
      <origin xyz="-0.101 0 0.122" rpy="0 0 0" />
      <geometry>
        <box size="0.088 0.118 0.01" />
        </geometry>
      <material name="toy_red">
        <color rgba="0.82 0.05 0.035 1" />
        </material>
      </visual>
    <visual name="underbody_spine">
      <origin xyz="0 0 0.066" rpy="0 0 0" />
      <geometry>
        <box size="0.318 0.052 0.014" />
        </geometry>
      <material name="dark_red_plastic">
        <color rgba="0.5 0.02 0.02 1" />
        </material>
      </visual>
    <visual name="front_axle_shaft">
      <origin xyz="0.094 0 0.036" rpy="-1.5708 0 0" />
      <geometry>
        <cylinder radius="0.0046" length="0.19" />
        </geometry>
      <material name="silver_plastic">
        <color rgba="0.72 0.72 0.68 1" />
        </material>
      </visual>
    <visual name="front_axle_shaft_boss">
      <origin xyz="0.094 0 0.055" rpy="0 0 0" />
      <geometry>
        <box size="0.024 0.026 0.046" />
        </geometry>
      <material name="dark_red_plastic">
        <color rgba="0.5 0.02 0.02 1" />
        </material>
      </visual>
    <visual name="rear_axle_shaft">
      <origin xyz="-0.106 0 0.036" rpy="-1.5708 0 0" />
      <geometry>
        <cylinder radius="0.0046" length="0.19" />
        </geometry>
      <material name="silver_plastic">
        <color rgba="0.72 0.72 0.68 1" />
        </material>
      </visual>
    <visual name="rear_axle_shaft_boss">
      <origin xyz="-0.106 0 0.055" rpy="0 0 0" />
      <geometry>
        <box size="0.024 0.026 0.046" />
        </geometry>
      <material name="dark_red_plastic">
        <color rgba="0.5 0.02 0.02 1" />
        </material>
      </visual>
    <visual name="front_side_0_arch_crown">
      <origin xyz="0.094 0.071 0.079" rpy="0 0 0" />
      <geometry>
        <box size="0.08 0.018 0.013" />
        </geometry>
      <material name="dark_red_plastic">
        <color rgba="0.5 0.02 0.02 1" />
        </material>
      </visual>
    <visual name="front_side_0_arch_front_leg">
      <origin xyz="0.14 0.071 0.064" rpy="0 0 0" />
      <geometry>
        <box size="0.01 0.018 0.032" />
        </geometry>
      <material name="dark_red_plastic">
        <color rgba="0.5 0.02 0.02 1" />
        </material>
      </visual>
    <visual name="front_side_0_arch_rear_leg">
      <origin xyz="0.048 0.071 0.064" rpy="0 0 0" />
      <geometry>
        <box size="0.01 0.018 0.032" />
        </geometry>
      <material name="dark_red_plastic">
        <color rgba="0.5 0.02 0.02 1" />
        </material>
      </visual>
    <visual name="front_side_1_arch_crown">
      <origin xyz="0.094 -0.071 0.079" rpy="0 0 0" />
      <geometry>
        <box size="0.08 0.018 0.013" />
        </geometry>
      <material name="dark_red_plastic">
        <color rgba="0.5 0.02 0.02 1" />
        </material>
      </visual>
    <visual name="front_side_1_arch_front_leg">
      <origin xyz="0.14 -0.071 0.064" rpy="0 0 0" />
      <geometry>
        <box size="0.01 0.018 0.032" />
        </geometry>
      <material name="dark_red_plastic">
        <color rgba="0.5 0.02 0.02 1" />
        </material>
      </visual>
    <visual name="front_side_1_arch_rear_leg">
      <origin xyz="0.048 -0.071 0.064" rpy="0 0 0" />
      <geometry>
        <box size="0.01 0.018 0.032" />
        </geometry>
      <material name="dark_red_plastic">
        <color rgba="0.5 0.02 0.02 1" />
        </material>
      </visual>
    <visual name="rear_side_0_arch_crown">
      <origin xyz="-0.106 0.071 0.079" rpy="0 0 0" />
      <geometry>
        <box size="0.08 0.018 0.013" />
        </geometry>
      <material name="dark_red_plastic">
        <color rgba="0.5 0.02 0.02 1" />
        </material>
      </visual>
    <visual name="rear_side_0_arch_front_leg">
      <origin xyz="-0.06 0.071 0.064" rpy="0 0 0" />
      <geometry>
        <box size="0.01 0.018 0.032" />
        </geometry>
      <material name="dark_red_plastic">
        <color rgba="0.5 0.02 0.02 1" />
        </material>
      </visual>
    <visual name="rear_side_0_arch_rear_leg">
      <origin xyz="-0.152 0.071 0.064" rpy="0 0 0" />
      <geometry>
        <box size="0.01 0.018 0.032" />
        </geometry>
      <material name="dark_red_plastic">
        <color rgba="0.5 0.02 0.02 1" />
        </material>
      </visual>
    <visual name="rear_side_1_arch_crown">
      <origin xyz="-0.106 -0.071 0.079" rpy="0 0 0" />
      <geometry>
        <box size="0.08 0.018 0.013" />
        </geometry>
      <material name="dark_red_plastic">
        <color rgba="0.5 0.02 0.02 1" />
        </material>
      </visual>
    <visual name="rear_side_1_arch_front_leg">
      <origin xyz="-0.06 -0.071 0.064" rpy="0 0 0" />
      <geometry>
        <box size="0.01 0.018 0.032" />
        </geometry>
      <material name="dark_red_plastic">
        <color rgba="0.5 0.02 0.02 1" />
        </material>
      </visual>
    <visual name="rear_side_1_arch_rear_leg">
      <origin xyz="-0.152 -0.071 0.064" rpy="0 0 0" />
      <geometry>
        <box size="0.01 0.018 0.032" />
        </geometry>
      <material name="dark_red_plastic">
        <color rgba="0.5 0.02 0.02 1" />
        </material>
      </visual>
    <visual name="side_window_0">
      <origin xyz="0.039 0.061 0.143" rpy="0 0 0" />
      <geometry>
        <box size="0.058 0.004 0.027" />
        </geometry>
      <material name="smoked_window">
        <color rgba="0.02 0.04 0.055 1" />
        </material>
      </visual>
    <visual name="side_window_1">
      <origin xyz="-0.037 0.061 0.143" rpy="0 0 0" />
      <geometry>
        <box size="0.058 0.004 0.027" />
        </geometry>
      <material name="smoked_window">
        <color rgba="0.02 0.04 0.055 1" />
        </material>
      </visual>
    <visual name="side_window_2">
      <origin xyz="0.039 -0.061 0.143" rpy="0 0 0" />
      <geometry>
        <box size="0.058 0.004 0.027" />
        </geometry>
      <material name="smoked_window">
        <color rgba="0.02 0.04 0.055 1" />
        </material>
      </visual>
    <visual name="side_window_3">
      <origin xyz="-0.037 -0.061 0.143" rpy="0 0 0" />
      <geometry>
        <box size="0.058 0.004 0.027" />
        </geometry>
      <material name="smoked_window">
        <color rgba="0.02 0.04 0.055 1" />
        </material>
      </visual>
    <visual name="windshield">
      <origin xyz="0.085 0 0.144" rpy="0 0 0" />
      <geometry>
        <box size="0.006 0.09 0.028" />
        </geometry>
      <material name="smoked_window">
        <color rgba="0.02 0.04 0.055 1" />
        </material>
      </visual>
    <visual name="rear_tail_panel">
      <origin xyz="-0.155 0 0.096" rpy="0 0 0" />
      <geometry>
        <box size="0.006 0.096 0.03" />
        </geometry>
      <material name="toy_red">
        <color rgba="0.82 0.05 0.035 1" />
        </material>
      </visual>
    <visual name="rear_hatch_pillar_0">
      <origin xyz="-0.151 0.064 0.136" rpy="0 0 0" />
      <geometry>
        <box size="0.012 0.008 0.056" />
        </geometry>
      <material name="toy_red">
        <color rgba="0.82 0.05 0.035 1" />
        </material>
      </visual>
    <visual name="rear_hatch_pillar_1">
      <origin xyz="-0.151 -0.064 0.136" rpy="0 0 0" />
      <geometry>
        <box size="0.012 0.008 0.056" />
        </geometry>
      <material name="toy_red">
        <color rgba="0.82 0.05 0.035 1" />
        </material>
      </visual>
    <visual name="door_hinge_pad_side_0_+0.074">
      <origin xyz="0.074 0.064 0.1" rpy="0 0 0" />
      <geometry>
        <box size="0.007 0.004 0.058" />
        </geometry>
      <material name="dark_red_plastic">
        <color rgba="0.5 0.02 0.02 1" />
        </material>
      </visual>
    <visual name="door_hinge_pad_side_1_+0.074">
      <origin xyz="0.074 -0.064 0.1" rpy="0 0 0" />
      <geometry>
        <box size="0.007 0.004 0.058" />
        </geometry>
      <material name="dark_red_plastic">
        <color rgba="0.5 0.02 0.02 1" />
        </material>
      </visual>
    <visual name="door_hinge_pad_side_0_-0.008">
      <origin xyz="-0.008 0.064 0.1" rpy="0 0 0" />
      <geometry>
        <box size="0.007 0.004 0.058" />
        </geometry>
      <material name="dark_red_plastic">
        <color rgba="0.5 0.02 0.02 1" />
        </material>
      </visual>
    <visual name="door_hinge_pad_side_1_-0.008">
      <origin xyz="-0.008 -0.064 0.1" rpy="0 0 0" />
      <geometry>
        <box size="0.007 0.004 0.058" />
        </geometry>
      <material name="dark_red_plastic">
        <color rgba="0.5 0.02 0.02 1" />
        </material>
      </visual>
    <visual name="hatch_top_hinge_pin">
      <origin xyz="-0.155 0 0.158" rpy="-1.5708 0 0" />
      <geometry>
        <cylinder radius="0.0026" length="0.128" />
        </geometry>
      <material name="silver_plastic">
        <color rgba="0.72 0.72 0.68 1" />
        </material>
      </visual>
    <visual name="trunk_deck_hinge_pin">
      <origin xyz="-0.071 0 0.129" rpy="-1.5708 0 0" />
      <geometry>
        <cylinder radius="0.0024" length="0.074" />
        </geometry>
      <material name="silver_plastic">
        <color rgba="0.72 0.72 0.68 1" />
        </material>
      </visual>
    <collision name="lower_shell">
      <origin xyz="0 0 0.098" rpy="0 0 0" />
      <geometry>
        <box size="0.33 0.128 0.048" />
        </geometry>
      </collision>
    <collision name="cabin_block">
      <origin xyz="0.01 0 0.136" rpy="0 0 0" />
      <geometry>
        <box size="0.152 0.118 0.052" />
        </geometry>
      </collision>
    <collision name="flat_roof">
      <origin xyz="0.01 0 0.168" rpy="0 0 0" />
      <geometry>
        <box size="0.156 0.124 0.012" />
        </geometry>
      </collision>
    <collision name="hood_deck">
      <origin xyz="0.108 0 0.127" rpy="0 0 0" />
      <geometry>
        <box size="0.094 0.124 0.014" />
        </geometry>
      </collision>
    <collision name="rear_body_deck">
      <origin xyz="-0.101 0 0.122" rpy="0 0 0" />
      <geometry>
        <box size="0.088 0.118 0.01" />
        </geometry>
      </collision>
    <collision name="underbody_spine">
      <origin xyz="0 0 0.066" rpy="0 0 0" />
      <geometry>
        <box size="0.318 0.052 0.014" />
        </geometry>
      </collision>
    <collision name="front_axle_shaft">
      <origin xyz="0.094 0 0.036" rpy="-1.5708 0 0" />
      <geometry>
        <cylinder radius="0.0046" length="0.19" />
        </geometry>
      </collision>
    <collision name="front_axle_shaft_boss">
      <origin xyz="0.094 0 0.055" rpy="0 0 0" />
      <geometry>
        <box size="0.024 0.026 0.046" />
        </geometry>
      </collision>
    <collision name="rear_axle_shaft">
      <origin xyz="-0.106 0 0.036" rpy="-1.5708 0 0" />
      <geometry>
        <cylinder radius="0.0046" length="0.19" />
        </geometry>
      </collision>
    <collision name="rear_axle_shaft_boss">
      <origin xyz="-0.106 0 0.055" rpy="0 0 0" />
      <geometry>
        <box size="0.024 0.026 0.046" />
        </geometry>
      </collision>
    <collision name="front_side_0_arch_crown">
      <origin xyz="0.094 0.071 0.079" rpy="0 0 0" />
      <geometry>
        <box size="0.08 0.018 0.013" />
        </geometry>
      </collision>
    <collision name="front_side_0_arch_front_leg">
      <origin xyz="0.14 0.071 0.064" rpy="0 0 0" />
      <geometry>
        <box size="0.01 0.018 0.032" />
        </geometry>
      </collision>
    <collision name="front_side_0_arch_rear_leg">
      <origin xyz="0.048 0.071 0.064" rpy="0 0 0" />
      <geometry>
        <box size="0.01 0.018 0.032" />
        </geometry>
      </collision>
    <collision name="front_side_1_arch_crown">
      <origin xyz="0.094 -0.071 0.079" rpy="0 0 0" />
      <geometry>
        <box size="0.08 0.018 0.013" />
        </geometry>
      </collision>
    <collision name="front_side_1_arch_front_leg">
      <origin xyz="0.14 -0.071 0.064" rpy="0 0 0" />
      <geometry>
        <box size="0.01 0.018 0.032" />
        </geometry>
      </collision>
    <collision name="front_side_1_arch_rear_leg">
      <origin xyz="0.048 -0.071 0.064" rpy="0 0 0" />
      <geometry>
        <box size="0.01 0.018 0.032" />
        </geometry>
      </collision>
    <collision name="rear_side_0_arch_crown">
      <origin xyz="-0.106 0.071 0.079" rpy="0 0 0" />
      <geometry>
        <box size="0.08 0.018 0.013" />
        </geometry>
      </collision>
    <collision name="rear_side_0_arch_front_leg">
      <origin xyz="-0.06 0.071 0.064" rpy="0 0 0" />
      <geometry>
        <box size="0.01 0.018 0.032" />
        </geometry>
      </collision>
    <collision name="rear_side_0_arch_rear_leg">
      <origin xyz="-0.152 0.071 0.064" rpy="0 0 0" />
      <geometry>
        <box size="0.01 0.018 0.032" />
        </geometry>
      </collision>
    <collision name="rear_side_1_arch_crown">
      <origin xyz="-0.106 -0.071 0.079" rpy="0 0 0" />
      <geometry>
        <box size="0.08 0.018 0.013" />
        </geometry>
      </collision>
    <collision name="rear_side_1_arch_front_leg">
      <origin xyz="-0.06 -0.071 0.064" rpy="0 0 0" />
      <geometry>
        <box size="0.01 0.018 0.032" />
        </geometry>
      </collision>
    <collision name="rear_side_1_arch_rear_leg">
      <origin xyz="-0.152 -0.071 0.064" rpy="0 0 0" />
      <geometry>
        <box size="0.01 0.018 0.032" />
        </geometry>
      </collision>
    <collision name="side_window_0">
      <origin xyz="0.039 0.061 0.143" rpy="0 0 0" />
      <geometry>
        <box size="0.058 0.004 0.027" />
        </geometry>
      </collision>
    <collision name="side_window_1">
      <origin xyz="-0.037 0.061 0.143" rpy="0 0 0" />
      <geometry>
        <box size="0.058 0.004 0.027" />
        </geometry>
      </collision>
    <collision name="side_window_2">
      <origin xyz="0.039 -0.061 0.143" rpy="0 0 0" />
      <geometry>
        <box size="0.058 0.004 0.027" />
        </geometry>
      </collision>
    <collision name="side_window_3">
      <origin xyz="-0.037 -0.061 0.143" rpy="0 0 0" />
      <geometry>
        <box size="0.058 0.004 0.027" />
        </geometry>
      </collision>
    <collision name="windshield">
      <origin xyz="0.085 0 0.144" rpy="0 0 0" />
      <geometry>
        <box size="0.006 0.09 0.028" />
        </geometry>
      </collision>
    <collision name="rear_tail_panel">
      <origin xyz="-0.155 0 0.096" rpy="0 0 0" />
      <geometry>
        <box size="0.006 0.096 0.03" />
        </geometry>
      </collision>
    <collision name="rear_hatch_pillar_0">
      <origin xyz="-0.151 0.064 0.136" rpy="0 0 0" />
      <geometry>
        <box size="0.012 0.008 0.056" />
        </geometry>
      </collision>
    <collision name="rear_hatch_pillar_1">
      <origin xyz="-0.151 -0.064 0.136" rpy="0 0 0" />
      <geometry>
        <box size="0.012 0.008 0.056" />
        </geometry>
      </collision>
    <collision name="door_hinge_pad_side_0_+0.074">
      <origin xyz="0.074 0.064 0.1" rpy="0 0 0" />
      <geometry>
        <box size="0.007 0.004 0.058" />
        </geometry>
      </collision>
    <collision name="door_hinge_pad_side_1_+0.074">
      <origin xyz="0.074 -0.064 0.1" rpy="0 0 0" />
      <geometry>
        <box size="0.007 0.004 0.058" />
        </geometry>
      </collision>
    <collision name="door_hinge_pad_side_0_-0.008">
      <origin xyz="-0.008 0.064 0.1" rpy="0 0 0" />
      <geometry>
        <box size="0.007 0.004 0.058" />
        </geometry>
      </collision>
    <collision name="door_hinge_pad_side_1_-0.008">
      <origin xyz="-0.008 -0.064 0.1" rpy="0 0 0" />
      <geometry>
        <box size="0.007 0.004 0.058" />
        </geometry>
      </collision>
    <collision name="hatch_top_hinge_pin">
      <origin xyz="-0.155 0 0.158" rpy="-1.5708 0 0" />
      <geometry>
        <cylinder radius="0.0026" length="0.128" />
        </geometry>
      </collision>
    <collision name="trunk_deck_hinge_pin">
      <origin xyz="-0.071 0 0.129" rpy="-1.5708 0 0" />
      <geometry>
        <cylinder radius="0.0024" length="0.074" />
        </geometry>
      </collision>
    </link>
  <link name="front_door_0">
    <visual name="door_panel">
      <origin xyz="-0.037 0.003 0" rpy="0 0 0" />
      <geometry>
        <box size="0.074 0.004 0.057" />
        </geometry>
      <material name="toy_red">
        <color rgba="0.82 0.05 0.035 1" />
        </material>
      </visual>
    <visual name="door_window">
      <origin xyz="-0.03848 0.0055 0.011" rpy="0 0 0" />
      <geometry>
        <box size="0.04144 0.0025 0.021" />
        </geometry>
      <material name="smoked_window">
        <color rgba="0.02 0.04 0.055 1" />
        </material>
      </visual>
    <visual name="door_handle">
      <origin xyz="-0.05624 0.0064 -0.01" rpy="0 0 0" />
      <geometry>
        <box size="0.012 0.004 0.004" />
        </geometry>
      <material name="soft_black_rubber">
        <color rgba="0.015 0.015 0.014 1" />
        </material>
      </visual>
    <visual name="hinge_barrel">
      <origin xyz="0 0.003 0" rpy="0 0 0" />
      <geometry>
        <cylinder radius="0.0022" length="0.059" />
        </geometry>
      <material name="silver_plastic">
        <color rgba="0.72 0.72 0.68 1" />
        </material>
      </visual>
    <collision name="door_panel">
      <origin xyz="-0.037 0.003 0" rpy="0 0 0" />
      <geometry>
        <box size="0.074 0.004 0.057" />
        </geometry>
      </collision>
    <collision name="door_window">
      <origin xyz="-0.03848 0.0055 0.011" rpy="0 0 0" />
      <geometry>
        <box size="0.04144 0.0025 0.021" />
        </geometry>
      </collision>
    <collision name="door_handle">
      <origin xyz="-0.05624 0.0064 -0.01" rpy="0 0 0" />
      <geometry>
        <box size="0.012 0.004 0.004" />
        </geometry>
      </collision>
    <collision name="hinge_barrel">
      <origin xyz="0 0.003 0" rpy="0 0 0" />
      <geometry>
        <cylinder radius="0.0022" length="0.059" />
        </geometry>
      </collision>
    </link>
  <link name="rear_door_0">
    <visual name="door_panel">
      <origin xyz="-0.034 0.003 0" rpy="0 0 0" />
      <geometry>
        <box size="0.068 0.004 0.057" />
        </geometry>
      <material name="toy_red">
        <color rgba="0.82 0.05 0.035 1" />
        </material>
      </visual>
    <visual name="door_window">
      <origin xyz="-0.03536 0.0055 0.011" rpy="0 0 0" />
      <geometry>
        <box size="0.03808 0.0025 0.021" />
        </geometry>
      <material name="smoked_window">
        <color rgba="0.02 0.04 0.055 1" />
        </material>
      </visual>
    <visual name="door_handle">
      <origin xyz="-0.05168 0.0064 -0.01" rpy="0 0 0" />
      <geometry>
        <box size="0.012 0.004 0.004" />
        </geometry>
      <material name="soft_black_rubber">
        <color rgba="0.015 0.015 0.014 1" />
        </material>
      </visual>
    <visual name="hinge_barrel">
      <origin xyz="0 0.003 0" rpy="0 0 0" />
      <geometry>
        <cylinder radius="0.0022" length="0.059" />
        </geometry>
      <material name="silver_plastic">
        <color rgba="0.72 0.72 0.68 1" />
        </material>
      </visual>
    <collision name="door_panel">
      <origin xyz="-0.034 0.003 0" rpy="0 0 0" />
      <geometry>
        <box size="0.068 0.004 0.057" />
        </geometry>
      </collision>
    <collision name="door_window">
      <origin xyz="-0.03536 0.0055 0.011" rpy="0 0 0" />
      <geometry>
        <box size="0.03808 0.0025 0.021" />
        </geometry>
      </collision>
    <collision name="door_handle">
      <origin xyz="-0.05168 0.0064 -0.01" rpy="0 0 0" />
      <geometry>
        <box size="0.012 0.004 0.004" />
        </geometry>
      </collision>
    <collision name="hinge_barrel">
      <origin xyz="0 0.003 0" rpy="0 0 0" />
      <geometry>
        <cylinder radius="0.0022" length="0.059" />
        </geometry>
      </collision>
    </link>
  <link name="front_door_1">
    <visual name="door_panel">
      <origin xyz="-0.037 -0.003 0" rpy="0 0 0" />
      <geometry>
        <box size="0.074 0.004 0.057" />
        </geometry>
      <material name="toy_red">
        <color rgba="0.82 0.05 0.035 1" />
        </material>
      </visual>
    <visual name="door_window">
      <origin xyz="-0.03848 -0.0055 0.011" rpy="0 0 0" />
      <geometry>
        <box size="0.04144 0.0025 0.021" />
        </geometry>
      <material name="smoked_window">
        <color rgba="0.02 0.04 0.055 1" />
        </material>
      </visual>
    <visual name="door_handle">
      <origin xyz="-0.05624 -0.0064 -0.01" rpy="0 0 0" />
      <geometry>
        <box size="0.012 0.004 0.004" />
        </geometry>
      <material name="soft_black_rubber">
        <color rgba="0.015 0.015 0.014 1" />
        </material>
      </visual>
    <visual name="hinge_barrel">
      <origin xyz="0 -0.003 0" rpy="0 0 0" />
      <geometry>
        <cylinder radius="0.0022" length="0.059" />
        </geometry>
      <material name="silver_plastic">
        <color rgba="0.72 0.72 0.68 1" />
        </material>
      </visual>
    <collision name="door_panel">
      <origin xyz="-0.037 -0.003 0" rpy="0 0 0" />
      <geometry>
        <box size="0.074 0.004 0.057" />
        </geometry>
      </collision>
    <collision name="door_window">
      <origin xyz="-0.03848 -0.0055 0.011" rpy="0 0 0" />
      <geometry>
        <box size="0.04144 0.0025 0.021" />
        </geometry>
      </collision>
    <collision name="door_handle">
      <origin xyz="-0.05624 -0.0064 -0.01" rpy="0 0 0" />
      <geometry>
        <box size="0.012 0.004 0.004" />
        </geometry>
      </collision>
    <collision name="hinge_barrel">
      <origin xyz="0 -0.003 0" rpy="0 0 0" />
      <geometry>
        <cylinder radius="0.0022" length="0.059" />
        </geometry>
      </collision>
    </link>
  <link name="rear_door_1">
    <visual name="door_panel">
      <origin xyz="-0.034 -0.003 0" rpy="0 0 0" />
      <geometry>
        <box size="0.068 0.004 0.057" />
        </geometry>
      <material name="toy_red">
        <color rgba="0.82 0.05 0.035 1" />
        </material>
      </visual>
    <visual name="door_window">
      <origin xyz="-0.03536 -0.0055 0.011" rpy="0 0 0" />
      <geometry>
        <box size="0.03808 0.0025 0.021" />
        </geometry>
      <material name="smoked_window">
        <color rgba="0.02 0.04 0.055 1" />
        </material>
      </visual>
    <visual name="door_handle">
      <origin xyz="-0.05168 -0.0064 -0.01" rpy="0 0 0" />
      <geometry>
        <box size="0.012 0.004 0.004" />
        </geometry>
      <material name="soft_black_rubber">
        <color rgba="0.015 0.015 0.014 1" />
        </material>
      </visual>
    <visual name="hinge_barrel">
      <origin xyz="0 -0.003 0" rpy="0 0 0" />
      <geometry>
        <cylinder radius="0.0022" length="0.059" />
        </geometry>
      <material name="silver_plastic">
        <color rgba="0.72 0.72 0.68 1" />
        </material>
      </visual>
    <collision name="door_panel">
      <origin xyz="-0.034 -0.003 0" rpy="0 0 0" />
      <geometry>
        <box size="0.068 0.004 0.057" />
        </geometry>
      </collision>
    <collision name="door_window">
      <origin xyz="-0.03536 -0.0055 0.011" rpy="0 0 0" />
      <geometry>
        <box size="0.03808 0.0025 0.021" />
        </geometry>
      </collision>
    <collision name="door_handle">
      <origin xyz="-0.05168 -0.0064 -0.01" rpy="0 0 0" />
      <geometry>
        <box size="0.012 0.004 0.004" />
        </geometry>
      </collision>
    <collision name="hinge_barrel">
      <origin xyz="0 -0.003 0" rpy="0 0 0" />
      <geometry>
        <cylinder radius="0.0022" length="0.059" />
        </geometry>
      </collision>
    </link>
  <link name="rear_hatch">
    <visual name="hatch_frame">
      <origin xyz="-0.003 0 -0.018" rpy="0 0 0" />
      <geometry>
        <box size="0.006 0.104 0.036" />
        </geometry>
      <material name="toy_red">
        <color rgba="0.82 0.05 0.035 1" />
        </material>
      </visual>
    <visual name="hatch_window">
      <origin xyz="-0.006 0 -0.019" rpy="0 0 0" />
      <geometry>
        <box size="0.0025 0.084 0.023" />
        </geometry>
      <material name="smoked_window">
        <color rgba="0.02 0.04 0.055 1" />
        </material>
      </visual>
    <visual name="hatch_hinge_barrel">
      <origin xyz="0 0 0" rpy="-1.5708 0 0" />
      <geometry>
        <cylinder radius="0.0022" length="0.096" />
        </geometry>
      <material name="silver_plastic">
        <color rgba="0.72 0.72 0.68 1" />
        </material>
      </visual>
    <collision name="hatch_frame">
      <origin xyz="-0.003 0 -0.018" rpy="0 0 0" />
      <geometry>
        <box size="0.006 0.104 0.036" />
        </geometry>
      </collision>
    <collision name="hatch_window">
      <origin xyz="-0.006 0 -0.019" rpy="0 0 0" />
      <geometry>
        <box size="0.0025 0.084 0.023" />
        </geometry>
      </collision>
    <collision name="hatch_hinge_barrel">
      <origin xyz="0 0 0" rpy="-1.5708 0 0" />
      <geometry>
        <cylinder radius="0.0022" length="0.096" />
        </geometry>
      </collision>
    </link>
  <link name="trunk_lid">
    <visual name="lid_panel">
      <origin xyz="-0.043 0 0.003" rpy="0 0 0" />
      <geometry>
        <box size="0.086 0.112 0.006" />
        </geometry>
      <material name="toy_red">
        <color rgba="0.82 0.05 0.035 1" />
        </material>
      </visual>
    <visual name="lid_pull">
      <origin xyz="-0.072 0 0.008" rpy="0 0 0" />
      <geometry>
        <box size="0.03 0.004 0.004" />
        </geometry>
      <material name="soft_black_rubber">
        <color rgba="0.015 0.015 0.014 1" />
        </material>
      </visual>
    <visual name="lid_hinge_barrel">
      <origin xyz="0 0 0.002" rpy="-1.5708 0 0" />
      <geometry>
        <cylinder radius="0.002" length="0.072" />
        </geometry>
      <material name="silver_plastic">
        <color rgba="0.72 0.72 0.68 1" />
        </material>
      </visual>
    <collision name="lid_panel">
      <origin xyz="-0.043 0 0.003" rpy="0 0 0" />
      <geometry>
        <box size="0.086 0.112 0.006" />
        </geometry>
      </collision>
    <collision name="lid_pull">
      <origin xyz="-0.072 0 0.008" rpy="0 0 0" />
      <geometry>
        <box size="0.03 0.004 0.004" />
        </geometry>
      </collision>
    <collision name="lid_hinge_barrel">
      <origin xyz="0 0 0.002" rpy="-1.5708 0 0" />
      <geometry>
        <cylinder radius="0.002" length="0.072" />
        </geometry>
      </collision>
    </link>
  <link name="wheel_0">
    <visual name="tire">
      <geometry>
        <mesh filename="assets/meshes/chunky_toy_tire.obj" />
        </geometry>
      <material name="soft_black_rubber">
        <color rgba="0.015 0.015 0.014 1" />
        </material>
      </visual>
    <visual name="rim">
      <geometry>
        <mesh filename="assets/meshes/silver_toy_rim.obj" />
        </geometry>
      <material name="silver_plastic">
        <color rgba="0.72 0.72 0.68 1" />
        </material>
      </visual>
    <collision name="tire">
      <geometry>
        <mesh filename="assets/meshes/chunky_toy_tire.obj" />
        </geometry>
      </collision>
    <collision name="rim">
      <geometry>
        <mesh filename="assets/meshes/silver_toy_rim.obj" />
        </geometry>
      </collision>
    </link>
  <link name="wheel_1">
    <visual name="tire">
      <geometry>
        <mesh filename="assets/meshes/chunky_toy_tire.obj" />
        </geometry>
      <material name="soft_black_rubber">
        <color rgba="0.015 0.015 0.014 1" />
        </material>
      </visual>
    <visual name="rim">
      <geometry>
        <mesh filename="assets/meshes/silver_toy_rim.obj" />
        </geometry>
      <material name="silver_plastic">
        <color rgba="0.72 0.72 0.68 1" />
        </material>
      </visual>
    <collision name="tire">
      <geometry>
        <mesh filename="assets/meshes/chunky_toy_tire.obj" />
        </geometry>
      </collision>
    <collision name="rim">
      <geometry>
        <mesh filename="assets/meshes/silver_toy_rim.obj" />
        </geometry>
      </collision>
    </link>
  <link name="wheel_2">
    <visual name="tire">
      <geometry>
        <mesh filename="assets/meshes/chunky_toy_tire.obj" />
        </geometry>
      <material name="soft_black_rubber">
        <color rgba="0.015 0.015 0.014 1" />
        </material>
      </visual>
    <visual name="rim">
      <geometry>
        <mesh filename="assets/meshes/silver_toy_rim.obj" />
        </geometry>
      <material name="silver_plastic">
        <color rgba="0.72 0.72 0.68 1" />
        </material>
      </visual>
    <collision name="tire">
      <geometry>
        <mesh filename="assets/meshes/chunky_toy_tire.obj" />
        </geometry>
      </collision>
    <collision name="rim">
      <geometry>
        <mesh filename="assets/meshes/silver_toy_rim.obj" />
        </geometry>
      </collision>
    </link>
  <link name="wheel_3">
    <visual name="tire">
      <geometry>
        <mesh filename="assets/meshes/chunky_toy_tire.obj" />
        </geometry>
      <material name="soft_black_rubber">
        <color rgba="0.015 0.015 0.014 1" />
        </material>
      </visual>
    <visual name="rim">
      <geometry>
        <mesh filename="assets/meshes/silver_toy_rim.obj" />
        </geometry>
      <material name="silver_plastic">
        <color rgba="0.72 0.72 0.68 1" />
        </material>
      </visual>
    <collision name="tire">
      <geometry>
        <mesh filename="assets/meshes/chunky_toy_tire.obj" />
        </geometry>
      </collision>
    <collision name="rim">
      <geometry>
        <mesh filename="assets/meshes/silver_toy_rim.obj" />
        </geometry>
      </collision>
    </link>
  <joint name="body_to_front_door_0" type="revolute">
    <origin xyz="0.074 0.068 0.1" rpy="0 0 0" />
    <parent link="body" />
    <child link="front_door_0" />
    <axis xyz="0 0 -1" />
    <limit effort="2" velocity="2.5" lower="0" upper="1.25" />
    </joint>
  <joint name="body_to_rear_door_0" type="revolute">
    <origin xyz="-0.008 0.068 0.1" rpy="0 0 0" />
    <parent link="body" />
    <child link="rear_door_0" />
    <axis xyz="0 0 -1" />
    <limit effort="2" velocity="2.5" lower="0" upper="1.25" />
    </joint>
  <joint name="body_to_front_door_1" type="revolute">
    <origin xyz="0.074 -0.068 0.1" rpy="0 0 0" />
    <parent link="body" />
    <child link="front_door_1" />
    <axis xyz="0 0 1" />
    <limit effort="2" velocity="2.5" lower="0" upper="1.25" />
    </joint>
  <joint name="body_to_rear_door_1" type="revolute">
    <origin xyz="-0.008 -0.068 0.1" rpy="0 0 0" />
    <parent link="body" />
    <child link="rear_door_1" />
    <axis xyz="0 0 1" />
    <limit effort="2" velocity="2.5" lower="0" upper="1.25" />
    </joint>
  <joint name="body_to_rear_hatch" type="revolute">
    <origin xyz="-0.155 0 0.158" rpy="0 0 0" />
    <parent link="body" />
    <child link="rear_hatch" />
    <axis xyz="0 1 0" />
    <limit effort="2" velocity="2" lower="0" upper="1.1" />
    </joint>
  <joint name="body_to_trunk_lid" type="revolute">
    <origin xyz="-0.071 0 0.129" rpy="0 0 0" />
    <parent link="body" />
    <child link="trunk_lid" />
    <axis xyz="0 1 0" />
    <limit effort="1.5" velocity="2" lower="0" upper="1.05" />
    </joint>
  <joint name="body_to_wheel_0" type="continuous">
    <origin xyz="0.094 0.086 0.036" rpy="0 0 1.5708" />
    <parent link="body" />
    <child link="wheel_0" />
    <axis xyz="1 0 0" />
    <limit effort="1" velocity="12" />
    </joint>
  <joint name="body_to_wheel_1" type="continuous">
    <origin xyz="0.094 -0.086 0.036" rpy="0 0 1.5708" />
    <parent link="body" />
    <child link="wheel_1" />
    <axis xyz="1 0 0" />
    <limit effort="1" velocity="12" />
    </joint>
  <joint name="body_to_wheel_2" type="continuous">
    <origin xyz="-0.106 0.086 0.036" rpy="0 0 1.5708" />
    <parent link="body" />
    <child link="wheel_2" />
    <axis xyz="1 0 0" />
    <limit effort="1" velocity="12" />
    </joint>
  <joint name="body_to_wheel_3" type="continuous">
    <origin xyz="-0.106 -0.086 0.036" rpy="0 0 1.5708" />
    <parent link="body" />
    <child link="wheel_3" />
    <axis xyz="1 0 0" />
    <limit effort="1" velocity="12" />
    </joint>
  </robot>
