<robot name="hotel_wall_safe">
  <material name="powder_coated_steel">
    <color rgba="0.18 0.19 0.2 1" />
    </material>
  <material name="dark_interior_steel">
    <color rgba="0.07 0.075 0.08 1" />
    </material>
  <material name="door_steel">
    <color rgba="0.24 0.25 0.26 1" />
    </material>
  <material name="recess_shadow">
    <color rgba="0.11 0.12 0.13 1" />
    </material>
  <material name="dial_black">
    <color rgba="0.015 0.016 0.018 1" />
    </material>
  <material name="dial_mark">
    <color rgba="0.86 0.86 0.8 1" />
    </material>
  <material name="brushed_metal">
    <color rgba="0.62 0.61 0.56 1" />
    </material>
  <material name="flap_blue_gray">
    <color rgba="0.34 0.4 0.46 1" />
    </material>
  <link name="body">
    <visual name="back_wall">
      <origin xyz="0 -0.2375 0" rpy="0 0 0" />
      <geometry>
        <box size="0.5 0.025 0.33" />
        </geometry>
      <material name="dark_interior_steel" />
      </visual>
    <visual name="side_wall_0">
      <origin xyz="-0.2375 -0.125 0" rpy="0 0 0" />
      <geometry>
        <box size="0.025 0.25 0.33" />
        </geometry>
      <material name="dark_interior_steel" />
      </visual>
    <visual name="side_wall_1">
      <origin xyz="0.2375 -0.125 0" rpy="0 0 0" />
      <geometry>
        <box size="0.025 0.25 0.33" />
        </geometry>
      <material name="dark_interior_steel" />
      </visual>
    <visual name="top_wall">
      <origin xyz="0 -0.125 0.1525" rpy="0 0 0" />
      <geometry>
        <box size="0.5 0.25 0.025" />
        </geometry>
      <material name="dark_interior_steel" />
      </visual>
    <visual name="bottom_wall">
      <origin xyz="0 -0.125 -0.1525" rpy="0 0 0" />
      <geometry>
        <box size="0.5 0.25 0.025" />
        </geometry>
      <material name="dark_interior_steel" />
      </visual>
    <visual name="flange_side_0">
      <origin xyz="-0.27 0 0" rpy="0 0 0" />
      <geometry>
        <box size="0.08 0.028 0.43" />
        </geometry>
      <material name="powder_coated_steel" />
      </visual>
    <visual name="flange_side_1">
      <origin xyz="0.27 0 0" rpy="0 0 0" />
      <geometry>
        <box size="0.08 0.028 0.43" />
        </geometry>
      <material name="powder_coated_steel" />
      </visual>
    <visual name="flange_top">
      <origin xyz="0 0 0.1825" rpy="0 0 0" />
      <geometry>
        <box size="0.62 0.028 0.065" />
        </geometry>
      <material name="powder_coated_steel" />
      </visual>
    <visual name="flange_bottom">
      <origin xyz="0 0 -0.1825" rpy="0 0 0" />
      <geometry>
        <box size="0.62 0.028 0.065" />
        </geometry>
      <material name="powder_coated_steel" />
      </visual>
    <visual name="hinge_mount">
      <origin xyz="0.221 0.03 0" rpy="0 0 0" />
      <geometry>
        <box size="0.03 0.032 0.2491" />
        </geometry>
      <material name="brushed_metal" />
      </visual>
    <visual name="flap_bracket_0">
      <origin xyz="-0.16 -0.08 0.13" rpy="0 0 0" />
      <geometry>
        <box size="0.014 0.02 0.038" />
        </geometry>
      <material name="brushed_metal" />
      </visual>
    <visual name="flap_bracket_1">
      <origin xyz="0.16 -0.08 0.13" rpy="0 0 0" />
      <geometry>
        <box size="0.014 0.02 0.038" />
        </geometry>
      <material name="brushed_metal" />
      </visual>
    <collision name="back_wall">
      <origin xyz="0 -0.2375 0" rpy="0 0 0" />
      <geometry>
        <box size="0.5 0.025 0.33" />
        </geometry>
      </collision>
    <collision name="side_wall_0">
      <origin xyz="-0.2375 -0.125 0" rpy="0 0 0" />
      <geometry>
        <box size="0.025 0.25 0.33" />
        </geometry>
      </collision>
    <collision name="side_wall_1">
      <origin xyz="0.2375 -0.125 0" rpy="0 0 0" />
      <geometry>
        <box size="0.025 0.25 0.33" />
        </geometry>
      </collision>
    <collision name="top_wall">
      <origin xyz="0 -0.125 0.1525" rpy="0 0 0" />
      <geometry>
        <box size="0.5 0.25 0.025" />
        </geometry>
      </collision>
    <collision name="bottom_wall">
      <origin xyz="0 -0.125 -0.1525" rpy="0 0 0" />
      <geometry>
        <box size="0.5 0.25 0.025" />
        </geometry>
      </collision>
    <collision name="flange_side_0">
      <origin xyz="-0.27 0 0" rpy="0 0 0" />
      <geometry>
        <box size="0.08 0.028 0.43" />
        </geometry>
      </collision>
    <collision name="flange_side_1">
      <origin xyz="0.27 0 0" rpy="0 0 0" />
      <geometry>
        <box size="0.08 0.028 0.43" />
        </geometry>
      </collision>
    <collision name="flange_top">
      <origin xyz="0 0 0.1825" rpy="0 0 0" />
      <geometry>
        <box size="0.62 0.028 0.065" />
        </geometry>
      </collision>
    <collision name="flange_bottom">
      <origin xyz="0 0 -0.1825" rpy="0 0 0" />
      <geometry>
        <box size="0.62 0.028 0.065" />
        </geometry>
      </collision>
    <collision name="hinge_mount">
      <origin xyz="0.221 0.03 0" rpy="0 0 0" />
      <geometry>
        <box size="0.03 0.032 0.2491" />
        </geometry>
      </collision>
    <collision name="flap_bracket_0">
      <origin xyz="-0.16 -0.08 0.13" rpy="0 0 0" />
      <geometry>
        <box size="0.014 0.02 0.038" />
        </geometry>
      </collision>
    <collision name="flap_bracket_1">
      <origin xyz="0.16 -0.08 0.13" rpy="0 0 0" />
      <geometry>
        <box size="0.014 0.02 0.038" />
        </geometry>
      </collision>
    </link>
  <link name="door">
    <visual name="door_slab">
      <origin xyz="-0.195 0 0" rpy="0 0 0" />
      <geometry>
        <box size="0.39 0.035 0.265" />
        </geometry>
      <material name="door_steel" />
      </visual>
    <visual name="recess_top">
      <origin xyz="-0.195 0.0183 0.106" rpy="0 0 0" />
      <geometry>
        <box size="0.33 0.003 0.012" />
        </geometry>
      <material name="recess_shadow" />
      </visual>
    <visual name="recess_bottom">
      <origin xyz="-0.195 0.0183 -0.119" rpy="0 0 0" />
      <geometry>
        <box size="0.33 0.003 0.012" />
        </geometry>
      <material name="recess_shadow" />
      </visual>
    <visual name="recess_side_0">
      <origin xyz="-0.324 0.0183 -0.006" rpy="0 0 0" />
      <geometry>
        <box size="0.012 0.003 0.195" />
        </geometry>
      <material name="recess_shadow" />
      </visual>
    <visual name="recess_side_1">
      <origin xyz="-0.006 0.0183 -0.006" rpy="0 0 0" />
      <geometry>
        <box size="0.012 0.003 0.195" />
        </geometry>
      <material name="recess_shadow" />
      </visual>
    <visual name="hinge_barrel">
      <geometry>
        <cylinder radius="0.013" length="0.2491" />
        </geometry>
      <material name="brushed_metal" />
      </visual>
    <collision name="door_slab">
      <origin xyz="-0.195 0 0" rpy="0 0 0" />
      <geometry>
        <box size="0.39 0.035 0.265" />
        </geometry>
      </collision>
    <collision name="recess_top">
      <origin xyz="-0.195 0.0183 0.106" rpy="0 0 0" />
      <geometry>
        <box size="0.33 0.003 0.012" />
        </geometry>
      </collision>
    <collision name="recess_bottom">
      <origin xyz="-0.195 0.0183 -0.119" rpy="0 0 0" />
      <geometry>
        <box size="0.33 0.003 0.012" />
        </geometry>
      </collision>
    <collision name="recess_side_0">
      <origin xyz="-0.324 0.0183 -0.006" rpy="0 0 0" />
      <geometry>
        <box size="0.012 0.003 0.195" />
        </geometry>
      </collision>
    <collision name="recess_side_1">
      <origin xyz="-0.006 0.0183 -0.006" rpy="0 0 0" />
      <geometry>
        <box size="0.012 0.003 0.195" />
        </geometry>
      </collision>
    <collision name="hinge_barrel">
      <geometry>
        <cylinder radius="0.013" length="0.2491" />
        </geometry>
      </collision>
    </link>
  <link name="dial">
    <visual name="dial_cap">
      <origin xyz="0 0 0" rpy="-1.5708 0 0" />
      <geometry>
        <mesh filename="assets/meshes/combination_dial.obj" />
        </geometry>
      <material name="dial_black" />
      </visual>
    <visual name="center_cap">
      <origin xyz="0 0.014 0" rpy="-1.5708 0 0" />
      <geometry>
        <cylinder radius="0.018" length="0.006" />
        </geometry>
      <material name="brushed_metal" />
      </visual>
    <visual name="dial_spindle">
      <origin xyz="0 -0.028 0" rpy="-1.5708 0 0" />
      <geometry>
        <cylinder radius="0.01" length="0.04" />
        </geometry>
      <material name="brushed_metal" />
      </visual>
    <collision name="dial_cap">
      <origin xyz="0 0 0" rpy="-1.5708 0 0" />
      <geometry>
        <mesh filename="assets/meshes/combination_dial.obj" />
        </geometry>
      </collision>
    <collision name="center_cap">
      <origin xyz="0 0.014 0" rpy="-1.5708 0 0" />
      <geometry>
        <cylinder radius="0.018" length="0.006" />
        </geometry>
      </collision>
    <collision name="dial_spindle">
      <origin xyz="0 -0.028 0" rpy="-1.5708 0 0" />
      <geometry>
        <cylinder radius="0.01" length="0.04" />
        </geometry>
      </collision>
    </link>
  <link name="handle">
    <visual name="front_hub">
      <origin xyz="0 0 0" rpy="-1.5708 0 0" />
      <geometry>
        <cylinder radius="0.025" length="0.026" />
        </geometry>
      <material name="brushed_metal" />
      </visual>
    <visual name="handle_spindle">
      <origin xyz="0 -0.028 0" rpy="-1.5708 0 0" />
      <geometry>
        <cylinder radius="0.012" length="0.04" />
        </geometry>
      <material name="brushed_metal" />
      </visual>
    <visual name="spoke_0">
      <origin xyz="0.032 0.009 0" rpy="0 -0 0" />
      <geometry>
        <box size="0.052 0.016 0.014" />
        </geometry>
      <material name="brushed_metal" />
      </visual>
    <visual name="spoke_1">
      <origin xyz="-0.032 0.009 3.91887e-18" rpy="0 -3.14159 0" />
      <geometry>
        <box size="0.052 0.016 0.014" />
        </geometry>
      <material name="brushed_metal" />
      </visual>
    <visual name="spoke_2">
      <origin xyz="1.95943e-18 0.009 -0.032" rpy="0 1.5708 0" />
      <geometry>
        <box size="0.052 0.016 0.014" />
        </geometry>
      <material name="brushed_metal" />
      </visual>
    <collision name="front_hub">
      <origin xyz="0 0 0" rpy="-1.5708 0 0" />
      <geometry>
        <cylinder radius="0.025" length="0.026" />
        </geometry>
      </collision>
    <collision name="handle_spindle">
      <origin xyz="0 -0.028 0" rpy="-1.5708 0 0" />
      <geometry>
        <cylinder radius="0.012" length="0.04" />
        </geometry>
      </collision>
    <collision name="spoke_0">
      <origin xyz="0.032 0.009 0" rpy="0 -0 0" />
      <geometry>
        <box size="0.052 0.016 0.014" />
        </geometry>
      </collision>
    <collision name="spoke_1">
      <origin xyz="-0.032 0.009 3.91887e-18" rpy="0 -3.14159 0" />
      <geometry>
        <box size="0.052 0.016 0.014" />
        </geometry>
      </collision>
    <collision name="spoke_2">
      <origin xyz="1.95943e-18 0.009 -0.032" rpy="0 1.5708 0" />
      <geometry>
        <box size="0.052 0.016 0.014" />
        </geometry>
      </collision>
    </link>
  <link name="document_flap">
    <visual name="flap_panel">
      <origin xyz="0 0 -0.0375" rpy="0 0 0" />
      <geometry>
        <box size="0.31 0.007 0.075" />
        </geometry>
      <material name="flap_blue_gray" />
      </visual>
    <visual name="top_sleeve">
      <origin xyz="0 0 0" rpy="0 1.5708 0" />
      <geometry>
        <cylinder radius="0.006" length="0.31" />
        </geometry>
      <material name="brushed_metal" />
      </visual>
    <visual name="finger_lip">
      <origin xyz="0 0.006 -0.069" rpy="0 0 0" />
      <geometry>
        <box size="0.105 0.012 0.012" />
        </geometry>
      <material name="brushed_metal" />
      </visual>
    <collision name="flap_panel">
      <origin xyz="0 0 -0.0375" rpy="0 0 0" />
      <geometry>
        <box size="0.31 0.007 0.075" />
        </geometry>
      </collision>
    <collision name="top_sleeve">
      <origin xyz="0 0 0" rpy="0 1.5708 0" />
      <geometry>
        <cylinder radius="0.006" length="0.31" />
        </geometry>
      </collision>
    <collision name="finger_lip">
      <origin xyz="0 0.006 -0.069" rpy="0 0 0" />
      <geometry>
        <box size="0.105 0.012 0.012" />
        </geometry>
      </collision>
    </link>
  <joint name="body_to_door" type="revolute">
    <origin xyz="0.195 0.0415 0" rpy="0 0 -0.62" />
    <parent link="body" />
    <child link="door" />
    <axis xyz="0 0 -1" />
    <limit effort="18" velocity="1.2" lower="-0.62" upper="1.2" />
    </joint>
  <joint name="door_to_dial" type="continuous">
    <origin xyz="-0.195 0.033 0" rpy="0 0 0" />
    <parent link="door" />
    <child link="dial" />
    <axis xyz="0 1 0" />
    <limit effort="1.5" velocity="6" />
    </joint>
  <joint name="door_to_handle" type="revolute">
    <origin xyz="-0.195 0.0345 -0.082" rpy="0 0 0" />
    <parent link="door" />
    <child link="handle" />
    <axis xyz="0 1 0" />
    <limit effort="8" velocity="2" lower="0" upper="1.5708" />
    </joint>
  <joint name="body_to_document_flap" type="revolute">
    <origin xyz="0 -0.08 0.118" rpy="0 0 0" />
    <parent link="body" />
    <child link="document_flap" />
    <axis xyz="1 0 0" />
    <limit effort="2.5" velocity="1.5" lower="0" upper="1.25" />
    </joint>
  </robot>
