<robot name="finger_phalanx_chain">
  <material name="clear_acrylic">
    <color rgba="0.58 0.86 1 0.38" />
    </material>
  <material name="smoke_acrylic">
    <color rgba="0.45 0.63 0.78 0.45" />
    </material>
  <material name="brushed_metal">
    <color rgba="0.72 0.73 0.7 1" />
    </material>
  <material name="dark_polymer">
    <color rgba="0.035 0.038 0.045 1" />
    </material>
  <material name="fingertip_rubber">
    <color rgba="0.03 0.03 0.035 1" />
    </material>
  <link name="base_knuckle">
    <visual name="palm_mount">
      <origin xyz="-0.044 0 -0.06" rpy="0 0 0" />
      <geometry>
        <box size="0.135 0.092 0.03" />
        </geometry>
      <material name="dark_polymer">
        <color rgba="0.035 0.038 0.045 1" />
        </material>
      </visual>
    <visual name="knuckle_bridge">
      <origin xyz="-0.004 0 -0.043" rpy="0 0 0" />
      <geometry>
        <box size="0.052 0.086 0.018" />
        </geometry>
      <material name="dark_polymer">
        <color rgba="0.035 0.038 0.045 1" />
        </material>
      </visual>
    <visual name="side_0_cheek">
      <origin xyz="0 0.034 0" rpy="0 0 0" />
      <geometry>
        <mesh filename="assets/meshes/base_side_plate.obj" />
        </geometry>
      <material name="smoke_acrylic">
        <color rgba="0.45 0.63 0.78 0.45" />
        </material>
      </visual>
    <visual name="side_1_cheek">
      <origin xyz="0 -0.034 0" rpy="0 0 0" />
      <geometry>
        <mesh filename="assets/meshes/base_side_plate.obj" />
        </geometry>
      <material name="smoke_acrylic">
        <color rgba="0.45 0.63 0.78 0.45" />
        </material>
      </visual>
    <collision name="palm_mount">
      <origin xyz="-0.044 0 -0.06" rpy="0 0 0" />
      <geometry>
        <box size="0.135 0.092 0.03" />
        </geometry>
      </collision>
    <collision name="knuckle_bridge">
      <origin xyz="-0.004 0 -0.043" rpy="0 0 0" />
      <geometry>
        <box size="0.052 0.086 0.018" />
        </geometry>
      </collision>
    <collision name="side_0_cheek">
      <origin xyz="0 0.034 0" rpy="0 0 0" />
      <geometry>
        <mesh filename="assets/meshes/base_side_plate.obj" />
        </geometry>
      </collision>
    <collision name="side_1_cheek">
      <origin xyz="0 -0.034 0" rpy="0 0 0" />
      <geometry>
        <mesh filename="assets/meshes/base_side_plate.obj" />
        </geometry>
      </collision>
    </link>
  <link name="proximal_phalanx">
    <visual name="side_0_plate">
      <origin xyz="0 0.02 0" rpy="0 0 0" />
      <geometry>
        <mesh filename="assets/meshes/proximal_side_plate.obj" />
        </geometry>
      <material name="clear_acrylic">
        <color rgba="0.58 0.86 1 0.38" />
        </material>
      </visual>
    <visual name="side_1_plate">
      <origin xyz="0 -0.02 0" rpy="0 0 0" />
      <geometry>
        <mesh filename="assets/meshes/proximal_side_plate.obj" />
        </geometry>
      <material name="clear_acrylic">
        <color rgba="0.58 0.86 1 0.38" />
        </material>
      </visual>
    <visual name="proximal_pin">
      <origin xyz="0 0 0" rpy="1.5708 0 0" />
      <geometry>
        <cylinder radius="0.0065" length="0.088" />
        </geometry>
      <material name="brushed_metal">
        <color rgba="0.72 0.73 0.7 1" />
        </material>
      </visual>
    <visual name="upper_bushing">
      <origin xyz="0 0.02 0" rpy="1.5708 0 0" />
      <geometry>
        <cylinder radius="0.012" length="0.006" />
        </geometry>
      <material name="brushed_metal">
        <color rgba="0.72 0.73 0.7 1" />
        </material>
      </visual>
    <visual name="lower_bushing">
      <origin xyz="0 -0.02 0" rpy="1.5708 0 0" />
      <geometry>
        <cylinder radius="0.012" length="0.006" />
        </geometry>
      <material name="brushed_metal">
        <color rgba="0.72 0.73 0.7 1" />
        </material>
      </visual>
    <visual name="upper_pin_head">
      <origin xyz="0 0.043 0" rpy="1.5708 0 0" />
      <geometry>
        <cylinder radius="0.011" length="0.005" />
        </geometry>
      <material name="brushed_metal">
        <color rgba="0.72 0.73 0.7 1" />
        </material>
      </visual>
    <visual name="lower_pin_head">
      <origin xyz="0 -0.043 0" rpy="1.5708 0 0" />
      <geometry>
        <cylinder radius="0.011" length="0.005" />
        </geometry>
      <material name="brushed_metal">
        <color rgba="0.72 0.73 0.7 1" />
        </material>
      </visual>
    <visual name="center_spine">
      <origin xyz="0.0525 0 -0.004" rpy="0 0 0" />
      <geometry>
        <box size="0.059 0.041 0.01" />
        </geometry>
      <material name="brushed_metal">
        <color rgba="0.72 0.73 0.7 1" />
        </material>
      </visual>
    <visual name="spacer_0">
      <origin xyz="0.0378 0 -0.014" rpy="1.5708 0 0" />
      <geometry>
        <cylinder radius="0.0045" length="0.047" />
        </geometry>
      <material name="brushed_metal">
        <color rgba="0.72 0.73 0.7 1" />
        </material>
      </visual>
    <visual name="spacer_1">
      <origin xyz="0.0546 0 -0.014" rpy="1.5708 0 0" />
      <geometry>
        <cylinder radius="0.0045" length="0.047" />
        </geometry>
      <material name="brushed_metal">
        <color rgba="0.72 0.73 0.7 1" />
        </material>
      </visual>
    <collision name="side_0_plate">
      <origin xyz="0 0.02 0" rpy="0 0 0" />
      <geometry>
        <mesh filename="assets/meshes/proximal_side_plate.obj" />
        </geometry>
      </collision>
    <collision name="side_1_plate">
      <origin xyz="0 -0.02 0" rpy="0 0 0" />
      <geometry>
        <mesh filename="assets/meshes/proximal_side_plate.obj" />
        </geometry>
      </collision>
    <collision name="proximal_pin">
      <origin xyz="0 0 0" rpy="1.5708 0 0" />
      <geometry>
        <cylinder radius="0.0065" length="0.088" />
        </geometry>
      </collision>
    <collision name="upper_bushing">
      <origin xyz="0 0.02 0" rpy="1.5708 0 0" />
      <geometry>
        <cylinder radius="0.012" length="0.006" />
        </geometry>
      </collision>
    <collision name="lower_bushing">
      <origin xyz="0 -0.02 0" rpy="1.5708 0 0" />
      <geometry>
        <cylinder radius="0.012" length="0.006" />
        </geometry>
      </collision>
    <collision name="upper_pin_head">
      <origin xyz="0 0.043 0" rpy="1.5708 0 0" />
      <geometry>
        <cylinder radius="0.011" length="0.005" />
        </geometry>
      </collision>
    <collision name="lower_pin_head">
      <origin xyz="0 -0.043 0" rpy="1.5708 0 0" />
      <geometry>
        <cylinder radius="0.011" length="0.005" />
        </geometry>
      </collision>
    <collision name="center_spine">
      <origin xyz="0.0525 0 -0.004" rpy="0 0 0" />
      <geometry>
        <box size="0.059 0.041 0.01" />
        </geometry>
      </collision>
    <collision name="spacer_0">
      <origin xyz="0.0378 0 -0.014" rpy="1.5708 0 0" />
      <geometry>
        <cylinder radius="0.0045" length="0.047" />
        </geometry>
      </collision>
    <collision name="spacer_1">
      <origin xyz="0.0546 0 -0.014" rpy="1.5708 0 0" />
      <geometry>
        <cylinder radius="0.0045" length="0.047" />
        </geometry>
      </collision>
    </link>
  <link name="middle_phalanx">
    <visual name="side_0_plate">
      <origin xyz="0 0.032 0" rpy="0 0 0" />
      <geometry>
        <mesh filename="assets/meshes/middle_side_plate.obj" />
        </geometry>
      <material name="clear_acrylic">
        <color rgba="0.58 0.86 1 0.38" />
        </material>
      </visual>
    <visual name="side_1_plate">
      <origin xyz="0 -0.032 0" rpy="0 0 0" />
      <geometry>
        <mesh filename="assets/meshes/middle_side_plate.obj" />
        </geometry>
      <material name="clear_acrylic">
        <color rgba="0.58 0.86 1 0.38" />
        </material>
      </visual>
    <visual name="proximal_pin">
      <origin xyz="0 0 0" rpy="1.5708 0 0" />
      <geometry>
        <cylinder radius="0.0065" length="0.088" />
        </geometry>
      <material name="brushed_metal">
        <color rgba="0.72 0.73 0.7 1" />
        </material>
      </visual>
    <visual name="upper_bushing">
      <origin xyz="0 0.032 0" rpy="1.5708 0 0" />
      <geometry>
        <cylinder radius="0.012" length="0.006" />
        </geometry>
      <material name="brushed_metal">
        <color rgba="0.72 0.73 0.7 1" />
        </material>
      </visual>
    <visual name="lower_bushing">
      <origin xyz="0 -0.032 0" rpy="1.5708 0 0" />
      <geometry>
        <cylinder radius="0.012" length="0.006" />
        </geometry>
      <material name="brushed_metal">
        <color rgba="0.72 0.73 0.7 1" />
        </material>
      </visual>
    <visual name="upper_pin_head">
      <origin xyz="0 0.043 0" rpy="1.5708 0 0" />
      <geometry>
        <cylinder radius="0.011" length="0.005" />
        </geometry>
      <material name="brushed_metal">
        <color rgba="0.72 0.73 0.7 1" />
        </material>
      </visual>
    <visual name="lower_pin_head">
      <origin xyz="0 -0.043 0" rpy="1.5708 0 0" />
      <geometry>
        <cylinder radius="0.011" length="0.005" />
        </geometry>
      <material name="brushed_metal">
        <color rgba="0.72 0.73 0.7 1" />
        </material>
      </visual>
    <visual name="center_spine">
      <origin xyz="0.039 0 -0.004" rpy="0 0 0" />
      <geometry>
        <box size="0.032 0.0656 0.01" />
        </geometry>
      <material name="brushed_metal">
        <color rgba="0.72 0.73 0.7 1" />
        </material>
      </visual>
    <visual name="spacer_0">
      <origin xyz="0.02808 0 -0.014" rpy="1.5708 0 0" />
      <geometry>
        <cylinder radius="0.0045" length="0.0752" />
        </geometry>
      <material name="brushed_metal">
        <color rgba="0.72 0.73 0.7 1" />
        </material>
      </visual>
    <visual name="spacer_1">
      <origin xyz="0.04056 0 -0.014" rpy="1.5708 0 0" />
      <geometry>
        <cylinder radius="0.0045" length="0.0752" />
        </geometry>
      <material name="brushed_metal">
        <color rgba="0.72 0.73 0.7 1" />
        </material>
      </visual>
    <collision name="side_0_plate">
      <origin xyz="0 0.032 0" rpy="0 0 0" />
      <geometry>
        <mesh filename="assets/meshes/middle_side_plate.obj" />
        </geometry>
      </collision>
    <collision name="side_1_plate">
      <origin xyz="0 -0.032 0" rpy="0 0 0" />
      <geometry>
        <mesh filename="assets/meshes/middle_side_plate.obj" />
        </geometry>
      </collision>
    <collision name="proximal_pin">
      <origin xyz="0 0 0" rpy="1.5708 0 0" />
      <geometry>
        <cylinder radius="0.0065" length="0.088" />
        </geometry>
      </collision>
    <collision name="upper_bushing">
      <origin xyz="0 0.032 0" rpy="1.5708 0 0" />
      <geometry>
        <cylinder radius="0.012" length="0.006" />
        </geometry>
      </collision>
    <collision name="lower_bushing">
      <origin xyz="0 -0.032 0" rpy="1.5708 0 0" />
      <geometry>
        <cylinder radius="0.012" length="0.006" />
        </geometry>
      </collision>
    <collision name="upper_pin_head">
      <origin xyz="0 0.043 0" rpy="1.5708 0 0" />
      <geometry>
        <cylinder radius="0.011" length="0.005" />
        </geometry>
      </collision>
    <collision name="lower_pin_head">
      <origin xyz="0 -0.043 0" rpy="1.5708 0 0" />
      <geometry>
        <cylinder radius="0.011" length="0.005" />
        </geometry>
      </collision>
    <collision name="center_spine">
      <origin xyz="0.039 0 -0.004" rpy="0 0 0" />
      <geometry>
        <box size="0.032 0.0656 0.01" />
        </geometry>
      </collision>
    <collision name="spacer_0">
      <origin xyz="0.02808 0 -0.014" rpy="1.5708 0 0" />
      <geometry>
        <cylinder radius="0.0045" length="0.0752" />
        </geometry>
      </collision>
    <collision name="spacer_1">
      <origin xyz="0.04056 0 -0.014" rpy="1.5708 0 0" />
      <geometry>
        <cylinder radius="0.0045" length="0.0752" />
        </geometry>
      </collision>
    </link>
  <link name="distal_phalanx">
    <visual name="side_0_plate">
      <origin xyz="0 0.02 0" rpy="0 0 0" />
      <geometry>
        <mesh filename="assets/meshes/distal_side_plate.obj" />
        </geometry>
      <material name="clear_acrylic">
        <color rgba="0.58 0.86 1 0.38" />
        </material>
      </visual>
    <visual name="side_1_plate">
      <origin xyz="0 -0.02 0" rpy="0 0 0" />
      <geometry>
        <mesh filename="assets/meshes/distal_side_plate.obj" />
        </geometry>
      <material name="clear_acrylic">
        <color rgba="0.58 0.86 1 0.38" />
        </material>
      </visual>
    <visual name="proximal_pin">
      <origin xyz="0 0 0" rpy="1.5708 0 0" />
      <geometry>
        <cylinder radius="0.0065" length="0.088" />
        </geometry>
      <material name="brushed_metal">
        <color rgba="0.72 0.73 0.7 1" />
        </material>
      </visual>
    <visual name="upper_bushing">
      <origin xyz="0 0.02 0" rpy="1.5708 0 0" />
      <geometry>
        <cylinder radius="0.012" length="0.006" />
        </geometry>
      <material name="brushed_metal">
        <color rgba="0.72 0.73 0.7 1" />
        </material>
      </visual>
    <visual name="lower_bushing">
      <origin xyz="0 -0.02 0" rpy="1.5708 0 0" />
      <geometry>
        <cylinder radius="0.012" length="0.006" />
        </geometry>
      <material name="brushed_metal">
        <color rgba="0.72 0.73 0.7 1" />
        </material>
      </visual>
    <visual name="upper_pin_head">
      <origin xyz="0 0.043 0" rpy="1.5708 0 0" />
      <geometry>
        <cylinder radius="0.011" length="0.005" />
        </geometry>
      <material name="brushed_metal">
        <color rgba="0.72 0.73 0.7 1" />
        </material>
      </visual>
    <visual name="lower_pin_head">
      <origin xyz="0 -0.043 0" rpy="1.5708 0 0" />
      <geometry>
        <cylinder radius="0.011" length="0.005" />
        </geometry>
      <material name="brushed_metal">
        <color rgba="0.72 0.73 0.7 1" />
        </material>
      </visual>
    <visual name="center_spine">
      <origin xyz="0.03 0 -0.004" rpy="0 0 0" />
      <geometry>
        <box size="0.02 0.041 0.01" />
        </geometry>
      <material name="brushed_metal">
        <color rgba="0.72 0.73 0.7 1" />
        </material>
      </visual>
    <visual name="spacer_0">
      <origin xyz="0.0216 0 -0.014" rpy="1.5708 0 0" />
      <geometry>
        <cylinder radius="0.0045" length="0.047" />
        </geometry>
      <material name="brushed_metal">
        <color rgba="0.72 0.73 0.7 1" />
        </material>
      </visual>
    <visual name="spacer_1">
      <origin xyz="0.0312 0 -0.014" rpy="1.5708 0 0" />
      <geometry>
        <cylinder radius="0.0045" length="0.047" />
        </geometry>
      <material name="brushed_metal">
        <color rgba="0.72 0.73 0.7 1" />
        </material>
      </visual>
    <visual name="tip_pad">
      <origin xyz="0.07 0 -0.002" rpy="0 0 0" />
      <geometry>
        <box size="0.02 0.046 0.012" />
        </geometry>
      <material name="fingertip_rubber">
        <color rgba="0.03 0.03 0.035 1" />
        </material>
      </visual>
    <collision name="side_0_plate">
      <origin xyz="0 0.02 0" rpy="0 0 0" />
      <geometry>
        <mesh filename="assets/meshes/distal_side_plate.obj" />
        </geometry>
      </collision>
    <collision name="side_1_plate">
      <origin xyz="0 -0.02 0" rpy="0 0 0" />
      <geometry>
        <mesh filename="assets/meshes/distal_side_plate.obj" />
        </geometry>
      </collision>
    <collision name="proximal_pin">
      <origin xyz="0 0 0" rpy="1.5708 0 0" />
      <geometry>
        <cylinder radius="0.0065" length="0.088" />
        </geometry>
      </collision>
    <collision name="upper_bushing">
      <origin xyz="0 0.02 0" rpy="1.5708 0 0" />
      <geometry>
        <cylinder radius="0.012" length="0.006" />
        </geometry>
      </collision>
    <collision name="lower_bushing">
      <origin xyz="0 -0.02 0" rpy="1.5708 0 0" />
      <geometry>
        <cylinder radius="0.012" length="0.006" />
        </geometry>
      </collision>
    <collision name="upper_pin_head">
      <origin xyz="0 0.043 0" rpy="1.5708 0 0" />
      <geometry>
        <cylinder radius="0.011" length="0.005" />
        </geometry>
      </collision>
    <collision name="lower_pin_head">
      <origin xyz="0 -0.043 0" rpy="1.5708 0 0" />
      <geometry>
        <cylinder radius="0.011" length="0.005" />
        </geometry>
      </collision>
    <collision name="center_spine">
      <origin xyz="0.03 0 -0.004" rpy="0 0 0" />
      <geometry>
        <box size="0.02 0.041 0.01" />
        </geometry>
      </collision>
    <collision name="spacer_0">
      <origin xyz="0.0216 0 -0.014" rpy="1.5708 0 0" />
      <geometry>
        <cylinder radius="0.0045" length="0.047" />
        </geometry>
      </collision>
    <collision name="spacer_1">
      <origin xyz="0.0312 0 -0.014" rpy="1.5708 0 0" />
      <geometry>
        <cylinder radius="0.0045" length="0.047" />
        </geometry>
      </collision>
    <collision name="tip_pad">
      <origin xyz="0.07 0 -0.002" rpy="0 0 0" />
      <geometry>
        <box size="0.02 0.046 0.012" />
        </geometry>
      </collision>
    </link>
  <joint name="base_joint" type="revolute">
    <parent link="base_knuckle" />
    <child link="proximal_phalanx" />
    <axis xyz="0 -1 0" />
    <limit effort="12" velocity="2.5" lower="0" upper="1.5708" />
    </joint>
  <joint name="middle_joint" type="revolute">
    <origin xyz="0.105 0 0" rpy="0 0 0" />
    <parent link="proximal_phalanx" />
    <child link="middle_phalanx" />
    <axis xyz="0 -1 0" />
    <limit effort="8" velocity="2.5" lower="0" upper="1.309" />
    </joint>
  <joint name="distal_joint" type="revolute">
    <origin xyz="0.078 0 0" rpy="0 0 0" />
    <parent link="middle_phalanx" />
    <child link="distal_phalanx" />
    <axis xyz="0 -1 0" />
    <limit effort="5" velocity="2.5" lower="0" upper="1.309" />
    </joint>
  </robot>
