<robot name="heavy_duty_h_frame_easel">
  <material name="sealed_beech_wood">
    <color rgba="0.72 0.48 0.25 1" />
    </material>
  <material name="darker_endgrain">
    <color rgba="0.48 0.3 0.14 1" />
    </material>
  <material name="black_powder_coated_steel">
    <color rgba="0.015 0.017 0.018 1" />
    </material>
  <material name="matte_black_rubber">
    <color rgba="0.01 0.01 0.009 1" />
    </material>
  <link name="front_frame">
    <visual name="upright_0">
      <origin xyz="-0.45 0 0.96" rpy="0 0 0" />
      <geometry>
        <box size="0.08 0.08 1.86" />
        </geometry>
      <material name="sealed_beech_wood">
        <color rgba="0.72 0.48 0.25 1" />
        </material>
      </visual>
    <visual name="front_foot_0">
      <origin xyz="-0.45 -0.09 0.03" rpy="0 0 0" />
      <geometry>
        <box size="0.13 0.52 0.06" />
        </geometry>
      <material name="darker_endgrain">
        <color rgba="0.48 0.3 0.14 1" />
        </material>
      </visual>
    <visual name="upright_1">
      <origin xyz="0.45 0 0.96" rpy="0 0 0" />
      <geometry>
        <box size="0.08 0.08 1.86" />
        </geometry>
      <material name="sealed_beech_wood">
        <color rgba="0.72 0.48 0.25 1" />
        </material>
      </visual>
    <visual name="front_foot_1">
      <origin xyz="0.45 -0.09 0.03" rpy="0 0 0" />
      <geometry>
        <box size="0.13 0.52 0.06" />
        </geometry>
      <material name="darker_endgrain">
        <color rgba="0.48 0.3 0.14 1" />
        </material>
      </visual>
    <visual name="lower_crossbar">
      <origin xyz="0 0 0.36" rpy="0 0 0" />
      <geometry>
        <box size="0.96 0.07 0.085" />
        </geometry>
      <material name="sealed_beech_wood">
        <color rgba="0.72 0.48 0.25 1" />
        </material>
      </visual>
    <visual name="upper_crossbar">
      <origin xyz="0 0 1.34" rpy="0 0 0" />
      <geometry>
        <box size="0.96 0.07 0.085" />
        </geometry>
      <material name="sealed_beech_wood">
        <color rgba="0.72 0.48 0.25 1" />
        </material>
      </visual>
    <visual name="channel_0_inner">
      <origin xyz="-0.473 -0.047 0.98" rpy="0 0 0" />
      <geometry>
        <box size="0.012 0.018 1.43" />
        </geometry>
      <material name="black_powder_coated_steel">
        <color rgba="0.015 0.017 0.018 1" />
        </material>
      </visual>
    <visual name="channel_0_outer">
      <origin xyz="-0.427 -0.047 0.98" rpy="0 0 0" />
      <geometry>
        <box size="0.012 0.018 1.43" />
        </geometry>
      <material name="black_powder_coated_steel">
        <color rgba="0.015 0.017 0.018 1" />
        </material>
      </visual>
    <visual name="channel_1_inner">
      <origin xyz="0.427 -0.047 0.98" rpy="0 0 0" />
      <geometry>
        <box size="0.012 0.018 1.43" />
        </geometry>
      <material name="black_powder_coated_steel">
        <color rgba="0.015 0.017 0.018 1" />
        </material>
      </visual>
    <visual name="channel_1_outer">
      <origin xyz="0.473 -0.047 0.98" rpy="0 0 0" />
      <geometry>
        <box size="0.012 0.018 1.43" />
        </geometry>
      <material name="black_powder_coated_steel">
        <color rgba="0.015 0.017 0.018 1" />
        </material>
      </visual>
    <visual name="rear_pivot_block">
      <origin xyz="0 0.065 1.34" rpy="0 0 0" />
      <geometry>
        <box size="0.18 0.11 0.12" />
        </geometry>
      <material name="black_powder_coated_steel">
        <color rgba="0.015 0.017 0.018 1" />
        </material>
      </visual>
    <visual name="pivot_pin">
      <origin xyz="0 0.052 1.34" rpy="0 1.5708 0" />
      <geometry>
        <cylinder radius="0.026" length="0.21" />
        </geometry>
      <material name="black_powder_coated_steel">
        <color rgba="0.015 0.017 0.018 1" />
        </material>
      </visual>
    <visual name="sleeve_cheek_0">
      <origin xyz="-0.047 0.304823 1.09414" rpy="-2.447 0 0" />
      <geometry>
        <box size="0.022 0.056 0.64" />
        </geometry>
      <material name="black_powder_coated_steel">
        <color rgba="0.015 0.017 0.018 1" />
        </material>
      </visual>
    <visual name="sleeve_cheek_1">
      <origin xyz="0.047 0.304823 1.09414" rpy="-2.447 0 0" />
      <geometry>
        <box size="0.022 0.056 0.64" />
        </geometry>
      <material name="black_powder_coated_steel">
        <color rgba="0.015 0.017 0.018 1" />
        </material>
      </visual>
    <visual name="sleeve_web">
      <origin xyz="0 0.277932 1.07174" rpy="-2.447 0 0" />
      <geometry>
        <box size="0.116 0.014 0.64" />
        </geometry>
      <material name="black_powder_coated_steel">
        <color rgba="0.015 0.017 0.018 1" />
        </material>
      </visual>
    <visual name="bolt_0">
      <origin xyz="-0.45 -0.046 0.36" rpy="1.5708 0 0" />
      <geometry>
        <cylinder radius="0.018" length="0.012" />
        </geometry>
      <material name="black_powder_coated_steel">
        <color rgba="0.015 0.017 0.018 1" />
        </material>
      </visual>
    <visual name="bolt_1">
      <origin xyz="0.45 -0.046 0.36" rpy="1.5708 0 0" />
      <geometry>
        <cylinder radius="0.018" length="0.012" />
        </geometry>
      <material name="black_powder_coated_steel">
        <color rgba="0.015 0.017 0.018 1" />
        </material>
      </visual>
    <visual name="bolt_2">
      <origin xyz="-0.45 -0.046 1.34" rpy="1.5708 0 0" />
      <geometry>
        <cylinder radius="0.018" length="0.012" />
        </geometry>
      <material name="black_powder_coated_steel">
        <color rgba="0.015 0.017 0.018 1" />
        </material>
      </visual>
    <visual name="bolt_3">
      <origin xyz="0.45 -0.046 1.34" rpy="1.5708 0 0" />
      <geometry>
        <cylinder radius="0.018" length="0.012" />
        </geometry>
      <material name="black_powder_coated_steel">
        <color rgba="0.015 0.017 0.018 1" />
        </material>
      </visual>
    <visual name="bolt_4">
      <origin xyz="-0.45 -0.046 0.73" rpy="1.5708 0 0" />
      <geometry>
        <cylinder radius="0.018" length="0.012" />
        </geometry>
      <material name="black_powder_coated_steel">
        <color rgba="0.015 0.017 0.018 1" />
        </material>
      </visual>
    <visual name="bolt_5">
      <origin xyz="0.45 -0.046 0.73" rpy="1.5708 0 0" />
      <geometry>
        <cylinder radius="0.018" length="0.012" />
        </geometry>
      <material name="black_powder_coated_steel">
        <color rgba="0.015 0.017 0.018 1" />
        </material>
      </visual>
    <visual name="bolt_6">
      <origin xyz="-0.45 -0.046 1.67" rpy="1.5708 0 0" />
      <geometry>
        <cylinder radius="0.018" length="0.012" />
        </geometry>
      <material name="black_powder_coated_steel">
        <color rgba="0.015 0.017 0.018 1" />
        </material>
      </visual>
    <visual name="bolt_7">
      <origin xyz="0.45 -0.046 1.67" rpy="1.5708 0 0" />
      <geometry>
        <cylinder radius="0.018" length="0.012" />
        </geometry>
      <material name="black_powder_coated_steel">
        <color rgba="0.015 0.017 0.018 1" />
        </material>
      </visual>
    <collision name="upright_0">
      <origin xyz="-0.45 0 0.96" rpy="0 0 0" />
      <geometry>
        <box size="0.08 0.08 1.86" />
        </geometry>
      </collision>
    <collision name="front_foot_0">
      <origin xyz="-0.45 -0.09 0.03" rpy="0 0 0" />
      <geometry>
        <box size="0.13 0.52 0.06" />
        </geometry>
      </collision>
    <collision name="upright_1">
      <origin xyz="0.45 0 0.96" rpy="0 0 0" />
      <geometry>
        <box size="0.08 0.08 1.86" />
        </geometry>
      </collision>
    <collision name="front_foot_1">
      <origin xyz="0.45 -0.09 0.03" rpy="0 0 0" />
      <geometry>
        <box size="0.13 0.52 0.06" />
        </geometry>
      </collision>
    <collision name="lower_crossbar">
      <origin xyz="0 0 0.36" rpy="0 0 0" />
      <geometry>
        <box size="0.96 0.07 0.085" />
        </geometry>
      </collision>
    <collision name="upper_crossbar">
      <origin xyz="0 0 1.34" rpy="0 0 0" />
      <geometry>
        <box size="0.96 0.07 0.085" />
        </geometry>
      </collision>
    <collision name="channel_0_inner">
      <origin xyz="-0.473 -0.047 0.98" rpy="0 0 0" />
      <geometry>
        <box size="0.012 0.018 1.43" />
        </geometry>
      </collision>
    <collision name="channel_0_outer">
      <origin xyz="-0.427 -0.047 0.98" rpy="0 0 0" />
      <geometry>
        <box size="0.012 0.018 1.43" />
        </geometry>
      </collision>
    <collision name="channel_1_inner">
      <origin xyz="0.427 -0.047 0.98" rpy="0 0 0" />
      <geometry>
        <box size="0.012 0.018 1.43" />
        </geometry>
      </collision>
    <collision name="channel_1_outer">
      <origin xyz="0.473 -0.047 0.98" rpy="0 0 0" />
      <geometry>
        <box size="0.012 0.018 1.43" />
        </geometry>
      </collision>
    <collision name="rear_pivot_block">
      <origin xyz="0 0.065 1.34" rpy="0 0 0" />
      <geometry>
        <box size="0.18 0.11 0.12" />
        </geometry>
      </collision>
    <collision name="pivot_pin">
      <origin xyz="0 0.052 1.34" rpy="0 1.5708 0" />
      <geometry>
        <cylinder radius="0.026" length="0.21" />
        </geometry>
      </collision>
    <collision name="sleeve_cheek_0">
      <origin xyz="-0.047 0.304823 1.09414" rpy="-2.447 0 0" />
      <geometry>
        <box size="0.022 0.056 0.64" />
        </geometry>
      </collision>
    <collision name="sleeve_cheek_1">
      <origin xyz="0.047 0.304823 1.09414" rpy="-2.447 0 0" />
      <geometry>
        <box size="0.022 0.056 0.64" />
        </geometry>
      </collision>
    <collision name="sleeve_web">
      <origin xyz="0 0.277932 1.07174" rpy="-2.447 0 0" />
      <geometry>
        <box size="0.116 0.014 0.64" />
        </geometry>
      </collision>
    <collision name="bolt_0">
      <origin xyz="-0.45 -0.046 0.36" rpy="1.5708 0 0" />
      <geometry>
        <cylinder radius="0.018" length="0.012" />
        </geometry>
      </collision>
    <collision name="bolt_1">
      <origin xyz="0.45 -0.046 0.36" rpy="1.5708 0 0" />
      <geometry>
        <cylinder radius="0.018" length="0.012" />
        </geometry>
      </collision>
    <collision name="bolt_2">
      <origin xyz="-0.45 -0.046 1.34" rpy="1.5708 0 0" />
      <geometry>
        <cylinder radius="0.018" length="0.012" />
        </geometry>
      </collision>
    <collision name="bolt_3">
      <origin xyz="0.45 -0.046 1.34" rpy="1.5708 0 0" />
      <geometry>
        <cylinder radius="0.018" length="0.012" />
        </geometry>
      </collision>
    <collision name="bolt_4">
      <origin xyz="-0.45 -0.046 0.73" rpy="1.5708 0 0" />
      <geometry>
        <cylinder radius="0.018" length="0.012" />
        </geometry>
      </collision>
    <collision name="bolt_5">
      <origin xyz="0.45 -0.046 0.73" rpy="1.5708 0 0" />
      <geometry>
        <cylinder radius="0.018" length="0.012" />
        </geometry>
      </collision>
    <collision name="bolt_6">
      <origin xyz="-0.45 -0.046 1.67" rpy="1.5708 0 0" />
      <geometry>
        <cylinder radius="0.018" length="0.012" />
        </geometry>
      </collision>
    <collision name="bolt_7">
      <origin xyz="0.45 -0.046 1.67" rpy="1.5708 0 0" />
      <geometry>
        <cylinder radius="0.018" length="0.012" />
        </geometry>
      </collision>
    </link>
  <link name="shelf">
    <visual name="shelf_board">
      <origin xyz="0 -0.145 0" rpy="0 0 0" />
      <geometry>
        <box size="1.12 0.14 0.06" />
        </geometry>
      <material name="sealed_beech_wood">
        <color rgba="0.72 0.48 0.25 1" />
        </material>
      </visual>
    <visual name="canvas_lip">
      <origin xyz="0 -0.215 0.045" rpy="0 0 0" />
      <geometry>
        <box size="1.16 0.036 0.09" />
        </geometry>
      <material name="darker_endgrain">
        <color rgba="0.48 0.3 0.14 1" />
        </material>
      </visual>
    <visual name="slider_tongue_0">
      <origin xyz="-0.45 -0.064 0" rpy="0 0 0" />
      <geometry>
        <box size="0.034 0.016 0.24" />
        </geometry>
      <material name="black_powder_coated_steel">
        <color rgba="0.015 0.017 0.018 1" />
        </material>
      </visual>
    <visual name="shelf_bracket_0">
      <origin xyz="-0.45 -0.083 0" rpy="0 0 0" />
      <geometry>
        <box size="0.09 0.028 0.17" />
        </geometry>
      <material name="black_powder_coated_steel">
        <color rgba="0.015 0.017 0.018 1" />
        </material>
      </visual>
    <visual name="slider_tongue_1">
      <origin xyz="0.45 -0.064 0" rpy="0 0 0" />
      <geometry>
        <box size="0.034 0.016 0.24" />
        </geometry>
      <material name="black_powder_coated_steel">
        <color rgba="0.015 0.017 0.018 1" />
        </material>
      </visual>
    <visual name="shelf_bracket_1">
      <origin xyz="0.45 -0.083 0" rpy="0 0 0" />
      <geometry>
        <box size="0.09 0.028 0.17" />
        </geometry>
      <material name="black_powder_coated_steel">
        <color rgba="0.015 0.017 0.018 1" />
        </material>
      </visual>
    <collision name="shelf_board">
      <origin xyz="0 -0.145 0" rpy="0 0 0" />
      <geometry>
        <box size="1.12 0.14 0.06" />
        </geometry>
      </collision>
    <collision name="canvas_lip">
      <origin xyz="0 -0.215 0.045" rpy="0 0 0" />
      <geometry>
        <box size="1.16 0.036 0.09" />
        </geometry>
      </collision>
    <collision name="slider_tongue_0">
      <origin xyz="-0.45 -0.064 0" rpy="0 0 0" />
      <geometry>
        <box size="0.034 0.016 0.24" />
        </geometry>
      </collision>
    <collision name="shelf_bracket_0">
      <origin xyz="-0.45 -0.083 0" rpy="0 0 0" />
      <geometry>
        <box size="0.09 0.028 0.17" />
        </geometry>
      </collision>
    <collision name="slider_tongue_1">
      <origin xyz="0.45 -0.064 0" rpy="0 0 0" />
      <geometry>
        <box size="0.034 0.016 0.24" />
        </geometry>
      </collision>
    <collision name="shelf_bracket_1">
      <origin xyz="0.45 -0.083 0" rpy="0 0 0" />
      <geometry>
        <box size="0.09 0.028 0.17" />
        </geometry>
      </collision>
    </link>
  <link name="rear_strut">
    <visual name="inner_strut">
      <origin xyz="0 0 0.84" rpy="0 0 0" />
      <geometry>
        <box size="0.072 0.028 1.5" />
        </geometry>
      <material name="black_powder_coated_steel">
        <color rgba="0.015 0.017 0.018 1" />
        </material>
      </visual>
    <visual name="rear_pad">
      <origin xyz="0 -0.004 1.615" rpy="0 0 0" />
      <geometry>
        <box size="0.23 0.065 0.06" />
        </geometry>
      <material name="matte_black_rubber">
        <color rgba="0.01 0.01 0.009 1" />
        </material>
      </visual>
    <collision name="inner_strut">
      <origin xyz="0 0 0.84" rpy="0 0 0" />
      <geometry>
        <box size="0.072 0.028 1.5" />
        </geometry>
      </collision>
    <collision name="rear_pad">
      <origin xyz="0 -0.004 1.615" rpy="0 0 0" />
      <geometry>
        <box size="0.23 0.065 0.06" />
        </geometry>
      </collision>
    </link>
  <joint name="frame_to_shelf" type="prismatic">
    <origin xyz="0 0 0.65" rpy="0 0 0" />
    <parent link="front_frame" />
    <child link="shelf" />
    <axis xyz="0 0 1" />
    <limit effort="120" velocity="0.18" lower="-0.25" upper="0.85" />
    </joint>
  <joint name="frame_to_rear_strut" type="prismatic">
    <origin xyz="0 0.1 1.34" rpy="-2.447 0 0" />
    <parent link="front_frame" />
    <child link="rear_strut" />
    <axis xyz="0 0 1" />
    <limit effort="180" velocity="0.15" lower="-0.2" upper="0.12" />
    </joint>
  </robot>
