<robot name="stationary_exercise_bike">
  <material name="satin_black">
    <color rgba="0.015 0.017 0.018 1" />
    </material>
  <material name="charcoal">
    <color rgba="0.08 0.09 0.095 1" />
    </material>
  <material name="graphite">
    <color rgba="0.17 0.18 0.18 1" />
    </material>
  <material name="dark_rubber">
    <color rgba="0.01 0.01 0.012 1" />
    </material>
  <material name="brushed_steel">
    <color rgba="0.62 0.64 0.62 1" />
    </material>
  <material name="flywheel_metal">
    <color rgba="0.43 0.46 0.46 1" />
    </material>
  <material name="accent_red">
    <color rgba="0.75 0.04 0.025 1" />
    </material>
  <link name="floor_frame">
    <visual name="front_foot">
      <origin xyz="-0.62 0 0.035" rpy="0 0 0" />
      <geometry>
        <box size="0.18 0.82 0.07" />
        </geometry>
      <material name="satin_black">
        <color rgba="0.015 0.017 0.018 1" />
        </material>
      </visual>
    <visual name="rear_foot">
      <origin xyz="0.54 0 0.035" rpy="0 0 0" />
      <geometry>
        <box size="0.2 0.78 0.07" />
        </geometry>
      <material name="satin_black">
        <color rgba="0.015 0.017 0.018 1" />
        </material>
      </visual>
    <visual name="floor_spine">
      <origin xyz="-0.03 0 0.095" rpy="0 0 0" />
      <geometry>
        <box size="1.22 0.13 0.085" />
        </geometry>
      <material name="satin_black">
        <color rgba="0.015 0.017 0.018 1" />
        </material>
      </visual>
    <visual name="front_roller">
      <origin xyz="-0.69 0 0.03" rpy="0 1.5708 0" />
      <geometry>
        <cylinder radius="0.035" length="0.12" />
        </geometry>
      <material name="dark_rubber">
        <color rgba="0.01 0.01 0.012 1" />
        </material>
      </visual>
    <visual name="rear_pad">
      <origin xyz="0.62 0 0.03" rpy="0 1.5708 0" />
      <geometry>
        <cylinder radius="0.032" length="0.14" />
        </geometry>
      <material name="dark_rubber">
        <color rgba="0.01 0.01 0.012 1" />
        </material>
      </visual>
    <visual name="front_fork_0">
      <origin xyz="-0.545 -0.18 0.2825" rpy="0 0.351031 0" />
      <geometry>
        <cylinder radius="0.035" length="0.378054" />
        </geometry>
      <material name="satin_black">
        <color rgba="0.015 0.017 0.018 1" />
        </material>
      </visual>
    <visual name="front_fork_1">
      <origin xyz="-0.545 0.18 0.2825" rpy="0 0.351031 0" />
      <geometry>
        <cylinder radius="0.035" length="0.378054" />
        </geometry>
      <material name="satin_black">
        <color rgba="0.015 0.017 0.018 1" />
        </material>
      </visual>
    <visual name="fork_root_0">
      <origin xyz="-0.61 -0.18 0.078" rpy="0 0 0" />
      <geometry>
        <box size="0.12 0.13 0.06" />
        </geometry>
      <material name="satin_black">
        <color rgba="0.015 0.017 0.018 1" />
        </material>
      </visual>
    <visual name="fork_root_1">
      <origin xyz="-0.61 0.18 0.078" rpy="0 0 0" />
      <geometry>
        <box size="0.12 0.13 0.06" />
        </geometry>
      <material name="satin_black">
        <color rgba="0.015 0.017 0.018 1" />
        </material>
      </visual>
    <visual name="axle_stay_0">
      <origin xyz="-0.3175 -0.155 0.4725" rpy="0 1.49402 0" />
      <geometry>
        <cylinder radius="0.024" length="0.32596" />
        </geometry>
      <material name="satin_black">
        <color rgba="0.015 0.017 0.018 1" />
        </material>
      </visual>
    <visual name="axle_stay_1">
      <origin xyz="-0.3175 0.155 0.4725" rpy="0 1.49402 0" />
      <geometry>
        <cylinder radius="0.024" length="0.32596" />
        </geometry>
      <material name="satin_black">
        <color rgba="0.015 0.017 0.018 1" />
        </material>
      </visual>
    <visual name="rear_chainstay">
      <origin xyz="0.2475 0 0.2525" rpy="0 -1.16369 0" />
      <geometry>
        <cylinder radius="0.04" length="0.593507" />
        </geometry>
      <material name="satin_black">
        <color rgba="0.015 0.017 0.018 1" />
        </material>
      </visual>
    <visual name="seat_support">
      <origin xyz="0.4475 0 0.275" rpy="0 -0.276097 0" />
      <geometry>
        <cylinder radius="0.042" length="0.311809" />
        </geometry>
      <material name="satin_black">
        <color rgba="0.015 0.017 0.018 1" />
        </material>
      </visual>
    <visual name="top_frame_tube">
      <origin xyz="0.115 0 0.755" rpy="0 -1.07685 0" />
      <geometry>
        <cylinder radius="0.038" length="0.295296" />
        </geometry>
      <material name="satin_black">
        <color rgba="0.015 0.017 0.018 1" />
        </material>
      </visual>
    <visual name="handlebar_mast">
      <origin xyz="0.0075 0 0.6725" rpy="0 -0.100333 0" />
      <geometry>
        <cylinder radius="0.045" length="0.748766" />
        </geometry>
      <material name="satin_black">
        <color rgba="0.015 0.017 0.018 1" />
        </material>
      </visual>
    <visual name="mast_brace_0">
      <origin xyz="-0.3375 -0.075 0.3675" rpy="0 0.75943 0" />
      <geometry>
        <cylinder radius="0.03" length="0.544656" />
        </geometry>
      <material name="satin_black">
        <color rgba="0.015 0.017 0.018 1" />
        </material>
      </visual>
    <visual name="mast_brace_1">
      <origin xyz="-0.3375 0.075 0.3675" rpy="0 0.75943 0" />
      <geometry>
        <cylinder radius="0.03" length="0.544656" />
        </geometry>
      <material name="satin_black">
        <color rgba="0.015 0.017 0.018 1" />
        </material>
      </visual>
    <visual name="bottom_bracket_shell">
      <origin xyz="-0.08 0 0.43" rpy="1.5708 0 0" />
      <geometry>
        <mesh filename="assets/meshes/bottom_bracket_shell.obj" />
        </geometry>
      <material name="graphite">
        <color rgba="0.17 0.18 0.18 1" />
        </material>
      </visual>
    <visual name="seat_sleeve">
      <origin xyz="0.32 0 0.5" rpy="0 0 0" />
      <geometry>
        <mesh filename="assets/meshes/seat_sleeve.obj" />
        </geometry>
      <material name="graphite">
        <color rgba="0.17 0.18 0.18 1" />
        </material>
      </visual>
    <visual name="seat_collar">
      <origin xyz="0.32 0 0.75" rpy="0 0 0" />
      <geometry>
        <mesh filename="assets/meshes/seat_collar.obj" />
        </geometry>
      <material name="charcoal">
        <color rgba="0.08 0.09 0.095 1" />
        </material>
      </visual>
    <visual name="flywheel_cowling">
      <origin xyz="-0.48 0 0.46" rpy="1.5708 0 0" />
      <geometry>
        <mesh filename="assets/meshes/flywheel_cowling.obj" />
        </geometry>
      <material name="charcoal">
        <color rgba="0.08 0.09 0.095 1" />
        </material>
      </visual>
    <visual name="flywheel_bearing_0">
      <origin xyz="-0.48 -0.11 0.46" rpy="1.5708 0 0" />
      <geometry>
        <mesh filename="assets/meshes/flywheel_bearing_-0.obj" />
        </geometry>
      <material name="graphite">
        <color rgba="0.17 0.18 0.18 1" />
        </material>
      </visual>
    <visual name="housing_web_0">
      <origin xyz="-0.48 -0.11 0.6115" rpy="0 0 0" />
      <geometry>
        <cylinder radius="0.015" length="0.213" />
        </geometry>
      <material name="charcoal">
        <color rgba="0.08 0.09 0.095 1" />
        </material>
      </visual>
    <visual name="lower_web_0">
      <origin xyz="-0.48 -0.11 0.31" rpy="0 3.14159 0" />
      <geometry>
        <cylinder radius="0.015" length="0.21" />
        </geometry>
      <material name="charcoal">
        <color rgba="0.08 0.09 0.095 1" />
        </material>
      </visual>
    <visual name="flywheel_bearing_1">
      <origin xyz="-0.48 0.11 0.46" rpy="1.5708 0 0" />
      <geometry>
        <mesh filename="assets/meshes/flywheel_bearing_-0.obj" />
        </geometry>
      <material name="graphite">
        <color rgba="0.17 0.18 0.18 1" />
        </material>
      </visual>
    <visual name="housing_web_1">
      <origin xyz="-0.48 0.11 0.6115" rpy="0 0 0" />
      <geometry>
        <cylinder radius="0.015" length="0.213" />
        </geometry>
      <material name="charcoal">
        <color rgba="0.08 0.09 0.095 1" />
        </material>
      </visual>
    <visual name="lower_web_1">
      <origin xyz="-0.48 0.11 0.31" rpy="0 3.14159 0" />
      <geometry>
        <cylinder radius="0.015" length="0.21" />
        </geometry>
      <material name="charcoal">
        <color rgba="0.08 0.09 0.095 1" />
        </material>
      </visual>
    <visual name="bar_stem">
      <origin xyz="-0.1175 0 1.08" rpy="0 -1.19029 0" />
      <geometry>
        <cylinder radius="0.03" length="0.188481" />
        </geometry>
      <material name="satin_black">
        <color rgba="0.015 0.017 0.018 1" />
        </material>
      </visual>
    <visual name="handlebar_crossbar">
      <origin xyz="-0.215 0 1.115" rpy="1.5708 0 0" />
      <geometry>
        <cylinder radius="0.028" length="0.62" />
        </geometry>
      <material name="satin_black">
        <color rgba="0.015 0.017 0.018 1" />
        </material>
      </visual>
    <visual name="grip_0">
      <origin xyz="-0.215 -0.33 1.115" rpy="1.5708 0 0" />
      <geometry>
        <cylinder radius="0.033" length="0.12" />
        </geometry>
      <material name="dark_rubber">
        <color rgba="0.01 0.01 0.012 1" />
        </material>
      </visual>
    <visual name="grip_1">
      <origin xyz="-0.215 0.33 1.115" rpy="1.5708 0 0" />
      <geometry>
        <cylinder radius="0.033" length="0.12" />
        </geometry>
      <material name="dark_rubber">
        <color rgba="0.01 0.01 0.012 1" />
        </material>
      </visual>
    <visual name="small_console">
      <origin xyz="-0.105 0 1.045" rpy="0 -0.4 0" />
      <geometry>
        <box size="0.18 0.06 0.09" />
        </geometry>
      <material name="charcoal">
        <color rgba="0.08 0.09 0.095 1" />
        </material>
      </visual>
    <collision name="front_foot">
      <origin xyz="-0.62 0 0.035" rpy="0 0 0" />
      <geometry>
        <box size="0.18 0.82 0.07" />
        </geometry>
      </collision>
    <collision name="rear_foot">
      <origin xyz="0.54 0 0.035" rpy="0 0 0" />
      <geometry>
        <box size="0.2 0.78 0.07" />
        </geometry>
      </collision>
    <collision name="floor_spine">
      <origin xyz="-0.03 0 0.095" rpy="0 0 0" />
      <geometry>
        <box size="1.22 0.13 0.085" />
        </geometry>
      </collision>
    <collision name="front_roller">
      <origin xyz="-0.69 0 0.03" rpy="0 1.5708 0" />
      <geometry>
        <cylinder radius="0.035" length="0.12" />
        </geometry>
      </collision>
    <collision name="rear_pad">
      <origin xyz="0.62 0 0.03" rpy="0 1.5708 0" />
      <geometry>
        <cylinder radius="0.032" length="0.14" />
        </geometry>
      </collision>
    <collision name="front_fork_0">
      <origin xyz="-0.545 -0.18 0.2825" rpy="0 0.351031 0" />
      <geometry>
        <cylinder radius="0.035" length="0.378054" />
        </geometry>
      </collision>
    <collision name="front_fork_1">
      <origin xyz="-0.545 0.18 0.2825" rpy="0 0.351031 0" />
      <geometry>
        <cylinder radius="0.035" length="0.378054" />
        </geometry>
      </collision>
    <collision name="fork_root_0">
      <origin xyz="-0.61 -0.18 0.078" rpy="0 0 0" />
      <geometry>
        <box size="0.12 0.13 0.06" />
        </geometry>
      </collision>
    <collision name="fork_root_1">
      <origin xyz="-0.61 0.18 0.078" rpy="0 0 0" />
      <geometry>
        <box size="0.12 0.13 0.06" />
        </geometry>
      </collision>
    <collision name="axle_stay_0">
      <origin xyz="-0.3175 -0.155 0.4725" rpy="0 1.49402 0" />
      <geometry>
        <cylinder radius="0.024" length="0.32596" />
        </geometry>
      </collision>
    <collision name="axle_stay_1">
      <origin xyz="-0.3175 0.155 0.4725" rpy="0 1.49402 0" />
      <geometry>
        <cylinder radius="0.024" length="0.32596" />
        </geometry>
      </collision>
    <collision name="rear_chainstay">
      <origin xyz="0.2475 0 0.2525" rpy="0 -1.16369 0" />
      <geometry>
        <cylinder radius="0.04" length="0.593507" />
        </geometry>
      </collision>
    <collision name="seat_support">
      <origin xyz="0.4475 0 0.275" rpy="0 -0.276097 0" />
      <geometry>
        <cylinder radius="0.042" length="0.311809" />
        </geometry>
      </collision>
    <collision name="top_frame_tube">
      <origin xyz="0.115 0 0.755" rpy="0 -1.07685 0" />
      <geometry>
        <cylinder radius="0.038" length="0.295296" />
        </geometry>
      </collision>
    <collision name="handlebar_mast">
      <origin xyz="0.0075 0 0.6725" rpy="0 -0.100333 0" />
      <geometry>
        <cylinder radius="0.045" length="0.748766" />
        </geometry>
      </collision>
    <collision name="mast_brace_0">
      <origin xyz="-0.3375 -0.075 0.3675" rpy="0 0.75943 0" />
      <geometry>
        <cylinder radius="0.03" length="0.544656" />
        </geometry>
      </collision>
    <collision name="mast_brace_1">
      <origin xyz="-0.3375 0.075 0.3675" rpy="0 0.75943 0" />
      <geometry>
        <cylinder radius="0.03" length="0.544656" />
        </geometry>
      </collision>
    <collision name="bottom_bracket_shell">
      <origin xyz="-0.08 0 0.43" rpy="1.5708 0 0" />
      <geometry>
        <mesh filename="assets/meshes/bottom_bracket_shell.obj" />
        </geometry>
      </collision>
    <collision name="seat_sleeve">
      <origin xyz="0.32 0 0.5" rpy="0 0 0" />
      <geometry>
        <mesh filename="assets/meshes/seat_sleeve.obj" />
        </geometry>
      </collision>
    <collision name="seat_collar">
      <origin xyz="0.32 0 0.75" rpy="0 0 0" />
      <geometry>
        <mesh filename="assets/meshes/seat_collar.obj" />
        </geometry>
      </collision>
    <collision name="flywheel_cowling">
      <origin xyz="-0.48 0 0.46" rpy="1.5708 0 0" />
      <geometry>
        <mesh filename="assets/meshes/flywheel_cowling.obj" />
        </geometry>
      </collision>
    <collision name="flywheel_bearing_0">
      <origin xyz="-0.48 -0.11 0.46" rpy="1.5708 0 0" />
      <geometry>
        <mesh filename="assets/meshes/flywheel_bearing_-0.obj" />
        </geometry>
      </collision>
    <collision name="housing_web_0">
      <origin xyz="-0.48 -0.11 0.6115" rpy="0 0 0" />
      <geometry>
        <cylinder radius="0.015" length="0.213" />
        </geometry>
      </collision>
    <collision name="lower_web_0">
      <origin xyz="-0.48 -0.11 0.31" rpy="0 3.14159 0" />
      <geometry>
        <cylinder radius="0.015" length="0.21" />
        </geometry>
      </collision>
    <collision name="flywheel_bearing_1">
      <origin xyz="-0.48 0.11 0.46" rpy="1.5708 0 0" />
      <geometry>
        <mesh filename="assets/meshes/flywheel_bearing_-0.obj" />
        </geometry>
      </collision>
    <collision name="housing_web_1">
      <origin xyz="-0.48 0.11 0.6115" rpy="0 0 0" />
      <geometry>
        <cylinder radius="0.015" length="0.213" />
        </geometry>
      </collision>
    <collision name="lower_web_1">
      <origin xyz="-0.48 0.11 0.31" rpy="0 3.14159 0" />
      <geometry>
        <cylinder radius="0.015" length="0.21" />
        </geometry>
      </collision>
    <collision name="bar_stem">
      <origin xyz="-0.1175 0 1.08" rpy="0 -1.19029 0" />
      <geometry>
        <cylinder radius="0.03" length="0.188481" />
        </geometry>
      </collision>
    <collision name="handlebar_crossbar">
      <origin xyz="-0.215 0 1.115" rpy="1.5708 0 0" />
      <geometry>
        <cylinder radius="0.028" length="0.62" />
        </geometry>
      </collision>
    <collision name="grip_0">
      <origin xyz="-0.215 -0.33 1.115" rpy="1.5708 0 0" />
      <geometry>
        <cylinder radius="0.033" length="0.12" />
        </geometry>
      </collision>
    <collision name="grip_1">
      <origin xyz="-0.215 0.33 1.115" rpy="1.5708 0 0" />
      <geometry>
        <cylinder radius="0.033" length="0.12" />
        </geometry>
      </collision>
    <collision name="small_console">
      <origin xyz="-0.105 0 1.045" rpy="0 -0.4 0" />
      <geometry>
        <box size="0.18 0.06 0.09" />
        </geometry>
      </collision>
    </link>
  <link name="flywheel">
    <visual name="flywheel_disk">
      <origin xyz="0 0 0" rpy="1.5708 0 0" />
      <geometry>
        <cylinder radius="0.235" length="0.065" />
        </geometry>
      <material name="flywheel_metal">
        <color rgba="0.43 0.46 0.46 1" />
        </material>
      </visual>
    <visual name="flywheel_rim">
      <origin xyz="0 0 0" rpy="1.5708 0 0" />
      <geometry>
        <cylinder radius="0.248" length="0.02" />
        </geometry>
      <material name="brushed_steel">
        <color rgba="0.62 0.64 0.62 1" />
        </material>
      </visual>
    <visual name="flywheel_axle">
      <origin xyz="0 0 0" rpy="1.5708 0 0" />
      <geometry>
        <cylinder radius="0.026" length="0.22" />
        </geometry>
      <material name="brushed_steel">
        <color rgba="0.62 0.64 0.62 1" />
        </material>
      </visual>
    <visual name="flywheel_hub">
      <origin xyz="0 0 0" rpy="1.5708 0 0" />
      <geometry>
        <cylinder radius="0.065" length="0.09" />
        </geometry>
      <material name="brushed_steel">
        <color rgba="0.62 0.64 0.62 1" />
        </material>
      </visual>
    <visual name="rim_marker">
      <origin xyz="0.15 -0.032 0.12" rpy="0 0 0" />
      <geometry>
        <box size="0.044 0.008 0.035" />
        </geometry>
      <material name="accent_red">
        <color rgba="0.75 0.04 0.025 1" />
        </material>
      </visual>
    <collision name="flywheel_disk">
      <origin xyz="0 0 0" rpy="1.5708 0 0" />
      <geometry>
        <cylinder radius="0.235" length="0.065" />
        </geometry>
      </collision>
    <collision name="flywheel_rim">
      <origin xyz="0 0 0" rpy="1.5708 0 0" />
      <geometry>
        <cylinder radius="0.248" length="0.02" />
        </geometry>
      </collision>
    <collision name="flywheel_axle">
      <origin xyz="0 0 0" rpy="1.5708 0 0" />
      <geometry>
        <cylinder radius="0.026" length="0.22" />
        </geometry>
      </collision>
    <collision name="flywheel_hub">
      <origin xyz="0 0 0" rpy="1.5708 0 0" />
      <geometry>
        <cylinder radius="0.065" length="0.09" />
        </geometry>
      </collision>
    <collision name="rim_marker">
      <origin xyz="0.15 -0.032 0.12" rpy="0 0 0" />
      <geometry>
        <box size="0.044 0.008 0.035" />
        </geometry>
      </collision>
    </link>
  <link name="crank">
    <visual name="crank_spindle">
      <origin xyz="0 0 0" rpy="1.5708 0 0" />
      <geometry>
        <cylinder radius="0.0345" length="0.235" />
        </geometry>
      <material name="brushed_steel">
        <color rgba="0.62 0.64 0.62 1" />
        </material>
      </visual>
    <visual name="crank_arm_0">
      <origin xyz="0 -0.12 -0.105" rpy="0 0 0" />
      <geometry>
        <box size="0.034 0.024 0.21" />
        </geometry>
      <material name="brushed_steel">
        <color rgba="0.62 0.64 0.62 1" />
        </material>
      </visual>
    <visual name="crank_arm_1">
      <origin xyz="0 0.12 0.105" rpy="0 0 0" />
      <geometry>
        <box size="0.034 0.024 0.21" />
        </geometry>
      <material name="brushed_steel">
        <color rgba="0.62 0.64 0.62 1" />
        </material>
      </visual>
    <visual name="pedal_0">
      <origin xyz="0 -0.15 -0.22" rpy="0 0 0" />
      <geometry>
        <box size="0.155 0.06 0.035" />
        </geometry>
      <material name="dark_rubber">
        <color rgba="0.01 0.01 0.012 1" />
        </material>
      </visual>
    <visual name="pedal_1">
      <origin xyz="0 0.15 0.22" rpy="0 0 0" />
      <geometry>
        <box size="0.155 0.06 0.035" />
        </geometry>
      <material name="dark_rubber">
        <color rgba="0.01 0.01 0.012 1" />
        </material>
      </visual>
    <collision name="crank_spindle">
      <origin xyz="0 0 0" rpy="1.5708 0 0" />
      <geometry>
        <cylinder radius="0.0345" length="0.235" />
        </geometry>
      </collision>
    <collision name="crank_arm_0">
      <origin xyz="0 -0.12 -0.105" rpy="0 0 0" />
      <geometry>
        <box size="0.034 0.024 0.21" />
        </geometry>
      </collision>
    <collision name="crank_arm_1">
      <origin xyz="0 0.12 0.105" rpy="0 0 0" />
      <geometry>
        <box size="0.034 0.024 0.21" />
        </geometry>
      </collision>
    <collision name="pedal_0">
      <origin xyz="0 -0.15 -0.22" rpy="0 0 0" />
      <geometry>
        <box size="0.155 0.06 0.035" />
        </geometry>
      </collision>
    <collision name="pedal_1">
      <origin xyz="0 0.15 0.22" rpy="0 0 0" />
      <geometry>
        <box size="0.155 0.06 0.035" />
        </geometry>
      </collision>
    </link>
  <link name="seat_post">
    <visual name="inner_post">
      <origin xyz="0 0 -0.06" rpy="0 0 0" />
      <geometry>
        <cylinder radius="0.029" length="0.62" />
        </geometry>
      <material name="brushed_steel">
        <color rgba="0.62 0.64 0.62 1" />
        </material>
      </visual>
    <visual name="saddle_clamp">
      <origin xyz="0.03 0 0.252" rpy="0 0 0" />
      <geometry>
        <box size="0.135 0.075 0.05" />
        </geometry>
      <material name="graphite">
        <color rgba="0.17 0.18 0.18 1" />
        </material>
      </visual>
    <visual name="saddle_pad">
      <origin xyz="0.075 0 0.298" rpy="0 0 0" />
      <geometry>
        <mesh filename="assets/meshes/saddle_pad.obj" />
        </geometry>
      <material name="dark_rubber">
        <color rgba="0.01 0.01 0.012 1" />
        </material>
      </visual>
    <collision name="inner_post">
      <origin xyz="0 0 -0.06" rpy="0 0 0" />
      <geometry>
        <cylinder radius="0.029" length="0.62" />
        </geometry>
      </collision>
    <collision name="saddle_clamp">
      <origin xyz="0.03 0 0.252" rpy="0 0 0" />
      <geometry>
        <box size="0.135 0.075 0.05" />
        </geometry>
      </collision>
    <collision name="saddle_pad">
      <origin xyz="0.075 0 0.298" rpy="0 0 0" />
      <geometry>
        <mesh filename="assets/meshes/saddle_pad.obj" />
        </geometry>
      </collision>
    </link>
  <joint name="flywheel_axle" type="continuous">
    <origin xyz="-0.48 0 0.46" rpy="0 0 0" />
    <parent link="floor_frame" />
    <child link="flywheel" />
    <axis xyz="0 1 0" />
    <limit effort="8" velocity="30" />
    </joint>
  <joint name="crank_axis" type="continuous">
    <origin xyz="-0.08 0 0.43" rpy="0 0 0" />
    <parent link="floor_frame" />
    <child link="crank" />
    <axis xyz="0 1 0" />
    <limit effort="12" velocity="20" />
    </joint>
  <joint name="seat_slide" type="prismatic">
    <origin xyz="0.32 0 0.75" rpy="0 0 0" />
    <parent link="floor_frame" />
    <child link="seat_post" />
    <axis xyz="0 0 1" />
    <limit effort="120" velocity="0.25" lower="0" upper="0.18" />
    </joint>
  </robot>
