<robot name="freight_goods_elevator">
  <material name="galvanized_steel">
    <color rgba="0.55 0.58 0.56 1" />
    </material>
  <material name="blackened_steel">
    <color rgba="0.08 0.09 0.09 1" />
    </material>
  <material name="safety_yellow">
    <color rgba="1 0.72 0.05 1" />
    </material>
  <material name="worn_grate_steel">
    <color rgba="0.32 0.34 0.34 1" />
    </material>
  <material name="cast_counterweight">
    <color rgba="0.18 0.19 0.2 1" />
    </material>
  <link name="fixed_frame">
    <visual name="rail_0_column">
      <origin xyz="-1.25 0.82 1.9" rpy="0 0 0" />
      <geometry>
        <box size="0.12 0.16 3.8" />
        </geometry>
      <material name="galvanized_steel">
        <color rgba="0.55 0.58 0.56 1" />
        </material>
      </visual>
    <visual name="rail_0_inner_track">
      <origin xyz="-1.215 0.7 1.9" rpy="0 0 0" />
      <geometry>
        <box size="0.045 0.045 3.7" />
        </geometry>
      <material name="blackened_steel">
        <color rgba="0.08 0.09 0.09 1" />
        </material>
      </visual>
    <visual name="rail_0_outer_flange">
      <origin xyz="-1.25 0.91 1.9" rpy="0 0 0" />
      <geometry>
        <box size="0.18 0.035 3.75" />
        </geometry>
      <material name="galvanized_steel">
        <color rgba="0.55 0.58 0.56 1" />
        </material>
      </visual>
    <visual name="rail_1_column">
      <origin xyz="1.25 0.82 1.9" rpy="0 0 0" />
      <geometry>
        <box size="0.12 0.16 3.8" />
        </geometry>
      <material name="galvanized_steel">
        <color rgba="0.55 0.58 0.56 1" />
        </material>
      </visual>
    <visual name="rail_1_inner_track">
      <origin xyz="1.215 0.7 1.9" rpy="0 0 0" />
      <geometry>
        <box size="0.045 0.045 3.7" />
        </geometry>
      <material name="blackened_steel">
        <color rgba="0.08 0.09 0.09 1" />
        </material>
      </visual>
    <visual name="rail_1_outer_flange">
      <origin xyz="1.25 0.91 1.9" rpy="0 0 0" />
      <geometry>
        <box size="0.18 0.035 3.75" />
        </geometry>
      <material name="galvanized_steel">
        <color rgba="0.55 0.58 0.56 1" />
        </material>
      </visual>
    <visual name="rear_base_sill">
      <origin xyz="0 0.82 0.05" rpy="0 0 0" />
      <geometry>
        <box size="2.8 0.16 0.1" />
        </geometry>
      <material name="blackened_steel">
        <color rgba="0.08 0.09 0.09 1" />
        </material>
      </visual>
    <visual name="front_base_sill">
      <origin xyz="0 -0.92 0.04" rpy="0 0 0" />
      <geometry>
        <box size="2.55 0.1 0.08" />
        </geometry>
      <material name="blackened_steel">
        <color rgba="0.08 0.09 0.09 1" />
        </material>
      </visual>
    <visual name="base_cross_tie_0">
      <origin xyz="-1.25 -0.05 0.04" rpy="0 0 0" />
      <geometry>
        <box size="0.1 1.88 0.08" />
        </geometry>
      <material name="blackened_steel">
        <color rgba="0.08 0.09 0.09 1" />
        </material>
      </visual>
    <visual name="base_cross_tie_1">
      <origin xyz="1.25 -0.05 0.04" rpy="0 0 0" />
      <geometry>
        <box size="0.1 1.88 0.08" />
        </geometry>
      <material name="blackened_steel">
        <color rgba="0.08 0.09 0.09 1" />
        </material>
      </visual>
    <visual name="head_crossbeam">
      <origin xyz="0 0.82 3.84" rpy="0 0 0" />
      <geometry>
        <box size="2.9 0.18 0.16" />
        </geometry>
      <material name="galvanized_steel">
        <color rgba="0.55 0.58 0.56 1" />
        </material>
      </visual>
    <visual name="head_front_tie">
      <origin xyz="0 -0.92 3.76" rpy="0 0 0" />
      <geometry>
        <box size="2.55 0.1 0.12" />
        </geometry>
      <material name="galvanized_steel">
        <color rgba="0.55 0.58 0.56 1" />
        </material>
      </visual>
    <visual name="top_cross_tie_0">
      <origin xyz="-1.25 -0.05 3.76" rpy="0 0 0" />
      <geometry>
        <box size="0.1 1.88 0.12" />
        </geometry>
      <material name="galvanized_steel">
        <color rgba="0.55 0.58 0.56 1" />
        </material>
      </visual>
    <visual name="top_cross_tie_1">
      <origin xyz="1.25 -0.05 3.76" rpy="0 0 0" />
      <geometry>
        <box size="0.1 1.88 0.12" />
        </geometry>
      <material name="galvanized_steel">
        <color rgba="0.55 0.58 0.56 1" />
        </material>
      </visual>
    <visual name="counterweight_back_rail">
      <origin xyz="1.55 1.08 2.05" rpy="0 0 0" />
      <geometry>
        <box size="0.08 0.06 3.1" />
        </geometry>
      <material name="blackened_steel">
        <color rgba="0.08 0.09 0.09 1" />
        </material>
      </visual>
    <visual name="counterweight_side_rail_0">
      <origin xyz="1.38 0.92 2.05" rpy="0 0 0" />
      <geometry>
        <box size="0.045 0.1 3.1" />
        </geometry>
      <material name="blackened_steel">
        <color rgba="0.08 0.09 0.09 1" />
        </material>
      </visual>
    <visual name="counterweight_side_rail_1">
      <origin xyz="1.72 0.92 2.05" rpy="0 0 0" />
      <geometry>
        <box size="0.045 0.1 3.1" />
        </geometry>
      <material name="blackened_steel">
        <color rgba="0.08 0.09 0.09 1" />
        </material>
      </visual>
    <visual name="counterweight_top_tie">
      <origin xyz="1.55 0.93 3.62" rpy="0 0 0" />
      <geometry>
        <box size="0.42 0.32 0.08" />
        </geometry>
      <material name="galvanized_steel">
        <color rgba="0.55 0.58 0.56 1" />
        </material>
      </visual>
    <visual name="counterweight_bottom_tie">
      <origin xyz="1.55 0.93 0.5" rpy="0 0 0" />
      <geometry>
        <box size="0.42 0.32 0.08" />
        </geometry>
      <material name="galvanized_steel">
        <color rgba="0.55 0.58 0.56 1" />
        </material>
      </visual>
    <visual name="head_sheave">
      <origin xyz="1.05 0.8 3.57" rpy="1.5708 0 0" />
      <geometry>
        <cylinder radius="0.18" length="0.08" />
        </geometry>
      <material name="blackened_steel">
        <color rgba="0.08 0.09 0.09 1" />
        </material>
      </visual>
    <visual name="sheave_axle">
      <origin xyz="1.05 0.8 3.57" rpy="1.5708 0 0" />
      <geometry>
        <cylinder radius="0.045" length="0.42" />
        </geometry>
      <material name="galvanized_steel">
        <color rgba="0.55 0.58 0.56 1" />
        </material>
      </visual>
    <collision name="rail_0_column">
      <origin xyz="-1.25 0.82 1.9" rpy="0 0 0" />
      <geometry>
        <box size="0.12 0.16 3.8" />
        </geometry>
      </collision>
    <collision name="rail_0_inner_track">
      <origin xyz="-1.215 0.7 1.9" rpy="0 0 0" />
      <geometry>
        <box size="0.045 0.045 3.7" />
        </geometry>
      </collision>
    <collision name="rail_0_outer_flange">
      <origin xyz="-1.25 0.91 1.9" rpy="0 0 0" />
      <geometry>
        <box size="0.18 0.035 3.75" />
        </geometry>
      </collision>
    <collision name="rail_1_column">
      <origin xyz="1.25 0.82 1.9" rpy="0 0 0" />
      <geometry>
        <box size="0.12 0.16 3.8" />
        </geometry>
      </collision>
    <collision name="rail_1_inner_track">
      <origin xyz="1.215 0.7 1.9" rpy="0 0 0" />
      <geometry>
        <box size="0.045 0.045 3.7" />
        </geometry>
      </collision>
    <collision name="rail_1_outer_flange">
      <origin xyz="1.25 0.91 1.9" rpy="0 0 0" />
      <geometry>
        <box size="0.18 0.035 3.75" />
        </geometry>
      </collision>
    <collision name="rear_base_sill">
      <origin xyz="0 0.82 0.05" rpy="0 0 0" />
      <geometry>
        <box size="2.8 0.16 0.1" />
        </geometry>
      </collision>
    <collision name="front_base_sill">
      <origin xyz="0 -0.92 0.04" rpy="0 0 0" />
      <geometry>
        <box size="2.55 0.1 0.08" />
        </geometry>
      </collision>
    <collision name="base_cross_tie_0">
      <origin xyz="-1.25 -0.05 0.04" rpy="0 0 0" />
      <geometry>
        <box size="0.1 1.88 0.08" />
        </geometry>
      </collision>
    <collision name="base_cross_tie_1">
      <origin xyz="1.25 -0.05 0.04" rpy="0 0 0" />
      <geometry>
        <box size="0.1 1.88 0.08" />
        </geometry>
      </collision>
    <collision name="head_crossbeam">
      <origin xyz="0 0.82 3.84" rpy="0 0 0" />
      <geometry>
        <box size="2.9 0.18 0.16" />
        </geometry>
      </collision>
    <collision name="head_front_tie">
      <origin xyz="0 -0.92 3.76" rpy="0 0 0" />
      <geometry>
        <box size="2.55 0.1 0.12" />
        </geometry>
      </collision>
    <collision name="top_cross_tie_0">
      <origin xyz="-1.25 -0.05 3.76" rpy="0 0 0" />
      <geometry>
        <box size="0.1 1.88 0.12" />
        </geometry>
      </collision>
    <collision name="top_cross_tie_1">
      <origin xyz="1.25 -0.05 3.76" rpy="0 0 0" />
      <geometry>
        <box size="0.1 1.88 0.12" />
        </geometry>
      </collision>
    <collision name="counterweight_back_rail">
      <origin xyz="1.55 1.08 2.05" rpy="0 0 0" />
      <geometry>
        <box size="0.08 0.06 3.1" />
        </geometry>
      </collision>
    <collision name="counterweight_side_rail_0">
      <origin xyz="1.38 0.92 2.05" rpy="0 0 0" />
      <geometry>
        <box size="0.045 0.1 3.1" />
        </geometry>
      </collision>
    <collision name="counterweight_side_rail_1">
      <origin xyz="1.72 0.92 2.05" rpy="0 0 0" />
      <geometry>
        <box size="0.045 0.1 3.1" />
        </geometry>
      </collision>
    <collision name="counterweight_top_tie">
      <origin xyz="1.55 0.93 3.62" rpy="0 0 0" />
      <geometry>
        <box size="0.42 0.32 0.08" />
        </geometry>
      </collision>
    <collision name="counterweight_bottom_tie">
      <origin xyz="1.55 0.93 0.5" rpy="0 0 0" />
      <geometry>
        <box size="0.42 0.32 0.08" />
        </geometry>
      </collision>
    <collision name="head_sheave">
      <origin xyz="1.05 0.8 3.57" rpy="1.5708 0 0" />
      <geometry>
        <cylinder radius="0.18" length="0.08" />
        </geometry>
      </collision>
    <collision name="sheave_axle">
      <origin xyz="1.05 0.8 3.57" rpy="1.5708 0 0" />
      <geometry>
        <cylinder radius="0.045" length="0.42" />
        </geometry>
      </collision>
    </link>
  <link name="platform">
    <visual name="front_floor_tube">
      <origin xyz="0 -0.8 0.04" rpy="0 0 0" />
      <geometry>
        <box size="2.2 0.08 0.08" />
        </geometry>
      <material name="blackened_steel">
        <color rgba="0.08 0.09 0.09 1" />
        </material>
      </visual>
    <visual name="rear_floor_tube">
      <origin xyz="0 0.8 0.04" rpy="0 0 0" />
      <geometry>
        <box size="2.2 0.08 0.08" />
        </geometry>
      <material name="blackened_steel">
        <color rgba="0.08 0.09 0.09 1" />
        </material>
      </visual>
    <visual name="side_floor_tube_0">
      <origin xyz="-1.1 0 0.04" rpy="0 0 0" />
      <geometry>
        <box size="0.08 1.66 0.08" />
        </geometry>
      <material name="blackened_steel">
        <color rgba="0.08 0.09 0.09 1" />
        </material>
      </visual>
    <visual name="side_floor_tube_1">
      <origin xyz="1.1 0 0.04" rpy="0 0 0" />
      <geometry>
        <box size="0.08 1.66 0.08" />
        </geometry>
      <material name="blackened_steel">
        <color rgba="0.08 0.09 0.09 1" />
        </material>
      </visual>
    <visual name="floor_crossbar_0">
      <origin xyz="-0.82 0 0.095" rpy="0 0 0" />
      <geometry>
        <box size="0.035 1.56 0.035" />
        </geometry>
      <material name="worn_grate_steel">
        <color rgba="0.32 0.34 0.34 1" />
        </material>
      </visual>
    <visual name="floor_crossbar_1">
      <origin xyz="-0.55 0 0.095" rpy="0 0 0" />
      <geometry>
        <box size="0.035 1.56 0.035" />
        </geometry>
      <material name="worn_grate_steel">
        <color rgba="0.32 0.34 0.34 1" />
        </material>
      </visual>
    <visual name="floor_crossbar_2">
      <origin xyz="-0.28 0 0.095" rpy="0 0 0" />
      <geometry>
        <box size="0.035 1.56 0.035" />
        </geometry>
      <material name="worn_grate_steel">
        <color rgba="0.32 0.34 0.34 1" />
        </material>
      </visual>
    <visual name="floor_crossbar_3">
      <origin xyz="0 0 0.095" rpy="0 0 0" />
      <geometry>
        <box size="0.035 1.56 0.035" />
        </geometry>
      <material name="worn_grate_steel">
        <color rgba="0.32 0.34 0.34 1" />
        </material>
      </visual>
    <visual name="floor_crossbar_4">
      <origin xyz="0.28 0 0.095" rpy="0 0 0" />
      <geometry>
        <box size="0.035 1.56 0.035" />
        </geometry>
      <material name="worn_grate_steel">
        <color rgba="0.32 0.34 0.34 1" />
        </material>
      </visual>
    <visual name="floor_crossbar_5">
      <origin xyz="0.55 0 0.095" rpy="0 0 0" />
      <geometry>
        <box size="0.035 1.56 0.035" />
        </geometry>
      <material name="worn_grate_steel">
        <color rgba="0.32 0.34 0.34 1" />
        </material>
      </visual>
    <visual name="floor_crossbar_6">
      <origin xyz="0.82 0 0.095" rpy="0 0 0" />
      <geometry>
        <box size="0.035 1.56 0.035" />
        </geometry>
      <material name="worn_grate_steel">
        <color rgba="0.32 0.34 0.34 1" />
        </material>
      </visual>
    <visual name="floor_longbar_0">
      <origin xyz="0 -0.58 0.12" rpy="0 0 0" />
      <geometry>
        <box size="2.02 0.03 0.03" />
        </geometry>
      <material name="worn_grate_steel">
        <color rgba="0.32 0.34 0.34 1" />
        </material>
      </visual>
    <visual name="floor_longbar_1">
      <origin xyz="0 -0.32 0.12" rpy="0 0 0" />
      <geometry>
        <box size="2.02 0.03 0.03" />
        </geometry>
      <material name="worn_grate_steel">
        <color rgba="0.32 0.34 0.34 1" />
        </material>
      </visual>
    <visual name="floor_longbar_2">
      <origin xyz="0 -0.06 0.12" rpy="0 0 0" />
      <geometry>
        <box size="2.02 0.03 0.03" />
        </geometry>
      <material name="worn_grate_steel">
        <color rgba="0.32 0.34 0.34 1" />
        </material>
      </visual>
    <visual name="floor_longbar_3">
      <origin xyz="0 0.2 0.12" rpy="0 0 0" />
      <geometry>
        <box size="2.02 0.03 0.03" />
        </geometry>
      <material name="worn_grate_steel">
        <color rgba="0.32 0.34 0.34 1" />
        </material>
      </visual>
    <visual name="floor_longbar_4">
      <origin xyz="0 0.46 0.12" rpy="0 0 0" />
      <geometry>
        <box size="2.02 0.03 0.03" />
        </geometry>
      <material name="worn_grate_steel">
        <color rgba="0.32 0.34 0.34 1" />
        </material>
      </visual>
    <visual name="floor_longbar_5">
      <origin xyz="0 0.68 0.12" rpy="0 0 0" />
      <geometry>
        <box size="2.02 0.03 0.03" />
        </geometry>
      <material name="worn_grate_steel">
        <color rgba="0.32 0.34 0.34 1" />
        </material>
      </visual>
    <visual name="rear_post_0">
      <origin xyz="-1.1 0.8 0.7" rpy="0 0 0" />
      <geometry>
        <box size="0.08 0.08 1.35" />
        </geometry>
      <material name="safety_yellow">
        <color rgba="1 0.72 0.05 1" />
        </material>
      </visual>
    <visual name="rear_post_1">
      <origin xyz="1.1 0.8 0.7" rpy="0 0 0" />
      <geometry>
        <box size="0.08 0.08 1.35" />
        </geometry>
      <material name="safety_yellow">
        <color rgba="1 0.72 0.05 1" />
        </material>
      </visual>
    <visual name="front_gate_post_0">
      <origin xyz="-1.1 -0.8 0.7" rpy="0 0 0" />
      <geometry>
        <box size="0.08 0.08 1.35" />
        </geometry>
      <material name="safety_yellow">
        <color rgba="1 0.72 0.05 1" />
        </material>
      </visual>
    <visual name="front_gate_post_1">
      <origin xyz="1.1 -0.8 0.7" rpy="0 0 0" />
      <geometry>
        <box size="0.08 0.08 1.35" />
        </geometry>
      <material name="safety_yellow">
        <color rgba="1 0.72 0.05 1" />
        </material>
      </visual>
    <visual name="rear_mid_rail">
      <origin xyz="0 0.8 0.68" rpy="0 0 0" />
      <geometry>
        <box size="2.22 0.06 0.07" />
        </geometry>
      <material name="safety_yellow">
        <color rgba="1 0.72 0.05 1" />
        </material>
      </visual>
    <visual name="side_mid_rail_0">
      <origin xyz="-1.1 0.02 0.68" rpy="0 0 0" />
      <geometry>
        <box size="0.06 1.55 0.07" />
        </geometry>
      <material name="safety_yellow">
        <color rgba="1 0.72 0.05 1" />
        </material>
      </visual>
    <visual name="side_mid_rail_1">
      <origin xyz="1.1 0.02 0.68" rpy="0 0 0" />
      <geometry>
        <box size="0.06 1.55 0.07" />
        </geometry>
      <material name="safety_yellow">
        <color rgba="1 0.72 0.05 1" />
        </material>
      </visual>
    <visual name="rear_top_rail">
      <origin xyz="0 0.8 1.18" rpy="0 0 0" />
      <geometry>
        <box size="2.22 0.06 0.07" />
        </geometry>
      <material name="safety_yellow">
        <color rgba="1 0.72 0.05 1" />
        </material>
      </visual>
    <visual name="side_top_rail_0">
      <origin xyz="-1.1 0.02 1.18" rpy="0 0 0" />
      <geometry>
        <box size="0.06 1.55 0.07" />
        </geometry>
      <material name="safety_yellow">
        <color rgba="1 0.72 0.05 1" />
        </material>
      </visual>
    <visual name="side_top_rail_1">
      <origin xyz="1.1 0.02 1.18" rpy="0 0 0" />
      <geometry>
        <box size="0.06 1.55 0.07" />
        </geometry>
      <material name="safety_yellow">
        <color rgba="1 0.72 0.05 1" />
        </material>
      </visual>
    <visual name="guide_shoe_0">
      <origin xyz="-1.1575 0.72 0.35" rpy="0 0 0" />
      <geometry>
        <box size="0.07 0.08 0.16" />
        </geometry>
      <material name="blackened_steel">
        <color rgba="0.08 0.09 0.09 1" />
        </material>
      </visual>
    <visual name="guide_shoe_1">
      <origin xyz="1.1575 0.72 0.35" rpy="0 0 0" />
      <geometry>
        <box size="0.07 0.08 0.16" />
        </geometry>
      <material name="blackened_steel">
        <color rgba="0.08 0.09 0.09 1" />
        </material>
      </visual>
    <visual name="guide_shoe_2">
      <origin xyz="-1.1575 0.72 1" rpy="0 0 0" />
      <geometry>
        <box size="0.07 0.08 0.16" />
        </geometry>
      <material name="blackened_steel">
        <color rgba="0.08 0.09 0.09 1" />
        </material>
      </visual>
    <visual name="guide_shoe_3">
      <origin xyz="1.1575 0.72 1" rpy="0 0 0" />
      <geometry>
        <box size="0.07 0.08 0.16" />
        </geometry>
      <material name="blackened_steel">
        <color rgba="0.08 0.09 0.09 1" />
        </material>
      </visual>
    <collision name="front_floor_tube">
      <origin xyz="0 -0.8 0.04" rpy="0 0 0" />
      <geometry>
        <box size="2.2 0.08 0.08" />
        </geometry>
      </collision>
    <collision name="rear_floor_tube">
      <origin xyz="0 0.8 0.04" rpy="0 0 0" />
      <geometry>
        <box size="2.2 0.08 0.08" />
        </geometry>
      </collision>
    <collision name="side_floor_tube_0">
      <origin xyz="-1.1 0 0.04" rpy="0 0 0" />
      <geometry>
        <box size="0.08 1.66 0.08" />
        </geometry>
      </collision>
    <collision name="side_floor_tube_1">
      <origin xyz="1.1 0 0.04" rpy="0 0 0" />
      <geometry>
        <box size="0.08 1.66 0.08" />
        </geometry>
      </collision>
    <collision name="floor_crossbar_0">
      <origin xyz="-0.82 0 0.095" rpy="0 0 0" />
      <geometry>
        <box size="0.035 1.56 0.035" />
        </geometry>
      </collision>
    <collision name="floor_crossbar_1">
      <origin xyz="-0.55 0 0.095" rpy="0 0 0" />
      <geometry>
        <box size="0.035 1.56 0.035" />
        </geometry>
      </collision>
    <collision name="floor_crossbar_2">
      <origin xyz="-0.28 0 0.095" rpy="0 0 0" />
      <geometry>
        <box size="0.035 1.56 0.035" />
        </geometry>
      </collision>
    <collision name="floor_crossbar_3">
      <origin xyz="0 0 0.095" rpy="0 0 0" />
      <geometry>
        <box size="0.035 1.56 0.035" />
        </geometry>
      </collision>
    <collision name="floor_crossbar_4">
      <origin xyz="0.28 0 0.095" rpy="0 0 0" />
      <geometry>
        <box size="0.035 1.56 0.035" />
        </geometry>
      </collision>
    <collision name="floor_crossbar_5">
      <origin xyz="0.55 0 0.095" rpy="0 0 0" />
      <geometry>
        <box size="0.035 1.56 0.035" />
        </geometry>
      </collision>
    <collision name="floor_crossbar_6">
      <origin xyz="0.82 0 0.095" rpy="0 0 0" />
      <geometry>
        <box size="0.035 1.56 0.035" />
        </geometry>
      </collision>
    <collision name="floor_longbar_0">
      <origin xyz="0 -0.58 0.12" rpy="0 0 0" />
      <geometry>
        <box size="2.02 0.03 0.03" />
        </geometry>
      </collision>
    <collision name="floor_longbar_1">
      <origin xyz="0 -0.32 0.12" rpy="0 0 0" />
      <geometry>
        <box size="2.02 0.03 0.03" />
        </geometry>
      </collision>
    <collision name="floor_longbar_2">
      <origin xyz="0 -0.06 0.12" rpy="0 0 0" />
      <geometry>
        <box size="2.02 0.03 0.03" />
        </geometry>
      </collision>
    <collision name="floor_longbar_3">
      <origin xyz="0 0.2 0.12" rpy="0 0 0" />
      <geometry>
        <box size="2.02 0.03 0.03" />
        </geometry>
      </collision>
    <collision name="floor_longbar_4">
      <origin xyz="0 0.46 0.12" rpy="0 0 0" />
      <geometry>
        <box size="2.02 0.03 0.03" />
        </geometry>
      </collision>
    <collision name="floor_longbar_5">
      <origin xyz="0 0.68 0.12" rpy="0 0 0" />
      <geometry>
        <box size="2.02 0.03 0.03" />
        </geometry>
      </collision>
    <collision name="rear_post_0">
      <origin xyz="-1.1 0.8 0.7" rpy="0 0 0" />
      <geometry>
        <box size="0.08 0.08 1.35" />
        </geometry>
      </collision>
    <collision name="rear_post_1">
      <origin xyz="1.1 0.8 0.7" rpy="0 0 0" />
      <geometry>
        <box size="0.08 0.08 1.35" />
        </geometry>
      </collision>
    <collision name="front_gate_post_0">
      <origin xyz="-1.1 -0.8 0.7" rpy="0 0 0" />
      <geometry>
        <box size="0.08 0.08 1.35" />
        </geometry>
      </collision>
    <collision name="front_gate_post_1">
      <origin xyz="1.1 -0.8 0.7" rpy="0 0 0" />
      <geometry>
        <box size="0.08 0.08 1.35" />
        </geometry>
      </collision>
    <collision name="rear_mid_rail">
      <origin xyz="0 0.8 0.68" rpy="0 0 0" />
      <geometry>
        <box size="2.22 0.06 0.07" />
        </geometry>
      </collision>
    <collision name="side_mid_rail_0">
      <origin xyz="-1.1 0.02 0.68" rpy="0 0 0" />
      <geometry>
        <box size="0.06 1.55 0.07" />
        </geometry>
      </collision>
    <collision name="side_mid_rail_1">
      <origin xyz="1.1 0.02 0.68" rpy="0 0 0" />
      <geometry>
        <box size="0.06 1.55 0.07" />
        </geometry>
      </collision>
    <collision name="rear_top_rail">
      <origin xyz="0 0.8 1.18" rpy="0 0 0" />
      <geometry>
        <box size="2.22 0.06 0.07" />
        </geometry>
      </collision>
    <collision name="side_top_rail_0">
      <origin xyz="-1.1 0.02 1.18" rpy="0 0 0" />
      <geometry>
        <box size="0.06 1.55 0.07" />
        </geometry>
      </collision>
    <collision name="side_top_rail_1">
      <origin xyz="1.1 0.02 1.18" rpy="0 0 0" />
      <geometry>
        <box size="0.06 1.55 0.07" />
        </geometry>
      </collision>
    <collision name="guide_shoe_0">
      <origin xyz="-1.1575 0.72 0.35" rpy="0 0 0" />
      <geometry>
        <box size="0.07 0.08 0.16" />
        </geometry>
      </collision>
    <collision name="guide_shoe_1">
      <origin xyz="1.1575 0.72 0.35" rpy="0 0 0" />
      <geometry>
        <box size="0.07 0.08 0.16" />
        </geometry>
      </collision>
    <collision name="guide_shoe_2">
      <origin xyz="-1.1575 0.72 1" rpy="0 0 0" />
      <geometry>
        <box size="0.07 0.08 0.16" />
        </geometry>
      </collision>
    <collision name="guide_shoe_3">
      <origin xyz="1.1575 0.72 1" rpy="0 0 0" />
      <geometry>
        <box size="0.07 0.08 0.16" />
        </geometry>
      </collision>
    </link>
  <link name="counterweight">
    <visual name="counterweight_block">
      <geometry>
        <box size="0.26 0.2 0.52" />
        </geometry>
      <material name="cast_counterweight">
        <color rgba="0.18 0.19 0.2 1" />
        </material>
      </visual>
    <visual name="counterweight_top_eye">
      <origin xyz="0 0 0.31" rpy="0 0 0" />
      <geometry>
        <box size="0.1 0.06 0.1" />
        </geometry>
      <material name="blackened_steel">
        <color rgba="0.08 0.09 0.09 1" />
        </material>
      </visual>
    <visual name="lower_guide_shoe_0">
      <origin xyz="-0.1395 0 -0.18" rpy="0 0 0" />
      <geometry>
        <box size="0.019 0.12 0.12" />
        </geometry>
      <material name="blackened_steel">
        <color rgba="0.08 0.09 0.09 1" />
        </material>
      </visual>
    <visual name="lower_guide_shoe_1">
      <origin xyz="0.1395 0 -0.18" rpy="0 0 0" />
      <geometry>
        <box size="0.019 0.12 0.12" />
        </geometry>
      <material name="blackened_steel">
        <color rgba="0.08 0.09 0.09 1" />
        </material>
      </visual>
    <visual name="upper_guide_shoe_0">
      <origin xyz="-0.1395 0 0.18" rpy="0 0 0" />
      <geometry>
        <box size="0.019 0.12 0.12" />
        </geometry>
      <material name="blackened_steel">
        <color rgba="0.08 0.09 0.09 1" />
        </material>
      </visual>
    <visual name="upper_guide_shoe_1">
      <origin xyz="0.1395 0 0.18" rpy="0 0 0" />
      <geometry>
        <box size="0.019 0.12 0.12" />
        </geometry>
      <material name="blackened_steel">
        <color rgba="0.08 0.09 0.09 1" />
        </material>
      </visual>
    <collision name="counterweight_block">
      <geometry>
        <box size="0.26 0.2 0.52" />
        </geometry>
      </collision>
    <collision name="counterweight_top_eye">
      <origin xyz="0 0 0.31" rpy="0 0 0" />
      <geometry>
        <box size="0.1 0.06 0.1" />
        </geometry>
      </collision>
    <collision name="lower_guide_shoe_0">
      <origin xyz="-0.1395 0 -0.18" rpy="0 0 0" />
      <geometry>
        <box size="0.019 0.12 0.12" />
        </geometry>
      </collision>
    <collision name="lower_guide_shoe_1">
      <origin xyz="0.1395 0 -0.18" rpy="0 0 0" />
      <geometry>
        <box size="0.019 0.12 0.12" />
        </geometry>
      </collision>
    <collision name="upper_guide_shoe_0">
      <origin xyz="-0.1395 0 0.18" rpy="0 0 0" />
      <geometry>
        <box size="0.019 0.12 0.12" />
        </geometry>
      </collision>
    <collision name="upper_guide_shoe_1">
      <origin xyz="0.1395 0 0.18" rpy="0 0 0" />
      <geometry>
        <box size="0.019 0.12 0.12" />
        </geometry>
      </collision>
    </link>
  <link name="gate_leaf_0">
    <visual name="hinge_stile">
      <origin xyz="0 0 0.55" rpy="0 0 0" />
      <geometry>
        <box size="0.05 0.045 1.1" />
        </geometry>
      <material name="safety_yellow">
        <color rgba="1 0.72 0.05 1" />
        </material>
      </visual>
    <visual name="latch_stile">
      <origin xyz="0.99 0 0.56" rpy="0 0 0" />
      <geometry>
        <box size="0.055 0.04 1.02" />
        </geometry>
      <material name="safety_yellow">
        <color rgba="1 0.72 0.05 1" />
        </material>
      </visual>
    <visual name="bottom_rail">
      <origin xyz="0.495 0 0.18" rpy="0 0 0" />
      <geometry>
        <box size="1.03 0.04 0.055" />
        </geometry>
      <material name="safety_yellow">
        <color rgba="1 0.72 0.05 1" />
        </material>
      </visual>
    <visual name="middle_rail">
      <origin xyz="0.495 0 0.55" rpy="0 0 0" />
      <geometry>
        <box size="1.03 0.04 0.055" />
        </geometry>
      <material name="safety_yellow">
        <color rgba="1 0.72 0.05 1" />
        </material>
      </visual>
    <visual name="top_rail">
      <origin xyz="0.495 0 0.96" rpy="0 0 0" />
      <geometry>
        <box size="1.03 0.04 0.055" />
        </geometry>
      <material name="safety_yellow">
        <color rgba="1 0.72 0.05 1" />
        </material>
      </visual>
    <visual name="infill_bar_0">
      <origin xyz="0.24 0 0.56" rpy="0 0 0" />
      <geometry>
        <box size="0.03 0.03 0.78" />
        </geometry>
      <material name="galvanized_steel">
        <color rgba="0.55 0.58 0.56 1" />
        </material>
      </visual>
    <visual name="infill_bar_1">
      <origin xyz="0.48 0 0.56" rpy="0 0 0" />
      <geometry>
        <box size="0.03 0.03 0.78" />
        </geometry>
      <material name="galvanized_steel">
        <color rgba="0.55 0.58 0.56 1" />
        </material>
      </visual>
    <visual name="infill_bar_2">
      <origin xyz="0.72 0 0.56" rpy="0 0 0" />
      <geometry>
        <box size="0.03 0.03 0.78" />
        </geometry>
      <material name="galvanized_steel">
        <color rgba="0.55 0.58 0.56 1" />
        </material>
      </visual>
    <collision name="hinge_stile">
      <origin xyz="0 0 0.55" rpy="0 0 0" />
      <geometry>
        <box size="0.05 0.045 1.1" />
        </geometry>
      </collision>
    <collision name="latch_stile">
      <origin xyz="0.99 0 0.56" rpy="0 0 0" />
      <geometry>
        <box size="0.055 0.04 1.02" />
        </geometry>
      </collision>
    <collision name="bottom_rail">
      <origin xyz="0.495 0 0.18" rpy="0 0 0" />
      <geometry>
        <box size="1.03 0.04 0.055" />
        </geometry>
      </collision>
    <collision name="middle_rail">
      <origin xyz="0.495 0 0.55" rpy="0 0 0" />
      <geometry>
        <box size="1.03 0.04 0.055" />
        </geometry>
      </collision>
    <collision name="top_rail">
      <origin xyz="0.495 0 0.96" rpy="0 0 0" />
      <geometry>
        <box size="1.03 0.04 0.055" />
        </geometry>
      </collision>
    <collision name="infill_bar_0">
      <origin xyz="0.24 0 0.56" rpy="0 0 0" />
      <geometry>
        <box size="0.03 0.03 0.78" />
        </geometry>
      </collision>
    <collision name="infill_bar_1">
      <origin xyz="0.48 0 0.56" rpy="0 0 0" />
      <geometry>
        <box size="0.03 0.03 0.78" />
        </geometry>
      </collision>
    <collision name="infill_bar_2">
      <origin xyz="0.72 0 0.56" rpy="0 0 0" />
      <geometry>
        <box size="0.03 0.03 0.78" />
        </geometry>
      </collision>
    </link>
  <link name="gate_leaf_1">
    <visual name="hinge_stile">
      <origin xyz="0 0 0.55" rpy="0 0 0" />
      <geometry>
        <box size="0.05 0.045 1.1" />
        </geometry>
      <material name="safety_yellow">
        <color rgba="1 0.72 0.05 1" />
        </material>
      </visual>
    <visual name="latch_stile">
      <origin xyz="-0.99 0 0.56" rpy="0 0 0" />
      <geometry>
        <box size="0.055 0.04 1.02" />
        </geometry>
      <material name="safety_yellow">
        <color rgba="1 0.72 0.05 1" />
        </material>
      </visual>
    <visual name="bottom_rail">
      <origin xyz="-0.495 0 0.18" rpy="0 0 0" />
      <geometry>
        <box size="1.03 0.04 0.055" />
        </geometry>
      <material name="safety_yellow">
        <color rgba="1 0.72 0.05 1" />
        </material>
      </visual>
    <visual name="middle_rail">
      <origin xyz="-0.495 0 0.55" rpy="0 0 0" />
      <geometry>
        <box size="1.03 0.04 0.055" />
        </geometry>
      <material name="safety_yellow">
        <color rgba="1 0.72 0.05 1" />
        </material>
      </visual>
    <visual name="top_rail">
      <origin xyz="-0.495 0 0.96" rpy="0 0 0" />
      <geometry>
        <box size="1.03 0.04 0.055" />
        </geometry>
      <material name="safety_yellow">
        <color rgba="1 0.72 0.05 1" />
        </material>
      </visual>
    <visual name="infill_bar_0">
      <origin xyz="-0.24 0 0.56" rpy="0 0 0" />
      <geometry>
        <box size="0.03 0.03 0.78" />
        </geometry>
      <material name="galvanized_steel">
        <color rgba="0.55 0.58 0.56 1" />
        </material>
      </visual>
    <visual name="infill_bar_1">
      <origin xyz="-0.48 0 0.56" rpy="0 0 0" />
      <geometry>
        <box size="0.03 0.03 0.78" />
        </geometry>
      <material name="galvanized_steel">
        <color rgba="0.55 0.58 0.56 1" />
        </material>
      </visual>
    <visual name="infill_bar_2">
      <origin xyz="-0.72 0 0.56" rpy="0 0 0" />
      <geometry>
        <box size="0.03 0.03 0.78" />
        </geometry>
      <material name="galvanized_steel">
        <color rgba="0.55 0.58 0.56 1" />
        </material>
      </visual>
    <collision name="hinge_stile">
      <origin xyz="0 0 0.55" rpy="0 0 0" />
      <geometry>
        <box size="0.05 0.045 1.1" />
        </geometry>
      </collision>
    <collision name="latch_stile">
      <origin xyz="-0.99 0 0.56" rpy="0 0 0" />
      <geometry>
        <box size="0.055 0.04 1.02" />
        </geometry>
      </collision>
    <collision name="bottom_rail">
      <origin xyz="-0.495 0 0.18" rpy="0 0 0" />
      <geometry>
        <box size="1.03 0.04 0.055" />
        </geometry>
      </collision>
    <collision name="middle_rail">
      <origin xyz="-0.495 0 0.55" rpy="0 0 0" />
      <geometry>
        <box size="1.03 0.04 0.055" />
        </geometry>
      </collision>
    <collision name="top_rail">
      <origin xyz="-0.495 0 0.96" rpy="0 0 0" />
      <geometry>
        <box size="1.03 0.04 0.055" />
        </geometry>
      </collision>
    <collision name="infill_bar_0">
      <origin xyz="-0.24 0 0.56" rpy="0 0 0" />
      <geometry>
        <box size="0.03 0.03 0.78" />
        </geometry>
      </collision>
    <collision name="infill_bar_1">
      <origin xyz="-0.48 0 0.56" rpy="0 0 0" />
      <geometry>
        <box size="0.03 0.03 0.78" />
        </geometry>
      </collision>
    <collision name="infill_bar_2">
      <origin xyz="-0.72 0 0.56" rpy="0 0 0" />
      <geometry>
        <box size="0.03 0.03 0.78" />
        </geometry>
      </collision>
    </link>
  <joint name="frame_to_platform" type="prismatic">
    <origin xyz="0 0 0.34" rpy="0 0 0" />
    <parent link="fixed_frame" />
    <child link="platform" />
    <axis xyz="0 0 1" />
    <limit effort="9000" velocity="0.35" lower="0" upper="1.55" />
    </joint>
  <joint name="frame_to_counterweight" type="prismatic">
    <origin xyz="1.55 0.92 2.82" rpy="0 0 0" />
    <parent link="fixed_frame" />
    <child link="counterweight" />
    <axis xyz="0 0 -1" />
    <limit effort="8000" velocity="0.35" lower="0" upper="1.45" />
    </joint>
  <joint name="platform_to_gate_leaf_0" type="revolute">
    <origin xyz="-1.04 -0.8 0.17" rpy="0 0 0" />
    <parent link="platform" />
    <child link="gate_leaf_0" />
    <axis xyz="0 0 -1" />
    <limit effort="90" velocity="1.2" lower="0" upper="1.57" />
    </joint>
  <joint name="platform_to_gate_leaf_1" type="revolute">
    <origin xyz="1.04 -0.8 0.17" rpy="0 0 0" />
    <parent link="platform" />
    <child link="gate_leaf_1" />
    <axis xyz="0 0 1" />
    <limit effort="90" velocity="1.2" lower="0" upper="1.57" />
    </joint>
  </robot>
