<robot name="tilt_slide_sunroof_cassette">
  <material name="brushed_aluminium">
    <color rgba="0.72 0.74 0.73 1" />
    </material>
  <material name="dark_anodized_track">
    <color rgba="0.05 0.055 0.06 1" />
    </material>
  <material name="black_rubber">
    <color rgba="0.01 0.01 0.012 1" />
    </material>
  <material name="smoked_translucent_glass">
    <color rgba="0.06 0.12 0.16 0.42" />
    </material>
  <material name="bearing_steel">
    <color rgba="0.8 0.8 0.76 1" />
    </material>
  <link name="cassette_frame">
    <visual name="side_member_0">
      <origin xyz="-0.575 -0.1 0.0275" rpy="0 0 0" />
      <geometry>
        <box size="0.085 1.45 0.055" />
        </geometry>
      <material name="brushed_aluminium">
        <color rgba="0.72 0.74 0.73 1" />
        </material>
      </visual>
    <visual name="side_member_1">
      <origin xyz="0.575 -0.1 0.0275" rpy="0 0 0" />
      <geometry>
        <box size="0.085 1.45 0.055" />
        </geometry>
      <material name="brushed_aluminium">
        <color rgba="0.72 0.74 0.73 1" />
        </material>
      </visual>
    <visual name="front_crossmember">
      <origin xyz="0 0.625 0.0275" rpy="0 0 0" />
      <geometry>
        <box size="1.15 0.085 0.055" />
        </geometry>
      <material name="brushed_aluminium">
        <color rgba="0.72 0.74 0.73 1" />
        </material>
      </visual>
    <visual name="rear_crossmember">
      <origin xyz="0 -0.825 0.0275" rpy="0 0 0" />
      <geometry>
        <box size="1.15 0.085 0.055" />
        </geometry>
      <material name="brushed_aluminium">
        <color rgba="0.72 0.74 0.73 1" />
        </material>
      </visual>
    <visual name="guide_bottom_0">
      <origin xyz="-0.46 -0.1 0.058" rpy="0 0 0" />
      <geometry>
        <box size="0.12 1.41 0.012" />
        </geometry>
      <material name="dark_anodized_track">
        <color rgba="0.05 0.055 0.06 1" />
        </material>
      </visual>
    <visual name="guide_bottom_1">
      <origin xyz="0.46 -0.1 0.058" rpy="0 0 0" />
      <geometry>
        <box size="0.12 1.41 0.012" />
        </geometry>
      <material name="dark_anodized_track">
        <color rgba="0.05 0.055 0.06 1" />
        </material>
      </visual>
    <visual name="guide_lip_0_0">
      <origin xyz="-0.518 -0.1 0.074" rpy="0 0 0" />
      <geometry>
        <box size="0.014 1.41 0.04" />
        </geometry>
      <material name="brushed_aluminium">
        <color rgba="0.72 0.74 0.73 1" />
        </material>
      </visual>
    <visual name="guide_lip_0_1">
      <origin xyz="-0.402 -0.1 0.074" rpy="0 0 0" />
      <geometry>
        <box size="0.014 1.41 0.04" />
        </geometry>
      <material name="brushed_aluminium">
        <color rgba="0.72 0.74 0.73 1" />
        </material>
      </visual>
    <visual name="guide_lip_1_0">
      <origin xyz="0.402 -0.1 0.074" rpy="0 0 0" />
      <geometry>
        <box size="0.014 1.41 0.04" />
        </geometry>
      <material name="brushed_aluminium">
        <color rgba="0.72 0.74 0.73 1" />
        </material>
      </visual>
    <visual name="guide_lip_1_1">
      <origin xyz="0.518 -0.1 0.074" rpy="0 0 0" />
      <geometry>
        <box size="0.014 1.41 0.04" />
        </geometry>
      <material name="brushed_aluminium">
        <color rgba="0.72 0.74 0.73 1" />
        </material>
      </visual>
    <visual name="front_screw_0">
      <origin xyz="-0.31 0.615 0.0575" rpy="0 0 0" />
      <geometry>
        <cylinder radius="0.012" length="0.006" />
        </geometry>
      <material name="dark_anodized_track">
        <color rgba="0.05 0.055 0.06 1" />
        </material>
      </visual>
    <visual name="rear_screw_0">
      <origin xyz="-0.31 -0.815 0.0575" rpy="0 0 0" />
      <geometry>
        <cylinder radius="0.012" length="0.006" />
        </geometry>
      <material name="dark_anodized_track">
        <color rgba="0.05 0.055 0.06 1" />
        </material>
      </visual>
    <visual name="front_screw_1">
      <origin xyz="0.31 0.615 0.0575" rpy="0 0 0" />
      <geometry>
        <cylinder radius="0.012" length="0.006" />
        </geometry>
      <material name="dark_anodized_track">
        <color rgba="0.05 0.055 0.06 1" />
        </material>
      </visual>
    <visual name="rear_screw_1">
      <origin xyz="0.31 -0.815 0.0575" rpy="0 0 0" />
      <geometry>
        <cylinder radius="0.012" length="0.006" />
        </geometry>
      <material name="dark_anodized_track">
        <color rgba="0.05 0.055 0.06 1" />
        </material>
      </visual>
    <collision name="side_member_0">
      <origin xyz="-0.575 -0.1 0.0275" rpy="0 0 0" />
      <geometry>
        <box size="0.085 1.45 0.055" />
        </geometry>
      </collision>
    <collision name="side_member_1">
      <origin xyz="0.575 -0.1 0.0275" rpy="0 0 0" />
      <geometry>
        <box size="0.085 1.45 0.055" />
        </geometry>
      </collision>
    <collision name="front_crossmember">
      <origin xyz="0 0.625 0.0275" rpy="0 0 0" />
      <geometry>
        <box size="1.15 0.085 0.055" />
        </geometry>
      </collision>
    <collision name="rear_crossmember">
      <origin xyz="0 -0.825 0.0275" rpy="0 0 0" />
      <geometry>
        <box size="1.15 0.085 0.055" />
        </geometry>
      </collision>
    <collision name="guide_bottom_0">
      <origin xyz="-0.46 -0.1 0.058" rpy="0 0 0" />
      <geometry>
        <box size="0.12 1.41 0.012" />
        </geometry>
      </collision>
    <collision name="guide_bottom_1">
      <origin xyz="0.46 -0.1 0.058" rpy="0 0 0" />
      <geometry>
        <box size="0.12 1.41 0.012" />
        </geometry>
      </collision>
    <collision name="guide_lip_0_0">
      <origin xyz="-0.518 -0.1 0.074" rpy="0 0 0" />
      <geometry>
        <box size="0.014 1.41 0.04" />
        </geometry>
      </collision>
    <collision name="guide_lip_0_1">
      <origin xyz="-0.402 -0.1 0.074" rpy="0 0 0" />
      <geometry>
        <box size="0.014 1.41 0.04" />
        </geometry>
      </collision>
    <collision name="guide_lip_1_0">
      <origin xyz="0.402 -0.1 0.074" rpy="0 0 0" />
      <geometry>
        <box size="0.014 1.41 0.04" />
        </geometry>
      </collision>
    <collision name="guide_lip_1_1">
      <origin xyz="0.518 -0.1 0.074" rpy="0 0 0" />
      <geometry>
        <box size="0.014 1.41 0.04" />
        </geometry>
      </collision>
    <collision name="front_screw_0">
      <origin xyz="-0.31 0.615 0.0575" rpy="0 0 0" />
      <geometry>
        <cylinder radius="0.012" length="0.006" />
        </geometry>
      </collision>
    <collision name="rear_screw_0">
      <origin xyz="-0.31 -0.815 0.0575" rpy="0 0 0" />
      <geometry>
        <cylinder radius="0.012" length="0.006" />
        </geometry>
      </collision>
    <collision name="front_screw_1">
      <origin xyz="0.31 0.615 0.0575" rpy="0 0 0" />
      <geometry>
        <cylinder radius="0.012" length="0.006" />
        </geometry>
      </collision>
    <collision name="rear_screw_1">
      <origin xyz="0.31 -0.815 0.0575" rpy="0 0 0" />
      <geometry>
        <cylinder radius="0.012" length="0.006" />
        </geometry>
      </collision>
    </link>
  <link name="slide_carrier">
    <visual name="rear_hinge_pin">
      <origin xyz="0 0 0.032" rpy="0 1.5708 0" />
      <geometry>
        <cylinder radius="0.009" length="0.98" />
        </geometry>
      <material name="bearing_steel">
        <color rgba="0.8 0.8 0.76 1" />
        </material>
      </visual>
    <visual name="hinge_stanchion_0">
      <origin xyz="-0.2 -0.04 0.012" rpy="0 0 0" />
      <geometry>
        <box size="0.04 0.07 0.03" />
        </geometry>
      <material name="brushed_aluminium">
        <color rgba="0.72 0.74 0.73 1" />
        </material>
      </visual>
    <visual name="hinge_stanchion_1">
      <origin xyz="0.2 -0.04 0.012" rpy="0 0 0" />
      <geometry>
        <box size="0.04 0.07 0.03" />
        </geometry>
      <material name="brushed_aluminium">
        <color rgba="0.72 0.74 0.73 1" />
        </material>
      </visual>
    <visual name="rear_tie_bar">
      <origin xyz="0 0.008 -0.003" rpy="0 0 0" />
      <geometry>
        <box size="0.96 0.03 0.018" />
        </geometry>
      <material name="brushed_aluminium">
        <color rgba="0.72 0.74 0.73 1" />
        </material>
      </visual>
    <visual name="side_beam_0">
      <origin xyz="-0.46 0.445 -0.003" rpy="0 0 0" />
      <geometry>
        <box size="0.035 0.89 0.018" />
        </geometry>
      <material name="brushed_aluminium">
        <color rgba="0.72 0.74 0.73 1" />
        </material>
      </visual>
    <visual name="side_beam_1">
      <origin xyz="0.46 0.445 -0.003" rpy="0 0 0" />
      <geometry>
        <box size="0.035 0.89 0.018" />
        </geometry>
      <material name="brushed_aluminium">
        <color rgba="0.72 0.74 0.73 1" />
        </material>
      </visual>
    <visual name="shoe_block_0_0">
      <origin xyz="-0.46 0.035 -0.017" rpy="0 0 0" />
      <geometry>
        <box size="0.075 0.082 0.03" />
        </geometry>
      <material name="brushed_aluminium">
        <color rgba="0.72 0.74 0.73 1" />
        </material>
      </visual>
    <visual name="shoe_roller_0_0">
      <origin xyz="-0.46 0.035 -0.026" rpy="0 1.5708 0" />
      <geometry>
        <cylinder radius="0.018" length="0.054" />
        </geometry>
      <material name="black_rubber">
        <color rgba="0.01 0.01 0.012 1" />
        </material>
      </visual>
    <visual name="roller_axle_0_0">
      <origin xyz="-0.46 0.035 -0.026" rpy="0 1.5708 0" />
      <geometry>
        <cylinder radius="0.006" length="0.086" />
        </geometry>
      <material name="bearing_steel">
        <color rgba="0.8 0.8 0.76 1" />
        </material>
      </visual>
    <visual name="shoe_block_0_1">
      <origin xyz="-0.46 0.865 -0.017" rpy="0 0 0" />
      <geometry>
        <box size="0.075 0.082 0.03" />
        </geometry>
      <material name="brushed_aluminium">
        <color rgba="0.72 0.74 0.73 1" />
        </material>
      </visual>
    <visual name="shoe_roller_0_1">
      <origin xyz="-0.46 0.865 -0.026" rpy="0 1.5708 0" />
      <geometry>
        <cylinder radius="0.018" length="0.054" />
        </geometry>
      <material name="black_rubber">
        <color rgba="0.01 0.01 0.012 1" />
        </material>
      </visual>
    <visual name="roller_axle_0_1">
      <origin xyz="-0.46 0.865 -0.026" rpy="0 1.5708 0" />
      <geometry>
        <cylinder radius="0.006" length="0.086" />
        </geometry>
      <material name="bearing_steel">
        <color rgba="0.8 0.8 0.76 1" />
        </material>
      </visual>
    <visual name="shoe_block_1_0">
      <origin xyz="0.46 0.035 -0.017" rpy="0 0 0" />
      <geometry>
        <box size="0.075 0.082 0.03" />
        </geometry>
      <material name="brushed_aluminium">
        <color rgba="0.72 0.74 0.73 1" />
        </material>
      </visual>
    <visual name="shoe_roller_1_0">
      <origin xyz="0.46 0.035 -0.026" rpy="0 1.5708 0" />
      <geometry>
        <cylinder radius="0.018" length="0.054" />
        </geometry>
      <material name="black_rubber">
        <color rgba="0.01 0.01 0.012 1" />
        </material>
      </visual>
    <visual name="roller_axle_1_0">
      <origin xyz="0.46 0.035 -0.026" rpy="0 1.5708 0" />
      <geometry>
        <cylinder radius="0.006" length="0.086" />
        </geometry>
      <material name="bearing_steel">
        <color rgba="0.8 0.8 0.76 1" />
        </material>
      </visual>
    <visual name="shoe_block_1_1">
      <origin xyz="0.46 0.865 -0.017" rpy="0 0 0" />
      <geometry>
        <box size="0.075 0.082 0.03" />
        </geometry>
      <material name="brushed_aluminium">
        <color rgba="0.72 0.74 0.73 1" />
        </material>
      </visual>
    <visual name="shoe_roller_1_1">
      <origin xyz="0.46 0.865 -0.026" rpy="0 1.5708 0" />
      <geometry>
        <cylinder radius="0.018" length="0.054" />
        </geometry>
      <material name="black_rubber">
        <color rgba="0.01 0.01 0.012 1" />
        </material>
      </visual>
    <visual name="roller_axle_1_1">
      <origin xyz="0.46 0.865 -0.026" rpy="0 1.5708 0" />
      <geometry>
        <cylinder radius="0.006" length="0.086" />
        </geometry>
      <material name="bearing_steel">
        <color rgba="0.8 0.8 0.76 1" />
        </material>
      </visual>
    <collision name="rear_hinge_pin">
      <origin xyz="0 0 0.032" rpy="0 1.5708 0" />
      <geometry>
        <cylinder radius="0.009" length="0.98" />
        </geometry>
      </collision>
    <collision name="hinge_stanchion_0">
      <origin xyz="-0.2 -0.04 0.012" rpy="0 0 0" />
      <geometry>
        <box size="0.04 0.07 0.03" />
        </geometry>
      </collision>
    <collision name="hinge_stanchion_1">
      <origin xyz="0.2 -0.04 0.012" rpy="0 0 0" />
      <geometry>
        <box size="0.04 0.07 0.03" />
        </geometry>
      </collision>
    <collision name="rear_tie_bar">
      <origin xyz="0 0.008 -0.003" rpy="0 0 0" />
      <geometry>
        <box size="0.96 0.03 0.018" />
        </geometry>
      </collision>
    <collision name="side_beam_0">
      <origin xyz="-0.46 0.445 -0.003" rpy="0 0 0" />
      <geometry>
        <box size="0.035 0.89 0.018" />
        </geometry>
      </collision>
    <collision name="side_beam_1">
      <origin xyz="0.46 0.445 -0.003" rpy="0 0 0" />
      <geometry>
        <box size="0.035 0.89 0.018" />
        </geometry>
      </collision>
    <collision name="shoe_block_0_0">
      <origin xyz="-0.46 0.035 -0.017" rpy="0 0 0" />
      <geometry>
        <box size="0.075 0.082 0.03" />
        </geometry>
      </collision>
    <collision name="shoe_roller_0_0">
      <origin xyz="-0.46 0.035 -0.026" rpy="0 1.5708 0" />
      <geometry>
        <cylinder radius="0.018" length="0.054" />
        </geometry>
      </collision>
    <collision name="roller_axle_0_0">
      <origin xyz="-0.46 0.035 -0.026" rpy="0 1.5708 0" />
      <geometry>
        <cylinder radius="0.006" length="0.086" />
        </geometry>
      </collision>
    <collision name="shoe_block_0_1">
      <origin xyz="-0.46 0.865 -0.017" rpy="0 0 0" />
      <geometry>
        <box size="0.075 0.082 0.03" />
        </geometry>
      </collision>
    <collision name="shoe_roller_0_1">
      <origin xyz="-0.46 0.865 -0.026" rpy="0 1.5708 0" />
      <geometry>
        <cylinder radius="0.018" length="0.054" />
        </geometry>
      </collision>
    <collision name="roller_axle_0_1">
      <origin xyz="-0.46 0.865 -0.026" rpy="0 1.5708 0" />
      <geometry>
        <cylinder radius="0.006" length="0.086" />
        </geometry>
      </collision>
    <collision name="shoe_block_1_0">
      <origin xyz="0.46 0.035 -0.017" rpy="0 0 0" />
      <geometry>
        <box size="0.075 0.082 0.03" />
        </geometry>
      </collision>
    <collision name="shoe_roller_1_0">
      <origin xyz="0.46 0.035 -0.026" rpy="0 1.5708 0" />
      <geometry>
        <cylinder radius="0.018" length="0.054" />
        </geometry>
      </collision>
    <collision name="roller_axle_1_0">
      <origin xyz="0.46 0.035 -0.026" rpy="0 1.5708 0" />
      <geometry>
        <cylinder radius="0.006" length="0.086" />
        </geometry>
      </collision>
    <collision name="shoe_block_1_1">
      <origin xyz="0.46 0.865 -0.017" rpy="0 0 0" />
      <geometry>
        <box size="0.075 0.082 0.03" />
        </geometry>
      </collision>
    <collision name="shoe_roller_1_1">
      <origin xyz="0.46 0.865 -0.026" rpy="0 1.5708 0" />
      <geometry>
        <cylinder radius="0.018" length="0.054" />
        </geometry>
      </collision>
    <collision name="roller_axle_1_1">
      <origin xyz="0.46 0.865 -0.026" rpy="0 1.5708 0" />
      <geometry>
        <cylinder radius="0.006" length="0.086" />
        </geometry>
      </collision>
    </link>
  <link name="glass_panel">
    <visual name="glass_sheet">
      <origin xyz="0 0.505 0.02" rpy="0 0 0" />
      <geometry>
        <box size="0.88 0.9 0.016" />
        </geometry>
      <material name="smoked_translucent_glass">
        <color rgba="0.06 0.12 0.16 0.42" />
        </material>
      </visual>
    <visual name="rear_seal">
      <origin xyz="0 0.035 0.019" rpy="0 0 0" />
      <geometry>
        <box size="0.94 0.05 0.022" />
        </geometry>
      <material name="black_rubber">
        <color rgba="0.01 0.01 0.012 1" />
        </material>
      </visual>
    <visual name="front_seal">
      <origin xyz="0 0.935 0.019" rpy="0 0 0" />
      <geometry>
        <box size="0.94 0.05 0.022" />
        </geometry>
      <material name="black_rubber">
        <color rgba="0.01 0.01 0.012 1" />
        </material>
      </visual>
    <visual name="side_seal_0">
      <origin xyz="-0.455 0.485 0.019" rpy="0 0 0" />
      <geometry>
        <box size="0.034 0.94 0.022" />
        </geometry>
      <material name="black_rubber">
        <color rgba="0.01 0.01 0.012 1" />
        </material>
      </visual>
    <visual name="side_seal_1">
      <origin xyz="0.455 0.485 0.019" rpy="0 0 0" />
      <geometry>
        <box size="0.034 0.94 0.022" />
        </geometry>
      <material name="black_rubber">
        <color rgba="0.01 0.01 0.012 1" />
        </material>
      </visual>
    <visual name="hinge_knuckle_0">
      <origin xyz="-0.32 0 0.032" rpy="0 1.5708 0" />
      <geometry>
        <cylinder radius="0.011" length="0.1" />
        </geometry>
      <material name="brushed_aluminium">
        <color rgba="0.72 0.74 0.73 1" />
        </material>
      </visual>
    <visual name="hinge_knuckle_1">
      <origin xyz="0.32 0 0.032" rpy="0 1.5708 0" />
      <geometry>
        <cylinder radius="0.011" length="0.1" />
        </geometry>
      <material name="brushed_aluminium">
        <color rgba="0.72 0.74 0.73 1" />
        </material>
      </visual>
    <collision name="glass_sheet">
      <origin xyz="0 0.505 0.02" rpy="0 0 0" />
      <geometry>
        <box size="0.88 0.9 0.016" />
        </geometry>
      </collision>
    <collision name="rear_seal">
      <origin xyz="0 0.035 0.019" rpy="0 0 0" />
      <geometry>
        <box size="0.94 0.05 0.022" />
        </geometry>
      </collision>
    <collision name="front_seal">
      <origin xyz="0 0.935 0.019" rpy="0 0 0" />
      <geometry>
        <box size="0.94 0.05 0.022" />
        </geometry>
      </collision>
    <collision name="side_seal_0">
      <origin xyz="-0.455 0.485 0.019" rpy="0 0 0" />
      <geometry>
        <box size="0.034 0.94 0.022" />
        </geometry>
      </collision>
    <collision name="side_seal_1">
      <origin xyz="0.455 0.485 0.019" rpy="0 0 0" />
      <geometry>
        <box size="0.034 0.94 0.022" />
        </geometry>
      </collision>
    <collision name="hinge_knuckle_0">
      <origin xyz="-0.32 0 0.032" rpy="0 1.5708 0" />
      <geometry>
        <cylinder radius="0.011" length="0.1" />
        </geometry>
      </collision>
    <collision name="hinge_knuckle_1">
      <origin xyz="0.32 0 0.032" rpy="0 1.5708 0" />
      <geometry>
        <cylinder radius="0.011" length="0.1" />
        </geometry>
      </collision>
    </link>
  <joint name="frame_to_carrier" type="prismatic">
    <origin xyz="0 -0.33 0.108" rpy="0 0 0" />
    <parent link="cassette_frame" />
    <child link="slide_carrier" />
    <axis xyz="0 -1 0" />
    <limit effort="180" velocity="0.35" lower="0" upper="0.36" />
    </joint>
  <joint name="carrier_to_glass" type="revolute">
    <parent link="slide_carrier" />
    <child link="glass_panel" />
    <axis xyz="1 0 0" />
    <limit effort="60" velocity="0.9" lower="0" upper="0.24" />
    </joint>
  </robot>
