<robot name="open_frame_robotic_leg_module">
  <link name="upper_housing">
    <visual name="electronics_case">
      <origin xyz="0 0 0.145" rpy="0 0 0" />
      <geometry>
        <box size="0.3 0.23 0.15" />
        </geometry>
      <material name="dark_anodized_aluminum">
        <color rgba="0.08 0.09 0.1 1" />
        </material>
      </visual>
    <visual name="top_mount">
      <origin xyz="0 0 0.237" rpy="0 0 0" />
      <geometry>
        <box size="0.24 0.18 0.035" />
        </geometry>
      <material name="brushed_aluminum">
        <color rgba="0.68 0.7 0.69 1" />
        </material>
      </visual>
    <visual name="hip_fork_plate_0">
      <origin xyz="0 -0.145 0.02" rpy="0 0 0" />
      <geometry>
        <box size="0.17 0.035 0.24" />
        </geometry>
      <material name="brushed_aluminum">
        <color rgba="0.68 0.7 0.69 1" />
        </material>
      </visual>
    <visual name="hip_fork_plate_1">
      <origin xyz="0 0.145 0.02" rpy="0 0 0" />
      <geometry>
        <box size="0.17 0.035 0.24" />
        </geometry>
      <material name="brushed_aluminum">
        <color rgba="0.68 0.7 0.69 1" />
        </material>
      </visual>
    <visual name="fork_back_tie">
      <origin xyz="-0.082 0 0.055" rpy="0 0 0" />
      <geometry>
        <box size="0.055 0.3 0.055" />
        </geometry>
      <material name="brushed_aluminum">
        <color rgba="0.68 0.7 0.69 1" />
        </material>
      </visual>
    <visual name="hip_bearing_cap_0">
      <origin xyz="0 -0.174 0" rpy="1.5708 0 0" />
      <geometry>
        <cylinder radius="0.073" length="0.034" />
        </geometry>
      <material name="black_bearing_rubber">
        <color rgba="0.015 0.015 0.014 1" />
        </material>
      </visual>
    <visual name="hip_bearing_cap_1">
      <origin xyz="0 0.174 0" rpy="1.5708 0 0" />
      <geometry>
        <cylinder radius="0.073" length="0.034" />
        </geometry>
      <material name="black_bearing_rubber">
        <color rgba="0.015 0.015 0.014 1" />
        </material>
      </visual>
    <visual name="front_service_panel">
      <origin xyz="0.156 0 0.15" rpy="0 0 0" />
      <geometry>
        <box size="0.012 0.17 0.095" />
        </geometry>
      <material name="safety_orange_joint_marks">
        <color rgba="1 0.38 0.05 1" />
        </material>
      </visual>
    <collision name="electronics_case">
      <origin xyz="0 0 0.145" rpy="0 0 0" />
      <geometry>
        <box size="0.3 0.23 0.15" />
        </geometry>
      </collision>
    <collision name="top_mount">
      <origin xyz="0 0 0.237" rpy="0 0 0" />
      <geometry>
        <box size="0.24 0.18 0.035" />
        </geometry>
      </collision>
    <collision name="hip_fork_plate_0">
      <origin xyz="0 -0.145 0.02" rpy="0 0 0" />
      <geometry>
        <box size="0.17 0.035 0.24" />
        </geometry>
      </collision>
    <collision name="hip_fork_plate_1">
      <origin xyz="0 0.145 0.02" rpy="0 0 0" />
      <geometry>
        <box size="0.17 0.035 0.24" />
        </geometry>
      </collision>
    <collision name="fork_back_tie">
      <origin xyz="-0.082 0 0.055" rpy="0 0 0" />
      <geometry>
        <box size="0.055 0.3 0.055" />
        </geometry>
      </collision>
    <collision name="hip_bearing_cap_0">
      <origin xyz="0 -0.174 0" rpy="1.5708 0 0" />
      <geometry>
        <cylinder radius="0.073" length="0.034" />
        </geometry>
      </collision>
    <collision name="hip_bearing_cap_1">
      <origin xyz="0 0.174 0" rpy="1.5708 0 0" />
      <geometry>
        <cylinder radius="0.073" length="0.034" />
        </geometry>
      </collision>
    <collision name="front_service_panel">
      <origin xyz="0.156 0 0.15" rpy="0 0 0" />
      <geometry>
        <box size="0.012 0.17 0.095" />
        </geometry>
      </collision>
    </link>
  <link name="thigh_link">
    <visual name="hip_hub">
      <origin xyz="0 0 0" rpy="1.5708 0 0" />
      <geometry>
        <cylinder radius="0.055" length="0.18" />
        </geometry>
      <material name="black_bearing_rubber">
        <color rgba="0.015 0.015 0.014 1" />
        </material>
      </visual>
    <visual name="hip_inner_axle">
      <origin xyz="0 0 0" rpy="1.5708 0 0" />
      <geometry>
        <cylinder radius="0.026" length="0.255" />
        </geometry>
      <material name="brushed_aluminum">
        <color rgba="0.68 0.7 0.69 1" />
        </material>
      </visual>
    <visual name="hip_bridge">
      <origin xyz="0 0 -0.08" rpy="0 0 0" />
      <geometry>
        <box size="0.13 0.16 0.06" />
        </geometry>
      <material name="brushed_aluminum">
        <color rgba="0.68 0.7 0.69 1" />
        </material>
      </visual>
    <visual name="rail_0">
      <origin xyz="-0.035 -0.065 -0.315" rpy="0 0 0" />
      <geometry>
        <box size="0.03 0.026 0.435" />
        </geometry>
      <material name="brushed_aluminum">
        <color rgba="0.68 0.7 0.69 1" />
        </material>
      </visual>
    <visual name="rail_1">
      <origin xyz="0.035 0.065 -0.315" rpy="0 0 0" />
      <geometry>
        <box size="0.03 0.026 0.435" />
        </geometry>
      <material name="brushed_aluminum">
        <color rgba="0.68 0.7 0.69 1" />
        </material>
      </visual>
    <visual name="diagonal_web_0">
      <origin xyz="0 0 -0.3175" rpy="0 2.89984 0" />
      <geometry>
        <box size="0.018 0.05 0.375932" />
        </geometry>
      <material name="brushed_aluminum">
        <color rgba="0.68 0.7 0.69 1" />
        </material>
      </visual>
    <visual name="diagonal_web_1">
      <origin xyz="0 0 -0.3175" rpy="0 -2.89984 0" />
      <geometry>
        <box size="0.018 0.05 0.375932" />
        </geometry>
      <material name="brushed_aluminum">
        <color rgba="0.68 0.7 0.69 1" />
        </material>
      </visual>
    <visual name="knee_bridge">
      <origin xyz="0 0 -0.525" rpy="0 0 0" />
      <geometry>
        <box size="0.14 0.192 0.05" />
        </geometry>
      <material name="brushed_aluminum">
        <color rgba="0.68 0.7 0.69 1" />
        </material>
      </visual>
    <visual name="knee_yoke_plate_0">
      <origin xyz="0 -0.096 -0.615" rpy="0 0 0" />
      <geometry>
        <box size="0.145 0.026 0.135" />
        </geometry>
      <material name="brushed_aluminum">
        <color rgba="0.68 0.7 0.69 1" />
        </material>
      </visual>
    <visual name="knee_yoke_plate_1">
      <origin xyz="0 0.096 -0.615" rpy="0 0 0" />
      <geometry>
        <box size="0.145 0.026 0.135" />
        </geometry>
      <material name="brushed_aluminum">
        <color rgba="0.68 0.7 0.69 1" />
        </material>
      </visual>
    <visual name="knee_outer_bearing_0">
      <origin xyz="0 -0.116 -0.62" rpy="1.5708 0 0" />
      <geometry>
        <cylinder radius="0.05" length="0.026" />
        </geometry>
      <material name="black_bearing_rubber">
        <color rgba="0.015 0.015 0.014 1" />
        </material>
      </visual>
    <visual name="knee_outer_bearing_1">
      <origin xyz="0 0.116 -0.62" rpy="1.5708 0 0" />
      <geometry>
        <cylinder radius="0.05" length="0.026" />
        </geometry>
      <material name="black_bearing_rubber">
        <color rgba="0.015 0.015 0.014 1" />
        </material>
      </visual>
    <collision name="hip_hub">
      <origin xyz="0 0 0" rpy="1.5708 0 0" />
      <geometry>
        <cylinder radius="0.055" length="0.18" />
        </geometry>
      </collision>
    <collision name="hip_inner_axle">
      <origin xyz="0 0 0" rpy="1.5708 0 0" />
      <geometry>
        <cylinder radius="0.026" length="0.255" />
        </geometry>
      </collision>
    <collision name="hip_bridge">
      <origin xyz="0 0 -0.08" rpy="0 0 0" />
      <geometry>
        <box size="0.13 0.16 0.06" />
        </geometry>
      </collision>
    <collision name="rail_0">
      <origin xyz="-0.035 -0.065 -0.315" rpy="0 0 0" />
      <geometry>
        <box size="0.03 0.026 0.435" />
        </geometry>
      </collision>
    <collision name="rail_1">
      <origin xyz="0.035 0.065 -0.315" rpy="0 0 0" />
      <geometry>
        <box size="0.03 0.026 0.435" />
        </geometry>
      </collision>
    <collision name="diagonal_web_0">
      <origin xyz="0 0 -0.3175" rpy="0 2.89984 0" />
      <geometry>
        <box size="0.018 0.05 0.375932" />
        </geometry>
      </collision>
    <collision name="diagonal_web_1">
      <origin xyz="0 0 -0.3175" rpy="0 -2.89984 0" />
      <geometry>
        <box size="0.018 0.05 0.375932" />
        </geometry>
      </collision>
    <collision name="knee_bridge">
      <origin xyz="0 0 -0.525" rpy="0 0 0" />
      <geometry>
        <box size="0.14 0.192 0.05" />
        </geometry>
      </collision>
    <collision name="knee_yoke_plate_0">
      <origin xyz="0 -0.096 -0.615" rpy="0 0 0" />
      <geometry>
        <box size="0.145 0.026 0.135" />
        </geometry>
      </collision>
    <collision name="knee_yoke_plate_1">
      <origin xyz="0 0.096 -0.615" rpy="0 0 0" />
      <geometry>
        <box size="0.145 0.026 0.135" />
        </geometry>
      </collision>
    <collision name="knee_outer_bearing_0">
      <origin xyz="0 -0.116 -0.62" rpy="1.5708 0 0" />
      <geometry>
        <cylinder radius="0.05" length="0.026" />
        </geometry>
      </collision>
    <collision name="knee_outer_bearing_1">
      <origin xyz="0 0.116 -0.62" rpy="1.5708 0 0" />
      <geometry>
        <cylinder radius="0.05" length="0.026" />
        </geometry>
      </collision>
    </link>
  <link name="shank_link">
    <visual name="knee_hub">
      <origin xyz="0 0 0" rpy="1.5708 0 0" />
      <geometry>
        <cylinder radius="0.045" length="0.13" />
        </geometry>
      <material name="black_bearing_rubber">
        <color rgba="0.015 0.015 0.014 1" />
        </material>
      </visual>
    <visual name="knee_axle">
      <origin xyz="0 0 0" rpy="1.5708 0 0" />
      <geometry>
        <cylinder radius="0.021" length="0.166" />
        </geometry>
      <material name="brushed_aluminum">
        <color rgba="0.68 0.7 0.69 1" />
        </material>
      </visual>
    <visual name="knee_socket">
      <origin xyz="0 0 -0.063" rpy="0 0 0" />
      <geometry>
        <box size="0.11 0.125 0.055" />
        </geometry>
      <material name="brushed_aluminum">
        <color rgba="0.68 0.7 0.69 1" />
        </material>
      </visual>
    <visual name="rail_0">
      <origin xyz="-0.03 -0.052 -0.26" rpy="0 0 0" />
      <geometry>
        <box size="0.025 0.023 0.34" />
        </geometry>
      <material name="brushed_aluminum">
        <color rgba="0.68 0.7 0.69 1" />
        </material>
      </visual>
    <visual name="rail_1">
      <origin xyz="0.03 0.052 -0.26" rpy="0 0 0" />
      <geometry>
        <box size="0.025 0.023 0.34" />
        </geometry>
      <material name="brushed_aluminum">
        <color rgba="0.68 0.7 0.69 1" />
        </material>
      </visual>
    <visual name="diagonal_web_0">
      <origin xyz="0 0 -0.257" rpy="0 2.90785 0" />
      <geometry>
        <box size="0.016 0.045 0.345393" />
        </geometry>
      <material name="brushed_aluminum">
        <color rgba="0.68 0.7 0.69 1" />
        </material>
      </visual>
    <visual name="diagonal_web_1">
      <origin xyz="0 0 -0.257" rpy="0 -2.90785 0" />
      <geometry>
        <box size="0.016 0.045 0.345393" />
        </geometry>
      <material name="brushed_aluminum">
        <color rgba="0.68 0.7 0.69 1" />
        </material>
      </visual>
    <visual name="ankle_bridge">
      <origin xyz="0 0 -0.445" rpy="0 0 0" />
      <geometry>
        <box size="0.12 0.13 0.04" />
        </geometry>
      <material name="brushed_aluminum">
        <color rgba="0.68 0.7 0.69 1" />
        </material>
      </visual>
    <visual name="ankle_yoke_plate_0">
      <origin xyz="0 -0.075 -0.52" rpy="0 0 0" />
      <geometry>
        <box size="0.115 0.023 0.12" />
        </geometry>
      <material name="brushed_aluminum">
        <color rgba="0.68 0.7 0.69 1" />
        </material>
      </visual>
    <visual name="ankle_yoke_plate_1">
      <origin xyz="0 0.075 -0.52" rpy="0 0 0" />
      <geometry>
        <box size="0.115 0.023 0.12" />
        </geometry>
      <material name="brushed_aluminum">
        <color rgba="0.68 0.7 0.69 1" />
        </material>
      </visual>
    <visual name="ankle_outer_bearing_0">
      <origin xyz="0 -0.094 -0.52" rpy="1.5708 0 0" />
      <geometry>
        <cylinder radius="0.042" length="0.022" />
        </geometry>
      <material name="black_bearing_rubber">
        <color rgba="0.015 0.015 0.014 1" />
        </material>
      </visual>
    <visual name="ankle_outer_bearing_1">
      <origin xyz="0 0.094 -0.52" rpy="1.5708 0 0" />
      <geometry>
        <cylinder radius="0.042" length="0.022" />
        </geometry>
      <material name="black_bearing_rubber">
        <color rgba="0.015 0.015 0.014 1" />
        </material>
      </visual>
    <collision name="knee_hub">
      <origin xyz="0 0 0" rpy="1.5708 0 0" />
      <geometry>
        <cylinder radius="0.045" length="0.13" />
        </geometry>
      </collision>
    <collision name="knee_axle">
      <origin xyz="0 0 0" rpy="1.5708 0 0" />
      <geometry>
        <cylinder radius="0.021" length="0.166" />
        </geometry>
      </collision>
    <collision name="knee_socket">
      <origin xyz="0 0 -0.063" rpy="0 0 0" />
      <geometry>
        <box size="0.11 0.125 0.055" />
        </geometry>
      </collision>
    <collision name="rail_0">
      <origin xyz="-0.03 -0.052 -0.26" rpy="0 0 0" />
      <geometry>
        <box size="0.025 0.023 0.34" />
        </geometry>
      </collision>
    <collision name="rail_1">
      <origin xyz="0.03 0.052 -0.26" rpy="0 0 0" />
      <geometry>
        <box size="0.025 0.023 0.34" />
        </geometry>
      </collision>
    <collision name="diagonal_web_0">
      <origin xyz="0 0 -0.257" rpy="0 2.90785 0" />
      <geometry>
        <box size="0.016 0.045 0.345393" />
        </geometry>
      </collision>
    <collision name="diagonal_web_1">
      <origin xyz="0 0 -0.257" rpy="0 -2.90785 0" />
      <geometry>
        <box size="0.016 0.045 0.345393" />
        </geometry>
      </collision>
    <collision name="ankle_bridge">
      <origin xyz="0 0 -0.445" rpy="0 0 0" />
      <geometry>
        <box size="0.12 0.13 0.04" />
        </geometry>
      </collision>
    <collision name="ankle_yoke_plate_0">
      <origin xyz="0 -0.075 -0.52" rpy="0 0 0" />
      <geometry>
        <box size="0.115 0.023 0.12" />
        </geometry>
      </collision>
    <collision name="ankle_yoke_plate_1">
      <origin xyz="0 0.075 -0.52" rpy="0 0 0" />
      <geometry>
        <box size="0.115 0.023 0.12" />
        </geometry>
      </collision>
    <collision name="ankle_outer_bearing_0">
      <origin xyz="0 -0.094 -0.52" rpy="1.5708 0 0" />
      <geometry>
        <cylinder radius="0.042" length="0.022" />
        </geometry>
      </collision>
    <collision name="ankle_outer_bearing_1">
      <origin xyz="0 0.094 -0.52" rpy="1.5708 0 0" />
      <geometry>
        <cylinder radius="0.042" length="0.022" />
        </geometry>
      </collision>
    </link>
  <link name="ankle_foot">
    <visual name="ankle_hub">
      <origin xyz="0 0 0" rpy="1.5708 0 0" />
      <geometry>
        <cylinder radius="0.038" length="0.108" />
        </geometry>
      <material name="black_bearing_rubber">
        <color rgba="0.015 0.015 0.014 1" />
        </material>
      </visual>
    <visual name="ankle_axle">
      <origin xyz="0 0 0" rpy="1.5708 0 0" />
      <geometry>
        <cylinder radius="0.018" length="0.127" />
        </geometry>
      <material name="brushed_aluminum">
        <color rgba="0.68 0.7 0.69 1" />
        </material>
      </visual>
    <visual name="ankle_block">
      <origin xyz="0 0 -0.075" rpy="0 0 0" />
      <geometry>
        <box size="0.08 0.104 0.102" />
        </geometry>
      <material name="brushed_aluminum">
        <color rgba="0.68 0.7 0.69 1" />
        </material>
      </visual>
    <visual name="sole_plate">
      <origin xyz="0.07 0 -0.142" rpy="0 0 0" />
      <geometry>
        <box size="0.335 0.16 0.045" />
        </geometry>
      <material name="dark_anodized_aluminum">
        <color rgba="0.08 0.09 0.1 1" />
        </material>
      </visual>
    <visual name="toe_roller">
      <origin xyz="0.245 0 -0.142" rpy="1.5708 0 0" />
      <geometry>
        <cylinder radius="0.026" length="0.16" />
        </geometry>
      <material name="matte_black_foot_rubber">
        <color rgba="0.02 0.022 0.024 1" />
        </material>
      </visual>
    <visual name="heel_roller">
      <origin xyz="-0.112 0 -0.142" rpy="1.5708 0 0" />
      <geometry>
        <cylinder radius="0.024" length="0.15" />
        </geometry>
      <material name="matte_black_foot_rubber">
        <color rgba="0.02 0.022 0.024 1" />
        </material>
      </visual>
    <visual name="sole_pad_0">
      <origin xyz="0.15 -0.047 -0.169" rpy="0 0 0" />
      <geometry>
        <box size="0.105 0.052 0.016" />
        </geometry>
      <material name="matte_black_foot_rubber">
        <color rgba="0.02 0.022 0.024 1" />
        </material>
      </visual>
    <visual name="sole_pad_1">
      <origin xyz="0.15 0.047 -0.169" rpy="0 0 0" />
      <geometry>
        <box size="0.105 0.052 0.016" />
        </geometry>
      <material name="matte_black_foot_rubber">
        <color rgba="0.02 0.022 0.024 1" />
        </material>
      </visual>
    <visual name="sole_pad_2">
      <origin xyz="-0.04 -0.045 -0.169" rpy="0 0 0" />
      <geometry>
        <box size="0.09 0.05 0.016" />
        </geometry>
      <material name="matte_black_foot_rubber">
        <color rgba="0.02 0.022 0.024 1" />
        </material>
      </visual>
    <visual name="sole_pad_3">
      <origin xyz="-0.04 0.045 -0.169" rpy="0 0 0" />
      <geometry>
        <box size="0.09 0.05 0.016" />
        </geometry>
      <material name="matte_black_foot_rubber">
        <color rgba="0.02 0.022 0.024 1" />
        </material>
      </visual>
    <collision name="ankle_hub">
      <origin xyz="0 0 0" rpy="1.5708 0 0" />
      <geometry>
        <cylinder radius="0.038" length="0.108" />
        </geometry>
      </collision>
    <collision name="ankle_axle">
      <origin xyz="0 0 0" rpy="1.5708 0 0" />
      <geometry>
        <cylinder radius="0.018" length="0.127" />
        </geometry>
      </collision>
    <collision name="ankle_block">
      <origin xyz="0 0 -0.075" rpy="0 0 0" />
      <geometry>
        <box size="0.08 0.104 0.102" />
        </geometry>
      </collision>
    <collision name="sole_plate">
      <origin xyz="0.07 0 -0.142" rpy="0 0 0" />
      <geometry>
        <box size="0.335 0.16 0.045" />
        </geometry>
      </collision>
    <collision name="toe_roller">
      <origin xyz="0.245 0 -0.142" rpy="1.5708 0 0" />
      <geometry>
        <cylinder radius="0.026" length="0.16" />
        </geometry>
      </collision>
    <collision name="heel_roller">
      <origin xyz="-0.112 0 -0.142" rpy="1.5708 0 0" />
      <geometry>
        <cylinder radius="0.024" length="0.15" />
        </geometry>
      </collision>
    <collision name="sole_pad_0">
      <origin xyz="0.15 -0.047 -0.169" rpy="0 0 0" />
      <geometry>
        <box size="0.105 0.052 0.016" />
        </geometry>
      </collision>
    <collision name="sole_pad_1">
      <origin xyz="0.15 0.047 -0.169" rpy="0 0 0" />
      <geometry>
        <box size="0.105 0.052 0.016" />
        </geometry>
      </collision>
    <collision name="sole_pad_2">
      <origin xyz="-0.04 -0.045 -0.169" rpy="0 0 0" />
      <geometry>
        <box size="0.09 0.05 0.016" />
        </geometry>
      </collision>
    <collision name="sole_pad_3">
      <origin xyz="-0.04 0.045 -0.169" rpy="0 0 0" />
      <geometry>
        <box size="0.09 0.05 0.016" />
        </geometry>
      </collision>
    </link>
  <joint name="hip" type="revolute">
    <parent link="upper_housing" />
    <child link="thigh_link" />
    <axis xyz="0 1 0" />
    <limit effort="95" velocity="4.5" lower="-0.7" upper="0.9" />
    </joint>
  <joint name="knee" type="revolute">
    <origin xyz="0 0 -0.62" rpy="0 0 0" />
    <parent link="thigh_link" />
    <child link="shank_link" />
    <axis xyz="0 1 0" />
    <limit effort="85" velocity="5" lower="0" upper="2.1" />
    </joint>
  <joint name="ankle" type="revolute">
    <origin xyz="0 0 -0.52" rpy="0 0 0" />
    <parent link="shank_link" />
    <child link="ankle_foot" />
    <axis xyz="0 1 0" />
    <limit effort="45" velocity="5" lower="-0.55" upper="0.55" />
    </joint>
  </robot>
