<robot name="nested_bracket_arm">
  <material name="dark_powder_coated_steel">
    <color rgba="0.055 0.065 0.07 1" />
    </material>
  <material name="charcoal_formed_plate">
    <color rgba="0.095 0.105 0.105 1" />
    </material>
  <material name="worn_formed_edges">
    <color rgba="0.145 0.155 0.15 1" />
    </material>
  <material name="zinc_plated_hardware">
    <color rgba="0.62 0.6 0.54 1" />
    </material>
  <material name="black_rubber">
    <color rgba="0.018 0.018 0.016 1" />
    </material>
  <material name="root_latch_orange">
    <color rgba="0.95 0.36 0.08 1" />
    </material>
  <link name="foot">
    <visual name="ground_plate">
      <origin xyz="-0.04 0 0.014" rpy="0 0 0" />
      <geometry>
        <box size="0.36 0.245 0.028" />
        </geometry>
      <material name="dark_powder_coated_steel">
        <color rgba="0.055 0.065 0.07 1" />
        </material>
      </visual>
    <visual name="root_plinth">
      <origin xyz="0 0 0.054" rpy="0 0 0" />
      <geometry>
        <box size="0.15 0.17 0.076" />
        </geometry>
      <material name="dark_powder_coated_steel">
        <color rgba="0.055 0.065 0.07 1" />
        </material>
      </visual>
    <visual name="clevis_bridge">
      <origin xyz="0 0 0.082" rpy="0 0 0" />
      <geometry>
        <box size="0.135 0.175 0.026" />
        </geometry>
      <material name="charcoal_formed_plate">
        <color rgba="0.095 0.105 0.105 1" />
        </material>
      </visual>
    <visual name="near_clevis_cheek">
      <origin xyz="0 -0.075 0.18" rpy="0 0 0" />
      <geometry>
        <mesh filename="assets/meshes/root_cheek.obj" />
        </geometry>
      <material name="charcoal_formed_plate">
        <color rgba="0.095 0.105 0.105 1" />
        </material>
      </visual>
    <visual name="near_rear_formed_edge">
      <origin xyz="-0.058 -0.075 0.116" rpy="0 0 0" />
      <geometry>
        <box size="0.02 0.006 0.095" />
        </geometry>
      <material name="worn_formed_edges">
        <color rgba="0.145 0.155 0.15 1" />
        </material>
      </visual>
    <visual name="near_front_formed_edge">
      <origin xyz="0.058 -0.075 0.116" rpy="0 0 0" />
      <geometry>
        <box size="0.02 0.006 0.095" />
        </geometry>
      <material name="worn_formed_edges">
        <color rgba="0.145 0.155 0.15 1" />
        </material>
      </visual>
    <visual name="far_clevis_cheek">
      <origin xyz="0 0.075 0.18" rpy="0 0 0" />
      <geometry>
        <mesh filename="assets/meshes/root_cheek.obj" />
        </geometry>
      <material name="charcoal_formed_plate">
        <color rgba="0.095 0.105 0.105 1" />
        </material>
      </visual>
    <visual name="far_rear_formed_edge">
      <origin xyz="-0.058 0.075 0.116" rpy="0 0 0" />
      <geometry>
        <box size="0.02 0.006 0.095" />
        </geometry>
      <material name="worn_formed_edges">
        <color rgba="0.145 0.155 0.15 1" />
        </material>
      </visual>
    <visual name="far_front_formed_edge">
      <origin xyz="0.058 0.075 0.116" rpy="0 0 0" />
      <geometry>
        <box size="0.02 0.006 0.095" />
        </geometry>
      <material name="worn_formed_edges">
        <color rgba="0.145 0.155 0.15 1" />
        </material>
      </visual>
    <visual name="rubber_pad_0_0">
      <origin xyz="-0.16 -0.09 0.001" rpy="0 0 0" />
      <geometry>
        <box size="0.052 0.04 0.012" />
        </geometry>
      <material name="black_rubber">
        <color rgba="0.018 0.018 0.016 1" />
        </material>
      </visual>
    <visual name="rubber_pad_0_1">
      <origin xyz="-0.16 0.09 0.001" rpy="0 0 0" />
      <geometry>
        <box size="0.052 0.04 0.012" />
        </geometry>
      <material name="black_rubber">
        <color rgba="0.018 0.018 0.016 1" />
        </material>
      </visual>
    <visual name="rubber_pad_1_0">
      <origin xyz="0.075 -0.09 0.001" rpy="0 0 0" />
      <geometry>
        <box size="0.052 0.04 0.012" />
        </geometry>
      <material name="black_rubber">
        <color rgba="0.018 0.018 0.016 1" />
        </material>
      </visual>
    <visual name="rubber_pad_1_1">
      <origin xyz="0.075 0.09 0.001" rpy="0 0 0" />
      <geometry>
        <box size="0.052 0.04 0.012" />
        </geometry>
      <material name="black_rubber">
        <color rgba="0.018 0.018 0.016 1" />
        </material>
      </visual>
    <visual name="latch_pivot">
      <origin xyz="0.03 -0.09 0.128" rpy="1.5708 0 0" />
      <geometry>
        <cylinder radius="0.01" length="0.018" />
        </geometry>
      <material name="zinc_plated_hardware">
        <color rgba="0.62 0.6 0.54 1" />
        </material>
      </visual>
    <visual name="latch_pawl">
      <origin xyz="0.068 -0.098 0.129" rpy="0 -0.139626 0" />
      <geometry>
        <box size="0.074 0.009 0.014" />
        </geometry>
      <material name="root_latch_orange">
        <color rgba="0.95 0.36 0.08 1" />
        </material>
      </visual>
    <visual name="latch_stop">
      <origin xyz="0.066 -0.078 0.102" rpy="0 0 0" />
      <geometry>
        <box size="0.03 0.014 0.026" />
        </geometry>
      <material name="zinc_plated_hardware">
        <color rgba="0.62 0.6 0.54 1" />
        </material>
      </visual>
    <visual name="base_cross_bolt">
      <origin xyz="-0.108 0 0.026" rpy="1.5708 0 0" />
      <geometry>
        <cylinder radius="0.007" length="0.19" />
        </geometry>
      <material name="zinc_plated_hardware">
        <color rgba="0.62 0.6 0.54 1" />
        </material>
      </visual>
    <collision name="ground_plate">
      <origin xyz="-0.04 0 0.014" rpy="0 0 0" />
      <geometry>
        <box size="0.36 0.245 0.028" />
        </geometry>
      </collision>
    <collision name="root_plinth">
      <origin xyz="0 0 0.054" rpy="0 0 0" />
      <geometry>
        <box size="0.15 0.17 0.076" />
        </geometry>
      </collision>
    <collision name="clevis_bridge">
      <origin xyz="0 0 0.082" rpy="0 0 0" />
      <geometry>
        <box size="0.135 0.175 0.026" />
        </geometry>
      </collision>
    <collision name="near_clevis_cheek">
      <origin xyz="0 -0.075 0.18" rpy="0 0 0" />
      <geometry>
        <mesh filename="assets/meshes/root_cheek.obj" />
        </geometry>
      </collision>
    <collision name="near_rear_formed_edge">
      <origin xyz="-0.058 -0.075 0.116" rpy="0 0 0" />
      <geometry>
        <box size="0.02 0.006 0.095" />
        </geometry>
      </collision>
    <collision name="near_front_formed_edge">
      <origin xyz="0.058 -0.075 0.116" rpy="0 0 0" />
      <geometry>
        <box size="0.02 0.006 0.095" />
        </geometry>
      </collision>
    <collision name="far_clevis_cheek">
      <origin xyz="0 0.075 0.18" rpy="0 0 0" />
      <geometry>
        <mesh filename="assets/meshes/root_cheek.obj" />
        </geometry>
      </collision>
    <collision name="far_rear_formed_edge">
      <origin xyz="-0.058 0.075 0.116" rpy="0 0 0" />
      <geometry>
        <box size="0.02 0.006 0.095" />
        </geometry>
      </collision>
    <collision name="far_front_formed_edge">
      <origin xyz="0.058 0.075 0.116" rpy="0 0 0" />
      <geometry>
        <box size="0.02 0.006 0.095" />
        </geometry>
      </collision>
    <collision name="rubber_pad_0_0">
      <origin xyz="-0.16 -0.09 0.001" rpy="0 0 0" />
      <geometry>
        <box size="0.052 0.04 0.012" />
        </geometry>
      </collision>
    <collision name="rubber_pad_0_1">
      <origin xyz="-0.16 0.09 0.001" rpy="0 0 0" />
      <geometry>
        <box size="0.052 0.04 0.012" />
        </geometry>
      </collision>
    <collision name="rubber_pad_1_0">
      <origin xyz="0.075 -0.09 0.001" rpy="0 0 0" />
      <geometry>
        <box size="0.052 0.04 0.012" />
        </geometry>
      </collision>
    <collision name="rubber_pad_1_1">
      <origin xyz="0.075 0.09 0.001" rpy="0 0 0" />
      <geometry>
        <box size="0.052 0.04 0.012" />
        </geometry>
      </collision>
    <collision name="latch_pivot">
      <origin xyz="0.03 -0.09 0.128" rpy="1.5708 0 0" />
      <geometry>
        <cylinder radius="0.01" length="0.018" />
        </geometry>
      </collision>
    <collision name="latch_pawl">
      <origin xyz="0.068 -0.098 0.129" rpy="0 -0.139626 0" />
      <geometry>
        <box size="0.074 0.009 0.014" />
        </geometry>
      </collision>
    <collision name="latch_stop">
      <origin xyz="0.066 -0.078 0.102" rpy="0 0 0" />
      <geometry>
        <box size="0.03 0.014 0.026" />
        </geometry>
      </collision>
    <collision name="base_cross_bolt">
      <origin xyz="-0.108 0 0.026" rpy="1.5708 0 0" />
      <geometry>
        <cylinder radius="0.007" length="0.19" />
        </geometry>
      </collision>
    </link>
  <link name="long_link_0">
    <visual name="near_plate">
      <origin xyz="0 -0.052 0" rpy="0 0 0" />
      <geometry>
        <mesh filename="assets/meshes/long0_plate_mesh.obj" />
        </geometry>
      <material name="charcoal_formed_plate">
        <color rgba="0.095 0.105 0.105 1" />
        </material>
      </visual>
    <visual name="near_upper_lip">
      <origin xyz="0.21 -0.052 0.031" rpy="0 0 0" />
      <geometry>
        <box size="0.3444 0.014 0.016" />
        </geometry>
      <material name="worn_formed_edges">
        <color rgba="0.145 0.155 0.15 1" />
        </material>
      </visual>
    <visual name="near_lower_lip">
      <origin xyz="0.21 -0.052 -0.031" rpy="0 0 0" />
      <geometry>
        <box size="0.3444 0.014 0.016" />
        </geometry>
      <material name="worn_formed_edges">
        <color rgba="0.145 0.155 0.15 1" />
        </material>
      </visual>
    <visual name="near_pressed_rib">
      <origin xyz="0.21 -0.0575 0" rpy="0 0 0" />
      <geometry>
        <box size="0.2184 0.004 0.00992" />
        </geometry>
      <material name="worn_formed_edges">
        <color rgba="0.145 0.155 0.15 1" />
        </material>
      </visual>
    <visual name="far_plate">
      <origin xyz="0 0.052 0" rpy="0 0 0" />
      <geometry>
        <mesh filename="assets/meshes/long0_plate_mesh.obj" />
        </geometry>
      <material name="charcoal_formed_plate">
        <color rgba="0.095 0.105 0.105 1" />
        </material>
      </visual>
    <visual name="far_upper_lip">
      <origin xyz="0.21 0.052 0.031" rpy="0 0 0" />
      <geometry>
        <box size="0.3444 0.014 0.016" />
        </geometry>
      <material name="worn_formed_edges">
        <color rgba="0.145 0.155 0.15 1" />
        </material>
      </visual>
    <visual name="far_lower_lip">
      <origin xyz="0.21 0.052 -0.031" rpy="0 0 0" />
      <geometry>
        <box size="0.3444 0.014 0.016" />
        </geometry>
      <material name="worn_formed_edges">
        <color rgba="0.145 0.155 0.15 1" />
        </material>
      </visual>
    <visual name="far_pressed_rib">
      <origin xyz="0.21 0.0575 0" rpy="0 0 0" />
      <geometry>
        <box size="0.2184 0.004 0.00992" />
        </geometry>
      <material name="worn_formed_edges">
        <color rgba="0.145 0.155 0.15 1" />
        </material>
      </visual>
    <visual name="inner_spacer">
      <origin xyz="0.1428 0 0" rpy="1.5708 0 0" />
      <geometry>
        <cylinder radius="0.01116" length="0.116" />
        </geometry>
      <material name="zinc_plated_hardware">
        <color rgba="0.62 0.6 0.54 1" />
        </material>
      </visual>
    <visual name="outer_spacer">
      <origin xyz="0.2772 0 0" rpy="1.5708 0 0" />
      <geometry>
        <cylinder radius="0.01116" length="0.116" />
        </geometry>
      <material name="zinc_plated_hardware">
        <color rgba="0.62 0.6 0.54 1" />
        </material>
      </visual>
    <visual name="shoulder_bolt">
      <origin xyz="0 0 0" rpy="1.5708 0 0" />
      <geometry>
        <cylinder radius="0.00896" length="0.167" />
        </geometry>
      <material name="zinc_plated_hardware">
        <color rgba="0.62 0.6 0.54 1" />
        </material>
      </visual>
    <visual name="far_washer">
      <origin xyz="0 0.058 0" rpy="1.5708 0 0" />
      <geometry>
        <cylinder radius="0.0189" length="0.006" />
        </geometry>
      <material name="zinc_plated_hardware">
        <color rgba="0.62 0.6 0.54 1" />
        </material>
      </visual>
    <visual name="near_washer">
      <origin xyz="0 -0.058 0" rpy="1.5708 0 0" />
      <geometry>
        <cylinder radius="0.0189" length="0.006" />
        </geometry>
      <material name="zinc_plated_hardware">
        <color rgba="0.62 0.6 0.54 1" />
        </material>
      </visual>
    <collision name="near_plate">
      <origin xyz="0 -0.052 0" rpy="0 0 0" />
      <geometry>
        <mesh filename="assets/meshes/long0_plate_mesh.obj" />
        </geometry>
      </collision>
    <collision name="near_upper_lip">
      <origin xyz="0.21 -0.052 0.031" rpy="0 0 0" />
      <geometry>
        <box size="0.3444 0.014 0.016" />
        </geometry>
      </collision>
    <collision name="near_lower_lip">
      <origin xyz="0.21 -0.052 -0.031" rpy="0 0 0" />
      <geometry>
        <box size="0.3444 0.014 0.016" />
        </geometry>
      </collision>
    <collision name="near_pressed_rib">
      <origin xyz="0.21 -0.0575 0" rpy="0 0 0" />
      <geometry>
        <box size="0.2184 0.004 0.00992" />
        </geometry>
      </collision>
    <collision name="far_plate">
      <origin xyz="0 0.052 0" rpy="0 0 0" />
      <geometry>
        <mesh filename="assets/meshes/long0_plate_mesh.obj" />
        </geometry>
      </collision>
    <collision name="far_upper_lip">
      <origin xyz="0.21 0.052 0.031" rpy="0 0 0" />
      <geometry>
        <box size="0.3444 0.014 0.016" />
        </geometry>
      </collision>
    <collision name="far_lower_lip">
      <origin xyz="0.21 0.052 -0.031" rpy="0 0 0" />
      <geometry>
        <box size="0.3444 0.014 0.016" />
        </geometry>
      </collision>
    <collision name="far_pressed_rib">
      <origin xyz="0.21 0.0575 0" rpy="0 0 0" />
      <geometry>
        <box size="0.2184 0.004 0.00992" />
        </geometry>
      </collision>
    <collision name="inner_spacer">
      <origin xyz="0.1428 0 0" rpy="1.5708 0 0" />
      <geometry>
        <cylinder radius="0.01116" length="0.116" />
        </geometry>
      </collision>
    <collision name="outer_spacer">
      <origin xyz="0.2772 0 0" rpy="1.5708 0 0" />
      <geometry>
        <cylinder radius="0.01116" length="0.116" />
        </geometry>
      </collision>
    <collision name="shoulder_bolt">
      <origin xyz="0 0 0" rpy="1.5708 0 0" />
      <geometry>
        <cylinder radius="0.00896" length="0.167" />
        </geometry>
      </collision>
    <collision name="far_washer">
      <origin xyz="0 0.058 0" rpy="1.5708 0 0" />
      <geometry>
        <cylinder radius="0.0189" length="0.006" />
        </geometry>
      </collision>
    <collision name="near_washer">
      <origin xyz="0 -0.058 0" rpy="1.5708 0 0" />
      <geometry>
        <cylinder radius="0.0189" length="0.006" />
        </geometry>
      </collision>
    </link>
  <link name="short_link_0">
    <visual name="near_plate">
      <origin xyz="0 -0.03 0" rpy="0 0 0" />
      <geometry>
        <mesh filename="assets/meshes/short0_plate_mesh.obj" />
        </geometry>
      <material name="charcoal_formed_plate">
        <color rgba="0.095 0.105 0.105 1" />
        </material>
      </visual>
    <visual name="near_upper_lip">
      <origin xyz="0.12 -0.03 0.026" rpy="0 0 0" />
      <geometry>
        <box size="0.1968 0.014 0.016" />
        </geometry>
      <material name="worn_formed_edges">
        <color rgba="0.145 0.155 0.15 1" />
        </material>
      </visual>
    <visual name="near_lower_lip">
      <origin xyz="0.12 -0.03 -0.026" rpy="0 0 0" />
      <geometry>
        <box size="0.1968 0.014 0.016" />
        </geometry>
      <material name="worn_formed_edges">
        <color rgba="0.145 0.155 0.15 1" />
        </material>
      </visual>
    <visual name="near_pressed_rib">
      <origin xyz="0.12 -0.0355 0" rpy="0 0 0" />
      <geometry>
        <box size="0.1248 0.004 0.00832" />
        </geometry>
      <material name="worn_formed_edges">
        <color rgba="0.145 0.155 0.15 1" />
        </material>
      </visual>
    <visual name="far_plate">
      <origin xyz="0 0.03 0" rpy="0 0 0" />
      <geometry>
        <mesh filename="assets/meshes/short0_plate_mesh.obj" />
        </geometry>
      <material name="charcoal_formed_plate">
        <color rgba="0.095 0.105 0.105 1" />
        </material>
      </visual>
    <visual name="far_upper_lip">
      <origin xyz="0.12 0.03 0.026" rpy="0 0 0" />
      <geometry>
        <box size="0.1968 0.014 0.016" />
        </geometry>
      <material name="worn_formed_edges">
        <color rgba="0.145 0.155 0.15 1" />
        </material>
      </visual>
    <visual name="far_lower_lip">
      <origin xyz="0.12 0.03 -0.026" rpy="0 0 0" />
      <geometry>
        <box size="0.1968 0.014 0.016" />
        </geometry>
      <material name="worn_formed_edges">
        <color rgba="0.145 0.155 0.15 1" />
        </material>
      </visual>
    <visual name="far_pressed_rib">
      <origin xyz="0.12 0.0355 0" rpy="0 0 0" />
      <geometry>
        <box size="0.1248 0.004 0.00832" />
        </geometry>
      <material name="worn_formed_edges">
        <color rgba="0.145 0.155 0.15 1" />
        </material>
      </visual>
    <visual name="inner_spacer">
      <origin xyz="0.0816 0 0" rpy="1.5708 0 0" />
      <geometry>
        <cylinder radius="0.00936" length="0.072" />
        </geometry>
      <material name="zinc_plated_hardware">
        <color rgba="0.62 0.6 0.54 1" />
        </material>
      </visual>
    <visual name="outer_spacer">
      <origin xyz="0.1584 0 0" rpy="1.5708 0 0" />
      <geometry>
        <cylinder radius="0.00936" length="0.072" />
        </geometry>
      <material name="zinc_plated_hardware">
        <color rgba="0.62 0.6 0.54 1" />
        </material>
      </visual>
    <visual name="shoulder_bolt">
      <origin xyz="0 0 0" rpy="1.5708 0 0" />
      <geometry>
        <cylinder radius="0.008" length="0.123" />
        </geometry>
      <material name="zinc_plated_hardware">
        <color rgba="0.62 0.6 0.54 1" />
        </material>
      </visual>
    <visual name="far_washer">
      <origin xyz="0 0.036 0" rpy="1.5708 0 0" />
      <geometry>
        <cylinder radius="0.016875" length="0.006" />
        </geometry>
      <material name="zinc_plated_hardware">
        <color rgba="0.62 0.6 0.54 1" />
        </material>
      </visual>
    <visual name="near_washer">
      <origin xyz="0 -0.036 0" rpy="1.5708 0 0" />
      <geometry>
        <cylinder radius="0.016875" length="0.006" />
        </geometry>
      <material name="zinc_plated_hardware">
        <color rgba="0.62 0.6 0.54 1" />
        </material>
      </visual>
    <collision name="near_plate">
      <origin xyz="0 -0.03 0" rpy="0 0 0" />
      <geometry>
        <mesh filename="assets/meshes/short0_plate_mesh.obj" />
        </geometry>
      </collision>
    <collision name="near_upper_lip">
      <origin xyz="0.12 -0.03 0.026" rpy="0 0 0" />
      <geometry>
        <box size="0.1968 0.014 0.016" />
        </geometry>
      </collision>
    <collision name="near_lower_lip">
      <origin xyz="0.12 -0.03 -0.026" rpy="0 0 0" />
      <geometry>
        <box size="0.1968 0.014 0.016" />
        </geometry>
      </collision>
    <collision name="near_pressed_rib">
      <origin xyz="0.12 -0.0355 0" rpy="0 0 0" />
      <geometry>
        <box size="0.1248 0.004 0.00832" />
        </geometry>
      </collision>
    <collision name="far_plate">
      <origin xyz="0 0.03 0" rpy="0 0 0" />
      <geometry>
        <mesh filename="assets/meshes/short0_plate_mesh.obj" />
        </geometry>
      </collision>
    <collision name="far_upper_lip">
      <origin xyz="0.12 0.03 0.026" rpy="0 0 0" />
      <geometry>
        <box size="0.1968 0.014 0.016" />
        </geometry>
      </collision>
    <collision name="far_lower_lip">
      <origin xyz="0.12 0.03 -0.026" rpy="0 0 0" />
      <geometry>
        <box size="0.1968 0.014 0.016" />
        </geometry>
      </collision>
    <collision name="far_pressed_rib">
      <origin xyz="0.12 0.0355 0" rpy="0 0 0" />
      <geometry>
        <box size="0.1248 0.004 0.00832" />
        </geometry>
      </collision>
    <collision name="inner_spacer">
      <origin xyz="0.0816 0 0" rpy="1.5708 0 0" />
      <geometry>
        <cylinder radius="0.00936" length="0.072" />
        </geometry>
      </collision>
    <collision name="outer_spacer">
      <origin xyz="0.1584 0 0" rpy="1.5708 0 0" />
      <geometry>
        <cylinder radius="0.00936" length="0.072" />
        </geometry>
      </collision>
    <collision name="shoulder_bolt">
      <origin xyz="0 0 0" rpy="1.5708 0 0" />
      <geometry>
        <cylinder radius="0.008" length="0.123" />
        </geometry>
      </collision>
    <collision name="far_washer">
      <origin xyz="0 0.036 0" rpy="1.5708 0 0" />
      <geometry>
        <cylinder radius="0.016875" length="0.006" />
        </geometry>
      </collision>
    <collision name="near_washer">
      <origin xyz="0 -0.036 0" rpy="1.5708 0 0" />
      <geometry>
        <cylinder radius="0.016875" length="0.006" />
        </geometry>
      </collision>
    </link>
  <link name="long_link_1">
    <visual name="near_plate">
      <origin xyz="0 -0.046 0" rpy="0 0 0" />
      <geometry>
        <mesh filename="assets/meshes/long1_plate_mesh.obj" />
        </geometry>
      <material name="charcoal_formed_plate">
        <color rgba="0.095 0.105 0.105 1" />
        </material>
      </visual>
    <visual name="near_upper_lip">
      <origin xyz="0.17 -0.046 0.0235" rpy="0 0 0" />
      <geometry>
        <box size="0.2788 0.014 0.016" />
        </geometry>
      <material name="worn_formed_edges">
        <color rgba="0.145 0.155 0.15 1" />
        </material>
      </visual>
    <visual name="near_lower_lip">
      <origin xyz="0.17 -0.046 -0.0235" rpy="0 0 0" />
      <geometry>
        <box size="0.2788 0.014 0.016" />
        </geometry>
      <material name="worn_formed_edges">
        <color rgba="0.145 0.155 0.15 1" />
        </material>
      </visual>
    <visual name="near_pressed_rib">
      <origin xyz="0.17 -0.051 0" rpy="0 0 0" />
      <geometry>
        <box size="0.1768 0.004 0.00752" />
        </geometry>
      <material name="worn_formed_edges">
        <color rgba="0.145 0.155 0.15 1" />
        </material>
      </visual>
    <visual name="far_plate">
      <origin xyz="0 0.046 0" rpy="0 0 0" />
      <geometry>
        <mesh filename="assets/meshes/long1_plate_mesh.obj" />
        </geometry>
      <material name="charcoal_formed_plate">
        <color rgba="0.095 0.105 0.105 1" />
        </material>
      </visual>
    <visual name="far_upper_lip">
      <origin xyz="0.17 0.046 0.0235" rpy="0 0 0" />
      <geometry>
        <box size="0.2788 0.014 0.016" />
        </geometry>
      <material name="worn_formed_edges">
        <color rgba="0.145 0.155 0.15 1" />
        </material>
      </visual>
    <visual name="far_lower_lip">
      <origin xyz="0.17 0.046 -0.0235" rpy="0 0 0" />
      <geometry>
        <box size="0.2788 0.014 0.016" />
        </geometry>
      <material name="worn_formed_edges">
        <color rgba="0.145 0.155 0.15 1" />
        </material>
      </visual>
    <visual name="far_pressed_rib">
      <origin xyz="0.17 0.051 0" rpy="0 0 0" />
      <geometry>
        <box size="0.1768 0.004 0.00752" />
        </geometry>
      <material name="worn_formed_edges">
        <color rgba="0.145 0.155 0.15 1" />
        </material>
      </visual>
    <visual name="inner_spacer">
      <origin xyz="0.1156 0 0" rpy="1.5708 0 0" />
      <geometry>
        <cylinder radius="0.00846" length="0.103" />
        </geometry>
      <material name="zinc_plated_hardware">
        <color rgba="0.62 0.6 0.54 1" />
        </material>
      </visual>
    <visual name="outer_spacer">
      <origin xyz="0.2244 0 0" rpy="1.5708 0 0" />
      <geometry>
        <cylinder radius="0.00846" length="0.103" />
        </geometry>
      <material name="zinc_plated_hardware">
        <color rgba="0.62 0.6 0.54 1" />
        </material>
      </visual>
    <visual name="shoulder_bolt">
      <origin xyz="0 0 0" rpy="1.5708 0 0" />
      <geometry>
        <cylinder radius="0.00768" length="0.154" />
        </geometry>
      <material name="zinc_plated_hardware">
        <color rgba="0.62 0.6 0.54 1" />
        </material>
      </visual>
    <visual name="far_washer">
      <origin xyz="0 0.0515 0" rpy="1.5708 0 0" />
      <geometry>
        <cylinder radius="0.0162" length="0.006" />
        </geometry>
      <material name="zinc_plated_hardware">
        <color rgba="0.62 0.6 0.54 1" />
        </material>
      </visual>
    <visual name="near_washer">
      <origin xyz="0 -0.0515 0" rpy="1.5708 0 0" />
      <geometry>
        <cylinder radius="0.0162" length="0.006" />
        </geometry>
      <material name="zinc_plated_hardware">
        <color rgba="0.62 0.6 0.54 1" />
        </material>
      </visual>
    <collision name="near_plate">
      <origin xyz="0 -0.046 0" rpy="0 0 0" />
      <geometry>
        <mesh filename="assets/meshes/long1_plate_mesh.obj" />
        </geometry>
      </collision>
    <collision name="near_upper_lip">
      <origin xyz="0.17 -0.046 0.0235" rpy="0 0 0" />
      <geometry>
        <box size="0.2788 0.014 0.016" />
        </geometry>
      </collision>
    <collision name="near_lower_lip">
      <origin xyz="0.17 -0.046 -0.0235" rpy="0 0 0" />
      <geometry>
        <box size="0.2788 0.014 0.016" />
        </geometry>
      </collision>
    <collision name="near_pressed_rib">
      <origin xyz="0.17 -0.051 0" rpy="0 0 0" />
      <geometry>
        <box size="0.1768 0.004 0.00752" />
        </geometry>
      </collision>
    <collision name="far_plate">
      <origin xyz="0 0.046 0" rpy="0 0 0" />
      <geometry>
        <mesh filename="assets/meshes/long1_plate_mesh.obj" />
        </geometry>
      </collision>
    <collision name="far_upper_lip">
      <origin xyz="0.17 0.046 0.0235" rpy="0 0 0" />
      <geometry>
        <box size="0.2788 0.014 0.016" />
        </geometry>
      </collision>
    <collision name="far_lower_lip">
      <origin xyz="0.17 0.046 -0.0235" rpy="0 0 0" />
      <geometry>
        <box size="0.2788 0.014 0.016" />
        </geometry>
      </collision>
    <collision name="far_pressed_rib">
      <origin xyz="0.17 0.051 0" rpy="0 0 0" />
      <geometry>
        <box size="0.1768 0.004 0.00752" />
        </geometry>
      </collision>
    <collision name="inner_spacer">
      <origin xyz="0.1156 0 0" rpy="1.5708 0 0" />
      <geometry>
        <cylinder radius="0.00846" length="0.103" />
        </geometry>
      </collision>
    <collision name="outer_spacer">
      <origin xyz="0.2244 0 0" rpy="1.5708 0 0" />
      <geometry>
        <cylinder radius="0.00846" length="0.103" />
        </geometry>
      </collision>
    <collision name="shoulder_bolt">
      <origin xyz="0 0 0" rpy="1.5708 0 0" />
      <geometry>
        <cylinder radius="0.00768" length="0.154" />
        </geometry>
      </collision>
    <collision name="far_washer">
      <origin xyz="0 0.0515 0" rpy="1.5708 0 0" />
      <geometry>
        <cylinder radius="0.0162" length="0.006" />
        </geometry>
      </collision>
    <collision name="near_washer">
      <origin xyz="0 -0.0515 0" rpy="1.5708 0 0" />
      <geometry>
        <cylinder radius="0.0162" length="0.006" />
        </geometry>
      </collision>
    </link>
  <link name="tray_bracket">
    <visual name="tray_floor">
      <origin xyz="0.086 0 -0.037" rpy="0 0 0" />
      <geometry>
        <box size="0.155 0.11 0.008" />
        </geometry>
      <material name="charcoal_formed_plate">
        <color rgba="0.095 0.105 0.105 1" />
        </material>
      </visual>
    <visual name="far_tray_lip">
      <origin xyz="0.092 0.057 -0.019" rpy="0 0 0" />
      <geometry>
        <box size="0.142 0.008 0.032" />
        </geometry>
      <material name="worn_formed_edges">
        <color rgba="0.145 0.155 0.15 1" />
        </material>
      </visual>
    <visual name="near_tray_lip">
      <origin xyz="0.092 -0.057 -0.019" rpy="0 0 0" />
      <geometry>
        <box size="0.142 0.008 0.032" />
        </geometry>
      <material name="worn_formed_edges">
        <color rgba="0.145 0.155 0.15 1" />
        </material>
      </visual>
    <visual name="tray_front_lip">
      <origin xyz="0.159 0 -0.019" rpy="0 0 0" />
      <geometry>
        <box size="0.012 0.112 0.032" />
        </geometry>
      <material name="worn_formed_edges">
        <color rgba="0.145 0.155 0.15 1" />
        </material>
      </visual>
    <visual name="wrist_bridge">
      <origin xyz="0.016 0 -0.033" rpy="0 0 0" />
      <geometry>
        <box size="0.052 0.078 0.012" />
        </geometry>
      <material name="charcoal_formed_plate">
        <color rgba="0.095 0.105 0.105 1" />
        </material>
      </visual>
    <visual name="near_wrist_ear">
      <origin xyz="0 -0.027 -0.002" rpy="0 0 0" />
      <geometry>
        <box size="0.06 0.01 0.056" />
        </geometry>
      <material name="charcoal_formed_plate">
        <color rgba="0.095 0.105 0.105 1" />
        </material>
      </visual>
    <visual name="far_wrist_ear">
      <origin xyz="0 0.027 -0.002" rpy="0 0 0" />
      <geometry>
        <box size="0.06 0.01 0.056" />
        </geometry>
      <material name="charcoal_formed_plate">
        <color rgba="0.095 0.105 0.105 1" />
        </material>
      </visual>
    <visual name="wrist_shoulder_bolt">
      <origin xyz="0 0 0" rpy="1.5708 0 0" />
      <geometry>
        <cylinder radius="0.008" length="0.128" />
        </geometry>
      <material name="zinc_plated_hardware">
        <color rgba="0.62 0.6 0.54 1" />
        </material>
      </visual>
    <visual name="far_wrist_washer">
      <origin xyz="0 0.035 0" rpy="1.5708 0 0" />
      <geometry>
        <cylinder radius="0.017" length="0.006" />
        </geometry>
      <material name="zinc_plated_hardware">
        <color rgba="0.62 0.6 0.54 1" />
        </material>
      </visual>
    <visual name="near_wrist_washer">
      <origin xyz="0 -0.035 0" rpy="1.5708 0 0" />
      <geometry>
        <cylinder radius="0.017" length="0.006" />
        </geometry>
      <material name="zinc_plated_hardware">
        <color rgba="0.62 0.6 0.54 1" />
        </material>
      </visual>
    <visual name="tray_spring_clip">
      <origin xyz="0.104 -0.061 -0.002" rpy="0 0 0" />
      <geometry>
        <box size="0.044 0.006 0.018" />
        </geometry>
      <material name="root_latch_orange">
        <color rgba="0.95 0.36 0.08 1" />
        </material>
      </visual>
    <collision name="tray_floor">
      <origin xyz="0.086 0 -0.037" rpy="0 0 0" />
      <geometry>
        <box size="0.155 0.11 0.008" />
        </geometry>
      </collision>
    <collision name="far_tray_lip">
      <origin xyz="0.092 0.057 -0.019" rpy="0 0 0" />
      <geometry>
        <box size="0.142 0.008 0.032" />
        </geometry>
      </collision>
    <collision name="near_tray_lip">
      <origin xyz="0.092 -0.057 -0.019" rpy="0 0 0" />
      <geometry>
        <box size="0.142 0.008 0.032" />
        </geometry>
      </collision>
    <collision name="tray_front_lip">
      <origin xyz="0.159 0 -0.019" rpy="0 0 0" />
      <geometry>
        <box size="0.012 0.112 0.032" />
        </geometry>
      </collision>
    <collision name="wrist_bridge">
      <origin xyz="0.016 0 -0.033" rpy="0 0 0" />
      <geometry>
        <box size="0.052 0.078 0.012" />
        </geometry>
      </collision>
    <collision name="near_wrist_ear">
      <origin xyz="0 -0.027 -0.002" rpy="0 0 0" />
      <geometry>
        <box size="0.06 0.01 0.056" />
        </geometry>
      </collision>
    <collision name="far_wrist_ear">
      <origin xyz="0 0.027 -0.002" rpy="0 0 0" />
      <geometry>
        <box size="0.06 0.01 0.056" />
        </geometry>
      </collision>
    <collision name="wrist_shoulder_bolt">
      <origin xyz="0 0 0" rpy="1.5708 0 0" />
      <geometry>
        <cylinder radius="0.008" length="0.128" />
        </geometry>
      </collision>
    <collision name="far_wrist_washer">
      <origin xyz="0 0.035 0" rpy="1.5708 0 0" />
      <geometry>
        <cylinder radius="0.017" length="0.006" />
        </geometry>
      </collision>
    <collision name="near_wrist_washer">
      <origin xyz="0 -0.035 0" rpy="1.5708 0 0" />
      <geometry>
        <cylinder radius="0.017" length="0.006" />
        </geometry>
      </collision>
    <collision name="tray_spring_clip">
      <origin xyz="0.104 -0.061 -0.002" rpy="0 0 0" />
      <geometry>
        <box size="0.044 0.006 0.018" />
        </geometry>
      </collision>
    </link>
  <joint name="foot_to_long" type="revolute">
    <origin xyz="0 0 0.18" rpy="0 -0.453786 0" />
    <parent link="foot" />
    <child link="long_link_0" />
    <axis xyz="0 1 0" />
    <limit effort="55" velocity="1.2" lower="-0.32" upper="0.4" />
    </joint>
  <joint name="long_to_short" type="revolute">
    <origin xyz="0.42 0 0" rpy="0 0.767945 0" />
    <parent link="long_link_0" />
    <child link="short_link_0" />
    <axis xyz="0 1 0" />
    <limit effort="40" velocity="1.4" lower="-0.38" upper="0.42" />
    </joint>
  <joint name="short_to_long" type="revolute">
    <origin xyz="0.24 0 0" rpy="0 -0.628319 0" />
    <parent link="short_link_0" />
    <child link="long_link_1" />
    <axis xyz="0 1 0" />
    <limit effort="32" velocity="1.4" lower="-0.36" upper="0.44" />
    </joint>
  <joint name="long_to_tray" type="revolute">
    <origin xyz="0.34 0 0" rpy="0 0.401426 0" />
    <parent link="long_link_1" />
    <child link="tray_bracket" />
    <axis xyz="0 1 0" />
    <limit effort="18" velocity="1.8" lower="-0.55" upper="0.62" />
    </joint>
  </robot>
