<robot name="portal_gantry">
  <link name="frame">
    <visual name="foot_0">
      <origin xyz="-1.05 0 0.03" rpy="0 0 0" />
      <geometry>
        <box size="0.42 0.44 0.06" />
        </geometry>
      <material name="dark_composite">
        <color rgba="0.05 0.055 0.06 1" />
        </material>
      </visual>
    <visual name="upright_0">
      <origin xyz="-1.05 0 0.745" rpy="0 0 0" />
      <geometry>
        <box size="0.13 0.13 1.39" />
        </geometry>
      <material name="anodized_aluminum">
        <color rgba="0.72 0.74 0.74 1" />
        </material>
      </visual>
    <visual name="top_corner_0">
      <origin xyz="-1.05 -0.015 1.405" rpy="0 0 0" />
      <geometry>
        <box size="0.24 0.2 0.06" />
        </geometry>
      <material name="anodized_aluminum">
        <color rgba="0.72 0.74 0.74 1" />
        </material>
      </visual>
    <visual name="foot_1">
      <origin xyz="1.05 0 0.03" rpy="0 0 0" />
      <geometry>
        <box size="0.42 0.44 0.06" />
        </geometry>
      <material name="dark_composite">
        <color rgba="0.05 0.055 0.06 1" />
        </material>
      </visual>
    <visual name="upright_1">
      <origin xyz="1.05 0 0.745" rpy="0 0 0" />
      <geometry>
        <box size="0.13 0.13 1.39" />
        </geometry>
      <material name="anodized_aluminum">
        <color rgba="0.72 0.74 0.74 1" />
        </material>
      </visual>
    <visual name="top_corner_1">
      <origin xyz="1.05 -0.015 1.405" rpy="0 0 0" />
      <geometry>
        <box size="0.24 0.2 0.06" />
        </geometry>
      <material name="anodized_aluminum">
        <color rgba="0.72 0.74 0.74 1" />
        </material>
      </visual>
    <visual name="top_beam">
      <origin xyz="0 0 1.5" rpy="0 0 0" />
      <geometry>
        <box size="2.36 0.16 0.14" />
        </geometry>
      <material name="anodized_aluminum">
        <color rgba="0.72 0.74 0.74 1" />
        </material>
      </visual>
    <visual name="rear_tie">
      <origin xyz="0 0.09 0.21" rpy="0 0 0" />
      <geometry>
        <box size="2.2 0.08 0.08" />
        </geometry>
      <material name="anodized_aluminum">
        <color rgba="0.72 0.74 0.74 1" />
        </material>
      </visual>
    <visual name="upper_linear_rail">
      <origin xyz="0 -0.094 1.525" rpy="0 0 0" />
      <geometry>
        <box size="1.88 0.032 0.025" />
        </geometry>
      <material name="blackened_steel">
        <color rgba="0.015 0.015 0.018 1" />
        </material>
      </visual>
    <visual name="lower_linear_rail">
      <origin xyz="0 -0.094 1.465" rpy="0 0 0" />
      <geometry>
        <box size="1.88 0.032 0.025" />
        </geometry>
      <material name="blackened_steel">
        <color rgba="0.015 0.015 0.018 1" />
        </material>
      </visual>
    <visual name="drive_screw">
      <origin xyz="0 -0.31 1.495" rpy="0 1.5708 0" />
      <geometry>
        <cylinder radius="0.014" length="1.86" />
        </geometry>
      <material name="blackened_steel">
        <color rgba="0.015 0.015 0.018 1" />
        </material>
      </visual>
    <visual name="screw_support_0">
      <origin xyz="-0.94 -0.165 1.495" rpy="0 0 0" />
      <geometry>
        <box size="0.08 0.34 0.095" />
        </geometry>
      <material name="dark_composite">
        <color rgba="0.05 0.055 0.06 1" />
        </material>
      </visual>
    <visual name="screw_support_1">
      <origin xyz="0.94 -0.165 1.495" rpy="0 0 0" />
      <geometry>
        <box size="0.08 0.34 0.095" />
        </geometry>
      <material name="dark_composite">
        <color rgba="0.05 0.055 0.06 1" />
        </material>
      </visual>
    <collision name="foot_0">
      <origin xyz="-1.05 0 0.03" rpy="0 0 0" />
      <geometry>
        <box size="0.42 0.44 0.06" />
        </geometry>
      </collision>
    <collision name="upright_0">
      <origin xyz="-1.05 0 0.745" rpy="0 0 0" />
      <geometry>
        <box size="0.13 0.13 1.39" />
        </geometry>
      </collision>
    <collision name="top_corner_0">
      <origin xyz="-1.05 -0.015 1.405" rpy="0 0 0" />
      <geometry>
        <box size="0.24 0.2 0.06" />
        </geometry>
      </collision>
    <collision name="foot_1">
      <origin xyz="1.05 0 0.03" rpy="0 0 0" />
      <geometry>
        <box size="0.42 0.44 0.06" />
        </geometry>
      </collision>
    <collision name="upright_1">
      <origin xyz="1.05 0 0.745" rpy="0 0 0" />
      <geometry>
        <box size="0.13 0.13 1.39" />
        </geometry>
      </collision>
    <collision name="top_corner_1">
      <origin xyz="1.05 -0.015 1.405" rpy="0 0 0" />
      <geometry>
        <box size="0.24 0.2 0.06" />
        </geometry>
      </collision>
    <collision name="top_beam">
      <origin xyz="0 0 1.5" rpy="0 0 0" />
      <geometry>
        <box size="2.36 0.16 0.14" />
        </geometry>
      </collision>
    <collision name="rear_tie">
      <origin xyz="0 0.09 0.21" rpy="0 0 0" />
      <geometry>
        <box size="2.2 0.08 0.08" />
        </geometry>
      </collision>
    <collision name="upper_linear_rail">
      <origin xyz="0 -0.094 1.525" rpy="0 0 0" />
      <geometry>
        <box size="1.88 0.032 0.025" />
        </geometry>
      </collision>
    <collision name="lower_linear_rail">
      <origin xyz="0 -0.094 1.465" rpy="0 0 0" />
      <geometry>
        <box size="1.88 0.032 0.025" />
        </geometry>
      </collision>
    <collision name="drive_screw">
      <origin xyz="0 -0.31 1.495" rpy="0 1.5708 0" />
      <geometry>
        <cylinder radius="0.014" length="1.86" />
        </geometry>
      </collision>
    <collision name="screw_support_0">
      <origin xyz="-0.94 -0.165 1.495" rpy="0 0 0" />
      <geometry>
        <box size="0.08 0.34 0.095" />
        </geometry>
      </collision>
    <collision name="screw_support_1">
      <origin xyz="0.94 -0.165 1.495" rpy="0 0 0" />
      <geometry>
        <box size="0.08 0.34 0.095" />
        </geometry>
      </collision>
    </link>
  <link name="carriage">
    <visual name="carriage_plate">
      <origin xyz="0 -0.033 0" rpy="0 0 0" />
      <geometry>
        <box size="0.36 0.055 0.3" />
        </geometry>
      <material name="dark_composite">
        <color rgba="0.05 0.055 0.06 1" />
        </material>
      </visual>
    <visual name="upper_bearing_0">
      <origin xyz="-0.115 0.01 0.03" rpy="0 0 0" />
      <geometry>
        <box size="0.095 0.07 0.044" />
        </geometry>
      <material name="blackened_steel">
        <color rgba="0.015 0.015 0.018 1" />
        </material>
      </visual>
    <visual name="upper_bearing_1">
      <origin xyz="0.115 0.01 0.03" rpy="0 0 0" />
      <geometry>
        <box size="0.095 0.07 0.044" />
        </geometry>
      <material name="blackened_steel">
        <color rgba="0.015 0.015 0.018 1" />
        </material>
      </visual>
    <visual name="lower_bearing_0">
      <origin xyz="-0.115 0.01 -0.03" rpy="0 0 0" />
      <geometry>
        <box size="0.095 0.07 0.044" />
        </geometry>
      <material name="blackened_steel">
        <color rgba="0.015 0.015 0.018 1" />
        </material>
      </visual>
    <visual name="lower_bearing_1">
      <origin xyz="0.115 0.01 -0.03" rpy="0 0 0" />
      <geometry>
        <box size="0.095 0.07 0.044" />
        </geometry>
      <material name="blackened_steel">
        <color rgba="0.015 0.015 0.018 1" />
        </material>
      </visual>
    <visual name="slide_backplate">
      <origin xyz="0 -0.07 -0.32" rpy="0 0 0" />
      <geometry>
        <box size="0.27 0.066 0.78" />
        </geometry>
      <material name="dark_composite">
        <color rgba="0.05 0.055 0.06 1" />
        </material>
      </visual>
    <visual name="vertical_rail_0">
      <origin xyz="-0.075 -0.116 -0.32" rpy="0 0 0" />
      <geometry>
        <box size="0.03 0.026 0.72" />
        </geometry>
      <material name="blackened_steel">
        <color rgba="0.015 0.015 0.018 1" />
        </material>
      </visual>
    <visual name="vertical_rail_1">
      <origin xyz="0.075 -0.116 -0.32" rpy="0 0 0" />
      <geometry>
        <box size="0.03 0.026 0.72" />
        </geometry>
      <material name="blackened_steel">
        <color rgba="0.015 0.015 0.018 1" />
        </material>
      </visual>
    <visual name="lower_guard">
      <origin xyz="0 -0.125 -0.7" rpy="0 0 0" />
      <geometry>
        <box size="0.28 0.03 0.055" />
        </geometry>
      <material name="safety_orange">
        <color rgba="1 0.42 0.08 1" />
        </material>
      </visual>
    <collision name="carriage_plate">
      <origin xyz="0 -0.033 0" rpy="0 0 0" />
      <geometry>
        <box size="0.36 0.055 0.3" />
        </geometry>
      </collision>
    <collision name="upper_bearing_0">
      <origin xyz="-0.115 0.01 0.03" rpy="0 0 0" />
      <geometry>
        <box size="0.095 0.07 0.044" />
        </geometry>
      </collision>
    <collision name="upper_bearing_1">
      <origin xyz="0.115 0.01 0.03" rpy="0 0 0" />
      <geometry>
        <box size="0.095 0.07 0.044" />
        </geometry>
      </collision>
    <collision name="lower_bearing_0">
      <origin xyz="-0.115 0.01 -0.03" rpy="0 0 0" />
      <geometry>
        <box size="0.095 0.07 0.044" />
        </geometry>
      </collision>
    <collision name="lower_bearing_1">
      <origin xyz="0.115 0.01 -0.03" rpy="0 0 0" />
      <geometry>
        <box size="0.095 0.07 0.044" />
        </geometry>
      </collision>
    <collision name="slide_backplate">
      <origin xyz="0 -0.07 -0.32" rpy="0 0 0" />
      <geometry>
        <box size="0.27 0.066 0.78" />
        </geometry>
      </collision>
    <collision name="vertical_rail_0">
      <origin xyz="-0.075 -0.116 -0.32" rpy="0 0 0" />
      <geometry>
        <box size="0.03 0.026 0.72" />
        </geometry>
      </collision>
    <collision name="vertical_rail_1">
      <origin xyz="0.075 -0.116 -0.32" rpy="0 0 0" />
      <geometry>
        <box size="0.03 0.026 0.72" />
        </geometry>
      </collision>
    <collision name="lower_guard">
      <origin xyz="0 -0.125 -0.7" rpy="0 0 0" />
      <geometry>
        <box size="0.28 0.03 0.055" />
        </geometry>
      </collision>
    </link>
  <link name="vertical_slide">
    <visual name="ram">
      <origin xyz="0 -0.037 -0.23" rpy="0 0 0" />
      <geometry>
        <box size="0.14 0.06 0.86" />
        </geometry>
      <material name="anodized_aluminum">
        <color rgba="0.72 0.74 0.74 1" />
        </material>
      </visual>
    <visual name="upper_shoe_0">
      <origin xyz="-0.075 -0.0015 0.11" rpy="0 0 0" />
      <geometry>
        <box size="0.086 0.045 0.072" />
        </geometry>
      <material name="blackened_steel">
        <color rgba="0.015 0.015 0.018 1" />
        </material>
      </visual>
    <visual name="upper_shoe_1">
      <origin xyz="0.075 -0.0015 0.11" rpy="0 0 0" />
      <geometry>
        <box size="0.086 0.045 0.072" />
        </geometry>
      <material name="blackened_steel">
        <color rgba="0.015 0.015 0.018 1" />
        </material>
      </visual>
    <visual name="lower_shoe_0">
      <origin xyz="-0.075 -0.0015 -0.06" rpy="0 0 0" />
      <geometry>
        <box size="0.086 0.045 0.072" />
        </geometry>
      <material name="blackened_steel">
        <color rgba="0.015 0.015 0.018 1" />
        </material>
      </visual>
    <visual name="lower_shoe_1">
      <origin xyz="0.075 -0.0015 -0.06" rpy="0 0 0" />
      <geometry>
        <box size="0.086 0.045 0.072" />
        </geometry>
      <material name="blackened_steel">
        <color rgba="0.015 0.015 0.018 1" />
        </material>
      </visual>
    <visual name="tool_plate">
      <origin xyz="0 -0.078 -0.69" rpy="0 0 0" />
      <geometry>
        <box size="0.24 0.042 0.13" />
        </geometry>
      <material name="safety_orange">
        <color rgba="1 0.42 0.08 1" />
        </material>
      </visual>
    <visual name="face_bolt_0">
      <origin xyz="-0.075 -0.101 -0.66" rpy="1.5708 0 0" />
      <geometry>
        <cylinder radius="0.012" length="0.008" />
        </geometry>
      <material name="blackened_steel">
        <color rgba="0.015 0.015 0.018 1" />
        </material>
      </visual>
    <visual name="face_bolt_1">
      <origin xyz="0.075 -0.101 -0.66" rpy="1.5708 0 0" />
      <geometry>
        <cylinder radius="0.012" length="0.008" />
        </geometry>
      <material name="blackened_steel">
        <color rgba="0.015 0.015 0.018 1" />
        </material>
      </visual>
    <visual name="face_bolt_2">
      <origin xyz="-0.075 -0.101 -0.72" rpy="1.5708 0 0" />
      <geometry>
        <cylinder radius="0.012" length="0.008" />
        </geometry>
      <material name="blackened_steel">
        <color rgba="0.015 0.015 0.018 1" />
        </material>
      </visual>
    <visual name="face_bolt_3">
      <origin xyz="0.075 -0.101 -0.72" rpy="1.5708 0 0" />
      <geometry>
        <cylinder radius="0.012" length="0.008" />
        </geometry>
      <material name="blackened_steel">
        <color rgba="0.015 0.015 0.018 1" />
        </material>
      </visual>
    <collision name="ram">
      <origin xyz="0 -0.037 -0.23" rpy="0 0 0" />
      <geometry>
        <box size="0.14 0.06 0.86" />
        </geometry>
      </collision>
    <collision name="upper_shoe_0">
      <origin xyz="-0.075 -0.0015 0.11" rpy="0 0 0" />
      <geometry>
        <box size="0.086 0.045 0.072" />
        </geometry>
      </collision>
    <collision name="upper_shoe_1">
      <origin xyz="0.075 -0.0015 0.11" rpy="0 0 0" />
      <geometry>
        <box size="0.086 0.045 0.072" />
        </geometry>
      </collision>
    <collision name="lower_shoe_0">
      <origin xyz="-0.075 -0.0015 -0.06" rpy="0 0 0" />
      <geometry>
        <box size="0.086 0.045 0.072" />
        </geometry>
      </collision>
    <collision name="lower_shoe_1">
      <origin xyz="0.075 -0.0015 -0.06" rpy="0 0 0" />
      <geometry>
        <box size="0.086 0.045 0.072" />
        </geometry>
      </collision>
    <collision name="tool_plate">
      <origin xyz="0 -0.078 -0.69" rpy="0 0 0" />
      <geometry>
        <box size="0.24 0.042 0.13" />
        </geometry>
      </collision>
    <collision name="face_bolt_0">
      <origin xyz="-0.075 -0.101 -0.66" rpy="1.5708 0 0" />
      <geometry>
        <cylinder radius="0.012" length="0.008" />
        </geometry>
      </collision>
    <collision name="face_bolt_1">
      <origin xyz="0.075 -0.101 -0.66" rpy="1.5708 0 0" />
      <geometry>
        <cylinder radius="0.012" length="0.008" />
        </geometry>
      </collision>
    <collision name="face_bolt_2">
      <origin xyz="-0.075 -0.101 -0.72" rpy="1.5708 0 0" />
      <geometry>
        <cylinder radius="0.012" length="0.008" />
        </geometry>
      </collision>
    <collision name="face_bolt_3">
      <origin xyz="0.075 -0.101 -0.72" rpy="1.5708 0 0" />
      <geometry>
        <cylinder radius="0.012" length="0.008" />
        </geometry>
      </collision>
    </link>
  <joint name="frame_to_carriage" type="prismatic">
    <origin xyz="0 -0.155 1.495" rpy="0 0 0" />
    <parent link="frame" />
    <child link="carriage" />
    <axis xyz="1 0 0" />
    <limit effort="600" velocity="0.55" lower="-0.55" upper="0.55" />
    </joint>
  <joint name="carriage_to_slide" type="prismatic">
    <origin xyz="0 -0.15 -0.295" rpy="0 0 0" />
    <parent link="carriage" />
    <child link="vertical_slide" />
    <axis xyz="0 0 -1" />
    <limit effort="450" velocity="0.35" lower="0" upper="0.32" />
    </joint>
  </robot>
