<robot name="rounded_curbside_mailbox">
  <material name="galvanized_steel">
    <color rgba="0.64 0.67 0.69 1" />
    </material>
  <material name="dark_hinge_metal">
    <color rgba="0.1 0.11 0.12 1" />
    </material>
  <material name="painted_post">
    <color rgba="0.3 0.24 0.18 1" />
    </material>
  <material name="mounting_plate">
    <color rgba="0.42 0.43 0.42 1" />
    </material>
  <material name="black_handle">
    <color rgba="0.04 0.04 0.04 1" />
    </material>
  <link name="mailbox_body">
    <visual name="ground_foot">
      <origin xyz="0 0 0.02" rpy="0 0 0" />
      <geometry>
        <box size="0.28 0.28 0.04" />
        </geometry>
      <material name="painted_post">
        <color rgba="0.3 0.24 0.18 1" />
        </material>
      </visual>
    <visual name="short_post">
      <origin xyz="0 0 0.295" rpy="0 0 0" />
      <geometry>
        <box size="0.08 0.08 0.51" />
        </geometry>
      <material name="painted_post">
        <color rgba="0.3 0.24 0.18 1" />
        </material>
      </visual>
    <visual name="mounting_plate">
      <origin xyz="-0.035 0 0.559" rpy="0 0 0" />
      <geometry>
        <box size="0.43 0.18 0.038" />
        </geometry>
      <material name="mounting_plate">
        <color rgba="0.42 0.43 0.42 1" />
        </material>
      </visual>
    <visual name="body_shell">
      <origin xyz="0 0 0.575" rpy="0 0 0" />
      <geometry>
        <mesh filename="assets/meshes/mailbox_rounded_shell.obj" />
        </geometry>
      <material name="galvanized_steel">
        <color rgba="0.64 0.67 0.69 1" />
        </material>
      </visual>
    <visual name="screw_head_0_0">
      <origin xyz="-0.17 -0.055 0.577" rpy="0 0 0" />
      <geometry>
        <cylinder radius="0.01" length="0.004" />
        </geometry>
      <material name="dark_hinge_metal">
        <color rgba="0.1 0.11 0.12 1" />
        </material>
      </visual>
    <visual name="screw_head_0_1">
      <origin xyz="-0.17 0.055 0.577" rpy="0 0 0" />
      <geometry>
        <cylinder radius="0.01" length="0.004" />
        </geometry>
      <material name="dark_hinge_metal">
        <color rgba="0.1 0.11 0.12 1" />
        </material>
      </visual>
    <visual name="screw_head_1_0">
      <origin xyz="0.08 -0.055 0.577" rpy="0 0 0" />
      <geometry>
        <cylinder radius="0.01" length="0.004" />
        </geometry>
      <material name="dark_hinge_metal">
        <color rgba="0.1 0.11 0.12 1" />
        </material>
      </visual>
    <visual name="screw_head_1_1">
      <origin xyz="0.08 0.055 0.577" rpy="0 0 0" />
      <geometry>
        <cylinder radius="0.01" length="0.004" />
        </geometry>
      <material name="dark_hinge_metal">
        <color rgba="0.1 0.11 0.12 1" />
        </material>
      </visual>
    <visual name="body_hinge_barrel_neg">
      <origin xyz="0.286 -0.086 0.563" rpy="1.5708 0 0" />
      <geometry>
        <cylinder radius="0.009" length="0.052" />
        </geometry>
      <material name="dark_hinge_metal">
        <color rgba="0.1 0.11 0.12 1" />
        </material>
      </visual>
    <visual name="body_hinge_leaf_neg">
      <origin xyz="0.286 -0.086 0.568" rpy="0 0 0" />
      <geometry>
        <box size="0.02 0.05 0.014" />
        </geometry>
      <material name="dark_hinge_metal">
        <color rgba="0.1 0.11 0.12 1" />
        </material>
      </visual>
    <visual name="body_hinge_barrel_pos">
      <origin xyz="0.286 0.086 0.563" rpy="1.5708 0 0" />
      <geometry>
        <cylinder radius="0.009" length="0.052" />
        </geometry>
      <material name="dark_hinge_metal">
        <color rgba="0.1 0.11 0.12 1" />
        </material>
      </visual>
    <visual name="body_hinge_leaf_pos">
      <origin xyz="0.286 0.086 0.568" rpy="0 0 0" />
      <geometry>
        <box size="0.02 0.05 0.014" />
        </geometry>
      <material name="dark_hinge_metal">
        <color rgba="0.1 0.11 0.12 1" />
        </material>
      </visual>
    <collision name="ground_foot">
      <origin xyz="0 0 0.02" rpy="0 0 0" />
      <geometry>
        <box size="0.28 0.28 0.04" />
        </geometry>
      </collision>
    <collision name="short_post">
      <origin xyz="0 0 0.295" rpy="0 0 0" />
      <geometry>
        <box size="0.08 0.08 0.51" />
        </geometry>
      </collision>
    <collision name="mounting_plate">
      <origin xyz="-0.035 0 0.559" rpy="0 0 0" />
      <geometry>
        <box size="0.43 0.18 0.038" />
        </geometry>
      </collision>
    <collision name="body_shell">
      <origin xyz="0 0 0.575" rpy="0 0 0" />
      <geometry>
        <mesh filename="assets/meshes/mailbox_rounded_shell.obj" />
        </geometry>
      </collision>
    <collision name="screw_head_0_0">
      <origin xyz="-0.17 -0.055 0.577" rpy="0 0 0" />
      <geometry>
        <cylinder radius="0.01" length="0.004" />
        </geometry>
      </collision>
    <collision name="screw_head_0_1">
      <origin xyz="-0.17 0.055 0.577" rpy="0 0 0" />
      <geometry>
        <cylinder radius="0.01" length="0.004" />
        </geometry>
      </collision>
    <collision name="screw_head_1_0">
      <origin xyz="0.08 -0.055 0.577" rpy="0 0 0" />
      <geometry>
        <cylinder radius="0.01" length="0.004" />
        </geometry>
      </collision>
    <collision name="screw_head_1_1">
      <origin xyz="0.08 0.055 0.577" rpy="0 0 0" />
      <geometry>
        <cylinder radius="0.01" length="0.004" />
        </geometry>
      </collision>
    <collision name="body_hinge_barrel_neg">
      <origin xyz="0.286 -0.086 0.563" rpy="1.5708 0 0" />
      <geometry>
        <cylinder radius="0.009" length="0.052" />
        </geometry>
      </collision>
    <collision name="body_hinge_leaf_neg">
      <origin xyz="0.286 -0.086 0.568" rpy="0 0 0" />
      <geometry>
        <box size="0.02 0.05 0.014" />
        </geometry>
      </collision>
    <collision name="body_hinge_barrel_pos">
      <origin xyz="0.286 0.086 0.563" rpy="1.5708 0 0" />
      <geometry>
        <cylinder radius="0.009" length="0.052" />
        </geometry>
      </collision>
    <collision name="body_hinge_leaf_pos">
      <origin xyz="0.286 0.086 0.568" rpy="0 0 0" />
      <geometry>
        <box size="0.02 0.05 0.014" />
        </geometry>
      </collision>
    </link>
  <link name="front_door">
    <visual name="door_panel">
      <geometry>
        <mesh filename="assets/meshes/mailbox_front_door.obj" />
        </geometry>
      <material name="galvanized_steel">
        <color rgba="0.64 0.67 0.69 1" />
        </material>
      </visual>
    <visual name="door_hinge_barrel">
      <origin xyz="0 0 0" rpy="1.5708 0 0" />
      <geometry>
        <cylinder radius="0.009" length="0.082" />
        </geometry>
      <material name="dark_hinge_metal">
        <color rgba="0.1 0.11 0.12 1" />
        </material>
      </visual>
    <visual name="door_hinge_leaf">
      <origin xyz="0.006 0 0.007" rpy="0 0 0" />
      <geometry>
        <box size="0.018 0.082 0.018" />
        </geometry>
      <material name="dark_hinge_metal">
        <color rgba="0.1 0.11 0.12 1" />
        </material>
      </visual>
    <visual name="handle_stem">
      <origin xyz="0.029 0 0.1092" rpy="0 1.5708 0" />
      <geometry>
        <cylinder radius="0.007" length="0.022" />
        </geometry>
      <material name="black_handle">
        <color rgba="0.04 0.04 0.04 1" />
        </material>
      </visual>
    <visual name="handle_knob">
      <origin xyz="0.046 0 0.1092" rpy="0 1.5708 0" />
      <geometry>
        <cylinder radius="0.018" length="0.012" />
        </geometry>
      <material name="black_handle">
        <color rgba="0.04 0.04 0.04 1" />
        </material>
      </visual>
    <collision name="door_panel">
      <geometry>
        <mesh filename="assets/meshes/mailbox_front_door.obj" />
        </geometry>
      </collision>
    <collision name="door_hinge_barrel">
      <origin xyz="0 0 0" rpy="1.5708 0 0" />
      <geometry>
        <cylinder radius="0.009" length="0.082" />
        </geometry>
      </collision>
    <collision name="door_hinge_leaf">
      <origin xyz="0.006 0 0.007" rpy="0 0 0" />
      <geometry>
        <box size="0.018 0.082 0.018" />
        </geometry>
      </collision>
    <collision name="handle_stem">
      <origin xyz="0.029 0 0.1092" rpy="0 1.5708 0" />
      <geometry>
        <cylinder radius="0.007" length="0.022" />
        </geometry>
      </collision>
    <collision name="handle_knob">
      <origin xyz="0.046 0 0.1092" rpy="0 1.5708 0" />
      <geometry>
        <cylinder radius="0.018" length="0.012" />
        </geometry>
      </collision>
    </link>
  <joint name="body_to_front_door" type="revolute">
    <origin xyz="0.286 0 0.563" rpy="0 0 0" />
    <parent link="mailbox_body" />
    <child link="front_door" />
    <axis xyz="0 1 0" />
    <limit effort="5" velocity="2" lower="0" upper="1.5708" />
    </joint>
  </robot>
