<robot name="aluminum_laptop_stand">
  <link name="base">
    <visual name="oval_base_plate">
      <geometry>
        <mesh filename="assets/meshes/oval_base_plate.obj" />
        </geometry>
      <material name="satin_aluminum">
        <color rgba="0.72 0.74 0.73 1" />
        </material>
      </visual>
    <visual name="pedestal_sleeve">
      <geometry>
        <mesh filename="assets/meshes/pedestal_sleeve.obj" />
        </geometry>
      <material name="satin_aluminum">
        <color rgba="0.72 0.74 0.73 1" />
        </material>
      </visual>
    <visual name="sleeve_collar">
      <origin xyz="0 0 0.023" rpy="0 0 0" />
      <geometry>
        <cylinder radius="0.052" length="0.01" />
        </geometry>
      <material name="dark_anodized_aluminum">
        <color rgba="0.3 0.31 0.31 1" />
        </material>
      </visual>
    <collision name="oval_base_plate">
      <geometry>
        <mesh filename="assets/meshes/oval_base_plate.obj" />
        </geometry>
      </collision>
    <collision name="pedestal_sleeve">
      <geometry>
        <mesh filename="assets/meshes/pedestal_sleeve.obj" />
        </geometry>
      </collision>
    <collision name="sleeve_collar">
      <origin xyz="0 0 0.023" rpy="0 0 0" />
      <geometry>
        <cylinder radius="0.052" length="0.01" />
        </geometry>
      </collision>
    </link>
  <link name="pedestal">
    <visual name="sliding_mast">
      <origin xyz="0 0 0.08" rpy="0 0 0" />
      <geometry>
        <cylinder radius="0.021" length="0.5" />
        </geometry>
      <material name="satin_aluminum">
        <color rgba="0.72 0.74 0.73 1" />
        </material>
      </visual>
    <visual name="head_collar">
      <origin xyz="0 0 0.315" rpy="0 0 0" />
      <geometry>
        <cylinder radius="0.032" length="0.04" />
        </geometry>
      <material name="dark_anodized_aluminum">
        <color rgba="0.3 0.31 0.31 1" />
        </material>
      </visual>
    <visual name="head_bridge">
      <origin xyz="0 0 0.322" rpy="0 0 0" />
      <geometry>
        <box size="0.075 0.14 0.03" />
        </geometry>
      <material name="satin_aluminum">
        <color rgba="0.72 0.74 0.73 1" />
        </material>
      </visual>
    <visual name="head_cheek_0">
      <origin xyz="0 -0.058 0.38" rpy="0 0 0" />
      <geometry>
        <box size="0.06 0.018 0.1" />
        </geometry>
      <material name="satin_aluminum">
        <color rgba="0.72 0.74 0.73 1" />
        </material>
      </visual>
    <visual name="head_cheek_1">
      <origin xyz="0 0.058 0.38" rpy="0 0 0" />
      <geometry>
        <box size="0.06 0.018 0.1" />
        </geometry>
      <material name="satin_aluminum">
        <color rgba="0.72 0.74 0.73 1" />
        </material>
      </visual>
    <visual name="hinge_pin">
      <origin xyz="0 0 0.39" rpy="1.5708 0 0" />
      <geometry>
        <cylinder radius="0.006" length="0.16" />
        </geometry>
      <material name="dark_anodized_aluminum">
        <color rgba="0.3 0.31 0.31 1" />
        </material>
      </visual>
    <collision name="sliding_mast">
      <origin xyz="0 0 0.08" rpy="0 0 0" />
      <geometry>
        <cylinder radius="0.021" length="0.5" />
        </geometry>
      </collision>
    <collision name="head_collar">
      <origin xyz="0 0 0.315" rpy="0 0 0" />
      <geometry>
        <cylinder radius="0.032" length="0.04" />
        </geometry>
      </collision>
    <collision name="head_bridge">
      <origin xyz="0 0 0.322" rpy="0 0 0" />
      <geometry>
        <box size="0.075 0.14 0.03" />
        </geometry>
      </collision>
    <collision name="head_cheek_0">
      <origin xyz="0 -0.058 0.38" rpy="0 0 0" />
      <geometry>
        <box size="0.06 0.018 0.1" />
        </geometry>
      </collision>
    <collision name="head_cheek_1">
      <origin xyz="0 0.058 0.38" rpy="0 0 0" />
      <geometry>
        <box size="0.06 0.018 0.1" />
        </geometry>
      </collision>
    <collision name="hinge_pin">
      <origin xyz="0 0 0.39" rpy="1.5708 0 0" />
      <geometry>
        <cylinder radius="0.006" length="0.16" />
        </geometry>
      </collision>
    </link>
  <link name="platform">
    <visual name="cooling_platform_plate">
      <origin xyz="0.23 0 -0.035" rpy="0 0 0" />
      <geometry>
        <mesh filename="assets/meshes/cooling_platform_plate.obj" />
        </geometry>
      <material name="satin_aluminum">
        <color rgba="0.72 0.74 0.73 1" />
        </material>
      </visual>
    <visual name="hinge_barrel">
      <origin xyz="0 0 0" rpy="1.5708 0 0" />
      <geometry>
        <cylinder radius="0.016" length="0.08" />
        </geometry>
      <material name="satin_aluminum">
        <color rgba="0.72 0.74 0.73 1" />
        </material>
      </visual>
    <visual name="barrel_strap">
      <origin xyz="0.045 0 -0.02" rpy="0 0 0" />
      <geometry>
        <box size="0.09 0.09 0.018" />
        </geometry>
      <material name="satin_aluminum">
        <color rgba="0.72 0.74 0.73 1" />
        </material>
      </visual>
    <visual name="front_lip">
      <origin xyz="0.402 0 -0.015" rpy="0 0 0" />
      <geometry>
        <box size="0.026 0.235 0.032" />
        </geometry>
      <material name="satin_aluminum">
        <color rgba="0.72 0.74 0.73 1" />
        </material>
      </visual>
    <visual name="rubber_pad_0">
      <origin xyz="0.14 -0.092 -0.0275" rpy="0 0 0" />
      <geometry>
        <box size="0.07 0.018 0.004" />
        </geometry>
      <material name="matte_black_rubber">
        <color rgba="0.015 0.014 0.013 1" />
        </material>
      </visual>
    <visual name="rubber_pad_1">
      <origin xyz="0.14 0.092 -0.0275" rpy="0 0 0" />
      <geometry>
        <box size="0.07 0.018 0.004" />
        </geometry>
      <material name="matte_black_rubber">
        <color rgba="0.015 0.014 0.013 1" />
        </material>
      </visual>
    <visual name="rubber_pad_2">
      <origin xyz="0.315 -0.092 -0.0275" rpy="0 0 0" />
      <geometry>
        <box size="0.07 0.018 0.004" />
        </geometry>
      <material name="matte_black_rubber">
        <color rgba="0.015 0.014 0.013 1" />
        </material>
      </visual>
    <visual name="rubber_pad_3">
      <origin xyz="0.315 0.092 -0.0275" rpy="0 0 0" />
      <geometry>
        <box size="0.07 0.018 0.004" />
        </geometry>
      <material name="matte_black_rubber">
        <color rgba="0.015 0.014 0.013 1" />
        </material>
      </visual>
    <collision name="cooling_platform_plate">
      <origin xyz="0.23 0 -0.035" rpy="0 0 0" />
      <geometry>
        <mesh filename="assets/meshes/cooling_platform_plate.obj" />
        </geometry>
      </collision>
    <collision name="hinge_barrel">
      <origin xyz="0 0 0" rpy="1.5708 0 0" />
      <geometry>
        <cylinder radius="0.016" length="0.08" />
        </geometry>
      </collision>
    <collision name="barrel_strap">
      <origin xyz="0.045 0 -0.02" rpy="0 0 0" />
      <geometry>
        <box size="0.09 0.09 0.018" />
        </geometry>
      </collision>
    <collision name="front_lip">
      <origin xyz="0.402 0 -0.015" rpy="0 0 0" />
      <geometry>
        <box size="0.026 0.235 0.032" />
        </geometry>
      </collision>
    <collision name="rubber_pad_0">
      <origin xyz="0.14 -0.092 -0.0275" rpy="0 0 0" />
      <geometry>
        <box size="0.07 0.018 0.004" />
        </geometry>
      </collision>
    <collision name="rubber_pad_1">
      <origin xyz="0.14 0.092 -0.0275" rpy="0 0 0" />
      <geometry>
        <box size="0.07 0.018 0.004" />
        </geometry>
      </collision>
    <collision name="rubber_pad_2">
      <origin xyz="0.315 -0.092 -0.0275" rpy="0 0 0" />
      <geometry>
        <box size="0.07 0.018 0.004" />
        </geometry>
      </collision>
    <collision name="rubber_pad_3">
      <origin xyz="0.315 0.092 -0.0275" rpy="0 0 0" />
      <geometry>
        <box size="0.07 0.018 0.004" />
        </geometry>
      </collision>
    </link>
  <joint name="base_to_pedestal" type="prismatic">
    <origin xyz="0 0 0.258" rpy="0 0 0" />
    <parent link="base" />
    <child link="pedestal" />
    <axis xyz="0 0 1" />
    <limit effort="90" velocity="0.18" lower="0" upper="0.12" />
    </joint>
  <joint name="pedestal_to_platform" type="revolute">
    <origin xyz="0 0 0.39" rpy="0 0 0" />
    <parent link="pedestal" />
    <child link="platform" />
    <axis xyz="0 -1 0" />
    <limit effort="12" velocity="1.5" lower="-0.2" upper="0.9" />
    </joint>
  </robot>
