<robot name="pedestal_offset_rotary_module">
  <link name="pedestal">
    <visual name="ground_foot">
      <origin xyz="0 0 0.03" rpy="0 0 0" />
      <geometry>
        <box size="0.9 0.42 0.06" />
        </geometry>
      <material name="dark_cast_iron">
        <color rgba="0.09 0.1 0.11 1" />
        </material>
      </visual>
    <visual name="front_rib">
      <origin xyz="0 -0.13 0.0725" rpy="0 0 0" />
      <geometry>
        <box size="0.84 0.08 0.025" />
        </geometry>
      <material name="black_oxide">
        <color rgba="0.015 0.016 0.018 1" />
        </material>
      </visual>
    <visual name="rear_rib">
      <origin xyz="0 0.13 0.0725" rpy="0 0 0" />
      <geometry>
        <box size="0.84 0.08 0.025" />
        </geometry>
      <material name="black_oxide">
        <color rgba="0.015 0.016 0.018 1" />
        </material>
      </visual>
    <visual name="lower_bearing">
      <origin xyz="0 0 0.09625" rpy="0 0 0" />
      <geometry>
        <cylinder radius="0.185" length="0.0825" />
        </geometry>
      <material name="brushed_bearing_steel">
        <color rgba="0.55 0.56 0.54 1" />
        </material>
      </visual>
    <visual name="lower_spindle_housing">
      <origin xyz="0 0 0.084" rpy="0 0 0" />
      <geometry>
        <cylinder radius="0.07" length="0.105" />
        </geometry>
      <material name="black_oxide">
        <color rgba="0.015 0.016 0.018 1" />
        </material>
      </visual>
    <visual name="side_upright">
      <origin xyz="0.46 0 0.31" rpy="0 0 0" />
      <geometry>
        <box size="0.11 0.24 0.51" />
        </geometry>
      <material name="dark_cast_iron">
        <color rgba="0.09 0.1 0.11 1" />
        </material>
      </visual>
    <visual name="upper_arm">
      <origin xyz="0.39 0 0.575" rpy="0 0 0" />
      <geometry>
        <box size="0.34 0.26 0.08" />
        </geometry>
      <material name="dark_cast_iron">
        <color rgba="0.09 0.1 0.11 1" />
        </material>
      </visual>
    <visual name="front_gusset">
      <origin xyz="0.36 -0.1275 0.35" rpy="0 0.5 0" />
      <geometry>
        <box size="0.23 0.035 0.38" />
        </geometry>
      <material name="black_oxide">
        <color rgba="0.015 0.016 0.018 1" />
        </material>
      </visual>
    <visual name="rear_gusset">
      <origin xyz="0.36 0.1275 0.35" rpy="0 0.5 0" />
      <geometry>
        <box size="0.23 0.035 0.38" />
        </geometry>
      <material name="black_oxide">
        <color rgba="0.015 0.016 0.018 1" />
        </material>
      </visual>
    <visual name="upper_bearing">
      <origin xyz="0.3 0 0.61" rpy="0 0 0" />
      <geometry>
        <cylinder radius="0.13" length="0.07" />
        </geometry>
      <material name="brushed_bearing_steel">
        <color rgba="0.55 0.56 0.54 1" />
        </material>
      </visual>
    <visual name="upper_spindle_housing">
      <origin xyz="0.3 0 0.6" rpy="0 0 0" />
      <geometry>
        <cylinder radius="0.055" length="0.09" />
        </geometry>
      <material name="black_oxide">
        <color rgba="0.015 0.016 0.018 1" />
        </material>
      </visual>
    <collision name="ground_foot">
      <origin xyz="0 0 0.03" rpy="0 0 0" />
      <geometry>
        <box size="0.9 0.42 0.06" />
        </geometry>
      </collision>
    <collision name="front_rib">
      <origin xyz="0 -0.13 0.0725" rpy="0 0 0" />
      <geometry>
        <box size="0.84 0.08 0.025" />
        </geometry>
      </collision>
    <collision name="rear_rib">
      <origin xyz="0 0.13 0.0725" rpy="0 0 0" />
      <geometry>
        <box size="0.84 0.08 0.025" />
        </geometry>
      </collision>
    <collision name="lower_bearing">
      <origin xyz="0 0 0.09625" rpy="0 0 0" />
      <geometry>
        <cylinder radius="0.185" length="0.0825" />
        </geometry>
      </collision>
    <collision name="lower_spindle_housing">
      <origin xyz="0 0 0.084" rpy="0 0 0" />
      <geometry>
        <cylinder radius="0.07" length="0.105" />
        </geometry>
      </collision>
    <collision name="side_upright">
      <origin xyz="0.46 0 0.31" rpy="0 0 0" />
      <geometry>
        <box size="0.11 0.24 0.51" />
        </geometry>
      </collision>
    <collision name="upper_arm">
      <origin xyz="0.39 0 0.575" rpy="0 0 0" />
      <geometry>
        <box size="0.34 0.26 0.08" />
        </geometry>
      </collision>
    <collision name="front_gusset">
      <origin xyz="0.36 -0.1275 0.35" rpy="0 0.5 0" />
      <geometry>
        <box size="0.23 0.035 0.38" />
        </geometry>
      </collision>
    <collision name="rear_gusset">
      <origin xyz="0.36 0.1275 0.35" rpy="0 0.5 0" />
      <geometry>
        <box size="0.23 0.035 0.38" />
        </geometry>
      </collision>
    <collision name="upper_bearing">
      <origin xyz="0.3 0 0.61" rpy="0 0 0" />
      <geometry>
        <cylinder radius="0.13" length="0.07" />
        </geometry>
      </collision>
    <collision name="upper_spindle_housing">
      <origin xyz="0.3 0 0.6" rpy="0 0 0" />
      <geometry>
        <cylinder radius="0.055" length="0.09" />
        </geometry>
      </collision>
    </link>
  <link name="lower_turntable">
    <visual name="turntable_disk">
      <geometry>
        <cylinder radius="0.23" length="0.055" />
        </geometry>
      <material name="machined_faceplate">
        <color rgba="0.72 0.72 0.68 1" />
        </material>
      </visual>
    <visual name="top_register">
      <origin xyz="0 0 0.0365" rpy="0 0 0" />
      <geometry>
        <cylinder radius="0.185" length="0.018" />
        </geometry>
      <material name="brushed_bearing_steel">
        <color rgba="0.55 0.56 0.54 1" />
        </material>
      </visual>
    <visual name="center_cap">
      <origin xyz="0 0 0.058" rpy="0 0 0" />
      <geometry>
        <cylinder radius="0.05" length="0.025" />
        </geometry>
      <material name="black_oxide">
        <color rgba="0.015 0.016 0.018 1" />
        </material>
      </visual>
    <visual name="index_bar">
      <origin xyz="0.075 0 0.0515" rpy="0 0 0" />
      <geometry>
        <box size="0.17 0.024 0.012" />
        </geometry>
      <material name="blue_index_mark">
        <color rgba="0.05 0.16 0.45 1" />
        </material>
      </visual>
    <visual name="bolt_0">
      <origin xyz="0.115 0.115 0.0495" rpy="0 0 0" />
      <geometry>
        <cylinder radius="0.014" length="0.008" />
        </geometry>
      <material name="black_oxide">
        <color rgba="0.015 0.016 0.018 1" />
        </material>
      </visual>
    <visual name="bolt_1">
      <origin xyz="-0.115 0.115 0.0495" rpy="0 0 0" />
      <geometry>
        <cylinder radius="0.014" length="0.008" />
        </geometry>
      <material name="black_oxide">
        <color rgba="0.015 0.016 0.018 1" />
        </material>
      </visual>
    <visual name="bolt_2">
      <origin xyz="-0.115 -0.115 0.0495" rpy="0 0 0" />
      <geometry>
        <cylinder radius="0.014" length="0.008" />
        </geometry>
      <material name="black_oxide">
        <color rgba="0.015 0.016 0.018 1" />
        </material>
      </visual>
    <visual name="bolt_3">
      <origin xyz="0.115 -0.115 0.0495" rpy="0 0 0" />
      <geometry>
        <cylinder radius="0.014" length="0.008" />
        </geometry>
      <material name="black_oxide">
        <color rgba="0.015 0.016 0.018 1" />
        </material>
      </visual>
    <collision name="turntable_disk">
      <geometry>
        <cylinder radius="0.23" length="0.055" />
        </geometry>
      </collision>
    <collision name="top_register">
      <origin xyz="0 0 0.0365" rpy="0 0 0" />
      <geometry>
        <cylinder radius="0.185" length="0.018" />
        </geometry>
      </collision>
    <collision name="center_cap">
      <origin xyz="0 0 0.058" rpy="0 0 0" />
      <geometry>
        <cylinder radius="0.05" length="0.025" />
        </geometry>
      </collision>
    <collision name="index_bar">
      <origin xyz="0.075 0 0.0515" rpy="0 0 0" />
      <geometry>
        <box size="0.17 0.024 0.012" />
        </geometry>
      </collision>
    <collision name="bolt_0">
      <origin xyz="0.115 0.115 0.0495" rpy="0 0 0" />
      <geometry>
        <cylinder radius="0.014" length="0.008" />
        </geometry>
      </collision>
    <collision name="bolt_1">
      <origin xyz="-0.115 0.115 0.0495" rpy="0 0 0" />
      <geometry>
        <cylinder radius="0.014" length="0.008" />
        </geometry>
      </collision>
    <collision name="bolt_2">
      <origin xyz="-0.115 -0.115 0.0495" rpy="0 0 0" />
      <geometry>
        <cylinder radius="0.014" length="0.008" />
        </geometry>
      </collision>
    <collision name="bolt_3">
      <origin xyz="0.115 -0.115 0.0495" rpy="0 0 0" />
      <geometry>
        <cylinder radius="0.014" length="0.008" />
        </geometry>
      </collision>
    </link>
  <link name="upper_faceplate">
    <visual name="faceplate_disk">
      <geometry>
        <cylinder radius="0.15" length="0.065" />
        </geometry>
      <material name="machined_faceplate">
        <color rgba="0.72 0.72 0.68 1" />
        </material>
      </visual>
    <visual name="raised_register">
      <origin xyz="0 0 0.0405" rpy="0 0 0" />
      <geometry>
        <cylinder radius="0.108" length="0.016" />
        </geometry>
      <material name="brushed_bearing_steel">
        <color rgba="0.55 0.56 0.54 1" />
        </material>
      </visual>
    <visual name="face_cap">
      <origin xyz="0 0 0.0605" rpy="0 0 0" />
      <geometry>
        <cylinder radius="0.038" length="0.024" />
        </geometry>
      <material name="black_oxide">
        <color rgba="0.015 0.016 0.018 1" />
        </material>
      </visual>
    <visual name="index_tab">
      <origin xyz="0.048 0 0.0535" rpy="0 0 0" />
      <geometry>
        <box size="0.105 0.02 0.01" />
        </geometry>
      <material name="blue_index_mark">
        <color rgba="0.05 0.16 0.45 1" />
        </material>
      </visual>
    <visual name="face_bolt_0">
      <origin xyz="0.074 0.074 0.052" rpy="0 0 0" />
      <geometry>
        <cylinder radius="0.011" length="0.007" />
        </geometry>
      <material name="black_oxide">
        <color rgba="0.015 0.016 0.018 1" />
        </material>
      </visual>
    <visual name="face_bolt_1">
      <origin xyz="-0.074 0.074 0.052" rpy="0 0 0" />
      <geometry>
        <cylinder radius="0.011" length="0.007" />
        </geometry>
      <material name="black_oxide">
        <color rgba="0.015 0.016 0.018 1" />
        </material>
      </visual>
    <visual name="face_bolt_2">
      <origin xyz="-0.074 -0.074 0.052" rpy="0 0 0" />
      <geometry>
        <cylinder radius="0.011" length="0.007" />
        </geometry>
      <material name="black_oxide">
        <color rgba="0.015 0.016 0.018 1" />
        </material>
      </visual>
    <visual name="face_bolt_3">
      <origin xyz="0.074 -0.074 0.052" rpy="0 0 0" />
      <geometry>
        <cylinder radius="0.011" length="0.007" />
        </geometry>
      <material name="black_oxide">
        <color rgba="0.015 0.016 0.018 1" />
        </material>
      </visual>
    <collision name="faceplate_disk">
      <geometry>
        <cylinder radius="0.15" length="0.065" />
        </geometry>
      </collision>
    <collision name="raised_register">
      <origin xyz="0 0 0.0405" rpy="0 0 0" />
      <geometry>
        <cylinder radius="0.108" length="0.016" />
        </geometry>
      </collision>
    <collision name="face_cap">
      <origin xyz="0 0 0.0605" rpy="0 0 0" />
      <geometry>
        <cylinder radius="0.038" length="0.024" />
        </geometry>
      </collision>
    <collision name="index_tab">
      <origin xyz="0.048 0 0.0535" rpy="0 0 0" />
      <geometry>
        <box size="0.105 0.02 0.01" />
        </geometry>
      </collision>
    <collision name="face_bolt_0">
      <origin xyz="0.074 0.074 0.052" rpy="0 0 0" />
      <geometry>
        <cylinder radius="0.011" length="0.007" />
        </geometry>
      </collision>
    <collision name="face_bolt_1">
      <origin xyz="-0.074 0.074 0.052" rpy="0 0 0" />
      <geometry>
        <cylinder radius="0.011" length="0.007" />
        </geometry>
      </collision>
    <collision name="face_bolt_2">
      <origin xyz="-0.074 -0.074 0.052" rpy="0 0 0" />
      <geometry>
        <cylinder radius="0.011" length="0.007" />
        </geometry>
      </collision>
    <collision name="face_bolt_3">
      <origin xyz="0.074 -0.074 0.052" rpy="0 0 0" />
      <geometry>
        <cylinder radius="0.011" length="0.007" />
        </geometry>
      </collision>
    </link>
  <joint name="lower_rotation" type="revolute">
    <origin xyz="0 0 0.165" rpy="0 0 0" />
    <parent link="pedestal" />
    <child link="lower_turntable" />
    <axis xyz="0 0 1" />
    <limit effort="40" velocity="4" lower="-3.14159" upper="3.14159" />
    </joint>
  <joint name="upper_rotation" type="revolute">
    <origin xyz="0.3 0 0.6775" rpy="0 0 0" />
    <parent link="pedestal" />
    <child link="upper_faceplate" />
    <axis xyz="0 0 1" />
    <limit effort="20" velocity="5" lower="-3.14159" upper="3.14159" />
    </joint>
  </robot>
