<robot name="backplate_monitor_arm">
  <link name="backplate">
    <visual name="wall_plate">
      <origin xyz="-0.015 0 0.17" rpy="0 0 0" />
      <geometry>
        <box size="0.03 0.24 0.34" />
        </geometry>
      <material name="satin_graphite">
        <color rgba="0.06 0.065 0.07 1" />
        </material>
      </visual>
    <visual name="pivot_standoff">
      <origin xyz="0.0325 0 0.18" rpy="0 0 0" />
      <geometry>
        <box size="0.065 0.1 0.14" />
        </geometry>
      <material name="matte_black">
        <color rgba="0.005 0.005 0.006 1" />
        </material>
      </visual>
    <visual name="shoulder_pin">
      <origin xyz="0.09 0 0.18" rpy="0 1.5708 0" />
      <geometry>
        <cylinder radius="0.014" length="0.05" />
        </geometry>
      <material name="brushed_aluminum">
        <color rgba="0.62 0.64 0.62 1" />
        </material>
      </visual>
    <visual name="screw_lower_a">
      <origin xyz="0.003 -0.072 0.095" rpy="0 1.5708 0" />
      <geometry>
        <cylinder radius="0.012" length="0.006" />
        </geometry>
      <material name="blackened_screw">
        <color rgba="0.01 0.01 0.012 1" />
        </material>
      </visual>
    <visual name="screw_upper_a">
      <origin xyz="0.003 -0.072 0.265" rpy="0 1.5708 0" />
      <geometry>
        <cylinder radius="0.012" length="0.006" />
        </geometry>
      <material name="blackened_screw">
        <color rgba="0.01 0.01 0.012 1" />
        </material>
      </visual>
    <visual name="screw_lower_b">
      <origin xyz="0.003 0.072 0.095" rpy="0 1.5708 0" />
      <geometry>
        <cylinder radius="0.012" length="0.006" />
        </geometry>
      <material name="blackened_screw">
        <color rgba="0.01 0.01 0.012 1" />
        </material>
      </visual>
    <visual name="screw_upper_b">
      <origin xyz="0.003 0.072 0.265" rpy="0 1.5708 0" />
      <geometry>
        <cylinder radius="0.012" length="0.006" />
        </geometry>
      <material name="blackened_screw">
        <color rgba="0.01 0.01 0.012 1" />
        </material>
      </visual>
    <visual name="bottom_pad">
      <origin xyz="-0.01 0 0.012" rpy="0 0 0" />
      <geometry>
        <box size="0.02 0.18 0.018" />
        </geometry>
      <material name="dark_rubber">
        <color rgba="0.015 0.014 0.013 1" />
        </material>
      </visual>
    <collision name="wall_plate">
      <origin xyz="-0.015 0 0.17" rpy="0 0 0" />
      <geometry>
        <box size="0.03 0.24 0.34" />
        </geometry>
      </collision>
    <collision name="pivot_standoff">
      <origin xyz="0.0325 0 0.18" rpy="0 0 0" />
      <geometry>
        <box size="0.065 0.1 0.14" />
        </geometry>
      </collision>
    <collision name="shoulder_pin">
      <origin xyz="0.09 0 0.18" rpy="0 1.5708 0" />
      <geometry>
        <cylinder radius="0.014" length="0.05" />
        </geometry>
      </collision>
    <collision name="screw_lower_a">
      <origin xyz="0.003 -0.072 0.095" rpy="0 1.5708 0" />
      <geometry>
        <cylinder radius="0.012" length="0.006" />
        </geometry>
      </collision>
    <collision name="screw_upper_a">
      <origin xyz="0.003 -0.072 0.265" rpy="0 1.5708 0" />
      <geometry>
        <cylinder radius="0.012" length="0.006" />
        </geometry>
      </collision>
    <collision name="screw_lower_b">
      <origin xyz="0.003 0.072 0.095" rpy="0 1.5708 0" />
      <geometry>
        <cylinder radius="0.012" length="0.006" />
        </geometry>
      </collision>
    <collision name="screw_upper_b">
      <origin xyz="0.003 0.072 0.265" rpy="0 1.5708 0" />
      <geometry>
        <cylinder radius="0.012" length="0.006" />
        </geometry>
      </collision>
    <collision name="bottom_pad">
      <origin xyz="-0.01 0 0.012" rpy="0 0 0" />
      <geometry>
        <box size="0.02 0.18 0.018" />
        </geometry>
      </collision>
    </link>
  <link name="shoulder_link">
    <visual name="root_hub">
      <geometry>
        <cylinder radius="0.043" length="0.07" />
        </geometry>
      <material name="matte_black">
        <color rgba="0.005 0.005 0.006 1" />
        </material>
      </visual>
    <visual name="end_hub">
      <origin xyz="0.36 0 0" rpy="0 0 0" />
      <geometry>
        <cylinder radius="0.043" length="0.07" />
        </geometry>
      <material name="matte_black">
        <color rgba="0.005 0.005 0.006 1" />
        </material>
      </visual>
    <visual name="rail_a">
      <origin xyz="0.18 -0.036 0" rpy="0 0 0" />
      <geometry>
        <box size="0.276 0.018 0.026" />
        </geometry>
      <material name="brushed_aluminum">
        <color rgba="0.62 0.64 0.62 1" />
        </material>
      </visual>
    <visual name="rail_b">
      <origin xyz="0.18 0.036 0" rpy="0 0 0" />
      <geometry>
        <box size="0.276 0.018 0.026" />
        </geometry>
      <material name="brushed_aluminum">
        <color rgba="0.62 0.64 0.62 1" />
        </material>
      </visual>
    <visual name="cable_channel">
      <origin xyz="0.174 0 -0.026" rpy="0 0 0" />
      <geometry>
        <box size="0.288 0.035 0.018" />
        </geometry>
      <material name="dark_rubber">
        <color rgba="0.015 0.014 0.013 1" />
        </material>
      </visual>
    <visual name="rail_clamp">
      <origin xyz="0.18 0 -0.012" rpy="0 0 0" />
      <geometry>
        <box size="0.035 0.09 0.03" />
        </geometry>
      <material name="matte_black">
        <color rgba="0.005 0.005 0.006 1" />
        </material>
      </visual>
    <collision name="root_hub">
      <geometry>
        <cylinder radius="0.043" length="0.07" />
        </geometry>
      </collision>
    <collision name="end_hub">
      <origin xyz="0.36 0 0" rpy="0 0 0" />
      <geometry>
        <cylinder radius="0.043" length="0.07" />
        </geometry>
      </collision>
    <collision name="rail_a">
      <origin xyz="0.18 -0.036 0" rpy="0 0 0" />
      <geometry>
        <box size="0.276 0.018 0.026" />
        </geometry>
      </collision>
    <collision name="rail_b">
      <origin xyz="0.18 0.036 0" rpy="0 0 0" />
      <geometry>
        <box size="0.276 0.018 0.026" />
        </geometry>
      </collision>
    <collision name="cable_channel">
      <origin xyz="0.174 0 -0.026" rpy="0 0 0" />
      <geometry>
        <box size="0.288 0.035 0.018" />
        </geometry>
      </collision>
    <collision name="rail_clamp">
      <origin xyz="0.18 0 -0.012" rpy="0 0 0" />
      <geometry>
        <box size="0.035 0.09 0.03" />
        </geometry>
      </collision>
    </link>
  <link name="elbow_link">
    <visual name="root_hub">
      <geometry>
        <cylinder radius="0.036" length="0.12" />
        </geometry>
      <material name="matte_black">
        <color rgba="0.005 0.005 0.006 1" />
        </material>
      </visual>
    <visual name="end_hub">
      <origin xyz="0.32 0 0" rpy="0 0 0" />
      <geometry>
        <cylinder radius="0.036" length="0.12" />
        </geometry>
      <material name="matte_black">
        <color rgba="0.005 0.005 0.006 1" />
        </material>
      </visual>
    <visual name="rail_a">
      <origin xyz="0.162 -0.03 0.055" rpy="0 0 0" />
      <geometry>
        <box size="0.256 0.016 0.024" />
        </geometry>
      <material name="brushed_aluminum">
        <color rgba="0.62 0.64 0.62 1" />
        </material>
      </visual>
    <visual name="rail_b">
      <origin xyz="0.162 0.03 0.055" rpy="0 0 0" />
      <geometry>
        <box size="0.256 0.016 0.024" />
        </geometry>
      <material name="brushed_aluminum">
        <color rgba="0.62 0.64 0.62 1" />
        </material>
      </visual>
    <visual name="cable_channel">
      <origin xyz="0.162 0 0.055" rpy="0 0 0" />
      <geometry>
        <box size="0.256 0.082 0.014" />
        </geometry>
      <material name="dark_rubber">
        <color rgba="0.015 0.014 0.013 1" />
        </material>
      </visual>
    <collision name="root_hub">
      <geometry>
        <cylinder radius="0.036" length="0.12" />
        </geometry>
      </collision>
    <collision name="end_hub">
      <origin xyz="0.32 0 0" rpy="0 0 0" />
      <geometry>
        <cylinder radius="0.036" length="0.12" />
        </geometry>
      </collision>
    <collision name="rail_a">
      <origin xyz="0.162 -0.03 0.055" rpy="0 0 0" />
      <geometry>
        <box size="0.256 0.016 0.024" />
        </geometry>
      </collision>
    <collision name="rail_b">
      <origin xyz="0.162 0.03 0.055" rpy="0 0 0" />
      <geometry>
        <box size="0.256 0.016 0.024" />
        </geometry>
      </collision>
    <collision name="cable_channel">
      <origin xyz="0.162 0 0.055" rpy="0 0 0" />
      <geometry>
        <box size="0.256 0.082 0.014" />
        </geometry>
      </collision>
    </link>
  <link name="swivel">
    <visual name="swivel_post">
      <geometry>
        <cylinder radius="0.03" length="0.17" />
        </geometry>
      <material name="matte_black">
        <color rgba="0.005 0.005 0.006 1" />
        </material>
      </visual>
    <visual name="lower_neck">
      <origin xyz="0.035 0 -0.08" rpy="0 0 0" />
      <geometry>
        <box size="0.07 0.05 0.02" />
        </geometry>
      <material name="matte_black">
        <color rgba="0.005 0.005 0.006 1" />
        </material>
      </visual>
    <visual name="yoke_bridge">
      <origin xyz="0.075 0 -0.08" rpy="0 0 0" />
      <geometry>
        <box size="0.035 0.1 0.02" />
        </geometry>
      <material name="matte_black">
        <color rgba="0.005 0.005 0.006 1" />
        </material>
      </visual>
    <visual name="yoke_cheek_a">
      <origin xyz="0.1 -0.048 0" rpy="0 0 0" />
      <geometry>
        <box size="0.035 0.014 0.17" />
        </geometry>
      <material name="matte_black">
        <color rgba="0.005 0.005 0.006 1" />
        </material>
      </visual>
    <visual name="yoke_cheek_b">
      <origin xyz="0.1 0.048 0" rpy="0 0 0" />
      <geometry>
        <box size="0.035 0.014 0.17" />
        </geometry>
      <material name="matte_black">
        <color rgba="0.005 0.005 0.006 1" />
        </material>
      </visual>
    <visual name="tilt_pin">
      <origin xyz="0.1 0 0" rpy="1.5708 0 0" />
      <geometry>
        <cylinder radius="0.011" length="0.12" />
        </geometry>
      <material name="brushed_aluminum">
        <color rgba="0.62 0.64 0.62 1" />
        </material>
      </visual>
    <collision name="swivel_post">
      <geometry>
        <cylinder radius="0.03" length="0.17" />
        </geometry>
      </collision>
    <collision name="lower_neck">
      <origin xyz="0.035 0 -0.08" rpy="0 0 0" />
      <geometry>
        <box size="0.07 0.05 0.02" />
        </geometry>
      </collision>
    <collision name="yoke_bridge">
      <origin xyz="0.075 0 -0.08" rpy="0 0 0" />
      <geometry>
        <box size="0.035 0.1 0.02" />
        </geometry>
      </collision>
    <collision name="yoke_cheek_a">
      <origin xyz="0.1 -0.048 0" rpy="0 0 0" />
      <geometry>
        <box size="0.035 0.014 0.17" />
        </geometry>
      </collision>
    <collision name="yoke_cheek_b">
      <origin xyz="0.1 0.048 0" rpy="0 0 0" />
      <geometry>
        <box size="0.035 0.014 0.17" />
        </geometry>
      </collision>
    <collision name="tilt_pin">
      <origin xyz="0.1 0 0" rpy="1.5708 0 0" />
      <geometry>
        <cylinder radius="0.011" length="0.12" />
        </geometry>
      </collision>
    </link>
  <link name="mount_head">
    <visual name="tilt_lug">
      <origin xyz="0 0 0" rpy="1.5708 0 0" />
      <geometry>
        <cylinder radius="0.025" length="0.06" />
        </geometry>
      <material name="matte_black">
        <color rgba="0.005 0.005 0.006 1" />
        </material>
      </visual>
    <visual name="hinge_block">
      <origin xyz="0.035 0 0" rpy="0 0 0" />
      <geometry>
        <box size="0.045 0.06 0.045" />
        </geometry>
      <material name="matte_black">
        <color rgba="0.005 0.005 0.006 1" />
        </material>
      </visual>
    <visual name="face_plate">
      <origin xyz="0.066 0 0" rpy="0 0 0" />
      <geometry>
        <box size="0.018 0.145 0.12" />
        </geometry>
      <material name="satin_graphite">
        <color rgba="0.06 0.065 0.07 1" />
        </material>
      </visual>
    <visual name="raised_boss">
      <origin xyz="0.0795 0 0" rpy="0 0 0" />
      <geometry>
        <box size="0.01 0.084 0.06" />
        </geometry>
      <material name="matte_black">
        <color rgba="0.005 0.005 0.006 1" />
        </material>
      </visual>
    <visual name="vesa_socket_lower_a">
      <origin xyz="0.077 -0.05 -0.035" rpy="0 1.5708 0" />
      <geometry>
        <cylinder radius="0.0065" length="0.006" />
        </geometry>
      <material name="blackened_screw">
        <color rgba="0.01 0.01 0.012 1" />
        </material>
      </visual>
    <visual name="vesa_socket_upper_a">
      <origin xyz="0.077 -0.05 0.035" rpy="0 1.5708 0" />
      <geometry>
        <cylinder radius="0.0065" length="0.006" />
        </geometry>
      <material name="blackened_screw">
        <color rgba="0.01 0.01 0.012 1" />
        </material>
      </visual>
    <visual name="vesa_socket_lower_b">
      <origin xyz="0.077 0.05 -0.035" rpy="0 1.5708 0" />
      <geometry>
        <cylinder radius="0.0065" length="0.006" />
        </geometry>
      <material name="blackened_screw">
        <color rgba="0.01 0.01 0.012 1" />
        </material>
      </visual>
    <visual name="vesa_socket_upper_b">
      <origin xyz="0.077 0.05 0.035" rpy="0 1.5708 0" />
      <geometry>
        <cylinder radius="0.0065" length="0.006" />
        </geometry>
      <material name="blackened_screw">
        <color rgba="0.01 0.01 0.012 1" />
        </material>
      </visual>
    <collision name="tilt_lug">
      <origin xyz="0 0 0" rpy="1.5708 0 0" />
      <geometry>
        <cylinder radius="0.025" length="0.06" />
        </geometry>
      </collision>
    <collision name="hinge_block">
      <origin xyz="0.035 0 0" rpy="0 0 0" />
      <geometry>
        <box size="0.045 0.06 0.045" />
        </geometry>
      </collision>
    <collision name="face_plate">
      <origin xyz="0.066 0 0" rpy="0 0 0" />
      <geometry>
        <box size="0.018 0.145 0.12" />
        </geometry>
      </collision>
    <collision name="raised_boss">
      <origin xyz="0.0795 0 0" rpy="0 0 0" />
      <geometry>
        <box size="0.01 0.084 0.06" />
        </geometry>
      </collision>
    <collision name="vesa_socket_lower_a">
      <origin xyz="0.077 -0.05 -0.035" rpy="0 1.5708 0" />
      <geometry>
        <cylinder radius="0.0065" length="0.006" />
        </geometry>
      </collision>
    <collision name="vesa_socket_upper_a">
      <origin xyz="0.077 -0.05 0.035" rpy="0 1.5708 0" />
      <geometry>
        <cylinder radius="0.0065" length="0.006" />
        </geometry>
      </collision>
    <collision name="vesa_socket_lower_b">
      <origin xyz="0.077 0.05 -0.035" rpy="0 1.5708 0" />
      <geometry>
        <cylinder radius="0.0065" length="0.006" />
        </geometry>
      </collision>
    <collision name="vesa_socket_upper_b">
      <origin xyz="0.077 0.05 0.035" rpy="0 1.5708 0" />
      <geometry>
        <cylinder radius="0.0065" length="0.006" />
        </geometry>
      </collision>
    </link>
  <joint name="backplate_to_shoulder" type="revolute">
    <origin xyz="0.115 0 0.18" rpy="0 0 0" />
    <parent link="backplate" />
    <child link="shoulder_link" />
    <axis xyz="0 0 1" />
    <limit effort="45" velocity="1.8" lower="-1.75" upper="1.75" />
    </joint>
  <joint name="shoulder_to_elbow" type="revolute">
    <origin xyz="0.36 0 0" rpy="0 0 0" />
    <parent link="shoulder_link" />
    <child link="elbow_link" />
    <axis xyz="0 0 1" />
    <limit effort="35" velocity="2" lower="-2.35" upper="2.35" />
    </joint>
  <joint name="elbow_to_swivel" type="revolute">
    <origin xyz="0.32 0 0" rpy="0 0 0" />
    <parent link="elbow_link" />
    <child link="swivel" />
    <axis xyz="0 0 1" />
    <limit effort="14" velocity="2.5" lower="-3.14159" upper="3.14159" />
    </joint>
  <joint name="swivel_to_head" type="revolute">
    <origin xyz="0.1 0 0" rpy="0 0 0" />
    <parent link="swivel" />
    <child link="mount_head" />
    <axis xyz="0 1 0" />
    <limit effort="12" velocity="1.6" lower="-0.55" upper="0.55" />
    </joint>
  </robot>
