<robot name="field_service_wind_turbine">
  <material name="galvanized_steel">
    <color rgba="0.5 0.54 0.56 1" />
    </material>
  <material name="dark_steel">
    <color rgba="0.12 0.13 0.14 1" />
    </material>
  <material name="service_yellow">
    <color rgba="0.95 0.72 0.08 1" />
    </material>
  <material name="weathered_white">
    <color rgba="0.82 0.84 0.8 1" />
    </material>
  <material name="blade_white">
    <color rgba="0.91 0.92 0.88 1" />
    </material>
  <material name="wear_orange">
    <color rgba="0.95 0.28 0.08 1" />
    </material>
  <material name="black_rubber">
    <color rgba="0.03 0.035 0.04 1" />
    </material>
  <link name="tower">
    <visual name="base_plate">
      <origin xyz="0 0 0.05" rpy="0 0 0" />
      <geometry>
        <box size="1.2 1.2 0.1" />
        </geometry>
      <material name="dark_steel">
        <color rgba="0.12 0.13 0.14 1" />
        </material>
      </visual>
    <visual name="tower_tube">
      <origin xyz="0 0 2.65" rpy="0 0 0" />
      <geometry>
        <cylinder radius="0.22" length="5.2" />
        </geometry>
      <material name="galvanized_steel">
        <color rgba="0.5 0.54 0.56 1" />
        </material>
      </visual>
    <visual name="lower_yaw_bearing">
      <origin xyz="0 0 5.31" rpy="0 0 0" />
      <geometry>
        <cylinder radius="0.33" length="0.12" />
        </geometry>
      <material name="dark_steel">
        <color rgba="0.12 0.13 0.14 1" />
        </material>
      </visual>
    <visual name="service_collar">
      <origin xyz="0 0 5.33" rpy="0 0 0" />
      <geometry>
        <cylinder radius="0.46" length="0.08" />
        </geometry>
      <material name="service_yellow">
        <color rgba="0.95 0.72 0.08 1" />
        </material>
      </visual>
    <visual name="anchor_bolt_0">
      <origin xyz="-0.42 -0.42 0.115" rpy="0 0 0" />
      <geometry>
        <cylinder radius="0.075" length="0.035" />
        </geometry>
      <material name="dark_steel">
        <color rgba="0.12 0.13 0.14 1" />
        </material>
      </visual>
    <visual name="anchor_bolt_1">
      <origin xyz="0.42 -0.42 0.115" rpy="0 0 0" />
      <geometry>
        <cylinder radius="0.075" length="0.035" />
        </geometry>
      <material name="dark_steel">
        <color rgba="0.12 0.13 0.14 1" />
        </material>
      </visual>
    <visual name="anchor_bolt_2">
      <origin xyz="-0.42 0.42 0.115" rpy="0 0 0" />
      <geometry>
        <cylinder radius="0.075" length="0.035" />
        </geometry>
      <material name="dark_steel">
        <color rgba="0.12 0.13 0.14 1" />
        </material>
      </visual>
    <visual name="anchor_bolt_3">
      <origin xyz="0.42 0.42 0.115" rpy="0 0 0" />
      <geometry>
        <cylinder radius="0.075" length="0.035" />
        </geometry>
      <material name="dark_steel">
        <color rgba="0.12 0.13 0.14 1" />
        </material>
      </visual>
    <visual name="ladder_rail_-0.16">
      <origin xyz="-0.16 -0.48 2.75" rpy="0 0 0" />
      <geometry>
        <cylinder radius="0.022" length="4.15" />
        </geometry>
      <material name="galvanized_steel">
        <color rgba="0.5 0.54 0.56 1" />
        </material>
      </visual>
    <visual name="ladder_rail_+0.16">
      <origin xyz="0.16 -0.48 2.75" rpy="0 0 0" />
      <geometry>
        <cylinder radius="0.022" length="4.15" />
        </geometry>
      <material name="galvanized_steel">
        <color rgba="0.5 0.54 0.56 1" />
        </material>
      </visual>
    <visual name="ladder_rung_0">
      <origin xyz="0 -0.48 0.82" rpy="0 1.5708 0" />
      <geometry>
        <cylinder radius="0.018" length="0.39" />
        </geometry>
      <material name="galvanized_steel">
        <color rgba="0.5 0.54 0.56 1" />
        </material>
      </visual>
    <visual name="ladder_rung_1">
      <origin xyz="0 -0.48 1.35" rpy="0 1.5708 0" />
      <geometry>
        <cylinder radius="0.018" length="0.39" />
        </geometry>
      <material name="galvanized_steel">
        <color rgba="0.5 0.54 0.56 1" />
        </material>
      </visual>
    <visual name="ladder_rung_2">
      <origin xyz="0 -0.48 1.88" rpy="0 1.5708 0" />
      <geometry>
        <cylinder radius="0.018" length="0.39" />
        </geometry>
      <material name="galvanized_steel">
        <color rgba="0.5 0.54 0.56 1" />
        </material>
      </visual>
    <visual name="ladder_rung_3">
      <origin xyz="0 -0.48 2.41" rpy="0 1.5708 0" />
      <geometry>
        <cylinder radius="0.018" length="0.39" />
        </geometry>
      <material name="galvanized_steel">
        <color rgba="0.5 0.54 0.56 1" />
        </material>
      </visual>
    <visual name="ladder_rung_4">
      <origin xyz="0 -0.48 2.94" rpy="0 1.5708 0" />
      <geometry>
        <cylinder radius="0.018" length="0.39" />
        </geometry>
      <material name="galvanized_steel">
        <color rgba="0.5 0.54 0.56 1" />
        </material>
      </visual>
    <visual name="ladder_rung_5">
      <origin xyz="0 -0.48 3.47" rpy="0 1.5708 0" />
      <geometry>
        <cylinder radius="0.018" length="0.39" />
        </geometry>
      <material name="galvanized_steel">
        <color rgba="0.5 0.54 0.56 1" />
        </material>
      </visual>
    <visual name="ladder_rung_6">
      <origin xyz="0 -0.48 4" rpy="0 1.5708 0" />
      <geometry>
        <cylinder radius="0.018" length="0.39" />
        </geometry>
      <material name="galvanized_steel">
        <color rgba="0.5 0.54 0.56 1" />
        </material>
      </visual>
    <visual name="ladder_rung_7">
      <origin xyz="0 -0.48 4.53" rpy="0 1.5708 0" />
      <geometry>
        <cylinder radius="0.018" length="0.39" />
        </geometry>
      <material name="galvanized_steel">
        <color rgba="0.5 0.54 0.56 1" />
        </material>
      </visual>
    <visual name="ladder_standoff_0_0">
      <origin xyz="-0.16 -0.3 0.9" rpy="0 0 0" />
      <geometry>
        <box size="0.055 0.39 0.055" />
        </geometry>
      <material name="galvanized_steel">
        <color rgba="0.5 0.54 0.56 1" />
        </material>
      </visual>
    <visual name="ladder_standoff_0_1">
      <origin xyz="0.16 -0.3 0.9" rpy="0 0 0" />
      <geometry>
        <box size="0.055 0.39 0.055" />
        </geometry>
      <material name="galvanized_steel">
        <color rgba="0.5 0.54 0.56 1" />
        </material>
      </visual>
    <visual name="ladder_standoff_1_0">
      <origin xyz="-0.16 -0.3 2.2" rpy="0 0 0" />
      <geometry>
        <box size="0.055 0.39 0.055" />
        </geometry>
      <material name="galvanized_steel">
        <color rgba="0.5 0.54 0.56 1" />
        </material>
      </visual>
    <visual name="ladder_standoff_1_1">
      <origin xyz="0.16 -0.3 2.2" rpy="0 0 0" />
      <geometry>
        <box size="0.055 0.39 0.055" />
        </geometry>
      <material name="galvanized_steel">
        <color rgba="0.5 0.54 0.56 1" />
        </material>
      </visual>
    <visual name="ladder_standoff_2_0">
      <origin xyz="-0.16 -0.3 3.5" rpy="0 0 0" />
      <geometry>
        <box size="0.055 0.39 0.055" />
        </geometry>
      <material name="galvanized_steel">
        <color rgba="0.5 0.54 0.56 1" />
        </material>
      </visual>
    <visual name="ladder_standoff_2_1">
      <origin xyz="0.16 -0.3 3.5" rpy="0 0 0" />
      <geometry>
        <box size="0.055 0.39 0.055" />
        </geometry>
      <material name="galvanized_steel">
        <color rgba="0.5 0.54 0.56 1" />
        </material>
      </visual>
    <visual name="ladder_standoff_3_0">
      <origin xyz="-0.16 -0.3 4.78" rpy="0 0 0" />
      <geometry>
        <box size="0.055 0.39 0.055" />
        </geometry>
      <material name="galvanized_steel">
        <color rgba="0.5 0.54 0.56 1" />
        </material>
      </visual>
    <visual name="ladder_standoff_3_1">
      <origin xyz="0.16 -0.3 4.78" rpy="0 0 0" />
      <geometry>
        <box size="0.055 0.39 0.055" />
        </geometry>
      <material name="galvanized_steel">
        <color rgba="0.5 0.54 0.56 1" />
        </material>
      </visual>
    <collision name="base_plate">
      <origin xyz="0 0 0.05" rpy="0 0 0" />
      <geometry>
        <box size="1.2 1.2 0.1" />
        </geometry>
      </collision>
    <collision name="tower_tube">
      <origin xyz="0 0 2.65" rpy="0 0 0" />
      <geometry>
        <cylinder radius="0.22" length="5.2" />
        </geometry>
      </collision>
    <collision name="lower_yaw_bearing">
      <origin xyz="0 0 5.31" rpy="0 0 0" />
      <geometry>
        <cylinder radius="0.33" length="0.12" />
        </geometry>
      </collision>
    <collision name="service_collar">
      <origin xyz="0 0 5.33" rpy="0 0 0" />
      <geometry>
        <cylinder radius="0.46" length="0.08" />
        </geometry>
      </collision>
    <collision name="anchor_bolt_0">
      <origin xyz="-0.42 -0.42 0.115" rpy="0 0 0" />
      <geometry>
        <cylinder radius="0.075" length="0.035" />
        </geometry>
      </collision>
    <collision name="anchor_bolt_1">
      <origin xyz="0.42 -0.42 0.115" rpy="0 0 0" />
      <geometry>
        <cylinder radius="0.075" length="0.035" />
        </geometry>
      </collision>
    <collision name="anchor_bolt_2">
      <origin xyz="-0.42 0.42 0.115" rpy="0 0 0" />
      <geometry>
        <cylinder radius="0.075" length="0.035" />
        </geometry>
      </collision>
    <collision name="anchor_bolt_3">
      <origin xyz="0.42 0.42 0.115" rpy="0 0 0" />
      <geometry>
        <cylinder radius="0.075" length="0.035" />
        </geometry>
      </collision>
    <collision name="ladder_rail_-0.16">
      <origin xyz="-0.16 -0.48 2.75" rpy="0 0 0" />
      <geometry>
        <cylinder radius="0.022" length="4.15" />
        </geometry>
      </collision>
    <collision name="ladder_rail_+0.16">
      <origin xyz="0.16 -0.48 2.75" rpy="0 0 0" />
      <geometry>
        <cylinder radius="0.022" length="4.15" />
        </geometry>
      </collision>
    <collision name="ladder_rung_0">
      <origin xyz="0 -0.48 0.82" rpy="0 1.5708 0" />
      <geometry>
        <cylinder radius="0.018" length="0.39" />
        </geometry>
      </collision>
    <collision name="ladder_rung_1">
      <origin xyz="0 -0.48 1.35" rpy="0 1.5708 0" />
      <geometry>
        <cylinder radius="0.018" length="0.39" />
        </geometry>
      </collision>
    <collision name="ladder_rung_2">
      <origin xyz="0 -0.48 1.88" rpy="0 1.5708 0" />
      <geometry>
        <cylinder radius="0.018" length="0.39" />
        </geometry>
      </collision>
    <collision name="ladder_rung_3">
      <origin xyz="0 -0.48 2.41" rpy="0 1.5708 0" />
      <geometry>
        <cylinder radius="0.018" length="0.39" />
        </geometry>
      </collision>
    <collision name="ladder_rung_4">
      <origin xyz="0 -0.48 2.94" rpy="0 1.5708 0" />
      <geometry>
        <cylinder radius="0.018" length="0.39" />
        </geometry>
      </collision>
    <collision name="ladder_rung_5">
      <origin xyz="0 -0.48 3.47" rpy="0 1.5708 0" />
      <geometry>
        <cylinder radius="0.018" length="0.39" />
        </geometry>
      </collision>
    <collision name="ladder_rung_6">
      <origin xyz="0 -0.48 4" rpy="0 1.5708 0" />
      <geometry>
        <cylinder radius="0.018" length="0.39" />
        </geometry>
      </collision>
    <collision name="ladder_rung_7">
      <origin xyz="0 -0.48 4.53" rpy="0 1.5708 0" />
      <geometry>
        <cylinder radius="0.018" length="0.39" />
        </geometry>
      </collision>
    <collision name="ladder_standoff_0_0">
      <origin xyz="-0.16 -0.3 0.9" rpy="0 0 0" />
      <geometry>
        <box size="0.055 0.39 0.055" />
        </geometry>
      </collision>
    <collision name="ladder_standoff_0_1">
      <origin xyz="0.16 -0.3 0.9" rpy="0 0 0" />
      <geometry>
        <box size="0.055 0.39 0.055" />
        </geometry>
      </collision>
    <collision name="ladder_standoff_1_0">
      <origin xyz="-0.16 -0.3 2.2" rpy="0 0 0" />
      <geometry>
        <box size="0.055 0.39 0.055" />
        </geometry>
      </collision>
    <collision name="ladder_standoff_1_1">
      <origin xyz="0.16 -0.3 2.2" rpy="0 0 0" />
      <geometry>
        <box size="0.055 0.39 0.055" />
        </geometry>
      </collision>
    <collision name="ladder_standoff_2_0">
      <origin xyz="-0.16 -0.3 3.5" rpy="0 0 0" />
      <geometry>
        <box size="0.055 0.39 0.055" />
        </geometry>
      </collision>
    <collision name="ladder_standoff_2_1">
      <origin xyz="0.16 -0.3 3.5" rpy="0 0 0" />
      <geometry>
        <box size="0.055 0.39 0.055" />
        </geometry>
      </collision>
    <collision name="ladder_standoff_3_0">
      <origin xyz="-0.16 -0.3 4.78" rpy="0 0 0" />
      <geometry>
        <box size="0.055 0.39 0.055" />
        </geometry>
      </collision>
    <collision name="ladder_standoff_3_1">
      <origin xyz="0.16 -0.3 4.78" rpy="0 0 0" />
      <geometry>
        <box size="0.055 0.39 0.055" />
        </geometry>
      </collision>
    </link>
  <link name="nacelle">
    <visual name="upper_yaw_bearing">
      <origin xyz="0 0 0.06" rpy="0 0 0" />
      <geometry>
        <cylinder radius="0.43" length="0.12" />
        </geometry>
      <material name="dark_steel">
        <color rgba="0.12 0.13 0.14 1" />
        </material>
      </visual>
    <visual name="service_body">
      <origin xyz="0.26 0 0.45" rpy="0 0 0" />
      <geometry>
        <box size="1.58 0.84 0.66" />
        </geometry>
      <material name="weathered_white">
        <color rgba="0.82 0.84 0.8 1" />
        </material>
      </visual>
    <visual name="front_bearing">
      <origin xyz="1.1 0 0.45" rpy="0 1.5708 0" />
      <geometry>
        <cylinder radius="0.35" length="0.2" />
        </geometry>
      <material name="dark_steel">
        <color rgba="0.12 0.13 0.14 1" />
        </material>
      </visual>
    <visual name="rear_cooling_port">
      <origin xyz="-0.58 0 0.43" rpy="0 1.5708 0" />
      <geometry>
        <cylinder radius="0.24" length="0.12" />
        </geometry>
      <material name="dark_steel">
        <color rgba="0.12 0.13 0.14 1" />
        </material>
      </visual>
    <visual name="access_frame">
      <origin xyz="-0.18 -0.435 0.45" rpy="0 0 0" />
      <geometry>
        <box size="0.62 0.035 0.44" />
        </geometry>
      <material name="service_yellow">
        <color rgba="0.95 0.72 0.08 1" />
        </material>
      </visual>
    <visual name="door_header">
      <origin xyz="0.26 -0.435 0.73" rpy="0 0 0" />
      <geometry>
        <box size="0.62 0.045 0.05" />
        </geometry>
      <material name="dark_steel">
        <color rgba="0.12 0.13 0.14 1" />
        </material>
      </visual>
    <visual name="roof_rail">
      <origin xyz="0.05 0 0.8" rpy="0 0 0" />
      <geometry>
        <box size="0.9 0.12 0.08" />
        </geometry>
      <material name="dark_steel">
        <color rgba="0.12 0.13 0.14 1" />
        </material>
      </visual>
    <visual name="lift_lug">
      <origin xyz="0.88 0 0.8" rpy="0 0 0" />
      <geometry>
        <box size="0.14 0.92 0.06" />
        </geometry>
      <material name="service_yellow">
        <color rgba="0.95 0.72 0.08 1" />
        </material>
      </visual>
    <visual name="hatch_fixed_knuckle_lower">
      <origin xyz="-0.49 -0.485 0.29" rpy="0 0 0" />
      <geometry>
        <cylinder radius="0.028" length="0.13" />
        </geometry>
      <material name="dark_steel">
        <color rgba="0.12 0.13 0.14 1" />
        </material>
      </visual>
    <visual name="hatch_hinge_leaf_lower">
      <origin xyz="-0.49 -0.445 0.29" rpy="0 0 0" />
      <geometry>
        <box size="0.055 0.08 0.1" />
        </geometry>
      <material name="dark_steel">
        <color rgba="0.12 0.13 0.14 1" />
        </material>
      </visual>
    <visual name="hatch_fixed_knuckle_upper">
      <origin xyz="-0.49 -0.485 0.61" rpy="0 0 0" />
      <geometry>
        <cylinder radius="0.028" length="0.13" />
        </geometry>
      <material name="dark_steel">
        <color rgba="0.12 0.13 0.14 1" />
        </material>
      </visual>
    <visual name="hatch_hinge_leaf_upper">
      <origin xyz="-0.49 -0.445 0.61" rpy="0 0 0" />
      <geometry>
        <box size="0.055 0.08 0.1" />
        </geometry>
      <material name="dark_steel">
        <color rgba="0.12 0.13 0.14 1" />
        </material>
      </visual>
    <collision name="upper_yaw_bearing">
      <origin xyz="0 0 0.06" rpy="0 0 0" />
      <geometry>
        <cylinder radius="0.43" length="0.12" />
        </geometry>
      </collision>
    <collision name="service_body">
      <origin xyz="0.26 0 0.45" rpy="0 0 0" />
      <geometry>
        <box size="1.58 0.84 0.66" />
        </geometry>
      </collision>
    <collision name="front_bearing">
      <origin xyz="1.1 0 0.45" rpy="0 1.5708 0" />
      <geometry>
        <cylinder radius="0.35" length="0.2" />
        </geometry>
      </collision>
    <collision name="rear_cooling_port">
      <origin xyz="-0.58 0 0.43" rpy="0 1.5708 0" />
      <geometry>
        <cylinder radius="0.24" length="0.12" />
        </geometry>
      </collision>
    <collision name="access_frame">
      <origin xyz="-0.18 -0.435 0.45" rpy="0 0 0" />
      <geometry>
        <box size="0.62 0.035 0.44" />
        </geometry>
      </collision>
    <collision name="door_header">
      <origin xyz="0.26 -0.435 0.73" rpy="0 0 0" />
      <geometry>
        <box size="0.62 0.045 0.05" />
        </geometry>
      </collision>
    <collision name="roof_rail">
      <origin xyz="0.05 0 0.8" rpy="0 0 0" />
      <geometry>
        <box size="0.9 0.12 0.08" />
        </geometry>
      </collision>
    <collision name="lift_lug">
      <origin xyz="0.88 0 0.8" rpy="0 0 0" />
      <geometry>
        <box size="0.14 0.92 0.06" />
        </geometry>
      </collision>
    <collision name="hatch_fixed_knuckle_lower">
      <origin xyz="-0.49 -0.485 0.29" rpy="0 0 0" />
      <geometry>
        <cylinder radius="0.028" length="0.13" />
        </geometry>
      </collision>
    <collision name="hatch_hinge_leaf_lower">
      <origin xyz="-0.49 -0.445 0.29" rpy="0 0 0" />
      <geometry>
        <box size="0.055 0.08 0.1" />
        </geometry>
      </collision>
    <collision name="hatch_fixed_knuckle_upper">
      <origin xyz="-0.49 -0.485 0.61" rpy="0 0 0" />
      <geometry>
        <cylinder radius="0.028" length="0.13" />
        </geometry>
      </collision>
    <collision name="hatch_hinge_leaf_upper">
      <origin xyz="-0.49 -0.445 0.61" rpy="0 0 0" />
      <geometry>
        <box size="0.055 0.08 0.1" />
        </geometry>
      </collision>
    </link>
  <link name="access_hatch">
    <visual name="hatch_panel">
      <origin xyz="0.275 -0.07 0" rpy="0 0 0" />
      <geometry>
        <box size="0.55 0.035 0.36" />
        </geometry>
      <material name="weathered_white">
        <color rgba="0.82 0.84 0.8 1" />
        </material>
      </visual>
    <visual name="hatch_handle">
      <origin xyz="0.43 -0.095 0" rpy="0 0 0" />
      <geometry>
        <box size="0.09 0.035 0.05" />
        </geometry>
      <material name="black_rubber">
        <color rgba="0.03 0.035 0.04 1" />
        </material>
      </visual>
    <visual name="hatch_knuckle">
      <origin xyz="0 -0.045 0" rpy="0 0 0" />
      <geometry>
        <cylinder radius="0.025" length="0.19" />
        </geometry>
      <material name="dark_steel">
        <color rgba="0.12 0.13 0.14 1" />
        </material>
      </visual>
    <visual name="hatch_leaf">
      <origin xyz="0.045 -0.075 0" rpy="0 0 0" />
      <geometry>
        <box size="0.1 0.035 0.26" />
        </geometry>
      <material name="dark_steel">
        <color rgba="0.12 0.13 0.14 1" />
        </material>
      </visual>
    <collision name="hatch_panel">
      <origin xyz="0.275 -0.07 0" rpy="0 0 0" />
      <geometry>
        <box size="0.55 0.035 0.36" />
        </geometry>
      </collision>
    <collision name="hatch_handle">
      <origin xyz="0.43 -0.095 0" rpy="0 0 0" />
      <geometry>
        <box size="0.09 0.035 0.05" />
        </geometry>
      </collision>
    <collision name="hatch_knuckle">
      <origin xyz="0 -0.045 0" rpy="0 0 0" />
      <geometry>
        <cylinder radius="0.025" length="0.19" />
        </geometry>
      </collision>
    <collision name="hatch_leaf">
      <origin xyz="0.045 -0.075 0" rpy="0 0 0" />
      <geometry>
        <box size="0.1 0.035 0.26" />
        </geometry>
      </collision>
    </link>
  <link name="rotor_hub">
    <visual name="replaceable_wear_flange">
      <origin xyz="0.04 0 0" rpy="0 1.5708 0" />
      <geometry>
        <cylinder radius="0.36" length="0.08" />
        </geometry>
      <material name="service_yellow">
        <color rgba="0.95 0.72 0.08 1" />
        </material>
      </visual>
    <visual name="hub_shell">
      <origin xyz="0.17 0 0" rpy="0 1.5708 0" />
      <geometry>
        <cylinder radius="0.28" length="0.34" />
        </geometry>
      <material name="dark_steel">
        <color rgba="0.12 0.13 0.14 1" />
        </material>
      </visual>
    <visual name="nose_cap">
      <origin xyz="0.37 0 0" rpy="0 0 0" />
      <geometry>
        <sphere radius="0.2" />
        </geometry>
      <material name="weathered_white">
        <color rgba="0.82 0.84 0.8 1" />
        </material>
      </visual>
    <visual name="flange_bolt_0">
      <origin xyz="0.08 0.285 0" rpy="0 1.5708 0" />
      <geometry>
        <cylinder radius="0.026" length="0.03" />
        </geometry>
      <material name="galvanized_steel">
        <color rgba="0.5 0.54 0.56 1" />
        </material>
      </visual>
    <visual name="flange_bolt_1">
      <origin xyz="0.08 0.201525 0.201525" rpy="0 1.5708 0" />
      <geometry>
        <cylinder radius="0.026" length="0.03" />
        </geometry>
      <material name="galvanized_steel">
        <color rgba="0.5 0.54 0.56 1" />
        </material>
      </visual>
    <visual name="flange_bolt_2">
      <origin xyz="0.08 1.74512e-17 0.285" rpy="0 1.5708 0" />
      <geometry>
        <cylinder radius="0.026" length="0.03" />
        </geometry>
      <material name="galvanized_steel">
        <color rgba="0.5 0.54 0.56 1" />
        </material>
      </visual>
    <visual name="flange_bolt_3">
      <origin xyz="0.08 -0.201525 0.201525" rpy="0 1.5708 0" />
      <geometry>
        <cylinder radius="0.026" length="0.03" />
        </geometry>
      <material name="galvanized_steel">
        <color rgba="0.5 0.54 0.56 1" />
        </material>
      </visual>
    <visual name="flange_bolt_4">
      <origin xyz="0.08 -0.285 3.49024e-17" rpy="0 1.5708 0" />
      <geometry>
        <cylinder radius="0.026" length="0.03" />
        </geometry>
      <material name="galvanized_steel">
        <color rgba="0.5 0.54 0.56 1" />
        </material>
      </visual>
    <visual name="flange_bolt_5">
      <origin xyz="0.08 -0.201525 -0.201525" rpy="0 1.5708 0" />
      <geometry>
        <cylinder radius="0.026" length="0.03" />
        </geometry>
      <material name="galvanized_steel">
        <color rgba="0.5 0.54 0.56 1" />
        </material>
      </visual>
    <visual name="flange_bolt_6">
      <origin xyz="0.08 -5.23537e-17 -0.285" rpy="0 1.5708 0" />
      <geometry>
        <cylinder radius="0.026" length="0.03" />
        </geometry>
      <material name="galvanized_steel">
        <color rgba="0.5 0.54 0.56 1" />
        </material>
      </visual>
    <visual name="flange_bolt_7">
      <origin xyz="0.08 0.201525 -0.201525" rpy="0 1.5708 0" />
      <geometry>
        <cylinder radius="0.026" length="0.03" />
        </geometry>
      <material name="galvanized_steel">
        <color rgba="0.5 0.54 0.56 1" />
        </material>
      </visual>
    <visual name="blade_socket_0">
      <origin xyz="0.2 1.95943e-17 0.32" rpy="0 0 0" />
      <geometry>
        <cylinder radius="0.135" length="0.32" />
        </geometry>
      <material name="dark_steel">
        <color rgba="0.12 0.13 0.14 1" />
        </material>
      </visual>
    <visual name="socket_wear_ring_0">
      <origin xyz="0.2 2.79832e-17 0.457" rpy="0 0 0" />
      <geometry>
        <cylinder radius="0.165" length="0.045" />
        </geometry>
      <material name="service_yellow">
        <color rgba="0.95 0.72 0.08 1" />
        </material>
      </visual>
    <visual name="blade_socket_1">
      <origin xyz="0.2 -0.277128 -0.16" rpy="2.0944 0 0" />
      <geometry>
        <cylinder radius="0.135" length="0.32" />
        </geometry>
      <material name="dark_steel">
        <color rgba="0.12 0.13 0.14 1" />
        </material>
      </visual>
    <visual name="socket_wear_ring_1">
      <origin xyz="0.2 -0.395774 -0.2285" rpy="2.0944 0 0" />
      <geometry>
        <cylinder radius="0.165" length="0.045" />
        </geometry>
      <material name="service_yellow">
        <color rgba="0.95 0.72 0.08 1" />
        </material>
      </visual>
    <visual name="blade_socket_2">
      <origin xyz="0.2 0.277128 -0.16" rpy="4.18879 0 0" />
      <geometry>
        <cylinder radius="0.135" length="0.32" />
        </geometry>
      <material name="dark_steel">
        <color rgba="0.12 0.13 0.14 1" />
        </material>
      </visual>
    <visual name="socket_wear_ring_2">
      <origin xyz="0.2 0.395774 -0.2285" rpy="4.18879 0 0" />
      <geometry>
        <cylinder radius="0.165" length="0.045" />
        </geometry>
      <material name="service_yellow">
        <color rgba="0.95 0.72 0.08 1" />
        </material>
      </visual>
    <collision name="replaceable_wear_flange">
      <origin xyz="0.04 0 0" rpy="0 1.5708 0" />
      <geometry>
        <cylinder radius="0.36" length="0.08" />
        </geometry>
      </collision>
    <collision name="hub_shell">
      <origin xyz="0.17 0 0" rpy="0 1.5708 0" />
      <geometry>
        <cylinder radius="0.28" length="0.34" />
        </geometry>
      </collision>
    <collision name="nose_cap">
      <origin xyz="0.37 0 0" rpy="0 0 0" />
      <geometry>
        <sphere radius="0.2" />
        </geometry>
      </collision>
    <collision name="flange_bolt_0">
      <origin xyz="0.08 0.285 0" rpy="0 1.5708 0" />
      <geometry>
        <cylinder radius="0.026" length="0.03" />
        </geometry>
      </collision>
    <collision name="flange_bolt_1">
      <origin xyz="0.08 0.201525 0.201525" rpy="0 1.5708 0" />
      <geometry>
        <cylinder radius="0.026" length="0.03" />
        </geometry>
      </collision>
    <collision name="flange_bolt_2">
      <origin xyz="0.08 1.74512e-17 0.285" rpy="0 1.5708 0" />
      <geometry>
        <cylinder radius="0.026" length="0.03" />
        </geometry>
      </collision>
    <collision name="flange_bolt_3">
      <origin xyz="0.08 -0.201525 0.201525" rpy="0 1.5708 0" />
      <geometry>
        <cylinder radius="0.026" length="0.03" />
        </geometry>
      </collision>
    <collision name="flange_bolt_4">
      <origin xyz="0.08 -0.285 3.49024e-17" rpy="0 1.5708 0" />
      <geometry>
        <cylinder radius="0.026" length="0.03" />
        </geometry>
      </collision>
    <collision name="flange_bolt_5">
      <origin xyz="0.08 -0.201525 -0.201525" rpy="0 1.5708 0" />
      <geometry>
        <cylinder radius="0.026" length="0.03" />
        </geometry>
      </collision>
    <collision name="flange_bolt_6">
      <origin xyz="0.08 -5.23537e-17 -0.285" rpy="0 1.5708 0" />
      <geometry>
        <cylinder radius="0.026" length="0.03" />
        </geometry>
      </collision>
    <collision name="flange_bolt_7">
      <origin xyz="0.08 0.201525 -0.201525" rpy="0 1.5708 0" />
      <geometry>
        <cylinder radius="0.026" length="0.03" />
        </geometry>
      </collision>
    <collision name="blade_socket_0">
      <origin xyz="0.2 1.95943e-17 0.32" rpy="0 0 0" />
      <geometry>
        <cylinder radius="0.135" length="0.32" />
        </geometry>
      </collision>
    <collision name="socket_wear_ring_0">
      <origin xyz="0.2 2.79832e-17 0.457" rpy="0 0 0" />
      <geometry>
        <cylinder radius="0.165" length="0.045" />
        </geometry>
      </collision>
    <collision name="blade_socket_1">
      <origin xyz="0.2 -0.277128 -0.16" rpy="2.0944 0 0" />
      <geometry>
        <cylinder radius="0.135" length="0.32" />
        </geometry>
      </collision>
    <collision name="socket_wear_ring_1">
      <origin xyz="0.2 -0.395774 -0.2285" rpy="2.0944 0 0" />
      <geometry>
        <cylinder radius="0.165" length="0.045" />
        </geometry>
      </collision>
    <collision name="blade_socket_2">
      <origin xyz="0.2 0.277128 -0.16" rpy="4.18879 0 0" />
      <geometry>
        <cylinder radius="0.135" length="0.32" />
        </geometry>
      </collision>
    <collision name="socket_wear_ring_2">
      <origin xyz="0.2 0.395774 -0.2285" rpy="4.18879 0 0" />
      <geometry>
        <cylinder radius="0.165" length="0.045" />
        </geometry>
      </collision>
    </link>
  <link name="blade_0">
    <visual name="root_bearing">
      <origin xyz="0 7.34788e-18 0.12" rpy="0 0 0" />
      <geometry>
        <cylinder radius="0.108" length="0.24" />
        </geometry>
      <material name="dark_steel">
        <color rgba="0.12 0.13 0.14 1" />
        </material>
      </visual>
    <visual name="root_wear_collar">
      <origin xyz="0 1.53081e-17 0.25" rpy="0 0 0" />
      <geometry>
        <cylinder radius="0.135" length="0.045" />
        </geometry>
      <material name="service_yellow">
        <color rgba="0.95 0.72 0.08 1" />
        </material>
      </visual>
    <visual name="blade_shell">
      <geometry>
        <mesh filename="assets/meshes/blade_0_shell.obj" />
        </geometry>
      <material name="blade_white">
        <color rgba="0.91 0.92 0.88 1" />
        </material>
      </visual>
    <visual name="tip_wear_cap">
      <geometry>
        <mesh filename="assets/meshes/blade_0_tip.obj" />
        </geometry>
      <material name="wear_orange">
        <color rgba="0.95 0.28 0.08 1" />
        </material>
      </visual>
    <collision name="root_bearing">
      <origin xyz="0 7.34788e-18 0.12" rpy="0 0 0" />
      <geometry>
        <cylinder radius="0.108" length="0.24" />
        </geometry>
      </collision>
    <collision name="root_wear_collar">
      <origin xyz="0 1.53081e-17 0.25" rpy="0 0 0" />
      <geometry>
        <cylinder radius="0.135" length="0.045" />
        </geometry>
      </collision>
    <collision name="blade_shell">
      <geometry>
        <mesh filename="assets/meshes/blade_0_shell.obj" />
        </geometry>
      </collision>
    <collision name="tip_wear_cap">
      <geometry>
        <mesh filename="assets/meshes/blade_0_tip.obj" />
        </geometry>
      </collision>
    </link>
  <link name="blade_1">
    <visual name="root_bearing">
      <origin xyz="0 -0.103923 -0.06" rpy="2.0944 0 0" />
      <geometry>
        <cylinder radius="0.108" length="0.24" />
        </geometry>
      <material name="dark_steel">
        <color rgba="0.12 0.13 0.14 1" />
        </material>
      </visual>
    <visual name="root_wear_collar">
      <origin xyz="0 -0.216506 -0.125" rpy="2.0944 0 0" />
      <geometry>
        <cylinder radius="0.135" length="0.045" />
        </geometry>
      <material name="service_yellow">
        <color rgba="0.95 0.72 0.08 1" />
        </material>
      </visual>
    <visual name="blade_shell">
      <geometry>
        <mesh filename="assets/meshes/blade_1_shell.obj" />
        </geometry>
      <material name="blade_white">
        <color rgba="0.91 0.92 0.88 1" />
        </material>
      </visual>
    <visual name="tip_wear_cap">
      <geometry>
        <mesh filename="assets/meshes/blade_1_tip.obj" />
        </geometry>
      <material name="wear_orange">
        <color rgba="0.95 0.28 0.08 1" />
        </material>
      </visual>
    <collision name="root_bearing">
      <origin xyz="0 -0.103923 -0.06" rpy="2.0944 0 0" />
      <geometry>
        <cylinder radius="0.108" length="0.24" />
        </geometry>
      </collision>
    <collision name="root_wear_collar">
      <origin xyz="0 -0.216506 -0.125" rpy="2.0944 0 0" />
      <geometry>
        <cylinder radius="0.135" length="0.045" />
        </geometry>
      </collision>
    <collision name="blade_shell">
      <geometry>
        <mesh filename="assets/meshes/blade_1_shell.obj" />
        </geometry>
      </collision>
    <collision name="tip_wear_cap">
      <geometry>
        <mesh filename="assets/meshes/blade_1_tip.obj" />
        </geometry>
      </collision>
    </link>
  <link name="blade_2">
    <visual name="root_bearing">
      <origin xyz="0 0.103923 -0.06" rpy="4.18879 0 0" />
      <geometry>
        <cylinder radius="0.108" length="0.24" />
        </geometry>
      <material name="dark_steel">
        <color rgba="0.12 0.13 0.14 1" />
        </material>
      </visual>
    <visual name="root_wear_collar">
      <origin xyz="0 0.216506 -0.125" rpy="4.18879 0 0" />
      <geometry>
        <cylinder radius="0.135" length="0.045" />
        </geometry>
      <material name="service_yellow">
        <color rgba="0.95 0.72 0.08 1" />
        </material>
      </visual>
    <visual name="blade_shell">
      <geometry>
        <mesh filename="assets/meshes/blade_2_shell.obj" />
        </geometry>
      <material name="blade_white">
        <color rgba="0.91 0.92 0.88 1" />
        </material>
      </visual>
    <visual name="tip_wear_cap">
      <geometry>
        <mesh filename="assets/meshes/blade_2_tip.obj" />
        </geometry>
      <material name="wear_orange">
        <color rgba="0.95 0.28 0.08 1" />
        </material>
      </visual>
    <collision name="root_bearing">
      <origin xyz="0 0.103923 -0.06" rpy="4.18879 0 0" />
      <geometry>
        <cylinder radius="0.108" length="0.24" />
        </geometry>
      </collision>
    <collision name="root_wear_collar">
      <origin xyz="0 0.216506 -0.125" rpy="4.18879 0 0" />
      <geometry>
        <cylinder radius="0.135" length="0.045" />
        </geometry>
      </collision>
    <collision name="blade_shell">
      <geometry>
        <mesh filename="assets/meshes/blade_2_shell.obj" />
        </geometry>
      </collision>
    <collision name="tip_wear_cap">
      <geometry>
        <mesh filename="assets/meshes/blade_2_tip.obj" />
        </geometry>
      </collision>
    </link>
  <joint name="tower_to_nacelle" type="revolute">
    <origin xyz="0 0 5.37" rpy="0 0 0" />
    <parent link="tower" />
    <child link="nacelle" />
    <axis xyz="0 0 1" />
    <limit effort="8000" velocity="0.2" lower="-3.14159" upper="3.14159" />
    </joint>
  <joint name="nacelle_to_hatch" type="revolute">
    <origin xyz="-0.49 -0.485 0.45" rpy="0 0 0" />
    <parent link="nacelle" />
    <child link="access_hatch" />
    <axis xyz="0 0 -1" />
    <limit effort="120" velocity="0.8" lower="0" upper="1.75" />
    </joint>
  <joint name="nacelle_to_hub" type="continuous">
    <origin xyz="1.2 0 0.45" rpy="0 0 0" />
    <parent link="nacelle" />
    <child link="rotor_hub" />
    <axis xyz="1 0 0" />
    <limit effort="2500" velocity="6" />
    </joint>
  <joint name="hub_to_blade_0" type="revolute">
    <origin xyz="0.2 2.93915e-17 0.48" rpy="0 0 0" />
    <parent link="rotor_hub" />
    <child link="blade_0" />
    <axis xyz="0 6.12323e-17 1" />
    <limit effort="900" velocity="0.55" lower="-0.35" upper="0.35" />
    </joint>
  <joint name="hub_to_blade_1" type="revolute">
    <origin xyz="0.2 -0.415692 -0.24" rpy="0 0 0" />
    <parent link="rotor_hub" />
    <child link="blade_1" />
    <axis xyz="0 -0.866025 -0.5" />
    <limit effort="900" velocity="0.55" lower="-0.35" upper="0.35" />
    </joint>
  <joint name="hub_to_blade_2" type="revolute">
    <origin xyz="0.2 0.415692 -0.24" rpy="0 0 0" />
    <parent link="rotor_hub" />
    <child link="blade_2" />
    <axis xyz="0 0.866025 -0.5" />
    <limit effort="900" velocity="0.55" lower="-0.35" upper="0.35" />
    </joint>
  </robot>
