<robot name="front_control_range">
  <material name="brushed_stainless">
    <color rgba="0.62 0.64 0.63 1" />
    </material>
  <material name="dark_brushed_steel">
    <color rgba="0.16 0.17 0.17 1" />
    </material>
  <material name="black_enamel">
    <color rgba="0.005 0.005 0.006 1" />
    </material>
  <material name="smoked_oven_glass">
    <color rgba="0.02 0.025 0.03 0.72" />
    </material>
  <material name="cast_iron_black">
    <color rgba="0.015 0.014 0.013 1" />
    </material>
  <material name="matte_rubber">
    <color rgba="0.035 0.035 0.035 1" />
    </material>
  <material name="white_silk_screen">
    <color rgba="0.92 0.91 0.86 1" />
    </material>
  <material name="amber_display">
    <color rgba="1 0.46 0.08 1" />
    </material>
  <link name="body">
    <visual name="side_panel_0">
      <origin xyz="-0.362 -0.02 0.46" rpy="0 0 0" />
      <geometry>
        <box size="0.036 0.66 0.82" />
        </geometry>
      <material name="brushed_stainless">
        <color rgba="0.62 0.64 0.63 1" />
        </material>
      </visual>
    <visual name="side_panel_1">
      <origin xyz="0.362 -0.02 0.46" rpy="0 0 0" />
      <geometry>
        <box size="0.036 0.66 0.82" />
        </geometry>
      <material name="brushed_stainless">
        <color rgba="0.62 0.64 0.63 1" />
        </material>
      </visual>
    <visual name="rear_panel">
      <origin xyz="0 0.292 0.46" rpy="0 0 0" />
      <geometry>
        <box size="0.76 0.036 0.82" />
        </geometry>
      <material name="brushed_stainless">
        <color rgba="0.62 0.64 0.63 1" />
        </material>
      </visual>
    <visual name="bottom_pan">
      <origin xyz="0 -0.02 0.033" rpy="0 0 0" />
      <geometry>
        <box size="0.76 0.66 0.065" />
        </geometry>
      <material name="dark_brushed_steel">
        <color rgba="0.16 0.17 0.17 1" />
        </material>
      </visual>
    <visual name="top_deck">
      <origin xyz="0 -0.02 0.851" rpy="0 0 0" />
      <geometry>
        <box size="0.76 0.66 0.058" />
        </geometry>
      <material name="brushed_stainless">
        <color rgba="0.62 0.64 0.63 1" />
        </material>
      </visual>
    <visual name="front_stile_0">
      <origin xyz="-0.35 -0.366 0.395" rpy="0 0 0" />
      <geometry>
        <box size="0.06 0.055 0.555" />
        </geometry>
      <material name="brushed_stainless">
        <color rgba="0.62 0.64 0.63 1" />
        </material>
      </visual>
    <visual name="front_stile_1">
      <origin xyz="0.35 -0.366 0.395" rpy="0 0 0" />
      <geometry>
        <box size="0.06 0.055 0.555" />
        </geometry>
      <material name="brushed_stainless">
        <color rgba="0.62 0.64 0.63 1" />
        </material>
      </visual>
    <visual name="upper_oven_rail">
      <origin xyz="0 -0.366 0.654" rpy="0 0 0" />
      <geometry>
        <box size="0.76 0.055 0.052" />
        </geometry>
      <material name="brushed_stainless">
        <color rgba="0.62 0.64 0.63 1" />
        </material>
      </visual>
    <visual name="lower_oven_rail">
      <origin xyz="0 -0.366 0.129" rpy="0 0 0" />
      <geometry>
        <box size="0.76 0.055 0.064" />
        </geometry>
      <material name="dark_brushed_steel">
        <color rgba="0.16 0.17 0.17 1" />
        </material>
      </visual>
    <visual name="toe_kick">
      <origin xyz="0 -0.37 0.073" rpy="0 0 0" />
      <geometry>
        <box size="0.76 0.06 0.095" />
        </geometry>
      <material name="dark_brushed_steel">
        <color rgba="0.16 0.17 0.17 1" />
        </material>
      </visual>
    <visual name="control_fascia">
      <origin xyz="0 -0.37 0.745" rpy="0 0 0" />
      <geometry>
        <box size="0.76 0.042 0.178" />
        </geometry>
      <material name="brushed_stainless">
        <color rgba="0.62 0.64 0.63 1" />
        </material>
      </visual>
    <visual name="upper_trim">
      <origin xyz="0 -0.395 0.838" rpy="0 0 0" />
      <geometry>
        <box size="0.735 0.01 0.02" />
        </geometry>
      <material name="dark_brushed_steel">
        <color rgba="0.16 0.17 0.17 1" />
        </material>
      </visual>
    <visual name="lower_trim">
      <origin xyz="0 -0.395 0.66" rpy="0 0 0" />
      <geometry>
        <box size="0.735 0.01 0.018" />
        </geometry>
      <material name="dark_brushed_steel">
        <color rgba="0.16 0.17 0.17 1" />
        </material>
      </visual>
    <visual name="oven_back_liner">
      <origin xyz="0 0.257 0.375" rpy="0 0 0" />
      <geometry>
        <box size="0.7 0.04 0.43" />
        </geometry>
      <material name="black_enamel">
        <color rgba="0.005 0.005 0.006 1" />
        </material>
      </visual>
    <visual name="oven_liner_0">
      <origin xyz="-0.335 -0.04 0.375" rpy="0 0 0" />
      <geometry>
        <box size="0.026 0.52 0.43" />
        </geometry>
      <material name="black_enamel">
        <color rgba="0.005 0.005 0.006 1" />
        </material>
      </visual>
    <visual name="oven_liner_1">
      <origin xyz="0.335 -0.04 0.375" rpy="0 0 0" />
      <geometry>
        <box size="0.026 0.52 0.43" />
        </geometry>
      <material name="black_enamel">
        <color rgba="0.005 0.005 0.006 1" />
        </material>
      </visual>
    <visual name="oven_floor">
      <origin xyz="0 -0.04 0.165" rpy="0 0 0" />
      <geometry>
        <box size="0.7 0.52 0.018" />
        </geometry>
      <material name="black_enamel">
        <color rgba="0.005 0.005 0.006 1" />
        </material>
      </visual>
    <visual name="oven_ceiling">
      <origin xyz="0 -0.04 0.585" rpy="0 0 0" />
      <geometry>
        <box size="0.7 0.52 0.018" />
        </geometry>
      <material name="black_enamel">
        <color rgba="0.005 0.005 0.006 1" />
        </material>
      </visual>
    <visual name="rack_rail_0_0.29">
      <origin xyz="-0.326 -0.045 0.295" rpy="0 0 0" />
      <geometry>
        <box size="0.012 0.47 0.012" />
        </geometry>
      <material name="dark_brushed_steel">
        <color rgba="0.16 0.17 0.17 1" />
        </material>
      </visual>
    <visual name="rack_rail_1_0.29">
      <origin xyz="0.326 -0.045 0.295" rpy="0 0 0" />
      <geometry>
        <box size="0.012 0.47 0.012" />
        </geometry>
      <material name="dark_brushed_steel">
        <color rgba="0.16 0.17 0.17 1" />
        </material>
      </visual>
    <visual name="rack_front_frame_0.29">
      <origin xyz="0 -0.255 0.305" rpy="0 0 0" />
      <geometry>
        <box size="0.66 0.006 0.006" />
        </geometry>
      <material name="dark_brushed_steel">
        <color rgba="0.16 0.17 0.17 1" />
        </material>
      </visual>
    <visual name="rack_rear_frame_0.29">
      <origin xyz="0 0.165 0.305" rpy="0 0 0" />
      <geometry>
        <box size="0.66 0.006 0.006" />
        </geometry>
      <material name="dark_brushed_steel">
        <color rgba="0.16 0.17 0.17 1" />
        </material>
      </visual>
    <visual name="rack_wire_-0.19_0.29">
      <origin xyz="-0.19 -0.045 0.305" rpy="0 0 0" />
      <geometry>
        <box size="0.006 0.42 0.006" />
        </geometry>
      <material name="dark_brushed_steel">
        <color rgba="0.16 0.17 0.17 1" />
        </material>
      </visual>
    <visual name="rack_wire_-0.10_0.29">
      <origin xyz="-0.095 -0.045 0.305" rpy="0 0 0" />
      <geometry>
        <box size="0.006 0.42 0.006" />
        </geometry>
      <material name="dark_brushed_steel">
        <color rgba="0.16 0.17 0.17 1" />
        </material>
      </visual>
    <visual name="rack_wire_0.00_0.29">
      <origin xyz="0 -0.045 0.305" rpy="0 0 0" />
      <geometry>
        <box size="0.006 0.42 0.006" />
        </geometry>
      <material name="dark_brushed_steel">
        <color rgba="0.16 0.17 0.17 1" />
        </material>
      </visual>
    <visual name="rack_wire_0.10_0.29">
      <origin xyz="0.095 -0.045 0.305" rpy="0 0 0" />
      <geometry>
        <box size="0.006 0.42 0.006" />
        </geometry>
      <material name="dark_brushed_steel">
        <color rgba="0.16 0.17 0.17 1" />
        </material>
      </visual>
    <visual name="rack_wire_0.19_0.29">
      <origin xyz="0.19 -0.045 0.305" rpy="0 0 0" />
      <geometry>
        <box size="0.006 0.42 0.006" />
        </geometry>
      <material name="dark_brushed_steel">
        <color rgba="0.16 0.17 0.17 1" />
        </material>
      </visual>
    <visual name="rack_rail_0_0.45">
      <origin xyz="-0.326 -0.045 0.445" rpy="0 0 0" />
      <geometry>
        <box size="0.012 0.47 0.012" />
        </geometry>
      <material name="dark_brushed_steel">
        <color rgba="0.16 0.17 0.17 1" />
        </material>
      </visual>
    <visual name="rack_rail_1_0.45">
      <origin xyz="0.326 -0.045 0.445" rpy="0 0 0" />
      <geometry>
        <box size="0.012 0.47 0.012" />
        </geometry>
      <material name="dark_brushed_steel">
        <color rgba="0.16 0.17 0.17 1" />
        </material>
      </visual>
    <visual name="rack_front_frame_0.45">
      <origin xyz="0 -0.255 0.455" rpy="0 0 0" />
      <geometry>
        <box size="0.66 0.006 0.006" />
        </geometry>
      <material name="dark_brushed_steel">
        <color rgba="0.16 0.17 0.17 1" />
        </material>
      </visual>
    <visual name="rack_rear_frame_0.45">
      <origin xyz="0 0.165 0.455" rpy="0 0 0" />
      <geometry>
        <box size="0.66 0.006 0.006" />
        </geometry>
      <material name="dark_brushed_steel">
        <color rgba="0.16 0.17 0.17 1" />
        </material>
      </visual>
    <visual name="rack_wire_-0.19_0.45">
      <origin xyz="-0.19 -0.045 0.455" rpy="0 0 0" />
      <geometry>
        <box size="0.006 0.42 0.006" />
        </geometry>
      <material name="dark_brushed_steel">
        <color rgba="0.16 0.17 0.17 1" />
        </material>
      </visual>
    <visual name="rack_wire_-0.10_0.45">
      <origin xyz="-0.095 -0.045 0.455" rpy="0 0 0" />
      <geometry>
        <box size="0.006 0.42 0.006" />
        </geometry>
      <material name="dark_brushed_steel">
        <color rgba="0.16 0.17 0.17 1" />
        </material>
      </visual>
    <visual name="rack_wire_0.00_0.45">
      <origin xyz="0 -0.045 0.455" rpy="0 0 0" />
      <geometry>
        <box size="0.006 0.42 0.006" />
        </geometry>
      <material name="dark_brushed_steel">
        <color rgba="0.16 0.17 0.17 1" />
        </material>
      </visual>
    <visual name="rack_wire_0.10_0.45">
      <origin xyz="0.095 -0.045 0.455" rpy="0 0 0" />
      <geometry>
        <box size="0.006 0.42 0.006" />
        </geometry>
      <material name="dark_brushed_steel">
        <color rgba="0.16 0.17 0.17 1" />
        </material>
      </visual>
    <visual name="rack_wire_0.19_0.45">
      <origin xyz="0.19 -0.045 0.455" rpy="0 0 0" />
      <geometry>
        <box size="0.006 0.42 0.006" />
        </geometry>
      <material name="dark_brushed_steel">
        <color rgba="0.16 0.17 0.17 1" />
        </material>
      </visual>
    <visual name="cooktop_glass">
      <origin xyz="0 -0.02 0.888" rpy="0 0 0" />
      <geometry>
        <box size="0.72 0.6 0.02" />
        </geometry>
      <material name="black_enamel">
        <color rgba="0.005 0.005 0.006 1" />
        </material>
      </visual>
    <visual name="front_cooktop_lip">
      <origin xyz="0 -0.322 0.896" rpy="0 0 0" />
      <geometry>
        <box size="0.735 0.018 0.026" />
        </geometry>
      <material name="dark_brushed_steel">
        <color rgba="0.16 0.17 0.17 1" />
        </material>
      </visual>
    <visual name="rear_cooktop_lip">
      <origin xyz="0 0.294 0.896" rpy="0 0 0" />
      <geometry>
        <box size="0.735 0.018 0.026" />
        </geometry>
      <material name="dark_brushed_steel">
        <color rgba="0.16 0.17 0.17 1" />
        </material>
      </visual>
    <visual name="side_cooktop_lip_0">
      <origin xyz="-0.368 -0.02 0.896" rpy="0 0 0" />
      <geometry>
        <box size="0.018 0.6 0.026" />
        </geometry>
      <material name="dark_brushed_steel">
        <color rgba="0.16 0.17 0.17 1" />
        </material>
      </visual>
    <visual name="side_cooktop_lip_1">
      <origin xyz="0.368 -0.02 0.896" rpy="0 0 0" />
      <geometry>
        <box size="0.018 0.6 0.026" />
        </geometry>
      <material name="dark_brushed_steel">
        <color rgba="0.16 0.17 0.17 1" />
        </material>
      </visual>
    <visual name="burner_trim_0">
      <origin xyz="-0.215 -0.175 0.904" rpy="0 0 0" />
      <geometry>
        <mesh filename="assets/meshes/burner_trim_ring.obj" />
        </geometry>
      <material name="dark_brushed_steel">
        <color rgba="0.16 0.17 0.17 1" />
        </material>
      </visual>
    <visual name="burner_cap_0">
      <origin xyz="-0.215 -0.175 0.904" rpy="0 0 0" />
      <geometry>
        <cylinder radius="0.086" length="0.012" />
        </geometry>
      <material name="matte_rubber">
        <color rgba="0.035 0.035 0.035 1" />
        </material>
      </visual>
    <visual name="burner_center_0">
      <origin xyz="-0.215 -0.175 0.912" rpy="0 0 0" />
      <geometry>
        <cylinder radius="0.04128" length="0.015" />
        </geometry>
      <material name="cast_iron_black">
        <color rgba="0.015 0.014 0.013 1" />
        </material>
      </visual>
    <visual name="grate_cross_x_0">
      <origin xyz="-0.215 -0.175 0.92" rpy="0 0 0" />
      <geometry>
        <box size="0.205 0.018 0.02" />
        </geometry>
      <material name="cast_iron_black">
        <color rgba="0.015 0.014 0.013 1" />
        </material>
      </visual>
    <visual name="grate_cross_y_0">
      <origin xyz="-0.215 -0.175 0.92" rpy="0 0 0" />
      <geometry>
        <box size="0.018 0.205 0.02" />
        </geometry>
      <material name="cast_iron_black">
        <color rgba="0.015 0.014 0.013 1" />
        </material>
      </visual>
    <visual name="grate_rear_0">
      <origin xyz="-0.215 -0.095 0.92" rpy="0 0 0" />
      <geometry>
        <box size="0.11 0.014 0.018" />
        </geometry>
      <material name="cast_iron_black">
        <color rgba="0.015 0.014 0.013 1" />
        </material>
      </visual>
    <visual name="grate_front_0">
      <origin xyz="-0.215 -0.255 0.92" rpy="0 0 0" />
      <geometry>
        <box size="0.11 0.014 0.018" />
        </geometry>
      <material name="cast_iron_black">
        <color rgba="0.015 0.014 0.013 1" />
        </material>
      </visual>
    <visual name="burner_trim_1">
      <origin xyz="0.215 -0.175 0.904" rpy="0 0 0" />
      <geometry>
        <mesh filename="assets/meshes/small_burner_trim_ring.obj" />
        </geometry>
      <material name="dark_brushed_steel">
        <color rgba="0.16 0.17 0.17 1" />
        </material>
      </visual>
    <visual name="burner_cap_1">
      <origin xyz="0.215 -0.175 0.904" rpy="0 0 0" />
      <geometry>
        <cylinder radius="0.074" length="0.012" />
        </geometry>
      <material name="matte_rubber">
        <color rgba="0.035 0.035 0.035 1" />
        </material>
      </visual>
    <visual name="burner_center_1">
      <origin xyz="0.215 -0.175 0.912" rpy="0 0 0" />
      <geometry>
        <cylinder radius="0.03552" length="0.015" />
        </geometry>
      <material name="cast_iron_black">
        <color rgba="0.015 0.014 0.013 1" />
        </material>
      </visual>
    <visual name="grate_cross_x_1">
      <origin xyz="0.215 -0.175 0.92" rpy="0 0 0" />
      <geometry>
        <box size="0.205 0.018 0.02" />
        </geometry>
      <material name="cast_iron_black">
        <color rgba="0.015 0.014 0.013 1" />
        </material>
      </visual>
    <visual name="grate_cross_y_1">
      <origin xyz="0.215 -0.175 0.92" rpy="0 0 0" />
      <geometry>
        <box size="0.018 0.205 0.02" />
        </geometry>
      <material name="cast_iron_black">
        <color rgba="0.015 0.014 0.013 1" />
        </material>
      </visual>
    <visual name="grate_rear_1">
      <origin xyz="0.215 -0.095 0.92" rpy="0 0 0" />
      <geometry>
        <box size="0.11 0.014 0.018" />
        </geometry>
      <material name="cast_iron_black">
        <color rgba="0.015 0.014 0.013 1" />
        </material>
      </visual>
    <visual name="grate_front_1">
      <origin xyz="0.215 -0.255 0.92" rpy="0 0 0" />
      <geometry>
        <box size="0.11 0.014 0.018" />
        </geometry>
      <material name="cast_iron_black">
        <color rgba="0.015 0.014 0.013 1" />
        </material>
      </visual>
    <visual name="burner_trim_2">
      <origin xyz="-0.215 0.125 0.904" rpy="0 0 0" />
      <geometry>
        <mesh filename="assets/meshes/small_burner_trim_ring.obj" />
        </geometry>
      <material name="dark_brushed_steel">
        <color rgba="0.16 0.17 0.17 1" />
        </material>
      </visual>
    <visual name="burner_cap_2">
      <origin xyz="-0.215 0.125 0.904" rpy="0 0 0" />
      <geometry>
        <cylinder radius="0.066" length="0.012" />
        </geometry>
      <material name="matte_rubber">
        <color rgba="0.035 0.035 0.035 1" />
        </material>
      </visual>
    <visual name="burner_center_2">
      <origin xyz="-0.215 0.125 0.912" rpy="0 0 0" />
      <geometry>
        <cylinder radius="0.03168" length="0.015" />
        </geometry>
      <material name="cast_iron_black">
        <color rgba="0.015 0.014 0.013 1" />
        </material>
      </visual>
    <visual name="grate_cross_x_2">
      <origin xyz="-0.215 0.125 0.92" rpy="0 0 0" />
      <geometry>
        <box size="0.205 0.018 0.02" />
        </geometry>
      <material name="cast_iron_black">
        <color rgba="0.015 0.014 0.013 1" />
        </material>
      </visual>
    <visual name="grate_cross_y_2">
      <origin xyz="-0.215 0.125 0.92" rpy="0 0 0" />
      <geometry>
        <box size="0.018 0.205 0.02" />
        </geometry>
      <material name="cast_iron_black">
        <color rgba="0.015 0.014 0.013 1" />
        </material>
      </visual>
    <visual name="grate_rear_2">
      <origin xyz="-0.215 0.205 0.92" rpy="0 0 0" />
      <geometry>
        <box size="0.11 0.014 0.018" />
        </geometry>
      <material name="cast_iron_black">
        <color rgba="0.015 0.014 0.013 1" />
        </material>
      </visual>
    <visual name="grate_front_2">
      <origin xyz="-0.215 0.045 0.92" rpy="0 0 0" />
      <geometry>
        <box size="0.11 0.014 0.018" />
        </geometry>
      <material name="cast_iron_black">
        <color rgba="0.015 0.014 0.013 1" />
        </material>
      </visual>
    <visual name="burner_trim_3">
      <origin xyz="0.215 0.125 0.904" rpy="0 0 0" />
      <geometry>
        <mesh filename="assets/meshes/burner_trim_ring.obj" />
        </geometry>
      <material name="dark_brushed_steel">
        <color rgba="0.16 0.17 0.17 1" />
        </material>
      </visual>
    <visual name="burner_cap_3">
      <origin xyz="0.215 0.125 0.904" rpy="0 0 0" />
      <geometry>
        <cylinder radius="0.09" length="0.012" />
        </geometry>
      <material name="matte_rubber">
        <color rgba="0.035 0.035 0.035 1" />
        </material>
      </visual>
    <visual name="burner_center_3">
      <origin xyz="0.215 0.125 0.912" rpy="0 0 0" />
      <geometry>
        <cylinder radius="0.0432" length="0.015" />
        </geometry>
      <material name="cast_iron_black">
        <color rgba="0.015 0.014 0.013 1" />
        </material>
      </visual>
    <visual name="grate_cross_x_3">
      <origin xyz="0.215 0.125 0.92" rpy="0 0 0" />
      <geometry>
        <box size="0.205 0.018 0.02" />
        </geometry>
      <material name="cast_iron_black">
        <color rgba="0.015 0.014 0.013 1" />
        </material>
      </visual>
    <visual name="grate_cross_y_3">
      <origin xyz="0.215 0.125 0.92" rpy="0 0 0" />
      <geometry>
        <box size="0.018 0.205 0.02" />
        </geometry>
      <material name="cast_iron_black">
        <color rgba="0.015 0.014 0.013 1" />
        </material>
      </visual>
    <visual name="grate_rear_3">
      <origin xyz="0.215 0.205 0.92" rpy="0 0 0" />
      <geometry>
        <box size="0.11 0.014 0.018" />
        </geometry>
      <material name="cast_iron_black">
        <color rgba="0.015 0.014 0.013 1" />
        </material>
      </visual>
    <visual name="grate_front_3">
      <origin xyz="0.215 0.045 0.92" rpy="0 0 0" />
      <geometry>
        <box size="0.11 0.014 0.018" />
        </geometry>
      <material name="cast_iron_black">
        <color rgba="0.015 0.014 0.013 1" />
        </material>
      </visual>
    <visual name="backguard_panel">
      <origin xyz="0 0.316 1" rpy="0 0 0" />
      <geometry>
        <box size="0.76 0.045 0.21" />
        </geometry>
      <material name="brushed_stainless">
        <color rgba="0.62 0.64 0.63 1" />
        </material>
      </visual>
    <visual name="backguard_foot">
      <origin xyz="0 0.291 0.887" rpy="0 0 0" />
      <geometry>
        <box size="0.72 0.012 0.02" />
        </geometry>
      <material name="dark_brushed_steel">
        <color rgba="0.16 0.17 0.17 1" />
        </material>
      </visual>
    <visual name="display_bezel">
      <origin xyz="0 -0.393 0.798" rpy="1.5708 0 0" />
      <geometry>
        <mesh filename="assets/meshes/display_bezel.obj" />
        </geometry>
      <material name="dark_brushed_steel">
        <color rgba="0.16 0.17 0.17 1" />
        </material>
      </visual>
    <visual name="display_lens">
      <origin xyz="0 -0.394 0.798" rpy="0 0 0" />
      <geometry>
        <box size="0.145 0.007 0.038" />
        </geometry>
      <material name="smoked_oven_glass">
        <color rgba="0.02 0.025 0.03 0.72" />
        </material>
      </visual>
    <visual name="display_segment_-0.04">
      <origin xyz="-0.042 -0.396 0.798" rpy="0 0 0" />
      <geometry>
        <box size="0.012 0.004 0.018" />
        </geometry>
      <material name="amber_display">
        <color rgba="1 0.46 0.08 1" />
        </material>
      </visual>
    <visual name="display_segment_-0.02">
      <origin xyz="-0.018 -0.396 0.798" rpy="0 0 0" />
      <geometry>
        <box size="0.012 0.004 0.018" />
        </geometry>
      <material name="amber_display">
        <color rgba="1 0.46 0.08 1" />
        </material>
      </visual>
    <visual name="display_segment_0.01">
      <origin xyz="0.006 -0.396 0.798" rpy="0 0 0" />
      <geometry>
        <box size="0.012 0.004 0.018" />
        </geometry>
      <material name="amber_display">
        <color rgba="1 0.46 0.08 1" />
        </material>
      </visual>
    <visual name="display_segment_0.03">
      <origin xyz="0.03 -0.396 0.798" rpy="0 0 0" />
      <geometry>
        <box size="0.012 0.004 0.018" />
        </geometry>
      <material name="amber_display">
        <color rgba="1 0.46 0.08 1" />
        </material>
      </visual>
    <visual name="knob_tick_0_0">
      <origin xyz="-0.3 -0.3905 0.74" rpy="0 0 0" />
      <geometry>
        <box size="0.006 0.004 0.018" />
        </geometry>
      <material name="white_silk_screen">
        <color rgba="0.92 0.91 0.86 1" />
        </material>
      </visual>
    <visual name="knob_tick_0_-36">
      <origin xyz="-0.320572 -0.3905 0.733316" rpy="0 0 -0.628319" />
      <geometry>
        <box size="0.006 0.004 0.012" />
        </geometry>
      <material name="white_silk_screen">
        <color rgba="0.92 0.91 0.86 1" />
        </material>
      </visual>
    <visual name="knob_tick_0_36">
      <origin xyz="-0.279428 -0.3905 0.733316" rpy="0 0 0.628319" />
      <geometry>
        <box size="0.006 0.004 0.012" />
        </geometry>
      <material name="white_silk_screen">
        <color rgba="0.92 0.91 0.86 1" />
        </material>
      </visual>
    <visual name="knob_tick_1_0">
      <origin xyz="-0.18 -0.3905 0.74" rpy="0 0 0" />
      <geometry>
        <box size="0.006 0.004 0.018" />
        </geometry>
      <material name="white_silk_screen">
        <color rgba="0.92 0.91 0.86 1" />
        </material>
      </visual>
    <visual name="knob_tick_1_-36">
      <origin xyz="-0.200572 -0.3905 0.733316" rpy="0 0 -0.628319" />
      <geometry>
        <box size="0.006 0.004 0.012" />
        </geometry>
      <material name="white_silk_screen">
        <color rgba="0.92 0.91 0.86 1" />
        </material>
      </visual>
    <visual name="knob_tick_1_36">
      <origin xyz="-0.159428 -0.3905 0.733316" rpy="0 0 0.628319" />
      <geometry>
        <box size="0.006 0.004 0.012" />
        </geometry>
      <material name="white_silk_screen">
        <color rgba="0.92 0.91 0.86 1" />
        </material>
      </visual>
    <visual name="knob_tick_2_0">
      <origin xyz="-0.06 -0.3905 0.74" rpy="0 0 0" />
      <geometry>
        <box size="0.006 0.004 0.018" />
        </geometry>
      <material name="white_silk_screen">
        <color rgba="0.92 0.91 0.86 1" />
        </material>
      </visual>
    <visual name="knob_tick_2_-36">
      <origin xyz="-0.0805725 -0.3905 0.733316" rpy="0 0 -0.628319" />
      <geometry>
        <box size="0.006 0.004 0.012" />
        </geometry>
      <material name="white_silk_screen">
        <color rgba="0.92 0.91 0.86 1" />
        </material>
      </visual>
    <visual name="knob_tick_2_36">
      <origin xyz="-0.0394275 -0.3905 0.733316" rpy="0 0 0.628319" />
      <geometry>
        <box size="0.006 0.004 0.012" />
        </geometry>
      <material name="white_silk_screen">
        <color rgba="0.92 0.91 0.86 1" />
        </material>
      </visual>
    <visual name="knob_tick_3_0">
      <origin xyz="0.18 -0.3905 0.74" rpy="0 0 0" />
      <geometry>
        <box size="0.006 0.004 0.018" />
        </geometry>
      <material name="white_silk_screen">
        <color rgba="0.92 0.91 0.86 1" />
        </material>
      </visual>
    <visual name="knob_tick_3_-36">
      <origin xyz="0.159428 -0.3905 0.733316" rpy="0 0 -0.628319" />
      <geometry>
        <box size="0.006 0.004 0.012" />
        </geometry>
      <material name="white_silk_screen">
        <color rgba="0.92 0.91 0.86 1" />
        </material>
      </visual>
    <visual name="knob_tick_3_36">
      <origin xyz="0.200572 -0.3905 0.733316" rpy="0 0 0.628319" />
      <geometry>
        <box size="0.006 0.004 0.012" />
        </geometry>
      <material name="white_silk_screen">
        <color rgba="0.92 0.91 0.86 1" />
        </material>
      </visual>
    <visual name="knob_tick_4_0">
      <origin xyz="0.3 -0.3905 0.74" rpy="0 0 0" />
      <geometry>
        <box size="0.006 0.004 0.018" />
        </geometry>
      <material name="white_silk_screen">
        <color rgba="0.92 0.91 0.86 1" />
        </material>
      </visual>
    <visual name="knob_tick_4_-36">
      <origin xyz="0.279428 -0.3905 0.733316" rpy="0 0 -0.628319" />
      <geometry>
        <box size="0.006 0.004 0.012" />
        </geometry>
      <material name="white_silk_screen">
        <color rgba="0.92 0.91 0.86 1" />
        </material>
      </visual>
    <visual name="knob_tick_4_36">
      <origin xyz="0.320572 -0.3905 0.733316" rpy="0 0 0.628319" />
      <geometry>
        <box size="0.006 0.004 0.012" />
        </geometry>
      <material name="white_silk_screen">
        <color rgba="0.92 0.91 0.86 1" />
        </material>
      </visual>
    <visual name="body_hinge_receiver_-0.24">
      <origin xyz="-0.245 -0.397 0.143" rpy="0 0 0" />
      <geometry>
        <box size="0.082 0.014 0.044" />
        </geometry>
      <material name="dark_brushed_steel">
        <color rgba="0.16 0.17 0.17 1" />
        </material>
      </visual>
    <visual name="body_hinge_receiver_0.24">
      <origin xyz="0.245 -0.397 0.143" rpy="0 0 0" />
      <geometry>
        <box size="0.082 0.014 0.044" />
        </geometry>
      <material name="dark_brushed_steel">
        <color rgba="0.16 0.17 0.17 1" />
        </material>
      </visual>
    <collision name="side_panel_0">
      <origin xyz="-0.362 -0.02 0.46" rpy="0 0 0" />
      <geometry>
        <box size="0.036 0.66 0.82" />
        </geometry>
      </collision>
    <collision name="side_panel_1">
      <origin xyz="0.362 -0.02 0.46" rpy="0 0 0" />
      <geometry>
        <box size="0.036 0.66 0.82" />
        </geometry>
      </collision>
    <collision name="rear_panel">
      <origin xyz="0 0.292 0.46" rpy="0 0 0" />
      <geometry>
        <box size="0.76 0.036 0.82" />
        </geometry>
      </collision>
    <collision name="bottom_pan">
      <origin xyz="0 -0.02 0.033" rpy="0 0 0" />
      <geometry>
        <box size="0.76 0.66 0.065" />
        </geometry>
      </collision>
    <collision name="top_deck">
      <origin xyz="0 -0.02 0.851" rpy="0 0 0" />
      <geometry>
        <box size="0.76 0.66 0.058" />
        </geometry>
      </collision>
    <collision name="front_stile_0">
      <origin xyz="-0.35 -0.366 0.395" rpy="0 0 0" />
      <geometry>
        <box size="0.06 0.055 0.555" />
        </geometry>
      </collision>
    <collision name="front_stile_1">
      <origin xyz="0.35 -0.366 0.395" rpy="0 0 0" />
      <geometry>
        <box size="0.06 0.055 0.555" />
        </geometry>
      </collision>
    <collision name="upper_oven_rail">
      <origin xyz="0 -0.366 0.654" rpy="0 0 0" />
      <geometry>
        <box size="0.76 0.055 0.052" />
        </geometry>
      </collision>
    <collision name="lower_oven_rail">
      <origin xyz="0 -0.366 0.129" rpy="0 0 0" />
      <geometry>
        <box size="0.76 0.055 0.064" />
        </geometry>
      </collision>
    <collision name="toe_kick">
      <origin xyz="0 -0.37 0.073" rpy="0 0 0" />
      <geometry>
        <box size="0.76 0.06 0.095" />
        </geometry>
      </collision>
    <collision name="control_fascia">
      <origin xyz="0 -0.37 0.745" rpy="0 0 0" />
      <geometry>
        <box size="0.76 0.042 0.178" />
        </geometry>
      </collision>
    <collision name="upper_trim">
      <origin xyz="0 -0.395 0.838" rpy="0 0 0" />
      <geometry>
        <box size="0.735 0.01 0.02" />
        </geometry>
      </collision>
    <collision name="lower_trim">
      <origin xyz="0 -0.395 0.66" rpy="0 0 0" />
      <geometry>
        <box size="0.735 0.01 0.018" />
        </geometry>
      </collision>
    <collision name="oven_back_liner">
      <origin xyz="0 0.257 0.375" rpy="0 0 0" />
      <geometry>
        <box size="0.7 0.04 0.43" />
        </geometry>
      </collision>
    <collision name="oven_liner_0">
      <origin xyz="-0.335 -0.04 0.375" rpy="0 0 0" />
      <geometry>
        <box size="0.026 0.52 0.43" />
        </geometry>
      </collision>
    <collision name="oven_liner_1">
      <origin xyz="0.335 -0.04 0.375" rpy="0 0 0" />
      <geometry>
        <box size="0.026 0.52 0.43" />
        </geometry>
      </collision>
    <collision name="oven_floor">
      <origin xyz="0 -0.04 0.165" rpy="0 0 0" />
      <geometry>
        <box size="0.7 0.52 0.018" />
        </geometry>
      </collision>
    <collision name="oven_ceiling">
      <origin xyz="0 -0.04 0.585" rpy="0 0 0" />
      <geometry>
        <box size="0.7 0.52 0.018" />
        </geometry>
      </collision>
    <collision name="rack_rail_0_0.29">
      <origin xyz="-0.326 -0.045 0.295" rpy="0 0 0" />
      <geometry>
        <box size="0.012 0.47 0.012" />
        </geometry>
      </collision>
    <collision name="rack_rail_1_0.29">
      <origin xyz="0.326 -0.045 0.295" rpy="0 0 0" />
      <geometry>
        <box size="0.012 0.47 0.012" />
        </geometry>
      </collision>
    <collision name="rack_front_frame_0.29">
      <origin xyz="0 -0.255 0.305" rpy="0 0 0" />
      <geometry>
        <box size="0.66 0.006 0.006" />
        </geometry>
      </collision>
    <collision name="rack_rear_frame_0.29">
      <origin xyz="0 0.165 0.305" rpy="0 0 0" />
      <geometry>
        <box size="0.66 0.006 0.006" />
        </geometry>
      </collision>
    <collision name="rack_wire_-0.19_0.29">
      <origin xyz="-0.19 -0.045 0.305" rpy="0 0 0" />
      <geometry>
        <box size="0.006 0.42 0.006" />
        </geometry>
      </collision>
    <collision name="rack_wire_-0.10_0.29">
      <origin xyz="-0.095 -0.045 0.305" rpy="0 0 0" />
      <geometry>
        <box size="0.006 0.42 0.006" />
        </geometry>
      </collision>
    <collision name="rack_wire_0.00_0.29">
      <origin xyz="0 -0.045 0.305" rpy="0 0 0" />
      <geometry>
        <box size="0.006 0.42 0.006" />
        </geometry>
      </collision>
    <collision name="rack_wire_0.10_0.29">
      <origin xyz="0.095 -0.045 0.305" rpy="0 0 0" />
      <geometry>
        <box size="0.006 0.42 0.006" />
        </geometry>
      </collision>
    <collision name="rack_wire_0.19_0.29">
      <origin xyz="0.19 -0.045 0.305" rpy="0 0 0" />
      <geometry>
        <box size="0.006 0.42 0.006" />
        </geometry>
      </collision>
    <collision name="rack_rail_0_0.45">
      <origin xyz="-0.326 -0.045 0.445" rpy="0 0 0" />
      <geometry>
        <box size="0.012 0.47 0.012" />
        </geometry>
      </collision>
    <collision name="rack_rail_1_0.45">
      <origin xyz="0.326 -0.045 0.445" rpy="0 0 0" />
      <geometry>
        <box size="0.012 0.47 0.012" />
        </geometry>
      </collision>
    <collision name="rack_front_frame_0.45">
      <origin xyz="0 -0.255 0.455" rpy="0 0 0" />
      <geometry>
        <box size="0.66 0.006 0.006" />
        </geometry>
      </collision>
    <collision name="rack_rear_frame_0.45">
      <origin xyz="0 0.165 0.455" rpy="0 0 0" />
      <geometry>
        <box size="0.66 0.006 0.006" />
        </geometry>
      </collision>
    <collision name="rack_wire_-0.19_0.45">
      <origin xyz="-0.19 -0.045 0.455" rpy="0 0 0" />
      <geometry>
        <box size="0.006 0.42 0.006" />
        </geometry>
      </collision>
    <collision name="rack_wire_-0.10_0.45">
      <origin xyz="-0.095 -0.045 0.455" rpy="0 0 0" />
      <geometry>
        <box size="0.006 0.42 0.006" />
        </geometry>
      </collision>
    <collision name="rack_wire_0.00_0.45">
      <origin xyz="0 -0.045 0.455" rpy="0 0 0" />
      <geometry>
        <box size="0.006 0.42 0.006" />
        </geometry>
      </collision>
    <collision name="rack_wire_0.10_0.45">
      <origin xyz="0.095 -0.045 0.455" rpy="0 0 0" />
      <geometry>
        <box size="0.006 0.42 0.006" />
        </geometry>
      </collision>
    <collision name="rack_wire_0.19_0.45">
      <origin xyz="0.19 -0.045 0.455" rpy="0 0 0" />
      <geometry>
        <box size="0.006 0.42 0.006" />
        </geometry>
      </collision>
    <collision name="cooktop_glass">
      <origin xyz="0 -0.02 0.888" rpy="0 0 0" />
      <geometry>
        <box size="0.72 0.6 0.02" />
        </geometry>
      </collision>
    <collision name="front_cooktop_lip">
      <origin xyz="0 -0.322 0.896" rpy="0 0 0" />
      <geometry>
        <box size="0.735 0.018 0.026" />
        </geometry>
      </collision>
    <collision name="rear_cooktop_lip">
      <origin xyz="0 0.294 0.896" rpy="0 0 0" />
      <geometry>
        <box size="0.735 0.018 0.026" />
        </geometry>
      </collision>
    <collision name="side_cooktop_lip_0">
      <origin xyz="-0.368 -0.02 0.896" rpy="0 0 0" />
      <geometry>
        <box size="0.018 0.6 0.026" />
        </geometry>
      </collision>
    <collision name="side_cooktop_lip_1">
      <origin xyz="0.368 -0.02 0.896" rpy="0 0 0" />
      <geometry>
        <box size="0.018 0.6 0.026" />
        </geometry>
      </collision>
    <collision name="burner_trim_0">
      <origin xyz="-0.215 -0.175 0.904" rpy="0 0 0" />
      <geometry>
        <mesh filename="assets/meshes/burner_trim_ring.obj" />
        </geometry>
      </collision>
    <collision name="burner_cap_0">
      <origin xyz="-0.215 -0.175 0.904" rpy="0 0 0" />
      <geometry>
        <cylinder radius="0.086" length="0.012" />
        </geometry>
      </collision>
    <collision name="burner_center_0">
      <origin xyz="-0.215 -0.175 0.912" rpy="0 0 0" />
      <geometry>
        <cylinder radius="0.04128" length="0.015" />
        </geometry>
      </collision>
    <collision name="grate_cross_x_0">
      <origin xyz="-0.215 -0.175 0.92" rpy="0 0 0" />
      <geometry>
        <box size="0.205 0.018 0.02" />
        </geometry>
      </collision>
    <collision name="grate_cross_y_0">
      <origin xyz="-0.215 -0.175 0.92" rpy="0 0 0" />
      <geometry>
        <box size="0.018 0.205 0.02" />
        </geometry>
      </collision>
    <collision name="grate_rear_0">
      <origin xyz="-0.215 -0.095 0.92" rpy="0 0 0" />
      <geometry>
        <box size="0.11 0.014 0.018" />
        </geometry>
      </collision>
    <collision name="grate_front_0">
      <origin xyz="-0.215 -0.255 0.92" rpy="0 0 0" />
      <geometry>
        <box size="0.11 0.014 0.018" />
        </geometry>
      </collision>
    <collision name="burner_trim_1">
      <origin xyz="0.215 -0.175 0.904" rpy="0 0 0" />
      <geometry>
        <mesh filename="assets/meshes/small_burner_trim_ring.obj" />
        </geometry>
      </collision>
    <collision name="burner_cap_1">
      <origin xyz="0.215 -0.175 0.904" rpy="0 0 0" />
      <geometry>
        <cylinder radius="0.074" length="0.012" />
        </geometry>
      </collision>
    <collision name="burner_center_1">
      <origin xyz="0.215 -0.175 0.912" rpy="0 0 0" />
      <geometry>
        <cylinder radius="0.03552" length="0.015" />
        </geometry>
      </collision>
    <collision name="grate_cross_x_1">
      <origin xyz="0.215 -0.175 0.92" rpy="0 0 0" />
      <geometry>
        <box size="0.205 0.018 0.02" />
        </geometry>
      </collision>
    <collision name="grate_cross_y_1">
      <origin xyz="0.215 -0.175 0.92" rpy="0 0 0" />
      <geometry>
        <box size="0.018 0.205 0.02" />
        </geometry>
      </collision>
    <collision name="grate_rear_1">
      <origin xyz="0.215 -0.095 0.92" rpy="0 0 0" />
      <geometry>
        <box size="0.11 0.014 0.018" />
        </geometry>
      </collision>
    <collision name="grate_front_1">
      <origin xyz="0.215 -0.255 0.92" rpy="0 0 0" />
      <geometry>
        <box size="0.11 0.014 0.018" />
        </geometry>
      </collision>
    <collision name="burner_trim_2">
      <origin xyz="-0.215 0.125 0.904" rpy="0 0 0" />
      <geometry>
        <mesh filename="assets/meshes/small_burner_trim_ring.obj" />
        </geometry>
      </collision>
    <collision name="burner_cap_2">
      <origin xyz="-0.215 0.125 0.904" rpy="0 0 0" />
      <geometry>
        <cylinder radius="0.066" length="0.012" />
        </geometry>
      </collision>
    <collision name="burner_center_2">
      <origin xyz="-0.215 0.125 0.912" rpy="0 0 0" />
      <geometry>
        <cylinder radius="0.03168" length="0.015" />
        </geometry>
      </collision>
    <collision name="grate_cross_x_2">
      <origin xyz="-0.215 0.125 0.92" rpy="0 0 0" />
      <geometry>
        <box size="0.205 0.018 0.02" />
        </geometry>
      </collision>
    <collision name="grate_cross_y_2">
      <origin xyz="-0.215 0.125 0.92" rpy="0 0 0" />
      <geometry>
        <box size="0.018 0.205 0.02" />
        </geometry>
      </collision>
    <collision name="grate_rear_2">
      <origin xyz="-0.215 0.205 0.92" rpy="0 0 0" />
      <geometry>
        <box size="0.11 0.014 0.018" />
        </geometry>
      </collision>
    <collision name="grate_front_2">
      <origin xyz="-0.215 0.045 0.92" rpy="0 0 0" />
      <geometry>
        <box size="0.11 0.014 0.018" />
        </geometry>
      </collision>
    <collision name="burner_trim_3">
      <origin xyz="0.215 0.125 0.904" rpy="0 0 0" />
      <geometry>
        <mesh filename="assets/meshes/burner_trim_ring.obj" />
        </geometry>
      </collision>
    <collision name="burner_cap_3">
      <origin xyz="0.215 0.125 0.904" rpy="0 0 0" />
      <geometry>
        <cylinder radius="0.09" length="0.012" />
        </geometry>
      </collision>
    <collision name="burner_center_3">
      <origin xyz="0.215 0.125 0.912" rpy="0 0 0" />
      <geometry>
        <cylinder radius="0.0432" length="0.015" />
        </geometry>
      </collision>
    <collision name="grate_cross_x_3">
      <origin xyz="0.215 0.125 0.92" rpy="0 0 0" />
      <geometry>
        <box size="0.205 0.018 0.02" />
        </geometry>
      </collision>
    <collision name="grate_cross_y_3">
      <origin xyz="0.215 0.125 0.92" rpy="0 0 0" />
      <geometry>
        <box size="0.018 0.205 0.02" />
        </geometry>
      </collision>
    <collision name="grate_rear_3">
      <origin xyz="0.215 0.205 0.92" rpy="0 0 0" />
      <geometry>
        <box size="0.11 0.014 0.018" />
        </geometry>
      </collision>
    <collision name="grate_front_3">
      <origin xyz="0.215 0.045 0.92" rpy="0 0 0" />
      <geometry>
        <box size="0.11 0.014 0.018" />
        </geometry>
      </collision>
    <collision name="backguard_panel">
      <origin xyz="0 0.316 1" rpy="0 0 0" />
      <geometry>
        <box size="0.76 0.045 0.21" />
        </geometry>
      </collision>
    <collision name="backguard_foot">
      <origin xyz="0 0.291 0.887" rpy="0 0 0" />
      <geometry>
        <box size="0.72 0.012 0.02" />
        </geometry>
      </collision>
    <collision name="display_bezel">
      <origin xyz="0 -0.393 0.798" rpy="1.5708 0 0" />
      <geometry>
        <mesh filename="assets/meshes/display_bezel.obj" />
        </geometry>
      </collision>
    <collision name="display_lens">
      <origin xyz="0 -0.394 0.798" rpy="0 0 0" />
      <geometry>
        <box size="0.145 0.007 0.038" />
        </geometry>
      </collision>
    <collision name="display_segment_-0.04">
      <origin xyz="-0.042 -0.396 0.798" rpy="0 0 0" />
      <geometry>
        <box size="0.012 0.004 0.018" />
        </geometry>
      </collision>
    <collision name="display_segment_-0.02">
      <origin xyz="-0.018 -0.396 0.798" rpy="0 0 0" />
      <geometry>
        <box size="0.012 0.004 0.018" />
        </geometry>
      </collision>
    <collision name="display_segment_0.01">
      <origin xyz="0.006 -0.396 0.798" rpy="0 0 0" />
      <geometry>
        <box size="0.012 0.004 0.018" />
        </geometry>
      </collision>
    <collision name="display_segment_0.03">
      <origin xyz="0.03 -0.396 0.798" rpy="0 0 0" />
      <geometry>
        <box size="0.012 0.004 0.018" />
        </geometry>
      </collision>
    <collision name="knob_tick_0_0">
      <origin xyz="-0.3 -0.3905 0.74" rpy="0 0 0" />
      <geometry>
        <box size="0.006 0.004 0.018" />
        </geometry>
      </collision>
    <collision name="knob_tick_0_-36">
      <origin xyz="-0.320572 -0.3905 0.733316" rpy="0 0 -0.628319" />
      <geometry>
        <box size="0.006 0.004 0.012" />
        </geometry>
      </collision>
    <collision name="knob_tick_0_36">
      <origin xyz="-0.279428 -0.3905 0.733316" rpy="0 0 0.628319" />
      <geometry>
        <box size="0.006 0.004 0.012" />
        </geometry>
      </collision>
    <collision name="knob_tick_1_0">
      <origin xyz="-0.18 -0.3905 0.74" rpy="0 0 0" />
      <geometry>
        <box size="0.006 0.004 0.018" />
        </geometry>
      </collision>
    <collision name="knob_tick_1_-36">
      <origin xyz="-0.200572 -0.3905 0.733316" rpy="0 0 -0.628319" />
      <geometry>
        <box size="0.006 0.004 0.012" />
        </geometry>
      </collision>
    <collision name="knob_tick_1_36">
      <origin xyz="-0.159428 -0.3905 0.733316" rpy="0 0 0.628319" />
      <geometry>
        <box size="0.006 0.004 0.012" />
        </geometry>
      </collision>
    <collision name="knob_tick_2_0">
      <origin xyz="-0.06 -0.3905 0.74" rpy="0 0 0" />
      <geometry>
        <box size="0.006 0.004 0.018" />
        </geometry>
      </collision>
    <collision name="knob_tick_2_-36">
      <origin xyz="-0.0805725 -0.3905 0.733316" rpy="0 0 -0.628319" />
      <geometry>
        <box size="0.006 0.004 0.012" />
        </geometry>
      </collision>
    <collision name="knob_tick_2_36">
      <origin xyz="-0.0394275 -0.3905 0.733316" rpy="0 0 0.628319" />
      <geometry>
        <box size="0.006 0.004 0.012" />
        </geometry>
      </collision>
    <collision name="knob_tick_3_0">
      <origin xyz="0.18 -0.3905 0.74" rpy="0 0 0" />
      <geometry>
        <box size="0.006 0.004 0.018" />
        </geometry>
      </collision>
    <collision name="knob_tick_3_-36">
      <origin xyz="0.159428 -0.3905 0.733316" rpy="0 0 -0.628319" />
      <geometry>
        <box size="0.006 0.004 0.012" />
        </geometry>
      </collision>
    <collision name="knob_tick_3_36">
      <origin xyz="0.200572 -0.3905 0.733316" rpy="0 0 0.628319" />
      <geometry>
        <box size="0.006 0.004 0.012" />
        </geometry>
      </collision>
    <collision name="knob_tick_4_0">
      <origin xyz="0.3 -0.3905 0.74" rpy="0 0 0" />
      <geometry>
        <box size="0.006 0.004 0.018" />
        </geometry>
      </collision>
    <collision name="knob_tick_4_-36">
      <origin xyz="0.279428 -0.3905 0.733316" rpy="0 0 -0.628319" />
      <geometry>
        <box size="0.006 0.004 0.012" />
        </geometry>
      </collision>
    <collision name="knob_tick_4_36">
      <origin xyz="0.320572 -0.3905 0.733316" rpy="0 0 0.628319" />
      <geometry>
        <box size="0.006 0.004 0.012" />
        </geometry>
      </collision>
    <collision name="body_hinge_receiver_-0.24">
      <origin xyz="-0.245 -0.397 0.143" rpy="0 0 0" />
      <geometry>
        <box size="0.082 0.014 0.044" />
        </geometry>
      </collision>
    <collision name="body_hinge_receiver_0.24">
      <origin xyz="0.245 -0.397 0.143" rpy="0 0 0" />
      <geometry>
        <box size="0.082 0.014 0.044" />
        </geometry>
      </collision>
    </link>
  <link name="oven_door">
    <visual name="door_slab">
      <origin xyz="0 -0.035 0.27" rpy="0 0 0" />
      <geometry>
        <box size="0.655 0.046 0.5" />
        </geometry>
      <material name="brushed_stainless">
        <color rgba="0.62 0.64 0.63 1" />
        </material>
      </visual>
    <visual name="window_bezel">
      <origin xyz="0 -0.06 0.33" rpy="1.5708 0 0" />
      <geometry>
        <mesh filename="assets/meshes/oven_window_bezel.obj" />
        </geometry>
      <material name="dark_brushed_steel">
        <color rgba="0.16 0.17 0.17 1" />
        </material>
      </visual>
    <visual name="window_glass">
      <origin xyz="0 -0.066 0.33" rpy="0 0 0" />
      <geometry>
        <box size="0.384 0.006 0.228" />
        </geometry>
      <material name="smoked_oven_glass">
        <color rgba="0.02 0.025 0.03 0.72" />
        </material>
      </visual>
    <visual name="upper_door_trim">
      <origin xyz="0 -0.062 0.505" rpy="0 0 0" />
      <geometry>
        <box size="0.59 0.012 0.024" />
        </geometry>
      <material name="dark_brushed_steel">
        <color rgba="0.16 0.17 0.17 1" />
        </material>
      </visual>
    <visual name="lower_door_trim">
      <origin xyz="0 -0.062 0.047" rpy="0 0 0" />
      <geometry>
        <box size="0.59 0.012 0.022" />
        </geometry>
      <material name="dark_brushed_steel">
        <color rgba="0.16 0.17 0.17 1" />
        </material>
      </visual>
    <visual name="door_handle_bar">
      <origin xyz="0 -0.087 0.474" rpy="0 1.5708 0" />
      <geometry>
        <cylinder radius="0.018" length="0.545" />
        </geometry>
      <material name="dark_brushed_steel">
        <color rgba="0.16 0.17 0.17 1" />
        </material>
      </visual>
    <visual name="handle_standoff_-0.24">
      <origin xyz="-0.245 -0.063 0.474" rpy="0 0 0" />
      <geometry>
        <box size="0.046 0.052 0.05" />
        </geometry>
      <material name="dark_brushed_steel">
        <color rgba="0.16 0.17 0.17 1" />
        </material>
      </visual>
    <visual name="door_hinge_knuckle_-0.24">
      <origin xyz="-0.245 -0.024 0.02" rpy="0 1.5708 0" />
      <geometry>
        <cylinder radius="0.014" length="0.08" />
        </geometry>
      <material name="dark_brushed_steel">
        <color rgba="0.16 0.17 0.17 1" />
        </material>
      </visual>
    <visual name="handle_standoff_0.24">
      <origin xyz="0.245 -0.063 0.474" rpy="0 0 0" />
      <geometry>
        <box size="0.046 0.052 0.05" />
        </geometry>
      <material name="dark_brushed_steel">
        <color rgba="0.16 0.17 0.17 1" />
        </material>
      </visual>
    <visual name="door_hinge_knuckle_0.24">
      <origin xyz="0.245 -0.024 0.02" rpy="0 1.5708 0" />
      <geometry>
        <cylinder radius="0.014" length="0.08" />
        </geometry>
      <material name="dark_brushed_steel">
        <color rgba="0.16 0.17 0.17 1" />
        </material>
      </visual>
    <collision name="door_slab">
      <origin xyz="0 -0.035 0.27" rpy="0 0 0" />
      <geometry>
        <box size="0.655 0.046 0.5" />
        </geometry>
      </collision>
    <collision name="window_bezel">
      <origin xyz="0 -0.06 0.33" rpy="1.5708 0 0" />
      <geometry>
        <mesh filename="assets/meshes/oven_window_bezel.obj" />
        </geometry>
      </collision>
    <collision name="window_glass">
      <origin xyz="0 -0.066 0.33" rpy="0 0 0" />
      <geometry>
        <box size="0.384 0.006 0.228" />
        </geometry>
      </collision>
    <collision name="upper_door_trim">
      <origin xyz="0 -0.062 0.505" rpy="0 0 0" />
      <geometry>
        <box size="0.59 0.012 0.024" />
        </geometry>
      </collision>
    <collision name="lower_door_trim">
      <origin xyz="0 -0.062 0.047" rpy="0 0 0" />
      <geometry>
        <box size="0.59 0.012 0.022" />
        </geometry>
      </collision>
    <collision name="door_handle_bar">
      <origin xyz="0 -0.087 0.474" rpy="0 1.5708 0" />
      <geometry>
        <cylinder radius="0.018" length="0.545" />
        </geometry>
      </collision>
    <collision name="handle_standoff_-0.24">
      <origin xyz="-0.245 -0.063 0.474" rpy="0 0 0" />
      <geometry>
        <box size="0.046 0.052 0.05" />
        </geometry>
      </collision>
    <collision name="door_hinge_knuckle_-0.24">
      <origin xyz="-0.245 -0.024 0.02" rpy="0 1.5708 0" />
      <geometry>
        <cylinder radius="0.014" length="0.08" />
        </geometry>
      </collision>
    <collision name="handle_standoff_0.24">
      <origin xyz="0.245 -0.063 0.474" rpy="0 0 0" />
      <geometry>
        <box size="0.046 0.052 0.05" />
        </geometry>
      </collision>
    <collision name="door_hinge_knuckle_0.24">
      <origin xyz="0.245 -0.024 0.02" rpy="0 1.5708 0" />
      <geometry>
        <cylinder radius="0.014" length="0.08" />
        </geometry>
      </collision>
    </link>
  <link name="knob_0">
    <visual name="knob_cap">
      <geometry>
        <mesh filename="assets/meshes/front_range_knob.obj" />
        </geometry>
      <material name="dark_brushed_steel">
        <color rgba="0.16 0.17 0.17 1" />
        </material>
      </visual>
    <collision name="knob_cap">
      <geometry>
        <mesh filename="assets/meshes/front_range_knob.obj" />
        </geometry>
      </collision>
    </link>
  <link name="knob_1">
    <visual name="knob_cap">
      <geometry>
        <mesh filename="assets/meshes/front_range_knob.obj" />
        </geometry>
      <material name="dark_brushed_steel">
        <color rgba="0.16 0.17 0.17 1" />
        </material>
      </visual>
    <collision name="knob_cap">
      <geometry>
        <mesh filename="assets/meshes/front_range_knob.obj" />
        </geometry>
      </collision>
    </link>
  <link name="knob_2">
    <visual name="knob_cap">
      <geometry>
        <mesh filename="assets/meshes/front_range_knob.obj" />
        </geometry>
      <material name="dark_brushed_steel">
        <color rgba="0.16 0.17 0.17 1" />
        </material>
      </visual>
    <collision name="knob_cap">
      <geometry>
        <mesh filename="assets/meshes/front_range_knob.obj" />
        </geometry>
      </collision>
    </link>
  <link name="knob_3">
    <visual name="knob_cap">
      <geometry>
        <mesh filename="assets/meshes/front_range_knob.obj" />
        </geometry>
      <material name="dark_brushed_steel">
        <color rgba="0.16 0.17 0.17 1" />
        </material>
      </visual>
    <collision name="knob_cap">
      <geometry>
        <mesh filename="assets/meshes/front_range_knob.obj" />
        </geometry>
      </collision>
    </link>
  <link name="knob_4">
    <visual name="knob_cap">
      <geometry>
        <mesh filename="assets/meshes/front_range_knob.obj" />
        </geometry>
      <material name="dark_brushed_steel">
        <color rgba="0.16 0.17 0.17 1" />
        </material>
      </visual>
    <collision name="knob_cap">
      <geometry>
        <mesh filename="assets/meshes/front_range_knob.obj" />
        </geometry>
      </collision>
    </link>
  <link name="button_0">
    <visual name="button_cap">
      <origin xyz="0 0 0.005" rpy="0 0 0" />
      <geometry>
        <box size="0.044 0.018 0.01" />
        </geometry>
      <material name="matte_rubber">
        <color rgba="0.035 0.035 0.035 1" />
        </material>
      </visual>
    <collision name="button_cap">
      <origin xyz="0 0 0.005" rpy="0 0 0" />
      <geometry>
        <box size="0.044 0.018 0.01" />
        </geometry>
      </collision>
    </link>
  <link name="button_1">
    <visual name="button_cap">
      <origin xyz="0 0 0.005" rpy="0 0 0" />
      <geometry>
        <box size="0.044 0.018 0.01" />
        </geometry>
      <material name="matte_rubber">
        <color rgba="0.035 0.035 0.035 1" />
        </material>
      </visual>
    <collision name="button_cap">
      <origin xyz="0 0 0.005" rpy="0 0 0" />
      <geometry>
        <box size="0.044 0.018 0.01" />
        </geometry>
      </collision>
    </link>
  <link name="button_2">
    <visual name="button_cap">
      <origin xyz="0 0 0.005" rpy="0 0 0" />
      <geometry>
        <box size="0.044 0.018 0.01" />
        </geometry>
      <material name="matte_rubber">
        <color rgba="0.035 0.035 0.035 1" />
        </material>
      </visual>
    <collision name="button_cap">
      <origin xyz="0 0 0.005" rpy="0 0 0" />
      <geometry>
        <box size="0.044 0.018 0.01" />
        </geometry>
      </collision>
    </link>
  <joint name="body_to_oven_door" type="revolute">
    <origin xyz="0 -0.394 0.123" rpy="0 0 0" />
    <parent link="body" />
    <child link="oven_door" />
    <axis xyz="1 0 0" />
    <limit effort="55" velocity="1.2" lower="0" upper="1.45" />
    </joint>
  <joint name="body_to_knob_0" type="revolute">
    <origin xyz="-0.3 -0.391 0.705" rpy="1.5708 0 0" />
    <parent link="body" />
    <child link="knob_0" />
    <axis xyz="0 0 1" />
    <limit effort="1.2" velocity="5" lower="-2.35" upper="2.35" />
    </joint>
  <joint name="body_to_knob_1" type="revolute">
    <origin xyz="-0.18 -0.391 0.705" rpy="1.5708 0 0" />
    <parent link="body" />
    <child link="knob_1" />
    <axis xyz="0 0 1" />
    <limit effort="1.2" velocity="5" lower="-2.35" upper="2.35" />
    </joint>
  <joint name="body_to_knob_2" type="revolute">
    <origin xyz="-0.06 -0.391 0.705" rpy="1.5708 0 0" />
    <parent link="body" />
    <child link="knob_2" />
    <axis xyz="0 0 1" />
    <limit effort="1.2" velocity="5" lower="-2.35" upper="2.35" />
    </joint>
  <joint name="body_to_knob_3" type="revolute">
    <origin xyz="0.18 -0.391 0.705" rpy="1.5708 0 0" />
    <parent link="body" />
    <child link="knob_3" />
    <axis xyz="0 0 1" />
    <limit effort="1.2" velocity="5" lower="-2.35" upper="2.35" />
    </joint>
  <joint name="body_to_knob_4" type="revolute">
    <origin xyz="0.3 -0.391 0.705" rpy="1.5708 0 0" />
    <parent link="body" />
    <child link="knob_4" />
    <axis xyz="0 0 1" />
    <limit effort="1.2" velocity="5" lower="-2.35" upper="2.35" />
    </joint>
  <joint name="body_to_button_0" type="prismatic">
    <origin xyz="0.135 -0.391 0.797" rpy="1.5708 0 0" />
    <parent link="body" />
    <child link="button_0" />
    <axis xyz="0 0 -1" />
    <limit effort="2" velocity="0.08" lower="0" upper="0.004" />
    </joint>
  <joint name="body_to_button_1" type="prismatic">
    <origin xyz="0.19 -0.391 0.797" rpy="1.5708 0 0" />
    <parent link="body" />
    <child link="button_1" />
    <axis xyz="0 0 -1" />
    <limit effort="2" velocity="0.08" lower="0" upper="0.004" />
    </joint>
  <joint name="body_to_button_2" type="prismatic">
    <origin xyz="0.245 -0.391 0.797" rpy="1.5708 0 0" />
    <parent link="body" />
    <child link="button_2" />
    <axis xyz="0 0 -1" />
    <limit effort="2" velocity="0.08" lower="0" upper="0.004" />
    </joint>
  </robot>
