<robot name="french_door_refrigerator">
  <material name="brushed_stainless">
    <color rgba="0.72 0.74 0.72 1" />
    </material>
  <material name="dark_cabinet">
    <color rgba="0.055 0.058 0.06 1" />
    </material>
  <material name="black_rubber_gasket">
    <color rgba="0.006 0.006 0.007 1" />
    </material>
  <material name="white_liner">
    <color rgba="0.91 0.93 0.9 1" />
    </material>
  <material name="zinc_slide_rail">
    <color rgba="0.58 0.6 0.57 1" />
    </material>
  <link name="cabinet">
    <visual name="back_panel">
      <origin xyz="0 0.3525 0.92" rpy="0 0 0" />
      <geometry>
        <box size="0.98 0.035 1.84" />
        </geometry>
      <material name="dark_cabinet">
        <color rgba="0.055 0.058 0.06 1" />
        </material>
      </visual>
    <visual name="side_wall_0">
      <origin xyz="-0.49 0 0.92" rpy="0 0 0" />
      <geometry>
        <box size="0.04 0.72 1.84" />
        </geometry>
      <material name="dark_cabinet">
        <color rgba="0.055 0.058 0.06 1" />
        </material>
      </visual>
    <visual name="side_wall_1">
      <origin xyz="0.49 0 0.92" rpy="0 0 0" />
      <geometry>
        <box size="0.04 0.72 1.84" />
        </geometry>
      <material name="dark_cabinet">
        <color rgba="0.055 0.058 0.06 1" />
        </material>
      </visual>
    <visual name="top_cap">
      <origin xyz="0 0 1.8125" rpy="0 0 0" />
      <geometry>
        <box size="0.98 0.72 0.055" />
        </geometry>
      <material name="dark_cabinet">
        <color rgba="0.055 0.058 0.06 1" />
        </material>
      </visual>
    <visual name="base_plinth">
      <origin xyz="0 0 0.0375" rpy="0 0 0" />
      <geometry>
        <box size="0.98 0.72 0.075" />
        </geometry>
      <material name="dark_cabinet">
        <color rgba="0.055 0.058 0.06 1" />
        </material>
      </visual>
    <visual name="freezer_divider">
      <origin xyz="0 0 0.6625" rpy="0 0 0" />
      <geometry>
        <box size="0.98 0.7 0.045" />
        </geometry>
      <material name="dark_cabinet">
        <color rgba="0.055 0.058 0.06 1" />
        </material>
      </visual>
    <visual name="center_mullion">
      <origin xyz="0 -0.355 1.2325" rpy="0 0 0" />
      <geometry>
        <box size="0.045 0.055 1.105" />
        </geometry>
      <material name="dark_cabinet">
        <color rgba="0.055 0.058 0.06 1" />
        </material>
      </visual>
    <visual name="upper_shelf_0">
      <origin xyz="0 0.035 1.06" rpy="0 0 0" />
      <geometry>
        <box size="0.94 0.62 0.018" />
        </geometry>
      <material name="white_liner">
        <color rgba="0.91 0.93 0.9 1" />
        </material>
      </visual>
    <visual name="upper_shelf_1">
      <origin xyz="0 0.035 1.4" rpy="0 0 0" />
      <geometry>
        <box size="0.94 0.62 0.018" />
        </geometry>
      <material name="white_liner">
        <color rgba="0.91 0.93 0.9 1" />
        </material>
      </visual>
    <visual name="fixed_rail_0">
      <origin xyz="-0.443 -0.055 0.35" rpy="0 0 0" />
      <geometry>
        <box size="0.054 0.61 0.048" />
        </geometry>
      <material name="zinc_slide_rail">
        <color rgba="0.58 0.6 0.57 1" />
        </material>
      </visual>
    <visual name="fixed_rail_1">
      <origin xyz="0.443 -0.055 0.35" rpy="0 0 0" />
      <geometry>
        <box size="0.054 0.61 0.048" />
        </geometry>
      <material name="zinc_slide_rail">
        <color rgba="0.58 0.6 0.57 1" />
        </material>
      </visual>
    <visual name="hinge_bracket_0_0">
      <origin xyz="-0.493 -0.406 0.86" rpy="0 0 0" />
      <geometry>
        <box size="0.034 0.092 0.11" />
        </geometry>
      <material name="dark_cabinet">
        <color rgba="0.055 0.058 0.06 1" />
        </material>
      </visual>
    <visual name="hinge_bracket_0_1">
      <origin xyz="-0.493 -0.406 1.24" rpy="0 0 0" />
      <geometry>
        <box size="0.034 0.092 0.11" />
        </geometry>
      <material name="dark_cabinet">
        <color rgba="0.055 0.058 0.06 1" />
        </material>
      </visual>
    <visual name="hinge_bracket_0_2">
      <origin xyz="-0.493 -0.406 1.62" rpy="0 0 0" />
      <geometry>
        <box size="0.034 0.092 0.11" />
        </geometry>
      <material name="dark_cabinet">
        <color rgba="0.055 0.058 0.06 1" />
        </material>
      </visual>
    <visual name="hinge_bracket_1_0">
      <origin xyz="0.493 -0.406 0.86" rpy="0 0 0" />
      <geometry>
        <box size="0.034 0.092 0.11" />
        </geometry>
      <material name="dark_cabinet">
        <color rgba="0.055 0.058 0.06 1" />
        </material>
      </visual>
    <visual name="hinge_bracket_1_1">
      <origin xyz="0.493 -0.406 1.24" rpy="0 0 0" />
      <geometry>
        <box size="0.034 0.092 0.11" />
        </geometry>
      <material name="dark_cabinet">
        <color rgba="0.055 0.058 0.06 1" />
        </material>
      </visual>
    <visual name="hinge_bracket_1_2">
      <origin xyz="0.493 -0.406 1.62" rpy="0 0 0" />
      <geometry>
        <box size="0.034 0.092 0.11" />
        </geometry>
      <material name="dark_cabinet">
        <color rgba="0.055 0.058 0.06 1" />
        </material>
      </visual>
    <collision name="back_panel">
      <origin xyz="0 0.3525 0.92" rpy="0 0 0" />
      <geometry>
        <box size="0.98 0.035 1.84" />
        </geometry>
      </collision>
    <collision name="side_wall_0">
      <origin xyz="-0.49 0 0.92" rpy="0 0 0" />
      <geometry>
        <box size="0.04 0.72 1.84" />
        </geometry>
      </collision>
    <collision name="side_wall_1">
      <origin xyz="0.49 0 0.92" rpy="0 0 0" />
      <geometry>
        <box size="0.04 0.72 1.84" />
        </geometry>
      </collision>
    <collision name="top_cap">
      <origin xyz="0 0 1.8125" rpy="0 0 0" />
      <geometry>
        <box size="0.98 0.72 0.055" />
        </geometry>
      </collision>
    <collision name="base_plinth">
      <origin xyz="0 0 0.0375" rpy="0 0 0" />
      <geometry>
        <box size="0.98 0.72 0.075" />
        </geometry>
      </collision>
    <collision name="freezer_divider">
      <origin xyz="0 0 0.6625" rpy="0 0 0" />
      <geometry>
        <box size="0.98 0.7 0.045" />
        </geometry>
      </collision>
    <collision name="center_mullion">
      <origin xyz="0 -0.355 1.2325" rpy="0 0 0" />
      <geometry>
        <box size="0.045 0.055 1.105" />
        </geometry>
      </collision>
    <collision name="upper_shelf_0">
      <origin xyz="0 0.035 1.06" rpy="0 0 0" />
      <geometry>
        <box size="0.94 0.62 0.018" />
        </geometry>
      </collision>
    <collision name="upper_shelf_1">
      <origin xyz="0 0.035 1.4" rpy="0 0 0" />
      <geometry>
        <box size="0.94 0.62 0.018" />
        </geometry>
      </collision>
    <collision name="fixed_rail_0">
      <origin xyz="-0.443 -0.055 0.35" rpy="0 0 0" />
      <geometry>
        <box size="0.054 0.61 0.048" />
        </geometry>
      </collision>
    <collision name="fixed_rail_1">
      <origin xyz="0.443 -0.055 0.35" rpy="0 0 0" />
      <geometry>
        <box size="0.054 0.61 0.048" />
        </geometry>
      </collision>
    <collision name="hinge_bracket_0_0">
      <origin xyz="-0.493 -0.406 0.86" rpy="0 0 0" />
      <geometry>
        <box size="0.034 0.092 0.11" />
        </geometry>
      </collision>
    <collision name="hinge_bracket_0_1">
      <origin xyz="-0.493 -0.406 1.24" rpy="0 0 0" />
      <geometry>
        <box size="0.034 0.092 0.11" />
        </geometry>
      </collision>
    <collision name="hinge_bracket_0_2">
      <origin xyz="-0.493 -0.406 1.62" rpy="0 0 0" />
      <geometry>
        <box size="0.034 0.092 0.11" />
        </geometry>
      </collision>
    <collision name="hinge_bracket_1_0">
      <origin xyz="0.493 -0.406 0.86" rpy="0 0 0" />
      <geometry>
        <box size="0.034 0.092 0.11" />
        </geometry>
      </collision>
    <collision name="hinge_bracket_1_1">
      <origin xyz="0.493 -0.406 1.24" rpy="0 0 0" />
      <geometry>
        <box size="0.034 0.092 0.11" />
        </geometry>
      </collision>
    <collision name="hinge_bracket_1_2">
      <origin xyz="0.493 -0.406 1.62" rpy="0 0 0" />
      <geometry>
        <box size="0.034 0.092 0.11" />
        </geometry>
      </collision>
    </link>
  <link name="upper_door_0">
    <visual name="outer_panel">
      <origin xyz="0.24 -0.025 0.55" rpy="0 0 0" />
      <geometry>
        <mesh filename="assets/meshes/upper_door_panel.obj" />
        </geometry>
      <material name="brushed_stainless">
        <color rgba="0.72 0.74 0.72 1" />
        </material>
      </visual>
    <visual name="inner_gasket">
      <origin xyz="0.242 0.022 0.55" rpy="0 0 0" />
      <geometry>
        <box size="0.395 0.018 1.02" />
        </geometry>
      <material name="black_rubber_gasket">
        <color rgba="0.006 0.006 0.007 1" />
        </material>
      </visual>
    <visual name="center_seal">
      <origin xyz="0.45 -0.067 0.55" rpy="0 0 0" />
      <geometry>
        <box size="0.02 0.026 1.07" />
        </geometry>
      <material name="black_rubber_gasket">
        <color rgba="0.006 0.006 0.007 1" />
        </material>
      </visual>
    <visual name="vertical_handle">
      <origin xyz="0.375 -0.108 0.565" rpy="0 0 0" />
      <geometry>
        <cylinder radius="0.017" length="0.76" />
        </geometry>
      <material name="brushed_stainless">
        <color rgba="0.72 0.74 0.72 1" />
        </material>
      </visual>
    <visual name="handle_mount_0">
      <origin xyz="0.375 -0.076 0.255" rpy="0 0 0" />
      <geometry>
        <box size="0.055 0.078 0.04" />
        </geometry>
      <material name="brushed_stainless">
        <color rgba="0.72 0.74 0.72 1" />
        </material>
      </visual>
    <visual name="handle_mount_1">
      <origin xyz="0.375 -0.076 0.875" rpy="0 0 0" />
      <geometry>
        <box size="0.055 0.078 0.04" />
        </geometry>
      <material name="brushed_stainless">
        <color rgba="0.72 0.74 0.72 1" />
        </material>
      </visual>
    <visual name="hinge_barrel">
      <origin xyz="0 0 0.552" rpy="0 0 0" />
      <geometry>
        <cylinder radius="0.016" length="1.035" />
        </geometry>
      <material name="dark_cabinet">
        <color rgba="0.055 0.058 0.06 1" />
        </material>
      </visual>
    <visual name="hinge_leaf">
      <origin xyz="0.015 0.012 0.552" rpy="0 0 0" />
      <geometry>
        <box size="0.03 0.04 1.02" />
        </geometry>
      <material name="dark_cabinet">
        <color rgba="0.055 0.058 0.06 1" />
        </material>
      </visual>
    <collision name="outer_panel">
      <origin xyz="0.24 -0.025 0.55" rpy="0 0 0" />
      <geometry>
        <mesh filename="assets/meshes/upper_door_panel.obj" />
        </geometry>
      </collision>
    <collision name="inner_gasket">
      <origin xyz="0.242 0.022 0.55" rpy="0 0 0" />
      <geometry>
        <box size="0.395 0.018 1.02" />
        </geometry>
      </collision>
    <collision name="center_seal">
      <origin xyz="0.45 -0.067 0.55" rpy="0 0 0" />
      <geometry>
        <box size="0.02 0.026 1.07" />
        </geometry>
      </collision>
    <collision name="vertical_handle">
      <origin xyz="0.375 -0.108 0.565" rpy="0 0 0" />
      <geometry>
        <cylinder radius="0.017" length="0.76" />
        </geometry>
      </collision>
    <collision name="handle_mount_0">
      <origin xyz="0.375 -0.076 0.255" rpy="0 0 0" />
      <geometry>
        <box size="0.055 0.078 0.04" />
        </geometry>
      </collision>
    <collision name="handle_mount_1">
      <origin xyz="0.375 -0.076 0.875" rpy="0 0 0" />
      <geometry>
        <box size="0.055 0.078 0.04" />
        </geometry>
      </collision>
    <collision name="hinge_barrel">
      <origin xyz="0 0 0.552" rpy="0 0 0" />
      <geometry>
        <cylinder radius="0.016" length="1.035" />
        </geometry>
      </collision>
    <collision name="hinge_leaf">
      <origin xyz="0.015 0.012 0.552" rpy="0 0 0" />
      <geometry>
        <box size="0.03 0.04 1.02" />
        </geometry>
      </collision>
    </link>
  <link name="upper_door_1">
    <visual name="outer_panel">
      <origin xyz="-0.24 -0.025 0.55" rpy="0 0 0" />
      <geometry>
        <mesh filename="assets/meshes/upper_door_panel.obj" />
        </geometry>
      <material name="brushed_stainless">
        <color rgba="0.72 0.74 0.72 1" />
        </material>
      </visual>
    <visual name="inner_gasket">
      <origin xyz="-0.242 0.022 0.55" rpy="0 0 0" />
      <geometry>
        <box size="0.395 0.018 1.02" />
        </geometry>
      <material name="black_rubber_gasket">
        <color rgba="0.006 0.006 0.007 1" />
        </material>
      </visual>
    <visual name="center_seal">
      <origin xyz="-0.45 -0.067 0.55" rpy="0 0 0" />
      <geometry>
        <box size="0.02 0.026 1.07" />
        </geometry>
      <material name="black_rubber_gasket">
        <color rgba="0.006 0.006 0.007 1" />
        </material>
      </visual>
    <visual name="vertical_handle">
      <origin xyz="-0.375 -0.108 0.565" rpy="0 0 0" />
      <geometry>
        <cylinder radius="0.017" length="0.76" />
        </geometry>
      <material name="brushed_stainless">
        <color rgba="0.72 0.74 0.72 1" />
        </material>
      </visual>
    <visual name="handle_mount_0">
      <origin xyz="-0.375 -0.076 0.255" rpy="0 0 0" />
      <geometry>
        <box size="0.055 0.078 0.04" />
        </geometry>
      <material name="brushed_stainless">
        <color rgba="0.72 0.74 0.72 1" />
        </material>
      </visual>
    <visual name="handle_mount_1">
      <origin xyz="-0.375 -0.076 0.875" rpy="0 0 0" />
      <geometry>
        <box size="0.055 0.078 0.04" />
        </geometry>
      <material name="brushed_stainless">
        <color rgba="0.72 0.74 0.72 1" />
        </material>
      </visual>
    <visual name="hinge_barrel">
      <origin xyz="0 0 0.552" rpy="0 0 0" />
      <geometry>
        <cylinder radius="0.016" length="1.035" />
        </geometry>
      <material name="dark_cabinet">
        <color rgba="0.055 0.058 0.06 1" />
        </material>
      </visual>
    <visual name="hinge_leaf">
      <origin xyz="-0.015 0.012 0.552" rpy="0 0 0" />
      <geometry>
        <box size="0.03 0.04 1.02" />
        </geometry>
      <material name="dark_cabinet">
        <color rgba="0.055 0.058 0.06 1" />
        </material>
      </visual>
    <collision name="outer_panel">
      <origin xyz="-0.24 -0.025 0.55" rpy="0 0 0" />
      <geometry>
        <mesh filename="assets/meshes/upper_door_panel.obj" />
        </geometry>
      </collision>
    <collision name="inner_gasket">
      <origin xyz="-0.242 0.022 0.55" rpy="0 0 0" />
      <geometry>
        <box size="0.395 0.018 1.02" />
        </geometry>
      </collision>
    <collision name="center_seal">
      <origin xyz="-0.45 -0.067 0.55" rpy="0 0 0" />
      <geometry>
        <box size="0.02 0.026 1.07" />
        </geometry>
      </collision>
    <collision name="vertical_handle">
      <origin xyz="-0.375 -0.108 0.565" rpy="0 0 0" />
      <geometry>
        <cylinder radius="0.017" length="0.76" />
        </geometry>
      </collision>
    <collision name="handle_mount_0">
      <origin xyz="-0.375 -0.076 0.255" rpy="0 0 0" />
      <geometry>
        <box size="0.055 0.078 0.04" />
        </geometry>
      </collision>
    <collision name="handle_mount_1">
      <origin xyz="-0.375 -0.076 0.875" rpy="0 0 0" />
      <geometry>
        <box size="0.055 0.078 0.04" />
        </geometry>
      </collision>
    <collision name="hinge_barrel">
      <origin xyz="0 0 0.552" rpy="0 0 0" />
      <geometry>
        <cylinder radius="0.016" length="1.035" />
        </geometry>
      </collision>
    <collision name="hinge_leaf">
      <origin xyz="-0.015 0.012 0.552" rpy="0 0 0" />
      <geometry>
        <box size="0.03 0.04 1.02" />
        </geometry>
      </collision>
    </link>
  <link name="freezer_drawer">
    <visual name="drawer_front">
      <origin xyz="0 -0.015 0" rpy="0 0 0" />
      <geometry>
        <mesh filename="assets/meshes/freezer_drawer_front.obj" />
        </geometry>
      <material name="brushed_stainless">
        <color rgba="0.72 0.74 0.72 1" />
        </material>
      </visual>
    <visual name="basket_floor">
      <origin xyz="0 0.28 -0.178" rpy="0 0 0" />
      <geometry>
        <box size="0.78 0.56 0.03" />
        </geometry>
      <material name="white_liner">
        <color rgba="0.91 0.93 0.9 1" />
        </material>
      </visual>
    <visual name="basket_side_0">
      <origin xyz="-0.39 0.28 -0.01" rpy="0 0 0" />
      <geometry>
        <box size="0.03 0.56 0.36" />
        </geometry>
      <material name="white_liner">
        <color rgba="0.91 0.93 0.9 1" />
        </material>
      </visual>
    <visual name="basket_side_1">
      <origin xyz="0.39 0.28 -0.01" rpy="0 0 0" />
      <geometry>
        <box size="0.03 0.56 0.36" />
        </geometry>
      <material name="white_liner">
        <color rgba="0.91 0.93 0.9 1" />
        </material>
      </visual>
    <visual name="basket_back">
      <origin xyz="0 0.56 -0.01" rpy="0 0 0" />
      <geometry>
        <box size="0.78 0.03 0.36" />
        </geometry>
      <material name="white_liner">
        <color rgba="0.91 0.93 0.9 1" />
        </material>
      </visual>
    <visual name="basket_front_wall">
      <origin xyz="0 0.01 -0.045" rpy="0 0 0" />
      <geometry>
        <box size="0.78 0.03 0.27" />
        </geometry>
      <material name="white_liner">
        <color rgba="0.91 0.93 0.9 1" />
        </material>
      </visual>
    <visual name="sliding_rail_0">
      <origin xyz="-0.4 0.18 0.015" rpy="0 0 0" />
      <geometry>
        <box size="0.032 0.8 0.038" />
        </geometry>
      <material name="zinc_slide_rail">
        <color rgba="0.58 0.6 0.57 1" />
        </material>
      </visual>
    <visual name="sliding_rail_1">
      <origin xyz="0.4 0.18 0.015" rpy="0 0 0" />
      <geometry>
        <box size="0.032 0.8 0.038" />
        </geometry>
      <material name="zinc_slide_rail">
        <color rgba="0.58 0.6 0.57 1" />
        </material>
      </visual>
    <visual name="wide_handle">
      <origin xyz="0 -0.11 0.08" rpy="0 1.5708 0" />
      <geometry>
        <cylinder radius="0.018" length="0.74" />
        </geometry>
      <material name="brushed_stainless">
        <color rgba="0.72 0.74 0.72 1" />
        </material>
      </visual>
    <visual name="handle_mount_0">
      <origin xyz="-0.315 -0.075 0.08" rpy="0 0 0" />
      <geometry>
        <box size="0.045 0.085 0.05" />
        </geometry>
      <material name="brushed_stainless">
        <color rgba="0.72 0.74 0.72 1" />
        </material>
      </visual>
    <visual name="handle_mount_1">
      <origin xyz="0.315 -0.075 0.08" rpy="0 0 0" />
      <geometry>
        <box size="0.045 0.085 0.05" />
        </geometry>
      <material name="brushed_stainless">
        <color rgba="0.72 0.74 0.72 1" />
        </material>
      </visual>
    <collision name="drawer_front">
      <origin xyz="0 -0.015 0" rpy="0 0 0" />
      <geometry>
        <mesh filename="assets/meshes/freezer_drawer_front.obj" />
        </geometry>
      </collision>
    <collision name="basket_floor">
      <origin xyz="0 0.28 -0.178" rpy="0 0 0" />
      <geometry>
        <box size="0.78 0.56 0.03" />
        </geometry>
      </collision>
    <collision name="basket_side_0">
      <origin xyz="-0.39 0.28 -0.01" rpy="0 0 0" />
      <geometry>
        <box size="0.03 0.56 0.36" />
        </geometry>
      </collision>
    <collision name="basket_side_1">
      <origin xyz="0.39 0.28 -0.01" rpy="0 0 0" />
      <geometry>
        <box size="0.03 0.56 0.36" />
        </geometry>
      </collision>
    <collision name="basket_back">
      <origin xyz="0 0.56 -0.01" rpy="0 0 0" />
      <geometry>
        <box size="0.78 0.03 0.36" />
        </geometry>
      </collision>
    <collision name="basket_front_wall">
      <origin xyz="0 0.01 -0.045" rpy="0 0 0" />
      <geometry>
        <box size="0.78 0.03 0.27" />
        </geometry>
      </collision>
    <collision name="sliding_rail_0">
      <origin xyz="-0.4 0.18 0.015" rpy="0 0 0" />
      <geometry>
        <box size="0.032 0.8 0.038" />
        </geometry>
      </collision>
    <collision name="sliding_rail_1">
      <origin xyz="0.4 0.18 0.015" rpy="0 0 0" />
      <geometry>
        <box size="0.032 0.8 0.038" />
        </geometry>
      </collision>
    <collision name="wide_handle">
      <origin xyz="0 -0.11 0.08" rpy="0 1.5708 0" />
      <geometry>
        <cylinder radius="0.018" length="0.74" />
        </geometry>
      </collision>
    <collision name="handle_mount_0">
      <origin xyz="-0.315 -0.075 0.08" rpy="0 0 0" />
      <geometry>
        <box size="0.045 0.085 0.05" />
        </geometry>
      </collision>
    <collision name="handle_mount_1">
      <origin xyz="0.315 -0.075 0.08" rpy="0 0 0" />
      <geometry>
        <box size="0.045 0.085 0.05" />
        </geometry>
      </collision>
    </link>
  <joint name="cabinet_to_upper_door_0" type="revolute">
    <origin xyz="-0.46 -0.425 0.69" rpy="0 0 0" />
    <parent link="cabinet" />
    <child link="upper_door_0" />
    <axis xyz="0 0 -1" />
    <limit effort="18" velocity="1.4" lower="0" upper="1.85" />
    </joint>
  <joint name="cabinet_to_upper_door_1" type="revolute">
    <origin xyz="0.46 -0.425 0.69" rpy="0 0 0" />
    <parent link="cabinet" />
    <child link="upper_door_1" />
    <axis xyz="0 0 1" />
    <limit effort="18" velocity="1.4" lower="0" upper="1.85" />
    </joint>
  <joint name="cabinet_to_freezer_drawer" type="prismatic">
    <origin xyz="0 -0.405 0.34" rpy="0 0 0" />
    <parent link="cabinet" />
    <child link="freezer_drawer" />
    <axis xyz="0 -1 0" />
    <limit effort="120" velocity="0.35" lower="0" upper="0.48" />
    </joint>
  </robot>
