<robot name="tower_cantilever_tooling_arm">
  <material name="painted_steel">
    <color rgba="0.16 0.19 0.22 1" />
    </material>
  <material name="dark_link_cover">
    <color rgba="0.04 0.07 0.09 1" />
    </material>
  <material name="bearing_steel">
    <color rgba="0.62 0.65 0.66 1" />
    </material>
  <material name="plain_faceplate_steel">
    <color rgba="0.72 0.73 0.71 1" />
    </material>
  <link name="tower">
    <visual name="floor_plate">
      <origin xyz="0 0 0.03" rpy="0 0 0" />
      <geometry>
        <box size="0.52 0.44 0.06" />
        </geometry>
      <material name="painted_steel">
        <color rgba="0.16 0.19 0.22 1" />
        </material>
      </visual>
    <visual name="pedestal_block">
      <origin xyz="0 0 0.1" rpy="0 0 0" />
      <geometry>
        <box size="0.34 0.3 0.08" />
        </geometry>
      <material name="painted_steel">
        <color rgba="0.16 0.19 0.22 1" />
        </material>
      </visual>
    <visual name="tower_column">
      <origin xyz="0 0 0.41" rpy="0 0 0" />
      <geometry>
        <box size="0.2 0.2 0.54" />
        </geometry>
      <material name="painted_steel">
        <color rgba="0.16 0.19 0.22 1" />
        </material>
      </visual>
    <visual name="top_saddle">
      <origin xyz="0 0 0.72" rpy="0 0 0" />
      <geometry>
        <box size="0.34 0.28 0.08" />
        </geometry>
      <material name="painted_steel">
        <color rgba="0.16 0.19 0.22 1" />
        </material>
      </visual>
    <visual name="shoulder_bearing">
      <origin xyz="0 0 0.72" rpy="0 0 0" />
      <geometry>
        <cylinder radius="0.17" length="0.08" />
        </geometry>
      <material name="bearing_steel">
        <color rgba="0.62 0.65 0.66 1" />
        </material>
      </visual>
    <collision name="floor_plate">
      <origin xyz="0 0 0.03" rpy="0 0 0" />
      <geometry>
        <box size="0.52 0.44 0.06" />
        </geometry>
      </collision>
    <collision name="pedestal_block">
      <origin xyz="0 0 0.1" rpy="0 0 0" />
      <geometry>
        <box size="0.34 0.3 0.08" />
        </geometry>
      </collision>
    <collision name="tower_column">
      <origin xyz="0 0 0.41" rpy="0 0 0" />
      <geometry>
        <box size="0.2 0.2 0.54" />
        </geometry>
      </collision>
    <collision name="top_saddle">
      <origin xyz="0 0 0.72" rpy="0 0 0" />
      <geometry>
        <box size="0.34 0.28 0.08" />
        </geometry>
      </collision>
    <collision name="shoulder_bearing">
      <origin xyz="0 0 0.72" rpy="0 0 0" />
      <geometry>
        <cylinder radius="0.17" length="0.08" />
        </geometry>
      </collision>
    </link>
  <link name="upper_link">
    <visual name="proximal_bearing">
      <origin xyz="0 0 0.04" rpy="0 0 0" />
      <geometry>
        <cylinder radius="0.165" length="0.08" />
        </geometry>
      <material name="bearing_steel">
        <color rgba="0.62 0.65 0.66 1" />
        </material>
      </visual>
    <visual name="main_beam">
      <origin xyz="0.45 0 0.04" rpy="0 0 0" />
      <geometry>
        <box size="0.82 0.14 0.075" />
        </geometry>
      <material name="painted_steel">
        <color rgba="0.16 0.19 0.22 1" />
        </material>
      </visual>
    <visual name="top_cover">
      <origin xyz="0.43 0 0.087" rpy="0 0 0" />
      <geometry>
        <box size="0.48 0.08 0.026" />
        </geometry>
      <material name="dark_link_cover">
        <color rgba="0.04 0.07 0.09 1" />
        </material>
      </visual>
    <visual name="distal_bearing">
      <origin xyz="0.9 0 0.04" rpy="0 0 0" />
      <geometry>
        <cylinder radius="0.145" length="0.08" />
        </geometry>
      <material name="bearing_steel">
        <color rgba="0.62 0.65 0.66 1" />
        </material>
      </visual>
    <collision name="proximal_bearing">
      <origin xyz="0 0 0.04" rpy="0 0 0" />
      <geometry>
        <cylinder radius="0.165" length="0.08" />
        </geometry>
      </collision>
    <collision name="main_beam">
      <origin xyz="0.45 0 0.04" rpy="0 0 0" />
      <geometry>
        <box size="0.82 0.14 0.075" />
        </geometry>
      </collision>
    <collision name="top_cover">
      <origin xyz="0.43 0 0.087" rpy="0 0 0" />
      <geometry>
        <box size="0.48 0.08 0.026" />
        </geometry>
      </collision>
    <collision name="distal_bearing">
      <origin xyz="0.9 0 0.04" rpy="0 0 0" />
      <geometry>
        <cylinder radius="0.145" length="0.08" />
        </geometry>
      </collision>
    </link>
  <link name="forelink">
    <visual name="proximal_bearing">
      <origin xyz="0 0 0.0375" rpy="0 0 0" />
      <geometry>
        <cylinder radius="0.135" length="0.075" />
        </geometry>
      <material name="bearing_steel">
        <color rgba="0.62 0.65 0.66 1" />
        </material>
      </visual>
    <visual name="main_beam">
      <origin xyz="0.28 0 0.0375" rpy="0 0 0" />
      <geometry>
        <box size="0.52 0.12 0.07" />
        </geometry>
      <material name="painted_steel">
        <color rgba="0.16 0.19 0.22 1" />
        </material>
      </visual>
    <visual name="top_cover">
      <origin xyz="0.29 0 0.081" rpy="0 0 0" />
      <geometry>
        <box size="0.34 0.066 0.022" />
        </geometry>
      <material name="dark_link_cover">
        <color rgba="0.04 0.07 0.09 1" />
        </material>
      </visual>
    <visual name="distal_bearing">
      <origin xyz="0.56 0 0.0375" rpy="0 0 0" />
      <geometry>
        <cylinder radius="0.115" length="0.075" />
        </geometry>
      <material name="bearing_steel">
        <color rgba="0.62 0.65 0.66 1" />
        </material>
      </visual>
    <collision name="proximal_bearing">
      <origin xyz="0 0 0.0375" rpy="0 0 0" />
      <geometry>
        <cylinder radius="0.135" length="0.075" />
        </geometry>
      </collision>
    <collision name="main_beam">
      <origin xyz="0.28 0 0.0375" rpy="0 0 0" />
      <geometry>
        <box size="0.52 0.12 0.07" />
        </geometry>
      </collision>
    <collision name="top_cover">
      <origin xyz="0.29 0 0.081" rpy="0 0 0" />
      <geometry>
        <box size="0.34 0.066 0.022" />
        </geometry>
      </collision>
    <collision name="distal_bearing">
      <origin xyz="0.56 0 0.0375" rpy="0 0 0" />
      <geometry>
        <cylinder radius="0.115" length="0.075" />
        </geometry>
      </collision>
    </link>
  <link name="wrist_cartridge">
    <visual name="wrist_hub">
      <origin xyz="0 0 0.03" rpy="0 0 0" />
      <geometry>
        <cylinder radius="0.105" length="0.06" />
        </geometry>
      <material name="bearing_steel">
        <color rgba="0.62 0.65 0.66 1" />
        </material>
      </visual>
    <visual name="cartridge_body">
      <origin xyz="0.16 0 0.055" rpy="0 0 0" />
      <geometry>
        <box size="0.3 0.085 0.11" />
        </geometry>
      <material name="painted_steel">
        <color rgba="0.16 0.19 0.22 1" />
        </material>
      </visual>
    <visual name="nose_block">
      <origin xyz="0.292 0 0.055" rpy="0 0 0" />
      <geometry>
        <box size="0.075 0.062 0.055" />
        </geometry>
      <material name="dark_link_cover">
        <color rgba="0.04 0.07 0.09 1" />
        </material>
      </visual>
    <visual name="faceplate">
      <origin xyz="0.34 0 0.07" rpy="0 0 0" />
      <geometry>
        <box size="0.032 0.18 0.16" />
        </geometry>
      <material name="plain_faceplate_steel">
        <color rgba="0.72 0.73 0.71 1" />
        </material>
      </visual>
    <collision name="wrist_hub">
      <origin xyz="0 0 0.03" rpy="0 0 0" />
      <geometry>
        <cylinder radius="0.105" length="0.06" />
        </geometry>
      </collision>
    <collision name="cartridge_body">
      <origin xyz="0.16 0 0.055" rpy="0 0 0" />
      <geometry>
        <box size="0.3 0.085 0.11" />
        </geometry>
      </collision>
    <collision name="nose_block">
      <origin xyz="0.292 0 0.055" rpy="0 0 0" />
      <geometry>
        <box size="0.075 0.062 0.055" />
        </geometry>
      </collision>
    <collision name="faceplate">
      <origin xyz="0.34 0 0.07" rpy="0 0 0" />
      <geometry>
        <box size="0.032 0.18 0.16" />
        </geometry>
      </collision>
    </link>
  <joint name="tower_to_upper" type="revolute">
    <origin xyz="0 0 0.76" rpy="0 0 0" />
    <parent link="tower" />
    <child link="upper_link" />
    <axis xyz="0 0 1" />
    <limit effort="160" velocity="1.2" lower="-2.6" upper="2.6" />
    </joint>
  <joint name="upper_to_forelink" type="revolute">
    <origin xyz="0.9 0 0.08" rpy="0 0 0" />
    <parent link="upper_link" />
    <child link="forelink" />
    <axis xyz="0 0 1" />
    <limit effort="95" velocity="1.5" lower="-2.4" upper="2.4" />
    </joint>
  <joint name="forelink_to_wrist" type="revolute">
    <origin xyz="0.56 0 0.075" rpy="0 0 0" />
    <parent link="forelink" />
    <child link="wrist_cartridge" />
    <axis xyz="0 0 1" />
    <limit effort="35" velocity="2.5" lower="-3.14159" upper="3.14159" />
    </joint>
  </robot>
