<robot name="teaching_room_drafting_table">
  <link name="floor_base">
    <visual name="wide_floor_plate">
      <origin xyz="0 0 0.03" rpy="0 0 0" />
      <geometry>
        <box size="1.05 0.75 0.06" />
        </geometry>
      <material name="painted_steel">
        <color rgba="0.18 0.2 0.22 1" />
        </material>
      </visual>
    <visual name="raised_center_spine">
      <origin xyz="0 0 0.078" rpy="0 0 0" />
      <geometry>
        <box size="0.88 0.09 0.055" />
        </geometry>
      <material name="painted_steel">
        <color rgba="0.18 0.2 0.22 1" />
        </material>
      </visual>
    <visual name="rubber_foot_0_0">
      <origin xyz="-0.42 -0.32 0.009" rpy="0 0 0" />
      <geometry>
        <box size="0.18 0.07 0.018" />
        </geometry>
      <material name="black_rubber">
        <color rgba="0.01 0.01 0.012 1" />
        </material>
      </visual>
    <visual name="rubber_foot_0_1">
      <origin xyz="0.42 -0.32 0.009" rpy="0 0 0" />
      <geometry>
        <box size="0.18 0.07 0.018" />
        </geometry>
      <material name="black_rubber">
        <color rgba="0.01 0.01 0.012 1" />
        </material>
      </visual>
    <visual name="rubber_foot_1_0">
      <origin xyz="-0.42 0.32 0.009" rpy="0 0 0" />
      <geometry>
        <box size="0.18 0.07 0.018" />
        </geometry>
      <material name="black_rubber">
        <color rgba="0.01 0.01 0.012 1" />
        </material>
      </visual>
    <visual name="rubber_foot_1_1">
      <origin xyz="0.42 0.32 0.009" rpy="0 0 0" />
      <geometry>
        <box size="0.18 0.07 0.018" />
        </geometry>
      <material name="black_rubber">
        <color rgba="0.01 0.01 0.012 1" />
        </material>
      </visual>
    <visual name="sleeve_x_0">
      <origin xyz="-0.0825 0 0.345" rpy="0 0 0" />
      <geometry>
        <box size="0.035 0.2 0.58" />
        </geometry>
      <material name="dark_steel">
        <color rgba="0.05 0.055 0.06 1" />
        </material>
      </visual>
    <visual name="sleeve_x_1">
      <origin xyz="0.0825 0 0.345" rpy="0 0 0" />
      <geometry>
        <box size="0.035 0.2 0.58" />
        </geometry>
      <material name="dark_steel">
        <color rgba="0.05 0.055 0.06 1" />
        </material>
      </visual>
    <visual name="sleeve_y_0">
      <origin xyz="0 -0.0825 0.345" rpy="0 0 0" />
      <geometry>
        <box size="0.13 0.035 0.58" />
        </geometry>
      <material name="dark_steel">
        <color rgba="0.05 0.055 0.06 1" />
        </material>
      </visual>
    <visual name="sleeve_y_1">
      <origin xyz="0 0.0825 0.345" rpy="0 0 0" />
      <geometry>
        <box size="0.13 0.035 0.58" />
        </geometry>
      <material name="dark_steel">
        <color rgba="0.05 0.055 0.06 1" />
        </material>
      </visual>
    <collision name="wide_floor_plate">
      <origin xyz="0 0 0.03" rpy="0 0 0" />
      <geometry>
        <box size="1.05 0.75 0.06" />
        </geometry>
      </collision>
    <collision name="raised_center_spine">
      <origin xyz="0 0 0.078" rpy="0 0 0" />
      <geometry>
        <box size="0.88 0.09 0.055" />
        </geometry>
      </collision>
    <collision name="rubber_foot_0_0">
      <origin xyz="-0.42 -0.32 0.009" rpy="0 0 0" />
      <geometry>
        <box size="0.18 0.07 0.018" />
        </geometry>
      </collision>
    <collision name="rubber_foot_0_1">
      <origin xyz="0.42 -0.32 0.009" rpy="0 0 0" />
      <geometry>
        <box size="0.18 0.07 0.018" />
        </geometry>
      </collision>
    <collision name="rubber_foot_1_0">
      <origin xyz="-0.42 0.32 0.009" rpy="0 0 0" />
      <geometry>
        <box size="0.18 0.07 0.018" />
        </geometry>
      </collision>
    <collision name="rubber_foot_1_1">
      <origin xyz="0.42 0.32 0.009" rpy="0 0 0" />
      <geometry>
        <box size="0.18 0.07 0.018" />
        </geometry>
      </collision>
    <collision name="sleeve_x_0">
      <origin xyz="-0.0825 0 0.345" rpy="0 0 0" />
      <geometry>
        <box size="0.035 0.2 0.58" />
        </geometry>
      </collision>
    <collision name="sleeve_x_1">
      <origin xyz="0.0825 0 0.345" rpy="0 0 0" />
      <geometry>
        <box size="0.035 0.2 0.58" />
        </geometry>
      </collision>
    <collision name="sleeve_y_0">
      <origin xyz="0 -0.0825 0.345" rpy="0 0 0" />
      <geometry>
        <box size="0.13 0.035 0.58" />
        </geometry>
      </collision>
    <collision name="sleeve_y_1">
      <origin xyz="0 0.0825 0.345" rpy="0 0 0" />
      <geometry>
        <box size="0.13 0.035 0.58" />
        </geometry>
      </collision>
    </link>
  <link name="height_column">
    <visual name="inner_post">
      <origin xyz="0 0 0.03" rpy="0 0 0" />
      <geometry>
        <box size="0.13 0.13 0.66" />
        </geometry>
      <material name="brushed_aluminum">
        <color rgba="0.62 0.64 0.62 1" />
        </material>
      </visual>
    <visual name="height_scale_strip">
      <origin xyz="-0.071 0 0.12" rpy="0 0 0" />
      <geometry>
        <box size="0.012 0.104 0.2" />
        </geometry>
      <material name="dark_steel">
        <color rgba="0.05 0.055 0.06 1" />
        </material>
      </visual>
    <collision name="inner_post">
      <origin xyz="0 0 0.03" rpy="0 0 0" />
      <geometry>
        <box size="0.13 0.13 0.66" />
        </geometry>
      </collision>
    <collision name="height_scale_strip">
      <origin xyz="-0.071 0 0.12" rpy="0 0 0" />
      <geometry>
        <box size="0.012 0.104 0.2" />
        </geometry>
      </collision>
    </link>
  <link name="board_support">
    <visual name="support_collar">
      <origin xyz="0 0 0.03" rpy="0 0 0" />
      <geometry>
        <box size="0.2 0.2 0.06" />
        </geometry>
      <material name="dark_steel">
        <color rgba="0.05 0.055 0.06 1" />
        </material>
      </visual>
    <visual name="support_riser">
      <origin xyz="0.055 0 0.1" rpy="0 0 0" />
      <geometry>
        <box size="0.1 0.12 0.12" />
        </geometry>
      <material name="dark_steel">
        <color rgba="0.05 0.055 0.06 1" />
        </material>
      </visual>
    <visual name="hinge_head_block">
      <origin xyz="0.12 0 0.13" rpy="0 0 0" />
      <geometry>
        <box size="0.1 0.42 0.03" />
        </geometry>
      <material name="dark_steel">
        <color rgba="0.05 0.055 0.06 1" />
        </material>
      </visual>
    <visual name="hinge_pin">
      <origin xyz="0.16 0 0.19" rpy="1.5708 0 0" />
      <geometry>
        <cylinder radius="0.012" length="0.46" />
        </geometry>
      <material name="brushed_aluminum">
        <color rgba="0.62 0.64 0.62 1" />
        </material>
      </visual>
    <visual name="yoke_cheek_0">
      <origin xyz="0.16 -0.21 0.19" rpy="0 0 0" />
      <geometry>
        <box size="0.04 0.035 0.12" />
        </geometry>
      <material name="dark_steel">
        <color rgba="0.05 0.055 0.06 1" />
        </material>
      </visual>
    <visual name="yoke_cheek_1">
      <origin xyz="0.16 0.21 0.19" rpy="0 0 0" />
      <geometry>
        <box size="0.04 0.035 0.12" />
        </geometry>
      <material name="dark_steel">
        <color rgba="0.05 0.055 0.06 1" />
        </material>
      </visual>
    <collision name="support_collar">
      <origin xyz="0 0 0.03" rpy="0 0 0" />
      <geometry>
        <box size="0.2 0.2 0.06" />
        </geometry>
      </collision>
    <collision name="support_riser">
      <origin xyz="0.055 0 0.1" rpy="0 0 0" />
      <geometry>
        <box size="0.1 0.12 0.12" />
        </geometry>
      </collision>
    <collision name="hinge_head_block">
      <origin xyz="0.12 0 0.13" rpy="0 0 0" />
      <geometry>
        <box size="0.1 0.42 0.03" />
        </geometry>
      </collision>
    <collision name="hinge_pin">
      <origin xyz="0.16 0 0.19" rpy="1.5708 0 0" />
      <geometry>
        <cylinder radius="0.012" length="0.46" />
        </geometry>
      </collision>
    <collision name="yoke_cheek_0">
      <origin xyz="0.16 -0.21 0.19" rpy="0 0 0" />
      <geometry>
        <box size="0.04 0.035 0.12" />
        </geometry>
      </collision>
    <collision name="yoke_cheek_1">
      <origin xyz="0.16 0.21 0.19" rpy="0 0 0" />
      <geometry>
        <box size="0.04 0.035 0.12" />
        </geometry>
      </collision>
    </link>
  <link name="board">
    <visual name="drawing_board">
      <origin xyz="-0.44 0 0.025" rpy="0 0 0" />
      <geometry>
        <box size="0.8 1.2 0.035" />
        </geometry>
      <material name="green_drafting_board">
        <color rgba="0.28 0.43 0.32 1" />
        </material>
      </visual>
    <visual name="drawing_sheet">
      <origin xyz="-0.44 0 0.0445" rpy="0 0 0" />
      <geometry>
        <box size="0.7 1.05 0.004" />
        </geometry>
      <material name="pale_drawing_sheet">
        <color rgba="0.93 0.9 0.8 1" />
        </material>
      </visual>
    <visual name="rear_frame">
      <origin xyz="-0.055 0 0" rpy="0 0 0" />
      <geometry>
        <box size="0.045 1.24 0.04" />
        </geometry>
      <material name="brushed_aluminum">
        <color rgba="0.62 0.64 0.62 1" />
        </material>
      </visual>
    <visual name="front_frame">
      <origin xyz="-0.825 0 0" rpy="0 0 0" />
      <geometry>
        <box size="0.045 1.24 0.04" />
        </geometry>
      <material name="brushed_aluminum">
        <color rgba="0.62 0.64 0.62 1" />
        </material>
      </visual>
    <visual name="side_frame_0">
      <origin xyz="-0.44 -0.62 0" rpy="0 0 0" />
      <geometry>
        <box size="0.8 0.035 0.04" />
        </geometry>
      <material name="brushed_aluminum">
        <color rgba="0.62 0.64 0.62 1" />
        </material>
      </visual>
    <visual name="side_frame_1">
      <origin xyz="-0.44 0.62 0" rpy="0 0 0" />
      <geometry>
        <box size="0.8 0.035 0.04" />
        </geometry>
      <material name="brushed_aluminum">
        <color rgba="0.62 0.64 0.62 1" />
        </material>
      </visual>
    <visual name="hinge_knuckle">
      <origin xyz="0 0 0" rpy="1.5708 0 0" />
      <geometry>
        <cylinder radius="0.022" length="0.32" />
        </geometry>
      <material name="dark_steel">
        <color rgba="0.05 0.055 0.06 1" />
        </material>
      </visual>
    <visual name="hinge_leaf">
      <origin xyz="-0.075 0 0" rpy="0 0 0" />
      <geometry>
        <box size="0.11 0.26 0.012" />
        </geometry>
      <material name="dark_steel">
        <color rgba="0.05 0.055 0.06 1" />
        </material>
      </visual>
    <visual name="tool_tray_shelf">
      <origin xyz="-0.885 0 -0.055" rpy="0 0 0" />
      <geometry>
        <box size="0.11 1.1 0.025" />
        </geometry>
      <material name="tray_gray">
        <color rgba="0.45 0.47 0.48 1" />
        </material>
      </visual>
    <visual name="tool_tray_back">
      <origin xyz="-0.827 0 -0.012" rpy="0 0 0" />
      <geometry>
        <box size="0.025 1.1 0.09" />
        </geometry>
      <material name="tray_gray">
        <color rgba="0.45 0.47 0.48 1" />
        </material>
      </visual>
    <visual name="tool_tray_lip">
      <origin xyz="-0.94 0 -0.025" rpy="0 0 0" />
      <geometry>
        <box size="0.025 1.1 0.07" />
        </geometry>
      <material name="tray_gray">
        <color rgba="0.45 0.47 0.48 1" />
        </material>
      </visual>
    <visual name="runner_0">
      <origin xyz="-0.5 -0.28 -0.085" rpy="0 0 0" />
      <geometry>
        <box size="0.62 0.035 0.035" />
        </geometry>
      <material name="dark_steel">
        <color rgba="0.05 0.055 0.06 1" />
        </material>
      </visual>
    <visual name="runner_1">
      <origin xyz="-0.5 0.28 -0.085" rpy="0 0 0" />
      <geometry>
        <box size="0.62 0.035 0.035" />
        </geometry>
      <material name="dark_steel">
        <color rgba="0.05 0.055 0.06 1" />
        </material>
      </visual>
    <visual name="runner_hanger_0_0">
      <origin xyz="-0.22 -0.28 -0.032" rpy="0 0 0" />
      <geometry>
        <box size="0.035 0.035 0.08" />
        </geometry>
      <material name="dark_steel">
        <color rgba="0.05 0.055 0.06 1" />
        </material>
      </visual>
    <visual name="runner_hanger_0_1">
      <origin xyz="-0.62 -0.28 -0.032" rpy="0 0 0" />
      <geometry>
        <box size="0.035 0.035 0.08" />
        </geometry>
      <material name="dark_steel">
        <color rgba="0.05 0.055 0.06 1" />
        </material>
      </visual>
    <visual name="runner_hanger_1_0">
      <origin xyz="-0.22 0.28 -0.032" rpy="0 0 0" />
      <geometry>
        <box size="0.035 0.035 0.08" />
        </geometry>
      <material name="dark_steel">
        <color rgba="0.05 0.055 0.06 1" />
        </material>
      </visual>
    <visual name="runner_hanger_1_1">
      <origin xyz="-0.62 0.28 -0.032" rpy="0 0 0" />
      <geometry>
        <box size="0.035 0.035 0.08" />
        </geometry>
      <material name="dark_steel">
        <color rgba="0.05 0.055 0.06 1" />
        </material>
      </visual>
    <collision name="drawing_board">
      <origin xyz="-0.44 0 0.025" rpy="0 0 0" />
      <geometry>
        <box size="0.8 1.2 0.035" />
        </geometry>
      </collision>
    <collision name="drawing_sheet">
      <origin xyz="-0.44 0 0.0445" rpy="0 0 0" />
      <geometry>
        <box size="0.7 1.05 0.004" />
        </geometry>
      </collision>
    <collision name="rear_frame">
      <origin xyz="-0.055 0 0" rpy="0 0 0" />
      <geometry>
        <box size="0.045 1.24 0.04" />
        </geometry>
      </collision>
    <collision name="front_frame">
      <origin xyz="-0.825 0 0" rpy="0 0 0" />
      <geometry>
        <box size="0.045 1.24 0.04" />
        </geometry>
      </collision>
    <collision name="side_frame_0">
      <origin xyz="-0.44 -0.62 0" rpy="0 0 0" />
      <geometry>
        <box size="0.8 0.035 0.04" />
        </geometry>
      </collision>
    <collision name="side_frame_1">
      <origin xyz="-0.44 0.62 0" rpy="0 0 0" />
      <geometry>
        <box size="0.8 0.035 0.04" />
        </geometry>
      </collision>
    <collision name="hinge_knuckle">
      <origin xyz="0 0 0" rpy="1.5708 0 0" />
      <geometry>
        <cylinder radius="0.022" length="0.32" />
        </geometry>
      </collision>
    <collision name="hinge_leaf">
      <origin xyz="-0.075 0 0" rpy="0 0 0" />
      <geometry>
        <box size="0.11 0.26 0.012" />
        </geometry>
      </collision>
    <collision name="tool_tray_shelf">
      <origin xyz="-0.885 0 -0.055" rpy="0 0 0" />
      <geometry>
        <box size="0.11 1.1 0.025" />
        </geometry>
      </collision>
    <collision name="tool_tray_back">
      <origin xyz="-0.827 0 -0.012" rpy="0 0 0" />
      <geometry>
        <box size="0.025 1.1 0.09" />
        </geometry>
      </collision>
    <collision name="tool_tray_lip">
      <origin xyz="-0.94 0 -0.025" rpy="0 0 0" />
      <geometry>
        <box size="0.025 1.1 0.07" />
        </geometry>
      </collision>
    <collision name="runner_0">
      <origin xyz="-0.5 -0.28 -0.085" rpy="0 0 0" />
      <geometry>
        <box size="0.62 0.035 0.035" />
        </geometry>
      </collision>
    <collision name="runner_1">
      <origin xyz="-0.5 0.28 -0.085" rpy="0 0 0" />
      <geometry>
        <box size="0.62 0.035 0.035" />
        </geometry>
      </collision>
    <collision name="runner_hanger_0_0">
      <origin xyz="-0.22 -0.28 -0.032" rpy="0 0 0" />
      <geometry>
        <box size="0.035 0.035 0.08" />
        </geometry>
      </collision>
    <collision name="runner_hanger_0_1">
      <origin xyz="-0.62 -0.28 -0.032" rpy="0 0 0" />
      <geometry>
        <box size="0.035 0.035 0.08" />
        </geometry>
      </collision>
    <collision name="runner_hanger_1_0">
      <origin xyz="-0.22 0.28 -0.032" rpy="0 0 0" />
      <geometry>
        <box size="0.035 0.035 0.08" />
        </geometry>
      </collision>
    <collision name="runner_hanger_1_1">
      <origin xyz="-0.62 0.28 -0.032" rpy="0 0 0" />
      <geometry>
        <box size="0.035 0.035 0.08" />
        </geometry>
      </collision>
    </link>
  <link name="drawer">
    <visual name="drawer_bottom">
      <origin xyz="0 0 -0.03" rpy="0 0 0" />
      <geometry>
        <box size="0.42 0.42 0.016" />
        </geometry>
      <material name="drawer_off_white">
        <color rgba="0.82 0.8 0.72 1" />
        </material>
      </visual>
    <visual name="drawer_side_0">
      <origin xyz="0 -0.211 0" rpy="0 0 0" />
      <geometry>
        <box size="0.42 0.018 0.07" />
        </geometry>
      <material name="drawer_off_white">
        <color rgba="0.82 0.8 0.72 1" />
        </material>
      </visual>
    <visual name="drawer_side_1">
      <origin xyz="0 0.211 0" rpy="0 0 0" />
      <geometry>
        <box size="0.42 0.018 0.07" />
        </geometry>
      <material name="drawer_off_white">
        <color rgba="0.82 0.8 0.72 1" />
        </material>
      </visual>
    <visual name="drawer_front">
      <origin xyz="-0.22 0 0.005" rpy="0 0 0" />
      <geometry>
        <box size="0.024 0.46 0.09" />
        </geometry>
      <material name="drawer_off_white">
        <color rgba="0.82 0.8 0.72 1" />
        </material>
      </visual>
    <visual name="drawer_back">
      <origin xyz="0.205 0 -0.005" rpy="0 0 0" />
      <geometry>
        <box size="0.022 0.42 0.06" />
        </geometry>
      <material name="drawer_off_white">
        <color rgba="0.82 0.8 0.72 1" />
        </material>
      </visual>
    <visual name="glide_0">
      <origin xyz="0 -0.262 0.0455" rpy="0 0 0" />
      <geometry>
        <box size="0.32 0.03 0.014" />
        </geometry>
      <material name="dark_steel">
        <color rgba="0.05 0.055 0.06 1" />
        </material>
      </visual>
    <visual name="glide_web_0">
      <origin xyz="0 -0.2335 0.0425" rpy="0 0 0" />
      <geometry>
        <box size="0.32 0.03 0.025" />
        </geometry>
      <material name="dark_steel">
        <color rgba="0.05 0.055 0.06 1" />
        </material>
      </visual>
    <visual name="glide_1">
      <origin xyz="0 0.262 0.0455" rpy="0 0 0" />
      <geometry>
        <box size="0.32 0.03 0.014" />
        </geometry>
      <material name="dark_steel">
        <color rgba="0.05 0.055 0.06 1" />
        </material>
      </visual>
    <visual name="glide_web_1">
      <origin xyz="0 0.2335 0.0425" rpy="0 0 0" />
      <geometry>
        <box size="0.32 0.03 0.025" />
        </geometry>
      <material name="dark_steel">
        <color rgba="0.05 0.055 0.06 1" />
        </material>
      </visual>
    <visual name="handle_stem_0">
      <origin xyz="-0.25 -0.08 0.015" rpy="0 0 0" />
      <geometry>
        <box size="0.045 0.015 0.018" />
        </geometry>
      <material name="dark_steel">
        <color rgba="0.05 0.055 0.06 1" />
        </material>
      </visual>
    <visual name="handle_stem_1">
      <origin xyz="-0.25 0.08 0.015" rpy="0 0 0" />
      <geometry>
        <box size="0.045 0.015 0.018" />
        </geometry>
      <material name="dark_steel">
        <color rgba="0.05 0.055 0.06 1" />
        </material>
      </visual>
    <visual name="drawer_pull">
      <origin xyz="-0.278 0 0.015" rpy="1.5708 0 0" />
      <geometry>
        <cylinder radius="0.011" length="0.22" />
        </geometry>
      <material name="dark_steel">
        <color rgba="0.05 0.055 0.06 1" />
        </material>
      </visual>
    <collision name="drawer_bottom">
      <origin xyz="0 0 -0.03" rpy="0 0 0" />
      <geometry>
        <box size="0.42 0.42 0.016" />
        </geometry>
      </collision>
    <collision name="drawer_side_0">
      <origin xyz="0 -0.211 0" rpy="0 0 0" />
      <geometry>
        <box size="0.42 0.018 0.07" />
        </geometry>
      </collision>
    <collision name="drawer_side_1">
      <origin xyz="0 0.211 0" rpy="0 0 0" />
      <geometry>
        <box size="0.42 0.018 0.07" />
        </geometry>
      </collision>
    <collision name="drawer_front">
      <origin xyz="-0.22 0 0.005" rpy="0 0 0" />
      <geometry>
        <box size="0.024 0.46 0.09" />
        </geometry>
      </collision>
    <collision name="drawer_back">
      <origin xyz="0.205 0 -0.005" rpy="0 0 0" />
      <geometry>
        <box size="0.022 0.42 0.06" />
        </geometry>
      </collision>
    <collision name="glide_0">
      <origin xyz="0 -0.262 0.0455" rpy="0 0 0" />
      <geometry>
        <box size="0.32 0.03 0.014" />
        </geometry>
      </collision>
    <collision name="glide_web_0">
      <origin xyz="0 -0.2335 0.0425" rpy="0 0 0" />
      <geometry>
        <box size="0.32 0.03 0.025" />
        </geometry>
      </collision>
    <collision name="glide_1">
      <origin xyz="0 0.262 0.0455" rpy="0 0 0" />
      <geometry>
        <box size="0.32 0.03 0.014" />
        </geometry>
      </collision>
    <collision name="glide_web_1">
      <origin xyz="0 0.2335 0.0425" rpy="0 0 0" />
      <geometry>
        <box size="0.32 0.03 0.025" />
        </geometry>
      </collision>
    <collision name="handle_stem_0">
      <origin xyz="-0.25 -0.08 0.015" rpy="0 0 0" />
      <geometry>
        <box size="0.045 0.015 0.018" />
        </geometry>
      </collision>
    <collision name="handle_stem_1">
      <origin xyz="-0.25 0.08 0.015" rpy="0 0 0" />
      <geometry>
        <box size="0.045 0.015 0.018" />
        </geometry>
      </collision>
    <collision name="drawer_pull">
      <origin xyz="-0.278 0 0.015" rpy="1.5708 0 0" />
      <geometry>
        <cylinder radius="0.011" length="0.22" />
        </geometry>
      </collision>
    </link>
  <joint name="base_to_column" type="prismatic">
    <origin xyz="0 0 0.62" rpy="0 0 0" />
    <parent link="floor_base" />
    <child link="height_column" />
    <axis xyz="0 0 1" />
    <limit effort="140" velocity="0.18" lower="0" upper="0.32" />
    </joint>
  <joint name="column_to_support" type="fixed">
    <origin xyz="0 0 0.36" rpy="0 0 0" />
    <parent link="height_column" />
    <child link="board_support" />
    </joint>
  <joint name="support_to_board" type="revolute">
    <origin xyz="0.16 0 0.19" rpy="0 0 0" />
    <parent link="board_support" />
    <child link="board" />
    <axis xyz="0 1 0" />
    <limit effort="65" velocity="0.7" lower="0" upper="0.95" />
    </joint>
  <joint name="board_to_drawer" type="prismatic">
    <origin xyz="-0.5 0 -0.155" rpy="0 0 0" />
    <parent link="board" />
    <child link="drawer" />
    <axis xyz="-1 0 0" />
    <limit effort="35" velocity="0.25" lower="0" upper="0.25" />
    </joint>
  </robot>
