<robot name="wheelie_bin">
  <material name="green_plastic">
    <color rgba="0.08 0.3 0.18 1" />
    </material>
  <material name="lid_green">
    <color rgba="0.1 0.36 0.2 1" />
    </material>
  <material name="dark_green">
    <color rgba="0.045 0.17 0.1 1" />
    </material>
  <material name="black_rubber">
    <color rgba="0.018 0.018 0.016 1" />
    </material>
  <material name="dark_steel">
    <color rgba="0.22 0.23 0.22 1" />
    </material>
  <material name="grey_plastic">
    <color rgba="0.3 0.32 0.3 1" />
    </material>
  <material name="cavity_shadow">
    <color rgba="0.015 0.03 0.02 1" />
    </material>
  <link name="body">
    <visual name="body_shell">
      <geometry>
        <mesh filename="assets/meshes/tapered_bin_body.obj" />
        </geometry>
      <material name="green_plastic">
        <color rgba="0.08 0.3 0.18 1" />
        </material>
      </visual>
    <visual name="inside_floor">
      <origin xyz="0 0.035 0.294" rpy="0 0 0" />
      <geometry>
        <box size="0.35 0.4 0.006" />
        </geometry>
      <material name="cavity_shadow">
        <color rgba="0.015 0.03 0.02 1" />
        </material>
      </visual>
    <visual name="front_rib_0">
      <origin xyz="-0.18 0.37 0.565" rpy="0 0 0" />
      <geometry>
        <box size="0.045 0.03 0.46" />
        </geometry>
      <material name="dark_green">
        <color rgba="0.045 0.17 0.1 1" />
        </material>
      </visual>
    <visual name="front_rib_1">
      <origin xyz="0.18 0.37 0.565" rpy="0 0 0" />
      <geometry>
        <box size="0.045 0.03 0.46" />
        </geometry>
      <material name="dark_green">
        <color rgba="0.045 0.17 0.1 1" />
        </material>
      </visual>
    <visual name="front_band">
      <origin xyz="0 0.397 0.815" rpy="0 0 0" />
      <geometry>
        <box size="0.44 0.028 0.055" />
        </geometry>
      <material name="dark_green">
        <color rgba="0.045 0.17 0.1 1" />
        </material>
      </visual>
    <visual name="side_pad_0">
      <origin xyz="-0.272 0.02 0.57" rpy="0 0 0" />
      <geometry>
        <box size="0.035 0.34 0.23" />
        </geometry>
      <material name="dark_green">
        <color rgba="0.045 0.17 0.1 1" />
        </material>
      </visual>
    <visual name="side_pad_1">
      <origin xyz="0.272 0.02 0.57" rpy="0 0 0" />
      <geometry>
        <box size="0.035 0.34 0.23" />
        </geometry>
      <material name="dark_green">
        <color rgba="0.045 0.17 0.1 1" />
        </material>
      </visual>
    <visual name="rear_handle">
      <origin xyz="0 -0.432 0.86" rpy="0 1.5708 0" />
      <geometry>
        <cylinder radius="0.02" length="0.66" />
        </geometry>
      <material name="dark_green">
        <color rgba="0.045 0.17 0.1 1" />
        </material>
      </visual>
    <visual name="handle_mount_0">
      <origin xyz="-0.235 -0.389 0.85" rpy="0 0 0" />
      <geometry>
        <box size="0.085 0.105 0.07" />
        </geometry>
      <material name="green_plastic">
        <color rgba="0.08 0.3 0.18 1" />
        </material>
      </visual>
    <visual name="handle_mount_1">
      <origin xyz="0.235 -0.389 0.85" rpy="0 0 0" />
      <geometry>
        <box size="0.085 0.105 0.07" />
        </geometry>
      <material name="green_plastic">
        <color rgba="0.08 0.3 0.18 1" />
        </material>
      </visual>
    <visual name="hinge_pad_0">
      <origin xyz="-0.27 -0.369 0.949" rpy="0 0 0" />
      <geometry>
        <box size="0.115 0.058 0.06" />
        </geometry>
      <material name="green_plastic">
        <color rgba="0.08 0.3 0.18 1" />
        </material>
      </visual>
    <visual name="hinge_pad_1">
      <origin xyz="0.27 -0.369 0.949" rpy="0 0 0" />
      <geometry>
        <box size="0.115 0.058 0.06" />
        </geometry>
      <material name="green_plastic">
        <color rgba="0.08 0.3 0.18 1" />
        </material>
      </visual>
    <visual name="rear_axle">
      <origin xyz="0 -0.27 0.145" rpy="0 1.5708 0" />
      <geometry>
        <cylinder radius="0.02" length="0.64" />
        </geometry>
      <material name="dark_steel">
        <color rgba="0.22 0.23 0.22 1" />
        </material>
      </visual>
    <visual name="axle_washer_0">
      <origin xyz="-0.313 -0.27 0.145" rpy="0 1.5708 0" />
      <geometry>
        <cylinder radius="0.052" length="0.014" />
        </geometry>
      <material name="dark_steel">
        <color rgba="0.22 0.23 0.22 1" />
        </material>
      </visual>
    <visual name="axle_washer_1">
      <origin xyz="0.313 -0.27 0.145" rpy="0 1.5708 0" />
      <geometry>
        <cylinder radius="0.052" length="0.014" />
        </geometry>
      <material name="dark_steel">
        <color rgba="0.22 0.23 0.22 1" />
        </material>
      </visual>
    <visual name="axle_bracket_0">
      <origin xyz="-0.235 -0.246 0.185" rpy="0 0 0" />
      <geometry>
        <box size="0.072 0.1 0.12" />
        </geometry>
      <material name="dark_green">
        <color rgba="0.045 0.17 0.1 1" />
        </material>
      </visual>
    <visual name="axle_bracket_1">
      <origin xyz="0.235 -0.246 0.185" rpy="0 0 0" />
      <geometry>
        <box size="0.072 0.1 0.12" />
        </geometry>
      <material name="dark_green">
        <color rgba="0.045 0.17 0.1 1" />
        </material>
      </visual>
    <visual name="rear_foot_bar">
      <origin xyz="0 -0.25 0.245" rpy="0 0 0" />
      <geometry>
        <box size="0.36 0.07 0.05" />
        </geometry>
      <material name="dark_green">
        <color rgba="0.045 0.17 0.1 1" />
        </material>
      </visual>
    <collision name="body_shell">
      <geometry>
        <mesh filename="assets/meshes/tapered_bin_body.obj" />
        </geometry>
      </collision>
    <collision name="inside_floor">
      <origin xyz="0 0.035 0.294" rpy="0 0 0" />
      <geometry>
        <box size="0.35 0.4 0.006" />
        </geometry>
      </collision>
    <collision name="front_rib_0">
      <origin xyz="-0.18 0.37 0.565" rpy="0 0 0" />
      <geometry>
        <box size="0.045 0.03 0.46" />
        </geometry>
      </collision>
    <collision name="front_rib_1">
      <origin xyz="0.18 0.37 0.565" rpy="0 0 0" />
      <geometry>
        <box size="0.045 0.03 0.46" />
        </geometry>
      </collision>
    <collision name="front_band">
      <origin xyz="0 0.397 0.815" rpy="0 0 0" />
      <geometry>
        <box size="0.44 0.028 0.055" />
        </geometry>
      </collision>
    <collision name="side_pad_0">
      <origin xyz="-0.272 0.02 0.57" rpy="0 0 0" />
      <geometry>
        <box size="0.035 0.34 0.23" />
        </geometry>
      </collision>
    <collision name="side_pad_1">
      <origin xyz="0.272 0.02 0.57" rpy="0 0 0" />
      <geometry>
        <box size="0.035 0.34 0.23" />
        </geometry>
      </collision>
    <collision name="rear_handle">
      <origin xyz="0 -0.432 0.86" rpy="0 1.5708 0" />
      <geometry>
        <cylinder radius="0.02" length="0.66" />
        </geometry>
      </collision>
    <collision name="handle_mount_0">
      <origin xyz="-0.235 -0.389 0.85" rpy="0 0 0" />
      <geometry>
        <box size="0.085 0.105 0.07" />
        </geometry>
      </collision>
    <collision name="handle_mount_1">
      <origin xyz="0.235 -0.389 0.85" rpy="0 0 0" />
      <geometry>
        <box size="0.085 0.105 0.07" />
        </geometry>
      </collision>
    <collision name="hinge_pad_0">
      <origin xyz="-0.27 -0.369 0.949" rpy="0 0 0" />
      <geometry>
        <box size="0.115 0.058 0.06" />
        </geometry>
      </collision>
    <collision name="hinge_pad_1">
      <origin xyz="0.27 -0.369 0.949" rpy="0 0 0" />
      <geometry>
        <box size="0.115 0.058 0.06" />
        </geometry>
      </collision>
    <collision name="rear_axle">
      <origin xyz="0 -0.27 0.145" rpy="0 1.5708 0" />
      <geometry>
        <cylinder radius="0.02" length="0.64" />
        </geometry>
      </collision>
    <collision name="axle_washer_0">
      <origin xyz="-0.313 -0.27 0.145" rpy="0 1.5708 0" />
      <geometry>
        <cylinder radius="0.052" length="0.014" />
        </geometry>
      </collision>
    <collision name="axle_washer_1">
      <origin xyz="0.313 -0.27 0.145" rpy="0 1.5708 0" />
      <geometry>
        <cylinder radius="0.052" length="0.014" />
        </geometry>
      </collision>
    <collision name="axle_bracket_0">
      <origin xyz="-0.235 -0.246 0.185" rpy="0 0 0" />
      <geometry>
        <box size="0.072 0.1 0.12" />
        </geometry>
      </collision>
    <collision name="axle_bracket_1">
      <origin xyz="0.235 -0.246 0.185" rpy="0 0 0" />
      <geometry>
        <box size="0.072 0.1 0.12" />
        </geometry>
      </collision>
    <collision name="rear_foot_bar">
      <origin xyz="0 -0.25 0.245" rpy="0 0 0" />
      <geometry>
        <box size="0.36 0.07 0.05" />
        </geometry>
      </collision>
    </link>
  <link name="lid">
    <visual name="lid_shell">
      <geometry>
        <mesh filename="assets/meshes/short_deep_lid.obj" />
        </geometry>
      <material name="lid_green">
        <color rgba="0.1 0.36 0.2 1" />
        </material>
      </visual>
    <visual name="hinge_barrel">
      <origin xyz="0 -0.005 0.012" rpy="0 1.5708 0" />
      <geometry>
        <cylinder radius="0.018" length="0.66" />
        </geometry>
      <material name="lid_green">
        <color rgba="0.1 0.36 0.2 1" />
        </material>
      </visual>
    <visual name="front_lip">
      <origin xyz="0 0.805 -0.004" rpy="0 0 0" />
      <geometry>
        <box size="0.61 0.04 0.052" />
        </geometry>
      <material name="dark_green">
        <color rgba="0.045 0.17 0.1 1" />
        </material>
      </visual>
    <visual name="side_lip_0">
      <origin xyz="-0.255 0.435 -0.002" rpy="0 0 0" />
      <geometry>
        <box size="0.044 0.65 0.03" />
        </geometry>
      <material name="dark_green">
        <color rgba="0.045 0.17 0.1 1" />
        </material>
      </visual>
    <visual name="side_lip_1">
      <origin xyz="0.255 0.435 -0.002" rpy="0 0 0" />
      <geometry>
        <box size="0.044 0.65 0.03" />
        </geometry>
      <material name="dark_green">
        <color rgba="0.045 0.17 0.1 1" />
        </material>
      </visual>
    <collision name="lid_shell">
      <geometry>
        <mesh filename="assets/meshes/short_deep_lid.obj" />
        </geometry>
      </collision>
    <collision name="hinge_barrel">
      <origin xyz="0 -0.005 0.012" rpy="0 1.5708 0" />
      <geometry>
        <cylinder radius="0.018" length="0.66" />
        </geometry>
      </collision>
    <collision name="front_lip">
      <origin xyz="0 0.805 -0.004" rpy="0 0 0" />
      <geometry>
        <box size="0.61 0.04 0.052" />
        </geometry>
      </collision>
    <collision name="side_lip_0">
      <origin xyz="-0.255 0.435 -0.002" rpy="0 0 0" />
      <geometry>
        <box size="0.044 0.65 0.03" />
        </geometry>
      </collision>
    <collision name="side_lip_1">
      <origin xyz="0.255 0.435 -0.002" rpy="0 0 0" />
      <geometry>
        <box size="0.044 0.65 0.03" />
        </geometry>
      </collision>
    </link>
  <link name="wheel_0">
    <visual name="tire">
      <geometry>
        <mesh filename="assets/meshes/wheel_0_tire.obj" />
        </geometry>
      <material name="black_rubber">
        <color rgba="0.018 0.018 0.016 1" />
        </material>
      </visual>
    <visual name="rim">
      <origin xyz="0 0 0" rpy="0 1.5708 0" />
      <geometry>
        <cylinder radius="0.095" length="0.072" />
        </geometry>
      <material name="grey_plastic">
        <color rgba="0.3 0.32 0.3 1" />
        </material>
      </visual>
    <visual name="hub_cap">
      <origin xyz="0 0 0" rpy="0 1.5708 0" />
      <geometry>
        <cylinder radius="0.036" length="0.09" />
        </geometry>
      <material name="dark_steel">
        <color rgba="0.22 0.23 0.22 1" />
        </material>
      </visual>
    <collision name="tire">
      <geometry>
        <mesh filename="assets/meshes/wheel_0_tire.obj" />
        </geometry>
      </collision>
    <collision name="rim">
      <origin xyz="0 0 0" rpy="0 1.5708 0" />
      <geometry>
        <cylinder radius="0.095" length="0.072" />
        </geometry>
      </collision>
    <collision name="hub_cap">
      <origin xyz="0 0 0" rpy="0 1.5708 0" />
      <geometry>
        <cylinder radius="0.036" length="0.09" />
        </geometry>
      </collision>
    </link>
  <link name="wheel_1">
    <visual name="tire">
      <geometry>
        <mesh filename="assets/meshes/wheel_1_tire.obj" />
        </geometry>
      <material name="black_rubber">
        <color rgba="0.018 0.018 0.016 1" />
        </material>
      </visual>
    <visual name="rim">
      <origin xyz="0 0 0" rpy="0 1.5708 0" />
      <geometry>
        <cylinder radius="0.095" length="0.072" />
        </geometry>
      <material name="grey_plastic">
        <color rgba="0.3 0.32 0.3 1" />
        </material>
      </visual>
    <visual name="hub_cap">
      <origin xyz="0 0 0" rpy="0 1.5708 0" />
      <geometry>
        <cylinder radius="0.036" length="0.09" />
        </geometry>
      <material name="dark_steel">
        <color rgba="0.22 0.23 0.22 1" />
        </material>
      </visual>
    <collision name="tire">
      <geometry>
        <mesh filename="assets/meshes/wheel_1_tire.obj" />
        </geometry>
      </collision>
    <collision name="rim">
      <origin xyz="0 0 0" rpy="0 1.5708 0" />
      <geometry>
        <cylinder radius="0.095" length="0.072" />
        </geometry>
      </collision>
    <collision name="hub_cap">
      <origin xyz="0 0 0" rpy="0 1.5708 0" />
      <geometry>
        <cylinder radius="0.036" length="0.09" />
        </geometry>
      </collision>
    </link>
  <joint name="lid_hinge" type="revolute">
    <origin xyz="0 -0.385 0.985" rpy="0 0 0" />
    <parent link="body" />
    <child link="lid" />
    <axis xyz="1 0 0" />
    <limit effort="8" velocity="2" lower="0" upper="1.8326" />
    </joint>
  <joint name="wheel_0_spin" type="continuous">
    <origin xyz="-0.365 -0.27 0.145" rpy="0 0 0" />
    <parent link="body" />
    <child link="wheel_0" />
    <axis xyz="1 0 0" />
    <limit effort="6" velocity="18" />
    </joint>
  <joint name="wheel_1_spin" type="continuous">
    <origin xyz="0.365 -0.27 0.145" rpy="0 0 0" />
    <parent link="body" />
    <child link="wheel_1" />
    <axis xyz="1 0 0" />
    <limit effort="6" velocity="18" />
    </joint>
  </robot>
