<robot name="warehouse_platform_cart">
  <material name="powder_coated_blue">
    <color rgba="0.05 0.17 0.34 1" />
    </material>
  <material name="dark_rubber">
    <color rgba="0.01 0.01 0.012 1" />
    </material>
  <material name="galvanized_steel">
    <color rgba="0.62 0.64 0.62 1" />
    </material>
  <material name="worn_steel">
    <color rgba="0.42 0.43 0.42 1" />
    </material>
  <material name="worn_safety_yellow">
    <color rgba="0.95 0.7 0.1 1" />
    </material>
  <link name="deck">
    <visual name="flat_deck">
      <origin xyz="0 0 0.235" rpy="0 0 0" />
      <geometry>
        <box size="1.1 0.62 0.06" />
        </geometry>
      <material name="powder_coated_blue">
        <color rgba="0.05 0.17 0.34 1" />
        </material>
      </visual>
    <visual name="ribbed_deck_mat">
      <origin xyz="0 0 0.269" rpy="0 0 0" />
      <geometry>
        <box size="0.94 0.46 0.008" />
        </geometry>
      <material name="dark_rubber">
        <color rgba="0.01 0.01 0.012 1" />
        </material>
      </visual>
    <visual name="deck_tread_rib_0">
      <origin xyz="0 -0.18 0.276" rpy="0 0 0" />
      <geometry>
        <box size="0.9 0.012 0.01" />
        </geometry>
      <material name="worn_steel">
        <color rgba="0.42 0.43 0.42 1" />
        </material>
      </visual>
    <visual name="deck_tread_rib_1">
      <origin xyz="0 0 0.276" rpy="0 0 0" />
      <geometry>
        <box size="0.9 0.012 0.01" />
        </geometry>
      <material name="worn_steel">
        <color rgba="0.42 0.43 0.42 1" />
        </material>
      </visual>
    <visual name="deck_tread_rib_2">
      <origin xyz="0 0.18 0.276" rpy="0 0 0" />
      <geometry>
        <box size="0.9 0.012 0.01" />
        </geometry>
      <material name="worn_steel">
        <color rgba="0.42 0.43 0.42 1" />
        </material>
      </visual>
    <visual name="front_mount_0">
      <origin xyz="0.43 -0.245 0.1875" rpy="0 0 0" />
      <geometry>
        <box size="0.22 0.18 0.036" />
        </geometry>
      <material name="galvanized_steel">
        <color rgba="0.62 0.64 0.62 1" />
        </material>
      </visual>
    <visual name="front_mount_1">
      <origin xyz="0.43 0.245 0.1875" rpy="0 0 0" />
      <geometry>
        <box size="0.22 0.18 0.036" />
        </geometry>
      <material name="galvanized_steel">
        <color rgba="0.62 0.64 0.62 1" />
        </material>
      </visual>
    <visual name="rear_mount_0">
      <origin xyz="-0.43 -0.245 0.1875" rpy="0 0 0" />
      <geometry>
        <box size="0.22 0.18 0.036" />
        </geometry>
      <material name="galvanized_steel">
        <color rgba="0.62 0.64 0.62 1" />
        </material>
      </visual>
    <visual name="rear_mount_1">
      <origin xyz="-0.43 0.245 0.1875" rpy="0 0 0" />
      <geometry>
        <box size="0.22 0.18 0.036" />
        </geometry>
      <material name="galvanized_steel">
        <color rgba="0.62 0.64 0.62 1" />
        </material>
      </visual>
    <visual name="side_rail_0">
      <origin xyz="0 -0.327 0.207" rpy="0 0 0" />
      <geometry>
        <box size="1 0.035 0.045" />
        </geometry>
      <material name="powder_coated_blue">
        <color rgba="0.05 0.17 0.34 1" />
        </material>
      </visual>
    <visual name="side_rail_1">
      <origin xyz="0 0.327 0.207" rpy="0 0 0" />
      <geometry>
        <box size="1 0.035 0.045" />
        </geometry>
      <material name="powder_coated_blue">
        <color rgba="0.05 0.17 0.34 1" />
        </material>
      </visual>
    <visual name="front_nose_rail">
      <origin xyz="0.557 0 0.207" rpy="0 0 0" />
      <geometry>
        <box size="0.035 0.58 0.045" />
        </geometry>
      <material name="powder_coated_blue">
        <color rgba="0.05 0.17 0.34 1" />
        </material>
      </visual>
    <visual name="handle_socket_0">
      <origin xyz="-0.5 -0.235 0.292" rpy="0 0 0" />
      <geometry>
        <cylinder radius="0.034" length="0.065" />
        </geometry>
      <material name="galvanized_steel">
        <color rgba="0.62 0.64 0.62 1" />
        </material>
      </visual>
    <visual name="handle_upright_0">
      <origin xyz="-0.5 -0.235 0.615" rpy="0 0 0" />
      <geometry>
        <cylinder radius="0.017" length="0.735" />
        </geometry>
      <material name="worn_safety_yellow">
        <color rgba="0.95 0.7 0.1 1" />
        </material>
      </visual>
    <visual name="handle_socket_1">
      <origin xyz="-0.5 0.235 0.292" rpy="0 0 0" />
      <geometry>
        <cylinder radius="0.034" length="0.065" />
        </geometry>
      <material name="galvanized_steel">
        <color rgba="0.62 0.64 0.62 1" />
        </material>
      </visual>
    <visual name="handle_upright_1">
      <origin xyz="-0.5 0.235 0.615" rpy="0 0 0" />
      <geometry>
        <cylinder radius="0.017" length="0.735" />
        </geometry>
      <material name="worn_safety_yellow">
        <color rgba="0.95 0.7 0.1 1" />
        </material>
      </visual>
    <visual name="handle_grip">
      <origin xyz="-0.5 0 0.98" rpy="1.5708 0 0" />
      <geometry>
        <cylinder radius="0.017" length="0.505" />
        </geometry>
      <material name="worn_safety_yellow">
        <color rgba="0.95 0.7 0.1 1" />
        </material>
      </visual>
    <visual name="handle_crossbar">
      <origin xyz="-0.5 0 0.43" rpy="1.5708 0 0" />
      <geometry>
        <cylinder radius="0.014" length="0.47" />
        </geometry>
      <material name="worn_safety_yellow">
        <color rgba="0.95 0.7 0.1 1" />
        </material>
      </visual>
    <collision name="flat_deck">
      <origin xyz="0 0 0.235" rpy="0 0 0" />
      <geometry>
        <box size="1.1 0.62 0.06" />
        </geometry>
      </collision>
    <collision name="ribbed_deck_mat">
      <origin xyz="0 0 0.269" rpy="0 0 0" />
      <geometry>
        <box size="0.94 0.46 0.008" />
        </geometry>
      </collision>
    <collision name="deck_tread_rib_0">
      <origin xyz="0 -0.18 0.276" rpy="0 0 0" />
      <geometry>
        <box size="0.9 0.012 0.01" />
        </geometry>
      </collision>
    <collision name="deck_tread_rib_1">
      <origin xyz="0 0 0.276" rpy="0 0 0" />
      <geometry>
        <box size="0.9 0.012 0.01" />
        </geometry>
      </collision>
    <collision name="deck_tread_rib_2">
      <origin xyz="0 0.18 0.276" rpy="0 0 0" />
      <geometry>
        <box size="0.9 0.012 0.01" />
        </geometry>
      </collision>
    <collision name="front_mount_0">
      <origin xyz="0.43 -0.245 0.1875" rpy="0 0 0" />
      <geometry>
        <box size="0.22 0.18 0.036" />
        </geometry>
      </collision>
    <collision name="front_mount_1">
      <origin xyz="0.43 0.245 0.1875" rpy="0 0 0" />
      <geometry>
        <box size="0.22 0.18 0.036" />
        </geometry>
      </collision>
    <collision name="rear_mount_0">
      <origin xyz="-0.43 -0.245 0.1875" rpy="0 0 0" />
      <geometry>
        <box size="0.22 0.18 0.036" />
        </geometry>
      </collision>
    <collision name="rear_mount_1">
      <origin xyz="-0.43 0.245 0.1875" rpy="0 0 0" />
      <geometry>
        <box size="0.22 0.18 0.036" />
        </geometry>
      </collision>
    <collision name="side_rail_0">
      <origin xyz="0 -0.327 0.207" rpy="0 0 0" />
      <geometry>
        <box size="1 0.035 0.045" />
        </geometry>
      </collision>
    <collision name="side_rail_1">
      <origin xyz="0 0.327 0.207" rpy="0 0 0" />
      <geometry>
        <box size="1 0.035 0.045" />
        </geometry>
      </collision>
    <collision name="front_nose_rail">
      <origin xyz="0.557 0 0.207" rpy="0 0 0" />
      <geometry>
        <box size="0.035 0.58 0.045" />
        </geometry>
      </collision>
    <collision name="handle_socket_0">
      <origin xyz="-0.5 -0.235 0.292" rpy="0 0 0" />
      <geometry>
        <cylinder radius="0.034" length="0.065" />
        </geometry>
      </collision>
    <collision name="handle_upright_0">
      <origin xyz="-0.5 -0.235 0.615" rpy="0 0 0" />
      <geometry>
        <cylinder radius="0.017" length="0.735" />
        </geometry>
      </collision>
    <collision name="handle_socket_1">
      <origin xyz="-0.5 0.235 0.292" rpy="0 0 0" />
      <geometry>
        <cylinder radius="0.034" length="0.065" />
        </geometry>
      </collision>
    <collision name="handle_upright_1">
      <origin xyz="-0.5 0.235 0.615" rpy="0 0 0" />
      <geometry>
        <cylinder radius="0.017" length="0.735" />
        </geometry>
      </collision>
    <collision name="handle_grip">
      <origin xyz="-0.5 0 0.98" rpy="1.5708 0 0" />
      <geometry>
        <cylinder radius="0.017" length="0.505" />
        </geometry>
      </collision>
    <collision name="handle_crossbar">
      <origin xyz="-0.5 0 0.43" rpy="1.5708 0 0" />
      <geometry>
        <cylinder radius="0.014" length="0.47" />
        </geometry>
      </collision>
    </link>
  <link name="front_fork_0">
    <visual name="swivel_plate">
      <origin xyz="0 0 -0.009" rpy="0 0 0" />
      <geometry>
        <cylinder radius="0.055" length="0.018" />
        </geometry>
      <material name="galvanized_steel">
        <color rgba="0.62 0.64 0.62 1" />
        </material>
      </visual>
    <visual name="swivel_stem">
      <origin xyz="0 0 -0.006" rpy="0 0 0" />
      <geometry>
        <cylinder radius="0.018" length="0.012" />
        </geometry>
      <material name="galvanized_steel">
        <color rgba="0.62 0.64 0.62 1" />
        </material>
      </visual>
    <visual name="fork_crown">
      <origin xyz="-0.0175 0 -0.012" rpy="0 0 0" />
      <geometry>
        <box size="0.145 0.096 0.014" />
        </geometry>
      <material name="galvanized_steel">
        <color rgba="0.62 0.64 0.62 1" />
        </material>
      </visual>
    <visual name="fork_cheek_0">
      <origin xyz="-0.035 -0.041 -0.079" rpy="0 0 0" />
      <geometry>
        <box size="0.078 0.014 0.122" />
        </geometry>
      <material name="galvanized_steel">
        <color rgba="0.62 0.64 0.62 1" />
        </material>
      </visual>
    <visual name="fork_cheek_1">
      <origin xyz="-0.035 0.041 -0.079" rpy="0 0 0" />
      <geometry>
        <box size="0.078 0.014 0.122" />
        </geometry>
      <material name="galvanized_steel">
        <color rgba="0.62 0.64 0.62 1" />
        </material>
      </visual>
    <visual name="axle_pin">
      <origin xyz="-0.035 0 -0.095" rpy="1.5708 0 0" />
      <geometry>
        <cylinder radius="0.007" length="0.102" />
        </geometry>
      <material name="worn_steel">
        <color rgba="0.42 0.43 0.42 1" />
        </material>
      </visual>
    <collision name="swivel_plate">
      <origin xyz="0 0 -0.009" rpy="0 0 0" />
      <geometry>
        <cylinder radius="0.055" length="0.018" />
        </geometry>
      </collision>
    <collision name="swivel_stem">
      <origin xyz="0 0 -0.006" rpy="0 0 0" />
      <geometry>
        <cylinder radius="0.018" length="0.012" />
        </geometry>
      </collision>
    <collision name="fork_crown">
      <origin xyz="-0.0175 0 -0.012" rpy="0 0 0" />
      <geometry>
        <box size="0.145 0.096 0.014" />
        </geometry>
      </collision>
    <collision name="fork_cheek_0">
      <origin xyz="-0.035 -0.041 -0.079" rpy="0 0 0" />
      <geometry>
        <box size="0.078 0.014 0.122" />
        </geometry>
      </collision>
    <collision name="fork_cheek_1">
      <origin xyz="-0.035 0.041 -0.079" rpy="0 0 0" />
      <geometry>
        <box size="0.078 0.014 0.122" />
        </geometry>
      </collision>
    <collision name="axle_pin">
      <origin xyz="-0.035 0 -0.095" rpy="1.5708 0 0" />
      <geometry>
        <cylinder radius="0.007" length="0.102" />
        </geometry>
      </collision>
    </link>
  <link name="front_wheel_0">
    <visual name="metal_rim">
      <geometry>
        <mesh filename="assets/meshes/caster_wheel_rim.obj" />
        </geometry>
      <material name="worn_steel">
        <color rgba="0.42 0.43 0.42 1" />
        </material>
      </visual>
    <visual name="rubber_tire">
      <geometry>
        <mesh filename="assets/meshes/caster_rubber_tire.obj" />
        </geometry>
      <material name="dark_rubber">
        <color rgba="0.01 0.01 0.012 1" />
        </material>
      </visual>
    <collision name="metal_rim">
      <geometry>
        <mesh filename="assets/meshes/caster_wheel_rim.obj" />
        </geometry>
      </collision>
    <collision name="rubber_tire">
      <geometry>
        <mesh filename="assets/meshes/caster_rubber_tire.obj" />
        </geometry>
      </collision>
    </link>
  <link name="front_fork_1">
    <visual name="swivel_plate">
      <origin xyz="0 0 -0.009" rpy="0 0 0" />
      <geometry>
        <cylinder radius="0.055" length="0.018" />
        </geometry>
      <material name="galvanized_steel">
        <color rgba="0.62 0.64 0.62 1" />
        </material>
      </visual>
    <visual name="swivel_stem">
      <origin xyz="0 0 -0.006" rpy="0 0 0" />
      <geometry>
        <cylinder radius="0.018" length="0.012" />
        </geometry>
      <material name="galvanized_steel">
        <color rgba="0.62 0.64 0.62 1" />
        </material>
      </visual>
    <visual name="fork_crown">
      <origin xyz="-0.0175 0 -0.012" rpy="0 0 0" />
      <geometry>
        <box size="0.145 0.096 0.014" />
        </geometry>
      <material name="galvanized_steel">
        <color rgba="0.62 0.64 0.62 1" />
        </material>
      </visual>
    <visual name="fork_cheek_0">
      <origin xyz="-0.035 -0.041 -0.079" rpy="0 0 0" />
      <geometry>
        <box size="0.078 0.014 0.122" />
        </geometry>
      <material name="galvanized_steel">
        <color rgba="0.62 0.64 0.62 1" />
        </material>
      </visual>
    <visual name="fork_cheek_1">
      <origin xyz="-0.035 0.041 -0.079" rpy="0 0 0" />
      <geometry>
        <box size="0.078 0.014 0.122" />
        </geometry>
      <material name="galvanized_steel">
        <color rgba="0.62 0.64 0.62 1" />
        </material>
      </visual>
    <visual name="axle_pin">
      <origin xyz="-0.035 0 -0.095" rpy="1.5708 0 0" />
      <geometry>
        <cylinder radius="0.007" length="0.102" />
        </geometry>
      <material name="worn_steel">
        <color rgba="0.42 0.43 0.42 1" />
        </material>
      </visual>
    <collision name="swivel_plate">
      <origin xyz="0 0 -0.009" rpy="0 0 0" />
      <geometry>
        <cylinder radius="0.055" length="0.018" />
        </geometry>
      </collision>
    <collision name="swivel_stem">
      <origin xyz="0 0 -0.006" rpy="0 0 0" />
      <geometry>
        <cylinder radius="0.018" length="0.012" />
        </geometry>
      </collision>
    <collision name="fork_crown">
      <origin xyz="-0.0175 0 -0.012" rpy="0 0 0" />
      <geometry>
        <box size="0.145 0.096 0.014" />
        </geometry>
      </collision>
    <collision name="fork_cheek_0">
      <origin xyz="-0.035 -0.041 -0.079" rpy="0 0 0" />
      <geometry>
        <box size="0.078 0.014 0.122" />
        </geometry>
      </collision>
    <collision name="fork_cheek_1">
      <origin xyz="-0.035 0.041 -0.079" rpy="0 0 0" />
      <geometry>
        <box size="0.078 0.014 0.122" />
        </geometry>
      </collision>
    <collision name="axle_pin">
      <origin xyz="-0.035 0 -0.095" rpy="1.5708 0 0" />
      <geometry>
        <cylinder radius="0.007" length="0.102" />
        </geometry>
      </collision>
    </link>
  <link name="front_wheel_1">
    <visual name="metal_rim">
      <geometry>
        <mesh filename="assets/meshes/caster_wheel_rim.obj" />
        </geometry>
      <material name="worn_steel">
        <color rgba="0.42 0.43 0.42 1" />
        </material>
      </visual>
    <visual name="rubber_tire">
      <geometry>
        <mesh filename="assets/meshes/caster_rubber_tire.obj" />
        </geometry>
      <material name="dark_rubber">
        <color rgba="0.01 0.01 0.012 1" />
        </material>
      </visual>
    <collision name="metal_rim">
      <geometry>
        <mesh filename="assets/meshes/caster_wheel_rim.obj" />
        </geometry>
      </collision>
    <collision name="rubber_tire">
      <geometry>
        <mesh filename="assets/meshes/caster_rubber_tire.obj" />
        </geometry>
      </collision>
    </link>
  <link name="rear_fork_0">
    <visual name="swivel_plate">
      <origin xyz="0 0 -0.009" rpy="0 0 0" />
      <geometry>
        <cylinder radius="0.055" length="0.018" />
        </geometry>
      <material name="galvanized_steel">
        <color rgba="0.62 0.64 0.62 1" />
        </material>
      </visual>
    <visual name="swivel_stem">
      <origin xyz="0 0 -0.006" rpy="0 0 0" />
      <geometry>
        <cylinder radius="0.018" length="0.012" />
        </geometry>
      <material name="galvanized_steel">
        <color rgba="0.62 0.64 0.62 1" />
        </material>
      </visual>
    <visual name="fork_crown">
      <origin xyz="-0 0 -0.012" rpy="0 0 0" />
      <geometry>
        <box size="0.11 0.096 0.014" />
        </geometry>
      <material name="galvanized_steel">
        <color rgba="0.62 0.64 0.62 1" />
        </material>
      </visual>
    <visual name="fork_cheek_0">
      <origin xyz="-0 -0.041 -0.079" rpy="0 0 0" />
      <geometry>
        <box size="0.078 0.014 0.122" />
        </geometry>
      <material name="galvanized_steel">
        <color rgba="0.62 0.64 0.62 1" />
        </material>
      </visual>
    <visual name="fork_cheek_1">
      <origin xyz="-0 0.041 -0.079" rpy="0 0 0" />
      <geometry>
        <box size="0.078 0.014 0.122" />
        </geometry>
      <material name="galvanized_steel">
        <color rgba="0.62 0.64 0.62 1" />
        </material>
      </visual>
    <visual name="axle_pin">
      <origin xyz="-0 0 -0.095" rpy="1.5708 0 0" />
      <geometry>
        <cylinder radius="0.007" length="0.102" />
        </geometry>
      <material name="worn_steel">
        <color rgba="0.42 0.43 0.42 1" />
        </material>
      </visual>
    <collision name="swivel_plate">
      <origin xyz="0 0 -0.009" rpy="0 0 0" />
      <geometry>
        <cylinder radius="0.055" length="0.018" />
        </geometry>
      </collision>
    <collision name="swivel_stem">
      <origin xyz="0 0 -0.006" rpy="0 0 0" />
      <geometry>
        <cylinder radius="0.018" length="0.012" />
        </geometry>
      </collision>
    <collision name="fork_crown">
      <origin xyz="-0 0 -0.012" rpy="0 0 0" />
      <geometry>
        <box size="0.11 0.096 0.014" />
        </geometry>
      </collision>
    <collision name="fork_cheek_0">
      <origin xyz="-0 -0.041 -0.079" rpy="0 0 0" />
      <geometry>
        <box size="0.078 0.014 0.122" />
        </geometry>
      </collision>
    <collision name="fork_cheek_1">
      <origin xyz="-0 0.041 -0.079" rpy="0 0 0" />
      <geometry>
        <box size="0.078 0.014 0.122" />
        </geometry>
      </collision>
    <collision name="axle_pin">
      <origin xyz="-0 0 -0.095" rpy="1.5708 0 0" />
      <geometry>
        <cylinder radius="0.007" length="0.102" />
        </geometry>
      </collision>
    </link>
  <link name="rear_wheel_0">
    <visual name="metal_rim">
      <geometry>
        <mesh filename="assets/meshes/caster_wheel_rim.obj" />
        </geometry>
      <material name="worn_steel">
        <color rgba="0.42 0.43 0.42 1" />
        </material>
      </visual>
    <visual name="rubber_tire">
      <geometry>
        <mesh filename="assets/meshes/caster_rubber_tire.obj" />
        </geometry>
      <material name="dark_rubber">
        <color rgba="0.01 0.01 0.012 1" />
        </material>
      </visual>
    <collision name="metal_rim">
      <geometry>
        <mesh filename="assets/meshes/caster_wheel_rim.obj" />
        </geometry>
      </collision>
    <collision name="rubber_tire">
      <geometry>
        <mesh filename="assets/meshes/caster_rubber_tire.obj" />
        </geometry>
      </collision>
    </link>
  <link name="rear_fork_1">
    <visual name="swivel_plate">
      <origin xyz="0 0 -0.009" rpy="0 0 0" />
      <geometry>
        <cylinder radius="0.055" length="0.018" />
        </geometry>
      <material name="galvanized_steel">
        <color rgba="0.62 0.64 0.62 1" />
        </material>
      </visual>
    <visual name="swivel_stem">
      <origin xyz="0 0 -0.006" rpy="0 0 0" />
      <geometry>
        <cylinder radius="0.018" length="0.012" />
        </geometry>
      <material name="galvanized_steel">
        <color rgba="0.62 0.64 0.62 1" />
        </material>
      </visual>
    <visual name="fork_crown">
      <origin xyz="-0 0 -0.012" rpy="0 0 0" />
      <geometry>
        <box size="0.11 0.096 0.014" />
        </geometry>
      <material name="galvanized_steel">
        <color rgba="0.62 0.64 0.62 1" />
        </material>
      </visual>
    <visual name="fork_cheek_0">
      <origin xyz="-0 -0.041 -0.079" rpy="0 0 0" />
      <geometry>
        <box size="0.078 0.014 0.122" />
        </geometry>
      <material name="galvanized_steel">
        <color rgba="0.62 0.64 0.62 1" />
        </material>
      </visual>
    <visual name="fork_cheek_1">
      <origin xyz="-0 0.041 -0.079" rpy="0 0 0" />
      <geometry>
        <box size="0.078 0.014 0.122" />
        </geometry>
      <material name="galvanized_steel">
        <color rgba="0.62 0.64 0.62 1" />
        </material>
      </visual>
    <visual name="axle_pin">
      <origin xyz="-0 0 -0.095" rpy="1.5708 0 0" />
      <geometry>
        <cylinder radius="0.007" length="0.102" />
        </geometry>
      <material name="worn_steel">
        <color rgba="0.42 0.43 0.42 1" />
        </material>
      </visual>
    <collision name="swivel_plate">
      <origin xyz="0 0 -0.009" rpy="0 0 0" />
      <geometry>
        <cylinder radius="0.055" length="0.018" />
        </geometry>
      </collision>
    <collision name="swivel_stem">
      <origin xyz="0 0 -0.006" rpy="0 0 0" />
      <geometry>
        <cylinder radius="0.018" length="0.012" />
        </geometry>
      </collision>
    <collision name="fork_crown">
      <origin xyz="-0 0 -0.012" rpy="0 0 0" />
      <geometry>
        <box size="0.11 0.096 0.014" />
        </geometry>
      </collision>
    <collision name="fork_cheek_0">
      <origin xyz="-0 -0.041 -0.079" rpy="0 0 0" />
      <geometry>
        <box size="0.078 0.014 0.122" />
        </geometry>
      </collision>
    <collision name="fork_cheek_1">
      <origin xyz="-0 0.041 -0.079" rpy="0 0 0" />
      <geometry>
        <box size="0.078 0.014 0.122" />
        </geometry>
      </collision>
    <collision name="axle_pin">
      <origin xyz="-0 0 -0.095" rpy="1.5708 0 0" />
      <geometry>
        <cylinder radius="0.007" length="0.102" />
        </geometry>
      </collision>
    </link>
  <link name="rear_wheel_1">
    <visual name="metal_rim">
      <geometry>
        <mesh filename="assets/meshes/caster_wheel_rim.obj" />
        </geometry>
      <material name="worn_steel">
        <color rgba="0.42 0.43 0.42 1" />
        </material>
      </visual>
    <visual name="rubber_tire">
      <geometry>
        <mesh filename="assets/meshes/caster_rubber_tire.obj" />
        </geometry>
      <material name="dark_rubber">
        <color rgba="0.01 0.01 0.012 1" />
        </material>
      </visual>
    <collision name="metal_rim">
      <geometry>
        <mesh filename="assets/meshes/caster_wheel_rim.obj" />
        </geometry>
      </collision>
    <collision name="rubber_tire">
      <geometry>
        <mesh filename="assets/meshes/caster_rubber_tire.obj" />
        </geometry>
      </collision>
    </link>
  <joint name="deck_to_front_fork_0" type="revolute">
    <origin xyz="0.43 -0.245 0.1695" rpy="0 0 0" />
    <parent link="deck" />
    <child link="front_fork_0" />
    <axis xyz="0 0 1" />
    <limit effort="12" velocity="5" lower="-3.14159" upper="3.14159" />
    </joint>
  <joint name="front_fork_0_to_front_wheel_0" type="continuous">
    <origin xyz="-0.035 0 -0.095" rpy="0 0 1.5708" />
    <parent link="front_fork_0" />
    <child link="front_wheel_0" />
    <axis xyz="1 0 0" />
    <limit effort="8" velocity="30" />
    </joint>
  <joint name="deck_to_front_fork_1" type="revolute">
    <origin xyz="0.43 0.245 0.1695" rpy="0 0 0" />
    <parent link="deck" />
    <child link="front_fork_1" />
    <axis xyz="0 0 1" />
    <limit effort="12" velocity="5" lower="-3.14159" upper="3.14159" />
    </joint>
  <joint name="front_fork_1_to_front_wheel_1" type="continuous">
    <origin xyz="-0.035 0 -0.095" rpy="0 0 1.5708" />
    <parent link="front_fork_1" />
    <child link="front_wheel_1" />
    <axis xyz="1 0 0" />
    <limit effort="8" velocity="30" />
    </joint>
  <joint name="deck_to_rear_fork_0" type="fixed">
    <origin xyz="-0.43 -0.245 0.1695" rpy="0 0 0" />
    <parent link="deck" />
    <child link="rear_fork_0" />
    </joint>
  <joint name="rear_fork_0_to_rear_wheel_0" type="continuous">
    <origin xyz="-0 0 -0.095" rpy="0 0 1.5708" />
    <parent link="rear_fork_0" />
    <child link="rear_wheel_0" />
    <axis xyz="1 0 0" />
    <limit effort="8" velocity="30" />
    </joint>
  <joint name="deck_to_rear_fork_1" type="fixed">
    <origin xyz="-0.43 0.245 0.1695" rpy="0 0 0" />
    <parent link="deck" />
    <child link="rear_fork_1" />
    </joint>
  <joint name="rear_fork_1_to_rear_wheel_1" type="continuous">
    <origin xyz="-0 0 -0.095" rpy="0 0 1.5708" />
    <parent link="rear_fork_1" />
    <child link="rear_wheel_1" />
    <axis xyz="1 0 0" />
    <limit effort="8" velocity="30" />
    </joint>
  </robot>
