<robot name="folding_gaming_headset">
  <material name="matte_black">
    <color rgba="0.015 0.015 0.018 1" />
    </material>
  <material name="soft_black">
    <color rgba="0.005 0.005 0.006 1" />
    </material>
  <material name="cushion">
    <color rgba="0.075 0.075 0.08 1" />
    </material>
  <material name="gunmetal">
    <color rgba="0.23 0.23 0.25 1" />
    </material>
  <material name="red_accent">
    <color rgba="0.85 0.04 0.035 1" />
    </material>
  <material name="mesh_cloth">
    <color rgba="0.025 0.026 0.03 1" />
    </material>
  <material name="dark_pin_metal">
    <color rgba="0.48 0.48 0.5 1" />
    </material>
  <link name="headband">
    <visual name="outer_band">
      <geometry>
        <mesh filename="assets/meshes/outer_band.obj" />
        </geometry>
      <material name="matte_black">
        <color rgba="0.015 0.015 0.018 1" />
        </material>
      </visual>
    <visual name="head_pad">
      <geometry>
        <mesh filename="assets/meshes/head_pad.obj" />
        </geometry>
      <material name="cushion">
        <color rgba="0.075 0.075 0.08 1" />
        </material>
      </visual>
    <visual name="hinge_bridge_0">
      <origin xyz="-0.124 0 0.184" rpy="0 0 0" />
      <geometry>
        <box size="0.028 0.105 0.014" />
        </geometry>
      <material name="matte_black">
        <color rgba="0.015 0.015 0.018 1" />
        </material>
      </visual>
    <visual name="hinge_stem_0">
      <origin xyz="-0.124 0 0.17" rpy="0 0 0" />
      <geometry>
        <box size="0.026 0.022 0.034" />
        </geometry>
      <material name="matte_black">
        <color rgba="0.015 0.015 0.018 1" />
        </material>
      </visual>
    <visual name="hinge_cheek_0_front">
      <origin xyz="-0.124 -0.043 0.166" rpy="0 0 0" />
      <geometry>
        <box size="0.026 0.01 0.03" />
        </geometry>
      <material name="matte_black">
        <color rgba="0.015 0.015 0.018 1" />
        </material>
      </visual>
    <visual name="hinge_cheek_0_rear">
      <origin xyz="-0.124 0.043 0.166" rpy="0 0 0" />
      <geometry>
        <box size="0.026 0.01 0.03" />
        </geometry>
      <material name="matte_black">
        <color rgba="0.015 0.015 0.018 1" />
        </material>
      </visual>
    <visual name="fold_pin_0">
      <origin xyz="-0.124 0 0.16" rpy="-1.5708 0 0" />
      <geometry>
        <cylinder radius="0.0042" length="0.096" />
        </geometry>
      <material name="dark_pin_metal">
        <color rgba="0.48 0.48 0.5 1" />
        </material>
      </visual>
    <visual name="hinge_bridge_1">
      <origin xyz="0.124 0 0.184" rpy="0 0 0" />
      <geometry>
        <box size="0.028 0.105 0.014" />
        </geometry>
      <material name="matte_black">
        <color rgba="0.015 0.015 0.018 1" />
        </material>
      </visual>
    <visual name="hinge_stem_1">
      <origin xyz="0.124 0 0.17" rpy="0 0 0" />
      <geometry>
        <box size="0.026 0.022 0.034" />
        </geometry>
      <material name="matte_black">
        <color rgba="0.015 0.015 0.018 1" />
        </material>
      </visual>
    <visual name="hinge_cheek_1_front">
      <origin xyz="0.124 -0.043 0.166" rpy="0 0 0" />
      <geometry>
        <box size="0.026 0.01 0.03" />
        </geometry>
      <material name="matte_black">
        <color rgba="0.015 0.015 0.018 1" />
        </material>
      </visual>
    <visual name="hinge_cheek_1_rear">
      <origin xyz="0.124 0.043 0.166" rpy="0 0 0" />
      <geometry>
        <box size="0.026 0.01 0.03" />
        </geometry>
      <material name="matte_black">
        <color rgba="0.015 0.015 0.018 1" />
        </material>
      </visual>
    <visual name="fold_pin_1">
      <origin xyz="0.124 0 0.16" rpy="-1.5708 0 0" />
      <geometry>
        <cylinder radius="0.0042" length="0.096" />
        </geometry>
      <material name="dark_pin_metal">
        <color rgba="0.48 0.48 0.5 1" />
        </material>
      </visual>
    <collision name="outer_band">
      <geometry>
        <mesh filename="assets/meshes/outer_band.obj" />
        </geometry>
      </collision>
    <collision name="head_pad">
      <geometry>
        <mesh filename="assets/meshes/head_pad.obj" />
        </geometry>
      </collision>
    <collision name="hinge_bridge_0">
      <origin xyz="-0.124 0 0.184" rpy="0 0 0" />
      <geometry>
        <box size="0.028 0.105 0.014" />
        </geometry>
      </collision>
    <collision name="hinge_stem_0">
      <origin xyz="-0.124 0 0.17" rpy="0 0 0" />
      <geometry>
        <box size="0.026 0.022 0.034" />
        </geometry>
      </collision>
    <collision name="hinge_cheek_0_front">
      <origin xyz="-0.124 -0.043 0.166" rpy="0 0 0" />
      <geometry>
        <box size="0.026 0.01 0.03" />
        </geometry>
      </collision>
    <collision name="hinge_cheek_0_rear">
      <origin xyz="-0.124 0.043 0.166" rpy="0 0 0" />
      <geometry>
        <box size="0.026 0.01 0.03" />
        </geometry>
      </collision>
    <collision name="fold_pin_0">
      <origin xyz="-0.124 0 0.16" rpy="-1.5708 0 0" />
      <geometry>
        <cylinder radius="0.0042" length="0.096" />
        </geometry>
      </collision>
    <collision name="hinge_bridge_1">
      <origin xyz="0.124 0 0.184" rpy="0 0 0" />
      <geometry>
        <box size="0.028 0.105 0.014" />
        </geometry>
      </collision>
    <collision name="hinge_stem_1">
      <origin xyz="0.124 0 0.17" rpy="0 0 0" />
      <geometry>
        <box size="0.026 0.022 0.034" />
        </geometry>
      </collision>
    <collision name="hinge_cheek_1_front">
      <origin xyz="0.124 -0.043 0.166" rpy="0 0 0" />
      <geometry>
        <box size="0.026 0.01 0.03" />
        </geometry>
      </collision>
    <collision name="hinge_cheek_1_rear">
      <origin xyz="0.124 0.043 0.166" rpy="0 0 0" />
      <geometry>
        <box size="0.026 0.01 0.03" />
        </geometry>
      </collision>
    <collision name="fold_pin_1">
      <origin xyz="0.124 0 0.16" rpy="-1.5708 0 0" />
      <geometry>
        <cylinder radius="0.0042" length="0.096" />
        </geometry>
      </collision>
    </link>
  <link name="yoke_0">
    <visual name="fold_knuckle_front">
      <origin xyz="0 -0.024 0" rpy="-1.5708 0 0" />
      <geometry>
        <cylinder radius="0.0105" length="0.019" />
        </geometry>
      <material name="gunmetal">
        <color rgba="0.23 0.23 0.25 1" />
        </material>
      </visual>
    <visual name="fold_knuckle_rear">
      <origin xyz="0 0.024 0" rpy="-1.5708 0 0" />
      <geometry>
        <cylinder radius="0.0105" length="0.019" />
        </geometry>
      <material name="gunmetal">
        <color rgba="0.23 0.23 0.25 1" />
        </material>
      </visual>
    <visual name="top_bridge">
      <origin xyz="0 0 -0.019" rpy="0 0 0" />
      <geometry>
        <box size="0.02 0.114 0.018" />
        </geometry>
      <material name="matte_black">
        <color rgba="0.015 0.015 0.018 1" />
        </material>
      </visual>
    <visual name="side_arm_front">
      <origin xyz="0 -0.056 -0.079" rpy="0 0 0" />
      <geometry>
        <box size="0.014 0.011 0.122" />
        </geometry>
      <material name="matte_black">
        <color rgba="0.015 0.015 0.018 1" />
        </material>
      </visual>
    <visual name="swivel_bearing_front">
      <origin xyz="0 -0.056 -0.102" rpy="-1.5708 0 0" />
      <geometry>
        <cylinder radius="0.0135" length="0.014" />
        </geometry>
      <material name="gunmetal">
        <color rgba="0.23 0.23 0.25 1" />
        </material>
      </visual>
    <visual name="side_arm_rear">
      <origin xyz="0 0.056 -0.079" rpy="0 0 0" />
      <geometry>
        <box size="0.014 0.011 0.122" />
        </geometry>
      <material name="matte_black">
        <color rgba="0.015 0.015 0.018 1" />
        </material>
      </visual>
    <visual name="swivel_bearing_rear">
      <origin xyz="0 0.056 -0.102" rpy="-1.5708 0 0" />
      <geometry>
        <cylinder radius="0.0135" length="0.014" />
        </geometry>
      <material name="gunmetal">
        <color rgba="0.23 0.23 0.25 1" />
        </material>
      </visual>
    <collision name="fold_knuckle_front">
      <origin xyz="0 -0.024 0" rpy="-1.5708 0 0" />
      <geometry>
        <cylinder radius="0.0105" length="0.019" />
        </geometry>
      </collision>
    <collision name="fold_knuckle_rear">
      <origin xyz="0 0.024 0" rpy="-1.5708 0 0" />
      <geometry>
        <cylinder radius="0.0105" length="0.019" />
        </geometry>
      </collision>
    <collision name="top_bridge">
      <origin xyz="0 0 -0.019" rpy="0 0 0" />
      <geometry>
        <box size="0.02 0.114 0.018" />
        </geometry>
      </collision>
    <collision name="side_arm_front">
      <origin xyz="0 -0.056 -0.079" rpy="0 0 0" />
      <geometry>
        <box size="0.014 0.011 0.122" />
        </geometry>
      </collision>
    <collision name="swivel_bearing_front">
      <origin xyz="0 -0.056 -0.102" rpy="-1.5708 0 0" />
      <geometry>
        <cylinder radius="0.0135" length="0.014" />
        </geometry>
      </collision>
    <collision name="side_arm_rear">
      <origin xyz="0 0.056 -0.079" rpy="0 0 0" />
      <geometry>
        <box size="0.014 0.011 0.122" />
        </geometry>
      </collision>
    <collision name="swivel_bearing_rear">
      <origin xyz="0 0.056 -0.102" rpy="-1.5708 0 0" />
      <geometry>
        <cylinder radius="0.0135" length="0.014" />
        </geometry>
      </collision>
    </link>
  <link name="yoke_1">
    <visual name="fold_knuckle_front">
      <origin xyz="0 -0.024 0" rpy="-1.5708 0 0" />
      <geometry>
        <cylinder radius="0.0105" length="0.019" />
        </geometry>
      <material name="gunmetal">
        <color rgba="0.23 0.23 0.25 1" />
        </material>
      </visual>
    <visual name="fold_knuckle_rear">
      <origin xyz="0 0.024 0" rpy="-1.5708 0 0" />
      <geometry>
        <cylinder radius="0.0105" length="0.019" />
        </geometry>
      <material name="gunmetal">
        <color rgba="0.23 0.23 0.25 1" />
        </material>
      </visual>
    <visual name="top_bridge">
      <origin xyz="0 0 -0.019" rpy="0 0 0" />
      <geometry>
        <box size="0.02 0.114 0.018" />
        </geometry>
      <material name="matte_black">
        <color rgba="0.015 0.015 0.018 1" />
        </material>
      </visual>
    <visual name="side_arm_front">
      <origin xyz="0 -0.056 -0.079" rpy="0 0 0" />
      <geometry>
        <box size="0.014 0.011 0.122" />
        </geometry>
      <material name="matte_black">
        <color rgba="0.015 0.015 0.018 1" />
        </material>
      </visual>
    <visual name="swivel_bearing_front">
      <origin xyz="0 -0.056 -0.102" rpy="-1.5708 0 0" />
      <geometry>
        <cylinder radius="0.0135" length="0.014" />
        </geometry>
      <material name="gunmetal">
        <color rgba="0.23 0.23 0.25 1" />
        </material>
      </visual>
    <visual name="side_arm_rear">
      <origin xyz="0 0.056 -0.079" rpy="0 0 0" />
      <geometry>
        <box size="0.014 0.011 0.122" />
        </geometry>
      <material name="matte_black">
        <color rgba="0.015 0.015 0.018 1" />
        </material>
      </visual>
    <visual name="swivel_bearing_rear">
      <origin xyz="0 0.056 -0.102" rpy="-1.5708 0 0" />
      <geometry>
        <cylinder radius="0.0135" length="0.014" />
        </geometry>
      <material name="gunmetal">
        <color rgba="0.23 0.23 0.25 1" />
        </material>
      </visual>
    <collision name="fold_knuckle_front">
      <origin xyz="0 -0.024 0" rpy="-1.5708 0 0" />
      <geometry>
        <cylinder radius="0.0105" length="0.019" />
        </geometry>
      </collision>
    <collision name="fold_knuckle_rear">
      <origin xyz="0 0.024 0" rpy="-1.5708 0 0" />
      <geometry>
        <cylinder radius="0.0105" length="0.019" />
        </geometry>
      </collision>
    <collision name="top_bridge">
      <origin xyz="0 0 -0.019" rpy="0 0 0" />
      <geometry>
        <box size="0.02 0.114 0.018" />
        </geometry>
      </collision>
    <collision name="side_arm_front">
      <origin xyz="0 -0.056 -0.079" rpy="0 0 0" />
      <geometry>
        <box size="0.014 0.011 0.122" />
        </geometry>
      </collision>
    <collision name="swivel_bearing_front">
      <origin xyz="0 -0.056 -0.102" rpy="-1.5708 0 0" />
      <geometry>
        <cylinder radius="0.0135" length="0.014" />
        </geometry>
      </collision>
    <collision name="side_arm_rear">
      <origin xyz="0 0.056 -0.079" rpy="0 0 0" />
      <geometry>
        <box size="0.014 0.011 0.122" />
        </geometry>
      </collision>
    <collision name="swivel_bearing_rear">
      <origin xyz="0 0.056 -0.102" rpy="-1.5708 0 0" />
      <geometry>
        <cylinder radius="0.0135" length="0.014" />
        </geometry>
      </collision>
    </link>
  <link name="cup_0">
    <visual name="cup_shell">
      <geometry>
        <mesh filename="assets/meshes/cup_shell_mesh.obj" />
        </geometry>
      <material name="matte_black">
        <color rgba="0.015 0.015 0.018 1" />
        </material>
      </visual>
    <visual name="ear_pad">
      <origin xyz="0.029 0 0" rpy="0 0 0" />
      <geometry>
        <mesh filename="assets/meshes/earpad_ring_mesh.obj" />
        </geometry>
      <material name="soft_black">
        <color rgba="0.005 0.005 0.006 1" />
        </material>
      </visual>
    <visual name="speaker_grille">
      <origin xyz="0.02204 0 0" rpy="0 0 0" />
      <geometry>
        <mesh filename="assets/meshes/speaker_grille_mesh.obj" />
        </geometry>
      <material name="mesh_cloth">
        <color rgba="0.025 0.026 0.03 1" />
        </material>
      </visual>
    <visual name="accent_ring">
      <origin xyz="-0.023 0 0" rpy="0 0 0" />
      <geometry>
        <mesh filename="assets/meshes/outer_accent_ring_mesh.obj" />
        </geometry>
      <material name="red_accent">
        <color rgba="0.85 0.04 0.035 1" />
        </material>
      </visual>
    <visual name="swivel_pin_front">
      <origin xyz="0 -0.057 0" rpy="-1.5708 0 0" />
      <geometry>
        <cylinder radius="0.0095" length="0.024" />
        </geometry>
      <material name="dark_pin_metal">
        <color rgba="0.48 0.48 0.5 1" />
        </material>
      </visual>
    <visual name="swivel_pin_rear">
      <origin xyz="0 0.057 0" rpy="-1.5708 0 0" />
      <geometry>
        <cylinder radius="0.0095" length="0.024" />
        </geometry>
      <material name="dark_pin_metal">
        <color rgba="0.48 0.48 0.5 1" />
        </material>
      </visual>
    <visual name="boom_socket">
      <origin xyz="-0.032 -0.05 -0.004" rpy="0 1.5708 0" />
      <geometry>
        <cylinder radius="0.0105" length="0.017" />
        </geometry>
      <material name="gunmetal">
        <color rgba="0.23 0.23 0.25 1" />
        </material>
      </visual>
    <visual name="socket_tab">
      <origin xyz="-0.024 -0.044 -0.004" rpy="0 0 0" />
      <geometry>
        <box size="0.008 0.02 0.016" />
        </geometry>
      <material name="gunmetal">
        <color rgba="0.23 0.23 0.25 1" />
        </material>
      </visual>
    <collision name="cup_shell">
      <geometry>
        <mesh filename="assets/meshes/cup_shell_mesh.obj" />
        </geometry>
      </collision>
    <collision name="ear_pad">
      <origin xyz="0.029 0 0" rpy="0 0 0" />
      <geometry>
        <mesh filename="assets/meshes/earpad_ring_mesh.obj" />
        </geometry>
      </collision>
    <collision name="speaker_grille">
      <origin xyz="0.02204 0 0" rpy="0 0 0" />
      <geometry>
        <mesh filename="assets/meshes/speaker_grille_mesh.obj" />
        </geometry>
      </collision>
    <collision name="accent_ring">
      <origin xyz="-0.023 0 0" rpy="0 0 0" />
      <geometry>
        <mesh filename="assets/meshes/outer_accent_ring_mesh.obj" />
        </geometry>
      </collision>
    <collision name="swivel_pin_front">
      <origin xyz="0 -0.057 0" rpy="-1.5708 0 0" />
      <geometry>
        <cylinder radius="0.0095" length="0.024" />
        </geometry>
      </collision>
    <collision name="swivel_pin_rear">
      <origin xyz="0 0.057 0" rpy="-1.5708 0 0" />
      <geometry>
        <cylinder radius="0.0095" length="0.024" />
        </geometry>
      </collision>
    <collision name="boom_socket">
      <origin xyz="-0.032 -0.05 -0.004" rpy="0 1.5708 0" />
      <geometry>
        <cylinder radius="0.0105" length="0.017" />
        </geometry>
      </collision>
    <collision name="socket_tab">
      <origin xyz="-0.024 -0.044 -0.004" rpy="0 0 0" />
      <geometry>
        <box size="0.008 0.02 0.016" />
        </geometry>
      </collision>
    </link>
  <link name="cup_1">
    <visual name="cup_shell">
      <geometry>
        <mesh filename="assets/meshes/cup_shell_mesh.obj" />
        </geometry>
      <material name="matte_black">
        <color rgba="0.015 0.015 0.018 1" />
        </material>
      </visual>
    <visual name="ear_pad">
      <origin xyz="-0.029 0 0" rpy="0 0 0" />
      <geometry>
        <mesh filename="assets/meshes/earpad_ring_mesh.obj" />
        </geometry>
      <material name="soft_black">
        <color rgba="0.005 0.005 0.006 1" />
        </material>
      </visual>
    <visual name="speaker_grille">
      <origin xyz="-0.02204 0 0" rpy="0 0 0" />
      <geometry>
        <mesh filename="assets/meshes/speaker_grille_mesh.obj" />
        </geometry>
      <material name="mesh_cloth">
        <color rgba="0.025 0.026 0.03 1" />
        </material>
      </visual>
    <visual name="accent_ring">
      <origin xyz="0.023 0 0" rpy="0 0 0" />
      <geometry>
        <mesh filename="assets/meshes/outer_accent_ring_mesh.obj" />
        </geometry>
      <material name="red_accent">
        <color rgba="0.85 0.04 0.035 1" />
        </material>
      </visual>
    <visual name="swivel_pin_front">
      <origin xyz="0 -0.057 0" rpy="-1.5708 0 0" />
      <geometry>
        <cylinder radius="0.0095" length="0.024" />
        </geometry>
      <material name="dark_pin_metal">
        <color rgba="0.48 0.48 0.5 1" />
        </material>
      </visual>
    <visual name="swivel_pin_rear">
      <origin xyz="0 0.057 0" rpy="-1.5708 0 0" />
      <geometry>
        <cylinder radius="0.0095" length="0.024" />
        </geometry>
      <material name="dark_pin_metal">
        <color rgba="0.48 0.48 0.5 1" />
        </material>
      </visual>
    <collision name="cup_shell">
      <geometry>
        <mesh filename="assets/meshes/cup_shell_mesh.obj" />
        </geometry>
      </collision>
    <collision name="ear_pad">
      <origin xyz="-0.029 0 0" rpy="0 0 0" />
      <geometry>
        <mesh filename="assets/meshes/earpad_ring_mesh.obj" />
        </geometry>
      </collision>
    <collision name="speaker_grille">
      <origin xyz="-0.02204 0 0" rpy="0 0 0" />
      <geometry>
        <mesh filename="assets/meshes/speaker_grille_mesh.obj" />
        </geometry>
      </collision>
    <collision name="accent_ring">
      <origin xyz="0.023 0 0" rpy="0 0 0" />
      <geometry>
        <mesh filename="assets/meshes/outer_accent_ring_mesh.obj" />
        </geometry>
      </collision>
    <collision name="swivel_pin_front">
      <origin xyz="0 -0.057 0" rpy="-1.5708 0 0" />
      <geometry>
        <cylinder radius="0.0095" length="0.024" />
        </geometry>
      </collision>
    <collision name="swivel_pin_rear">
      <origin xyz="0 0.057 0" rpy="-1.5708 0 0" />
      <geometry>
        <cylinder radius="0.0095" length="0.024" />
        </geometry>
      </collision>
    </link>
  <link name="boom_microphone">
    <visual name="pivot_collar">
      <origin xyz="-0.006 0 0" rpy="0 1.5708 0" />
      <geometry>
        <cylinder radius="0.0155" length="0.012" />
        </geometry>
      <material name="gunmetal">
        <color rgba="0.23 0.23 0.25 1" />
        </material>
      </visual>
    <visual name="boom_arm">
      <geometry>
        <mesh filename="assets/meshes/boom_arm.obj" />
        </geometry>
      <material name="matte_black">
        <color rgba="0.015 0.015 0.018 1" />
        </material>
      </visual>
    <visual name="mic_capsule">
      <origin xyz="-0.011 -0.139 -0.034" rpy="-1.5708 0 0" />
      <geometry>
        <cylinder radius="0.008" length="0.03" />
        </geometry>
      <material name="soft_black">
        <color rgba="0.005 0.005 0.006 1" />
        </material>
      </visual>
    <visual name="mic_end_cap">
      <origin xyz="-0.011 -0.154 -0.034" rpy="0 0 0" />
      <geometry>
        <sphere radius="0.006" />
        </geometry>
      <material name="soft_black">
        <color rgba="0.005 0.005 0.006 1" />
        </material>
      </visual>
    <collision name="pivot_collar">
      <origin xyz="-0.006 0 0" rpy="0 1.5708 0" />
      <geometry>
        <cylinder radius="0.0155" length="0.012" />
        </geometry>
      </collision>
    <collision name="boom_arm">
      <geometry>
        <mesh filename="assets/meshes/boom_arm.obj" />
        </geometry>
      </collision>
    <collision name="mic_capsule">
      <origin xyz="-0.011 -0.139 -0.034" rpy="-1.5708 0 0" />
      <geometry>
        <cylinder radius="0.008" length="0.03" />
        </geometry>
      </collision>
    <collision name="mic_end_cap">
      <origin xyz="-0.011 -0.154 -0.034" rpy="0 0 0" />
      <geometry>
        <sphere radius="0.006" />
        </geometry>
      </collision>
    </link>
  <joint name="fold_hinge_0" type="revolute">
    <origin xyz="-0.124 0 0.16" rpy="0 0 0" />
    <parent link="headband" />
    <child link="yoke_0" />
    <axis xyz="0 -1 0" />
    <limit effort="2" velocity="2" lower="0" upper="1.55" />
    </joint>
  <joint name="fold_hinge_1" type="revolute">
    <origin xyz="0.124 0 0.16" rpy="0 0 0" />
    <parent link="headband" />
    <child link="yoke_1" />
    <axis xyz="0 1 0" />
    <limit effort="2" velocity="2" lower="0" upper="1.55" />
    </joint>
  <joint name="cup_swivel_0" type="revolute">
    <origin xyz="0 0 -0.102" rpy="0 0 0" />
    <parent link="yoke_0" />
    <child link="cup_0" />
    <axis xyz="0 1 0" />
    <limit effort="1" velocity="2.5" lower="-0.45" upper="0.45" />
    </joint>
  <joint name="cup_swivel_1" type="revolute">
    <origin xyz="0 0 -0.102" rpy="0 0 0" />
    <parent link="yoke_1" />
    <child link="cup_1" />
    <axis xyz="0 1 0" />
    <limit effort="1" velocity="2.5" lower="-0.45" upper="0.45" />
    </joint>
  <joint name="boom_pivot" type="revolute">
    <origin xyz="-0.032 -0.05 -0.004" rpy="0 0 0" />
    <parent link="cup_0" />
    <child link="boom_microphone" />
    <axis xyz="-1 0 0" />
    <limit effort="0.4" velocity="3" lower="0" upper="1.8" />
    </joint>
  </robot>
