<robot name="guarded_thumbstick">
  <material name="matte_console">
    <color rgba="0.025 0.028 0.03 1" />
    </material>
  <material name="blackened_steel">
    <color rgba="0.07 0.074 0.078 1" />
    </material>
  <material name="dark_machined_fork">
    <color rgba="0.12 0.13 0.14 1" />
    </material>
  <material name="brushed_pivot_steel">
    <color rgba="0.55 0.57 0.58 1" />
    </material>
  <material name="oxide_inner_ring">
    <color rgba="0.025 0.03 0.035 1" />
    </material>
  <material name="soft_black_rubber">
    <color rgba="0.006 0.006 0.005 1" />
    </material>
  <link name="base">
    <visual name="console_plate">
      <origin xyz="0 0 0.012" rpy="0 0 0" />
      <geometry>
        <box size="0.18 0.16 0.024" />
        </geometry>
      <material name="matte_console">
        <color rgba="0.025 0.028 0.03 1" />
        </material>
      </visual>
    <visual name="octagonal_bezel">
      <origin xyz="0 0 0.024" rpy="0 0 0" />
      <geometry>
        <mesh filename="assets/meshes/octagonal_bezel.obj" />
        </geometry>
      <material name="blackened_steel">
        <color rgba="0.07 0.074 0.078 1" />
        </material>
      </visual>
    <visual name="recess_liner">
      <origin xyz="0 0 0.026" rpy="0 0 0" />
      <geometry>
        <cylinder radius="0.042" length="0.004" />
        </geometry>
      <material name="soft_black_rubber">
        <color rgba="0.006 0.006 0.005 1" />
        </material>
      </visual>
    <visual name="bearing_pedestal_0">
      <origin xyz="-0.062 0 0.046" rpy="0 0 0" />
      <geometry>
        <box size="0.02 0.04 0.04" />
        </geometry>
      <material name="blackened_steel">
        <color rgba="0.07 0.074 0.078 1" />
        </material>
      </visual>
    <visual name="fork_bearing_0">
      <origin xyz="-0.062 0 0.06" rpy="0 1.5708 0" />
      <geometry>
        <cylinder radius="0.014" length="0.018" />
        </geometry>
      <material name="brushed_pivot_steel">
        <color rgba="0.55 0.57 0.58 1" />
        </material>
      </visual>
    <visual name="bearing_pedestal_1">
      <origin xyz="0.062 0 0.046" rpy="0 0 0" />
      <geometry>
        <box size="0.02 0.04 0.04" />
        </geometry>
      <material name="blackened_steel">
        <color rgba="0.07 0.074 0.078 1" />
        </material>
      </visual>
    <visual name="fork_bearing_1">
      <origin xyz="0.062 0 0.06" rpy="0 1.5708 0" />
      <geometry>
        <cylinder radius="0.014" length="0.018" />
        </geometry>
      <material name="brushed_pivot_steel">
        <color rgba="0.55 0.57 0.58 1" />
        </material>
      </visual>
    <collision name="console_plate">
      <origin xyz="0 0 0.012" rpy="0 0 0" />
      <geometry>
        <box size="0.18 0.16 0.024" />
        </geometry>
      </collision>
    <collision name="octagonal_bezel">
      <origin xyz="0 0 0.024" rpy="0 0 0" />
      <geometry>
        <mesh filename="assets/meshes/octagonal_bezel.obj" />
        </geometry>
      </collision>
    <collision name="recess_liner">
      <origin xyz="0 0 0.026" rpy="0 0 0" />
      <geometry>
        <cylinder radius="0.042" length="0.004" />
        </geometry>
      </collision>
    <collision name="bearing_pedestal_0">
      <origin xyz="-0.062 0 0.046" rpy="0 0 0" />
      <geometry>
        <box size="0.02 0.04 0.04" />
        </geometry>
      </collision>
    <collision name="fork_bearing_0">
      <origin xyz="-0.062 0 0.06" rpy="0 1.5708 0" />
      <geometry>
        <cylinder radius="0.014" length="0.018" />
        </geometry>
      </collision>
    <collision name="bearing_pedestal_1">
      <origin xyz="0.062 0 0.046" rpy="0 0 0" />
      <geometry>
        <box size="0.02 0.04 0.04" />
        </geometry>
      </collision>
    <collision name="fork_bearing_1">
      <origin xyz="0.062 0 0.06" rpy="0 1.5708 0" />
      <geometry>
        <cylinder radius="0.014" length="0.018" />
        </geometry>
      </collision>
    </link>
  <link name="outer_fork">
    <visual name="fork_guard">
      <geometry>
        <mesh filename="assets/meshes/outer_fork_guard.obj" />
        </geometry>
      <material name="dark_machined_fork">
        <color rgba="0.12 0.13 0.14 1" />
        </material>
      </visual>
    <visual name="ring_bearing_0">
      <origin xyz="0 -0.035 0" rpy="0 0 0" />
      <geometry>
        <box size="0.018 0.006 0.018" />
        </geometry>
      <material name="brushed_pivot_steel">
        <color rgba="0.55 0.57 0.58 1" />
        </material>
      </visual>
    <visual name="ring_bearing_1">
      <origin xyz="0 0.035 0" rpy="0 0 0" />
      <geometry>
        <box size="0.018 0.006 0.018" />
        </geometry>
      <material name="brushed_pivot_steel">
        <color rgba="0.55 0.57 0.58 1" />
        </material>
      </visual>
    <visual name="trunnion_0">
      <origin xyz="-0.043 0 0" rpy="0 1.5708 0" />
      <geometry>
        <cylinder radius="0.007" length="0.018" />
        </geometry>
      <material name="brushed_pivot_steel">
        <color rgba="0.55 0.57 0.58 1" />
        </material>
      </visual>
    <visual name="trunnion_1">
      <origin xyz="0.043 0 0" rpy="0 1.5708 0" />
      <geometry>
        <cylinder radius="0.007" length="0.018" />
        </geometry>
      <material name="brushed_pivot_steel">
        <color rgba="0.55 0.57 0.58 1" />
        </material>
      </visual>
    <collision name="fork_guard">
      <geometry>
        <mesh filename="assets/meshes/outer_fork_guard.obj" />
        </geometry>
      </collision>
    <collision name="ring_bearing_0">
      <origin xyz="0 -0.035 0" rpy="0 0 0" />
      <geometry>
        <box size="0.018 0.006 0.018" />
        </geometry>
      </collision>
    <collision name="ring_bearing_1">
      <origin xyz="0 0.035 0" rpy="0 0 0" />
      <geometry>
        <box size="0.018 0.006 0.018" />
        </geometry>
      </collision>
    <collision name="trunnion_0">
      <origin xyz="-0.043 0 0" rpy="0 1.5708 0" />
      <geometry>
        <cylinder radius="0.007" length="0.018" />
        </geometry>
      </collision>
    <collision name="trunnion_1">
      <origin xyz="0.043 0 0" rpy="0 1.5708 0" />
      <geometry>
        <cylinder radius="0.007" length="0.018" />
        </geometry>
      </collision>
    </link>
  <link name="inner_ring">
    <visual name="ring_carrier">
      <geometry>
        <mesh filename="assets/meshes/inner_ring_carrier.obj" />
        </geometry>
      <material name="oxide_inner_ring">
        <color rgba="0.025 0.03 0.035 1" />
        </material>
      </visual>
    <visual name="ring_pivot_pin">
      <origin xyz="0 0 0" rpy="1.5708 0 0" />
      <geometry>
        <cylinder radius="0.0055" length="0.064" />
        </geometry>
      <material name="brushed_pivot_steel">
        <color rgba="0.55 0.57 0.58 1" />
        </material>
      </visual>
    <visual name="control_post">
      <origin xyz="0 0 0.023" rpy="0 0 0" />
      <geometry>
        <cylinder radius="0.01" length="0.046" />
        </geometry>
      <material name="soft_black_rubber">
        <color rgba="0.006 0.006 0.005 1" />
        </material>
      </visual>
    <visual name="thumb_cap">
      <origin xyz="0 0 0.05" rpy="0 0 0" />
      <geometry>
        <cylinder radius="0.017" length="0.012" />
        </geometry>
      <material name="soft_black_rubber">
        <color rgba="0.006 0.006 0.005 1" />
        </material>
      </visual>
    <collision name="ring_carrier">
      <geometry>
        <mesh filename="assets/meshes/inner_ring_carrier.obj" />
        </geometry>
      </collision>
    <collision name="ring_pivot_pin">
      <origin xyz="0 0 0" rpy="1.5708 0 0" />
      <geometry>
        <cylinder radius="0.0055" length="0.064" />
        </geometry>
      </collision>
    <collision name="control_post">
      <origin xyz="0 0 0.023" rpy="0 0 0" />
      <geometry>
        <cylinder radius="0.01" length="0.046" />
        </geometry>
      </collision>
    <collision name="thumb_cap">
      <origin xyz="0 0 0.05" rpy="0 0 0" />
      <geometry>
        <cylinder radius="0.017" length="0.012" />
        </geometry>
      </collision>
    </link>
  <joint name="base_to_fork" type="revolute">
    <origin xyz="0 0 0.06" rpy="0 0 0" />
    <parent link="base" />
    <child link="outer_fork" />
    <axis xyz="1 0 0" />
    <limit effort="2" velocity="3" lower="-0.35" upper="0.35" />
    </joint>
  <joint name="fork_to_ring" type="revolute">
    <parent link="outer_fork" />
    <child link="inner_ring" />
    <axis xyz="0 1 0" />
    <limit effort="1.5" velocity="3" lower="-0.35" upper="0.35" />
    </joint>
  </robot>
