<robot name="underslung_two_joint_chain">
  <material name="zinc_plated_steel">
    <color rgba="0.68 0.7 0.69 1" />
    </material>
  <material name="dark_bushed_steel">
    <color rgba="0.08 0.085 0.09 1" />
    </material>
  <material name="safety_yellow_link">
    <color rgba="0.95 0.65 0.12 1" />
    </material>
  <material name="worn_orange_tab">
    <color rgba="0.9 0.36 0.1 1" />
    </material>
  <link name="top_support">
    <visual name="mount_plate">
      <origin xyz="0 0 0.088" rpy="0 0 0" />
      <geometry>
        <box size="0.24 0.16 0.022" />
        </geometry>
      <material name="zinc_plated_steel">
        <color rgba="0.68 0.7 0.69 1" />
        </material>
      </visual>
    <visual name="cross_web">
      <origin xyz="0 0 0.0675" rpy="0 0 0" />
      <geometry>
        <box size="0.08 0.132 0.02" />
        </geometry>
      <material name="zinc_plated_steel">
        <color rgba="0.68 0.7 0.69 1" />
        </material>
      </visual>
    <visual name="cheek_0">
      <origin xyz="0 -0.06 0.0275" rpy="0 0 0" />
      <geometry>
        <box size="0.058 0.02 0.095" />
        </geometry>
      <material name="zinc_plated_steel">
        <color rgba="0.68 0.7 0.69 1" />
        </material>
      </visual>
    <visual name="cheek_1">
      <origin xyz="0 0.06 0.0275" rpy="0 0 0" />
      <geometry>
        <box size="0.058 0.02 0.095" />
        </geometry>
      <material name="zinc_plated_steel">
        <color rgba="0.68 0.7 0.69 1" />
        </material>
      </visual>
    <visual name="outer_boss_0">
      <origin xyz="0 -0.074 0" rpy="1.5708 0 0" />
      <geometry>
        <cylinder radius="0.018" length="0.018" />
        </geometry>
      <material name="dark_bushed_steel">
        <color rgba="0.08 0.085 0.09 1" />
        </material>
      </visual>
    <visual name="outer_boss_1">
      <origin xyz="0 0.074 0" rpy="1.5708 0 0" />
      <geometry>
        <cylinder radius="0.018" length="0.018" />
        </geometry>
      <material name="dark_bushed_steel">
        <color rgba="0.08 0.085 0.09 1" />
        </material>
      </visual>
    <visual name="support_pin">
      <origin xyz="0 0 0" rpy="1.5708 0 0" />
      <geometry>
        <cylinder radius="0.009" length="0.15" />
        </geometry>
      <material name="dark_bushed_steel">
        <color rgba="0.08 0.085 0.09 1" />
        </material>
      </visual>
    <visual name="bolt_-0.075_-0.050">
      <origin xyz="-0.075 -0.05 0.102" rpy="0 0 0" />
      <geometry>
        <cylinder radius="0.01" length="0.006" />
        </geometry>
      <material name="dark_bushed_steel">
        <color rgba="0.08 0.085 0.09 1" />
        </material>
      </visual>
    <visual name="bolt_-0.075_+0.050">
      <origin xyz="-0.075 0.05 0.102" rpy="0 0 0" />
      <geometry>
        <cylinder radius="0.01" length="0.006" />
        </geometry>
      <material name="dark_bushed_steel">
        <color rgba="0.08 0.085 0.09 1" />
        </material>
      </visual>
    <visual name="bolt_+0.075_-0.050">
      <origin xyz="0.075 -0.05 0.102" rpy="0 0 0" />
      <geometry>
        <cylinder radius="0.01" length="0.006" />
        </geometry>
      <material name="dark_bushed_steel">
        <color rgba="0.08 0.085 0.09 1" />
        </material>
      </visual>
    <visual name="bolt_+0.075_+0.050">
      <origin xyz="0.075 0.05 0.102" rpy="0 0 0" />
      <geometry>
        <cylinder radius="0.01" length="0.006" />
        </geometry>
      <material name="dark_bushed_steel">
        <color rgba="0.08 0.085 0.09 1" />
        </material>
      </visual>
    <collision name="mount_plate">
      <origin xyz="0 0 0.088" rpy="0 0 0" />
      <geometry>
        <box size="0.24 0.16 0.022" />
        </geometry>
      </collision>
    <collision name="cross_web">
      <origin xyz="0 0 0.0675" rpy="0 0 0" />
      <geometry>
        <box size="0.08 0.132 0.02" />
        </geometry>
      </collision>
    <collision name="cheek_0">
      <origin xyz="0 -0.06 0.0275" rpy="0 0 0" />
      <geometry>
        <box size="0.058 0.02 0.095" />
        </geometry>
      </collision>
    <collision name="cheek_1">
      <origin xyz="0 0.06 0.0275" rpy="0 0 0" />
      <geometry>
        <box size="0.058 0.02 0.095" />
        </geometry>
      </collision>
    <collision name="outer_boss_0">
      <origin xyz="0 -0.074 0" rpy="1.5708 0 0" />
      <geometry>
        <cylinder radius="0.018" length="0.018" />
        </geometry>
      </collision>
    <collision name="outer_boss_1">
      <origin xyz="0 0.074 0" rpy="1.5708 0 0" />
      <geometry>
        <cylinder radius="0.018" length="0.018" />
        </geometry>
      </collision>
    <collision name="support_pin">
      <origin xyz="0 0 0" rpy="1.5708 0 0" />
      <geometry>
        <cylinder radius="0.009" length="0.15" />
        </geometry>
      </collision>
    <collision name="bolt_-0.075_-0.050">
      <origin xyz="-0.075 -0.05 0.102" rpy="0 0 0" />
      <geometry>
        <cylinder radius="0.01" length="0.006" />
        </geometry>
      </collision>
    <collision name="bolt_-0.075_+0.050">
      <origin xyz="-0.075 0.05 0.102" rpy="0 0 0" />
      <geometry>
        <cylinder radius="0.01" length="0.006" />
        </geometry>
      </collision>
    <collision name="bolt_+0.075_-0.050">
      <origin xyz="0.075 -0.05 0.102" rpy="0 0 0" />
      <geometry>
        <cylinder radius="0.01" length="0.006" />
        </geometry>
      </collision>
    <collision name="bolt_+0.075_+0.050">
      <origin xyz="0.075 0.05 0.102" rpy="0 0 0" />
      <geometry>
        <cylinder radius="0.01" length="0.006" />
        </geometry>
      </collision>
    </link>
  <link name="upper_link">
    <visual name="upper_lug">
      <origin xyz="0 0 0" rpy="1.5708 0 0" />
      <geometry>
        <cylinder radius="0.022" length="0.07" />
        </geometry>
      <material name="safety_yellow_link">
        <color rgba="0.95 0.65 0.12 1" />
        </material>
      </visual>
    <visual name="side_plate_0">
      <origin xyz="0 -0.034 -0.142" rpy="0 0 0" />
      <geometry>
        <box size="0.028 0.01 0.25" />
        </geometry>
      <material name="safety_yellow_link">
        <color rgba="0.95 0.65 0.12 1" />
        </material>
      </visual>
    <visual name="side_plate_1">
      <origin xyz="0 0.034 -0.142" rpy="0 0 0" />
      <geometry>
        <box size="0.028 0.01 0.25" />
        </geometry>
      <material name="safety_yellow_link">
        <color rgba="0.95 0.65 0.12 1" />
        </material>
      </visual>
    <visual name="lower_boss_0">
      <origin xyz="0 -0.034 -0.285" rpy="1.5708 0 0" />
      <geometry>
        <cylinder radius="0.024" length="0.012" />
        </geometry>
      <material name="safety_yellow_link">
        <color rgba="0.95 0.65 0.12 1" />
        </material>
      </visual>
    <visual name="lower_boss_1">
      <origin xyz="0 0.034 -0.285" rpy="1.5708 0 0" />
      <geometry>
        <cylinder radius="0.024" length="0.012" />
        </geometry>
      <material name="safety_yellow_link">
        <color rgba="0.95 0.65 0.12 1" />
        </material>
      </visual>
    <visual name="middle_pin">
      <origin xyz="0 0 -0.285" rpy="1.5708 0 0" />
      <geometry>
        <cylinder radius="0.009" length="0.07" />
        </geometry>
      <material name="dark_bushed_steel">
        <color rgba="0.08 0.085 0.09 1" />
        </material>
      </visual>
    <collision name="upper_lug">
      <origin xyz="0 0 0" rpy="1.5708 0 0" />
      <geometry>
        <cylinder radius="0.022" length="0.07" />
        </geometry>
      </collision>
    <collision name="side_plate_0">
      <origin xyz="0 -0.034 -0.142" rpy="0 0 0" />
      <geometry>
        <box size="0.028 0.01 0.25" />
        </geometry>
      </collision>
    <collision name="side_plate_1">
      <origin xyz="0 0.034 -0.142" rpy="0 0 0" />
      <geometry>
        <box size="0.028 0.01 0.25" />
        </geometry>
      </collision>
    <collision name="lower_boss_0">
      <origin xyz="0 -0.034 -0.285" rpy="1.5708 0 0" />
      <geometry>
        <cylinder radius="0.024" length="0.012" />
        </geometry>
      </collision>
    <collision name="lower_boss_1">
      <origin xyz="0 0.034 -0.285" rpy="1.5708 0 0" />
      <geometry>
        <cylinder radius="0.024" length="0.012" />
        </geometry>
      </collision>
    <collision name="middle_pin">
      <origin xyz="0 0 -0.285" rpy="1.5708 0 0" />
      <geometry>
        <cylinder radius="0.009" length="0.07" />
        </geometry>
      </collision>
    </link>
  <link name="lower_link">
    <visual name="upper_lug">
      <origin xyz="0 0 0" rpy="1.5708 0 0" />
      <geometry>
        <cylinder radius="0.021" length="0.046" />
        </geometry>
      <material name="worn_orange_tab">
        <color rgba="0.9 0.36 0.1 1" />
        </material>
      </visual>
    <visual name="web_strap">
      <origin xyz="0 0 -0.11" rpy="0 0 0" />
      <geometry>
        <box size="0.03 0.026 0.19" />
        </geometry>
      <material name="worn_orange_tab">
        <color rgba="0.9 0.36 0.1 1" />
        </material>
      </visual>
    <visual name="end_tab_plate">
      <origin xyz="0 0 -0.225" rpy="0 0 0" />
      <geometry>
        <box size="0.05 0.034 0.045" />
        </geometry>
      <material name="worn_orange_tab">
        <color rgba="0.9 0.36 0.1 1" />
        </material>
      </visual>
    <visual name="end_tab_round">
      <origin xyz="0 0 -0.245" rpy="1.5708 0 0" />
      <geometry>
        <cylinder radius="0.025" length="0.034" />
        </geometry>
      <material name="worn_orange_tab">
        <color rgba="0.9 0.36 0.1 1" />
        </material>
      </visual>
    <visual name="tab_eye_0">
      <origin xyz="0 -0.0185 -0.235" rpy="1.5708 0 0" />
      <geometry>
        <cylinder radius="0.008" length="0.005" />
        </geometry>
      <material name="dark_bushed_steel">
        <color rgba="0.08 0.085 0.09 1" />
        </material>
      </visual>
    <visual name="tab_eye_1">
      <origin xyz="0 0.0185 -0.235" rpy="1.5708 0 0" />
      <geometry>
        <cylinder radius="0.008" length="0.005" />
        </geometry>
      <material name="dark_bushed_steel">
        <color rgba="0.08 0.085 0.09 1" />
        </material>
      </visual>
    <collision name="upper_lug">
      <origin xyz="0 0 0" rpy="1.5708 0 0" />
      <geometry>
        <cylinder radius="0.021" length="0.046" />
        </geometry>
      </collision>
    <collision name="web_strap">
      <origin xyz="0 0 -0.11" rpy="0 0 0" />
      <geometry>
        <box size="0.03 0.026 0.19" />
        </geometry>
      </collision>
    <collision name="end_tab_plate">
      <origin xyz="0 0 -0.225" rpy="0 0 0" />
      <geometry>
        <box size="0.05 0.034 0.045" />
        </geometry>
      </collision>
    <collision name="end_tab_round">
      <origin xyz="0 0 -0.245" rpy="1.5708 0 0" />
      <geometry>
        <cylinder radius="0.025" length="0.034" />
        </geometry>
      </collision>
    <collision name="tab_eye_0">
      <origin xyz="0 -0.0185 -0.235" rpy="1.5708 0 0" />
      <geometry>
        <cylinder radius="0.008" length="0.005" />
        </geometry>
      </collision>
    <collision name="tab_eye_1">
      <origin xyz="0 0.0185 -0.235" rpy="1.5708 0 0" />
      <geometry>
        <cylinder radius="0.008" length="0.005" />
        </geometry>
      </collision>
    </link>
  <joint name="support_hinge" type="revolute">
    <parent link="top_support" />
    <child link="upper_link" />
    <axis xyz="0 1 0" />
    <limit effort="18" velocity="2" lower="-1.05" upper="1.05" />
    </joint>
  <joint name="middle_hinge" type="revolute">
    <origin xyz="0 0 -0.285" rpy="0 0 0" />
    <parent link="upper_link" />
    <child link="lower_link" />
    <axis xyz="0 1 0" />
    <limit effort="12" velocity="2.2" lower="-1.25" upper="1.25" />
    </joint>
  </robot>
