<robot name="low_profile_drawer_slide">
  <material name="dark_zinc">
    <color rgba="0.22 0.23 0.24 1" />
    </material>
  <material name="satin_steel">
    <color rgba="0.62 0.64 0.63 1" />
    </material>
  <material name="polished_race">
    <color rgba="0.82 0.84 0.8 1" />
    </material>
  <material name="black_plate">
    <color rgba="0.04 0.045 0.05 1" />
    </material>
  <material name="screw_dark">
    <color rgba="0.11 0.11 0.12 1" />
    </material>
  <link name="channel">
    <visual name="bottom_web">
      <origin xyz="0.26 0 0.002" rpy="0 0 0" />
      <geometry>
        <box size="0.52 0.065 0.004" />
        </geometry>
      <material name="dark_zinc">
        <color rgba="0.22 0.23 0.24 1" />
        </material>
      </visual>
    <visual name="side_wall_neg">
      <origin xyz="0.26 -0.0305 0.0185" rpy="0 0 0" />
      <geometry>
        <box size="0.52 0.004 0.031" />
        </geometry>
      <material name="dark_zinc">
        <color rgba="0.22 0.23 0.24 1" />
        </material>
      </visual>
    <visual name="retaining_lip_neg">
      <origin xyz="0.26 -0.022 0.0315" rpy="0 0 0" />
      <geometry>
        <box size="0.52 0.014 0.004" />
        </geometry>
      <material name="dark_zinc">
        <color rgba="0.22 0.23 0.24 1" />
        </material>
      </visual>
    <visual name="outer_race_neg">
      <origin xyz="0.26 -0.02775 0.018" rpy="0 0 0" />
      <geometry>
        <box size="0.48 0.002 0.006" />
        </geometry>
      <material name="polished_race">
        <color rgba="0.82 0.84 0.8 1" />
        </material>
      </visual>
    <visual name="side_wall_pos">
      <origin xyz="0.26 0.0305 0.0185" rpy="0 0 0" />
      <geometry>
        <box size="0.52 0.004 0.031" />
        </geometry>
      <material name="dark_zinc">
        <color rgba="0.22 0.23 0.24 1" />
        </material>
      </visual>
    <visual name="retaining_lip_pos">
      <origin xyz="0.26 0.022 0.0315" rpy="0 0 0" />
      <geometry>
        <box size="0.52 0.014 0.004" />
        </geometry>
      <material name="dark_zinc">
        <color rgba="0.22 0.23 0.24 1" />
        </material>
      </visual>
    <visual name="outer_race_pos">
      <origin xyz="0.26 0.02775 0.018" rpy="0 0 0" />
      <geometry>
        <box size="0.48 0.002 0.006" />
        </geometry>
      <material name="polished_race">
        <color rgba="0.82 0.84 0.8 1" />
        </material>
      </visual>
    <collision name="bottom_web">
      <origin xyz="0.26 0 0.002" rpy="0 0 0" />
      <geometry>
        <box size="0.52 0.065 0.004" />
        </geometry>
      </collision>
    <collision name="side_wall_neg">
      <origin xyz="0.26 -0.0305 0.0185" rpy="0 0 0" />
      <geometry>
        <box size="0.52 0.004 0.031" />
        </geometry>
      </collision>
    <collision name="retaining_lip_neg">
      <origin xyz="0.26 -0.022 0.0315" rpy="0 0 0" />
      <geometry>
        <box size="0.52 0.014 0.004" />
        </geometry>
      </collision>
    <collision name="outer_race_neg">
      <origin xyz="0.26 -0.02775 0.018" rpy="0 0 0" />
      <geometry>
        <box size="0.48 0.002 0.006" />
        </geometry>
      </collision>
    <collision name="side_wall_pos">
      <origin xyz="0.26 0.0305 0.0185" rpy="0 0 0" />
      <geometry>
        <box size="0.52 0.004 0.031" />
        </geometry>
      </collision>
    <collision name="retaining_lip_pos">
      <origin xyz="0.26 0.022 0.0315" rpy="0 0 0" />
      <geometry>
        <box size="0.52 0.014 0.004" />
        </geometry>
      </collision>
    <collision name="outer_race_pos">
      <origin xyz="0.26 0.02775 0.018" rpy="0 0 0" />
      <geometry>
        <box size="0.48 0.002 0.006" />
        </geometry>
      </collision>
    </link>
  <link name="middle_slide">
    <visual name="middle_bottom">
      <origin xyz="0.215 0 0.006" rpy="0 0 0" />
      <geometry>
        <box size="0.43 0.036 0.004" />
        </geometry>
      <material name="satin_steel">
        <color rgba="0.62 0.64 0.63 1" />
        </material>
      </visual>
    <visual name="middle_side_neg">
      <origin xyz="0.215 -0.018 0.0165" rpy="0 0 0" />
      <geometry>
        <box size="0.43 0.004 0.017" />
        </geometry>
      <material name="satin_steel">
        <color rgba="0.62 0.64 0.63 1" />
        </material>
      </visual>
    <visual name="middle_lip_neg">
      <origin xyz="0.215 -0.013 0.0251" rpy="0 0 0" />
      <geometry>
        <box size="0.43 0.006 0.0035" />
        </geometry>
      <material name="satin_steel">
        <color rgba="0.62 0.64 0.63 1" />
        </material>
      </visual>
    <visual name="middle_race_neg">
      <origin xyz="0.215 -0.0152 0.017" rpy="0 0 0" />
      <geometry>
        <box size="0.4 0.002 0.006" />
        </geometry>
      <material name="polished_race">
        <color rgba="0.82 0.84 0.8 1" />
        </material>
      </visual>
    <visual name="middle_side_pos">
      <origin xyz="0.215 0.018 0.0165" rpy="0 0 0" />
      <geometry>
        <box size="0.43 0.004 0.017" />
        </geometry>
      <material name="satin_steel">
        <color rgba="0.62 0.64 0.63 1" />
        </material>
      </visual>
    <visual name="middle_lip_pos">
      <origin xyz="0.215 0.013 0.0251" rpy="0 0 0" />
      <geometry>
        <box size="0.43 0.006 0.0035" />
        </geometry>
      <material name="satin_steel">
        <color rgba="0.62 0.64 0.63 1" />
        </material>
      </visual>
    <visual name="middle_race_pos">
      <origin xyz="0.215 0.0152 0.017" rpy="0 0 0" />
      <geometry>
        <box size="0.4 0.002 0.006" />
        </geometry>
      <material name="polished_race">
        <color rgba="0.82 0.84 0.8 1" />
        </material>
      </visual>
    <collision name="middle_bottom">
      <origin xyz="0.215 0 0.006" rpy="0 0 0" />
      <geometry>
        <box size="0.43 0.036 0.004" />
        </geometry>
      </collision>
    <collision name="middle_side_neg">
      <origin xyz="0.215 -0.018 0.0165" rpy="0 0 0" />
      <geometry>
        <box size="0.43 0.004 0.017" />
        </geometry>
      </collision>
    <collision name="middle_lip_neg">
      <origin xyz="0.215 -0.013 0.0251" rpy="0 0 0" />
      <geometry>
        <box size="0.43 0.006 0.0035" />
        </geometry>
      </collision>
    <collision name="middle_race_neg">
      <origin xyz="0.215 -0.0152 0.017" rpy="0 0 0" />
      <geometry>
        <box size="0.4 0.002 0.006" />
        </geometry>
      </collision>
    <collision name="middle_side_pos">
      <origin xyz="0.215 0.018 0.0165" rpy="0 0 0" />
      <geometry>
        <box size="0.43 0.004 0.017" />
        </geometry>
      </collision>
    <collision name="middle_lip_pos">
      <origin xyz="0.215 0.013 0.0251" rpy="0 0 0" />
      <geometry>
        <box size="0.43 0.006 0.0035" />
        </geometry>
      </collision>
    <collision name="middle_race_pos">
      <origin xyz="0.215 0.0152 0.017" rpy="0 0 0" />
      <geometry>
        <box size="0.4 0.002 0.006" />
        </geometry>
      </collision>
    </link>
  <link name="inner_slide">
    <visual name="inner_tongue">
      <origin xyz="0.18 0 0.01375" rpy="0 0 0" />
      <geometry>
        <box size="0.36 0.012 0.0115" />
        </geometry>
      <material name="satin_steel">
        <color rgba="0.62 0.64 0.63 1" />
        </material>
      </visual>
    <visual name="inner_top_race">
      <origin xyz="0.18 0 0.0208" rpy="0 0 0" />
      <geometry>
        <box size="0.36 0.012 0.003" />
        </geometry>
      <material name="polished_race">
        <color rgba="0.82 0.84 0.8 1" />
        </material>
      </visual>
    <visual name="front_nose">
      <origin xyz="0.357 0 0.017" rpy="0 0 0" />
      <geometry>
        <box size="0.006 0.016 0.014" />
        </geometry>
      <material name="satin_steel">
        <color rgba="0.62 0.64 0.63 1" />
        </material>
      </visual>
    <collision name="inner_tongue">
      <origin xyz="0.18 0 0.01375" rpy="0 0 0" />
      <geometry>
        <box size="0.36 0.012 0.0115" />
        </geometry>
      </collision>
    <collision name="inner_top_race">
      <origin xyz="0.18 0 0.0208" rpy="0 0 0" />
      <geometry>
        <box size="0.36 0.012 0.003" />
        </geometry>
      </collision>
    <collision name="front_nose">
      <origin xyz="0.357 0 0.017" rpy="0 0 0" />
      <geometry>
        <box size="0.006 0.016 0.014" />
        </geometry>
      </collision>
    </link>
  <link name="equipment_plate">
    <visual name="end_tab">
      <origin xyz="0.006 0 0.0295" rpy="0 0 0" />
      <geometry>
        <box size="0.012 0.018 0.015" />
        </geometry>
      <material name="black_plate">
        <color rgba="0.04 0.045 0.05 1" />
        </material>
      </visual>
    <visual name="mount_plate">
      <origin xyz="0.052 0 0.0398" rpy="0 0 0" />
      <geometry>
        <box size="0.09 0.078 0.006" />
        </geometry>
      <material name="black_plate">
        <color rgba="0.04 0.045 0.05 1" />
        </material>
      </visual>
    <visual name="screw_0.030_neg">
      <origin xyz="0.03 -0.023 0.044" rpy="0 0 0" />
      <geometry>
        <cylinder radius="0.0055" length="0.0026" />
        </geometry>
      <material name="screw_dark">
        <color rgba="0.11 0.11 0.12 1" />
        </material>
      </visual>
    <visual name="screw_0.030_pos">
      <origin xyz="0.03 0.023 0.044" rpy="0 0 0" />
      <geometry>
        <cylinder radius="0.0055" length="0.0026" />
        </geometry>
      <material name="screw_dark">
        <color rgba="0.11 0.11 0.12 1" />
        </material>
      </visual>
    <visual name="screw_0.074_neg">
      <origin xyz="0.074 -0.023 0.044" rpy="0 0 0" />
      <geometry>
        <cylinder radius="0.0055" length="0.0026" />
        </geometry>
      <material name="screw_dark">
        <color rgba="0.11 0.11 0.12 1" />
        </material>
      </visual>
    <visual name="screw_0.074_pos">
      <origin xyz="0.074 0.023 0.044" rpy="0 0 0" />
      <geometry>
        <cylinder radius="0.0055" length="0.0026" />
        </geometry>
      <material name="screw_dark">
        <color rgba="0.11 0.11 0.12 1" />
        </material>
      </visual>
    <collision name="end_tab">
      <origin xyz="0.006 0 0.0295" rpy="0 0 0" />
      <geometry>
        <box size="0.012 0.018 0.015" />
        </geometry>
      </collision>
    <collision name="mount_plate">
      <origin xyz="0.052 0 0.0398" rpy="0 0 0" />
      <geometry>
        <box size="0.09 0.078 0.006" />
        </geometry>
      </collision>
    <collision name="screw_0.030_neg">
      <origin xyz="0.03 -0.023 0.044" rpy="0 0 0" />
      <geometry>
        <cylinder radius="0.0055" length="0.0026" />
        </geometry>
      </collision>
    <collision name="screw_0.030_pos">
      <origin xyz="0.03 0.023 0.044" rpy="0 0 0" />
      <geometry>
        <cylinder radius="0.0055" length="0.0026" />
        </geometry>
      </collision>
    <collision name="screw_0.074_neg">
      <origin xyz="0.074 -0.023 0.044" rpy="0 0 0" />
      <geometry>
        <cylinder radius="0.0055" length="0.0026" />
        </geometry>
      </collision>
    <collision name="screw_0.074_pos">
      <origin xyz="0.074 0.023 0.044" rpy="0 0 0" />
      <geometry>
        <cylinder radius="0.0055" length="0.0026" />
        </geometry>
      </collision>
    </link>
  <joint name="channel_to_middle" type="prismatic">
    <origin xyz="0.045 0 0" rpy="0 0 0" />
    <parent link="channel" />
    <child link="middle_slide" />
    <axis xyz="1 0 0" />
    <limit effort="65" velocity="0.35" lower="0" upper="0.18" />
    </joint>
  <joint name="middle_to_inner" type="prismatic">
    <origin xyz="0.035 0 0" rpy="0 0 0" />
    <parent link="middle_slide" />
    <child link="inner_slide" />
    <axis xyz="1 0 0" />
    <limit effort="45" velocity="0.35" lower="0" upper="0.16" />
    </joint>
  <joint name="inner_to_plate" type="fixed">
    <origin xyz="0.36 0 0" rpy="0 0 0" />
    <parent link="inner_slide" />
    <child link="equipment_plate" />
    </joint>
  </robot>
