<robot name="artisan_stand_mixer">
  <material name="deep_red_enamel">
    <color rgba="0.62 0.035 0.03 1" />
    </material>
  <material name="dark_red_shadow">
    <color rgba="0.34 0.018 0.016 1" />
    </material>
  <material name="polished_stainless">
    <color rgba="0.82 0.83 0.8 1" />
    </material>
  <material name="bright_chrome">
    <color rgba="0.72 0.74 0.76 1" />
    </material>
  <material name="black_rubber">
    <color rgba="0.025 0.025 0.025 1" />
    </material>
  <material name="cream_badge">
    <color rgba="0.92 0.86 0.68 1" />
    </material>
  <material name="dark_slot">
    <color rgba="0.08 0.08 0.085 1" />
    </material>
  <link name="base">
    <visual name="pedestal_base">
      <origin xyz="0.02 0 0.04" rpy="0 0 0" />
      <geometry>
        <box size="0.58 0.38 0.08" />
        </geometry>
      <material name="deep_red_enamel">
        <color rgba="0.62 0.035 0.03 1" />
        </material>
      </visual>
    <visual name="raised_deck">
      <origin xyz="0.075 0 0.098" rpy="0 0 0" />
      <geometry>
        <box size="0.48 0.3 0.035" />
        </geometry>
      <material name="dark_red_shadow">
        <color rgba="0.34 0.018 0.016 1" />
        </material>
      </visual>
    <visual name="rear_column">
      <origin xyz="-0.18 0 0.27" rpy="0 0 0" />
      <geometry>
        <box size="0.15 0.24 0.38" />
        </geometry>
      <material name="deep_red_enamel">
        <color rgba="0.62 0.035 0.03 1" />
        </material>
      </visual>
    <visual name="hinge_cheek_0">
      <origin xyz="-0.18 0.12 0.475" rpy="0 0 0" />
      <geometry>
        <box size="0.18 0.05 0.08" />
        </geometry>
      <material name="deep_red_enamel">
        <color rgba="0.62 0.035 0.03 1" />
        </material>
      </visual>
    <visual name="hinge_cheek_1">
      <origin xyz="-0.18 -0.12 0.475" rpy="0 0 0" />
      <geometry>
        <box size="0.18 0.05 0.08" />
        </geometry>
      <material name="deep_red_enamel">
        <color rgba="0.62 0.035 0.03 1" />
        </material>
      </visual>
    <visual name="hinge_knuckle_0">
      <origin xyz="-0.18 0.12 0.5" rpy="-1.5708 0 0" />
      <geometry>
        <cylinder radius="0.034" length="0.08" />
        </geometry>
      <material name="bright_chrome">
        <color rgba="0.72 0.74 0.76 1" />
        </material>
      </visual>
    <visual name="hinge_knuckle_1">
      <origin xyz="-0.18 -0.12 0.5" rpy="-1.5708 0 0" />
      <geometry>
        <cylinder radius="0.034" length="0.08" />
        </geometry>
      <material name="bright_chrome">
        <color rgba="0.72 0.74 0.76 1" />
        </material>
      </visual>
    <visual name="slide_rail_0">
      <origin xyz="0.075 0.095 0.112" rpy="0 1.5708 0" />
      <geometry>
        <cylinder radius="0.01" length="0.32" />
        </geometry>
      <material name="bright_chrome">
        <color rgba="0.72 0.74 0.76 1" />
        </material>
      </visual>
    <visual name="slide_rail_1">
      <origin xyz="0.075 -0.095 0.112" rpy="0 1.5708 0" />
      <geometry>
        <cylinder radius="0.01" length="0.32" />
        </geometry>
      <material name="bright_chrome">
        <color rgba="0.72 0.74 0.76 1" />
        </material>
      </visual>
    <visual name="rear_slide_stop">
      <origin xyz="-0.08 0 0.126" rpy="0 0 0" />
      <geometry>
        <box size="0.02 0.24 0.035" />
        </geometry>
      <material name="dark_slot">
        <color rgba="0.08 0.08 0.085 1" />
        </material>
      </visual>
    <visual name="front_slide_stop">
      <origin xyz="0.32 0 0.126" rpy="0 0 0" />
      <geometry>
        <box size="0.02 0.24 0.035" />
        </geometry>
      <material name="dark_slot">
        <color rgba="0.08 0.08 0.085 1" />
        </material>
      </visual>
    <visual name="speed_gate">
      <origin xyz="-0.18 -0.121 0.26" rpy="0 0 0" />
      <geometry>
        <box size="0.095 0.006 0.026" />
        </geometry>
      <material name="dark_slot">
        <color rgba="0.08 0.08 0.085 1" />
        </material>
      </visual>
    <visual name="lock_recess">
      <origin xyz="-0.18 0.114 0.275" rpy="0 0 0" />
      <geometry>
        <box size="0.08 0.007 0.03" />
        </geometry>
      <material name="dark_slot">
        <color rgba="0.08 0.08 0.085 1" />
        </material>
      </visual>
    <visual name="artisan_badge">
      <origin xyz="0.1 -0.185 0.07" rpy="0 0 0" />
      <geometry>
        <box size="0.115 0.01 0.035" />
        </geometry>
      <material name="cream_badge">
        <color rgba="0.92 0.86 0.68 1" />
        </material>
      </visual>
    <visual name="rubber_foot_-0.2_-0.13">
      <origin xyz="-0.2 -0.13 0.009" rpy="0 0 0" />
      <geometry>
        <cylinder radius="0.03" length="0.018" />
        </geometry>
      <material name="black_rubber">
        <color rgba="0.025 0.025 0.025 1" />
        </material>
      </visual>
    <visual name="rubber_foot_-0.2_0.13">
      <origin xyz="-0.2 0.13 0.009" rpy="0 0 0" />
      <geometry>
        <cylinder radius="0.03" length="0.018" />
        </geometry>
      <material name="black_rubber">
        <color rgba="0.025 0.025 0.025 1" />
        </material>
      </visual>
    <visual name="rubber_foot_0.24_-0.13">
      <origin xyz="0.24 -0.13 0.009" rpy="0 0 0" />
      <geometry>
        <cylinder radius="0.03" length="0.018" />
        </geometry>
      <material name="black_rubber">
        <color rgba="0.025 0.025 0.025 1" />
        </material>
      </visual>
    <visual name="rubber_foot_0.24_0.13">
      <origin xyz="0.24 0.13 0.009" rpy="0 0 0" />
      <geometry>
        <cylinder radius="0.03" length="0.018" />
        </geometry>
      <material name="black_rubber">
        <color rgba="0.025 0.025 0.025 1" />
        </material>
      </visual>
    <collision name="pedestal_base">
      <origin xyz="0.02 0 0.04" rpy="0 0 0" />
      <geometry>
        <box size="0.58 0.38 0.08" />
        </geometry>
      </collision>
    <collision name="raised_deck">
      <origin xyz="0.075 0 0.098" rpy="0 0 0" />
      <geometry>
        <box size="0.48 0.3 0.035" />
        </geometry>
      </collision>
    <collision name="rear_column">
      <origin xyz="-0.18 0 0.27" rpy="0 0 0" />
      <geometry>
        <box size="0.15 0.24 0.38" />
        </geometry>
      </collision>
    <collision name="hinge_cheek_0">
      <origin xyz="-0.18 0.12 0.475" rpy="0 0 0" />
      <geometry>
        <box size="0.18 0.05 0.08" />
        </geometry>
      </collision>
    <collision name="hinge_cheek_1">
      <origin xyz="-0.18 -0.12 0.475" rpy="0 0 0" />
      <geometry>
        <box size="0.18 0.05 0.08" />
        </geometry>
      </collision>
    <collision name="hinge_knuckle_0">
      <origin xyz="-0.18 0.12 0.5" rpy="-1.5708 0 0" />
      <geometry>
        <cylinder radius="0.034" length="0.08" />
        </geometry>
      </collision>
    <collision name="hinge_knuckle_1">
      <origin xyz="-0.18 -0.12 0.5" rpy="-1.5708 0 0" />
      <geometry>
        <cylinder radius="0.034" length="0.08" />
        </geometry>
      </collision>
    <collision name="slide_rail_0">
      <origin xyz="0.075 0.095 0.112" rpy="0 1.5708 0" />
      <geometry>
        <cylinder radius="0.01" length="0.32" />
        </geometry>
      </collision>
    <collision name="slide_rail_1">
      <origin xyz="0.075 -0.095 0.112" rpy="0 1.5708 0" />
      <geometry>
        <cylinder radius="0.01" length="0.32" />
        </geometry>
      </collision>
    <collision name="rear_slide_stop">
      <origin xyz="-0.08 0 0.126" rpy="0 0 0" />
      <geometry>
        <box size="0.02 0.24 0.035" />
        </geometry>
      </collision>
    <collision name="front_slide_stop">
      <origin xyz="0.32 0 0.126" rpy="0 0 0" />
      <geometry>
        <box size="0.02 0.24 0.035" />
        </geometry>
      </collision>
    <collision name="speed_gate">
      <origin xyz="-0.18 -0.121 0.26" rpy="0 0 0" />
      <geometry>
        <box size="0.095 0.006 0.026" />
        </geometry>
      </collision>
    <collision name="lock_recess">
      <origin xyz="-0.18 0.114 0.275" rpy="0 0 0" />
      <geometry>
        <box size="0.08 0.007 0.03" />
        </geometry>
      </collision>
    <collision name="artisan_badge">
      <origin xyz="0.1 -0.185 0.07" rpy="0 0 0" />
      <geometry>
        <box size="0.115 0.01 0.035" />
        </geometry>
      </collision>
    <collision name="rubber_foot_-0.2_-0.13">
      <origin xyz="-0.2 -0.13 0.009" rpy="0 0 0" />
      <geometry>
        <cylinder radius="0.03" length="0.018" />
        </geometry>
      </collision>
    <collision name="rubber_foot_-0.2_0.13">
      <origin xyz="-0.2 0.13 0.009" rpy="0 0 0" />
      <geometry>
        <cylinder radius="0.03" length="0.018" />
        </geometry>
      </collision>
    <collision name="rubber_foot_0.24_-0.13">
      <origin xyz="0.24 -0.13 0.009" rpy="0 0 0" />
      <geometry>
        <cylinder radius="0.03" length="0.018" />
        </geometry>
      </collision>
    <collision name="rubber_foot_0.24_0.13">
      <origin xyz="0.24 0.13 0.009" rpy="0 0 0" />
      <geometry>
        <cylinder radius="0.03" length="0.018" />
        </geometry>
      </collision>
    </link>
  <link name="bowl_carriage">
    <visual name="slide_saddle">
      <origin xyz="0.07 0 0.016" rpy="0 0 0" />
      <geometry>
        <box size="0.3 0.22 0.032" />
        </geometry>
      <material name="bright_chrome">
        <color rgba="0.72 0.74 0.76 1" />
        </material>
      </visual>
    <visual name="bowl_clip_0">
      <origin xyz="0.125 0.118 0.048" rpy="0 0 0" />
      <geometry>
        <box size="0.16 0.025 0.045" />
        </geometry>
      <material name="bright_chrome">
        <color rgba="0.72 0.74 0.76 1" />
        </material>
      </visual>
    <visual name="bowl_clip_1">
      <origin xyz="0.125 -0.118 0.048" rpy="0 0 0" />
      <geometry>
        <box size="0.16 0.025 0.045" />
        </geometry>
      <material name="bright_chrome">
        <color rgba="0.72 0.74 0.76 1" />
        </material>
      </visual>
    <visual name="bowl_foot_socket">
      <origin xyz="0.125 0 0.04" rpy="0 0 0" />
      <geometry>
        <cylinder radius="0.06" length="0.02" />
        </geometry>
      <material name="bright_chrome">
        <color rgba="0.72 0.74 0.76 1" />
        </material>
      </visual>
    <visual name="mixing_bowl">
      <origin xyz="0.125 0 0.041" rpy="0 0 0" />
      <geometry>
        <mesh filename="assets/meshes/polished_mixing_bowl.obj" />
        </geometry>
      <material name="polished_stainless">
        <color rgba="0.82 0.83 0.8 1" />
        </material>
      </visual>
    <collision name="slide_saddle">
      <origin xyz="0.07 0 0.016" rpy="0 0 0" />
      <geometry>
        <box size="0.3 0.22 0.032" />
        </geometry>
      </collision>
    <collision name="bowl_clip_0">
      <origin xyz="0.125 0.118 0.048" rpy="0 0 0" />
      <geometry>
        <box size="0.16 0.025 0.045" />
        </geometry>
      </collision>
    <collision name="bowl_clip_1">
      <origin xyz="0.125 -0.118 0.048" rpy="0 0 0" />
      <geometry>
        <box size="0.16 0.025 0.045" />
        </geometry>
      </collision>
    <collision name="bowl_foot_socket">
      <origin xyz="0.125 0 0.04" rpy="0 0 0" />
      <geometry>
        <cylinder radius="0.06" length="0.02" />
        </geometry>
      </collision>
    <collision name="mixing_bowl">
      <origin xyz="0.125 0 0.041" rpy="0 0 0" />
      <geometry>
        <mesh filename="assets/meshes/polished_mixing_bowl.obj" />
        </geometry>
      </collision>
    </link>
  <link name="tilt_head">
    <visual name="rounded_head_shell">
      <origin xyz="0.31 0 0.03" rpy="0 0 0" />
      <geometry>
        <mesh filename="assets/meshes/rounded_head_shell.obj" />
        </geometry>
      <material name="deep_red_enamel">
        <color rgba="0.62 0.035 0.03 1" />
        </material>
      </visual>
    <visual name="center_hinge_barrel">
      <origin xyz="0 0 0" rpy="-1.5708 0 0" />
      <geometry>
        <cylinder radius="0.035" length="0.16" />
        </geometry>
      <material name="bright_chrome">
        <color rgba="0.72 0.74 0.76 1" />
        </material>
      </visual>
    <visual name="rear_hinge_lug">
      <origin xyz="0.08 0 0.02" rpy="0 0 0" />
      <geometry>
        <box size="0.15 0.14 0.07" />
        </geometry>
      <material name="dark_red_shadow">
        <color rgba="0.34 0.018 0.016 1" />
        </material>
      </visual>
    <visual name="front_trim_band">
      <origin xyz="0.51 0 0.03" rpy="0 1.5708 0" />
      <geometry>
        <cylinder radius="0.052" length="0.03" />
        </geometry>
      <material name="bright_chrome">
        <color rgba="0.72 0.74 0.76 1" />
        </material>
      </visual>
    <visual name="drive_hub">
      <origin xyz="0.335 0 -0.08" rpy="0 0 0" />
      <geometry>
        <cylinder radius="0.036" length="0.06" />
        </geometry>
      <material name="bright_chrome">
        <color rgba="0.72 0.74 0.76 1" />
        </material>
      </visual>
    <visual name="side_name_plate">
      <origin xyz="0.22 -0.078 0.075" rpy="0 0 0" />
      <geometry>
        <box size="0.07 0.012 0.03" />
        </geometry>
      <material name="cream_badge">
        <color rgba="0.92 0.86 0.68 1" />
        </material>
      </visual>
    <collision name="rounded_head_shell">
      <origin xyz="0.31 0 0.03" rpy="0 0 0" />
      <geometry>
        <mesh filename="assets/meshes/rounded_head_shell.obj" />
        </geometry>
      </collision>
    <collision name="center_hinge_barrel">
      <origin xyz="0 0 0" rpy="-1.5708 0 0" />
      <geometry>
        <cylinder radius="0.035" length="0.16" />
        </geometry>
      </collision>
    <collision name="rear_hinge_lug">
      <origin xyz="0.08 0 0.02" rpy="0 0 0" />
      <geometry>
        <box size="0.15 0.14 0.07" />
        </geometry>
      </collision>
    <collision name="front_trim_band">
      <origin xyz="0.51 0 0.03" rpy="0 1.5708 0" />
      <geometry>
        <cylinder radius="0.052" length="0.03" />
        </geometry>
      </collision>
    <collision name="drive_hub">
      <origin xyz="0.335 0 -0.08" rpy="0 0 0" />
      <geometry>
        <cylinder radius="0.036" length="0.06" />
        </geometry>
      </collision>
    <collision name="side_name_plate">
      <origin xyz="0.22 -0.078 0.075" rpy="0 0 0" />
      <geometry>
        <box size="0.07 0.012 0.03" />
        </geometry>
      </collision>
    </link>
  <link name="whisk">
    <visual name="drive_shaft">
      <origin xyz="0 0 -0.06" rpy="0 0 0" />
      <geometry>
        <cylinder radius="0.006" length="0.12" />
        </geometry>
      <material name="polished_stainless">
        <color rgba="0.82 0.83 0.8 1" />
        </material>
      </visual>
    <visual name="upper_collar">
      <origin xyz="0 0 -0.016" rpy="0 0 0" />
      <geometry>
        <cylinder radius="0.026" length="0.032" />
        </geometry>
      <material name="bright_chrome">
        <color rgba="0.72 0.74 0.76 1" />
        </material>
      </visual>
    <visual name="lower_collar">
      <origin xyz="0 0 -0.204" rpy="0 0 0" />
      <geometry>
        <cylinder radius="0.018" length="0.026" />
        </geometry>
      <material name="bright_chrome">
        <color rgba="0.72 0.74 0.76 1" />
        </material>
      </visual>
    <visual name="wire_loop_0">
      <geometry>
        <mesh filename="assets/meshes/whisk_wire_0.obj" />
        </geometry>
      <material name="polished_stainless">
        <color rgba="0.82 0.83 0.8 1" />
        </material>
      </visual>
    <visual name="wire_loop_1">
      <geometry>
        <mesh filename="assets/meshes/whisk_wire_1.obj" />
        </geometry>
      <material name="polished_stainless">
        <color rgba="0.82 0.83 0.8 1" />
        </material>
      </visual>
    <visual name="wire_loop_2">
      <geometry>
        <mesh filename="assets/meshes/whisk_wire_2.obj" />
        </geometry>
      <material name="polished_stainless">
        <color rgba="0.82 0.83 0.8 1" />
        </material>
      </visual>
    <visual name="wire_loop_3">
      <geometry>
        <mesh filename="assets/meshes/whisk_wire_3.obj" />
        </geometry>
      <material name="polished_stainless">
        <color rgba="0.82 0.83 0.8 1" />
        </material>
      </visual>
    <visual name="wire_loop_4">
      <geometry>
        <mesh filename="assets/meshes/whisk_wire_4.obj" />
        </geometry>
      <material name="polished_stainless">
        <color rgba="0.82 0.83 0.8 1" />
        </material>
      </visual>
    <visual name="wire_loop_5">
      <geometry>
        <mesh filename="assets/meshes/whisk_wire_5.obj" />
        </geometry>
      <material name="polished_stainless">
        <color rgba="0.82 0.83 0.8 1" />
        </material>
      </visual>
    <collision name="drive_shaft">
      <origin xyz="0 0 -0.06" rpy="0 0 0" />
      <geometry>
        <cylinder radius="0.006" length="0.12" />
        </geometry>
      </collision>
    <collision name="upper_collar">
      <origin xyz="0 0 -0.016" rpy="0 0 0" />
      <geometry>
        <cylinder radius="0.026" length="0.032" />
        </geometry>
      </collision>
    <collision name="lower_collar">
      <origin xyz="0 0 -0.204" rpy="0 0 0" />
      <geometry>
        <cylinder radius="0.018" length="0.026" />
        </geometry>
      </collision>
    <collision name="wire_loop_0">
      <geometry>
        <mesh filename="assets/meshes/whisk_wire_0.obj" />
        </geometry>
      </collision>
    <collision name="wire_loop_1">
      <geometry>
        <mesh filename="assets/meshes/whisk_wire_1.obj" />
        </geometry>
      </collision>
    <collision name="wire_loop_2">
      <geometry>
        <mesh filename="assets/meshes/whisk_wire_2.obj" />
        </geometry>
      </collision>
    <collision name="wire_loop_3">
      <geometry>
        <mesh filename="assets/meshes/whisk_wire_3.obj" />
        </geometry>
      </collision>
    <collision name="wire_loop_4">
      <geometry>
        <mesh filename="assets/meshes/whisk_wire_4.obj" />
        </geometry>
      </collision>
    <collision name="wire_loop_5">
      <geometry>
        <mesh filename="assets/meshes/whisk_wire_5.obj" />
        </geometry>
      </collision>
    </link>
  <link name="speed_lever">
    <visual name="lever_pivot">
      <origin xyz="0 0 0" rpy="-1.5708 0 0" />
      <geometry>
        <cylinder radius="0.02" length="0.02" />
        </geometry>
      <material name="bright_chrome">
        <color rgba="0.72 0.74 0.76 1" />
        </material>
      </visual>
    <visual name="lever_stem">
      <origin xyz="0 0.003 0" rpy="0 0 0" />
      <geometry>
        <box size="0.018 0.014 0.026" />
        </geometry>
      <material name="bright_chrome">
        <color rgba="0.72 0.74 0.76 1" />
        </material>
      </visual>
    <visual name="lever_blade">
      <origin xyz="0.025 -0.018 0.056" rpy="0 0 0" />
      <geometry>
        <box size="0.02 0.016 0.112" />
        </geometry>
      <material name="bright_chrome">
        <color rgba="0.72 0.74 0.76 1" />
        </material>
      </visual>
    <visual name="lever_knob">
      <origin xyz="0.047 -0.02 0.112" rpy="-1.5708 0 0" />
      <geometry>
        <cylinder radius="0.017" length="0.026" />
        </geometry>
      <material name="black_rubber">
        <color rgba="0.025 0.025 0.025 1" />
        </material>
      </visual>
    <collision name="lever_pivot">
      <origin xyz="0 0 0" rpy="-1.5708 0 0" />
      <geometry>
        <cylinder radius="0.02" length="0.02" />
        </geometry>
      </collision>
    <collision name="lever_stem">
      <origin xyz="0 0.003 0" rpy="0 0 0" />
      <geometry>
        <box size="0.018 0.014 0.026" />
        </geometry>
      </collision>
    <collision name="lever_blade">
      <origin xyz="0.025 -0.018 0.056" rpy="0 0 0" />
      <geometry>
        <box size="0.02 0.016 0.112" />
        </geometry>
      </collision>
    <collision name="lever_knob">
      <origin xyz="0.047 -0.02 0.112" rpy="-1.5708 0 0" />
      <geometry>
        <cylinder radius="0.017" length="0.026" />
        </geometry>
      </collision>
    </link>
  <link name="lock_button">
    <visual name="push_button">
      <origin xyz="0 0.013 0" rpy="-1.5708 0 0" />
      <geometry>
        <cylinder radius="0.019" length="0.026" />
        </geometry>
      <material name="bright_chrome">
        <color rgba="0.72 0.74 0.76 1" />
        </material>
      </visual>
    <visual name="button_stem">
      <origin xyz="0 -0.002 0" rpy="0 0 0" />
      <geometry>
        <box size="0.022 0.01 0.026" />
        </geometry>
      <material name="bright_chrome">
        <color rgba="0.72 0.74 0.76 1" />
        </material>
      </visual>
    <collision name="push_button">
      <origin xyz="0 0.013 0" rpy="-1.5708 0 0" />
      <geometry>
        <cylinder radius="0.019" length="0.026" />
        </geometry>
      </collision>
    <collision name="button_stem">
      <origin xyz="0 -0.002 0" rpy="0 0 0" />
      <geometry>
        <box size="0.022 0.01 0.026" />
        </geometry>
      </collision>
    </link>
  <joint name="base_to_bowl_carriage" type="prismatic">
    <origin xyz="0.04 0 0.122" rpy="0 0 0" />
    <parent link="base" />
    <child link="bowl_carriage" />
    <axis xyz="1 0 0" />
    <limit effort="45" velocity="0.2" lower="0" upper="0.055" />
    </joint>
  <joint name="base_to_head" type="revolute">
    <origin xyz="-0.18 0 0.5" rpy="0 0 0" />
    <parent link="base" />
    <child link="tilt_head" />
    <axis xyz="0 -1 0" />
    <limit effort="28" velocity="1.6" lower="0" upper="1.05" />
    </joint>
  <joint name="head_to_whisk" type="continuous">
    <origin xyz="0.335 0 -0.11" rpy="0 0 0" />
    <parent link="tilt_head" />
    <child link="whisk" />
    <axis xyz="0 0 1" />
    <limit effort="4" velocity="35" />
    </joint>
  <joint name="base_to_speed_lever" type="revolute">
    <origin xyz="-0.18 -0.131 0.26" rpy="0 0 0" />
    <parent link="base" />
    <child link="speed_lever" />
    <axis xyz="0 1 0" />
    <limit effort="1.4" velocity="2.5" lower="-0.55" upper="0.55" />
    </joint>
  <joint name="base_to_lock_button" type="prismatic">
    <origin xyz="-0.18 0.126 0.275" rpy="0 0 0" />
    <parent link="base" />
    <child link="lock_button" />
    <axis xyz="0 -1 0" />
    <limit effort="8" velocity="0.08" lower="0" upper="0.014" />
    </joint>
  </robot>
