<robot name="modern_tall_tub_dishwasher">
  <material name="brushed_stainless">
    <color rgba="0.68 0.7 0.7 1" />
    </material>
  <material name="black_glass">
    <color rgba="0.01 0.012 0.014 1" />
    </material>
  <material name="black_rubber">
    <color rgba="0.015 0.015 0.014 1" />
    </material>
  <material name="dark_gray_nylon">
    <color rgba="0.1 0.11 0.12 1" />
    </material>
  <material name="light_gray_plastic">
    <color rgba="0.72 0.74 0.74 1" />
    </material>
  <material name="white_marking">
    <color rgba="0.92 0.94 0.92 1" />
    </material>
  <material name="translucent_blue_cap">
    <color rgba="0.08 0.22 0.55 1" />
    </material>
  <link name="tub">
    <visual name="left_wall">
      <origin xyz="-0.2875 0 0.46" rpy="0 0 0" />
      <geometry>
        <box size="0.025 0.6 0.78" />
        </geometry>
      <material name="brushed_stainless">
        <color rgba="0.68 0.7 0.7 1" />
        </material>
      </visual>
    <visual name="right_wall">
      <origin xyz="0.2875 0 0.46" rpy="0 0 0" />
      <geometry>
        <box size="0.025 0.6 0.78" />
        </geometry>
      <material name="brushed_stainless">
        <color rgba="0.68 0.7 0.7 1" />
        </material>
      </visual>
    <visual name="back_wall">
      <origin xyz="0 0.2875 0.46" rpy="0 0 0" />
      <geometry>
        <box size="0.6 0.025 0.78" />
        </geometry>
      <material name="brushed_stainless">
        <color rgba="0.68 0.7 0.7 1" />
        </material>
      </visual>
    <visual name="bottom_pan">
      <origin xyz="0 0 0.055" rpy="0 0 0" />
      <geometry>
        <box size="0.6 0.6 0.03" />
        </geometry>
      <material name="brushed_stainless">
        <color rgba="0.68 0.7 0.7 1" />
        </material>
      </visual>
    <visual name="top_panel">
      <origin xyz="0 0 0.855" rpy="0 0 0" />
      <geometry>
        <box size="0.6 0.6 0.03" />
        </geometry>
      <material name="brushed_stainless">
        <color rgba="0.68 0.7 0.7 1" />
        </material>
      </visual>
    <visual name="lower_hinge_leaf">
      <origin xyz="0 -0.299 0.07" rpy="0 0 0" />
      <geometry>
        <box size="0.5 0.028 0.02" />
        </geometry>
      <material name="brushed_stainless">
        <color rgba="0.68 0.7 0.7 1" />
        </material>
      </visual>
    <visual name="front_left_stile">
      <origin xyz="-0.287 -0.285 0.465" rpy="0 0 0" />
      <geometry>
        <box size="0.026 0.03 0.76" />
        </geometry>
      <material name="brushed_stainless">
        <color rgba="0.68 0.7 0.7 1" />
        </material>
      </visual>
    <visual name="front_right_stile">
      <origin xyz="0.287 -0.285 0.465" rpy="0 0 0" />
      <geometry>
        <box size="0.026 0.03 0.76" />
        </geometry>
      <material name="brushed_stainless">
        <color rgba="0.68 0.7 0.7 1" />
        </material>
      </visual>
    <visual name="front_top_rail">
      <origin xyz="0 -0.285 0.835" rpy="0 0 0" />
      <geometry>
        <box size="0.6 0.03 0.026" />
        </geometry>
      <material name="brushed_stainless">
        <color rgba="0.68 0.7 0.7 1" />
        </material>
      </visual>
    <visual name="front_bottom_sill">
      <origin xyz="0 -0.285 0.115" rpy="0 0 0" />
      <geometry>
        <box size="0.6 0.028 0.024" />
        </geometry>
      <material name="brushed_stainless">
        <color rgba="0.68 0.7 0.7 1" />
        </material>
      </visual>
    <visual name="gasket_top">
      <origin xyz="0 -0.29 0.805" rpy="0 0 0" />
      <geometry>
        <box size="0.54 0.012 0.02" />
        </geometry>
      <material name="black_rubber">
        <color rgba="0.015 0.015 0.014 1" />
        </material>
      </visual>
    <visual name="gasket_bottom">
      <origin xyz="0 -0.29 0.125" rpy="0 0 0" />
      <geometry>
        <box size="0.54 0.012 0.018" />
        </geometry>
      <material name="black_rubber">
        <color rgba="0.015 0.015 0.014 1" />
        </material>
      </visual>
    <visual name="gasket_left">
      <origin xyz="-0.255 -0.29 0.465" rpy="0 0 0" />
      <geometry>
        <box size="0.018 0.012 0.68" />
        </geometry>
      <material name="black_rubber">
        <color rgba="0.015 0.015 0.014 1" />
        </material>
      </visual>
    <visual name="gasket_right">
      <origin xyz="0.255 -0.29 0.465" rpy="0 0 0" />
      <geometry>
        <box size="0.018 0.012 0.68" />
        </geometry>
      <material name="black_rubber">
        <color rgba="0.015 0.015 0.014 1" />
        </material>
      </visual>
    <visual name="sump_well">
      <origin xyz="0 0.055 0.075" rpy="0 0 0" />
      <geometry>
        <cylinder radius="0.085" length="0.018" />
        </geometry>
      <material name="light_gray_plastic">
        <color rgba="0.72 0.74 0.74 1" />
        </material>
      </visual>
    <visual name="filter_screen">
      <origin xyz="0 0.055 0.089" rpy="0 0 0" />
      <geometry>
        <cylinder radius="0.06" length="0.01" />
        </geometry>
      <material name="black_glass">
        <color rgba="0.01 0.012 0.014 1" />
        </material>
      </visual>
    <visual name="lower_spray_standpipe">
      <origin xyz="0 0.02 0.1095" rpy="0 0 0" />
      <geometry>
        <cylinder radius="0.025" length="0.053" />
        </geometry>
      <material name="light_gray_plastic">
        <color rgba="0.72 0.74 0.74 1" />
        </material>
      </visual>
    <visual name="upper_spray_feed_tube">
      <origin xyz="0 0.17 0.421" rpy="0 0 0" />
      <geometry>
        <box size="0.026 0.23 0.026" />
        </geometry>
      <material name="light_gray_plastic">
        <color rgba="0.72 0.74 0.74 1" />
        </material>
      </visual>
    <visual name="lower_rail_0">
      <origin xyz="-0.264 0 0.22" rpy="0 0 0" />
      <geometry>
        <box size="0.022 0.51 0.018" />
        </geometry>
      <material name="brushed_stainless">
        <color rgba="0.68 0.7 0.7 1" />
        </material>
      </visual>
    <visual name="lower_rail_1">
      <origin xyz="0.264 0 0.22" rpy="0 0 0" />
      <geometry>
        <box size="0.022 0.51 0.018" />
        </geometry>
      <material name="brushed_stainless">
        <color rgba="0.68 0.7 0.7 1" />
        </material>
      </visual>
    <visual name="upper_rail_0">
      <origin xyz="-0.264 0 0.485" rpy="0 0 0" />
      <geometry>
        <box size="0.022 0.51 0.018" />
        </geometry>
      <material name="brushed_stainless">
        <color rgba="0.68 0.7 0.7 1" />
        </material>
      </visual>
    <visual name="upper_rail_1">
      <origin xyz="0.264 0 0.485" rpy="0 0 0" />
      <geometry>
        <box size="0.022 0.51 0.018" />
        </geometry>
      <material name="brushed_stainless">
        <color rgba="0.68 0.7 0.7 1" />
        </material>
      </visual>
    <visual name="tray_rail_0">
      <origin xyz="-0.264 0 0.655" rpy="0 0 0" />
      <geometry>
        <box size="0.022 0.51 0.018" />
        </geometry>
      <material name="brushed_stainless">
        <color rgba="0.68 0.7 0.7 1" />
        </material>
      </visual>
    <visual name="tray_rail_1">
      <origin xyz="0.264 0 0.655" rpy="0 0 0" />
      <geometry>
        <box size="0.022 0.51 0.018" />
        </geometry>
      <material name="brushed_stainless">
        <color rgba="0.68 0.7 0.7 1" />
        </material>
      </visual>
    <collision name="left_wall">
      <origin xyz="-0.2875 0 0.46" rpy="0 0 0" />
      <geometry>
        <box size="0.025 0.6 0.78" />
        </geometry>
      </collision>
    <collision name="right_wall">
      <origin xyz="0.2875 0 0.46" rpy="0 0 0" />
      <geometry>
        <box size="0.025 0.6 0.78" />
        </geometry>
      </collision>
    <collision name="back_wall">
      <origin xyz="0 0.2875 0.46" rpy="0 0 0" />
      <geometry>
        <box size="0.6 0.025 0.78" />
        </geometry>
      </collision>
    <collision name="bottom_pan">
      <origin xyz="0 0 0.055" rpy="0 0 0" />
      <geometry>
        <box size="0.6 0.6 0.03" />
        </geometry>
      </collision>
    <collision name="top_panel">
      <origin xyz="0 0 0.855" rpy="0 0 0" />
      <geometry>
        <box size="0.6 0.6 0.03" />
        </geometry>
      </collision>
    <collision name="lower_hinge_leaf">
      <origin xyz="0 -0.299 0.07" rpy="0 0 0" />
      <geometry>
        <box size="0.5 0.028 0.02" />
        </geometry>
      </collision>
    <collision name="front_left_stile">
      <origin xyz="-0.287 -0.285 0.465" rpy="0 0 0" />
      <geometry>
        <box size="0.026 0.03 0.76" />
        </geometry>
      </collision>
    <collision name="front_right_stile">
      <origin xyz="0.287 -0.285 0.465" rpy="0 0 0" />
      <geometry>
        <box size="0.026 0.03 0.76" />
        </geometry>
      </collision>
    <collision name="front_top_rail">
      <origin xyz="0 -0.285 0.835" rpy="0 0 0" />
      <geometry>
        <box size="0.6 0.03 0.026" />
        </geometry>
      </collision>
    <collision name="front_bottom_sill">
      <origin xyz="0 -0.285 0.115" rpy="0 0 0" />
      <geometry>
        <box size="0.6 0.028 0.024" />
        </geometry>
      </collision>
    <collision name="gasket_top">
      <origin xyz="0 -0.29 0.805" rpy="0 0 0" />
      <geometry>
        <box size="0.54 0.012 0.02" />
        </geometry>
      </collision>
    <collision name="gasket_bottom">
      <origin xyz="0 -0.29 0.125" rpy="0 0 0" />
      <geometry>
        <box size="0.54 0.012 0.018" />
        </geometry>
      </collision>
    <collision name="gasket_left">
      <origin xyz="-0.255 -0.29 0.465" rpy="0 0 0" />
      <geometry>
        <box size="0.018 0.012 0.68" />
        </geometry>
      </collision>
    <collision name="gasket_right">
      <origin xyz="0.255 -0.29 0.465" rpy="0 0 0" />
      <geometry>
        <box size="0.018 0.012 0.68" />
        </geometry>
      </collision>
    <collision name="sump_well">
      <origin xyz="0 0.055 0.075" rpy="0 0 0" />
      <geometry>
        <cylinder radius="0.085" length="0.018" />
        </geometry>
      </collision>
    <collision name="filter_screen">
      <origin xyz="0 0.055 0.089" rpy="0 0 0" />
      <geometry>
        <cylinder radius="0.06" length="0.01" />
        </geometry>
      </collision>
    <collision name="lower_spray_standpipe">
      <origin xyz="0 0.02 0.1095" rpy="0 0 0" />
      <geometry>
        <cylinder radius="0.025" length="0.053" />
        </geometry>
      </collision>
    <collision name="upper_spray_feed_tube">
      <origin xyz="0 0.17 0.421" rpy="0 0 0" />
      <geometry>
        <box size="0.026 0.23 0.026" />
        </geometry>
      </collision>
    <collision name="lower_rail_0">
      <origin xyz="-0.264 0 0.22" rpy="0 0 0" />
      <geometry>
        <box size="0.022 0.51 0.018" />
        </geometry>
      </collision>
    <collision name="lower_rail_1">
      <origin xyz="0.264 0 0.22" rpy="0 0 0" />
      <geometry>
        <box size="0.022 0.51 0.018" />
        </geometry>
      </collision>
    <collision name="upper_rail_0">
      <origin xyz="-0.264 0 0.485" rpy="0 0 0" />
      <geometry>
        <box size="0.022 0.51 0.018" />
        </geometry>
      </collision>
    <collision name="upper_rail_1">
      <origin xyz="0.264 0 0.485" rpy="0 0 0" />
      <geometry>
        <box size="0.022 0.51 0.018" />
        </geometry>
      </collision>
    <collision name="tray_rail_0">
      <origin xyz="-0.264 0 0.655" rpy="0 0 0" />
      <geometry>
        <box size="0.022 0.51 0.018" />
        </geometry>
      </collision>
    <collision name="tray_rail_1">
      <origin xyz="0.264 0 0.655" rpy="0 0 0" />
      <geometry>
        <box size="0.022 0.51 0.018" />
        </geometry>
      </collision>
    </link>
  <link name="door">
    <visual name="outer_slab">
      <origin xyz="0 -0.405 0" rpy="0 0 0" />
      <geometry>
        <box size="0.61 0.76 0.05" />
        </geometry>
      <material name="brushed_stainless">
        <color rgba="0.68 0.7 0.7 1" />
        </material>
      </visual>
    <visual name="inner_liner_pan">
      <origin xyz="0 -0.39 0.029" rpy="0 0 0" />
      <geometry>
        <box size="0.545 0.62 0.01" />
        </geometry>
      <material name="brushed_stainless">
        <color rgba="0.68 0.7 0.7 1" />
        </material>
      </visual>
    <visual name="liner_left_wall">
      <origin xyz="-0.282 -0.39 0.044" rpy="0 0 0" />
      <geometry>
        <box size="0.018 0.61 0.022" />
        </geometry>
      <material name="brushed_stainless">
        <color rgba="0.68 0.7 0.7 1" />
        </material>
      </visual>
    <visual name="liner_right_wall">
      <origin xyz="0.282 -0.39 0.044" rpy="0 0 0" />
      <geometry>
        <box size="0.018 0.61 0.022" />
        </geometry>
      <material name="brushed_stainless">
        <color rgba="0.68 0.7 0.7 1" />
        </material>
      </visual>
    <visual name="liner_top_wall">
      <origin xyz="0 -0.695 0.044" rpy="0 0 0" />
      <geometry>
        <box size="0.56 0.018 0.022" />
        </geometry>
      <material name="brushed_stainless">
        <color rgba="0.68 0.7 0.7 1" />
        </material>
      </visual>
    <visual name="liner_bottom_wall">
      <origin xyz="0 -0.085 0.044" rpy="0 0 0" />
      <geometry>
        <box size="0.56 0.018 0.022" />
        </geometry>
      <material name="brushed_stainless">
        <color rgba="0.68 0.7 0.7 1" />
        </material>
      </visual>
    <visual name="detergent_cup">
      <origin xyz="0.125 -0.255 0.044" rpy="0 0 0" />
      <geometry>
        <box size="0.145 0.09 0.022" />
        </geometry>
      <material name="light_gray_plastic">
        <color rgba="0.72 0.74 0.74 1" />
        </material>
      </visual>
    <visual name="detergent_lid_seam">
      <origin xyz="0.125 -0.218 0.054" rpy="0 0 0" />
      <geometry>
        <box size="0.125 0.006 0.004" />
        </geometry>
      <material name="black_glass">
        <color rgba="0.01 0.012 0.014 1" />
        </material>
      </visual>
    <visual name="bottom_hinge_bar">
      <origin xyz="0 -0.02 0" rpy="0 1.5708 0" />
      <geometry>
        <cylinder radius="0.012" length="0.5" />
        </geometry>
      <material name="brushed_stainless">
        <color rgba="0.68 0.7 0.7 1" />
        </material>
      </visual>
    <visual name="control_bank">
      <origin xyz="0 -0.705 -0.0285" rpy="0 0 0" />
      <geometry>
        <box size="0.545 0.092 0.008" />
        </geometry>
      <material name="black_glass">
        <color rgba="0.01 0.012 0.014 1" />
        </material>
      </visual>
    <visual name="handle_recess">
      <origin xyz="0 -0.6 -0.0285" rpy="0 0 0" />
      <geometry>
        <box size="0.44 0.066 0.006" />
        </geometry>
      <material name="black_glass">
        <color rgba="0.01 0.012 0.014 1" />
        </material>
      </visual>
    <visual name="handle_bar">
      <origin xyz="0 -0.6 -0.044" rpy="0 0 0" />
      <geometry>
        <box size="0.42 0.014 0.014" />
        </geometry>
      <material name="brushed_stainless">
        <color rgba="0.68 0.7 0.7 1" />
        </material>
      </visual>
    <visual name="handle_mount_0">
      <origin xyz="-0.205 -0.6 -0.036" rpy="0 0 0" />
      <geometry>
        <box size="0.018 0.05 0.024" />
        </geometry>
      <material name="brushed_stainless">
        <color rgba="0.68 0.7 0.7 1" />
        </material>
      </visual>
    <visual name="handle_mount_1">
      <origin xyz="0.205 -0.6 -0.036" rpy="0 0 0" />
      <geometry>
        <box size="0.018 0.05 0.024" />
        </geometry>
      <material name="brushed_stainless">
        <color rgba="0.68 0.7 0.7 1" />
        </material>
      </visual>
    <collision name="outer_slab">
      <origin xyz="0 -0.405 0" rpy="0 0 0" />
      <geometry>
        <box size="0.61 0.76 0.05" />
        </geometry>
      </collision>
    <collision name="inner_liner_pan">
      <origin xyz="0 -0.39 0.029" rpy="0 0 0" />
      <geometry>
        <box size="0.545 0.62 0.01" />
        </geometry>
      </collision>
    <collision name="liner_left_wall">
      <origin xyz="-0.282 -0.39 0.044" rpy="0 0 0" />
      <geometry>
        <box size="0.018 0.61 0.022" />
        </geometry>
      </collision>
    <collision name="liner_right_wall">
      <origin xyz="0.282 -0.39 0.044" rpy="0 0 0" />
      <geometry>
        <box size="0.018 0.61 0.022" />
        </geometry>
      </collision>
    <collision name="liner_top_wall">
      <origin xyz="0 -0.695 0.044" rpy="0 0 0" />
      <geometry>
        <box size="0.56 0.018 0.022" />
        </geometry>
      </collision>
    <collision name="liner_bottom_wall">
      <origin xyz="0 -0.085 0.044" rpy="0 0 0" />
      <geometry>
        <box size="0.56 0.018 0.022" />
        </geometry>
      </collision>
    <collision name="detergent_cup">
      <origin xyz="0.125 -0.255 0.044" rpy="0 0 0" />
      <geometry>
        <box size="0.145 0.09 0.022" />
        </geometry>
      </collision>
    <collision name="detergent_lid_seam">
      <origin xyz="0.125 -0.218 0.054" rpy="0 0 0" />
      <geometry>
        <box size="0.125 0.006 0.004" />
        </geometry>
      </collision>
    <collision name="bottom_hinge_bar">
      <origin xyz="0 -0.02 0" rpy="0 1.5708 0" />
      <geometry>
        <cylinder radius="0.012" length="0.5" />
        </geometry>
      </collision>
    <collision name="control_bank">
      <origin xyz="0 -0.705 -0.0285" rpy="0 0 0" />
      <geometry>
        <box size="0.545 0.092 0.008" />
        </geometry>
      </collision>
    <collision name="handle_recess">
      <origin xyz="0 -0.6 -0.0285" rpy="0 0 0" />
      <geometry>
        <box size="0.44 0.066 0.006" />
        </geometry>
      </collision>
    <collision name="handle_bar">
      <origin xyz="0 -0.6 -0.044" rpy="0 0 0" />
      <geometry>
        <box size="0.42 0.014 0.014" />
        </geometry>
      </collision>
    <collision name="handle_mount_0">
      <origin xyz="-0.205 -0.6 -0.036" rpy="0 0 0" />
      <geometry>
        <box size="0.018 0.05 0.024" />
        </geometry>
      </collision>
    <collision name="handle_mount_1">
      <origin xyz="0.205 -0.6 -0.036" rpy="0 0 0" />
      <geometry>
        <box size="0.018 0.05 0.024" />
        </geometry>
      </collision>
    </link>
  <link name="lower_rack">
    <visual name="lower_runner_0">
      <origin xyz="-0.244 0 0" rpy="0 0 0" />
      <geometry>
        <box size="0.018 0.46 0.016" />
        </geometry>
      <material name="dark_gray_nylon">
        <color rgba="0.1 0.11 0.12 1" />
        </material>
      </visual>
    <visual name="lower_top_side_0">
      <origin xyz="-0.244 0 0.14" rpy="0 0 0" />
      <geometry>
        <box size="0.014 0.46 0.012" />
        </geometry>
      <material name="dark_gray_nylon">
        <color rgba="0.1 0.11 0.12 1" />
        </material>
      </visual>
    <visual name="lower_runner_1">
      <origin xyz="0.244 0 0" rpy="0 0 0" />
      <geometry>
        <box size="0.018 0.46 0.016" />
        </geometry>
      <material name="dark_gray_nylon">
        <color rgba="0.1 0.11 0.12 1" />
        </material>
      </visual>
    <visual name="lower_top_side_1">
      <origin xyz="0.244 0 0.14" rpy="0 0 0" />
      <geometry>
        <box size="0.014 0.46 0.012" />
        </geometry>
      <material name="dark_gray_nylon">
        <color rgba="0.1 0.11 0.12 1" />
        </material>
      </visual>
    <visual name="lower_bottom_cross_0">
      <origin xyz="0 -0.23 0" rpy="0 0 0" />
      <geometry>
        <box size="0.488 0.016 0.016" />
        </geometry>
      <material name="dark_gray_nylon">
        <color rgba="0.1 0.11 0.12 1" />
        </material>
      </visual>
    <visual name="lower_top_cross_0">
      <origin xyz="0 -0.23 0.14" rpy="0 0 0" />
      <geometry>
        <box size="0.488 0.014 0.012" />
        </geometry>
      <material name="dark_gray_nylon">
        <color rgba="0.1 0.11 0.12 1" />
        </material>
      </visual>
    <visual name="lower_bottom_cross_1">
      <origin xyz="0 0.23 0" rpy="0 0 0" />
      <geometry>
        <box size="0.488 0.016 0.016" />
        </geometry>
      <material name="dark_gray_nylon">
        <color rgba="0.1 0.11 0.12 1" />
        </material>
      </visual>
    <visual name="lower_top_cross_1">
      <origin xyz="0 0.23 0.14" rpy="0 0 0" />
      <geometry>
        <box size="0.488 0.014 0.012" />
        </geometry>
      <material name="dark_gray_nylon">
        <color rgba="0.1 0.11 0.12 1" />
        </material>
      </visual>
    <visual name="lower_corner_post_0_0">
      <origin xyz="-0.244 -0.23 0.07" rpy="0 0 0" />
      <geometry>
        <box size="0.012 0.012 0.14" />
        </geometry>
      <material name="dark_gray_nylon">
        <color rgba="0.1 0.11 0.12 1" />
        </material>
      </visual>
    <visual name="lower_corner_post_0_1">
      <origin xyz="-0.244 0.23 0.07" rpy="0 0 0" />
      <geometry>
        <box size="0.012 0.012 0.14" />
        </geometry>
      <material name="dark_gray_nylon">
        <color rgba="0.1 0.11 0.12 1" />
        </material>
      </visual>
    <visual name="lower_corner_post_1_0">
      <origin xyz="0.244 -0.23 0.07" rpy="0 0 0" />
      <geometry>
        <box size="0.012 0.012 0.14" />
        </geometry>
      <material name="dark_gray_nylon">
        <color rgba="0.1 0.11 0.12 1" />
        </material>
      </visual>
    <visual name="lower_corner_post_1_1">
      <origin xyz="0.244 0.23 0.07" rpy="0 0 0" />
      <geometry>
        <box size="0.012 0.012 0.14" />
        </geometry>
      <material name="dark_gray_nylon">
        <color rgba="0.1 0.11 0.12 1" />
        </material>
      </visual>
    <visual name="lower_grid_cross_0">
      <origin xyz="0 -0.16 0.01" rpy="0 0 0" />
      <geometry>
        <box size="0.488 0.007 0.008" />
        </geometry>
      <material name="dark_gray_nylon">
        <color rgba="0.1 0.11 0.12 1" />
        </material>
      </visual>
    <visual name="lower_grid_cross_1">
      <origin xyz="0 -0.08 0.01" rpy="0 0 0" />
      <geometry>
        <box size="0.488 0.007 0.008" />
        </geometry>
      <material name="dark_gray_nylon">
        <color rgba="0.1 0.11 0.12 1" />
        </material>
      </visual>
    <visual name="lower_grid_cross_2">
      <origin xyz="0 0 0.01" rpy="0 0 0" />
      <geometry>
        <box size="0.488 0.007 0.008" />
        </geometry>
      <material name="dark_gray_nylon">
        <color rgba="0.1 0.11 0.12 1" />
        </material>
      </visual>
    <visual name="lower_grid_cross_3">
      <origin xyz="0 0.08 0.01" rpy="0 0 0" />
      <geometry>
        <box size="0.488 0.007 0.008" />
        </geometry>
      <material name="dark_gray_nylon">
        <color rgba="0.1 0.11 0.12 1" />
        </material>
      </visual>
    <visual name="lower_grid_cross_4">
      <origin xyz="0 0.16 0.01" rpy="0 0 0" />
      <geometry>
        <box size="0.488 0.007 0.008" />
        </geometry>
      <material name="dark_gray_nylon">
        <color rgba="0.1 0.11 0.12 1" />
        </material>
      </visual>
    <visual name="lower_grid_long_0">
      <origin xyz="-0.16 0 0.01" rpy="0 0 0" />
      <geometry>
        <box size="0.007 0.46 0.008" />
        </geometry>
      <material name="dark_gray_nylon">
        <color rgba="0.1 0.11 0.12 1" />
        </material>
      </visual>
    <visual name="lower_grid_long_1">
      <origin xyz="-0.08 0 0.01" rpy="0 0 0" />
      <geometry>
        <box size="0.007 0.46 0.008" />
        </geometry>
      <material name="dark_gray_nylon">
        <color rgba="0.1 0.11 0.12 1" />
        </material>
      </visual>
    <visual name="lower_grid_long_2">
      <origin xyz="0 0 0.01" rpy="0 0 0" />
      <geometry>
        <box size="0.007 0.46 0.008" />
        </geometry>
      <material name="dark_gray_nylon">
        <color rgba="0.1 0.11 0.12 1" />
        </material>
      </visual>
    <visual name="lower_grid_long_3">
      <origin xyz="0.08 0 0.01" rpy="0 0 0" />
      <geometry>
        <box size="0.007 0.46 0.008" />
        </geometry>
      <material name="dark_gray_nylon">
        <color rgba="0.1 0.11 0.12 1" />
        </material>
      </visual>
    <visual name="lower_grid_long_4">
      <origin xyz="0.16 0 0.01" rpy="0 0 0" />
      <geometry>
        <box size="0.007 0.46 0.008" />
        </geometry>
      <material name="dark_gray_nylon">
        <color rgba="0.1 0.11 0.12 1" />
        </material>
      </visual>
    <visual name="lower_tine_0">
      <origin xyz="-0.16 -0.08 0.052" rpy="0 0 0" />
      <geometry>
        <box size="0.007 0.007 0.085" />
        </geometry>
      <material name="dark_gray_nylon">
        <color rgba="0.1 0.11 0.12 1" />
        </material>
      </visual>
    <visual name="lower_tine_1">
      <origin xyz="-0.08 -0.08 0.052" rpy="0 0 0" />
      <geometry>
        <box size="0.007 0.007 0.085" />
        </geometry>
      <material name="dark_gray_nylon">
        <color rgba="0.1 0.11 0.12 1" />
        </material>
      </visual>
    <visual name="lower_tine_2">
      <origin xyz="0 -0.08 0.052" rpy="0 0 0" />
      <geometry>
        <box size="0.007 0.007 0.085" />
        </geometry>
      <material name="dark_gray_nylon">
        <color rgba="0.1 0.11 0.12 1" />
        </material>
      </visual>
    <visual name="lower_tine_3">
      <origin xyz="0.08 -0.08 0.052" rpy="0 0 0" />
      <geometry>
        <box size="0.007 0.007 0.085" />
        </geometry>
      <material name="dark_gray_nylon">
        <color rgba="0.1 0.11 0.12 1" />
        </material>
      </visual>
    <visual name="lower_tine_4">
      <origin xyz="0.16 -0.08 0.052" rpy="0 0 0" />
      <geometry>
        <box size="0.007 0.007 0.085" />
        </geometry>
      <material name="dark_gray_nylon">
        <color rgba="0.1 0.11 0.12 1" />
        </material>
      </visual>
    <visual name="lower_tine_5">
      <origin xyz="-0.16 0.08 0.052" rpy="0 0 0" />
      <geometry>
        <box size="0.007 0.007 0.085" />
        </geometry>
      <material name="dark_gray_nylon">
        <color rgba="0.1 0.11 0.12 1" />
        </material>
      </visual>
    <visual name="lower_tine_6">
      <origin xyz="-0.08 0.08 0.052" rpy="0 0 0" />
      <geometry>
        <box size="0.007 0.007 0.085" />
        </geometry>
      <material name="dark_gray_nylon">
        <color rgba="0.1 0.11 0.12 1" />
        </material>
      </visual>
    <visual name="lower_tine_7">
      <origin xyz="0 0.08 0.052" rpy="0 0 0" />
      <geometry>
        <box size="0.007 0.007 0.085" />
        </geometry>
      <material name="dark_gray_nylon">
        <color rgba="0.1 0.11 0.12 1" />
        </material>
      </visual>
    <visual name="lower_tine_8">
      <origin xyz="0.08 0.08 0.052" rpy="0 0 0" />
      <geometry>
        <box size="0.007 0.007 0.085" />
        </geometry>
      <material name="dark_gray_nylon">
        <color rgba="0.1 0.11 0.12 1" />
        </material>
      </visual>
    <visual name="lower_tine_9">
      <origin xyz="0.16 0.08 0.052" rpy="0 0 0" />
      <geometry>
        <box size="0.007 0.007 0.085" />
        </geometry>
      <material name="dark_gray_nylon">
        <color rgba="0.1 0.11 0.12 1" />
        </material>
      </visual>
    <visual name="lower_tine_10">
      <origin xyz="-0.08 0.16 0.052" rpy="0 0 0" />
      <geometry>
        <box size="0.007 0.007 0.085" />
        </geometry>
      <material name="dark_gray_nylon">
        <color rgba="0.1 0.11 0.12 1" />
        </material>
      </visual>
    <visual name="lower_tine_11">
      <origin xyz="0.08 0.16 0.052" rpy="0 0 0" />
      <geometry>
        <box size="0.007 0.007 0.085" />
        </geometry>
      <material name="dark_gray_nylon">
        <color rgba="0.1 0.11 0.12 1" />
        </material>
      </visual>
    <collision name="lower_runner_0">
      <origin xyz="-0.244 0 0" rpy="0 0 0" />
      <geometry>
        <box size="0.018 0.46 0.016" />
        </geometry>
      </collision>
    <collision name="lower_top_side_0">
      <origin xyz="-0.244 0 0.14" rpy="0 0 0" />
      <geometry>
        <box size="0.014 0.46 0.012" />
        </geometry>
      </collision>
    <collision name="lower_runner_1">
      <origin xyz="0.244 0 0" rpy="0 0 0" />
      <geometry>
        <box size="0.018 0.46 0.016" />
        </geometry>
      </collision>
    <collision name="lower_top_side_1">
      <origin xyz="0.244 0 0.14" rpy="0 0 0" />
      <geometry>
        <box size="0.014 0.46 0.012" />
        </geometry>
      </collision>
    <collision name="lower_bottom_cross_0">
      <origin xyz="0 -0.23 0" rpy="0 0 0" />
      <geometry>
        <box size="0.488 0.016 0.016" />
        </geometry>
      </collision>
    <collision name="lower_top_cross_0">
      <origin xyz="0 -0.23 0.14" rpy="0 0 0" />
      <geometry>
        <box size="0.488 0.014 0.012" />
        </geometry>
      </collision>
    <collision name="lower_bottom_cross_1">
      <origin xyz="0 0.23 0" rpy="0 0 0" />
      <geometry>
        <box size="0.488 0.016 0.016" />
        </geometry>
      </collision>
    <collision name="lower_top_cross_1">
      <origin xyz="0 0.23 0.14" rpy="0 0 0" />
      <geometry>
        <box size="0.488 0.014 0.012" />
        </geometry>
      </collision>
    <collision name="lower_corner_post_0_0">
      <origin xyz="-0.244 -0.23 0.07" rpy="0 0 0" />
      <geometry>
        <box size="0.012 0.012 0.14" />
        </geometry>
      </collision>
    <collision name="lower_corner_post_0_1">
      <origin xyz="-0.244 0.23 0.07" rpy="0 0 0" />
      <geometry>
        <box size="0.012 0.012 0.14" />
        </geometry>
      </collision>
    <collision name="lower_corner_post_1_0">
      <origin xyz="0.244 -0.23 0.07" rpy="0 0 0" />
      <geometry>
        <box size="0.012 0.012 0.14" />
        </geometry>
      </collision>
    <collision name="lower_corner_post_1_1">
      <origin xyz="0.244 0.23 0.07" rpy="0 0 0" />
      <geometry>
        <box size="0.012 0.012 0.14" />
        </geometry>
      </collision>
    <collision name="lower_grid_cross_0">
      <origin xyz="0 -0.16 0.01" rpy="0 0 0" />
      <geometry>
        <box size="0.488 0.007 0.008" />
        </geometry>
      </collision>
    <collision name="lower_grid_cross_1">
      <origin xyz="0 -0.08 0.01" rpy="0 0 0" />
      <geometry>
        <box size="0.488 0.007 0.008" />
        </geometry>
      </collision>
    <collision name="lower_grid_cross_2">
      <origin xyz="0 0 0.01" rpy="0 0 0" />
      <geometry>
        <box size="0.488 0.007 0.008" />
        </geometry>
      </collision>
    <collision name="lower_grid_cross_3">
      <origin xyz="0 0.08 0.01" rpy="0 0 0" />
      <geometry>
        <box size="0.488 0.007 0.008" />
        </geometry>
      </collision>
    <collision name="lower_grid_cross_4">
      <origin xyz="0 0.16 0.01" rpy="0 0 0" />
      <geometry>
        <box size="0.488 0.007 0.008" />
        </geometry>
      </collision>
    <collision name="lower_grid_long_0">
      <origin xyz="-0.16 0 0.01" rpy="0 0 0" />
      <geometry>
        <box size="0.007 0.46 0.008" />
        </geometry>
      </collision>
    <collision name="lower_grid_long_1">
      <origin xyz="-0.08 0 0.01" rpy="0 0 0" />
      <geometry>
        <box size="0.007 0.46 0.008" />
        </geometry>
      </collision>
    <collision name="lower_grid_long_2">
      <origin xyz="0 0 0.01" rpy="0 0 0" />
      <geometry>
        <box size="0.007 0.46 0.008" />
        </geometry>
      </collision>
    <collision name="lower_grid_long_3">
      <origin xyz="0.08 0 0.01" rpy="0 0 0" />
      <geometry>
        <box size="0.007 0.46 0.008" />
        </geometry>
      </collision>
    <collision name="lower_grid_long_4">
      <origin xyz="0.16 0 0.01" rpy="0 0 0" />
      <geometry>
        <box size="0.007 0.46 0.008" />
        </geometry>
      </collision>
    <collision name="lower_tine_0">
      <origin xyz="-0.16 -0.08 0.052" rpy="0 0 0" />
      <geometry>
        <box size="0.007 0.007 0.085" />
        </geometry>
      </collision>
    <collision name="lower_tine_1">
      <origin xyz="-0.08 -0.08 0.052" rpy="0 0 0" />
      <geometry>
        <box size="0.007 0.007 0.085" />
        </geometry>
      </collision>
    <collision name="lower_tine_2">
      <origin xyz="0 -0.08 0.052" rpy="0 0 0" />
      <geometry>
        <box size="0.007 0.007 0.085" />
        </geometry>
      </collision>
    <collision name="lower_tine_3">
      <origin xyz="0.08 -0.08 0.052" rpy="0 0 0" />
      <geometry>
        <box size="0.007 0.007 0.085" />
        </geometry>
      </collision>
    <collision name="lower_tine_4">
      <origin xyz="0.16 -0.08 0.052" rpy="0 0 0" />
      <geometry>
        <box size="0.007 0.007 0.085" />
        </geometry>
      </collision>
    <collision name="lower_tine_5">
      <origin xyz="-0.16 0.08 0.052" rpy="0 0 0" />
      <geometry>
        <box size="0.007 0.007 0.085" />
        </geometry>
      </collision>
    <collision name="lower_tine_6">
      <origin xyz="-0.08 0.08 0.052" rpy="0 0 0" />
      <geometry>
        <box size="0.007 0.007 0.085" />
        </geometry>
      </collision>
    <collision name="lower_tine_7">
      <origin xyz="0 0.08 0.052" rpy="0 0 0" />
      <geometry>
        <box size="0.007 0.007 0.085" />
        </geometry>
      </collision>
    <collision name="lower_tine_8">
      <origin xyz="0.08 0.08 0.052" rpy="0 0 0" />
      <geometry>
        <box size="0.007 0.007 0.085" />
        </geometry>
      </collision>
    <collision name="lower_tine_9">
      <origin xyz="0.16 0.08 0.052" rpy="0 0 0" />
      <geometry>
        <box size="0.007 0.007 0.085" />
        </geometry>
      </collision>
    <collision name="lower_tine_10">
      <origin xyz="-0.08 0.16 0.052" rpy="0 0 0" />
      <geometry>
        <box size="0.007 0.007 0.085" />
        </geometry>
      </collision>
    <collision name="lower_tine_11">
      <origin xyz="0.08 0.16 0.052" rpy="0 0 0" />
      <geometry>
        <box size="0.007 0.007 0.085" />
        </geometry>
      </collision>
    </link>
  <link name="upper_rack">
    <visual name="upper_runner_0">
      <origin xyz="-0.244 0 0" rpy="0 0 0" />
      <geometry>
        <box size="0.018 0.44 0.016" />
        </geometry>
      <material name="dark_gray_nylon">
        <color rgba="0.1 0.11 0.12 1" />
        </material>
      </visual>
    <visual name="upper_top_side_0">
      <origin xyz="-0.244 0 0.125" rpy="0 0 0" />
      <geometry>
        <box size="0.014 0.44 0.012" />
        </geometry>
      <material name="dark_gray_nylon">
        <color rgba="0.1 0.11 0.12 1" />
        </material>
      </visual>
    <visual name="upper_runner_1">
      <origin xyz="0.244 0 0" rpy="0 0 0" />
      <geometry>
        <box size="0.018 0.44 0.016" />
        </geometry>
      <material name="dark_gray_nylon">
        <color rgba="0.1 0.11 0.12 1" />
        </material>
      </visual>
    <visual name="upper_top_side_1">
      <origin xyz="0.244 0 0.125" rpy="0 0 0" />
      <geometry>
        <box size="0.014 0.44 0.012" />
        </geometry>
      <material name="dark_gray_nylon">
        <color rgba="0.1 0.11 0.12 1" />
        </material>
      </visual>
    <visual name="upper_bottom_cross_0">
      <origin xyz="0 -0.22 0" rpy="0 0 0" />
      <geometry>
        <box size="0.488 0.016 0.016" />
        </geometry>
      <material name="dark_gray_nylon">
        <color rgba="0.1 0.11 0.12 1" />
        </material>
      </visual>
    <visual name="upper_top_cross_0">
      <origin xyz="0 -0.22 0.125" rpy="0 0 0" />
      <geometry>
        <box size="0.488 0.014 0.012" />
        </geometry>
      <material name="dark_gray_nylon">
        <color rgba="0.1 0.11 0.12 1" />
        </material>
      </visual>
    <visual name="upper_bottom_cross_1">
      <origin xyz="0 0.22 0" rpy="0 0 0" />
      <geometry>
        <box size="0.488 0.016 0.016" />
        </geometry>
      <material name="dark_gray_nylon">
        <color rgba="0.1 0.11 0.12 1" />
        </material>
      </visual>
    <visual name="upper_top_cross_1">
      <origin xyz="0 0.22 0.125" rpy="0 0 0" />
      <geometry>
        <box size="0.488 0.014 0.012" />
        </geometry>
      <material name="dark_gray_nylon">
        <color rgba="0.1 0.11 0.12 1" />
        </material>
      </visual>
    <visual name="upper_corner_post_0_0">
      <origin xyz="-0.244 -0.22 0.0625" rpy="0 0 0" />
      <geometry>
        <box size="0.012 0.012 0.125" />
        </geometry>
      <material name="dark_gray_nylon">
        <color rgba="0.1 0.11 0.12 1" />
        </material>
      </visual>
    <visual name="upper_corner_post_0_1">
      <origin xyz="-0.244 0.22 0.0625" rpy="0 0 0" />
      <geometry>
        <box size="0.012 0.012 0.125" />
        </geometry>
      <material name="dark_gray_nylon">
        <color rgba="0.1 0.11 0.12 1" />
        </material>
      </visual>
    <visual name="upper_corner_post_1_0">
      <origin xyz="0.244 -0.22 0.0625" rpy="0 0 0" />
      <geometry>
        <box size="0.012 0.012 0.125" />
        </geometry>
      <material name="dark_gray_nylon">
        <color rgba="0.1 0.11 0.12 1" />
        </material>
      </visual>
    <visual name="upper_corner_post_1_1">
      <origin xyz="0.244 0.22 0.0625" rpy="0 0 0" />
      <geometry>
        <box size="0.012 0.012 0.125" />
        </geometry>
      <material name="dark_gray_nylon">
        <color rgba="0.1 0.11 0.12 1" />
        </material>
      </visual>
    <visual name="upper_grid_cross_0">
      <origin xyz="0 -0.16 0.01" rpy="0 0 0" />
      <geometry>
        <box size="0.488 0.007 0.008" />
        </geometry>
      <material name="dark_gray_nylon">
        <color rgba="0.1 0.11 0.12 1" />
        </material>
      </visual>
    <visual name="upper_grid_cross_1">
      <origin xyz="0 -0.08 0.01" rpy="0 0 0" />
      <geometry>
        <box size="0.488 0.007 0.008" />
        </geometry>
      <material name="dark_gray_nylon">
        <color rgba="0.1 0.11 0.12 1" />
        </material>
      </visual>
    <visual name="upper_grid_cross_2">
      <origin xyz="0 0 0.01" rpy="0 0 0" />
      <geometry>
        <box size="0.488 0.007 0.008" />
        </geometry>
      <material name="dark_gray_nylon">
        <color rgba="0.1 0.11 0.12 1" />
        </material>
      </visual>
    <visual name="upper_grid_cross_3">
      <origin xyz="0 0.08 0.01" rpy="0 0 0" />
      <geometry>
        <box size="0.488 0.007 0.008" />
        </geometry>
      <material name="dark_gray_nylon">
        <color rgba="0.1 0.11 0.12 1" />
        </material>
      </visual>
    <visual name="upper_grid_cross_4">
      <origin xyz="0 0.16 0.01" rpy="0 0 0" />
      <geometry>
        <box size="0.488 0.007 0.008" />
        </geometry>
      <material name="dark_gray_nylon">
        <color rgba="0.1 0.11 0.12 1" />
        </material>
      </visual>
    <visual name="upper_grid_long_0">
      <origin xyz="-0.16 0 0.01" rpy="0 0 0" />
      <geometry>
        <box size="0.007 0.44 0.008" />
        </geometry>
      <material name="dark_gray_nylon">
        <color rgba="0.1 0.11 0.12 1" />
        </material>
      </visual>
    <visual name="upper_grid_long_1">
      <origin xyz="-0.08 0 0.01" rpy="0 0 0" />
      <geometry>
        <box size="0.007 0.44 0.008" />
        </geometry>
      <material name="dark_gray_nylon">
        <color rgba="0.1 0.11 0.12 1" />
        </material>
      </visual>
    <visual name="upper_grid_long_2">
      <origin xyz="0 0 0.01" rpy="0 0 0" />
      <geometry>
        <box size="0.007 0.44 0.008" />
        </geometry>
      <material name="dark_gray_nylon">
        <color rgba="0.1 0.11 0.12 1" />
        </material>
      </visual>
    <visual name="upper_grid_long_3">
      <origin xyz="0.08 0 0.01" rpy="0 0 0" />
      <geometry>
        <box size="0.007 0.44 0.008" />
        </geometry>
      <material name="dark_gray_nylon">
        <color rgba="0.1 0.11 0.12 1" />
        </material>
      </visual>
    <visual name="upper_grid_long_4">
      <origin xyz="0.16 0 0.01" rpy="0 0 0" />
      <geometry>
        <box size="0.007 0.44 0.008" />
        </geometry>
      <material name="dark_gray_nylon">
        <color rgba="0.1 0.11 0.12 1" />
        </material>
      </visual>
    <visual name="upper_tine_0">
      <origin xyz="-0.16 -0.08 0.052" rpy="0 0 0" />
      <geometry>
        <box size="0.007 0.007 0.085" />
        </geometry>
      <material name="dark_gray_nylon">
        <color rgba="0.1 0.11 0.12 1" />
        </material>
      </visual>
    <visual name="upper_tine_1">
      <origin xyz="-0.08 -0.08 0.052" rpy="0 0 0" />
      <geometry>
        <box size="0.007 0.007 0.085" />
        </geometry>
      <material name="dark_gray_nylon">
        <color rgba="0.1 0.11 0.12 1" />
        </material>
      </visual>
    <visual name="upper_tine_2">
      <origin xyz="0 -0.08 0.052" rpy="0 0 0" />
      <geometry>
        <box size="0.007 0.007 0.085" />
        </geometry>
      <material name="dark_gray_nylon">
        <color rgba="0.1 0.11 0.12 1" />
        </material>
      </visual>
    <visual name="upper_tine_3">
      <origin xyz="0.08 -0.08 0.052" rpy="0 0 0" />
      <geometry>
        <box size="0.007 0.007 0.085" />
        </geometry>
      <material name="dark_gray_nylon">
        <color rgba="0.1 0.11 0.12 1" />
        </material>
      </visual>
    <visual name="upper_tine_4">
      <origin xyz="0.16 -0.08 0.052" rpy="0 0 0" />
      <geometry>
        <box size="0.007 0.007 0.085" />
        </geometry>
      <material name="dark_gray_nylon">
        <color rgba="0.1 0.11 0.12 1" />
        </material>
      </visual>
    <visual name="upper_tine_5">
      <origin xyz="-0.16 0.08 0.052" rpy="0 0 0" />
      <geometry>
        <box size="0.007 0.007 0.085" />
        </geometry>
      <material name="dark_gray_nylon">
        <color rgba="0.1 0.11 0.12 1" />
        </material>
      </visual>
    <visual name="upper_tine_6">
      <origin xyz="-0.08 0.08 0.052" rpy="0 0 0" />
      <geometry>
        <box size="0.007 0.007 0.085" />
        </geometry>
      <material name="dark_gray_nylon">
        <color rgba="0.1 0.11 0.12 1" />
        </material>
      </visual>
    <visual name="upper_tine_7">
      <origin xyz="0 0.08 0.052" rpy="0 0 0" />
      <geometry>
        <box size="0.007 0.007 0.085" />
        </geometry>
      <material name="dark_gray_nylon">
        <color rgba="0.1 0.11 0.12 1" />
        </material>
      </visual>
    <visual name="upper_tine_8">
      <origin xyz="0.08 0.08 0.052" rpy="0 0 0" />
      <geometry>
        <box size="0.007 0.007 0.085" />
        </geometry>
      <material name="dark_gray_nylon">
        <color rgba="0.1 0.11 0.12 1" />
        </material>
      </visual>
    <visual name="upper_tine_9">
      <origin xyz="0.16 0.08 0.052" rpy="0 0 0" />
      <geometry>
        <box size="0.007 0.007 0.085" />
        </geometry>
      <material name="dark_gray_nylon">
        <color rgba="0.1 0.11 0.12 1" />
        </material>
      </visual>
    <visual name="upper_tine_10">
      <origin xyz="-0.08 0.16 0.052" rpy="0 0 0" />
      <geometry>
        <box size="0.007 0.007 0.085" />
        </geometry>
      <material name="dark_gray_nylon">
        <color rgba="0.1 0.11 0.12 1" />
        </material>
      </visual>
    <visual name="upper_tine_11">
      <origin xyz="0.08 0.16 0.052" rpy="0 0 0" />
      <geometry>
        <box size="0.007 0.007 0.085" />
        </geometry>
      <material name="dark_gray_nylon">
        <color rgba="0.1 0.11 0.12 1" />
        </material>
      </visual>
    <collision name="upper_runner_0">
      <origin xyz="-0.244 0 0" rpy="0 0 0" />
      <geometry>
        <box size="0.018 0.44 0.016" />
        </geometry>
      </collision>
    <collision name="upper_top_side_0">
      <origin xyz="-0.244 0 0.125" rpy="0 0 0" />
      <geometry>
        <box size="0.014 0.44 0.012" />
        </geometry>
      </collision>
    <collision name="upper_runner_1">
      <origin xyz="0.244 0 0" rpy="0 0 0" />
      <geometry>
        <box size="0.018 0.44 0.016" />
        </geometry>
      </collision>
    <collision name="upper_top_side_1">
      <origin xyz="0.244 0 0.125" rpy="0 0 0" />
      <geometry>
        <box size="0.014 0.44 0.012" />
        </geometry>
      </collision>
    <collision name="upper_bottom_cross_0">
      <origin xyz="0 -0.22 0" rpy="0 0 0" />
      <geometry>
        <box size="0.488 0.016 0.016" />
        </geometry>
      </collision>
    <collision name="upper_top_cross_0">
      <origin xyz="0 -0.22 0.125" rpy="0 0 0" />
      <geometry>
        <box size="0.488 0.014 0.012" />
        </geometry>
      </collision>
    <collision name="upper_bottom_cross_1">
      <origin xyz="0 0.22 0" rpy="0 0 0" />
      <geometry>
        <box size="0.488 0.016 0.016" />
        </geometry>
      </collision>
    <collision name="upper_top_cross_1">
      <origin xyz="0 0.22 0.125" rpy="0 0 0" />
      <geometry>
        <box size="0.488 0.014 0.012" />
        </geometry>
      </collision>
    <collision name="upper_corner_post_0_0">
      <origin xyz="-0.244 -0.22 0.0625" rpy="0 0 0" />
      <geometry>
        <box size="0.012 0.012 0.125" />
        </geometry>
      </collision>
    <collision name="upper_corner_post_0_1">
      <origin xyz="-0.244 0.22 0.0625" rpy="0 0 0" />
      <geometry>
        <box size="0.012 0.012 0.125" />
        </geometry>
      </collision>
    <collision name="upper_corner_post_1_0">
      <origin xyz="0.244 -0.22 0.0625" rpy="0 0 0" />
      <geometry>
        <box size="0.012 0.012 0.125" />
        </geometry>
      </collision>
    <collision name="upper_corner_post_1_1">
      <origin xyz="0.244 0.22 0.0625" rpy="0 0 0" />
      <geometry>
        <box size="0.012 0.012 0.125" />
        </geometry>
      </collision>
    <collision name="upper_grid_cross_0">
      <origin xyz="0 -0.16 0.01" rpy="0 0 0" />
      <geometry>
        <box size="0.488 0.007 0.008" />
        </geometry>
      </collision>
    <collision name="upper_grid_cross_1">
      <origin xyz="0 -0.08 0.01" rpy="0 0 0" />
      <geometry>
        <box size="0.488 0.007 0.008" />
        </geometry>
      </collision>
    <collision name="upper_grid_cross_2">
      <origin xyz="0 0 0.01" rpy="0 0 0" />
      <geometry>
        <box size="0.488 0.007 0.008" />
        </geometry>
      </collision>
    <collision name="upper_grid_cross_3">
      <origin xyz="0 0.08 0.01" rpy="0 0 0" />
      <geometry>
        <box size="0.488 0.007 0.008" />
        </geometry>
      </collision>
    <collision name="upper_grid_cross_4">
      <origin xyz="0 0.16 0.01" rpy="0 0 0" />
      <geometry>
        <box size="0.488 0.007 0.008" />
        </geometry>
      </collision>
    <collision name="upper_grid_long_0">
      <origin xyz="-0.16 0 0.01" rpy="0 0 0" />
      <geometry>
        <box size="0.007 0.44 0.008" />
        </geometry>
      </collision>
    <collision name="upper_grid_long_1">
      <origin xyz="-0.08 0 0.01" rpy="0 0 0" />
      <geometry>
        <box size="0.007 0.44 0.008" />
        </geometry>
      </collision>
    <collision name="upper_grid_long_2">
      <origin xyz="0 0 0.01" rpy="0 0 0" />
      <geometry>
        <box size="0.007 0.44 0.008" />
        </geometry>
      </collision>
    <collision name="upper_grid_long_3">
      <origin xyz="0.08 0 0.01" rpy="0 0 0" />
      <geometry>
        <box size="0.007 0.44 0.008" />
        </geometry>
      </collision>
    <collision name="upper_grid_long_4">
      <origin xyz="0.16 0 0.01" rpy="0 0 0" />
      <geometry>
        <box size="0.007 0.44 0.008" />
        </geometry>
      </collision>
    <collision name="upper_tine_0">
      <origin xyz="-0.16 -0.08 0.052" rpy="0 0 0" />
      <geometry>
        <box size="0.007 0.007 0.085" />
        </geometry>
      </collision>
    <collision name="upper_tine_1">
      <origin xyz="-0.08 -0.08 0.052" rpy="0 0 0" />
      <geometry>
        <box size="0.007 0.007 0.085" />
        </geometry>
      </collision>
    <collision name="upper_tine_2">
      <origin xyz="0 -0.08 0.052" rpy="0 0 0" />
      <geometry>
        <box size="0.007 0.007 0.085" />
        </geometry>
      </collision>
    <collision name="upper_tine_3">
      <origin xyz="0.08 -0.08 0.052" rpy="0 0 0" />
      <geometry>
        <box size="0.007 0.007 0.085" />
        </geometry>
      </collision>
    <collision name="upper_tine_4">
      <origin xyz="0.16 -0.08 0.052" rpy="0 0 0" />
      <geometry>
        <box size="0.007 0.007 0.085" />
        </geometry>
      </collision>
    <collision name="upper_tine_5">
      <origin xyz="-0.16 0.08 0.052" rpy="0 0 0" />
      <geometry>
        <box size="0.007 0.007 0.085" />
        </geometry>
      </collision>
    <collision name="upper_tine_6">
      <origin xyz="-0.08 0.08 0.052" rpy="0 0 0" />
      <geometry>
        <box size="0.007 0.007 0.085" />
        </geometry>
      </collision>
    <collision name="upper_tine_7">
      <origin xyz="0 0.08 0.052" rpy="0 0 0" />
      <geometry>
        <box size="0.007 0.007 0.085" />
        </geometry>
      </collision>
    <collision name="upper_tine_8">
      <origin xyz="0.08 0.08 0.052" rpy="0 0 0" />
      <geometry>
        <box size="0.007 0.007 0.085" />
        </geometry>
      </collision>
    <collision name="upper_tine_9">
      <origin xyz="0.16 0.08 0.052" rpy="0 0 0" />
      <geometry>
        <box size="0.007 0.007 0.085" />
        </geometry>
      </collision>
    <collision name="upper_tine_10">
      <origin xyz="-0.08 0.16 0.052" rpy="0 0 0" />
      <geometry>
        <box size="0.007 0.007 0.085" />
        </geometry>
      </collision>
    <collision name="upper_tine_11">
      <origin xyz="0.08 0.16 0.052" rpy="0 0 0" />
      <geometry>
        <box size="0.007 0.007 0.085" />
        </geometry>
      </collision>
    </link>
  <link name="utensil_tray">
    <visual name="tray_runner_0">
      <origin xyz="-0.244 0 0" rpy="0 0 0" />
      <geometry>
        <box size="0.018 0.41 0.016" />
        </geometry>
      <material name="dark_gray_nylon">
        <color rgba="0.1 0.11 0.12 1" />
        </material>
      </visual>
    <visual name="tray_top_side_0">
      <origin xyz="-0.244 0 0.06" rpy="0 0 0" />
      <geometry>
        <box size="0.014 0.41 0.012" />
        </geometry>
      <material name="dark_gray_nylon">
        <color rgba="0.1 0.11 0.12 1" />
        </material>
      </visual>
    <visual name="tray_runner_1">
      <origin xyz="0.244 0 0" rpy="0 0 0" />
      <geometry>
        <box size="0.018 0.41 0.016" />
        </geometry>
      <material name="dark_gray_nylon">
        <color rgba="0.1 0.11 0.12 1" />
        </material>
      </visual>
    <visual name="tray_top_side_1">
      <origin xyz="0.244 0 0.06" rpy="0 0 0" />
      <geometry>
        <box size="0.014 0.41 0.012" />
        </geometry>
      <material name="dark_gray_nylon">
        <color rgba="0.1 0.11 0.12 1" />
        </material>
      </visual>
    <visual name="tray_bottom_cross_0">
      <origin xyz="0 -0.205 0" rpy="0 0 0" />
      <geometry>
        <box size="0.488 0.016 0.016" />
        </geometry>
      <material name="dark_gray_nylon">
        <color rgba="0.1 0.11 0.12 1" />
        </material>
      </visual>
    <visual name="tray_top_cross_0">
      <origin xyz="0 -0.205 0.06" rpy="0 0 0" />
      <geometry>
        <box size="0.488 0.014 0.012" />
        </geometry>
      <material name="dark_gray_nylon">
        <color rgba="0.1 0.11 0.12 1" />
        </material>
      </visual>
    <visual name="tray_bottom_cross_1">
      <origin xyz="0 0.205 0" rpy="0 0 0" />
      <geometry>
        <box size="0.488 0.016 0.016" />
        </geometry>
      <material name="dark_gray_nylon">
        <color rgba="0.1 0.11 0.12 1" />
        </material>
      </visual>
    <visual name="tray_top_cross_1">
      <origin xyz="0 0.205 0.06" rpy="0 0 0" />
      <geometry>
        <box size="0.488 0.014 0.012" />
        </geometry>
      <material name="dark_gray_nylon">
        <color rgba="0.1 0.11 0.12 1" />
        </material>
      </visual>
    <visual name="tray_corner_post_0_0">
      <origin xyz="-0.244 -0.205 0.03" rpy="0 0 0" />
      <geometry>
        <box size="0.012 0.012 0.06" />
        </geometry>
      <material name="dark_gray_nylon">
        <color rgba="0.1 0.11 0.12 1" />
        </material>
      </visual>
    <visual name="tray_corner_post_0_1">
      <origin xyz="-0.244 0.205 0.03" rpy="0 0 0" />
      <geometry>
        <box size="0.012 0.012 0.06" />
        </geometry>
      <material name="dark_gray_nylon">
        <color rgba="0.1 0.11 0.12 1" />
        </material>
      </visual>
    <visual name="tray_corner_post_1_0">
      <origin xyz="0.244 -0.205 0.03" rpy="0 0 0" />
      <geometry>
        <box size="0.012 0.012 0.06" />
        </geometry>
      <material name="dark_gray_nylon">
        <color rgba="0.1 0.11 0.12 1" />
        </material>
      </visual>
    <visual name="tray_corner_post_1_1">
      <origin xyz="0.244 0.205 0.03" rpy="0 0 0" />
      <geometry>
        <box size="0.012 0.012 0.06" />
        </geometry>
      <material name="dark_gray_nylon">
        <color rgba="0.1 0.11 0.12 1" />
        </material>
      </visual>
    <visual name="tray_grid_cross_0">
      <origin xyz="0 -0.16 0.01" rpy="0 0 0" />
      <geometry>
        <box size="0.488 0.007 0.008" />
        </geometry>
      <material name="dark_gray_nylon">
        <color rgba="0.1 0.11 0.12 1" />
        </material>
      </visual>
    <visual name="tray_grid_cross_1">
      <origin xyz="0 -0.08 0.01" rpy="0 0 0" />
      <geometry>
        <box size="0.488 0.007 0.008" />
        </geometry>
      <material name="dark_gray_nylon">
        <color rgba="0.1 0.11 0.12 1" />
        </material>
      </visual>
    <visual name="tray_grid_cross_2">
      <origin xyz="0 0 0.01" rpy="0 0 0" />
      <geometry>
        <box size="0.488 0.007 0.008" />
        </geometry>
      <material name="dark_gray_nylon">
        <color rgba="0.1 0.11 0.12 1" />
        </material>
      </visual>
    <visual name="tray_grid_cross_3">
      <origin xyz="0 0.08 0.01" rpy="0 0 0" />
      <geometry>
        <box size="0.488 0.007 0.008" />
        </geometry>
      <material name="dark_gray_nylon">
        <color rgba="0.1 0.11 0.12 1" />
        </material>
      </visual>
    <visual name="tray_grid_cross_4">
      <origin xyz="0 0.16 0.01" rpy="0 0 0" />
      <geometry>
        <box size="0.488 0.007 0.008" />
        </geometry>
      <material name="dark_gray_nylon">
        <color rgba="0.1 0.11 0.12 1" />
        </material>
      </visual>
    <visual name="tray_grid_long_0">
      <origin xyz="-0.16 0 0.01" rpy="0 0 0" />
      <geometry>
        <box size="0.007 0.41 0.008" />
        </geometry>
      <material name="dark_gray_nylon">
        <color rgba="0.1 0.11 0.12 1" />
        </material>
      </visual>
    <visual name="tray_grid_long_1">
      <origin xyz="-0.08 0 0.01" rpy="0 0 0" />
      <geometry>
        <box size="0.007 0.41 0.008" />
        </geometry>
      <material name="dark_gray_nylon">
        <color rgba="0.1 0.11 0.12 1" />
        </material>
      </visual>
    <visual name="tray_grid_long_2">
      <origin xyz="0 0 0.01" rpy="0 0 0" />
      <geometry>
        <box size="0.007 0.41 0.008" />
        </geometry>
      <material name="dark_gray_nylon">
        <color rgba="0.1 0.11 0.12 1" />
        </material>
      </visual>
    <visual name="tray_grid_long_3">
      <origin xyz="0.08 0 0.01" rpy="0 0 0" />
      <geometry>
        <box size="0.007 0.41 0.008" />
        </geometry>
      <material name="dark_gray_nylon">
        <color rgba="0.1 0.11 0.12 1" />
        </material>
      </visual>
    <visual name="tray_grid_long_4">
      <origin xyz="0.16 0 0.01" rpy="0 0 0" />
      <geometry>
        <box size="0.007 0.41 0.008" />
        </geometry>
      <material name="dark_gray_nylon">
        <color rgba="0.1 0.11 0.12 1" />
        </material>
      </visual>
    <visual name="tray_tine_0">
      <origin xyz="-0.16 -0.08 0.052" rpy="0 0 0" />
      <geometry>
        <box size="0.007 0.007 0.085" />
        </geometry>
      <material name="dark_gray_nylon">
        <color rgba="0.1 0.11 0.12 1" />
        </material>
      </visual>
    <visual name="tray_tine_1">
      <origin xyz="-0.08 -0.08 0.052" rpy="0 0 0" />
      <geometry>
        <box size="0.007 0.007 0.085" />
        </geometry>
      <material name="dark_gray_nylon">
        <color rgba="0.1 0.11 0.12 1" />
        </material>
      </visual>
    <visual name="tray_tine_2">
      <origin xyz="0 -0.08 0.052" rpy="0 0 0" />
      <geometry>
        <box size="0.007 0.007 0.085" />
        </geometry>
      <material name="dark_gray_nylon">
        <color rgba="0.1 0.11 0.12 1" />
        </material>
      </visual>
    <visual name="tray_tine_3">
      <origin xyz="0.08 -0.08 0.052" rpy="0 0 0" />
      <geometry>
        <box size="0.007 0.007 0.085" />
        </geometry>
      <material name="dark_gray_nylon">
        <color rgba="0.1 0.11 0.12 1" />
        </material>
      </visual>
    <visual name="tray_tine_4">
      <origin xyz="0.16 -0.08 0.052" rpy="0 0 0" />
      <geometry>
        <box size="0.007 0.007 0.085" />
        </geometry>
      <material name="dark_gray_nylon">
        <color rgba="0.1 0.11 0.12 1" />
        </material>
      </visual>
    <visual name="tray_tine_5">
      <origin xyz="-0.16 0.08 0.052" rpy="0 0 0" />
      <geometry>
        <box size="0.007 0.007 0.085" />
        </geometry>
      <material name="dark_gray_nylon">
        <color rgba="0.1 0.11 0.12 1" />
        </material>
      </visual>
    <visual name="tray_tine_6">
      <origin xyz="-0.08 0.08 0.052" rpy="0 0 0" />
      <geometry>
        <box size="0.007 0.007 0.085" />
        </geometry>
      <material name="dark_gray_nylon">
        <color rgba="0.1 0.11 0.12 1" />
        </material>
      </visual>
    <visual name="tray_tine_7">
      <origin xyz="0 0.08 0.052" rpy="0 0 0" />
      <geometry>
        <box size="0.007 0.007 0.085" />
        </geometry>
      <material name="dark_gray_nylon">
        <color rgba="0.1 0.11 0.12 1" />
        </material>
      </visual>
    <visual name="tray_tine_8">
      <origin xyz="0.08 0.08 0.052" rpy="0 0 0" />
      <geometry>
        <box size="0.007 0.007 0.085" />
        </geometry>
      <material name="dark_gray_nylon">
        <color rgba="0.1 0.11 0.12 1" />
        </material>
      </visual>
    <visual name="tray_tine_9">
      <origin xyz="0.16 0.08 0.052" rpy="0 0 0" />
      <geometry>
        <box size="0.007 0.007 0.085" />
        </geometry>
      <material name="dark_gray_nylon">
        <color rgba="0.1 0.11 0.12 1" />
        </material>
      </visual>
    <visual name="tray_tine_10">
      <origin xyz="-0.08 0.16 0.052" rpy="0 0 0" />
      <geometry>
        <box size="0.007 0.007 0.085" />
        </geometry>
      <material name="dark_gray_nylon">
        <color rgba="0.1 0.11 0.12 1" />
        </material>
      </visual>
    <visual name="tray_tine_11">
      <origin xyz="0.08 0.16 0.052" rpy="0 0 0" />
      <geometry>
        <box size="0.007 0.007 0.085" />
        </geometry>
      <material name="dark_gray_nylon">
        <color rgba="0.1 0.11 0.12 1" />
        </material>
      </visual>
    <visual name="divider_0">
      <origin xyz="-0.14 0 0.031" rpy="0 0 0" />
      <geometry>
        <box size="0.006 0.36 0.05" />
        </geometry>
      <material name="dark_gray_nylon">
        <color rgba="0.1 0.11 0.12 1" />
        </material>
      </visual>
    <visual name="divider_1">
      <origin xyz="-0.07 0 0.031" rpy="0 0 0" />
      <geometry>
        <box size="0.006 0.36 0.05" />
        </geometry>
      <material name="dark_gray_nylon">
        <color rgba="0.1 0.11 0.12 1" />
        </material>
      </visual>
    <visual name="divider_2">
      <origin xyz="0 0 0.031" rpy="0 0 0" />
      <geometry>
        <box size="0.006 0.36 0.05" />
        </geometry>
      <material name="dark_gray_nylon">
        <color rgba="0.1 0.11 0.12 1" />
        </material>
      </visual>
    <visual name="divider_3">
      <origin xyz="0.07 0 0.031" rpy="0 0 0" />
      <geometry>
        <box size="0.006 0.36 0.05" />
        </geometry>
      <material name="dark_gray_nylon">
        <color rgba="0.1 0.11 0.12 1" />
        </material>
      </visual>
    <visual name="divider_4">
      <origin xyz="0.14 0 0.031" rpy="0 0 0" />
      <geometry>
        <box size="0.006 0.36 0.05" />
        </geometry>
      <material name="dark_gray_nylon">
        <color rgba="0.1 0.11 0.12 1" />
        </material>
      </visual>
    <collision name="tray_runner_0">
      <origin xyz="-0.244 0 0" rpy="0 0 0" />
      <geometry>
        <box size="0.018 0.41 0.016" />
        </geometry>
      </collision>
    <collision name="tray_top_side_0">
      <origin xyz="-0.244 0 0.06" rpy="0 0 0" />
      <geometry>
        <box size="0.014 0.41 0.012" />
        </geometry>
      </collision>
    <collision name="tray_runner_1">
      <origin xyz="0.244 0 0" rpy="0 0 0" />
      <geometry>
        <box size="0.018 0.41 0.016" />
        </geometry>
      </collision>
    <collision name="tray_top_side_1">
      <origin xyz="0.244 0 0.06" rpy="0 0 0" />
      <geometry>
        <box size="0.014 0.41 0.012" />
        </geometry>
      </collision>
    <collision name="tray_bottom_cross_0">
      <origin xyz="0 -0.205 0" rpy="0 0 0" />
      <geometry>
        <box size="0.488 0.016 0.016" />
        </geometry>
      </collision>
    <collision name="tray_top_cross_0">
      <origin xyz="0 -0.205 0.06" rpy="0 0 0" />
      <geometry>
        <box size="0.488 0.014 0.012" />
        </geometry>
      </collision>
    <collision name="tray_bottom_cross_1">
      <origin xyz="0 0.205 0" rpy="0 0 0" />
      <geometry>
        <box size="0.488 0.016 0.016" />
        </geometry>
      </collision>
    <collision name="tray_top_cross_1">
      <origin xyz="0 0.205 0.06" rpy="0 0 0" />
      <geometry>
        <box size="0.488 0.014 0.012" />
        </geometry>
      </collision>
    <collision name="tray_corner_post_0_0">
      <origin xyz="-0.244 -0.205 0.03" rpy="0 0 0" />
      <geometry>
        <box size="0.012 0.012 0.06" />
        </geometry>
      </collision>
    <collision name="tray_corner_post_0_1">
      <origin xyz="-0.244 0.205 0.03" rpy="0 0 0" />
      <geometry>
        <box size="0.012 0.012 0.06" />
        </geometry>
      </collision>
    <collision name="tray_corner_post_1_0">
      <origin xyz="0.244 -0.205 0.03" rpy="0 0 0" />
      <geometry>
        <box size="0.012 0.012 0.06" />
        </geometry>
      </collision>
    <collision name="tray_corner_post_1_1">
      <origin xyz="0.244 0.205 0.03" rpy="0 0 0" />
      <geometry>
        <box size="0.012 0.012 0.06" />
        </geometry>
      </collision>
    <collision name="tray_grid_cross_0">
      <origin xyz="0 -0.16 0.01" rpy="0 0 0" />
      <geometry>
        <box size="0.488 0.007 0.008" />
        </geometry>
      </collision>
    <collision name="tray_grid_cross_1">
      <origin xyz="0 -0.08 0.01" rpy="0 0 0" />
      <geometry>
        <box size="0.488 0.007 0.008" />
        </geometry>
      </collision>
    <collision name="tray_grid_cross_2">
      <origin xyz="0 0 0.01" rpy="0 0 0" />
      <geometry>
        <box size="0.488 0.007 0.008" />
        </geometry>
      </collision>
    <collision name="tray_grid_cross_3">
      <origin xyz="0 0.08 0.01" rpy="0 0 0" />
      <geometry>
        <box size="0.488 0.007 0.008" />
        </geometry>
      </collision>
    <collision name="tray_grid_cross_4">
      <origin xyz="0 0.16 0.01" rpy="0 0 0" />
      <geometry>
        <box size="0.488 0.007 0.008" />
        </geometry>
      </collision>
    <collision name="tray_grid_long_0">
      <origin xyz="-0.16 0 0.01" rpy="0 0 0" />
      <geometry>
        <box size="0.007 0.41 0.008" />
        </geometry>
      </collision>
    <collision name="tray_grid_long_1">
      <origin xyz="-0.08 0 0.01" rpy="0 0 0" />
      <geometry>
        <box size="0.007 0.41 0.008" />
        </geometry>
      </collision>
    <collision name="tray_grid_long_2">
      <origin xyz="0 0 0.01" rpy="0 0 0" />
      <geometry>
        <box size="0.007 0.41 0.008" />
        </geometry>
      </collision>
    <collision name="tray_grid_long_3">
      <origin xyz="0.08 0 0.01" rpy="0 0 0" />
      <geometry>
        <box size="0.007 0.41 0.008" />
        </geometry>
      </collision>
    <collision name="tray_grid_long_4">
      <origin xyz="0.16 0 0.01" rpy="0 0 0" />
      <geometry>
        <box size="0.007 0.41 0.008" />
        </geometry>
      </collision>
    <collision name="tray_tine_0">
      <origin xyz="-0.16 -0.08 0.052" rpy="0 0 0" />
      <geometry>
        <box size="0.007 0.007 0.085" />
        </geometry>
      </collision>
    <collision name="tray_tine_1">
      <origin xyz="-0.08 -0.08 0.052" rpy="0 0 0" />
      <geometry>
        <box size="0.007 0.007 0.085" />
        </geometry>
      </collision>
    <collision name="tray_tine_2">
      <origin xyz="0 -0.08 0.052" rpy="0 0 0" />
      <geometry>
        <box size="0.007 0.007 0.085" />
        </geometry>
      </collision>
    <collision name="tray_tine_3">
      <origin xyz="0.08 -0.08 0.052" rpy="0 0 0" />
      <geometry>
        <box size="0.007 0.007 0.085" />
        </geometry>
      </collision>
    <collision name="tray_tine_4">
      <origin xyz="0.16 -0.08 0.052" rpy="0 0 0" />
      <geometry>
        <box size="0.007 0.007 0.085" />
        </geometry>
      </collision>
    <collision name="tray_tine_5">
      <origin xyz="-0.16 0.08 0.052" rpy="0 0 0" />
      <geometry>
        <box size="0.007 0.007 0.085" />
        </geometry>
      </collision>
    <collision name="tray_tine_6">
      <origin xyz="-0.08 0.08 0.052" rpy="0 0 0" />
      <geometry>
        <box size="0.007 0.007 0.085" />
        </geometry>
      </collision>
    <collision name="tray_tine_7">
      <origin xyz="0 0.08 0.052" rpy="0 0 0" />
      <geometry>
        <box size="0.007 0.007 0.085" />
        </geometry>
      </collision>
    <collision name="tray_tine_8">
      <origin xyz="0.08 0.08 0.052" rpy="0 0 0" />
      <geometry>
        <box size="0.007 0.007 0.085" />
        </geometry>
      </collision>
    <collision name="tray_tine_9">
      <origin xyz="0.16 0.08 0.052" rpy="0 0 0" />
      <geometry>
        <box size="0.007 0.007 0.085" />
        </geometry>
      </collision>
    <collision name="tray_tine_10">
      <origin xyz="-0.08 0.16 0.052" rpy="0 0 0" />
      <geometry>
        <box size="0.007 0.007 0.085" />
        </geometry>
      </collision>
    <collision name="tray_tine_11">
      <origin xyz="0.08 0.16 0.052" rpy="0 0 0" />
      <geometry>
        <box size="0.007 0.007 0.085" />
        </geometry>
      </collision>
    <collision name="divider_0">
      <origin xyz="-0.14 0 0.031" rpy="0 0 0" />
      <geometry>
        <box size="0.006 0.36 0.05" />
        </geometry>
      </collision>
    <collision name="divider_1">
      <origin xyz="-0.07 0 0.031" rpy="0 0 0" />
      <geometry>
        <box size="0.006 0.36 0.05" />
        </geometry>
      </collision>
    <collision name="divider_2">
      <origin xyz="0 0 0.031" rpy="0 0 0" />
      <geometry>
        <box size="0.006 0.36 0.05" />
        </geometry>
      </collision>
    <collision name="divider_3">
      <origin xyz="0.07 0 0.031" rpy="0 0 0" />
      <geometry>
        <box size="0.006 0.36 0.05" />
        </geometry>
      </collision>
    <collision name="divider_4">
      <origin xyz="0.14 0 0.031" rpy="0 0 0" />
      <geometry>
        <box size="0.006 0.36 0.05" />
        </geometry>
      </collision>
    </link>
  <link name="lower_spray_arm">
    <visual name="lower_spray_hub">
      <geometry>
        <cylinder radius="0.035" length="0.038" />
        </geometry>
      <material name="light_gray_plastic">
        <color rgba="0.72 0.74 0.74 1" />
        </material>
      </visual>
    <visual name="lower_spray_arm_long">
      <geometry>
        <box size="0.46 0.034 0.012" />
        </geometry>
      <material name="light_gray_plastic">
        <color rgba="0.72 0.74 0.74 1" />
        </material>
      </visual>
    <visual name="lower_spray_arm_short">
      <origin xyz="0 0 0.002" rpy="0 0 0" />
      <geometry>
        <box size="0.034 0.23 0.01" />
        </geometry>
      <material name="light_gray_plastic">
        <color rgba="0.72 0.74 0.74 1" />
        </material>
      </visual>
    <visual name="lower_spray_nozzle_0">
      <origin xyz="-0.16 0 0.006" rpy="0 0 0" />
      <geometry>
        <box size="0.024 0.006 0.004" />
        </geometry>
      <material name="black_glass">
        <color rgba="0.01 0.012 0.014 1" />
        </material>
      </visual>
    <visual name="lower_spray_nozzle_1">
      <origin xyz="-0.07 0 0.006" rpy="0 0 0" />
      <geometry>
        <box size="0.024 0.006 0.004" />
        </geometry>
      <material name="black_glass">
        <color rgba="0.01 0.012 0.014 1" />
        </material>
      </visual>
    <visual name="lower_spray_nozzle_2">
      <origin xyz="0.08 0 0.006" rpy="0 0 0" />
      <geometry>
        <box size="0.024 0.006 0.004" />
        </geometry>
      <material name="black_glass">
        <color rgba="0.01 0.012 0.014 1" />
        </material>
      </visual>
    <visual name="lower_spray_nozzle_3">
      <origin xyz="0.18 0 0.006" rpy="0 0 0" />
      <geometry>
        <box size="0.024 0.006 0.004" />
        </geometry>
      <material name="black_glass">
        <color rgba="0.01 0.012 0.014 1" />
        </material>
      </visual>
    <visual name="lower_spray_nozzle_4">
      <origin xyz="0 -0.08 0.006" rpy="0 0 0" />
      <geometry>
        <box size="0.024 0.006 0.004" />
        </geometry>
      <material name="black_glass">
        <color rgba="0.01 0.012 0.014 1" />
        </material>
      </visual>
    <visual name="lower_spray_nozzle_5">
      <origin xyz="0 0.08 0.006" rpy="0 0 0" />
      <geometry>
        <box size="0.024 0.006 0.004" />
        </geometry>
      <material name="black_glass">
        <color rgba="0.01 0.012 0.014 1" />
        </material>
      </visual>
    <collision name="lower_spray_hub">
      <geometry>
        <cylinder radius="0.035" length="0.038" />
        </geometry>
      </collision>
    <collision name="lower_spray_arm_long">
      <geometry>
        <box size="0.46 0.034 0.012" />
        </geometry>
      </collision>
    <collision name="lower_spray_arm_short">
      <origin xyz="0 0 0.002" rpy="0 0 0" />
      <geometry>
        <box size="0.034 0.23 0.01" />
        </geometry>
      </collision>
    <collision name="lower_spray_nozzle_0">
      <origin xyz="-0.16 0 0.006" rpy="0 0 0" />
      <geometry>
        <box size="0.024 0.006 0.004" />
        </geometry>
      </collision>
    <collision name="lower_spray_nozzle_1">
      <origin xyz="-0.07 0 0.006" rpy="0 0 0" />
      <geometry>
        <box size="0.024 0.006 0.004" />
        </geometry>
      </collision>
    <collision name="lower_spray_nozzle_2">
      <origin xyz="0.08 0 0.006" rpy="0 0 0" />
      <geometry>
        <box size="0.024 0.006 0.004" />
        </geometry>
      </collision>
    <collision name="lower_spray_nozzle_3">
      <origin xyz="0.18 0 0.006" rpy="0 0 0" />
      <geometry>
        <box size="0.024 0.006 0.004" />
        </geometry>
      </collision>
    <collision name="lower_spray_nozzle_4">
      <origin xyz="0 -0.08 0.006" rpy="0 0 0" />
      <geometry>
        <box size="0.024 0.006 0.004" />
        </geometry>
      </collision>
    <collision name="lower_spray_nozzle_5">
      <origin xyz="0 0.08 0.006" rpy="0 0 0" />
      <geometry>
        <box size="0.024 0.006 0.004" />
        </geometry>
      </collision>
    </link>
  <link name="upper_spray_arm">
    <visual name="upper_spray_hub">
      <geometry>
        <cylinder radius="0.035" length="0.038" />
        </geometry>
      <material name="light_gray_plastic">
        <color rgba="0.72 0.74 0.74 1" />
        </material>
      </visual>
    <visual name="upper_spray_arm_long">
      <geometry>
        <box size="0.46 0.034 0.012" />
        </geometry>
      <material name="light_gray_plastic">
        <color rgba="0.72 0.74 0.74 1" />
        </material>
      </visual>
    <visual name="upper_spray_arm_short">
      <origin xyz="0 0 0.002" rpy="0 0 0" />
      <geometry>
        <box size="0.034 0.23 0.01" />
        </geometry>
      <material name="light_gray_plastic">
        <color rgba="0.72 0.74 0.74 1" />
        </material>
      </visual>
    <visual name="upper_spray_nozzle_0">
      <origin xyz="-0.16 0 0.006" rpy="0 0 0" />
      <geometry>
        <box size="0.024 0.006 0.004" />
        </geometry>
      <material name="black_glass">
        <color rgba="0.01 0.012 0.014 1" />
        </material>
      </visual>
    <visual name="upper_spray_nozzle_1">
      <origin xyz="-0.07 0 0.006" rpy="0 0 0" />
      <geometry>
        <box size="0.024 0.006 0.004" />
        </geometry>
      <material name="black_glass">
        <color rgba="0.01 0.012 0.014 1" />
        </material>
      </visual>
    <visual name="upper_spray_nozzle_2">
      <origin xyz="0.08 0 0.006" rpy="0 0 0" />
      <geometry>
        <box size="0.024 0.006 0.004" />
        </geometry>
      <material name="black_glass">
        <color rgba="0.01 0.012 0.014 1" />
        </material>
      </visual>
    <visual name="upper_spray_nozzle_3">
      <origin xyz="0.18 0 0.006" rpy="0 0 0" />
      <geometry>
        <box size="0.024 0.006 0.004" />
        </geometry>
      <material name="black_glass">
        <color rgba="0.01 0.012 0.014 1" />
        </material>
      </visual>
    <visual name="upper_spray_nozzle_4">
      <origin xyz="0 -0.08 0.006" rpy="0 0 0" />
      <geometry>
        <box size="0.024 0.006 0.004" />
        </geometry>
      <material name="black_glass">
        <color rgba="0.01 0.012 0.014 1" />
        </material>
      </visual>
    <visual name="upper_spray_nozzle_5">
      <origin xyz="0 0.08 0.006" rpy="0 0 0" />
      <geometry>
        <box size="0.024 0.006 0.004" />
        </geometry>
      <material name="black_glass">
        <color rgba="0.01 0.012 0.014 1" />
        </material>
      </visual>
    <collision name="upper_spray_hub">
      <geometry>
        <cylinder radius="0.035" length="0.038" />
        </geometry>
      </collision>
    <collision name="upper_spray_arm_long">
      <geometry>
        <box size="0.46 0.034 0.012" />
        </geometry>
      </collision>
    <collision name="upper_spray_arm_short">
      <origin xyz="0 0 0.002" rpy="0 0 0" />
      <geometry>
        <box size="0.034 0.23 0.01" />
        </geometry>
      </collision>
    <collision name="upper_spray_nozzle_0">
      <origin xyz="-0.16 0 0.006" rpy="0 0 0" />
      <geometry>
        <box size="0.024 0.006 0.004" />
        </geometry>
      </collision>
    <collision name="upper_spray_nozzle_1">
      <origin xyz="-0.07 0 0.006" rpy="0 0 0" />
      <geometry>
        <box size="0.024 0.006 0.004" />
        </geometry>
      </collision>
    <collision name="upper_spray_nozzle_2">
      <origin xyz="0.08 0 0.006" rpy="0 0 0" />
      <geometry>
        <box size="0.024 0.006 0.004" />
        </geometry>
      </collision>
    <collision name="upper_spray_nozzle_3">
      <origin xyz="0.18 0 0.006" rpy="0 0 0" />
      <geometry>
        <box size="0.024 0.006 0.004" />
        </geometry>
      </collision>
    <collision name="upper_spray_nozzle_4">
      <origin xyz="0 -0.08 0.006" rpy="0 0 0" />
      <geometry>
        <box size="0.024 0.006 0.004" />
        </geometry>
      </collision>
    <collision name="upper_spray_nozzle_5">
      <origin xyz="0 0.08 0.006" rpy="0 0 0" />
      <geometry>
        <box size="0.024 0.006 0.004" />
        </geometry>
      </collision>
    </link>
  <link name="dial">
    <visual name="dial_cap">
      <geometry>
        <mesh filename="assets/meshes/cycle_dial.obj" />
        </geometry>
      <material name="light_gray_plastic">
        <color rgba="0.72 0.74 0.74 1" />
        </material>
      </visual>
    <visual name="dial_pointer">
      <origin xyz="0 0.014 -0.0085" rpy="0 0 0" />
      <geometry>
        <box size="0.006 0.028 0.003" />
        </geometry>
      <material name="white_marking">
        <color rgba="0.92 0.94 0.92 1" />
        </material>
      </visual>
    <collision name="dial_cap">
      <geometry>
        <mesh filename="assets/meshes/cycle_dial.obj" />
        </geometry>
      </collision>
    <collision name="dial_pointer">
      <origin xyz="0 0.014 -0.0085" rpy="0 0 0" />
      <geometry>
        <box size="0.006 0.028 0.003" />
        </geometry>
      </collision>
    </link>
  <link name="option_button_0">
    <visual name="button_cap">
      <geometry>
        <box size="0.046 0.026 0.012" />
        </geometry>
      <material name="light_gray_plastic">
        <color rgba="0.72 0.74 0.74 1" />
        </material>
      </visual>
    <visual name="button_label">
      <origin xyz="0 0 -0.0058" rpy="0 0 0" />
      <geometry>
        <box size="0.024 0.003 0.0015" />
        </geometry>
      <material name="white_marking">
        <color rgba="0.92 0.94 0.92 1" />
        </material>
      </visual>
    <collision name="button_cap">
      <geometry>
        <box size="0.046 0.026 0.012" />
        </geometry>
      </collision>
    <collision name="button_label">
      <origin xyz="0 0 -0.0058" rpy="0 0 0" />
      <geometry>
        <box size="0.024 0.003 0.0015" />
        </geometry>
      </collision>
    </link>
  <link name="option_button_1">
    <visual name="button_cap">
      <geometry>
        <box size="0.046 0.026 0.012" />
        </geometry>
      <material name="light_gray_plastic">
        <color rgba="0.72 0.74 0.74 1" />
        </material>
      </visual>
    <visual name="button_label">
      <origin xyz="0 0 -0.0058" rpy="0 0 0" />
      <geometry>
        <box size="0.024 0.003 0.0015" />
        </geometry>
      <material name="white_marking">
        <color rgba="0.92 0.94 0.92 1" />
        </material>
      </visual>
    <collision name="button_cap">
      <geometry>
        <box size="0.046 0.026 0.012" />
        </geometry>
      </collision>
    <collision name="button_label">
      <origin xyz="0 0 -0.0058" rpy="0 0 0" />
      <geometry>
        <box size="0.024 0.003 0.0015" />
        </geometry>
      </collision>
    </link>
  <link name="option_button_2">
    <visual name="button_cap">
      <geometry>
        <box size="0.046 0.026 0.012" />
        </geometry>
      <material name="light_gray_plastic">
        <color rgba="0.72 0.74 0.74 1" />
        </material>
      </visual>
    <visual name="button_label">
      <origin xyz="0 0 -0.0058" rpy="0 0 0" />
      <geometry>
        <box size="0.024 0.003 0.0015" />
        </geometry>
      <material name="white_marking">
        <color rgba="0.92 0.94 0.92 1" />
        </material>
      </visual>
    <collision name="button_cap">
      <geometry>
        <box size="0.046 0.026 0.012" />
        </geometry>
      </collision>
    <collision name="button_label">
      <origin xyz="0 0 -0.0058" rpy="0 0 0" />
      <geometry>
        <box size="0.024 0.003 0.0015" />
        </geometry>
      </collision>
    </link>
  <link name="option_button_3">
    <visual name="button_cap">
      <geometry>
        <box size="0.046 0.026 0.012" />
        </geometry>
      <material name="light_gray_plastic">
        <color rgba="0.72 0.74 0.74 1" />
        </material>
      </visual>
    <visual name="button_label">
      <origin xyz="0 0 -0.0058" rpy="0 0 0" />
      <geometry>
        <box size="0.024 0.003 0.0015" />
        </geometry>
      <material name="white_marking">
        <color rgba="0.92 0.94 0.92 1" />
        </material>
      </visual>
    <collision name="button_cap">
      <geometry>
        <box size="0.046 0.026 0.012" />
        </geometry>
      </collision>
    <collision name="button_label">
      <origin xyz="0 0 -0.0058" rpy="0 0 0" />
      <geometry>
        <box size="0.024 0.003 0.0015" />
        </geometry>
      </collision>
    </link>
  <link name="option_button_4">
    <visual name="button_cap">
      <geometry>
        <box size="0.046 0.026 0.012" />
        </geometry>
      <material name="light_gray_plastic">
        <color rgba="0.72 0.74 0.74 1" />
        </material>
      </visual>
    <visual name="button_label">
      <origin xyz="0 0 -0.0058" rpy="0 0 0" />
      <geometry>
        <box size="0.024 0.003 0.0015" />
        </geometry>
      <material name="white_marking">
        <color rgba="0.92 0.94 0.92 1" />
        </material>
      </visual>
    <collision name="button_cap">
      <geometry>
        <box size="0.046 0.026 0.012" />
        </geometry>
      </collision>
    <collision name="button_label">
      <origin xyz="0 0 -0.0058" rpy="0 0 0" />
      <geometry>
        <box size="0.024 0.003 0.0015" />
        </geometry>
      </collision>
    </link>
  <link name="option_button_5">
    <visual name="button_cap">
      <geometry>
        <box size="0.046 0.026 0.012" />
        </geometry>
      <material name="light_gray_plastic">
        <color rgba="0.72 0.74 0.74 1" />
        </material>
      </visual>
    <visual name="button_label">
      <origin xyz="0 0 -0.0058" rpy="0 0 0" />
      <geometry>
        <box size="0.024 0.003 0.0015" />
        </geometry>
      <material name="white_marking">
        <color rgba="0.92 0.94 0.92 1" />
        </material>
      </visual>
    <collision name="button_cap">
      <geometry>
        <box size="0.046 0.026 0.012" />
        </geometry>
      </collision>
    <collision name="button_label">
      <origin xyz="0 0 -0.0058" rpy="0 0 0" />
      <geometry>
        <box size="0.024 0.003 0.0015" />
        </geometry>
      </collision>
    </link>
  <link name="rinse_cap">
    <visual name="cap_disk">
      <origin xyz="0 0 0.005" rpy="0 0 0" />
      <geometry>
        <cylinder radius="0.036" length="0.01" />
        </geometry>
      <material name="translucent_blue_cap">
        <color rgba="0.08 0.22 0.55 1" />
        </material>
      </visual>
    <visual name="cap_grip">
      <origin xyz="0 0 0.013" rpy="0 0 0" />
      <geometry>
        <box size="0.014 0.054 0.006" />
        </geometry>
      <material name="light_gray_plastic">
        <color rgba="0.72 0.74 0.74 1" />
        </material>
      </visual>
    <collision name="cap_disk">
      <origin xyz="0 0 0.005" rpy="0 0 0" />
      <geometry>
        <cylinder radius="0.036" length="0.01" />
        </geometry>
      </collision>
    <collision name="cap_grip">
      <origin xyz="0 0 0.013" rpy="0 0 0" />
      <geometry>
        <box size="0.014 0.054 0.006" />
        </geometry>
      </collision>
    </link>
  <joint name="tub_to_door" type="revolute">
    <origin xyz="0 -0.305 0.07" rpy="0 0 0" />
    <parent link="tub" />
    <child link="door" />
    <axis xyz="-1 0 0" />
    <limit effort="120" velocity="1" lower="0" upper="1.45" />
    </joint>
  <joint name="tub_to_lower_rack" type="prismatic">
    <origin xyz="0 -0.005 0.235" rpy="0 0 0" />
    <parent link="tub" />
    <child link="lower_rack" />
    <axis xyz="0 -1 0" />
    <limit effort="80" velocity="0.35" lower="0" upper="0.43" />
    </joint>
  <joint name="tub_to_upper_rack" type="prismatic">
    <origin xyz="0 -0.005 0.5" rpy="0 0 0" />
    <parent link="tub" />
    <child link="upper_rack" />
    <axis xyz="0 -1 0" />
    <limit effort="65" velocity="0.35" lower="0" upper="0.4" />
    </joint>
  <joint name="tub_to_utensil_tray" type="prismatic">
    <origin xyz="0 -0.005 0.67" rpy="0 0 0" />
    <parent link="tub" />
    <child link="utensil_tray" />
    <axis xyz="0 -1 0" />
    <limit effort="40" velocity="0.3" lower="0" upper="0.36" />
    </joint>
  <joint name="tub_to_lower_spray_arm" type="continuous">
    <origin xyz="0 0.02 0.155" rpy="0 0 0" />
    <parent link="tub" />
    <child link="lower_spray_arm" />
    <axis xyz="0 0 1" />
    <limit effort="2" velocity="8" />
    </joint>
  <joint name="tub_to_upper_spray_arm" type="continuous">
    <origin xyz="0 0.02 0.44" rpy="0 0 0" />
    <parent link="tub" />
    <child link="upper_spray_arm" />
    <axis xyz="0 0 1" />
    <limit effort="2" velocity="8" />
    </joint>
  <joint name="door_to_dial" type="continuous">
    <origin xyz="0 -0.705 -0.0415" rpy="0 0 0" />
    <parent link="door" />
    <child link="dial" />
    <axis xyz="0 0 -1" />
    <limit effort="0.5" velocity="6" />
    </joint>
  <joint name="door_to_option_button_0" type="prismatic">
    <origin xyz="-0.225 -0.705 -0.0385" rpy="0 0 0" />
    <parent link="door" />
    <child link="option_button_0" />
    <axis xyz="0 0 1" />
    <limit effort="1" velocity="0.08" lower="0" upper="0.006" />
    </joint>
  <joint name="door_to_option_button_1" type="prismatic">
    <origin xyz="-0.165 -0.705 -0.0385" rpy="0 0 0" />
    <parent link="door" />
    <child link="option_button_1" />
    <axis xyz="0 0 1" />
    <limit effort="1" velocity="0.08" lower="0" upper="0.006" />
    </joint>
  <joint name="door_to_option_button_2" type="prismatic">
    <origin xyz="-0.105 -0.705 -0.0385" rpy="0 0 0" />
    <parent link="door" />
    <child link="option_button_2" />
    <axis xyz="0 0 1" />
    <limit effort="1" velocity="0.08" lower="0" upper="0.006" />
    </joint>
  <joint name="door_to_option_button_3" type="prismatic">
    <origin xyz="0.105 -0.705 -0.0385" rpy="0 0 0" />
    <parent link="door" />
    <child link="option_button_3" />
    <axis xyz="0 0 1" />
    <limit effort="1" velocity="0.08" lower="0" upper="0.006" />
    </joint>
  <joint name="door_to_option_button_4" type="prismatic">
    <origin xyz="0.165 -0.705 -0.0385" rpy="0 0 0" />
    <parent link="door" />
    <child link="option_button_4" />
    <axis xyz="0 0 1" />
    <limit effort="1" velocity="0.08" lower="0" upper="0.006" />
    </joint>
  <joint name="door_to_option_button_5" type="prismatic">
    <origin xyz="0.225 -0.705 -0.0385" rpy="0 0 0" />
    <parent link="door" />
    <child link="option_button_5" />
    <axis xyz="0 0 1" />
    <limit effort="1" velocity="0.08" lower="0" upper="0.006" />
    </joint>
  <joint name="door_to_rinse_cap" type="continuous">
    <origin xyz="-0.135 -0.285 0.034" rpy="0 0 0" />
    <parent link="door" />
    <child link="rinse_cap" />
    <axis xyz="0 0 1" />
    <limit effort="0.4" velocity="4" />
    </joint>
  </robot>
