<robot name="cafe_shutter_set">
  <link name="window_frame">
    <visual name="jamb_0">
      <origin xyz="-0.64 0 0.85" rpy="0 0 0" />
      <geometry>
        <box size="0.08 0.12 1.7" />
        </geometry>
      <material name="warm painted wood">
        <color rgba="0.86 0.82 0.72 1" />
        </material>
      </visual>
    <visual name="jamb_1">
      <origin xyz="0.64 0 0.85" rpy="0 0 0" />
      <geometry>
        <box size="0.08 0.12 1.7" />
        </geometry>
      <material name="warm painted wood">
        <color rgba="0.86 0.82 0.72 1" />
        </material>
      </visual>
    <visual name="head_rail">
      <origin xyz="0 0 1.658" rpy="0 0 0" />
      <geometry>
        <box size="1.36 0.12 0.085" />
        </geometry>
      <material name="warm painted wood">
        <color rgba="0.86 0.82 0.72 1" />
        </material>
      </visual>
    <visual name="sill">
      <origin xyz="0 0 0.208" rpy="0 0 0" />
      <geometry>
        <box size="1.36 0.14 0.085" />
        </geometry>
      <material name="warm painted wood">
        <color rgba="0.86 0.82 0.72 1" />
        </material>
      </visual>
    <visual name="cafe_stop">
      <origin xyz="0 0.055 1.265" rpy="0 0 0" />
      <geometry>
        <box size="1.24 0.032 0.032" />
        </geometry>
      <material name="exposed end grain">
        <color rgba="0.72 0.6 0.43 1" />
        </material>
      </visual>
    <visual name="opening_shadow">
      <origin xyz="0 0.06 0.755" rpy="0 0 0" />
      <geometry>
        <box size="1.24 0.02 0.9" />
        </geometry>
      <material name="dark louver gaps">
        <color rgba="0.12 0.1 0.08 1" />
        </material>
      </visual>
    <collision name="jamb_0">
      <origin xyz="-0.64 0 0.85" rpy="0 0 0" />
      <geometry>
        <box size="0.08 0.12 1.7" />
        </geometry>
      </collision>
    <collision name="jamb_1">
      <origin xyz="0.64 0 0.85" rpy="0 0 0" />
      <geometry>
        <box size="0.08 0.12 1.7" />
        </geometry>
      </collision>
    <collision name="head_rail">
      <origin xyz="0 0 1.658" rpy="0 0 0" />
      <geometry>
        <box size="1.36 0.12 0.085" />
        </geometry>
      </collision>
    <collision name="sill">
      <origin xyz="0 0 0.208" rpy="0 0 0" />
      <geometry>
        <box size="1.36 0.14 0.085" />
        </geometry>
      </collision>
    <collision name="cafe_stop">
      <origin xyz="0 0.055 1.265" rpy="0 0 0" />
      <geometry>
        <box size="1.24 0.032 0.032" />
        </geometry>
      </collision>
    <collision name="opening_shadow">
      <origin xyz="0 0.06 0.755" rpy="0 0 0" />
      <geometry>
        <box size="1.24 0.02 0.9" />
        </geometry>
      </collision>
    </link>
  <link name="leaf_0">
    <visual name="outer_stile">
      <origin xyz="0.0275 0 0" rpy="0 0 0" />
      <geometry>
        <box size="0.055 0.06 1" />
        </geometry>
      <material name="warm painted wood">
        <color rgba="0.86 0.82 0.72 1" />
        </material>
      </visual>
    <visual name="inner_stile">
      <origin xyz="0.5325 0 0" rpy="0 0 0" />
      <geometry>
        <box size="0.055 0.06 1" />
        </geometry>
      <material name="warm painted wood">
        <color rgba="0.86 0.82 0.72 1" />
        </material>
      </visual>
    <visual name="top_rail">
      <origin xyz="0.28 0 0.46" rpy="0 0 0" />
      <geometry>
        <box size="0.56 0.06 0.08" />
        </geometry>
      <material name="warm painted wood">
        <color rgba="0.86 0.82 0.72 1" />
        </material>
      </visual>
    <visual name="bottom_rail">
      <origin xyz="0.28 0 -0.46" rpy="0 0 0" />
      <geometry>
        <box size="0.56 0.06 0.08" />
        </geometry>
      <material name="warm painted wood">
        <color rgba="0.86 0.82 0.72 1" />
        </material>
      </visual>
    <visual name="hinge_barrel_0">
      <origin xyz="-0.002 -0.055 -0.28" rpy="0 0 0" />
      <geometry>
        <cylinder radius="0.012" length="0.21" />
        </geometry>
      <material name="aged brass">
        <color rgba="0.82 0.62 0.28 1" />
        </material>
      </visual>
    <visual name="hinge_leaf_0">
      <origin xyz="0.012 -0.04 -0.28" rpy="0 0 0" />
      <geometry>
        <box size="0.052 0.026 0.17" />
        </geometry>
      <material name="aged brass">
        <color rgba="0.82 0.62 0.28 1" />
        </material>
      </visual>
    <visual name="hinge_barrel_1">
      <origin xyz="-0.002 -0.055 0.28" rpy="0 0 0" />
      <geometry>
        <cylinder radius="0.012" length="0.21" />
        </geometry>
      <material name="aged brass">
        <color rgba="0.82 0.62 0.28 1" />
        </material>
      </visual>
    <visual name="hinge_leaf_1">
      <origin xyz="0.012 -0.04 0.28" rpy="0 0 0" />
      <geometry>
        <box size="0.052 0.026 0.17" />
        </geometry>
      <material name="aged brass">
        <color rgba="0.82 0.62 0.28 1" />
        </material>
      </visual>
    <collision name="outer_stile">
      <origin xyz="0.0275 0 0" rpy="0 0 0" />
      <geometry>
        <box size="0.055 0.06 1" />
        </geometry>
      </collision>
    <collision name="inner_stile">
      <origin xyz="0.5325 0 0" rpy="0 0 0" />
      <geometry>
        <box size="0.055 0.06 1" />
        </geometry>
      </collision>
    <collision name="top_rail">
      <origin xyz="0.28 0 0.46" rpy="0 0 0" />
      <geometry>
        <box size="0.56 0.06 0.08" />
        </geometry>
      </collision>
    <collision name="bottom_rail">
      <origin xyz="0.28 0 -0.46" rpy="0 0 0" />
      <geometry>
        <box size="0.56 0.06 0.08" />
        </geometry>
      </collision>
    <collision name="hinge_barrel_0">
      <origin xyz="-0.002 -0.055 -0.28" rpy="0 0 0" />
      <geometry>
        <cylinder radius="0.012" length="0.21" />
        </geometry>
      </collision>
    <collision name="hinge_leaf_0">
      <origin xyz="0.012 -0.04 -0.28" rpy="0 0 0" />
      <geometry>
        <box size="0.052 0.026 0.17" />
        </geometry>
      </collision>
    <collision name="hinge_barrel_1">
      <origin xyz="-0.002 -0.055 0.28" rpy="0 0 0" />
      <geometry>
        <cylinder radius="0.012" length="0.21" />
        </geometry>
      </collision>
    <collision name="hinge_leaf_1">
      <origin xyz="0.012 -0.04 0.28" rpy="0 0 0" />
      <geometry>
        <box size="0.052 0.026 0.17" />
        </geometry>
      </collision>
    </link>
  <link name="tilt_rod_0">
    <visual name="rod_bar">
      <origin xyz="0.28 -0.082 0" rpy="0 0 0" />
      <geometry>
        <box size="0.018 0.014 0.735" />
        </geometry>
      <material name="aged brass">
        <color rgba="0.82 0.62 0.28 1" />
        </material>
      </visual>
    <visual name="link_tab_0">
      <origin xyz="0.28 -0.053 -0.315" rpy="0 0 0" />
      <geometry>
        <box size="0.036 0.044 0.02" />
        </geometry>
      <material name="aged brass">
        <color rgba="0.82 0.62 0.28 1" />
        </material>
      </visual>
    <visual name="link_tab_1">
      <origin xyz="0.28 -0.053 -0.195" rpy="0 0 0" />
      <geometry>
        <box size="0.036 0.044 0.02" />
        </geometry>
      <material name="aged brass">
        <color rgba="0.82 0.62 0.28 1" />
        </material>
      </visual>
    <visual name="link_tab_2">
      <origin xyz="0.28 -0.053 -0.075" rpy="0 0 0" />
      <geometry>
        <box size="0.036 0.044 0.02" />
        </geometry>
      <material name="aged brass">
        <color rgba="0.82 0.62 0.28 1" />
        </material>
      </visual>
    <visual name="link_tab_3">
      <origin xyz="0.28 -0.053 0.045" rpy="0 0 0" />
      <geometry>
        <box size="0.036 0.044 0.02" />
        </geometry>
      <material name="aged brass">
        <color rgba="0.82 0.62 0.28 1" />
        </material>
      </visual>
    <visual name="link_tab_4">
      <origin xyz="0.28 -0.053 0.165" rpy="0 0 0" />
      <geometry>
        <box size="0.036 0.044 0.02" />
        </geometry>
      <material name="aged brass">
        <color rgba="0.82 0.62 0.28 1" />
        </material>
      </visual>
    <visual name="link_tab_5">
      <origin xyz="0.28 -0.053 0.285" rpy="0 0 0" />
      <geometry>
        <box size="0.036 0.044 0.02" />
        </geometry>
      <material name="aged brass">
        <color rgba="0.82 0.62 0.28 1" />
        </material>
      </visual>
    <collision name="rod_bar">
      <origin xyz="0.28 -0.082 0" rpy="0 0 0" />
      <geometry>
        <box size="0.018 0.014 0.735" />
        </geometry>
      </collision>
    <collision name="link_tab_0">
      <origin xyz="0.28 -0.053 -0.315" rpy="0 0 0" />
      <geometry>
        <box size="0.036 0.044 0.02" />
        </geometry>
      </collision>
    <collision name="link_tab_1">
      <origin xyz="0.28 -0.053 -0.195" rpy="0 0 0" />
      <geometry>
        <box size="0.036 0.044 0.02" />
        </geometry>
      </collision>
    <collision name="link_tab_2">
      <origin xyz="0.28 -0.053 -0.075" rpy="0 0 0" />
      <geometry>
        <box size="0.036 0.044 0.02" />
        </geometry>
      </collision>
    <collision name="link_tab_3">
      <origin xyz="0.28 -0.053 0.045" rpy="0 0 0" />
      <geometry>
        <box size="0.036 0.044 0.02" />
        </geometry>
      </collision>
    <collision name="link_tab_4">
      <origin xyz="0.28 -0.053 0.165" rpy="0 0 0" />
      <geometry>
        <box size="0.036 0.044 0.02" />
        </geometry>
      </collision>
    <collision name="link_tab_5">
      <origin xyz="0.28 -0.053 0.285" rpy="0 0 0" />
      <geometry>
        <box size="0.036 0.044 0.02" />
        </geometry>
      </collision>
    </link>
  <link name="knob_0">
    <visual name="knob_cap">
      <origin xyz="0 0 0" rpy="1.5708 0 0" />
      <geometry>
        <cylinder radius="0.034" length="0.026" />
        </geometry>
      <material name="ivory knob">
        <color rgba="0.95 0.9 0.78 1" />
        </material>
      </visual>
    <visual name="knob_stem">
      <origin xyz="0 0.024 0" rpy="1.5708 0 0" />
      <geometry>
        <cylinder radius="0.007" length="0.024" />
        </geometry>
      <material name="aged brass">
        <color rgba="0.82 0.62 0.28 1" />
        </material>
      </visual>
    <visual name="grip_ridge">
      <origin xyz="0 -0.015 0.014" rpy="0 0 0" />
      <geometry>
        <box size="0.012 0.007 0.04" />
        </geometry>
      <material name="aged brass">
        <color rgba="0.82 0.62 0.28 1" />
        </material>
      </visual>
    <collision name="knob_cap">
      <origin xyz="0 0 0" rpy="1.5708 0 0" />
      <geometry>
        <cylinder radius="0.034" length="0.026" />
        </geometry>
      </collision>
    <collision name="knob_stem">
      <origin xyz="0 0.024 0" rpy="1.5708 0 0" />
      <geometry>
        <cylinder radius="0.007" length="0.024" />
        </geometry>
      </collision>
    <collision name="grip_ridge">
      <origin xyz="0 -0.015 0.014" rpy="0 0 0" />
      <geometry>
        <box size="0.012 0.007 0.04" />
        </geometry>
      </collision>
    </link>
  <link name="louver_0_0">
    <visual name="slat">
      <origin xyz="0 0 0" rpy="0.38 0 0" />
      <geometry>
        <box size="0.42 0.11 0.018" />
        </geometry>
      <material name="warm painted wood">
        <color rgba="0.86 0.82 0.72 1" />
        </material>
      </visual>
    <visual name="pin_0">
      <origin xyz="-0.235 0 0" rpy="0 1.5708 0" />
      <geometry>
        <cylinder radius="0.009" length="0.075" />
        </geometry>
      <material name="aged brass">
        <color rgba="0.82 0.62 0.28 1" />
        </material>
      </visual>
    <visual name="pin_1">
      <origin xyz="0.235 0 0" rpy="0 1.5708 0" />
      <geometry>
        <cylinder radius="0.009" length="0.075" />
        </geometry>
      <material name="aged brass">
        <color rgba="0.82 0.62 0.28 1" />
        </material>
      </visual>
    <collision name="slat">
      <origin xyz="0 0 0" rpy="0.38 0 0" />
      <geometry>
        <box size="0.42 0.11 0.018" />
        </geometry>
      </collision>
    <collision name="pin_0">
      <origin xyz="-0.235 0 0" rpy="0 1.5708 0" />
      <geometry>
        <cylinder radius="0.009" length="0.075" />
        </geometry>
      </collision>
    <collision name="pin_1">
      <origin xyz="0.235 0 0" rpy="0 1.5708 0" />
      <geometry>
        <cylinder radius="0.009" length="0.075" />
        </geometry>
      </collision>
    </link>
  <link name="louver_0_1">
    <visual name="slat">
      <origin xyz="0 0 0" rpy="0.38 0 0" />
      <geometry>
        <box size="0.42 0.11 0.018" />
        </geometry>
      <material name="warm painted wood">
        <color rgba="0.86 0.82 0.72 1" />
        </material>
      </visual>
    <visual name="pin_0">
      <origin xyz="-0.235 0 0" rpy="0 1.5708 0" />
      <geometry>
        <cylinder radius="0.009" length="0.075" />
        </geometry>
      <material name="aged brass">
        <color rgba="0.82 0.62 0.28 1" />
        </material>
      </visual>
    <visual name="pin_1">
      <origin xyz="0.235 0 0" rpy="0 1.5708 0" />
      <geometry>
        <cylinder radius="0.009" length="0.075" />
        </geometry>
      <material name="aged brass">
        <color rgba="0.82 0.62 0.28 1" />
        </material>
      </visual>
    <collision name="slat">
      <origin xyz="0 0 0" rpy="0.38 0 0" />
      <geometry>
        <box size="0.42 0.11 0.018" />
        </geometry>
      </collision>
    <collision name="pin_0">
      <origin xyz="-0.235 0 0" rpy="0 1.5708 0" />
      <geometry>
        <cylinder radius="0.009" length="0.075" />
        </geometry>
      </collision>
    <collision name="pin_1">
      <origin xyz="0.235 0 0" rpy="0 1.5708 0" />
      <geometry>
        <cylinder radius="0.009" length="0.075" />
        </geometry>
      </collision>
    </link>
  <link name="louver_0_2">
    <visual name="slat">
      <origin xyz="0 0 0" rpy="0.38 0 0" />
      <geometry>
        <box size="0.42 0.11 0.018" />
        </geometry>
      <material name="warm painted wood">
        <color rgba="0.86 0.82 0.72 1" />
        </material>
      </visual>
    <visual name="pin_0">
      <origin xyz="-0.235 0 0" rpy="0 1.5708 0" />
      <geometry>
        <cylinder radius="0.009" length="0.075" />
        </geometry>
      <material name="aged brass">
        <color rgba="0.82 0.62 0.28 1" />
        </material>
      </visual>
    <visual name="pin_1">
      <origin xyz="0.235 0 0" rpy="0 1.5708 0" />
      <geometry>
        <cylinder radius="0.009" length="0.075" />
        </geometry>
      <material name="aged brass">
        <color rgba="0.82 0.62 0.28 1" />
        </material>
      </visual>
    <collision name="slat">
      <origin xyz="0 0 0" rpy="0.38 0 0" />
      <geometry>
        <box size="0.42 0.11 0.018" />
        </geometry>
      </collision>
    <collision name="pin_0">
      <origin xyz="-0.235 0 0" rpy="0 1.5708 0" />
      <geometry>
        <cylinder radius="0.009" length="0.075" />
        </geometry>
      </collision>
    <collision name="pin_1">
      <origin xyz="0.235 0 0" rpy="0 1.5708 0" />
      <geometry>
        <cylinder radius="0.009" length="0.075" />
        </geometry>
      </collision>
    </link>
  <link name="louver_0_3">
    <visual name="slat">
      <origin xyz="0 0 0" rpy="0.38 0 0" />
      <geometry>
        <box size="0.42 0.11 0.018" />
        </geometry>
      <material name="warm painted wood">
        <color rgba="0.86 0.82 0.72 1" />
        </material>
      </visual>
    <visual name="pin_0">
      <origin xyz="-0.235 0 0" rpy="0 1.5708 0" />
      <geometry>
        <cylinder radius="0.009" length="0.075" />
        </geometry>
      <material name="aged brass">
        <color rgba="0.82 0.62 0.28 1" />
        </material>
      </visual>
    <visual name="pin_1">
      <origin xyz="0.235 0 0" rpy="0 1.5708 0" />
      <geometry>
        <cylinder radius="0.009" length="0.075" />
        </geometry>
      <material name="aged brass">
        <color rgba="0.82 0.62 0.28 1" />
        </material>
      </visual>
    <collision name="slat">
      <origin xyz="0 0 0" rpy="0.38 0 0" />
      <geometry>
        <box size="0.42 0.11 0.018" />
        </geometry>
      </collision>
    <collision name="pin_0">
      <origin xyz="-0.235 0 0" rpy="0 1.5708 0" />
      <geometry>
        <cylinder radius="0.009" length="0.075" />
        </geometry>
      </collision>
    <collision name="pin_1">
      <origin xyz="0.235 0 0" rpy="0 1.5708 0" />
      <geometry>
        <cylinder radius="0.009" length="0.075" />
        </geometry>
      </collision>
    </link>
  <link name="louver_0_4">
    <visual name="slat">
      <origin xyz="0 0 0" rpy="0.38 0 0" />
      <geometry>
        <box size="0.42 0.11 0.018" />
        </geometry>
      <material name="warm painted wood">
        <color rgba="0.86 0.82 0.72 1" />
        </material>
      </visual>
    <visual name="pin_0">
      <origin xyz="-0.235 0 0" rpy="0 1.5708 0" />
      <geometry>
        <cylinder radius="0.009" length="0.075" />
        </geometry>
      <material name="aged brass">
        <color rgba="0.82 0.62 0.28 1" />
        </material>
      </visual>
    <visual name="pin_1">
      <origin xyz="0.235 0 0" rpy="0 1.5708 0" />
      <geometry>
        <cylinder radius="0.009" length="0.075" />
        </geometry>
      <material name="aged brass">
        <color rgba="0.82 0.62 0.28 1" />
        </material>
      </visual>
    <collision name="slat">
      <origin xyz="0 0 0" rpy="0.38 0 0" />
      <geometry>
        <box size="0.42 0.11 0.018" />
        </geometry>
      </collision>
    <collision name="pin_0">
      <origin xyz="-0.235 0 0" rpy="0 1.5708 0" />
      <geometry>
        <cylinder radius="0.009" length="0.075" />
        </geometry>
      </collision>
    <collision name="pin_1">
      <origin xyz="0.235 0 0" rpy="0 1.5708 0" />
      <geometry>
        <cylinder radius="0.009" length="0.075" />
        </geometry>
      </collision>
    </link>
  <link name="louver_0_5">
    <visual name="slat">
      <origin xyz="0 0 0" rpy="0.38 0 0" />
      <geometry>
        <box size="0.42 0.11 0.018" />
        </geometry>
      <material name="warm painted wood">
        <color rgba="0.86 0.82 0.72 1" />
        </material>
      </visual>
    <visual name="pin_0">
      <origin xyz="-0.235 0 0" rpy="0 1.5708 0" />
      <geometry>
        <cylinder radius="0.009" length="0.075" />
        </geometry>
      <material name="aged brass">
        <color rgba="0.82 0.62 0.28 1" />
        </material>
      </visual>
    <visual name="pin_1">
      <origin xyz="0.235 0 0" rpy="0 1.5708 0" />
      <geometry>
        <cylinder radius="0.009" length="0.075" />
        </geometry>
      <material name="aged brass">
        <color rgba="0.82 0.62 0.28 1" />
        </material>
      </visual>
    <collision name="slat">
      <origin xyz="0 0 0" rpy="0.38 0 0" />
      <geometry>
        <box size="0.42 0.11 0.018" />
        </geometry>
      </collision>
    <collision name="pin_0">
      <origin xyz="-0.235 0 0" rpy="0 1.5708 0" />
      <geometry>
        <cylinder radius="0.009" length="0.075" />
        </geometry>
      </collision>
    <collision name="pin_1">
      <origin xyz="0.235 0 0" rpy="0 1.5708 0" />
      <geometry>
        <cylinder radius="0.009" length="0.075" />
        </geometry>
      </collision>
    </link>
  <link name="leaf_1">
    <visual name="outer_stile">
      <origin xyz="-0.0275 0 0" rpy="0 0 0" />
      <geometry>
        <box size="0.055 0.06 1" />
        </geometry>
      <material name="warm painted wood">
        <color rgba="0.86 0.82 0.72 1" />
        </material>
      </visual>
    <visual name="inner_stile">
      <origin xyz="-0.5325 0 0" rpy="0 0 0" />
      <geometry>
        <box size="0.055 0.06 1" />
        </geometry>
      <material name="warm painted wood">
        <color rgba="0.86 0.82 0.72 1" />
        </material>
      </visual>
    <visual name="top_rail">
      <origin xyz="-0.28 0 0.46" rpy="0 0 0" />
      <geometry>
        <box size="0.56 0.06 0.08" />
        </geometry>
      <material name="warm painted wood">
        <color rgba="0.86 0.82 0.72 1" />
        </material>
      </visual>
    <visual name="bottom_rail">
      <origin xyz="-0.28 0 -0.46" rpy="0 0 0" />
      <geometry>
        <box size="0.56 0.06 0.08" />
        </geometry>
      <material name="warm painted wood">
        <color rgba="0.86 0.82 0.72 1" />
        </material>
      </visual>
    <visual name="hinge_barrel_0">
      <origin xyz="0.002 -0.055 -0.28" rpy="0 0 0" />
      <geometry>
        <cylinder radius="0.012" length="0.21" />
        </geometry>
      <material name="aged brass">
        <color rgba="0.82 0.62 0.28 1" />
        </material>
      </visual>
    <visual name="hinge_leaf_0">
      <origin xyz="-0.012 -0.04 -0.28" rpy="0 0 0" />
      <geometry>
        <box size="0.052 0.026 0.17" />
        </geometry>
      <material name="aged brass">
        <color rgba="0.82 0.62 0.28 1" />
        </material>
      </visual>
    <visual name="hinge_barrel_1">
      <origin xyz="0.002 -0.055 0.28" rpy="0 0 0" />
      <geometry>
        <cylinder radius="0.012" length="0.21" />
        </geometry>
      <material name="aged brass">
        <color rgba="0.82 0.62 0.28 1" />
        </material>
      </visual>
    <visual name="hinge_leaf_1">
      <origin xyz="-0.012 -0.04 0.28" rpy="0 0 0" />
      <geometry>
        <box size="0.052 0.026 0.17" />
        </geometry>
      <material name="aged brass">
        <color rgba="0.82 0.62 0.28 1" />
        </material>
      </visual>
    <collision name="outer_stile">
      <origin xyz="-0.0275 0 0" rpy="0 0 0" />
      <geometry>
        <box size="0.055 0.06 1" />
        </geometry>
      </collision>
    <collision name="inner_stile">
      <origin xyz="-0.5325 0 0" rpy="0 0 0" />
      <geometry>
        <box size="0.055 0.06 1" />
        </geometry>
      </collision>
    <collision name="top_rail">
      <origin xyz="-0.28 0 0.46" rpy="0 0 0" />
      <geometry>
        <box size="0.56 0.06 0.08" />
        </geometry>
      </collision>
    <collision name="bottom_rail">
      <origin xyz="-0.28 0 -0.46" rpy="0 0 0" />
      <geometry>
        <box size="0.56 0.06 0.08" />
        </geometry>
      </collision>
    <collision name="hinge_barrel_0">
      <origin xyz="0.002 -0.055 -0.28" rpy="0 0 0" />
      <geometry>
        <cylinder radius="0.012" length="0.21" />
        </geometry>
      </collision>
    <collision name="hinge_leaf_0">
      <origin xyz="-0.012 -0.04 -0.28" rpy="0 0 0" />
      <geometry>
        <box size="0.052 0.026 0.17" />
        </geometry>
      </collision>
    <collision name="hinge_barrel_1">
      <origin xyz="0.002 -0.055 0.28" rpy="0 0 0" />
      <geometry>
        <cylinder radius="0.012" length="0.21" />
        </geometry>
      </collision>
    <collision name="hinge_leaf_1">
      <origin xyz="-0.012 -0.04 0.28" rpy="0 0 0" />
      <geometry>
        <box size="0.052 0.026 0.17" />
        </geometry>
      </collision>
    </link>
  <link name="tilt_rod_1">
    <visual name="rod_bar">
      <origin xyz="-0.28 -0.082 0" rpy="0 0 0" />
      <geometry>
        <box size="0.018 0.014 0.735" />
        </geometry>
      <material name="aged brass">
        <color rgba="0.82 0.62 0.28 1" />
        </material>
      </visual>
    <visual name="link_tab_0">
      <origin xyz="-0.28 -0.053 -0.315" rpy="0 0 0" />
      <geometry>
        <box size="0.036 0.044 0.02" />
        </geometry>
      <material name="aged brass">
        <color rgba="0.82 0.62 0.28 1" />
        </material>
      </visual>
    <visual name="link_tab_1">
      <origin xyz="-0.28 -0.053 -0.195" rpy="0 0 0" />
      <geometry>
        <box size="0.036 0.044 0.02" />
        </geometry>
      <material name="aged brass">
        <color rgba="0.82 0.62 0.28 1" />
        </material>
      </visual>
    <visual name="link_tab_2">
      <origin xyz="-0.28 -0.053 -0.075" rpy="0 0 0" />
      <geometry>
        <box size="0.036 0.044 0.02" />
        </geometry>
      <material name="aged brass">
        <color rgba="0.82 0.62 0.28 1" />
        </material>
      </visual>
    <visual name="link_tab_3">
      <origin xyz="-0.28 -0.053 0.045" rpy="0 0 0" />
      <geometry>
        <box size="0.036 0.044 0.02" />
        </geometry>
      <material name="aged brass">
        <color rgba="0.82 0.62 0.28 1" />
        </material>
      </visual>
    <visual name="link_tab_4">
      <origin xyz="-0.28 -0.053 0.165" rpy="0 0 0" />
      <geometry>
        <box size="0.036 0.044 0.02" />
        </geometry>
      <material name="aged brass">
        <color rgba="0.82 0.62 0.28 1" />
        </material>
      </visual>
    <visual name="link_tab_5">
      <origin xyz="-0.28 -0.053 0.285" rpy="0 0 0" />
      <geometry>
        <box size="0.036 0.044 0.02" />
        </geometry>
      <material name="aged brass">
        <color rgba="0.82 0.62 0.28 1" />
        </material>
      </visual>
    <collision name="rod_bar">
      <origin xyz="-0.28 -0.082 0" rpy="0 0 0" />
      <geometry>
        <box size="0.018 0.014 0.735" />
        </geometry>
      </collision>
    <collision name="link_tab_0">
      <origin xyz="-0.28 -0.053 -0.315" rpy="0 0 0" />
      <geometry>
        <box size="0.036 0.044 0.02" />
        </geometry>
      </collision>
    <collision name="link_tab_1">
      <origin xyz="-0.28 -0.053 -0.195" rpy="0 0 0" />
      <geometry>
        <box size="0.036 0.044 0.02" />
        </geometry>
      </collision>
    <collision name="link_tab_2">
      <origin xyz="-0.28 -0.053 -0.075" rpy="0 0 0" />
      <geometry>
        <box size="0.036 0.044 0.02" />
        </geometry>
      </collision>
    <collision name="link_tab_3">
      <origin xyz="-0.28 -0.053 0.045" rpy="0 0 0" />
      <geometry>
        <box size="0.036 0.044 0.02" />
        </geometry>
      </collision>
    <collision name="link_tab_4">
      <origin xyz="-0.28 -0.053 0.165" rpy="0 0 0" />
      <geometry>
        <box size="0.036 0.044 0.02" />
        </geometry>
      </collision>
    <collision name="link_tab_5">
      <origin xyz="-0.28 -0.053 0.285" rpy="0 0 0" />
      <geometry>
        <box size="0.036 0.044 0.02" />
        </geometry>
      </collision>
    </link>
  <link name="knob_1">
    <visual name="knob_cap">
      <origin xyz="0 0 0" rpy="1.5708 0 0" />
      <geometry>
        <cylinder radius="0.034" length="0.026" />
        </geometry>
      <material name="ivory knob">
        <color rgba="0.95 0.9 0.78 1" />
        </material>
      </visual>
    <visual name="knob_stem">
      <origin xyz="0 0.024 0" rpy="1.5708 0 0" />
      <geometry>
        <cylinder radius="0.007" length="0.024" />
        </geometry>
      <material name="aged brass">
        <color rgba="0.82 0.62 0.28 1" />
        </material>
      </visual>
    <visual name="grip_ridge">
      <origin xyz="0 -0.015 0.014" rpy="0 0 0" />
      <geometry>
        <box size="0.012 0.007 0.04" />
        </geometry>
      <material name="aged brass">
        <color rgba="0.82 0.62 0.28 1" />
        </material>
      </visual>
    <collision name="knob_cap">
      <origin xyz="0 0 0" rpy="1.5708 0 0" />
      <geometry>
        <cylinder radius="0.034" length="0.026" />
        </geometry>
      </collision>
    <collision name="knob_stem">
      <origin xyz="0 0.024 0" rpy="1.5708 0 0" />
      <geometry>
        <cylinder radius="0.007" length="0.024" />
        </geometry>
      </collision>
    <collision name="grip_ridge">
      <origin xyz="0 -0.015 0.014" rpy="0 0 0" />
      <geometry>
        <box size="0.012 0.007 0.04" />
        </geometry>
      </collision>
    </link>
  <link name="louver_1_0">
    <visual name="slat">
      <origin xyz="0 0 0" rpy="0.38 0 0" />
      <geometry>
        <box size="0.42 0.11 0.018" />
        </geometry>
      <material name="warm painted wood">
        <color rgba="0.86 0.82 0.72 1" />
        </material>
      </visual>
    <visual name="pin_0">
      <origin xyz="-0.235 0 0" rpy="0 1.5708 0" />
      <geometry>
        <cylinder radius="0.009" length="0.075" />
        </geometry>
      <material name="aged brass">
        <color rgba="0.82 0.62 0.28 1" />
        </material>
      </visual>
    <visual name="pin_1">
      <origin xyz="0.235 0 0" rpy="0 1.5708 0" />
      <geometry>
        <cylinder radius="0.009" length="0.075" />
        </geometry>
      <material name="aged brass">
        <color rgba="0.82 0.62 0.28 1" />
        </material>
      </visual>
    <collision name="slat">
      <origin xyz="0 0 0" rpy="0.38 0 0" />
      <geometry>
        <box size="0.42 0.11 0.018" />
        </geometry>
      </collision>
    <collision name="pin_0">
      <origin xyz="-0.235 0 0" rpy="0 1.5708 0" />
      <geometry>
        <cylinder radius="0.009" length="0.075" />
        </geometry>
      </collision>
    <collision name="pin_1">
      <origin xyz="0.235 0 0" rpy="0 1.5708 0" />
      <geometry>
        <cylinder radius="0.009" length="0.075" />
        </geometry>
      </collision>
    </link>
  <link name="louver_1_1">
    <visual name="slat">
      <origin xyz="0 0 0" rpy="0.38 0 0" />
      <geometry>
        <box size="0.42 0.11 0.018" />
        </geometry>
      <material name="warm painted wood">
        <color rgba="0.86 0.82 0.72 1" />
        </material>
      </visual>
    <visual name="pin_0">
      <origin xyz="-0.235 0 0" rpy="0 1.5708 0" />
      <geometry>
        <cylinder radius="0.009" length="0.075" />
        </geometry>
      <material name="aged brass">
        <color rgba="0.82 0.62 0.28 1" />
        </material>
      </visual>
    <visual name="pin_1">
      <origin xyz="0.235 0 0" rpy="0 1.5708 0" />
      <geometry>
        <cylinder radius="0.009" length="0.075" />
        </geometry>
      <material name="aged brass">
        <color rgba="0.82 0.62 0.28 1" />
        </material>
      </visual>
    <collision name="slat">
      <origin xyz="0 0 0" rpy="0.38 0 0" />
      <geometry>
        <box size="0.42 0.11 0.018" />
        </geometry>
      </collision>
    <collision name="pin_0">
      <origin xyz="-0.235 0 0" rpy="0 1.5708 0" />
      <geometry>
        <cylinder radius="0.009" length="0.075" />
        </geometry>
      </collision>
    <collision name="pin_1">
      <origin xyz="0.235 0 0" rpy="0 1.5708 0" />
      <geometry>
        <cylinder radius="0.009" length="0.075" />
        </geometry>
      </collision>
    </link>
  <link name="louver_1_2">
    <visual name="slat">
      <origin xyz="0 0 0" rpy="0.38 0 0" />
      <geometry>
        <box size="0.42 0.11 0.018" />
        </geometry>
      <material name="warm painted wood">
        <color rgba="0.86 0.82 0.72 1" />
        </material>
      </visual>
    <visual name="pin_0">
      <origin xyz="-0.235 0 0" rpy="0 1.5708 0" />
      <geometry>
        <cylinder radius="0.009" length="0.075" />
        </geometry>
      <material name="aged brass">
        <color rgba="0.82 0.62 0.28 1" />
        </material>
      </visual>
    <visual name="pin_1">
      <origin xyz="0.235 0 0" rpy="0 1.5708 0" />
      <geometry>
        <cylinder radius="0.009" length="0.075" />
        </geometry>
      <material name="aged brass">
        <color rgba="0.82 0.62 0.28 1" />
        </material>
      </visual>
    <collision name="slat">
      <origin xyz="0 0 0" rpy="0.38 0 0" />
      <geometry>
        <box size="0.42 0.11 0.018" />
        </geometry>
      </collision>
    <collision name="pin_0">
      <origin xyz="-0.235 0 0" rpy="0 1.5708 0" />
      <geometry>
        <cylinder radius="0.009" length="0.075" />
        </geometry>
      </collision>
    <collision name="pin_1">
      <origin xyz="0.235 0 0" rpy="0 1.5708 0" />
      <geometry>
        <cylinder radius="0.009" length="0.075" />
        </geometry>
      </collision>
    </link>
  <link name="louver_1_3">
    <visual name="slat">
      <origin xyz="0 0 0" rpy="0.38 0 0" />
      <geometry>
        <box size="0.42 0.11 0.018" />
        </geometry>
      <material name="warm painted wood">
        <color rgba="0.86 0.82 0.72 1" />
        </material>
      </visual>
    <visual name="pin_0">
      <origin xyz="-0.235 0 0" rpy="0 1.5708 0" />
      <geometry>
        <cylinder radius="0.009" length="0.075" />
        </geometry>
      <material name="aged brass">
        <color rgba="0.82 0.62 0.28 1" />
        </material>
      </visual>
    <visual name="pin_1">
      <origin xyz="0.235 0 0" rpy="0 1.5708 0" />
      <geometry>
        <cylinder radius="0.009" length="0.075" />
        </geometry>
      <material name="aged brass">
        <color rgba="0.82 0.62 0.28 1" />
        </material>
      </visual>
    <collision name="slat">
      <origin xyz="0 0 0" rpy="0.38 0 0" />
      <geometry>
        <box size="0.42 0.11 0.018" />
        </geometry>
      </collision>
    <collision name="pin_0">
      <origin xyz="-0.235 0 0" rpy="0 1.5708 0" />
      <geometry>
        <cylinder radius="0.009" length="0.075" />
        </geometry>
      </collision>
    <collision name="pin_1">
      <origin xyz="0.235 0 0" rpy="0 1.5708 0" />
      <geometry>
        <cylinder radius="0.009" length="0.075" />
        </geometry>
      </collision>
    </link>
  <link name="louver_1_4">
    <visual name="slat">
      <origin xyz="0 0 0" rpy="0.38 0 0" />
      <geometry>
        <box size="0.42 0.11 0.018" />
        </geometry>
      <material name="warm painted wood">
        <color rgba="0.86 0.82 0.72 1" />
        </material>
      </visual>
    <visual name="pin_0">
      <origin xyz="-0.235 0 0" rpy="0 1.5708 0" />
      <geometry>
        <cylinder radius="0.009" length="0.075" />
        </geometry>
      <material name="aged brass">
        <color rgba="0.82 0.62 0.28 1" />
        </material>
      </visual>
    <visual name="pin_1">
      <origin xyz="0.235 0 0" rpy="0 1.5708 0" />
      <geometry>
        <cylinder radius="0.009" length="0.075" />
        </geometry>
      <material name="aged brass">
        <color rgba="0.82 0.62 0.28 1" />
        </material>
      </visual>
    <collision name="slat">
      <origin xyz="0 0 0" rpy="0.38 0 0" />
      <geometry>
        <box size="0.42 0.11 0.018" />
        </geometry>
      </collision>
    <collision name="pin_0">
      <origin xyz="-0.235 0 0" rpy="0 1.5708 0" />
      <geometry>
        <cylinder radius="0.009" length="0.075" />
        </geometry>
      </collision>
    <collision name="pin_1">
      <origin xyz="0.235 0 0" rpy="0 1.5708 0" />
      <geometry>
        <cylinder radius="0.009" length="0.075" />
        </geometry>
      </collision>
    </link>
  <link name="louver_1_5">
    <visual name="slat">
      <origin xyz="0 0 0" rpy="0.38 0 0" />
      <geometry>
        <box size="0.42 0.11 0.018" />
        </geometry>
      <material name="warm painted wood">
        <color rgba="0.86 0.82 0.72 1" />
        </material>
      </visual>
    <visual name="pin_0">
      <origin xyz="-0.235 0 0" rpy="0 1.5708 0" />
      <geometry>
        <cylinder radius="0.009" length="0.075" />
        </geometry>
      <material name="aged brass">
        <color rgba="0.82 0.62 0.28 1" />
        </material>
      </visual>
    <visual name="pin_1">
      <origin xyz="0.235 0 0" rpy="0 1.5708 0" />
      <geometry>
        <cylinder radius="0.009" length="0.075" />
        </geometry>
      <material name="aged brass">
        <color rgba="0.82 0.62 0.28 1" />
        </material>
      </visual>
    <collision name="slat">
      <origin xyz="0 0 0" rpy="0.38 0 0" />
      <geometry>
        <box size="0.42 0.11 0.018" />
        </geometry>
      </collision>
    <collision name="pin_0">
      <origin xyz="-0.235 0 0" rpy="0 1.5708 0" />
      <geometry>
        <cylinder radius="0.009" length="0.075" />
        </geometry>
      </collision>
    <collision name="pin_1">
      <origin xyz="0.235 0 0" rpy="0 1.5708 0" />
      <geometry>
        <cylinder radius="0.009" length="0.075" />
        </geometry>
      </collision>
    </link>
  <joint name="leaf_0_hinge" type="revolute">
    <origin xyz="-0.58 0 0.75" rpy="0 0 0" />
    <parent link="window_frame" />
    <child link="leaf_0" />
    <axis xyz="0 0 -1" />
    <limit effort="18" velocity="1.6" lower="0" upper="1.55" />
    </joint>
  <joint name="tilt_rod_0_slide" type="prismatic">
    <parent link="leaf_0" />
    <child link="tilt_rod_0" />
    <axis xyz="0 0 1" />
    <limit effort="6" velocity="0.25" lower="-0.035" upper="0.035" />
    </joint>
  <joint name="knob_0_turn" type="revolute">
    <origin xyz="0.28 -0.125 0" rpy="0 0 0" />
    <parent link="tilt_rod_0" />
    <child link="knob_0" />
    <axis xyz="0 1 0" />
    <limit effort="0.8" velocity="4" lower="-3.14159" upper="3.14159" />
    </joint>
  <joint name="louver_0_0_pivot" type="revolute">
    <origin xyz="0.28 0 -0.315" rpy="0 0 0" />
    <parent link="leaf_0" />
    <child link="louver_0_0" />
    <axis xyz="1 0 0" />
    <limit effort="0.6" velocity="2" lower="-0.42" upper="0.42" />
    </joint>
  <joint name="louver_0_1_pivot" type="revolute">
    <origin xyz="0.28 0 -0.195" rpy="0 0 0" />
    <parent link="leaf_0" />
    <child link="louver_0_1" />
    <axis xyz="1 0 0" />
    <limit effort="0.6" velocity="2" lower="-0.42" upper="0.42" />
    </joint>
  <joint name="louver_0_2_pivot" type="revolute">
    <origin xyz="0.28 0 -0.075" rpy="0 0 0" />
    <parent link="leaf_0" />
    <child link="louver_0_2" />
    <axis xyz="1 0 0" />
    <limit effort="0.6" velocity="2" lower="-0.42" upper="0.42" />
    </joint>
  <joint name="louver_0_3_pivot" type="revolute">
    <origin xyz="0.28 0 0.045" rpy="0 0 0" />
    <parent link="leaf_0" />
    <child link="louver_0_3" />
    <axis xyz="1 0 0" />
    <limit effort="0.6" velocity="2" lower="-0.42" upper="0.42" />
    </joint>
  <joint name="louver_0_4_pivot" type="revolute">
    <origin xyz="0.28 0 0.165" rpy="0 0 0" />
    <parent link="leaf_0" />
    <child link="louver_0_4" />
    <axis xyz="1 0 0" />
    <limit effort="0.6" velocity="2" lower="-0.42" upper="0.42" />
    </joint>
  <joint name="louver_0_5_pivot" type="revolute">
    <origin xyz="0.28 0 0.285" rpy="0 0 0" />
    <parent link="leaf_0" />
    <child link="louver_0_5" />
    <axis xyz="1 0 0" />
    <limit effort="0.6" velocity="2" lower="-0.42" upper="0.42" />
    </joint>
  <joint name="leaf_1_hinge" type="revolute">
    <origin xyz="0.58 0 0.75" rpy="0 0 0" />
    <parent link="window_frame" />
    <child link="leaf_1" />
    <axis xyz="0 0 1" />
    <limit effort="18" velocity="1.6" lower="0" upper="1.55" />
    </joint>
  <joint name="tilt_rod_1_slide" type="prismatic">
    <parent link="leaf_1" />
    <child link="tilt_rod_1" />
    <axis xyz="0 0 1" />
    <limit effort="6" velocity="0.25" lower="-0.035" upper="0.035" />
    </joint>
  <joint name="knob_1_turn" type="revolute">
    <origin xyz="-0.28 -0.125 0" rpy="0 0 0" />
    <parent link="tilt_rod_1" />
    <child link="knob_1" />
    <axis xyz="0 1 0" />
    <limit effort="0.8" velocity="4" lower="-3.14159" upper="3.14159" />
    </joint>
  <joint name="louver_1_0_pivot" type="revolute">
    <origin xyz="-0.28 0 -0.315" rpy="0 0 0" />
    <parent link="leaf_1" />
    <child link="louver_1_0" />
    <axis xyz="1 0 0" />
    <limit effort="0.6" velocity="2" lower="-0.42" upper="0.42" />
    </joint>
  <joint name="louver_1_1_pivot" type="revolute">
    <origin xyz="-0.28 0 -0.195" rpy="0 0 0" />
    <parent link="leaf_1" />
    <child link="louver_1_1" />
    <axis xyz="1 0 0" />
    <limit effort="0.6" velocity="2" lower="-0.42" upper="0.42" />
    </joint>
  <joint name="louver_1_2_pivot" type="revolute">
    <origin xyz="-0.28 0 -0.075" rpy="0 0 0" />
    <parent link="leaf_1" />
    <child link="louver_1_2" />
    <axis xyz="1 0 0" />
    <limit effort="0.6" velocity="2" lower="-0.42" upper="0.42" />
    </joint>
  <joint name="louver_1_3_pivot" type="revolute">
    <origin xyz="-0.28 0 0.045" rpy="0 0 0" />
    <parent link="leaf_1" />
    <child link="louver_1_3" />
    <axis xyz="1 0 0" />
    <limit effort="0.6" velocity="2" lower="-0.42" upper="0.42" />
    </joint>
  <joint name="louver_1_4_pivot" type="revolute">
    <origin xyz="-0.28 0 0.165" rpy="0 0 0" />
    <parent link="leaf_1" />
    <child link="louver_1_4" />
    <axis xyz="1 0 0" />
    <limit effort="0.6" velocity="2" lower="-0.42" upper="0.42" />
    </joint>
  <joint name="louver_1_5_pivot" type="revolute">
    <origin xyz="-0.28 0 0.285" rpy="0 0 0" />
    <parent link="leaf_1" />
    <child link="louver_1_5" />
    <axis xyz="1 0 0" />
    <limit effort="0.6" velocity="2" lower="-0.42" upper="0.42" />
    </joint>
  </robot>
