<robot name="compact_pan_lift_module">
  <material name="cast_dark">
    <color rgba="0.08 0.085 0.09 1" />
    </material>
  <material name="graphite">
    <color rgba="0.16 0.17 0.18 1" />
    </material>
  <material name="satin_metal">
    <color rgba="0.62 0.64 0.66 1" />
    </material>
  <material name="guide_steel">
    <color rgba="0.78 0.8 0.82 1" />
    </material>
  <material name="carriage_blue">
    <color rgba="0.08 0.26 0.52 1" />
    </material>
  <material name="black_rubber">
    <color rgba="0.015 0.015 0.018 1" />
    </material>
  <link name="stator">
    <inertial>
      <origin xyz="0 0 0.0175" rpy="0 0 0" />
      <mass value="3.2" />
      <inertia ixx="0.0276333" ixy="0" ixz="0" iyy="0.0473667" iyz="0" izz="0.0743467" />
      </inertial>
    <visual name="floor_plate">
      <origin xyz="0 0 0.0175" rpy="0 0 0" />
      <geometry>
        <box size="0.42 0.32 0.035" />
        </geometry>
      <material name="cast_dark">
        <color rgba="0.08 0.085 0.09 1" />
        </material>
      </visual>
    <visual name="fixed_bearing">
      <origin xyz="0 0 0.044" rpy="0 0 0" />
      <geometry>
        <cylinder radius="0.125" length="0.018" />
        </geometry>
      <material name="graphite">
        <color rgba="0.16 0.17 0.18 1" />
        </material>
      </visual>
    <visual name="front_foot">
      <origin xyz="0 0.151 0.04" rpy="0 0 0" />
      <geometry>
        <box size="0.34 0.018 0.01" />
        </geometry>
      <material name="black_rubber">
        <color rgba="0.015 0.015 0.018 1" />
        </material>
      </visual>
    <visual name="rear_foot">
      <origin xyz="0 -0.151 0.04" rpy="0 0 0" />
      <geometry>
        <box size="0.34 0.018 0.01" />
        </geometry>
      <material name="black_rubber">
        <color rgba="0.015 0.015 0.018 1" />
        </material>
      </visual>
    <collision name="floor_plate">
      <origin xyz="0 0 0.0175" rpy="0 0 0" />
      <geometry>
        <box size="0.42 0.32 0.035" />
        </geometry>
      </collision>
    <collision name="fixed_bearing">
      <origin xyz="0 0 0.044" rpy="0 0 0" />
      <geometry>
        <cylinder radius="0.125" length="0.018" />
        </geometry>
      </collision>
    <collision name="front_foot">
      <origin xyz="0 0.151 0.04" rpy="0 0 0" />
      <geometry>
        <box size="0.34 0.018 0.01" />
        </geometry>
      </collision>
    <collision name="rear_foot">
      <origin xyz="0 -0.151 0.04" rpy="0 0 0" />
      <geometry>
        <box size="0.34 0.018 0.01" />
        </geometry>
      </collision>
    </link>
  <link name="lower_stage">
    <inertial>
      <origin xyz="0 0 0.035" rpy="0 0 0" />
      <mass value="5" />
      <inertia ixx="0.0422604" ixy="0" ixz="0" iyy="0.0422604" iyz="0" izz="0.081" />
      </inertial>
    <visual name="turntable_disk">
      <origin xyz="0 0 0.0325" rpy="0 0 0" />
      <geometry>
        <cylinder radius="0.18" length="0.065" />
        </geometry>
      <material name="graphite">
        <color rgba="0.16 0.17 0.18 1" />
        </material>
      </visual>
    <visual name="gearbox_hump">
      <origin xyz="0 0 0.085" rpy="0 0 0" />
      <geometry>
        <box size="0.24 0.16 0.046" />
        </geometry>
      <material name="cast_dark">
        <color rgba="0.08 0.085 0.09 1" />
        </material>
      </visual>
    <visual name="mast_column">
      <origin xyz="0 0 0.285" rpy="0 0 0" />
      <geometry>
        <box size="0.056 0.12 0.43" />
        </geometry>
      <material name="cast_dark">
        <color rgba="0.08 0.085 0.09 1" />
        </material>
      </visual>
    <visual name="lower_rail_clamp">
      <origin xyz="0 0 0.0925" rpy="0 0 0" />
      <geometry>
        <box size="0.07 0.178 0.025" />
        </geometry>
      <material name="graphite">
        <color rgba="0.16 0.17 0.18 1" />
        </material>
      </visual>
    <visual name="upper_rail_clamp">
      <origin xyz="0 0 0.475" rpy="0 0 0" />
      <geometry>
        <box size="0.07 0.178 0.025" />
        </geometry>
      <material name="graphite">
        <color rgba="0.16 0.17 0.18 1" />
        </material>
      </visual>
    <visual name="mast_cap">
      <origin xyz="0 0 0.512" rpy="0 0 0" />
      <geometry>
        <box size="0.1 0.15 0.024" />
        </geometry>
      <material name="graphite">
        <color rgba="0.16 0.17 0.18 1" />
        </material>
      </visual>
    <visual name="guide_rail_0">
      <origin xyz="0.014 0.076 0.285" rpy="0 0 0" />
      <geometry>
        <cylinder radius="0.006" length="0.38" />
        </geometry>
      <material name="guide_steel">
        <color rgba="0.78 0.8 0.82 1" />
        </material>
      </visual>
    <visual name="guide_rail_1">
      <origin xyz="0.014 -0.076 0.285" rpy="0 0 0" />
      <geometry>
        <cylinder radius="0.006" length="0.38" />
        </geometry>
      <material name="guide_steel">
        <color rgba="0.78 0.8 0.82 1" />
        </material>
      </visual>
    <collision name="turntable_disk">
      <origin xyz="0 0 0.0325" rpy="0 0 0" />
      <geometry>
        <cylinder radius="0.18" length="0.065" />
        </geometry>
      </collision>
    <collision name="gearbox_hump">
      <origin xyz="0 0 0.085" rpy="0 0 0" />
      <geometry>
        <box size="0.24 0.16 0.046" />
        </geometry>
      </collision>
    <collision name="mast_column">
      <origin xyz="0 0 0.285" rpy="0 0 0" />
      <geometry>
        <box size="0.056 0.12 0.43" />
        </geometry>
      </collision>
    <collision name="lower_rail_clamp">
      <origin xyz="0 0 0.0925" rpy="0 0 0" />
      <geometry>
        <box size="0.07 0.178 0.025" />
        </geometry>
      </collision>
    <collision name="upper_rail_clamp">
      <origin xyz="0 0 0.475" rpy="0 0 0" />
      <geometry>
        <box size="0.07 0.178 0.025" />
        </geometry>
      </collision>
    <collision name="mast_cap">
      <origin xyz="0 0 0.512" rpy="0 0 0" />
      <geometry>
        <box size="0.1 0.15 0.024" />
        </geometry>
      </collision>
    <collision name="guide_rail_0">
      <origin xyz="0.014 0.076 0.285" rpy="0 0 0" />
      <geometry>
        <cylinder radius="0.006" length="0.38" />
        </geometry>
      </collision>
    <collision name="guide_rail_1">
      <origin xyz="0.014 -0.076 0.285" rpy="0 0 0" />
      <geometry>
        <cylinder radius="0.006" length="0.38" />
        </geometry>
      </collision>
    </link>
  <link name="carriage">
    <inertial>
      <origin xyz="0.019 0 0.0775" rpy="0 0 0" />
      <mass value="0.72" />
      <inertia ixx="0.002379" ixy="0" ixz="0" iyy="0.00152814" iyz="0" izz="0.00102414" />
      </inertial>
    <visual name="slide_plate">
      <origin xyz="0.019 0 0.0775" rpy="0 0 0" />
      <geometry>
        <box size="0.038 0.125 0.155" />
        </geometry>
      <material name="carriage_blue">
        <color rgba="0.08 0.26 0.52 1" />
        </material>
      </visual>
    <visual name="payload_tray">
      <origin xyz="0.088 0 0.135" rpy="0 0 0" />
      <geometry>
        <box size="0.115 0.145 0.022" />
        </geometry>
      <material name="satin_metal">
        <color rgba="0.62 0.64 0.66 1" />
        </material>
      </visual>
    <visual name="tray_lip">
      <origin xyz="0.143 0 0.159" rpy="0 0 0" />
      <geometry>
        <box size="0.012 0.145 0.05" />
        </geometry>
      <material name="satin_metal">
        <color rgba="0.62 0.64 0.66 1" />
        </material>
      </visual>
    <visual name="side_rib_0">
      <origin xyz="0.073 0.055 0.09" rpy="0 0 0" />
      <geometry>
        <box size="0.078 0.018 0.075" />
        </geometry>
      <material name="carriage_blue">
        <color rgba="0.08 0.26 0.52 1" />
        </material>
      </visual>
    <visual name="side_rib_1">
      <origin xyz="0.073 -0.055 0.09" rpy="0 0 0" />
      <geometry>
        <box size="0.078 0.018 0.075" />
        </geometry>
      <material name="carriage_blue">
        <color rgba="0.08 0.26 0.52 1" />
        </material>
      </visual>
    <collision name="slide_plate">
      <origin xyz="0.019 0 0.0775" rpy="0 0 0" />
      <geometry>
        <box size="0.038 0.125 0.155" />
        </geometry>
      </collision>
    <collision name="payload_tray">
      <origin xyz="0.088 0 0.135" rpy="0 0 0" />
      <geometry>
        <box size="0.115 0.145 0.022" />
        </geometry>
      </collision>
    <collision name="tray_lip">
      <origin xyz="0.143 0 0.159" rpy="0 0 0" />
      <geometry>
        <box size="0.012 0.145 0.05" />
        </geometry>
      </collision>
    <collision name="side_rib_0">
      <origin xyz="0.073 0.055 0.09" rpy="0 0 0" />
      <geometry>
        <box size="0.078 0.018 0.075" />
        </geometry>
      </collision>
    <collision name="side_rib_1">
      <origin xyz="0.073 -0.055 0.09" rpy="0 0 0" />
      <geometry>
        <box size="0.078 0.018 0.075" />
        </geometry>
      </collision>
    </link>
  <joint name="stator_to_lower_stage" type="revolute">
    <origin xyz="0 0 0.053" rpy="0 0 0" />
    <parent link="stator" />
    <child link="lower_stage" />
    <axis xyz="0 0 1" />
    <limit effort="120" velocity="1.2" lower="-3.14159" upper="3.14159" />
    </joint>
  <joint name="mast_to_carriage" type="prismatic">
    <origin xyz="0.028 0 0.135" rpy="0 0 0" />
    <parent link="lower_stage" />
    <child link="carriage" />
    <axis xyz="0 0 1" />
    <limit effort="80" velocity="0.22" lower="0" upper="0.17" />
    </joint>
  </robot>
