<robot name="end_cap_display_freezer">
  <link name="cabinet">
    <visual name="plinth">
      <origin xyz="0 0 0.05" rpy="0 0 0" />
      <geometry>
        <box size="1.72 0.7 0.1" />
        </geometry>
      <material name="dark_recessed_plinth">
        <color rgba="0.08 0.09 0.1 1" />
        </material>
      </visual>
    <visual name="bottom_insulation">
      <origin xyz="0 0 0.14" rpy="0 0 0" />
      <geometry>
        <box size="1.8 0.82 0.08" />
        </geometry>
      <material name="warm_white_insulated_shell">
        <color rgba="0.88 0.91 0.9 1" />
        </material>
      </visual>
    <visual name="recessed_well">
      <origin xyz="0 0 0.205" rpy="0 0 0" />
      <geometry>
        <box size="1.64 0.62 0.035" />
        </geometry>
      <material name="dark_cold_well">
        <color rgba="0.05 0.07 0.09 1" />
        </material>
      </visual>
    <visual name="side_wall">
      <origin xyz="0 0.37 0.5" rpy="0 0 0" />
      <geometry>
        <box size="1.8 0.08 0.64" />
        </geometry>
      <material name="warm_white_insulated_shell">
        <color rgba="0.88 0.91 0.9 1" />
        </material>
      </visual>
    <visual name="side_wall_1">
      <origin xyz="0 -0.37 0.5" rpy="0 0 0" />
      <geometry>
        <box size="1.8 0.08 0.64" />
        </geometry>
      <material name="warm_white_insulated_shell">
        <color rgba="0.88 0.91 0.9 1" />
        </material>
      </visual>
    <visual name="end_wall">
      <origin xyz="-0.86 0 0.5" rpy="0 0 0" />
      <geometry>
        <box size="0.08 0.82 0.64" />
        </geometry>
      <material name="warm_white_insulated_shell">
        <color rgba="0.88 0.91 0.9 1" />
        </material>
      </visual>
    <visual name="rear_wall">
      <origin xyz="0.86 0 0.5" rpy="0 0 0" />
      <geometry>
        <box size="0.08 0.82 0.64" />
        </geometry>
      <material name="warm_white_insulated_shell">
        <color rgba="0.88 0.91 0.9 1" />
        </material>
      </visual>
    <visual name="top_rim">
      <origin xyz="0 0.3675 0.84" rpy="0 0 0" />
      <geometry>
        <box size="1.8 0.085 0.04" />
        </geometry>
      <material name="warm_white_insulated_shell">
        <color rgba="0.88 0.91 0.9 1" />
        </material>
      </visual>
    <visual name="top_rim_1">
      <origin xyz="0 -0.3675 0.84" rpy="0 0 0" />
      <geometry>
        <box size="1.8 0.085 0.04" />
        </geometry>
      <material name="warm_white_insulated_shell">
        <color rgba="0.88 0.91 0.9 1" />
        </material>
      </visual>
    <visual name="lower_track">
      <origin xyz="0 0.3075 0.88" rpy="0 0 0" />
      <geometry>
        <box size="1.7 0.045 0.044" />
        </geometry>
      <material name="brushed_aluminum">
        <color rgba="0.72 0.76 0.77 1" />
        </material>
      </visual>
    <visual name="lower_track_1">
      <origin xyz="0 -0.3075 0.88" rpy="0 0 0" />
      <geometry>
        <box size="1.7 0.045 0.044" />
        </geometry>
      <material name="brushed_aluminum">
        <color rgba="0.72 0.76 0.77 1" />
        </material>
      </visual>
    <visual name="upper_track">
      <origin xyz="0 0.3775 0.897" rpy="0 0 0" />
      <geometry>
        <box size="1.7 0.055 0.074" />
        </geometry>
      <material name="brushed_aluminum">
        <color rgba="0.72 0.76 0.77 1" />
        </material>
      </visual>
    <visual name="upper_track_1">
      <origin xyz="0 -0.3775 0.897" rpy="0 0 0" />
      <geometry>
        <box size="1.7 0.055 0.074" />
        </geometry>
      <material name="brushed_aluminum">
        <color rgba="0.72 0.76 0.77 1" />
        </material>
      </visual>
    <visual name="key_cylinder">
      <origin xyz="0.45 0.416 0.55" rpy="-1.5708 0 0" />
      <geometry>
        <cylinder radius="0.03" length="0.012" />
        </geometry>
      <material name="lock_chrome">
        <color rgba="0.75 0.76 0.74 1" />
        </material>
      </visual>
    <visual name="key_slot">
      <origin xyz="0.45 0.4235 0.55" rpy="0 0 0" />
      <geometry>
        <box size="0.008 0.003 0.036" />
        </geometry>
      <material name="black_rubber_gasket">
        <color rgba="0.01 0.012 0.014 1" />
        </material>
      </visual>
    <visual name="flap_hinge_leaf">
      <origin xyz="0.39 0.417 0.55" rpy="0 0 0" />
      <geometry>
        <box size="0.024 0.014 0.11" />
        </geometry>
      <material name="lock_chrome">
        <color rgba="0.75 0.76 0.74 1" />
        </material>
      </visual>
    </link>
  <link name="glass_top_0">
    <visual name="glass_pane">
      <geometry>
        <box size="0.77 0.545 0.012" />
        </geometry>
      <material name="blue_tinted_glass">
        <color rgba="0.55 0.85 1 0.38" />
        </material>
      </visual>
    <visual name="side_frame">
      <origin xyz="0 0.29 0" rpy="0 0 0" />
      <geometry>
        <box size="0.84 0.035 0.03" />
        </geometry>
      <material name="brushed_aluminum">
        <color rgba="0.72 0.76 0.77 1" />
        </material>
      </visual>
    <visual name="side_frame_1">
      <origin xyz="0 -0.29 0" rpy="0 0 0" />
      <geometry>
        <box size="0.84 0.035 0.03" />
        </geometry>
      <material name="brushed_aluminum">
        <color rgba="0.72 0.76 0.77 1" />
        </material>
      </visual>
    <visual name="end_frame">
      <origin xyz="0.4025 0.29 0" rpy="0 0 0" />
      <geometry>
        <box size="0.035 0.035 0.03" />
        </geometry>
      <material name="brushed_aluminum">
        <color rgba="0.72 0.76 0.77 1" />
        </material>
      </visual>
    <visual name="end_frame_1">
      <origin xyz="-0.4025 0.29 0" rpy="0 0 0" />
      <geometry>
        <box size="0.035 0.035 0.03" />
        </geometry>
      <material name="brushed_aluminum">
        <color rgba="0.72 0.76 0.77 1" />
        </material>
      </visual>
    <visual name="end_frame_2">
      <origin xyz="0.4025 -0.29 0" rpy="0 0 0" />
      <geometry>
        <box size="0.035 0.035 0.03" />
        </geometry>
      <material name="brushed_aluminum">
        <color rgba="0.72 0.76 0.77 1" />
        </material>
      </visual>
    <visual name="end_frame_3">
      <origin xyz="-0.4025 -0.29 0" rpy="0 0 0" />
      <geometry>
        <box size="0.035 0.035 0.03" />
        </geometry>
      <material name="brushed_aluminum">
        <color rgba="0.72 0.76 0.77 1" />
        </material>
      </visual>
    <visual name="finger_pull">
      <origin xyz="0 0 0.015" rpy="0 0 0" />
      <geometry>
        <box size="0.16 0.018 0.018" />
        </geometry>
      <material name="black_rubber_gasket">
        <color rgba="0.01 0.012 0.014 1" />
        </material>
      </visual>
    </link>
  <link name="glass_top_1">
    <visual name="glass_pane">
      <geometry>
        <box size="0.77 0.665 0.012" />
        </geometry>
      <material name="blue_tinted_glass">
        <color rgba="0.55 0.85 1 0.38" />
        </material>
      </visual>
    <visual name="side_frame">
      <origin xyz="0 0.35 0" rpy="0 0 0" />
      <geometry>
        <box size="0.84 0.035 0.03" />
        </geometry>
      <material name="brushed_aluminum">
        <color rgba="0.72 0.76 0.77 1" />
        </material>
      </visual>
    <visual name="side_frame_1">
      <origin xyz="0 -0.35 0" rpy="0 0 0" />
      <geometry>
        <box size="0.84 0.035 0.03" />
        </geometry>
      <material name="brushed_aluminum">
        <color rgba="0.72 0.76 0.77 1" />
        </material>
      </visual>
    <visual name="end_frame">
      <origin xyz="0.4025 0.35 0" rpy="0 0 0" />
      <geometry>
        <box size="0.035 0.035 0.03" />
        </geometry>
      <material name="brushed_aluminum">
        <color rgba="0.72 0.76 0.77 1" />
        </material>
      </visual>
    <visual name="end_frame_1">
      <origin xyz="-0.4025 0.35 0" rpy="0 0 0" />
      <geometry>
        <box size="0.035 0.035 0.03" />
        </geometry>
      <material name="brushed_aluminum">
        <color rgba="0.72 0.76 0.77 1" />
        </material>
      </visual>
    <visual name="end_frame_2">
      <origin xyz="0.4025 -0.35 0" rpy="0 0 0" />
      <geometry>
        <box size="0.035 0.035 0.03" />
        </geometry>
      <material name="brushed_aluminum">
        <color rgba="0.72 0.76 0.77 1" />
        </material>
      </visual>
    <visual name="end_frame_3">
      <origin xyz="-0.4025 -0.35 0" rpy="0 0 0" />
      <geometry>
        <box size="0.035 0.035 0.03" />
        </geometry>
      <material name="brushed_aluminum">
        <color rgba="0.72 0.76 0.77 1" />
        </material>
      </visual>
    <visual name="finger_pull">
      <origin xyz="0 0 0.015" rpy="0 0 0" />
      <geometry>
        <box size="0.16 0.018 0.018" />
        </geometry>
      <material name="black_rubber_gasket">
        <color rgba="0.01 0.012 0.014 1" />
        </material>
      </visual>
    </link>
  <link name="control_panel">
    <visual name="panel_plate">
      <geometry>
        <box size="0.025 0.4 0.2" />
        </geometry>
      <material name="black_control_panel">
        <color rgba="0.02 0.025 0.03 1" />
        </material>
      </visual>
    <visual name="display_window">
      <origin xyz="-0.0145 -0.095 0.04" rpy="0 0 0" />
      <geometry>
        <box size="0.004 0.14 0.045" />
        </geometry>
      <material name="blue_lit_display">
        <color rgba="0.05 0.3 0.55 1" />
        </material>
      </visual>
    <visual name="cold_mark">
      <origin xyz="-0.0145 -0.005 0.08" rpy="0 0 0" />
      <geometry>
        <box size="0.004 0.018 0.018" />
        </geometry>
      <material name="white_panel_markings">
        <color rgba="0.92 0.95 0.93 1" />
        </material>
      </visual>
    <visual name="tick_mark">
      <origin xyz="-0.0145 0.095 0.08" rpy="0 0 0" />
      <geometry>
        <box size="0.004 0.01 0.035" />
        </geometry>
      <material name="white_panel_markings">
        <color rgba="0.92 0.95 0.93 1" />
        </material>
      </visual>
    <visual name="tick_mark_1">
      <origin xyz="-0.0145 0.135 0.035" rpy="0 0 0" />
      <geometry>
        <box size="0.004 0.035 0.01" />
        </geometry>
      <material name="white_panel_markings">
        <color rgba="0.92 0.95 0.93 1" />
        </material>
      </visual>
    <visual name="tick_mark_2">
      <origin xyz="-0.0145 0.055 0.035" rpy="0 0 0" />
      <geometry>
        <box size="0.004 0.035 0.01" />
        </geometry>
      <material name="white_panel_markings">
        <color rgba="0.92 0.95 0.93 1" />
        </material>
      </visual>
    </link>
  <link name="temperature_knob">
    <visual name="knob_cap">
      <origin xyz="0 0 0" rpy="0 -1.5708 0" />
      <geometry>
        <mesh filename="assets/meshes/temperature_knob.obj" />
        </geometry>
      <material name="matte_gray_knob">
        <color rgba="0.34 0.36 0.36 1" />
        </material>
      </visual>
    </link>
  <link name="lock_flap">
    <visual name="cover_plate">
      <origin xyz="0.045 0 0" rpy="0 0 0" />
      <geometry>
        <box size="0.09 0.012 0.09" />
        </geometry>
      <material name="lock_chrome">
        <color rgba="0.75 0.76 0.74 1" />
        </material>
      </visual>
    <visual name="hinge_barrel">
      <geometry>
        <cylinder radius="0.008" length="0.095" />
        </geometry>
      <material name="lock_chrome">
        <color rgba="0.75 0.76 0.74 1" />
        </material>
      </visual>
    <visual name="hinge_web">
      <origin xyz="0.02 0.001 0" rpy="0 0 0" />
      <geometry>
        <box size="0.018 0.01 0.05" />
        </geometry>
      <material name="lock_chrome">
        <color rgba="0.75 0.76 0.74 1" />
        </material>
      </visual>
    </link>
  <joint name="cabinet_to_glass_top_0" type="prismatic">
    <origin xyz="-0.43 0 0.917" rpy="0 0 0" />
    <parent link="cabinet" />
    <child link="glass_top_0" />
    <axis xyz="1 0 0" />
    <limit effort="120" velocity="0.35" lower="0" upper="0.52" />
    </joint>
  <joint name="cabinet_to_glass_top_1" type="prismatic">
    <origin xyz="0.43 0 0.949" rpy="0 0 0" />
    <parent link="cabinet" />
    <child link="glass_top_1" />
    <axis xyz="-1 0 0" />
    <limit effort="120" velocity="0.35" lower="0" upper="0.52" />
    </joint>
  <joint name="cabinet_to_control_panel" type="fixed">
    <origin xyz="-0.9125 0 0.47" rpy="0 0 0" />
    <parent link="cabinet" />
    <child link="control_panel" />
    </joint>
  <joint name="panel_to_temperature_knob" type="continuous">
    <origin xyz="-0.0125 0.095 0.005" rpy="0 0 0" />
    <parent link="control_panel" />
    <child link="temperature_knob" />
    <axis xyz="-1 0 0" />
    <limit effort="1" velocity="4" />
    </joint>
  <joint name="cabinet_to_lock_flap" type="revolute">
    <origin xyz="0.39 0.432 0.55" rpy="0 0 0" />
    <parent link="cabinet" />
    <child link="lock_flap" />
    <axis xyz="0 0 1" />
    <limit effort="2" velocity="2" lower="0" upper="1.65" />
    </joint>
  </robot>
