<robot name="segmented_phalanx_chain">
  <material name="warm_ivory_polymer">
    <color rgba="0.82 0.76 0.64 1" />
    </material>
  <material name="brushed_side_plates">
    <color rgba="0.3 0.34 0.36 1" />
    </material>
  <material name="dark_pivot_caps">
    <color rgba="0.06 0.065 0.07 1" />
    </material>
  <material name="matte_black_base">
    <color rgba="0.09 0.1 0.105 1" />
    </material>
  <material name="soft_fingertip_rubber">
    <color rgba="0.12 0.105 0.095 1" />
    </material>
  <link name="root_knuckle">
    <visual name="base_plate">
      <origin xyz="-0.03 0 -0.06" rpy="0 0 0" />
      <geometry>
        <box size="0.085 0.08 0.015" />
        </geometry>
      <material name="matte_black_base">
        <color rgba="0.09 0.1 0.105 1" />
        </material>
      </visual>
    <visual name="upright_block">
      <origin xyz="-0.027 0 -0.037" rpy="0 0 0" />
      <geometry>
        <box size="0.026 0.054 0.046" />
        </geometry>
      <material name="matte_black_base">
        <color rgba="0.09 0.1 0.105 1" />
        </material>
      </visual>
    <visual name="root_cheek_bridge">
      <origin xyz="-0.025 0 -0.012" rpy="0 0 0" />
      <geometry>
        <box size="0.014 0.046 0.014" />
        </geometry>
      <material name="brushed_side_plates">
        <color rgba="0.3 0.34 0.36 1" />
        </material>
      </visual>
    <visual name="root_pin">
      <origin xyz="0 0 0" rpy="1.5708 0 0" />
      <geometry>
        <cylinder radius="0.0042" length="0.058" />
        </geometry>
      <material name="dark_pivot_caps">
        <color rgba="0.06 0.065 0.07 1" />
        </material>
      </visual>
    <visual name="root_cheek_pos">
      <origin xyz="-0.01 0.021 0" rpy="0 0 0" />
      <geometry>
        <box size="0.036 0.012 0.04" />
        </geometry>
      <material name="brushed_side_plates">
        <color rgba="0.3 0.34 0.36 1" />
        </material>
      </visual>
    <visual name="root_pin_cap_pos">
      <origin xyz="0 0.028 0" rpy="1.5708 0 0" />
      <geometry>
        <cylinder radius="0.011" length="0.006" />
        </geometry>
      <material name="dark_pivot_caps">
        <color rgba="0.06 0.065 0.07 1" />
        </material>
      </visual>
    <visual name="root_cheek_neg">
      <origin xyz="-0.01 -0.021 0" rpy="0 0 0" />
      <geometry>
        <box size="0.036 0.012 0.04" />
        </geometry>
      <material name="brushed_side_plates">
        <color rgba="0.3 0.34 0.36 1" />
        </material>
      </visual>
    <visual name="root_pin_cap_neg">
      <origin xyz="0 -0.028 0" rpy="1.5708 0 0" />
      <geometry>
        <cylinder radius="0.011" length="0.006" />
        </geometry>
      <material name="dark_pivot_caps">
        <color rgba="0.06 0.065 0.07 1" />
        </material>
      </visual>
    <visual name="bolt_-0.058_-0.026">
      <origin xyz="-0.058 -0.026 -0.051" rpy="0 0 0" />
      <geometry>
        <cylinder radius="0.0045" length="0.003" />
        </geometry>
      <material name="dark_pivot_caps">
        <color rgba="0.06 0.065 0.07 1" />
        </material>
      </visual>
    <visual name="bolt_-0.058_+0.026">
      <origin xyz="-0.058 0.026 -0.051" rpy="0 0 0" />
      <geometry>
        <cylinder radius="0.0045" length="0.003" />
        </geometry>
      <material name="dark_pivot_caps">
        <color rgba="0.06 0.065 0.07 1" />
        </material>
      </visual>
    <visual name="bolt_-0.002_-0.026">
      <origin xyz="-0.002 -0.026 -0.051" rpy="0 0 0" />
      <geometry>
        <cylinder radius="0.0045" length="0.003" />
        </geometry>
      <material name="dark_pivot_caps">
        <color rgba="0.06 0.065 0.07 1" />
        </material>
      </visual>
    <visual name="bolt_-0.002_+0.026">
      <origin xyz="-0.002 0.026 -0.051" rpy="0 0 0" />
      <geometry>
        <cylinder radius="0.0045" length="0.003" />
        </geometry>
      <material name="dark_pivot_caps">
        <color rgba="0.06 0.065 0.07 1" />
        </material>
      </visual>
    <collision name="base_plate">
      <origin xyz="-0.03 0 -0.06" rpy="0 0 0" />
      <geometry>
        <box size="0.085 0.08 0.015" />
        </geometry>
      </collision>
    <collision name="upright_block">
      <origin xyz="-0.027 0 -0.037" rpy="0 0 0" />
      <geometry>
        <box size="0.026 0.054 0.046" />
        </geometry>
      </collision>
    <collision name="root_cheek_bridge">
      <origin xyz="-0.025 0 -0.012" rpy="0 0 0" />
      <geometry>
        <box size="0.014 0.046 0.014" />
        </geometry>
      </collision>
    <collision name="root_pin">
      <origin xyz="0 0 0" rpy="1.5708 0 0" />
      <geometry>
        <cylinder radius="0.0042" length="0.058" />
        </geometry>
      </collision>
    <collision name="root_cheek_pos">
      <origin xyz="-0.01 0.021 0" rpy="0 0 0" />
      <geometry>
        <box size="0.036 0.012 0.04" />
        </geometry>
      </collision>
    <collision name="root_pin_cap_pos">
      <origin xyz="0 0.028 0" rpy="1.5708 0 0" />
      <geometry>
        <cylinder radius="0.011" length="0.006" />
        </geometry>
      </collision>
    <collision name="root_cheek_neg">
      <origin xyz="-0.01 -0.021 0" rpy="0 0 0" />
      <geometry>
        <box size="0.036 0.012 0.04" />
        </geometry>
      </collision>
    <collision name="root_pin_cap_neg">
      <origin xyz="0 -0.028 0" rpy="1.5708 0 0" />
      <geometry>
        <cylinder radius="0.011" length="0.006" />
        </geometry>
      </collision>
    <collision name="bolt_-0.058_-0.026">
      <origin xyz="-0.058 -0.026 -0.051" rpy="0 0 0" />
      <geometry>
        <cylinder radius="0.0045" length="0.003" />
        </geometry>
      </collision>
    <collision name="bolt_-0.058_+0.026">
      <origin xyz="-0.058 0.026 -0.051" rpy="0 0 0" />
      <geometry>
        <cylinder radius="0.0045" length="0.003" />
        </geometry>
      </collision>
    <collision name="bolt_-0.002_-0.026">
      <origin xyz="-0.002 -0.026 -0.051" rpy="0 0 0" />
      <geometry>
        <cylinder radius="0.0045" length="0.003" />
        </geometry>
      </collision>
    <collision name="bolt_-0.002_+0.026">
      <origin xyz="-0.002 0.026 -0.051" rpy="0 0 0" />
      <geometry>
        <cylinder radius="0.0045" length="0.003" />
        </geometry>
      </collision>
    </link>
  <link name="proximal">
    <visual name="body">
      <geometry>
        <mesh filename="assets/meshes/proximal_body.obj" />
        </geometry>
      <material name="warm_ivory_polymer">
        <color rgba="0.82 0.76 0.64 1" />
        </material>
      </visual>
    <visual name="proximal_boss">
      <origin xyz="0 0 0" rpy="1.5708 0 0" />
      <geometry>
        <cylinder radius="0.0105" length="0.024" />
        </geometry>
      <material name="warm_ivory_polymer">
        <color rgba="0.82 0.76 0.64 1" />
        </material>
      </visual>
    <visual name="middle_cheek_bridge">
      <origin xyz="0.057 0 -0.012" rpy="0 0 0" />
      <geometry>
        <box size="0.014 0.046 0.014" />
        </geometry>
      <material name="brushed_side_plates">
        <color rgba="0.3 0.34 0.36 1" />
        </material>
      </visual>
    <visual name="middle_pin">
      <origin xyz="0.082 0 0" rpy="1.5708 0 0" />
      <geometry>
        <cylinder radius="0.0042" length="0.058" />
        </geometry>
      <material name="dark_pivot_caps">
        <color rgba="0.06 0.065 0.07 1" />
        </material>
      </visual>
    <visual name="middle_cheek_pos">
      <origin xyz="0.072 0.021 0" rpy="0 0 0" />
      <geometry>
        <box size="0.036 0.012 0.04" />
        </geometry>
      <material name="brushed_side_plates">
        <color rgba="0.3 0.34 0.36 1" />
        </material>
      </visual>
    <visual name="middle_pin_cap_pos">
      <origin xyz="0.082 0.028 0" rpy="1.5708 0 0" />
      <geometry>
        <cylinder radius="0.011" length="0.006" />
        </geometry>
      <material name="dark_pivot_caps">
        <color rgba="0.06 0.065 0.07 1" />
        </material>
      </visual>
    <visual name="middle_cheek_neg">
      <origin xyz="0.072 -0.021 0" rpy="0 0 0" />
      <geometry>
        <box size="0.036 0.012 0.04" />
        </geometry>
      <material name="brushed_side_plates">
        <color rgba="0.3 0.34 0.36 1" />
        </material>
      </visual>
    <visual name="middle_pin_cap_neg">
      <origin xyz="0.082 -0.028 0" rpy="1.5708 0 0" />
      <geometry>
        <cylinder radius="0.011" length="0.006" />
        </geometry>
      <material name="dark_pivot_caps">
        <color rgba="0.06 0.065 0.07 1" />
        </material>
      </visual>
    <collision name="body">
      <geometry>
        <mesh filename="assets/meshes/proximal_body.obj" />
        </geometry>
      </collision>
    <collision name="proximal_boss">
      <origin xyz="0 0 0" rpy="1.5708 0 0" />
      <geometry>
        <cylinder radius="0.0105" length="0.024" />
        </geometry>
      </collision>
    <collision name="middle_cheek_bridge">
      <origin xyz="0.057 0 -0.012" rpy="0 0 0" />
      <geometry>
        <box size="0.014 0.046 0.014" />
        </geometry>
      </collision>
    <collision name="middle_pin">
      <origin xyz="0.082 0 0" rpy="1.5708 0 0" />
      <geometry>
        <cylinder radius="0.0042" length="0.058" />
        </geometry>
      </collision>
    <collision name="middle_cheek_pos">
      <origin xyz="0.072 0.021 0" rpy="0 0 0" />
      <geometry>
        <box size="0.036 0.012 0.04" />
        </geometry>
      </collision>
    <collision name="middle_pin_cap_pos">
      <origin xyz="0.082 0.028 0" rpy="1.5708 0 0" />
      <geometry>
        <cylinder radius="0.011" length="0.006" />
        </geometry>
      </collision>
    <collision name="middle_cheek_neg">
      <origin xyz="0.072 -0.021 0" rpy="0 0 0" />
      <geometry>
        <box size="0.036 0.012 0.04" />
        </geometry>
      </collision>
    <collision name="middle_pin_cap_neg">
      <origin xyz="0.082 -0.028 0" rpy="1.5708 0 0" />
      <geometry>
        <cylinder radius="0.011" length="0.006" />
        </geometry>
      </collision>
    </link>
  <link name="middle">
    <visual name="body">
      <geometry>
        <mesh filename="assets/meshes/middle_body.obj" />
        </geometry>
      <material name="warm_ivory_polymer">
        <color rgba="0.82 0.76 0.64 1" />
        </material>
      </visual>
    <visual name="middle_boss">
      <origin xyz="0 0 0" rpy="1.5708 0 0" />
      <geometry>
        <cylinder radius="0.0105" length="0.024" />
        </geometry>
      <material name="warm_ivory_polymer">
        <color rgba="0.82 0.76 0.64 1" />
        </material>
      </visual>
    <visual name="distal_cheek_bridge">
      <origin xyz="0.033 0 -0.012" rpy="0 0 0" />
      <geometry>
        <box size="0.014 0.046 0.014" />
        </geometry>
      <material name="brushed_side_plates">
        <color rgba="0.3 0.34 0.36 1" />
        </material>
      </visual>
    <visual name="distal_pin">
      <origin xyz="0.058 0 0" rpy="1.5708 0 0" />
      <geometry>
        <cylinder radius="0.0042" length="0.058" />
        </geometry>
      <material name="dark_pivot_caps">
        <color rgba="0.06 0.065 0.07 1" />
        </material>
      </visual>
    <visual name="distal_cheek_pos">
      <origin xyz="0.048 0.021 0" rpy="0 0 0" />
      <geometry>
        <box size="0.036 0.012 0.04" />
        </geometry>
      <material name="brushed_side_plates">
        <color rgba="0.3 0.34 0.36 1" />
        </material>
      </visual>
    <visual name="distal_pin_cap_pos">
      <origin xyz="0.058 0.028 0" rpy="1.5708 0 0" />
      <geometry>
        <cylinder radius="0.011" length="0.006" />
        </geometry>
      <material name="dark_pivot_caps">
        <color rgba="0.06 0.065 0.07 1" />
        </material>
      </visual>
    <visual name="distal_cheek_neg">
      <origin xyz="0.048 -0.021 0" rpy="0 0 0" />
      <geometry>
        <box size="0.036 0.012 0.04" />
        </geometry>
      <material name="brushed_side_plates">
        <color rgba="0.3 0.34 0.36 1" />
        </material>
      </visual>
    <visual name="distal_pin_cap_neg">
      <origin xyz="0.058 -0.028 0" rpy="1.5708 0 0" />
      <geometry>
        <cylinder radius="0.011" length="0.006" />
        </geometry>
      <material name="dark_pivot_caps">
        <color rgba="0.06 0.065 0.07 1" />
        </material>
      </visual>
    <collision name="body">
      <geometry>
        <mesh filename="assets/meshes/middle_body.obj" />
        </geometry>
      </collision>
    <collision name="middle_boss">
      <origin xyz="0 0 0" rpy="1.5708 0 0" />
      <geometry>
        <cylinder radius="0.0105" length="0.024" />
        </geometry>
      </collision>
    <collision name="distal_cheek_bridge">
      <origin xyz="0.033 0 -0.012" rpy="0 0 0" />
      <geometry>
        <box size="0.014 0.046 0.014" />
        </geometry>
      </collision>
    <collision name="distal_pin">
      <origin xyz="0.058 0 0" rpy="1.5708 0 0" />
      <geometry>
        <cylinder radius="0.0042" length="0.058" />
        </geometry>
      </collision>
    <collision name="distal_cheek_pos">
      <origin xyz="0.048 0.021 0" rpy="0 0 0" />
      <geometry>
        <box size="0.036 0.012 0.04" />
        </geometry>
      </collision>
    <collision name="distal_pin_cap_pos">
      <origin xyz="0.058 0.028 0" rpy="1.5708 0 0" />
      <geometry>
        <cylinder radius="0.011" length="0.006" />
        </geometry>
      </collision>
    <collision name="distal_cheek_neg">
      <origin xyz="0.048 -0.021 0" rpy="0 0 0" />
      <geometry>
        <box size="0.036 0.012 0.04" />
        </geometry>
      </collision>
    <collision name="distal_pin_cap_neg">
      <origin xyz="0.058 -0.028 0" rpy="1.5708 0 0" />
      <geometry>
        <cylinder radius="0.011" length="0.006" />
        </geometry>
      </collision>
    </link>
  <link name="distal">
    <visual name="body">
      <geometry>
        <mesh filename="assets/meshes/distal_body.obj" />
        </geometry>
      <material name="warm_ivory_polymer">
        <color rgba="0.82 0.76 0.64 1" />
        </material>
      </visual>
    <visual name="distal_boss">
      <origin xyz="0 0 0" rpy="1.5708 0 0" />
      <geometry>
        <cylinder radius="0.0105" length="0.024" />
        </geometry>
      <material name="warm_ivory_polymer">
        <color rgba="0.82 0.76 0.64 1" />
        </material>
      </visual>
    <visual name="fingertip_pad">
      <geometry>
        <mesh filename="assets/meshes/fingertip_pad.obj" />
        </geometry>
      <material name="soft_fingertip_rubber">
        <color rgba="0.12 0.105 0.095 1" />
        </material>
      </visual>
    <collision name="body">
      <geometry>
        <mesh filename="assets/meshes/distal_body.obj" />
        </geometry>
      </collision>
    <collision name="distal_boss">
      <origin xyz="0 0 0" rpy="1.5708 0 0" />
      <geometry>
        <cylinder radius="0.0105" length="0.024" />
        </geometry>
      </collision>
    <collision name="fingertip_pad">
      <geometry>
        <mesh filename="assets/meshes/fingertip_pad.obj" />
        </geometry>
      </collision>
    </link>
  <joint name="root_to_proximal" type="revolute">
    <parent link="root_knuckle" />
    <child link="proximal" />
    <axis xyz="0 1 0" />
    <limit effort="8" velocity="4" lower="0" upper="1.25" />
    </joint>
  <joint name="proximal_to_middle" type="revolute">
    <origin xyz="0.082 0 0" rpy="0 0 0" />
    <parent link="proximal" />
    <child link="middle" />
    <axis xyz="0 1 0" />
    <limit effort="6" velocity="4" lower="0" upper="1.35" />
    </joint>
  <joint name="middle_to_distal" type="revolute">
    <origin xyz="0.058 0 0" rpy="0 0 0" />
    <parent link="middle" />
    <child link="distal" />
    <axis xyz="0 1 0" />
    <limit effort="4" velocity="4" lower="0" upper="1.2" />
    </joint>
  </robot>
