<robot name="compact_lift_axis_wrist">
  <material name="warm_light_gray_paint">
    <color rgba="0.72 0.74 0.72 1" />
    </material>
  <material name="blackened_steel">
    <color rgba="0.03 0.035 0.04 1" />
    </material>
  <material name="polished_linear_rail">
    <color rgba="0.8 0.82 0.83 1" />
    </material>
  <material name="blue_anodized_carriage">
    <color rgba="0.08 0.2 0.42 1" />
    </material>
  <material name="brushed_lead_screw">
    <color rgba="0.62 0.58 0.5 1" />
    </material>
  <material name="dark_tool_face">
    <color rgba="0.015 0.017 0.018 1" />
    </material>
  <link name="fixed_column">
    <visual name="base_plate">
      <origin xyz="0 0 0.0125" rpy="0 0 0" />
      <geometry>
        <box size="0.24 0.18 0.025" />
        </geometry>
      <material name="warm_light_gray_paint">
        <color rgba="0.72 0.74 0.72 1" />
        </material>
      </visual>
    <visual name="column_spine">
      <origin xyz="0 -0.055 0.294" rpy="0 0 0" />
      <geometry>
        <box size="0.072 0.06 0.542" />
        </geometry>
      <material name="warm_light_gray_paint">
        <color rgba="0.72 0.74 0.72 1" />
        </material>
      </visual>
    <visual name="lower_rail_clamp">
      <origin xyz="0 -0.005 0.065" rpy="0 0 0" />
      <geometry>
        <box size="0.135 0.055 0.025" />
        </geometry>
      <material name="blackened_steel">
        <color rgba="0.03 0.035 0.04 1" />
        </material>
      </visual>
    <visual name="upper_rail_clamp">
      <origin xyz="0 -0.005 0.515" rpy="0 0 0" />
      <geometry>
        <box size="0.135 0.055 0.025" />
        </geometry>
      <material name="blackened_steel">
        <color rgba="0.03 0.035 0.04 1" />
        </material>
      </visual>
    <visual name="guide_rail_0">
      <origin xyz="-0.04 0.005 0.29" rpy="0 0 0" />
      <geometry>
        <cylinder radius="0.008" length="0.46" />
        </geometry>
      <material name="polished_linear_rail">
        <color rgba="0.8 0.82 0.83 1" />
        </material>
      </visual>
    <visual name="guide_rail_1">
      <origin xyz="0.04 0.005 0.29" rpy="0 0 0" />
      <geometry>
        <cylinder radius="0.008" length="0.46" />
        </geometry>
      <material name="polished_linear_rail">
        <color rgba="0.8 0.82 0.83 1" />
        </material>
      </visual>
    <visual name="lead_screw">
      <origin xyz="0 0.015 0.291" rpy="0 0 0" />
      <geometry>
        <cylinder radius="0.005" length="0.462" />
        </geometry>
      <material name="brushed_lead_screw">
        <color rgba="0.62 0.58 0.5 1" />
        </material>
      </visual>
    <visual name="top_motor">
      <origin xyz="0 -0.055 0.595" rpy="0 0 0" />
      <geometry>
        <box size="0.08 0.07 0.07" />
        </geometry>
      <material name="blackened_steel">
        <color rgba="0.03 0.035 0.04 1" />
        </material>
      </visual>
    <collision name="base_plate">
      <origin xyz="0 0 0.0125" rpy="0 0 0" />
      <geometry>
        <box size="0.24 0.18 0.025" />
        </geometry>
      </collision>
    <collision name="column_spine">
      <origin xyz="0 -0.055 0.294" rpy="0 0 0" />
      <geometry>
        <box size="0.072 0.06 0.542" />
        </geometry>
      </collision>
    <collision name="lower_rail_clamp">
      <origin xyz="0 -0.005 0.065" rpy="0 0 0" />
      <geometry>
        <box size="0.135 0.055 0.025" />
        </geometry>
      </collision>
    <collision name="upper_rail_clamp">
      <origin xyz="0 -0.005 0.515" rpy="0 0 0" />
      <geometry>
        <box size="0.135 0.055 0.025" />
        </geometry>
      </collision>
    <collision name="guide_rail_0">
      <origin xyz="-0.04 0.005 0.29" rpy="0 0 0" />
      <geometry>
        <cylinder radius="0.008" length="0.46" />
        </geometry>
      </collision>
    <collision name="guide_rail_1">
      <origin xyz="0.04 0.005 0.29" rpy="0 0 0" />
      <geometry>
        <cylinder radius="0.008" length="0.46" />
        </geometry>
      </collision>
    <collision name="lead_screw">
      <origin xyz="0 0.015 0.291" rpy="0 0 0" />
      <geometry>
        <cylinder radius="0.005" length="0.462" />
        </geometry>
      </collision>
    <collision name="top_motor">
      <origin xyz="0 -0.055 0.595" rpy="0 0 0" />
      <geometry>
        <box size="0.08 0.07 0.07" />
        </geometry>
      </collision>
    </link>
  <link name="carriage">
    <visual name="bearing_block">
      <geometry>
        <mesh filename="assets/meshes/carriage_block.obj" />
        </geometry>
      <material name="blue_anodized_carriage">
        <color rgba="0.08 0.2 0.42 1" />
        </material>
      </visual>
    <visual name="yoke">
      <origin xyz="0 0.058 -0.058" rpy="0 0 0" />
      <geometry>
        <mesh filename="assets/meshes/carriage_yoke.obj" />
        </geometry>
      <material name="blue_anodized_carriage">
        <color rgba="0.08 0.2 0.42 1" />
        </material>
      </visual>
    <visual name="front_shelf">
      <origin xyz="0 0.042 -0.03" rpy="0 0 0" />
      <geometry>
        <box size="0.09 0.018 0.04" />
        </geometry>
      <material name="blue_anodized_carriage">
        <color rgba="0.08 0.2 0.42 1" />
        </material>
      </visual>
    <collision name="bearing_block">
      <geometry>
        <mesh filename="assets/meshes/carriage_block.obj" />
        </geometry>
      </collision>
    <collision name="yoke">
      <origin xyz="0 0.058 -0.058" rpy="0 0 0" />
      <geometry>
        <mesh filename="assets/meshes/carriage_yoke.obj" />
        </geometry>
      </collision>
    <collision name="front_shelf">
      <origin xyz="0 0.042 -0.03" rpy="0 0 0" />
      <geometry>
        <box size="0.09 0.018 0.04" />
        </geometry>
      </collision>
    </link>
  <link name="wrist_plate">
    <visual name="pivot_pin">
      <origin xyz="0 0 0" rpy="0 1.5708 0" />
      <geometry>
        <cylinder radius="0.0075" length="0.134" />
        </geometry>
      <material name="polished_linear_rail">
        <color rgba="0.8 0.82 0.83 1" />
        </material>
      </visual>
    <visual name="center_barrel">
      <origin xyz="0 0 0" rpy="0 1.5708 0" />
      <geometry>
        <cylinder radius="0.014" length="0.058" />
        </geometry>
      <material name="blackened_steel">
        <color rgba="0.03 0.035 0.04 1" />
        </material>
      </visual>
    <visual name="tilt_arm">
      <origin xyz="0 0.074 -0.01" rpy="0 0 0" />
      <geometry>
        <box size="0.03 0.124 0.02" />
        </geometry>
      <material name="blackened_steel">
        <color rgba="0.03 0.035 0.04 1" />
        </material>
      </visual>
    <visual name="plate_body">
      <origin xyz="0 0.138 -0.036" rpy="0 0 0" />
      <geometry>
        <box size="0.092 0.012 0.095" />
        </geometry>
      <material name="warm_light_gray_paint">
        <color rgba="0.72 0.74 0.72 1" />
        </material>
      </visual>
    <visual name="tool_face">
      <origin xyz="0 0.1465 -0.036" rpy="0 0 0" />
      <geometry>
        <box size="0.072 0.005 0.07" />
        </geometry>
      <material name="dark_tool_face">
        <color rgba="0.015 0.017 0.018 1" />
        </material>
      </visual>
    <visual name="face_screw_-0.024_-0.058">
      <origin xyz="-0.024 0.151 -0.058" rpy="1.5708 0 0" />
      <geometry>
        <cylinder radius="0.004" length="0.006" />
        </geometry>
      <material name="polished_linear_rail">
        <color rgba="0.8 0.82 0.83 1" />
        </material>
      </visual>
    <visual name="face_screw_-0.024_-0.014">
      <origin xyz="-0.024 0.151 -0.014" rpy="1.5708 0 0" />
      <geometry>
        <cylinder radius="0.004" length="0.006" />
        </geometry>
      <material name="polished_linear_rail">
        <color rgba="0.8 0.82 0.83 1" />
        </material>
      </visual>
    <visual name="face_screw_0.024_-0.058">
      <origin xyz="0.024 0.151 -0.058" rpy="1.5708 0 0" />
      <geometry>
        <cylinder radius="0.004" length="0.006" />
        </geometry>
      <material name="polished_linear_rail">
        <color rgba="0.8 0.82 0.83 1" />
        </material>
      </visual>
    <visual name="face_screw_0.024_-0.014">
      <origin xyz="0.024 0.151 -0.014" rpy="1.5708 0 0" />
      <geometry>
        <cylinder radius="0.004" length="0.006" />
        </geometry>
      <material name="polished_linear_rail">
        <color rgba="0.8 0.82 0.83 1" />
        </material>
      </visual>
    <collision name="pivot_pin">
      <origin xyz="0 0 0" rpy="0 1.5708 0" />
      <geometry>
        <cylinder radius="0.0075" length="0.134" />
        </geometry>
      </collision>
    <collision name="center_barrel">
      <origin xyz="0 0 0" rpy="0 1.5708 0" />
      <geometry>
        <cylinder radius="0.014" length="0.058" />
        </geometry>
      </collision>
    <collision name="tilt_arm">
      <origin xyz="0 0.074 -0.01" rpy="0 0 0" />
      <geometry>
        <box size="0.03 0.124 0.02" />
        </geometry>
      </collision>
    <collision name="plate_body">
      <origin xyz="0 0.138 -0.036" rpy="0 0 0" />
      <geometry>
        <box size="0.092 0.012 0.095" />
        </geometry>
      </collision>
    <collision name="tool_face">
      <origin xyz="0 0.1465 -0.036" rpy="0 0 0" />
      <geometry>
        <box size="0.072 0.005 0.07" />
        </geometry>
      </collision>
    <collision name="face_screw_-0.024_-0.058">
      <origin xyz="-0.024 0.151 -0.058" rpy="1.5708 0 0" />
      <geometry>
        <cylinder radius="0.004" length="0.006" />
        </geometry>
      </collision>
    <collision name="face_screw_-0.024_-0.014">
      <origin xyz="-0.024 0.151 -0.014" rpy="1.5708 0 0" />
      <geometry>
        <cylinder radius="0.004" length="0.006" />
        </geometry>
      </collision>
    <collision name="face_screw_0.024_-0.058">
      <origin xyz="0.024 0.151 -0.058" rpy="1.5708 0 0" />
      <geometry>
        <cylinder radius="0.004" length="0.006" />
        </geometry>
      </collision>
    <collision name="face_screw_0.024_-0.014">
      <origin xyz="0.024 0.151 -0.014" rpy="1.5708 0 0" />
      <geometry>
        <cylinder radius="0.004" length="0.006" />
        </geometry>
      </collision>
    </link>
  <joint name="column_slide" type="prismatic">
    <origin xyz="0 0.01 0.175" rpy="0 0 0" />
    <parent link="fixed_column" />
    <child link="carriage" />
    <axis xyz="0 0 1" />
    <limit effort="120" velocity="0.18" lower="0" upper="0.22" />
    </joint>
  <joint name="wrist_pivot" type="revolute">
    <origin xyz="0 0.058 0" rpy="0 0 0" />
    <parent link="carriage" />
    <child link="wrist_plate" />
    <axis xyz="1 0 0" />
    <limit effort="12" velocity="1" lower="-0.2" upper="0.8" />
    </joint>
  </robot>
