<robot name="staggered_lever_chain_study">
  <link name="base">
    <visual name="ground_plate">
      <origin xyz="0 0 0.0125" rpy="0 0 0" />
      <geometry>
        <box size="1.9 0.36 0.025" />
        </geometry>
      <material name="dark_oxide_steel">
        <color rgba="0.12 0.13 0.14 1" />
        </material>
      </visual>
    <visual name="side_rail_-0.155">
      <origin xyz="0 -0.155 0.039" rpy="0 0 0" />
      <geometry>
        <box size="1.78 0.028 0.028" />
        </geometry>
      <material name="bead_blasted_steel">
        <color rgba="0.45 0.48 0.5 1" />
        </material>
      </visual>
    <visual name="rail_slot_-0.62_-0.15">
      <origin xyz="-0.62 -0.155 0.0535" rpy="0 0 0" />
      <geometry>
        <box size="0.058 0.01 0.002" />
        </geometry>
      <material name="black_recess_shadow">
        <color rgba="0.02 0.02 0.018 1" />
        </material>
      </visual>
    <visual name="slot_end_a_-0.62_-0.15">
      <origin xyz="-0.649 -0.155 0.054" rpy="0 0 0" />
      <geometry>
        <cylinder radius="0.005" length="0.0025" />
        </geometry>
      <material name="black_recess_shadow">
        <color rgba="0.02 0.02 0.018 1" />
        </material>
      </visual>
    <visual name="slot_end_b_-0.62_-0.15">
      <origin xyz="-0.591 -0.155 0.054" rpy="0 0 0" />
      <geometry>
        <cylinder radius="0.005" length="0.0025" />
        </geometry>
      <material name="black_recess_shadow">
        <color rgba="0.02 0.02 0.018 1" />
        </material>
      </visual>
    <visual name="rail_slot_-0.36_-0.15">
      <origin xyz="-0.36 -0.155 0.0535" rpy="0 0 0" />
      <geometry>
        <box size="0.058 0.01 0.002" />
        </geometry>
      <material name="black_recess_shadow">
        <color rgba="0.02 0.02 0.018 1" />
        </material>
      </visual>
    <visual name="slot_end_a_-0.36_-0.15">
      <origin xyz="-0.389 -0.155 0.054" rpy="0 0 0" />
      <geometry>
        <cylinder radius="0.005" length="0.0025" />
        </geometry>
      <material name="black_recess_shadow">
        <color rgba="0.02 0.02 0.018 1" />
        </material>
      </visual>
    <visual name="slot_end_b_-0.36_-0.15">
      <origin xyz="-0.331 -0.155 0.054" rpy="0 0 0" />
      <geometry>
        <cylinder radius="0.005" length="0.0025" />
        </geometry>
      <material name="black_recess_shadow">
        <color rgba="0.02 0.02 0.018 1" />
        </material>
      </visual>
    <visual name="rail_slot_-0.10_-0.15">
      <origin xyz="-0.1 -0.155 0.0535" rpy="0 0 0" />
      <geometry>
        <box size="0.058 0.01 0.002" />
        </geometry>
      <material name="black_recess_shadow">
        <color rgba="0.02 0.02 0.018 1" />
        </material>
      </visual>
    <visual name="slot_end_a_-0.10_-0.15">
      <origin xyz="-0.129 -0.155 0.054" rpy="0 0 0" />
      <geometry>
        <cylinder radius="0.005" length="0.0025" />
        </geometry>
      <material name="black_recess_shadow">
        <color rgba="0.02 0.02 0.018 1" />
        </material>
      </visual>
    <visual name="slot_end_b_-0.10_-0.15">
      <origin xyz="-0.071 -0.155 0.054" rpy="0 0 0" />
      <geometry>
        <cylinder radius="0.005" length="0.0025" />
        </geometry>
      <material name="black_recess_shadow">
        <color rgba="0.02 0.02 0.018 1" />
        </material>
      </visual>
    <visual name="rail_slot_+0.16_-0.15">
      <origin xyz="0.16 -0.155 0.0535" rpy="0 0 0" />
      <geometry>
        <box size="0.058 0.01 0.002" />
        </geometry>
      <material name="black_recess_shadow">
        <color rgba="0.02 0.02 0.018 1" />
        </material>
      </visual>
    <visual name="slot_end_a_+0.16_-0.15">
      <origin xyz="0.131 -0.155 0.054" rpy="0 0 0" />
      <geometry>
        <cylinder radius="0.005" length="0.0025" />
        </geometry>
      <material name="black_recess_shadow">
        <color rgba="0.02 0.02 0.018 1" />
        </material>
      </visual>
    <visual name="slot_end_b_+0.16_-0.15">
      <origin xyz="0.189 -0.155 0.054" rpy="0 0 0" />
      <geometry>
        <cylinder radius="0.005" length="0.0025" />
        </geometry>
      <material name="black_recess_shadow">
        <color rgba="0.02 0.02 0.018 1" />
        </material>
      </visual>
    <visual name="rail_slot_+0.42_-0.15">
      <origin xyz="0.42 -0.155 0.0535" rpy="0 0 0" />
      <geometry>
        <box size="0.058 0.01 0.002" />
        </geometry>
      <material name="black_recess_shadow">
        <color rgba="0.02 0.02 0.018 1" />
        </material>
      </visual>
    <visual name="slot_end_a_+0.42_-0.15">
      <origin xyz="0.391 -0.155 0.054" rpy="0 0 0" />
      <geometry>
        <cylinder radius="0.005" length="0.0025" />
        </geometry>
      <material name="black_recess_shadow">
        <color rgba="0.02 0.02 0.018 1" />
        </material>
      </visual>
    <visual name="slot_end_b_+0.42_-0.15">
      <origin xyz="0.449 -0.155 0.054" rpy="0 0 0" />
      <geometry>
        <cylinder radius="0.005" length="0.0025" />
        </geometry>
      <material name="black_recess_shadow">
        <color rgba="0.02 0.02 0.018 1" />
        </material>
      </visual>
    <visual name="rail_slot_+0.68_-0.15">
      <origin xyz="0.68 -0.155 0.0535" rpy="0 0 0" />
      <geometry>
        <box size="0.058 0.01 0.002" />
        </geometry>
      <material name="black_recess_shadow">
        <color rgba="0.02 0.02 0.018 1" />
        </material>
      </visual>
    <visual name="slot_end_a_+0.68_-0.15">
      <origin xyz="0.651 -0.155 0.054" rpy="0 0 0" />
      <geometry>
        <cylinder radius="0.005" length="0.0025" />
        </geometry>
      <material name="black_recess_shadow">
        <color rgba="0.02 0.02 0.018 1" />
        </material>
      </visual>
    <visual name="slot_end_b_+0.68_-0.15">
      <origin xyz="0.709 -0.155 0.054" rpy="0 0 0" />
      <geometry>
        <cylinder radius="0.005" length="0.0025" />
        </geometry>
      <material name="black_recess_shadow">
        <color rgba="0.02 0.02 0.018 1" />
        </material>
      </visual>
    <visual name="side_rail_+0.155">
      <origin xyz="0 0.155 0.039" rpy="0 0 0" />
      <geometry>
        <box size="1.78 0.028 0.028" />
        </geometry>
      <material name="bead_blasted_steel">
        <color rgba="0.45 0.48 0.5 1" />
        </material>
      </visual>
    <visual name="rail_slot_-0.62_+0.15">
      <origin xyz="-0.62 0.155 0.0535" rpy="0 0 0" />
      <geometry>
        <box size="0.058 0.01 0.002" />
        </geometry>
      <material name="black_recess_shadow">
        <color rgba="0.02 0.02 0.018 1" />
        </material>
      </visual>
    <visual name="slot_end_a_-0.62_+0.15">
      <origin xyz="-0.649 0.155 0.054" rpy="0 0 0" />
      <geometry>
        <cylinder radius="0.005" length="0.0025" />
        </geometry>
      <material name="black_recess_shadow">
        <color rgba="0.02 0.02 0.018 1" />
        </material>
      </visual>
    <visual name="slot_end_b_-0.62_+0.15">
      <origin xyz="-0.591 0.155 0.054" rpy="0 0 0" />
      <geometry>
        <cylinder radius="0.005" length="0.0025" />
        </geometry>
      <material name="black_recess_shadow">
        <color rgba="0.02 0.02 0.018 1" />
        </material>
      </visual>
    <visual name="rail_slot_-0.36_+0.15">
      <origin xyz="-0.36 0.155 0.0535" rpy="0 0 0" />
      <geometry>
        <box size="0.058 0.01 0.002" />
        </geometry>
      <material name="black_recess_shadow">
        <color rgba="0.02 0.02 0.018 1" />
        </material>
      </visual>
    <visual name="slot_end_a_-0.36_+0.15">
      <origin xyz="-0.389 0.155 0.054" rpy="0 0 0" />
      <geometry>
        <cylinder radius="0.005" length="0.0025" />
        </geometry>
      <material name="black_recess_shadow">
        <color rgba="0.02 0.02 0.018 1" />
        </material>
      </visual>
    <visual name="slot_end_b_-0.36_+0.15">
      <origin xyz="-0.331 0.155 0.054" rpy="0 0 0" />
      <geometry>
        <cylinder radius="0.005" length="0.0025" />
        </geometry>
      <material name="black_recess_shadow">
        <color rgba="0.02 0.02 0.018 1" />
        </material>
      </visual>
    <visual name="rail_slot_-0.10_+0.15">
      <origin xyz="-0.1 0.155 0.0535" rpy="0 0 0" />
      <geometry>
        <box size="0.058 0.01 0.002" />
        </geometry>
      <material name="black_recess_shadow">
        <color rgba="0.02 0.02 0.018 1" />
        </material>
      </visual>
    <visual name="slot_end_a_-0.10_+0.15">
      <origin xyz="-0.129 0.155 0.054" rpy="0 0 0" />
      <geometry>
        <cylinder radius="0.005" length="0.0025" />
        </geometry>
      <material name="black_recess_shadow">
        <color rgba="0.02 0.02 0.018 1" />
        </material>
      </visual>
    <visual name="slot_end_b_-0.10_+0.15">
      <origin xyz="-0.071 0.155 0.054" rpy="0 0 0" />
      <geometry>
        <cylinder radius="0.005" length="0.0025" />
        </geometry>
      <material name="black_recess_shadow">
        <color rgba="0.02 0.02 0.018 1" />
        </material>
      </visual>
    <visual name="rail_slot_+0.16_+0.15">
      <origin xyz="0.16 0.155 0.0535" rpy="0 0 0" />
      <geometry>
        <box size="0.058 0.01 0.002" />
        </geometry>
      <material name="black_recess_shadow">
        <color rgba="0.02 0.02 0.018 1" />
        </material>
      </visual>
    <visual name="slot_end_a_+0.16_+0.15">
      <origin xyz="0.131 0.155 0.054" rpy="0 0 0" />
      <geometry>
        <cylinder radius="0.005" length="0.0025" />
        </geometry>
      <material name="black_recess_shadow">
        <color rgba="0.02 0.02 0.018 1" />
        </material>
      </visual>
    <visual name="slot_end_b_+0.16_+0.15">
      <origin xyz="0.189 0.155 0.054" rpy="0 0 0" />
      <geometry>
        <cylinder radius="0.005" length="0.0025" />
        </geometry>
      <material name="black_recess_shadow">
        <color rgba="0.02 0.02 0.018 1" />
        </material>
      </visual>
    <visual name="rail_slot_+0.42_+0.15">
      <origin xyz="0.42 0.155 0.0535" rpy="0 0 0" />
      <geometry>
        <box size="0.058 0.01 0.002" />
        </geometry>
      <material name="black_recess_shadow">
        <color rgba="0.02 0.02 0.018 1" />
        </material>
      </visual>
    <visual name="slot_end_a_+0.42_+0.15">
      <origin xyz="0.391 0.155 0.054" rpy="0 0 0" />
      <geometry>
        <cylinder radius="0.005" length="0.0025" />
        </geometry>
      <material name="black_recess_shadow">
        <color rgba="0.02 0.02 0.018 1" />
        </material>
      </visual>
    <visual name="slot_end_b_+0.42_+0.15">
      <origin xyz="0.449 0.155 0.054" rpy="0 0 0" />
      <geometry>
        <cylinder radius="0.005" length="0.0025" />
        </geometry>
      <material name="black_recess_shadow">
        <color rgba="0.02 0.02 0.018 1" />
        </material>
      </visual>
    <visual name="rail_slot_+0.68_+0.15">
      <origin xyz="0.68 0.155 0.0535" rpy="0 0 0" />
      <geometry>
        <box size="0.058 0.01 0.002" />
        </geometry>
      <material name="black_recess_shadow">
        <color rgba="0.02 0.02 0.018 1" />
        </material>
      </visual>
    <visual name="slot_end_a_+0.68_+0.15">
      <origin xyz="0.651 0.155 0.054" rpy="0 0 0" />
      <geometry>
        <cylinder radius="0.005" length="0.0025" />
        </geometry>
      <material name="black_recess_shadow">
        <color rgba="0.02 0.02 0.018 1" />
        </material>
      </visual>
    <visual name="slot_end_b_+0.68_+0.15">
      <origin xyz="0.709 0.155 0.054" rpy="0 0 0" />
      <geometry>
        <cylinder radius="0.005" length="0.0025" />
        </geometry>
      <material name="black_recess_shadow">
        <color rgba="0.02 0.02 0.018 1" />
        </material>
      </visual>
    <visual name="cross_tie_-0.55">
      <origin xyz="-0.55 0 0.034" rpy="0 0 0" />
      <geometry>
        <box size="0.045 0.315 0.018" />
        </geometry>
      <material name="bead_blasted_steel">
        <color rgba="0.45 0.48 0.5 1" />
        </material>
      </visual>
    <visual name="cross_tie_-0.18">
      <origin xyz="-0.18 0 0.034" rpy="0 0 0" />
      <geometry>
        <box size="0.045 0.315 0.018" />
        </geometry>
      <material name="bead_blasted_steel">
        <color rgba="0.45 0.48 0.5 1" />
        </material>
      </visual>
    <visual name="cross_tie_+0.24">
      <origin xyz="0.24 0 0.034" rpy="0 0 0" />
      <geometry>
        <box size="0.045 0.315 0.018" />
        </geometry>
      <material name="bead_blasted_steel">
        <color rgba="0.45 0.48 0.5 1" />
        </material>
      </visual>
    <visual name="cross_tie_+0.68">
      <origin xyz="0.68 0 0.034" rpy="0 0 0" />
      <geometry>
        <box size="0.045 0.315 0.018" />
        </geometry>
      <material name="bead_blasted_steel">
        <color rgba="0.45 0.48 0.5 1" />
        </material>
      </visual>
    <visual name="input_lever_cheek_-0.05">
      <origin xyz="-0.55 -0.05 0.114" rpy="0 0 0" />
      <geometry>
        <box size="0.086 0.014 0.18" />
        </geometry>
      <material name="bead_blasted_steel">
        <color rgba="0.45 0.48 0.5 1" />
        </material>
      </visual>
    <visual name="input_lever_outer_bushing_-0.05">
      <origin xyz="-0.55 -0.0615 0.13" rpy="1.5708 0 0" />
      <geometry>
        <cylinder radius="0.027" length="0.012" />
        </geometry>
      <material name="oilite_bronze_bushings">
        <color rgba="0.72 0.52 0.26 1" />
        </material>
      </visual>
    <visual name="input_lever_bore_shadow_-0.05">
      <origin xyz="-0.55 -0.0685 0.13" rpy="1.5708 0 0" />
      <geometry>
        <cylinder radius="0.01" length="0.002" />
        </geometry>
      <material name="black_recess_shadow">
        <color rgba="0.02 0.02 0.018 1" />
        </material>
      </visual>
    <visual name="input_lever_cheek_+0.05">
      <origin xyz="-0.55 0.05 0.114" rpy="0 0 0" />
      <geometry>
        <box size="0.086 0.014 0.18" />
        </geometry>
      <material name="bead_blasted_steel">
        <color rgba="0.45 0.48 0.5 1" />
        </material>
      </visual>
    <visual name="input_lever_outer_bushing_+0.05">
      <origin xyz="-0.55 0.0615 0.13" rpy="1.5708 0 0" />
      <geometry>
        <cylinder radius="0.027" length="0.012" />
        </geometry>
      <material name="oilite_bronze_bushings">
        <color rgba="0.72 0.52 0.26 1" />
        </material>
      </visual>
    <visual name="input_lever_bore_shadow_+0.05">
      <origin xyz="-0.55 0.0685 0.13" rpy="1.5708 0 0" />
      <geometry>
        <cylinder radius="0.01" length="0.002" />
        </geometry>
      <material name="black_recess_shadow">
        <color rgba="0.02 0.02 0.018 1" />
        </material>
      </visual>
    <visual name="input_lever_rear_web">
      <origin xyz="-0.606 0 0.066" rpy="0 0 0" />
      <geometry>
        <box size="0.018 0.112 0.09" />
        </geometry>
      <material name="bead_blasted_steel">
        <color rgba="0.45 0.48 0.5 1" />
        </material>
      </visual>
    <visual name="input_lever_base_bolt_-0.58_-0.07">
      <origin xyz="-0.577 -0.073 0.028" rpy="0 0 0" />
      <geometry>
        <cylinder radius="0.006" length="0.006" />
        </geometry>
      <material name="bead_blasted_steel">
        <color rgba="0.45 0.48 0.5 1" />
        </material>
      </visual>
    <visual name="input_lever_base_bolt_-0.58_+0.07">
      <origin xyz="-0.577 0.073 0.028" rpy="0 0 0" />
      <geometry>
        <cylinder radius="0.006" length="0.006" />
        </geometry>
      <material name="bead_blasted_steel">
        <color rgba="0.45 0.48 0.5 1" />
        </material>
      </visual>
    <visual name="input_lever_base_bolt_-0.52_-0.07">
      <origin xyz="-0.523 -0.073 0.028" rpy="0 0 0" />
      <geometry>
        <cylinder radius="0.006" length="0.006" />
        </geometry>
      <material name="bead_blasted_steel">
        <color rgba="0.45 0.48 0.5 1" />
        </material>
      </visual>
    <visual name="input_lever_base_bolt_-0.52_+0.07">
      <origin xyz="-0.523 0.073 0.028" rpy="0 0 0" />
      <geometry>
        <cylinder radius="0.006" length="0.006" />
        </geometry>
      <material name="bead_blasted_steel">
        <color rgba="0.45 0.48 0.5 1" />
        </material>
      </visual>
    <visual name="rocker_0_cheek_-0.05">
      <origin xyz="-0.18 -0.05 0.159" rpy="0 0 0" />
      <geometry>
        <box size="0.086 0.014 0.27" />
        </geometry>
      <material name="bead_blasted_steel">
        <color rgba="0.45 0.48 0.5 1" />
        </material>
      </visual>
    <visual name="rocker_0_outer_bushing_-0.05">
      <origin xyz="-0.18 -0.0615 0.22" rpy="1.5708 0 0" />
      <geometry>
        <cylinder radius="0.027" length="0.012" />
        </geometry>
      <material name="oilite_bronze_bushings">
        <color rgba="0.72 0.52 0.26 1" />
        </material>
      </visual>
    <visual name="rocker_0_bore_shadow_-0.05">
      <origin xyz="-0.18 -0.0685 0.22" rpy="1.5708 0 0" />
      <geometry>
        <cylinder radius="0.01" length="0.002" />
        </geometry>
      <material name="black_recess_shadow">
        <color rgba="0.02 0.02 0.018 1" />
        </material>
      </visual>
    <visual name="rocker_0_cheek_+0.05">
      <origin xyz="-0.18 0.05 0.159" rpy="0 0 0" />
      <geometry>
        <box size="0.086 0.014 0.27" />
        </geometry>
      <material name="bead_blasted_steel">
        <color rgba="0.45 0.48 0.5 1" />
        </material>
      </visual>
    <visual name="rocker_0_outer_bushing_+0.05">
      <origin xyz="-0.18 0.0615 0.22" rpy="1.5708 0 0" />
      <geometry>
        <cylinder radius="0.027" length="0.012" />
        </geometry>
      <material name="oilite_bronze_bushings">
        <color rgba="0.72 0.52 0.26 1" />
        </material>
      </visual>
    <visual name="rocker_0_bore_shadow_+0.05">
      <origin xyz="-0.18 0.0685 0.22" rpy="1.5708 0 0" />
      <geometry>
        <cylinder radius="0.01" length="0.002" />
        </geometry>
      <material name="black_recess_shadow">
        <color rgba="0.02 0.02 0.018 1" />
        </material>
      </visual>
    <visual name="rocker_0_rear_web">
      <origin xyz="-0.236 0 0.066" rpy="0 0 0" />
      <geometry>
        <box size="0.018 0.112 0.09" />
        </geometry>
      <material name="bead_blasted_steel">
        <color rgba="0.45 0.48 0.5 1" />
        </material>
      </visual>
    <visual name="rocker_0_base_bolt_-0.21_-0.07">
      <origin xyz="-0.207 -0.073 0.028" rpy="0 0 0" />
      <geometry>
        <cylinder radius="0.006" length="0.006" />
        </geometry>
      <material name="bead_blasted_steel">
        <color rgba="0.45 0.48 0.5 1" />
        </material>
      </visual>
    <visual name="rocker_0_base_bolt_-0.21_+0.07">
      <origin xyz="-0.207 0.073 0.028" rpy="0 0 0" />
      <geometry>
        <cylinder radius="0.006" length="0.006" />
        </geometry>
      <material name="bead_blasted_steel">
        <color rgba="0.45 0.48 0.5 1" />
        </material>
      </visual>
    <visual name="rocker_0_base_bolt_-0.15_-0.07">
      <origin xyz="-0.153 -0.073 0.028" rpy="0 0 0" />
      <geometry>
        <cylinder radius="0.006" length="0.006" />
        </geometry>
      <material name="bead_blasted_steel">
        <color rgba="0.45 0.48 0.5 1" />
        </material>
      </visual>
    <visual name="rocker_0_base_bolt_-0.15_+0.07">
      <origin xyz="-0.153 0.073 0.028" rpy="0 0 0" />
      <geometry>
        <cylinder radius="0.006" length="0.006" />
        </geometry>
      <material name="bead_blasted_steel">
        <color rgba="0.45 0.48 0.5 1" />
        </material>
      </visual>
    <visual name="rocker_1_cheek_-0.05">
      <origin xyz="0.24 -0.05 0.1265" rpy="0 0 0" />
      <geometry>
        <box size="0.086 0.014 0.205" />
        </geometry>
      <material name="bead_blasted_steel">
        <color rgba="0.45 0.48 0.5 1" />
        </material>
      </visual>
    <visual name="rocker_1_outer_bushing_-0.05">
      <origin xyz="0.24 -0.0615 0.155" rpy="1.5708 0 0" />
      <geometry>
        <cylinder radius="0.027" length="0.012" />
        </geometry>
      <material name="oilite_bronze_bushings">
        <color rgba="0.72 0.52 0.26 1" />
        </material>
      </visual>
    <visual name="rocker_1_bore_shadow_-0.05">
      <origin xyz="0.24 -0.0685 0.155" rpy="1.5708 0 0" />
      <geometry>
        <cylinder radius="0.01" length="0.002" />
        </geometry>
      <material name="black_recess_shadow">
        <color rgba="0.02 0.02 0.018 1" />
        </material>
      </visual>
    <visual name="rocker_1_cheek_+0.05">
      <origin xyz="0.24 0.05 0.1265" rpy="0 0 0" />
      <geometry>
        <box size="0.086 0.014 0.205" />
        </geometry>
      <material name="bead_blasted_steel">
        <color rgba="0.45 0.48 0.5 1" />
        </material>
      </visual>
    <visual name="rocker_1_outer_bushing_+0.05">
      <origin xyz="0.24 0.0615 0.155" rpy="1.5708 0 0" />
      <geometry>
        <cylinder radius="0.027" length="0.012" />
        </geometry>
      <material name="oilite_bronze_bushings">
        <color rgba="0.72 0.52 0.26 1" />
        </material>
      </visual>
    <visual name="rocker_1_bore_shadow_+0.05">
      <origin xyz="0.24 0.0685 0.155" rpy="1.5708 0 0" />
      <geometry>
        <cylinder radius="0.01" length="0.002" />
        </geometry>
      <material name="black_recess_shadow">
        <color rgba="0.02 0.02 0.018 1" />
        </material>
      </visual>
    <visual name="rocker_1_rear_web">
      <origin xyz="0.184 0 0.066" rpy="0 0 0" />
      <geometry>
        <box size="0.018 0.112 0.09" />
        </geometry>
      <material name="bead_blasted_steel">
        <color rgba="0.45 0.48 0.5 1" />
        </material>
      </visual>
    <visual name="rocker_1_base_bolt_+0.21_-0.07">
      <origin xyz="0.213 -0.073 0.028" rpy="0 0 0" />
      <geometry>
        <cylinder radius="0.006" length="0.006" />
        </geometry>
      <material name="bead_blasted_steel">
        <color rgba="0.45 0.48 0.5 1" />
        </material>
      </visual>
    <visual name="rocker_1_base_bolt_+0.21_+0.07">
      <origin xyz="0.213 0.073 0.028" rpy="0 0 0" />
      <geometry>
        <cylinder radius="0.006" length="0.006" />
        </geometry>
      <material name="bead_blasted_steel">
        <color rgba="0.45 0.48 0.5 1" />
        </material>
      </visual>
    <visual name="rocker_1_base_bolt_+0.27_-0.07">
      <origin xyz="0.267 -0.073 0.028" rpy="0 0 0" />
      <geometry>
        <cylinder radius="0.006" length="0.006" />
        </geometry>
      <material name="bead_blasted_steel">
        <color rgba="0.45 0.48 0.5 1" />
        </material>
      </visual>
    <visual name="rocker_1_base_bolt_+0.27_+0.07">
      <origin xyz="0.267 0.073 0.028" rpy="0 0 0" />
      <geometry>
        <cylinder radius="0.006" length="0.006" />
        </geometry>
      <material name="bead_blasted_steel">
        <color rgba="0.45 0.48 0.5 1" />
        </material>
      </visual>
    <visual name="output_lever_cheek_-0.05">
      <origin xyz="0.68 -0.05 0.1515" rpy="0 0 0" />
      <geometry>
        <box size="0.086 0.014 0.255" />
        </geometry>
      <material name="bead_blasted_steel">
        <color rgba="0.45 0.48 0.5 1" />
        </material>
      </visual>
    <visual name="output_lever_outer_bushing_-0.05">
      <origin xyz="0.68 -0.0615 0.205" rpy="1.5708 0 0" />
      <geometry>
        <cylinder radius="0.027" length="0.012" />
        </geometry>
      <material name="oilite_bronze_bushings">
        <color rgba="0.72 0.52 0.26 1" />
        </material>
      </visual>
    <visual name="output_lever_bore_shadow_-0.05">
      <origin xyz="0.68 -0.0685 0.205" rpy="1.5708 0 0" />
      <geometry>
        <cylinder radius="0.01" length="0.002" />
        </geometry>
      <material name="black_recess_shadow">
        <color rgba="0.02 0.02 0.018 1" />
        </material>
      </visual>
    <visual name="output_lever_cheek_+0.05">
      <origin xyz="0.68 0.05 0.1515" rpy="0 0 0" />
      <geometry>
        <box size="0.086 0.014 0.255" />
        </geometry>
      <material name="bead_blasted_steel">
        <color rgba="0.45 0.48 0.5 1" />
        </material>
      </visual>
    <visual name="output_lever_outer_bushing_+0.05">
      <origin xyz="0.68 0.0615 0.205" rpy="1.5708 0 0" />
      <geometry>
        <cylinder radius="0.027" length="0.012" />
        </geometry>
      <material name="oilite_bronze_bushings">
        <color rgba="0.72 0.52 0.26 1" />
        </material>
      </visual>
    <visual name="output_lever_bore_shadow_+0.05">
      <origin xyz="0.68 0.0685 0.205" rpy="1.5708 0 0" />
      <geometry>
        <cylinder radius="0.01" length="0.002" />
        </geometry>
      <material name="black_recess_shadow">
        <color rgba="0.02 0.02 0.018 1" />
        </material>
      </visual>
    <visual name="output_lever_rear_web">
      <origin xyz="0.624 0 0.066" rpy="0 0 0" />
      <geometry>
        <box size="0.018 0.112 0.09" />
        </geometry>
      <material name="bead_blasted_steel">
        <color rgba="0.45 0.48 0.5 1" />
        </material>
      </visual>
    <visual name="output_lever_base_bolt_+0.65_-0.07">
      <origin xyz="0.653 -0.073 0.028" rpy="0 0 0" />
      <geometry>
        <cylinder radius="0.006" length="0.006" />
        </geometry>
      <material name="bead_blasted_steel">
        <color rgba="0.45 0.48 0.5 1" />
        </material>
      </visual>
    <visual name="output_lever_base_bolt_+0.65_+0.07">
      <origin xyz="0.653 0.073 0.028" rpy="0 0 0" />
      <geometry>
        <cylinder radius="0.006" length="0.006" />
        </geometry>
      <material name="bead_blasted_steel">
        <color rgba="0.45 0.48 0.5 1" />
        </material>
      </visual>
    <visual name="output_lever_base_bolt_+0.71_-0.07">
      <origin xyz="0.707 -0.073 0.028" rpy="0 0 0" />
      <geometry>
        <cylinder radius="0.006" length="0.006" />
        </geometry>
      <material name="bead_blasted_steel">
        <color rgba="0.45 0.48 0.5 1" />
        </material>
      </visual>
    <visual name="output_lever_base_bolt_+0.71_+0.07">
      <origin xyz="0.707 0.073 0.028" rpy="0 0 0" />
      <geometry>
        <cylinder radius="0.006" length="0.006" />
        </geometry>
      <material name="bead_blasted_steel">
        <color rgba="0.45 0.48 0.5 1" />
        </material>
      </visual>
    <visual name="stop_pad_0">
      <origin xyz="-0.42 -0.095 0.034" rpy="0 0 0.20944" />
      <geometry>
        <box size="0.07 0.026 0.018" />
        </geometry>
      <material name="matte_black_stop_pads">
        <color rgba="0.01 0.011 0.01 1" />
        </material>
      </visual>
    <visual name="stop_pad_1">
      <origin xyz="-0.05 0.105 0.034" rpy="0 0 -0.174533" />
      <geometry>
        <box size="0.07 0.026 0.018" />
        </geometry>
      <material name="matte_black_stop_pads">
        <color rgba="0.01 0.011 0.01 1" />
        </material>
      </visual>
    <visual name="stop_pad_2">
      <origin xyz="0.36 -0.1 0.034" rpy="0 0 0.279253" />
      <geometry>
        <box size="0.07 0.026 0.018" />
        </geometry>
      <material name="matte_black_stop_pads">
        <color rgba="0.01 0.011 0.01 1" />
        </material>
      </visual>
    <visual name="stop_pad_3">
      <origin xyz="0.78 0.095 0.034" rpy="0 0 -0.244346" />
      <geometry>
        <box size="0.07 0.026 0.018" />
        </geometry>
      <material name="matte_black_stop_pads">
        <color rgba="0.01 0.011 0.01 1" />
        </material>
      </visual>
    <visual name="cover_standoff_-0.36_-0.10_-0.03">
      <origin xyz="-0.465 -0.14 0.053" rpy="0 0 0" />
      <geometry>
        <cylinder radius="0.01" length="0.056" />
        </geometry>
      <material name="bead_blasted_steel">
        <color rgba="0.45 0.48 0.5 1" />
        </material>
      </visual>
    <visual name="cover_standoff_-0.36_-0.10_+0.03">
      <origin xyz="-0.465 -0.08 0.053" rpy="0 0 0" />
      <geometry>
        <cylinder radius="0.01" length="0.056" />
        </geometry>
      <material name="bead_blasted_steel">
        <color rgba="0.45 0.48 0.5 1" />
        </material>
      </visual>
    <visual name="cover_standoff_-0.36_+0.10_-0.03">
      <origin xyz="-0.255 -0.14 0.053" rpy="0 0 0" />
      <geometry>
        <cylinder radius="0.01" length="0.056" />
        </geometry>
      <material name="bead_blasted_steel">
        <color rgba="0.45 0.48 0.5 1" />
        </material>
      </visual>
    <visual name="cover_standoff_-0.36_+0.10_+0.03">
      <origin xyz="-0.255 -0.08 0.053" rpy="0 0 0" />
      <geometry>
        <cylinder radius="0.01" length="0.056" />
        </geometry>
      <material name="bead_blasted_steel">
        <color rgba="0.45 0.48 0.5 1" />
        </material>
      </visual>
    <visual name="cover_standoff_+0.36_-0.10_-0.03">
      <origin xyz="0.255 -0.14 0.053" rpy="0 0 0" />
      <geometry>
        <cylinder radius="0.01" length="0.056" />
        </geometry>
      <material name="bead_blasted_steel">
        <color rgba="0.45 0.48 0.5 1" />
        </material>
      </visual>
    <visual name="cover_standoff_+0.36_-0.10_+0.03">
      <origin xyz="0.255 -0.08 0.053" rpy="0 0 0" />
      <geometry>
        <cylinder radius="0.01" length="0.056" />
        </geometry>
      <material name="bead_blasted_steel">
        <color rgba="0.45 0.48 0.5 1" />
        </material>
      </visual>
    <visual name="cover_standoff_+0.36_+0.10_-0.03">
      <origin xyz="0.465 -0.14 0.053" rpy="0 0 0" />
      <geometry>
        <cylinder radius="0.01" length="0.056" />
        </geometry>
      <material name="bead_blasted_steel">
        <color rgba="0.45 0.48 0.5 1" />
        </material>
      </visual>
    <visual name="cover_standoff_+0.36_+0.10_+0.03">
      <origin xyz="0.465 -0.08 0.053" rpy="0 0 0" />
      <geometry>
        <cylinder radius="0.01" length="0.056" />
        </geometry>
      <material name="bead_blasted_steel">
        <color rgba="0.45 0.48 0.5 1" />
        </material>
      </visual>
    <collision name="ground_plate">
      <origin xyz="0 0 0.0125" rpy="0 0 0" />
      <geometry>
        <box size="1.9 0.36 0.025" />
        </geometry>
      </collision>
    <collision name="side_rail_-0.155">
      <origin xyz="0 -0.155 0.039" rpy="0 0 0" />
      <geometry>
        <box size="1.78 0.028 0.028" />
        </geometry>
      </collision>
    <collision name="rail_slot_-0.62_-0.15">
      <origin xyz="-0.62 -0.155 0.0535" rpy="0 0 0" />
      <geometry>
        <box size="0.058 0.01 0.002" />
        </geometry>
      </collision>
    <collision name="slot_end_a_-0.62_-0.15">
      <origin xyz="-0.649 -0.155 0.054" rpy="0 0 0" />
      <geometry>
        <cylinder radius="0.005" length="0.0025" />
        </geometry>
      </collision>
    <collision name="slot_end_b_-0.62_-0.15">
      <origin xyz="-0.591 -0.155 0.054" rpy="0 0 0" />
      <geometry>
        <cylinder radius="0.005" length="0.0025" />
        </geometry>
      </collision>
    <collision name="rail_slot_-0.36_-0.15">
      <origin xyz="-0.36 -0.155 0.0535" rpy="0 0 0" />
      <geometry>
        <box size="0.058 0.01 0.002" />
        </geometry>
      </collision>
    <collision name="slot_end_a_-0.36_-0.15">
      <origin xyz="-0.389 -0.155 0.054" rpy="0 0 0" />
      <geometry>
        <cylinder radius="0.005" length="0.0025" />
        </geometry>
      </collision>
    <collision name="slot_end_b_-0.36_-0.15">
      <origin xyz="-0.331 -0.155 0.054" rpy="0 0 0" />
      <geometry>
        <cylinder radius="0.005" length="0.0025" />
        </geometry>
      </collision>
    <collision name="rail_slot_-0.10_-0.15">
      <origin xyz="-0.1 -0.155 0.0535" rpy="0 0 0" />
      <geometry>
        <box size="0.058 0.01 0.002" />
        </geometry>
      </collision>
    <collision name="slot_end_a_-0.10_-0.15">
      <origin xyz="-0.129 -0.155 0.054" rpy="0 0 0" />
      <geometry>
        <cylinder radius="0.005" length="0.0025" />
        </geometry>
      </collision>
    <collision name="slot_end_b_-0.10_-0.15">
      <origin xyz="-0.071 -0.155 0.054" rpy="0 0 0" />
      <geometry>
        <cylinder radius="0.005" length="0.0025" />
        </geometry>
      </collision>
    <collision name="rail_slot_+0.16_-0.15">
      <origin xyz="0.16 -0.155 0.0535" rpy="0 0 0" />
      <geometry>
        <box size="0.058 0.01 0.002" />
        </geometry>
      </collision>
    <collision name="slot_end_a_+0.16_-0.15">
      <origin xyz="0.131 -0.155 0.054" rpy="0 0 0" />
      <geometry>
        <cylinder radius="0.005" length="0.0025" />
        </geometry>
      </collision>
    <collision name="slot_end_b_+0.16_-0.15">
      <origin xyz="0.189 -0.155 0.054" rpy="0 0 0" />
      <geometry>
        <cylinder radius="0.005" length="0.0025" />
        </geometry>
      </collision>
    <collision name="rail_slot_+0.42_-0.15">
      <origin xyz="0.42 -0.155 0.0535" rpy="0 0 0" />
      <geometry>
        <box size="0.058 0.01 0.002" />
        </geometry>
      </collision>
    <collision name="slot_end_a_+0.42_-0.15">
      <origin xyz="0.391 -0.155 0.054" rpy="0 0 0" />
      <geometry>
        <cylinder radius="0.005" length="0.0025" />
        </geometry>
      </collision>
    <collision name="slot_end_b_+0.42_-0.15">
      <origin xyz="0.449 -0.155 0.054" rpy="0 0 0" />
      <geometry>
        <cylinder radius="0.005" length="0.0025" />
        </geometry>
      </collision>
    <collision name="rail_slot_+0.68_-0.15">
      <origin xyz="0.68 -0.155 0.0535" rpy="0 0 0" />
      <geometry>
        <box size="0.058 0.01 0.002" />
        </geometry>
      </collision>
    <collision name="slot_end_a_+0.68_-0.15">
      <origin xyz="0.651 -0.155 0.054" rpy="0 0 0" />
      <geometry>
        <cylinder radius="0.005" length="0.0025" />
        </geometry>
      </collision>
    <collision name="slot_end_b_+0.68_-0.15">
      <origin xyz="0.709 -0.155 0.054" rpy="0 0 0" />
      <geometry>
        <cylinder radius="0.005" length="0.0025" />
        </geometry>
      </collision>
    <collision name="side_rail_+0.155">
      <origin xyz="0 0.155 0.039" rpy="0 0 0" />
      <geometry>
        <box size="1.78 0.028 0.028" />
        </geometry>
      </collision>
    <collision name="rail_slot_-0.62_+0.15">
      <origin xyz="-0.62 0.155 0.0535" rpy="0 0 0" />
      <geometry>
        <box size="0.058 0.01 0.002" />
        </geometry>
      </collision>
    <collision name="slot_end_a_-0.62_+0.15">
      <origin xyz="-0.649 0.155 0.054" rpy="0 0 0" />
      <geometry>
        <cylinder radius="0.005" length="0.0025" />
        </geometry>
      </collision>
    <collision name="slot_end_b_-0.62_+0.15">
      <origin xyz="-0.591 0.155 0.054" rpy="0 0 0" />
      <geometry>
        <cylinder radius="0.005" length="0.0025" />
        </geometry>
      </collision>
    <collision name="rail_slot_-0.36_+0.15">
      <origin xyz="-0.36 0.155 0.0535" rpy="0 0 0" />
      <geometry>
        <box size="0.058 0.01 0.002" />
        </geometry>
      </collision>
    <collision name="slot_end_a_-0.36_+0.15">
      <origin xyz="-0.389 0.155 0.054" rpy="0 0 0" />
      <geometry>
        <cylinder radius="0.005" length="0.0025" />
        </geometry>
      </collision>
    <collision name="slot_end_b_-0.36_+0.15">
      <origin xyz="-0.331 0.155 0.054" rpy="0 0 0" />
      <geometry>
        <cylinder radius="0.005" length="0.0025" />
        </geometry>
      </collision>
    <collision name="rail_slot_-0.10_+0.15">
      <origin xyz="-0.1 0.155 0.0535" rpy="0 0 0" />
      <geometry>
        <box size="0.058 0.01 0.002" />
        </geometry>
      </collision>
    <collision name="slot_end_a_-0.10_+0.15">
      <origin xyz="-0.129 0.155 0.054" rpy="0 0 0" />
      <geometry>
        <cylinder radius="0.005" length="0.0025" />
        </geometry>
      </collision>
    <collision name="slot_end_b_-0.10_+0.15">
      <origin xyz="-0.071 0.155 0.054" rpy="0 0 0" />
      <geometry>
        <cylinder radius="0.005" length="0.0025" />
        </geometry>
      </collision>
    <collision name="rail_slot_+0.16_+0.15">
      <origin xyz="0.16 0.155 0.0535" rpy="0 0 0" />
      <geometry>
        <box size="0.058 0.01 0.002" />
        </geometry>
      </collision>
    <collision name="slot_end_a_+0.16_+0.15">
      <origin xyz="0.131 0.155 0.054" rpy="0 0 0" />
      <geometry>
        <cylinder radius="0.005" length="0.0025" />
        </geometry>
      </collision>
    <collision name="slot_end_b_+0.16_+0.15">
      <origin xyz="0.189 0.155 0.054" rpy="0 0 0" />
      <geometry>
        <cylinder radius="0.005" length="0.0025" />
        </geometry>
      </collision>
    <collision name="rail_slot_+0.42_+0.15">
      <origin xyz="0.42 0.155 0.0535" rpy="0 0 0" />
      <geometry>
        <box size="0.058 0.01 0.002" />
        </geometry>
      </collision>
    <collision name="slot_end_a_+0.42_+0.15">
      <origin xyz="0.391 0.155 0.054" rpy="0 0 0" />
      <geometry>
        <cylinder radius="0.005" length="0.0025" />
        </geometry>
      </collision>
    <collision name="slot_end_b_+0.42_+0.15">
      <origin xyz="0.449 0.155 0.054" rpy="0 0 0" />
      <geometry>
        <cylinder radius="0.005" length="0.0025" />
        </geometry>
      </collision>
    <collision name="rail_slot_+0.68_+0.15">
      <origin xyz="0.68 0.155 0.0535" rpy="0 0 0" />
      <geometry>
        <box size="0.058 0.01 0.002" />
        </geometry>
      </collision>
    <collision name="slot_end_a_+0.68_+0.15">
      <origin xyz="0.651 0.155 0.054" rpy="0 0 0" />
      <geometry>
        <cylinder radius="0.005" length="0.0025" />
        </geometry>
      </collision>
    <collision name="slot_end_b_+0.68_+0.15">
      <origin xyz="0.709 0.155 0.054" rpy="0 0 0" />
      <geometry>
        <cylinder radius="0.005" length="0.0025" />
        </geometry>
      </collision>
    <collision name="cross_tie_-0.55">
      <origin xyz="-0.55 0 0.034" rpy="0 0 0" />
      <geometry>
        <box size="0.045 0.315 0.018" />
        </geometry>
      </collision>
    <collision name="cross_tie_-0.18">
      <origin xyz="-0.18 0 0.034" rpy="0 0 0" />
      <geometry>
        <box size="0.045 0.315 0.018" />
        </geometry>
      </collision>
    <collision name="cross_tie_+0.24">
      <origin xyz="0.24 0 0.034" rpy="0 0 0" />
      <geometry>
        <box size="0.045 0.315 0.018" />
        </geometry>
      </collision>
    <collision name="cross_tie_+0.68">
      <origin xyz="0.68 0 0.034" rpy="0 0 0" />
      <geometry>
        <box size="0.045 0.315 0.018" />
        </geometry>
      </collision>
    <collision name="input_lever_cheek_-0.05">
      <origin xyz="-0.55 -0.05 0.114" rpy="0 0 0" />
      <geometry>
        <box size="0.086 0.014 0.18" />
        </geometry>
      </collision>
    <collision name="input_lever_outer_bushing_-0.05">
      <origin xyz="-0.55 -0.0615 0.13" rpy="1.5708 0 0" />
      <geometry>
        <cylinder radius="0.027" length="0.012" />
        </geometry>
      </collision>
    <collision name="input_lever_bore_shadow_-0.05">
      <origin xyz="-0.55 -0.0685 0.13" rpy="1.5708 0 0" />
      <geometry>
        <cylinder radius="0.01" length="0.002" />
        </geometry>
      </collision>
    <collision name="input_lever_cheek_+0.05">
      <origin xyz="-0.55 0.05 0.114" rpy="0 0 0" />
      <geometry>
        <box size="0.086 0.014 0.18" />
        </geometry>
      </collision>
    <collision name="input_lever_outer_bushing_+0.05">
      <origin xyz="-0.55 0.0615 0.13" rpy="1.5708 0 0" />
      <geometry>
        <cylinder radius="0.027" length="0.012" />
        </geometry>
      </collision>
    <collision name="input_lever_bore_shadow_+0.05">
      <origin xyz="-0.55 0.0685 0.13" rpy="1.5708 0 0" />
      <geometry>
        <cylinder radius="0.01" length="0.002" />
        </geometry>
      </collision>
    <collision name="input_lever_rear_web">
      <origin xyz="-0.606 0 0.066" rpy="0 0 0" />
      <geometry>
        <box size="0.018 0.112 0.09" />
        </geometry>
      </collision>
    <collision name="input_lever_base_bolt_-0.58_-0.07">
      <origin xyz="-0.577 -0.073 0.028" rpy="0 0 0" />
      <geometry>
        <cylinder radius="0.006" length="0.006" />
        </geometry>
      </collision>
    <collision name="input_lever_base_bolt_-0.58_+0.07">
      <origin xyz="-0.577 0.073 0.028" rpy="0 0 0" />
      <geometry>
        <cylinder radius="0.006" length="0.006" />
        </geometry>
      </collision>
    <collision name="input_lever_base_bolt_-0.52_-0.07">
      <origin xyz="-0.523 -0.073 0.028" rpy="0 0 0" />
      <geometry>
        <cylinder radius="0.006" length="0.006" />
        </geometry>
      </collision>
    <collision name="input_lever_base_bolt_-0.52_+0.07">
      <origin xyz="-0.523 0.073 0.028" rpy="0 0 0" />
      <geometry>
        <cylinder radius="0.006" length="0.006" />
        </geometry>
      </collision>
    <collision name="rocker_0_cheek_-0.05">
      <origin xyz="-0.18 -0.05 0.159" rpy="0 0 0" />
      <geometry>
        <box size="0.086 0.014 0.27" />
        </geometry>
      </collision>
    <collision name="rocker_0_outer_bushing_-0.05">
      <origin xyz="-0.18 -0.0615 0.22" rpy="1.5708 0 0" />
      <geometry>
        <cylinder radius="0.027" length="0.012" />
        </geometry>
      </collision>
    <collision name="rocker_0_bore_shadow_-0.05">
      <origin xyz="-0.18 -0.0685 0.22" rpy="1.5708 0 0" />
      <geometry>
        <cylinder radius="0.01" length="0.002" />
        </geometry>
      </collision>
    <collision name="rocker_0_cheek_+0.05">
      <origin xyz="-0.18 0.05 0.159" rpy="0 0 0" />
      <geometry>
        <box size="0.086 0.014 0.27" />
        </geometry>
      </collision>
    <collision name="rocker_0_outer_bushing_+0.05">
      <origin xyz="-0.18 0.0615 0.22" rpy="1.5708 0 0" />
      <geometry>
        <cylinder radius="0.027" length="0.012" />
        </geometry>
      </collision>
    <collision name="rocker_0_bore_shadow_+0.05">
      <origin xyz="-0.18 0.0685 0.22" rpy="1.5708 0 0" />
      <geometry>
        <cylinder radius="0.01" length="0.002" />
        </geometry>
      </collision>
    <collision name="rocker_0_rear_web">
      <origin xyz="-0.236 0 0.066" rpy="0 0 0" />
      <geometry>
        <box size="0.018 0.112 0.09" />
        </geometry>
      </collision>
    <collision name="rocker_0_base_bolt_-0.21_-0.07">
      <origin xyz="-0.207 -0.073 0.028" rpy="0 0 0" />
      <geometry>
        <cylinder radius="0.006" length="0.006" />
        </geometry>
      </collision>
    <collision name="rocker_0_base_bolt_-0.21_+0.07">
      <origin xyz="-0.207 0.073 0.028" rpy="0 0 0" />
      <geometry>
        <cylinder radius="0.006" length="0.006" />
        </geometry>
      </collision>
    <collision name="rocker_0_base_bolt_-0.15_-0.07">
      <origin xyz="-0.153 -0.073 0.028" rpy="0 0 0" />
      <geometry>
        <cylinder radius="0.006" length="0.006" />
        </geometry>
      </collision>
    <collision name="rocker_0_base_bolt_-0.15_+0.07">
      <origin xyz="-0.153 0.073 0.028" rpy="0 0 0" />
      <geometry>
        <cylinder radius="0.006" length="0.006" />
        </geometry>
      </collision>
    <collision name="rocker_1_cheek_-0.05">
      <origin xyz="0.24 -0.05 0.1265" rpy="0 0 0" />
      <geometry>
        <box size="0.086 0.014 0.205" />
        </geometry>
      </collision>
    <collision name="rocker_1_outer_bushing_-0.05">
      <origin xyz="0.24 -0.0615 0.155" rpy="1.5708 0 0" />
      <geometry>
        <cylinder radius="0.027" length="0.012" />
        </geometry>
      </collision>
    <collision name="rocker_1_bore_shadow_-0.05">
      <origin xyz="0.24 -0.0685 0.155" rpy="1.5708 0 0" />
      <geometry>
        <cylinder radius="0.01" length="0.002" />
        </geometry>
      </collision>
    <collision name="rocker_1_cheek_+0.05">
      <origin xyz="0.24 0.05 0.1265" rpy="0 0 0" />
      <geometry>
        <box size="0.086 0.014 0.205" />
        </geometry>
      </collision>
    <collision name="rocker_1_outer_bushing_+0.05">
      <origin xyz="0.24 0.0615 0.155" rpy="1.5708 0 0" />
      <geometry>
        <cylinder radius="0.027" length="0.012" />
        </geometry>
      </collision>
    <collision name="rocker_1_bore_shadow_+0.05">
      <origin xyz="0.24 0.0685 0.155" rpy="1.5708 0 0" />
      <geometry>
        <cylinder radius="0.01" length="0.002" />
        </geometry>
      </collision>
    <collision name="rocker_1_rear_web">
      <origin xyz="0.184 0 0.066" rpy="0 0 0" />
      <geometry>
        <box size="0.018 0.112 0.09" />
        </geometry>
      </collision>
    <collision name="rocker_1_base_bolt_+0.21_-0.07">
      <origin xyz="0.213 -0.073 0.028" rpy="0 0 0" />
      <geometry>
        <cylinder radius="0.006" length="0.006" />
        </geometry>
      </collision>
    <collision name="rocker_1_base_bolt_+0.21_+0.07">
      <origin xyz="0.213 0.073 0.028" rpy="0 0 0" />
      <geometry>
        <cylinder radius="0.006" length="0.006" />
        </geometry>
      </collision>
    <collision name="rocker_1_base_bolt_+0.27_-0.07">
      <origin xyz="0.267 -0.073 0.028" rpy="0 0 0" />
      <geometry>
        <cylinder radius="0.006" length="0.006" />
        </geometry>
      </collision>
    <collision name="rocker_1_base_bolt_+0.27_+0.07">
      <origin xyz="0.267 0.073 0.028" rpy="0 0 0" />
      <geometry>
        <cylinder radius="0.006" length="0.006" />
        </geometry>
      </collision>
    <collision name="output_lever_cheek_-0.05">
      <origin xyz="0.68 -0.05 0.1515" rpy="0 0 0" />
      <geometry>
        <box size="0.086 0.014 0.255" />
        </geometry>
      </collision>
    <collision name="output_lever_outer_bushing_-0.05">
      <origin xyz="0.68 -0.0615 0.205" rpy="1.5708 0 0" />
      <geometry>
        <cylinder radius="0.027" length="0.012" />
        </geometry>
      </collision>
    <collision name="output_lever_bore_shadow_-0.05">
      <origin xyz="0.68 -0.0685 0.205" rpy="1.5708 0 0" />
      <geometry>
        <cylinder radius="0.01" length="0.002" />
        </geometry>
      </collision>
    <collision name="output_lever_cheek_+0.05">
      <origin xyz="0.68 0.05 0.1515" rpy="0 0 0" />
      <geometry>
        <box size="0.086 0.014 0.255" />
        </geometry>
      </collision>
    <collision name="output_lever_outer_bushing_+0.05">
      <origin xyz="0.68 0.0615 0.205" rpy="1.5708 0 0" />
      <geometry>
        <cylinder radius="0.027" length="0.012" />
        </geometry>
      </collision>
    <collision name="output_lever_bore_shadow_+0.05">
      <origin xyz="0.68 0.0685 0.205" rpy="1.5708 0 0" />
      <geometry>
        <cylinder radius="0.01" length="0.002" />
        </geometry>
      </collision>
    <collision name="output_lever_rear_web">
      <origin xyz="0.624 0 0.066" rpy="0 0 0" />
      <geometry>
        <box size="0.018 0.112 0.09" />
        </geometry>
      </collision>
    <collision name="output_lever_base_bolt_+0.65_-0.07">
      <origin xyz="0.653 -0.073 0.028" rpy="0 0 0" />
      <geometry>
        <cylinder radius="0.006" length="0.006" />
        </geometry>
      </collision>
    <collision name="output_lever_base_bolt_+0.65_+0.07">
      <origin xyz="0.653 0.073 0.028" rpy="0 0 0" />
      <geometry>
        <cylinder radius="0.006" length="0.006" />
        </geometry>
      </collision>
    <collision name="output_lever_base_bolt_+0.71_-0.07">
      <origin xyz="0.707 -0.073 0.028" rpy="0 0 0" />
      <geometry>
        <cylinder radius="0.006" length="0.006" />
        </geometry>
      </collision>
    <collision name="output_lever_base_bolt_+0.71_+0.07">
      <origin xyz="0.707 0.073 0.028" rpy="0 0 0" />
      <geometry>
        <cylinder radius="0.006" length="0.006" />
        </geometry>
      </collision>
    <collision name="stop_pad_0">
      <origin xyz="-0.42 -0.095 0.034" rpy="0 0 0.20944" />
      <geometry>
        <box size="0.07 0.026 0.018" />
        </geometry>
      </collision>
    <collision name="stop_pad_1">
      <origin xyz="-0.05 0.105 0.034" rpy="0 0 -0.174533" />
      <geometry>
        <box size="0.07 0.026 0.018" />
        </geometry>
      </collision>
    <collision name="stop_pad_2">
      <origin xyz="0.36 -0.1 0.034" rpy="0 0 0.279253" />
      <geometry>
        <box size="0.07 0.026 0.018" />
        </geometry>
      </collision>
    <collision name="stop_pad_3">
      <origin xyz="0.78 0.095 0.034" rpy="0 0 -0.244346" />
      <geometry>
        <box size="0.07 0.026 0.018" />
        </geometry>
      </collision>
    <collision name="cover_standoff_-0.36_-0.10_-0.03">
      <origin xyz="-0.465 -0.14 0.053" rpy="0 0 0" />
      <geometry>
        <cylinder radius="0.01" length="0.056" />
        </geometry>
      </collision>
    <collision name="cover_standoff_-0.36_-0.10_+0.03">
      <origin xyz="-0.465 -0.08 0.053" rpy="0 0 0" />
      <geometry>
        <cylinder radius="0.01" length="0.056" />
        </geometry>
      </collision>
    <collision name="cover_standoff_-0.36_+0.10_-0.03">
      <origin xyz="-0.255 -0.14 0.053" rpy="0 0 0" />
      <geometry>
        <cylinder radius="0.01" length="0.056" />
        </geometry>
      </collision>
    <collision name="cover_standoff_-0.36_+0.10_+0.03">
      <origin xyz="-0.255 -0.08 0.053" rpy="0 0 0" />
      <geometry>
        <cylinder radius="0.01" length="0.056" />
        </geometry>
      </collision>
    <collision name="cover_standoff_+0.36_-0.10_-0.03">
      <origin xyz="0.255 -0.14 0.053" rpy="0 0 0" />
      <geometry>
        <cylinder radius="0.01" length="0.056" />
        </geometry>
      </collision>
    <collision name="cover_standoff_+0.36_-0.10_+0.03">
      <origin xyz="0.255 -0.08 0.053" rpy="0 0 0" />
      <geometry>
        <cylinder radius="0.01" length="0.056" />
        </geometry>
      </collision>
    <collision name="cover_standoff_+0.36_+0.10_-0.03">
      <origin xyz="0.465 -0.14 0.053" rpy="0 0 0" />
      <geometry>
        <cylinder radius="0.01" length="0.056" />
        </geometry>
      </collision>
    <collision name="cover_standoff_+0.36_+0.10_+0.03">
      <origin xyz="0.465 -0.08 0.053" rpy="0 0 0" />
      <geometry>
        <cylinder radius="0.01" length="0.056" />
        </geometry>
      </collision>
    </link>
  <link name="input_lever">
    <visual name="web_plate">
      <origin xyz="0 0 0" rpy="1.5708 0 0" />
      <geometry>
        <mesh filename="assets/meshes/input_lever_plate.obj" />
        </geometry>
      <material name="tempered_blue_steel">
        <color rgba="0.2 0.3 0.42 1" />
        </material>
      </visual>
    <visual name="bearing_+0.00">
      <origin xyz="0 0 0" rpy="1.5708 0 0" />
      <geometry>
        <cylinder radius="0.022" length="0.086" />
        </geometry>
      <material name="oilite_bronze_bushings">
        <color rgba="0.72 0.52 0.26 1" />
        </material>
      </visual>
    <visual name="washer_+0.00_-0.01">
      <origin xyz="0 -0.012 0" rpy="1.5708 0 0" />
      <geometry>
        <cylinder radius="0.026" length="0.006" />
        </geometry>
      <material name="bead_blasted_steel">
        <color rgba="0.45 0.48 0.5 1" />
        </material>
      </visual>
    <visual name="washer_+0.00_+0.01">
      <origin xyz="0 0.012 0" rpy="1.5708 0 0" />
      <geometry>
        <cylinder radius="0.026" length="0.006" />
        </geometry>
      <material name="bead_blasted_steel">
        <color rgba="0.45 0.48 0.5 1" />
        </material>
      </visual>
    <visual name="bearing_+0.20">
      <origin xyz="0.2 0 0" rpy="1.5708 0 0" />
      <geometry>
        <cylinder radius="0.022" length="0.086" />
        </geometry>
      <material name="oilite_bronze_bushings">
        <color rgba="0.72 0.52 0.26 1" />
        </material>
      </visual>
    <visual name="washer_+0.20_-0.01">
      <origin xyz="0.2 -0.012 0" rpy="1.5708 0 0" />
      <geometry>
        <cylinder radius="0.026" length="0.006" />
        </geometry>
      <material name="bead_blasted_steel">
        <color rgba="0.45 0.48 0.5 1" />
        </material>
      </visual>
    <visual name="washer_+0.20_+0.01">
      <origin xyz="0.2 0.012 0" rpy="1.5708 0 0" />
      <geometry>
        <cylinder radius="0.026" length="0.006" />
        </geometry>
      <material name="bead_blasted_steel">
        <color rgba="0.45 0.48 0.5 1" />
        </material>
      </visual>
    <visual name="outboard_pin_+0.20">
      <origin xyz="0.2 0.041 0" rpy="1.5708 0 0" />
      <geometry>
        <cylinder radius="0.012" length="0.078" />
        </geometry>
      <material name="bead_blasted_steel">
        <color rgba="0.45 0.48 0.5 1" />
        </material>
      </visual>
    <visual name="pin_cap_+0.20">
      <origin xyz="0.2 0.083 0" rpy="1.5708 0 0" />
      <geometry>
        <cylinder radius="0.016" length="0.006" />
        </geometry>
      <material name="bead_blasted_steel">
        <color rgba="0.45 0.48 0.5 1" />
        </material>
      </visual>
    <collision name="web_plate">
      <origin xyz="0 0 0" rpy="1.5708 0 0" />
      <geometry>
        <mesh filename="assets/meshes/input_lever_plate.obj" />
        </geometry>
      </collision>
    <collision name="bearing_+0.00">
      <origin xyz="0 0 0" rpy="1.5708 0 0" />
      <geometry>
        <cylinder radius="0.022" length="0.086" />
        </geometry>
      </collision>
    <collision name="washer_+0.00_-0.01">
      <origin xyz="0 -0.012 0" rpy="1.5708 0 0" />
      <geometry>
        <cylinder radius="0.026" length="0.006" />
        </geometry>
      </collision>
    <collision name="washer_+0.00_+0.01">
      <origin xyz="0 0.012 0" rpy="1.5708 0 0" />
      <geometry>
        <cylinder radius="0.026" length="0.006" />
        </geometry>
      </collision>
    <collision name="bearing_+0.20">
      <origin xyz="0.2 0 0" rpy="1.5708 0 0" />
      <geometry>
        <cylinder radius="0.022" length="0.086" />
        </geometry>
      </collision>
    <collision name="washer_+0.20_-0.01">
      <origin xyz="0.2 -0.012 0" rpy="1.5708 0 0" />
      <geometry>
        <cylinder radius="0.026" length="0.006" />
        </geometry>
      </collision>
    <collision name="washer_+0.20_+0.01">
      <origin xyz="0.2 0.012 0" rpy="1.5708 0 0" />
      <geometry>
        <cylinder radius="0.026" length="0.006" />
        </geometry>
      </collision>
    <collision name="outboard_pin_+0.20">
      <origin xyz="0.2 0.041 0" rpy="1.5708 0 0" />
      <geometry>
        <cylinder radius="0.012" length="0.078" />
        </geometry>
      </collision>
    <collision name="pin_cap_+0.20">
      <origin xyz="0.2 0.083 0" rpy="1.5708 0 0" />
      <geometry>
        <cylinder radius="0.016" length="0.006" />
        </geometry>
      </collision>
    </link>
  <link name="rocker_0">
    <visual name="web_plate">
      <origin xyz="0 0 0" rpy="1.5708 0 0" />
      <geometry>
        <mesh filename="assets/meshes/rocker_0_plate.obj" />
        </geometry>
      <material name="tempered_blue_steel">
        <color rgba="0.2 0.3 0.42 1" />
        </material>
      </visual>
    <visual name="bearing_-0.12">
      <origin xyz="-0.12 0 0" rpy="1.5708 0 0" />
      <geometry>
        <cylinder radius="0.022" length="0.086" />
        </geometry>
      <material name="oilite_bronze_bushings">
        <color rgba="0.72 0.52 0.26 1" />
        </material>
      </visual>
    <visual name="washer_-0.12_-0.01">
      <origin xyz="-0.12 -0.012 0" rpy="1.5708 0 0" />
      <geometry>
        <cylinder radius="0.026" length="0.006" />
        </geometry>
      <material name="bead_blasted_steel">
        <color rgba="0.45 0.48 0.5 1" />
        </material>
      </visual>
    <visual name="washer_-0.12_+0.01">
      <origin xyz="-0.12 0.012 0" rpy="1.5708 0 0" />
      <geometry>
        <cylinder radius="0.026" length="0.006" />
        </geometry>
      <material name="bead_blasted_steel">
        <color rgba="0.45 0.48 0.5 1" />
        </material>
      </visual>
    <visual name="outboard_pin_-0.12">
      <origin xyz="-0.12 0.041 0" rpy="1.5708 0 0" />
      <geometry>
        <cylinder radius="0.012" length="0.078" />
        </geometry>
      <material name="bead_blasted_steel">
        <color rgba="0.45 0.48 0.5 1" />
        </material>
      </visual>
    <visual name="pin_cap_-0.12">
      <origin xyz="-0.12 0.083 0" rpy="1.5708 0 0" />
      <geometry>
        <cylinder radius="0.016" length="0.006" />
        </geometry>
      <material name="bead_blasted_steel">
        <color rgba="0.45 0.48 0.5 1" />
        </material>
      </visual>
    <visual name="bearing_+0.00">
      <origin xyz="0 0 0" rpy="1.5708 0 0" />
      <geometry>
        <cylinder radius="0.022" length="0.086" />
        </geometry>
      <material name="oilite_bronze_bushings">
        <color rgba="0.72 0.52 0.26 1" />
        </material>
      </visual>
    <visual name="washer_+0.00_-0.01">
      <origin xyz="0 -0.012 0" rpy="1.5708 0 0" />
      <geometry>
        <cylinder radius="0.026" length="0.006" />
        </geometry>
      <material name="bead_blasted_steel">
        <color rgba="0.45 0.48 0.5 1" />
        </material>
      </visual>
    <visual name="washer_+0.00_+0.01">
      <origin xyz="0 0.012 0" rpy="1.5708 0 0" />
      <geometry>
        <cylinder radius="0.026" length="0.006" />
        </geometry>
      <material name="bead_blasted_steel">
        <color rgba="0.45 0.48 0.5 1" />
        </material>
      </visual>
    <visual name="bearing_+0.14">
      <origin xyz="0.14 0 0" rpy="1.5708 0 0" />
      <geometry>
        <cylinder radius="0.022" length="0.086" />
        </geometry>
      <material name="oilite_bronze_bushings">
        <color rgba="0.72 0.52 0.26 1" />
        </material>
      </visual>
    <visual name="washer_+0.14_-0.01">
      <origin xyz="0.14 -0.012 0" rpy="1.5708 0 0" />
      <geometry>
        <cylinder radius="0.026" length="0.006" />
        </geometry>
      <material name="bead_blasted_steel">
        <color rgba="0.45 0.48 0.5 1" />
        </material>
      </visual>
    <visual name="washer_+0.14_+0.01">
      <origin xyz="0.14 0.012 0" rpy="1.5708 0 0" />
      <geometry>
        <cylinder radius="0.026" length="0.006" />
        </geometry>
      <material name="bead_blasted_steel">
        <color rgba="0.45 0.48 0.5 1" />
        </material>
      </visual>
    <visual name="outboard_pin_+0.14">
      <origin xyz="0.14 0.041 0" rpy="1.5708 0 0" />
      <geometry>
        <cylinder radius="0.012" length="0.078" />
        </geometry>
      <material name="bead_blasted_steel">
        <color rgba="0.45 0.48 0.5 1" />
        </material>
      </visual>
    <visual name="pin_cap_+0.14">
      <origin xyz="0.14 0.083 0" rpy="1.5708 0 0" />
      <geometry>
        <cylinder radius="0.016" length="0.006" />
        </geometry>
      <material name="bead_blasted_steel">
        <color rgba="0.45 0.48 0.5 1" />
        </material>
      </visual>
    <collision name="web_plate">
      <origin xyz="0 0 0" rpy="1.5708 0 0" />
      <geometry>
        <mesh filename="assets/meshes/rocker_0_plate.obj" />
        </geometry>
      </collision>
    <collision name="bearing_-0.12">
      <origin xyz="-0.12 0 0" rpy="1.5708 0 0" />
      <geometry>
        <cylinder radius="0.022" length="0.086" />
        </geometry>
      </collision>
    <collision name="washer_-0.12_-0.01">
      <origin xyz="-0.12 -0.012 0" rpy="1.5708 0 0" />
      <geometry>
        <cylinder radius="0.026" length="0.006" />
        </geometry>
      </collision>
    <collision name="washer_-0.12_+0.01">
      <origin xyz="-0.12 0.012 0" rpy="1.5708 0 0" />
      <geometry>
        <cylinder radius="0.026" length="0.006" />
        </geometry>
      </collision>
    <collision name="outboard_pin_-0.12">
      <origin xyz="-0.12 0.041 0" rpy="1.5708 0 0" />
      <geometry>
        <cylinder radius="0.012" length="0.078" />
        </geometry>
      </collision>
    <collision name="pin_cap_-0.12">
      <origin xyz="-0.12 0.083 0" rpy="1.5708 0 0" />
      <geometry>
        <cylinder radius="0.016" length="0.006" />
        </geometry>
      </collision>
    <collision name="bearing_+0.00">
      <origin xyz="0 0 0" rpy="1.5708 0 0" />
      <geometry>
        <cylinder radius="0.022" length="0.086" />
        </geometry>
      </collision>
    <collision name="washer_+0.00_-0.01">
      <origin xyz="0 -0.012 0" rpy="1.5708 0 0" />
      <geometry>
        <cylinder radius="0.026" length="0.006" />
        </geometry>
      </collision>
    <collision name="washer_+0.00_+0.01">
      <origin xyz="0 0.012 0" rpy="1.5708 0 0" />
      <geometry>
        <cylinder radius="0.026" length="0.006" />
        </geometry>
      </collision>
    <collision name="bearing_+0.14">
      <origin xyz="0.14 0 0" rpy="1.5708 0 0" />
      <geometry>
        <cylinder radius="0.022" length="0.086" />
        </geometry>
      </collision>
    <collision name="washer_+0.14_-0.01">
      <origin xyz="0.14 -0.012 0" rpy="1.5708 0 0" />
      <geometry>
        <cylinder radius="0.026" length="0.006" />
        </geometry>
      </collision>
    <collision name="washer_+0.14_+0.01">
      <origin xyz="0.14 0.012 0" rpy="1.5708 0 0" />
      <geometry>
        <cylinder radius="0.026" length="0.006" />
        </geometry>
      </collision>
    <collision name="outboard_pin_+0.14">
      <origin xyz="0.14 0.041 0" rpy="1.5708 0 0" />
      <geometry>
        <cylinder radius="0.012" length="0.078" />
        </geometry>
      </collision>
    <collision name="pin_cap_+0.14">
      <origin xyz="0.14 0.083 0" rpy="1.5708 0 0" />
      <geometry>
        <cylinder radius="0.016" length="0.006" />
        </geometry>
      </collision>
    </link>
  <link name="rocker_1">
    <visual name="web_plate">
      <origin xyz="0 0 0" rpy="1.5708 0 0" />
      <geometry>
        <mesh filename="assets/meshes/rocker_1_plate.obj" />
        </geometry>
      <material name="tempered_blue_steel">
        <color rgba="0.2 0.3 0.42 1" />
        </material>
      </visual>
    <visual name="bearing_-0.16">
      <origin xyz="-0.16 0 0" rpy="1.5708 0 0" />
      <geometry>
        <cylinder radius="0.022" length="0.086" />
        </geometry>
      <material name="oilite_bronze_bushings">
        <color rgba="0.72 0.52 0.26 1" />
        </material>
      </visual>
    <visual name="washer_-0.16_-0.01">
      <origin xyz="-0.16 -0.012 0" rpy="1.5708 0 0" />
      <geometry>
        <cylinder radius="0.026" length="0.006" />
        </geometry>
      <material name="bead_blasted_steel">
        <color rgba="0.45 0.48 0.5 1" />
        </material>
      </visual>
    <visual name="washer_-0.16_+0.01">
      <origin xyz="-0.16 0.012 0" rpy="1.5708 0 0" />
      <geometry>
        <cylinder radius="0.026" length="0.006" />
        </geometry>
      <material name="bead_blasted_steel">
        <color rgba="0.45 0.48 0.5 1" />
        </material>
      </visual>
    <visual name="outboard_pin_-0.16">
      <origin xyz="-0.16 0.041 0" rpy="1.5708 0 0" />
      <geometry>
        <cylinder radius="0.012" length="0.078" />
        </geometry>
      <material name="bead_blasted_steel">
        <color rgba="0.45 0.48 0.5 1" />
        </material>
      </visual>
    <visual name="pin_cap_-0.16">
      <origin xyz="-0.16 0.083 0" rpy="1.5708 0 0" />
      <geometry>
        <cylinder radius="0.016" length="0.006" />
        </geometry>
      <material name="bead_blasted_steel">
        <color rgba="0.45 0.48 0.5 1" />
        </material>
      </visual>
    <visual name="bearing_+0.00">
      <origin xyz="0 0 0" rpy="1.5708 0 0" />
      <geometry>
        <cylinder radius="0.022" length="0.086" />
        </geometry>
      <material name="oilite_bronze_bushings">
        <color rgba="0.72 0.52 0.26 1" />
        </material>
      </visual>
    <visual name="washer_+0.00_-0.01">
      <origin xyz="0 -0.012 0" rpy="1.5708 0 0" />
      <geometry>
        <cylinder radius="0.026" length="0.006" />
        </geometry>
      <material name="bead_blasted_steel">
        <color rgba="0.45 0.48 0.5 1" />
        </material>
      </visual>
    <visual name="washer_+0.00_+0.01">
      <origin xyz="0 0.012 0" rpy="1.5708 0 0" />
      <geometry>
        <cylinder radius="0.026" length="0.006" />
        </geometry>
      <material name="bead_blasted_steel">
        <color rgba="0.45 0.48 0.5 1" />
        </material>
      </visual>
    <visual name="bearing_+0.16">
      <origin xyz="0.16 0 0" rpy="1.5708 0 0" />
      <geometry>
        <cylinder radius="0.022" length="0.086" />
        </geometry>
      <material name="oilite_bronze_bushings">
        <color rgba="0.72 0.52 0.26 1" />
        </material>
      </visual>
    <visual name="washer_+0.16_-0.01">
      <origin xyz="0.16 -0.012 0" rpy="1.5708 0 0" />
      <geometry>
        <cylinder radius="0.026" length="0.006" />
        </geometry>
      <material name="bead_blasted_steel">
        <color rgba="0.45 0.48 0.5 1" />
        </material>
      </visual>
    <visual name="washer_+0.16_+0.01">
      <origin xyz="0.16 0.012 0" rpy="1.5708 0 0" />
      <geometry>
        <cylinder radius="0.026" length="0.006" />
        </geometry>
      <material name="bead_blasted_steel">
        <color rgba="0.45 0.48 0.5 1" />
        </material>
      </visual>
    <visual name="outboard_pin_+0.16">
      <origin xyz="0.16 0.041 0" rpy="1.5708 0 0" />
      <geometry>
        <cylinder radius="0.012" length="0.078" />
        </geometry>
      <material name="bead_blasted_steel">
        <color rgba="0.45 0.48 0.5 1" />
        </material>
      </visual>
    <visual name="pin_cap_+0.16">
      <origin xyz="0.16 0.083 0" rpy="1.5708 0 0" />
      <geometry>
        <cylinder radius="0.016" length="0.006" />
        </geometry>
      <material name="bead_blasted_steel">
        <color rgba="0.45 0.48 0.5 1" />
        </material>
      </visual>
    <collision name="web_plate">
      <origin xyz="0 0 0" rpy="1.5708 0 0" />
      <geometry>
        <mesh filename="assets/meshes/rocker_1_plate.obj" />
        </geometry>
      </collision>
    <collision name="bearing_-0.16">
      <origin xyz="-0.16 0 0" rpy="1.5708 0 0" />
      <geometry>
        <cylinder radius="0.022" length="0.086" />
        </geometry>
      </collision>
    <collision name="washer_-0.16_-0.01">
      <origin xyz="-0.16 -0.012 0" rpy="1.5708 0 0" />
      <geometry>
        <cylinder radius="0.026" length="0.006" />
        </geometry>
      </collision>
    <collision name="washer_-0.16_+0.01">
      <origin xyz="-0.16 0.012 0" rpy="1.5708 0 0" />
      <geometry>
        <cylinder radius="0.026" length="0.006" />
        </geometry>
      </collision>
    <collision name="outboard_pin_-0.16">
      <origin xyz="-0.16 0.041 0" rpy="1.5708 0 0" />
      <geometry>
        <cylinder radius="0.012" length="0.078" />
        </geometry>
      </collision>
    <collision name="pin_cap_-0.16">
      <origin xyz="-0.16 0.083 0" rpy="1.5708 0 0" />
      <geometry>
        <cylinder radius="0.016" length="0.006" />
        </geometry>
      </collision>
    <collision name="bearing_+0.00">
      <origin xyz="0 0 0" rpy="1.5708 0 0" />
      <geometry>
        <cylinder radius="0.022" length="0.086" />
        </geometry>
      </collision>
    <collision name="washer_+0.00_-0.01">
      <origin xyz="0 -0.012 0" rpy="1.5708 0 0" />
      <geometry>
        <cylinder radius="0.026" length="0.006" />
        </geometry>
      </collision>
    <collision name="washer_+0.00_+0.01">
      <origin xyz="0 0.012 0" rpy="1.5708 0 0" />
      <geometry>
        <cylinder radius="0.026" length="0.006" />
        </geometry>
      </collision>
    <collision name="bearing_+0.16">
      <origin xyz="0.16 0 0" rpy="1.5708 0 0" />
      <geometry>
        <cylinder radius="0.022" length="0.086" />
        </geometry>
      </collision>
    <collision name="washer_+0.16_-0.01">
      <origin xyz="0.16 -0.012 0" rpy="1.5708 0 0" />
      <geometry>
        <cylinder radius="0.026" length="0.006" />
        </geometry>
      </collision>
    <collision name="washer_+0.16_+0.01">
      <origin xyz="0.16 0.012 0" rpy="1.5708 0 0" />
      <geometry>
        <cylinder radius="0.026" length="0.006" />
        </geometry>
      </collision>
    <collision name="outboard_pin_+0.16">
      <origin xyz="0.16 0.041 0" rpy="1.5708 0 0" />
      <geometry>
        <cylinder radius="0.012" length="0.078" />
        </geometry>
      </collision>
    <collision name="pin_cap_+0.16">
      <origin xyz="0.16 0.083 0" rpy="1.5708 0 0" />
      <geometry>
        <cylinder radius="0.016" length="0.006" />
        </geometry>
      </collision>
    </link>
  <link name="output_lever">
    <visual name="web_plate">
      <origin xyz="0 0 0" rpy="1.5708 0 0" />
      <geometry>
        <mesh filename="assets/meshes/output_lever_plate.obj" />
        </geometry>
      <material name="tempered_blue_steel">
        <color rgba="0.2 0.3 0.42 1" />
        </material>
      </visual>
    <visual name="bearing_-0.20">
      <origin xyz="-0.2 0 0" rpy="1.5708 0 0" />
      <geometry>
        <cylinder radius="0.022" length="0.086" />
        </geometry>
      <material name="oilite_bronze_bushings">
        <color rgba="0.72 0.52 0.26 1" />
        </material>
      </visual>
    <visual name="washer_-0.20_-0.01">
      <origin xyz="-0.2 -0.012 0" rpy="1.5708 0 0" />
      <geometry>
        <cylinder radius="0.026" length="0.006" />
        </geometry>
      <material name="bead_blasted_steel">
        <color rgba="0.45 0.48 0.5 1" />
        </material>
      </visual>
    <visual name="washer_-0.20_+0.01">
      <origin xyz="-0.2 0.012 0" rpy="1.5708 0 0" />
      <geometry>
        <cylinder radius="0.026" length="0.006" />
        </geometry>
      <material name="bead_blasted_steel">
        <color rgba="0.45 0.48 0.5 1" />
        </material>
      </visual>
    <visual name="outboard_pin_-0.20">
      <origin xyz="-0.2 0.041 0" rpy="1.5708 0 0" />
      <geometry>
        <cylinder radius="0.012" length="0.078" />
        </geometry>
      <material name="bead_blasted_steel">
        <color rgba="0.45 0.48 0.5 1" />
        </material>
      </visual>
    <visual name="pin_cap_-0.20">
      <origin xyz="-0.2 0.083 0" rpy="1.5708 0 0" />
      <geometry>
        <cylinder radius="0.016" length="0.006" />
        </geometry>
      <material name="bead_blasted_steel">
        <color rgba="0.45 0.48 0.5 1" />
        </material>
      </visual>
    <visual name="bearing_+0.00">
      <origin xyz="0 0 0" rpy="1.5708 0 0" />
      <geometry>
        <cylinder radius="0.022" length="0.086" />
        </geometry>
      <material name="oilite_bronze_bushings">
        <color rgba="0.72 0.52 0.26 1" />
        </material>
      </visual>
    <visual name="washer_+0.00_-0.01">
      <origin xyz="0 -0.012 0" rpy="1.5708 0 0" />
      <geometry>
        <cylinder radius="0.026" length="0.006" />
        </geometry>
      <material name="bead_blasted_steel">
        <color rgba="0.45 0.48 0.5 1" />
        </material>
      </visual>
    <visual name="washer_+0.00_+0.01">
      <origin xyz="0 0.012 0" rpy="1.5708 0 0" />
      <geometry>
        <cylinder radius="0.026" length="0.006" />
        </geometry>
      <material name="bead_blasted_steel">
        <color rgba="0.45 0.48 0.5 1" />
        </material>
      </visual>
    <visual name="bearing_+0.22">
      <origin xyz="0.22 0 0" rpy="1.5708 0 0" />
      <geometry>
        <cylinder radius="0.022" length="0.086" />
        </geometry>
      <material name="oilite_bronze_bushings">
        <color rgba="0.72 0.52 0.26 1" />
        </material>
      </visual>
    <visual name="washer_+0.22_-0.01">
      <origin xyz="0.22 -0.012 0" rpy="1.5708 0 0" />
      <geometry>
        <cylinder radius="0.026" length="0.006" />
        </geometry>
      <material name="bead_blasted_steel">
        <color rgba="0.45 0.48 0.5 1" />
        </material>
      </visual>
    <visual name="washer_+0.22_+0.01">
      <origin xyz="0.22 0.012 0" rpy="1.5708 0 0" />
      <geometry>
        <cylinder radius="0.026" length="0.006" />
        </geometry>
      <material name="bead_blasted_steel">
        <color rgba="0.45 0.48 0.5 1" />
        </material>
      </visual>
    <visual name="outboard_pin_+0.22">
      <origin xyz="0.22 0.041 0" rpy="1.5708 0 0" />
      <geometry>
        <cylinder radius="0.012" length="0.078" />
        </geometry>
      <material name="bead_blasted_steel">
        <color rgba="0.45 0.48 0.5 1" />
        </material>
      </visual>
    <visual name="pin_cap_+0.22">
      <origin xyz="0.22 0.083 0" rpy="1.5708 0 0" />
      <geometry>
        <cylinder radius="0.016" length="0.006" />
        </geometry>
      <material name="bead_blasted_steel">
        <color rgba="0.45 0.48 0.5 1" />
        </material>
      </visual>
    <collision name="web_plate">
      <origin xyz="0 0 0" rpy="1.5708 0 0" />
      <geometry>
        <mesh filename="assets/meshes/output_lever_plate.obj" />
        </geometry>
      </collision>
    <collision name="bearing_-0.20">
      <origin xyz="-0.2 0 0" rpy="1.5708 0 0" />
      <geometry>
        <cylinder radius="0.022" length="0.086" />
        </geometry>
      </collision>
    <collision name="washer_-0.20_-0.01">
      <origin xyz="-0.2 -0.012 0" rpy="1.5708 0 0" />
      <geometry>
        <cylinder radius="0.026" length="0.006" />
        </geometry>
      </collision>
    <collision name="washer_-0.20_+0.01">
      <origin xyz="-0.2 0.012 0" rpy="1.5708 0 0" />
      <geometry>
        <cylinder radius="0.026" length="0.006" />
        </geometry>
      </collision>
    <collision name="outboard_pin_-0.20">
      <origin xyz="-0.2 0.041 0" rpy="1.5708 0 0" />
      <geometry>
        <cylinder radius="0.012" length="0.078" />
        </geometry>
      </collision>
    <collision name="pin_cap_-0.20">
      <origin xyz="-0.2 0.083 0" rpy="1.5708 0 0" />
      <geometry>
        <cylinder radius="0.016" length="0.006" />
        </geometry>
      </collision>
    <collision name="bearing_+0.00">
      <origin xyz="0 0 0" rpy="1.5708 0 0" />
      <geometry>
        <cylinder radius="0.022" length="0.086" />
        </geometry>
      </collision>
    <collision name="washer_+0.00_-0.01">
      <origin xyz="0 -0.012 0" rpy="1.5708 0 0" />
      <geometry>
        <cylinder radius="0.026" length="0.006" />
        </geometry>
      </collision>
    <collision name="washer_+0.00_+0.01">
      <origin xyz="0 0.012 0" rpy="1.5708 0 0" />
      <geometry>
        <cylinder radius="0.026" length="0.006" />
        </geometry>
      </collision>
    <collision name="bearing_+0.22">
      <origin xyz="0.22 0 0" rpy="1.5708 0 0" />
      <geometry>
        <cylinder radius="0.022" length="0.086" />
        </geometry>
      </collision>
    <collision name="washer_+0.22_-0.01">
      <origin xyz="0.22 -0.012 0" rpy="1.5708 0 0" />
      <geometry>
        <cylinder radius="0.026" length="0.006" />
        </geometry>
      </collision>
    <collision name="washer_+0.22_+0.01">
      <origin xyz="0.22 0.012 0" rpy="1.5708 0 0" />
      <geometry>
        <cylinder radius="0.026" length="0.006" />
        </geometry>
      </collision>
    <collision name="outboard_pin_+0.22">
      <origin xyz="0.22 0.041 0" rpy="1.5708 0 0" />
      <geometry>
        <cylinder radius="0.012" length="0.078" />
        </geometry>
      </collision>
    <collision name="pin_cap_+0.22">
      <origin xyz="0.22 0.083 0" rpy="1.5708 0 0" />
      <geometry>
        <cylinder radius="0.016" length="0.006" />
        </geometry>
      </collision>
    </link>
  <link name="coupler_0">
    <visual name="link_plate">
      <origin xyz="0 0 0" rpy="1.5708 0 0" />
      <geometry>
        <mesh filename="assets/meshes/coupler_0_plate.obj" />
        </geometry>
      <material name="bead_blasted_steel">
        <color rgba="0.45 0.48 0.5 1" />
        </material>
      </visual>
    <collision name="link_plate">
      <origin xyz="0 0 0" rpy="1.5708 0 0" />
      <geometry>
        <mesh filename="assets/meshes/coupler_0_plate.obj" />
        </geometry>
      </collision>
    </link>
  <link name="coupler_1">
    <visual name="link_plate">
      <origin xyz="0 0 0" rpy="1.5708 0 0" />
      <geometry>
        <mesh filename="assets/meshes/coupler_1_plate.obj" />
        </geometry>
      <material name="bead_blasted_steel">
        <color rgba="0.45 0.48 0.5 1" />
        </material>
      </visual>
    <collision name="link_plate">
      <origin xyz="0 0 0" rpy="1.5708 0 0" />
      <geometry>
        <mesh filename="assets/meshes/coupler_1_plate.obj" />
        </geometry>
      </collision>
    </link>
  <link name="coupler_2">
    <visual name="link_plate">
      <origin xyz="0 0 0" rpy="1.5708 0 0" />
      <geometry>
        <mesh filename="assets/meshes/coupler_2_plate.obj" />
        </geometry>
      <material name="bead_blasted_steel">
        <color rgba="0.45 0.48 0.5 1" />
        </material>
      </visual>
    <collision name="link_plate">
      <origin xyz="0 0 0" rpy="1.5708 0 0" />
      <geometry>
        <mesh filename="assets/meshes/coupler_2_plate.obj" />
        </geometry>
      </collision>
    </link>
  <link name="access_cover_0">
    <visual name="slotted_panel">
      <geometry>
        <mesh filename="assets/meshes/access_cover_0_panel.obj" />
        </geometry>
      <material name="removable_cover_gray">
        <color rgba="0.36 0.38 0.39 1" />
        </material>
      </visual>
    <visual name="captive_screw_-0.10_-0.03">
      <origin xyz="-0.105 -0.03 0.0055" rpy="0 0 0" />
      <geometry>
        <cylinder radius="0.0075" length="0.005" />
        </geometry>
      <material name="bead_blasted_steel">
        <color rgba="0.45 0.48 0.5 1" />
        </material>
      </visual>
    <visual name="captive_screw_-0.10_+0.03">
      <origin xyz="-0.105 0.03 0.0055" rpy="0 0 0" />
      <geometry>
        <cylinder radius="0.0075" length="0.005" />
        </geometry>
      <material name="bead_blasted_steel">
        <color rgba="0.45 0.48 0.5 1" />
        </material>
      </visual>
    <visual name="captive_screw_+0.10_-0.03">
      <origin xyz="0.105 -0.03 0.0055" rpy="0 0 0" />
      <geometry>
        <cylinder radius="0.0075" length="0.005" />
        </geometry>
      <material name="bead_blasted_steel">
        <color rgba="0.45 0.48 0.5 1" />
        </material>
      </visual>
    <visual name="captive_screw_+0.10_+0.03">
      <origin xyz="0.105 0.03 0.0055" rpy="0 0 0" />
      <geometry>
        <cylinder radius="0.0075" length="0.005" />
        </geometry>
      <material name="bead_blasted_steel">
        <color rgba="0.45 0.48 0.5 1" />
        </material>
      </visual>
    <collision name="slotted_panel">
      <geometry>
        <mesh filename="assets/meshes/access_cover_0_panel.obj" />
        </geometry>
      </collision>
    <collision name="captive_screw_-0.10_-0.03">
      <origin xyz="-0.105 -0.03 0.0055" rpy="0 0 0" />
      <geometry>
        <cylinder radius="0.0075" length="0.005" />
        </geometry>
      </collision>
    <collision name="captive_screw_-0.10_+0.03">
      <origin xyz="-0.105 0.03 0.0055" rpy="0 0 0" />
      <geometry>
        <cylinder radius="0.0075" length="0.005" />
        </geometry>
      </collision>
    <collision name="captive_screw_+0.10_-0.03">
      <origin xyz="0.105 -0.03 0.0055" rpy="0 0 0" />
      <geometry>
        <cylinder radius="0.0075" length="0.005" />
        </geometry>
      </collision>
    <collision name="captive_screw_+0.10_+0.03">
      <origin xyz="0.105 0.03 0.0055" rpy="0 0 0" />
      <geometry>
        <cylinder radius="0.0075" length="0.005" />
        </geometry>
      </collision>
    </link>
  <link name="access_cover_1">
    <visual name="slotted_panel">
      <geometry>
        <mesh filename="assets/meshes/access_cover_1_panel.obj" />
        </geometry>
      <material name="removable_cover_gray">
        <color rgba="0.36 0.38 0.39 1" />
        </material>
      </visual>
    <visual name="captive_screw_-0.10_-0.03">
      <origin xyz="-0.105 -0.03 0.0055" rpy="0 0 0" />
      <geometry>
        <cylinder radius="0.0075" length="0.005" />
        </geometry>
      <material name="bead_blasted_steel">
        <color rgba="0.45 0.48 0.5 1" />
        </material>
      </visual>
    <visual name="captive_screw_-0.10_+0.03">
      <origin xyz="-0.105 0.03 0.0055" rpy="0 0 0" />
      <geometry>
        <cylinder radius="0.0075" length="0.005" />
        </geometry>
      <material name="bead_blasted_steel">
        <color rgba="0.45 0.48 0.5 1" />
        </material>
      </visual>
    <visual name="captive_screw_+0.10_-0.03">
      <origin xyz="0.105 -0.03 0.0055" rpy="0 0 0" />
      <geometry>
        <cylinder radius="0.0075" length="0.005" />
        </geometry>
      <material name="bead_blasted_steel">
        <color rgba="0.45 0.48 0.5 1" />
        </material>
      </visual>
    <visual name="captive_screw_+0.10_+0.03">
      <origin xyz="0.105 0.03 0.0055" rpy="0 0 0" />
      <geometry>
        <cylinder radius="0.0075" length="0.005" />
        </geometry>
      <material name="bead_blasted_steel">
        <color rgba="0.45 0.48 0.5 1" />
        </material>
      </visual>
    <collision name="slotted_panel">
      <geometry>
        <mesh filename="assets/meshes/access_cover_1_panel.obj" />
        </geometry>
      </collision>
    <collision name="captive_screw_-0.10_-0.03">
      <origin xyz="-0.105 -0.03 0.0055" rpy="0 0 0" />
      <geometry>
        <cylinder radius="0.0075" length="0.005" />
        </geometry>
      </collision>
    <collision name="captive_screw_-0.10_+0.03">
      <origin xyz="-0.105 0.03 0.0055" rpy="0 0 0" />
      <geometry>
        <cylinder radius="0.0075" length="0.005" />
        </geometry>
      </collision>
    <collision name="captive_screw_+0.10_-0.03">
      <origin xyz="0.105 -0.03 0.0055" rpy="0 0 0" />
      <geometry>
        <cylinder radius="0.0075" length="0.005" />
        </geometry>
      </collision>
    <collision name="captive_screw_+0.10_+0.03">
      <origin xyz="0.105 0.03 0.0055" rpy="0 0 0" />
      <geometry>
        <cylinder radius="0.0075" length="0.005" />
        </geometry>
      </collision>
    </link>
  <joint name="base_to_access_cover_0" type="prismatic">
    <origin xyz="-0.36 -0.11 0.084" rpy="0 0 0" />
    <parent link="base" />
    <child link="access_cover_0" />
    <axis xyz="0 0 1" />
    <limit effort="20" velocity="0.08" lower="0" upper="0.06" />
    </joint>
  <joint name="base_to_access_cover_1" type="prismatic">
    <origin xyz="0.36 -0.11 0.084" rpy="0 0 0" />
    <parent link="base" />
    <child link="access_cover_1" />
    <axis xyz="0 0 1" />
    <limit effort="20" velocity="0.08" lower="0" upper="0.06" />
    </joint>
  <joint name="base_to_input_lever" type="revolute">
    <origin xyz="-0.55 0 0.13" rpy="0 -0.610865 0" />
    <parent link="base" />
    <child link="input_lever" />
    <axis xyz="0 1 0" />
    <limit effort="80" velocity="1.2" lower="-0.55" upper="0.55" />
    </joint>
  <joint name="base_to_rocker_0" type="revolute">
    <origin xyz="-0.18 0 0.22" rpy="0 -0.122173 0" />
    <parent link="base" />
    <child link="rocker_0" />
    <axis xyz="0 1 0" />
    <limit effort="70" velocity="1.2" lower="-0.45" upper="0.45" />
    <mimic joint="base_to_input_lever" multiplier="-0.65" />
    </joint>
  <joint name="base_to_rocker_1" type="revolute">
    <origin xyz="0.24 0 0.155" rpy="0 0.20944 0" />
    <parent link="base" />
    <child link="rocker_1" />
    <axis xyz="0 1 0" />
    <limit effort="70" velocity="1.2" lower="-0.45" upper="0.45" />
    <mimic joint="base_to_input_lever" multiplier="0.55" />
    </joint>
  <joint name="base_to_output_lever" type="revolute">
    <origin xyz="0.68 0 0.205" rpy="0 -0.349066 0" />
    <parent link="base" />
    <child link="output_lever" />
    <axis xyz="0 1 0" />
    <limit effort="75" velocity="1.2" lower="-0.55" upper="0.55" />
    <mimic joint="base_to_input_lever" multiplier="-0.75" />
    </joint>
  <joint name="input_lever_to_coupler_0" type="revolute">
    <origin xyz="0.2 0.065 0" rpy="0 1.03525 0" />
    <parent link="input_lever" />
    <child link="coupler_0" />
    <axis xyz="0 1 0" />
    <limit effort="12" velocity="1.5" lower="-0.7" upper="0.7" />
    <mimic joint="base_to_input_lever" multiplier="0.22" />
    </joint>
  <joint name="rocker_0_to_coupler_1" type="revolute">
    <origin xyz="0.14 0.065 0" rpy="0 0.495598 0" />
    <parent link="rocker_0" />
    <child link="coupler_1" />
    <axis xyz="0 1 0" />
    <limit effort="12" velocity="1.5" lower="-0.7" upper="0.7" />
    <mimic joint="base_to_input_lever" multiplier="-0.18" />
    </joint>
  <joint name="rocker_1_to_coupler_2" type="revolute">
    <origin xyz="0.16 0.065 0" rpy="0 -0.363731 0" />
    <parent link="rocker_1" />
    <child link="coupler_2" />
    <axis xyz="0 1 0" />
    <limit effort="12" velocity="1.5" lower="-0.7" upper="0.7" />
    <mimic joint="base_to_input_lever" multiplier="0.2" />
    </joint>
  </robot>
