<robot name="advertising_blimp">
  <material name="warm_white_fabric">
    <color rgba="0.92 0.88 0.72 1" />
    </material>
  <material name="advertising_blue">
    <color rgba="0.08 0.22 0.62 1" />
    </material>
  <material name="accent_yellow">
    <color rgba="0.95 0.68 0.16 1" />
    </material>
  <material name="gondola_white">
    <color rgba="0.86 0.88 0.88 1" />
    </material>
  <material name="blue_tinted_glass">
    <color rgba="0.25 0.55 0.76 0.65" />
    </material>
  <material name="dull_aluminum">
    <color rgba="0.55 0.57 0.58 1" />
    </material>
  <material name="rubber_black">
    <color rgba="0.03 0.035 0.04 1" />
    </material>
  <link name="envelope">
    <visual name="envelope_shell">
      <geometry>
        <mesh filename="assets/meshes/cigar_envelope.obj" />
        </geometry>
      <material name="warm_white_fabric">
        <color rgba="0.92 0.88 0.72 1" />
        </material>
      </visual>
    <visual name="port_ad_panel">
      <origin xyz="4 6.74 8.15" rpy="0 0 0" />
      <geometry>
        <box size="17 0.08 2.05" />
        </geometry>
      <material name="advertising_blue">
        <color rgba="0.08 0.22 0.62 1" />
        </material>
      </visual>
    <visual name="port_logo_block">
      <origin xyz="0 6.76 8.15" rpy="0 0 0" />
      <geometry>
        <box size="4 0.095 1.28" />
        </geometry>
      <material name="accent_yellow">
        <color rgba="0.95 0.68 0.16 1" />
        </material>
      </visual>
    <visual name="starboard_ad_panel">
      <origin xyz="4 -6.74 8.15" rpy="0 0 0" />
      <geometry>
        <box size="17 0.08 2.05" />
        </geometry>
      <material name="advertising_blue">
        <color rgba="0.08 0.22 0.62 1" />
        </material>
      </visual>
    <visual name="starboard_logo_block">
      <origin xyz="0 -6.76 8.15" rpy="0 0 0" />
      <geometry>
        <box size="4 0.095 1.28" />
        </geometry>
      <material name="accent_yellow">
        <color rgba="0.95 0.68 0.16 1" />
        </material>
      </visual>
    <visual name="keel_rail">
      <origin xyz="0 0 1.22" rpy="0 0 0" />
      <geometry>
        <box size="7.2 0.42 0.24" />
        </geometry>
      <material name="dull_aluminum">
        <color rgba="0.55 0.57 0.58 1" />
        </material>
      </visual>
    <visual name="port_engine_pad">
      <origin xyz="4 6.55 5.25" rpy="0 0 0" />
      <geometry>
        <box size="1.3 0.8 0.9" />
        </geometry>
      <material name="dull_aluminum">
        <color rgba="0.55 0.57 0.58 1" />
        </material>
      </visual>
    <visual name="starboard_engine_pad">
      <origin xyz="4 -6.55 5.25" rpy="0 0 0" />
      <geometry>
        <box size="1.3 0.8 0.9" />
        </geometry>
      <material name="dull_aluminum">
        <color rgba="0.55 0.57 0.58 1" />
        </material>
      </visual>
    <visual name="dorsal_fin">
      <origin xyz="-26.5 0 13.6" rpy="0 0 0" />
      <geometry>
        <box size="7 0.18 4.2" />
        </geometry>
      <material name="advertising_blue">
        <color rgba="0.08 0.22 0.62 1" />
        </material>
      </visual>
    <visual name="ventral_fin">
      <origin xyz="-26.5 0 2.95" rpy="0 0 0" />
      <geometry>
        <box size="7 0.18 3.7" />
        </geometry>
      <material name="advertising_blue">
        <color rgba="0.08 0.22 0.62 1" />
        </material>
      </visual>
    <visual name="port_tailplane">
      <origin xyz="-26.5 4.15 8" rpy="0 0 0" />
      <geometry>
        <box size="7 4.4 0.18" />
        </geometry>
      <material name="advertising_blue">
        <color rgba="0.08 0.22 0.62 1" />
        </material>
      </visual>
    <visual name="starboard_tailplane">
      <origin xyz="-26.5 -4.15 8" rpy="0 0 0" />
      <geometry>
        <box size="7 4.4 0.18" />
        </geometry>
      <material name="advertising_blue">
        <color rgba="0.08 0.22 0.62 1" />
        </material>
      </visual>
    <collision name="envelope_shell">
      <geometry>
        <mesh filename="assets/meshes/cigar_envelope.obj" />
        </geometry>
      </collision>
    <collision name="port_ad_panel">
      <origin xyz="4 6.74 8.15" rpy="0 0 0" />
      <geometry>
        <box size="17 0.08 2.05" />
        </geometry>
      </collision>
    <collision name="port_logo_block">
      <origin xyz="0 6.76 8.15" rpy="0 0 0" />
      <geometry>
        <box size="4 0.095 1.28" />
        </geometry>
      </collision>
    <collision name="starboard_ad_panel">
      <origin xyz="4 -6.74 8.15" rpy="0 0 0" />
      <geometry>
        <box size="17 0.08 2.05" />
        </geometry>
      </collision>
    <collision name="starboard_logo_block">
      <origin xyz="0 -6.76 8.15" rpy="0 0 0" />
      <geometry>
        <box size="4 0.095 1.28" />
        </geometry>
      </collision>
    <collision name="keel_rail">
      <origin xyz="0 0 1.22" rpy="0 0 0" />
      <geometry>
        <box size="7.2 0.42 0.24" />
        </geometry>
      </collision>
    <collision name="port_engine_pad">
      <origin xyz="4 6.55 5.25" rpy="0 0 0" />
      <geometry>
        <box size="1.3 0.8 0.9" />
        </geometry>
      </collision>
    <collision name="starboard_engine_pad">
      <origin xyz="4 -6.55 5.25" rpy="0 0 0" />
      <geometry>
        <box size="1.3 0.8 0.9" />
        </geometry>
      </collision>
    <collision name="dorsal_fin">
      <origin xyz="-26.5 0 13.6" rpy="0 0 0" />
      <geometry>
        <box size="7 0.18 4.2" />
        </geometry>
      </collision>
    <collision name="ventral_fin">
      <origin xyz="-26.5 0 2.95" rpy="0 0 0" />
      <geometry>
        <box size="7 0.18 3.7" />
        </geometry>
      </collision>
    <collision name="port_tailplane">
      <origin xyz="-26.5 4.15 8" rpy="0 0 0" />
      <geometry>
        <box size="7 4.4 0.18" />
        </geometry>
      </collision>
    <collision name="starboard_tailplane">
      <origin xyz="-26.5 -4.15 8" rpy="0 0 0" />
      <geometry>
        <box size="7 4.4 0.18" />
        </geometry>
      </collision>
    </link>
  <link name="gondola">
    <visual name="cabin_shell">
      <origin xyz="0 0 -0.38" rpy="0 0 0" />
      <geometry>
        <box size="7.8 2.15 1.65" />
        </geometry>
      <material name="gondola_white">
        <color rgba="0.86 0.88 0.88 1" />
        </material>
      </visual>
    <visual name="front_windshield">
      <origin xyz="3.45 0 -0.05" rpy="0 0 0" />
      <geometry>
        <box size="1.5 1.92 0.68" />
        </geometry>
      <material name="blue_tinted_glass">
        <color rgba="0.25 0.55 0.76 0.65" />
        </material>
      </visual>
    <visual name="port_window_0">
      <origin xyz="-2.1 1.095 -0.2" rpy="0 0 0" />
      <geometry>
        <box size="0.72 0.05 0.55" />
        </geometry>
      <material name="blue_tinted_glass">
        <color rgba="0.25 0.55 0.76 0.65" />
        </material>
      </visual>
    <visual name="port_window_1">
      <origin xyz="-0.7 1.095 -0.2" rpy="0 0 0" />
      <geometry>
        <box size="0.72 0.05 0.55" />
        </geometry>
      <material name="blue_tinted_glass">
        <color rgba="0.25 0.55 0.76 0.65" />
        </material>
      </visual>
    <visual name="port_window_2">
      <origin xyz="0.7 1.095 -0.2" rpy="0 0 0" />
      <geometry>
        <box size="0.72 0.05 0.55" />
        </geometry>
      <material name="blue_tinted_glass">
        <color rgba="0.25 0.55 0.76 0.65" />
        </material>
      </visual>
    <visual name="port_window_3">
      <origin xyz="2.1 1.095 -0.2" rpy="0 0 0" />
      <geometry>
        <box size="0.72 0.05 0.55" />
        </geometry>
      <material name="blue_tinted_glass">
        <color rgba="0.25 0.55 0.76 0.65" />
        </material>
      </visual>
    <visual name="starboard_window_0">
      <origin xyz="-2.1 -1.095 -0.2" rpy="0 0 0" />
      <geometry>
        <box size="0.72 0.05 0.55" />
        </geometry>
      <material name="blue_tinted_glass">
        <color rgba="0.25 0.55 0.76 0.65" />
        </material>
      </visual>
    <visual name="starboard_window_1">
      <origin xyz="-0.7 -1.095 -0.2" rpy="0 0 0" />
      <geometry>
        <box size="0.72 0.05 0.55" />
        </geometry>
      <material name="blue_tinted_glass">
        <color rgba="0.25 0.55 0.76 0.65" />
        </material>
      </visual>
    <visual name="starboard_window_2">
      <origin xyz="0.7 -1.095 -0.2" rpy="0 0 0" />
      <geometry>
        <box size="0.72 0.05 0.55" />
        </geometry>
      <material name="blue_tinted_glass">
        <color rgba="0.25 0.55 0.76 0.65" />
        </material>
      </visual>
    <visual name="starboard_window_3">
      <origin xyz="2.1 -1.095 -0.2" rpy="0 0 0" />
      <geometry>
        <box size="0.72 0.05 0.55" />
        </geometry>
      <material name="blue_tinted_glass">
        <color rgba="0.25 0.55 0.76 0.65" />
        </material>
      </visual>
    <visual name="cabin_strut_rear">
      <origin xyz="-2.25 0 0.75" rpy="0 0 0" />
      <geometry>
        <box size="0.3 0.36 0.7" />
        </geometry>
      <material name="dull_aluminum">
        <color rgba="0.55 0.57 0.58 1" />
        </material>
      </visual>
    <visual name="cabin_strut_front">
      <origin xyz="2.25 0 0.75" rpy="0 0 0" />
      <geometry>
        <box size="0.3 0.36 0.7" />
        </geometry>
      <material name="dull_aluminum">
        <color rgba="0.55 0.57 0.58 1" />
        </material>
      </visual>
    <visual name="port_fork_prong">
      <origin xyz="-3.15 0.34 -1.78" rpy="0 0 0" />
      <geometry>
        <box size="0.22 0.1 1.18" />
        </geometry>
      <material name="dull_aluminum">
        <color rgba="0.55 0.57 0.58 1" />
        </material>
      </visual>
    <visual name="starboard_fork_prong">
      <origin xyz="-3.15 -0.34 -1.78" rpy="0 0 0" />
      <geometry>
        <box size="0.22 0.1 1.18" />
        </geometry>
      <material name="dull_aluminum">
        <color rgba="0.55 0.57 0.58 1" />
        </material>
      </visual>
    <visual name="wheel_axle">
      <origin xyz="-3.15 0 -2.02" rpy="-1.5708 0 0" />
      <geometry>
        <cylinder radius="0.063" length="0.76" />
        </geometry>
      <material name="dull_aluminum">
        <color rgba="0.55 0.57 0.58 1" />
        </material>
      </visual>
    <collision name="cabin_shell">
      <origin xyz="0 0 -0.38" rpy="0 0 0" />
      <geometry>
        <box size="7.8 2.15 1.65" />
        </geometry>
      </collision>
    <collision name="front_windshield">
      <origin xyz="3.45 0 -0.05" rpy="0 0 0" />
      <geometry>
        <box size="1.5 1.92 0.68" />
        </geometry>
      </collision>
    <collision name="port_window_0">
      <origin xyz="-2.1 1.095 -0.2" rpy="0 0 0" />
      <geometry>
        <box size="0.72 0.05 0.55" />
        </geometry>
      </collision>
    <collision name="port_window_1">
      <origin xyz="-0.7 1.095 -0.2" rpy="0 0 0" />
      <geometry>
        <box size="0.72 0.05 0.55" />
        </geometry>
      </collision>
    <collision name="port_window_2">
      <origin xyz="0.7 1.095 -0.2" rpy="0 0 0" />
      <geometry>
        <box size="0.72 0.05 0.55" />
        </geometry>
      </collision>
    <collision name="port_window_3">
      <origin xyz="2.1 1.095 -0.2" rpy="0 0 0" />
      <geometry>
        <box size="0.72 0.05 0.55" />
        </geometry>
      </collision>
    <collision name="starboard_window_0">
      <origin xyz="-2.1 -1.095 -0.2" rpy="0 0 0" />
      <geometry>
        <box size="0.72 0.05 0.55" />
        </geometry>
      </collision>
    <collision name="starboard_window_1">
      <origin xyz="-0.7 -1.095 -0.2" rpy="0 0 0" />
      <geometry>
        <box size="0.72 0.05 0.55" />
        </geometry>
      </collision>
    <collision name="starboard_window_2">
      <origin xyz="0.7 -1.095 -0.2" rpy="0 0 0" />
      <geometry>
        <box size="0.72 0.05 0.55" />
        </geometry>
      </collision>
    <collision name="starboard_window_3">
      <origin xyz="2.1 -1.095 -0.2" rpy="0 0 0" />
      <geometry>
        <box size="0.72 0.05 0.55" />
        </geometry>
      </collision>
    <collision name="cabin_strut_rear">
      <origin xyz="-2.25 0 0.75" rpy="0 0 0" />
      <geometry>
        <box size="0.3 0.36 0.7" />
        </geometry>
      </collision>
    <collision name="cabin_strut_front">
      <origin xyz="2.25 0 0.75" rpy="0 0 0" />
      <geometry>
        <box size="0.3 0.36 0.7" />
        </geometry>
      </collision>
    <collision name="port_fork_prong">
      <origin xyz="-3.15 0.34 -1.78" rpy="0 0 0" />
      <geometry>
        <box size="0.22 0.1 1.18" />
        </geometry>
      </collision>
    <collision name="starboard_fork_prong">
      <origin xyz="-3.15 -0.34 -1.78" rpy="0 0 0" />
      <geometry>
        <box size="0.22 0.1 1.18" />
        </geometry>
      </collision>
    <collision name="wheel_axle">
      <origin xyz="-3.15 0 -2.02" rpy="-1.5708 0 0" />
      <geometry>
        <cylinder radius="0.063" length="0.76" />
        </geometry>
      </collision>
    </link>
  <link name="port_nacelle">
    <visual name="nacelle_shell">
      <geometry>
        <mesh filename="assets/meshes/nacelle_shell.obj" />
        </geometry>
      <material name="dull_aluminum">
        <color rgba="0.55 0.57 0.58 1" />
        </material>
      </visual>
    <visual name="support_pylon">
      <origin xyz="0 -0.66 1.24" rpy="0 0.728317 -1.5708" />
      <geometry>
        <cylinder radius="0.13" length="1.98313" />
        </geometry>
      <material name="dull_aluminum">
        <color rgba="0.55 0.57 0.58 1" />
        </material>
      </visual>
    <visual name="prop_shaft">
      <origin xyz="1.43 0 0" rpy="0 1.5708 0" />
      <geometry>
        <cylinder radius="0.16" length="0.32" />
        </geometry>
      <material name="rubber_black">
        <color rgba="0.03 0.035 0.04 1" />
        </material>
      </visual>
    <collision name="nacelle_shell">
      <geometry>
        <mesh filename="assets/meshes/nacelle_shell.obj" />
        </geometry>
      </collision>
    <collision name="support_pylon">
      <origin xyz="0 -0.66 1.24" rpy="0 0.728317 -1.5708" />
      <geometry>
        <cylinder radius="0.13" length="1.98313" />
        </geometry>
      </collision>
    <collision name="prop_shaft">
      <origin xyz="1.43 0 0" rpy="0 1.5708 0" />
      <geometry>
        <cylinder radius="0.16" length="0.32" />
        </geometry>
      </collision>
    </link>
  <link name="port_propeller">
    <visual name="propeller_rotor">
      <origin xyz="0 0 0" rpy="0 1.5708 0" />
      <geometry>
        <mesh filename="assets/meshes/port_propeller_rotor.obj" />
        </geometry>
      <material name="rubber_black">
        <color rgba="0.03 0.035 0.04 1" />
        </material>
      </visual>
    <collision name="propeller_rotor">
      <origin xyz="0 0 0" rpy="0 1.5708 0" />
      <geometry>
        <mesh filename="assets/meshes/port_propeller_rotor.obj" />
        </geometry>
      </collision>
    </link>
  <link name="starboard_nacelle">
    <visual name="nacelle_shell">
      <geometry>
        <mesh filename="assets/meshes/nacelle_shell.obj" />
        </geometry>
      <material name="dull_aluminum">
        <color rgba="0.55 0.57 0.58 1" />
        </material>
      </visual>
    <visual name="support_pylon">
      <origin xyz="0 0.66 1.24" rpy="0 0.728317 1.5708" />
      <geometry>
        <cylinder radius="0.13" length="1.98313" />
        </geometry>
      <material name="dull_aluminum">
        <color rgba="0.55 0.57 0.58 1" />
        </material>
      </visual>
    <visual name="prop_shaft">
      <origin xyz="1.43 0 0" rpy="0 1.5708 0" />
      <geometry>
        <cylinder radius="0.16" length="0.32" />
        </geometry>
      <material name="rubber_black">
        <color rgba="0.03 0.035 0.04 1" />
        </material>
      </visual>
    <collision name="nacelle_shell">
      <geometry>
        <mesh filename="assets/meshes/nacelle_shell.obj" />
        </geometry>
      </collision>
    <collision name="support_pylon">
      <origin xyz="0 0.66 1.24" rpy="0 0.728317 1.5708" />
      <geometry>
        <cylinder radius="0.13" length="1.98313" />
        </geometry>
      </collision>
    <collision name="prop_shaft">
      <origin xyz="1.43 0 0" rpy="0 1.5708 0" />
      <geometry>
        <cylinder radius="0.16" length="0.32" />
        </geometry>
      </collision>
    </link>
  <link name="starboard_propeller">
    <visual name="propeller_rotor">
      <origin xyz="0 0 0" rpy="0 1.5708 0" />
      <geometry>
        <mesh filename="assets/meshes/starboard_propeller_rotor.obj" />
        </geometry>
      <material name="rubber_black">
        <color rgba="0.03 0.035 0.04 1" />
        </material>
      </visual>
    <collision name="propeller_rotor">
      <origin xyz="0 0 0" rpy="0 1.5708 0" />
      <geometry>
        <mesh filename="assets/meshes/starboard_propeller_rotor.obj" />
        </geometry>
      </collision>
    </link>
  <link name="rudder">
    <visual name="rudder_panel">
      <origin xyz="-1.275 0 0" rpy="0 0 0" />
      <geometry>
        <box size="2.55 0.16 6.2" />
        </geometry>
      <material name="advertising_blue">
        <color rgba="0.08 0.22 0.62 1" />
        </material>
      </visual>
    <collision name="rudder_panel">
      <origin xyz="-1.275 0 0" rpy="0 0 0" />
      <geometry>
        <box size="2.55 0.16 6.2" />
        </geometry>
      </collision>
    </link>
  <link name="port_elevator">
    <visual name="elevator_panel">
      <origin xyz="-1.225 0 0" rpy="0 0 0" />
      <geometry>
        <box size="2.45 3.85 0.16" />
        </geometry>
      <material name="advertising_blue">
        <color rgba="0.08 0.22 0.62 1" />
        </material>
      </visual>
    <collision name="elevator_panel">
      <origin xyz="-1.225 0 0" rpy="0 0 0" />
      <geometry>
        <box size="2.45 3.85 0.16" />
        </geometry>
      </collision>
    </link>
  <link name="starboard_elevator">
    <visual name="elevator_panel">
      <origin xyz="-1.225 0 0" rpy="0 0 0" />
      <geometry>
        <box size="2.45 3.85 0.16" />
        </geometry>
      <material name="advertising_blue">
        <color rgba="0.08 0.22 0.62 1" />
        </material>
      </visual>
    <collision name="elevator_panel">
      <origin xyz="-1.225 0 0" rpy="0 0 0" />
      <geometry>
        <box size="2.45 3.85 0.16" />
        </geometry>
      </collision>
    </link>
  <link name="mooring_wheel">
    <visual name="tire">
      <origin xyz="0 0 0" rpy="0 0 1.5708" />
      <geometry>
        <mesh filename="assets/meshes/mooring_tire.obj" />
        </geometry>
      <material name="rubber_black">
        <color rgba="0.03 0.035 0.04 1" />
        </material>
      </visual>
    <visual name="rim">
      <origin xyz="0 0 0" rpy="0 0 1.5708" />
      <geometry>
        <mesh filename="assets/meshes/mooring_rim.obj" />
        </geometry>
      <material name="dull_aluminum">
        <color rgba="0.55 0.57 0.58 1" />
        </material>
      </visual>
    <collision name="tire">
      <origin xyz="0 0 0" rpy="0 0 1.5708" />
      <geometry>
        <mesh filename="assets/meshes/mooring_tire.obj" />
        </geometry>
      </collision>
    <collision name="rim">
      <origin xyz="0 0 0" rpy="0 0 1.5708" />
      <geometry>
        <mesh filename="assets/meshes/mooring_rim.obj" />
        </geometry>
      </collision>
    </link>
  <joint name="envelope_to_gondola" type="fixed">
    <parent link="envelope" />
    <child link="gondola" />
    </joint>
  <joint name="envelope_to_port_nacelle" type="fixed">
    <origin xyz="4 8.27 3.27" rpy="0 0 0" />
    <parent link="envelope" />
    <child link="port_nacelle" />
    </joint>
  <joint name="port_propeller_spin" type="continuous">
    <origin xyz="1.56 0 0" rpy="0 0 0" />
    <parent link="port_nacelle" />
    <child link="port_propeller" />
    <axis xyz="1 0 0" />
    <limit effort="80" velocity="45" />
    </joint>
  <joint name="envelope_to_starboard_nacelle" type="fixed">
    <origin xyz="4 -8.27 3.27" rpy="0 0 0" />
    <parent link="envelope" />
    <child link="starboard_nacelle" />
    </joint>
  <joint name="starboard_propeller_spin" type="continuous">
    <origin xyz="1.56 0 0" rpy="0 0 0" />
    <parent link="starboard_nacelle" />
    <child link="starboard_propeller" />
    <axis xyz="1 0 0" />
    <limit effort="80" velocity="45" />
    </joint>
  <joint name="rudder_hinge" type="revolute">
    <origin xyz="-30 0 8" rpy="0 0 0" />
    <parent link="envelope" />
    <child link="rudder" />
    <axis xyz="0 0 1" />
    <limit effort="30" velocity="1.2" lower="-0.48" upper="0.48" />
    </joint>
  <joint name="port_elevator_hinge" type="revolute">
    <origin xyz="-30 3.7 8" rpy="0 0 0" />
    <parent link="envelope" />
    <child link="port_elevator" />
    <axis xyz="0 1 0" />
    <limit effort="22" velocity="1.2" lower="-0.42" upper="0.42" />
    </joint>
  <joint name="starboard_elevator_hinge" type="revolute">
    <origin xyz="-30 -3.7 8" rpy="0 0 0" />
    <parent link="envelope" />
    <child link="starboard_elevator" />
    <axis xyz="0 1 0" />
    <limit effort="22" velocity="1.2" lower="-0.42" upper="0.42" />
    </joint>
  <joint name="mooring_wheel_spin" type="continuous">
    <origin xyz="-3.15 0 -2.02" rpy="0 0 0" />
    <parent link="gondola" />
    <child link="mooring_wheel" />
    <axis xyz="0 1 0" />
    <limit effort="20" velocity="15" />
    </joint>
  </robot>
