<robot name="dj_mixer">
  <material name="mat_black_plastic">
    <color rgba="0.008 0.009 0.011 1" />
    </material>
  <material name="mat_graphite_panel">
    <color rgba="0.055 0.058 0.062 1" />
    </material>
  <material name="mat_dark_recess">
    <color rgba="0 0 0 1" />
    </material>
  <material name="mat_rubber">
    <color rgba="0.015 0.015 0.017 1" />
    </material>
  <material name="mat_knob_gray">
    <color rgba="0.24 0.25 0.26 1" />
    </material>
  <material name="mat_fader_silver">
    <color rgba="0.72 0.72 0.7 1" />
    </material>
  <material name="mat_white_print">
    <color rgba="0.92 0.92 0.86 1" />
    </material>
  <material name="mat_cue_blue">
    <color rgba="0.05 0.2 0.95 1" />
    </material>
  <material name="mat_red_led">
    <color rgba="1 0.05 0.02 1" />
    </material>
  <material name="mat_yellow_led">
    <color rgba="1 0.78 0.04 1" />
    </material>
  <material name="mat_green_led">
    <color rgba="0.05 0.9 0.18 1" />
    </material>
  <link name="deck">
    <visual name="chassis">
      <origin xyz="0 0 0.0225" rpy="0 0 0" />
      <geometry>
        <box size="0.44 0.32 0.045" />
        </geometry>
      <material name="mat_black_plastic">
        <color rgba="0.008 0.009 0.011 1" />
        </material>
      </visual>
    <visual name="faceplate">
      <origin xyz="0 0 0.048" rpy="0 0 0" />
      <geometry>
        <box size="0.42 0.3 0.006" />
        </geometry>
      <material name="mat_graphite_panel">
        <color rgba="0.055 0.058 0.062 1" />
        </material>
      </visual>
    <visual name="center_divider">
      <origin xyz="0 0.012 0.05175" rpy="0 0 0" />
      <geometry>
        <box size="0.006 0.265 0.0015" />
        </geometry>
      <material name="mat_white_print">
        <color rgba="0.92 0.92 0.86 1" />
        </material>
      </visual>
    <visual name="channel_strip_0">
      <origin xyz="-0.105 0.035 0.0517" rpy="0 0 0" />
      <geometry>
        <box size="0.155 0.226 0.0014" />
        </geometry>
      <material name="channel_tint_0">
        <color rgba="0.038 0.041 0.045 1" />
        </material>
      </visual>
    <visual name="channel_label_0">
      <origin xyz="-0.105 0.142 0.05155" rpy="0 0 0" />
      <geometry>
        <box size="0.09 0.006 0.0012" />
        </geometry>
      <material name="mat_white_print">
        <color rgba="0.92 0.92 0.86 1" />
        </material>
      </visual>
    <visual name="eq_label_0">
      <origin xyz="-0.105 -0.06 0.0524" rpy="0 0 0" />
      <geometry>
        <box size="0.07 0.005 0.0012" />
        </geometry>
      <material name="mat_white_print">
        <color rgba="0.92 0.92 0.86 1" />
        </material>
      </visual>
    <visual name="channel_strip_1">
      <origin xyz="0.105 0.035 0.0517" rpy="0 0 0" />
      <geometry>
        <box size="0.155 0.226 0.0014" />
        </geometry>
      <material name="channel_tint_1">
        <color rgba="0.038 0.041 0.045 1" />
        </material>
      </visual>
    <visual name="channel_label_1">
      <origin xyz="0.105 0.142 0.05155" rpy="0 0 0" />
      <geometry>
        <box size="0.09 0.006 0.0012" />
        </geometry>
      <material name="mat_white_print">
        <color rgba="0.92 0.92 0.86 1" />
        </material>
      </visual>
    <visual name="eq_label_1">
      <origin xyz="0.105 -0.06 0.0524" rpy="0 0 0" />
      <geometry>
        <box size="0.07 0.005 0.0012" />
        </geometry>
      <material name="mat_white_print">
        <color rgba="0.92 0.92 0.86 1" />
        </material>
      </visual>
    <visual name="tick_-0.10_0.12_a">
      <origin xyz="-0.127 0.117 0.05245" rpy="0 0 0.55" />
      <geometry>
        <box size="0.0026 0.014 0.0012" />
        </geometry>
      <material name="mat_white_print">
        <color rgba="0.92 0.92 0.86 1" />
        </material>
      </visual>
    <visual name="tick_-0.10_0.07_a">
      <origin xyz="-0.127 0.072 0.05245" rpy="0 0 0.55" />
      <geometry>
        <box size="0.0026 0.014 0.0012" />
        </geometry>
      <material name="mat_white_print">
        <color rgba="0.92 0.92 0.86 1" />
        </material>
      </visual>
    <visual name="tick_-0.10_0.03_a">
      <origin xyz="-0.127 0.027 0.05245" rpy="0 0 0.55" />
      <geometry>
        <box size="0.0026 0.014 0.0012" />
        </geometry>
      <material name="mat_white_print">
        <color rgba="0.92 0.92 0.86 1" />
        </material>
      </visual>
    <visual name="tick_-0.10_-0.02_a">
      <origin xyz="-0.127 -0.018 0.05245" rpy="0 0 0.55" />
      <geometry>
        <box size="0.0026 0.014 0.0012" />
        </geometry>
      <material name="mat_white_print">
        <color rgba="0.92 0.92 0.86 1" />
        </material>
      </visual>
    <visual name="tick_0.10_0.12_a">
      <origin xyz="0.083 0.117 0.05245" rpy="0 0 0.55" />
      <geometry>
        <box size="0.0026 0.014 0.0012" />
        </geometry>
      <material name="mat_white_print">
        <color rgba="0.92 0.92 0.86 1" />
        </material>
      </visual>
    <visual name="tick_0.10_0.07_a">
      <origin xyz="0.083 0.072 0.05245" rpy="0 0 0.55" />
      <geometry>
        <box size="0.0026 0.014 0.0012" />
        </geometry>
      <material name="mat_white_print">
        <color rgba="0.92 0.92 0.86 1" />
        </material>
      </visual>
    <visual name="tick_0.10_0.03_a">
      <origin xyz="0.083 0.027 0.05245" rpy="0 0 0.55" />
      <geometry>
        <box size="0.0026 0.014 0.0012" />
        </geometry>
      <material name="mat_white_print">
        <color rgba="0.92 0.92 0.86 1" />
        </material>
      </visual>
    <visual name="tick_0.10_-0.02_a">
      <origin xyz="0.083 -0.018 0.05245" rpy="0 0 0.55" />
      <geometry>
        <box size="0.0026 0.014 0.0012" />
        </geometry>
      <material name="mat_white_print">
        <color rgba="0.92 0.92 0.86 1" />
        </material>
      </visual>
    <visual name="crossfader_channel">
      <origin xyz="0 -0.124 0.0525" rpy="0 0 0" />
      <geometry>
        <box size="0.335 0.02 0.003" />
        </geometry>
      <material name="mat_dark_recess">
        <color rgba="0 0 0 1" />
        </material>
      </visual>
    <visual name="crossfader_stop_a">
      <origin xyz="-0.174 -0.124 0.053" rpy="0 0 0" />
      <geometry>
        <box size="0.006 0.032 0.004" />
        </geometry>
      <material name="mat_rubber">
        <color rgba="0.015 0.015 0.017 1" />
        </material>
      </visual>
    <visual name="crossfader_stop_b">
      <origin xyz="0.174 -0.124 0.053" rpy="0 0 0" />
      <geometry>
        <box size="0.006 0.032 0.004" />
        </geometry>
      <material name="mat_rubber">
        <color rgba="0.015 0.015 0.017 1" />
        </material>
      </visual>
    <visual name="meter_0_a">
      <origin xyz="-0.023 0.035 0.0529" rpy="0 0 0" />
      <geometry>
        <box size="0.012 0.006 0.0018" />
        </geometry>
      <material name="mat_green_led">
        <color rgba="0.05 0.9 0.18 1" />
        </material>
      </visual>
    <visual name="meter_0_b">
      <origin xyz="0.023 0.035 0.0529" rpy="0 0 0" />
      <geometry>
        <box size="0.012 0.006 0.0018" />
        </geometry>
      <material name="mat_green_led">
        <color rgba="0.05 0.9 0.18 1" />
        </material>
      </visual>
    <visual name="meter_1_a">
      <origin xyz="-0.023 0.049 0.0529" rpy="0 0 0" />
      <geometry>
        <box size="0.012 0.006 0.0018" />
        </geometry>
      <material name="mat_green_led">
        <color rgba="0.05 0.9 0.18 1" />
        </material>
      </visual>
    <visual name="meter_1_b">
      <origin xyz="0.023 0.049 0.0529" rpy="0 0 0" />
      <geometry>
        <box size="0.012 0.006 0.0018" />
        </geometry>
      <material name="mat_green_led">
        <color rgba="0.05 0.9 0.18 1" />
        </material>
      </visual>
    <visual name="meter_2_a">
      <origin xyz="-0.023 0.063 0.0529" rpy="0 0 0" />
      <geometry>
        <box size="0.012 0.006 0.0018" />
        </geometry>
      <material name="mat_green_led">
        <color rgba="0.05 0.9 0.18 1" />
        </material>
      </visual>
    <visual name="meter_2_b">
      <origin xyz="0.023 0.063 0.0529" rpy="0 0 0" />
      <geometry>
        <box size="0.012 0.006 0.0018" />
        </geometry>
      <material name="mat_green_led">
        <color rgba="0.05 0.9 0.18 1" />
        </material>
      </visual>
    <visual name="meter_3_a">
      <origin xyz="-0.023 0.077 0.0529" rpy="0 0 0" />
      <geometry>
        <box size="0.012 0.006 0.0018" />
        </geometry>
      <material name="mat_yellow_led">
        <color rgba="1 0.78 0.04 1" />
        </material>
      </visual>
    <visual name="meter_3_b">
      <origin xyz="0.023 0.077 0.0529" rpy="0 0 0" />
      <geometry>
        <box size="0.012 0.006 0.0018" />
        </geometry>
      <material name="mat_yellow_led">
        <color rgba="1 0.78 0.04 1" />
        </material>
      </visual>
    <visual name="meter_4_a">
      <origin xyz="-0.023 0.091 0.0529" rpy="0 0 0" />
      <geometry>
        <box size="0.012 0.006 0.0018" />
        </geometry>
      <material name="mat_yellow_led">
        <color rgba="1 0.78 0.04 1" />
        </material>
      </visual>
    <visual name="meter_4_b">
      <origin xyz="0.023 0.091 0.0529" rpy="0 0 0" />
      <geometry>
        <box size="0.012 0.006 0.0018" />
        </geometry>
      <material name="mat_yellow_led">
        <color rgba="1 0.78 0.04 1" />
        </material>
      </visual>
    <visual name="meter_5_a">
      <origin xyz="-0.023 0.105 0.0529" rpy="0 0 0" />
      <geometry>
        <box size="0.012 0.006 0.0018" />
        </geometry>
      <material name="mat_red_led">
        <color rgba="1 0.05 0.02 1" />
        </material>
      </visual>
    <visual name="meter_5_b">
      <origin xyz="0.023 0.105 0.0529" rpy="0 0 0" />
      <geometry>
        <box size="0.012 0.006 0.0018" />
        </geometry>
      <material name="mat_red_led">
        <color rgba="1 0.05 0.02 1" />
        </material>
      </visual>
    <visual name="cue_button_0">
      <origin xyz="-0.156 -0.079 0.053" rpy="0 0 0" />
      <geometry>
        <box size="0.018 0.018 0.004" />
        </geometry>
      <material name="mat_rubber">
        <color rgba="0.015 0.015 0.017 1" />
        </material>
      </visual>
    <visual name="cue_button_1">
      <origin xyz="-0.132 -0.079 0.053" rpy="0 0 0" />
      <geometry>
        <box size="0.018 0.018 0.004" />
        </geometry>
      <material name="mat_cue_blue">
        <color rgba="0.05 0.2 0.95 1" />
        </material>
      </visual>
    <visual name="cue_button_2">
      <origin xyz="0.132 -0.079 0.053" rpy="0 0 0" />
      <geometry>
        <box size="0.018 0.018 0.004" />
        </geometry>
      <material name="mat_cue_blue">
        <color rgba="0.05 0.2 0.95 1" />
        </material>
      </visual>
    <visual name="cue_button_3">
      <origin xyz="0.156 -0.079 0.053" rpy="0 0 0" />
      <geometry>
        <box size="0.018 0.018 0.004" />
        </geometry>
      <material name="mat_rubber">
        <color rgba="0.015 0.015 0.017 1" />
        </material>
      </visual>
    <visual name="cue_yoke_0">
      <origin xyz="-0.019 -0.067 0.058" rpy="0 0 0" />
      <geometry>
        <box size="0.006 0.02 0.014" />
        </geometry>
      <material name="mat_black_plastic">
        <color rgba="0.008 0.009 0.011 1" />
        </material>
      </visual>
    <visual name="cue_yoke_1">
      <origin xyz="0.019 -0.067 0.058" rpy="0 0 0" />
      <geometry>
        <box size="0.006 0.02 0.014" />
        </geometry>
      <material name="mat_black_plastic">
        <color rgba="0.008 0.009 0.011 1" />
        </material>
      </visual>
    <visual name="cue_slot_plate">
      <origin xyz="0 -0.067 0.052" rpy="0 0 0" />
      <geometry>
        <box size="0.048 0.024 0.002" />
        </geometry>
      <material name="mat_dark_recess">
        <color rgba="0 0 0 1" />
        </material>
      </visual>
    <collision name="chassis">
      <origin xyz="0 0 0.0225" rpy="0 0 0" />
      <geometry>
        <box size="0.44 0.32 0.045" />
        </geometry>
      </collision>
    <collision name="faceplate">
      <origin xyz="0 0 0.048" rpy="0 0 0" />
      <geometry>
        <box size="0.42 0.3 0.006" />
        </geometry>
      </collision>
    <collision name="center_divider">
      <origin xyz="0 0.012 0.05175" rpy="0 0 0" />
      <geometry>
        <box size="0.006 0.265 0.0015" />
        </geometry>
      </collision>
    <collision name="channel_strip_0">
      <origin xyz="-0.105 0.035 0.0517" rpy="0 0 0" />
      <geometry>
        <box size="0.155 0.226 0.0014" />
        </geometry>
      </collision>
    <collision name="channel_label_0">
      <origin xyz="-0.105 0.142 0.05155" rpy="0 0 0" />
      <geometry>
        <box size="0.09 0.006 0.0012" />
        </geometry>
      </collision>
    <collision name="eq_label_0">
      <origin xyz="-0.105 -0.06 0.0524" rpy="0 0 0" />
      <geometry>
        <box size="0.07 0.005 0.0012" />
        </geometry>
      </collision>
    <collision name="channel_strip_1">
      <origin xyz="0.105 0.035 0.0517" rpy="0 0 0" />
      <geometry>
        <box size="0.155 0.226 0.0014" />
        </geometry>
      </collision>
    <collision name="channel_label_1">
      <origin xyz="0.105 0.142 0.05155" rpy="0 0 0" />
      <geometry>
        <box size="0.09 0.006 0.0012" />
        </geometry>
      </collision>
    <collision name="eq_label_1">
      <origin xyz="0.105 -0.06 0.0524" rpy="0 0 0" />
      <geometry>
        <box size="0.07 0.005 0.0012" />
        </geometry>
      </collision>
    <collision name="tick_-0.10_0.12_a">
      <origin xyz="-0.127 0.117 0.05245" rpy="0 0 0.55" />
      <geometry>
        <box size="0.0026 0.014 0.0012" />
        </geometry>
      </collision>
    <collision name="tick_-0.10_0.07_a">
      <origin xyz="-0.127 0.072 0.05245" rpy="0 0 0.55" />
      <geometry>
        <box size="0.0026 0.014 0.0012" />
        </geometry>
      </collision>
    <collision name="tick_-0.10_0.03_a">
      <origin xyz="-0.127 0.027 0.05245" rpy="0 0 0.55" />
      <geometry>
        <box size="0.0026 0.014 0.0012" />
        </geometry>
      </collision>
    <collision name="tick_-0.10_-0.02_a">
      <origin xyz="-0.127 -0.018 0.05245" rpy="0 0 0.55" />
      <geometry>
        <box size="0.0026 0.014 0.0012" />
        </geometry>
      </collision>
    <collision name="tick_0.10_0.12_a">
      <origin xyz="0.083 0.117 0.05245" rpy="0 0 0.55" />
      <geometry>
        <box size="0.0026 0.014 0.0012" />
        </geometry>
      </collision>
    <collision name="tick_0.10_0.07_a">
      <origin xyz="0.083 0.072 0.05245" rpy="0 0 0.55" />
      <geometry>
        <box size="0.0026 0.014 0.0012" />
        </geometry>
      </collision>
    <collision name="tick_0.10_0.03_a">
      <origin xyz="0.083 0.027 0.05245" rpy="0 0 0.55" />
      <geometry>
        <box size="0.0026 0.014 0.0012" />
        </geometry>
      </collision>
    <collision name="tick_0.10_-0.02_a">
      <origin xyz="0.083 -0.018 0.05245" rpy="0 0 0.55" />
      <geometry>
        <box size="0.0026 0.014 0.0012" />
        </geometry>
      </collision>
    <collision name="crossfader_channel">
      <origin xyz="0 -0.124 0.0525" rpy="0 0 0" />
      <geometry>
        <box size="0.335 0.02 0.003" />
        </geometry>
      </collision>
    <collision name="crossfader_stop_a">
      <origin xyz="-0.174 -0.124 0.053" rpy="0 0 0" />
      <geometry>
        <box size="0.006 0.032 0.004" />
        </geometry>
      </collision>
    <collision name="crossfader_stop_b">
      <origin xyz="0.174 -0.124 0.053" rpy="0 0 0" />
      <geometry>
        <box size="0.006 0.032 0.004" />
        </geometry>
      </collision>
    <collision name="meter_0_a">
      <origin xyz="-0.023 0.035 0.0529" rpy="0 0 0" />
      <geometry>
        <box size="0.012 0.006 0.0018" />
        </geometry>
      </collision>
    <collision name="meter_0_b">
      <origin xyz="0.023 0.035 0.0529" rpy="0 0 0" />
      <geometry>
        <box size="0.012 0.006 0.0018" />
        </geometry>
      </collision>
    <collision name="meter_1_a">
      <origin xyz="-0.023 0.049 0.0529" rpy="0 0 0" />
      <geometry>
        <box size="0.012 0.006 0.0018" />
        </geometry>
      </collision>
    <collision name="meter_1_b">
      <origin xyz="0.023 0.049 0.0529" rpy="0 0 0" />
      <geometry>
        <box size="0.012 0.006 0.0018" />
        </geometry>
      </collision>
    <collision name="meter_2_a">
      <origin xyz="-0.023 0.063 0.0529" rpy="0 0 0" />
      <geometry>
        <box size="0.012 0.006 0.0018" />
        </geometry>
      </collision>
    <collision name="meter_2_b">
      <origin xyz="0.023 0.063 0.0529" rpy="0 0 0" />
      <geometry>
        <box size="0.012 0.006 0.0018" />
        </geometry>
      </collision>
    <collision name="meter_3_a">
      <origin xyz="-0.023 0.077 0.0529" rpy="0 0 0" />
      <geometry>
        <box size="0.012 0.006 0.0018" />
        </geometry>
      </collision>
    <collision name="meter_3_b">
      <origin xyz="0.023 0.077 0.0529" rpy="0 0 0" />
      <geometry>
        <box size="0.012 0.006 0.0018" />
        </geometry>
      </collision>
    <collision name="meter_4_a">
      <origin xyz="-0.023 0.091 0.0529" rpy="0 0 0" />
      <geometry>
        <box size="0.012 0.006 0.0018" />
        </geometry>
      </collision>
    <collision name="meter_4_b">
      <origin xyz="0.023 0.091 0.0529" rpy="0 0 0" />
      <geometry>
        <box size="0.012 0.006 0.0018" />
        </geometry>
      </collision>
    <collision name="meter_5_a">
      <origin xyz="-0.023 0.105 0.0529" rpy="0 0 0" />
      <geometry>
        <box size="0.012 0.006 0.0018" />
        </geometry>
      </collision>
    <collision name="meter_5_b">
      <origin xyz="0.023 0.105 0.0529" rpy="0 0 0" />
      <geometry>
        <box size="0.012 0.006 0.0018" />
        </geometry>
      </collision>
    <collision name="cue_button_0">
      <origin xyz="-0.156 -0.079 0.053" rpy="0 0 0" />
      <geometry>
        <box size="0.018 0.018 0.004" />
        </geometry>
      </collision>
    <collision name="cue_button_1">
      <origin xyz="-0.132 -0.079 0.053" rpy="0 0 0" />
      <geometry>
        <box size="0.018 0.018 0.004" />
        </geometry>
      </collision>
    <collision name="cue_button_2">
      <origin xyz="0.132 -0.079 0.053" rpy="0 0 0" />
      <geometry>
        <box size="0.018 0.018 0.004" />
        </geometry>
      </collision>
    <collision name="cue_button_3">
      <origin xyz="0.156 -0.079 0.053" rpy="0 0 0" />
      <geometry>
        <box size="0.018 0.018 0.004" />
        </geometry>
      </collision>
    <collision name="cue_yoke_0">
      <origin xyz="-0.019 -0.067 0.058" rpy="0 0 0" />
      <geometry>
        <box size="0.006 0.02 0.014" />
        </geometry>
      </collision>
    <collision name="cue_yoke_1">
      <origin xyz="0.019 -0.067 0.058" rpy="0 0 0" />
      <geometry>
        <box size="0.006 0.02 0.014" />
        </geometry>
      </collision>
    <collision name="cue_slot_plate">
      <origin xyz="0 -0.067 0.052" rpy="0 0 0" />
      <geometry>
        <box size="0.048 0.024 0.002" />
        </geometry>
      </collision>
    </link>
  <link name="channel_knob_0_0">
    <visual name="knob_cap">
      <geometry>
        <mesh filename="assets/meshes/channel_rotary_knob.obj" />
        </geometry>
      <material name="mat_knob_gray">
        <color rgba="0.24 0.25 0.26 1" />
        </material>
      </visual>
    <visual name="pointer_line">
      <origin xyz="0 0.0065 0.0208" rpy="0 0 0" />
      <geometry>
        <box size="0.0032 0.016 0.0016" />
        </geometry>
      <material name="mat_white_print">
        <color rgba="0.92 0.92 0.86 1" />
        </material>
      </visual>
    <collision name="knob_cap">
      <geometry>
        <mesh filename="assets/meshes/channel_rotary_knob.obj" />
        </geometry>
      </collision>
    <collision name="pointer_line">
      <origin xyz="0 0.0065 0.0208" rpy="0 0 0" />
      <geometry>
        <box size="0.0032 0.016 0.0016" />
        </geometry>
      </collision>
    </link>
  <link name="channel_knob_0_1">
    <visual name="knob_cap">
      <geometry>
        <mesh filename="assets/meshes/channel_rotary_knob.obj" />
        </geometry>
      <material name="mat_knob_gray">
        <color rgba="0.24 0.25 0.26 1" />
        </material>
      </visual>
    <visual name="pointer_line">
      <origin xyz="0 0.0065 0.0208" rpy="0 0 0" />
      <geometry>
        <box size="0.0032 0.016 0.0016" />
        </geometry>
      <material name="mat_white_print">
        <color rgba="0.92 0.92 0.86 1" />
        </material>
      </visual>
    <collision name="knob_cap">
      <geometry>
        <mesh filename="assets/meshes/channel_rotary_knob.obj" />
        </geometry>
      </collision>
    <collision name="pointer_line">
      <origin xyz="0 0.0065 0.0208" rpy="0 0 0" />
      <geometry>
        <box size="0.0032 0.016 0.0016" />
        </geometry>
      </collision>
    </link>
  <link name="channel_knob_0_2">
    <visual name="knob_cap">
      <geometry>
        <mesh filename="assets/meshes/channel_rotary_knob.obj" />
        </geometry>
      <material name="mat_knob_gray">
        <color rgba="0.24 0.25 0.26 1" />
        </material>
      </visual>
    <visual name="pointer_line">
      <origin xyz="0 0.0065 0.0208" rpy="0 0 0" />
      <geometry>
        <box size="0.0032 0.016 0.0016" />
        </geometry>
      <material name="mat_white_print">
        <color rgba="0.92 0.92 0.86 1" />
        </material>
      </visual>
    <collision name="knob_cap">
      <geometry>
        <mesh filename="assets/meshes/channel_rotary_knob.obj" />
        </geometry>
      </collision>
    <collision name="pointer_line">
      <origin xyz="0 0.0065 0.0208" rpy="0 0 0" />
      <geometry>
        <box size="0.0032 0.016 0.0016" />
        </geometry>
      </collision>
    </link>
  <link name="channel_knob_0_3">
    <visual name="knob_cap">
      <geometry>
        <mesh filename="assets/meshes/channel_rotary_knob.obj" />
        </geometry>
      <material name="mat_knob_gray">
        <color rgba="0.24 0.25 0.26 1" />
        </material>
      </visual>
    <visual name="pointer_line">
      <origin xyz="0 0.0065 0.0208" rpy="0 0 0" />
      <geometry>
        <box size="0.0032 0.016 0.0016" />
        </geometry>
      <material name="mat_white_print">
        <color rgba="0.92 0.92 0.86 1" />
        </material>
      </visual>
    <collision name="knob_cap">
      <geometry>
        <mesh filename="assets/meshes/channel_rotary_knob.obj" />
        </geometry>
      </collision>
    <collision name="pointer_line">
      <origin xyz="0 0.0065 0.0208" rpy="0 0 0" />
      <geometry>
        <box size="0.0032 0.016 0.0016" />
        </geometry>
      </collision>
    </link>
  <link name="channel_knob_1_0">
    <visual name="knob_cap">
      <geometry>
        <mesh filename="assets/meshes/channel_rotary_knob.obj" />
        </geometry>
      <material name="mat_knob_gray">
        <color rgba="0.24 0.25 0.26 1" />
        </material>
      </visual>
    <visual name="pointer_line">
      <origin xyz="0 0.0065 0.0208" rpy="0 0 0" />
      <geometry>
        <box size="0.0032 0.016 0.0016" />
        </geometry>
      <material name="mat_white_print">
        <color rgba="0.92 0.92 0.86 1" />
        </material>
      </visual>
    <collision name="knob_cap">
      <geometry>
        <mesh filename="assets/meshes/channel_rotary_knob.obj" />
        </geometry>
      </collision>
    <collision name="pointer_line">
      <origin xyz="0 0.0065 0.0208" rpy="0 0 0" />
      <geometry>
        <box size="0.0032 0.016 0.0016" />
        </geometry>
      </collision>
    </link>
  <link name="channel_knob_1_1">
    <visual name="knob_cap">
      <geometry>
        <mesh filename="assets/meshes/channel_rotary_knob.obj" />
        </geometry>
      <material name="mat_knob_gray">
        <color rgba="0.24 0.25 0.26 1" />
        </material>
      </visual>
    <visual name="pointer_line">
      <origin xyz="0 0.0065 0.0208" rpy="0 0 0" />
      <geometry>
        <box size="0.0032 0.016 0.0016" />
        </geometry>
      <material name="mat_white_print">
        <color rgba="0.92 0.92 0.86 1" />
        </material>
      </visual>
    <collision name="knob_cap">
      <geometry>
        <mesh filename="assets/meshes/channel_rotary_knob.obj" />
        </geometry>
      </collision>
    <collision name="pointer_line">
      <origin xyz="0 0.0065 0.0208" rpy="0 0 0" />
      <geometry>
        <box size="0.0032 0.016 0.0016" />
        </geometry>
      </collision>
    </link>
  <link name="channel_knob_1_2">
    <visual name="knob_cap">
      <geometry>
        <mesh filename="assets/meshes/channel_rotary_knob.obj" />
        </geometry>
      <material name="mat_knob_gray">
        <color rgba="0.24 0.25 0.26 1" />
        </material>
      </visual>
    <visual name="pointer_line">
      <origin xyz="0 0.0065 0.0208" rpy="0 0 0" />
      <geometry>
        <box size="0.0032 0.016 0.0016" />
        </geometry>
      <material name="mat_white_print">
        <color rgba="0.92 0.92 0.86 1" />
        </material>
      </visual>
    <collision name="knob_cap">
      <geometry>
        <mesh filename="assets/meshes/channel_rotary_knob.obj" />
        </geometry>
      </collision>
    <collision name="pointer_line">
      <origin xyz="0 0.0065 0.0208" rpy="0 0 0" />
      <geometry>
        <box size="0.0032 0.016 0.0016" />
        </geometry>
      </collision>
    </link>
  <link name="channel_knob_1_3">
    <visual name="knob_cap">
      <geometry>
        <mesh filename="assets/meshes/channel_rotary_knob.obj" />
        </geometry>
      <material name="mat_knob_gray">
        <color rgba="0.24 0.25 0.26 1" />
        </material>
      </visual>
    <visual name="pointer_line">
      <origin xyz="0 0.0065 0.0208" rpy="0 0 0" />
      <geometry>
        <box size="0.0032 0.016 0.0016" />
        </geometry>
      <material name="mat_white_print">
        <color rgba="0.92 0.92 0.86 1" />
        </material>
      </visual>
    <collision name="knob_cap">
      <geometry>
        <mesh filename="assets/meshes/channel_rotary_knob.obj" />
        </geometry>
      </collision>
    <collision name="pointer_line">
      <origin xyz="0 0.0065 0.0208" rpy="0 0 0" />
      <geometry>
        <box size="0.0032 0.016 0.0016" />
        </geometry>
      </collision>
    </link>
  <link name="crossfader">
    <visual name="fader_cap">
      <origin xyz="0 0 0.005" rpy="0 0 0" />
      <geometry>
        <box size="0.058 0.026 0.01" />
        </geometry>
      <material name="mat_fader_silver">
        <color rgba="0.72 0.72 0.7 1" />
        </material>
      </visual>
    <visual name="finger_ridge">
      <origin xyz="0 0 0.013" rpy="0 0 0" />
      <geometry>
        <box size="0.036 0.014 0.006" />
        </geometry>
      <material name="mat_white_print">
        <color rgba="0.92 0.92 0.86 1" />
        </material>
      </visual>
    <collision name="fader_cap">
      <origin xyz="0 0 0.005" rpy="0 0 0" />
      <geometry>
        <box size="0.058 0.026 0.01" />
        </geometry>
      </collision>
    <collision name="finger_ridge">
      <origin xyz="0 0 0.013" rpy="0 0 0" />
      <geometry>
        <box size="0.036 0.014 0.006" />
        </geometry>
      </collision>
    </link>
  <link name="cue_lever">
    <visual name="hinge_barrel">
      <origin xyz="0 0 0" rpy="0 1.5708 0" />
      <geometry>
        <cylinder radius="0.005" length="0.032" />
        </geometry>
      <material name="mat_black_plastic">
        <color rgba="0.008 0.009 0.011 1" />
        </material>
      </visual>
    <visual name="lever_stem">
      <origin xyz="0 0.0268901 0.0154247" rpy="-1.05 0 0" />
      <geometry>
        <cylinder radius="0.0032" length="0.062" />
        </geometry>
      <material name="mat_fader_silver">
        <color rgba="0.72 0.72 0.7 1" />
        </material>
      </visual>
    <visual name="lever_tip">
      <origin xyz="0 0.051 0.029" rpy="-1.05 0 0" />
      <geometry>
        <box size="0.03 0.014 0.01" />
        </geometry>
      <material name="mat_cue_blue">
        <color rgba="0.05 0.2 0.95 1" />
        </material>
      </visual>
    <collision name="hinge_barrel">
      <origin xyz="0 0 0" rpy="0 1.5708 0" />
      <geometry>
        <cylinder radius="0.005" length="0.032" />
        </geometry>
      </collision>
    <collision name="lever_stem">
      <origin xyz="0 0.0268901 0.0154247" rpy="-1.05 0 0" />
      <geometry>
        <cylinder radius="0.0032" length="0.062" />
        </geometry>
      </collision>
    <collision name="lever_tip">
      <origin xyz="0 0.051 0.029" rpy="-1.05 0 0" />
      <geometry>
        <box size="0.03 0.014 0.01" />
        </geometry>
      </collision>
    </link>
  <joint name="deck_to_channel_knob_0_0" type="revolute">
    <origin xyz="-0.105 0.115 0.051" rpy="0 0 0" />
    <parent link="deck" />
    <child link="channel_knob_0_0" />
    <axis xyz="0 0 1" />
    <limit effort="0.25" velocity="3" lower="-2.35" upper="2.35" />
    </joint>
  <joint name="deck_to_channel_knob_0_1" type="revolute">
    <origin xyz="-0.105 0.07 0.051" rpy="0 0 0" />
    <parent link="deck" />
    <child link="channel_knob_0_1" />
    <axis xyz="0 0 1" />
    <limit effort="0.25" velocity="3" lower="-2.35" upper="2.35" />
    </joint>
  <joint name="deck_to_channel_knob_0_2" type="revolute">
    <origin xyz="-0.105 0.025 0.051" rpy="0 0 0" />
    <parent link="deck" />
    <child link="channel_knob_0_2" />
    <axis xyz="0 0 1" />
    <limit effort="0.25" velocity="3" lower="-2.35" upper="2.35" />
    </joint>
  <joint name="deck_to_channel_knob_0_3" type="revolute">
    <origin xyz="-0.105 -0.02 0.051" rpy="0 0 0" />
    <parent link="deck" />
    <child link="channel_knob_0_3" />
    <axis xyz="0 0 1" />
    <limit effort="0.25" velocity="3" lower="-2.35" upper="2.35" />
    </joint>
  <joint name="deck_to_channel_knob_1_0" type="revolute">
    <origin xyz="0.105 0.115 0.051" rpy="0 0 0" />
    <parent link="deck" />
    <child link="channel_knob_1_0" />
    <axis xyz="0 0 1" />
    <limit effort="0.25" velocity="3" lower="-2.35" upper="2.35" />
    </joint>
  <joint name="deck_to_channel_knob_1_1" type="revolute">
    <origin xyz="0.105 0.07 0.051" rpy="0 0 0" />
    <parent link="deck" />
    <child link="channel_knob_1_1" />
    <axis xyz="0 0 1" />
    <limit effort="0.25" velocity="3" lower="-2.35" upper="2.35" />
    </joint>
  <joint name="deck_to_channel_knob_1_2" type="revolute">
    <origin xyz="0.105 0.025 0.051" rpy="0 0 0" />
    <parent link="deck" />
    <child link="channel_knob_1_2" />
    <axis xyz="0 0 1" />
    <limit effort="0.25" velocity="3" lower="-2.35" upper="2.35" />
    </joint>
  <joint name="deck_to_channel_knob_1_3" type="revolute">
    <origin xyz="0.105 -0.02 0.051" rpy="0 0 0" />
    <parent link="deck" />
    <child link="channel_knob_1_3" />
    <axis xyz="0 0 1" />
    <limit effort="0.25" velocity="3" lower="-2.35" upper="2.35" />
    </joint>
  <joint name="deck_to_crossfader" type="prismatic">
    <origin xyz="0 -0.124 0.054" rpy="0 0 0" />
    <parent link="deck" />
    <child link="crossfader" />
    <axis xyz="1 0 0" />
    <limit effort="6" velocity="0.9" lower="-0.126" upper="0.126" />
    </joint>
  <joint name="deck_to_cue_lever" type="revolute">
    <origin xyz="0 -0.067 0.058" rpy="0 0 0" />
    <parent link="deck" />
    <child link="cue_lever" />
    <axis xyz="1 0 0" />
    <limit effort="0.6" velocity="2" lower="-0.45" upper="0.45" />
    </joint>
  </robot>
