<robot name="machine_slide_rotary_head">
  <link name="guide">
    <visual name="base_plate">
      <origin xyz="0 0 0.02" rpy="0 0 0" />
      <geometry>
        <box size="1.05 0.34 0.04" />
        </geometry>
      <material name="painted_cast_iron">
        <color rgba="0.16 0.19 0.22 1" />
        </material>
      </visual>
    <visual name="center_way">
      <origin xyz="0 0 0.065" rpy="0 0 0" />
      <geometry>
        <box size="0.94 0.15 0.052" />
        </geometry>
      <material name="painted_cast_iron">
        <color rgba="0.16 0.19 0.22 1" />
        </material>
      </visual>
    <visual name="linear_rail_0">
      <origin xyz="0 -0.052 0.0985" rpy="0 0 0" />
      <geometry>
        <box size="0.92 0.03 0.019" />
        </geometry>
      <material name="ground_steel">
        <color rgba="0.72 0.74 0.72 1" />
        </material>
      </visual>
    <visual name="linear_rail_1">
      <origin xyz="0 0.052 0.0985" rpy="0 0 0" />
      <geometry>
        <box size="0.92 0.03 0.019" />
        </geometry>
      <material name="ground_steel">
        <color rgba="0.72 0.74 0.72 1" />
        </material>
      </visual>
    <visual name="end_stop_0">
      <origin xyz="-0.485 0 0.1" rpy="0 0 0" />
      <geometry>
        <box size="0.045 0.3 0.12" />
        </geometry>
      <material name="painted_cast_iron">
        <color rgba="0.16 0.19 0.22 1" />
        </material>
      </visual>
    <visual name="stop_screw_0_0">
      <origin xyz="-0.485 -0.095 0.164" rpy="0 0 0" />
      <geometry>
        <cylinder radius="0.01" length="0.008" />
        </geometry>
      <material name="dark_blued_steel">
        <color rgba="0.05 0.055 0.06 1" />
        </material>
      </visual>
    <visual name="stop_screw_0_1">
      <origin xyz="-0.485 0.095 0.164" rpy="0 0 0" />
      <geometry>
        <cylinder radius="0.01" length="0.008" />
        </geometry>
      <material name="dark_blued_steel">
        <color rgba="0.05 0.055 0.06 1" />
        </material>
      </visual>
    <visual name="end_stop_1">
      <origin xyz="0.485 0 0.1" rpy="0 0 0" />
      <geometry>
        <box size="0.045 0.3 0.12" />
        </geometry>
      <material name="painted_cast_iron">
        <color rgba="0.16 0.19 0.22 1" />
        </material>
      </visual>
    <visual name="stop_screw_1_0">
      <origin xyz="0.485 -0.095 0.164" rpy="0 0 0" />
      <geometry>
        <cylinder radius="0.01" length="0.008" />
        </geometry>
      <material name="dark_blued_steel">
        <color rgba="0.05 0.055 0.06 1" />
        </material>
      </visual>
    <visual name="stop_screw_1_1">
      <origin xyz="0.485 0.095 0.164" rpy="0 0 0" />
      <geometry>
        <cylinder radius="0.01" length="0.008" />
        </geometry>
      <material name="dark_blued_steel">
        <color rgba="0.05 0.055 0.06 1" />
        </material>
      </visual>
    <collision name="base_plate">
      <origin xyz="0 0 0.02" rpy="0 0 0" />
      <geometry>
        <box size="1.05 0.34 0.04" />
        </geometry>
      </collision>
    <collision name="center_way">
      <origin xyz="0 0 0.065" rpy="0 0 0" />
      <geometry>
        <box size="0.94 0.15 0.052" />
        </geometry>
      </collision>
    <collision name="linear_rail_0">
      <origin xyz="0 -0.052 0.0985" rpy="0 0 0" />
      <geometry>
        <box size="0.92 0.03 0.019" />
        </geometry>
      </collision>
    <collision name="linear_rail_1">
      <origin xyz="0 0.052 0.0985" rpy="0 0 0" />
      <geometry>
        <box size="0.92 0.03 0.019" />
        </geometry>
      </collision>
    <collision name="end_stop_0">
      <origin xyz="-0.485 0 0.1" rpy="0 0 0" />
      <geometry>
        <box size="0.045 0.3 0.12" />
        </geometry>
      </collision>
    <collision name="stop_screw_0_0">
      <origin xyz="-0.485 -0.095 0.164" rpy="0 0 0" />
      <geometry>
        <cylinder radius="0.01" length="0.008" />
        </geometry>
      </collision>
    <collision name="stop_screw_0_1">
      <origin xyz="-0.485 0.095 0.164" rpy="0 0 0" />
      <geometry>
        <cylinder radius="0.01" length="0.008" />
        </geometry>
      </collision>
    <collision name="end_stop_1">
      <origin xyz="0.485 0 0.1" rpy="0 0 0" />
      <geometry>
        <box size="0.045 0.3 0.12" />
        </geometry>
      </collision>
    <collision name="stop_screw_1_0">
      <origin xyz="0.485 -0.095 0.164" rpy="0 0 0" />
      <geometry>
        <cylinder radius="0.01" length="0.008" />
        </geometry>
      </collision>
    <collision name="stop_screw_1_1">
      <origin xyz="0.485 0.095 0.164" rpy="0 0 0" />
      <geometry>
        <cylinder radius="0.01" length="0.008" />
        </geometry>
      </collision>
    </link>
  <link name="carriage">
    <visual name="carriage_block">
      <geometry>
        <box size="0.22 0.24 0.09" />
        </geometry>
      <material name="carriage_blue_gray">
        <color rgba="0.22 0.3 0.36 1" />
        </material>
      </visual>
    <visual name="wear_pad_0">
      <origin xyz="0 -0.052 -0.05" rpy="0 0 0" />
      <geometry>
        <box size="0.185 0.024 0.013" />
        </geometry>
      <material name="ground_steel">
        <color rgba="0.72 0.74 0.72 1" />
        </material>
      </visual>
    <visual name="wear_pad_1">
      <origin xyz="0 0.052 -0.05" rpy="0 0 0" />
      <geometry>
        <box size="0.185 0.024 0.013" />
        </geometry>
      <material name="ground_steel">
        <color rgba="0.72 0.74 0.72 1" />
        </material>
      </visual>
    <visual name="side_gib_0">
      <origin xyz="0 -0.102 -0.057" rpy="0 0 0" />
      <geometry>
        <box size="0.205 0.034 0.058" />
        </geometry>
      <material name="carriage_blue_gray">
        <color rgba="0.22 0.3 0.36 1" />
        </material>
      </visual>
    <visual name="side_gib_1">
      <origin xyz="0 0.102 -0.057" rpy="0 0 0" />
      <geometry>
        <box size="0.205 0.034 0.058" />
        </geometry>
      <material name="carriage_blue_gray">
        <color rgba="0.22 0.3 0.36 1" />
        </material>
      </visual>
    <visual name="bearing_plate">
      <origin xyz="0 -0.142 0.05" rpy="0 0 0" />
      <geometry>
        <box size="0.178 0.044 0.178" />
        </geometry>
      <material name="carriage_blue_gray">
        <color rgba="0.22 0.3 0.36 1" />
        </material>
      </visual>
    <visual name="bearing_ring">
      <origin xyz="0 -0.166 0.06" rpy="0 0 0" />
      <geometry>
        <mesh filename="assets/meshes/bearing_ring.obj" />
        </geometry>
      <material name="ground_steel">
        <color rgba="0.72 0.74 0.72 1" />
        </material>
      </visual>
    <visual name="bearing_gusset_0">
      <origin xyz="-0.075 -0.118 0.018" rpy="0 0 0" />
      <geometry>
        <box size="0.026 0.065 0.105" />
        </geometry>
      <material name="carriage_blue_gray">
        <color rgba="0.22 0.3 0.36 1" />
        </material>
      </visual>
    <visual name="bearing_gusset_1">
      <origin xyz="0.075 -0.118 0.018" rpy="0 0 0" />
      <geometry>
        <box size="0.026 0.065 0.105" />
        </geometry>
      <material name="carriage_blue_gray">
        <color rgba="0.22 0.3 0.36 1" />
        </material>
      </visual>
    <visual name="cap_screw_0_0">
      <origin xyz="-0.07 -0.07 0.048" rpy="0 0 0" />
      <geometry>
        <cylinder radius="0.01" length="0.007" />
        </geometry>
      <material name="dark_blued_steel">
        <color rgba="0.05 0.055 0.06 1" />
        </material>
      </visual>
    <visual name="cap_screw_0_1">
      <origin xyz="-0.07 0.07 0.048" rpy="0 0 0" />
      <geometry>
        <cylinder radius="0.01" length="0.007" />
        </geometry>
      <material name="dark_blued_steel">
        <color rgba="0.05 0.055 0.06 1" />
        </material>
      </visual>
    <visual name="cap_screw_1_0">
      <origin xyz="0.07 -0.07 0.048" rpy="0 0 0" />
      <geometry>
        <cylinder radius="0.01" length="0.007" />
        </geometry>
      <material name="dark_blued_steel">
        <color rgba="0.05 0.055 0.06 1" />
        </material>
      </visual>
    <visual name="cap_screw_1_1">
      <origin xyz="0.07 0.07 0.048" rpy="0 0 0" />
      <geometry>
        <cylinder radius="0.01" length="0.007" />
        </geometry>
      <material name="dark_blued_steel">
        <color rgba="0.05 0.055 0.06 1" />
        </material>
      </visual>
    <collision name="carriage_block">
      <geometry>
        <box size="0.22 0.24 0.09" />
        </geometry>
      </collision>
    <collision name="wear_pad_0">
      <origin xyz="0 -0.052 -0.05" rpy="0 0 0" />
      <geometry>
        <box size="0.185 0.024 0.013" />
        </geometry>
      </collision>
    <collision name="wear_pad_1">
      <origin xyz="0 0.052 -0.05" rpy="0 0 0" />
      <geometry>
        <box size="0.185 0.024 0.013" />
        </geometry>
      </collision>
    <collision name="side_gib_0">
      <origin xyz="0 -0.102 -0.057" rpy="0 0 0" />
      <geometry>
        <box size="0.205 0.034 0.058" />
        </geometry>
      </collision>
    <collision name="side_gib_1">
      <origin xyz="0 0.102 -0.057" rpy="0 0 0" />
      <geometry>
        <box size="0.205 0.034 0.058" />
        </geometry>
      </collision>
    <collision name="bearing_plate">
      <origin xyz="0 -0.142 0.05" rpy="0 0 0" />
      <geometry>
        <box size="0.178 0.044 0.178" />
        </geometry>
      </collision>
    <collision name="bearing_ring">
      <origin xyz="0 -0.166 0.06" rpy="0 0 0" />
      <geometry>
        <mesh filename="assets/meshes/bearing_ring.obj" />
        </geometry>
      </collision>
    <collision name="bearing_gusset_0">
      <origin xyz="-0.075 -0.118 0.018" rpy="0 0 0" />
      <geometry>
        <box size="0.026 0.065 0.105" />
        </geometry>
      </collision>
    <collision name="bearing_gusset_1">
      <origin xyz="0.075 -0.118 0.018" rpy="0 0 0" />
      <geometry>
        <box size="0.026 0.065 0.105" />
        </geometry>
      </collision>
    <collision name="cap_screw_0_0">
      <origin xyz="-0.07 -0.07 0.048" rpy="0 0 0" />
      <geometry>
        <cylinder radius="0.01" length="0.007" />
        </geometry>
      </collision>
    <collision name="cap_screw_0_1">
      <origin xyz="-0.07 0.07 0.048" rpy="0 0 0" />
      <geometry>
        <cylinder radius="0.01" length="0.007" />
        </geometry>
      </collision>
    <collision name="cap_screw_1_0">
      <origin xyz="0.07 -0.07 0.048" rpy="0 0 0" />
      <geometry>
        <cylinder radius="0.01" length="0.007" />
        </geometry>
      </collision>
    <collision name="cap_screw_1_1">
      <origin xyz="0.07 0.07 0.048" rpy="0 0 0" />
      <geometry>
        <cylinder radius="0.01" length="0.007" />
        </geometry>
      </collision>
    </link>
  <link name="head">
    <visual name="head_body">
      <origin xyz="0 -0.065 0" rpy="1.5708 0 0" />
      <geometry>
        <cylinder radius="0.065" length="0.13" />
        </geometry>
      <material name="dark_blued_steel">
        <color rgba="0.05 0.055 0.06 1" />
        </material>
      </visual>
    <visual name="faceplate">
      <origin xyz="0 -0.143 0" rpy="1.5708 0 0" />
      <geometry>
        <cylinder radius="0.085" length="0.026" />
        </geometry>
      <material name="plain_faceplate_steel">
        <color rgba="0.5 0.51 0.49 1" />
        </material>
      </visual>
    <visual name="center_pilot">
      <origin xyz="0 -0.164 0" rpy="1.5708 0 0" />
      <geometry>
        <cylinder radius="0.03" length="0.017" />
        </geometry>
      <material name="ground_steel">
        <color rgba="0.72 0.74 0.72 1" />
        </material>
      </visual>
    <visual name="index_mark">
      <origin xyz="0 -0.1585 0.055" rpy="0 0 0" />
      <geometry>
        <box size="0.012 0.006 0.03" />
        </geometry>
      <material name="black_index_mark">
        <color rgba="0.01 0.01 0.01 1" />
        </material>
      </visual>
    <collision name="head_body">
      <origin xyz="0 -0.065 0" rpy="1.5708 0 0" />
      <geometry>
        <cylinder radius="0.065" length="0.13" />
        </geometry>
      </collision>
    <collision name="faceplate">
      <origin xyz="0 -0.143 0" rpy="1.5708 0 0" />
      <geometry>
        <cylinder radius="0.085" length="0.026" />
        </geometry>
      </collision>
    <collision name="center_pilot">
      <origin xyz="0 -0.164 0" rpy="1.5708 0 0" />
      <geometry>
        <cylinder radius="0.03" length="0.017" />
        </geometry>
      </collision>
    <collision name="index_mark">
      <origin xyz="0 -0.1585 0.055" rpy="0 0 0" />
      <geometry>
        <box size="0.012 0.006 0.03" />
        </geometry>
      </collision>
    </link>
  <joint name="guide_to_carriage" type="prismatic">
    <origin xyz="-0.25 0 0.1645" rpy="0 0 0" />
    <parent link="guide" />
    <child link="carriage" />
    <axis xyz="1 0 0" />
    <limit effort="250" velocity="0.35" lower="0" upper="0.5" />
    </joint>
  <joint name="carriage_to_head" type="revolute">
    <origin xyz="0 -0.16 0.06" rpy="0 0 0" />
    <parent link="carriage" />
    <child link="head" />
    <axis xyz="0 -1 0" />
    <limit effort="80" velocity="2" lower="-3.14159" upper="3.14159" />
    </joint>
  </robot>
