<robot name="track_pump">
  <material name="brushed_steel">
    <color rgba="0.62 0.66 0.68 1" />
    </material>
  <material name="dark_steel">
    <color rgba="0.18 0.19 0.2 1" />
    </material>
  <material name="matte_black">
    <color rgba="0.015 0.015 0.014 1" />
    </material>
  <material name="black_rubber">
    <color rgba="0.005 0.005 0.004 1" />
    </material>
  <material name="gauge_face">
    <color rgba="0.92 0.9 0.84 1" />
    </material>
  <material name="red_needle">
    <color rgba="0.85 0.02 0.01 1" />
    </material>
  <link name="body">
    <visual name="foot_plate">
      <origin xyz="0 0 0.016" rpy="0 0 0" />
      <geometry>
        <box size="0.42 0.16 0.032" />
        </geometry>
      <material name="matte_black">
        <color rgba="0.015 0.015 0.014 1" />
        </material>
      </visual>
    <visual name="pump_head">
      <origin xyz="0 0 0.06" rpy="0 0 0" />
      <geometry>
        <box size="0.09 0.08 0.06" />
        </geometry>
      <material name="dark_steel">
        <color rgba="0.18 0.19 0.2 1" />
        </material>
      </visual>
    <visual name="barrel">
      <origin xyz="0 0 0.36" rpy="0 0 0" />
      <geometry>
        <cylinder radius="0.028" length="0.54" />
        </geometry>
      <material name="brushed_steel">
        <color rgba="0.62 0.66 0.68 1" />
        </material>
      </visual>
    <visual name="lower_band">
      <origin xyz="0 0 0.1" rpy="0 0 0" />
      <geometry>
        <cylinder radius="0.035" length="0.044" />
        </geometry>
      <material name="dark_steel">
        <color rgba="0.18 0.19 0.2 1" />
        </material>
      </visual>
    <visual name="top_collar">
      <origin xyz="0 0 0.63" rpy="0 0 0" />
      <geometry>
        <cylinder radius="0.036" length="0.04" />
        </geometry>
      <material name="dark_steel">
        <color rgba="0.18 0.19 0.2 1" />
        </material>
      </visual>
    <visual name="foot_pad_0">
      <origin xyz="-0.105 -0.002 0.041" rpy="0 0 0" />
      <geometry>
        <box size="0.19 0.045 0.018" />
        </geometry>
      <material name="black_rubber">
        <color rgba="0.005 0.005 0.004 1" />
        </material>
      </visual>
    <visual name="foot_pad_1">
      <origin xyz="0.105 -0.002 0.041" rpy="0 0 0" />
      <geometry>
        <box size="0.19 0.045 0.018" />
        </geometry>
      <material name="black_rubber">
        <color rgba="0.005 0.005 0.004 1" />
        </material>
      </visual>
    <visual name="gauge_neck">
      <origin xyz="0 -0.062 0.16" rpy="-1.5708 0 0" />
      <geometry>
        <cylinder radius="0.008" length="0.068" />
        </geometry>
      <material name="dark_steel">
        <color rgba="0.18 0.19 0.2 1" />
        </material>
      </visual>
    <visual name="gauge_case">
      <origin xyz="0 -0.105 0.16" rpy="-1.5708 0 0" />
      <geometry>
        <cylinder radius="0.057" length="0.018" />
        </geometry>
      <material name="matte_black">
        <color rgba="0.015 0.015 0.014 1" />
        </material>
      </visual>
    <visual name="gauge_dial">
      <origin xyz="0 -0.116 0.16" rpy="-1.5708 0 0" />
      <geometry>
        <cylinder radius="0.048" length="0.004" />
        </geometry>
      <material name="gauge_face">
        <color rgba="0.92 0.9 0.84 1" />
        </material>
      </visual>
    <visual name="gauge_tick_0">
      <origin xyz="-0.0311769 -0.119 0.178" rpy="0 -1.0472 0" />
      <geometry>
        <box size="0.004 0.002 0.012" />
        </geometry>
      <material name="matte_black">
        <color rgba="0.015 0.015 0.014 1" />
        </material>
      </visual>
    <visual name="gauge_tick_1">
      <origin xyz="-0.018 -0.119 0.191177" rpy="0 -0.523599 0" />
      <geometry>
        <box size="0.004 0.002 0.012" />
        </geometry>
      <material name="matte_black">
        <color rgba="0.015 0.015 0.014 1" />
        </material>
      </visual>
    <visual name="gauge_tick_2">
      <origin xyz="0 -0.119 0.196" rpy="0 0 0" />
      <geometry>
        <box size="0.004 0.002 0.012" />
        </geometry>
      <material name="matte_black">
        <color rgba="0.015 0.015 0.014 1" />
        </material>
      </visual>
    <visual name="gauge_tick_3">
      <origin xyz="0.018 -0.119 0.191177" rpy="0 0.523599 0" />
      <geometry>
        <box size="0.004 0.002 0.012" />
        </geometry>
      <material name="matte_black">
        <color rgba="0.015 0.015 0.014 1" />
        </material>
      </visual>
    <visual name="gauge_tick_4">
      <origin xyz="0.0311769 -0.119 0.178" rpy="0 1.0472 0" />
      <geometry>
        <box size="0.004 0.002 0.012" />
        </geometry>
      <material name="matte_black">
        <color rgba="0.015 0.015 0.014 1" />
        </material>
      </visual>
    <visual name="parked_hose">
      <geometry>
        <mesh filename="assets/meshes/parked_hose.obj" />
        </geometry>
      <material name="black_rubber">
        <color rgba="0.005 0.005 0.004 1" />
        </material>
      </visual>
    <visual name="hose_port">
      <origin xyz="0.026 -0.025 0.126" rpy="0 0 0" />
      <geometry>
        <sphere radius="0.013" />
        </geometry>
      <material name="dark_steel">
        <color rgba="0.18 0.19 0.2 1" />
        </material>
      </visual>
    <visual name="hose_clip_0">
      <origin xyz="0.039 -0.021 0.35" rpy="0 0 0" />
      <geometry>
        <box size="0.044 0.02 0.018" />
        </geometry>
      <material name="matte_black">
        <color rgba="0.015 0.015 0.014 1" />
        </material>
      </visual>
    <visual name="hose_clip_1">
      <origin xyz="0.039 -0.021 0.505" rpy="0 0 0" />
      <geometry>
        <box size="0.044 0.02 0.018" />
        </geometry>
      <material name="matte_black">
        <color rgba="0.015 0.015 0.014 1" />
        </material>
      </visual>
    <collision name="foot_plate">
      <origin xyz="0 0 0.016" rpy="0 0 0" />
      <geometry>
        <box size="0.42 0.16 0.032" />
        </geometry>
      </collision>
    <collision name="pump_head">
      <origin xyz="0 0 0.06" rpy="0 0 0" />
      <geometry>
        <box size="0.09 0.08 0.06" />
        </geometry>
      </collision>
    <collision name="barrel">
      <origin xyz="0 0 0.36" rpy="0 0 0" />
      <geometry>
        <cylinder radius="0.028" length="0.54" />
        </geometry>
      </collision>
    <collision name="lower_band">
      <origin xyz="0 0 0.1" rpy="0 0 0" />
      <geometry>
        <cylinder radius="0.035" length="0.044" />
        </geometry>
      </collision>
    <collision name="top_collar">
      <origin xyz="0 0 0.63" rpy="0 0 0" />
      <geometry>
        <cylinder radius="0.036" length="0.04" />
        </geometry>
      </collision>
    <collision name="foot_pad_0">
      <origin xyz="-0.105 -0.002 0.041" rpy="0 0 0" />
      <geometry>
        <box size="0.19 0.045 0.018" />
        </geometry>
      </collision>
    <collision name="foot_pad_1">
      <origin xyz="0.105 -0.002 0.041" rpy="0 0 0" />
      <geometry>
        <box size="0.19 0.045 0.018" />
        </geometry>
      </collision>
    <collision name="gauge_neck">
      <origin xyz="0 -0.062 0.16" rpy="-1.5708 0 0" />
      <geometry>
        <cylinder radius="0.008" length="0.068" />
        </geometry>
      </collision>
    <collision name="gauge_case">
      <origin xyz="0 -0.105 0.16" rpy="-1.5708 0 0" />
      <geometry>
        <cylinder radius="0.057" length="0.018" />
        </geometry>
      </collision>
    <collision name="gauge_dial">
      <origin xyz="0 -0.116 0.16" rpy="-1.5708 0 0" />
      <geometry>
        <cylinder radius="0.048" length="0.004" />
        </geometry>
      </collision>
    <collision name="gauge_tick_0">
      <origin xyz="-0.0311769 -0.119 0.178" rpy="0 -1.0472 0" />
      <geometry>
        <box size="0.004 0.002 0.012" />
        </geometry>
      </collision>
    <collision name="gauge_tick_1">
      <origin xyz="-0.018 -0.119 0.191177" rpy="0 -0.523599 0" />
      <geometry>
        <box size="0.004 0.002 0.012" />
        </geometry>
      </collision>
    <collision name="gauge_tick_2">
      <origin xyz="0 -0.119 0.196" rpy="0 0 0" />
      <geometry>
        <box size="0.004 0.002 0.012" />
        </geometry>
      </collision>
    <collision name="gauge_tick_3">
      <origin xyz="0.018 -0.119 0.191177" rpy="0 0.523599 0" />
      <geometry>
        <box size="0.004 0.002 0.012" />
        </geometry>
      </collision>
    <collision name="gauge_tick_4">
      <origin xyz="0.0311769 -0.119 0.178" rpy="0 1.0472 0" />
      <geometry>
        <box size="0.004 0.002 0.012" />
        </geometry>
      </collision>
    <collision name="parked_hose">
      <geometry>
        <mesh filename="assets/meshes/parked_hose.obj" />
        </geometry>
      </collision>
    <collision name="hose_port">
      <origin xyz="0.026 -0.025 0.126" rpy="0 0 0" />
      <geometry>
        <sphere radius="0.013" />
        </geometry>
      </collision>
    <collision name="hose_clip_0">
      <origin xyz="0.039 -0.021 0.35" rpy="0 0 0" />
      <geometry>
        <box size="0.044 0.02 0.018" />
        </geometry>
      </collision>
    <collision name="hose_clip_1">
      <origin xyz="0.039 -0.021 0.505" rpy="0 0 0" />
      <geometry>
        <box size="0.044 0.02 0.018" />
        </geometry>
      </collision>
    </link>
  <link name="handle">
    <visual name="piston_rod">
      <origin xyz="0 0 0.14" rpy="0 0 0" />
      <geometry>
        <cylinder radius="0.006" length="0.28" />
        </geometry>
      <material name="brushed_steel">
        <color rgba="0.62 0.66 0.68 1" />
        </material>
      </visual>
    <visual name="crossbar">
      <origin xyz="0 0 0.292" rpy="0 1.5708 0" />
      <geometry>
        <cylinder radius="0.018" length="0.36" />
        </geometry>
      <material name="matte_black">
        <color rgba="0.015 0.015 0.014 1" />
        </material>
      </visual>
    <visual name="handle_boss">
      <origin xyz="0 0 0.292" rpy="0 0 0" />
      <geometry>
        <sphere radius="0.024" />
        </geometry>
      <material name="matte_black">
        <color rgba="0.015 0.015 0.014 1" />
        </material>
      </visual>
    <collision name="piston_rod">
      <origin xyz="0 0 0.14" rpy="0 0 0" />
      <geometry>
        <cylinder radius="0.006" length="0.28" />
        </geometry>
      </collision>
    <collision name="crossbar">
      <origin xyz="0 0 0.292" rpy="0 1.5708 0" />
      <geometry>
        <cylinder radius="0.018" length="0.36" />
        </geometry>
      </collision>
    <collision name="handle_boss">
      <origin xyz="0 0 0.292" rpy="0 0 0" />
      <geometry>
        <sphere radius="0.024" />
        </geometry>
      </collision>
    </link>
  <link name="grip">
    <visual name="grip_sleeve">
      <origin xyz="0 0 0" rpy="0 1.5708 0" />
      <geometry>
        <cylinder radius="0.024" length="0.15" />
        </geometry>
      <material name="black_rubber">
        <color rgba="0.005 0.005 0.004 1" />
        </material>
      </visual>
    <visual name="folding_tab">
      <origin xyz="0 -0.026 0" rpy="0 0 0" />
      <geometry>
        <box size="0.115 0.007 0.02" />
        </geometry>
      <material name="dark_steel">
        <color rgba="0.18 0.19 0.2 1" />
        </material>
      </visual>
    <collision name="grip_sleeve">
      <origin xyz="0 0 0" rpy="0 1.5708 0" />
      <geometry>
        <cylinder radius="0.024" length="0.15" />
        </geometry>
      </collision>
    <collision name="folding_tab">
      <origin xyz="0 -0.026 0" rpy="0 0 0" />
      <geometry>
        <box size="0.115 0.007 0.02" />
        </geometry>
      </collision>
    </link>
  <link name="needle">
    <visual name="pointer">
      <origin xyz="0 0 0.024" rpy="0 0 0" />
      <geometry>
        <box size="0.005 0.002 0.044" />
        </geometry>
      <material name="red_needle">
        <color rgba="0.85 0.02 0.01 1" />
        </material>
      </visual>
    <visual name="pivot_cap">
      <origin xyz="0 0.001 0" rpy="-1.5708 0 0" />
      <geometry>
        <cylinder radius="0.006" length="0.006" />
        </geometry>
      <material name="matte_black">
        <color rgba="0.015 0.015 0.014 1" />
        </material>
      </visual>
    <collision name="pointer">
      <origin xyz="0 0 0.024" rpy="0 0 0" />
      <geometry>
        <box size="0.005 0.002 0.044" />
        </geometry>
      </collision>
    <collision name="pivot_cap">
      <origin xyz="0 0.001 0" rpy="-1.5708 0 0" />
      <geometry>
        <cylinder radius="0.006" length="0.006" />
        </geometry>
      </collision>
    </link>
  <joint name="body_to_handle" type="prismatic">
    <origin xyz="0 0 0.65" rpy="0 0 0" />
    <parent link="body" />
    <child link="handle" />
    <axis xyz="0 0 1" />
    <limit effort="120" velocity="0.45" lower="0" upper="0.21" />
    </joint>
  <joint name="handle_to_grip" type="continuous">
    <origin xyz="0.105 0 0.292" rpy="0 0 0" />
    <parent link="handle" />
    <child link="grip" />
    <axis xyz="1 0 0" />
    <limit effort="2" velocity="8" />
    </joint>
  <joint name="body_to_needle" type="revolute">
    <origin xyz="0 -0.122 0.16" rpy="0 0 0" />
    <parent link="body" />
    <child link="needle" />
    <axis xyz="0 1 0" />
    <limit effort="0.05" velocity="12" lower="-1.2" upper="1.2" />
    </joint>
  </robot>
