<robot name="compact_watch_winder_box">
  <link name="base">
    <visual name="floor">
      <origin xyz="0 0 0.005" rpy="0 0 0" />
      <geometry>
        <box size="0.24 0.16 0.01" />
        </geometry>
      <material name="matte_black_leather">
        <color rgba="0.015 0.014 0.013 1" />
        </material>
      </visual>
    <visual name="side_wall_0">
      <origin xyz="0 0.076 0.05" rpy="0 0 0" />
      <geometry>
        <box size="0.24 0.008 0.081" />
        </geometry>
      <material name="matte_black_leather">
        <color rgba="0.015 0.014 0.013 1" />
        </material>
      </visual>
    <visual name="side_wall_1">
      <origin xyz="0 -0.076 0.05" rpy="0 0 0" />
      <geometry>
        <box size="0.24 0.008 0.081" />
        </geometry>
      <material name="matte_black_leather">
        <color rgba="0.015 0.014 0.013 1" />
        </material>
      </visual>
    <visual name="rear_wall">
      <origin xyz="-0.116 0 0.05" rpy="0 0 0" />
      <geometry>
        <box size="0.008 0.16 0.081" />
        </geometry>
      <material name="matte_black_leather">
        <color rgba="0.015 0.014 0.013 1" />
        </material>
      </visual>
    <visual name="front_wall">
      <origin xyz="0.116 0 0.05" rpy="0 0 0" />
      <geometry>
        <box size="0.008 0.16 0.081" />
        </geometry>
      <material name="matte_black_leather">
        <color rgba="0.015 0.014 0.013 1" />
        </material>
      </visual>
    <visual name="velvet_liner">
      <origin xyz="0.006 0 0.012" rpy="0 0 0" />
      <geometry>
        <box size="0.206 0.126 0.003" />
        </geometry>
      <material name="charcoal_velvet">
        <color rgba="0.02 0.025 0.03 1" />
        </material>
      </visual>
    <visual name="hinge_strap_0">
      <origin xyz="-0.12 -0.058 0.093" rpy="0 0 0" />
      <geometry>
        <box size="0.018 0.032 0.01" />
        </geometry>
      <material name="brushed_steel">
        <color rgba="0.72 0.7 0.65 1" />
        </material>
      </visual>
    <visual name="hinge_knuckle_0">
      <origin xyz="-0.12 -0.058 0.098" rpy="-1.5708 0 0" />
      <geometry>
        <cylinder radius="0.006" length="0.032" />
        </geometry>
      <material name="brushed_steel">
        <color rgba="0.72 0.7 0.65 1" />
        </material>
      </visual>
    <visual name="hinge_strap_1">
      <origin xyz="-0.12 0 0.093" rpy="0 0 0" />
      <geometry>
        <box size="0.018 0.032 0.01" />
        </geometry>
      <material name="brushed_steel">
        <color rgba="0.72 0.7 0.65 1" />
        </material>
      </visual>
    <visual name="hinge_knuckle_1">
      <origin xyz="-0.12 0 0.098" rpy="-1.5708 0 0" />
      <geometry>
        <cylinder radius="0.006" length="0.032" />
        </geometry>
      <material name="brushed_steel">
        <color rgba="0.72 0.7 0.65 1" />
        </material>
      </visual>
    <visual name="hinge_strap_2">
      <origin xyz="-0.12 0.058 0.093" rpy="0 0 0" />
      <geometry>
        <box size="0.018 0.032 0.01" />
        </geometry>
      <material name="brushed_steel">
        <color rgba="0.72 0.7 0.65 1" />
        </material>
      </visual>
    <visual name="hinge_knuckle_2">
      <origin xyz="-0.12 0.058 0.098" rpy="-1.5708 0 0" />
      <geometry>
        <cylinder radius="0.006" length="0.032" />
        </geometry>
      <material name="brushed_steel">
        <color rgba="0.72 0.7 0.65 1" />
        </material>
      </visual>
    <visual name="bearing_post_0">
      <origin xyz="0.014 -0.058 0.0265" rpy="0 0 0" />
      <geometry>
        <box size="0.024 0.014 0.035" />
        </geometry>
      <material name="satin_black">
        <color rgba="0.03 0.032 0.035 1" />
        </material>
      </visual>
    <visual name="bearing_boss_0">
      <origin xyz="0.014 -0.058 0.052" rpy="-1.5708 0 0" />
      <geometry>
        <cylinder radius="0.01" length="0.016" />
        </geometry>
      <material name="brushed_steel">
        <color rgba="0.72 0.7 0.65 1" />
        </material>
      </visual>
    <visual name="bearing_post_1">
      <origin xyz="0.014 0.058 0.0265" rpy="0 0 0" />
      <geometry>
        <box size="0.024 0.014 0.035" />
        </geometry>
      <material name="satin_black">
        <color rgba="0.03 0.032 0.035 1" />
        </material>
      </visual>
    <visual name="bearing_boss_1">
      <origin xyz="0.014 0.058 0.052" rpy="-1.5708 0 0" />
      <geometry>
        <cylinder radius="0.01" length="0.016" />
        </geometry>
      <material name="brushed_steel">
        <color rgba="0.72 0.7 0.65 1" />
        </material>
      </visual>
    <collision name="floor">
      <origin xyz="0 0 0.005" rpy="0 0 0" />
      <geometry>
        <box size="0.24 0.16 0.01" />
        </geometry>
      </collision>
    <collision name="side_wall_0">
      <origin xyz="0 0.076 0.05" rpy="0 0 0" />
      <geometry>
        <box size="0.24 0.008 0.081" />
        </geometry>
      </collision>
    <collision name="side_wall_1">
      <origin xyz="0 -0.076 0.05" rpy="0 0 0" />
      <geometry>
        <box size="0.24 0.008 0.081" />
        </geometry>
      </collision>
    <collision name="rear_wall">
      <origin xyz="-0.116 0 0.05" rpy="0 0 0" />
      <geometry>
        <box size="0.008 0.16 0.081" />
        </geometry>
      </collision>
    <collision name="front_wall">
      <origin xyz="0.116 0 0.05" rpy="0 0 0" />
      <geometry>
        <box size="0.008 0.16 0.081" />
        </geometry>
      </collision>
    <collision name="velvet_liner">
      <origin xyz="0.006 0 0.012" rpy="0 0 0" />
      <geometry>
        <box size="0.206 0.126 0.003" />
        </geometry>
      </collision>
    <collision name="hinge_strap_0">
      <origin xyz="-0.12 -0.058 0.093" rpy="0 0 0" />
      <geometry>
        <box size="0.018 0.032 0.01" />
        </geometry>
      </collision>
    <collision name="hinge_knuckle_0">
      <origin xyz="-0.12 -0.058 0.098" rpy="-1.5708 0 0" />
      <geometry>
        <cylinder radius="0.006" length="0.032" />
        </geometry>
      </collision>
    <collision name="hinge_strap_1">
      <origin xyz="-0.12 0 0.093" rpy="0 0 0" />
      <geometry>
        <box size="0.018 0.032 0.01" />
        </geometry>
      </collision>
    <collision name="hinge_knuckle_1">
      <origin xyz="-0.12 0 0.098" rpy="-1.5708 0 0" />
      <geometry>
        <cylinder radius="0.006" length="0.032" />
        </geometry>
      </collision>
    <collision name="hinge_strap_2">
      <origin xyz="-0.12 0.058 0.093" rpy="0 0 0" />
      <geometry>
        <box size="0.018 0.032 0.01" />
        </geometry>
      </collision>
    <collision name="hinge_knuckle_2">
      <origin xyz="-0.12 0.058 0.098" rpy="-1.5708 0 0" />
      <geometry>
        <cylinder radius="0.006" length="0.032" />
        </geometry>
      </collision>
    <collision name="bearing_post_0">
      <origin xyz="0.014 -0.058 0.0265" rpy="0 0 0" />
      <geometry>
        <box size="0.024 0.014 0.035" />
        </geometry>
      </collision>
    <collision name="bearing_boss_0">
      <origin xyz="0.014 -0.058 0.052" rpy="-1.5708 0 0" />
      <geometry>
        <cylinder radius="0.01" length="0.016" />
        </geometry>
      </collision>
    <collision name="bearing_post_1">
      <origin xyz="0.014 0.058 0.0265" rpy="0 0 0" />
      <geometry>
        <box size="0.024 0.014 0.035" />
        </geometry>
      </collision>
    <collision name="bearing_boss_1">
      <origin xyz="0.014 0.058 0.052" rpy="-1.5708 0 0" />
      <geometry>
        <cylinder radius="0.01" length="0.016" />
        </geometry>
      </collision>
    </link>
  <link name="lid">
    <visual name="window">
      <origin xyz="0.118 0 0.006" rpy="0 0 0" />
      <geometry>
        <box size="0.224 0.146 0.008" />
        </geometry>
      <material name="smoked_acrylic">
        <color rgba="0.2 0.24 0.28 0.42" />
        </material>
      </visual>
    <visual name="side_frame_0">
      <origin xyz="0.118 0.07 0.006" rpy="0 0 0" />
      <geometry>
        <box size="0.224 0.01 0.012" />
        </geometry>
      <material name="matte_black_leather">
        <color rgba="0.015 0.014 0.013 1" />
        </material>
      </visual>
    <visual name="side_frame_1">
      <origin xyz="0.118 -0.07 0.006" rpy="0 0 0" />
      <geometry>
        <box size="0.224 0.01 0.012" />
        </geometry>
      <material name="matte_black_leather">
        <color rgba="0.015 0.014 0.013 1" />
        </material>
      </visual>
    <visual name="rear_frame">
      <origin xyz="0.02 0 0.006" rpy="0 0 0" />
      <geometry>
        <box size="0.014 0.146 0.012" />
        </geometry>
      <material name="matte_black_leather">
        <color rgba="0.015 0.014 0.013 1" />
        </material>
      </visual>
    <visual name="front_frame">
      <origin xyz="0.228 0 0.006" rpy="0 0 0" />
      <geometry>
        <box size="0.014 0.146 0.012" />
        </geometry>
      <material name="matte_black_leather">
        <color rgba="0.015 0.014 0.013 1" />
        </material>
      </visual>
    <visual name="hinge_leaf_0">
      <origin xyz="0.004 -0.029 0.004" rpy="0 0 0" />
      <geometry>
        <box size="0.018 0.022 0.008" />
        </geometry>
      <material name="brushed_steel">
        <color rgba="0.72 0.7 0.65 1" />
        </material>
      </visual>
    <visual name="hinge_barrel_0">
      <origin xyz="0 -0.029 0" rpy="-1.5708 0 0" />
      <geometry>
        <cylinder radius="0.006" length="0.022" />
        </geometry>
      <material name="brushed_steel">
        <color rgba="0.72 0.7 0.65 1" />
        </material>
      </visual>
    <visual name="hinge_leaf_1">
      <origin xyz="0.004 0.029 0.004" rpy="0 0 0" />
      <geometry>
        <box size="0.018 0.022 0.008" />
        </geometry>
      <material name="brushed_steel">
        <color rgba="0.72 0.7 0.65 1" />
        </material>
      </visual>
    <visual name="hinge_barrel_1">
      <origin xyz="0 0.029 0" rpy="-1.5708 0 0" />
      <geometry>
        <cylinder radius="0.006" length="0.022" />
        </geometry>
      <material name="brushed_steel">
        <color rgba="0.72 0.7 0.65 1" />
        </material>
      </visual>
    <collision name="window">
      <origin xyz="0.118 0 0.006" rpy="0 0 0" />
      <geometry>
        <box size="0.224 0.146 0.008" />
        </geometry>
      </collision>
    <collision name="side_frame_0">
      <origin xyz="0.118 0.07 0.006" rpy="0 0 0" />
      <geometry>
        <box size="0.224 0.01 0.012" />
        </geometry>
      </collision>
    <collision name="side_frame_1">
      <origin xyz="0.118 -0.07 0.006" rpy="0 0 0" />
      <geometry>
        <box size="0.224 0.01 0.012" />
        </geometry>
      </collision>
    <collision name="rear_frame">
      <origin xyz="0.02 0 0.006" rpy="0 0 0" />
      <geometry>
        <box size="0.014 0.146 0.012" />
        </geometry>
      </collision>
    <collision name="front_frame">
      <origin xyz="0.228 0 0.006" rpy="0 0 0" />
      <geometry>
        <box size="0.014 0.146 0.012" />
        </geometry>
      </collision>
    <collision name="hinge_leaf_0">
      <origin xyz="0.004 -0.029 0.004" rpy="0 0 0" />
      <geometry>
        <box size="0.018 0.022 0.008" />
        </geometry>
      </collision>
    <collision name="hinge_barrel_0">
      <origin xyz="0 -0.029 0" rpy="-1.5708 0 0" />
      <geometry>
        <cylinder radius="0.006" length="0.022" />
        </geometry>
      </collision>
    <collision name="hinge_leaf_1">
      <origin xyz="0.004 0.029 0.004" rpy="0 0 0" />
      <geometry>
        <box size="0.018 0.022 0.008" />
        </geometry>
      </collision>
    <collision name="hinge_barrel_1">
      <origin xyz="0 0.029 0" rpy="-1.5708 0 0" />
      <geometry>
        <cylinder radius="0.006" length="0.022" />
        </geometry>
      </collision>
    </link>
  <link name="cradle">
    <visual name="axle">
      <origin xyz="0 0 0" rpy="-1.5708 0 0" />
      <geometry>
        <cylinder radius="0.0048" length="0.136" />
        </geometry>
      <material name="brushed_steel">
        <color rgba="0.72 0.7 0.65 1" />
        </material>
      </visual>
    <visual name="pillow">
      <origin xyz="0 0 0" rpy="-1.5708 0 0" />
      <geometry>
        <cylinder radius="0.026" length="0.082" />
        </geometry>
      <material name="charcoal_velvet">
        <color rgba="0.02 0.025 0.03 1" />
        </material>
      </visual>
    <visual name="hub_collar_0">
      <origin xyz="0 -0.046 0" rpy="-1.5708 0 0" />
      <geometry>
        <cylinder radius="0.012" length="0.01" />
        </geometry>
      <material name="brushed_steel">
        <color rgba="0.72 0.7 0.65 1" />
        </material>
      </visual>
    <visual name="hub_collar_1">
      <origin xyz="0 0.046 0" rpy="-1.5708 0 0" />
      <geometry>
        <cylinder radius="0.012" length="0.01" />
        </geometry>
      <material name="brushed_steel">
        <color rgba="0.72 0.7 0.65 1" />
        </material>
      </visual>
    <visual name="watch_bezel">
      <origin xyz="0.027 0 0" rpy="0 1.5708 0" />
      <geometry>
        <cylinder radius="0.013" length="0.004" />
        </geometry>
      <material name="warm_gold">
        <color rgba="0.92 0.7 0.32 1" />
        </material>
      </visual>
    <visual name="watch_dial">
      <origin xyz="0.029 0 0" rpy="0 1.5708 0" />
      <geometry>
        <cylinder radius="0.01" length="0.005" />
        </geometry>
      <material name="satin_black">
        <color rgba="0.03 0.032 0.035 1" />
        </material>
      </visual>
    <visual name="watch_strap_top">
      <origin xyz="0.01 0 0.023" rpy="0 0 0" />
      <geometry>
        <box size="0.008 0.086 0.006" />
        </geometry>
      <material name="satin_black">
        <color rgba="0.03 0.032 0.035 1" />
        </material>
      </visual>
    <visual name="watch_strap_bottom">
      <origin xyz="0.01 0 -0.023" rpy="0 0 0" />
      <geometry>
        <box size="0.008 0.086 0.006" />
        </geometry>
      <material name="satin_black">
        <color rgba="0.03 0.032 0.035 1" />
        </material>
      </visual>
    <collision name="axle">
      <origin xyz="0 0 0" rpy="-1.5708 0 0" />
      <geometry>
        <cylinder radius="0.0048" length="0.136" />
        </geometry>
      </collision>
    <collision name="pillow">
      <origin xyz="0 0 0" rpy="-1.5708 0 0" />
      <geometry>
        <cylinder radius="0.026" length="0.082" />
        </geometry>
      </collision>
    <collision name="hub_collar_0">
      <origin xyz="0 -0.046 0" rpy="-1.5708 0 0" />
      <geometry>
        <cylinder radius="0.012" length="0.01" />
        </geometry>
      </collision>
    <collision name="hub_collar_1">
      <origin xyz="0 0.046 0" rpy="-1.5708 0 0" />
      <geometry>
        <cylinder radius="0.012" length="0.01" />
        </geometry>
      </collision>
    <collision name="watch_bezel">
      <origin xyz="0.027 0 0" rpy="0 1.5708 0" />
      <geometry>
        <cylinder radius="0.013" length="0.004" />
        </geometry>
      </collision>
    <collision name="watch_dial">
      <origin xyz="0.029 0 0" rpy="0 1.5708 0" />
      <geometry>
        <cylinder radius="0.01" length="0.005" />
        </geometry>
      </collision>
    <collision name="watch_strap_top">
      <origin xyz="0.01 0 0.023" rpy="0 0 0" />
      <geometry>
        <box size="0.008 0.086 0.006" />
        </geometry>
      </collision>
    <collision name="watch_strap_bottom">
      <origin xyz="0.01 0 -0.023" rpy="0 0 0" />
      <geometry>
        <box size="0.008 0.086 0.006" />
        </geometry>
      </collision>
    </link>
  <joint name="base_to_lid" type="revolute">
    <origin xyz="-0.12 0 0.098" rpy="0 0 0" />
    <parent link="base" />
    <child link="lid" />
    <axis xyz="0 -1 0" />
    <limit effort="4" velocity="2" lower="0" upper="2.55" />
    <dynamics damping="0.08" friction="0.02" />
    </joint>
  <joint name="base_to_cradle" type="continuous">
    <origin xyz="0.014 0 0.052" rpy="0 0 0" />
    <parent link="base" />
    <child link="cradle" />
    <axis xyz="0 -1 0" />
    <limit effort="1.5" velocity="1" />
    <dynamics damping="0.02" friction="0.005" />
    </joint>
  </robot>
