<robot name="independent_flap_array_panel">
  <link name="frame">
    <visual name="back_plate">
      <geometry>
        <box size="1.2 0.02 0.82" />
        </geometry>
      <material name="powder_coated_frame">
        <color rgba="0.08 0.09 0.1 1" />
        </material>
      </visual>
    <visual name="top_rail">
      <origin xyz="0 -0.02 0.375" rpy="0 0 0" />
      <geometry>
        <box size="1.2 0.028 0.07" />
        </geometry>
      <material name="slightly_worn_black_rails">
        <color rgba="0.13 0.14 0.15 1" />
        </material>
      </visual>
    <visual name="bottom_rail">
      <origin xyz="0 -0.02 -0.375" rpy="0 0 0" />
      <geometry>
        <box size="1.2 0.028 0.07" />
        </geometry>
      <material name="slightly_worn_black_rails">
        <color rgba="0.13 0.14 0.15 1" />
        </material>
      </visual>
    <visual name="side_rail_0">
      <origin xyz="-0.565 -0.02 0" rpy="0 0 0" />
      <geometry>
        <box size="0.07 0.028 0.82" />
        </geometry>
      <material name="slightly_worn_black_rails">
        <color rgba="0.13 0.14 0.15 1" />
        </material>
      </visual>
    <visual name="side_rail_1">
      <origin xyz="0.565 -0.02 0" rpy="0 0 0" />
      <geometry>
        <box size="0.07 0.028 0.82" />
        </geometry>
      <material name="slightly_worn_black_rails">
        <color rgba="0.13 0.14 0.15 1" />
        </material>
      </visual>
    <visual name="vertical_mullion_0">
      <origin xyz="-0.18 -0.023 0" rpy="0 0 0" />
      <geometry>
        <box size="0.038 0.03 0.72" />
        </geometry>
      <material name="slightly_worn_black_rails">
        <color rgba="0.13 0.14 0.15 1" />
        </material>
      </visual>
    <visual name="vertical_mullion_1">
      <origin xyz="0.18 -0.023 0" rpy="0 0 0" />
      <geometry>
        <box size="0.038 0.03 0.72" />
        </geometry>
      <material name="slightly_worn_black_rails">
        <color rgba="0.13 0.14 0.15 1" />
        </material>
      </visual>
    <visual name="middle_rail">
      <origin xyz="0 -0.023 -0.006" rpy="0 0 0" />
      <geometry>
        <box size="1.08 0.03 0.058" />
        </geometry>
      <material name="slightly_worn_black_rails">
        <color rgba="0.13 0.14 0.15 1" />
        </material>
      </visual>
    <visual name="stanchion_0_0_a">
      <origin xyz="-0.524 -0.047 0.316" rpy="0 0 0" />
      <geometry>
        <box size="0.02 0.034 0.104" />
        </geometry>
      <material name="brushed_steel_hinges">
        <color rgba="0.7 0.68 0.62 1" />
        </material>
      </visual>
    <visual name="stanchion_0_0_b">
      <origin xyz="-0.196 -0.047 0.316" rpy="0 0 0" />
      <geometry>
        <box size="0.02 0.034 0.104" />
        </geometry>
      <material name="brushed_steel_hinges">
        <color rgba="0.7 0.68 0.62 1" />
        </material>
      </visual>
    <visual name="hinge_pin_0_0">
      <origin xyz="-0.36 -0.047 0.275" rpy="0 1.5708 0" />
      <geometry>
        <cylinder radius="0.0065" length="0.362" />
        </geometry>
      <material name="brushed_steel_hinges">
        <color rgba="0.7 0.68 0.62 1" />
        </material>
      </visual>
    <visual name="bottom_seal_0_0">
      <origin xyz="-0.36 -0.034 0.019" rpy="0 0 0" />
      <geometry>
        <box size="0.322 0.006 0.014" />
        </geometry>
      <material name="dark_rubber_seals">
        <color rgba="0.02 0.022 0.025 1" />
        </material>
      </visual>
    <visual name="stanchion_0_1_a">
      <origin xyz="-0.164 -0.047 0.316" rpy="0 0 0" />
      <geometry>
        <box size="0.02 0.034 0.104" />
        </geometry>
      <material name="brushed_steel_hinges">
        <color rgba="0.7 0.68 0.62 1" />
        </material>
      </visual>
    <visual name="stanchion_0_1_b">
      <origin xyz="0.164 -0.047 0.316" rpy="0 0 0" />
      <geometry>
        <box size="0.02 0.034 0.104" />
        </geometry>
      <material name="brushed_steel_hinges">
        <color rgba="0.7 0.68 0.62 1" />
        </material>
      </visual>
    <visual name="hinge_pin_0_1">
      <origin xyz="0 -0.047 0.275" rpy="0 1.5708 0" />
      <geometry>
        <cylinder radius="0.0065" length="0.362" />
        </geometry>
      <material name="brushed_steel_hinges">
        <color rgba="0.7 0.68 0.62 1" />
        </material>
      </visual>
    <visual name="bottom_seal_0_1">
      <origin xyz="0 -0.034 0.019" rpy="0 0 0" />
      <geometry>
        <box size="0.322 0.006 0.014" />
        </geometry>
      <material name="dark_rubber_seals">
        <color rgba="0.02 0.022 0.025 1" />
        </material>
      </visual>
    <visual name="stanchion_0_2_a">
      <origin xyz="0.196 -0.047 0.316" rpy="0 0 0" />
      <geometry>
        <box size="0.02 0.034 0.104" />
        </geometry>
      <material name="brushed_steel_hinges">
        <color rgba="0.7 0.68 0.62 1" />
        </material>
      </visual>
    <visual name="stanchion_0_2_b">
      <origin xyz="0.524 -0.047 0.316" rpy="0 0 0" />
      <geometry>
        <box size="0.02 0.034 0.104" />
        </geometry>
      <material name="brushed_steel_hinges">
        <color rgba="0.7 0.68 0.62 1" />
        </material>
      </visual>
    <visual name="hinge_pin_0_2">
      <origin xyz="0.36 -0.047 0.275" rpy="0 1.5708 0" />
      <geometry>
        <cylinder radius="0.0065" length="0.362" />
        </geometry>
      <material name="brushed_steel_hinges">
        <color rgba="0.7 0.68 0.62 1" />
        </material>
      </visual>
    <visual name="bottom_seal_0_2">
      <origin xyz="0.36 -0.034 0.019" rpy="0 0 0" />
      <geometry>
        <box size="0.322 0.006 0.014" />
        </geometry>
      <material name="dark_rubber_seals">
        <color rgba="0.02 0.022 0.025 1" />
        </material>
      </visual>
    <visual name="stanchion_1_0_a">
      <origin xyz="-0.524 -0.047 -0.0325" rpy="0 0 0" />
      <geometry>
        <box size="0.02 0.034 0.107" />
        </geometry>
      <material name="brushed_steel_hinges">
        <color rgba="0.7 0.68 0.62 1" />
        </material>
      </visual>
    <visual name="stanchion_1_0_b">
      <origin xyz="-0.196 -0.047 -0.0325" rpy="0 0 0" />
      <geometry>
        <box size="0.02 0.034 0.107" />
        </geometry>
      <material name="brushed_steel_hinges">
        <color rgba="0.7 0.68 0.62 1" />
        </material>
      </visual>
    <visual name="hinge_pin_1_0">
      <origin xyz="-0.36 -0.047 -0.075" rpy="0 1.5708 0" />
      <geometry>
        <cylinder radius="0.0065" length="0.362" />
        </geometry>
      <material name="brushed_steel_hinges">
        <color rgba="0.7 0.68 0.62 1" />
        </material>
      </visual>
    <visual name="bottom_seal_1_0">
      <origin xyz="-0.36 -0.034 -0.331" rpy="0 0 0" />
      <geometry>
        <box size="0.322 0.006 0.014" />
        </geometry>
      <material name="dark_rubber_seals">
        <color rgba="0.02 0.022 0.025 1" />
        </material>
      </visual>
    <visual name="stanchion_1_1_a">
      <origin xyz="-0.164 -0.047 -0.0325" rpy="0 0 0" />
      <geometry>
        <box size="0.02 0.034 0.107" />
        </geometry>
      <material name="brushed_steel_hinges">
        <color rgba="0.7 0.68 0.62 1" />
        </material>
      </visual>
    <visual name="stanchion_1_1_b">
      <origin xyz="0.164 -0.047 -0.0325" rpy="0 0 0" />
      <geometry>
        <box size="0.02 0.034 0.107" />
        </geometry>
      <material name="brushed_steel_hinges">
        <color rgba="0.7 0.68 0.62 1" />
        </material>
      </visual>
    <visual name="hinge_pin_1_1">
      <origin xyz="0 -0.047 -0.075" rpy="0 1.5708 0" />
      <geometry>
        <cylinder radius="0.0065" length="0.362" />
        </geometry>
      <material name="brushed_steel_hinges">
        <color rgba="0.7 0.68 0.62 1" />
        </material>
      </visual>
    <visual name="bottom_seal_1_1">
      <origin xyz="0 -0.034 -0.331" rpy="0 0 0" />
      <geometry>
        <box size="0.322 0.006 0.014" />
        </geometry>
      <material name="dark_rubber_seals">
        <color rgba="0.02 0.022 0.025 1" />
        </material>
      </visual>
    <visual name="stanchion_1_2_a">
      <origin xyz="0.196 -0.047 -0.0325" rpy="0 0 0" />
      <geometry>
        <box size="0.02 0.034 0.107" />
        </geometry>
      <material name="brushed_steel_hinges">
        <color rgba="0.7 0.68 0.62 1" />
        </material>
      </visual>
    <visual name="stanchion_1_2_b">
      <origin xyz="0.524 -0.047 -0.0325" rpy="0 0 0" />
      <geometry>
        <box size="0.02 0.034 0.107" />
        </geometry>
      <material name="brushed_steel_hinges">
        <color rgba="0.7 0.68 0.62 1" />
        </material>
      </visual>
    <visual name="hinge_pin_1_2">
      <origin xyz="0.36 -0.047 -0.075" rpy="0 1.5708 0" />
      <geometry>
        <cylinder radius="0.0065" length="0.362" />
        </geometry>
      <material name="brushed_steel_hinges">
        <color rgba="0.7 0.68 0.62 1" />
        </material>
      </visual>
    <visual name="bottom_seal_1_2">
      <origin xyz="0.36 -0.034 -0.331" rpy="0 0 0" />
      <geometry>
        <box size="0.322 0.006 0.014" />
        </geometry>
      <material name="dark_rubber_seals">
        <color rgba="0.02 0.022 0.025 1" />
        </material>
      </visual>
    <collision name="back_plate">
      <geometry>
        <box size="1.2 0.02 0.82" />
        </geometry>
      </collision>
    <collision name="top_rail">
      <origin xyz="0 -0.02 0.375" rpy="0 0 0" />
      <geometry>
        <box size="1.2 0.028 0.07" />
        </geometry>
      </collision>
    <collision name="bottom_rail">
      <origin xyz="0 -0.02 -0.375" rpy="0 0 0" />
      <geometry>
        <box size="1.2 0.028 0.07" />
        </geometry>
      </collision>
    <collision name="side_rail_0">
      <origin xyz="-0.565 -0.02 0" rpy="0 0 0" />
      <geometry>
        <box size="0.07 0.028 0.82" />
        </geometry>
      </collision>
    <collision name="side_rail_1">
      <origin xyz="0.565 -0.02 0" rpy="0 0 0" />
      <geometry>
        <box size="0.07 0.028 0.82" />
        </geometry>
      </collision>
    <collision name="vertical_mullion_0">
      <origin xyz="-0.18 -0.023 0" rpy="0 0 0" />
      <geometry>
        <box size="0.038 0.03 0.72" />
        </geometry>
      </collision>
    <collision name="vertical_mullion_1">
      <origin xyz="0.18 -0.023 0" rpy="0 0 0" />
      <geometry>
        <box size="0.038 0.03 0.72" />
        </geometry>
      </collision>
    <collision name="middle_rail">
      <origin xyz="0 -0.023 -0.006" rpy="0 0 0" />
      <geometry>
        <box size="1.08 0.03 0.058" />
        </geometry>
      </collision>
    <collision name="stanchion_0_0_a">
      <origin xyz="-0.524 -0.047 0.316" rpy="0 0 0" />
      <geometry>
        <box size="0.02 0.034 0.104" />
        </geometry>
      </collision>
    <collision name="stanchion_0_0_b">
      <origin xyz="-0.196 -0.047 0.316" rpy="0 0 0" />
      <geometry>
        <box size="0.02 0.034 0.104" />
        </geometry>
      </collision>
    <collision name="hinge_pin_0_0">
      <origin xyz="-0.36 -0.047 0.275" rpy="0 1.5708 0" />
      <geometry>
        <cylinder radius="0.0065" length="0.362" />
        </geometry>
      </collision>
    <collision name="bottom_seal_0_0">
      <origin xyz="-0.36 -0.034 0.019" rpy="0 0 0" />
      <geometry>
        <box size="0.322 0.006 0.014" />
        </geometry>
      </collision>
    <collision name="stanchion_0_1_a">
      <origin xyz="-0.164 -0.047 0.316" rpy="0 0 0" />
      <geometry>
        <box size="0.02 0.034 0.104" />
        </geometry>
      </collision>
    <collision name="stanchion_0_1_b">
      <origin xyz="0.164 -0.047 0.316" rpy="0 0 0" />
      <geometry>
        <box size="0.02 0.034 0.104" />
        </geometry>
      </collision>
    <collision name="hinge_pin_0_1">
      <origin xyz="0 -0.047 0.275" rpy="0 1.5708 0" />
      <geometry>
        <cylinder radius="0.0065" length="0.362" />
        </geometry>
      </collision>
    <collision name="bottom_seal_0_1">
      <origin xyz="0 -0.034 0.019" rpy="0 0 0" />
      <geometry>
        <box size="0.322 0.006 0.014" />
        </geometry>
      </collision>
    <collision name="stanchion_0_2_a">
      <origin xyz="0.196 -0.047 0.316" rpy="0 0 0" />
      <geometry>
        <box size="0.02 0.034 0.104" />
        </geometry>
      </collision>
    <collision name="stanchion_0_2_b">
      <origin xyz="0.524 -0.047 0.316" rpy="0 0 0" />
      <geometry>
        <box size="0.02 0.034 0.104" />
        </geometry>
      </collision>
    <collision name="hinge_pin_0_2">
      <origin xyz="0.36 -0.047 0.275" rpy="0 1.5708 0" />
      <geometry>
        <cylinder radius="0.0065" length="0.362" />
        </geometry>
      </collision>
    <collision name="bottom_seal_0_2">
      <origin xyz="0.36 -0.034 0.019" rpy="0 0 0" />
      <geometry>
        <box size="0.322 0.006 0.014" />
        </geometry>
      </collision>
    <collision name="stanchion_1_0_a">
      <origin xyz="-0.524 -0.047 -0.0325" rpy="0 0 0" />
      <geometry>
        <box size="0.02 0.034 0.107" />
        </geometry>
      </collision>
    <collision name="stanchion_1_0_b">
      <origin xyz="-0.196 -0.047 -0.0325" rpy="0 0 0" />
      <geometry>
        <box size="0.02 0.034 0.107" />
        </geometry>
      </collision>
    <collision name="hinge_pin_1_0">
      <origin xyz="-0.36 -0.047 -0.075" rpy="0 1.5708 0" />
      <geometry>
        <cylinder radius="0.0065" length="0.362" />
        </geometry>
      </collision>
    <collision name="bottom_seal_1_0">
      <origin xyz="-0.36 -0.034 -0.331" rpy="0 0 0" />
      <geometry>
        <box size="0.322 0.006 0.014" />
        </geometry>
      </collision>
    <collision name="stanchion_1_1_a">
      <origin xyz="-0.164 -0.047 -0.0325" rpy="0 0 0" />
      <geometry>
        <box size="0.02 0.034 0.107" />
        </geometry>
      </collision>
    <collision name="stanchion_1_1_b">
      <origin xyz="0.164 -0.047 -0.0325" rpy="0 0 0" />
      <geometry>
        <box size="0.02 0.034 0.107" />
        </geometry>
      </collision>
    <collision name="hinge_pin_1_1">
      <origin xyz="0 -0.047 -0.075" rpy="0 1.5708 0" />
      <geometry>
        <cylinder radius="0.0065" length="0.362" />
        </geometry>
      </collision>
    <collision name="bottom_seal_1_1">
      <origin xyz="0 -0.034 -0.331" rpy="0 0 0" />
      <geometry>
        <box size="0.322 0.006 0.014" />
        </geometry>
      </collision>
    <collision name="stanchion_1_2_a">
      <origin xyz="0.196 -0.047 -0.0325" rpy="0 0 0" />
      <geometry>
        <box size="0.02 0.034 0.107" />
        </geometry>
      </collision>
    <collision name="stanchion_1_2_b">
      <origin xyz="0.524 -0.047 -0.0325" rpy="0 0 0" />
      <geometry>
        <box size="0.02 0.034 0.107" />
        </geometry>
      </collision>
    <collision name="hinge_pin_1_2">
      <origin xyz="0.36 -0.047 -0.075" rpy="0 1.5708 0" />
      <geometry>
        <cylinder radius="0.0065" length="0.362" />
        </geometry>
      </collision>
    <collision name="bottom_seal_1_2">
      <origin xyz="0.36 -0.034 -0.331" rpy="0 0 0" />
      <geometry>
        <box size="0.322 0.006 0.014" />
        </geometry>
      </collision>
    </link>
  <link name="flap_0_0">
    <visual name="face">
      <origin xyz="0 -0.016 -0.1295" rpy="0 0 0" />
      <geometry>
        <box size="0.292 0.012 0.235" />
        </geometry>
      <material name="painted_aluminum_flaps">
        <color rgba="0.3 0.43 0.52 1" />
        </material>
      </visual>
    <visual name="barrel">
      <origin xyz="0 0 0" rpy="0 1.5708 0" />
      <geometry>
        <cylinder radius="0.012" length="0.2044" />
        </geometry>
      <material name="brushed_steel_hinges">
        <color rgba="0.7 0.68 0.62 1" />
        </material>
      </visual>
    <visual name="hinge_leaf">
      <origin xyz="0 -0.013 -0.02" rpy="0 0 0" />
      <geometry>
        <box size="0.24528 0.007 0.042" />
        </geometry>
      <material name="brushed_steel_hinges">
        <color rgba="0.7 0.68 0.62 1" />
        </material>
      </visual>
    <visual name="lower_lip">
      <origin xyz="0 -0.024 -0.227" rpy="0 0 0" />
      <geometry>
        <box size="0.23944 0.01 0.018" />
        </geometry>
      <material name="dark_rubber_seals">
        <color rgba="0.02 0.022 0.025 1" />
        </material>
      </visual>
    <visual name="edge_0">
      <origin xyz="-0.122 -0.024 -0.1269" rpy="0 0 0" />
      <geometry>
        <box size="0.014 0.01 0.1692" />
        </geometry>
      <material name="painted_aluminum_flaps">
        <color rgba="0.3 0.43 0.52 1" />
        </material>
      </visual>
    <visual name="edge_1">
      <origin xyz="0.122 -0.024 -0.1269" rpy="0 0 0" />
      <geometry>
        <box size="0.014 0.01 0.1692" />
        </geometry>
      <material name="painted_aluminum_flaps">
        <color rgba="0.3 0.43 0.52 1" />
        </material>
      </visual>
    <visual name="pull_tab">
      <origin xyz="0 -0.027 -0.1363" rpy="0 0 0" />
      <geometry>
        <box size="0.06 0.012 0.03" />
        </geometry>
      <material name="brushed_steel_hinges">
        <color rgba="0.7 0.68 0.62 1" />
        </material>
      </visual>
    <collision name="face">
      <origin xyz="0 -0.016 -0.1295" rpy="0 0 0" />
      <geometry>
        <box size="0.292 0.012 0.235" />
        </geometry>
      </collision>
    <collision name="barrel">
      <origin xyz="0 0 0" rpy="0 1.5708 0" />
      <geometry>
        <cylinder radius="0.012" length="0.2044" />
        </geometry>
      </collision>
    <collision name="hinge_leaf">
      <origin xyz="0 -0.013 -0.02" rpy="0 0 0" />
      <geometry>
        <box size="0.24528 0.007 0.042" />
        </geometry>
      </collision>
    <collision name="lower_lip">
      <origin xyz="0 -0.024 -0.227" rpy="0 0 0" />
      <geometry>
        <box size="0.23944 0.01 0.018" />
        </geometry>
      </collision>
    <collision name="edge_0">
      <origin xyz="-0.122 -0.024 -0.1269" rpy="0 0 0" />
      <geometry>
        <box size="0.014 0.01 0.1692" />
        </geometry>
      </collision>
    <collision name="edge_1">
      <origin xyz="0.122 -0.024 -0.1269" rpy="0 0 0" />
      <geometry>
        <box size="0.014 0.01 0.1692" />
        </geometry>
      </collision>
    <collision name="pull_tab">
      <origin xyz="0 -0.027 -0.1363" rpy="0 0 0" />
      <geometry>
        <box size="0.06 0.012 0.03" />
        </geometry>
      </collision>
    </link>
  <link name="flap_0_1">
    <visual name="face">
      <origin xyz="0 -0.016 -0.1295" rpy="0 0 0" />
      <geometry>
        <box size="0.292 0.012 0.235" />
        </geometry>
      <material name="painted_aluminum_flaps">
        <color rgba="0.3 0.43 0.52 1" />
        </material>
      </visual>
    <visual name="barrel">
      <origin xyz="0 0 0" rpy="0 1.5708 0" />
      <geometry>
        <cylinder radius="0.012" length="0.2044" />
        </geometry>
      <material name="brushed_steel_hinges">
        <color rgba="0.7 0.68 0.62 1" />
        </material>
      </visual>
    <visual name="hinge_leaf">
      <origin xyz="0 -0.013 -0.02" rpy="0 0 0" />
      <geometry>
        <box size="0.24528 0.007 0.042" />
        </geometry>
      <material name="brushed_steel_hinges">
        <color rgba="0.7 0.68 0.62 1" />
        </material>
      </visual>
    <visual name="lower_lip">
      <origin xyz="0 -0.024 -0.227" rpy="0 0 0" />
      <geometry>
        <box size="0.23944 0.01 0.018" />
        </geometry>
      <material name="dark_rubber_seals">
        <color rgba="0.02 0.022 0.025 1" />
        </material>
      </visual>
    <visual name="edge_0">
      <origin xyz="-0.122 -0.024 -0.1269" rpy="0 0 0" />
      <geometry>
        <box size="0.014 0.01 0.1692" />
        </geometry>
      <material name="painted_aluminum_flaps">
        <color rgba="0.3 0.43 0.52 1" />
        </material>
      </visual>
    <visual name="edge_1">
      <origin xyz="0.122 -0.024 -0.1269" rpy="0 0 0" />
      <geometry>
        <box size="0.014 0.01 0.1692" />
        </geometry>
      <material name="painted_aluminum_flaps">
        <color rgba="0.3 0.43 0.52 1" />
        </material>
      </visual>
    <visual name="pull_tab">
      <origin xyz="0 -0.027 -0.1363" rpy="0 0 0" />
      <geometry>
        <box size="0.06 0.012 0.03" />
        </geometry>
      <material name="brushed_steel_hinges">
        <color rgba="0.7 0.68 0.62 1" />
        </material>
      </visual>
    <collision name="face">
      <origin xyz="0 -0.016 -0.1295" rpy="0 0 0" />
      <geometry>
        <box size="0.292 0.012 0.235" />
        </geometry>
      </collision>
    <collision name="barrel">
      <origin xyz="0 0 0" rpy="0 1.5708 0" />
      <geometry>
        <cylinder radius="0.012" length="0.2044" />
        </geometry>
      </collision>
    <collision name="hinge_leaf">
      <origin xyz="0 -0.013 -0.02" rpy="0 0 0" />
      <geometry>
        <box size="0.24528 0.007 0.042" />
        </geometry>
      </collision>
    <collision name="lower_lip">
      <origin xyz="0 -0.024 -0.227" rpy="0 0 0" />
      <geometry>
        <box size="0.23944 0.01 0.018" />
        </geometry>
      </collision>
    <collision name="edge_0">
      <origin xyz="-0.122 -0.024 -0.1269" rpy="0 0 0" />
      <geometry>
        <box size="0.014 0.01 0.1692" />
        </geometry>
      </collision>
    <collision name="edge_1">
      <origin xyz="0.122 -0.024 -0.1269" rpy="0 0 0" />
      <geometry>
        <box size="0.014 0.01 0.1692" />
        </geometry>
      </collision>
    <collision name="pull_tab">
      <origin xyz="0 -0.027 -0.1363" rpy="0 0 0" />
      <geometry>
        <box size="0.06 0.012 0.03" />
        </geometry>
      </collision>
    </link>
  <link name="flap_0_2">
    <visual name="face">
      <origin xyz="0 -0.016 -0.1295" rpy="0 0 0" />
      <geometry>
        <box size="0.292 0.012 0.235" />
        </geometry>
      <material name="painted_aluminum_flaps">
        <color rgba="0.3 0.43 0.52 1" />
        </material>
      </visual>
    <visual name="barrel">
      <origin xyz="0 0 0" rpy="0 1.5708 0" />
      <geometry>
        <cylinder radius="0.012" length="0.2044" />
        </geometry>
      <material name="brushed_steel_hinges">
        <color rgba="0.7 0.68 0.62 1" />
        </material>
      </visual>
    <visual name="hinge_leaf">
      <origin xyz="0 -0.013 -0.02" rpy="0 0 0" />
      <geometry>
        <box size="0.24528 0.007 0.042" />
        </geometry>
      <material name="brushed_steel_hinges">
        <color rgba="0.7 0.68 0.62 1" />
        </material>
      </visual>
    <visual name="lower_lip">
      <origin xyz="0 -0.024 -0.227" rpy="0 0 0" />
      <geometry>
        <box size="0.23944 0.01 0.018" />
        </geometry>
      <material name="dark_rubber_seals">
        <color rgba="0.02 0.022 0.025 1" />
        </material>
      </visual>
    <visual name="edge_0">
      <origin xyz="-0.122 -0.024 -0.1269" rpy="0 0 0" />
      <geometry>
        <box size="0.014 0.01 0.1692" />
        </geometry>
      <material name="painted_aluminum_flaps">
        <color rgba="0.3 0.43 0.52 1" />
        </material>
      </visual>
    <visual name="edge_1">
      <origin xyz="0.122 -0.024 -0.1269" rpy="0 0 0" />
      <geometry>
        <box size="0.014 0.01 0.1692" />
        </geometry>
      <material name="painted_aluminum_flaps">
        <color rgba="0.3 0.43 0.52 1" />
        </material>
      </visual>
    <visual name="pull_tab">
      <origin xyz="0 -0.027 -0.1363" rpy="0 0 0" />
      <geometry>
        <box size="0.06 0.012 0.03" />
        </geometry>
      <material name="brushed_steel_hinges">
        <color rgba="0.7 0.68 0.62 1" />
        </material>
      </visual>
    <collision name="face">
      <origin xyz="0 -0.016 -0.1295" rpy="0 0 0" />
      <geometry>
        <box size="0.292 0.012 0.235" />
        </geometry>
      </collision>
    <collision name="barrel">
      <origin xyz="0 0 0" rpy="0 1.5708 0" />
      <geometry>
        <cylinder radius="0.012" length="0.2044" />
        </geometry>
      </collision>
    <collision name="hinge_leaf">
      <origin xyz="0 -0.013 -0.02" rpy="0 0 0" />
      <geometry>
        <box size="0.24528 0.007 0.042" />
        </geometry>
      </collision>
    <collision name="lower_lip">
      <origin xyz="0 -0.024 -0.227" rpy="0 0 0" />
      <geometry>
        <box size="0.23944 0.01 0.018" />
        </geometry>
      </collision>
    <collision name="edge_0">
      <origin xyz="-0.122 -0.024 -0.1269" rpy="0 0 0" />
      <geometry>
        <box size="0.014 0.01 0.1692" />
        </geometry>
      </collision>
    <collision name="edge_1">
      <origin xyz="0.122 -0.024 -0.1269" rpy="0 0 0" />
      <geometry>
        <box size="0.014 0.01 0.1692" />
        </geometry>
      </collision>
    <collision name="pull_tab">
      <origin xyz="0 -0.027 -0.1363" rpy="0 0 0" />
      <geometry>
        <box size="0.06 0.012 0.03" />
        </geometry>
      </collision>
    </link>
  <link name="flap_1_0">
    <visual name="face">
      <origin xyz="0 -0.016 -0.1295" rpy="0 0 0" />
      <geometry>
        <box size="0.292 0.012 0.235" />
        </geometry>
      <material name="painted_aluminum_flaps">
        <color rgba="0.3 0.43 0.52 1" />
        </material>
      </visual>
    <visual name="barrel">
      <origin xyz="0 0 0" rpy="0 1.5708 0" />
      <geometry>
        <cylinder radius="0.012" length="0.2044" />
        </geometry>
      <material name="brushed_steel_hinges">
        <color rgba="0.7 0.68 0.62 1" />
        </material>
      </visual>
    <visual name="hinge_leaf">
      <origin xyz="0 -0.013 -0.02" rpy="0 0 0" />
      <geometry>
        <box size="0.24528 0.007 0.042" />
        </geometry>
      <material name="brushed_steel_hinges">
        <color rgba="0.7 0.68 0.62 1" />
        </material>
      </visual>
    <visual name="lower_lip">
      <origin xyz="0 -0.024 -0.227" rpy="0 0 0" />
      <geometry>
        <box size="0.23944 0.01 0.018" />
        </geometry>
      <material name="dark_rubber_seals">
        <color rgba="0.02 0.022 0.025 1" />
        </material>
      </visual>
    <visual name="edge_0">
      <origin xyz="-0.122 -0.024 -0.1269" rpy="0 0 0" />
      <geometry>
        <box size="0.014 0.01 0.1692" />
        </geometry>
      <material name="painted_aluminum_flaps">
        <color rgba="0.3 0.43 0.52 1" />
        </material>
      </visual>
    <visual name="edge_1">
      <origin xyz="0.122 -0.024 -0.1269" rpy="0 0 0" />
      <geometry>
        <box size="0.014 0.01 0.1692" />
        </geometry>
      <material name="painted_aluminum_flaps">
        <color rgba="0.3 0.43 0.52 1" />
        </material>
      </visual>
    <visual name="pull_tab">
      <origin xyz="0 -0.027 -0.1363" rpy="0 0 0" />
      <geometry>
        <box size="0.06 0.012 0.03" />
        </geometry>
      <material name="brushed_steel_hinges">
        <color rgba="0.7 0.68 0.62 1" />
        </material>
      </visual>
    <collision name="face">
      <origin xyz="0 -0.016 -0.1295" rpy="0 0 0" />
      <geometry>
        <box size="0.292 0.012 0.235" />
        </geometry>
      </collision>
    <collision name="barrel">
      <origin xyz="0 0 0" rpy="0 1.5708 0" />
      <geometry>
        <cylinder radius="0.012" length="0.2044" />
        </geometry>
      </collision>
    <collision name="hinge_leaf">
      <origin xyz="0 -0.013 -0.02" rpy="0 0 0" />
      <geometry>
        <box size="0.24528 0.007 0.042" />
        </geometry>
      </collision>
    <collision name="lower_lip">
      <origin xyz="0 -0.024 -0.227" rpy="0 0 0" />
      <geometry>
        <box size="0.23944 0.01 0.018" />
        </geometry>
      </collision>
    <collision name="edge_0">
      <origin xyz="-0.122 -0.024 -0.1269" rpy="0 0 0" />
      <geometry>
        <box size="0.014 0.01 0.1692" />
        </geometry>
      </collision>
    <collision name="edge_1">
      <origin xyz="0.122 -0.024 -0.1269" rpy="0 0 0" />
      <geometry>
        <box size="0.014 0.01 0.1692" />
        </geometry>
      </collision>
    <collision name="pull_tab">
      <origin xyz="0 -0.027 -0.1363" rpy="0 0 0" />
      <geometry>
        <box size="0.06 0.012 0.03" />
        </geometry>
      </collision>
    </link>
  <link name="flap_1_1">
    <visual name="face">
      <origin xyz="0 -0.016 -0.1295" rpy="0 0 0" />
      <geometry>
        <box size="0.292 0.012 0.235" />
        </geometry>
      <material name="painted_aluminum_flaps">
        <color rgba="0.3 0.43 0.52 1" />
        </material>
      </visual>
    <visual name="barrel">
      <origin xyz="0 0 0" rpy="0 1.5708 0" />
      <geometry>
        <cylinder radius="0.012" length="0.2044" />
        </geometry>
      <material name="brushed_steel_hinges">
        <color rgba="0.7 0.68 0.62 1" />
        </material>
      </visual>
    <visual name="hinge_leaf">
      <origin xyz="0 -0.013 -0.02" rpy="0 0 0" />
      <geometry>
        <box size="0.24528 0.007 0.042" />
        </geometry>
      <material name="brushed_steel_hinges">
        <color rgba="0.7 0.68 0.62 1" />
        </material>
      </visual>
    <visual name="lower_lip">
      <origin xyz="0 -0.024 -0.227" rpy="0 0 0" />
      <geometry>
        <box size="0.23944 0.01 0.018" />
        </geometry>
      <material name="dark_rubber_seals">
        <color rgba="0.02 0.022 0.025 1" />
        </material>
      </visual>
    <visual name="edge_0">
      <origin xyz="-0.122 -0.024 -0.1269" rpy="0 0 0" />
      <geometry>
        <box size="0.014 0.01 0.1692" />
        </geometry>
      <material name="painted_aluminum_flaps">
        <color rgba="0.3 0.43 0.52 1" />
        </material>
      </visual>
    <visual name="edge_1">
      <origin xyz="0.122 -0.024 -0.1269" rpy="0 0 0" />
      <geometry>
        <box size="0.014 0.01 0.1692" />
        </geometry>
      <material name="painted_aluminum_flaps">
        <color rgba="0.3 0.43 0.52 1" />
        </material>
      </visual>
    <visual name="pull_tab">
      <origin xyz="0 -0.027 -0.1363" rpy="0 0 0" />
      <geometry>
        <box size="0.06 0.012 0.03" />
        </geometry>
      <material name="brushed_steel_hinges">
        <color rgba="0.7 0.68 0.62 1" />
        </material>
      </visual>
    <collision name="face">
      <origin xyz="0 -0.016 -0.1295" rpy="0 0 0" />
      <geometry>
        <box size="0.292 0.012 0.235" />
        </geometry>
      </collision>
    <collision name="barrel">
      <origin xyz="0 0 0" rpy="0 1.5708 0" />
      <geometry>
        <cylinder radius="0.012" length="0.2044" />
        </geometry>
      </collision>
    <collision name="hinge_leaf">
      <origin xyz="0 -0.013 -0.02" rpy="0 0 0" />
      <geometry>
        <box size="0.24528 0.007 0.042" />
        </geometry>
      </collision>
    <collision name="lower_lip">
      <origin xyz="0 -0.024 -0.227" rpy="0 0 0" />
      <geometry>
        <box size="0.23944 0.01 0.018" />
        </geometry>
      </collision>
    <collision name="edge_0">
      <origin xyz="-0.122 -0.024 -0.1269" rpy="0 0 0" />
      <geometry>
        <box size="0.014 0.01 0.1692" />
        </geometry>
      </collision>
    <collision name="edge_1">
      <origin xyz="0.122 -0.024 -0.1269" rpy="0 0 0" />
      <geometry>
        <box size="0.014 0.01 0.1692" />
        </geometry>
      </collision>
    <collision name="pull_tab">
      <origin xyz="0 -0.027 -0.1363" rpy="0 0 0" />
      <geometry>
        <box size="0.06 0.012 0.03" />
        </geometry>
      </collision>
    </link>
  <link name="flap_1_2">
    <visual name="face">
      <origin xyz="0 -0.016 -0.1295" rpy="0 0 0" />
      <geometry>
        <box size="0.292 0.012 0.235" />
        </geometry>
      <material name="painted_aluminum_flaps">
        <color rgba="0.3 0.43 0.52 1" />
        </material>
      </visual>
    <visual name="barrel">
      <origin xyz="0 0 0" rpy="0 1.5708 0" />
      <geometry>
        <cylinder radius="0.012" length="0.2044" />
        </geometry>
      <material name="brushed_steel_hinges">
        <color rgba="0.7 0.68 0.62 1" />
        </material>
      </visual>
    <visual name="hinge_leaf">
      <origin xyz="0 -0.013 -0.02" rpy="0 0 0" />
      <geometry>
        <box size="0.24528 0.007 0.042" />
        </geometry>
      <material name="brushed_steel_hinges">
        <color rgba="0.7 0.68 0.62 1" />
        </material>
      </visual>
    <visual name="lower_lip">
      <origin xyz="0 -0.024 -0.227" rpy="0 0 0" />
      <geometry>
        <box size="0.23944 0.01 0.018" />
        </geometry>
      <material name="dark_rubber_seals">
        <color rgba="0.02 0.022 0.025 1" />
        </material>
      </visual>
    <visual name="edge_0">
      <origin xyz="-0.122 -0.024 -0.1269" rpy="0 0 0" />
      <geometry>
        <box size="0.014 0.01 0.1692" />
        </geometry>
      <material name="painted_aluminum_flaps">
        <color rgba="0.3 0.43 0.52 1" />
        </material>
      </visual>
    <visual name="edge_1">
      <origin xyz="0.122 -0.024 -0.1269" rpy="0 0 0" />
      <geometry>
        <box size="0.014 0.01 0.1692" />
        </geometry>
      <material name="painted_aluminum_flaps">
        <color rgba="0.3 0.43 0.52 1" />
        </material>
      </visual>
    <visual name="pull_tab">
      <origin xyz="0 -0.027 -0.1363" rpy="0 0 0" />
      <geometry>
        <box size="0.06 0.012 0.03" />
        </geometry>
      <material name="brushed_steel_hinges">
        <color rgba="0.7 0.68 0.62 1" />
        </material>
      </visual>
    <collision name="face">
      <origin xyz="0 -0.016 -0.1295" rpy="0 0 0" />
      <geometry>
        <box size="0.292 0.012 0.235" />
        </geometry>
      </collision>
    <collision name="barrel">
      <origin xyz="0 0 0" rpy="0 1.5708 0" />
      <geometry>
        <cylinder radius="0.012" length="0.2044" />
        </geometry>
      </collision>
    <collision name="hinge_leaf">
      <origin xyz="0 -0.013 -0.02" rpy="0 0 0" />
      <geometry>
        <box size="0.24528 0.007 0.042" />
        </geometry>
      </collision>
    <collision name="lower_lip">
      <origin xyz="0 -0.024 -0.227" rpy="0 0 0" />
      <geometry>
        <box size="0.23944 0.01 0.018" />
        </geometry>
      </collision>
    <collision name="edge_0">
      <origin xyz="-0.122 -0.024 -0.1269" rpy="0 0 0" />
      <geometry>
        <box size="0.014 0.01 0.1692" />
        </geometry>
      </collision>
    <collision name="edge_1">
      <origin xyz="0.122 -0.024 -0.1269" rpy="0 0 0" />
      <geometry>
        <box size="0.014 0.01 0.1692" />
        </geometry>
      </collision>
    <collision name="pull_tab">
      <origin xyz="0 -0.027 -0.1363" rpy="0 0 0" />
      <geometry>
        <box size="0.06 0.012 0.03" />
        </geometry>
      </collision>
    </link>
  <joint name="frame_to_flap_0_0" type="revolute">
    <origin xyz="-0.36 -0.047 0.275" rpy="0 0 0" />
    <parent link="frame" />
    <child link="flap_0_0" />
    <axis xyz="-1 0 0" />
    <limit effort="8" velocity="2.5" lower="0" upper="1.1" />
    </joint>
  <joint name="frame_to_flap_0_1" type="revolute">
    <origin xyz="0 -0.047 0.275" rpy="0 0 0" />
    <parent link="frame" />
    <child link="flap_0_1" />
    <axis xyz="-1 0 0" />
    <limit effort="8" velocity="2.5" lower="0" upper="1.1" />
    </joint>
  <joint name="frame_to_flap_0_2" type="revolute">
    <origin xyz="0.36 -0.047 0.275" rpy="0 0 0" />
    <parent link="frame" />
    <child link="flap_0_2" />
    <axis xyz="-1 0 0" />
    <limit effort="8" velocity="2.5" lower="0" upper="1.1" />
    </joint>
  <joint name="frame_to_flap_1_0" type="revolute">
    <origin xyz="-0.36 -0.047 -0.075" rpy="0 0 0" />
    <parent link="frame" />
    <child link="flap_1_0" />
    <axis xyz="-1 0 0" />
    <limit effort="8" velocity="2.5" lower="0" upper="1.1" />
    </joint>
  <joint name="frame_to_flap_1_1" type="revolute">
    <origin xyz="0 -0.047 -0.075" rpy="0 0 0" />
    <parent link="frame" />
    <child link="flap_1_1" />
    <axis xyz="-1 0 0" />
    <limit effort="8" velocity="2.5" lower="0" upper="1.1" />
    </joint>
  <joint name="frame_to_flap_1_2" type="revolute">
    <origin xyz="0.36 -0.047 -0.075" rpy="0 0 0" />
    <parent link="frame" />
    <child link="flap_1_2" />
    <axis xyz="-1 0 0" />
    <limit effort="8" velocity="2.5" lower="0" upper="1.1" />
    </joint>
  </robot>
