<robot name="rectangular_louvered_shutter">
  <material name="painted_white">
    <color rgba="0.88 0.87 0.82 1" />
    </material>
  <material name="warm_off_white">
    <color rgba="0.8 0.78 0.7 1" />
    </material>
  <material name="galvanized_steel">
    <color rgba="0.58 0.6 0.61 1" />
    </material>
  <material name="shadow_dark">
    <color rgba="0.11 0.1 0.09 1" />
    </material>
  <link name="frame">
    <inertial>
      <mass value="5" />
      <inertia ixx="0.60126" ixy="0" ixz="0" iyy="0.804167" iyz="0" izz="0.205427" />
      </inertial>
    <visual name="side_stile_0">
      <origin xyz="-0.3125 0 0" rpy="0 0 0" />
      <geometry>
        <box size="0.075 0.055 1.2" />
        </geometry>
      <material name="painted_white">
        <color rgba="0.88 0.87 0.82 1" />
        </material>
      </visual>
    <visual name="side_stile_1">
      <origin xyz="0.3125 0 0" rpy="0 0 0" />
      <geometry>
        <box size="0.075 0.055 1.2" />
        </geometry>
      <material name="painted_white">
        <color rgba="0.88 0.87 0.82 1" />
        </material>
      </visual>
    <visual name="top_rail">
      <origin xyz="0 0 0.56" rpy="0 0 0" />
      <geometry>
        <box size="0.7 0.055 0.08" />
        </geometry>
      <material name="painted_white">
        <color rgba="0.88 0.87 0.82 1" />
        </material>
      </visual>
    <visual name="bottom_rail">
      <origin xyz="0 0 -0.56" rpy="0 0 0" />
      <geometry>
        <box size="0.7 0.055 0.08" />
        </geometry>
      <material name="painted_white">
        <color rgba="0.88 0.87 0.82 1" />
        </material>
      </visual>
    <visual name="inner_reveal_0">
      <origin xyz="-0.272 0.0255 0" rpy="0 0 0" />
      <geometry>
        <box size="0.01 0.01 1.04" />
        </geometry>
      <material name="shadow_dark">
        <color rgba="0.11 0.1 0.09 1" />
        </material>
      </visual>
    <visual name="inner_reveal_1">
      <origin xyz="0.272 0.0255 0" rpy="0 0 0" />
      <geometry>
        <box size="0.01 0.01 1.04" />
        </geometry>
      <material name="shadow_dark">
        <color rgba="0.11 0.1 0.09 1" />
        </material>
      </visual>
    <collision name="side_stile_0">
      <origin xyz="-0.3125 0 0" rpy="0 0 0" />
      <geometry>
        <box size="0.075 0.055 1.2" />
        </geometry>
      </collision>
    <collision name="side_stile_1">
      <origin xyz="0.3125 0 0" rpy="0 0 0" />
      <geometry>
        <box size="0.075 0.055 1.2" />
        </geometry>
      </collision>
    <collision name="top_rail">
      <origin xyz="0 0 0.56" rpy="0 0 0" />
      <geometry>
        <box size="0.7 0.055 0.08" />
        </geometry>
      </collision>
    <collision name="bottom_rail">
      <origin xyz="0 0 -0.56" rpy="0 0 0" />
      <geometry>
        <box size="0.7 0.055 0.08" />
        </geometry>
      </collision>
    <collision name="inner_reveal_0">
      <origin xyz="-0.272 0.0255 0" rpy="0 0 0" />
      <geometry>
        <box size="0.01 0.01 1.04" />
        </geometry>
      </collision>
    <collision name="inner_reveal_1">
      <origin xyz="0.272 0.0255 0" rpy="0 0 0" />
      <geometry>
        <box size="0.01 0.01 1.04" />
        </geometry>
      </collision>
    </link>
  <link name="slat_0">
    <inertial>
      <mass value="0.28" />
      <inertia ixx="0.000146533" ixy="0" ixz="0" iyy="0.0119707" iyz="0" izz="0.0118333" />
      </inertial>
    <visual name="blade">
      <geometry>
        <mesh filename="assets/meshes/rounded_louver_blade.obj" />
        </geometry>
      <material name="warm_off_white">
        <color rgba="0.8 0.78 0.7 1" />
        </material>
      </visual>
    <visual name="pin_0">
      <origin xyz="-0.303 0 0" rpy="0 1.5708 0" />
      <geometry>
        <cylinder radius="0.006" length="0.096" />
        </geometry>
      <material name="galvanized_steel">
        <color rgba="0.58 0.6 0.61 1" />
        </material>
      </visual>
    <visual name="pin_1">
      <origin xyz="0.303 0 0" rpy="0 1.5708 0" />
      <geometry>
        <cylinder radius="0.006" length="0.096" />
        </geometry>
      <material name="galvanized_steel">
        <color rgba="0.58 0.6 0.61 1" />
        </material>
      </visual>
    <visual name="pin_head_0">
      <origin xyz="-0.353 0 0" rpy="0 1.5708 0" />
      <geometry>
        <cylinder radius="0.012" length="0.006" />
        </geometry>
      <material name="galvanized_steel">
        <color rgba="0.58 0.6 0.61 1" />
        </material>
      </visual>
    <visual name="pin_head_1">
      <origin xyz="0.353 0 0" rpy="0 1.5708 0" />
      <geometry>
        <cylinder radius="0.012" length="0.006" />
        </geometry>
      <material name="galvanized_steel">
        <color rgba="0.58 0.6 0.61 1" />
        </material>
      </visual>
    <collision name="blade">
      <geometry>
        <mesh filename="assets/meshes/rounded_louver_blade.obj" />
        </geometry>
      </collision>
    <collision name="pin_0">
      <origin xyz="-0.303 0 0" rpy="0 1.5708 0" />
      <geometry>
        <cylinder radius="0.006" length="0.096" />
        </geometry>
      </collision>
    <collision name="pin_1">
      <origin xyz="0.303 0 0" rpy="0 1.5708 0" />
      <geometry>
        <cylinder radius="0.006" length="0.096" />
        </geometry>
      </collision>
    <collision name="pin_head_0">
      <origin xyz="-0.353 0 0" rpy="0 1.5708 0" />
      <geometry>
        <cylinder radius="0.012" length="0.006" />
        </geometry>
      </collision>
    <collision name="pin_head_1">
      <origin xyz="0.353 0 0" rpy="0 1.5708 0" />
      <geometry>
        <cylinder radius="0.012" length="0.006" />
        </geometry>
      </collision>
    </link>
  <link name="slat_1">
    <inertial>
      <mass value="0.28" />
      <inertia ixx="0.000146533" ixy="0" ixz="0" iyy="0.0119707" iyz="0" izz="0.0118333" />
      </inertial>
    <visual name="blade">
      <geometry>
        <mesh filename="assets/meshes/rounded_louver_blade.obj" />
        </geometry>
      <material name="warm_off_white">
        <color rgba="0.8 0.78 0.7 1" />
        </material>
      </visual>
    <visual name="pin_0">
      <origin xyz="-0.303 0 0" rpy="0 1.5708 0" />
      <geometry>
        <cylinder radius="0.006" length="0.096" />
        </geometry>
      <material name="galvanized_steel">
        <color rgba="0.58 0.6 0.61 1" />
        </material>
      </visual>
    <visual name="pin_1">
      <origin xyz="0.303 0 0" rpy="0 1.5708 0" />
      <geometry>
        <cylinder radius="0.006" length="0.096" />
        </geometry>
      <material name="galvanized_steel">
        <color rgba="0.58 0.6 0.61 1" />
        </material>
      </visual>
    <visual name="pin_head_0">
      <origin xyz="-0.353 0 0" rpy="0 1.5708 0" />
      <geometry>
        <cylinder radius="0.012" length="0.006" />
        </geometry>
      <material name="galvanized_steel">
        <color rgba="0.58 0.6 0.61 1" />
        </material>
      </visual>
    <visual name="pin_head_1">
      <origin xyz="0.353 0 0" rpy="0 1.5708 0" />
      <geometry>
        <cylinder radius="0.012" length="0.006" />
        </geometry>
      <material name="galvanized_steel">
        <color rgba="0.58 0.6 0.61 1" />
        </material>
      </visual>
    <collision name="blade">
      <geometry>
        <mesh filename="assets/meshes/rounded_louver_blade.obj" />
        </geometry>
      </collision>
    <collision name="pin_0">
      <origin xyz="-0.303 0 0" rpy="0 1.5708 0" />
      <geometry>
        <cylinder radius="0.006" length="0.096" />
        </geometry>
      </collision>
    <collision name="pin_1">
      <origin xyz="0.303 0 0" rpy="0 1.5708 0" />
      <geometry>
        <cylinder radius="0.006" length="0.096" />
        </geometry>
      </collision>
    <collision name="pin_head_0">
      <origin xyz="-0.353 0 0" rpy="0 1.5708 0" />
      <geometry>
        <cylinder radius="0.012" length="0.006" />
        </geometry>
      </collision>
    <collision name="pin_head_1">
      <origin xyz="0.353 0 0" rpy="0 1.5708 0" />
      <geometry>
        <cylinder radius="0.012" length="0.006" />
        </geometry>
      </collision>
    </link>
  <link name="slat_2">
    <inertial>
      <mass value="0.28" />
      <inertia ixx="0.000146533" ixy="0" ixz="0" iyy="0.0119707" iyz="0" izz="0.0118333" />
      </inertial>
    <visual name="blade">
      <geometry>
        <mesh filename="assets/meshes/rounded_louver_blade.obj" />
        </geometry>
      <material name="warm_off_white">
        <color rgba="0.8 0.78 0.7 1" />
        </material>
      </visual>
    <visual name="pin_0">
      <origin xyz="-0.303 0 0" rpy="0 1.5708 0" />
      <geometry>
        <cylinder radius="0.006" length="0.096" />
        </geometry>
      <material name="galvanized_steel">
        <color rgba="0.58 0.6 0.61 1" />
        </material>
      </visual>
    <visual name="pin_1">
      <origin xyz="0.303 0 0" rpy="0 1.5708 0" />
      <geometry>
        <cylinder radius="0.006" length="0.096" />
        </geometry>
      <material name="galvanized_steel">
        <color rgba="0.58 0.6 0.61 1" />
        </material>
      </visual>
    <visual name="pin_head_0">
      <origin xyz="-0.353 0 0" rpy="0 1.5708 0" />
      <geometry>
        <cylinder radius="0.012" length="0.006" />
        </geometry>
      <material name="galvanized_steel">
        <color rgba="0.58 0.6 0.61 1" />
        </material>
      </visual>
    <visual name="pin_head_1">
      <origin xyz="0.353 0 0" rpy="0 1.5708 0" />
      <geometry>
        <cylinder radius="0.012" length="0.006" />
        </geometry>
      <material name="galvanized_steel">
        <color rgba="0.58 0.6 0.61 1" />
        </material>
      </visual>
    <collision name="blade">
      <geometry>
        <mesh filename="assets/meshes/rounded_louver_blade.obj" />
        </geometry>
      </collision>
    <collision name="pin_0">
      <origin xyz="-0.303 0 0" rpy="0 1.5708 0" />
      <geometry>
        <cylinder radius="0.006" length="0.096" />
        </geometry>
      </collision>
    <collision name="pin_1">
      <origin xyz="0.303 0 0" rpy="0 1.5708 0" />
      <geometry>
        <cylinder radius="0.006" length="0.096" />
        </geometry>
      </collision>
    <collision name="pin_head_0">
      <origin xyz="-0.353 0 0" rpy="0 1.5708 0" />
      <geometry>
        <cylinder radius="0.012" length="0.006" />
        </geometry>
      </collision>
    <collision name="pin_head_1">
      <origin xyz="0.353 0 0" rpy="0 1.5708 0" />
      <geometry>
        <cylinder radius="0.012" length="0.006" />
        </geometry>
      </collision>
    </link>
  <link name="slat_3">
    <inertial>
      <mass value="0.28" />
      <inertia ixx="0.000146533" ixy="0" ixz="0" iyy="0.0119707" iyz="0" izz="0.0118333" />
      </inertial>
    <visual name="blade">
      <geometry>
        <mesh filename="assets/meshes/rounded_louver_blade.obj" />
        </geometry>
      <material name="warm_off_white">
        <color rgba="0.8 0.78 0.7 1" />
        </material>
      </visual>
    <visual name="pin_0">
      <origin xyz="-0.303 0 0" rpy="0 1.5708 0" />
      <geometry>
        <cylinder radius="0.006" length="0.096" />
        </geometry>
      <material name="galvanized_steel">
        <color rgba="0.58 0.6 0.61 1" />
        </material>
      </visual>
    <visual name="pin_1">
      <origin xyz="0.303 0 0" rpy="0 1.5708 0" />
      <geometry>
        <cylinder radius="0.006" length="0.096" />
        </geometry>
      <material name="galvanized_steel">
        <color rgba="0.58 0.6 0.61 1" />
        </material>
      </visual>
    <visual name="pin_head_0">
      <origin xyz="-0.353 0 0" rpy="0 1.5708 0" />
      <geometry>
        <cylinder radius="0.012" length="0.006" />
        </geometry>
      <material name="galvanized_steel">
        <color rgba="0.58 0.6 0.61 1" />
        </material>
      </visual>
    <visual name="pin_head_1">
      <origin xyz="0.353 0 0" rpy="0 1.5708 0" />
      <geometry>
        <cylinder radius="0.012" length="0.006" />
        </geometry>
      <material name="galvanized_steel">
        <color rgba="0.58 0.6 0.61 1" />
        </material>
      </visual>
    <collision name="blade">
      <geometry>
        <mesh filename="assets/meshes/rounded_louver_blade.obj" />
        </geometry>
      </collision>
    <collision name="pin_0">
      <origin xyz="-0.303 0 0" rpy="0 1.5708 0" />
      <geometry>
        <cylinder radius="0.006" length="0.096" />
        </geometry>
      </collision>
    <collision name="pin_1">
      <origin xyz="0.303 0 0" rpy="0 1.5708 0" />
      <geometry>
        <cylinder radius="0.006" length="0.096" />
        </geometry>
      </collision>
    <collision name="pin_head_0">
      <origin xyz="-0.353 0 0" rpy="0 1.5708 0" />
      <geometry>
        <cylinder radius="0.012" length="0.006" />
        </geometry>
      </collision>
    <collision name="pin_head_1">
      <origin xyz="0.353 0 0" rpy="0 1.5708 0" />
      <geometry>
        <cylinder radius="0.012" length="0.006" />
        </geometry>
      </collision>
    </link>
  <link name="slat_4">
    <inertial>
      <mass value="0.28" />
      <inertia ixx="0.000146533" ixy="0" ixz="0" iyy="0.0119707" iyz="0" izz="0.0118333" />
      </inertial>
    <visual name="blade">
      <geometry>
        <mesh filename="assets/meshes/rounded_louver_blade.obj" />
        </geometry>
      <material name="warm_off_white">
        <color rgba="0.8 0.78 0.7 1" />
        </material>
      </visual>
    <visual name="pin_0">
      <origin xyz="-0.303 0 0" rpy="0 1.5708 0" />
      <geometry>
        <cylinder radius="0.006" length="0.096" />
        </geometry>
      <material name="galvanized_steel">
        <color rgba="0.58 0.6 0.61 1" />
        </material>
      </visual>
    <visual name="pin_1">
      <origin xyz="0.303 0 0" rpy="0 1.5708 0" />
      <geometry>
        <cylinder radius="0.006" length="0.096" />
        </geometry>
      <material name="galvanized_steel">
        <color rgba="0.58 0.6 0.61 1" />
        </material>
      </visual>
    <visual name="pin_head_0">
      <origin xyz="-0.353 0 0" rpy="0 1.5708 0" />
      <geometry>
        <cylinder radius="0.012" length="0.006" />
        </geometry>
      <material name="galvanized_steel">
        <color rgba="0.58 0.6 0.61 1" />
        </material>
      </visual>
    <visual name="pin_head_1">
      <origin xyz="0.353 0 0" rpy="0 1.5708 0" />
      <geometry>
        <cylinder radius="0.012" length="0.006" />
        </geometry>
      <material name="galvanized_steel">
        <color rgba="0.58 0.6 0.61 1" />
        </material>
      </visual>
    <collision name="blade">
      <geometry>
        <mesh filename="assets/meshes/rounded_louver_blade.obj" />
        </geometry>
      </collision>
    <collision name="pin_0">
      <origin xyz="-0.303 0 0" rpy="0 1.5708 0" />
      <geometry>
        <cylinder radius="0.006" length="0.096" />
        </geometry>
      </collision>
    <collision name="pin_1">
      <origin xyz="0.303 0 0" rpy="0 1.5708 0" />
      <geometry>
        <cylinder radius="0.006" length="0.096" />
        </geometry>
      </collision>
    <collision name="pin_head_0">
      <origin xyz="-0.353 0 0" rpy="0 1.5708 0" />
      <geometry>
        <cylinder radius="0.012" length="0.006" />
        </geometry>
      </collision>
    <collision name="pin_head_1">
      <origin xyz="0.353 0 0" rpy="0 1.5708 0" />
      <geometry>
        <cylinder radius="0.012" length="0.006" />
        </geometry>
      </collision>
    </link>
  <link name="slat_5">
    <inertial>
      <mass value="0.28" />
      <inertia ixx="0.000146533" ixy="0" ixz="0" iyy="0.0119707" iyz="0" izz="0.0118333" />
      </inertial>
    <visual name="blade">
      <geometry>
        <mesh filename="assets/meshes/rounded_louver_blade.obj" />
        </geometry>
      <material name="warm_off_white">
        <color rgba="0.8 0.78 0.7 1" />
        </material>
      </visual>
    <visual name="pin_0">
      <origin xyz="-0.303 0 0" rpy="0 1.5708 0" />
      <geometry>
        <cylinder radius="0.006" length="0.096" />
        </geometry>
      <material name="galvanized_steel">
        <color rgba="0.58 0.6 0.61 1" />
        </material>
      </visual>
    <visual name="pin_1">
      <origin xyz="0.303 0 0" rpy="0 1.5708 0" />
      <geometry>
        <cylinder radius="0.006" length="0.096" />
        </geometry>
      <material name="galvanized_steel">
        <color rgba="0.58 0.6 0.61 1" />
        </material>
      </visual>
    <visual name="pin_head_0">
      <origin xyz="-0.353 0 0" rpy="0 1.5708 0" />
      <geometry>
        <cylinder radius="0.012" length="0.006" />
        </geometry>
      <material name="galvanized_steel">
        <color rgba="0.58 0.6 0.61 1" />
        </material>
      </visual>
    <visual name="pin_head_1">
      <origin xyz="0.353 0 0" rpy="0 1.5708 0" />
      <geometry>
        <cylinder radius="0.012" length="0.006" />
        </geometry>
      <material name="galvanized_steel">
        <color rgba="0.58 0.6 0.61 1" />
        </material>
      </visual>
    <collision name="blade">
      <geometry>
        <mesh filename="assets/meshes/rounded_louver_blade.obj" />
        </geometry>
      </collision>
    <collision name="pin_0">
      <origin xyz="-0.303 0 0" rpy="0 1.5708 0" />
      <geometry>
        <cylinder radius="0.006" length="0.096" />
        </geometry>
      </collision>
    <collision name="pin_1">
      <origin xyz="0.303 0 0" rpy="0 1.5708 0" />
      <geometry>
        <cylinder radius="0.006" length="0.096" />
        </geometry>
      </collision>
    <collision name="pin_head_0">
      <origin xyz="-0.353 0 0" rpy="0 1.5708 0" />
      <geometry>
        <cylinder radius="0.012" length="0.006" />
        </geometry>
      </collision>
    <collision name="pin_head_1">
      <origin xyz="0.353 0 0" rpy="0 1.5708 0" />
      <geometry>
        <cylinder radius="0.012" length="0.006" />
        </geometry>
      </collision>
    </link>
  <link name="slat_6">
    <inertial>
      <mass value="0.28" />
      <inertia ixx="0.000146533" ixy="0" ixz="0" iyy="0.0119707" iyz="0" izz="0.0118333" />
      </inertial>
    <visual name="blade">
      <geometry>
        <mesh filename="assets/meshes/rounded_louver_blade.obj" />
        </geometry>
      <material name="warm_off_white">
        <color rgba="0.8 0.78 0.7 1" />
        </material>
      </visual>
    <visual name="pin_0">
      <origin xyz="-0.303 0 0" rpy="0 1.5708 0" />
      <geometry>
        <cylinder radius="0.006" length="0.096" />
        </geometry>
      <material name="galvanized_steel">
        <color rgba="0.58 0.6 0.61 1" />
        </material>
      </visual>
    <visual name="pin_1">
      <origin xyz="0.303 0 0" rpy="0 1.5708 0" />
      <geometry>
        <cylinder radius="0.006" length="0.096" />
        </geometry>
      <material name="galvanized_steel">
        <color rgba="0.58 0.6 0.61 1" />
        </material>
      </visual>
    <visual name="pin_head_0">
      <origin xyz="-0.353 0 0" rpy="0 1.5708 0" />
      <geometry>
        <cylinder radius="0.012" length="0.006" />
        </geometry>
      <material name="galvanized_steel">
        <color rgba="0.58 0.6 0.61 1" />
        </material>
      </visual>
    <visual name="pin_head_1">
      <origin xyz="0.353 0 0" rpy="0 1.5708 0" />
      <geometry>
        <cylinder radius="0.012" length="0.006" />
        </geometry>
      <material name="galvanized_steel">
        <color rgba="0.58 0.6 0.61 1" />
        </material>
      </visual>
    <collision name="blade">
      <geometry>
        <mesh filename="assets/meshes/rounded_louver_blade.obj" />
        </geometry>
      </collision>
    <collision name="pin_0">
      <origin xyz="-0.303 0 0" rpy="0 1.5708 0" />
      <geometry>
        <cylinder radius="0.006" length="0.096" />
        </geometry>
      </collision>
    <collision name="pin_1">
      <origin xyz="0.303 0 0" rpy="0 1.5708 0" />
      <geometry>
        <cylinder radius="0.006" length="0.096" />
        </geometry>
      </collision>
    <collision name="pin_head_0">
      <origin xyz="-0.353 0 0" rpy="0 1.5708 0" />
      <geometry>
        <cylinder radius="0.012" length="0.006" />
        </geometry>
      </collision>
    <collision name="pin_head_1">
      <origin xyz="0.353 0 0" rpy="0 1.5708 0" />
      <geometry>
        <cylinder radius="0.012" length="0.006" />
        </geometry>
      </collision>
    </link>
  <link name="slat_7">
    <inertial>
      <mass value="0.28" />
      <inertia ixx="0.000146533" ixy="0" ixz="0" iyy="0.0119707" iyz="0" izz="0.0118333" />
      </inertial>
    <visual name="blade">
      <geometry>
        <mesh filename="assets/meshes/rounded_louver_blade.obj" />
        </geometry>
      <material name="warm_off_white">
        <color rgba="0.8 0.78 0.7 1" />
        </material>
      </visual>
    <visual name="pin_0">
      <origin xyz="-0.303 0 0" rpy="0 1.5708 0" />
      <geometry>
        <cylinder radius="0.006" length="0.096" />
        </geometry>
      <material name="galvanized_steel">
        <color rgba="0.58 0.6 0.61 1" />
        </material>
      </visual>
    <visual name="pin_1">
      <origin xyz="0.303 0 0" rpy="0 1.5708 0" />
      <geometry>
        <cylinder radius="0.006" length="0.096" />
        </geometry>
      <material name="galvanized_steel">
        <color rgba="0.58 0.6 0.61 1" />
        </material>
      </visual>
    <visual name="pin_head_0">
      <origin xyz="-0.353 0 0" rpy="0 1.5708 0" />
      <geometry>
        <cylinder radius="0.012" length="0.006" />
        </geometry>
      <material name="galvanized_steel">
        <color rgba="0.58 0.6 0.61 1" />
        </material>
      </visual>
    <visual name="pin_head_1">
      <origin xyz="0.353 0 0" rpy="0 1.5708 0" />
      <geometry>
        <cylinder radius="0.012" length="0.006" />
        </geometry>
      <material name="galvanized_steel">
        <color rgba="0.58 0.6 0.61 1" />
        </material>
      </visual>
    <collision name="blade">
      <geometry>
        <mesh filename="assets/meshes/rounded_louver_blade.obj" />
        </geometry>
      </collision>
    <collision name="pin_0">
      <origin xyz="-0.303 0 0" rpy="0 1.5708 0" />
      <geometry>
        <cylinder radius="0.006" length="0.096" />
        </geometry>
      </collision>
    <collision name="pin_1">
      <origin xyz="0.303 0 0" rpy="0 1.5708 0" />
      <geometry>
        <cylinder radius="0.006" length="0.096" />
        </geometry>
      </collision>
    <collision name="pin_head_0">
      <origin xyz="-0.353 0 0" rpy="0 1.5708 0" />
      <geometry>
        <cylinder radius="0.012" length="0.006" />
        </geometry>
      </collision>
    <collision name="pin_head_1">
      <origin xyz="0.353 0 0" rpy="0 1.5708 0" />
      <geometry>
        <cylinder radius="0.012" length="0.006" />
        </geometry>
      </collision>
    </link>
  <joint name="slat_pivot_0" type="revolute">
    <origin xyz="0 0 -0.455" rpy="0 0 0" />
    <parent link="frame" />
    <child link="slat_0" />
    <axis xyz="1 0 0" />
    <limit effort="1.2" velocity="2" lower="0" upper="1.5708" />
    </joint>
  <joint name="slat_pivot_1" type="revolute">
    <origin xyz="0 0 -0.325" rpy="0 0 0" />
    <parent link="frame" />
    <child link="slat_1" />
    <axis xyz="1 0 0" />
    <limit effort="1.2" velocity="2" lower="0" upper="1.5708" />
    </joint>
  <joint name="slat_pivot_2" type="revolute">
    <origin xyz="0 0 -0.195" rpy="0 0 0" />
    <parent link="frame" />
    <child link="slat_2" />
    <axis xyz="1 0 0" />
    <limit effort="1.2" velocity="2" lower="0" upper="1.5708" />
    </joint>
  <joint name="slat_pivot_3" type="revolute">
    <origin xyz="0 0 -0.065" rpy="0 0 0" />
    <parent link="frame" />
    <child link="slat_3" />
    <axis xyz="1 0 0" />
    <limit effort="1.2" velocity="2" lower="0" upper="1.5708" />
    </joint>
  <joint name="slat_pivot_4" type="revolute">
    <origin xyz="0 0 0.065" rpy="0 0 0" />
    <parent link="frame" />
    <child link="slat_4" />
    <axis xyz="1 0 0" />
    <limit effort="1.2" velocity="2" lower="0" upper="1.5708" />
    </joint>
  <joint name="slat_pivot_5" type="revolute">
    <origin xyz="0 0 0.195" rpy="0 0 0" />
    <parent link="frame" />
    <child link="slat_5" />
    <axis xyz="1 0 0" />
    <limit effort="1.2" velocity="2" lower="0" upper="1.5708" />
    </joint>
  <joint name="slat_pivot_6" type="revolute">
    <origin xyz="0 0 0.325" rpy="0 0 0" />
    <parent link="frame" />
    <child link="slat_6" />
    <axis xyz="1 0 0" />
    <limit effort="1.2" velocity="2" lower="0" upper="1.5708" />
    </joint>
  <joint name="slat_pivot_7" type="revolute">
    <origin xyz="0 0 0.455" rpy="0 0 0" />
    <parent link="frame" />
    <child link="slat_7" />
    <axis xyz="1 0 0" />
    <limit effort="1.2" velocity="2" lower="0" upper="1.5708" />
    </joint>
  </robot>
