<robot name="stacked_oven_range_cooker">
  <material name="brushed_stainless">
    <color rgba="0.62 0.62 0.58 1" />
    </material>
  <material name="black_enamel">
    <color rgba="0.02 0.022 0.02 1" />
    </material>
  <material name="matte_cast_iron">
    <color rgba="0.006 0.006 0.005 1" />
    </material>
  <material name="smoky_oven_glass">
    <color rgba="0.03 0.045 0.055 0.72" />
    </material>
  <material name="polished_handle">
    <color rgba="0.78 0.76 0.7 1" />
    </material>
  <material name="white_indicator">
    <color rgba="0.92 0.9 0.82 1" />
    </material>
  <link name="body">
    <visual name="plinth">
      <origin xyz="0 0 0.04" rpy="0 0 0" />
      <geometry>
        <box size="0.95 0.7 0.08" />
        </geometry>
      <material name="brushed_stainless">
        <color rgba="0.62 0.62 0.58 1" />
        </material>
      </visual>
    <visual name="side_stile_0">
      <origin xyz="-0.4575 0 0.4725" rpy="0 0 0" />
      <geometry>
        <box size="0.035 0.66 0.785" />
        </geometry>
      <material name="brushed_stainless">
        <color rgba="0.62 0.62 0.58 1" />
        </material>
      </visual>
    <visual name="side_stile_1">
      <origin xyz="0.4575 0 0.4725" rpy="0 0 0" />
      <geometry>
        <box size="0.035 0.66 0.785" />
        </geometry>
      <material name="brushed_stainless">
        <color rgba="0.62 0.62 0.58 1" />
        </material>
      </visual>
    <visual name="rear_panel">
      <origin xyz="0 0.3125 0.4725" rpy="0 0 0" />
      <geometry>
        <box size="0.9 0.035 0.785" />
        </geometry>
      <material name="brushed_stainless">
        <color rgba="0.62 0.62 0.58 1" />
        </material>
      </visual>
    <visual name="cooktop">
      <origin xyz="0 0 0.89" rpy="0 0 0" />
      <geometry>
        <box size="0.95 0.7 0.06" />
        </geometry>
      <material name="black_enamel">
        <color rgba="0.02 0.022 0.02 1" />
        </material>
      </visual>
    <visual name="front_stile_0">
      <origin xyz="-0.43 -0.3475 0.405" rpy="0 0 0" />
      <geometry>
        <box size="0.04 0.035 0.66" />
        </geometry>
      <material name="brushed_stainless">
        <color rgba="0.62 0.62 0.58 1" />
        </material>
      </visual>
    <visual name="front_stile_1">
      <origin xyz="0.43 -0.3475 0.405" rpy="0 0 0" />
      <geometry>
        <box size="0.04 0.035 0.66" />
        </geometry>
      <material name="brushed_stainless">
        <color rgba="0.62 0.62 0.58 1" />
        </material>
      </visual>
    <visual name="lower_sill">
      <origin xyz="0 -0.3475 0.0975" rpy="0 0 0" />
      <geometry>
        <box size="0.88 0.035 0.035" />
        </geometry>
      <material name="brushed_stainless">
        <color rgba="0.62 0.62 0.58 1" />
        </material>
      </visual>
    <visual name="center_rail">
      <origin xyz="0 -0.3475 0.405" rpy="0 0 0" />
      <geometry>
        <box size="0.88 0.035 0.03" />
        </geometry>
      <material name="brushed_stainless">
        <color rgba="0.62 0.62 0.58 1" />
        </material>
      </visual>
    <visual name="upper_rail">
      <origin xyz="0 -0.3475 0.725" rpy="0 0 0" />
      <geometry>
        <box size="0.88 0.035 0.03" />
        </geometry>
      <material name="brushed_stainless">
        <color rgba="0.62 0.62 0.58 1" />
        </material>
      </visual>
    <visual name="control_fascia">
      <origin xyz="0 -0.3475 0.795" rpy="0 0 0" />
      <geometry>
        <box size="0.88 0.035 0.13" />
        </geometry>
      <material name="brushed_stainless">
        <color rgba="0.62 0.62 0.58 1" />
        </material>
      </visual>
    <visual name="lower_cavity">
      <origin xyz="0 -0.326 0.25" rpy="0 0 0" />
      <geometry>
        <box size="0.84 0.012 0.3" />
        </geometry>
      <material name="black_enamel">
        <color rgba="0.02 0.022 0.02 1" />
        </material>
      </visual>
    <visual name="upper_cavity">
      <origin xyz="0 -0.326 0.575" rpy="0 0 0" />
      <geometry>
        <box size="0.84 0.012 0.31" />
        </geometry>
      <material name="black_enamel">
        <color rgba="0.02 0.022 0.02 1" />
        </material>
      </visual>
    <visual name="burner_ring_0">
      <origin xyz="-0.31 -0.16 0.923" rpy="0 0 0" />
      <geometry>
        <cylinder radius="0.078" length="0.006" />
        </geometry>
      <material name="polished_handle">
        <color rgba="0.78 0.76 0.7 1" />
        </material>
      </visual>
    <visual name="burner_cap_0">
      <origin xyz="-0.31 -0.16 0.928" rpy="0 0 0" />
      <geometry>
        <cylinder radius="0.052" length="0.01" />
        </geometry>
      <material name="matte_cast_iron">
        <color rgba="0.006 0.006 0.005 1" />
        </material>
      </visual>
    <visual name="burner_ring_1">
      <origin xyz="0 -0.16 0.923" rpy="0 0 0" />
      <geometry>
        <cylinder radius="0.078" length="0.006" />
        </geometry>
      <material name="polished_handle">
        <color rgba="0.78 0.76 0.7 1" />
        </material>
      </visual>
    <visual name="burner_cap_1">
      <origin xyz="0 -0.16 0.928" rpy="0 0 0" />
      <geometry>
        <cylinder radius="0.052" length="0.01" />
        </geometry>
      <material name="matte_cast_iron">
        <color rgba="0.006 0.006 0.005 1" />
        </material>
      </visual>
    <visual name="burner_ring_2">
      <origin xyz="0.31 -0.16 0.923" rpy="0 0 0" />
      <geometry>
        <cylinder radius="0.078" length="0.006" />
        </geometry>
      <material name="polished_handle">
        <color rgba="0.78 0.76 0.7 1" />
        </material>
      </visual>
    <visual name="burner_cap_2">
      <origin xyz="0.31 -0.16 0.928" rpy="0 0 0" />
      <geometry>
        <cylinder radius="0.052" length="0.01" />
        </geometry>
      <material name="matte_cast_iron">
        <color rgba="0.006 0.006 0.005 1" />
        </material>
      </visual>
    <visual name="burner_ring_3">
      <origin xyz="-0.31 0.15 0.923" rpy="0 0 0" />
      <geometry>
        <cylinder radius="0.078" length="0.006" />
        </geometry>
      <material name="polished_handle">
        <color rgba="0.78 0.76 0.7 1" />
        </material>
      </visual>
    <visual name="burner_cap_3">
      <origin xyz="-0.31 0.15 0.928" rpy="0 0 0" />
      <geometry>
        <cylinder radius="0.052" length="0.01" />
        </geometry>
      <material name="matte_cast_iron">
        <color rgba="0.006 0.006 0.005 1" />
        </material>
      </visual>
    <visual name="burner_ring_4">
      <origin xyz="0 0.15 0.923" rpy="0 0 0" />
      <geometry>
        <cylinder radius="0.078" length="0.006" />
        </geometry>
      <material name="polished_handle">
        <color rgba="0.78 0.76 0.7 1" />
        </material>
      </visual>
    <visual name="burner_cap_4">
      <origin xyz="0 0.15 0.928" rpy="0 0 0" />
      <geometry>
        <cylinder radius="0.052" length="0.01" />
        </geometry>
      <material name="matte_cast_iron">
        <color rgba="0.006 0.006 0.005 1" />
        </material>
      </visual>
    <visual name="burner_ring_5">
      <origin xyz="0.31 0.15 0.923" rpy="0 0 0" />
      <geometry>
        <cylinder radius="0.078" length="0.006" />
        </geometry>
      <material name="polished_handle">
        <color rgba="0.78 0.76 0.7 1" />
        </material>
      </visual>
    <visual name="burner_cap_5">
      <origin xyz="0.31 0.15 0.928" rpy="0 0 0" />
      <geometry>
        <cylinder radius="0.052" length="0.01" />
        </geometry>
      <material name="matte_cast_iron">
        <color rgba="0.006 0.006 0.005 1" />
        </material>
      </visual>
    <collision name="plinth">
      <origin xyz="0 0 0.04" rpy="0 0 0" />
      <geometry>
        <box size="0.95 0.7 0.08" />
        </geometry>
      </collision>
    <collision name="side_stile_0">
      <origin xyz="-0.4575 0 0.4725" rpy="0 0 0" />
      <geometry>
        <box size="0.035 0.66 0.785" />
        </geometry>
      </collision>
    <collision name="side_stile_1">
      <origin xyz="0.4575 0 0.4725" rpy="0 0 0" />
      <geometry>
        <box size="0.035 0.66 0.785" />
        </geometry>
      </collision>
    <collision name="rear_panel">
      <origin xyz="0 0.3125 0.4725" rpy="0 0 0" />
      <geometry>
        <box size="0.9 0.035 0.785" />
        </geometry>
      </collision>
    <collision name="cooktop">
      <origin xyz="0 0 0.89" rpy="0 0 0" />
      <geometry>
        <box size="0.95 0.7 0.06" />
        </geometry>
      </collision>
    <collision name="front_stile_0">
      <origin xyz="-0.43 -0.3475 0.405" rpy="0 0 0" />
      <geometry>
        <box size="0.04 0.035 0.66" />
        </geometry>
      </collision>
    <collision name="front_stile_1">
      <origin xyz="0.43 -0.3475 0.405" rpy="0 0 0" />
      <geometry>
        <box size="0.04 0.035 0.66" />
        </geometry>
      </collision>
    <collision name="lower_sill">
      <origin xyz="0 -0.3475 0.0975" rpy="0 0 0" />
      <geometry>
        <box size="0.88 0.035 0.035" />
        </geometry>
      </collision>
    <collision name="center_rail">
      <origin xyz="0 -0.3475 0.405" rpy="0 0 0" />
      <geometry>
        <box size="0.88 0.035 0.03" />
        </geometry>
      </collision>
    <collision name="upper_rail">
      <origin xyz="0 -0.3475 0.725" rpy="0 0 0" />
      <geometry>
        <box size="0.88 0.035 0.03" />
        </geometry>
      </collision>
    <collision name="control_fascia">
      <origin xyz="0 -0.3475 0.795" rpy="0 0 0" />
      <geometry>
        <box size="0.88 0.035 0.13" />
        </geometry>
      </collision>
    <collision name="lower_cavity">
      <origin xyz="0 -0.326 0.25" rpy="0 0 0" />
      <geometry>
        <box size="0.84 0.012 0.3" />
        </geometry>
      </collision>
    <collision name="upper_cavity">
      <origin xyz="0 -0.326 0.575" rpy="0 0 0" />
      <geometry>
        <box size="0.84 0.012 0.31" />
        </geometry>
      </collision>
    <collision name="burner_ring_0">
      <origin xyz="-0.31 -0.16 0.923" rpy="0 0 0" />
      <geometry>
        <cylinder radius="0.078" length="0.006" />
        </geometry>
      </collision>
    <collision name="burner_cap_0">
      <origin xyz="-0.31 -0.16 0.928" rpy="0 0 0" />
      <geometry>
        <cylinder radius="0.052" length="0.01" />
        </geometry>
      </collision>
    <collision name="burner_ring_1">
      <origin xyz="0 -0.16 0.923" rpy="0 0 0" />
      <geometry>
        <cylinder radius="0.078" length="0.006" />
        </geometry>
      </collision>
    <collision name="burner_cap_1">
      <origin xyz="0 -0.16 0.928" rpy="0 0 0" />
      <geometry>
        <cylinder radius="0.052" length="0.01" />
        </geometry>
      </collision>
    <collision name="burner_ring_2">
      <origin xyz="0.31 -0.16 0.923" rpy="0 0 0" />
      <geometry>
        <cylinder radius="0.078" length="0.006" />
        </geometry>
      </collision>
    <collision name="burner_cap_2">
      <origin xyz="0.31 -0.16 0.928" rpy="0 0 0" />
      <geometry>
        <cylinder radius="0.052" length="0.01" />
        </geometry>
      </collision>
    <collision name="burner_ring_3">
      <origin xyz="-0.31 0.15 0.923" rpy="0 0 0" />
      <geometry>
        <cylinder radius="0.078" length="0.006" />
        </geometry>
      </collision>
    <collision name="burner_cap_3">
      <origin xyz="-0.31 0.15 0.928" rpy="0 0 0" />
      <geometry>
        <cylinder radius="0.052" length="0.01" />
        </geometry>
      </collision>
    <collision name="burner_ring_4">
      <origin xyz="0 0.15 0.923" rpy="0 0 0" />
      <geometry>
        <cylinder radius="0.078" length="0.006" />
        </geometry>
      </collision>
    <collision name="burner_cap_4">
      <origin xyz="0 0.15 0.928" rpy="0 0 0" />
      <geometry>
        <cylinder radius="0.052" length="0.01" />
        </geometry>
      </collision>
    <collision name="burner_ring_5">
      <origin xyz="0.31 0.15 0.923" rpy="0 0 0" />
      <geometry>
        <cylinder radius="0.078" length="0.006" />
        </geometry>
      </collision>
    <collision name="burner_cap_5">
      <origin xyz="0.31 0.15 0.928" rpy="0 0 0" />
      <geometry>
        <cylinder radius="0.052" length="0.01" />
        </geometry>
      </collision>
    </link>
  <link name="grate_0">
    <visual name="foot_0">
      <origin xyz="-0.0915 -0.0815 0.006" rpy="0 0 0" />
      <geometry>
        <box size="0.034 0.034 0.012" />
        </geometry>
      <material name="matte_cast_iron">
        <color rgba="0.006 0.006 0.005 1" />
        </material>
      </visual>
    <visual name="foot_1">
      <origin xyz="0.0915 -0.0815 0.006" rpy="0 0 0" />
      <geometry>
        <box size="0.034 0.034 0.012" />
        </geometry>
      <material name="matte_cast_iron">
        <color rgba="0.006 0.006 0.005 1" />
        </material>
      </visual>
    <visual name="foot_2">
      <origin xyz="-0.0915 0.0815 0.006" rpy="0 0 0" />
      <geometry>
        <box size="0.034 0.034 0.012" />
        </geometry>
      <material name="matte_cast_iron">
        <color rgba="0.006 0.006 0.005 1" />
        </material>
      </visual>
    <visual name="foot_3">
      <origin xyz="0.0915 0.0815 0.006" rpy="0 0 0" />
      <geometry>
        <box size="0.034 0.034 0.012" />
        </geometry>
      <material name="matte_cast_iron">
        <color rgba="0.006 0.006 0.005 1" />
        </material>
      </visual>
    <visual name="front_bar">
      <origin xyz="0 -0.1075 0.02" rpy="0 0 0" />
      <geometry>
        <box size="0.235 0.02 0.016" />
        </geometry>
      <material name="matte_cast_iron">
        <color rgba="0.006 0.006 0.005 1" />
        </material>
      </visual>
    <visual name="rear_bar">
      <origin xyz="0 0.1075 0.02" rpy="0 0 0" />
      <geometry>
        <box size="0.235 0.02 0.016" />
        </geometry>
      <material name="matte_cast_iron">
        <color rgba="0.006 0.006 0.005 1" />
        </material>
      </visual>
    <visual name="side_bar_0">
      <origin xyz="-0.1175 0 0.02" rpy="0 0 0" />
      <geometry>
        <box size="0.02 0.215 0.016" />
        </geometry>
      <material name="matte_cast_iron">
        <color rgba="0.006 0.006 0.005 1" />
        </material>
      </visual>
    <visual name="side_bar_1">
      <origin xyz="0.1175 0 0.02" rpy="0 0 0" />
      <geometry>
        <box size="0.02 0.215 0.016" />
        </geometry>
      <material name="matte_cast_iron">
        <color rgba="0.006 0.006 0.005 1" />
        </material>
      </visual>
    <visual name="cross_bar_y">
      <origin xyz="0 0 0.02" rpy="0 0 0" />
      <geometry>
        <box size="0.02 0.215 0.016" />
        </geometry>
      <material name="matte_cast_iron">
        <color rgba="0.006 0.006 0.005 1" />
        </material>
      </visual>
    <visual name="cross_bar_x">
      <origin xyz="0 0 0.02" rpy="0 0 0" />
      <geometry>
        <box size="0.235 0.02 0.016" />
        </geometry>
      <material name="matte_cast_iron">
        <color rgba="0.006 0.006 0.005 1" />
        </material>
      </visual>
    <collision name="foot_0">
      <origin xyz="-0.0915 -0.0815 0.006" rpy="0 0 0" />
      <geometry>
        <box size="0.034 0.034 0.012" />
        </geometry>
      </collision>
    <collision name="foot_1">
      <origin xyz="0.0915 -0.0815 0.006" rpy="0 0 0" />
      <geometry>
        <box size="0.034 0.034 0.012" />
        </geometry>
      </collision>
    <collision name="foot_2">
      <origin xyz="-0.0915 0.0815 0.006" rpy="0 0 0" />
      <geometry>
        <box size="0.034 0.034 0.012" />
        </geometry>
      </collision>
    <collision name="foot_3">
      <origin xyz="0.0915 0.0815 0.006" rpy="0 0 0" />
      <geometry>
        <box size="0.034 0.034 0.012" />
        </geometry>
      </collision>
    <collision name="front_bar">
      <origin xyz="0 -0.1075 0.02" rpy="0 0 0" />
      <geometry>
        <box size="0.235 0.02 0.016" />
        </geometry>
      </collision>
    <collision name="rear_bar">
      <origin xyz="0 0.1075 0.02" rpy="0 0 0" />
      <geometry>
        <box size="0.235 0.02 0.016" />
        </geometry>
      </collision>
    <collision name="side_bar_0">
      <origin xyz="-0.1175 0 0.02" rpy="0 0 0" />
      <geometry>
        <box size="0.02 0.215 0.016" />
        </geometry>
      </collision>
    <collision name="side_bar_1">
      <origin xyz="0.1175 0 0.02" rpy="0 0 0" />
      <geometry>
        <box size="0.02 0.215 0.016" />
        </geometry>
      </collision>
    <collision name="cross_bar_y">
      <origin xyz="0 0 0.02" rpy="0 0 0" />
      <geometry>
        <box size="0.02 0.215 0.016" />
        </geometry>
      </collision>
    <collision name="cross_bar_x">
      <origin xyz="0 0 0.02" rpy="0 0 0" />
      <geometry>
        <box size="0.235 0.02 0.016" />
        </geometry>
      </collision>
    </link>
  <link name="grate_1">
    <visual name="foot_0">
      <origin xyz="-0.0915 -0.0815 0.006" rpy="0 0 0" />
      <geometry>
        <box size="0.034 0.034 0.012" />
        </geometry>
      <material name="matte_cast_iron">
        <color rgba="0.006 0.006 0.005 1" />
        </material>
      </visual>
    <visual name="foot_1">
      <origin xyz="0.0915 -0.0815 0.006" rpy="0 0 0" />
      <geometry>
        <box size="0.034 0.034 0.012" />
        </geometry>
      <material name="matte_cast_iron">
        <color rgba="0.006 0.006 0.005 1" />
        </material>
      </visual>
    <visual name="foot_2">
      <origin xyz="-0.0915 0.0815 0.006" rpy="0 0 0" />
      <geometry>
        <box size="0.034 0.034 0.012" />
        </geometry>
      <material name="matte_cast_iron">
        <color rgba="0.006 0.006 0.005 1" />
        </material>
      </visual>
    <visual name="foot_3">
      <origin xyz="0.0915 0.0815 0.006" rpy="0 0 0" />
      <geometry>
        <box size="0.034 0.034 0.012" />
        </geometry>
      <material name="matte_cast_iron">
        <color rgba="0.006 0.006 0.005 1" />
        </material>
      </visual>
    <visual name="front_bar">
      <origin xyz="0 -0.1075 0.02" rpy="0 0 0" />
      <geometry>
        <box size="0.235 0.02 0.016" />
        </geometry>
      <material name="matte_cast_iron">
        <color rgba="0.006 0.006 0.005 1" />
        </material>
      </visual>
    <visual name="rear_bar">
      <origin xyz="0 0.1075 0.02" rpy="0 0 0" />
      <geometry>
        <box size="0.235 0.02 0.016" />
        </geometry>
      <material name="matte_cast_iron">
        <color rgba="0.006 0.006 0.005 1" />
        </material>
      </visual>
    <visual name="side_bar_0">
      <origin xyz="-0.1175 0 0.02" rpy="0 0 0" />
      <geometry>
        <box size="0.02 0.215 0.016" />
        </geometry>
      <material name="matte_cast_iron">
        <color rgba="0.006 0.006 0.005 1" />
        </material>
      </visual>
    <visual name="side_bar_1">
      <origin xyz="0.1175 0 0.02" rpy="0 0 0" />
      <geometry>
        <box size="0.02 0.215 0.016" />
        </geometry>
      <material name="matte_cast_iron">
        <color rgba="0.006 0.006 0.005 1" />
        </material>
      </visual>
    <visual name="cross_bar_y">
      <origin xyz="0 0 0.02" rpy="0 0 0" />
      <geometry>
        <box size="0.02 0.215 0.016" />
        </geometry>
      <material name="matte_cast_iron">
        <color rgba="0.006 0.006 0.005 1" />
        </material>
      </visual>
    <visual name="cross_bar_x">
      <origin xyz="0 0 0.02" rpy="0 0 0" />
      <geometry>
        <box size="0.235 0.02 0.016" />
        </geometry>
      <material name="matte_cast_iron">
        <color rgba="0.006 0.006 0.005 1" />
        </material>
      </visual>
    <collision name="foot_0">
      <origin xyz="-0.0915 -0.0815 0.006" rpy="0 0 0" />
      <geometry>
        <box size="0.034 0.034 0.012" />
        </geometry>
      </collision>
    <collision name="foot_1">
      <origin xyz="0.0915 -0.0815 0.006" rpy="0 0 0" />
      <geometry>
        <box size="0.034 0.034 0.012" />
        </geometry>
      </collision>
    <collision name="foot_2">
      <origin xyz="-0.0915 0.0815 0.006" rpy="0 0 0" />
      <geometry>
        <box size="0.034 0.034 0.012" />
        </geometry>
      </collision>
    <collision name="foot_3">
      <origin xyz="0.0915 0.0815 0.006" rpy="0 0 0" />
      <geometry>
        <box size="0.034 0.034 0.012" />
        </geometry>
      </collision>
    <collision name="front_bar">
      <origin xyz="0 -0.1075 0.02" rpy="0 0 0" />
      <geometry>
        <box size="0.235 0.02 0.016" />
        </geometry>
      </collision>
    <collision name="rear_bar">
      <origin xyz="0 0.1075 0.02" rpy="0 0 0" />
      <geometry>
        <box size="0.235 0.02 0.016" />
        </geometry>
      </collision>
    <collision name="side_bar_0">
      <origin xyz="-0.1175 0 0.02" rpy="0 0 0" />
      <geometry>
        <box size="0.02 0.215 0.016" />
        </geometry>
      </collision>
    <collision name="side_bar_1">
      <origin xyz="0.1175 0 0.02" rpy="0 0 0" />
      <geometry>
        <box size="0.02 0.215 0.016" />
        </geometry>
      </collision>
    <collision name="cross_bar_y">
      <origin xyz="0 0 0.02" rpy="0 0 0" />
      <geometry>
        <box size="0.02 0.215 0.016" />
        </geometry>
      </collision>
    <collision name="cross_bar_x">
      <origin xyz="0 0 0.02" rpy="0 0 0" />
      <geometry>
        <box size="0.235 0.02 0.016" />
        </geometry>
      </collision>
    </link>
  <link name="grate_2">
    <visual name="foot_0">
      <origin xyz="-0.0915 -0.0815 0.006" rpy="0 0 0" />
      <geometry>
        <box size="0.034 0.034 0.012" />
        </geometry>
      <material name="matte_cast_iron">
        <color rgba="0.006 0.006 0.005 1" />
        </material>
      </visual>
    <visual name="foot_1">
      <origin xyz="0.0915 -0.0815 0.006" rpy="0 0 0" />
      <geometry>
        <box size="0.034 0.034 0.012" />
        </geometry>
      <material name="matte_cast_iron">
        <color rgba="0.006 0.006 0.005 1" />
        </material>
      </visual>
    <visual name="foot_2">
      <origin xyz="-0.0915 0.0815 0.006" rpy="0 0 0" />
      <geometry>
        <box size="0.034 0.034 0.012" />
        </geometry>
      <material name="matte_cast_iron">
        <color rgba="0.006 0.006 0.005 1" />
        </material>
      </visual>
    <visual name="foot_3">
      <origin xyz="0.0915 0.0815 0.006" rpy="0 0 0" />
      <geometry>
        <box size="0.034 0.034 0.012" />
        </geometry>
      <material name="matte_cast_iron">
        <color rgba="0.006 0.006 0.005 1" />
        </material>
      </visual>
    <visual name="front_bar">
      <origin xyz="0 -0.1075 0.02" rpy="0 0 0" />
      <geometry>
        <box size="0.235 0.02 0.016" />
        </geometry>
      <material name="matte_cast_iron">
        <color rgba="0.006 0.006 0.005 1" />
        </material>
      </visual>
    <visual name="rear_bar">
      <origin xyz="0 0.1075 0.02" rpy="0 0 0" />
      <geometry>
        <box size="0.235 0.02 0.016" />
        </geometry>
      <material name="matte_cast_iron">
        <color rgba="0.006 0.006 0.005 1" />
        </material>
      </visual>
    <visual name="side_bar_0">
      <origin xyz="-0.1175 0 0.02" rpy="0 0 0" />
      <geometry>
        <box size="0.02 0.215 0.016" />
        </geometry>
      <material name="matte_cast_iron">
        <color rgba="0.006 0.006 0.005 1" />
        </material>
      </visual>
    <visual name="side_bar_1">
      <origin xyz="0.1175 0 0.02" rpy="0 0 0" />
      <geometry>
        <box size="0.02 0.215 0.016" />
        </geometry>
      <material name="matte_cast_iron">
        <color rgba="0.006 0.006 0.005 1" />
        </material>
      </visual>
    <visual name="cross_bar_y">
      <origin xyz="0 0 0.02" rpy="0 0 0" />
      <geometry>
        <box size="0.02 0.215 0.016" />
        </geometry>
      <material name="matte_cast_iron">
        <color rgba="0.006 0.006 0.005 1" />
        </material>
      </visual>
    <visual name="cross_bar_x">
      <origin xyz="0 0 0.02" rpy="0 0 0" />
      <geometry>
        <box size="0.235 0.02 0.016" />
        </geometry>
      <material name="matte_cast_iron">
        <color rgba="0.006 0.006 0.005 1" />
        </material>
      </visual>
    <collision name="foot_0">
      <origin xyz="-0.0915 -0.0815 0.006" rpy="0 0 0" />
      <geometry>
        <box size="0.034 0.034 0.012" />
        </geometry>
      </collision>
    <collision name="foot_1">
      <origin xyz="0.0915 -0.0815 0.006" rpy="0 0 0" />
      <geometry>
        <box size="0.034 0.034 0.012" />
        </geometry>
      </collision>
    <collision name="foot_2">
      <origin xyz="-0.0915 0.0815 0.006" rpy="0 0 0" />
      <geometry>
        <box size="0.034 0.034 0.012" />
        </geometry>
      </collision>
    <collision name="foot_3">
      <origin xyz="0.0915 0.0815 0.006" rpy="0 0 0" />
      <geometry>
        <box size="0.034 0.034 0.012" />
        </geometry>
      </collision>
    <collision name="front_bar">
      <origin xyz="0 -0.1075 0.02" rpy="0 0 0" />
      <geometry>
        <box size="0.235 0.02 0.016" />
        </geometry>
      </collision>
    <collision name="rear_bar">
      <origin xyz="0 0.1075 0.02" rpy="0 0 0" />
      <geometry>
        <box size="0.235 0.02 0.016" />
        </geometry>
      </collision>
    <collision name="side_bar_0">
      <origin xyz="-0.1175 0 0.02" rpy="0 0 0" />
      <geometry>
        <box size="0.02 0.215 0.016" />
        </geometry>
      </collision>
    <collision name="side_bar_1">
      <origin xyz="0.1175 0 0.02" rpy="0 0 0" />
      <geometry>
        <box size="0.02 0.215 0.016" />
        </geometry>
      </collision>
    <collision name="cross_bar_y">
      <origin xyz="0 0 0.02" rpy="0 0 0" />
      <geometry>
        <box size="0.02 0.215 0.016" />
        </geometry>
      </collision>
    <collision name="cross_bar_x">
      <origin xyz="0 0 0.02" rpy="0 0 0" />
      <geometry>
        <box size="0.235 0.02 0.016" />
        </geometry>
      </collision>
    </link>
  <link name="grate_3">
    <visual name="foot_0">
      <origin xyz="-0.0915 -0.0815 0.006" rpy="0 0 0" />
      <geometry>
        <box size="0.034 0.034 0.012" />
        </geometry>
      <material name="matte_cast_iron">
        <color rgba="0.006 0.006 0.005 1" />
        </material>
      </visual>
    <visual name="foot_1">
      <origin xyz="0.0915 -0.0815 0.006" rpy="0 0 0" />
      <geometry>
        <box size="0.034 0.034 0.012" />
        </geometry>
      <material name="matte_cast_iron">
        <color rgba="0.006 0.006 0.005 1" />
        </material>
      </visual>
    <visual name="foot_2">
      <origin xyz="-0.0915 0.0815 0.006" rpy="0 0 0" />
      <geometry>
        <box size="0.034 0.034 0.012" />
        </geometry>
      <material name="matte_cast_iron">
        <color rgba="0.006 0.006 0.005 1" />
        </material>
      </visual>
    <visual name="foot_3">
      <origin xyz="0.0915 0.0815 0.006" rpy="0 0 0" />
      <geometry>
        <box size="0.034 0.034 0.012" />
        </geometry>
      <material name="matte_cast_iron">
        <color rgba="0.006 0.006 0.005 1" />
        </material>
      </visual>
    <visual name="front_bar">
      <origin xyz="0 -0.1075 0.02" rpy="0 0 0" />
      <geometry>
        <box size="0.235 0.02 0.016" />
        </geometry>
      <material name="matte_cast_iron">
        <color rgba="0.006 0.006 0.005 1" />
        </material>
      </visual>
    <visual name="rear_bar">
      <origin xyz="0 0.1075 0.02" rpy="0 0 0" />
      <geometry>
        <box size="0.235 0.02 0.016" />
        </geometry>
      <material name="matte_cast_iron">
        <color rgba="0.006 0.006 0.005 1" />
        </material>
      </visual>
    <visual name="side_bar_0">
      <origin xyz="-0.1175 0 0.02" rpy="0 0 0" />
      <geometry>
        <box size="0.02 0.215 0.016" />
        </geometry>
      <material name="matte_cast_iron">
        <color rgba="0.006 0.006 0.005 1" />
        </material>
      </visual>
    <visual name="side_bar_1">
      <origin xyz="0.1175 0 0.02" rpy="0 0 0" />
      <geometry>
        <box size="0.02 0.215 0.016" />
        </geometry>
      <material name="matte_cast_iron">
        <color rgba="0.006 0.006 0.005 1" />
        </material>
      </visual>
    <visual name="cross_bar_y">
      <origin xyz="0 0 0.02" rpy="0 0 0" />
      <geometry>
        <box size="0.02 0.215 0.016" />
        </geometry>
      <material name="matte_cast_iron">
        <color rgba="0.006 0.006 0.005 1" />
        </material>
      </visual>
    <visual name="cross_bar_x">
      <origin xyz="0 0 0.02" rpy="0 0 0" />
      <geometry>
        <box size="0.235 0.02 0.016" />
        </geometry>
      <material name="matte_cast_iron">
        <color rgba="0.006 0.006 0.005 1" />
        </material>
      </visual>
    <collision name="foot_0">
      <origin xyz="-0.0915 -0.0815 0.006" rpy="0 0 0" />
      <geometry>
        <box size="0.034 0.034 0.012" />
        </geometry>
      </collision>
    <collision name="foot_1">
      <origin xyz="0.0915 -0.0815 0.006" rpy="0 0 0" />
      <geometry>
        <box size="0.034 0.034 0.012" />
        </geometry>
      </collision>
    <collision name="foot_2">
      <origin xyz="-0.0915 0.0815 0.006" rpy="0 0 0" />
      <geometry>
        <box size="0.034 0.034 0.012" />
        </geometry>
      </collision>
    <collision name="foot_3">
      <origin xyz="0.0915 0.0815 0.006" rpy="0 0 0" />
      <geometry>
        <box size="0.034 0.034 0.012" />
        </geometry>
      </collision>
    <collision name="front_bar">
      <origin xyz="0 -0.1075 0.02" rpy="0 0 0" />
      <geometry>
        <box size="0.235 0.02 0.016" />
        </geometry>
      </collision>
    <collision name="rear_bar">
      <origin xyz="0 0.1075 0.02" rpy="0 0 0" />
      <geometry>
        <box size="0.235 0.02 0.016" />
        </geometry>
      </collision>
    <collision name="side_bar_0">
      <origin xyz="-0.1175 0 0.02" rpy="0 0 0" />
      <geometry>
        <box size="0.02 0.215 0.016" />
        </geometry>
      </collision>
    <collision name="side_bar_1">
      <origin xyz="0.1175 0 0.02" rpy="0 0 0" />
      <geometry>
        <box size="0.02 0.215 0.016" />
        </geometry>
      </collision>
    <collision name="cross_bar_y">
      <origin xyz="0 0 0.02" rpy="0 0 0" />
      <geometry>
        <box size="0.02 0.215 0.016" />
        </geometry>
      </collision>
    <collision name="cross_bar_x">
      <origin xyz="0 0 0.02" rpy="0 0 0" />
      <geometry>
        <box size="0.235 0.02 0.016" />
        </geometry>
      </collision>
    </link>
  <link name="grate_4">
    <visual name="foot_0">
      <origin xyz="-0.0915 -0.0815 0.006" rpy="0 0 0" />
      <geometry>
        <box size="0.034 0.034 0.012" />
        </geometry>
      <material name="matte_cast_iron">
        <color rgba="0.006 0.006 0.005 1" />
        </material>
      </visual>
    <visual name="foot_1">
      <origin xyz="0.0915 -0.0815 0.006" rpy="0 0 0" />
      <geometry>
        <box size="0.034 0.034 0.012" />
        </geometry>
      <material name="matte_cast_iron">
        <color rgba="0.006 0.006 0.005 1" />
        </material>
      </visual>
    <visual name="foot_2">
      <origin xyz="-0.0915 0.0815 0.006" rpy="0 0 0" />
      <geometry>
        <box size="0.034 0.034 0.012" />
        </geometry>
      <material name="matte_cast_iron">
        <color rgba="0.006 0.006 0.005 1" />
        </material>
      </visual>
    <visual name="foot_3">
      <origin xyz="0.0915 0.0815 0.006" rpy="0 0 0" />
      <geometry>
        <box size="0.034 0.034 0.012" />
        </geometry>
      <material name="matte_cast_iron">
        <color rgba="0.006 0.006 0.005 1" />
        </material>
      </visual>
    <visual name="front_bar">
      <origin xyz="0 -0.1075 0.02" rpy="0 0 0" />
      <geometry>
        <box size="0.235 0.02 0.016" />
        </geometry>
      <material name="matte_cast_iron">
        <color rgba="0.006 0.006 0.005 1" />
        </material>
      </visual>
    <visual name="rear_bar">
      <origin xyz="0 0.1075 0.02" rpy="0 0 0" />
      <geometry>
        <box size="0.235 0.02 0.016" />
        </geometry>
      <material name="matte_cast_iron">
        <color rgba="0.006 0.006 0.005 1" />
        </material>
      </visual>
    <visual name="side_bar_0">
      <origin xyz="-0.1175 0 0.02" rpy="0 0 0" />
      <geometry>
        <box size="0.02 0.215 0.016" />
        </geometry>
      <material name="matte_cast_iron">
        <color rgba="0.006 0.006 0.005 1" />
        </material>
      </visual>
    <visual name="side_bar_1">
      <origin xyz="0.1175 0 0.02" rpy="0 0 0" />
      <geometry>
        <box size="0.02 0.215 0.016" />
        </geometry>
      <material name="matte_cast_iron">
        <color rgba="0.006 0.006 0.005 1" />
        </material>
      </visual>
    <visual name="cross_bar_y">
      <origin xyz="0 0 0.02" rpy="0 0 0" />
      <geometry>
        <box size="0.02 0.215 0.016" />
        </geometry>
      <material name="matte_cast_iron">
        <color rgba="0.006 0.006 0.005 1" />
        </material>
      </visual>
    <visual name="cross_bar_x">
      <origin xyz="0 0 0.02" rpy="0 0 0" />
      <geometry>
        <box size="0.235 0.02 0.016" />
        </geometry>
      <material name="matte_cast_iron">
        <color rgba="0.006 0.006 0.005 1" />
        </material>
      </visual>
    <collision name="foot_0">
      <origin xyz="-0.0915 -0.0815 0.006" rpy="0 0 0" />
      <geometry>
        <box size="0.034 0.034 0.012" />
        </geometry>
      </collision>
    <collision name="foot_1">
      <origin xyz="0.0915 -0.0815 0.006" rpy="0 0 0" />
      <geometry>
        <box size="0.034 0.034 0.012" />
        </geometry>
      </collision>
    <collision name="foot_2">
      <origin xyz="-0.0915 0.0815 0.006" rpy="0 0 0" />
      <geometry>
        <box size="0.034 0.034 0.012" />
        </geometry>
      </collision>
    <collision name="foot_3">
      <origin xyz="0.0915 0.0815 0.006" rpy="0 0 0" />
      <geometry>
        <box size="0.034 0.034 0.012" />
        </geometry>
      </collision>
    <collision name="front_bar">
      <origin xyz="0 -0.1075 0.02" rpy="0 0 0" />
      <geometry>
        <box size="0.235 0.02 0.016" />
        </geometry>
      </collision>
    <collision name="rear_bar">
      <origin xyz="0 0.1075 0.02" rpy="0 0 0" />
      <geometry>
        <box size="0.235 0.02 0.016" />
        </geometry>
      </collision>
    <collision name="side_bar_0">
      <origin xyz="-0.1175 0 0.02" rpy="0 0 0" />
      <geometry>
        <box size="0.02 0.215 0.016" />
        </geometry>
      </collision>
    <collision name="side_bar_1">
      <origin xyz="0.1175 0 0.02" rpy="0 0 0" />
      <geometry>
        <box size="0.02 0.215 0.016" />
        </geometry>
      </collision>
    <collision name="cross_bar_y">
      <origin xyz="0 0 0.02" rpy="0 0 0" />
      <geometry>
        <box size="0.02 0.215 0.016" />
        </geometry>
      </collision>
    <collision name="cross_bar_x">
      <origin xyz="0 0 0.02" rpy="0 0 0" />
      <geometry>
        <box size="0.235 0.02 0.016" />
        </geometry>
      </collision>
    </link>
  <link name="grate_5">
    <visual name="foot_0">
      <origin xyz="-0.0915 -0.0815 0.006" rpy="0 0 0" />
      <geometry>
        <box size="0.034 0.034 0.012" />
        </geometry>
      <material name="matte_cast_iron">
        <color rgba="0.006 0.006 0.005 1" />
        </material>
      </visual>
    <visual name="foot_1">
      <origin xyz="0.0915 -0.0815 0.006" rpy="0 0 0" />
      <geometry>
        <box size="0.034 0.034 0.012" />
        </geometry>
      <material name="matte_cast_iron">
        <color rgba="0.006 0.006 0.005 1" />
        </material>
      </visual>
    <visual name="foot_2">
      <origin xyz="-0.0915 0.0815 0.006" rpy="0 0 0" />
      <geometry>
        <box size="0.034 0.034 0.012" />
        </geometry>
      <material name="matte_cast_iron">
        <color rgba="0.006 0.006 0.005 1" />
        </material>
      </visual>
    <visual name="foot_3">
      <origin xyz="0.0915 0.0815 0.006" rpy="0 0 0" />
      <geometry>
        <box size="0.034 0.034 0.012" />
        </geometry>
      <material name="matte_cast_iron">
        <color rgba="0.006 0.006 0.005 1" />
        </material>
      </visual>
    <visual name="front_bar">
      <origin xyz="0 -0.1075 0.02" rpy="0 0 0" />
      <geometry>
        <box size="0.235 0.02 0.016" />
        </geometry>
      <material name="matte_cast_iron">
        <color rgba="0.006 0.006 0.005 1" />
        </material>
      </visual>
    <visual name="rear_bar">
      <origin xyz="0 0.1075 0.02" rpy="0 0 0" />
      <geometry>
        <box size="0.235 0.02 0.016" />
        </geometry>
      <material name="matte_cast_iron">
        <color rgba="0.006 0.006 0.005 1" />
        </material>
      </visual>
    <visual name="side_bar_0">
      <origin xyz="-0.1175 0 0.02" rpy="0 0 0" />
      <geometry>
        <box size="0.02 0.215 0.016" />
        </geometry>
      <material name="matte_cast_iron">
        <color rgba="0.006 0.006 0.005 1" />
        </material>
      </visual>
    <visual name="side_bar_1">
      <origin xyz="0.1175 0 0.02" rpy="0 0 0" />
      <geometry>
        <box size="0.02 0.215 0.016" />
        </geometry>
      <material name="matte_cast_iron">
        <color rgba="0.006 0.006 0.005 1" />
        </material>
      </visual>
    <visual name="cross_bar_y">
      <origin xyz="0 0 0.02" rpy="0 0 0" />
      <geometry>
        <box size="0.02 0.215 0.016" />
        </geometry>
      <material name="matte_cast_iron">
        <color rgba="0.006 0.006 0.005 1" />
        </material>
      </visual>
    <visual name="cross_bar_x">
      <origin xyz="0 0 0.02" rpy="0 0 0" />
      <geometry>
        <box size="0.235 0.02 0.016" />
        </geometry>
      <material name="matte_cast_iron">
        <color rgba="0.006 0.006 0.005 1" />
        </material>
      </visual>
    <collision name="foot_0">
      <origin xyz="-0.0915 -0.0815 0.006" rpy="0 0 0" />
      <geometry>
        <box size="0.034 0.034 0.012" />
        </geometry>
      </collision>
    <collision name="foot_1">
      <origin xyz="0.0915 -0.0815 0.006" rpy="0 0 0" />
      <geometry>
        <box size="0.034 0.034 0.012" />
        </geometry>
      </collision>
    <collision name="foot_2">
      <origin xyz="-0.0915 0.0815 0.006" rpy="0 0 0" />
      <geometry>
        <box size="0.034 0.034 0.012" />
        </geometry>
      </collision>
    <collision name="foot_3">
      <origin xyz="0.0915 0.0815 0.006" rpy="0 0 0" />
      <geometry>
        <box size="0.034 0.034 0.012" />
        </geometry>
      </collision>
    <collision name="front_bar">
      <origin xyz="0 -0.1075 0.02" rpy="0 0 0" />
      <geometry>
        <box size="0.235 0.02 0.016" />
        </geometry>
      </collision>
    <collision name="rear_bar">
      <origin xyz="0 0.1075 0.02" rpy="0 0 0" />
      <geometry>
        <box size="0.235 0.02 0.016" />
        </geometry>
      </collision>
    <collision name="side_bar_0">
      <origin xyz="-0.1175 0 0.02" rpy="0 0 0" />
      <geometry>
        <box size="0.02 0.215 0.016" />
        </geometry>
      </collision>
    <collision name="side_bar_1">
      <origin xyz="0.1175 0 0.02" rpy="0 0 0" />
      <geometry>
        <box size="0.02 0.215 0.016" />
        </geometry>
      </collision>
    <collision name="cross_bar_y">
      <origin xyz="0 0 0.02" rpy="0 0 0" />
      <geometry>
        <box size="0.02 0.215 0.016" />
        </geometry>
      </collision>
    <collision name="cross_bar_x">
      <origin xyz="0 0 0.02" rpy="0 0 0" />
      <geometry>
        <box size="0.235 0.02 0.016" />
        </geometry>
      </collision>
    </link>
  <link name="lower_door">
    <visual name="door_panel">
      <origin xyz="0 -0.02 0.15" rpy="0 0 0" />
      <geometry>
        <box size="0.8 0.04 0.3" />
        </geometry>
      <material name="brushed_stainless">
        <color rgba="0.62 0.62 0.58 1" />
        </material>
      </visual>
    <visual name="glass_window">
      <origin xyz="0 -0.0425 0.159" rpy="0 0 0" />
      <geometry>
        <box size="0.58 0.006 0.15" />
        </geometry>
      <material name="smoky_oven_glass">
        <color rgba="0.03 0.045 0.055 0.72" />
        </material>
      </visual>
    <visual name="handle_bar">
      <origin xyz="0 -0.078 0.242" rpy="0 1.5708 0" />
      <geometry>
        <cylinder radius="0.012" length="0.62" />
        </geometry>
      <material name="polished_handle">
        <color rgba="0.78 0.76 0.7 1" />
        </material>
      </visual>
    <visual name="handle_post_0">
      <origin xyz="-0.27 -0.061 0.242" rpy="1.5708 0 0" />
      <geometry>
        <cylinder radius="0.008" length="0.048" />
        </geometry>
      <material name="polished_handle">
        <color rgba="0.78 0.76 0.7 1" />
        </material>
      </visual>
    <visual name="handle_post_1">
      <origin xyz="0.27 -0.061 0.242" rpy="1.5708 0 0" />
      <geometry>
        <cylinder radius="0.008" length="0.048" />
        </geometry>
      <material name="polished_handle">
        <color rgba="0.78 0.76 0.7 1" />
        </material>
      </visual>
    <collision name="door_panel">
      <origin xyz="0 -0.02 0.15" rpy="0 0 0" />
      <geometry>
        <box size="0.8 0.04 0.3" />
        </geometry>
      </collision>
    <collision name="glass_window">
      <origin xyz="0 -0.0425 0.159" rpy="0 0 0" />
      <geometry>
        <box size="0.58 0.006 0.15" />
        </geometry>
      </collision>
    <collision name="handle_bar">
      <origin xyz="0 -0.078 0.242" rpy="0 1.5708 0" />
      <geometry>
        <cylinder radius="0.012" length="0.62" />
        </geometry>
      </collision>
    <collision name="handle_post_0">
      <origin xyz="-0.27 -0.061 0.242" rpy="1.5708 0 0" />
      <geometry>
        <cylinder radius="0.008" length="0.048" />
        </geometry>
      </collision>
    <collision name="handle_post_1">
      <origin xyz="0.27 -0.061 0.242" rpy="1.5708 0 0" />
      <geometry>
        <cylinder radius="0.008" length="0.048" />
        </geometry>
      </collision>
    </link>
  <link name="upper_door">
    <visual name="door_panel">
      <origin xyz="0 -0.02 0.145" rpy="0 0 0" />
      <geometry>
        <box size="0.8 0.04 0.29" />
        </geometry>
      <material name="brushed_stainless">
        <color rgba="0.62 0.62 0.58 1" />
        </material>
      </visual>
    <visual name="glass_window">
      <origin xyz="0 -0.0425 0.1537" rpy="0 0 0" />
      <geometry>
        <box size="0.58 0.006 0.14" />
        </geometry>
      <material name="smoky_oven_glass">
        <color rgba="0.03 0.045 0.055 0.72" />
        </material>
      </visual>
    <visual name="handle_bar">
      <origin xyz="0 -0.078 0.232" rpy="0 1.5708 0" />
      <geometry>
        <cylinder radius="0.012" length="0.62" />
        </geometry>
      <material name="polished_handle">
        <color rgba="0.78 0.76 0.7 1" />
        </material>
      </visual>
    <visual name="handle_post_0">
      <origin xyz="-0.27 -0.061 0.232" rpy="1.5708 0 0" />
      <geometry>
        <cylinder radius="0.008" length="0.048" />
        </geometry>
      <material name="polished_handle">
        <color rgba="0.78 0.76 0.7 1" />
        </material>
      </visual>
    <visual name="handle_post_1">
      <origin xyz="0.27 -0.061 0.232" rpy="1.5708 0 0" />
      <geometry>
        <cylinder radius="0.008" length="0.048" />
        </geometry>
      <material name="polished_handle">
        <color rgba="0.78 0.76 0.7 1" />
        </material>
      </visual>
    <collision name="door_panel">
      <origin xyz="0 -0.02 0.145" rpy="0 0 0" />
      <geometry>
        <box size="0.8 0.04 0.29" />
        </geometry>
      </collision>
    <collision name="glass_window">
      <origin xyz="0 -0.0425 0.1537" rpy="0 0 0" />
      <geometry>
        <box size="0.58 0.006 0.14" />
        </geometry>
      </collision>
    <collision name="handle_bar">
      <origin xyz="0 -0.078 0.232" rpy="0 1.5708 0" />
      <geometry>
        <cylinder radius="0.012" length="0.62" />
        </geometry>
      </collision>
    <collision name="handle_post_0">
      <origin xyz="-0.27 -0.061 0.232" rpy="1.5708 0 0" />
      <geometry>
        <cylinder radius="0.008" length="0.048" />
        </geometry>
      </collision>
    <collision name="handle_post_1">
      <origin xyz="0.27 -0.061 0.232" rpy="1.5708 0 0" />
      <geometry>
        <cylinder radius="0.008" length="0.048" />
        </geometry>
      </collision>
    </link>
  <link name="knob_0">
    <visual name="knob_cap">
      <origin xyz="0 -0.017 0" rpy="1.5708 0 0" />
      <geometry>
        <cylinder radius="0.02" length="0.034" />
        </geometry>
      <material name="polished_handle">
        <color rgba="0.78 0.76 0.7 1" />
        </material>
      </visual>
    <visual name="indicator_line">
      <origin xyz="0 -0.036 0.0032" rpy="0 0 0" />
      <geometry>
        <box size="0.004 0.005 0.027" />
        </geometry>
      <material name="white_indicator">
        <color rgba="0.92 0.9 0.82 1" />
        </material>
      </visual>
    <collision name="knob_cap">
      <origin xyz="0 -0.017 0" rpy="1.5708 0 0" />
      <geometry>
        <cylinder radius="0.02" length="0.034" />
        </geometry>
      </collision>
    <collision name="indicator_line">
      <origin xyz="0 -0.036 0.0032" rpy="0 0 0" />
      <geometry>
        <box size="0.004 0.005 0.027" />
        </geometry>
      </collision>
    </link>
  <link name="knob_1">
    <visual name="knob_cap">
      <origin xyz="0 -0.017 0" rpy="1.5708 0 0" />
      <geometry>
        <cylinder radius="0.02" length="0.034" />
        </geometry>
      <material name="polished_handle">
        <color rgba="0.78 0.76 0.7 1" />
        </material>
      </visual>
    <visual name="indicator_line">
      <origin xyz="0 -0.036 0.0032" rpy="0 0 0" />
      <geometry>
        <box size="0.004 0.005 0.027" />
        </geometry>
      <material name="white_indicator">
        <color rgba="0.92 0.9 0.82 1" />
        </material>
      </visual>
    <collision name="knob_cap">
      <origin xyz="0 -0.017 0" rpy="1.5708 0 0" />
      <geometry>
        <cylinder radius="0.02" length="0.034" />
        </geometry>
      </collision>
    <collision name="indicator_line">
      <origin xyz="0 -0.036 0.0032" rpy="0 0 0" />
      <geometry>
        <box size="0.004 0.005 0.027" />
        </geometry>
      </collision>
    </link>
  <link name="knob_2">
    <visual name="knob_cap">
      <origin xyz="0 -0.017 0" rpy="1.5708 0 0" />
      <geometry>
        <cylinder radius="0.02" length="0.034" />
        </geometry>
      <material name="polished_handle">
        <color rgba="0.78 0.76 0.7 1" />
        </material>
      </visual>
    <visual name="indicator_line">
      <origin xyz="0 -0.036 0.0032" rpy="0 0 0" />
      <geometry>
        <box size="0.004 0.005 0.027" />
        </geometry>
      <material name="white_indicator">
        <color rgba="0.92 0.9 0.82 1" />
        </material>
      </visual>
    <collision name="knob_cap">
      <origin xyz="0 -0.017 0" rpy="1.5708 0 0" />
      <geometry>
        <cylinder radius="0.02" length="0.034" />
        </geometry>
      </collision>
    <collision name="indicator_line">
      <origin xyz="0 -0.036 0.0032" rpy="0 0 0" />
      <geometry>
        <box size="0.004 0.005 0.027" />
        </geometry>
      </collision>
    </link>
  <link name="knob_3">
    <visual name="knob_cap">
      <origin xyz="0 -0.017 0" rpy="1.5708 0 0" />
      <geometry>
        <cylinder radius="0.02" length="0.034" />
        </geometry>
      <material name="polished_handle">
        <color rgba="0.78 0.76 0.7 1" />
        </material>
      </visual>
    <visual name="indicator_line">
      <origin xyz="0 -0.036 0.0032" rpy="0 0 0" />
      <geometry>
        <box size="0.004 0.005 0.027" />
        </geometry>
      <material name="white_indicator">
        <color rgba="0.92 0.9 0.82 1" />
        </material>
      </visual>
    <collision name="knob_cap">
      <origin xyz="0 -0.017 0" rpy="1.5708 0 0" />
      <geometry>
        <cylinder radius="0.02" length="0.034" />
        </geometry>
      </collision>
    <collision name="indicator_line">
      <origin xyz="0 -0.036 0.0032" rpy="0 0 0" />
      <geometry>
        <box size="0.004 0.005 0.027" />
        </geometry>
      </collision>
    </link>
  <link name="knob_4">
    <visual name="knob_cap">
      <origin xyz="0 -0.017 0" rpy="1.5708 0 0" />
      <geometry>
        <cylinder radius="0.02" length="0.034" />
        </geometry>
      <material name="polished_handle">
        <color rgba="0.78 0.76 0.7 1" />
        </material>
      </visual>
    <visual name="indicator_line">
      <origin xyz="0 -0.036 0.0032" rpy="0 0 0" />
      <geometry>
        <box size="0.004 0.005 0.027" />
        </geometry>
      <material name="white_indicator">
        <color rgba="0.92 0.9 0.82 1" />
        </material>
      </visual>
    <collision name="knob_cap">
      <origin xyz="0 -0.017 0" rpy="1.5708 0 0" />
      <geometry>
        <cylinder radius="0.02" length="0.034" />
        </geometry>
      </collision>
    <collision name="indicator_line">
      <origin xyz="0 -0.036 0.0032" rpy="0 0 0" />
      <geometry>
        <box size="0.004 0.005 0.027" />
        </geometry>
      </collision>
    </link>
  <link name="knob_5">
    <visual name="knob_cap">
      <origin xyz="0 -0.017 0" rpy="1.5708 0 0" />
      <geometry>
        <cylinder radius="0.02" length="0.034" />
        </geometry>
      <material name="polished_handle">
        <color rgba="0.78 0.76 0.7 1" />
        </material>
      </visual>
    <visual name="indicator_line">
      <origin xyz="0 -0.036 0.0032" rpy="0 0 0" />
      <geometry>
        <box size="0.004 0.005 0.027" />
        </geometry>
      <material name="white_indicator">
        <color rgba="0.92 0.9 0.82 1" />
        </material>
      </visual>
    <collision name="knob_cap">
      <origin xyz="0 -0.017 0" rpy="1.5708 0 0" />
      <geometry>
        <cylinder radius="0.02" length="0.034" />
        </geometry>
      </collision>
    <collision name="indicator_line">
      <origin xyz="0 -0.036 0.0032" rpy="0 0 0" />
      <geometry>
        <box size="0.004 0.005 0.027" />
        </geometry>
      </collision>
    </link>
  <link name="knob_6">
    <visual name="knob_cap">
      <origin xyz="0 -0.017 0" rpy="1.5708 0 0" />
      <geometry>
        <cylinder radius="0.022" length="0.034" />
        </geometry>
      <material name="polished_handle">
        <color rgba="0.78 0.76 0.7 1" />
        </material>
      </visual>
    <visual name="indicator_line">
      <origin xyz="0 -0.036 0.00352" rpy="0 0 0" />
      <geometry>
        <box size="0.004 0.005 0.0297" />
        </geometry>
      <material name="white_indicator">
        <color rgba="0.92 0.9 0.82 1" />
        </material>
      </visual>
    <collision name="knob_cap">
      <origin xyz="0 -0.017 0" rpy="1.5708 0 0" />
      <geometry>
        <cylinder radius="0.022" length="0.034" />
        </geometry>
      </collision>
    <collision name="indicator_line">
      <origin xyz="0 -0.036 0.00352" rpy="0 0 0" />
      <geometry>
        <box size="0.004 0.005 0.0297" />
        </geometry>
      </collision>
    </link>
  <link name="knob_7">
    <visual name="knob_cap">
      <origin xyz="0 -0.017 0" rpy="1.5708 0 0" />
      <geometry>
        <cylinder radius="0.022" length="0.034" />
        </geometry>
      <material name="polished_handle">
        <color rgba="0.78 0.76 0.7 1" />
        </material>
      </visual>
    <visual name="indicator_line">
      <origin xyz="0 -0.036 0.00352" rpy="0 0 0" />
      <geometry>
        <box size="0.004 0.005 0.0297" />
        </geometry>
      <material name="white_indicator">
        <color rgba="0.92 0.9 0.82 1" />
        </material>
      </visual>
    <collision name="knob_cap">
      <origin xyz="0 -0.017 0" rpy="1.5708 0 0" />
      <geometry>
        <cylinder radius="0.022" length="0.034" />
        </geometry>
      </collision>
    <collision name="indicator_line">
      <origin xyz="0 -0.036 0.00352" rpy="0 0 0" />
      <geometry>
        <box size="0.004 0.005 0.0297" />
        </geometry>
      </collision>
    </link>
  <joint name="body_to_grate_0" type="fixed">
    <origin xyz="-0.31 -0.16 0.92" rpy="0 0 0" />
    <parent link="body" />
    <child link="grate_0" />
    </joint>
  <joint name="body_to_grate_1" type="fixed">
    <origin xyz="0 -0.16 0.92" rpy="0 0 0" />
    <parent link="body" />
    <child link="grate_1" />
    </joint>
  <joint name="body_to_grate_2" type="fixed">
    <origin xyz="0.31 -0.16 0.92" rpy="0 0 0" />
    <parent link="body" />
    <child link="grate_2" />
    </joint>
  <joint name="body_to_grate_3" type="fixed">
    <origin xyz="-0.31 0.15 0.92" rpy="0 0 0" />
    <parent link="body" />
    <child link="grate_3" />
    </joint>
  <joint name="body_to_grate_4" type="fixed">
    <origin xyz="0 0.15 0.92" rpy="0 0 0" />
    <parent link="body" />
    <child link="grate_4" />
    </joint>
  <joint name="body_to_grate_5" type="fixed">
    <origin xyz="0.31 0.15 0.92" rpy="0 0 0" />
    <parent link="body" />
    <child link="grate_5" />
    </joint>
  <joint name="body_to_lower_door" type="revolute">
    <origin xyz="0 -0.365 0.1" rpy="0 0 0" />
    <parent link="body" />
    <child link="lower_door" />
    <axis xyz="1 0 0" />
    <limit effort="45" velocity="1" lower="0" upper="1.45" />
    </joint>
  <joint name="body_to_upper_door" type="revolute">
    <origin xyz="0 -0.365 0.43" rpy="0 0 0" />
    <parent link="body" />
    <child link="upper_door" />
    <axis xyz="1 0 0" />
    <limit effort="45" velocity="1" lower="0" upper="1.45" />
    </joint>
  <joint name="body_to_knob_0" type="revolute">
    <origin xyz="-0.36 -0.365 0.795" rpy="0 0 0" />
    <parent link="body" />
    <child link="knob_0" />
    <axis xyz="0 -1 0" />
    <limit effort="1" velocity="3" lower="-2.35" upper="2.35" />
    </joint>
  <joint name="body_to_knob_1" type="revolute">
    <origin xyz="-0.255 -0.365 0.795" rpy="0 0 0" />
    <parent link="body" />
    <child link="knob_1" />
    <axis xyz="0 -1 0" />
    <limit effort="1" velocity="3" lower="-2.35" upper="2.35" />
    </joint>
  <joint name="body_to_knob_2" type="revolute">
    <origin xyz="-0.15 -0.365 0.795" rpy="0 0 0" />
    <parent link="body" />
    <child link="knob_2" />
    <axis xyz="0 -1 0" />
    <limit effort="1" velocity="3" lower="-2.35" upper="2.35" />
    </joint>
  <joint name="body_to_knob_3" type="revolute">
    <origin xyz="-0.045 -0.365 0.795" rpy="0 0 0" />
    <parent link="body" />
    <child link="knob_3" />
    <axis xyz="0 -1 0" />
    <limit effort="1" velocity="3" lower="-2.35" upper="2.35" />
    </joint>
  <joint name="body_to_knob_4" type="revolute">
    <origin xyz="0.085 -0.365 0.795" rpy="0 0 0" />
    <parent link="body" />
    <child link="knob_4" />
    <axis xyz="0 -1 0" />
    <limit effort="1" velocity="3" lower="-2.35" upper="2.35" />
    </joint>
  <joint name="body_to_knob_5" type="revolute">
    <origin xyz="0.195 -0.365 0.795" rpy="0 0 0" />
    <parent link="body" />
    <child link="knob_5" />
    <axis xyz="0 -1 0" />
    <limit effort="1" velocity="3" lower="-2.35" upper="2.35" />
    </joint>
  <joint name="body_to_knob_6" type="revolute">
    <origin xyz="0.305 -0.365 0.795" rpy="0 0 0" />
    <parent link="body" />
    <child link="knob_6" />
    <axis xyz="0 -1 0" />
    <limit effort="1" velocity="3" lower="-2.35" upper="2.35" />
    </joint>
  <joint name="body_to_knob_7" type="revolute">
    <origin xyz="0.405 -0.365 0.795" rpy="0 0 0" />
    <parent link="body" />
    <child link="knob_7" />
    <axis xyz="0 -1 0" />
    <limit effort="1" velocity="3" lower="-2.35" upper="2.35" />
    </joint>
  </robot>
