<robot name="civil_war_field_cannon">
  <material name="weathered_oak">
    <color rgba="0.48 0.3 0.16 1" />
    </material>
  <material name="end_grain">
    <color rgba="0.38 0.22 0.12 1" />
    </material>
  <material name="cast_iron">
    <color rgba="0.05 0.052 0.048 1" />
    </material>
  <material name="worn_iron">
    <color rgba="0.12 0.12 0.115 1" />
    </material>
  <material name="brass_fittings">
    <color rgba="0.72 0.54 0.24 1" />
    </material>
  <link name="carriage">
    <inertial>
      <origin xyz="0 -0.3 0.45" rpy="0 0 0" />
      <mass value="430" />
      <inertia ixx="168.596" ixy="0" ixz="0" iyy="118.429" iyz="0" izz="222.346" />
      </inertial>
    <visual name="axle">
      <origin xyz="0 -0.15 0.46" rpy="0 1.5708 0" />
      <geometry>
        <cylinder radius="0.055" length="1.28" />
        </geometry>
      <material name="weathered_oak">
        <color rgba="0.48 0.3 0.16 1" />
        </material>
      </visual>
    <visual name="axle_iron_skin">
      <origin xyz="0 -0.15 0.46" rpy="0 1.5708 0" />
      <geometry>
        <cylinder radius="0.065" length="1.12" />
        </geometry>
      <material name="worn_iron">
        <color rgba="0.12 0.12 0.115 1" />
        </material>
      </visual>
    <visual name="cheek_0">
      <origin xyz="0.285 0.015 0.65" rpy="0 0 -0.025" />
      <geometry>
        <box size="0.105 0.86 0.185" />
        </geometry>
      <material name="weathered_oak">
        <color rgba="0.48 0.3 0.16 1" />
        </material>
      </visual>
    <visual name="bearing_block_0">
      <origin xyz="0.285 0.18 0.69" rpy="0 0 0" />
      <geometry>
        <box size="0.115 0.27 0.15" />
        </geometry>
      <material name="end_grain">
        <color rgba="0.38 0.22 0.12 1" />
        </material>
      </visual>
    <visual name="trunnion_cap_0">
      <origin xyz="0.285 0.18 0.93" rpy="0 0 0" />
      <geometry>
        <box size="0.12 0.3 0.03" />
        </geometry>
      <material name="worn_iron">
        <color rgba="0.12 0.12 0.115 1" />
        </material>
      </visual>
    <visual name="front_iron_strap_0">
      <origin xyz="0.285 0.064 0.82" rpy="0 0 0" />
      <geometry>
        <box size="0.122 0.03 0.25" />
        </geometry>
      <material name="worn_iron">
        <color rgba="0.12 0.12 0.115 1" />
        </material>
      </visual>
    <visual name="rear_iron_strap_0">
      <origin xyz="0.285 0.296 0.82" rpy="0 0 0" />
      <geometry>
        <box size="0.122 0.03 0.25" />
        </geometry>
      <material name="worn_iron">
        <color rgba="0.12 0.12 0.115 1" />
        </material>
      </visual>
    <visual name="cheek_1">
      <origin xyz="-0.285 0.015 0.65" rpy="0 0 0.025" />
      <geometry>
        <box size="0.105 0.86 0.185" />
        </geometry>
      <material name="weathered_oak">
        <color rgba="0.48 0.3 0.16 1" />
        </material>
      </visual>
    <visual name="bearing_block_1">
      <origin xyz="-0.285 0.18 0.69" rpy="0 0 0" />
      <geometry>
        <box size="0.115 0.27 0.15" />
        </geometry>
      <material name="end_grain">
        <color rgba="0.38 0.22 0.12 1" />
        </material>
      </visual>
    <visual name="trunnion_cap_1">
      <origin xyz="-0.285 0.18 0.93" rpy="0 0 0" />
      <geometry>
        <box size="0.12 0.3 0.03" />
        </geometry>
      <material name="worn_iron">
        <color rgba="0.12 0.12 0.115 1" />
        </material>
      </visual>
    <visual name="front_iron_strap_1">
      <origin xyz="-0.285 0.064 0.82" rpy="0 0 0" />
      <geometry>
        <box size="0.122 0.03 0.25" />
        </geometry>
      <material name="worn_iron">
        <color rgba="0.12 0.12 0.115 1" />
        </material>
      </visual>
    <visual name="rear_iron_strap_1">
      <origin xyz="-0.285 0.296 0.82" rpy="0 0 0" />
      <geometry>
        <box size="0.122 0.03 0.25" />
        </geometry>
      <material name="worn_iron">
        <color rgba="0.12 0.12 0.115 1" />
        </material>
      </visual>
    <visual name="trail_beam_0">
      <geometry>
        <mesh filename="assets/meshes/trail_beam_0.obj" />
        </geometry>
      <material name="weathered_oak">
        <color rgba="0.48 0.3 0.16 1" />
        </material>
      </visual>
    <visual name="trail_beam_1">
      <geometry>
        <mesh filename="assets/meshes/trail_beam_1.obj" />
        </geometry>
      <material name="weathered_oak">
        <color rgba="0.48 0.3 0.16 1" />
        </material>
      </visual>
    <visual name="front_transom">
      <origin xyz="0 0.03 0.575" rpy="0 0 0" />
      <geometry>
        <box size="0.65 0.11 0.11" />
        </geometry>
      <material name="weathered_oak">
        <color rgba="0.48 0.3 0.16 1" />
        </material>
      </visual>
    <visual name="middle_transom">
      <origin xyz="0 -0.43 0.445" rpy="0 0 0" />
      <geometry>
        <box size="0.58 0.1 0.1" />
        </geometry>
      <material name="weathered_oak">
        <color rgba="0.48 0.3 0.16 1" />
        </material>
      </visual>
    <visual name="trail_tail">
      <origin xyz="0 -1.19 0.245" rpy="0 0 0" />
      <geometry>
        <box size="0.24 0.13 0.1" />
        </geometry>
      <material name="weathered_oak">
        <color rgba="0.48 0.3 0.16 1" />
        </material>
      </visual>
    <visual name="front_tie_rod">
      <origin xyz="0 0.42 0.54" rpy="0 1.5708 0" />
      <geometry>
        <cylinder radius="0.025" length="0.61" />
        </geometry>
      <material name="worn_iron">
        <color rgba="0.12 0.12 0.115 1" />
        </material>
      </visual>
    <visual name="rear_tie_rod">
      <origin xyz="0 -0.82 0.315" rpy="0 1.5708 0" />
      <geometry>
        <cylinder radius="0.02" length="0.41" />
        </geometry>
      <material name="worn_iron">
        <color rgba="0.12 0.12 0.115 1" />
        </material>
      </visual>
    <visual name="lunette_ring">
      <origin xyz="0 -1.345 0.235" rpy="1.5708 0 0" />
      <geometry>
        <cylinder radius="0.032" length="0.18" />
        </geometry>
      <material name="worn_iron">
        <color rgba="0.12 0.12 0.115 1" />
        </material>
      </visual>
    <collision name="axle">
      <origin xyz="0 -0.15 0.46" rpy="0 1.5708 0" />
      <geometry>
        <cylinder radius="0.055" length="1.28" />
        </geometry>
      </collision>
    <collision name="axle_iron_skin">
      <origin xyz="0 -0.15 0.46" rpy="0 1.5708 0" />
      <geometry>
        <cylinder radius="0.065" length="1.12" />
        </geometry>
      </collision>
    <collision name="cheek_0">
      <origin xyz="0.285 0.015 0.65" rpy="0 0 -0.025" />
      <geometry>
        <box size="0.105 0.86 0.185" />
        </geometry>
      </collision>
    <collision name="bearing_block_0">
      <origin xyz="0.285 0.18 0.69" rpy="0 0 0" />
      <geometry>
        <box size="0.115 0.27 0.15" />
        </geometry>
      </collision>
    <collision name="trunnion_cap_0">
      <origin xyz="0.285 0.18 0.93" rpy="0 0 0" />
      <geometry>
        <box size="0.12 0.3 0.03" />
        </geometry>
      </collision>
    <collision name="front_iron_strap_0">
      <origin xyz="0.285 0.064 0.82" rpy="0 0 0" />
      <geometry>
        <box size="0.122 0.03 0.25" />
        </geometry>
      </collision>
    <collision name="rear_iron_strap_0">
      <origin xyz="0.285 0.296 0.82" rpy="0 0 0" />
      <geometry>
        <box size="0.122 0.03 0.25" />
        </geometry>
      </collision>
    <collision name="cheek_1">
      <origin xyz="-0.285 0.015 0.65" rpy="0 0 0.025" />
      <geometry>
        <box size="0.105 0.86 0.185" />
        </geometry>
      </collision>
    <collision name="bearing_block_1">
      <origin xyz="-0.285 0.18 0.69" rpy="0 0 0" />
      <geometry>
        <box size="0.115 0.27 0.15" />
        </geometry>
      </collision>
    <collision name="trunnion_cap_1">
      <origin xyz="-0.285 0.18 0.93" rpy="0 0 0" />
      <geometry>
        <box size="0.12 0.3 0.03" />
        </geometry>
      </collision>
    <collision name="front_iron_strap_1">
      <origin xyz="-0.285 0.064 0.82" rpy="0 0 0" />
      <geometry>
        <box size="0.122 0.03 0.25" />
        </geometry>
      </collision>
    <collision name="rear_iron_strap_1">
      <origin xyz="-0.285 0.296 0.82" rpy="0 0 0" />
      <geometry>
        <box size="0.122 0.03 0.25" />
        </geometry>
      </collision>
    <collision name="trail_beam_0">
      <geometry>
        <mesh filename="assets/meshes/trail_beam_0.obj" />
        </geometry>
      </collision>
    <collision name="trail_beam_1">
      <geometry>
        <mesh filename="assets/meshes/trail_beam_1.obj" />
        </geometry>
      </collision>
    <collision name="front_transom">
      <origin xyz="0 0.03 0.575" rpy="0 0 0" />
      <geometry>
        <box size="0.65 0.11 0.11" />
        </geometry>
      </collision>
    <collision name="middle_transom">
      <origin xyz="0 -0.43 0.445" rpy="0 0 0" />
      <geometry>
        <box size="0.58 0.1 0.1" />
        </geometry>
      </collision>
    <collision name="trail_tail">
      <origin xyz="0 -1.19 0.245" rpy="0 0 0" />
      <geometry>
        <box size="0.24 0.13 0.1" />
        </geometry>
      </collision>
    <collision name="front_tie_rod">
      <origin xyz="0 0.42 0.54" rpy="0 1.5708 0" />
      <geometry>
        <cylinder radius="0.025" length="0.61" />
        </geometry>
      </collision>
    <collision name="rear_tie_rod">
      <origin xyz="0 -0.82 0.315" rpy="0 1.5708 0" />
      <geometry>
        <cylinder radius="0.02" length="0.41" />
        </geometry>
      </collision>
    <collision name="lunette_ring">
      <origin xyz="0 -1.345 0.235" rpy="1.5708 0 0" />
      <geometry>
        <cylinder radius="0.032" length="0.18" />
        </geometry>
      </collision>
    </link>
  <link name="barrel">
    <inertial>
      <origin xyz="0 0.335 0" rpy="-1.5708 0 0" />
      <mass value="360" />
      <inertia ixx="111.216" ixy="0" ixz="0" iyy="111.216" iyz="0" izz="5.832" />
      </inertial>
    <visual name="barrel_casting">
      <geometry>
        <mesh filename="assets/meshes/cast_iron_barrel.obj" />
        </geometry>
      <material name="cast_iron">
        <color rgba="0.05 0.052 0.048 1" />
        </material>
      </visual>
    <visual name="trunnion_pin">
      <origin xyz="0 0 0" rpy="0 1.5708 0" />
      <geometry>
        <cylinder radius="0.065" length="0.78" />
        </geometry>
      <material name="cast_iron">
        <color rgba="0.05 0.052 0.048 1" />
        </material>
      </visual>
    <visual name="cascabel_ring">
      <origin xyz="0 -0.575 0" rpy="1.5708 0 0" />
      <geometry>
        <cylinder radius="0.035" length="0.16" />
        </geometry>
      <material name="brass_fittings">
        <color rgba="0.72 0.54 0.24 1" />
        </material>
      </visual>
    <collision name="barrel_casting">
      <geometry>
        <mesh filename="assets/meshes/cast_iron_barrel.obj" />
        </geometry>
      </collision>
    <collision name="trunnion_pin">
      <origin xyz="0 0 0" rpy="0 1.5708 0" />
      <geometry>
        <cylinder radius="0.065" length="0.78" />
        </geometry>
      </collision>
    <collision name="cascabel_ring">
      <origin xyz="0 -0.575 0" rpy="1.5708 0 0" />
      <geometry>
        <cylinder radius="0.035" length="0.16" />
        </geometry>
      </collision>
    </link>
  <link name="wheel_0">
    <inertial>
      <origin xyz="0 0 0" rpy="0 1.5708 0" />
      <mass value="62" />
      <inertia ixx="3.28329" ixy="0" ixz="0" iyy="3.28329" iyz="0" izz="6.41778" />
      </inertial>
    <visual name="wooden_wheel">
      <geometry>
        <mesh filename="assets/meshes/wooden_spoked_wheel.obj" />
        </geometry>
      <material name="weathered_oak">
        <color rgba="0.48 0.3 0.16 1" />
        </material>
      </visual>
    <visual name="iron_tire">
      <geometry>
        <mesh filename="assets/meshes/iron_wheel_tire.obj" />
        </geometry>
      <material name="worn_iron">
        <color rgba="0.12 0.12 0.115 1" />
        </material>
      </visual>
    <visual name="hub_band">
      <origin xyz="0.074 0 0" rpy="0 1.5708 0" />
      <geometry>
        <cylinder radius="0.075" length="0.038" />
        </geometry>
      <material name="worn_iron">
        <color rgba="0.12 0.12 0.115 1" />
        </material>
      </visual>
    <collision name="wooden_wheel">
      <geometry>
        <mesh filename="assets/meshes/wooden_spoked_wheel.obj" />
        </geometry>
      </collision>
    <collision name="iron_tire">
      <geometry>
        <mesh filename="assets/meshes/iron_wheel_tire.obj" />
        </geometry>
      </collision>
    <collision name="hub_band">
      <origin xyz="0.074 0 0" rpy="0 1.5708 0" />
      <geometry>
        <cylinder radius="0.075" length="0.038" />
        </geometry>
      </collision>
    </link>
  <link name="wheel_1">
    <inertial>
      <origin xyz="0 0 0" rpy="0 1.5708 0" />
      <mass value="62" />
      <inertia ixx="3.28329" ixy="0" ixz="0" iyy="3.28329" iyz="0" izz="6.41778" />
      </inertial>
    <visual name="wooden_wheel">
      <geometry>
        <mesh filename="assets/meshes/wooden_spoked_wheel.obj" />
        </geometry>
      <material name="weathered_oak">
        <color rgba="0.48 0.3 0.16 1" />
        </material>
      </visual>
    <visual name="iron_tire">
      <geometry>
        <mesh filename="assets/meshes/iron_wheel_tire.obj" />
        </geometry>
      <material name="worn_iron">
        <color rgba="0.12 0.12 0.115 1" />
        </material>
      </visual>
    <visual name="hub_band">
      <origin xyz="-0.074 0 0" rpy="0 1.5708 0" />
      <geometry>
        <cylinder radius="0.075" length="0.038" />
        </geometry>
      <material name="worn_iron">
        <color rgba="0.12 0.12 0.115 1" />
        </material>
      </visual>
    <collision name="wooden_wheel">
      <geometry>
        <mesh filename="assets/meshes/wooden_spoked_wheel.obj" />
        </geometry>
      </collision>
    <collision name="iron_tire">
      <geometry>
        <mesh filename="assets/meshes/iron_wheel_tire.obj" />
        </geometry>
      </collision>
    <collision name="hub_band">
      <origin xyz="-0.074 0 0" rpy="0 1.5708 0" />
      <geometry>
        <cylinder radius="0.075" length="0.038" />
        </geometry>
      </collision>
    </link>
  <joint name="wheel_0_spin" type="continuous">
    <origin xyz="0.652 -0.15 0.46" rpy="0 0 0" />
    <parent link="carriage" />
    <child link="wheel_0" />
    <axis xyz="1 0 0" />
    <limit effort="150" velocity="20" />
    </joint>
  <joint name="wheel_1_spin" type="continuous">
    <origin xyz="-0.652 -0.15 0.46" rpy="0 0 0" />
    <parent link="carriage" />
    <child link="wheel_1" />
    <axis xyz="1 0 0" />
    <limit effort="150" velocity="20" />
    </joint>
  <joint name="barrel_elevation" type="revolute">
    <origin xyz="0 0.18 0.83" rpy="0 0 0" />
    <parent link="carriage" />
    <child link="barrel" />
    <axis xyz="1 0 0" />
    <limit effort="220" velocity="0.8" lower="-0.08" upper="0.48" />
    </joint>
  </robot>
