<robot name="long_reach_tv_wall_mount">
  <material name="powder_black">
    <color rgba="0.01 0.012 0.012 1" />
    </material>
  <material name="satin_black">
    <color rgba="0.035 0.038 0.04 1" />
    </material>
  <material name="dark_polymer_cover">
    <color rgba="0.006 0.007 0.008 1" />
    </material>
  <material name="cast_grey">
    <color rgba="0.18 0.19 0.19 1" />
    </material>
  <material name="zinc_fasteners">
    <color rgba="0.62 0.62 0.58 1" />
    </material>
  <link name="wall_plate">
    <visual name="wall_back_plate">
      <origin xyz="-0.012 0 0" rpy="0 0 0" />
      <geometry>
        <box size="0.035 0.22 0.5" />
        </geometry>
      <material name="powder_black">
        <color rgba="0.01 0.012 0.012 1" />
        </material>
      </visual>
    <visual name="raised_spine">
      <origin xyz="0.012 0 0" rpy="0 0 0" />
      <geometry>
        <box size="0.034 0.122 0.39" />
        </geometry>
      <material name="satin_black">
        <color rgba="0.035 0.038 0.04 1" />
        </material>
      </visual>
    <visual name="wall_cable_cover">
      <origin xyz="0.034 0 -0.012" rpy="0 0 0" />
      <geometry>
        <box size="0.02 0.082 0.3" />
        </geometry>
      <material name="dark_polymer_cover">
        <color rgba="0.006 0.007 0.008 1" />
        </material>
      </visual>
    <visual name="lag_bolt_0">
      <origin xyz="0.03 -0.068 -0.185" rpy="0 1.5708 0" />
      <geometry>
        <cylinder radius="0.011" length="0.014" />
        </geometry>
      <material name="zinc_fasteners">
        <color rgba="0.62 0.62 0.58 1" />
        </material>
      </visual>
    <visual name="lag_bolt_1">
      <origin xyz="0.03 0.068 -0.185" rpy="0 1.5708 0" />
      <geometry>
        <cylinder radius="0.011" length="0.014" />
        </geometry>
      <material name="zinc_fasteners">
        <color rgba="0.62 0.62 0.58 1" />
        </material>
      </visual>
    <visual name="lag_bolt_2">
      <origin xyz="0.03 -0.068 0.185" rpy="0 1.5708 0" />
      <geometry>
        <cylinder radius="0.011" length="0.014" />
        </geometry>
      <material name="zinc_fasteners">
        <color rgba="0.62 0.62 0.58 1" />
        </material>
      </visual>
    <visual name="lag_bolt_3">
      <origin xyz="0.03 0.068 0.185" rpy="0 1.5708 0" />
      <geometry>
        <cylinder radius="0.011" length="0.014" />
        </geometry>
      <material name="zinc_fasteners">
        <color rgba="0.62 0.62 0.58 1" />
        </material>
      </visual>
    <visual name="wall_upper_standoff">
      <origin xyz="0.08 0 0.085" rpy="0 0 0" />
      <geometry>
        <box size="0.13 0.118 0.032" />
        </geometry>
      <material name="cast_grey">
        <color rgba="0.18 0.19 0.19 1" />
        </material>
      </visual>
    <visual name="wall_upper_knuckle">
      <origin xyz="0.14 0 0.085" rpy="0 0 0" />
      <geometry>
        <cylinder radius="0.054" length="0.06" />
        </geometry>
      <material name="cast_grey">
        <color rgba="0.18 0.19 0.19 1" />
        </material>
      </visual>
    <visual name="wall_lower_standoff">
      <origin xyz="0.08 0 -0.085" rpy="0 0 0" />
      <geometry>
        <box size="0.13 0.118 0.032" />
        </geometry>
      <material name="cast_grey">
        <color rgba="0.18 0.19 0.19 1" />
        </material>
      </visual>
    <visual name="wall_lower_knuckle">
      <origin xyz="0.14 0 -0.085" rpy="0 0 0" />
      <geometry>
        <cylinder radius="0.054" length="0.06" />
        </geometry>
      <material name="cast_grey">
        <color rgba="0.18 0.19 0.19 1" />
        </material>
      </visual>
    <collision name="wall_back_plate">
      <origin xyz="-0.012 0 0" rpy="0 0 0" />
      <geometry>
        <box size="0.035 0.22 0.5" />
        </geometry>
      </collision>
    <collision name="raised_spine">
      <origin xyz="0.012 0 0" rpy="0 0 0" />
      <geometry>
        <box size="0.034 0.122 0.39" />
        </geometry>
      </collision>
    <collision name="wall_cable_cover">
      <origin xyz="0.034 0 -0.012" rpy="0 0 0" />
      <geometry>
        <box size="0.02 0.082 0.3" />
        </geometry>
      </collision>
    <collision name="lag_bolt_0">
      <origin xyz="0.03 -0.068 -0.185" rpy="0 1.5708 0" />
      <geometry>
        <cylinder radius="0.011" length="0.014" />
        </geometry>
      </collision>
    <collision name="lag_bolt_1">
      <origin xyz="0.03 0.068 -0.185" rpy="0 1.5708 0" />
      <geometry>
        <cylinder radius="0.011" length="0.014" />
        </geometry>
      </collision>
    <collision name="lag_bolt_2">
      <origin xyz="0.03 -0.068 0.185" rpy="0 1.5708 0" />
      <geometry>
        <cylinder radius="0.011" length="0.014" />
        </geometry>
      </collision>
    <collision name="lag_bolt_3">
      <origin xyz="0.03 0.068 0.185" rpy="0 1.5708 0" />
      <geometry>
        <cylinder radius="0.011" length="0.014" />
        </geometry>
      </collision>
    <collision name="wall_upper_standoff">
      <origin xyz="0.08 0 0.085" rpy="0 0 0" />
      <geometry>
        <box size="0.13 0.118 0.032" />
        </geometry>
      </collision>
    <collision name="wall_upper_knuckle">
      <origin xyz="0.14 0 0.085" rpy="0 0 0" />
      <geometry>
        <cylinder radius="0.054" length="0.06" />
        </geometry>
      </collision>
    <collision name="wall_lower_standoff">
      <origin xyz="0.08 0 -0.085" rpy="0 0 0" />
      <geometry>
        <box size="0.13 0.118 0.032" />
        </geometry>
      </collision>
    <collision name="wall_lower_knuckle">
      <origin xyz="0.14 0 -0.085" rpy="0 0 0" />
      <geometry>
        <cylinder radius="0.054" length="0.06" />
        </geometry>
      </collision>
    </link>
  <link name="first_arm">
    <visual name="wall_barrel">
      <geometry>
        <cylinder radius="0.047" length="0.11" />
        </geometry>
      <material name="cast_grey">
        <color rgba="0.18 0.19 0.19 1" />
        </material>
      </visual>
    <visual name="wall_elbow_casting">
      <origin xyz="0.085 0 0" rpy="0 0 0" />
      <geometry>
        <box size="0.17 0.086 0.054" />
        </geometry>
      <material name="cast_grey">
        <color rgba="0.18 0.19 0.19 1" />
        </material>
      </visual>
    <visual name="first_core_web">
      <origin xyz="0.33 0 0" rpy="0 0 0" />
      <geometry>
        <box size="0.66 0.03 0.03" />
        </geometry>
      <material name="satin_black">
        <color rgba="0.035 0.038 0.04 1" />
        </material>
      </visual>
    <visual name="first_channel">
      <origin xyz="0.35 0 0" rpy="0 0 0" />
      <geometry>
        <mesh filename="assets/meshes/first_channel_mesh.obj" />
        </geometry>
      <material name="powder_black">
        <color rgba="0.01 0.012 0.012 1" />
        </material>
      </visual>
    <visual name="first_cable_lid">
      <origin xyz="0.36 0 0.027" rpy="0 0 0" />
      <geometry>
        <box size="0.47 0.03 0.01" />
        </geometry>
      <material name="dark_polymer_cover">
        <color rgba="0.006 0.007 0.008 1" />
        </material>
      </visual>
    <visual name="first_stamped_rib_side_0">
      <origin xyz="0.365 -0.055 0.031" rpy="0 0 0" />
      <geometry>
        <box size="0.36 0.011 0.012" />
        </geometry>
      <material name="satin_black">
        <color rgba="0.035 0.038 0.04 1" />
        </material>
      </visual>
    <visual name="first_stamped_rib_side_1">
      <origin xyz="0.365 0.055 0.031" rpy="0 0 0" />
      <geometry>
        <box size="0.36 0.011 0.012" />
        </geometry>
      <material name="satin_black">
        <color rgba="0.035 0.038 0.04 1" />
        </material>
      </visual>
    <visual name="elbow_cheek_side_0">
      <origin xyz="0.655 -0.061 0" rpy="0 0 0" />
      <geometry>
        <box size="0.16 0.018 0.14" />
        </geometry>
      <material name="cast_grey">
        <color rgba="0.18 0.19 0.19 1" />
        </material>
      </visual>
    <visual name="elbow_web_side_0">
      <origin xyz="0.565 -0.05246 0" rpy="0 0 0" />
      <geometry>
        <box size="0.07 0.03 0.052" />
        </geometry>
      <material name="cast_grey">
        <color rgba="0.18 0.19 0.19 1" />
        </material>
      </visual>
    <visual name="elbow_cheek_side_1">
      <origin xyz="0.655 0.061 0" rpy="0 0 0" />
      <geometry>
        <box size="0.16 0.018 0.14" />
        </geometry>
      <material name="cast_grey">
        <color rgba="0.18 0.19 0.19 1" />
        </material>
      </visual>
    <visual name="elbow_web_side_1">
      <origin xyz="0.565 0.05246 0" rpy="0 0 0" />
      <geometry>
        <box size="0.07 0.03 0.052" />
        </geometry>
      <material name="cast_grey">
        <color rgba="0.18 0.19 0.19 1" />
        </material>
      </visual>
    <visual name="elbow_center_web">
      <origin xyz="0.625 0 0" rpy="0 0 0" />
      <geometry>
        <box size="0.07 0.12 0.03" />
        </geometry>
      <material name="cast_grey">
        <color rgba="0.18 0.19 0.19 1" />
        </material>
      </visual>
    <visual name="elbow_upper_knuckle">
      <origin xyz="0.72 0 0.085" rpy="0 0 0" />
      <geometry>
        <cylinder radius="0.055" length="0.056" />
        </geometry>
      <material name="cast_grey">
        <color rgba="0.18 0.19 0.19 1" />
        </material>
      </visual>
    <visual name="elbow_lower_knuckle">
      <origin xyz="0.72 0 -0.085" rpy="0 0 0" />
      <geometry>
        <cylinder radius="0.055" length="0.056" />
        </geometry>
      <material name="cast_grey">
        <color rgba="0.18 0.19 0.19 1" />
        </material>
      </visual>
    <collision name="wall_barrel">
      <geometry>
        <cylinder radius="0.047" length="0.11" />
        </geometry>
      </collision>
    <collision name="wall_elbow_casting">
      <origin xyz="0.085 0 0" rpy="0 0 0" />
      <geometry>
        <box size="0.17 0.086 0.054" />
        </geometry>
      </collision>
    <collision name="first_core_web">
      <origin xyz="0.33 0 0" rpy="0 0 0" />
      <geometry>
        <box size="0.66 0.03 0.03" />
        </geometry>
      </collision>
    <collision name="first_channel">
      <origin xyz="0.35 0 0" rpy="0 0 0" />
      <geometry>
        <mesh filename="assets/meshes/first_channel_mesh.obj" />
        </geometry>
      </collision>
    <collision name="first_cable_lid">
      <origin xyz="0.36 0 0.027" rpy="0 0 0" />
      <geometry>
        <box size="0.47 0.03 0.01" />
        </geometry>
      </collision>
    <collision name="first_stamped_rib_side_0">
      <origin xyz="0.365 -0.055 0.031" rpy="0 0 0" />
      <geometry>
        <box size="0.36 0.011 0.012" />
        </geometry>
      </collision>
    <collision name="first_stamped_rib_side_1">
      <origin xyz="0.365 0.055 0.031" rpy="0 0 0" />
      <geometry>
        <box size="0.36 0.011 0.012" />
        </geometry>
      </collision>
    <collision name="elbow_cheek_side_0">
      <origin xyz="0.655 -0.061 0" rpy="0 0 0" />
      <geometry>
        <box size="0.16 0.018 0.14" />
        </geometry>
      </collision>
    <collision name="elbow_web_side_0">
      <origin xyz="0.565 -0.05246 0" rpy="0 0 0" />
      <geometry>
        <box size="0.07 0.03 0.052" />
        </geometry>
      </collision>
    <collision name="elbow_cheek_side_1">
      <origin xyz="0.655 0.061 0" rpy="0 0 0" />
      <geometry>
        <box size="0.16 0.018 0.14" />
        </geometry>
      </collision>
    <collision name="elbow_web_side_1">
      <origin xyz="0.565 0.05246 0" rpy="0 0 0" />
      <geometry>
        <box size="0.07 0.03 0.052" />
        </geometry>
      </collision>
    <collision name="elbow_center_web">
      <origin xyz="0.625 0 0" rpy="0 0 0" />
      <geometry>
        <box size="0.07 0.12 0.03" />
        </geometry>
      </collision>
    <collision name="elbow_upper_knuckle">
      <origin xyz="0.72 0 0.085" rpy="0 0 0" />
      <geometry>
        <cylinder radius="0.055" length="0.056" />
        </geometry>
      </collision>
    <collision name="elbow_lower_knuckle">
      <origin xyz="0.72 0 -0.085" rpy="0 0 0" />
      <geometry>
        <cylinder radius="0.055" length="0.056" />
        </geometry>
      </collision>
    </link>
  <link name="second_arm">
    <visual name="elbow_barrel">
      <geometry>
        <cylinder radius="0.04" length="0.114" />
        </geometry>
      <material name="cast_grey">
        <color rgba="0.18 0.19 0.19 1" />
        </material>
      </visual>
    <visual name="elbow_inner_casting">
      <origin xyz="0.075 0 0" rpy="0 0 0" />
      <geometry>
        <box size="0.15 0.074 0.05" />
        </geometry>
      <material name="cast_grey">
        <color rgba="0.18 0.19 0.19 1" />
        </material>
      </visual>
    <visual name="second_core_web">
      <origin xyz="0.175 0 0" rpy="0 0 0" />
      <geometry>
        <box size="0.35 0.026 0.028" />
        </geometry>
      <material name="satin_black">
        <color rgba="0.035 0.038 0.04 1" />
        </material>
      </visual>
    <visual name="second_channel">
      <origin xyz="0.205 0 0" rpy="0 0 0" />
      <geometry>
        <mesh filename="assets/meshes/second_channel_mesh.obj" />
        </geometry>
      <material name="powder_black">
        <color rgba="0.01 0.012 0.012 1" />
        </material>
      </visual>
    <visual name="second_cable_lid">
      <origin xyz="0.235 0 0.027" rpy="0 0 0" />
      <geometry>
        <box size="0.255 0.027 0.009" />
        </geometry>
      <material name="dark_polymer_cover">
        <color rgba="0.006 0.007 0.008 1" />
        </material>
      </visual>
    <visual name="wrist_cheek_side_0">
      <origin xyz="0.365 -0.056 0" rpy="0 0 0" />
      <geometry>
        <box size="0.135 0.018 0.128" />
        </geometry>
      <material name="cast_grey">
        <color rgba="0.18 0.19 0.19 1" />
        </material>
      </visual>
    <visual name="wrist_web_side_0">
      <origin xyz="0.3 -0.04704 0" rpy="0 0 0" />
      <geometry>
        <box size="0.055 0.028 0.048" />
        </geometry>
      <material name="cast_grey">
        <color rgba="0.18 0.19 0.19 1" />
        </material>
      </visual>
    <visual name="wrist_cheek_side_1">
      <origin xyz="0.365 0.056 0" rpy="0 0 0" />
      <geometry>
        <box size="0.135 0.018 0.128" />
        </geometry>
      <material name="cast_grey">
        <color rgba="0.18 0.19 0.19 1" />
        </material>
      </visual>
    <visual name="wrist_web_side_1">
      <origin xyz="0.3 0.04704 0" rpy="0 0 0" />
      <geometry>
        <box size="0.055 0.028 0.048" />
        </geometry>
      <material name="cast_grey">
        <color rgba="0.18 0.19 0.19 1" />
        </material>
      </visual>
    <visual name="wrist_center_web">
      <origin xyz="0.33 0 0" rpy="0 0 0" />
      <geometry>
        <box size="0.06 0.11 0.028" />
        </geometry>
      <material name="cast_grey">
        <color rgba="0.18 0.19 0.19 1" />
        </material>
      </visual>
    <visual name="wrist_upper_knuckle">
      <origin xyz="0.42 0 0.077" rpy="0 0 0" />
      <geometry>
        <cylinder radius="0.048" length="0.052" />
        </geometry>
      <material name="cast_grey">
        <color rgba="0.18 0.19 0.19 1" />
        </material>
      </visual>
    <visual name="wrist_lower_knuckle">
      <origin xyz="0.42 0 -0.077" rpy="0 0 0" />
      <geometry>
        <cylinder radius="0.048" length="0.052" />
        </geometry>
      <material name="cast_grey">
        <color rgba="0.18 0.19 0.19 1" />
        </material>
      </visual>
    <collision name="elbow_barrel">
      <geometry>
        <cylinder radius="0.04" length="0.114" />
        </geometry>
      </collision>
    <collision name="elbow_inner_casting">
      <origin xyz="0.075 0 0" rpy="0 0 0" />
      <geometry>
        <box size="0.15 0.074 0.05" />
        </geometry>
      </collision>
    <collision name="second_core_web">
      <origin xyz="0.175 0 0" rpy="0 0 0" />
      <geometry>
        <box size="0.35 0.026 0.028" />
        </geometry>
      </collision>
    <collision name="second_channel">
      <origin xyz="0.205 0 0" rpy="0 0 0" />
      <geometry>
        <mesh filename="assets/meshes/second_channel_mesh.obj" />
        </geometry>
      </collision>
    <collision name="second_cable_lid">
      <origin xyz="0.235 0 0.027" rpy="0 0 0" />
      <geometry>
        <box size="0.255 0.027 0.009" />
        </geometry>
      </collision>
    <collision name="wrist_cheek_side_0">
      <origin xyz="0.365 -0.056 0" rpy="0 0 0" />
      <geometry>
        <box size="0.135 0.018 0.128" />
        </geometry>
      </collision>
    <collision name="wrist_web_side_0">
      <origin xyz="0.3 -0.04704 0" rpy="0 0 0" />
      <geometry>
        <box size="0.055 0.028 0.048" />
        </geometry>
      </collision>
    <collision name="wrist_cheek_side_1">
      <origin xyz="0.365 0.056 0" rpy="0 0 0" />
      <geometry>
        <box size="0.135 0.018 0.128" />
        </geometry>
      </collision>
    <collision name="wrist_web_side_1">
      <origin xyz="0.3 0.04704 0" rpy="0 0 0" />
      <geometry>
        <box size="0.055 0.028 0.048" />
        </geometry>
      </collision>
    <collision name="wrist_center_web">
      <origin xyz="0.33 0 0" rpy="0 0 0" />
      <geometry>
        <box size="0.06 0.11 0.028" />
        </geometry>
      </collision>
    <collision name="wrist_upper_knuckle">
      <origin xyz="0.42 0 0.077" rpy="0 0 0" />
      <geometry>
        <cylinder radius="0.048" length="0.052" />
        </geometry>
      </collision>
    <collision name="wrist_lower_knuckle">
      <origin xyz="0.42 0 -0.077" rpy="0 0 0" />
      <geometry>
        <cylinder radius="0.048" length="0.052" />
        </geometry>
      </collision>
    </link>
  <link name="head_frame">
    <visual name="wrist_barrel">
      <geometry>
        <cylinder radius="0.036" length="0.102" />
        </geometry>
      <material name="cast_grey">
        <color rgba="0.18 0.19 0.19 1" />
        </material>
      </visual>
    <visual name="head_neck_casting">
      <origin xyz="0.082 0 0" rpy="0 0 0" />
      <geometry>
        <box size="0.165 0.075 0.048" />
        </geometry>
      <material name="cast_grey">
        <color rgba="0.18 0.19 0.19 1" />
        </material>
      </visual>
    <visual name="head_center_spine">
      <origin xyz="0.155 0 0" rpy="0 0 0" />
      <geometry>
        <box size="0.105 0.048 0.042" />
        </geometry>
      <material name="cast_grey">
        <color rgba="0.18 0.19 0.19 1" />
        </material>
      </visual>
    <visual name="square_head_frame">
      <origin xyz="0.19 0 0" rpy="0 1.5708 0" />
      <geometry>
        <mesh filename="assets/meshes/square_head_frame_mesh.obj" />
        </geometry>
      <material name="powder_black">
        <color rgba="0.01 0.012 0.012 1" />
        </material>
      </visual>
    <visual name="head_horizontal_crossbar">
      <origin xyz="0.19 0 0" rpy="0 0 0" />
      <geometry>
        <box size="0.03 0.14 0.024" />
        </geometry>
      <material name="powder_black">
        <color rgba="0.01 0.012 0.012 1" />
        </material>
      </visual>
    <visual name="head_vertical_crossbar">
      <origin xyz="0.19 0 0" rpy="0 0 0" />
      <geometry>
        <box size="0.03 0.024 0.22" />
        </geometry>
      <material name="powder_black">
        <color rgba="0.01 0.012 0.012 1" />
        </material>
      </visual>
    <visual name="tilt_pad_side_0">
      <origin xyz="0.19 -0.118 0" rpy="0 0 0" />
      <geometry>
        <box size="0.045 0.03 0.075" />
        </geometry>
      <material name="cast_grey">
        <color rgba="0.18 0.19 0.19 1" />
        </material>
      </visual>
    <visual name="tilt_pad_side_1">
      <origin xyz="0.19 0.118 0" rpy="0 0 0" />
      <geometry>
        <box size="0.045 0.03 0.075" />
        </geometry>
      <material name="cast_grey">
        <color rgba="0.18 0.19 0.19 1" />
        </material>
      </visual>
    <visual name="tilt_upper_stop">
      <origin xyz="0.214 0 0.112" rpy="0 0 0" />
      <geometry>
        <box size="0.02 0.082 0.014" />
        </geometry>
      <material name="dark_polymer_cover">
        <color rgba="0.006 0.007 0.008 1" />
        </material>
      </visual>
    <visual name="tilt_lower_stop">
      <origin xyz="0.214 0 -0.112" rpy="0 0 0" />
      <geometry>
        <box size="0.02 0.082 0.014" />
        </geometry>
      <material name="dark_polymer_cover">
        <color rgba="0.006 0.007 0.008 1" />
        </material>
      </visual>
    <collision name="wrist_barrel">
      <geometry>
        <cylinder radius="0.036" length="0.102" />
        </geometry>
      </collision>
    <collision name="head_neck_casting">
      <origin xyz="0.082 0 0" rpy="0 0 0" />
      <geometry>
        <box size="0.165 0.075 0.048" />
        </geometry>
      </collision>
    <collision name="head_center_spine">
      <origin xyz="0.155 0 0" rpy="0 0 0" />
      <geometry>
        <box size="0.105 0.048 0.042" />
        </geometry>
      </collision>
    <collision name="square_head_frame">
      <origin xyz="0.19 0 0" rpy="0 1.5708 0" />
      <geometry>
        <mesh filename="assets/meshes/square_head_frame_mesh.obj" />
        </geometry>
      </collision>
    <collision name="head_horizontal_crossbar">
      <origin xyz="0.19 0 0" rpy="0 0 0" />
      <geometry>
        <box size="0.03 0.14 0.024" />
        </geometry>
      </collision>
    <collision name="head_vertical_crossbar">
      <origin xyz="0.19 0 0" rpy="0 0 0" />
      <geometry>
        <box size="0.03 0.024 0.22" />
        </geometry>
      </collision>
    <collision name="tilt_pad_side_0">
      <origin xyz="0.19 -0.118 0" rpy="0 0 0" />
      <geometry>
        <box size="0.045 0.03 0.075" />
        </geometry>
      </collision>
    <collision name="tilt_pad_side_1">
      <origin xyz="0.19 0.118 0" rpy="0 0 0" />
      <geometry>
        <box size="0.045 0.03 0.075" />
        </geometry>
      </collision>
    <collision name="tilt_upper_stop">
      <origin xyz="0.214 0 0.112" rpy="0 0 0" />
      <geometry>
        <box size="0.02 0.082 0.014" />
        </geometry>
      </collision>
    <collision name="tilt_lower_stop">
      <origin xyz="0.214 0 -0.112" rpy="0 0 0" />
      <geometry>
        <box size="0.02 0.082 0.014" />
        </geometry>
      </collision>
    </link>
  <link name="tilt_cradle">
    <visual name="cradle_top_rail">
      <origin xyz="0.034 0 0.088" rpy="0 0 0" />
      <geometry>
        <box size="0.02 0.156 0.02" />
        </geometry>
      <material name="powder_black">
        <color rgba="0.01 0.012 0.012 1" />
        </material>
      </visual>
    <visual name="cradle_bottom_rail">
      <origin xyz="0.034 0 -0.088" rpy="0 0 0" />
      <geometry>
        <box size="0.02 0.156 0.02" />
        </geometry>
      <material name="powder_black">
        <color rgba="0.01 0.012 0.012 1" />
        </material>
      </visual>
    <visual name="vesa_rail_side_0">
      <origin xyz="0.034 -0.064 0" rpy="0 0 0" />
      <geometry>
        <box size="0.02 0.022 0.21" />
        </geometry>
      <material name="powder_black">
        <color rgba="0.01 0.012 0.012 1" />
        </material>
      </visual>
    <visual name="hinge_bridge_side_0">
      <origin xyz="0.038 -0.07552 0" rpy="0 0 0" />
      <geometry>
        <box size="0.026 0.032 0.034" />
        </geometry>
      <material name="cast_grey">
        <color rgba="0.18 0.19 0.19 1" />
        </material>
      </visual>
    <visual name="hinge_lug_side_0">
      <origin xyz="0.014 -0.088 0" rpy="0 0 0" />
      <geometry>
        <box size="0.03 0.03 0.06" />
        </geometry>
      <material name="cast_grey">
        <color rgba="0.18 0.19 0.19 1" />
        </material>
      </visual>
    <visual name="vesa_rail_side_1">
      <origin xyz="0.034 0.064 0" rpy="0 0 0" />
      <geometry>
        <box size="0.02 0.022 0.21" />
        </geometry>
      <material name="powder_black">
        <color rgba="0.01 0.012 0.012 1" />
        </material>
      </visual>
    <visual name="hinge_bridge_side_1">
      <origin xyz="0.038 0.07552 0" rpy="0 0 0" />
      <geometry>
        <box size="0.026 0.032 0.034" />
        </geometry>
      <material name="cast_grey">
        <color rgba="0.18 0.19 0.19 1" />
        </material>
      </visual>
    <visual name="hinge_lug_side_1">
      <origin xyz="0.014 0.088 0" rpy="0 0 0" />
      <geometry>
        <box size="0.03 0.03 0.06" />
        </geometry>
      <material name="cast_grey">
        <color rgba="0.18 0.19 0.19 1" />
        </material>
      </visual>
    <visual name="tilt_center_boss">
      <origin xyz="0.04 0 0" rpy="0 0 0" />
      <geometry>
        <box size="0.028 0.112 0.042" />
        </geometry>
      <material name="cast_grey">
        <color rgba="0.18 0.19 0.19 1" />
        </material>
      </visual>
    <visual name="vesa_slot_bolt_0">
      <origin xyz="0.046 -0.05 -0.05" rpy="0 1.5708 0" />
      <geometry>
        <cylinder radius="0.006" length="0.012" />
        </geometry>
      <material name="zinc_fasteners">
        <color rgba="0.62 0.62 0.58 1" />
        </material>
      </visual>
    <visual name="vesa_slot_bolt_1">
      <origin xyz="0.046 0.05 -0.05" rpy="0 1.5708 0" />
      <geometry>
        <cylinder radius="0.006" length="0.012" />
        </geometry>
      <material name="zinc_fasteners">
        <color rgba="0.62 0.62 0.58 1" />
        </material>
      </visual>
    <visual name="vesa_slot_bolt_2">
      <origin xyz="0.046 -0.05 0.05" rpy="0 1.5708 0" />
      <geometry>
        <cylinder radius="0.006" length="0.012" />
        </geometry>
      <material name="zinc_fasteners">
        <color rgba="0.62 0.62 0.58 1" />
        </material>
      </visual>
    <visual name="vesa_slot_bolt_3">
      <origin xyz="0.046 0.05 0.05" rpy="0 1.5708 0" />
      <geometry>
        <cylinder radius="0.006" length="0.012" />
        </geometry>
      <material name="zinc_fasteners">
        <color rgba="0.62 0.62 0.58 1" />
        </material>
      </visual>
    <collision name="cradle_top_rail">
      <origin xyz="0.034 0 0.088" rpy="0 0 0" />
      <geometry>
        <box size="0.02 0.156 0.02" />
        </geometry>
      </collision>
    <collision name="cradle_bottom_rail">
      <origin xyz="0.034 0 -0.088" rpy="0 0 0" />
      <geometry>
        <box size="0.02 0.156 0.02" />
        </geometry>
      </collision>
    <collision name="vesa_rail_side_0">
      <origin xyz="0.034 -0.064 0" rpy="0 0 0" />
      <geometry>
        <box size="0.02 0.022 0.21" />
        </geometry>
      </collision>
    <collision name="hinge_bridge_side_0">
      <origin xyz="0.038 -0.07552 0" rpy="0 0 0" />
      <geometry>
        <box size="0.026 0.032 0.034" />
        </geometry>
      </collision>
    <collision name="hinge_lug_side_0">
      <origin xyz="0.014 -0.088 0" rpy="0 0 0" />
      <geometry>
        <box size="0.03 0.03 0.06" />
        </geometry>
      </collision>
    <collision name="vesa_rail_side_1">
      <origin xyz="0.034 0.064 0" rpy="0 0 0" />
      <geometry>
        <box size="0.02 0.022 0.21" />
        </geometry>
      </collision>
    <collision name="hinge_bridge_side_1">
      <origin xyz="0.038 0.07552 0" rpy="0 0 0" />
      <geometry>
        <box size="0.026 0.032 0.034" />
        </geometry>
      </collision>
    <collision name="hinge_lug_side_1">
      <origin xyz="0.014 0.088 0" rpy="0 0 0" />
      <geometry>
        <box size="0.03 0.03 0.06" />
        </geometry>
      </collision>
    <collision name="tilt_center_boss">
      <origin xyz="0.04 0 0" rpy="0 0 0" />
      <geometry>
        <box size="0.028 0.112 0.042" />
        </geometry>
      </collision>
    <collision name="vesa_slot_bolt_0">
      <origin xyz="0.046 -0.05 -0.05" rpy="0 1.5708 0" />
      <geometry>
        <cylinder radius="0.006" length="0.012" />
        </geometry>
      </collision>
    <collision name="vesa_slot_bolt_1">
      <origin xyz="0.046 0.05 -0.05" rpy="0 1.5708 0" />
      <geometry>
        <cylinder radius="0.006" length="0.012" />
        </geometry>
      </collision>
    <collision name="vesa_slot_bolt_2">
      <origin xyz="0.046 -0.05 0.05" rpy="0 1.5708 0" />
      <geometry>
        <cylinder radius="0.006" length="0.012" />
        </geometry>
      </collision>
    <collision name="vesa_slot_bolt_3">
      <origin xyz="0.046 0.05 0.05" rpy="0 1.5708 0" />
      <geometry>
        <cylinder radius="0.006" length="0.012" />
        </geometry>
      </collision>
    </link>
  <joint name="wall_to_first" type="revolute">
    <origin xyz="0.14 0 0" rpy="0 0 0" />
    <parent link="wall_plate" />
    <child link="first_arm" />
    <axis xyz="0 0 1" />
    <limit effort="160" velocity="0.65" lower="-0.85" upper="0.85" />
    </joint>
  <joint name="first_to_second" type="revolute">
    <origin xyz="0.72 0 0" rpy="0 0 0" />
    <parent link="first_arm" />
    <child link="second_arm" />
    <axis xyz="0 0 1" />
    <limit effort="135" velocity="0.75" lower="-1.15" upper="1.15" />
    </joint>
  <joint name="second_to_head" type="revolute">
    <origin xyz="0.42 0 0" rpy="0 0 0" />
    <parent link="second_arm" />
    <child link="head_frame" />
    <axis xyz="0 0 1" />
    <limit effort="95" velocity="0.8" lower="-0.75" upper="0.75" />
    </joint>
  <joint name="head_to_cradle" type="revolute">
    <origin xyz="0.19 0 0" rpy="0 0 0" />
    <parent link="head_frame" />
    <child link="tilt_cradle" />
    <axis xyz="0 1 0" />
    <limit effort="80" velocity="0.55" lower="-0.35" upper="0.28" />
    </joint>
  </robot>
