<robot name="wide_dual_bay_air_purifier">
  <material name="warm_white_plastic">
    <color rgba="0.86 0.87 0.84 1" />
    </material>
  <material name="satin_white_door">
    <color rgba="0.94 0.95 0.92 1" />
    </material>
  <material name="dark_filter_media">
    <color rgba="0.035 0.038 0.042 1" />
    </material>
  <material name="graphite_trim">
    <color rgba="0.12 0.13 0.14 1" />
    </material>
  <material name="black_rubber_gasket">
    <color rgba="0.015 0.015 0.014 1" />
    </material>
  <material name="dull_hinge_metal">
    <color rgba="0.48 0.5 0.49 1" />
    </material>
  <link name="body">
    <visual name="rear_shell">
      <origin xyz="0 0.02 0.32" rpy="0 0 0" />
      <geometry>
        <box size="1.18 0.38 0.64" />
        </geometry>
      <material name="warm_white_plastic">
        <color rgba="0.86 0.87 0.84 1" />
        </material>
      </visual>
    <visual name="top_rail">
      <origin xyz="0 -0.205 0.5975" rpy="0 0 0" />
      <geometry>
        <box size="1.18 0.07 0.085" />
        </geometry>
      <material name="warm_white_plastic">
        <color rgba="0.86 0.87 0.84 1" />
        </material>
      </visual>
    <visual name="bottom_rail">
      <origin xyz="0 -0.205 0.0425" rpy="0 0 0" />
      <geometry>
        <box size="1.18 0.07 0.085" />
        </geometry>
      <material name="warm_white_plastic">
        <color rgba="0.86 0.87 0.84 1" />
        </material>
      </visual>
    <visual name="side_rail_0">
      <origin xyz="-0.5525 -0.205 0.32" rpy="0 0 0" />
      <geometry>
        <box size="0.075 0.07 0.64" />
        </geometry>
      <material name="warm_white_plastic">
        <color rgba="0.86 0.87 0.84 1" />
        </material>
      </visual>
    <visual name="side_rail_1">
      <origin xyz="0.5525 -0.205 0.32" rpy="0 0 0" />
      <geometry>
        <box size="0.075 0.07 0.64" />
        </geometry>
      <material name="warm_white_plastic">
        <color rgba="0.86 0.87 0.84 1" />
        </material>
      </visual>
    <visual name="center_mullion">
      <origin xyz="0 -0.205 0.3" rpy="0 0 0" />
      <geometry>
        <box size="0.065 0.07 0.505" />
        </geometry>
      <material name="warm_white_plastic">
        <color rgba="0.86 0.87 0.84 1" />
        </material>
      </visual>
    <visual name="filter_media_0">
      <origin xyz="-0.275 -0.176 0.305" rpy="1.5708 0 0" />
      <geometry>
        <mesh filename="assets/meshes/filter_media_0.obj" />
        </geometry>
      <material name="dark_filter_media">
        <color rgba="0.035 0.038 0.042 1" />
        </material>
      </visual>
    <visual name="filter_shadow_0">
      <origin xyz="-0.275 -0.17 0.305" rpy="0 0 0" />
      <geometry>
        <box size="0.445 0.012 0.44" />
        </geometry>
      <material name="graphite_trim">
        <color rgba="0.12 0.13 0.14 1" />
        </material>
      </visual>
    <visual name="filter_media_1">
      <origin xyz="0.275 -0.176 0.305" rpy="1.5708 0 0" />
      <geometry>
        <mesh filename="assets/meshes/filter_media_1.obj" />
        </geometry>
      <material name="dark_filter_media">
        <color rgba="0.035 0.038 0.042 1" />
        </material>
      </visual>
    <visual name="filter_shadow_1">
      <origin xyz="0.275 -0.17 0.305" rpy="0 0 0" />
      <geometry>
        <box size="0.445 0.012 0.44" />
        </geometry>
      <material name="graphite_trim">
        <color rgba="0.12 0.13 0.14 1" />
        </material>
      </visual>
    <visual name="top_outlet_grille">
      <origin xyz="0 0.05 0.643" rpy="0 0 0" />
      <geometry>
        <mesh filename="assets/meshes/top_outlet_grille.obj" />
        </geometry>
      <material name="graphite_trim">
        <color rgba="0.12 0.13 0.14 1" />
        </material>
      </visual>
    <visual name="hinge_plate_0">
      <origin xyz="-0.546 -0.243 0.305" rpy="0 0 0" />
      <geometry>
        <box size="0.02 0.006 0.505" />
        </geometry>
      <material name="dull_hinge_metal">
        <color rgba="0.48 0.5 0.49 1" />
        </material>
      </visual>
    <visual name="hinge_plate_1">
      <origin xyz="0.546 -0.243 0.305" rpy="0 0 0" />
      <geometry>
        <box size="0.02 0.006 0.505" />
        </geometry>
      <material name="dull_hinge_metal">
        <color rgba="0.48 0.5 0.49 1" />
        </material>
      </visual>
    <visual name="foot_0">
      <origin xyz="-0.46 -0.1 -0.013" rpy="0 0 0" />
      <geometry>
        <box size="0.13 0.07 0.026" />
        </geometry>
      <material name="graphite_trim">
        <color rgba="0.12 0.13 0.14 1" />
        </material>
      </visual>
    <visual name="foot_1">
      <origin xyz="0.46 -0.1 -0.013" rpy="0 0 0" />
      <geometry>
        <box size="0.13 0.07 0.026" />
        </geometry>
      <material name="graphite_trim">
        <color rgba="0.12 0.13 0.14 1" />
        </material>
      </visual>
    <visual name="foot_2">
      <origin xyz="-0.46 0.15 -0.013" rpy="0 0 0" />
      <geometry>
        <box size="0.13 0.07 0.026" />
        </geometry>
      <material name="graphite_trim">
        <color rgba="0.12 0.13 0.14 1" />
        </material>
      </visual>
    <visual name="foot_3">
      <origin xyz="0.46 0.15 -0.013" rpy="0 0 0" />
      <geometry>
        <box size="0.13 0.07 0.026" />
        </geometry>
      <material name="graphite_trim">
        <color rgba="0.12 0.13 0.14 1" />
        </material>
      </visual>
    <collision name="rear_shell">
      <origin xyz="0 0.02 0.32" rpy="0 0 0" />
      <geometry>
        <box size="1.18 0.38 0.64" />
        </geometry>
      </collision>
    <collision name="top_rail">
      <origin xyz="0 -0.205 0.5975" rpy="0 0 0" />
      <geometry>
        <box size="1.18 0.07 0.085" />
        </geometry>
      </collision>
    <collision name="bottom_rail">
      <origin xyz="0 -0.205 0.0425" rpy="0 0 0" />
      <geometry>
        <box size="1.18 0.07 0.085" />
        </geometry>
      </collision>
    <collision name="side_rail_0">
      <origin xyz="-0.5525 -0.205 0.32" rpy="0 0 0" />
      <geometry>
        <box size="0.075 0.07 0.64" />
        </geometry>
      </collision>
    <collision name="side_rail_1">
      <origin xyz="0.5525 -0.205 0.32" rpy="0 0 0" />
      <geometry>
        <box size="0.075 0.07 0.64" />
        </geometry>
      </collision>
    <collision name="center_mullion">
      <origin xyz="0 -0.205 0.3" rpy="0 0 0" />
      <geometry>
        <box size="0.065 0.07 0.505" />
        </geometry>
      </collision>
    <collision name="filter_media_0">
      <origin xyz="-0.275 -0.176 0.305" rpy="1.5708 0 0" />
      <geometry>
        <mesh filename="assets/meshes/filter_media_0.obj" />
        </geometry>
      </collision>
    <collision name="filter_shadow_0">
      <origin xyz="-0.275 -0.17 0.305" rpy="0 0 0" />
      <geometry>
        <box size="0.445 0.012 0.44" />
        </geometry>
      </collision>
    <collision name="filter_media_1">
      <origin xyz="0.275 -0.176 0.305" rpy="1.5708 0 0" />
      <geometry>
        <mesh filename="assets/meshes/filter_media_1.obj" />
        </geometry>
      </collision>
    <collision name="filter_shadow_1">
      <origin xyz="0.275 -0.17 0.305" rpy="0 0 0" />
      <geometry>
        <box size="0.445 0.012 0.44" />
        </geometry>
      </collision>
    <collision name="top_outlet_grille">
      <origin xyz="0 0.05 0.643" rpy="0 0 0" />
      <geometry>
        <mesh filename="assets/meshes/top_outlet_grille.obj" />
        </geometry>
      </collision>
    <collision name="hinge_plate_0">
      <origin xyz="-0.546 -0.243 0.305" rpy="0 0 0" />
      <geometry>
        <box size="0.02 0.006 0.505" />
        </geometry>
      </collision>
    <collision name="hinge_plate_1">
      <origin xyz="0.546 -0.243 0.305" rpy="0 0 0" />
      <geometry>
        <box size="0.02 0.006 0.505" />
        </geometry>
      </collision>
    <collision name="foot_0">
      <origin xyz="-0.46 -0.1 -0.013" rpy="0 0 0" />
      <geometry>
        <box size="0.13 0.07 0.026" />
        </geometry>
      </collision>
    <collision name="foot_1">
      <origin xyz="0.46 -0.1 -0.013" rpy="0 0 0" />
      <geometry>
        <box size="0.13 0.07 0.026" />
        </geometry>
      </collision>
    <collision name="foot_2">
      <origin xyz="-0.46 0.15 -0.013" rpy="0 0 0" />
      <geometry>
        <box size="0.13 0.07 0.026" />
        </geometry>
      </collision>
    <collision name="foot_3">
      <origin xyz="0.46 0.15 -0.013" rpy="0 0 0" />
      <geometry>
        <box size="0.13 0.07 0.026" />
        </geometry>
      </collision>
    </link>
  <link name="filter_door_0">
    <visual name="panel">
      <origin xyz="0.245 -0.018 0" rpy="0 0 0" />
      <geometry>
        <box size="0.49 0.032 0.5" />
        </geometry>
      <material name="satin_white_door">
        <color rgba="0.94 0.95 0.92 1" />
        </material>
      </visual>
    <visual name="top_lip">
      <origin xyz="0.245 -0.0385 0.227" rpy="0 0 0" />
      <geometry>
        <box size="0.455 0.01 0.026" />
        </geometry>
      <material name="warm_white_plastic">
        <color rgba="0.86 0.87 0.84 1" />
        </material>
      </visual>
    <visual name="bottom_lip">
      <origin xyz="0.245 -0.0385 -0.227" rpy="0 0 0" />
      <geometry>
        <box size="0.455 0.01 0.026" />
        </geometry>
      <material name="warm_white_plastic">
        <color rgba="0.86 0.87 0.84 1" />
        </material>
      </visual>
    <visual name="hinge_lip">
      <origin xyz="0.018 -0.0385 0" rpy="0 0 0" />
      <geometry>
        <box size="0.026 0.01 0.465" />
        </geometry>
      <material name="warm_white_plastic">
        <color rgba="0.86 0.87 0.84 1" />
        </material>
      </visual>
    <visual name="free_lip">
      <origin xyz="0.472 -0.0385 0" rpy="0 0 0" />
      <geometry>
        <box size="0.026 0.01 0.465" />
        </geometry>
      <material name="warm_white_plastic">
        <color rgba="0.86 0.87 0.84 1" />
        </material>
      </visual>
    <visual name="rear_gasket">
      <origin xyz="0.245 -0.001 0" rpy="0 0 0" />
      <geometry>
        <box size="0.435 0.004 0.445" />
        </geometry>
      <material name="black_rubber_gasket">
        <color rgba="0.015 0.015 0.014 1" />
        </material>
      </visual>
    <visual name="vertical_pull">
      <origin xyz="0.445 -0.0385 0" rpy="0 0 0" />
      <geometry>
        <box size="0.02 0.01 0.32" />
        </geometry>
      <material name="graphite_trim">
        <color rgba="0.12 0.13 0.14 1" />
        </material>
      </visual>
    <visual name="hinge_barrel">
      <origin xyz="0 -0.022 0" rpy="0 0 0" />
      <geometry>
        <cylinder radius="0.012" length="0.5" />
        </geometry>
      <material name="dull_hinge_metal">
        <color rgba="0.48 0.5 0.49 1" />
        </material>
      </visual>
    <visual name="hinge_leaf">
      <origin xyz="0.014 -0.021 0" rpy="0 0 0" />
      <geometry>
        <box size="0.028 0.01 0.5" />
        </geometry>
      <material name="dull_hinge_metal">
        <color rgba="0.48 0.5 0.49 1" />
        </material>
      </visual>
    <collision name="panel">
      <origin xyz="0.245 -0.018 0" rpy="0 0 0" />
      <geometry>
        <box size="0.49 0.032 0.5" />
        </geometry>
      </collision>
    <collision name="top_lip">
      <origin xyz="0.245 -0.0385 0.227" rpy="0 0 0" />
      <geometry>
        <box size="0.455 0.01 0.026" />
        </geometry>
      </collision>
    <collision name="bottom_lip">
      <origin xyz="0.245 -0.0385 -0.227" rpy="0 0 0" />
      <geometry>
        <box size="0.455 0.01 0.026" />
        </geometry>
      </collision>
    <collision name="hinge_lip">
      <origin xyz="0.018 -0.0385 0" rpy="0 0 0" />
      <geometry>
        <box size="0.026 0.01 0.465" />
        </geometry>
      </collision>
    <collision name="free_lip">
      <origin xyz="0.472 -0.0385 0" rpy="0 0 0" />
      <geometry>
        <box size="0.026 0.01 0.465" />
        </geometry>
      </collision>
    <collision name="rear_gasket">
      <origin xyz="0.245 -0.001 0" rpy="0 0 0" />
      <geometry>
        <box size="0.435 0.004 0.445" />
        </geometry>
      </collision>
    <collision name="vertical_pull">
      <origin xyz="0.445 -0.0385 0" rpy="0 0 0" />
      <geometry>
        <box size="0.02 0.01 0.32" />
        </geometry>
      </collision>
    <collision name="hinge_barrel">
      <origin xyz="0 -0.022 0" rpy="0 0 0" />
      <geometry>
        <cylinder radius="0.012" length="0.5" />
        </geometry>
      </collision>
    <collision name="hinge_leaf">
      <origin xyz="0.014 -0.021 0" rpy="0 0 0" />
      <geometry>
        <box size="0.028 0.01 0.5" />
        </geometry>
      </collision>
    </link>
  <link name="filter_door_1">
    <visual name="panel">
      <origin xyz="-0.245 -0.018 0" rpy="0 0 0" />
      <geometry>
        <box size="0.49 0.032 0.5" />
        </geometry>
      <material name="satin_white_door">
        <color rgba="0.94 0.95 0.92 1" />
        </material>
      </visual>
    <visual name="top_lip">
      <origin xyz="-0.245 -0.0385 0.227" rpy="0 0 0" />
      <geometry>
        <box size="0.455 0.01 0.026" />
        </geometry>
      <material name="warm_white_plastic">
        <color rgba="0.86 0.87 0.84 1" />
        </material>
      </visual>
    <visual name="bottom_lip">
      <origin xyz="-0.245 -0.0385 -0.227" rpy="0 0 0" />
      <geometry>
        <box size="0.455 0.01 0.026" />
        </geometry>
      <material name="warm_white_plastic">
        <color rgba="0.86 0.87 0.84 1" />
        </material>
      </visual>
    <visual name="hinge_lip">
      <origin xyz="-0.018 -0.0385 0" rpy="0 0 0" />
      <geometry>
        <box size="0.026 0.01 0.465" />
        </geometry>
      <material name="warm_white_plastic">
        <color rgba="0.86 0.87 0.84 1" />
        </material>
      </visual>
    <visual name="free_lip">
      <origin xyz="-0.472 -0.0385 0" rpy="0 0 0" />
      <geometry>
        <box size="0.026 0.01 0.465" />
        </geometry>
      <material name="warm_white_plastic">
        <color rgba="0.86 0.87 0.84 1" />
        </material>
      </visual>
    <visual name="rear_gasket">
      <origin xyz="-0.245 -0.001 0" rpy="0 0 0" />
      <geometry>
        <box size="0.435 0.004 0.445" />
        </geometry>
      <material name="black_rubber_gasket">
        <color rgba="0.015 0.015 0.014 1" />
        </material>
      </visual>
    <visual name="vertical_pull">
      <origin xyz="-0.445 -0.0385 0" rpy="0 0 0" />
      <geometry>
        <box size="0.02 0.01 0.32" />
        </geometry>
      <material name="graphite_trim">
        <color rgba="0.12 0.13 0.14 1" />
        </material>
      </visual>
    <visual name="hinge_barrel">
      <origin xyz="0 -0.022 0" rpy="0 0 0" />
      <geometry>
        <cylinder radius="0.012" length="0.5" />
        </geometry>
      <material name="dull_hinge_metal">
        <color rgba="0.48 0.5 0.49 1" />
        </material>
      </visual>
    <visual name="hinge_leaf">
      <origin xyz="-0.014 -0.021 0" rpy="0 0 0" />
      <geometry>
        <box size="0.028 0.01 0.5" />
        </geometry>
      <material name="dull_hinge_metal">
        <color rgba="0.48 0.5 0.49 1" />
        </material>
      </visual>
    <collision name="panel">
      <origin xyz="-0.245 -0.018 0" rpy="0 0 0" />
      <geometry>
        <box size="0.49 0.032 0.5" />
        </geometry>
      </collision>
    <collision name="top_lip">
      <origin xyz="-0.245 -0.0385 0.227" rpy="0 0 0" />
      <geometry>
        <box size="0.455 0.01 0.026" />
        </geometry>
      </collision>
    <collision name="bottom_lip">
      <origin xyz="-0.245 -0.0385 -0.227" rpy="0 0 0" />
      <geometry>
        <box size="0.455 0.01 0.026" />
        </geometry>
      </collision>
    <collision name="hinge_lip">
      <origin xyz="-0.018 -0.0385 0" rpy="0 0 0" />
      <geometry>
        <box size="0.026 0.01 0.465" />
        </geometry>
      </collision>
    <collision name="free_lip">
      <origin xyz="-0.472 -0.0385 0" rpy="0 0 0" />
      <geometry>
        <box size="0.026 0.01 0.465" />
        </geometry>
      </collision>
    <collision name="rear_gasket">
      <origin xyz="-0.245 -0.001 0" rpy="0 0 0" />
      <geometry>
        <box size="0.435 0.004 0.445" />
        </geometry>
      </collision>
    <collision name="vertical_pull">
      <origin xyz="-0.445 -0.0385 0" rpy="0 0 0" />
      <geometry>
        <box size="0.02 0.01 0.32" />
        </geometry>
      </collision>
    <collision name="hinge_barrel">
      <origin xyz="0 -0.022 0" rpy="0 0 0" />
      <geometry>
        <cylinder radius="0.012" length="0.5" />
        </geometry>
      </collision>
    <collision name="hinge_leaf">
      <origin xyz="-0.014 -0.021 0" rpy="0 0 0" />
      <geometry>
        <box size="0.028 0.01 0.5" />
        </geometry>
      </collision>
    </link>
  <joint name="body_to_filter_door_0" type="revolute">
    <origin xyz="-0.53 -0.241 0.305" rpy="0 0 0" />
    <parent link="body" />
    <child link="filter_door_0" />
    <axis xyz="0 0 -1" />
    <limit effort="18" velocity="1.6" lower="0" upper="1.75" />
    </joint>
  <joint name="body_to_filter_door_1" type="revolute">
    <origin xyz="0.53 -0.241 0.305" rpy="0 0 0" />
    <parent link="body" />
    <child link="filter_door_1" />
    <axis xyz="0 0 1" />
    <limit effort="18" velocity="1.6" lower="0" upper="1.75" />
    </joint>
  </robot>
