<robot name="pivoting_vane_array">
  <material name="powder_coated_frame">
    <color rgba="0.08 0.09 0.1 1" />
    </material>
  <material name="worn_black_edges">
    <color rgba="0.16 0.17 0.18 1" />
    </material>
  <material name="dark_bushing">
    <color rgba="0.03 0.035 0.04 1" />
    </material>
  <material name="satin_aluminum">
    <color rgba="0.72 0.76 0.78 1" />
    </material>
  <material name="polished_pivot_shafts">
    <color rgba="0.55 0.57 0.58 1" />
    </material>
  <material name="fastener_heads">
    <color rgba="0.25 0.26 0.27 1" />
    </material>
  <link name="support_frame">
    <inertial>
      <origin xyz="0 0 0.36" rpy="0 0 0" />
      <mass value="5" />
      <inertia ixx="0.224167" ixy="0" ixz="0" iyy="0.584167" iyz="0" izz="0.376333" />
      </inertial>
    <visual name="top_rail">
      <origin xyz="0 0 0.68" rpy="0 0 0" />
      <geometry>
        <box size="0.94 0.12 0.08" />
        </geometry>
      <material name="powder_coated_frame">
        <color rgba="0.08 0.09 0.1 1" />
        </material>
      </visual>
    <visual name="bottom_rail">
      <origin xyz="0 0 0.04" rpy="0 0 0" />
      <geometry>
        <box size="0.94 0.12 0.08" />
        </geometry>
      <material name="powder_coated_frame">
        <color rgba="0.08 0.09 0.1 1" />
        </material>
      </visual>
    <visual name="side_rail_0">
      <origin xyz="-0.43 0 0.36" rpy="0 0 0" />
      <geometry>
        <box size="0.08 0.12 0.72" />
        </geometry>
      <material name="powder_coated_frame">
        <color rgba="0.08 0.09 0.1 1" />
        </material>
      </visual>
    <visual name="side_rail_1">
      <origin xyz="0.43 0 0.36" rpy="0 0 0" />
      <geometry>
        <box size="0.08 0.12 0.72" />
        </geometry>
      <material name="powder_coated_frame">
        <color rgba="0.08 0.09 0.1 1" />
        </material>
      </visual>
    <visual name="rear_top_lip">
      <origin xyz="0 -0.069 0.635" rpy="0 0 0" />
      <geometry>
        <box size="0.86 0.018 0.018" />
        </geometry>
      <material name="worn_black_edges">
        <color rgba="0.16 0.17 0.18 1" />
        </material>
      </visual>
    <visual name="rear_bottom_lip">
      <origin xyz="0 -0.069 0.085" rpy="0 0 0" />
      <geometry>
        <box size="0.86 0.018 0.018" />
        </geometry>
      <material name="worn_black_edges">
        <color rgba="0.16 0.17 0.18 1" />
        </material>
      </visual>
    <visual name="top_bearing_-0.30_rear">
      <origin xyz="-0.3 -0.046 0.618" rpy="0 0 0" />
      <geometry>
        <box size="0.05 0.02 0.052" />
        </geometry>
      <material name="dark_bushing">
        <color rgba="0.03 0.035 0.04 1" />
        </material>
      </visual>
    <visual name="bottom_bearing_-0.30_rear">
      <origin xyz="-0.3 -0.046 0.102" rpy="0 0 0" />
      <geometry>
        <box size="0.05 0.02 0.052" />
        </geometry>
      <material name="dark_bushing">
        <color rgba="0.03 0.035 0.04 1" />
        </material>
      </visual>
    <visual name="top_bearing_-0.30_front">
      <origin xyz="-0.3 0.046 0.618" rpy="0 0 0" />
      <geometry>
        <box size="0.05 0.02 0.052" />
        </geometry>
      <material name="dark_bushing">
        <color rgba="0.03 0.035 0.04 1" />
        </material>
      </visual>
    <visual name="bottom_bearing_-0.30_front">
      <origin xyz="-0.3 0.046 0.102" rpy="0 0 0" />
      <geometry>
        <box size="0.05 0.02 0.052" />
        </geometry>
      <material name="dark_bushing">
        <color rgba="0.03 0.035 0.04 1" />
        </material>
      </visual>
    <visual name="top_screw_-0.30">
      <origin xyz="-0.33 0.061 0.675" rpy="0 0 0" />
      <geometry>
        <cylinder radius="0.01" length="0.012" />
        </geometry>
      <material name="fastener_heads">
        <color rgba="0.25 0.26 0.27 1" />
        </material>
      </visual>
    <visual name="bottom_screw_-0.30">
      <origin xyz="-0.27 0.061 0.045" rpy="0 0 0" />
      <geometry>
        <cylinder radius="0.01" length="0.012" />
        </geometry>
      <material name="fastener_heads">
        <color rgba="0.25 0.26 0.27 1" />
        </material>
      </visual>
    <visual name="stop_ear_-0.30_0">
      <origin xyz="-0.342 -0.03 0.098" rpy="0 0 0" />
      <geometry>
        <box size="0.018 0.018 0.04" />
        </geometry>
      <material name="worn_black_edges">
        <color rgba="0.16 0.17 0.18 1" />
        </material>
      </visual>
    <visual name="stop_ear_-0.30_1">
      <origin xyz="-0.258 0.03 0.098" rpy="0 0 0" />
      <geometry>
        <box size="0.018 0.018 0.04" />
        </geometry>
      <material name="worn_black_edges">
        <color rgba="0.16 0.17 0.18 1" />
        </material>
      </visual>
    <visual name="top_bearing_-0.18_rear">
      <origin xyz="-0.18 -0.046 0.618" rpy="0 0 0" />
      <geometry>
        <box size="0.05 0.02 0.052" />
        </geometry>
      <material name="dark_bushing">
        <color rgba="0.03 0.035 0.04 1" />
        </material>
      </visual>
    <visual name="bottom_bearing_-0.18_rear">
      <origin xyz="-0.18 -0.046 0.102" rpy="0 0 0" />
      <geometry>
        <box size="0.05 0.02 0.052" />
        </geometry>
      <material name="dark_bushing">
        <color rgba="0.03 0.035 0.04 1" />
        </material>
      </visual>
    <visual name="top_bearing_-0.18_front">
      <origin xyz="-0.18 0.046 0.618" rpy="0 0 0" />
      <geometry>
        <box size="0.05 0.02 0.052" />
        </geometry>
      <material name="dark_bushing">
        <color rgba="0.03 0.035 0.04 1" />
        </material>
      </visual>
    <visual name="bottom_bearing_-0.18_front">
      <origin xyz="-0.18 0.046 0.102" rpy="0 0 0" />
      <geometry>
        <box size="0.05 0.02 0.052" />
        </geometry>
      <material name="dark_bushing">
        <color rgba="0.03 0.035 0.04 1" />
        </material>
      </visual>
    <visual name="top_screw_-0.18">
      <origin xyz="-0.21 0.061 0.675" rpy="0 0 0" />
      <geometry>
        <cylinder radius="0.01" length="0.012" />
        </geometry>
      <material name="fastener_heads">
        <color rgba="0.25 0.26 0.27 1" />
        </material>
      </visual>
    <visual name="bottom_screw_-0.18">
      <origin xyz="-0.15 0.061 0.045" rpy="0 0 0" />
      <geometry>
        <cylinder radius="0.01" length="0.012" />
        </geometry>
      <material name="fastener_heads">
        <color rgba="0.25 0.26 0.27 1" />
        </material>
      </visual>
    <visual name="stop_ear_-0.18_0">
      <origin xyz="-0.222 -0.03 0.098" rpy="0 0 0" />
      <geometry>
        <box size="0.018 0.018 0.04" />
        </geometry>
      <material name="worn_black_edges">
        <color rgba="0.16 0.17 0.18 1" />
        </material>
      </visual>
    <visual name="stop_ear_-0.18_1">
      <origin xyz="-0.138 0.03 0.098" rpy="0 0 0" />
      <geometry>
        <box size="0.018 0.018 0.04" />
        </geometry>
      <material name="worn_black_edges">
        <color rgba="0.16 0.17 0.18 1" />
        </material>
      </visual>
    <visual name="top_bearing_-0.06_rear">
      <origin xyz="-0.06 -0.046 0.618" rpy="0 0 0" />
      <geometry>
        <box size="0.05 0.02 0.052" />
        </geometry>
      <material name="dark_bushing">
        <color rgba="0.03 0.035 0.04 1" />
        </material>
      </visual>
    <visual name="bottom_bearing_-0.06_rear">
      <origin xyz="-0.06 -0.046 0.102" rpy="0 0 0" />
      <geometry>
        <box size="0.05 0.02 0.052" />
        </geometry>
      <material name="dark_bushing">
        <color rgba="0.03 0.035 0.04 1" />
        </material>
      </visual>
    <visual name="top_bearing_-0.06_front">
      <origin xyz="-0.06 0.046 0.618" rpy="0 0 0" />
      <geometry>
        <box size="0.05 0.02 0.052" />
        </geometry>
      <material name="dark_bushing">
        <color rgba="0.03 0.035 0.04 1" />
        </material>
      </visual>
    <visual name="bottom_bearing_-0.06_front">
      <origin xyz="-0.06 0.046 0.102" rpy="0 0 0" />
      <geometry>
        <box size="0.05 0.02 0.052" />
        </geometry>
      <material name="dark_bushing">
        <color rgba="0.03 0.035 0.04 1" />
        </material>
      </visual>
    <visual name="top_screw_-0.06">
      <origin xyz="-0.09 0.061 0.675" rpy="0 0 0" />
      <geometry>
        <cylinder radius="0.01" length="0.012" />
        </geometry>
      <material name="fastener_heads">
        <color rgba="0.25 0.26 0.27 1" />
        </material>
      </visual>
    <visual name="bottom_screw_-0.06">
      <origin xyz="-0.03 0.061 0.045" rpy="0 0 0" />
      <geometry>
        <cylinder radius="0.01" length="0.012" />
        </geometry>
      <material name="fastener_heads">
        <color rgba="0.25 0.26 0.27 1" />
        </material>
      </visual>
    <visual name="stop_ear_-0.06_0">
      <origin xyz="-0.102 -0.03 0.098" rpy="0 0 0" />
      <geometry>
        <box size="0.018 0.018 0.04" />
        </geometry>
      <material name="worn_black_edges">
        <color rgba="0.16 0.17 0.18 1" />
        </material>
      </visual>
    <visual name="stop_ear_-0.06_1">
      <origin xyz="-0.018 0.03 0.098" rpy="0 0 0" />
      <geometry>
        <box size="0.018 0.018 0.04" />
        </geometry>
      <material name="worn_black_edges">
        <color rgba="0.16 0.17 0.18 1" />
        </material>
      </visual>
    <visual name="top_bearing_+0.06_rear">
      <origin xyz="0.06 -0.046 0.618" rpy="0 0 0" />
      <geometry>
        <box size="0.05 0.02 0.052" />
        </geometry>
      <material name="dark_bushing">
        <color rgba="0.03 0.035 0.04 1" />
        </material>
      </visual>
    <visual name="bottom_bearing_+0.06_rear">
      <origin xyz="0.06 -0.046 0.102" rpy="0 0 0" />
      <geometry>
        <box size="0.05 0.02 0.052" />
        </geometry>
      <material name="dark_bushing">
        <color rgba="0.03 0.035 0.04 1" />
        </material>
      </visual>
    <visual name="top_bearing_+0.06_front">
      <origin xyz="0.06 0.046 0.618" rpy="0 0 0" />
      <geometry>
        <box size="0.05 0.02 0.052" />
        </geometry>
      <material name="dark_bushing">
        <color rgba="0.03 0.035 0.04 1" />
        </material>
      </visual>
    <visual name="bottom_bearing_+0.06_front">
      <origin xyz="0.06 0.046 0.102" rpy="0 0 0" />
      <geometry>
        <box size="0.05 0.02 0.052" />
        </geometry>
      <material name="dark_bushing">
        <color rgba="0.03 0.035 0.04 1" />
        </material>
      </visual>
    <visual name="top_screw_+0.06">
      <origin xyz="0.03 0.061 0.675" rpy="0 0 0" />
      <geometry>
        <cylinder radius="0.01" length="0.012" />
        </geometry>
      <material name="fastener_heads">
        <color rgba="0.25 0.26 0.27 1" />
        </material>
      </visual>
    <visual name="bottom_screw_+0.06">
      <origin xyz="0.09 0.061 0.045" rpy="0 0 0" />
      <geometry>
        <cylinder radius="0.01" length="0.012" />
        </geometry>
      <material name="fastener_heads">
        <color rgba="0.25 0.26 0.27 1" />
        </material>
      </visual>
    <visual name="stop_ear_+0.06_0">
      <origin xyz="0.018 -0.03 0.098" rpy="0 0 0" />
      <geometry>
        <box size="0.018 0.018 0.04" />
        </geometry>
      <material name="worn_black_edges">
        <color rgba="0.16 0.17 0.18 1" />
        </material>
      </visual>
    <visual name="stop_ear_+0.06_1">
      <origin xyz="0.102 0.03 0.098" rpy="0 0 0" />
      <geometry>
        <box size="0.018 0.018 0.04" />
        </geometry>
      <material name="worn_black_edges">
        <color rgba="0.16 0.17 0.18 1" />
        </material>
      </visual>
    <visual name="top_bearing_+0.18_rear">
      <origin xyz="0.18 -0.046 0.618" rpy="0 0 0" />
      <geometry>
        <box size="0.05 0.02 0.052" />
        </geometry>
      <material name="dark_bushing">
        <color rgba="0.03 0.035 0.04 1" />
        </material>
      </visual>
    <visual name="bottom_bearing_+0.18_rear">
      <origin xyz="0.18 -0.046 0.102" rpy="0 0 0" />
      <geometry>
        <box size="0.05 0.02 0.052" />
        </geometry>
      <material name="dark_bushing">
        <color rgba="0.03 0.035 0.04 1" />
        </material>
      </visual>
    <visual name="top_bearing_+0.18_front">
      <origin xyz="0.18 0.046 0.618" rpy="0 0 0" />
      <geometry>
        <box size="0.05 0.02 0.052" />
        </geometry>
      <material name="dark_bushing">
        <color rgba="0.03 0.035 0.04 1" />
        </material>
      </visual>
    <visual name="bottom_bearing_+0.18_front">
      <origin xyz="0.18 0.046 0.102" rpy="0 0 0" />
      <geometry>
        <box size="0.05 0.02 0.052" />
        </geometry>
      <material name="dark_bushing">
        <color rgba="0.03 0.035 0.04 1" />
        </material>
      </visual>
    <visual name="top_screw_+0.18">
      <origin xyz="0.15 0.061 0.675" rpy="0 0 0" />
      <geometry>
        <cylinder radius="0.01" length="0.012" />
        </geometry>
      <material name="fastener_heads">
        <color rgba="0.25 0.26 0.27 1" />
        </material>
      </visual>
    <visual name="bottom_screw_+0.18">
      <origin xyz="0.21 0.061 0.045" rpy="0 0 0" />
      <geometry>
        <cylinder radius="0.01" length="0.012" />
        </geometry>
      <material name="fastener_heads">
        <color rgba="0.25 0.26 0.27 1" />
        </material>
      </visual>
    <visual name="stop_ear_+0.18_0">
      <origin xyz="0.138 -0.03 0.098" rpy="0 0 0" />
      <geometry>
        <box size="0.018 0.018 0.04" />
        </geometry>
      <material name="worn_black_edges">
        <color rgba="0.16 0.17 0.18 1" />
        </material>
      </visual>
    <visual name="stop_ear_+0.18_1">
      <origin xyz="0.222 0.03 0.098" rpy="0 0 0" />
      <geometry>
        <box size="0.018 0.018 0.04" />
        </geometry>
      <material name="worn_black_edges">
        <color rgba="0.16 0.17 0.18 1" />
        </material>
      </visual>
    <visual name="top_bearing_+0.30_rear">
      <origin xyz="0.3 -0.046 0.618" rpy="0 0 0" />
      <geometry>
        <box size="0.05 0.02 0.052" />
        </geometry>
      <material name="dark_bushing">
        <color rgba="0.03 0.035 0.04 1" />
        </material>
      </visual>
    <visual name="bottom_bearing_+0.30_rear">
      <origin xyz="0.3 -0.046 0.102" rpy="0 0 0" />
      <geometry>
        <box size="0.05 0.02 0.052" />
        </geometry>
      <material name="dark_bushing">
        <color rgba="0.03 0.035 0.04 1" />
        </material>
      </visual>
    <visual name="top_bearing_+0.30_front">
      <origin xyz="0.3 0.046 0.618" rpy="0 0 0" />
      <geometry>
        <box size="0.05 0.02 0.052" />
        </geometry>
      <material name="dark_bushing">
        <color rgba="0.03 0.035 0.04 1" />
        </material>
      </visual>
    <visual name="bottom_bearing_+0.30_front">
      <origin xyz="0.3 0.046 0.102" rpy="0 0 0" />
      <geometry>
        <box size="0.05 0.02 0.052" />
        </geometry>
      <material name="dark_bushing">
        <color rgba="0.03 0.035 0.04 1" />
        </material>
      </visual>
    <visual name="top_screw_+0.30">
      <origin xyz="0.27 0.061 0.675" rpy="0 0 0" />
      <geometry>
        <cylinder radius="0.01" length="0.012" />
        </geometry>
      <material name="fastener_heads">
        <color rgba="0.25 0.26 0.27 1" />
        </material>
      </visual>
    <visual name="bottom_screw_+0.30">
      <origin xyz="0.33 0.061 0.045" rpy="0 0 0" />
      <geometry>
        <cylinder radius="0.01" length="0.012" />
        </geometry>
      <material name="fastener_heads">
        <color rgba="0.25 0.26 0.27 1" />
        </material>
      </visual>
    <visual name="stop_ear_+0.30_0">
      <origin xyz="0.258 -0.03 0.098" rpy="0 0 0" />
      <geometry>
        <box size="0.018 0.018 0.04" />
        </geometry>
      <material name="worn_black_edges">
        <color rgba="0.16 0.17 0.18 1" />
        </material>
      </visual>
    <visual name="stop_ear_+0.30_1">
      <origin xyz="0.342 0.03 0.098" rpy="0 0 0" />
      <geometry>
        <box size="0.018 0.018 0.04" />
        </geometry>
      <material name="worn_black_edges">
        <color rgba="0.16 0.17 0.18 1" />
        </material>
      </visual>
    <collision name="top_rail">
      <origin xyz="0 0 0.68" rpy="0 0 0" />
      <geometry>
        <box size="0.94 0.12 0.08" />
        </geometry>
      </collision>
    <collision name="bottom_rail">
      <origin xyz="0 0 0.04" rpy="0 0 0" />
      <geometry>
        <box size="0.94 0.12 0.08" />
        </geometry>
      </collision>
    <collision name="side_rail_0">
      <origin xyz="-0.43 0 0.36" rpy="0 0 0" />
      <geometry>
        <box size="0.08 0.12 0.72" />
        </geometry>
      </collision>
    <collision name="side_rail_1">
      <origin xyz="0.43 0 0.36" rpy="0 0 0" />
      <geometry>
        <box size="0.08 0.12 0.72" />
        </geometry>
      </collision>
    <collision name="rear_top_lip">
      <origin xyz="0 -0.069 0.635" rpy="0 0 0" />
      <geometry>
        <box size="0.86 0.018 0.018" />
        </geometry>
      </collision>
    <collision name="rear_bottom_lip">
      <origin xyz="0 -0.069 0.085" rpy="0 0 0" />
      <geometry>
        <box size="0.86 0.018 0.018" />
        </geometry>
      </collision>
    <collision name="top_bearing_-0.30_rear">
      <origin xyz="-0.3 -0.046 0.618" rpy="0 0 0" />
      <geometry>
        <box size="0.05 0.02 0.052" />
        </geometry>
      </collision>
    <collision name="bottom_bearing_-0.30_rear">
      <origin xyz="-0.3 -0.046 0.102" rpy="0 0 0" />
      <geometry>
        <box size="0.05 0.02 0.052" />
        </geometry>
      </collision>
    <collision name="top_bearing_-0.30_front">
      <origin xyz="-0.3 0.046 0.618" rpy="0 0 0" />
      <geometry>
        <box size="0.05 0.02 0.052" />
        </geometry>
      </collision>
    <collision name="bottom_bearing_-0.30_front">
      <origin xyz="-0.3 0.046 0.102" rpy="0 0 0" />
      <geometry>
        <box size="0.05 0.02 0.052" />
        </geometry>
      </collision>
    <collision name="top_screw_-0.30">
      <origin xyz="-0.33 0.061 0.675" rpy="0 0 0" />
      <geometry>
        <cylinder radius="0.01" length="0.012" />
        </geometry>
      </collision>
    <collision name="bottom_screw_-0.30">
      <origin xyz="-0.27 0.061 0.045" rpy="0 0 0" />
      <geometry>
        <cylinder radius="0.01" length="0.012" />
        </geometry>
      </collision>
    <collision name="stop_ear_-0.30_0">
      <origin xyz="-0.342 -0.03 0.098" rpy="0 0 0" />
      <geometry>
        <box size="0.018 0.018 0.04" />
        </geometry>
      </collision>
    <collision name="stop_ear_-0.30_1">
      <origin xyz="-0.258 0.03 0.098" rpy="0 0 0" />
      <geometry>
        <box size="0.018 0.018 0.04" />
        </geometry>
      </collision>
    <collision name="top_bearing_-0.18_rear">
      <origin xyz="-0.18 -0.046 0.618" rpy="0 0 0" />
      <geometry>
        <box size="0.05 0.02 0.052" />
        </geometry>
      </collision>
    <collision name="bottom_bearing_-0.18_rear">
      <origin xyz="-0.18 -0.046 0.102" rpy="0 0 0" />
      <geometry>
        <box size="0.05 0.02 0.052" />
        </geometry>
      </collision>
    <collision name="top_bearing_-0.18_front">
      <origin xyz="-0.18 0.046 0.618" rpy="0 0 0" />
      <geometry>
        <box size="0.05 0.02 0.052" />
        </geometry>
      </collision>
    <collision name="bottom_bearing_-0.18_front">
      <origin xyz="-0.18 0.046 0.102" rpy="0 0 0" />
      <geometry>
        <box size="0.05 0.02 0.052" />
        </geometry>
      </collision>
    <collision name="top_screw_-0.18">
      <origin xyz="-0.21 0.061 0.675" rpy="0 0 0" />
      <geometry>
        <cylinder radius="0.01" length="0.012" />
        </geometry>
      </collision>
    <collision name="bottom_screw_-0.18">
      <origin xyz="-0.15 0.061 0.045" rpy="0 0 0" />
      <geometry>
        <cylinder radius="0.01" length="0.012" />
        </geometry>
      </collision>
    <collision name="stop_ear_-0.18_0">
      <origin xyz="-0.222 -0.03 0.098" rpy="0 0 0" />
      <geometry>
        <box size="0.018 0.018 0.04" />
        </geometry>
      </collision>
    <collision name="stop_ear_-0.18_1">
      <origin xyz="-0.138 0.03 0.098" rpy="0 0 0" />
      <geometry>
        <box size="0.018 0.018 0.04" />
        </geometry>
      </collision>
    <collision name="top_bearing_-0.06_rear">
      <origin xyz="-0.06 -0.046 0.618" rpy="0 0 0" />
      <geometry>
        <box size="0.05 0.02 0.052" />
        </geometry>
      </collision>
    <collision name="bottom_bearing_-0.06_rear">
      <origin xyz="-0.06 -0.046 0.102" rpy="0 0 0" />
      <geometry>
        <box size="0.05 0.02 0.052" />
        </geometry>
      </collision>
    <collision name="top_bearing_-0.06_front">
      <origin xyz="-0.06 0.046 0.618" rpy="0 0 0" />
      <geometry>
        <box size="0.05 0.02 0.052" />
        </geometry>
      </collision>
    <collision name="bottom_bearing_-0.06_front">
      <origin xyz="-0.06 0.046 0.102" rpy="0 0 0" />
      <geometry>
        <box size="0.05 0.02 0.052" />
        </geometry>
      </collision>
    <collision name="top_screw_-0.06">
      <origin xyz="-0.09 0.061 0.675" rpy="0 0 0" />
      <geometry>
        <cylinder radius="0.01" length="0.012" />
        </geometry>
      </collision>
    <collision name="bottom_screw_-0.06">
      <origin xyz="-0.03 0.061 0.045" rpy="0 0 0" />
      <geometry>
        <cylinder radius="0.01" length="0.012" />
        </geometry>
      </collision>
    <collision name="stop_ear_-0.06_0">
      <origin xyz="-0.102 -0.03 0.098" rpy="0 0 0" />
      <geometry>
        <box size="0.018 0.018 0.04" />
        </geometry>
      </collision>
    <collision name="stop_ear_-0.06_1">
      <origin xyz="-0.018 0.03 0.098" rpy="0 0 0" />
      <geometry>
        <box size="0.018 0.018 0.04" />
        </geometry>
      </collision>
    <collision name="top_bearing_+0.06_rear">
      <origin xyz="0.06 -0.046 0.618" rpy="0 0 0" />
      <geometry>
        <box size="0.05 0.02 0.052" />
        </geometry>
      </collision>
    <collision name="bottom_bearing_+0.06_rear">
      <origin xyz="0.06 -0.046 0.102" rpy="0 0 0" />
      <geometry>
        <box size="0.05 0.02 0.052" />
        </geometry>
      </collision>
    <collision name="top_bearing_+0.06_front">
      <origin xyz="0.06 0.046 0.618" rpy="0 0 0" />
      <geometry>
        <box size="0.05 0.02 0.052" />
        </geometry>
      </collision>
    <collision name="bottom_bearing_+0.06_front">
      <origin xyz="0.06 0.046 0.102" rpy="0 0 0" />
      <geometry>
        <box size="0.05 0.02 0.052" />
        </geometry>
      </collision>
    <collision name="top_screw_+0.06">
      <origin xyz="0.03 0.061 0.675" rpy="0 0 0" />
      <geometry>
        <cylinder radius="0.01" length="0.012" />
        </geometry>
      </collision>
    <collision name="bottom_screw_+0.06">
      <origin xyz="0.09 0.061 0.045" rpy="0 0 0" />
      <geometry>
        <cylinder radius="0.01" length="0.012" />
        </geometry>
      </collision>
    <collision name="stop_ear_+0.06_0">
      <origin xyz="0.018 -0.03 0.098" rpy="0 0 0" />
      <geometry>
        <box size="0.018 0.018 0.04" />
        </geometry>
      </collision>
    <collision name="stop_ear_+0.06_1">
      <origin xyz="0.102 0.03 0.098" rpy="0 0 0" />
      <geometry>
        <box size="0.018 0.018 0.04" />
        </geometry>
      </collision>
    <collision name="top_bearing_+0.18_rear">
      <origin xyz="0.18 -0.046 0.618" rpy="0 0 0" />
      <geometry>
        <box size="0.05 0.02 0.052" />
        </geometry>
      </collision>
    <collision name="bottom_bearing_+0.18_rear">
      <origin xyz="0.18 -0.046 0.102" rpy="0 0 0" />
      <geometry>
        <box size="0.05 0.02 0.052" />
        </geometry>
      </collision>
    <collision name="top_bearing_+0.18_front">
      <origin xyz="0.18 0.046 0.618" rpy="0 0 0" />
      <geometry>
        <box size="0.05 0.02 0.052" />
        </geometry>
      </collision>
    <collision name="bottom_bearing_+0.18_front">
      <origin xyz="0.18 0.046 0.102" rpy="0 0 0" />
      <geometry>
        <box size="0.05 0.02 0.052" />
        </geometry>
      </collision>
    <collision name="top_screw_+0.18">
      <origin xyz="0.15 0.061 0.675" rpy="0 0 0" />
      <geometry>
        <cylinder radius="0.01" length="0.012" />
        </geometry>
      </collision>
    <collision name="bottom_screw_+0.18">
      <origin xyz="0.21 0.061 0.045" rpy="0 0 0" />
      <geometry>
        <cylinder radius="0.01" length="0.012" />
        </geometry>
      </collision>
    <collision name="stop_ear_+0.18_0">
      <origin xyz="0.138 -0.03 0.098" rpy="0 0 0" />
      <geometry>
        <box size="0.018 0.018 0.04" />
        </geometry>
      </collision>
    <collision name="stop_ear_+0.18_1">
      <origin xyz="0.222 0.03 0.098" rpy="0 0 0" />
      <geometry>
        <box size="0.018 0.018 0.04" />
        </geometry>
      </collision>
    <collision name="top_bearing_+0.30_rear">
      <origin xyz="0.3 -0.046 0.618" rpy="0 0 0" />
      <geometry>
        <box size="0.05 0.02 0.052" />
        </geometry>
      </collision>
    <collision name="bottom_bearing_+0.30_rear">
      <origin xyz="0.3 -0.046 0.102" rpy="0 0 0" />
      <geometry>
        <box size="0.05 0.02 0.052" />
        </geometry>
      </collision>
    <collision name="top_bearing_+0.30_front">
      <origin xyz="0.3 0.046 0.618" rpy="0 0 0" />
      <geometry>
        <box size="0.05 0.02 0.052" />
        </geometry>
      </collision>
    <collision name="bottom_bearing_+0.30_front">
      <origin xyz="0.3 0.046 0.102" rpy="0 0 0" />
      <geometry>
        <box size="0.05 0.02 0.052" />
        </geometry>
      </collision>
    <collision name="top_screw_+0.30">
      <origin xyz="0.27 0.061 0.675" rpy="0 0 0" />
      <geometry>
        <cylinder radius="0.01" length="0.012" />
        </geometry>
      </collision>
    <collision name="bottom_screw_+0.30">
      <origin xyz="0.33 0.061 0.045" rpy="0 0 0" />
      <geometry>
        <cylinder radius="0.01" length="0.012" />
        </geometry>
      </collision>
    <collision name="stop_ear_+0.30_0">
      <origin xyz="0.258 -0.03 0.098" rpy="0 0 0" />
      <geometry>
        <box size="0.018 0.018 0.04" />
        </geometry>
      </collision>
    <collision name="stop_ear_+0.30_1">
      <origin xyz="0.342 0.03 0.098" rpy="0 0 0" />
      <geometry>
        <box size="0.018 0.018 0.04" />
        </geometry>
      </collision>
    </link>
  <link name="vane_0">
    <inertial>
      <mass value="0.22" />
      <inertia ixx="0.00535746" ixy="0" ixz="0" iyy="0.00552933" iyz="0" izz="0.000194792" />
      </inertial>
    <visual name="pivot_shaft">
      <geometry>
        <cylinder radius="0.0085" length="0.56" />
        </geometry>
      <material name="polished_pivot_shafts">
        <color rgba="0.55 0.57 0.58 1" />
        </material>
      </visual>
    <visual name="blade_shell">
      <origin xyz="0 0 0" rpy="0 0 0.383972" />
      <geometry>
        <mesh filename="assets/meshes/slim_airfoil_vane.obj" />
        </geometry>
      <material name="satin_aluminum">
        <color rgba="0.72 0.76 0.78 1" />
        </material>
      </visual>
    <visual name="lower_hub">
      <origin xyz="0 0 -0.246" rpy="0 0 0.383972" />
      <geometry>
        <box size="0.03 0.014 0.022" />
        </geometry>
      <material name="satin_aluminum">
        <color rgba="0.72 0.76 0.78 1" />
        </material>
      </visual>
    <visual name="upper_hub">
      <origin xyz="0 0 0.246" rpy="0 0 0.383972" />
      <geometry>
        <box size="0.03 0.014 0.022" />
        </geometry>
      <material name="satin_aluminum">
        <color rgba="0.72 0.76 0.78 1" />
        </material>
      </visual>
    <collision name="pivot_shaft">
      <geometry>
        <cylinder radius="0.0085" length="0.56" />
        </geometry>
      </collision>
    <collision name="blade_shell">
      <origin xyz="0 0 0" rpy="0 0 0.383972" />
      <geometry>
        <mesh filename="assets/meshes/slim_airfoil_vane.obj" />
        </geometry>
      </collision>
    <collision name="lower_hub">
      <origin xyz="0 0 -0.246" rpy="0 0 0.383972" />
      <geometry>
        <box size="0.03 0.014 0.022" />
        </geometry>
      </collision>
    <collision name="upper_hub">
      <origin xyz="0 0 0.246" rpy="0 0 0.383972" />
      <geometry>
        <box size="0.03 0.014 0.022" />
        </geometry>
      </collision>
    </link>
  <link name="vane_1">
    <inertial>
      <mass value="0.22" />
      <inertia ixx="0.00535746" ixy="0" ixz="0" iyy="0.00552933" iyz="0" izz="0.000194792" />
      </inertial>
    <visual name="pivot_shaft">
      <geometry>
        <cylinder radius="0.0085" length="0.56" />
        </geometry>
      <material name="polished_pivot_shafts">
        <color rgba="0.55 0.57 0.58 1" />
        </material>
      </visual>
    <visual name="blade_shell">
      <origin xyz="0 0 0" rpy="0 0 0.383972" />
      <geometry>
        <mesh filename="assets/meshes/slim_airfoil_vane.obj" />
        </geometry>
      <material name="satin_aluminum">
        <color rgba="0.72 0.76 0.78 1" />
        </material>
      </visual>
    <visual name="lower_hub">
      <origin xyz="0 0 -0.246" rpy="0 0 0.383972" />
      <geometry>
        <box size="0.03 0.014 0.022" />
        </geometry>
      <material name="satin_aluminum">
        <color rgba="0.72 0.76 0.78 1" />
        </material>
      </visual>
    <visual name="upper_hub">
      <origin xyz="0 0 0.246" rpy="0 0 0.383972" />
      <geometry>
        <box size="0.03 0.014 0.022" />
        </geometry>
      <material name="satin_aluminum">
        <color rgba="0.72 0.76 0.78 1" />
        </material>
      </visual>
    <collision name="pivot_shaft">
      <geometry>
        <cylinder radius="0.0085" length="0.56" />
        </geometry>
      </collision>
    <collision name="blade_shell">
      <origin xyz="0 0 0" rpy="0 0 0.383972" />
      <geometry>
        <mesh filename="assets/meshes/slim_airfoil_vane.obj" />
        </geometry>
      </collision>
    <collision name="lower_hub">
      <origin xyz="0 0 -0.246" rpy="0 0 0.383972" />
      <geometry>
        <box size="0.03 0.014 0.022" />
        </geometry>
      </collision>
    <collision name="upper_hub">
      <origin xyz="0 0 0.246" rpy="0 0 0.383972" />
      <geometry>
        <box size="0.03 0.014 0.022" />
        </geometry>
      </collision>
    </link>
  <link name="vane_2">
    <inertial>
      <mass value="0.22" />
      <inertia ixx="0.00535746" ixy="0" ixz="0" iyy="0.00552933" iyz="0" izz="0.000194792" />
      </inertial>
    <visual name="pivot_shaft">
      <geometry>
        <cylinder radius="0.0085" length="0.56" />
        </geometry>
      <material name="polished_pivot_shafts">
        <color rgba="0.55 0.57 0.58 1" />
        </material>
      </visual>
    <visual name="blade_shell">
      <origin xyz="0 0 0" rpy="0 0 0.383972" />
      <geometry>
        <mesh filename="assets/meshes/slim_airfoil_vane.obj" />
        </geometry>
      <material name="satin_aluminum">
        <color rgba="0.72 0.76 0.78 1" />
        </material>
      </visual>
    <visual name="lower_hub">
      <origin xyz="0 0 -0.246" rpy="0 0 0.383972" />
      <geometry>
        <box size="0.03 0.014 0.022" />
        </geometry>
      <material name="satin_aluminum">
        <color rgba="0.72 0.76 0.78 1" />
        </material>
      </visual>
    <visual name="upper_hub">
      <origin xyz="0 0 0.246" rpy="0 0 0.383972" />
      <geometry>
        <box size="0.03 0.014 0.022" />
        </geometry>
      <material name="satin_aluminum">
        <color rgba="0.72 0.76 0.78 1" />
        </material>
      </visual>
    <collision name="pivot_shaft">
      <geometry>
        <cylinder radius="0.0085" length="0.56" />
        </geometry>
      </collision>
    <collision name="blade_shell">
      <origin xyz="0 0 0" rpy="0 0 0.383972" />
      <geometry>
        <mesh filename="assets/meshes/slim_airfoil_vane.obj" />
        </geometry>
      </collision>
    <collision name="lower_hub">
      <origin xyz="0 0 -0.246" rpy="0 0 0.383972" />
      <geometry>
        <box size="0.03 0.014 0.022" />
        </geometry>
      </collision>
    <collision name="upper_hub">
      <origin xyz="0 0 0.246" rpy="0 0 0.383972" />
      <geometry>
        <box size="0.03 0.014 0.022" />
        </geometry>
      </collision>
    </link>
  <link name="vane_3">
    <inertial>
      <mass value="0.22" />
      <inertia ixx="0.00535746" ixy="0" ixz="0" iyy="0.00552933" iyz="0" izz="0.000194792" />
      </inertial>
    <visual name="pivot_shaft">
      <geometry>
        <cylinder radius="0.0085" length="0.56" />
        </geometry>
      <material name="polished_pivot_shafts">
        <color rgba="0.55 0.57 0.58 1" />
        </material>
      </visual>
    <visual name="blade_shell">
      <origin xyz="0 0 0" rpy="0 0 0.383972" />
      <geometry>
        <mesh filename="assets/meshes/slim_airfoil_vane.obj" />
        </geometry>
      <material name="satin_aluminum">
        <color rgba="0.72 0.76 0.78 1" />
        </material>
      </visual>
    <visual name="lower_hub">
      <origin xyz="0 0 -0.246" rpy="0 0 0.383972" />
      <geometry>
        <box size="0.03 0.014 0.022" />
        </geometry>
      <material name="satin_aluminum">
        <color rgba="0.72 0.76 0.78 1" />
        </material>
      </visual>
    <visual name="upper_hub">
      <origin xyz="0 0 0.246" rpy="0 0 0.383972" />
      <geometry>
        <box size="0.03 0.014 0.022" />
        </geometry>
      <material name="satin_aluminum">
        <color rgba="0.72 0.76 0.78 1" />
        </material>
      </visual>
    <collision name="pivot_shaft">
      <geometry>
        <cylinder radius="0.0085" length="0.56" />
        </geometry>
      </collision>
    <collision name="blade_shell">
      <origin xyz="0 0 0" rpy="0 0 0.383972" />
      <geometry>
        <mesh filename="assets/meshes/slim_airfoil_vane.obj" />
        </geometry>
      </collision>
    <collision name="lower_hub">
      <origin xyz="0 0 -0.246" rpy="0 0 0.383972" />
      <geometry>
        <box size="0.03 0.014 0.022" />
        </geometry>
      </collision>
    <collision name="upper_hub">
      <origin xyz="0 0 0.246" rpy="0 0 0.383972" />
      <geometry>
        <box size="0.03 0.014 0.022" />
        </geometry>
      </collision>
    </link>
  <link name="vane_4">
    <inertial>
      <mass value="0.22" />
      <inertia ixx="0.00535746" ixy="0" ixz="0" iyy="0.00552933" iyz="0" izz="0.000194792" />
      </inertial>
    <visual name="pivot_shaft">
      <geometry>
        <cylinder radius="0.0085" length="0.56" />
        </geometry>
      <material name="polished_pivot_shafts">
        <color rgba="0.55 0.57 0.58 1" />
        </material>
      </visual>
    <visual name="blade_shell">
      <origin xyz="0 0 0" rpy="0 0 0.383972" />
      <geometry>
        <mesh filename="assets/meshes/slim_airfoil_vane.obj" />
        </geometry>
      <material name="satin_aluminum">
        <color rgba="0.72 0.76 0.78 1" />
        </material>
      </visual>
    <visual name="lower_hub">
      <origin xyz="0 0 -0.246" rpy="0 0 0.383972" />
      <geometry>
        <box size="0.03 0.014 0.022" />
        </geometry>
      <material name="satin_aluminum">
        <color rgba="0.72 0.76 0.78 1" />
        </material>
      </visual>
    <visual name="upper_hub">
      <origin xyz="0 0 0.246" rpy="0 0 0.383972" />
      <geometry>
        <box size="0.03 0.014 0.022" />
        </geometry>
      <material name="satin_aluminum">
        <color rgba="0.72 0.76 0.78 1" />
        </material>
      </visual>
    <collision name="pivot_shaft">
      <geometry>
        <cylinder radius="0.0085" length="0.56" />
        </geometry>
      </collision>
    <collision name="blade_shell">
      <origin xyz="0 0 0" rpy="0 0 0.383972" />
      <geometry>
        <mesh filename="assets/meshes/slim_airfoil_vane.obj" />
        </geometry>
      </collision>
    <collision name="lower_hub">
      <origin xyz="0 0 -0.246" rpy="0 0 0.383972" />
      <geometry>
        <box size="0.03 0.014 0.022" />
        </geometry>
      </collision>
    <collision name="upper_hub">
      <origin xyz="0 0 0.246" rpy="0 0 0.383972" />
      <geometry>
        <box size="0.03 0.014 0.022" />
        </geometry>
      </collision>
    </link>
  <link name="vane_5">
    <inertial>
      <mass value="0.22" />
      <inertia ixx="0.00535746" ixy="0" ixz="0" iyy="0.00552933" iyz="0" izz="0.000194792" />
      </inertial>
    <visual name="pivot_shaft">
      <geometry>
        <cylinder radius="0.0085" length="0.56" />
        </geometry>
      <material name="polished_pivot_shafts">
        <color rgba="0.55 0.57 0.58 1" />
        </material>
      </visual>
    <visual name="blade_shell">
      <origin xyz="0 0 0" rpy="0 0 0.383972" />
      <geometry>
        <mesh filename="assets/meshes/slim_airfoil_vane.obj" />
        </geometry>
      <material name="satin_aluminum">
        <color rgba="0.72 0.76 0.78 1" />
        </material>
      </visual>
    <visual name="lower_hub">
      <origin xyz="0 0 -0.246" rpy="0 0 0.383972" />
      <geometry>
        <box size="0.03 0.014 0.022" />
        </geometry>
      <material name="satin_aluminum">
        <color rgba="0.72 0.76 0.78 1" />
        </material>
      </visual>
    <visual name="upper_hub">
      <origin xyz="0 0 0.246" rpy="0 0 0.383972" />
      <geometry>
        <box size="0.03 0.014 0.022" />
        </geometry>
      <material name="satin_aluminum">
        <color rgba="0.72 0.76 0.78 1" />
        </material>
      </visual>
    <collision name="pivot_shaft">
      <geometry>
        <cylinder radius="0.0085" length="0.56" />
        </geometry>
      </collision>
    <collision name="blade_shell">
      <origin xyz="0 0 0" rpy="0 0 0.383972" />
      <geometry>
        <mesh filename="assets/meshes/slim_airfoil_vane.obj" />
        </geometry>
      </collision>
    <collision name="lower_hub">
      <origin xyz="0 0 -0.246" rpy="0 0 0.383972" />
      <geometry>
        <box size="0.03 0.014 0.022" />
        </geometry>
      </collision>
    <collision name="upper_hub">
      <origin xyz="0 0 0.246" rpy="0 0 0.383972" />
      <geometry>
        <box size="0.03 0.014 0.022" />
        </geometry>
      </collision>
    </link>
  <joint name="vane_0_pivot" type="revolute">
    <origin xyz="-0.3 0 0.36" rpy="0 0 0" />
    <parent link="support_frame" />
    <child link="vane_0" />
    <axis xyz="0 0 1" />
    <limit effort="1.2" velocity="2" lower="-0.75" upper="0.75" />
    </joint>
  <joint name="vane_1_pivot" type="revolute">
    <origin xyz="-0.18 0 0.36" rpy="0 0 0" />
    <parent link="support_frame" />
    <child link="vane_1" />
    <axis xyz="0 0 1" />
    <limit effort="1.2" velocity="2" lower="-0.75" upper="0.75" />
    </joint>
  <joint name="vane_2_pivot" type="revolute">
    <origin xyz="-0.06 0 0.36" rpy="0 0 0" />
    <parent link="support_frame" />
    <child link="vane_2" />
    <axis xyz="0 0 1" />
    <limit effort="1.2" velocity="2" lower="-0.75" upper="0.75" />
    </joint>
  <joint name="vane_3_pivot" type="revolute">
    <origin xyz="0.06 0 0.36" rpy="0 0 0" />
    <parent link="support_frame" />
    <child link="vane_3" />
    <axis xyz="0 0 1" />
    <limit effort="1.2" velocity="2" lower="-0.75" upper="0.75" />
    </joint>
  <joint name="vane_4_pivot" type="revolute">
    <origin xyz="0.18 0 0.36" rpy="0 0 0" />
    <parent link="support_frame" />
    <child link="vane_4" />
    <axis xyz="0 0 1" />
    <limit effort="1.2" velocity="2" lower="-0.75" upper="0.75" />
    </joint>
  <joint name="vane_5_pivot" type="revolute">
    <origin xyz="0.3 0 0.36" rpy="0 0 0" />
    <parent link="support_frame" />
    <child link="vane_5" />
    <axis xyz="0 0 1" />
    <limit effort="1.2" velocity="2" lower="-0.75" upper="0.75" />
    </joint>
  </robot>
