<robot name="pickup_tailgate">
  <material name="painted_blue">
    <color rgba="0.05 0.18 0.42 1" />
    </material>
  <material name="shadowed_blue">
    <color rgba="0.025 0.07 0.16 1" />
    </material>
  <material name="black_plastic">
    <color rgba="0.01 0.01 0.012 1" />
    </material>
  <material name="dark_zinc_steel">
    <color rgba="0.32 0.34 0.35 1" />
    </material>
  <material name="rubber_black">
    <color rgba="0.015 0.014 0.012 1" />
    </material>
  <link name="bed_frame">
    <visual name="lower_sill">
      <origin xyz="0 0.08 0.64" rpy="0 0 0" />
      <geometry>
        <box size="1.92 0.24 0.12" />
        </geometry>
      <material name="painted_blue">
        <color rgba="0.05 0.18 0.42 1" />
        </material>
      </visual>
    <visual name="bed_floor">
      <origin xyz="0 0.41 0.7225" rpy="0 0 0" />
      <geometry>
        <box size="1.78 0.65 0.045" />
        </geometry>
      <material name="shadowed_blue">
        <color rgba="0.025 0.07 0.16 1" />
        </material>
      </visual>
    <visual name="rear_jamb_0">
      <origin xyz="-0.93 0.08 1.0725" rpy="0 0 0" />
      <geometry>
        <box size="0.12 0.34 0.755" />
        </geometry>
      <material name="painted_blue">
        <color rgba="0.05 0.18 0.42 1" />
        </material>
      </visual>
    <visual name="bed_rail_0">
      <origin xyz="-0.93 0.43 1.335" rpy="0 0 0" />
      <geometry>
        <box size="0.12 0.72 0.11" />
        </geometry>
      <material name="painted_blue">
        <color rgba="0.05 0.18 0.42 1" />
        </material>
      </visual>
    <visual name="side_wall_0">
      <origin xyz="-0.93 0.43 0.91" rpy="0 0 0" />
      <geometry>
        <box size="0.08 0.7 0.34" />
        </geometry>
      <material name="shadowed_blue">
        <color rgba="0.025 0.07 0.16 1" />
        </material>
      </visual>
    <visual name="hinge_bracket_0">
      <origin xyz="-0.879036 -0.07 0.7" rpy="0 0 0" />
      <geometry>
        <box size="0.06 0.1 0.14" />
        </geometry>
      <material name="dark_zinc_steel">
        <color rgba="0.32 0.34 0.35 1" />
        </material>
      </visual>
    <visual name="hinge_hole_0">
      <origin xyz="-0.879036 -0.121 0.7" rpy="1.5708 0 0" />
      <geometry>
        <cylinder radius="0.02" length="0.007" />
        </geometry>
      <material name="black_plastic">
        <color rgba="0.01 0.01 0.012 1" />
        </material>
      </visual>
    <visual name="striker_pin_0">
      <origin xyz="-0.837 -0.02 1.225" rpy="0 1.5708 0" />
      <geometry>
        <cylinder radius="0.018" length="0.09" />
        </geometry>
      <material name="dark_zinc_steel">
        <color rgba="0.32 0.34 0.35 1" />
        </material>
      </visual>
    <visual name="rear_jamb_1">
      <origin xyz="0.93 0.08 1.0725" rpy="0 0 0" />
      <geometry>
        <box size="0.12 0.34 0.755" />
        </geometry>
      <material name="painted_blue">
        <color rgba="0.05 0.18 0.42 1" />
        </material>
      </visual>
    <visual name="bed_rail_1">
      <origin xyz="0.93 0.43 1.335" rpy="0 0 0" />
      <geometry>
        <box size="0.12 0.72 0.11" />
        </geometry>
      <material name="painted_blue">
        <color rgba="0.05 0.18 0.42 1" />
        </material>
      </visual>
    <visual name="side_wall_1">
      <origin xyz="0.93 0.43 0.91" rpy="0 0 0" />
      <geometry>
        <box size="0.08 0.7 0.34" />
        </geometry>
      <material name="shadowed_blue">
        <color rgba="0.025 0.07 0.16 1" />
        </material>
      </visual>
    <visual name="hinge_bracket_1">
      <origin xyz="0.879036 -0.07 0.7" rpy="0 0 0" />
      <geometry>
        <box size="0.06 0.1 0.14" />
        </geometry>
      <material name="dark_zinc_steel">
        <color rgba="0.32 0.34 0.35 1" />
        </material>
      </visual>
    <visual name="hinge_hole_1">
      <origin xyz="0.879036 -0.121 0.7" rpy="1.5708 0 0" />
      <geometry>
        <cylinder radius="0.02" length="0.007" />
        </geometry>
      <material name="black_plastic">
        <color rgba="0.01 0.01 0.012 1" />
        </material>
      </visual>
    <visual name="striker_pin_1">
      <origin xyz="0.837 -0.02 1.225" rpy="0 1.5708 0" />
      <geometry>
        <cylinder radius="0.018" length="0.09" />
        </geometry>
      <material name="dark_zinc_steel">
        <color rgba="0.32 0.34 0.35 1" />
        </material>
      </visual>
    <collision name="lower_sill">
      <origin xyz="0 0.08 0.64" rpy="0 0 0" />
      <geometry>
        <box size="1.92 0.24 0.12" />
        </geometry>
      </collision>
    <collision name="bed_floor">
      <origin xyz="0 0.41 0.7225" rpy="0 0 0" />
      <geometry>
        <box size="1.78 0.65 0.045" />
        </geometry>
      </collision>
    <collision name="rear_jamb_0">
      <origin xyz="-0.93 0.08 1.0725" rpy="0 0 0" />
      <geometry>
        <box size="0.12 0.34 0.755" />
        </geometry>
      </collision>
    <collision name="bed_rail_0">
      <origin xyz="-0.93 0.43 1.335" rpy="0 0 0" />
      <geometry>
        <box size="0.12 0.72 0.11" />
        </geometry>
      </collision>
    <collision name="side_wall_0">
      <origin xyz="-0.93 0.43 0.91" rpy="0 0 0" />
      <geometry>
        <box size="0.08 0.7 0.34" />
        </geometry>
      </collision>
    <collision name="hinge_bracket_0">
      <origin xyz="-0.879036 -0.07 0.7" rpy="0 0 0" />
      <geometry>
        <box size="0.06 0.1 0.14" />
        </geometry>
      </collision>
    <collision name="hinge_hole_0">
      <origin xyz="-0.879036 -0.121 0.7" rpy="1.5708 0 0" />
      <geometry>
        <cylinder radius="0.02" length="0.007" />
        </geometry>
      </collision>
    <collision name="striker_pin_0">
      <origin xyz="-0.837 -0.02 1.225" rpy="0 1.5708 0" />
      <geometry>
        <cylinder radius="0.018" length="0.09" />
        </geometry>
      </collision>
    <collision name="rear_jamb_1">
      <origin xyz="0.93 0.08 1.0725" rpy="0 0 0" />
      <geometry>
        <box size="0.12 0.34 0.755" />
        </geometry>
      </collision>
    <collision name="bed_rail_1">
      <origin xyz="0.93 0.43 1.335" rpy="0 0 0" />
      <geometry>
        <box size="0.12 0.72 0.11" />
        </geometry>
      </collision>
    <collision name="side_wall_1">
      <origin xyz="0.93 0.43 0.91" rpy="0 0 0" />
      <geometry>
        <box size="0.08 0.7 0.34" />
        </geometry>
      </collision>
    <collision name="hinge_bracket_1">
      <origin xyz="0.879036 -0.07 0.7" rpy="0 0 0" />
      <geometry>
        <box size="0.06 0.1 0.14" />
        </geometry>
      </collision>
    <collision name="hinge_hole_1">
      <origin xyz="0.879036 -0.121 0.7" rpy="1.5708 0 0" />
      <geometry>
        <cylinder radius="0.02" length="0.007" />
        </geometry>
      </collision>
    <collision name="striker_pin_1">
      <origin xyz="0.837 -0.02 1.225" rpy="0 1.5708 0" />
      <geometry>
        <cylinder radius="0.018" length="0.09" />
        </geometry>
      </collision>
    </link>
  <link name="tailgate">
    <visual name="outer_panel">
      <origin xyz="0 -0.04 0.3" rpy="0 0 0" />
      <geometry>
        <box size="1.68 0.075 0.6" />
        </geometry>
      <material name="painted_blue">
        <color rgba="0.05 0.18 0.42 1" />
        </material>
      </visual>
    <visual name="top_cap">
      <origin xyz="0 -0.038 0.6" rpy="0 0 0" />
      <geometry>
        <box size="1.7 0.09 0.06" />
        </geometry>
      <material name="painted_blue">
        <color rgba="0.05 0.18 0.42 1" />
        </material>
      </visual>
    <visual name="upper_stamping">
      <origin xyz="0 -0.0845 0.54" rpy="0 0 0" />
      <geometry>
        <box size="1.62 0.014 0.035" />
        </geometry>
      <material name="painted_blue">
        <color rgba="0.05 0.18 0.42 1" />
        </material>
      </visual>
    <visual name="lower_stamping">
      <origin xyz="0 -0.0845 0.075" rpy="0 0 0" />
      <geometry>
        <box size="1.48 0.014 0.035" />
        </geometry>
      <material name="painted_blue">
        <color rgba="0.05 0.18 0.42 1" />
        </material>
      </visual>
    <visual name="side_stamping_0">
      <origin xyz="-0.775 -0.0845 0.305" rpy="0 0 0" />
      <geometry>
        <box size="0.055 0.014 0.46" />
        </geometry>
      <material name="painted_blue">
        <color rgba="0.05 0.18 0.42 1" />
        </material>
      </visual>
    <visual name="latch_pocket_0">
      <origin xyz="-0.809875 -0.014 0.515" rpy="0 0 0" />
      <geometry>
        <box size="0.055 0.03 0.11" />
        </geometry>
      <material name="dark_zinc_steel">
        <color rgba="0.32 0.34 0.35 1" />
        </material>
      </visual>
    <visual name="side_stamping_1">
      <origin xyz="0.775 -0.0845 0.305" rpy="0 0 0" />
      <geometry>
        <box size="0.055 0.014 0.46" />
        </geometry>
      <material name="painted_blue">
        <color rgba="0.05 0.18 0.42 1" />
        </material>
      </visual>
    <visual name="latch_pocket_1">
      <origin xyz="0.809875 -0.014 0.515" rpy="0 0 0" />
      <geometry>
        <box size="0.055 0.03 0.11" />
        </geometry>
      <material name="dark_zinc_steel">
        <color rgba="0.32 0.34 0.35 1" />
        </material>
      </visual>
    <visual name="center_recess">
      <origin xyz="0 -0.09 0.305" rpy="0 0 0" />
      <geometry>
        <box size="0.8 0.01 0.235" />
        </geometry>
      <material name="shadowed_blue">
        <color rgba="0.025 0.07 0.16 1" />
        </material>
      </visual>
    <visual name="handle_pocket">
      <origin xyz="0 -0.083 0.49" rpy="0 0 0" />
      <geometry>
        <box size="0.365 0.012 0.16" />
        </geometry>
      <material name="black_plastic">
        <color rgba="0.01 0.01 0.012 1" />
        </material>
      </visual>
    <visual name="handle_bezel_top">
      <origin xyz="0 -0.09 0.585" rpy="0 0 0" />
      <geometry>
        <box size="0.42 0.014 0.03" />
        </geometry>
      <material name="painted_blue">
        <color rgba="0.05 0.18 0.42 1" />
        </material>
      </visual>
    <visual name="handle_bezel_bottom">
      <origin xyz="0 -0.09 0.395" rpy="0 0 0" />
      <geometry>
        <box size="0.42 0.014 0.03" />
        </geometry>
      <material name="painted_blue">
        <color rgba="0.05 0.18 0.42 1" />
        </material>
      </visual>
    <visual name="handle_bezel_side_0">
      <origin xyz="-0.212 -0.09 0.49" rpy="0 0 0" />
      <geometry>
        <box size="0.03 0.014 0.19" />
        </geometry>
      <material name="painted_blue">
        <color rgba="0.05 0.18 0.42 1" />
        </material>
      </visual>
    <visual name="handle_bezel_side_1">
      <origin xyz="0.212 -0.09 0.49" rpy="0 0 0" />
      <geometry>
        <box size="0.03 0.014 0.19" />
        </geometry>
      <material name="painted_blue">
        <color rgba="0.05 0.18 0.42 1" />
        </material>
      </visual>
    <visual name="hinge_barrel_0">
      <origin xyz="-0.805 0 0" rpy="0 1.5708 0" />
      <geometry>
        <cylinder radius="0.026" length="0.09" />
        </geometry>
      <material name="dark_zinc_steel">
        <color rgba="0.32 0.34 0.35 1" />
        </material>
      </visual>
    <visual name="hinge_strap_0">
      <origin xyz="-0.805 -0.03 0.055" rpy="0 0 0" />
      <geometry>
        <box size="0.075 0.03 0.115" />
        </geometry>
      <material name="dark_zinc_steel">
        <color rgba="0.32 0.34 0.35 1" />
        </material>
      </visual>
    <visual name="hinge_barrel_1">
      <origin xyz="0.805 0 0" rpy="0 1.5708 0" />
      <geometry>
        <cylinder radius="0.026" length="0.09" />
        </geometry>
      <material name="dark_zinc_steel">
        <color rgba="0.32 0.34 0.35 1" />
        </material>
      </visual>
    <visual name="hinge_strap_1">
      <origin xyz="0.805 -0.03 0.055" rpy="0 0 0" />
      <geometry>
        <box size="0.075 0.03 0.115" />
        </geometry>
      <material name="dark_zinc_steel">
        <color rgba="0.32 0.34 0.35 1" />
        </material>
      </visual>
    <visual name="lower_seal">
      <origin xyz="0 -0.002 0.055" rpy="0 0 0" />
      <geometry>
        <box size="1.58 0.012 0.035" />
        </geometry>
      <material name="rubber_black">
        <color rgba="0.015 0.014 0.012 1" />
        </material>
      </visual>
    <collision name="outer_panel">
      <origin xyz="0 -0.04 0.3" rpy="0 0 0" />
      <geometry>
        <box size="1.68 0.075 0.6" />
        </geometry>
      </collision>
    <collision name="top_cap">
      <origin xyz="0 -0.038 0.6" rpy="0 0 0" />
      <geometry>
        <box size="1.7 0.09 0.06" />
        </geometry>
      </collision>
    <collision name="upper_stamping">
      <origin xyz="0 -0.0845 0.54" rpy="0 0 0" />
      <geometry>
        <box size="1.62 0.014 0.035" />
        </geometry>
      </collision>
    <collision name="lower_stamping">
      <origin xyz="0 -0.0845 0.075" rpy="0 0 0" />
      <geometry>
        <box size="1.48 0.014 0.035" />
        </geometry>
      </collision>
    <collision name="side_stamping_0">
      <origin xyz="-0.775 -0.0845 0.305" rpy="0 0 0" />
      <geometry>
        <box size="0.055 0.014 0.46" />
        </geometry>
      </collision>
    <collision name="latch_pocket_0">
      <origin xyz="-0.809875 -0.014 0.515" rpy="0 0 0" />
      <geometry>
        <box size="0.055 0.03 0.11" />
        </geometry>
      </collision>
    <collision name="side_stamping_1">
      <origin xyz="0.775 -0.0845 0.305" rpy="0 0 0" />
      <geometry>
        <box size="0.055 0.014 0.46" />
        </geometry>
      </collision>
    <collision name="latch_pocket_1">
      <origin xyz="0.809875 -0.014 0.515" rpy="0 0 0" />
      <geometry>
        <box size="0.055 0.03 0.11" />
        </geometry>
      </collision>
    <collision name="center_recess">
      <origin xyz="0 -0.09 0.305" rpy="0 0 0" />
      <geometry>
        <box size="0.8 0.01 0.235" />
        </geometry>
      </collision>
    <collision name="handle_pocket">
      <origin xyz="0 -0.083 0.49" rpy="0 0 0" />
      <geometry>
        <box size="0.365 0.012 0.16" />
        </geometry>
      </collision>
    <collision name="handle_bezel_top">
      <origin xyz="0 -0.09 0.585" rpy="0 0 0" />
      <geometry>
        <box size="0.42 0.014 0.03" />
        </geometry>
      </collision>
    <collision name="handle_bezel_bottom">
      <origin xyz="0 -0.09 0.395" rpy="0 0 0" />
      <geometry>
        <box size="0.42 0.014 0.03" />
        </geometry>
      </collision>
    <collision name="handle_bezel_side_0">
      <origin xyz="-0.212 -0.09 0.49" rpy="0 0 0" />
      <geometry>
        <box size="0.03 0.014 0.19" />
        </geometry>
      </collision>
    <collision name="handle_bezel_side_1">
      <origin xyz="0.212 -0.09 0.49" rpy="0 0 0" />
      <geometry>
        <box size="0.03 0.014 0.19" />
        </geometry>
      </collision>
    <collision name="hinge_barrel_0">
      <origin xyz="-0.805 0 0" rpy="0 1.5708 0" />
      <geometry>
        <cylinder radius="0.026" length="0.09" />
        </geometry>
      </collision>
    <collision name="hinge_strap_0">
      <origin xyz="-0.805 -0.03 0.055" rpy="0 0 0" />
      <geometry>
        <box size="0.075 0.03 0.115" />
        </geometry>
      </collision>
    <collision name="hinge_barrel_1">
      <origin xyz="0.805 0 0" rpy="0 1.5708 0" />
      <geometry>
        <cylinder radius="0.026" length="0.09" />
        </geometry>
      </collision>
    <collision name="hinge_strap_1">
      <origin xyz="0.805 -0.03 0.055" rpy="0 0 0" />
      <geometry>
        <box size="0.075 0.03 0.115" />
        </geometry>
      </collision>
    <collision name="lower_seal">
      <origin xyz="0 -0.002 0.055" rpy="0 0 0" />
      <geometry>
        <box size="1.58 0.012 0.035" />
        </geometry>
      </collision>
    </link>
  <link name="latch_handle">
    <visual name="handle_pivot">
      <origin xyz="0 -0.011 -0.004" rpy="0 1.5708 0" />
      <geometry>
        <cylinder radius="0.011" length="0.3" />
        </geometry>
      <material name="dark_zinc_steel">
        <color rgba="0.32 0.34 0.35 1" />
        </material>
      </visual>
    <visual name="handle_paddle">
      <origin xyz="0 -0.009 -0.055" rpy="0 0 0" />
      <geometry>
        <box size="0.26 0.018 0.09" />
        </geometry>
      <material name="black_plastic">
        <color rgba="0.01 0.01 0.012 1" />
        </material>
      </visual>
    <visual name="handle_grip_lip">
      <origin xyz="0 -0.015 -0.095" rpy="0 0 0" />
      <geometry>
        <box size="0.22 0.03 0.022" />
        </geometry>
      <material name="black_plastic">
        <color rgba="0.01 0.01 0.012 1" />
        </material>
      </visual>
    <collision name="handle_pivot">
      <origin xyz="0 -0.011 -0.004" rpy="0 1.5708 0" />
      <geometry>
        <cylinder radius="0.011" length="0.3" />
        </geometry>
      </collision>
    <collision name="handle_paddle">
      <origin xyz="0 -0.009 -0.055" rpy="0 0 0" />
      <geometry>
        <box size="0.26 0.018 0.09" />
        </geometry>
      </collision>
    <collision name="handle_grip_lip">
      <origin xyz="0 -0.015 -0.095" rpy="0 0 0" />
      <geometry>
        <box size="0.22 0.03 0.022" />
        </geometry>
      </collision>
    </link>
  <joint name="bed_to_tailgate" type="revolute">
    <origin xyz="0 -0.07 0.7" rpy="0 0 0" />
    <parent link="bed_frame" />
    <child link="tailgate" />
    <axis xyz="1 0 0" />
    <limit effort="250" velocity="1.2" lower="0" upper="1.45" />
    </joint>
  <joint name="tailgate_to_latch_handle" type="revolute">
    <origin xyz="0 -0.089 0.535" rpy="0 0 0" />
    <parent link="tailgate" />
    <child link="latch_handle" />
    <axis xyz="-1 0 0" />
    <limit effort="8" velocity="3" lower="0" upper="0.45" />
    </joint>
  </robot>
