<robot name="victorian_civic_clock_tower">
  <material name="warm_limestone">
    <color rgba="0.66 0.62 0.53 1" />
    </material>
  <material name="pale_stone_edges">
    <color rgba="0.76 0.73 0.64 1" />
    </material>
  <material name="recess_shadow_stone">
    <color rgba="0.36 0.34 0.31 1" />
    </material>
  <material name="aged_ivory_enamel">
    <color rgba="0.92 0.88 0.72 1" />
    </material>
  <material name="blackened_bronze">
    <color rgba="0.03 0.025 0.018 1" />
    </material>
  <material name="blue_grey_slate">
    <color rgba="0.16 0.19 0.22 1" />
    </material>
  <material name="dark_glass">
    <color rgba="0.05 0.07 0.08 1" />
    </material>
  <link name="tower">
    <visual name="ground_plinth">
      <origin xyz="0 0 0.14" rpy="0 0 0" />
      <geometry>
        <box size="2.15 2.15 0.28" />
        </geometry>
      <material name="recess_shadow_stone">
        <color rgba="0.36 0.34 0.31 1" />
        </material>
      </visual>
    <visual name="stepped_plinth">
      <origin xyz="0 0 0.38" rpy="0 0 0" />
      <geometry>
        <box size="1.82 1.82 0.3" />
        </geometry>
      <material name="warm_limestone">
        <color rgba="0.66 0.62 0.53 1" />
        </material>
      </visual>
    <visual name="square_shaft">
      <origin xyz="0 0 2.86" rpy="0 0 0" />
      <geometry>
        <box size="1.24 1.24 4.8" />
        </geometry>
      <material name="warm_limestone">
        <color rgba="0.66 0.62 0.53 1" />
        </material>
      </visual>
    <visual name="quoin_-1_-1">
      <origin xyz="-0.545 -0.545 2.86" rpy="0 0 0" />
      <geometry>
        <box size="0.19 0.19 4.92" />
        </geometry>
      <material name="pale_stone_edges">
        <color rgba="0.76 0.73 0.64 1" />
        </material>
      </visual>
    <visual name="quoin_-1_1">
      <origin xyz="-0.545 0.545 2.86" rpy="0 0 0" />
      <geometry>
        <box size="0.19 0.19 4.92" />
        </geometry>
      <material name="pale_stone_edges">
        <color rgba="0.76 0.73 0.64 1" />
        </material>
      </visual>
    <visual name="quoin_1_-1">
      <origin xyz="0.545 -0.545 2.86" rpy="0 0 0" />
      <geometry>
        <box size="0.19 0.19 4.92" />
        </geometry>
      <material name="pale_stone_edges">
        <color rgba="0.76 0.73 0.64 1" />
        </material>
      </visual>
    <visual name="quoin_1_1">
      <origin xyz="0.545 0.545 2.86" rpy="0 0 0" />
      <geometry>
        <box size="0.19 0.19 4.92" />
        </geometry>
      <material name="pale_stone_edges">
        <color rgba="0.76 0.73 0.64 1" />
        </material>
      </visual>
    <visual name="masonry_course_0">
      <origin xyz="0 0 0.84" rpy="0 0 0" />
      <geometry>
        <box size="1.34 1.34 0.05" />
        </geometry>
      <material name="pale_stone_edges">
        <color rgba="0.76 0.73 0.64 1" />
        </material>
      </visual>
    <visual name="masonry_course_1">
      <origin xyz="0 0 1.48" rpy="0 0 0" />
      <geometry>
        <box size="1.34 1.34 0.05" />
        </geometry>
      <material name="pale_stone_edges">
        <color rgba="0.76 0.73 0.64 1" />
        </material>
      </visual>
    <visual name="masonry_course_2">
      <origin xyz="0 0 2.12" rpy="0 0 0" />
      <geometry>
        <box size="1.34 1.34 0.05" />
        </geometry>
      <material name="pale_stone_edges">
        <color rgba="0.76 0.73 0.64 1" />
        </material>
      </visual>
    <visual name="masonry_course_3">
      <origin xyz="0 0 2.76" rpy="0 0 0" />
      <geometry>
        <box size="1.34 1.34 0.05" />
        </geometry>
      <material name="pale_stone_edges">
        <color rgba="0.76 0.73 0.64 1" />
        </material>
      </visual>
    <visual name="masonry_course_4">
      <origin xyz="0 0 3.4" rpy="0 0 0" />
      <geometry>
        <box size="1.34 1.34 0.05" />
        </geometry>
      <material name="pale_stone_edges">
        <color rgba="0.76 0.73 0.64 1" />
        </material>
      </visual>
    <visual name="masonry_course_5">
      <origin xyz="0 0 4.04" rpy="0 0 0" />
      <geometry>
        <box size="1.34 1.34 0.05" />
        </geometry>
      <material name="pale_stone_edges">
        <color rgba="0.76 0.73 0.64 1" />
        </material>
      </visual>
    <visual name="masonry_course_6">
      <origin xyz="0 0 4.68" rpy="0 0 0" />
      <geometry>
        <box size="1.34 1.34 0.05" />
        </geometry>
      <material name="pale_stone_edges">
        <color rgba="0.76 0.73 0.64 1" />
        </material>
      </visual>
    <visual name="front_door">
      <origin xyz="0 0.642 0.93" rpy="0 0 0" />
      <geometry>
        <box size="0.44 0.04 0.82" />
        </geometry>
      <material name="blackened_bronze">
        <color rgba="0.03 0.025 0.018 1" />
        </material>
      </visual>
    <visual name="door_lintel">
      <origin xyz="0 0.66 1.4" rpy="0 0 0" />
      <geometry>
        <box size="0.58 0.07 0.15" />
        </geometry>
      <material name="pale_stone_edges">
        <color rgba="0.76 0.73 0.64 1" />
        </material>
      </visual>
    <visual name="front_window">
      <origin xyz="0 0.642 3.35" rpy="0 0 0" />
      <geometry>
        <box size="0.3 0.038 0.72" />
        </geometry>
      <material name="dark_glass">
        <color rgba="0.05 0.07 0.08 1" />
        </material>
      </visual>
    <visual name="rear_window">
      <origin xyz="0 -0.642 3.35" rpy="0 0 0" />
      <geometry>
        <box size="0.3 0.038 0.72" />
        </geometry>
      <material name="dark_glass">
        <color rgba="0.05 0.07 0.08 1" />
        </material>
      </visual>
    <visual name="side_window_0">
      <origin xyz="0.642 0 3.35" rpy="0 0 0" />
      <geometry>
        <box size="0.038 0.3 0.72" />
        </geometry>
      <material name="dark_glass">
        <color rgba="0.05 0.07 0.08 1" />
        </material>
      </visual>
    <visual name="side_window_1">
      <origin xyz="-0.642 0 3.35" rpy="0 0 0" />
      <geometry>
        <box size="0.038 0.3 0.72" />
        </geometry>
      <material name="dark_glass">
        <color rgba="0.05 0.07 0.08 1" />
        </material>
      </visual>
    <visual name="neck_band">
      <origin xyz="0 0 5.3" rpy="0 0 0" />
      <geometry>
        <box size="1.38 1.38 0.18" />
        </geometry>
      <material name="pale_stone_edges">
        <color rgba="0.76 0.73 0.64 1" />
        </material>
      </visual>
    <visual name="front_corbel_0">
      <origin xyz="-0.42 0.705 5.45" rpy="0 0 0" />
      <geometry>
        <box size="0.2 0.3 0.3" />
        </geometry>
      <material name="pale_stone_edges">
        <color rgba="0.76 0.73 0.64 1" />
        </material>
      </visual>
    <visual name="front_corbel_1">
      <origin xyz="0 0.705 5.45" rpy="0 0 0" />
      <geometry>
        <box size="0.2 0.3 0.3" />
        </geometry>
      <material name="pale_stone_edges">
        <color rgba="0.76 0.73 0.64 1" />
        </material>
      </visual>
    <visual name="front_corbel_2">
      <origin xyz="0.42 0.705 5.45" rpy="0 0 0" />
      <geometry>
        <box size="0.2 0.3 0.3" />
        </geometry>
      <material name="pale_stone_edges">
        <color rgba="0.76 0.73 0.64 1" />
        </material>
      </visual>
    <visual name="rear_corbel_0">
      <origin xyz="-0.42 -0.705 5.45" rpy="0 0 0" />
      <geometry>
        <box size="0.2 0.3 0.3" />
        </geometry>
      <material name="pale_stone_edges">
        <color rgba="0.76 0.73 0.64 1" />
        </material>
      </visual>
    <visual name="rear_corbel_1">
      <origin xyz="0 -0.705 5.45" rpy="0 0 0" />
      <geometry>
        <box size="0.2 0.3 0.3" />
        </geometry>
      <material name="pale_stone_edges">
        <color rgba="0.76 0.73 0.64 1" />
        </material>
      </visual>
    <visual name="rear_corbel_2">
      <origin xyz="0.42 -0.705 5.45" rpy="0 0 0" />
      <geometry>
        <box size="0.2 0.3 0.3" />
        </geometry>
      <material name="pale_stone_edges">
        <color rgba="0.76 0.73 0.64 1" />
        </material>
      </visual>
    <visual name="side_0_corbel_0">
      <origin xyz="0.705 -0.42 5.45" rpy="0 0 0" />
      <geometry>
        <box size="0.3 0.2 0.3" />
        </geometry>
      <material name="pale_stone_edges">
        <color rgba="0.76 0.73 0.64 1" />
        </material>
      </visual>
    <visual name="side_0_corbel_1">
      <origin xyz="0.705 0 5.45" rpy="0 0 0" />
      <geometry>
        <box size="0.3 0.2 0.3" />
        </geometry>
      <material name="pale_stone_edges">
        <color rgba="0.76 0.73 0.64 1" />
        </material>
      </visual>
    <visual name="side_0_corbel_2">
      <origin xyz="0.705 0.42 5.45" rpy="0 0 0" />
      <geometry>
        <box size="0.3 0.2 0.3" />
        </geometry>
      <material name="pale_stone_edges">
        <color rgba="0.76 0.73 0.64 1" />
        </material>
      </visual>
    <visual name="side_1_corbel_0">
      <origin xyz="-0.705 -0.42 5.45" rpy="0 0 0" />
      <geometry>
        <box size="0.3 0.2 0.3" />
        </geometry>
      <material name="pale_stone_edges">
        <color rgba="0.76 0.73 0.64 1" />
        </material>
      </visual>
    <visual name="side_1_corbel_1">
      <origin xyz="-0.705 0 5.45" rpy="0 0 0" />
      <geometry>
        <box size="0.3 0.2 0.3" />
        </geometry>
      <material name="pale_stone_edges">
        <color rgba="0.76 0.73 0.64 1" />
        </material>
      </visual>
    <visual name="side_1_corbel_2">
      <origin xyz="-0.705 0.42 5.45" rpy="0 0 0" />
      <geometry>
        <box size="0.3 0.2 0.3" />
        </geometry>
      <material name="pale_stone_edges">
        <color rgba="0.76 0.73 0.64 1" />
        </material>
      </visual>
    <visual name="corbel_slab">
      <origin xyz="0 0 5.55" rpy="0 0 0" />
      <geometry>
        <box size="1.58 1.58 0.18" />
        </geometry>
      <material name="pale_stone_edges">
        <color rgba="0.76 0.73 0.64 1" />
        </material>
      </visual>
    <visual name="clock_stage">
      <origin xyz="0 0 6.36" rpy="0 0 0" />
      <geometry>
        <box size="1.72 1.72 1.52" />
        </geometry>
      <material name="warm_limestone">
        <color rgba="0.66 0.62 0.53 1" />
        </material>
      </visual>
    <visual name="upper_cornice">
      <origin xyz="0 0 7.22" rpy="0 0 0" />
      <geometry>
        <box size="1.9 1.9 0.2" />
        </geometry>
      <material name="pale_stone_edges">
        <color rgba="0.76 0.73 0.64 1" />
        </material>
      </visual>
    <visual name="slate_roof">
      <origin xyz="0 0 7.27" rpy="0 0 0" />
      <geometry>
        <mesh filename="assets/meshes/clock_tower_pyramidal_slate_roof.obj" />
        </geometry>
      <material name="blue_grey_slate">
        <color rgba="0.16 0.19 0.22 1" />
        </material>
      </visual>
    <visual name="roof_finial">
      <origin xyz="0 0 8.46" rpy="0 0 0" />
      <geometry>
        <cylinder radius="0.045" length="0.55" />
        </geometry>
      <material name="blackened_bronze">
        <color rgba="0.03 0.025 0.018 1" />
        </material>
      </visual>
    <visual name="finial_ball">
      <origin xyz="0 0 8.76" rpy="0 0 0" />
      <geometry>
        <sphere radius="0.075" />
        </geometry>
      <material name="blackened_bronze">
        <color rgba="0.03 0.025 0.018 1" />
        </material>
      </visual>
    <visual name="front_recess_panel">
      <origin xyz="0 0.878 6.42" rpy="1.5708 -0 3.14159" />
      <geometry>
        <box size="0.96 0.96 0.045" />
        </geometry>
      <material name="recess_shadow_stone">
        <color rgba="0.36 0.34 0.31 1" />
        </material>
      </visual>
    <visual name="front_clock_rim">
      <origin xyz="0 0.9 6.42" rpy="1.5708 -0 3.14159" />
      <geometry>
        <cylinder radius="0.505" length="0.038" />
        </geometry>
      <material name="blackened_bronze">
        <color rgba="0.03 0.025 0.018 1" />
        </material>
      </visual>
    <visual name="front_dial">
      <origin xyz="0 0.921 6.42" rpy="1.5708 -0 3.14159" />
      <geometry>
        <cylinder radius="0.455" length="0.045" />
        </geometry>
      <material name="aged_ivory_enamel">
        <color rgba="0.92 0.88 0.72 1" />
        </material>
      </visual>
    <visual name="front_hour_mark_0">
      <origin xyz="0 0.9485 6.785" rpy="1.5708 -0 3.14159" />
      <geometry>
        <cylinder radius="0.032" length="0.014" />
        </geometry>
      <material name="blackened_bronze">
        <color rgba="0.03 0.025 0.018 1" />
        </material>
      </visual>
    <visual name="front_hour_mark_1">
      <origin xyz="-0.1825 0.9485 6.7361" rpy="1.5708 -0 3.14159" />
      <geometry>
        <cylinder radius="0.022" length="0.014" />
        </geometry>
      <material name="blackened_bronze">
        <color rgba="0.03 0.025 0.018 1" />
        </material>
      </visual>
    <visual name="front_hour_mark_2">
      <origin xyz="-0.316099 0.9485 6.6025" rpy="1.5708 -0 3.14159" />
      <geometry>
        <cylinder radius="0.022" length="0.014" />
        </geometry>
      <material name="blackened_bronze">
        <color rgba="0.03 0.025 0.018 1" />
        </material>
      </visual>
    <visual name="front_hour_mark_3">
      <origin xyz="-0.365 0.9485 6.42" rpy="1.5708 -0 3.14159" />
      <geometry>
        <cylinder radius="0.032" length="0.014" />
        </geometry>
      <material name="blackened_bronze">
        <color rgba="0.03 0.025 0.018 1" />
        </material>
      </visual>
    <visual name="front_hour_mark_4">
      <origin xyz="-0.316099 0.9485 6.2375" rpy="1.5708 -0 3.14159" />
      <geometry>
        <cylinder radius="0.022" length="0.014" />
        </geometry>
      <material name="blackened_bronze">
        <color rgba="0.03 0.025 0.018 1" />
        </material>
      </visual>
    <visual name="front_hour_mark_5">
      <origin xyz="-0.1825 0.9485 6.1039" rpy="1.5708 -0 3.14159" />
      <geometry>
        <cylinder radius="0.022" length="0.014" />
        </geometry>
      <material name="blackened_bronze">
        <color rgba="0.03 0.025 0.018 1" />
        </material>
      </visual>
    <visual name="front_hour_mark_6">
      <origin xyz="-4.46996e-17 0.9485 6.055" rpy="1.5708 -0 3.14159" />
      <geometry>
        <cylinder radius="0.032" length="0.014" />
        </geometry>
      <material name="blackened_bronze">
        <color rgba="0.03 0.025 0.018 1" />
        </material>
      </visual>
    <visual name="front_hour_mark_7">
      <origin xyz="0.1825 0.9485 6.1039" rpy="1.5708 -0 3.14159" />
      <geometry>
        <cylinder radius="0.022" length="0.014" />
        </geometry>
      <material name="blackened_bronze">
        <color rgba="0.03 0.025 0.018 1" />
        </material>
      </visual>
    <visual name="front_hour_mark_8">
      <origin xyz="0.316099 0.9485 6.2375" rpy="1.5708 -0 3.14159" />
      <geometry>
        <cylinder radius="0.022" length="0.014" />
        </geometry>
      <material name="blackened_bronze">
        <color rgba="0.03 0.025 0.018 1" />
        </material>
      </visual>
    <visual name="front_hour_mark_9">
      <origin xyz="0.365 0.9485 6.42" rpy="1.5708 -0 3.14159" />
      <geometry>
        <cylinder radius="0.032" length="0.014" />
        </geometry>
      <material name="blackened_bronze">
        <color rgba="0.03 0.025 0.018 1" />
        </material>
      </visual>
    <visual name="front_hour_mark_10">
      <origin xyz="0.316099 0.9485 6.6025" rpy="1.5708 -0 3.14159" />
      <geometry>
        <cylinder radius="0.022" length="0.014" />
        </geometry>
      <material name="blackened_bronze">
        <color rgba="0.03 0.025 0.018 1" />
        </material>
      </visual>
    <visual name="front_hour_mark_11">
      <origin xyz="0.1825 0.9485 6.7361" rpy="1.5708 -0 3.14159" />
      <geometry>
        <cylinder radius="0.022" length="0.014" />
        </geometry>
      <material name="blackened_bronze">
        <color rgba="0.03 0.025 0.018 1" />
        </material>
      </visual>
    <visual name="rear_recess_panel">
      <origin xyz="0 -0.878 6.42" rpy="1.5708 -0 0" />
      <geometry>
        <box size="0.96 0.96 0.045" />
        </geometry>
      <material name="recess_shadow_stone">
        <color rgba="0.36 0.34 0.31 1" />
        </material>
      </visual>
    <visual name="rear_clock_rim">
      <origin xyz="0 -0.9 6.42" rpy="1.5708 -0 0" />
      <geometry>
        <cylinder radius="0.505" length="0.038" />
        </geometry>
      <material name="blackened_bronze">
        <color rgba="0.03 0.025 0.018 1" />
        </material>
      </visual>
    <visual name="rear_dial">
      <origin xyz="0 -0.921 6.42" rpy="1.5708 -0 0" />
      <geometry>
        <cylinder radius="0.455" length="0.045" />
        </geometry>
      <material name="aged_ivory_enamel">
        <color rgba="0.92 0.88 0.72 1" />
        </material>
      </visual>
    <visual name="rear_hour_mark_0">
      <origin xyz="0 -0.9485 6.785" rpy="1.5708 -0 0" />
      <geometry>
        <cylinder radius="0.032" length="0.014" />
        </geometry>
      <material name="blackened_bronze">
        <color rgba="0.03 0.025 0.018 1" />
        </material>
      </visual>
    <visual name="rear_hour_mark_1">
      <origin xyz="0.1825 -0.9485 6.7361" rpy="1.5708 -0 0" />
      <geometry>
        <cylinder radius="0.022" length="0.014" />
        </geometry>
      <material name="blackened_bronze">
        <color rgba="0.03 0.025 0.018 1" />
        </material>
      </visual>
    <visual name="rear_hour_mark_2">
      <origin xyz="0.316099 -0.9485 6.6025" rpy="1.5708 -0 0" />
      <geometry>
        <cylinder radius="0.022" length="0.014" />
        </geometry>
      <material name="blackened_bronze">
        <color rgba="0.03 0.025 0.018 1" />
        </material>
      </visual>
    <visual name="rear_hour_mark_3">
      <origin xyz="0.365 -0.9485 6.42" rpy="1.5708 -0 0" />
      <geometry>
        <cylinder radius="0.032" length="0.014" />
        </geometry>
      <material name="blackened_bronze">
        <color rgba="0.03 0.025 0.018 1" />
        </material>
      </visual>
    <visual name="rear_hour_mark_4">
      <origin xyz="0.316099 -0.9485 6.2375" rpy="1.5708 -0 0" />
      <geometry>
        <cylinder radius="0.022" length="0.014" />
        </geometry>
      <material name="blackened_bronze">
        <color rgba="0.03 0.025 0.018 1" />
        </material>
      </visual>
    <visual name="rear_hour_mark_5">
      <origin xyz="0.1825 -0.9485 6.1039" rpy="1.5708 -0 0" />
      <geometry>
        <cylinder radius="0.022" length="0.014" />
        </geometry>
      <material name="blackened_bronze">
        <color rgba="0.03 0.025 0.018 1" />
        </material>
      </visual>
    <visual name="rear_hour_mark_6">
      <origin xyz="4.46996e-17 -0.9485 6.055" rpy="1.5708 -0 0" />
      <geometry>
        <cylinder radius="0.032" length="0.014" />
        </geometry>
      <material name="blackened_bronze">
        <color rgba="0.03 0.025 0.018 1" />
        </material>
      </visual>
    <visual name="rear_hour_mark_7">
      <origin xyz="-0.1825 -0.9485 6.1039" rpy="1.5708 -0 0" />
      <geometry>
        <cylinder radius="0.022" length="0.014" />
        </geometry>
      <material name="blackened_bronze">
        <color rgba="0.03 0.025 0.018 1" />
        </material>
      </visual>
    <visual name="rear_hour_mark_8">
      <origin xyz="-0.316099 -0.9485 6.2375" rpy="1.5708 -0 0" />
      <geometry>
        <cylinder radius="0.022" length="0.014" />
        </geometry>
      <material name="blackened_bronze">
        <color rgba="0.03 0.025 0.018 1" />
        </material>
      </visual>
    <visual name="rear_hour_mark_9">
      <origin xyz="-0.365 -0.9485 6.42" rpy="1.5708 -0 0" />
      <geometry>
        <cylinder radius="0.032" length="0.014" />
        </geometry>
      <material name="blackened_bronze">
        <color rgba="0.03 0.025 0.018 1" />
        </material>
      </visual>
    <visual name="rear_hour_mark_10">
      <origin xyz="-0.316099 -0.9485 6.6025" rpy="1.5708 -0 0" />
      <geometry>
        <cylinder radius="0.022" length="0.014" />
        </geometry>
      <material name="blackened_bronze">
        <color rgba="0.03 0.025 0.018 1" />
        </material>
      </visual>
    <visual name="rear_hour_mark_11">
      <origin xyz="-0.1825 -0.9485 6.7361" rpy="1.5708 -0 0" />
      <geometry>
        <cylinder radius="0.022" length="0.014" />
        </geometry>
      <material name="blackened_bronze">
        <color rgba="0.03 0.025 0.018 1" />
        </material>
      </visual>
    <visual name="side_0_recess_panel">
      <origin xyz="0.878 0 6.42" rpy="1.5708 -0 1.5708" />
      <geometry>
        <box size="0.96 0.96 0.045" />
        </geometry>
      <material name="recess_shadow_stone">
        <color rgba="0.36 0.34 0.31 1" />
        </material>
      </visual>
    <visual name="side_0_clock_rim">
      <origin xyz="0.9 0 6.42" rpy="1.5708 -0 1.5708" />
      <geometry>
        <cylinder radius="0.505" length="0.038" />
        </geometry>
      <material name="blackened_bronze">
        <color rgba="0.03 0.025 0.018 1" />
        </material>
      </visual>
    <visual name="side_0_dial">
      <origin xyz="0.921 0 6.42" rpy="1.5708 -0 1.5708" />
      <geometry>
        <cylinder radius="0.455" length="0.045" />
        </geometry>
      <material name="aged_ivory_enamel">
        <color rgba="0.92 0.88 0.72 1" />
        </material>
      </visual>
    <visual name="side_0_hour_mark_0">
      <origin xyz="0.9485 0 6.785" rpy="1.5708 -0 1.5708" />
      <geometry>
        <cylinder radius="0.032" length="0.014" />
        </geometry>
      <material name="blackened_bronze">
        <color rgba="0.03 0.025 0.018 1" />
        </material>
      </visual>
    <visual name="side_0_hour_mark_1">
      <origin xyz="0.9485 0.1825 6.7361" rpy="1.5708 -0 1.5708" />
      <geometry>
        <cylinder radius="0.022" length="0.014" />
        </geometry>
      <material name="blackened_bronze">
        <color rgba="0.03 0.025 0.018 1" />
        </material>
      </visual>
    <visual name="side_0_hour_mark_2">
      <origin xyz="0.9485 0.316099 6.6025" rpy="1.5708 -0 1.5708" />
      <geometry>
        <cylinder radius="0.022" length="0.014" />
        </geometry>
      <material name="blackened_bronze">
        <color rgba="0.03 0.025 0.018 1" />
        </material>
      </visual>
    <visual name="side_0_hour_mark_3">
      <origin xyz="0.9485 0.365 6.42" rpy="1.5708 -0 1.5708" />
      <geometry>
        <cylinder radius="0.032" length="0.014" />
        </geometry>
      <material name="blackened_bronze">
        <color rgba="0.03 0.025 0.018 1" />
        </material>
      </visual>
    <visual name="side_0_hour_mark_4">
      <origin xyz="0.9485 0.316099 6.2375" rpy="1.5708 -0 1.5708" />
      <geometry>
        <cylinder radius="0.022" length="0.014" />
        </geometry>
      <material name="blackened_bronze">
        <color rgba="0.03 0.025 0.018 1" />
        </material>
      </visual>
    <visual name="side_0_hour_mark_5">
      <origin xyz="0.9485 0.1825 6.1039" rpy="1.5708 -0 1.5708" />
      <geometry>
        <cylinder radius="0.022" length="0.014" />
        </geometry>
      <material name="blackened_bronze">
        <color rgba="0.03 0.025 0.018 1" />
        </material>
      </visual>
    <visual name="side_0_hour_mark_6">
      <origin xyz="0.9485 4.46996e-17 6.055" rpy="1.5708 -0 1.5708" />
      <geometry>
        <cylinder radius="0.032" length="0.014" />
        </geometry>
      <material name="blackened_bronze">
        <color rgba="0.03 0.025 0.018 1" />
        </material>
      </visual>
    <visual name="side_0_hour_mark_7">
      <origin xyz="0.9485 -0.1825 6.1039" rpy="1.5708 -0 1.5708" />
      <geometry>
        <cylinder radius="0.022" length="0.014" />
        </geometry>
      <material name="blackened_bronze">
        <color rgba="0.03 0.025 0.018 1" />
        </material>
      </visual>
    <visual name="side_0_hour_mark_8">
      <origin xyz="0.9485 -0.316099 6.2375" rpy="1.5708 -0 1.5708" />
      <geometry>
        <cylinder radius="0.022" length="0.014" />
        </geometry>
      <material name="blackened_bronze">
        <color rgba="0.03 0.025 0.018 1" />
        </material>
      </visual>
    <visual name="side_0_hour_mark_9">
      <origin xyz="0.9485 -0.365 6.42" rpy="1.5708 -0 1.5708" />
      <geometry>
        <cylinder radius="0.032" length="0.014" />
        </geometry>
      <material name="blackened_bronze">
        <color rgba="0.03 0.025 0.018 1" />
        </material>
      </visual>
    <visual name="side_0_hour_mark_10">
      <origin xyz="0.9485 -0.316099 6.6025" rpy="1.5708 -0 1.5708" />
      <geometry>
        <cylinder radius="0.022" length="0.014" />
        </geometry>
      <material name="blackened_bronze">
        <color rgba="0.03 0.025 0.018 1" />
        </material>
      </visual>
    <visual name="side_0_hour_mark_11">
      <origin xyz="0.9485 -0.1825 6.7361" rpy="1.5708 -0 1.5708" />
      <geometry>
        <cylinder radius="0.022" length="0.014" />
        </geometry>
      <material name="blackened_bronze">
        <color rgba="0.03 0.025 0.018 1" />
        </material>
      </visual>
    <visual name="side_1_recess_panel">
      <origin xyz="-0.878 0 6.42" rpy="1.5708 -0 -1.5708" />
      <geometry>
        <box size="0.96 0.96 0.045" />
        </geometry>
      <material name="recess_shadow_stone">
        <color rgba="0.36 0.34 0.31 1" />
        </material>
      </visual>
    <visual name="side_1_clock_rim">
      <origin xyz="-0.9 0 6.42" rpy="1.5708 -0 -1.5708" />
      <geometry>
        <cylinder radius="0.505" length="0.038" />
        </geometry>
      <material name="blackened_bronze">
        <color rgba="0.03 0.025 0.018 1" />
        </material>
      </visual>
    <visual name="side_1_dial">
      <origin xyz="-0.921 0 6.42" rpy="1.5708 -0 -1.5708" />
      <geometry>
        <cylinder radius="0.455" length="0.045" />
        </geometry>
      <material name="aged_ivory_enamel">
        <color rgba="0.92 0.88 0.72 1" />
        </material>
      </visual>
    <visual name="side_1_hour_mark_0">
      <origin xyz="-0.9485 0 6.785" rpy="1.5708 -0 -1.5708" />
      <geometry>
        <cylinder radius="0.032" length="0.014" />
        </geometry>
      <material name="blackened_bronze">
        <color rgba="0.03 0.025 0.018 1" />
        </material>
      </visual>
    <visual name="side_1_hour_mark_1">
      <origin xyz="-0.9485 -0.1825 6.7361" rpy="1.5708 -0 -1.5708" />
      <geometry>
        <cylinder radius="0.022" length="0.014" />
        </geometry>
      <material name="blackened_bronze">
        <color rgba="0.03 0.025 0.018 1" />
        </material>
      </visual>
    <visual name="side_1_hour_mark_2">
      <origin xyz="-0.9485 -0.316099 6.6025" rpy="1.5708 -0 -1.5708" />
      <geometry>
        <cylinder radius="0.022" length="0.014" />
        </geometry>
      <material name="blackened_bronze">
        <color rgba="0.03 0.025 0.018 1" />
        </material>
      </visual>
    <visual name="side_1_hour_mark_3">
      <origin xyz="-0.9485 -0.365 6.42" rpy="1.5708 -0 -1.5708" />
      <geometry>
        <cylinder radius="0.032" length="0.014" />
        </geometry>
      <material name="blackened_bronze">
        <color rgba="0.03 0.025 0.018 1" />
        </material>
      </visual>
    <visual name="side_1_hour_mark_4">
      <origin xyz="-0.9485 -0.316099 6.2375" rpy="1.5708 -0 -1.5708" />
      <geometry>
        <cylinder radius="0.022" length="0.014" />
        </geometry>
      <material name="blackened_bronze">
        <color rgba="0.03 0.025 0.018 1" />
        </material>
      </visual>
    <visual name="side_1_hour_mark_5">
      <origin xyz="-0.9485 -0.1825 6.1039" rpy="1.5708 -0 -1.5708" />
      <geometry>
        <cylinder radius="0.022" length="0.014" />
        </geometry>
      <material name="blackened_bronze">
        <color rgba="0.03 0.025 0.018 1" />
        </material>
      </visual>
    <visual name="side_1_hour_mark_6">
      <origin xyz="-0.9485 -4.46996e-17 6.055" rpy="1.5708 -0 -1.5708" />
      <geometry>
        <cylinder radius="0.032" length="0.014" />
        </geometry>
      <material name="blackened_bronze">
        <color rgba="0.03 0.025 0.018 1" />
        </material>
      </visual>
    <visual name="side_1_hour_mark_7">
      <origin xyz="-0.9485 0.1825 6.1039" rpy="1.5708 -0 -1.5708" />
      <geometry>
        <cylinder radius="0.022" length="0.014" />
        </geometry>
      <material name="blackened_bronze">
        <color rgba="0.03 0.025 0.018 1" />
        </material>
      </visual>
    <visual name="side_1_hour_mark_8">
      <origin xyz="-0.9485 0.316099 6.2375" rpy="1.5708 -0 -1.5708" />
      <geometry>
        <cylinder radius="0.022" length="0.014" />
        </geometry>
      <material name="blackened_bronze">
        <color rgba="0.03 0.025 0.018 1" />
        </material>
      </visual>
    <visual name="side_1_hour_mark_9">
      <origin xyz="-0.9485 0.365 6.42" rpy="1.5708 -0 -1.5708" />
      <geometry>
        <cylinder radius="0.032" length="0.014" />
        </geometry>
      <material name="blackened_bronze">
        <color rgba="0.03 0.025 0.018 1" />
        </material>
      </visual>
    <visual name="side_1_hour_mark_10">
      <origin xyz="-0.9485 0.316099 6.6025" rpy="1.5708 -0 -1.5708" />
      <geometry>
        <cylinder radius="0.022" length="0.014" />
        </geometry>
      <material name="blackened_bronze">
        <color rgba="0.03 0.025 0.018 1" />
        </material>
      </visual>
    <visual name="side_1_hour_mark_11">
      <origin xyz="-0.9485 0.1825 6.7361" rpy="1.5708 -0 -1.5708" />
      <geometry>
        <cylinder radius="0.022" length="0.014" />
        </geometry>
      <material name="blackened_bronze">
        <color rgba="0.03 0.025 0.018 1" />
        </material>
      </visual>
    <collision name="ground_plinth">
      <origin xyz="0 0 0.14" rpy="0 0 0" />
      <geometry>
        <box size="2.15 2.15 0.28" />
        </geometry>
      </collision>
    <collision name="stepped_plinth">
      <origin xyz="0 0 0.38" rpy="0 0 0" />
      <geometry>
        <box size="1.82 1.82 0.3" />
        </geometry>
      </collision>
    <collision name="square_shaft">
      <origin xyz="0 0 2.86" rpy="0 0 0" />
      <geometry>
        <box size="1.24 1.24 4.8" />
        </geometry>
      </collision>
    <collision name="quoin_-1_-1">
      <origin xyz="-0.545 -0.545 2.86" rpy="0 0 0" />
      <geometry>
        <box size="0.19 0.19 4.92" />
        </geometry>
      </collision>
    <collision name="quoin_-1_1">
      <origin xyz="-0.545 0.545 2.86" rpy="0 0 0" />
      <geometry>
        <box size="0.19 0.19 4.92" />
        </geometry>
      </collision>
    <collision name="quoin_1_-1">
      <origin xyz="0.545 -0.545 2.86" rpy="0 0 0" />
      <geometry>
        <box size="0.19 0.19 4.92" />
        </geometry>
      </collision>
    <collision name="quoin_1_1">
      <origin xyz="0.545 0.545 2.86" rpy="0 0 0" />
      <geometry>
        <box size="0.19 0.19 4.92" />
        </geometry>
      </collision>
    <collision name="masonry_course_0">
      <origin xyz="0 0 0.84" rpy="0 0 0" />
      <geometry>
        <box size="1.34 1.34 0.05" />
        </geometry>
      </collision>
    <collision name="masonry_course_1">
      <origin xyz="0 0 1.48" rpy="0 0 0" />
      <geometry>
        <box size="1.34 1.34 0.05" />
        </geometry>
      </collision>
    <collision name="masonry_course_2">
      <origin xyz="0 0 2.12" rpy="0 0 0" />
      <geometry>
        <box size="1.34 1.34 0.05" />
        </geometry>
      </collision>
    <collision name="masonry_course_3">
      <origin xyz="0 0 2.76" rpy="0 0 0" />
      <geometry>
        <box size="1.34 1.34 0.05" />
        </geometry>
      </collision>
    <collision name="masonry_course_4">
      <origin xyz="0 0 3.4" rpy="0 0 0" />
      <geometry>
        <box size="1.34 1.34 0.05" />
        </geometry>
      </collision>
    <collision name="masonry_course_5">
      <origin xyz="0 0 4.04" rpy="0 0 0" />
      <geometry>
        <box size="1.34 1.34 0.05" />
        </geometry>
      </collision>
    <collision name="masonry_course_6">
      <origin xyz="0 0 4.68" rpy="0 0 0" />
      <geometry>
        <box size="1.34 1.34 0.05" />
        </geometry>
      </collision>
    <collision name="front_door">
      <origin xyz="0 0.642 0.93" rpy="0 0 0" />
      <geometry>
        <box size="0.44 0.04 0.82" />
        </geometry>
      </collision>
    <collision name="door_lintel">
      <origin xyz="0 0.66 1.4" rpy="0 0 0" />
      <geometry>
        <box size="0.58 0.07 0.15" />
        </geometry>
      </collision>
    <collision name="front_window">
      <origin xyz="0 0.642 3.35" rpy="0 0 0" />
      <geometry>
        <box size="0.3 0.038 0.72" />
        </geometry>
      </collision>
    <collision name="rear_window">
      <origin xyz="0 -0.642 3.35" rpy="0 0 0" />
      <geometry>
        <box size="0.3 0.038 0.72" />
        </geometry>
      </collision>
    <collision name="side_window_0">
      <origin xyz="0.642 0 3.35" rpy="0 0 0" />
      <geometry>
        <box size="0.038 0.3 0.72" />
        </geometry>
      </collision>
    <collision name="side_window_1">
      <origin xyz="-0.642 0 3.35" rpy="0 0 0" />
      <geometry>
        <box size="0.038 0.3 0.72" />
        </geometry>
      </collision>
    <collision name="neck_band">
      <origin xyz="0 0 5.3" rpy="0 0 0" />
      <geometry>
        <box size="1.38 1.38 0.18" />
        </geometry>
      </collision>
    <collision name="front_corbel_0">
      <origin xyz="-0.42 0.705 5.45" rpy="0 0 0" />
      <geometry>
        <box size="0.2 0.3 0.3" />
        </geometry>
      </collision>
    <collision name="front_corbel_1">
      <origin xyz="0 0.705 5.45" rpy="0 0 0" />
      <geometry>
        <box size="0.2 0.3 0.3" />
        </geometry>
      </collision>
    <collision name="front_corbel_2">
      <origin xyz="0.42 0.705 5.45" rpy="0 0 0" />
      <geometry>
        <box size="0.2 0.3 0.3" />
        </geometry>
      </collision>
    <collision name="rear_corbel_0">
      <origin xyz="-0.42 -0.705 5.45" rpy="0 0 0" />
      <geometry>
        <box size="0.2 0.3 0.3" />
        </geometry>
      </collision>
    <collision name="rear_corbel_1">
      <origin xyz="0 -0.705 5.45" rpy="0 0 0" />
      <geometry>
        <box size="0.2 0.3 0.3" />
        </geometry>
      </collision>
    <collision name="rear_corbel_2">
      <origin xyz="0.42 -0.705 5.45" rpy="0 0 0" />
      <geometry>
        <box size="0.2 0.3 0.3" />
        </geometry>
      </collision>
    <collision name="side_0_corbel_0">
      <origin xyz="0.705 -0.42 5.45" rpy="0 0 0" />
      <geometry>
        <box size="0.3 0.2 0.3" />
        </geometry>
      </collision>
    <collision name="side_0_corbel_1">
      <origin xyz="0.705 0 5.45" rpy="0 0 0" />
      <geometry>
        <box size="0.3 0.2 0.3" />
        </geometry>
      </collision>
    <collision name="side_0_corbel_2">
      <origin xyz="0.705 0.42 5.45" rpy="0 0 0" />
      <geometry>
        <box size="0.3 0.2 0.3" />
        </geometry>
      </collision>
    <collision name="side_1_corbel_0">
      <origin xyz="-0.705 -0.42 5.45" rpy="0 0 0" />
      <geometry>
        <box size="0.3 0.2 0.3" />
        </geometry>
      </collision>
    <collision name="side_1_corbel_1">
      <origin xyz="-0.705 0 5.45" rpy="0 0 0" />
      <geometry>
        <box size="0.3 0.2 0.3" />
        </geometry>
      </collision>
    <collision name="side_1_corbel_2">
      <origin xyz="-0.705 0.42 5.45" rpy="0 0 0" />
      <geometry>
        <box size="0.3 0.2 0.3" />
        </geometry>
      </collision>
    <collision name="corbel_slab">
      <origin xyz="0 0 5.55" rpy="0 0 0" />
      <geometry>
        <box size="1.58 1.58 0.18" />
        </geometry>
      </collision>
    <collision name="clock_stage">
      <origin xyz="0 0 6.36" rpy="0 0 0" />
      <geometry>
        <box size="1.72 1.72 1.52" />
        </geometry>
      </collision>
    <collision name="upper_cornice">
      <origin xyz="0 0 7.22" rpy="0 0 0" />
      <geometry>
        <box size="1.9 1.9 0.2" />
        </geometry>
      </collision>
    <collision name="slate_roof">
      <origin xyz="0 0 7.27" rpy="0 0 0" />
      <geometry>
        <mesh filename="assets/meshes/clock_tower_pyramidal_slate_roof.obj" />
        </geometry>
      </collision>
    <collision name="roof_finial">
      <origin xyz="0 0 8.46" rpy="0 0 0" />
      <geometry>
        <cylinder radius="0.045" length="0.55" />
        </geometry>
      </collision>
    <collision name="finial_ball">
      <origin xyz="0 0 8.76" rpy="0 0 0" />
      <geometry>
        <sphere radius="0.075" />
        </geometry>
      </collision>
    <collision name="front_recess_panel">
      <origin xyz="0 0.878 6.42" rpy="1.5708 -0 3.14159" />
      <geometry>
        <box size="0.96 0.96 0.045" />
        </geometry>
      </collision>
    <collision name="front_clock_rim">
      <origin xyz="0 0.9 6.42" rpy="1.5708 -0 3.14159" />
      <geometry>
        <cylinder radius="0.505" length="0.038" />
        </geometry>
      </collision>
    <collision name="front_dial">
      <origin xyz="0 0.921 6.42" rpy="1.5708 -0 3.14159" />
      <geometry>
        <cylinder radius="0.455" length="0.045" />
        </geometry>
      </collision>
    <collision name="front_hour_mark_0">
      <origin xyz="0 0.9485 6.785" rpy="1.5708 -0 3.14159" />
      <geometry>
        <cylinder radius="0.032" length="0.014" />
        </geometry>
      </collision>
    <collision name="front_hour_mark_1">
      <origin xyz="-0.1825 0.9485 6.7361" rpy="1.5708 -0 3.14159" />
      <geometry>
        <cylinder radius="0.022" length="0.014" />
        </geometry>
      </collision>
    <collision name="front_hour_mark_2">
      <origin xyz="-0.316099 0.9485 6.6025" rpy="1.5708 -0 3.14159" />
      <geometry>
        <cylinder radius="0.022" length="0.014" />
        </geometry>
      </collision>
    <collision name="front_hour_mark_3">
      <origin xyz="-0.365 0.9485 6.42" rpy="1.5708 -0 3.14159" />
      <geometry>
        <cylinder radius="0.032" length="0.014" />
        </geometry>
      </collision>
    <collision name="front_hour_mark_4">
      <origin xyz="-0.316099 0.9485 6.2375" rpy="1.5708 -0 3.14159" />
      <geometry>
        <cylinder radius="0.022" length="0.014" />
        </geometry>
      </collision>
    <collision name="front_hour_mark_5">
      <origin xyz="-0.1825 0.9485 6.1039" rpy="1.5708 -0 3.14159" />
      <geometry>
        <cylinder radius="0.022" length="0.014" />
        </geometry>
      </collision>
    <collision name="front_hour_mark_6">
      <origin xyz="-4.46996e-17 0.9485 6.055" rpy="1.5708 -0 3.14159" />
      <geometry>
        <cylinder radius="0.032" length="0.014" />
        </geometry>
      </collision>
    <collision name="front_hour_mark_7">
      <origin xyz="0.1825 0.9485 6.1039" rpy="1.5708 -0 3.14159" />
      <geometry>
        <cylinder radius="0.022" length="0.014" />
        </geometry>
      </collision>
    <collision name="front_hour_mark_8">
      <origin xyz="0.316099 0.9485 6.2375" rpy="1.5708 -0 3.14159" />
      <geometry>
        <cylinder radius="0.022" length="0.014" />
        </geometry>
      </collision>
    <collision name="front_hour_mark_9">
      <origin xyz="0.365 0.9485 6.42" rpy="1.5708 -0 3.14159" />
      <geometry>
        <cylinder radius="0.032" length="0.014" />
        </geometry>
      </collision>
    <collision name="front_hour_mark_10">
      <origin xyz="0.316099 0.9485 6.6025" rpy="1.5708 -0 3.14159" />
      <geometry>
        <cylinder radius="0.022" length="0.014" />
        </geometry>
      </collision>
    <collision name="front_hour_mark_11">
      <origin xyz="0.1825 0.9485 6.7361" rpy="1.5708 -0 3.14159" />
      <geometry>
        <cylinder radius="0.022" length="0.014" />
        </geometry>
      </collision>
    <collision name="rear_recess_panel">
      <origin xyz="0 -0.878 6.42" rpy="1.5708 -0 0" />
      <geometry>
        <box size="0.96 0.96 0.045" />
        </geometry>
      </collision>
    <collision name="rear_clock_rim">
      <origin xyz="0 -0.9 6.42" rpy="1.5708 -0 0" />
      <geometry>
        <cylinder radius="0.505" length="0.038" />
        </geometry>
      </collision>
    <collision name="rear_dial">
      <origin xyz="0 -0.921 6.42" rpy="1.5708 -0 0" />
      <geometry>
        <cylinder radius="0.455" length="0.045" />
        </geometry>
      </collision>
    <collision name="rear_hour_mark_0">
      <origin xyz="0 -0.9485 6.785" rpy="1.5708 -0 0" />
      <geometry>
        <cylinder radius="0.032" length="0.014" />
        </geometry>
      </collision>
    <collision name="rear_hour_mark_1">
      <origin xyz="0.1825 -0.9485 6.7361" rpy="1.5708 -0 0" />
      <geometry>
        <cylinder radius="0.022" length="0.014" />
        </geometry>
      </collision>
    <collision name="rear_hour_mark_2">
      <origin xyz="0.316099 -0.9485 6.6025" rpy="1.5708 -0 0" />
      <geometry>
        <cylinder radius="0.022" length="0.014" />
        </geometry>
      </collision>
    <collision name="rear_hour_mark_3">
      <origin xyz="0.365 -0.9485 6.42" rpy="1.5708 -0 0" />
      <geometry>
        <cylinder radius="0.032" length="0.014" />
        </geometry>
      </collision>
    <collision name="rear_hour_mark_4">
      <origin xyz="0.316099 -0.9485 6.2375" rpy="1.5708 -0 0" />
      <geometry>
        <cylinder radius="0.022" length="0.014" />
        </geometry>
      </collision>
    <collision name="rear_hour_mark_5">
      <origin xyz="0.1825 -0.9485 6.1039" rpy="1.5708 -0 0" />
      <geometry>
        <cylinder radius="0.022" length="0.014" />
        </geometry>
      </collision>
    <collision name="rear_hour_mark_6">
      <origin xyz="4.46996e-17 -0.9485 6.055" rpy="1.5708 -0 0" />
      <geometry>
        <cylinder radius="0.032" length="0.014" />
        </geometry>
      </collision>
    <collision name="rear_hour_mark_7">
      <origin xyz="-0.1825 -0.9485 6.1039" rpy="1.5708 -0 0" />
      <geometry>
        <cylinder radius="0.022" length="0.014" />
        </geometry>
      </collision>
    <collision name="rear_hour_mark_8">
      <origin xyz="-0.316099 -0.9485 6.2375" rpy="1.5708 -0 0" />
      <geometry>
        <cylinder radius="0.022" length="0.014" />
        </geometry>
      </collision>
    <collision name="rear_hour_mark_9">
      <origin xyz="-0.365 -0.9485 6.42" rpy="1.5708 -0 0" />
      <geometry>
        <cylinder radius="0.032" length="0.014" />
        </geometry>
      </collision>
    <collision name="rear_hour_mark_10">
      <origin xyz="-0.316099 -0.9485 6.6025" rpy="1.5708 -0 0" />
      <geometry>
        <cylinder radius="0.022" length="0.014" />
        </geometry>
      </collision>
    <collision name="rear_hour_mark_11">
      <origin xyz="-0.1825 -0.9485 6.7361" rpy="1.5708 -0 0" />
      <geometry>
        <cylinder radius="0.022" length="0.014" />
        </geometry>
      </collision>
    <collision name="side_0_recess_panel">
      <origin xyz="0.878 0 6.42" rpy="1.5708 -0 1.5708" />
      <geometry>
        <box size="0.96 0.96 0.045" />
        </geometry>
      </collision>
    <collision name="side_0_clock_rim">
      <origin xyz="0.9 0 6.42" rpy="1.5708 -0 1.5708" />
      <geometry>
        <cylinder radius="0.505" length="0.038" />
        </geometry>
      </collision>
    <collision name="side_0_dial">
      <origin xyz="0.921 0 6.42" rpy="1.5708 -0 1.5708" />
      <geometry>
        <cylinder radius="0.455" length="0.045" />
        </geometry>
      </collision>
    <collision name="side_0_hour_mark_0">
      <origin xyz="0.9485 0 6.785" rpy="1.5708 -0 1.5708" />
      <geometry>
        <cylinder radius="0.032" length="0.014" />
        </geometry>
      </collision>
    <collision name="side_0_hour_mark_1">
      <origin xyz="0.9485 0.1825 6.7361" rpy="1.5708 -0 1.5708" />
      <geometry>
        <cylinder radius="0.022" length="0.014" />
        </geometry>
      </collision>
    <collision name="side_0_hour_mark_2">
      <origin xyz="0.9485 0.316099 6.6025" rpy="1.5708 -0 1.5708" />
      <geometry>
        <cylinder radius="0.022" length="0.014" />
        </geometry>
      </collision>
    <collision name="side_0_hour_mark_3">
      <origin xyz="0.9485 0.365 6.42" rpy="1.5708 -0 1.5708" />
      <geometry>
        <cylinder radius="0.032" length="0.014" />
        </geometry>
      </collision>
    <collision name="side_0_hour_mark_4">
      <origin xyz="0.9485 0.316099 6.2375" rpy="1.5708 -0 1.5708" />
      <geometry>
        <cylinder radius="0.022" length="0.014" />
        </geometry>
      </collision>
    <collision name="side_0_hour_mark_5">
      <origin xyz="0.9485 0.1825 6.1039" rpy="1.5708 -0 1.5708" />
      <geometry>
        <cylinder radius="0.022" length="0.014" />
        </geometry>
      </collision>
    <collision name="side_0_hour_mark_6">
      <origin xyz="0.9485 4.46996e-17 6.055" rpy="1.5708 -0 1.5708" />
      <geometry>
        <cylinder radius="0.032" length="0.014" />
        </geometry>
      </collision>
    <collision name="side_0_hour_mark_7">
      <origin xyz="0.9485 -0.1825 6.1039" rpy="1.5708 -0 1.5708" />
      <geometry>
        <cylinder radius="0.022" length="0.014" />
        </geometry>
      </collision>
    <collision name="side_0_hour_mark_8">
      <origin xyz="0.9485 -0.316099 6.2375" rpy="1.5708 -0 1.5708" />
      <geometry>
        <cylinder radius="0.022" length="0.014" />
        </geometry>
      </collision>
    <collision name="side_0_hour_mark_9">
      <origin xyz="0.9485 -0.365 6.42" rpy="1.5708 -0 1.5708" />
      <geometry>
        <cylinder radius="0.032" length="0.014" />
        </geometry>
      </collision>
    <collision name="side_0_hour_mark_10">
      <origin xyz="0.9485 -0.316099 6.6025" rpy="1.5708 -0 1.5708" />
      <geometry>
        <cylinder radius="0.022" length="0.014" />
        </geometry>
      </collision>
    <collision name="side_0_hour_mark_11">
      <origin xyz="0.9485 -0.1825 6.7361" rpy="1.5708 -0 1.5708" />
      <geometry>
        <cylinder radius="0.022" length="0.014" />
        </geometry>
      </collision>
    <collision name="side_1_recess_panel">
      <origin xyz="-0.878 0 6.42" rpy="1.5708 -0 -1.5708" />
      <geometry>
        <box size="0.96 0.96 0.045" />
        </geometry>
      </collision>
    <collision name="side_1_clock_rim">
      <origin xyz="-0.9 0 6.42" rpy="1.5708 -0 -1.5708" />
      <geometry>
        <cylinder radius="0.505" length="0.038" />
        </geometry>
      </collision>
    <collision name="side_1_dial">
      <origin xyz="-0.921 0 6.42" rpy="1.5708 -0 -1.5708" />
      <geometry>
        <cylinder radius="0.455" length="0.045" />
        </geometry>
      </collision>
    <collision name="side_1_hour_mark_0">
      <origin xyz="-0.9485 0 6.785" rpy="1.5708 -0 -1.5708" />
      <geometry>
        <cylinder radius="0.032" length="0.014" />
        </geometry>
      </collision>
    <collision name="side_1_hour_mark_1">
      <origin xyz="-0.9485 -0.1825 6.7361" rpy="1.5708 -0 -1.5708" />
      <geometry>
        <cylinder radius="0.022" length="0.014" />
        </geometry>
      </collision>
    <collision name="side_1_hour_mark_2">
      <origin xyz="-0.9485 -0.316099 6.6025" rpy="1.5708 -0 -1.5708" />
      <geometry>
        <cylinder radius="0.022" length="0.014" />
        </geometry>
      </collision>
    <collision name="side_1_hour_mark_3">
      <origin xyz="-0.9485 -0.365 6.42" rpy="1.5708 -0 -1.5708" />
      <geometry>
        <cylinder radius="0.032" length="0.014" />
        </geometry>
      </collision>
    <collision name="side_1_hour_mark_4">
      <origin xyz="-0.9485 -0.316099 6.2375" rpy="1.5708 -0 -1.5708" />
      <geometry>
        <cylinder radius="0.022" length="0.014" />
        </geometry>
      </collision>
    <collision name="side_1_hour_mark_5">
      <origin xyz="-0.9485 -0.1825 6.1039" rpy="1.5708 -0 -1.5708" />
      <geometry>
        <cylinder radius="0.022" length="0.014" />
        </geometry>
      </collision>
    <collision name="side_1_hour_mark_6">
      <origin xyz="-0.9485 -4.46996e-17 6.055" rpy="1.5708 -0 -1.5708" />
      <geometry>
        <cylinder radius="0.032" length="0.014" />
        </geometry>
      </collision>
    <collision name="side_1_hour_mark_7">
      <origin xyz="-0.9485 0.1825 6.1039" rpy="1.5708 -0 -1.5708" />
      <geometry>
        <cylinder radius="0.022" length="0.014" />
        </geometry>
      </collision>
    <collision name="side_1_hour_mark_8">
      <origin xyz="-0.9485 0.316099 6.2375" rpy="1.5708 -0 -1.5708" />
      <geometry>
        <cylinder radius="0.022" length="0.014" />
        </geometry>
      </collision>
    <collision name="side_1_hour_mark_9">
      <origin xyz="-0.9485 0.365 6.42" rpy="1.5708 -0 -1.5708" />
      <geometry>
        <cylinder radius="0.032" length="0.014" />
        </geometry>
      </collision>
    <collision name="side_1_hour_mark_10">
      <origin xyz="-0.9485 0.316099 6.6025" rpy="1.5708 -0 -1.5708" />
      <geometry>
        <cylinder radius="0.022" length="0.014" />
        </geometry>
      </collision>
    <collision name="side_1_hour_mark_11">
      <origin xyz="-0.9485 0.1825 6.7361" rpy="1.5708 -0 -1.5708" />
      <geometry>
        <cylinder radius="0.022" length="0.014" />
        </geometry>
      </collision>
    </link>
  <link name="front_hour_hand">
    <visual name="hour_blade">
      <origin xyz="0 0.1535 0" rpy="0 0 0" />
      <geometry>
        <box size="0.046 0.263 0.016" />
        </geometry>
      <material name="blackened_bronze">
        <color rgba="0.03 0.025 0.018 1" />
        </material>
      </visual>
    <visual name="hour_counterweight">
      <origin xyz="0 -0.046 0" rpy="0 0 0" />
      <geometry>
        <box size="0.02852 0.048 0.014" />
        </geometry>
      <material name="blackened_bronze">
        <color rgba="0.03 0.025 0.018 1" />
        </material>
      </visual>
    <visual name="hour_boss">
      <geometry>
        <cylinder radius="0.044" length="0.02" />
        </geometry>
      <material name="blackened_bronze">
        <color rgba="0.03 0.025 0.018 1" />
        </material>
      </visual>
    <visual name="hour_arbor">
      <origin xyz="0 0 -0.01275" rpy="0 0 0" />
      <geometry>
        <cylinder radius="0.016" length="0.0375" />
        </geometry>
      <material name="blackened_bronze">
        <color rgba="0.03 0.025 0.018 1" />
        </material>
      </visual>
    <collision name="hour_blade">
      <origin xyz="0 0.1535 0" rpy="0 0 0" />
      <geometry>
        <box size="0.046 0.263 0.016" />
        </geometry>
      </collision>
    <collision name="hour_counterweight">
      <origin xyz="0 -0.046 0" rpy="0 0 0" />
      <geometry>
        <box size="0.02852 0.048 0.014" />
        </geometry>
      </collision>
    <collision name="hour_boss">
      <geometry>
        <cylinder radius="0.044" length="0.02" />
        </geometry>
      </collision>
    <collision name="hour_arbor">
      <origin xyz="0 0 -0.01275" rpy="0 0 0" />
      <geometry>
        <cylinder radius="0.016" length="0.0375" />
        </geometry>
      </collision>
    </link>
  <link name="front_minute_hand">
    <visual name="minute_blade">
      <origin xyz="0 0.206 0" rpy="0 0 0" />
      <geometry>
        <box size="0.03 0.368 0.016" />
        </geometry>
      <material name="blackened_bronze">
        <color rgba="0.03 0.025 0.018 1" />
        </material>
      </visual>
    <visual name="minute_counterweight">
      <origin xyz="0 -0.0635 0" rpy="0 0 0" />
      <geometry>
        <box size="0.0186 0.083 0.014" />
        </geometry>
      <material name="blackened_bronze">
        <color rgba="0.03 0.025 0.018 1" />
        </material>
      </visual>
    <visual name="minute_boss">
      <geometry>
        <cylinder radius="0.05" length="0.02" />
        </geometry>
      <material name="blackened_bronze">
        <color rgba="0.03 0.025 0.018 1" />
        </material>
      </visual>
    <visual name="minute_arbor">
      <origin xyz="0 0 -0.03375" rpy="0 0 0" />
      <geometry>
        <cylinder radius="0.012" length="0.0795" />
        </geometry>
      <material name="blackened_bronze">
        <color rgba="0.03 0.025 0.018 1" />
        </material>
      </visual>
    <collision name="minute_blade">
      <origin xyz="0 0.206 0" rpy="0 0 0" />
      <geometry>
        <box size="0.03 0.368 0.016" />
        </geometry>
      </collision>
    <collision name="minute_counterweight">
      <origin xyz="0 -0.0635 0" rpy="0 0 0" />
      <geometry>
        <box size="0.0186 0.083 0.014" />
        </geometry>
      </collision>
    <collision name="minute_boss">
      <geometry>
        <cylinder radius="0.05" length="0.02" />
        </geometry>
      </collision>
    <collision name="minute_arbor">
      <origin xyz="0 0 -0.03375" rpy="0 0 0" />
      <geometry>
        <cylinder radius="0.012" length="0.0795" />
        </geometry>
      </collision>
    </link>
  <link name="rear_hour_hand">
    <visual name="hour_blade">
      <origin xyz="0 0.1535 0" rpy="0 0 0" />
      <geometry>
        <box size="0.046 0.263 0.016" />
        </geometry>
      <material name="blackened_bronze">
        <color rgba="0.03 0.025 0.018 1" />
        </material>
      </visual>
    <visual name="hour_counterweight">
      <origin xyz="0 -0.046 0" rpy="0 0 0" />
      <geometry>
        <box size="0.02852 0.048 0.014" />
        </geometry>
      <material name="blackened_bronze">
        <color rgba="0.03 0.025 0.018 1" />
        </material>
      </visual>
    <visual name="hour_boss">
      <geometry>
        <cylinder radius="0.044" length="0.02" />
        </geometry>
      <material name="blackened_bronze">
        <color rgba="0.03 0.025 0.018 1" />
        </material>
      </visual>
    <visual name="hour_arbor">
      <origin xyz="0 0 -0.01275" rpy="0 0 0" />
      <geometry>
        <cylinder radius="0.016" length="0.0375" />
        </geometry>
      <material name="blackened_bronze">
        <color rgba="0.03 0.025 0.018 1" />
        </material>
      </visual>
    <collision name="hour_blade">
      <origin xyz="0 0.1535 0" rpy="0 0 0" />
      <geometry>
        <box size="0.046 0.263 0.016" />
        </geometry>
      </collision>
    <collision name="hour_counterweight">
      <origin xyz="0 -0.046 0" rpy="0 0 0" />
      <geometry>
        <box size="0.02852 0.048 0.014" />
        </geometry>
      </collision>
    <collision name="hour_boss">
      <geometry>
        <cylinder radius="0.044" length="0.02" />
        </geometry>
      </collision>
    <collision name="hour_arbor">
      <origin xyz="0 0 -0.01275" rpy="0 0 0" />
      <geometry>
        <cylinder radius="0.016" length="0.0375" />
        </geometry>
      </collision>
    </link>
  <link name="rear_minute_hand">
    <visual name="minute_blade">
      <origin xyz="0 0.206 0" rpy="0 0 0" />
      <geometry>
        <box size="0.03 0.368 0.016" />
        </geometry>
      <material name="blackened_bronze">
        <color rgba="0.03 0.025 0.018 1" />
        </material>
      </visual>
    <visual name="minute_counterweight">
      <origin xyz="0 -0.0635 0" rpy="0 0 0" />
      <geometry>
        <box size="0.0186 0.083 0.014" />
        </geometry>
      <material name="blackened_bronze">
        <color rgba="0.03 0.025 0.018 1" />
        </material>
      </visual>
    <visual name="minute_boss">
      <geometry>
        <cylinder radius="0.05" length="0.02" />
        </geometry>
      <material name="blackened_bronze">
        <color rgba="0.03 0.025 0.018 1" />
        </material>
      </visual>
    <visual name="minute_arbor">
      <origin xyz="0 0 -0.03375" rpy="0 0 0" />
      <geometry>
        <cylinder radius="0.012" length="0.0795" />
        </geometry>
      <material name="blackened_bronze">
        <color rgba="0.03 0.025 0.018 1" />
        </material>
      </visual>
    <collision name="minute_blade">
      <origin xyz="0 0.206 0" rpy="0 0 0" />
      <geometry>
        <box size="0.03 0.368 0.016" />
        </geometry>
      </collision>
    <collision name="minute_counterweight">
      <origin xyz="0 -0.0635 0" rpy="0 0 0" />
      <geometry>
        <box size="0.0186 0.083 0.014" />
        </geometry>
      </collision>
    <collision name="minute_boss">
      <geometry>
        <cylinder radius="0.05" length="0.02" />
        </geometry>
      </collision>
    <collision name="minute_arbor">
      <origin xyz="0 0 -0.03375" rpy="0 0 0" />
      <geometry>
        <cylinder radius="0.012" length="0.0795" />
        </geometry>
      </collision>
    </link>
  <link name="side_0_hour_hand">
    <visual name="hour_blade">
      <origin xyz="0 0.1535 0" rpy="0 0 0" />
      <geometry>
        <box size="0.046 0.263 0.016" />
        </geometry>
      <material name="blackened_bronze">
        <color rgba="0.03 0.025 0.018 1" />
        </material>
      </visual>
    <visual name="hour_counterweight">
      <origin xyz="0 -0.046 0" rpy="0 0 0" />
      <geometry>
        <box size="0.02852 0.048 0.014" />
        </geometry>
      <material name="blackened_bronze">
        <color rgba="0.03 0.025 0.018 1" />
        </material>
      </visual>
    <visual name="hour_boss">
      <geometry>
        <cylinder radius="0.044" length="0.02" />
        </geometry>
      <material name="blackened_bronze">
        <color rgba="0.03 0.025 0.018 1" />
        </material>
      </visual>
    <visual name="hour_arbor">
      <origin xyz="0 0 -0.01275" rpy="0 0 0" />
      <geometry>
        <cylinder radius="0.016" length="0.0375" />
        </geometry>
      <material name="blackened_bronze">
        <color rgba="0.03 0.025 0.018 1" />
        </material>
      </visual>
    <collision name="hour_blade">
      <origin xyz="0 0.1535 0" rpy="0 0 0" />
      <geometry>
        <box size="0.046 0.263 0.016" />
        </geometry>
      </collision>
    <collision name="hour_counterweight">
      <origin xyz="0 -0.046 0" rpy="0 0 0" />
      <geometry>
        <box size="0.02852 0.048 0.014" />
        </geometry>
      </collision>
    <collision name="hour_boss">
      <geometry>
        <cylinder radius="0.044" length="0.02" />
        </geometry>
      </collision>
    <collision name="hour_arbor">
      <origin xyz="0 0 -0.01275" rpy="0 0 0" />
      <geometry>
        <cylinder radius="0.016" length="0.0375" />
        </geometry>
      </collision>
    </link>
  <link name="side_0_minute_hand">
    <visual name="minute_blade">
      <origin xyz="0 0.206 0" rpy="0 0 0" />
      <geometry>
        <box size="0.03 0.368 0.016" />
        </geometry>
      <material name="blackened_bronze">
        <color rgba="0.03 0.025 0.018 1" />
        </material>
      </visual>
    <visual name="minute_counterweight">
      <origin xyz="0 -0.0635 0" rpy="0 0 0" />
      <geometry>
        <box size="0.0186 0.083 0.014" />
        </geometry>
      <material name="blackened_bronze">
        <color rgba="0.03 0.025 0.018 1" />
        </material>
      </visual>
    <visual name="minute_boss">
      <geometry>
        <cylinder radius="0.05" length="0.02" />
        </geometry>
      <material name="blackened_bronze">
        <color rgba="0.03 0.025 0.018 1" />
        </material>
      </visual>
    <visual name="minute_arbor">
      <origin xyz="0 0 -0.03375" rpy="0 0 0" />
      <geometry>
        <cylinder radius="0.012" length="0.0795" />
        </geometry>
      <material name="blackened_bronze">
        <color rgba="0.03 0.025 0.018 1" />
        </material>
      </visual>
    <collision name="minute_blade">
      <origin xyz="0 0.206 0" rpy="0 0 0" />
      <geometry>
        <box size="0.03 0.368 0.016" />
        </geometry>
      </collision>
    <collision name="minute_counterweight">
      <origin xyz="0 -0.0635 0" rpy="0 0 0" />
      <geometry>
        <box size="0.0186 0.083 0.014" />
        </geometry>
      </collision>
    <collision name="minute_boss">
      <geometry>
        <cylinder radius="0.05" length="0.02" />
        </geometry>
      </collision>
    <collision name="minute_arbor">
      <origin xyz="0 0 -0.03375" rpy="0 0 0" />
      <geometry>
        <cylinder radius="0.012" length="0.0795" />
        </geometry>
      </collision>
    </link>
  <link name="side_1_hour_hand">
    <visual name="hour_blade">
      <origin xyz="0 0.1535 0" rpy="0 0 0" />
      <geometry>
        <box size="0.046 0.263 0.016" />
        </geometry>
      <material name="blackened_bronze">
        <color rgba="0.03 0.025 0.018 1" />
        </material>
      </visual>
    <visual name="hour_counterweight">
      <origin xyz="0 -0.046 0" rpy="0 0 0" />
      <geometry>
        <box size="0.02852 0.048 0.014" />
        </geometry>
      <material name="blackened_bronze">
        <color rgba="0.03 0.025 0.018 1" />
        </material>
      </visual>
    <visual name="hour_boss">
      <geometry>
        <cylinder radius="0.044" length="0.02" />
        </geometry>
      <material name="blackened_bronze">
        <color rgba="0.03 0.025 0.018 1" />
        </material>
      </visual>
    <visual name="hour_arbor">
      <origin xyz="0 0 -0.01275" rpy="0 0 0" />
      <geometry>
        <cylinder radius="0.016" length="0.0375" />
        </geometry>
      <material name="blackened_bronze">
        <color rgba="0.03 0.025 0.018 1" />
        </material>
      </visual>
    <collision name="hour_blade">
      <origin xyz="0 0.1535 0" rpy="0 0 0" />
      <geometry>
        <box size="0.046 0.263 0.016" />
        </geometry>
      </collision>
    <collision name="hour_counterweight">
      <origin xyz="0 -0.046 0" rpy="0 0 0" />
      <geometry>
        <box size="0.02852 0.048 0.014" />
        </geometry>
      </collision>
    <collision name="hour_boss">
      <geometry>
        <cylinder radius="0.044" length="0.02" />
        </geometry>
      </collision>
    <collision name="hour_arbor">
      <origin xyz="0 0 -0.01275" rpy="0 0 0" />
      <geometry>
        <cylinder radius="0.016" length="0.0375" />
        </geometry>
      </collision>
    </link>
  <link name="side_1_minute_hand">
    <visual name="minute_blade">
      <origin xyz="0 0.206 0" rpy="0 0 0" />
      <geometry>
        <box size="0.03 0.368 0.016" />
        </geometry>
      <material name="blackened_bronze">
        <color rgba="0.03 0.025 0.018 1" />
        </material>
      </visual>
    <visual name="minute_counterweight">
      <origin xyz="0 -0.0635 0" rpy="0 0 0" />
      <geometry>
        <box size="0.0186 0.083 0.014" />
        </geometry>
      <material name="blackened_bronze">
        <color rgba="0.03 0.025 0.018 1" />
        </material>
      </visual>
    <visual name="minute_boss">
      <geometry>
        <cylinder radius="0.05" length="0.02" />
        </geometry>
      <material name="blackened_bronze">
        <color rgba="0.03 0.025 0.018 1" />
        </material>
      </visual>
    <visual name="minute_arbor">
      <origin xyz="0 0 -0.03375" rpy="0 0 0" />
      <geometry>
        <cylinder radius="0.012" length="0.0795" />
        </geometry>
      <material name="blackened_bronze">
        <color rgba="0.03 0.025 0.018 1" />
        </material>
      </visual>
    <collision name="minute_blade">
      <origin xyz="0 0.206 0" rpy="0 0 0" />
      <geometry>
        <box size="0.03 0.368 0.016" />
        </geometry>
      </collision>
    <collision name="minute_counterweight">
      <origin xyz="0 -0.0635 0" rpy="0 0 0" />
      <geometry>
        <box size="0.0186 0.083 0.014" />
        </geometry>
      </collision>
    <collision name="minute_boss">
      <geometry>
        <cylinder radius="0.05" length="0.02" />
        </geometry>
      </collision>
    <collision name="minute_arbor">
      <origin xyz="0 0 -0.03375" rpy="0 0 0" />
      <geometry>
        <cylinder radius="0.012" length="0.0795" />
        </geometry>
      </collision>
    </link>
  <joint name="front_hour_pivot" type="revolute">
    <origin xyz="0 0.972 6.42" rpy="1.5708 -0 3.14159" />
    <parent link="tower" />
    <child link="front_hour_hand" />
    <axis xyz="0 0 1" />
    <limit effort="0.35" velocity="0.08" lower="0" upper="6.28319" />
    </joint>
  <joint name="front_minute_pivot" type="revolute">
    <origin xyz="0 1.014 6.42" rpy="1.5708 -0 3.14159" />
    <parent link="tower" />
    <child link="front_minute_hand" />
    <axis xyz="0 0 1" />
    <limit effort="0.25" velocity="0.45" lower="0" upper="6.28319" />
    </joint>
  <joint name="rear_hour_pivot" type="revolute">
    <origin xyz="0 -0.972 6.42" rpy="1.5708 -0 0" />
    <parent link="tower" />
    <child link="rear_hour_hand" />
    <axis xyz="0 0 1" />
    <limit effort="0.35" velocity="0.08" lower="0" upper="6.28319" />
    </joint>
  <joint name="rear_minute_pivot" type="revolute">
    <origin xyz="0 -1.014 6.42" rpy="1.5708 -0 0" />
    <parent link="tower" />
    <child link="rear_minute_hand" />
    <axis xyz="0 0 1" />
    <limit effort="0.25" velocity="0.45" lower="0" upper="6.28319" />
    </joint>
  <joint name="side_0_hour_pivot" type="revolute">
    <origin xyz="0.972 0 6.42" rpy="1.5708 -0 1.5708" />
    <parent link="tower" />
    <child link="side_0_hour_hand" />
    <axis xyz="0 0 1" />
    <limit effort="0.35" velocity="0.08" lower="0" upper="6.28319" />
    </joint>
  <joint name="side_0_minute_pivot" type="revolute">
    <origin xyz="1.014 0 6.42" rpy="1.5708 -0 1.5708" />
    <parent link="tower" />
    <child link="side_0_minute_hand" />
    <axis xyz="0 0 1" />
    <limit effort="0.25" velocity="0.45" lower="0" upper="6.28319" />
    </joint>
  <joint name="side_1_hour_pivot" type="revolute">
    <origin xyz="-0.972 0 6.42" rpy="1.5708 -0 -1.5708" />
    <parent link="tower" />
    <child link="side_1_hour_hand" />
    <axis xyz="0 0 1" />
    <limit effort="0.35" velocity="0.08" lower="0" upper="6.28319" />
    </joint>
  <joint name="side_1_minute_pivot" type="revolute">
    <origin xyz="-1.014 0 6.42" rpy="1.5708 -0 -1.5708" />
    <parent link="tower" />
    <child link="side_1_minute_hand" />
    <axis xyz="0 0 1" />
    <limit effort="0.25" velocity="0.45" lower="0" upper="6.28319" />
    </joint>
  </robot>
