<robot name="clamp_base_monitor_mount_task_lamp">
  <material name="matte_black">
    <color rgba="0.005 0.006 0.007 1" />
    </material>
  <material name="satin_black">
    <color rgba="0.02 0.022 0.024 1" />
    </material>
  <material name="dark_metal">
    <color rgba="0.1 0.105 0.11 1" />
    </material>
  <material name="brushed_steel">
    <color rgba="0.55 0.55 0.52 1" />
    </material>
  <material name="rubber">
    <color rgba="0.015 0.015 0.014 1" />
    </material>
  <material name="warm_led_diffuser">
    <color rgba="1 0.88 0.58 1" />
    </material>
  <link name="clamp_base">
    <visual name="rear_spine">
      <origin xyz="-0.015 0 0.1" rpy="0 0 0" />
      <geometry>
        <box size="0.04 0.12 0.2" />
        </geometry>
      <material name="matte_black">
        <color rgba="0.005 0.006 0.007 1" />
        </material>
      </visual>
    <visual name="top_jaw">
      <origin xyz="0.08 0 0.2" rpy="0 0 0" />
      <geometry>
        <box size="0.2 0.12 0.035" />
        </geometry>
      <material name="matte_black">
        <color rgba="0.005 0.006 0.007 1" />
        </material>
      </visual>
    <visual name="lower_jaw">
      <origin xyz="0.08 0 0.02" rpy="0 0 0" />
      <geometry>
        <box size="0.2 0.12 0.035" />
        </geometry>
      <material name="matte_black">
        <color rgba="0.005 0.006 0.007 1" />
        </material>
      </visual>
    <visual name="upper_grip_pad">
      <origin xyz="0.138 0 0.18" rpy="0 0 0" />
      <geometry>
        <box size="0.09 0.09 0.012" />
        </geometry>
      <material name="rubber">
        <color rgba="0.015 0.015 0.014 1" />
        </material>
      </visual>
    <visual name="clamp_screw">
      <origin xyz="0.145 0 0.084" rpy="0 0 0" />
      <geometry>
        <cylinder radius="0.009" length="0.132" />
        </geometry>
      <material name="brushed_steel">
        <color rgba="0.55 0.55 0.52 1" />
        </material>
      </visual>
    <visual name="pressure_pad">
      <origin xyz="0.145 0 0.153" rpy="0 0 0" />
      <geometry>
        <cylinder radius="0.041" length="0.012" />
        </geometry>
      <material name="rubber">
        <color rgba="0.015 0.015 0.014 1" />
        </material>
      </visual>
    <visual name="tommy_bar">
      <origin xyz="0.145 0 0.014" rpy="1.5708 0 0" />
      <geometry>
        <cylinder radius="0.006" length="0.105" />
        </geometry>
      <material name="brushed_steel">
        <color rgba="0.55 0.55 0.52 1" />
        </material>
      </visual>
    <visual name="swivel_boss">
      <origin xyz="0.02 0 0.2425" rpy="0 0 0" />
      <geometry>
        <cylinder radius="0.04" length="0.05" />
        </geometry>
      <material name="dark_metal">
        <color rgba="0.1 0.105 0.11 1" />
        </material>
      </visual>
    <collision name="rear_spine">
      <origin xyz="-0.015 0 0.1" rpy="0 0 0" />
      <geometry>
        <box size="0.04 0.12 0.2" />
        </geometry>
      </collision>
    <collision name="top_jaw">
      <origin xyz="0.08 0 0.2" rpy="0 0 0" />
      <geometry>
        <box size="0.2 0.12 0.035" />
        </geometry>
      </collision>
    <collision name="lower_jaw">
      <origin xyz="0.08 0 0.02" rpy="0 0 0" />
      <geometry>
        <box size="0.2 0.12 0.035" />
        </geometry>
      </collision>
    <collision name="upper_grip_pad">
      <origin xyz="0.138 0 0.18" rpy="0 0 0" />
      <geometry>
        <box size="0.09 0.09 0.012" />
        </geometry>
      </collision>
    <collision name="clamp_screw">
      <origin xyz="0.145 0 0.084" rpy="0 0 0" />
      <geometry>
        <cylinder radius="0.009" length="0.132" />
        </geometry>
      </collision>
    <collision name="pressure_pad">
      <origin xyz="0.145 0 0.153" rpy="0 0 0" />
      <geometry>
        <cylinder radius="0.041" length="0.012" />
        </geometry>
      </collision>
    <collision name="tommy_bar">
      <origin xyz="0.145 0 0.014" rpy="1.5708 0 0" />
      <geometry>
        <cylinder radius="0.006" length="0.105" />
        </geometry>
      </collision>
    <collision name="swivel_boss">
      <origin xyz="0.02 0 0.2425" rpy="0 0 0" />
      <geometry>
        <cylinder radius="0.04" length="0.05" />
        </geometry>
      </collision>
    </link>
  <link name="post">
    <visual name="post_shaft">
      <origin xyz="0 0 0.0725" rpy="0 0 0" />
      <geometry>
        <cylinder radius="0.021" length="0.145" />
        </geometry>
      <material name="satin_black">
        <color rgba="0.02 0.022 0.024 1" />
        </material>
      </visual>
    <visual name="shoulder_yoke_bridge">
      <origin xyz="0 0 0.137" rpy="0 0 0" />
      <geometry>
        <box size="0.05 0.132 0.022" />
        </geometry>
      <material name="satin_black">
        <color rgba="0.02 0.022 0.024 1" />
        </material>
      </visual>
    <visual name="shoulder_cheek_0">
      <origin xyz="0 0.068 0.176" rpy="0 0 0" />
      <geometry>
        <box size="0.052 0.014 0.066" />
        </geometry>
      <material name="satin_black">
        <color rgba="0.02 0.022 0.024 1" />
        </material>
      </visual>
    <visual name="shoulder_cheek_1">
      <origin xyz="0 -0.068 0.176" rpy="0 0 0" />
      <geometry>
        <box size="0.052 0.014 0.066" />
        </geometry>
      <material name="satin_black">
        <color rgba="0.02 0.022 0.024 1" />
        </material>
      </visual>
    <collision name="post_shaft">
      <origin xyz="0 0 0.0725" rpy="0 0 0" />
      <geometry>
        <cylinder radius="0.021" length="0.145" />
        </geometry>
      </collision>
    <collision name="shoulder_yoke_bridge">
      <origin xyz="0 0 0.137" rpy="0 0 0" />
      <geometry>
        <box size="0.05 0.132 0.022" />
        </geometry>
      </collision>
    <collision name="shoulder_cheek_0">
      <origin xyz="0 0.068 0.176" rpy="0 0 0" />
      <geometry>
        <box size="0.052 0.014 0.066" />
        </geometry>
      </collision>
    <collision name="shoulder_cheek_1">
      <origin xyz="0 -0.068 0.176" rpy="0 0 0" />
      <geometry>
        <box size="0.052 0.014 0.066" />
        </geometry>
      </collision>
    </link>
  <link name="upper_arm">
    <visual name="shoulder_hub">
      <origin xyz="0 0 0" rpy="1.5708 0 0" />
      <geometry>
        <cylinder radius="0.021" length="0.122" />
        </geometry>
      <material name="dark_metal">
        <color rgba="0.1 0.105 0.11 1" />
        </material>
      </visual>
    <visual name="side_rail_0">
      <origin xyz="0.19 -0.044 0" rpy="0 1.5708 0" />
      <geometry>
        <cylinder radius="0.008" length="0.34" />
        </geometry>
      <material name="satin_black">
        <color rgba="0.02 0.022 0.024 1" />
        </material>
      </visual>
    <visual name="side_rail_1">
      <origin xyz="0.19 0.044 0" rpy="0 1.5708 0" />
      <geometry>
        <cylinder radius="0.008" length="0.34" />
        </geometry>
      <material name="satin_black">
        <color rgba="0.02 0.022 0.024 1" />
        </material>
      </visual>
    <visual name="elbow_fork_0">
      <origin xyz="0.35 0.044 0" rpy="0 0 0" />
      <geometry>
        <box size="0.035 0.02 0.03" />
        </geometry>
      <material name="satin_black">
        <color rgba="0.02 0.022 0.024 1" />
        </material>
      </visual>
    <visual name="elbow_fork_1">
      <origin xyz="0.35 -0.044 0" rpy="0 0 0" />
      <geometry>
        <box size="0.035 0.02 0.03" />
        </geometry>
      <material name="satin_black">
        <color rgba="0.02 0.022 0.024 1" />
        </material>
      </visual>
    <collision name="shoulder_hub">
      <origin xyz="0 0 0" rpy="1.5708 0 0" />
      <geometry>
        <cylinder radius="0.021" length="0.122" />
        </geometry>
      </collision>
    <collision name="side_rail_0">
      <origin xyz="0.19 -0.044 0" rpy="0 1.5708 0" />
      <geometry>
        <cylinder radius="0.008" length="0.34" />
        </geometry>
      </collision>
    <collision name="side_rail_1">
      <origin xyz="0.19 0.044 0" rpy="0 1.5708 0" />
      <geometry>
        <cylinder radius="0.008" length="0.34" />
        </geometry>
      </collision>
    <collision name="elbow_fork_0">
      <origin xyz="0.35 0.044 0" rpy="0 0 0" />
      <geometry>
        <box size="0.035 0.02 0.03" />
        </geometry>
      </collision>
    <collision name="elbow_fork_1">
      <origin xyz="0.35 -0.044 0" rpy="0 0 0" />
      <geometry>
        <box size="0.035 0.02 0.03" />
        </geometry>
      </collision>
    </link>
  <link name="forearm_sleeve">
    <visual name="elbow_hub">
      <origin xyz="0 0 0" rpy="1.5708 0 0" />
      <geometry>
        <cylinder radius="0.02" length="0.068" />
        </geometry>
      <material name="dark_metal">
        <color rgba="0.1 0.105 0.11 1" />
        </material>
      </visual>
    <visual name="sleeve_shell">
      <geometry>
        <mesh filename="assets/meshes/forearm_sleeve_shell.obj" />
        </geometry>
      <material name="satin_black">
        <color rgba="0.02 0.022 0.024 1" />
        </material>
      </visual>
    <visual name="sleeve_lip">
      <origin xyz="0.326 0 0.033" rpy="0 0 0" />
      <geometry>
        <box size="0.055 0.07 0.01" />
        </geometry>
      <material name="satin_black">
        <color rgba="0.02 0.022 0.024 1" />
        </material>
      </visual>
    <collision name="elbow_hub">
      <origin xyz="0 0 0" rpy="1.5708 0 0" />
      <geometry>
        <cylinder radius="0.02" length="0.068" />
        </geometry>
      </collision>
    <collision name="sleeve_shell">
      <geometry>
        <mesh filename="assets/meshes/forearm_sleeve_shell.obj" />
        </geometry>
      </collision>
    <collision name="sleeve_lip">
      <origin xyz="0.326 0 0.033" rpy="0 0 0" />
      <geometry>
        <box size="0.055 0.07 0.01" />
        </geometry>
      </collision>
    </link>
  <link name="forearm">
    <visual name="slider_tube">
      <origin xyz="0.128 0 0" rpy="0 0 0" />
      <geometry>
        <box size="0.35 0.024 0.014" />
        </geometry>
      <material name="dark_metal">
        <color rgba="0.1 0.105 0.11 1" />
        </material>
      </visual>
    <visual name="head_yoke_bridge">
      <origin xyz="0.288 0 0" rpy="0 0 0" />
      <geometry>
        <box size="0.03 0.07 0.014" />
        </geometry>
      <material name="dark_metal">
        <color rgba="0.1 0.105 0.11 1" />
        </material>
      </visual>
    <visual name="head_cheek_0">
      <origin xyz="0.318 0.038 0" rpy="0 0 0" />
      <geometry>
        <box size="0.04 0.01 0.052" />
        </geometry>
      <material name="dark_metal">
        <color rgba="0.1 0.105 0.11 1" />
        </material>
      </visual>
    <visual name="head_cheek_1">
      <origin xyz="0.318 -0.038 0" rpy="0 0 0" />
      <geometry>
        <box size="0.04 0.01 0.052" />
        </geometry>
      <material name="dark_metal">
        <color rgba="0.1 0.105 0.11 1" />
        </material>
      </visual>
    <collision name="slider_tube">
      <origin xyz="0.128 0 0" rpy="0 0 0" />
      <geometry>
        <box size="0.35 0.024 0.014" />
        </geometry>
      </collision>
    <collision name="head_yoke_bridge">
      <origin xyz="0.288 0 0" rpy="0 0 0" />
      <geometry>
        <box size="0.03 0.07 0.014" />
        </geometry>
      </collision>
    <collision name="head_cheek_0">
      <origin xyz="0.318 0.038 0" rpy="0 0 0" />
      <geometry>
        <box size="0.04 0.01 0.052" />
        </geometry>
      </collision>
    <collision name="head_cheek_1">
      <origin xyz="0.318 -0.038 0" rpy="0 0 0" />
      <geometry>
        <box size="0.04 0.01 0.052" />
        </geometry>
      </collision>
    </link>
  <link name="head">
    <visual name="tilt_barrel">
      <origin xyz="0 0 0" rpy="1.5708 0 0" />
      <geometry>
        <cylinder radius="0.016" length="0.066" />
        </geometry>
      <material name="dark_metal">
        <color rgba="0.1 0.105 0.11 1" />
        </material>
      </visual>
    <visual name="neck_link">
      <origin xyz="0.025 0 -0.012" rpy="0 0 0" />
      <geometry>
        <box size="0.05 0.028 0.016" />
        </geometry>
      <material name="dark_metal">
        <color rgba="0.1 0.105 0.11 1" />
        </material>
      </visual>
    <visual name="neck_drop">
      <origin xyz="0.047 0 -0.028" rpy="0 0 0" />
      <geometry>
        <box size="0.026 0.026 0.024" />
        </geometry>
      <material name="dark_metal">
        <color rgba="0.1 0.105 0.11 1" />
        </material>
      </visual>
    <visual name="head_shell">
      <origin xyz="0.105 0 -0.045" rpy="0 0 0" />
      <geometry>
        <mesh filename="assets/meshes/led_head_shell.obj" />
        </geometry>
      <material name="satin_black">
        <color rgba="0.02 0.022 0.024 1" />
        </material>
      </visual>
    <visual name="led_panel">
      <origin xyz="0.105 0 -0.0635" rpy="0 0 0" />
      <geometry>
        <box size="0.105 0.052 0.004" />
        </geometry>
      <material name="warm_led_diffuser">
        <color rgba="1 0.88 0.58 1" />
        </material>
      </visual>
    <visual name="cooling_rib_0">
      <origin xyz="0.105 -0.026 -0.025" rpy="0 0 0" />
      <geometry>
        <box size="0.09 0.004 0.005" />
        </geometry>
      <material name="matte_black">
        <color rgba="0.005 0.006 0.007 1" />
        </material>
      </visual>
    <visual name="cooling_rib_1">
      <origin xyz="0.105 0 -0.025" rpy="0 0 0" />
      <geometry>
        <box size="0.09 0.004 0.005" />
        </geometry>
      <material name="matte_black">
        <color rgba="0.005 0.006 0.007 1" />
        </material>
      </visual>
    <visual name="cooling_rib_2">
      <origin xyz="0.105 0.026 -0.025" rpy="0 0 0" />
      <geometry>
        <box size="0.09 0.004 0.005" />
        </geometry>
      <material name="matte_black">
        <color rgba="0.005 0.006 0.007 1" />
        </material>
      </visual>
    <collision name="tilt_barrel">
      <origin xyz="0 0 0" rpy="1.5708 0 0" />
      <geometry>
        <cylinder radius="0.016" length="0.066" />
        </geometry>
      </collision>
    <collision name="neck_link">
      <origin xyz="0.025 0 -0.012" rpy="0 0 0" />
      <geometry>
        <box size="0.05 0.028 0.016" />
        </geometry>
      </collision>
    <collision name="neck_drop">
      <origin xyz="0.047 0 -0.028" rpy="0 0 0" />
      <geometry>
        <box size="0.026 0.026 0.024" />
        </geometry>
      </collision>
    <collision name="head_shell">
      <origin xyz="0.105 0 -0.045" rpy="0 0 0" />
      <geometry>
        <mesh filename="assets/meshes/led_head_shell.obj" />
        </geometry>
      </collision>
    <collision name="led_panel">
      <origin xyz="0.105 0 -0.0635" rpy="0 0 0" />
      <geometry>
        <box size="0.105 0.052 0.004" />
        </geometry>
      </collision>
    <collision name="cooling_rib_0">
      <origin xyz="0.105 -0.026 -0.025" rpy="0 0 0" />
      <geometry>
        <box size="0.09 0.004 0.005" />
        </geometry>
      </collision>
    <collision name="cooling_rib_1">
      <origin xyz="0.105 0 -0.025" rpy="0 0 0" />
      <geometry>
        <box size="0.09 0.004 0.005" />
        </geometry>
      </collision>
    <collision name="cooling_rib_2">
      <origin xyz="0.105 0.026 -0.025" rpy="0 0 0" />
      <geometry>
        <box size="0.09 0.004 0.005" />
        </geometry>
      </collision>
    </link>
  <joint name="clamp_to_post" type="revolute">
    <origin xyz="0.02 0 0.2675" rpy="0 0 0" />
    <parent link="clamp_base" />
    <child link="post" />
    <axis xyz="0 0 1" />
    <limit effort="6" velocity="2.2" lower="-3.14159" upper="3.14159" />
    </joint>
  <joint name="post_to_upper_arm" type="revolute">
    <origin xyz="0 0 0.176" rpy="0 0 0" />
    <parent link="post" />
    <child link="upper_arm" />
    <axis xyz="0 -1 0" />
    <limit effort="8" velocity="1.5" lower="-0.75" upper="1.2" />
    </joint>
  <joint name="upper_arm_to_forearm_sleeve" type="revolute">
    <origin xyz="0.36 0 0" rpy="0 0 0" />
    <parent link="upper_arm" />
    <child link="forearm_sleeve" />
    <axis xyz="0 -1 0" />
    <limit effort="8" velocity="1.5" lower="-1.25" upper="1.25" />
    </joint>
  <joint name="forearm_sleeve_to_forearm" type="prismatic">
    <origin xyz="0.12 0 0" rpy="0 0 0" />
    <parent link="forearm_sleeve" />
    <child link="forearm" />
    <axis xyz="1 0 0" />
    <limit effort="35" velocity="0.2" lower="0" upper="0.16" />
    </joint>
  <joint name="forearm_to_head" type="revolute">
    <origin xyz="0.325 0 0" rpy="0 0 0" />
    <parent link="forearm" />
    <child link="head" />
    <axis xyz="0 1 0" />
    <limit effort="3" velocity="1.5" lower="-0.85" upper="0.85" />
    </joint>
  </robot>
