<robot name="wide_machine_gantry">
  <link name="base">
    <visual name="base_rail_0">
      <origin xyz="0 -0.66 0.06" rpy="0 0 0" />
      <geometry>
        <box size="3.55 0.22 0.12" />
        </geometry>
      <material name="painted_cast_iron">
        <color rgba="0.16 0.18 0.2 1" />
        </material>
      </visual>
    <visual name="rail_pad_0">
      <origin xyz="0 -0.66 0.1375" rpy="0 0 0" />
      <geometry>
        <box size="3.24 0.075 0.035" />
        </geometry>
      <material name="ground_rail_steel">
        <color rgba="0.62 0.64 0.62 1" />
        </material>
      </visual>
    <visual name="pad_bolt_0_0">
      <origin xyz="-1.34 -0.66 0.16" rpy="0 0 0" />
      <geometry>
        <cylinder radius="0.022" length="0.01" />
        </geometry>
      <material name="darkened_steel">
        <color rgba="0.08 0.09 0.1 1" />
        </material>
      </visual>
    <visual name="pad_bolt_0_1">
      <origin xyz="-0.67 -0.66 0.16" rpy="0 0 0" />
      <geometry>
        <cylinder radius="0.022" length="0.01" />
        </geometry>
      <material name="darkened_steel">
        <color rgba="0.08 0.09 0.1 1" />
        </material>
      </visual>
    <visual name="pad_bolt_0_2">
      <origin xyz="0 -0.66 0.16" rpy="0 0 0" />
      <geometry>
        <cylinder radius="0.022" length="0.01" />
        </geometry>
      <material name="darkened_steel">
        <color rgba="0.08 0.09 0.1 1" />
        </material>
      </visual>
    <visual name="pad_bolt_0_3">
      <origin xyz="0.67 -0.66 0.16" rpy="0 0 0" />
      <geometry>
        <cylinder radius="0.022" length="0.01" />
        </geometry>
      <material name="darkened_steel">
        <color rgba="0.08 0.09 0.1 1" />
        </material>
      </visual>
    <visual name="pad_bolt_0_4">
      <origin xyz="1.34 -0.66 0.16" rpy="0 0 0" />
      <geometry>
        <cylinder radius="0.022" length="0.01" />
        </geometry>
      <material name="darkened_steel">
        <color rgba="0.08 0.09 0.1 1" />
        </material>
      </visual>
    <visual name="base_rail_1">
      <origin xyz="0 0.66 0.06" rpy="0 0 0" />
      <geometry>
        <box size="3.55 0.22 0.12" />
        </geometry>
      <material name="painted_cast_iron">
        <color rgba="0.16 0.18 0.2 1" />
        </material>
      </visual>
    <visual name="rail_pad_1">
      <origin xyz="0 0.66 0.1375" rpy="0 0 0" />
      <geometry>
        <box size="3.24 0.075 0.035" />
        </geometry>
      <material name="ground_rail_steel">
        <color rgba="0.62 0.64 0.62 1" />
        </material>
      </visual>
    <visual name="pad_bolt_1_0">
      <origin xyz="-1.34 0.66 0.16" rpy="0 0 0" />
      <geometry>
        <cylinder radius="0.022" length="0.01" />
        </geometry>
      <material name="darkened_steel">
        <color rgba="0.08 0.09 0.1 1" />
        </material>
      </visual>
    <visual name="pad_bolt_1_1">
      <origin xyz="-0.67 0.66 0.16" rpy="0 0 0" />
      <geometry>
        <cylinder radius="0.022" length="0.01" />
        </geometry>
      <material name="darkened_steel">
        <color rgba="0.08 0.09 0.1 1" />
        </material>
      </visual>
    <visual name="pad_bolt_1_2">
      <origin xyz="0 0.66 0.16" rpy="0 0 0" />
      <geometry>
        <cylinder radius="0.022" length="0.01" />
        </geometry>
      <material name="darkened_steel">
        <color rgba="0.08 0.09 0.1 1" />
        </material>
      </visual>
    <visual name="pad_bolt_1_3">
      <origin xyz="0.67 0.66 0.16" rpy="0 0 0" />
      <geometry>
        <cylinder radius="0.022" length="0.01" />
        </geometry>
      <material name="darkened_steel">
        <color rgba="0.08 0.09 0.1 1" />
        </material>
      </visual>
    <visual name="pad_bolt_1_4">
      <origin xyz="1.34 0.66 0.16" rpy="0 0 0" />
      <geometry>
        <cylinder radius="0.022" length="0.01" />
        </geometry>
      <material name="darkened_steel">
        <color rgba="0.08 0.09 0.1 1" />
        </material>
      </visual>
    <visual name="cross_tie_0">
      <origin xyz="-1.32 0 0.045" rpy="0 0 0" />
      <geometry>
        <box size="0.2 1.56 0.08" />
        </geometry>
      <material name="painted_cast_iron">
        <color rgba="0.16 0.18 0.2 1" />
        </material>
      </visual>
    <visual name="cross_tie_1">
      <origin xyz="0 0 0.045" rpy="0 0 0" />
      <geometry>
        <box size="0.2 1.56 0.08" />
        </geometry>
      <material name="painted_cast_iron">
        <color rgba="0.16 0.18 0.2 1" />
        </material>
      </visual>
    <visual name="cross_tie_2">
      <origin xyz="1.32 0 0.045" rpy="0 0 0" />
      <geometry>
        <box size="0.2 1.56 0.08" />
        </geometry>
      <material name="painted_cast_iron">
        <color rgba="0.16 0.18 0.2 1" />
        </material>
      </visual>
    <visual name="travel_stop_0_0">
      <origin xyz="-1.6 -0.66 0.21" rpy="0 0 0" />
      <geometry>
        <box size="0.1 0.18 0.12" />
        </geometry>
      <material name="red_stop_blocks">
        <color rgba="0.58 0.07 0.05 1" />
        </material>
      </visual>
    <visual name="travel_stop_0_1">
      <origin xyz="-1.6 0.66 0.21" rpy="0 0 0" />
      <geometry>
        <box size="0.1 0.18 0.12" />
        </geometry>
      <material name="red_stop_blocks">
        <color rgba="0.58 0.07 0.05 1" />
        </material>
      </visual>
    <visual name="travel_stop_1_0">
      <origin xyz="1.6 -0.66 0.21" rpy="0 0 0" />
      <geometry>
        <box size="0.1 0.18 0.12" />
        </geometry>
      <material name="red_stop_blocks">
        <color rgba="0.58 0.07 0.05 1" />
        </material>
      </visual>
    <visual name="travel_stop_1_1">
      <origin xyz="1.6 0.66 0.21" rpy="0 0 0" />
      <geometry>
        <box size="0.1 0.18 0.12" />
        </geometry>
      <material name="red_stop_blocks">
        <color rgba="0.58 0.07 0.05 1" />
        </material>
      </visual>
    <collision name="base_rail_0">
      <origin xyz="0 -0.66 0.06" rpy="0 0 0" />
      <geometry>
        <box size="3.55 0.22 0.12" />
        </geometry>
      </collision>
    <collision name="rail_pad_0">
      <origin xyz="0 -0.66 0.1375" rpy="0 0 0" />
      <geometry>
        <box size="3.24 0.075 0.035" />
        </geometry>
      </collision>
    <collision name="pad_bolt_0_0">
      <origin xyz="-1.34 -0.66 0.16" rpy="0 0 0" />
      <geometry>
        <cylinder radius="0.022" length="0.01" />
        </geometry>
      </collision>
    <collision name="pad_bolt_0_1">
      <origin xyz="-0.67 -0.66 0.16" rpy="0 0 0" />
      <geometry>
        <cylinder radius="0.022" length="0.01" />
        </geometry>
      </collision>
    <collision name="pad_bolt_0_2">
      <origin xyz="0 -0.66 0.16" rpy="0 0 0" />
      <geometry>
        <cylinder radius="0.022" length="0.01" />
        </geometry>
      </collision>
    <collision name="pad_bolt_0_3">
      <origin xyz="0.67 -0.66 0.16" rpy="0 0 0" />
      <geometry>
        <cylinder radius="0.022" length="0.01" />
        </geometry>
      </collision>
    <collision name="pad_bolt_0_4">
      <origin xyz="1.34 -0.66 0.16" rpy="0 0 0" />
      <geometry>
        <cylinder radius="0.022" length="0.01" />
        </geometry>
      </collision>
    <collision name="base_rail_1">
      <origin xyz="0 0.66 0.06" rpy="0 0 0" />
      <geometry>
        <box size="3.55 0.22 0.12" />
        </geometry>
      </collision>
    <collision name="rail_pad_1">
      <origin xyz="0 0.66 0.1375" rpy="0 0 0" />
      <geometry>
        <box size="3.24 0.075 0.035" />
        </geometry>
      </collision>
    <collision name="pad_bolt_1_0">
      <origin xyz="-1.34 0.66 0.16" rpy="0 0 0" />
      <geometry>
        <cylinder radius="0.022" length="0.01" />
        </geometry>
      </collision>
    <collision name="pad_bolt_1_1">
      <origin xyz="-0.67 0.66 0.16" rpy="0 0 0" />
      <geometry>
        <cylinder radius="0.022" length="0.01" />
        </geometry>
      </collision>
    <collision name="pad_bolt_1_2">
      <origin xyz="0 0.66 0.16" rpy="0 0 0" />
      <geometry>
        <cylinder radius="0.022" length="0.01" />
        </geometry>
      </collision>
    <collision name="pad_bolt_1_3">
      <origin xyz="0.67 0.66 0.16" rpy="0 0 0" />
      <geometry>
        <cylinder radius="0.022" length="0.01" />
        </geometry>
      </collision>
    <collision name="pad_bolt_1_4">
      <origin xyz="1.34 0.66 0.16" rpy="0 0 0" />
      <geometry>
        <cylinder radius="0.022" length="0.01" />
        </geometry>
      </collision>
    <collision name="cross_tie_0">
      <origin xyz="-1.32 0 0.045" rpy="0 0 0" />
      <geometry>
        <box size="0.2 1.56 0.08" />
        </geometry>
      </collision>
    <collision name="cross_tie_1">
      <origin xyz="0 0 0.045" rpy="0 0 0" />
      <geometry>
        <box size="0.2 1.56 0.08" />
        </geometry>
      </collision>
    <collision name="cross_tie_2">
      <origin xyz="1.32 0 0.045" rpy="0 0 0" />
      <geometry>
        <box size="0.2 1.56 0.08" />
        </geometry>
      </collision>
    <collision name="travel_stop_0_0">
      <origin xyz="-1.6 -0.66 0.21" rpy="0 0 0" />
      <geometry>
        <box size="0.1 0.18 0.12" />
        </geometry>
      </collision>
    <collision name="travel_stop_0_1">
      <origin xyz="-1.6 0.66 0.21" rpy="0 0 0" />
      <geometry>
        <box size="0.1 0.18 0.12" />
        </geometry>
      </collision>
    <collision name="travel_stop_1_0">
      <origin xyz="1.6 -0.66 0.21" rpy="0 0 0" />
      <geometry>
        <box size="0.1 0.18 0.12" />
        </geometry>
      </collision>
    <collision name="travel_stop_1_1">
      <origin xyz="1.6 0.66 0.21" rpy="0 0 0" />
      <geometry>
        <box size="0.1 0.18 0.12" />
        </geometry>
      </collision>
    </link>
  <link name="portal">
    <visual name="truck_0">
      <origin xyz="0 -0.66 0.25" rpy="0 0 0" />
      <geometry>
        <box size="0.52 0.34 0.2" />
        </geometry>
      <material name="darkened_steel">
        <color rgba="0.08 0.09 0.1 1" />
        </material>
      </visual>
    <visual name="bearing_shoe_0">
      <origin xyz="0 -0.66 0.1875" rpy="0 0 0" />
      <geometry>
        <box size="0.42 0.24 0.075" />
        </geometry>
      <material name="ground_rail_steel">
        <color rgba="0.62 0.64 0.62 1" />
        </material>
      </visual>
    <visual name="upright_0">
      <origin xyz="0 -0.66 0.82" rpy="0 0 0" />
      <geometry>
        <box size="0.36 0.3 0.98" />
        </geometry>
      <material name="safety_blue_covers">
        <color rgba="0.07 0.22 0.42 1" />
        </material>
      </visual>
    <visual name="truck_1">
      <origin xyz="0 0.66 0.25" rpy="0 0 0" />
      <geometry>
        <box size="0.52 0.34 0.2" />
        </geometry>
      <material name="darkened_steel">
        <color rgba="0.08 0.09 0.1 1" />
        </material>
      </visual>
    <visual name="bearing_shoe_1">
      <origin xyz="0 0.66 0.1875" rpy="0 0 0" />
      <geometry>
        <box size="0.42 0.24 0.075" />
        </geometry>
      <material name="ground_rail_steel">
        <color rgba="0.62 0.64 0.62 1" />
        </material>
      </visual>
    <visual name="upright_1">
      <origin xyz="0 0.66 0.82" rpy="0 0 0" />
      <geometry>
        <box size="0.36 0.3 0.98" />
        </geometry>
      <material name="safety_blue_covers">
        <color rgba="0.07 0.22 0.42 1" />
        </material>
      </visual>
    <visual name="portal_beam">
      <origin xyz="0 0 1.315" rpy="0 0 0" />
      <geometry>
        <box size="0.44 1.72 0.32" />
        </geometry>
      <material name="safety_blue_covers">
        <color rgba="0.07 0.22 0.42 1" />
        </material>
      </visual>
    <visual name="top_cover_flange">
      <origin xyz="-0.25 0 1.5025" rpy="0 0 0" />
      <geometry>
        <box size="0.12 1.62 0.055" />
        </geometry>
      <material name="safety_blue_covers">
        <color rgba="0.07 0.22 0.42 1" />
        </material>
      </visual>
    <visual name="bottom_cover_flange">
      <origin xyz="-0.25 0 1.1275" rpy="0 0 0" />
      <geometry>
        <box size="0.12 1.62 0.055" />
        </geometry>
      <material name="safety_blue_covers">
        <color rgba="0.07 0.22 0.42 1" />
        </material>
      </visual>
    <visual name="front_guide_0">
      <origin xyz="-0.29 0 1.205" rpy="0 0 0" />
      <geometry>
        <box size="0.14 1.34 0.05" />
        </geometry>
      <material name="ground_rail_steel">
        <color rgba="0.62 0.64 0.62 1" />
        </material>
      </visual>
    <visual name="front_guide_1">
      <origin xyz="-0.29 0 1.425" rpy="0 0 0" />
      <geometry>
        <box size="0.14 1.34 0.05" />
        </geometry>
      <material name="ground_rail_steel">
        <color rgba="0.62 0.64 0.62 1" />
        </material>
      </visual>
    <visual name="carriage_stop_0">
      <origin xyz="-0.285 -0.755 1.315" rpy="0 0 0" />
      <geometry>
        <box size="0.16 0.07 0.3" />
        </geometry>
      <material name="red_stop_blocks">
        <color rgba="0.58 0.07 0.05 1" />
        </material>
      </visual>
    <visual name="carriage_stop_1">
      <origin xyz="-0.285 0.755 1.315" rpy="0 0 0" />
      <geometry>
        <box size="0.16 0.07 0.3" />
        </geometry>
      <material name="red_stop_blocks">
        <color rgba="0.58 0.07 0.05 1" />
        </material>
      </visual>
    <collision name="truck_0">
      <origin xyz="0 -0.66 0.25" rpy="0 0 0" />
      <geometry>
        <box size="0.52 0.34 0.2" />
        </geometry>
      </collision>
    <collision name="bearing_shoe_0">
      <origin xyz="0 -0.66 0.1875" rpy="0 0 0" />
      <geometry>
        <box size="0.42 0.24 0.075" />
        </geometry>
      </collision>
    <collision name="upright_0">
      <origin xyz="0 -0.66 0.82" rpy="0 0 0" />
      <geometry>
        <box size="0.36 0.3 0.98" />
        </geometry>
      </collision>
    <collision name="truck_1">
      <origin xyz="0 0.66 0.25" rpy="0 0 0" />
      <geometry>
        <box size="0.52 0.34 0.2" />
        </geometry>
      </collision>
    <collision name="bearing_shoe_1">
      <origin xyz="0 0.66 0.1875" rpy="0 0 0" />
      <geometry>
        <box size="0.42 0.24 0.075" />
        </geometry>
      </collision>
    <collision name="upright_1">
      <origin xyz="0 0.66 0.82" rpy="0 0 0" />
      <geometry>
        <box size="0.36 0.3 0.98" />
        </geometry>
      </collision>
    <collision name="portal_beam">
      <origin xyz="0 0 1.315" rpy="0 0 0" />
      <geometry>
        <box size="0.44 1.72 0.32" />
        </geometry>
      </collision>
    <collision name="top_cover_flange">
      <origin xyz="-0.25 0 1.5025" rpy="0 0 0" />
      <geometry>
        <box size="0.12 1.62 0.055" />
        </geometry>
      </collision>
    <collision name="bottom_cover_flange">
      <origin xyz="-0.25 0 1.1275" rpy="0 0 0" />
      <geometry>
        <box size="0.12 1.62 0.055" />
        </geometry>
      </collision>
    <collision name="front_guide_0">
      <origin xyz="-0.29 0 1.205" rpy="0 0 0" />
      <geometry>
        <box size="0.14 1.34 0.05" />
        </geometry>
      </collision>
    <collision name="front_guide_1">
      <origin xyz="-0.29 0 1.425" rpy="0 0 0" />
      <geometry>
        <box size="0.14 1.34 0.05" />
        </geometry>
      </collision>
    <collision name="carriage_stop_0">
      <origin xyz="-0.285 -0.755 1.315" rpy="0 0 0" />
      <geometry>
        <box size="0.16 0.07 0.3" />
        </geometry>
      </collision>
    <collision name="carriage_stop_1">
      <origin xyz="-0.285 0.755 1.315" rpy="0 0 0" />
      <geometry>
        <box size="0.16 0.07 0.3" />
        </geometry>
      </collision>
    </link>
  <link name="carriage">
    <visual name="carriage_housing">
      <origin xyz="-0.08 0 0" rpy="0 0 0" />
      <geometry>
        <box size="0.16 0.3 0.26" />
        </geometry>
      <material name="carriage_gray">
        <color rgba="0.34 0.36 0.37 1" />
        </material>
      </visual>
    <visual name="bearing_pad_0">
      <origin xyz="-0.0225 0 -0.11" rpy="0 0 0" />
      <geometry>
        <box size="0.045 0.33 0.06" />
        </geometry>
      <material name="darkened_steel">
        <color rgba="0.08 0.09 0.1 1" />
        </material>
      </visual>
    <visual name="bearing_pad_1">
      <origin xyz="-0.0225 0 0.11" rpy="0 0 0" />
      <geometry>
        <box size="0.045 0.33 0.06" />
        </geometry>
      <material name="darkened_steel">
        <color rgba="0.08 0.09 0.1 1" />
        </material>
      </visual>
    <visual name="front_tool_plate">
      <origin xyz="-0.1825 0 0" rpy="0 0 0" />
      <geometry>
        <box size="0.045 0.24 0.3" />
        </geometry>
      <material name="darkened_steel">
        <color rgba="0.08 0.09 0.1 1" />
        </material>
      </visual>
    <visual name="tool_mount_boss">
      <origin xyz="-0.235 0 -0.01" rpy="0 0 0" />
      <geometry>
        <box size="0.06 0.12 0.12" />
        </geometry>
      <material name="darkened_steel">
        <color rgba="0.08 0.09 0.1 1" />
        </material>
      </visual>
    <collision name="carriage_housing">
      <origin xyz="-0.08 0 0" rpy="0 0 0" />
      <geometry>
        <box size="0.16 0.3 0.26" />
        </geometry>
      </collision>
    <collision name="bearing_pad_0">
      <origin xyz="-0.0225 0 -0.11" rpy="0 0 0" />
      <geometry>
        <box size="0.045 0.33 0.06" />
        </geometry>
      </collision>
    <collision name="bearing_pad_1">
      <origin xyz="-0.0225 0 0.11" rpy="0 0 0" />
      <geometry>
        <box size="0.045 0.33 0.06" />
        </geometry>
      </collision>
    <collision name="front_tool_plate">
      <origin xyz="-0.1825 0 0" rpy="0 0 0" />
      <geometry>
        <box size="0.045 0.24 0.3" />
        </geometry>
      </collision>
    <collision name="tool_mount_boss">
      <origin xyz="-0.235 0 -0.01" rpy="0 0 0" />
      <geometry>
        <box size="0.06 0.12 0.12" />
        </geometry>
      </collision>
    </link>
  <joint name="portal_slide" type="prismatic">
    <origin xyz="-1 0 0.005" rpy="0 0 0" />
    <parent link="base" />
    <child link="portal" />
    <axis xyz="1 0 0" />
    <limit effort="2200" velocity="0.55" lower="0" upper="2" />
    </joint>
  <joint name="carriage_slide" type="prismatic">
    <origin xyz="-0.36 -0.45 1.315" rpy="0 0 0" />
    <parent link="portal" />
    <child link="carriage" />
    <axis xyz="0 1 0" />
    <limit effort="650" velocity="0.45" lower="0" upper="0.9" />
    </joint>
  </robot>
