<robot name="empty_tv_wall_mount">
  <material name="satin_black_powder_coat">
    <color rgba="0.02 0.022 0.024 1" />
    </material>
  <material name="dark_pin_caps">
    <color rgba="0.005 0.005 0.006 1" />
    </material>
  <material name="black_screw_heads">
    <color rgba="0.01 0.01 0.012 1" />
    </material>
  <material name="worn_edge_highlights">
    <color rgba="0.18 0.18 0.17 1" />
    </material>
  <link name="wall_plate">
    <visual name="plate_slab">
      <origin xyz="-0.06 0 0" rpy="0 0 0" />
      <geometry>
        <box size="0.018 0.26 0.42" />
        </geometry>
      <material name="satin_black_powder_coat">
        <color rgba="0.02 0.022 0.024 1" />
        </material>
      </visual>
    <visual name="side_lip_0">
      <origin xyz="-0.047 0.13 0" rpy="0 0 0" />
      <geometry>
        <box size="0.012 0.02 0.42" />
        </geometry>
      <material name="worn_edge_highlights">
        <color rgba="0.18 0.18 0.17 1" />
        </material>
      </visual>
    <visual name="side_lip_1">
      <origin xyz="-0.047 -0.13 0" rpy="0 0 0" />
      <geometry>
        <box size="0.012 0.02 0.42" />
        </geometry>
      <material name="worn_edge_highlights">
        <color rgba="0.18 0.18 0.17 1" />
        </material>
      </visual>
    <visual name="top_lip">
      <origin xyz="-0.047 0 0.195" rpy="0 0 0" />
      <geometry>
        <box size="0.012 0.22 0.018" />
        </geometry>
      <material name="worn_edge_highlights">
        <color rgba="0.18 0.18 0.17 1" />
        </material>
      </visual>
    <visual name="bottom_lip">
      <origin xyz="-0.047 0 -0.195" rpy="0 0 0" />
      <geometry>
        <box size="0.012 0.22 0.018" />
        </geometry>
      <material name="worn_edge_highlights">
        <color rgba="0.18 0.18 0.17 1" />
        </material>
      </visual>
    <visual name="lag_screw_0">
      <origin xyz="-0.049 -0.085 0.14" rpy="0 1.5708 0" />
      <geometry>
        <cylinder radius="0.014" length="0.006" />
        </geometry>
      <material name="black_screw_heads">
        <color rgba="0.01 0.01 0.012 1" />
        </material>
      </visual>
    <visual name="lag_screw_1">
      <origin xyz="-0.049 0.085 0.14" rpy="0 1.5708 0" />
      <geometry>
        <cylinder radius="0.014" length="0.006" />
        </geometry>
      <material name="black_screw_heads">
        <color rgba="0.01 0.01 0.012 1" />
        </material>
      </visual>
    <visual name="lag_screw_2">
      <origin xyz="-0.049 -0.085 -0.14" rpy="0 1.5708 0" />
      <geometry>
        <cylinder radius="0.014" length="0.006" />
        </geometry>
      <material name="black_screw_heads">
        <color rgba="0.01 0.01 0.012 1" />
        </material>
      </visual>
    <visual name="lag_screw_3">
      <origin xyz="-0.049 0.085 -0.14" rpy="0 1.5708 0" />
      <geometry>
        <cylinder radius="0.014" length="0.006" />
        </geometry>
      <material name="black_screw_heads">
        <color rgba="0.01 0.01 0.012 1" />
        </material>
      </visual>
    <visual name="shoulder_clevis_upper">
      <origin xyz="-0.025 0 0.0525" rpy="0 0 0" />
      <geometry>
        <box size="0.052 0.094 0.035" />
        </geometry>
      <material name="satin_black_powder_coat">
        <color rgba="0.02 0.022 0.024 1" />
        </material>
      </visual>
    <visual name="shoulder_knuckle_upper">
      <origin xyz="0 0 0.0525" rpy="0 0 0" />
      <geometry>
        <cylinder radius="0.034" length="0.035" />
        </geometry>
      <material name="satin_black_powder_coat">
        <color rgba="0.02 0.022 0.024 1" />
        </material>
      </visual>
    <visual name="shoulder_clevis_lower">
      <origin xyz="-0.025 0 -0.0525" rpy="0 0 0" />
      <geometry>
        <box size="0.052 0.094 0.035" />
        </geometry>
      <material name="satin_black_powder_coat">
        <color rgba="0.02 0.022 0.024 1" />
        </material>
      </visual>
    <visual name="shoulder_knuckle_lower">
      <origin xyz="0 0 -0.0525" rpy="0 0 0" />
      <geometry>
        <cylinder radius="0.034" length="0.035" />
        </geometry>
      <material name="satin_black_powder_coat">
        <color rgba="0.02 0.022 0.024 1" />
        </material>
      </visual>
    <visual name="shoulder_pin">
      <geometry>
        <cylinder radius="0.018" length="0.156" />
        </geometry>
      <material name="dark_pin_caps">
        <color rgba="0.005 0.005 0.006 1" />
        </material>
      </visual>
    <collision name="plate_slab">
      <origin xyz="-0.06 0 0" rpy="0 0 0" />
      <geometry>
        <box size="0.018 0.26 0.42" />
        </geometry>
      </collision>
    <collision name="side_lip_0">
      <origin xyz="-0.047 0.13 0" rpy="0 0 0" />
      <geometry>
        <box size="0.012 0.02 0.42" />
        </geometry>
      </collision>
    <collision name="side_lip_1">
      <origin xyz="-0.047 -0.13 0" rpy="0 0 0" />
      <geometry>
        <box size="0.012 0.02 0.42" />
        </geometry>
      </collision>
    <collision name="top_lip">
      <origin xyz="-0.047 0 0.195" rpy="0 0 0" />
      <geometry>
        <box size="0.012 0.22 0.018" />
        </geometry>
      </collision>
    <collision name="bottom_lip">
      <origin xyz="-0.047 0 -0.195" rpy="0 0 0" />
      <geometry>
        <box size="0.012 0.22 0.018" />
        </geometry>
      </collision>
    <collision name="lag_screw_0">
      <origin xyz="-0.049 -0.085 0.14" rpy="0 1.5708 0" />
      <geometry>
        <cylinder radius="0.014" length="0.006" />
        </geometry>
      </collision>
    <collision name="lag_screw_1">
      <origin xyz="-0.049 0.085 0.14" rpy="0 1.5708 0" />
      <geometry>
        <cylinder radius="0.014" length="0.006" />
        </geometry>
      </collision>
    <collision name="lag_screw_2">
      <origin xyz="-0.049 -0.085 -0.14" rpy="0 1.5708 0" />
      <geometry>
        <cylinder radius="0.014" length="0.006" />
        </geometry>
      </collision>
    <collision name="lag_screw_3">
      <origin xyz="-0.049 0.085 -0.14" rpy="0 1.5708 0" />
      <geometry>
        <cylinder radius="0.014" length="0.006" />
        </geometry>
      </collision>
    <collision name="shoulder_clevis_upper">
      <origin xyz="-0.025 0 0.0525" rpy="0 0 0" />
      <geometry>
        <box size="0.052 0.094 0.035" />
        </geometry>
      </collision>
    <collision name="shoulder_knuckle_upper">
      <origin xyz="0 0 0.0525" rpy="0 0 0" />
      <geometry>
        <cylinder radius="0.034" length="0.035" />
        </geometry>
      </collision>
    <collision name="shoulder_clevis_lower">
      <origin xyz="-0.025 0 -0.0525" rpy="0 0 0" />
      <geometry>
        <box size="0.052 0.094 0.035" />
        </geometry>
      </collision>
    <collision name="shoulder_knuckle_lower">
      <origin xyz="0 0 -0.0525" rpy="0 0 0" />
      <geometry>
        <cylinder radius="0.034" length="0.035" />
        </geometry>
      </collision>
    <collision name="shoulder_pin">
      <geometry>
        <cylinder radius="0.018" length="0.156" />
        </geometry>
      </collision>
    </link>
  <link name="outer_arm">
    <visual name="shoulder_barrel">
      <geometry>
        <cylinder radius="0.03" length="0.07" />
        </geometry>
      <material name="satin_black_powder_coat">
        <color rgba="0.02 0.022 0.024 1" />
        </material>
      </visual>
    <visual name="outer_tube">
      <origin xyz="0.19 0 0" rpy="0 0 0" />
      <geometry>
        <box size="0.32 0.054 0.07" />
        </geometry>
      <material name="satin_black_powder_coat">
        <color rgba="0.02 0.022 0.024 1" />
        </material>
      </visual>
    <visual name="outer_side_flange_0">
      <origin xyz="0.19 0.034 0" rpy="0 0 0" />
      <geometry>
        <box size="0.3 0.018 0.084" />
        </geometry>
      <material name="worn_edge_highlights">
        <color rgba="0.18 0.18 0.17 1" />
        </material>
      </visual>
    <visual name="outer_side_flange_1">
      <origin xyz="0.19 -0.034 0" rpy="0 0 0" />
      <geometry>
        <box size="0.3 0.018 0.084" />
        </geometry>
      <material name="worn_edge_highlights">
        <color rgba="0.18 0.18 0.17 1" />
        </material>
      </visual>
    <visual name="elbow_knuckle_upper">
      <origin xyz="0.38 0 0.0525" rpy="0 0 0" />
      <geometry>
        <cylinder radius="0.034" length="0.035" />
        </geometry>
      <material name="satin_black_powder_coat">
        <color rgba="0.02 0.022 0.024 1" />
        </material>
      </visual>
    <visual name="elbow_clevis_upper">
      <origin xyz="0.36 0 0.0525" rpy="0 0 0" />
      <geometry>
        <box size="0.044 0.078 0.035" />
        </geometry>
      <material name="satin_black_powder_coat">
        <color rgba="0.02 0.022 0.024 1" />
        </material>
      </visual>
    <visual name="elbow_knuckle_lower">
      <origin xyz="0.38 0 -0.0525" rpy="0 0 0" />
      <geometry>
        <cylinder radius="0.034" length="0.035" />
        </geometry>
      <material name="satin_black_powder_coat">
        <color rgba="0.02 0.022 0.024 1" />
        </material>
      </visual>
    <visual name="elbow_clevis_lower">
      <origin xyz="0.36 0 -0.0525" rpy="0 0 0" />
      <geometry>
        <box size="0.044 0.078 0.035" />
        </geometry>
      <material name="satin_black_powder_coat">
        <color rgba="0.02 0.022 0.024 1" />
        </material>
      </visual>
    <visual name="elbow_pin">
      <origin xyz="0.38 0 0" rpy="0 0 0" />
      <geometry>
        <cylinder radius="0.017" length="0.156" />
        </geometry>
      <material name="dark_pin_caps">
        <color rgba="0.005 0.005 0.006 1" />
        </material>
      </visual>
    <collision name="shoulder_barrel">
      <geometry>
        <cylinder radius="0.03" length="0.07" />
        </geometry>
      </collision>
    <collision name="outer_tube">
      <origin xyz="0.19 0 0" rpy="0 0 0" />
      <geometry>
        <box size="0.32 0.054 0.07" />
        </geometry>
      </collision>
    <collision name="outer_side_flange_0">
      <origin xyz="0.19 0.034 0" rpy="0 0 0" />
      <geometry>
        <box size="0.3 0.018 0.084" />
        </geometry>
      </collision>
    <collision name="outer_side_flange_1">
      <origin xyz="0.19 -0.034 0" rpy="0 0 0" />
      <geometry>
        <box size="0.3 0.018 0.084" />
        </geometry>
      </collision>
    <collision name="elbow_knuckle_upper">
      <origin xyz="0.38 0 0.0525" rpy="0 0 0" />
      <geometry>
        <cylinder radius="0.034" length="0.035" />
        </geometry>
      </collision>
    <collision name="elbow_clevis_upper">
      <origin xyz="0.36 0 0.0525" rpy="0 0 0" />
      <geometry>
        <box size="0.044 0.078 0.035" />
        </geometry>
      </collision>
    <collision name="elbow_knuckle_lower">
      <origin xyz="0.38 0 -0.0525" rpy="0 0 0" />
      <geometry>
        <cylinder radius="0.034" length="0.035" />
        </geometry>
      </collision>
    <collision name="elbow_clevis_lower">
      <origin xyz="0.36 0 -0.0525" rpy="0 0 0" />
      <geometry>
        <box size="0.044 0.078 0.035" />
        </geometry>
      </collision>
    <collision name="elbow_pin">
      <origin xyz="0.38 0 0" rpy="0 0 0" />
      <geometry>
        <cylinder radius="0.017" length="0.156" />
        </geometry>
      </collision>
    </link>
  <link name="inner_arm">
    <visual name="elbow_barrel">
      <geometry>
        <cylinder radius="0.03" length="0.07" />
        </geometry>
      <material name="satin_black_powder_coat">
        <color rgba="0.02 0.022 0.024 1" />
        </material>
      </visual>
    <visual name="elbow_web">
      <origin xyz="0.04 0 0" rpy="0 0 0" />
      <geometry>
        <box size="0.035 0.048 0.052" />
        </geometry>
      <material name="satin_black_powder_coat">
        <color rgba="0.02 0.022 0.024 1" />
        </material>
      </visual>
    <visual name="inner_tube">
      <origin xyz="0.17 0 0" rpy="0 0 0" />
      <geometry>
        <box size="0.28 0.052 0.066" />
        </geometry>
      <material name="satin_black_powder_coat">
        <color rgba="0.02 0.022 0.024 1" />
        </material>
      </visual>
    <visual name="inner_side_flange_0">
      <origin xyz="0.17 0.033 0" rpy="0 0 0" />
      <geometry>
        <box size="0.26 0.016 0.08" />
        </geometry>
      <material name="worn_edge_highlights">
        <color rgba="0.18 0.18 0.17 1" />
        </material>
      </visual>
    <visual name="inner_side_flange_1">
      <origin xyz="0.17 -0.033 0" rpy="0 0 0" />
      <geometry>
        <box size="0.26 0.016 0.08" />
        </geometry>
      <material name="worn_edge_highlights">
        <color rgba="0.18 0.18 0.17 1" />
        </material>
      </visual>
    <visual name="head_knuckle_upper">
      <origin xyz="0.34 0 0.0525" rpy="0 0 0" />
      <geometry>
        <cylinder radius="0.032" length="0.035" />
        </geometry>
      <material name="satin_black_powder_coat">
        <color rgba="0.02 0.022 0.024 1" />
        </material>
      </visual>
    <visual name="head_clevis_upper">
      <origin xyz="0.322 0 0.0525" rpy="0 0 0" />
      <geometry>
        <box size="0.04 0.072 0.035" />
        </geometry>
      <material name="satin_black_powder_coat">
        <color rgba="0.02 0.022 0.024 1" />
        </material>
      </visual>
    <visual name="head_knuckle_lower">
      <origin xyz="0.34 0 -0.0525" rpy="0 0 0" />
      <geometry>
        <cylinder radius="0.032" length="0.035" />
        </geometry>
      <material name="satin_black_powder_coat">
        <color rgba="0.02 0.022 0.024 1" />
        </material>
      </visual>
    <visual name="head_clevis_lower">
      <origin xyz="0.322 0 -0.0525" rpy="0 0 0" />
      <geometry>
        <box size="0.04 0.072 0.035" />
        </geometry>
      <material name="satin_black_powder_coat">
        <color rgba="0.02 0.022 0.024 1" />
        </material>
      </visual>
    <visual name="head_side_web_side_0">
      <origin xyz="0.305 0.042 0" rpy="0 0 0" />
      <geometry>
        <box size="0.07 0.018 0.15" />
        </geometry>
      <material name="satin_black_powder_coat">
        <color rgba="0.02 0.022 0.024 1" />
        </material>
      </visual>
    <visual name="head_side_web_side_1">
      <origin xyz="0.305 -0.042 0" rpy="0 0 0" />
      <geometry>
        <box size="0.07 0.018 0.15" />
        </geometry>
      <material name="satin_black_powder_coat">
        <color rgba="0.02 0.022 0.024 1" />
        </material>
      </visual>
    <visual name="head_pin">
      <origin xyz="0.34 0 0" rpy="0 0 0" />
      <geometry>
        <cylinder radius="0.016" length="0.15" />
        </geometry>
      <material name="dark_pin_caps">
        <color rgba="0.005 0.005 0.006 1" />
        </material>
      </visual>
    <collision name="elbow_barrel">
      <geometry>
        <cylinder radius="0.03" length="0.07" />
        </geometry>
      </collision>
    <collision name="elbow_web">
      <origin xyz="0.04 0 0" rpy="0 0 0" />
      <geometry>
        <box size="0.035 0.048 0.052" />
        </geometry>
      </collision>
    <collision name="inner_tube">
      <origin xyz="0.17 0 0" rpy="0 0 0" />
      <geometry>
        <box size="0.28 0.052 0.066" />
        </geometry>
      </collision>
    <collision name="inner_side_flange_0">
      <origin xyz="0.17 0.033 0" rpy="0 0 0" />
      <geometry>
        <box size="0.26 0.016 0.08" />
        </geometry>
      </collision>
    <collision name="inner_side_flange_1">
      <origin xyz="0.17 -0.033 0" rpy="0 0 0" />
      <geometry>
        <box size="0.26 0.016 0.08" />
        </geometry>
      </collision>
    <collision name="head_knuckle_upper">
      <origin xyz="0.34 0 0.0525" rpy="0 0 0" />
      <geometry>
        <cylinder radius="0.032" length="0.035" />
        </geometry>
      </collision>
    <collision name="head_clevis_upper">
      <origin xyz="0.322 0 0.0525" rpy="0 0 0" />
      <geometry>
        <box size="0.04 0.072 0.035" />
        </geometry>
      </collision>
    <collision name="head_knuckle_lower">
      <origin xyz="0.34 0 -0.0525" rpy="0 0 0" />
      <geometry>
        <cylinder radius="0.032" length="0.035" />
        </geometry>
      </collision>
    <collision name="head_clevis_lower">
      <origin xyz="0.322 0 -0.0525" rpy="0 0 0" />
      <geometry>
        <box size="0.04 0.072 0.035" />
        </geometry>
      </collision>
    <collision name="head_side_web_side_0">
      <origin xyz="0.305 0.042 0" rpy="0 0 0" />
      <geometry>
        <box size="0.07 0.018 0.15" />
        </geometry>
      </collision>
    <collision name="head_side_web_side_1">
      <origin xyz="0.305 -0.042 0" rpy="0 0 0" />
      <geometry>
        <box size="0.07 0.018 0.15" />
        </geometry>
      </collision>
    <collision name="head_pin">
      <origin xyz="0.34 0 0" rpy="0 0 0" />
      <geometry>
        <cylinder radius="0.016" length="0.15" />
        </geometry>
      </collision>
    </link>
  <link name="swivel_head">
    <visual name="swivel_barrel">
      <geometry>
        <cylinder radius="0.028" length="0.07" />
        </geometry>
      <material name="satin_black_powder_coat">
        <color rgba="0.02 0.022 0.024 1" />
        </material>
      </visual>
    <visual name="wrist_block">
      <origin xyz="0.043 0 0" rpy="0 0 0" />
      <geometry>
        <box size="0.042 0.11 0.05" />
        </geometry>
      <material name="satin_black_powder_coat">
        <color rgba="0.02 0.022 0.024 1" />
        </material>
      </visual>
    <visual name="wrist_side_bridge_side_0">
      <origin xyz="0.07 0.055 0" rpy="0 0 0" />
      <geometry>
        <box size="0.05 0.014 0.026" />
        </geometry>
      <material name="satin_black_powder_coat">
        <color rgba="0.02 0.022 0.024 1" />
        </material>
      </visual>
    <visual name="wrist_side_bridge_side_1">
      <origin xyz="0.07 -0.055 0" rpy="0 0 0" />
      <geometry>
        <box size="0.05 0.014 0.026" />
        </geometry>
      <material name="satin_black_powder_coat">
        <color rgba="0.02 0.022 0.024 1" />
        </material>
      </visual>
    <visual name="tilt_yoke_side_0">
      <origin xyz="0.09 0.0575 0" rpy="0 0 0" />
      <geometry>
        <box size="0.044 0.035 0.082" />
        </geometry>
      <material name="satin_black_powder_coat">
        <color rgba="0.02 0.022 0.024 1" />
        </material>
      </visual>
    <visual name="tilt_knuckle_side_0">
      <origin xyz="0.09 0.0575 0" rpy="-1.5708 0 0" />
      <geometry>
        <cylinder radius="0.028" length="0.035" />
        </geometry>
      <material name="satin_black_powder_coat">
        <color rgba="0.02 0.022 0.024 1" />
        </material>
      </visual>
    <visual name="tilt_yoke_side_1">
      <origin xyz="0.09 -0.0575 0" rpy="0 0 0" />
      <geometry>
        <box size="0.044 0.035 0.082" />
        </geometry>
      <material name="satin_black_powder_coat">
        <color rgba="0.02 0.022 0.024 1" />
        </material>
      </visual>
    <visual name="tilt_knuckle_side_1">
      <origin xyz="0.09 -0.0575 0" rpy="-1.5708 0 0" />
      <geometry>
        <cylinder radius="0.028" length="0.035" />
        </geometry>
      <material name="satin_black_powder_coat">
        <color rgba="0.02 0.022 0.024 1" />
        </material>
      </visual>
    <visual name="tilt_pin">
      <origin xyz="0.09 0 0" rpy="-1.5708 0 0" />
      <geometry>
        <cylinder radius="0.013" length="0.17" />
        </geometry>
      <material name="dark_pin_caps">
        <color rgba="0.005 0.005 0.006 1" />
        </material>
      </visual>
    <collision name="swivel_barrel">
      <geometry>
        <cylinder radius="0.028" length="0.07" />
        </geometry>
      </collision>
    <collision name="wrist_block">
      <origin xyz="0.043 0 0" rpy="0 0 0" />
      <geometry>
        <box size="0.042 0.11 0.05" />
        </geometry>
      </collision>
    <collision name="wrist_side_bridge_side_0">
      <origin xyz="0.07 0.055 0" rpy="0 0 0" />
      <geometry>
        <box size="0.05 0.014 0.026" />
        </geometry>
      </collision>
    <collision name="wrist_side_bridge_side_1">
      <origin xyz="0.07 -0.055 0" rpy="0 0 0" />
      <geometry>
        <box size="0.05 0.014 0.026" />
        </geometry>
      </collision>
    <collision name="tilt_yoke_side_0">
      <origin xyz="0.09 0.0575 0" rpy="0 0 0" />
      <geometry>
        <box size="0.044 0.035 0.082" />
        </geometry>
      </collision>
    <collision name="tilt_knuckle_side_0">
      <origin xyz="0.09 0.0575 0" rpy="-1.5708 0 0" />
      <geometry>
        <cylinder radius="0.028" length="0.035" />
        </geometry>
      </collision>
    <collision name="tilt_yoke_side_1">
      <origin xyz="0.09 -0.0575 0" rpy="0 0 0" />
      <geometry>
        <box size="0.044 0.035 0.082" />
        </geometry>
      </collision>
    <collision name="tilt_knuckle_side_1">
      <origin xyz="0.09 -0.0575 0" rpy="-1.5708 0 0" />
      <geometry>
        <cylinder radius="0.028" length="0.035" />
        </geometry>
      </collision>
    <collision name="tilt_pin">
      <origin xyz="0.09 0 0" rpy="-1.5708 0 0" />
      <geometry>
        <cylinder radius="0.013" length="0.17" />
        </geometry>
      </collision>
    </link>
  <link name="mounting_frame">
    <visual name="tilt_barrel">
      <origin xyz="0 0 0" rpy="-1.5708 0 0" />
      <geometry>
        <cylinder radius="0.024" length="0.08" />
        </geometry>
      <material name="satin_black_powder_coat">
        <color rgba="0.02 0.022 0.024 1" />
        </material>
      </visual>
    <visual name="tilt_web">
      <origin xyz="0.028 0 0" rpy="0 0 0" />
      <geometry>
        <box size="0.014 0.05 0.04" />
        </geometry>
      <material name="satin_black_powder_coat">
        <color rgba="0.02 0.022 0.024 1" />
        </material>
      </visual>
    <visual name="center_plate">
      <origin xyz="0.06 0 0" rpy="0 0 0" />
      <geometry>
        <box size="0.065 0.11 0.06" />
        </geometry>
      <material name="satin_black_powder_coat">
        <color rgba="0.02 0.022 0.024 1" />
        </material>
      </visual>
    <visual name="center_spine">
      <origin xyz="0.1 0 0" rpy="0 0 0" />
      <geometry>
        <box size="0.032 0.066 0.264" />
        </geometry>
      <material name="satin_black_powder_coat">
        <color rgba="0.02 0.022 0.024 1" />
        </material>
      </visual>
    <visual name="middle_crossbar">
      <origin xyz="0.1 0 0" rpy="0 0 0" />
      <geometry>
        <box size="0.032 0.23 0.03" />
        </geometry>
      <material name="satin_black_powder_coat">
        <color rgba="0.02 0.022 0.024 1" />
        </material>
      </visual>
    <visual name="top_bar">
      <origin xyz="0.1 0 0.145" rpy="0 0 0" />
      <geometry>
        <box size="0.026 0.42 0.032" />
        </geometry>
      <material name="satin_black_powder_coat">
        <color rgba="0.02 0.022 0.024 1" />
        </material>
      </visual>
    <visual name="bottom_bar">
      <origin xyz="0.1 0 -0.145" rpy="0 0 0" />
      <geometry>
        <box size="0.026 0.42 0.032" />
        </geometry>
      <material name="satin_black_powder_coat">
        <color rgba="0.02 0.022 0.024 1" />
        </material>
      </visual>
    <visual name="side_rail_side_0">
      <origin xyz="0.1 0.195 0" rpy="0 0 0" />
      <geometry>
        <box size="0.026 0.032 0.29" />
        </geometry>
      <material name="satin_black_powder_coat">
        <color rgba="0.02 0.022 0.024 1" />
        </material>
      </visual>
    <visual name="side_rail_side_1">
      <origin xyz="0.1 -0.195 0" rpy="0 0 0" />
      <geometry>
        <box size="0.026 0.032 0.29" />
        </geometry>
      <material name="satin_black_powder_coat">
        <color rgba="0.02 0.022 0.024 1" />
        </material>
      </visual>
    <visual name="vesa_rail_inner_0">
      <origin xyz="0.095 0.095 0" rpy="0 0 0" />
      <geometry>
        <box size="0.024 0.028 0.29" />
        </geometry>
      <material name="worn_edge_highlights">
        <color rgba="0.18 0.18 0.17 1" />
        </material>
      </visual>
    <visual name="vesa_slot_inner_0_0">
      <origin xyz="0.108 0.095 -0.085" rpy="0 1.5708 0" />
      <geometry>
        <cylinder radius="0.014" length="0.006" />
        </geometry>
      <material name="black_screw_heads">
        <color rgba="0.01 0.01 0.012 1" />
        </material>
      </visual>
    <visual name="vesa_slot_inner_0_1">
      <origin xyz="0.108 0.095 0.085" rpy="0 1.5708 0" />
      <geometry>
        <cylinder radius="0.014" length="0.006" />
        </geometry>
      <material name="black_screw_heads">
        <color rgba="0.01 0.01 0.012 1" />
        </material>
      </visual>
    <visual name="vesa_rail_inner_1">
      <origin xyz="0.095 -0.095 0" rpy="0 0 0" />
      <geometry>
        <box size="0.024 0.028 0.29" />
        </geometry>
      <material name="worn_edge_highlights">
        <color rgba="0.18 0.18 0.17 1" />
        </material>
      </visual>
    <visual name="vesa_slot_inner_1_0">
      <origin xyz="0.108 -0.095 -0.085" rpy="0 1.5708 0" />
      <geometry>
        <cylinder radius="0.014" length="0.006" />
        </geometry>
      <material name="black_screw_heads">
        <color rgba="0.01 0.01 0.012 1" />
        </material>
      </visual>
    <visual name="vesa_slot_inner_1_1">
      <origin xyz="0.108 -0.095 0.085" rpy="0 1.5708 0" />
      <geometry>
        <cylinder radius="0.014" length="0.006" />
        </geometry>
      <material name="black_screw_heads">
        <color rgba="0.01 0.01 0.012 1" />
        </material>
      </visual>
    <collision name="tilt_barrel">
      <origin xyz="0 0 0" rpy="-1.5708 0 0" />
      <geometry>
        <cylinder radius="0.024" length="0.08" />
        </geometry>
      </collision>
    <collision name="tilt_web">
      <origin xyz="0.028 0 0" rpy="0 0 0" />
      <geometry>
        <box size="0.014 0.05 0.04" />
        </geometry>
      </collision>
    <collision name="center_plate">
      <origin xyz="0.06 0 0" rpy="0 0 0" />
      <geometry>
        <box size="0.065 0.11 0.06" />
        </geometry>
      </collision>
    <collision name="center_spine">
      <origin xyz="0.1 0 0" rpy="0 0 0" />
      <geometry>
        <box size="0.032 0.066 0.264" />
        </geometry>
      </collision>
    <collision name="middle_crossbar">
      <origin xyz="0.1 0 0" rpy="0 0 0" />
      <geometry>
        <box size="0.032 0.23 0.03" />
        </geometry>
      </collision>
    <collision name="top_bar">
      <origin xyz="0.1 0 0.145" rpy="0 0 0" />
      <geometry>
        <box size="0.026 0.42 0.032" />
        </geometry>
      </collision>
    <collision name="bottom_bar">
      <origin xyz="0.1 0 -0.145" rpy="0 0 0" />
      <geometry>
        <box size="0.026 0.42 0.032" />
        </geometry>
      </collision>
    <collision name="side_rail_side_0">
      <origin xyz="0.1 0.195 0" rpy="0 0 0" />
      <geometry>
        <box size="0.026 0.032 0.29" />
        </geometry>
      </collision>
    <collision name="side_rail_side_1">
      <origin xyz="0.1 -0.195 0" rpy="0 0 0" />
      <geometry>
        <box size="0.026 0.032 0.29" />
        </geometry>
      </collision>
    <collision name="vesa_rail_inner_0">
      <origin xyz="0.095 0.095 0" rpy="0 0 0" />
      <geometry>
        <box size="0.024 0.028 0.29" />
        </geometry>
      </collision>
    <collision name="vesa_slot_inner_0_0">
      <origin xyz="0.108 0.095 -0.085" rpy="0 1.5708 0" />
      <geometry>
        <cylinder radius="0.014" length="0.006" />
        </geometry>
      </collision>
    <collision name="vesa_slot_inner_0_1">
      <origin xyz="0.108 0.095 0.085" rpy="0 1.5708 0" />
      <geometry>
        <cylinder radius="0.014" length="0.006" />
        </geometry>
      </collision>
    <collision name="vesa_rail_inner_1">
      <origin xyz="0.095 -0.095 0" rpy="0 0 0" />
      <geometry>
        <box size="0.024 0.028 0.29" />
        </geometry>
      </collision>
    <collision name="vesa_slot_inner_1_0">
      <origin xyz="0.108 -0.095 -0.085" rpy="0 1.5708 0" />
      <geometry>
        <cylinder radius="0.014" length="0.006" />
        </geometry>
      </collision>
    <collision name="vesa_slot_inner_1_1">
      <origin xyz="0.108 -0.095 0.085" rpy="0 1.5708 0" />
      <geometry>
        <cylinder radius="0.014" length="0.006" />
        </geometry>
      </collision>
    </link>
  <joint name="shoulder_yaw" type="revolute">
    <parent link="wall_plate" />
    <child link="outer_arm" />
    <axis xyz="0 0 1" />
    <limit effort="80" velocity="1" lower="-1.5708" upper="1.5708" />
    </joint>
  <joint name="elbow_yaw" type="revolute">
    <origin xyz="0.38 0 0" rpy="0 0 0" />
    <parent link="outer_arm" />
    <child link="inner_arm" />
    <axis xyz="0 0 1" />
    <limit effort="70" velocity="1" lower="-1.5708" upper="1.5708" />
    </joint>
  <joint name="head_swivel" type="revolute">
    <origin xyz="0.34 0 0" rpy="0 0 0" />
    <parent link="inner_arm" />
    <child link="swivel_head" />
    <axis xyz="0 0 1" />
    <limit effort="35" velocity="1" lower="-0.785398" upper="0.785398" />
    </joint>
  <joint name="head_tilt" type="revolute">
    <origin xyz="0.09 0 0" rpy="0 0 0" />
    <parent link="swivel_head" />
    <child link="mounting_frame" />
    <axis xyz="0 1 0" />
    <limit effort="30" velocity="0.8" lower="-0.261799" upper="0.261799" />
    </joint>
  </robot>
