<robot name="folding_service_arm">
  <material name="painted_steel">
    <color rgba="0.18 0.2 0.22 1" />
    </material>
  <material name="blackened_steel">
    <color rgba="0.05 0.055 0.06 1" />
    </material>
  <material name="brushed_aluminum">
    <color rgba="0.62 0.65 0.67 1" />
    </material>
  <material name="brushed_steel">
    <color rgba="0.72 0.74 0.76 1" />
    </material>
  <material name="zinc_bolt">
    <color rgba="0.8 0.78 0.7 1" />
    </material>
  <material name="rubber">
    <color rgba="0.015 0.015 0.014 1" />
    </material>
  <link name="base_bracket">
    <visual name="ground_plate">
      <origin xyz="0 0 0.008" rpy="0 0 0" />
      <geometry>
        <box size="0.22 0.155 0.016" />
        </geometry>
      <material name="painted_steel" />
      </visual>
    <visual name="rear_web">
      <origin xyz="-0.077 0 0.066" rpy="0 0 0" />
      <geometry>
        <box size="0.024 0.112 0.116" />
        </geometry>
      <material name="painted_steel" />
      </visual>
    <visual name="lower_yoke">
      <origin xyz="0 0 0.07" rpy="0 0 0" />
      <geometry>
        <mesh filename="assets/meshes/lower_yoke_mesh.obj" />
        </geometry>
      <material name="painted_steel" />
      </visual>
    <visual name="upper_yoke">
      <origin xyz="0 0 0.13" rpy="0 0 0" />
      <geometry>
        <mesh filename="assets/meshes/upper_yoke_mesh.obj" />
        </geometry>
      <material name="painted_steel" />
      </visual>
    <visual name="shoulder_shank">
      <origin xyz="0 0 0.112" rpy="0 0 0" />
      <geometry>
        <cylinder radius="0.0095" length="0.08" />
        </geometry>
      <material name="zinc_bolt" />
      </visual>
    <visual name="shoulder_head">
      <origin xyz="0 0 0.139" rpy="0 0 0" />
      <geometry>
        <cylinder radius="0.025" length="0.006" />
        </geometry>
      <material name="zinc_bolt" />
      </visual>
    <visual name="shoulder_nut">
      <origin xyz="0 0 0.061" rpy="0 0 0" />
      <geometry>
        <cylinder radius="0.021" length="0.006" />
        </geometry>
      <material name="zinc_bolt" />
      </visual>
    <visual name="base_bolt_0">
      <origin xyz="-0.078 -0.052 0.018" rpy="0 0 0" />
      <geometry>
        <cylinder radius="0.01" length="0.004" />
        </geometry>
      <material name="zinc_bolt" />
      </visual>
    <visual name="base_bolt_1">
      <origin xyz="-0.078 0.052 0.018" rpy="0 0 0" />
      <geometry>
        <cylinder radius="0.01" length="0.004" />
        </geometry>
      <material name="zinc_bolt" />
      </visual>
    <visual name="base_bolt_2">
      <origin xyz="0.078 -0.052 0.018" rpy="0 0 0" />
      <geometry>
        <cylinder radius="0.01" length="0.004" />
        </geometry>
      <material name="zinc_bolt" />
      </visual>
    <visual name="base_bolt_3">
      <origin xyz="0.078 0.052 0.018" rpy="0 0 0" />
      <geometry>
        <cylinder radius="0.01" length="0.004" />
        </geometry>
      <material name="zinc_bolt" />
      </visual>
    <collision name="ground_plate">
      <origin xyz="0 0 0.008" rpy="0 0 0" />
      <geometry>
        <box size="0.22 0.155 0.016" />
        </geometry>
      </collision>
    <collision name="rear_web">
      <origin xyz="-0.077 0 0.066" rpy="0 0 0" />
      <geometry>
        <box size="0.024 0.112 0.116" />
        </geometry>
      </collision>
    <collision name="lower_yoke">
      <origin xyz="0 0 0.07" rpy="0 0 0" />
      <geometry>
        <mesh filename="assets/meshes/lower_yoke_mesh.obj" />
        </geometry>
      </collision>
    <collision name="upper_yoke">
      <origin xyz="0 0 0.13" rpy="0 0 0" />
      <geometry>
        <mesh filename="assets/meshes/upper_yoke_mesh.obj" />
        </geometry>
      </collision>
    <collision name="shoulder_shank">
      <origin xyz="0 0 0.112" rpy="0 0 0" />
      <geometry>
        <cylinder radius="0.0095" length="0.08" />
        </geometry>
      </collision>
    <collision name="shoulder_head">
      <origin xyz="0 0 0.139" rpy="0 0 0" />
      <geometry>
        <cylinder radius="0.025" length="0.006" />
        </geometry>
      </collision>
    <collision name="shoulder_nut">
      <origin xyz="0 0 0.061" rpy="0 0 0" />
      <geometry>
        <cylinder radius="0.021" length="0.006" />
        </geometry>
      </collision>
    <collision name="base_bolt_0">
      <origin xyz="-0.078 -0.052 0.018" rpy="0 0 0" />
      <geometry>
        <cylinder radius="0.01" length="0.004" />
        </geometry>
      </collision>
    <collision name="base_bolt_1">
      <origin xyz="-0.078 0.052 0.018" rpy="0 0 0" />
      <geometry>
        <cylinder radius="0.01" length="0.004" />
        </geometry>
      </collision>
    <collision name="base_bolt_2">
      <origin xyz="0.078 -0.052 0.018" rpy="0 0 0" />
      <geometry>
        <cylinder radius="0.01" length="0.004" />
        </geometry>
      </collision>
    <collision name="base_bolt_3">
      <origin xyz="0.078 0.052 0.018" rpy="0 0 0" />
      <geometry>
        <cylinder radius="0.01" length="0.004" />
        </geometry>
      </collision>
    </link>
  <link name="first_link">
    <visual name="link_plate">
      <geometry>
        <mesh filename="assets/meshes/first_link_plate_mesh.obj" />
        </geometry>
      <material name="brushed_aluminum" />
      </visual>
    <visual name="edge_flange_0">
      <origin xyz="0.23 -0.032 0.012" rpy="0 0 0" />
      <geometry>
        <box size="0.35 0.008 0.006" />
        </geometry>
      <material name="brushed_steel" />
      </visual>
    <visual name="edge_flange_1">
      <origin xyz="0.23 0.032 0.012" rpy="0 0 0" />
      <geometry>
        <box size="0.35 0.008 0.006" />
        </geometry>
      <material name="brushed_steel" />
      </visual>
    <visual name="shoulder_collar">
      <origin xyz="0 0 0.013" rpy="0 0 0" />
      <geometry>
        <mesh filename="assets/meshes/shoulder_collar_mesh.obj" />
        </geometry>
      <material name="brushed_steel" />
      </visual>
    <visual name="elbow_collar">
      <origin xyz="0.46 0 0.013" rpy="0 0 0" />
      <geometry>
        <mesh filename="assets/meshes/elbow_collar_mesh.obj" />
        </geometry>
      <material name="brushed_steel" />
      </visual>
    <visual name="elbow_nut">
      <origin xyz="0.46 0 -0.013" rpy="0 0 0" />
      <geometry>
        <mesh filename="assets/meshes/elbow_nut_mesh.obj" />
        </geometry>
      <material name="zinc_bolt" />
      </visual>
    <collision name="link_plate">
      <geometry>
        <mesh filename="assets/meshes/first_link_plate_mesh.obj" />
        </geometry>
      </collision>
    <collision name="edge_flange_0">
      <origin xyz="0.23 -0.032 0.012" rpy="0 0 0" />
      <geometry>
        <box size="0.35 0.008 0.006" />
        </geometry>
      </collision>
    <collision name="edge_flange_1">
      <origin xyz="0.23 0.032 0.012" rpy="0 0 0" />
      <geometry>
        <box size="0.35 0.008 0.006" />
        </geometry>
      </collision>
    <collision name="shoulder_collar">
      <origin xyz="0 0 0.013" rpy="0 0 0" />
      <geometry>
        <mesh filename="assets/meshes/shoulder_collar_mesh.obj" />
        </geometry>
      </collision>
    <collision name="elbow_collar">
      <origin xyz="0.46 0 0.013" rpy="0 0 0" />
      <geometry>
        <mesh filename="assets/meshes/elbow_collar_mesh.obj" />
        </geometry>
      </collision>
    <collision name="elbow_nut">
      <origin xyz="0.46 0 -0.013" rpy="0 0 0" />
      <geometry>
        <mesh filename="assets/meshes/elbow_nut_mesh.obj" />
        </geometry>
      </collision>
    </link>
  <link name="second_link">
    <visual name="link_plate">
      <origin xyz="0 0 0.032" rpy="0 0 0" />
      <geometry>
        <mesh filename="assets/meshes/second_link_plate_mesh.obj" />
        </geometry>
      <material name="brushed_aluminum" />
      </visual>
    <visual name="edge_flange_0">
      <origin xyz="0.15 -0.022 0.0395" rpy="0 0 0" />
      <geometry>
        <box size="0.22 0.006 0.005" />
        </geometry>
      <material name="brushed_steel" />
      </visual>
    <visual name="edge_flange_1">
      <origin xyz="0.15 0.022 0.0395" rpy="0 0 0" />
      <geometry>
        <box size="0.22 0.006 0.005" />
        </geometry>
      <material name="brushed_steel" />
      </visual>
    <visual name="elbow_head">
      <origin xyz="0 0 0.042" rpy="0 0 0" />
      <geometry>
        <mesh filename="assets/meshes/elbow_top_washer_mesh.obj" />
        </geometry>
      <material name="zinc_bolt" />
      </visual>
    <visual name="elbow_shank">
      <origin xyz="0 0 0.015" rpy="0 0 0" />
      <geometry>
        <cylinder radius="0.009" length="0.06" />
        </geometry>
      <material name="zinc_bolt" />
      </visual>
    <visual name="end_clevis">
      <origin xyz="0.316 0 0.032" rpy="0 0 0" />
      <geometry>
        <box size="0.034 0.058 0.02" />
        </geometry>
      <material name="brushed_steel" />
      </visual>
    <collision name="link_plate">
      <origin xyz="0 0 0.032" rpy="0 0 0" />
      <geometry>
        <mesh filename="assets/meshes/second_link_plate_mesh.obj" />
        </geometry>
      </collision>
    <collision name="edge_flange_0">
      <origin xyz="0.15 -0.022 0.0395" rpy="0 0 0" />
      <geometry>
        <box size="0.22 0.006 0.005" />
        </geometry>
      </collision>
    <collision name="edge_flange_1">
      <origin xyz="0.15 0.022 0.0395" rpy="0 0 0" />
      <geometry>
        <box size="0.22 0.006 0.005" />
        </geometry>
      </collision>
    <collision name="elbow_head">
      <origin xyz="0 0 0.042" rpy="0 0 0" />
      <geometry>
        <mesh filename="assets/meshes/elbow_top_washer_mesh.obj" />
        </geometry>
      </collision>
    <collision name="elbow_shank">
      <origin xyz="0 0 0.015" rpy="0 0 0" />
      <geometry>
        <cylinder radius="0.009" length="0.06" />
        </geometry>
      </collision>
    <collision name="end_clevis">
      <origin xyz="0.316 0 0.032" rpy="0 0 0" />
      <geometry>
        <box size="0.034 0.058 0.02" />
        </geometry>
      </collision>
    </link>
  <link name="end_pad">
    <visual name="pad_saddle">
      <origin xyz="0.009 0 0" rpy="0 0 0" />
      <geometry>
        <box size="0.018 0.06 0.03" />
        </geometry>
      <material name="blackened_steel" />
      </visual>
    <visual name="rubber_face">
      <origin xyz="0.033 0 0" rpy="0 0 0" />
      <geometry>
        <box size="0.03 0.074 0.044" />
        </geometry>
      <material name="rubber" />
      </visual>
    <collision name="pad_saddle">
      <origin xyz="0.009 0 0" rpy="0 0 0" />
      <geometry>
        <box size="0.018 0.06 0.03" />
        </geometry>
      </collision>
    <collision name="rubber_face">
      <origin xyz="0.033 0 0" rpy="0 0 0" />
      <geometry>
        <box size="0.03 0.074 0.044" />
        </geometry>
      </collision>
    </link>
  <joint name="shoulder" type="revolute">
    <origin xyz="0 0 0.1" rpy="0 0 0" />
    <parent link="base_bracket" />
    <child link="first_link" />
    <axis xyz="0 0 1" />
    <limit effort="40" velocity="1.6" lower="-1.1" upper="1.1" />
    </joint>
  <joint name="elbow" type="revolute">
    <origin xyz="0.46 0 0" rpy="0 0 0" />
    <parent link="first_link" />
    <child link="second_link" />
    <axis xyz="0 0 1" />
    <limit effort="22" velocity="1.8" lower="-2.2" upper="2.2" />
    </joint>
  <joint name="pad_mount" type="fixed">
    <origin xyz="0.333 0 0.032" rpy="0 0 0" />
    <parent link="second_link" />
    <child link="end_pad" />
    </joint>
  </robot>
