<robot name="split_body_slide_rotary_nose">
  <material name="cast_iron">
    <color rgba="0.19 0.21 0.22 1" />
    </material>
  <material name="ground_steel">
    <color rgba="0.63 0.66 0.68 1" />
    </material>
  <material name="dark_oxide">
    <color rgba="0.05 0.055 0.06 1" />
    </material>
  <material name="carriage_paint">
    <color rgba="0.08 0.18 0.28 1" />
    </material>
  <material name="bronze_wear">
    <color rgba="0.75 0.48 0.19 1" />
    </material>
  <material name="nose_steel">
    <color rgba="0.8 0.8 0.76 1" />
    </material>
  <material name="marker_red">
    <color rgba="0.82 0.08 0.05 1" />
    </material>
  <link name="guide">
    <inertial>
      <mass value="3.5" />
      <inertia ixx="0.0135333" ixy="0" ixz="0" iyy="0.0635833" iyz="0" izz="0.0733833" />
      </inertial>
    <visual name="base_plate">
      <origin xyz="0 0 0.0125" rpy="0 0 0" />
      <geometry>
        <box size="0.46 0.2 0.025" />
        </geometry>
      <material name="cast_iron">
        <color rgba="0.19 0.21 0.22 1" />
        </material>
      </visual>
    <visual name="rail_0">
      <origin xyz="0 0.075 0.0525" rpy="0 0 0" />
      <geometry>
        <box size="0.44 0.04 0.055" />
        </geometry>
      <material name="ground_steel">
        <color rgba="0.63 0.66 0.68 1" />
        </material>
      </visual>
    <visual name="bolt_0_0">
      <origin xyz="-0.165 0.075 0.0825" rpy="0 0 0" />
      <geometry>
        <cylinder radius="0.0065" length="0.006" />
        </geometry>
      <material name="dark_oxide">
        <color rgba="0.05 0.055 0.06 1" />
        </material>
      </visual>
    <visual name="bolt_0_1">
      <origin xyz="-0.055 0.075 0.0825" rpy="0 0 0" />
      <geometry>
        <cylinder radius="0.0065" length="0.006" />
        </geometry>
      <material name="dark_oxide">
        <color rgba="0.05 0.055 0.06 1" />
        </material>
      </visual>
    <visual name="bolt_0_2">
      <origin xyz="0.055 0.075 0.0825" rpy="0 0 0" />
      <geometry>
        <cylinder radius="0.0065" length="0.006" />
        </geometry>
      <material name="dark_oxide">
        <color rgba="0.05 0.055 0.06 1" />
        </material>
      </visual>
    <visual name="bolt_0_3">
      <origin xyz="0.165 0.075 0.0825" rpy="0 0 0" />
      <geometry>
        <cylinder radius="0.0065" length="0.006" />
        </geometry>
      <material name="dark_oxide">
        <color rgba="0.05 0.055 0.06 1" />
        </material>
      </visual>
    <visual name="rail_1">
      <origin xyz="0 -0.075 0.0525" rpy="0 0 0" />
      <geometry>
        <box size="0.44 0.04 0.055" />
        </geometry>
      <material name="ground_steel">
        <color rgba="0.63 0.66 0.68 1" />
        </material>
      </visual>
    <visual name="bolt_1_0">
      <origin xyz="-0.165 -0.075 0.0825" rpy="0 0 0" />
      <geometry>
        <cylinder radius="0.0065" length="0.006" />
        </geometry>
      <material name="dark_oxide">
        <color rgba="0.05 0.055 0.06 1" />
        </material>
      </visual>
    <visual name="bolt_1_1">
      <origin xyz="-0.055 -0.075 0.0825" rpy="0 0 0" />
      <geometry>
        <cylinder radius="0.0065" length="0.006" />
        </geometry>
      <material name="dark_oxide">
        <color rgba="0.05 0.055 0.06 1" />
        </material>
      </visual>
    <visual name="bolt_1_2">
      <origin xyz="0.055 -0.075 0.0825" rpy="0 0 0" />
      <geometry>
        <cylinder radius="0.0065" length="0.006" />
        </geometry>
      <material name="dark_oxide">
        <color rgba="0.05 0.055 0.06 1" />
        </material>
      </visual>
    <visual name="bolt_1_3">
      <origin xyz="0.165 -0.075 0.0825" rpy="0 0 0" />
      <geometry>
        <cylinder radius="0.0065" length="0.006" />
        </geometry>
      <material name="dark_oxide">
        <color rgba="0.05 0.055 0.06 1" />
        </material>
      </visual>
    <visual name="end_stop_0_0">
      <origin xyz="-0.219 0.075 0.055" rpy="0 0 0" />
      <geometry>
        <box size="0.02 0.052 0.06" />
        </geometry>
      <material name="cast_iron">
        <color rgba="0.19 0.21 0.22 1" />
        </material>
      </visual>
    <visual name="end_stop_0_1">
      <origin xyz="-0.219 -0.075 0.055" rpy="0 0 0" />
      <geometry>
        <box size="0.02 0.052 0.06" />
        </geometry>
      <material name="cast_iron">
        <color rgba="0.19 0.21 0.22 1" />
        </material>
      </visual>
    <visual name="end_stop_1_0">
      <origin xyz="0.219 0.075 0.055" rpy="0 0 0" />
      <geometry>
        <box size="0.02 0.052 0.06" />
        </geometry>
      <material name="cast_iron">
        <color rgba="0.19 0.21 0.22 1" />
        </material>
      </visual>
    <visual name="end_stop_1_1">
      <origin xyz="0.219 -0.075 0.055" rpy="0 0 0" />
      <geometry>
        <box size="0.02 0.052 0.06" />
        </geometry>
      <material name="cast_iron">
        <color rgba="0.19 0.21 0.22 1" />
        </material>
      </visual>
    <collision name="base_plate">
      <origin xyz="0 0 0.0125" rpy="0 0 0" />
      <geometry>
        <box size="0.46 0.2 0.025" />
        </geometry>
      </collision>
    <collision name="rail_0">
      <origin xyz="0 0.075 0.0525" rpy="0 0 0" />
      <geometry>
        <box size="0.44 0.04 0.055" />
        </geometry>
      </collision>
    <collision name="bolt_0_0">
      <origin xyz="-0.165 0.075 0.0825" rpy="0 0 0" />
      <geometry>
        <cylinder radius="0.0065" length="0.006" />
        </geometry>
      </collision>
    <collision name="bolt_0_1">
      <origin xyz="-0.055 0.075 0.0825" rpy="0 0 0" />
      <geometry>
        <cylinder radius="0.0065" length="0.006" />
        </geometry>
      </collision>
    <collision name="bolt_0_2">
      <origin xyz="0.055 0.075 0.0825" rpy="0 0 0" />
      <geometry>
        <cylinder radius="0.0065" length="0.006" />
        </geometry>
      </collision>
    <collision name="bolt_0_3">
      <origin xyz="0.165 0.075 0.0825" rpy="0 0 0" />
      <geometry>
        <cylinder radius="0.0065" length="0.006" />
        </geometry>
      </collision>
    <collision name="rail_1">
      <origin xyz="0 -0.075 0.0525" rpy="0 0 0" />
      <geometry>
        <box size="0.44 0.04 0.055" />
        </geometry>
      </collision>
    <collision name="bolt_1_0">
      <origin xyz="-0.165 -0.075 0.0825" rpy="0 0 0" />
      <geometry>
        <cylinder radius="0.0065" length="0.006" />
        </geometry>
      </collision>
    <collision name="bolt_1_1">
      <origin xyz="-0.055 -0.075 0.0825" rpy="0 0 0" />
      <geometry>
        <cylinder radius="0.0065" length="0.006" />
        </geometry>
      </collision>
    <collision name="bolt_1_2">
      <origin xyz="0.055 -0.075 0.0825" rpy="0 0 0" />
      <geometry>
        <cylinder radius="0.0065" length="0.006" />
        </geometry>
      </collision>
    <collision name="bolt_1_3">
      <origin xyz="0.165 -0.075 0.0825" rpy="0 0 0" />
      <geometry>
        <cylinder radius="0.0065" length="0.006" />
        </geometry>
      </collision>
    <collision name="end_stop_0_0">
      <origin xyz="-0.219 0.075 0.055" rpy="0 0 0" />
      <geometry>
        <box size="0.02 0.052 0.06" />
        </geometry>
      </collision>
    <collision name="end_stop_0_1">
      <origin xyz="-0.219 -0.075 0.055" rpy="0 0 0" />
      <geometry>
        <box size="0.02 0.052 0.06" />
        </geometry>
      </collision>
    <collision name="end_stop_1_0">
      <origin xyz="0.219 0.075 0.055" rpy="0 0 0" />
      <geometry>
        <box size="0.02 0.052 0.06" />
        </geometry>
      </collision>
    <collision name="end_stop_1_1">
      <origin xyz="0.219 -0.075 0.055" rpy="0 0 0" />
      <geometry>
        <box size="0.02 0.052 0.06" />
        </geometry>
      </collision>
    </link>
  <link name="carriage">
    <inertial>
      <origin xyz="0.006 0 0.006" rpy="0 0 0" />
      <mass value="0.9" />
      <inertia ixx="0.0011271" ixy="0" ixz="0" iyy="0.00142417" iyz="0" izz="0.00204667" />
      </inertial>
    <visual name="saddle_block">
      <geometry>
        <box size="0.105 0.096 0.04" />
        </geometry>
      <material name="carriage_paint">
        <color rgba="0.08 0.18 0.28 1" />
        </material>
      </visual>
    <visual name="top_cap">
      <origin xyz="0 0 0.026" rpy="0 0 0" />
      <geometry>
        <box size="0.115 0.108 0.012" />
        </geometry>
      <material name="carriage_paint">
        <color rgba="0.08 0.18 0.28 1" />
        </material>
      </visual>
    <visual name="wear_pad_0">
      <origin xyz="0 0.0515 -0.004" rpy="0 0 0" />
      <geometry>
        <box size="0.09 0.007 0.026" />
        </geometry>
      <material name="bronze_wear">
        <color rgba="0.75 0.48 0.19 1" />
        </material>
      </visual>
    <visual name="wear_pad_1">
      <origin xyz="0 -0.0515 -0.004" rpy="0 0 0" />
      <geometry>
        <box size="0.09 0.007 0.026" />
        </geometry>
      <material name="bronze_wear">
        <color rgba="0.75 0.48 0.19 1" />
        </material>
      </visual>
    <visual name="front_boss">
      <origin xyz="0.0525 0 0.004" rpy="0 0 0" />
      <geometry>
        <box size="0.012 0.058 0.044" />
        </geometry>
      <material name="carriage_paint">
        <color rgba="0.08 0.18 0.28 1" />
        </material>
      </visual>
    <visual name="bearing_ring">
      <origin xyz="0.064 0 0.005" rpy="0 0 0" />
      <geometry>
        <mesh filename="assets/meshes/carriage_bearing_ring.obj" />
        </geometry>
      <material name="ground_steel">
        <color rgba="0.63 0.66 0.68 1" />
        </material>
      </visual>
    <collision name="saddle_block">
      <geometry>
        <box size="0.105 0.096 0.04" />
        </geometry>
      </collision>
    <collision name="top_cap">
      <origin xyz="0 0 0.026" rpy="0 0 0" />
      <geometry>
        <box size="0.115 0.108 0.012" />
        </geometry>
      </collision>
    <collision name="wear_pad_0">
      <origin xyz="0 0.0515 -0.004" rpy="0 0 0" />
      <geometry>
        <box size="0.09 0.007 0.026" />
        </geometry>
      </collision>
    <collision name="wear_pad_1">
      <origin xyz="0 -0.0515 -0.004" rpy="0 0 0" />
      <geometry>
        <box size="0.09 0.007 0.026" />
        </geometry>
      </collision>
    <collision name="front_boss">
      <origin xyz="0.0525 0 0.004" rpy="0 0 0" />
      <geometry>
        <box size="0.012 0.058 0.044" />
        </geometry>
      </collision>
    <collision name="bearing_ring">
      <origin xyz="0.064 0 0.005" rpy="0 0 0" />
      <geometry>
        <mesh filename="assets/meshes/carriage_bearing_ring.obj" />
        </geometry>
      </collision>
    </link>
  <link name="nose">
    <inertial>
      <origin xyz="0.04 0 0" rpy="0 1.5708 0" />
      <mass value="0.28" />
      <inertia ixx="0.00024003" ixy="0" ixz="0" iyy="0.00024003" iyz="0" izz="0.00010206" />
      </inertial>
    <visual name="rear_stub">
      <origin xyz="0.008 0 0" rpy="0 1.5708 0" />
      <geometry>
        <cylinder radius="0.014" length="0.035" />
        </geometry>
      <material name="nose_steel">
        <color rgba="0.8 0.8 0.76 1" />
        </material>
      </visual>
    <visual name="cartridge_body">
      <origin xyz="0.04 0 0" rpy="0 1.5708 0" />
      <geometry>
        <cylinder radius="0.017" length="0.058" />
        </geometry>
      <material name="nose_steel">
        <color rgba="0.8 0.8 0.76 1" />
        </material>
      </visual>
    <visual name="flange">
      <origin xyz="0.074 0 0" rpy="0 1.5708 0" />
      <geometry>
        <cylinder radius="0.027" length="0.01" />
        </geometry>
      <material name="nose_steel">
        <color rgba="0.8 0.8 0.76 1" />
        </material>
      </visual>
    <visual name="front_cap">
      <origin xyz="0.082 0 0" rpy="0 1.5708 0" />
      <geometry>
        <cylinder radius="0.012" length="0.006" />
        </geometry>
      <material name="dark_oxide">
        <color rgba="0.05 0.055 0.06 1" />
        </material>
      </visual>
    <visual name="index_tab">
      <origin xyz="0.074 0 0.029" rpy="0 0 0" />
      <geometry>
        <box size="0.008 0.01 0.01" />
        </geometry>
      <material name="marker_red">
        <color rgba="0.82 0.08 0.05 1" />
        </material>
      </visual>
    <collision name="rear_stub">
      <origin xyz="0.008 0 0" rpy="0 1.5708 0" />
      <geometry>
        <cylinder radius="0.014" length="0.035" />
        </geometry>
      </collision>
    <collision name="cartridge_body">
      <origin xyz="0.04 0 0" rpy="0 1.5708 0" />
      <geometry>
        <cylinder radius="0.017" length="0.058" />
        </geometry>
      </collision>
    <collision name="flange">
      <origin xyz="0.074 0 0" rpy="0 1.5708 0" />
      <geometry>
        <cylinder radius="0.027" length="0.01" />
        </geometry>
      </collision>
    <collision name="front_cap">
      <origin xyz="0.082 0 0" rpy="0 1.5708 0" />
      <geometry>
        <cylinder radius="0.012" length="0.006" />
        </geometry>
      </collision>
    <collision name="index_tab">
      <origin xyz="0.074 0 0.029" rpy="0 0 0" />
      <geometry>
        <box size="0.008 0.01 0.01" />
        </geometry>
      </collision>
    </link>
  <joint name="carriage_slide" type="prismatic">
    <origin xyz="-0.09 0 0.064" rpy="0 0 0" />
    <parent link="guide" />
    <child link="carriage" />
    <axis xyz="1 0 0" />
    <limit effort="90" velocity="0.35" lower="0" upper="0.18" />
    </joint>
  <joint name="nose_spin" type="revolute">
    <origin xyz="0.064 0 0.005" rpy="0 0 0" />
    <parent link="carriage" />
    <child link="nose" />
    <axis xyz="1 0 0" />
    <limit effort="8" velocity="6" lower="-3.14159" upper="3.14159" />
    </joint>
  </robot>
