<robot name="wide_range_cooker_rotisserie">
  <material name="brushed_stainless">
    <color rgba="0.72 0.72 0.68 1" />
    </material>
  <material name="black_enamel">
    <color rgba="0.035 0.035 0.038 1" />
    </material>
  <material name="matte_cast_iron">
    <color rgba="0.01 0.01 0.012 1" />
    </material>
  <material name="smoky_glass">
    <color rgba="0.08 0.13 0.16 0.42" />
    </material>
  <material name="polished_handle">
    <color rgba="0.86 0.86 0.82 1" />
    </material>
  <link name="body">
    <visual name="bottom_plinth">
      <origin xyz="0 0 0.1" rpy="0 0 0" />
      <geometry>
        <box size="1.2 0.68 0.06" />
        </geometry>
      <material name="brushed_stainless">
        <color rgba="0.72 0.72 0.68 1" />
        </material>
      </visual>
    <visual name="cooktop_deck">
      <origin xyz="0 0 0.865" rpy="0 0 0" />
      <geometry>
        <box size="1.2 0.68 0.07" />
        </geometry>
      <material name="brushed_stainless">
        <color rgba="0.72 0.72 0.68 1" />
        </material>
      </visual>
    <visual name="side_panel_0">
      <origin xyz="-0.575 0 0.48" rpy="0 0 0" />
      <geometry>
        <box size="0.05 0.68 0.82" />
        </geometry>
      <material name="brushed_stainless">
        <color rgba="0.72 0.72 0.68 1" />
        </material>
      </visual>
    <visual name="side_panel_1">
      <origin xyz="0.575 0 0.48" rpy="0 0 0" />
      <geometry>
        <box size="0.05 0.68 0.82" />
        </geometry>
      <material name="brushed_stainless">
        <color rgba="0.72 0.72 0.68 1" />
        </material>
      </visual>
    <visual name="rear_panel">
      <origin xyz="0 0.318 0.48" rpy="0 0 0" />
      <geometry>
        <box size="1.2 0.045 0.82" />
        </geometry>
      <material name="brushed_stainless">
        <color rgba="0.72 0.72 0.68 1" />
        </material>
      </visual>
    <visual name="front_fascia">
      <origin xyz="0 -0.333 0.78" rpy="0 0 0" />
      <geometry>
        <box size="1.2 0.038 0.165" />
        </geometry>
      <material name="brushed_stainless">
        <color rgba="0.72 0.72 0.68 1" />
        </material>
      </visual>
    <visual name="front_post_0">
      <origin xyz="-0.5425 -0.333 0.435" rpy="0 0 0" />
      <geometry>
        <box size="0.115 0.038 0.565" />
        </geometry>
      <material name="brushed_stainless">
        <color rgba="0.72 0.72 0.68 1" />
        </material>
      </visual>
    <visual name="front_post_1">
      <origin xyz="0.5425 -0.333 0.435" rpy="0 0 0" />
      <geometry>
        <box size="0.115 0.038 0.565" />
        </geometry>
      <material name="brushed_stainless">
        <color rgba="0.72 0.72 0.68 1" />
        </material>
      </visual>
    <visual name="front_sill">
      <origin xyz="0 -0.333 0.177" rpy="0 0 0" />
      <geometry>
        <box size="1.2 0.038 0.085" />
        </geometry>
      <material name="brushed_stainless">
        <color rgba="0.72 0.72 0.68 1" />
        </material>
      </visual>
    <visual name="oven_back_liner">
      <origin xyz="0 0.287 0.455" rpy="0 0 0" />
      <geometry>
        <box size="1.03 0.018 0.5" />
        </geometry>
      <material name="black_enamel">
        <color rgba="0.035 0.035 0.038 1" />
        </material>
      </visual>
    <visual name="oven_floor">
      <origin xyz="0 -0.02 0.205" rpy="0 0 0" />
      <geometry>
        <box size="1.12 0.555 0.016" />
        </geometry>
      <material name="black_enamel">
        <color rgba="0.035 0.035 0.038 1" />
        </material>
      </visual>
    <visual name="oven_ceiling">
      <origin xyz="0 -0.02 0.692" rpy="0 0 0" />
      <geometry>
        <box size="1.12 0.555 0.016" />
        </geometry>
      <material name="black_enamel">
        <color rgba="0.035 0.035 0.038 1" />
        </material>
      </visual>
    <visual name="body_hinge_barrel">
      <origin xyz="0 -0.35 0.185" rpy="0 1.5708 0" />
      <geometry>
        <cylinder radius="0.01" length="1.12" />
        </geometry>
      <material name="polished_handle">
        <color rgba="0.86 0.86 0.82 1" />
        </material>
      </visual>
    <visual name="spit_shelf_0">
      <origin xyz="-0.528 -0.04 0.454" rpy="0 0 0" />
      <geometry>
        <box size="0.06 0.085 0.008" />
        </geometry>
      <material name="polished_handle">
        <color rgba="0.86 0.86 0.82 1" />
        </material>
      </visual>
    <visual name="spit_shelf_1">
      <origin xyz="0.528 -0.04 0.454" rpy="0 0 0" />
      <geometry>
        <box size="0.06 0.085 0.008" />
        </geometry>
      <material name="polished_handle">
        <color rgba="0.86 0.86 0.82 1" />
        </material>
      </visual>
    <visual name="foot_0">
      <origin xyz="-0.48 -0.24 0.035" rpy="0 0 0" />
      <geometry>
        <cylinder radius="0.035" length="0.07" />
        </geometry>
      <material name="black_enamel">
        <color rgba="0.035 0.035 0.038 1" />
        </material>
      </visual>
    <visual name="foot_1">
      <origin xyz="0.48 -0.24 0.035" rpy="0 0 0" />
      <geometry>
        <cylinder radius="0.035" length="0.07" />
        </geometry>
      <material name="black_enamel">
        <color rgba="0.035 0.035 0.038 1" />
        </material>
      </visual>
    <visual name="foot_2">
      <origin xyz="-0.48 0.24 0.035" rpy="0 0 0" />
      <geometry>
        <cylinder radius="0.035" length="0.07" />
        </geometry>
      <material name="black_enamel">
        <color rgba="0.035 0.035 0.038 1" />
        </material>
      </visual>
    <visual name="foot_3">
      <origin xyz="0.48 0.24 0.035" rpy="0 0 0" />
      <geometry>
        <cylinder radius="0.035" length="0.07" />
        </geometry>
      <material name="black_enamel">
        <color rgba="0.035 0.035 0.038 1" />
        </material>
      </visual>
    <visual name="burner_cap_0">
      <origin xyz="-0.38 -0.18 0.904" rpy="0 0 0" />
      <geometry>
        <cylinder radius="0.06" length="0.012" />
        </geometry>
      <material name="matte_cast_iron">
        <color rgba="0.01 0.01 0.012 1" />
        </material>
      </visual>
    <visual name="burner_grate_x_0">
      <origin xyz="-0.38 -0.18 0.918" rpy="0 0 0" />
      <geometry>
        <box size="0.147 0.018 0.016" />
        </geometry>
      <material name="matte_cast_iron">
        <color rgba="0.01 0.01 0.012 1" />
        </material>
      </visual>
    <visual name="burner_grate_y_0">
      <origin xyz="-0.38 -0.18 0.918" rpy="0 0 0" />
      <geometry>
        <box size="0.018 0.147 0.016" />
        </geometry>
      <material name="matte_cast_iron">
        <color rgba="0.01 0.01 0.012 1" />
        </material>
      </visual>
    <visual name="burner_cap_1">
      <origin xyz="0 -0.18 0.904" rpy="0 0 0" />
      <geometry>
        <cylinder radius="0.072" length="0.012" />
        </geometry>
      <material name="matte_cast_iron">
        <color rgba="0.01 0.01 0.012 1" />
        </material>
      </visual>
    <visual name="burner_grate_x_1">
      <origin xyz="0 -0.18 0.918" rpy="0 0 0" />
      <geometry>
        <box size="0.1764 0.018 0.016" />
        </geometry>
      <material name="matte_cast_iron">
        <color rgba="0.01 0.01 0.012 1" />
        </material>
      </visual>
    <visual name="burner_grate_y_1">
      <origin xyz="0 -0.18 0.918" rpy="0 0 0" />
      <geometry>
        <box size="0.018 0.1764 0.016" />
        </geometry>
      <material name="matte_cast_iron">
        <color rgba="0.01 0.01 0.012 1" />
        </material>
      </visual>
    <visual name="burner_cap_2">
      <origin xyz="0.38 -0.18 0.904" rpy="0 0 0" />
      <geometry>
        <cylinder radius="0.06" length="0.012" />
        </geometry>
      <material name="matte_cast_iron">
        <color rgba="0.01 0.01 0.012 1" />
        </material>
      </visual>
    <visual name="burner_grate_x_2">
      <origin xyz="0.38 -0.18 0.918" rpy="0 0 0" />
      <geometry>
        <box size="0.147 0.018 0.016" />
        </geometry>
      <material name="matte_cast_iron">
        <color rgba="0.01 0.01 0.012 1" />
        </material>
      </visual>
    <visual name="burner_grate_y_2">
      <origin xyz="0.38 -0.18 0.918" rpy="0 0 0" />
      <geometry>
        <box size="0.018 0.147 0.016" />
        </geometry>
      <material name="matte_cast_iron">
        <color rgba="0.01 0.01 0.012 1" />
        </material>
      </visual>
    <visual name="burner_cap_3">
      <origin xyz="-0.24 0.17 0.904" rpy="0 0 0" />
      <geometry>
        <cylinder radius="0.06" length="0.012" />
        </geometry>
      <material name="matte_cast_iron">
        <color rgba="0.01 0.01 0.012 1" />
        </material>
      </visual>
    <visual name="burner_grate_x_3">
      <origin xyz="-0.24 0.17 0.918" rpy="0 0 0" />
      <geometry>
        <box size="0.147 0.018 0.016" />
        </geometry>
      <material name="matte_cast_iron">
        <color rgba="0.01 0.01 0.012 1" />
        </material>
      </visual>
    <visual name="burner_grate_y_3">
      <origin xyz="-0.24 0.17 0.918" rpy="0 0 0" />
      <geometry>
        <box size="0.018 0.147 0.016" />
        </geometry>
      <material name="matte_cast_iron">
        <color rgba="0.01 0.01 0.012 1" />
        </material>
      </visual>
    <visual name="burner_cap_4">
      <origin xyz="0.24 0.17 0.904" rpy="0 0 0" />
      <geometry>
        <cylinder radius="0.06" length="0.012" />
        </geometry>
      <material name="matte_cast_iron">
        <color rgba="0.01 0.01 0.012 1" />
        </material>
      </visual>
    <visual name="burner_grate_x_4">
      <origin xyz="0.24 0.17 0.918" rpy="0 0 0" />
      <geometry>
        <box size="0.147 0.018 0.016" />
        </geometry>
      <material name="matte_cast_iron">
        <color rgba="0.01 0.01 0.012 1" />
        </material>
      </visual>
    <visual name="burner_grate_y_4">
      <origin xyz="0.24 0.17 0.918" rpy="0 0 0" />
      <geometry>
        <box size="0.018 0.147 0.016" />
        </geometry>
      <material name="matte_cast_iron">
        <color rgba="0.01 0.01 0.012 1" />
        </material>
      </visual>
    <collision name="bottom_plinth">
      <origin xyz="0 0 0.1" rpy="0 0 0" />
      <geometry>
        <box size="1.2 0.68 0.06" />
        </geometry>
      </collision>
    <collision name="cooktop_deck">
      <origin xyz="0 0 0.865" rpy="0 0 0" />
      <geometry>
        <box size="1.2 0.68 0.07" />
        </geometry>
      </collision>
    <collision name="side_panel_0">
      <origin xyz="-0.575 0 0.48" rpy="0 0 0" />
      <geometry>
        <box size="0.05 0.68 0.82" />
        </geometry>
      </collision>
    <collision name="side_panel_1">
      <origin xyz="0.575 0 0.48" rpy="0 0 0" />
      <geometry>
        <box size="0.05 0.68 0.82" />
        </geometry>
      </collision>
    <collision name="rear_panel">
      <origin xyz="0 0.318 0.48" rpy="0 0 0" />
      <geometry>
        <box size="1.2 0.045 0.82" />
        </geometry>
      </collision>
    <collision name="front_fascia">
      <origin xyz="0 -0.333 0.78" rpy="0 0 0" />
      <geometry>
        <box size="1.2 0.038 0.165" />
        </geometry>
      </collision>
    <collision name="front_post_0">
      <origin xyz="-0.5425 -0.333 0.435" rpy="0 0 0" />
      <geometry>
        <box size="0.115 0.038 0.565" />
        </geometry>
      </collision>
    <collision name="front_post_1">
      <origin xyz="0.5425 -0.333 0.435" rpy="0 0 0" />
      <geometry>
        <box size="0.115 0.038 0.565" />
        </geometry>
      </collision>
    <collision name="front_sill">
      <origin xyz="0 -0.333 0.177" rpy="0 0 0" />
      <geometry>
        <box size="1.2 0.038 0.085" />
        </geometry>
      </collision>
    <collision name="oven_back_liner">
      <origin xyz="0 0.287 0.455" rpy="0 0 0" />
      <geometry>
        <box size="1.03 0.018 0.5" />
        </geometry>
      </collision>
    <collision name="oven_floor">
      <origin xyz="0 -0.02 0.205" rpy="0 0 0" />
      <geometry>
        <box size="1.12 0.555 0.016" />
        </geometry>
      </collision>
    <collision name="oven_ceiling">
      <origin xyz="0 -0.02 0.692" rpy="0 0 0" />
      <geometry>
        <box size="1.12 0.555 0.016" />
        </geometry>
      </collision>
    <collision name="body_hinge_barrel">
      <origin xyz="0 -0.35 0.185" rpy="0 1.5708 0" />
      <geometry>
        <cylinder radius="0.01" length="1.12" />
        </geometry>
      </collision>
    <collision name="spit_shelf_0">
      <origin xyz="-0.528 -0.04 0.454" rpy="0 0 0" />
      <geometry>
        <box size="0.06 0.085 0.008" />
        </geometry>
      </collision>
    <collision name="spit_shelf_1">
      <origin xyz="0.528 -0.04 0.454" rpy="0 0 0" />
      <geometry>
        <box size="0.06 0.085 0.008" />
        </geometry>
      </collision>
    <collision name="foot_0">
      <origin xyz="-0.48 -0.24 0.035" rpy="0 0 0" />
      <geometry>
        <cylinder radius="0.035" length="0.07" />
        </geometry>
      </collision>
    <collision name="foot_1">
      <origin xyz="0.48 -0.24 0.035" rpy="0 0 0" />
      <geometry>
        <cylinder radius="0.035" length="0.07" />
        </geometry>
      </collision>
    <collision name="foot_2">
      <origin xyz="-0.48 0.24 0.035" rpy="0 0 0" />
      <geometry>
        <cylinder radius="0.035" length="0.07" />
        </geometry>
      </collision>
    <collision name="foot_3">
      <origin xyz="0.48 0.24 0.035" rpy="0 0 0" />
      <geometry>
        <cylinder radius="0.035" length="0.07" />
        </geometry>
      </collision>
    <collision name="burner_cap_0">
      <origin xyz="-0.38 -0.18 0.904" rpy="0 0 0" />
      <geometry>
        <cylinder radius="0.06" length="0.012" />
        </geometry>
      </collision>
    <collision name="burner_grate_x_0">
      <origin xyz="-0.38 -0.18 0.918" rpy="0 0 0" />
      <geometry>
        <box size="0.147 0.018 0.016" />
        </geometry>
      </collision>
    <collision name="burner_grate_y_0">
      <origin xyz="-0.38 -0.18 0.918" rpy="0 0 0" />
      <geometry>
        <box size="0.018 0.147 0.016" />
        </geometry>
      </collision>
    <collision name="burner_cap_1">
      <origin xyz="0 -0.18 0.904" rpy="0 0 0" />
      <geometry>
        <cylinder radius="0.072" length="0.012" />
        </geometry>
      </collision>
    <collision name="burner_grate_x_1">
      <origin xyz="0 -0.18 0.918" rpy="0 0 0" />
      <geometry>
        <box size="0.1764 0.018 0.016" />
        </geometry>
      </collision>
    <collision name="burner_grate_y_1">
      <origin xyz="0 -0.18 0.918" rpy="0 0 0" />
      <geometry>
        <box size="0.018 0.1764 0.016" />
        </geometry>
      </collision>
    <collision name="burner_cap_2">
      <origin xyz="0.38 -0.18 0.904" rpy="0 0 0" />
      <geometry>
        <cylinder radius="0.06" length="0.012" />
        </geometry>
      </collision>
    <collision name="burner_grate_x_2">
      <origin xyz="0.38 -0.18 0.918" rpy="0 0 0" />
      <geometry>
        <box size="0.147 0.018 0.016" />
        </geometry>
      </collision>
    <collision name="burner_grate_y_2">
      <origin xyz="0.38 -0.18 0.918" rpy="0 0 0" />
      <geometry>
        <box size="0.018 0.147 0.016" />
        </geometry>
      </collision>
    <collision name="burner_cap_3">
      <origin xyz="-0.24 0.17 0.904" rpy="0 0 0" />
      <geometry>
        <cylinder radius="0.06" length="0.012" />
        </geometry>
      </collision>
    <collision name="burner_grate_x_3">
      <origin xyz="-0.24 0.17 0.918" rpy="0 0 0" />
      <geometry>
        <box size="0.147 0.018 0.016" />
        </geometry>
      </collision>
    <collision name="burner_grate_y_3">
      <origin xyz="-0.24 0.17 0.918" rpy="0 0 0" />
      <geometry>
        <box size="0.018 0.147 0.016" />
        </geometry>
      </collision>
    <collision name="burner_cap_4">
      <origin xyz="0.24 0.17 0.904" rpy="0 0 0" />
      <geometry>
        <cylinder radius="0.06" length="0.012" />
        </geometry>
      </collision>
    <collision name="burner_grate_x_4">
      <origin xyz="0.24 0.17 0.918" rpy="0 0 0" />
      <geometry>
        <box size="0.147 0.018 0.016" />
        </geometry>
      </collision>
    <collision name="burner_grate_y_4">
      <origin xyz="0.24 0.17 0.918" rpy="0 0 0" />
      <geometry>
        <box size="0.018 0.147 0.016" />
        </geometry>
      </collision>
    </link>
  <link name="door">
    <visual name="door_hinge_barrel">
      <origin xyz="0 0 0" rpy="0 1.5708 0" />
      <geometry>
        <cylinder radius="0.026" length="1.1" />
        </geometry>
      <material name="polished_handle">
        <color rgba="0.86 0.86 0.82 1" />
        </material>
      </visual>
    <visual name="door_bottom_rail">
      <origin xyz="0 0 0.0425" rpy="0 0 0" />
      <geometry>
        <box size="1.06 0.05 0.085" />
        </geometry>
      <material name="brushed_stainless">
        <color rgba="0.72 0.72 0.68 1" />
        </material>
      </visual>
    <visual name="door_top_rail">
      <origin xyz="0 0 0.4675" rpy="0 0 0" />
      <geometry>
        <box size="1.06 0.05 0.085" />
        </geometry>
      <material name="brushed_stainless">
        <color rgba="0.72 0.72 0.68 1" />
        </material>
      </visual>
    <visual name="door_side_0">
      <origin xyz="-0.485 0 0.255" rpy="0 0 0" />
      <geometry>
        <box size="0.09 0.05 0.51" />
        </geometry>
      <material name="brushed_stainless">
        <color rgba="0.72 0.72 0.68 1" />
        </material>
      </visual>
    <visual name="door_side_1">
      <origin xyz="0.485 0 0.255" rpy="0 0 0" />
      <geometry>
        <box size="0.09 0.05 0.51" />
        </geometry>
      <material name="brushed_stainless">
        <color rgba="0.72 0.72 0.68 1" />
        </material>
      </visual>
    <visual name="glass_panel">
      <origin xyz="0 -0.03 0.255" rpy="0 0 0" />
      <geometry>
        <box size="0.9 0.012 0.375" />
        </geometry>
      <material name="smoky_glass">
        <color rgba="0.08 0.13 0.16 0.42" />
        </material>
      </visual>
    <visual name="handle_standoff_0">
      <origin xyz="-0.41 -0.058 0.4" rpy="1.5708 0 0" />
      <geometry>
        <cylinder radius="0.014" length="0.08" />
        </geometry>
      <material name="polished_handle">
        <color rgba="0.86 0.86 0.82 1" />
        </material>
      </visual>
    <visual name="handle_standoff_1">
      <origin xyz="0.41 -0.058 0.4" rpy="1.5708 0 0" />
      <geometry>
        <cylinder radius="0.014" length="0.08" />
        </geometry>
      <material name="polished_handle">
        <color rgba="0.86 0.86 0.82 1" />
        </material>
      </visual>
    <visual name="bar_handle">
      <origin xyz="0 -0.098 0.4" rpy="0 1.5708 0" />
      <geometry>
        <cylinder radius="0.018" length="0.92" />
        </geometry>
      <material name="polished_handle">
        <color rgba="0.86 0.86 0.82 1" />
        </material>
      </visual>
    <collision name="door_hinge_barrel">
      <origin xyz="0 0 0" rpy="0 1.5708 0" />
      <geometry>
        <cylinder radius="0.026" length="1.1" />
        </geometry>
      </collision>
    <collision name="door_bottom_rail">
      <origin xyz="0 0 0.0425" rpy="0 0 0" />
      <geometry>
        <box size="1.06 0.05 0.085" />
        </geometry>
      </collision>
    <collision name="door_top_rail">
      <origin xyz="0 0 0.4675" rpy="0 0 0" />
      <geometry>
        <box size="1.06 0.05 0.085" />
        </geometry>
      </collision>
    <collision name="door_side_0">
      <origin xyz="-0.485 0 0.255" rpy="0 0 0" />
      <geometry>
        <box size="0.09 0.05 0.51" />
        </geometry>
      </collision>
    <collision name="door_side_1">
      <origin xyz="0.485 0 0.255" rpy="0 0 0" />
      <geometry>
        <box size="0.09 0.05 0.51" />
        </geometry>
      </collision>
    <collision name="glass_panel">
      <origin xyz="0 -0.03 0.255" rpy="0 0 0" />
      <geometry>
        <box size="0.9 0.012 0.375" />
        </geometry>
      </collision>
    <collision name="handle_standoff_0">
      <origin xyz="-0.41 -0.058 0.4" rpy="1.5708 0 0" />
      <geometry>
        <cylinder radius="0.014" length="0.08" />
        </geometry>
      </collision>
    <collision name="handle_standoff_1">
      <origin xyz="0.41 -0.058 0.4" rpy="1.5708 0 0" />
      <geometry>
        <cylinder radius="0.014" length="0.08" />
        </geometry>
      </collision>
    <collision name="bar_handle">
      <origin xyz="0 -0.098 0.4" rpy="0 1.5708 0" />
      <geometry>
        <cylinder radius="0.018" length="0.92" />
        </geometry>
      </collision>
    </link>
  <link name="spit">
    <visual name="spit_rod">
      <origin xyz="0 0 0" rpy="0 1.5708 0" />
      <geometry>
        <cylinder radius="0.012" length="1.08" />
        </geometry>
      <material name="polished_handle">
        <color rgba="0.86 0.86 0.82 1" />
        </material>
      </visual>
    <visual name="fork_collar_0">
      <origin xyz="-0.205 0 0" rpy="0 1.5708 0" />
      <geometry>
        <cylinder radius="0.024" length="0.038" />
        </geometry>
      <material name="polished_handle">
        <color rgba="0.86 0.86 0.82 1" />
        </material>
      </visual>
    <visual name="fork_collar_1">
      <origin xyz="0.205 0 0" rpy="0 1.5708 0" />
      <geometry>
        <cylinder radius="0.024" length="0.038" />
        </geometry>
      <material name="polished_handle">
        <color rgba="0.86 0.86 0.82 1" />
        </material>
      </visual>
    <visual name="fork_tine_0">
      <origin xyz="-0.13 -0.014 0.014" rpy="0 1.5708 0" />
      <geometry>
        <cylinder radius="0.004" length="0.145" />
        </geometry>
      <material name="polished_handle">
        <color rgba="0.86 0.86 0.82 1" />
        </material>
      </visual>
    <visual name="fork_tine_1">
      <origin xyz="-0.13 0.014 0.014" rpy="0 1.5708 0" />
      <geometry>
        <cylinder radius="0.004" length="0.145" />
        </geometry>
      <material name="polished_handle">
        <color rgba="0.86 0.86 0.82 1" />
        </material>
      </visual>
    <visual name="fork_tine_2">
      <origin xyz="0.13 -0.014 0.014" rpy="0 1.5708 0" />
      <geometry>
        <cylinder radius="0.004" length="0.145" />
        </geometry>
      <material name="polished_handle">
        <color rgba="0.86 0.86 0.82 1" />
        </material>
      </visual>
    <visual name="fork_tine_3">
      <origin xyz="0.13 0.014 0.014" rpy="0 1.5708 0" />
      <geometry>
        <cylinder radius="0.004" length="0.145" />
        </geometry>
      <material name="polished_handle">
        <color rgba="0.86 0.86 0.82 1" />
        </material>
      </visual>
    <collision name="spit_rod">
      <origin xyz="0 0 0" rpy="0 1.5708 0" />
      <geometry>
        <cylinder radius="0.012" length="1.08" />
        </geometry>
      </collision>
    <collision name="fork_collar_0">
      <origin xyz="-0.205 0 0" rpy="0 1.5708 0" />
      <geometry>
        <cylinder radius="0.024" length="0.038" />
        </geometry>
      </collision>
    <collision name="fork_collar_1">
      <origin xyz="0.205 0 0" rpy="0 1.5708 0" />
      <geometry>
        <cylinder radius="0.024" length="0.038" />
        </geometry>
      </collision>
    <collision name="fork_tine_0">
      <origin xyz="-0.13 -0.014 0.014" rpy="0 1.5708 0" />
      <geometry>
        <cylinder radius="0.004" length="0.145" />
        </geometry>
      </collision>
    <collision name="fork_tine_1">
      <origin xyz="-0.13 0.014 0.014" rpy="0 1.5708 0" />
      <geometry>
        <cylinder radius="0.004" length="0.145" />
        </geometry>
      </collision>
    <collision name="fork_tine_2">
      <origin xyz="0.13 -0.014 0.014" rpy="0 1.5708 0" />
      <geometry>
        <cylinder radius="0.004" length="0.145" />
        </geometry>
      </collision>
    <collision name="fork_tine_3">
      <origin xyz="0.13 0.014 0.014" rpy="0 1.5708 0" />
      <geometry>
        <cylinder radius="0.004" length="0.145" />
        </geometry>
      </collision>
    </link>
  <link name="knob_0">
    <visual name="knob_skirt">
      <origin xyz="0 -0.003 0" rpy="1.5708 0 0" />
      <geometry>
        <cylinder radius="0.032" length="0.006" />
        </geometry>
      <material name="brushed_stainless">
        <color rgba="0.72 0.72 0.68 1" />
        </material>
      </visual>
    <visual name="knob_cap">
      <origin xyz="0 -0.014 0" rpy="1.5708 0 0" />
      <geometry>
        <cylinder radius="0.026" length="0.024" />
        </geometry>
      <material name="brushed_stainless">
        <color rgba="0.72 0.72 0.68 1" />
        </material>
      </visual>
    <visual name="knob_marker">
      <origin xyz="0 -0.026 0.012" rpy="0 0 0" />
      <geometry>
        <box size="0.006 0.006 0.024" />
        </geometry>
      <material name="black_enamel">
        <color rgba="0.035 0.035 0.038 1" />
        </material>
      </visual>
    <collision name="knob_skirt">
      <origin xyz="0 -0.003 0" rpy="1.5708 0 0" />
      <geometry>
        <cylinder radius="0.032" length="0.006" />
        </geometry>
      </collision>
    <collision name="knob_cap">
      <origin xyz="0 -0.014 0" rpy="1.5708 0 0" />
      <geometry>
        <cylinder radius="0.026" length="0.024" />
        </geometry>
      </collision>
    <collision name="knob_marker">
      <origin xyz="0 -0.026 0.012" rpy="0 0 0" />
      <geometry>
        <box size="0.006 0.006 0.024" />
        </geometry>
      </collision>
    </link>
  <link name="knob_1">
    <visual name="knob_skirt">
      <origin xyz="0 -0.003 0" rpy="1.5708 0 0" />
      <geometry>
        <cylinder radius="0.032" length="0.006" />
        </geometry>
      <material name="brushed_stainless">
        <color rgba="0.72 0.72 0.68 1" />
        </material>
      </visual>
    <visual name="knob_cap">
      <origin xyz="0 -0.014 0" rpy="1.5708 0 0" />
      <geometry>
        <cylinder radius="0.026" length="0.024" />
        </geometry>
      <material name="brushed_stainless">
        <color rgba="0.72 0.72 0.68 1" />
        </material>
      </visual>
    <visual name="knob_marker">
      <origin xyz="0 -0.026 0.012" rpy="0 0 0" />
      <geometry>
        <box size="0.006 0.006 0.024" />
        </geometry>
      <material name="black_enamel">
        <color rgba="0.035 0.035 0.038 1" />
        </material>
      </visual>
    <collision name="knob_skirt">
      <origin xyz="0 -0.003 0" rpy="1.5708 0 0" />
      <geometry>
        <cylinder radius="0.032" length="0.006" />
        </geometry>
      </collision>
    <collision name="knob_cap">
      <origin xyz="0 -0.014 0" rpy="1.5708 0 0" />
      <geometry>
        <cylinder radius="0.026" length="0.024" />
        </geometry>
      </collision>
    <collision name="knob_marker">
      <origin xyz="0 -0.026 0.012" rpy="0 0 0" />
      <geometry>
        <box size="0.006 0.006 0.024" />
        </geometry>
      </collision>
    </link>
  <link name="knob_2">
    <visual name="knob_skirt">
      <origin xyz="0 -0.003 0" rpy="1.5708 0 0" />
      <geometry>
        <cylinder radius="0.032" length="0.006" />
        </geometry>
      <material name="brushed_stainless">
        <color rgba="0.72 0.72 0.68 1" />
        </material>
      </visual>
    <visual name="knob_cap">
      <origin xyz="0 -0.014 0" rpy="1.5708 0 0" />
      <geometry>
        <cylinder radius="0.026" length="0.024" />
        </geometry>
      <material name="brushed_stainless">
        <color rgba="0.72 0.72 0.68 1" />
        </material>
      </visual>
    <visual name="knob_marker">
      <origin xyz="0 -0.026 0.012" rpy="0 0 0" />
      <geometry>
        <box size="0.006 0.006 0.024" />
        </geometry>
      <material name="black_enamel">
        <color rgba="0.035 0.035 0.038 1" />
        </material>
      </visual>
    <collision name="knob_skirt">
      <origin xyz="0 -0.003 0" rpy="1.5708 0 0" />
      <geometry>
        <cylinder radius="0.032" length="0.006" />
        </geometry>
      </collision>
    <collision name="knob_cap">
      <origin xyz="0 -0.014 0" rpy="1.5708 0 0" />
      <geometry>
        <cylinder radius="0.026" length="0.024" />
        </geometry>
      </collision>
    <collision name="knob_marker">
      <origin xyz="0 -0.026 0.012" rpy="0 0 0" />
      <geometry>
        <box size="0.006 0.006 0.024" />
        </geometry>
      </collision>
    </link>
  <link name="knob_3">
    <visual name="knob_skirt">
      <origin xyz="0 -0.003 0" rpy="1.5708 0 0" />
      <geometry>
        <cylinder radius="0.032" length="0.006" />
        </geometry>
      <material name="brushed_stainless">
        <color rgba="0.72 0.72 0.68 1" />
        </material>
      </visual>
    <visual name="knob_cap">
      <origin xyz="0 -0.014 0" rpy="1.5708 0 0" />
      <geometry>
        <cylinder radius="0.026" length="0.024" />
        </geometry>
      <material name="brushed_stainless">
        <color rgba="0.72 0.72 0.68 1" />
        </material>
      </visual>
    <visual name="knob_marker">
      <origin xyz="0 -0.026 0.012" rpy="0 0 0" />
      <geometry>
        <box size="0.006 0.006 0.024" />
        </geometry>
      <material name="black_enamel">
        <color rgba="0.035 0.035 0.038 1" />
        </material>
      </visual>
    <collision name="knob_skirt">
      <origin xyz="0 -0.003 0" rpy="1.5708 0 0" />
      <geometry>
        <cylinder radius="0.032" length="0.006" />
        </geometry>
      </collision>
    <collision name="knob_cap">
      <origin xyz="0 -0.014 0" rpy="1.5708 0 0" />
      <geometry>
        <cylinder radius="0.026" length="0.024" />
        </geometry>
      </collision>
    <collision name="knob_marker">
      <origin xyz="0 -0.026 0.012" rpy="0 0 0" />
      <geometry>
        <box size="0.006 0.006 0.024" />
        </geometry>
      </collision>
    </link>
  <link name="knob_4">
    <visual name="knob_skirt">
      <origin xyz="0 -0.003 0" rpy="1.5708 0 0" />
      <geometry>
        <cylinder radius="0.032" length="0.006" />
        </geometry>
      <material name="brushed_stainless">
        <color rgba="0.72 0.72 0.68 1" />
        </material>
      </visual>
    <visual name="knob_cap">
      <origin xyz="0 -0.014 0" rpy="1.5708 0 0" />
      <geometry>
        <cylinder radius="0.026" length="0.024" />
        </geometry>
      <material name="brushed_stainless">
        <color rgba="0.72 0.72 0.68 1" />
        </material>
      </visual>
    <visual name="knob_marker">
      <origin xyz="0 -0.026 0.012" rpy="0 0 0" />
      <geometry>
        <box size="0.006 0.006 0.024" />
        </geometry>
      <material name="black_enamel">
        <color rgba="0.035 0.035 0.038 1" />
        </material>
      </visual>
    <collision name="knob_skirt">
      <origin xyz="0 -0.003 0" rpy="1.5708 0 0" />
      <geometry>
        <cylinder radius="0.032" length="0.006" />
        </geometry>
      </collision>
    <collision name="knob_cap">
      <origin xyz="0 -0.014 0" rpy="1.5708 0 0" />
      <geometry>
        <cylinder radius="0.026" length="0.024" />
        </geometry>
      </collision>
    <collision name="knob_marker">
      <origin xyz="0 -0.026 0.012" rpy="0 0 0" />
      <geometry>
        <box size="0.006 0.006 0.024" />
        </geometry>
      </collision>
    </link>
  <joint name="body_to_door" type="revolute">
    <origin xyz="0 -0.386 0.185" rpy="0 0 0" />
    <parent link="body" />
    <child link="door" />
    <axis xyz="1 0 0" />
    <limit effort="45" velocity="1.2" lower="0" upper="1.65" />
    </joint>
  <joint name="body_to_spit" type="revolute">
    <origin xyz="0 -0.04 0.47" rpy="0 0 0" />
    <parent link="body" />
    <child link="spit" />
    <axis xyz="1 0 0" />
    <limit effort="8" velocity="6" lower="-3.14159" upper="3.14159" />
    </joint>
  <joint name="body_to_knob_0" type="revolute">
    <origin xyz="-0.43 -0.352 0.805" rpy="0 0 0" />
    <parent link="body" />
    <child link="knob_0" />
    <axis xyz="0 -1 0" />
    <limit effort="1" velocity="3" lower="-2.45" upper="2.45" />
    </joint>
  <joint name="body_to_knob_1" type="revolute">
    <origin xyz="-0.215 -0.352 0.805" rpy="0 0 0" />
    <parent link="body" />
    <child link="knob_1" />
    <axis xyz="0 -1 0" />
    <limit effort="1" velocity="3" lower="-2.45" upper="2.45" />
    </joint>
  <joint name="body_to_knob_2" type="revolute">
    <origin xyz="0 -0.352 0.805" rpy="0 0 0" />
    <parent link="body" />
    <child link="knob_2" />
    <axis xyz="0 -1 0" />
    <limit effort="1" velocity="3" lower="-2.45" upper="2.45" />
    </joint>
  <joint name="body_to_knob_3" type="revolute">
    <origin xyz="0.215 -0.352 0.805" rpy="0 0 0" />
    <parent link="body" />
    <child link="knob_3" />
    <axis xyz="0 -1 0" />
    <limit effort="1" velocity="3" lower="-2.45" upper="2.45" />
    </joint>
  <joint name="body_to_knob_4" type="revolute">
    <origin xyz="0.43 -0.352 0.805" rpy="0 0 0" />
    <parent link="body" />
    <child link="knob_4" />
    <axis xyz="0 -1 0" />
    <limit effort="1" velocity="3" lower="-2.45" upper="2.45" />
    </joint>
  </robot>
