<robot name="compact_grasping_finger">
  <material name="clear_anodized_aluminum">
    <color rgba="0.68 0.7 0.72 1" />
    </material>
  <material name="dark_hard_anodized_aluminum">
    <color rgba="0.12 0.13 0.14 1" />
    </material>
  <material name="brushed_steel">
    <color rgba="0.78 0.76 0.7 1" />
    </material>
  <material name="replaceable_black_rubber">
    <color rgba="0.015 0.015 0.013 1" />
    </material>
  <material name="bronze_bushing">
    <color rgba="0.83 0.56 0.22 1" />
    </material>
  <link name="machine_base">
    <visual name="housing_body">
      <geometry>
        <mesh filename="assets/meshes/housing_body.obj" />
        </geometry>
      <material name="dark_hard_anodized_aluminum">
        <color rgba="0.12 0.13 0.14 1" />
        </material>
      </visual>
    <visual name="base_clevis_upper">
      <geometry>
        <mesh filename="assets/meshes/base_clevis_upper.obj" />
        </geometry>
      <material name="dark_hard_anodized_aluminum">
        <color rgba="0.12 0.13 0.14 1" />
        </material>
      </visual>
    <visual name="base_pin_cap_upper">
      <origin xyz="0 0.062 0" rpy="1.5708 0 0" />
      <geometry>
        <cylinder radius="0.0105" length="0.003" />
        </geometry>
      <material name="brushed_steel">
        <color rgba="0.78 0.76 0.7 1" />
        </material>
      </visual>
    <visual name="base_bushing_face_upper">
      <origin xyz="0 0.039 0" rpy="1.5708 0 0" />
      <geometry>
        <cylinder radius="0.015" length="0.0025" />
        </geometry>
      <material name="bronze_bushing">
        <color rgba="0.83 0.56 0.22 1" />
        </material>
      </visual>
    <visual name="base_clevis_lower">
      <geometry>
        <mesh filename="assets/meshes/base_clevis_lower.obj" />
        </geometry>
      <material name="dark_hard_anodized_aluminum">
        <color rgba="0.12 0.13 0.14 1" />
        </material>
      </visual>
    <visual name="base_pin_cap_lower">
      <origin xyz="0 -0.062 0" rpy="1.5708 0 0" />
      <geometry>
        <cylinder radius="0.0105" length="0.003" />
        </geometry>
      <material name="brushed_steel">
        <color rgba="0.78 0.76 0.7 1" />
        </material>
      </visual>
    <visual name="base_bushing_face_lower">
      <origin xyz="0 -0.039 0" rpy="1.5708 0 0" />
      <geometry>
        <cylinder radius="0.015" length="0.0025" />
        </geometry>
      <material name="bronze_bushing">
        <color rgba="0.83 0.56 0.22 1" />
        </material>
      </visual>
    <visual name="cap_screw_-0.137_-0.043">
      <origin xyz="-0.137 -0.043 0.0385" rpy="0 0 0" />
      <geometry>
        <cylinder radius="0.0065" length="0.003" />
        </geometry>
      <material name="brushed_steel">
        <color rgba="0.78 0.76 0.7 1" />
        </material>
      </visual>
    <visual name="cap_screw_-0.137_+0.043">
      <origin xyz="-0.137 0.043 0.0385" rpy="0 0 0" />
      <geometry>
        <cylinder radius="0.0065" length="0.003" />
        </geometry>
      <material name="brushed_steel">
        <color rgba="0.78 0.76 0.7 1" />
        </material>
      </visual>
    <visual name="cap_screw_-0.063_-0.043">
      <origin xyz="-0.063 -0.043 0.0385" rpy="0 0 0" />
      <geometry>
        <cylinder radius="0.0065" length="0.003" />
        </geometry>
      <material name="brushed_steel">
        <color rgba="0.78 0.76 0.7 1" />
        </material>
      </visual>
    <visual name="cap_screw_-0.063_+0.043">
      <origin xyz="-0.063 0.043 0.0385" rpy="0 0 0" />
      <geometry>
        <cylinder radius="0.0065" length="0.003" />
        </geometry>
      <material name="brushed_steel">
        <color rgba="0.78 0.76 0.7 1" />
        </material>
      </visual>
    <collision name="housing_body">
      <geometry>
        <mesh filename="assets/meshes/housing_body.obj" />
        </geometry>
      </collision>
    <collision name="base_clevis_upper">
      <geometry>
        <mesh filename="assets/meshes/base_clevis_upper.obj" />
        </geometry>
      </collision>
    <collision name="base_pin_cap_upper">
      <origin xyz="0 0.062 0" rpy="1.5708 0 0" />
      <geometry>
        <cylinder radius="0.0105" length="0.003" />
        </geometry>
      </collision>
    <collision name="base_bushing_face_upper">
      <origin xyz="0 0.039 0" rpy="1.5708 0 0" />
      <geometry>
        <cylinder radius="0.015" length="0.0025" />
        </geometry>
      </collision>
    <collision name="base_clevis_lower">
      <geometry>
        <mesh filename="assets/meshes/base_clevis_lower.obj" />
        </geometry>
      </collision>
    <collision name="base_pin_cap_lower">
      <origin xyz="0 -0.062 0" rpy="1.5708 0 0" />
      <geometry>
        <cylinder radius="0.0105" length="0.003" />
        </geometry>
      </collision>
    <collision name="base_bushing_face_lower">
      <origin xyz="0 -0.039 0" rpy="1.5708 0 0" />
      <geometry>
        <cylinder radius="0.015" length="0.0025" />
        </geometry>
      </collision>
    <collision name="cap_screw_-0.137_-0.043">
      <origin xyz="-0.137 -0.043 0.0385" rpy="0 0 0" />
      <geometry>
        <cylinder radius="0.0065" length="0.003" />
        </geometry>
      </collision>
    <collision name="cap_screw_-0.137_+0.043">
      <origin xyz="-0.137 0.043 0.0385" rpy="0 0 0" />
      <geometry>
        <cylinder radius="0.0065" length="0.003" />
        </geometry>
      </collision>
    <collision name="cap_screw_-0.063_-0.043">
      <origin xyz="-0.063 -0.043 0.0385" rpy="0 0 0" />
      <geometry>
        <cylinder radius="0.0065" length="0.003" />
        </geometry>
      </collision>
    <collision name="cap_screw_-0.063_+0.043">
      <origin xyz="-0.063 0.043 0.0385" rpy="0 0 0" />
      <geometry>
        <cylinder radius="0.0065" length="0.003" />
        </geometry>
      </collision>
    </link>
  <link name="root_link">
    <visual name="root_proximal_boss">
      <geometry>
        <mesh filename="assets/meshes/root_proximal_boss.obj" />
        </geometry>
      <material name="clear_anodized_aluminum">
        <color rgba="0.68 0.7 0.72 1" />
        </material>
      </visual>
    <visual name="root_body">
      <geometry>
        <mesh filename="assets/meshes/root_body.obj" />
        </geometry>
      <material name="clear_anodized_aluminum">
        <color rgba="0.68 0.7 0.72 1" />
        </material>
      </visual>
    <visual name="root_fork_bridge">
      <geometry>
        <mesh filename="assets/meshes/root_fork_bridge.obj" />
        </geometry>
      <material name="clear_anodized_aluminum">
        <color rgba="0.68 0.7 0.72 1" />
        </material>
      </visual>
    <visual name="root_fork_upper">
      <geometry>
        <mesh filename="assets/meshes/root_fork_upper.obj" />
        </geometry>
      <material name="clear_anodized_aluminum">
        <color rgba="0.68 0.7 0.72 1" />
        </material>
      </visual>
    <visual name="mid_pin_cap_upper">
      <origin xyz="0.11 0.052 0" rpy="1.5708 0 0" />
      <geometry>
        <cylinder radius="0.01" length="0.003" />
        </geometry>
      <material name="brushed_steel">
        <color rgba="0.78 0.76 0.7 1" />
        </material>
      </visual>
    <visual name="root_fork_lower">
      <geometry>
        <mesh filename="assets/meshes/root_fork_lower.obj" />
        </geometry>
      <material name="clear_anodized_aluminum">
        <color rgba="0.68 0.7 0.72 1" />
        </material>
      </visual>
    <visual name="mid_pin_cap_lower">
      <origin xyz="0.11 -0.052 0" rpy="1.5708 0 0" />
      <geometry>
        <cylinder radius="0.01" length="0.003" />
        </geometry>
      <material name="brushed_steel">
        <color rgba="0.78 0.76 0.7 1" />
        </material>
      </visual>
    <visual name="root_bushing_face_upper">
      <origin xyz="0 0.042 0" rpy="1.5708 0 0" />
      <geometry>
        <cylinder radius="0.0135" length="0.003" />
        </geometry>
      <material name="bronze_bushing">
        <color rgba="0.83 0.56 0.22 1" />
        </material>
      </visual>
    <visual name="root_bushing_face_lower">
      <origin xyz="0 -0.042 0" rpy="1.5708 0 0" />
      <geometry>
        <cylinder radius="0.0135" length="0.003" />
        </geometry>
      <material name="bronze_bushing">
        <color rgba="0.83 0.56 0.22 1" />
        </material>
      </visual>
    <collision name="root_proximal_boss">
      <geometry>
        <mesh filename="assets/meshes/root_proximal_boss.obj" />
        </geometry>
      </collision>
    <collision name="root_body">
      <geometry>
        <mesh filename="assets/meshes/root_body.obj" />
        </geometry>
      </collision>
    <collision name="root_fork_bridge">
      <geometry>
        <mesh filename="assets/meshes/root_fork_bridge.obj" />
        </geometry>
      </collision>
    <collision name="root_fork_upper">
      <geometry>
        <mesh filename="assets/meshes/root_fork_upper.obj" />
        </geometry>
      </collision>
    <collision name="mid_pin_cap_upper">
      <origin xyz="0.11 0.052 0" rpy="1.5708 0 0" />
      <geometry>
        <cylinder radius="0.01" length="0.003" />
        </geometry>
      </collision>
    <collision name="root_fork_lower">
      <geometry>
        <mesh filename="assets/meshes/root_fork_lower.obj" />
        </geometry>
      </collision>
    <collision name="mid_pin_cap_lower">
      <origin xyz="0.11 -0.052 0" rpy="1.5708 0 0" />
      <geometry>
        <cylinder radius="0.01" length="0.003" />
        </geometry>
      </collision>
    <collision name="root_bushing_face_upper">
      <origin xyz="0 0.042 0" rpy="1.5708 0 0" />
      <geometry>
        <cylinder radius="0.0135" length="0.003" />
        </geometry>
      </collision>
    <collision name="root_bushing_face_lower">
      <origin xyz="0 -0.042 0" rpy="1.5708 0 0" />
      <geometry>
        <cylinder radius="0.0135" length="0.003" />
        </geometry>
      </collision>
    </link>
  <link name="mid_link">
    <visual name="mid_proximal_boss">
      <geometry>
        <mesh filename="assets/meshes/mid_proximal_boss.obj" />
        </geometry>
      <material name="clear_anodized_aluminum">
        <color rgba="0.68 0.7 0.72 1" />
        </material>
      </visual>
    <visual name="mid_web">
      <geometry>
        <mesh filename="assets/meshes/mid_web.obj" />
        </geometry>
      <material name="clear_anodized_aluminum">
        <color rgba="0.68 0.7 0.72 1" />
        </material>
      </visual>
    <visual name="mid_fork_bridge">
      <geometry>
        <mesh filename="assets/meshes/mid_fork_bridge.obj" />
        </geometry>
      <material name="clear_anodized_aluminum">
        <color rgba="0.68 0.7 0.72 1" />
        </material>
      </visual>
    <visual name="mid_fork_upper">
      <geometry>
        <mesh filename="assets/meshes/mid_fork_upper.obj" />
        </geometry>
      <material name="clear_anodized_aluminum">
        <color rgba="0.68 0.7 0.72 1" />
        </material>
      </visual>
    <visual name="distal_pin_cap_upper">
      <origin xyz="0.09 0.041 -0.02" rpy="1.5708 0 0" />
      <geometry>
        <cylinder radius="0.0085" length="0.0028" />
        </geometry>
      <material name="brushed_steel">
        <color rgba="0.78 0.76 0.7 1" />
        </material>
      </visual>
    <visual name="mid_fork_lower">
      <geometry>
        <mesh filename="assets/meshes/mid_fork_lower.obj" />
        </geometry>
      <material name="clear_anodized_aluminum">
        <color rgba="0.68 0.7 0.72 1" />
        </material>
      </visual>
    <visual name="distal_pin_cap_lower">
      <origin xyz="0.09 -0.041 -0.02" rpy="1.5708 0 0" />
      <geometry>
        <cylinder radius="0.0085" length="0.0028" />
        </geometry>
      <material name="brushed_steel">
        <color rgba="0.78 0.76 0.7 1" />
        </material>
      </visual>
    <visual name="mid_bushing_face_upper">
      <origin xyz="0 0.033 0" rpy="1.5708 0 0" />
      <geometry>
        <cylinder radius="0.011" length="0.003" />
        </geometry>
      <material name="bronze_bushing">
        <color rgba="0.83 0.56 0.22 1" />
        </material>
      </visual>
    <visual name="mid_bushing_face_lower">
      <origin xyz="0 -0.033 0" rpy="1.5708 0 0" />
      <geometry>
        <cylinder radius="0.011" length="0.003" />
        </geometry>
      <material name="bronze_bushing">
        <color rgba="0.83 0.56 0.22 1" />
        </material>
      </visual>
    <collision name="mid_proximal_boss">
      <geometry>
        <mesh filename="assets/meshes/mid_proximal_boss.obj" />
        </geometry>
      </collision>
    <collision name="mid_web">
      <geometry>
        <mesh filename="assets/meshes/mid_web.obj" />
        </geometry>
      </collision>
    <collision name="mid_fork_bridge">
      <geometry>
        <mesh filename="assets/meshes/mid_fork_bridge.obj" />
        </geometry>
      </collision>
    <collision name="mid_fork_upper">
      <geometry>
        <mesh filename="assets/meshes/mid_fork_upper.obj" />
        </geometry>
      </collision>
    <collision name="distal_pin_cap_upper">
      <origin xyz="0.09 0.041 -0.02" rpy="1.5708 0 0" />
      <geometry>
        <cylinder radius="0.0085" length="0.0028" />
        </geometry>
      </collision>
    <collision name="mid_fork_lower">
      <geometry>
        <mesh filename="assets/meshes/mid_fork_lower.obj" />
        </geometry>
      </collision>
    <collision name="distal_pin_cap_lower">
      <origin xyz="0.09 -0.041 -0.02" rpy="1.5708 0 0" />
      <geometry>
        <cylinder radius="0.0085" length="0.0028" />
        </geometry>
      </collision>
    <collision name="mid_bushing_face_upper">
      <origin xyz="0 0.033 0" rpy="1.5708 0 0" />
      <geometry>
        <cylinder radius="0.011" length="0.003" />
        </geometry>
      </collision>
    <collision name="mid_bushing_face_lower">
      <origin xyz="0 -0.033 0" rpy="1.5708 0 0" />
      <geometry>
        <cylinder radius="0.011" length="0.003" />
        </geometry>
      </collision>
    </link>
  <link name="distal_link">
    <visual name="distal_boss">
      <geometry>
        <mesh filename="assets/meshes/distal_boss.obj" />
        </geometry>
      <material name="clear_anodized_aluminum">
        <color rgba="0.68 0.7 0.72 1" />
        </material>
      </visual>
    <visual name="distal_shank">
      <geometry>
        <mesh filename="assets/meshes/distal_shank.obj" />
        </geometry>
      <material name="clear_anodized_aluminum">
        <color rgba="0.68 0.7 0.72 1" />
        </material>
      </visual>
    <visual name="distal_bushing_face_upper">
      <origin xyz="0 0.025 0" rpy="1.5708 0 0" />
      <geometry>
        <cylinder radius="0.009" length="0.0025" />
        </geometry>
      <material name="bronze_bushing">
        <color rgba="0.83 0.56 0.22 1" />
        </material>
      </visual>
    <visual name="distal_bushing_face_lower">
      <origin xyz="0 -0.025 0" rpy="1.5708 0 0" />
      <geometry>
        <cylinder radius="0.009" length="0.0025" />
        </geometry>
      <material name="bronze_bushing">
        <color rgba="0.83 0.56 0.22 1" />
        </material>
      </visual>
    <visual name="tip_pad">
      <origin xyz="0.103 0 -0.001" rpy="0 0 0" />
      <geometry>
        <box size="0.007 0.054 0.044" />
        </geometry>
      <material name="replaceable_black_rubber">
        <color rgba="0.015 0.015 0.013 1" />
        </material>
      </visual>
    <visual name="pad_screw_-0.016_-0.014">
      <origin xyz="0.107 -0.016 -0.014" rpy="0 1.5708 0" />
      <geometry>
        <cylinder radius="0.0022" length="0.0025" />
        </geometry>
      <material name="brushed_steel">
        <color rgba="0.78 0.76 0.7 1" />
        </material>
      </visual>
    <visual name="pad_screw_-0.016_+0.012">
      <origin xyz="0.107 -0.016 0.012" rpy="0 1.5708 0" />
      <geometry>
        <cylinder radius="0.0022" length="0.0025" />
        </geometry>
      <material name="brushed_steel">
        <color rgba="0.78 0.76 0.7 1" />
        </material>
      </visual>
    <visual name="pad_screw_+0.016_-0.014">
      <origin xyz="0.107 0.016 -0.014" rpy="0 1.5708 0" />
      <geometry>
        <cylinder radius="0.0022" length="0.0025" />
        </geometry>
      <material name="brushed_steel">
        <color rgba="0.78 0.76 0.7 1" />
        </material>
      </visual>
    <visual name="pad_screw_+0.016_+0.012">
      <origin xyz="0.107 0.016 0.012" rpy="0 1.5708 0" />
      <geometry>
        <cylinder radius="0.0022" length="0.0025" />
        </geometry>
      <material name="brushed_steel">
        <color rgba="0.78 0.76 0.7 1" />
        </material>
      </visual>
    <collision name="distal_boss">
      <geometry>
        <mesh filename="assets/meshes/distal_boss.obj" />
        </geometry>
      </collision>
    <collision name="distal_shank">
      <geometry>
        <mesh filename="assets/meshes/distal_shank.obj" />
        </geometry>
      </collision>
    <collision name="distal_bushing_face_upper">
      <origin xyz="0 0.025 0" rpy="1.5708 0 0" />
      <geometry>
        <cylinder radius="0.009" length="0.0025" />
        </geometry>
      </collision>
    <collision name="distal_bushing_face_lower">
      <origin xyz="0 -0.025 0" rpy="1.5708 0 0" />
      <geometry>
        <cylinder radius="0.009" length="0.0025" />
        </geometry>
      </collision>
    <collision name="tip_pad">
      <origin xyz="0.103 0 -0.001" rpy="0 0 0" />
      <geometry>
        <box size="0.007 0.054 0.044" />
        </geometry>
      </collision>
    <collision name="pad_screw_-0.016_-0.014">
      <origin xyz="0.107 -0.016 -0.014" rpy="0 1.5708 0" />
      <geometry>
        <cylinder radius="0.0022" length="0.0025" />
        </geometry>
      </collision>
    <collision name="pad_screw_-0.016_+0.012">
      <origin xyz="0.107 -0.016 0.012" rpy="0 1.5708 0" />
      <geometry>
        <cylinder radius="0.0022" length="0.0025" />
        </geometry>
      </collision>
    <collision name="pad_screw_+0.016_-0.014">
      <origin xyz="0.107 0.016 -0.014" rpy="0 1.5708 0" />
      <geometry>
        <cylinder radius="0.0022" length="0.0025" />
        </geometry>
      </collision>
    <collision name="pad_screw_+0.016_+0.012">
      <origin xyz="0.107 0.016 0.012" rpy="0 1.5708 0" />
      <geometry>
        <cylinder radius="0.0022" length="0.0025" />
        </geometry>
      </collision>
    </link>
  <joint name="base_to_root" type="revolute">
    <parent link="machine_base" />
    <child link="root_link" />
    <axis xyz="0 1 0" />
    <limit effort="45" velocity="2.2" lower="0" upper="0.9" />
    </joint>
  <joint name="root_to_mid" type="revolute">
    <origin xyz="0.11 0 0" rpy="0 0 0" />
    <parent link="root_link" />
    <child link="mid_link" />
    <axis xyz="0 1 0" />
    <limit effort="30" velocity="2.6" lower="0" upper="1.05" />
    </joint>
  <joint name="mid_to_distal" type="revolute">
    <origin xyz="0.09 0 -0.02" rpy="0 0 0" />
    <parent link="mid_link" />
    <child link="distal_link" />
    <axis xyz="0 1 0" />
    <limit effort="18" velocity="3.2" lower="0" upper="1.15" />
    </joint>
  </robot>
