<robot name="bench_style_three_column_standing_desk">
  <link name="base_frame">
    <visual name="front_floor_rail">
      <origin xyz="0 -0.105 0.0875" rpy="0 0 0" />
      <geometry>
        <box size="2.05 0.07 0.075" />
        </geometry>
      <material name="black_powder_coated_steel">
        <color rgba="0.015 0.017 0.018 1" />
        </material>
      </visual>
    <visual name="rear_floor_rail">
      <origin xyz="0 0.105 0.0875" rpy="0 0 0" />
      <geometry>
        <box size="2.05 0.07 0.075" />
        </geometry>
      <material name="black_powder_coated_steel">
        <color rgba="0.015 0.017 0.018 1" />
        </material>
      </visual>
    <visual name="foot_0">
      <origin xyz="-0.85 0 0.0275" rpy="0 0 0" />
      <geometry>
        <box size="0.28 0.86 0.055" />
        </geometry>
      <material name="black_powder_coated_steel">
        <color rgba="0.015 0.017 0.018 1" />
        </material>
      </visual>
    <visual name="front_plinth_0">
      <origin xyz="-0.85 -0.105 0.075" rpy="0 0 0" />
      <geometry>
        <box size="0.21 0.07 0.07" />
        </geometry>
      <material name="black_powder_coated_steel">
        <color rgba="0.015 0.017 0.018 1" />
        </material>
      </visual>
    <visual name="rear_plinth_0">
      <origin xyz="-0.85 0.105 0.075" rpy="0 0 0" />
      <geometry>
        <box size="0.21 0.07 0.07" />
        </geometry>
      <material name="black_powder_coated_steel">
        <color rgba="0.015 0.017 0.018 1" />
        </material>
      </visual>
    <visual name="outer_sleeve_0_front">
      <origin xyz="-0.85 -0.0625 0.335" rpy="0 0 0" />
      <geometry>
        <box size="0.14 0.015 0.57" />
        </geometry>
      <material name="black_powder_coated_steel">
        <color rgba="0.015 0.017 0.018 1" />
        </material>
      </visual>
    <visual name="outer_sleeve_0_rear">
      <origin xyz="-0.85 0.0625 0.335" rpy="0 0 0" />
      <geometry>
        <box size="0.14 0.015 0.57" />
        </geometry>
      <material name="black_powder_coated_steel">
        <color rgba="0.015 0.017 0.018 1" />
        </material>
      </visual>
    <visual name="outer_sleeve_0_side_0">
      <origin xyz="-0.9125 0 0.335" rpy="0 0 0" />
      <geometry>
        <box size="0.015 0.11 0.57" />
        </geometry>
      <material name="black_powder_coated_steel">
        <color rgba="0.015 0.017 0.018 1" />
        </material>
      </visual>
    <visual name="outer_sleeve_0_side_1">
      <origin xyz="-0.7875 0 0.335" rpy="0 0 0" />
      <geometry>
        <box size="0.015 0.11 0.57" />
        </geometry>
      <material name="black_powder_coated_steel">
        <color rgba="0.015 0.017 0.018 1" />
        </material>
      </visual>
    <visual name="sleeve_lip_0_front">
      <origin xyz="-0.85 -0.0725 0.608" rpy="0 0 0" />
      <geometry>
        <box size="0.16 0.015 0.024" />
        </geometry>
      <material name="black_powder_coated_steel">
        <color rgba="0.015 0.017 0.018 1" />
        </material>
      </visual>
    <visual name="sleeve_lip_0_rear">
      <origin xyz="-0.85 0.0725 0.608" rpy="0 0 0" />
      <geometry>
        <box size="0.16 0.015 0.024" />
        </geometry>
      <material name="black_powder_coated_steel">
        <color rgba="0.015 0.017 0.018 1" />
        </material>
      </visual>
    <visual name="sleeve_lip_0_side_0">
      <origin xyz="-0.9225 0 0.608" rpy="0 0 0" />
      <geometry>
        <box size="0.015 0.13 0.024" />
        </geometry>
      <material name="black_powder_coated_steel">
        <color rgba="0.015 0.017 0.018 1" />
        </material>
      </visual>
    <visual name="sleeve_lip_0_side_1">
      <origin xyz="-0.7775 0 0.608" rpy="0 0 0" />
      <geometry>
        <box size="0.015 0.13 0.024" />
        </geometry>
      <material name="black_powder_coated_steel">
        <color rgba="0.015 0.017 0.018 1" />
        </material>
      </visual>
    <visual name="foot_1">
      <origin xyz="0 0 0.0275" rpy="0 0 0" />
      <geometry>
        <box size="0.28 0.86 0.055" />
        </geometry>
      <material name="black_powder_coated_steel">
        <color rgba="0.015 0.017 0.018 1" />
        </material>
      </visual>
    <visual name="front_plinth_1">
      <origin xyz="0 -0.105 0.075" rpy="0 0 0" />
      <geometry>
        <box size="0.21 0.07 0.07" />
        </geometry>
      <material name="black_powder_coated_steel">
        <color rgba="0.015 0.017 0.018 1" />
        </material>
      </visual>
    <visual name="rear_plinth_1">
      <origin xyz="0 0.105 0.075" rpy="0 0 0" />
      <geometry>
        <box size="0.21 0.07 0.07" />
        </geometry>
      <material name="black_powder_coated_steel">
        <color rgba="0.015 0.017 0.018 1" />
        </material>
      </visual>
    <visual name="outer_sleeve_1_front">
      <origin xyz="0 -0.0625 0.335" rpy="0 0 0" />
      <geometry>
        <box size="0.14 0.015 0.57" />
        </geometry>
      <material name="black_powder_coated_steel">
        <color rgba="0.015 0.017 0.018 1" />
        </material>
      </visual>
    <visual name="outer_sleeve_1_rear">
      <origin xyz="0 0.0625 0.335" rpy="0 0 0" />
      <geometry>
        <box size="0.14 0.015 0.57" />
        </geometry>
      <material name="black_powder_coated_steel">
        <color rgba="0.015 0.017 0.018 1" />
        </material>
      </visual>
    <visual name="outer_sleeve_1_side_0">
      <origin xyz="-0.0625 0 0.335" rpy="0 0 0" />
      <geometry>
        <box size="0.015 0.11 0.57" />
        </geometry>
      <material name="black_powder_coated_steel">
        <color rgba="0.015 0.017 0.018 1" />
        </material>
      </visual>
    <visual name="outer_sleeve_1_side_1">
      <origin xyz="0.0625 0 0.335" rpy="0 0 0" />
      <geometry>
        <box size="0.015 0.11 0.57" />
        </geometry>
      <material name="black_powder_coated_steel">
        <color rgba="0.015 0.017 0.018 1" />
        </material>
      </visual>
    <visual name="sleeve_lip_1_front">
      <origin xyz="0 -0.0725 0.608" rpy="0 0 0" />
      <geometry>
        <box size="0.16 0.015 0.024" />
        </geometry>
      <material name="black_powder_coated_steel">
        <color rgba="0.015 0.017 0.018 1" />
        </material>
      </visual>
    <visual name="sleeve_lip_1_rear">
      <origin xyz="0 0.0725 0.608" rpy="0 0 0" />
      <geometry>
        <box size="0.16 0.015 0.024" />
        </geometry>
      <material name="black_powder_coated_steel">
        <color rgba="0.015 0.017 0.018 1" />
        </material>
      </visual>
    <visual name="sleeve_lip_1_side_0">
      <origin xyz="-0.0725 0 0.608" rpy="0 0 0" />
      <geometry>
        <box size="0.015 0.13 0.024" />
        </geometry>
      <material name="black_powder_coated_steel">
        <color rgba="0.015 0.017 0.018 1" />
        </material>
      </visual>
    <visual name="sleeve_lip_1_side_1">
      <origin xyz="0.0725 0 0.608" rpy="0 0 0" />
      <geometry>
        <box size="0.015 0.13 0.024" />
        </geometry>
      <material name="black_powder_coated_steel">
        <color rgba="0.015 0.017 0.018 1" />
        </material>
      </visual>
    <visual name="foot_2">
      <origin xyz="0.85 0 0.0275" rpy="0 0 0" />
      <geometry>
        <box size="0.28 0.86 0.055" />
        </geometry>
      <material name="black_powder_coated_steel">
        <color rgba="0.015 0.017 0.018 1" />
        </material>
      </visual>
    <visual name="front_plinth_2">
      <origin xyz="0.85 -0.105 0.075" rpy="0 0 0" />
      <geometry>
        <box size="0.21 0.07 0.07" />
        </geometry>
      <material name="black_powder_coated_steel">
        <color rgba="0.015 0.017 0.018 1" />
        </material>
      </visual>
    <visual name="rear_plinth_2">
      <origin xyz="0.85 0.105 0.075" rpy="0 0 0" />
      <geometry>
        <box size="0.21 0.07 0.07" />
        </geometry>
      <material name="black_powder_coated_steel">
        <color rgba="0.015 0.017 0.018 1" />
        </material>
      </visual>
    <visual name="outer_sleeve_2_front">
      <origin xyz="0.85 -0.0625 0.335" rpy="0 0 0" />
      <geometry>
        <box size="0.14 0.015 0.57" />
        </geometry>
      <material name="black_powder_coated_steel">
        <color rgba="0.015 0.017 0.018 1" />
        </material>
      </visual>
    <visual name="outer_sleeve_2_rear">
      <origin xyz="0.85 0.0625 0.335" rpy="0 0 0" />
      <geometry>
        <box size="0.14 0.015 0.57" />
        </geometry>
      <material name="black_powder_coated_steel">
        <color rgba="0.015 0.017 0.018 1" />
        </material>
      </visual>
    <visual name="outer_sleeve_2_side_0">
      <origin xyz="0.7875 0 0.335" rpy="0 0 0" />
      <geometry>
        <box size="0.015 0.11 0.57" />
        </geometry>
      <material name="black_powder_coated_steel">
        <color rgba="0.015 0.017 0.018 1" />
        </material>
      </visual>
    <visual name="outer_sleeve_2_side_1">
      <origin xyz="0.9125 0 0.335" rpy="0 0 0" />
      <geometry>
        <box size="0.015 0.11 0.57" />
        </geometry>
      <material name="black_powder_coated_steel">
        <color rgba="0.015 0.017 0.018 1" />
        </material>
      </visual>
    <visual name="sleeve_lip_2_front">
      <origin xyz="0.85 -0.0725 0.608" rpy="0 0 0" />
      <geometry>
        <box size="0.16 0.015 0.024" />
        </geometry>
      <material name="black_powder_coated_steel">
        <color rgba="0.015 0.017 0.018 1" />
        </material>
      </visual>
    <visual name="sleeve_lip_2_rear">
      <origin xyz="0.85 0.0725 0.608" rpy="0 0 0" />
      <geometry>
        <box size="0.16 0.015 0.024" />
        </geometry>
      <material name="black_powder_coated_steel">
        <color rgba="0.015 0.017 0.018 1" />
        </material>
      </visual>
    <visual name="sleeve_lip_2_side_0">
      <origin xyz="0.7775 0 0.608" rpy="0 0 0" />
      <geometry>
        <box size="0.015 0.13 0.024" />
        </geometry>
      <material name="black_powder_coated_steel">
        <color rgba="0.015 0.017 0.018 1" />
        </material>
      </visual>
    <visual name="sleeve_lip_2_side_1">
      <origin xyz="0.9225 0 0.608" rpy="0 0 0" />
      <geometry>
        <box size="0.015 0.13 0.024" />
        </geometry>
      <material name="black_powder_coated_steel">
        <color rgba="0.015 0.017 0.018 1" />
        </material>
      </visual>
    <collision name="front_floor_rail">
      <origin xyz="0 -0.105 0.0875" rpy="0 0 0" />
      <geometry>
        <box size="2.05 0.07 0.075" />
        </geometry>
      </collision>
    <collision name="rear_floor_rail">
      <origin xyz="0 0.105 0.0875" rpy="0 0 0" />
      <geometry>
        <box size="2.05 0.07 0.075" />
        </geometry>
      </collision>
    <collision name="foot_0">
      <origin xyz="-0.85 0 0.0275" rpy="0 0 0" />
      <geometry>
        <box size="0.28 0.86 0.055" />
        </geometry>
      </collision>
    <collision name="front_plinth_0">
      <origin xyz="-0.85 -0.105 0.075" rpy="0 0 0" />
      <geometry>
        <box size="0.21 0.07 0.07" />
        </geometry>
      </collision>
    <collision name="rear_plinth_0">
      <origin xyz="-0.85 0.105 0.075" rpy="0 0 0" />
      <geometry>
        <box size="0.21 0.07 0.07" />
        </geometry>
      </collision>
    <collision name="outer_sleeve_0_front">
      <origin xyz="-0.85 -0.0625 0.335" rpy="0 0 0" />
      <geometry>
        <box size="0.14 0.015 0.57" />
        </geometry>
      </collision>
    <collision name="outer_sleeve_0_rear">
      <origin xyz="-0.85 0.0625 0.335" rpy="0 0 0" />
      <geometry>
        <box size="0.14 0.015 0.57" />
        </geometry>
      </collision>
    <collision name="outer_sleeve_0_side_0">
      <origin xyz="-0.9125 0 0.335" rpy="0 0 0" />
      <geometry>
        <box size="0.015 0.11 0.57" />
        </geometry>
      </collision>
    <collision name="outer_sleeve_0_side_1">
      <origin xyz="-0.7875 0 0.335" rpy="0 0 0" />
      <geometry>
        <box size="0.015 0.11 0.57" />
        </geometry>
      </collision>
    <collision name="sleeve_lip_0_front">
      <origin xyz="-0.85 -0.0725 0.608" rpy="0 0 0" />
      <geometry>
        <box size="0.16 0.015 0.024" />
        </geometry>
      </collision>
    <collision name="sleeve_lip_0_rear">
      <origin xyz="-0.85 0.0725 0.608" rpy="0 0 0" />
      <geometry>
        <box size="0.16 0.015 0.024" />
        </geometry>
      </collision>
    <collision name="sleeve_lip_0_side_0">
      <origin xyz="-0.9225 0 0.608" rpy="0 0 0" />
      <geometry>
        <box size="0.015 0.13 0.024" />
        </geometry>
      </collision>
    <collision name="sleeve_lip_0_side_1">
      <origin xyz="-0.7775 0 0.608" rpy="0 0 0" />
      <geometry>
        <box size="0.015 0.13 0.024" />
        </geometry>
      </collision>
    <collision name="foot_1">
      <origin xyz="0 0 0.0275" rpy="0 0 0" />
      <geometry>
        <box size="0.28 0.86 0.055" />
        </geometry>
      </collision>
    <collision name="front_plinth_1">
      <origin xyz="0 -0.105 0.075" rpy="0 0 0" />
      <geometry>
        <box size="0.21 0.07 0.07" />
        </geometry>
      </collision>
    <collision name="rear_plinth_1">
      <origin xyz="0 0.105 0.075" rpy="0 0 0" />
      <geometry>
        <box size="0.21 0.07 0.07" />
        </geometry>
      </collision>
    <collision name="outer_sleeve_1_front">
      <origin xyz="0 -0.0625 0.335" rpy="0 0 0" />
      <geometry>
        <box size="0.14 0.015 0.57" />
        </geometry>
      </collision>
    <collision name="outer_sleeve_1_rear">
      <origin xyz="0 0.0625 0.335" rpy="0 0 0" />
      <geometry>
        <box size="0.14 0.015 0.57" />
        </geometry>
      </collision>
    <collision name="outer_sleeve_1_side_0">
      <origin xyz="-0.0625 0 0.335" rpy="0 0 0" />
      <geometry>
        <box size="0.015 0.11 0.57" />
        </geometry>
      </collision>
    <collision name="outer_sleeve_1_side_1">
      <origin xyz="0.0625 0 0.335" rpy="0 0 0" />
      <geometry>
        <box size="0.015 0.11 0.57" />
        </geometry>
      </collision>
    <collision name="sleeve_lip_1_front">
      <origin xyz="0 -0.0725 0.608" rpy="0 0 0" />
      <geometry>
        <box size="0.16 0.015 0.024" />
        </geometry>
      </collision>
    <collision name="sleeve_lip_1_rear">
      <origin xyz="0 0.0725 0.608" rpy="0 0 0" />
      <geometry>
        <box size="0.16 0.015 0.024" />
        </geometry>
      </collision>
    <collision name="sleeve_lip_1_side_0">
      <origin xyz="-0.0725 0 0.608" rpy="0 0 0" />
      <geometry>
        <box size="0.015 0.13 0.024" />
        </geometry>
      </collision>
    <collision name="sleeve_lip_1_side_1">
      <origin xyz="0.0725 0 0.608" rpy="0 0 0" />
      <geometry>
        <box size="0.015 0.13 0.024" />
        </geometry>
      </collision>
    <collision name="foot_2">
      <origin xyz="0.85 0 0.0275" rpy="0 0 0" />
      <geometry>
        <box size="0.28 0.86 0.055" />
        </geometry>
      </collision>
    <collision name="front_plinth_2">
      <origin xyz="0.85 -0.105 0.075" rpy="0 0 0" />
      <geometry>
        <box size="0.21 0.07 0.07" />
        </geometry>
      </collision>
    <collision name="rear_plinth_2">
      <origin xyz="0.85 0.105 0.075" rpy="0 0 0" />
      <geometry>
        <box size="0.21 0.07 0.07" />
        </geometry>
      </collision>
    <collision name="outer_sleeve_2_front">
      <origin xyz="0.85 -0.0625 0.335" rpy="0 0 0" />
      <geometry>
        <box size="0.14 0.015 0.57" />
        </geometry>
      </collision>
    <collision name="outer_sleeve_2_rear">
      <origin xyz="0.85 0.0625 0.335" rpy="0 0 0" />
      <geometry>
        <box size="0.14 0.015 0.57" />
        </geometry>
      </collision>
    <collision name="outer_sleeve_2_side_0">
      <origin xyz="0.7875 0 0.335" rpy="0 0 0" />
      <geometry>
        <box size="0.015 0.11 0.57" />
        </geometry>
      </collision>
    <collision name="outer_sleeve_2_side_1">
      <origin xyz="0.9125 0 0.335" rpy="0 0 0" />
      <geometry>
        <box size="0.015 0.11 0.57" />
        </geometry>
      </collision>
    <collision name="sleeve_lip_2_front">
      <origin xyz="0.85 -0.0725 0.608" rpy="0 0 0" />
      <geometry>
        <box size="0.16 0.015 0.024" />
        </geometry>
      </collision>
    <collision name="sleeve_lip_2_rear">
      <origin xyz="0.85 0.0725 0.608" rpy="0 0 0" />
      <geometry>
        <box size="0.16 0.015 0.024" />
        </geometry>
      </collision>
    <collision name="sleeve_lip_2_side_0">
      <origin xyz="0.7775 0 0.608" rpy="0 0 0" />
      <geometry>
        <box size="0.015 0.13 0.024" />
        </geometry>
      </collision>
    <collision name="sleeve_lip_2_side_1">
      <origin xyz="0.9225 0 0.608" rpy="0 0 0" />
      <geometry>
        <box size="0.015 0.13 0.024" />
        </geometry>
      </collision>
    </link>
  <link name="inner_stage_0">
    <visual name="inner_tube">
      <origin xyz="0 0 -0.22" rpy="0 0 0" />
      <geometry>
        <box size="0.084 0.084 0.58" />
        </geometry>
      <material name="brushed_inner_steel">
        <color rgba="0.55 0.57 0.56 1" />
        </material>
      </visual>
    <visual name="upper_cap">
      <origin xyz="0 0 0.05" rpy="0 0 0" />
      <geometry>
        <box size="0.118 0.118 0.04" />
        </geometry>
      <material name="black_powder_coated_steel">
        <color rgba="0.015 0.017 0.018 1" />
        </material>
      </visual>
    <collision name="inner_tube">
      <origin xyz="0 0 -0.22" rpy="0 0 0" />
      <geometry>
        <box size="0.084 0.084 0.58" />
        </geometry>
      </collision>
    <collision name="upper_cap">
      <origin xyz="0 0 0.05" rpy="0 0 0" />
      <geometry>
        <box size="0.118 0.118 0.04" />
        </geometry>
      </collision>
    </link>
  <link name="inner_stage_1">
    <visual name="inner_tube">
      <origin xyz="0 0 -0.22" rpy="0 0 0" />
      <geometry>
        <box size="0.084 0.084 0.58" />
        </geometry>
      <material name="brushed_inner_steel">
        <color rgba="0.55 0.57 0.56 1" />
        </material>
      </visual>
    <visual name="upper_cap">
      <origin xyz="0 0 0.05" rpy="0 0 0" />
      <geometry>
        <box size="0.118 0.118 0.04" />
        </geometry>
      <material name="black_powder_coated_steel">
        <color rgba="0.015 0.017 0.018 1" />
        </material>
      </visual>
    <collision name="inner_tube">
      <origin xyz="0 0 -0.22" rpy="0 0 0" />
      <geometry>
        <box size="0.084 0.084 0.58" />
        </geometry>
      </collision>
    <collision name="upper_cap">
      <origin xyz="0 0 0.05" rpy="0 0 0" />
      <geometry>
        <box size="0.118 0.118 0.04" />
        </geometry>
      </collision>
    </link>
  <link name="inner_stage_2">
    <visual name="inner_tube">
      <origin xyz="0 0 -0.22" rpy="0 0 0" />
      <geometry>
        <box size="0.084 0.084 0.58" />
        </geometry>
      <material name="brushed_inner_steel">
        <color rgba="0.55 0.57 0.56 1" />
        </material>
      </visual>
    <visual name="upper_cap">
      <origin xyz="0 0 0.05" rpy="0 0 0" />
      <geometry>
        <box size="0.118 0.118 0.04" />
        </geometry>
      <material name="black_powder_coated_steel">
        <color rgba="0.015 0.017 0.018 1" />
        </material>
      </visual>
    <collision name="inner_tube">
      <origin xyz="0 0 -0.22" rpy="0 0 0" />
      <geometry>
        <box size="0.084 0.084 0.58" />
        </geometry>
      </collision>
    <collision name="upper_cap">
      <origin xyz="0 0 0.05" rpy="0 0 0" />
      <geometry>
        <box size="0.118 0.118 0.04" />
        </geometry>
      </collision>
    </link>
  <link name="desktop_frame">
    <visual name="long_desktop">
      <origin xyz="0 0 0.0975" rpy="0 0 0" />
      <geometry>
        <box size="2.4 0.9 0.045" />
        </geometry>
      <material name="warm_maple_laminate">
        <color rgba="0.72 0.55 0.34 1" />
        </material>
      </visual>
    <visual name="front_frame_rail">
      <origin xyz="0 -0.32 0.045" rpy="0 0 0" />
      <geometry>
        <box size="2.18 0.07 0.06" />
        </geometry>
      <material name="black_powder_coated_steel">
        <color rgba="0.015 0.017 0.018 1" />
        </material>
      </visual>
    <visual name="rear_frame_rail">
      <origin xyz="0 0.32 0.045" rpy="0 0 0" />
      <geometry>
        <box size="2.18 0.07 0.06" />
        </geometry>
      <material name="black_powder_coated_steel">
        <color rgba="0.015 0.017 0.018 1" />
        </material>
      </visual>
    <visual name="center_spine">
      <origin xyz="0 0 0.045" rpy="0 0 0" />
      <geometry>
        <box size="2.18 0.075 0.06" />
        </geometry>
      <material name="black_powder_coated_steel">
        <color rgba="0.015 0.017 0.018 1" />
        </material>
      </visual>
    <visual name="cross_bearer_0">
      <origin xyz="-0.85 0 0.045" rpy="0 0 0" />
      <geometry>
        <box size="0.11 0.72 0.06" />
        </geometry>
      <material name="black_powder_coated_steel">
        <color rgba="0.015 0.017 0.018 1" />
        </material>
      </visual>
    <visual name="support_plate_0">
      <origin xyz="-0.85 0 0.0125" rpy="0 0 0" />
      <geometry>
        <box size="0.24 0.2 0.025" />
        </geometry>
      <material name="black_powder_coated_steel">
        <color rgba="0.015 0.017 0.018 1" />
        </material>
      </visual>
    <visual name="column_socket_0">
      <origin xyz="-0.85 0 0.03" rpy="0 0 0" />
      <geometry>
        <box size="0.15 0.15 0.045" />
        </geometry>
      <material name="black_powder_coated_steel">
        <color rgba="0.015 0.017 0.018 1" />
        </material>
      </visual>
    <visual name="cross_bearer_1">
      <origin xyz="0 0 0.045" rpy="0 0 0" />
      <geometry>
        <box size="0.11 0.72 0.06" />
        </geometry>
      <material name="black_powder_coated_steel">
        <color rgba="0.015 0.017 0.018 1" />
        </material>
      </visual>
    <visual name="support_plate_1">
      <origin xyz="0 0 0.0125" rpy="0 0 0" />
      <geometry>
        <box size="0.24 0.2 0.025" />
        </geometry>
      <material name="black_powder_coated_steel">
        <color rgba="0.015 0.017 0.018 1" />
        </material>
      </visual>
    <visual name="column_socket_1">
      <origin xyz="0 0 0.03" rpy="0 0 0" />
      <geometry>
        <box size="0.15 0.15 0.045" />
        </geometry>
      <material name="black_powder_coated_steel">
        <color rgba="0.015 0.017 0.018 1" />
        </material>
      </visual>
    <visual name="cross_bearer_2">
      <origin xyz="0.85 0 0.045" rpy="0 0 0" />
      <geometry>
        <box size="0.11 0.72 0.06" />
        </geometry>
      <material name="black_powder_coated_steel">
        <color rgba="0.015 0.017 0.018 1" />
        </material>
      </visual>
    <visual name="support_plate_2">
      <origin xyz="0.85 0 0.0125" rpy="0 0 0" />
      <geometry>
        <box size="0.24 0.2 0.025" />
        </geometry>
      <material name="black_powder_coated_steel">
        <color rgba="0.015 0.017 0.018 1" />
        </material>
      </visual>
    <visual name="column_socket_2">
      <origin xyz="0.85 0 0.03" rpy="0 0 0" />
      <geometry>
        <box size="0.15 0.15 0.045" />
        </geometry>
      <material name="black_powder_coated_steel">
        <color rgba="0.015 0.017 0.018 1" />
        </material>
      </visual>
    <collision name="long_desktop">
      <origin xyz="0 0 0.0975" rpy="0 0 0" />
      <geometry>
        <box size="2.4 0.9 0.045" />
        </geometry>
      </collision>
    <collision name="front_frame_rail">
      <origin xyz="0 -0.32 0.045" rpy="0 0 0" />
      <geometry>
        <box size="2.18 0.07 0.06" />
        </geometry>
      </collision>
    <collision name="rear_frame_rail">
      <origin xyz="0 0.32 0.045" rpy="0 0 0" />
      <geometry>
        <box size="2.18 0.07 0.06" />
        </geometry>
      </collision>
    <collision name="center_spine">
      <origin xyz="0 0 0.045" rpy="0 0 0" />
      <geometry>
        <box size="2.18 0.075 0.06" />
        </geometry>
      </collision>
    <collision name="cross_bearer_0">
      <origin xyz="-0.85 0 0.045" rpy="0 0 0" />
      <geometry>
        <box size="0.11 0.72 0.06" />
        </geometry>
      </collision>
    <collision name="support_plate_0">
      <origin xyz="-0.85 0 0.0125" rpy="0 0 0" />
      <geometry>
        <box size="0.24 0.2 0.025" />
        </geometry>
      </collision>
    <collision name="column_socket_0">
      <origin xyz="-0.85 0 0.03" rpy="0 0 0" />
      <geometry>
        <box size="0.15 0.15 0.045" />
        </geometry>
      </collision>
    <collision name="cross_bearer_1">
      <origin xyz="0 0 0.045" rpy="0 0 0" />
      <geometry>
        <box size="0.11 0.72 0.06" />
        </geometry>
      </collision>
    <collision name="support_plate_1">
      <origin xyz="0 0 0.0125" rpy="0 0 0" />
      <geometry>
        <box size="0.24 0.2 0.025" />
        </geometry>
      </collision>
    <collision name="column_socket_1">
      <origin xyz="0 0 0.03" rpy="0 0 0" />
      <geometry>
        <box size="0.15 0.15 0.045" />
        </geometry>
      </collision>
    <collision name="cross_bearer_2">
      <origin xyz="0.85 0 0.045" rpy="0 0 0" />
      <geometry>
        <box size="0.11 0.72 0.06" />
        </geometry>
      </collision>
    <collision name="support_plate_2">
      <origin xyz="0.85 0 0.0125" rpy="0 0 0" />
      <geometry>
        <box size="0.24 0.2 0.025" />
        </geometry>
      </collision>
    <collision name="column_socket_2">
      <origin xyz="0.85 0 0.03" rpy="0 0 0" />
      <geometry>
        <box size="0.15 0.15 0.045" />
        </geometry>
      </collision>
    </link>
  <link name="paddle_housing">
    <visual name="housing">
      <geometry>
        <box size="0.18 0.07 0.04" />
        </geometry>
      <material name="matte_black_plastic">
        <color rgba="0.025 0.026 0.028 1" />
        </material>
      </visual>
    <visual name="hinge_tab_0">
      <origin xyz="-0.072 -0.035 -0.027" rpy="0 0 0" />
      <geometry>
        <box size="0.018 0.025 0.03" />
        </geometry>
      <material name="matte_black_plastic">
        <color rgba="0.025 0.026 0.028 1" />
        </material>
      </visual>
    <visual name="hinge_tab_1">
      <origin xyz="0.072 -0.035 -0.027" rpy="0 0 0" />
      <geometry>
        <box size="0.018 0.025 0.03" />
        </geometry>
      <material name="matte_black_plastic">
        <color rgba="0.025 0.026 0.028 1" />
        </material>
      </visual>
    <collision name="housing">
      <geometry>
        <box size="0.18 0.07 0.04" />
        </geometry>
      </collision>
    <collision name="hinge_tab_0">
      <origin xyz="-0.072 -0.035 -0.027" rpy="0 0 0" />
      <geometry>
        <box size="0.018 0.025 0.03" />
        </geometry>
      </collision>
    <collision name="hinge_tab_1">
      <origin xyz="0.072 -0.035 -0.027" rpy="0 0 0" />
      <geometry>
        <box size="0.018 0.025 0.03" />
        </geometry>
      </collision>
    </link>
  <link name="paddle">
    <visual name="hinge_barrel">
      <origin xyz="0 0 0" rpy="0 1.5708 0" />
      <geometry>
        <cylinder radius="0.006" length="0.125" />
        </geometry>
      <material name="black_powder_coated_steel">
        <color rgba="0.015 0.017 0.018 1" />
        </material>
      </visual>
    <visual name="paddle_face">
      <origin xyz="0 -0.03 -0.012" rpy="0 0 0" />
      <geometry>
        <box size="0.14 0.06 0.012" />
        </geometry>
      <material name="soft_dark_rubber">
        <color rgba="0.04 0.04 0.042 1" />
        </material>
      </visual>
    <collision name="hinge_barrel">
      <origin xyz="0 0 0" rpy="0 1.5708 0" />
      <geometry>
        <cylinder radius="0.006" length="0.125" />
        </geometry>
      </collision>
    <collision name="paddle_face">
      <origin xyz="0 -0.03 -0.012" rpy="0 0 0" />
      <geometry>
        <box size="0.14 0.06 0.012" />
        </geometry>
      </collision>
    </link>
  <link name="handset">
    <visual name="body">
      <geometry>
        <box size="0.24 0.12 0.035" />
        </geometry>
      <material name="matte_black_plastic">
        <color rgba="0.025 0.026 0.028 1" />
        </material>
      </visual>
    <visual name="button_bezel">
      <origin xyz="0 0 -0.0195" rpy="0 0 0" />
      <geometry>
        <box size="0.2 0.085 0.004" />
        </geometry>
      <material name="black_powder_coated_steel">
        <color rgba="0.015 0.017 0.018 1" />
        </material>
      </visual>
    <collision name="body">
      <geometry>
        <box size="0.24 0.12 0.035" />
        </geometry>
      </collision>
    <collision name="button_bezel">
      <origin xyz="0 0 -0.0195" rpy="0 0 0" />
      <geometry>
        <box size="0.2 0.085 0.004" />
        </geometry>
      </collision>
    </link>
  <link name="button_0">
    <visual name="cap">
      <origin xyz="0 0 -0.005" rpy="0 0 0" />
      <geometry>
        <cylinder radius="0.018" length="0.01" />
        </geometry>
      <material name="cool_grey_button">
        <color rgba="0.32 0.34 0.35 1" />
        </material>
      </visual>
    <visual name="rubber_skirt">
      <origin xyz="0 0 -0.013" rpy="0 0 0" />
      <geometry>
        <cylinder radius="0.012" length="0.008" />
        </geometry>
      <material name="soft_dark_rubber">
        <color rgba="0.04 0.04 0.042 1" />
        </material>
      </visual>
    <collision name="cap">
      <origin xyz="0 0 -0.005" rpy="0 0 0" />
      <geometry>
        <cylinder radius="0.018" length="0.01" />
        </geometry>
      </collision>
    <collision name="rubber_skirt">
      <origin xyz="0 0 -0.013" rpy="0 0 0" />
      <geometry>
        <cylinder radius="0.012" length="0.008" />
        </geometry>
      </collision>
    </link>
  <link name="button_1">
    <visual name="cap">
      <origin xyz="0 0 -0.005" rpy="0 0 0" />
      <geometry>
        <cylinder radius="0.018" length="0.01" />
        </geometry>
      <material name="cool_grey_button">
        <color rgba="0.32 0.34 0.35 1" />
        </material>
      </visual>
    <visual name="rubber_skirt">
      <origin xyz="0 0 -0.013" rpy="0 0 0" />
      <geometry>
        <cylinder radius="0.012" length="0.008" />
        </geometry>
      <material name="soft_dark_rubber">
        <color rgba="0.04 0.04 0.042 1" />
        </material>
      </visual>
    <collision name="cap">
      <origin xyz="0 0 -0.005" rpy="0 0 0" />
      <geometry>
        <cylinder radius="0.018" length="0.01" />
        </geometry>
      </collision>
    <collision name="rubber_skirt">
      <origin xyz="0 0 -0.013" rpy="0 0 0" />
      <geometry>
        <cylinder radius="0.012" length="0.008" />
        </geometry>
      </collision>
    </link>
  <link name="button_2">
    <visual name="cap">
      <origin xyz="0 0 -0.005" rpy="0 0 0" />
      <geometry>
        <cylinder radius="0.018" length="0.01" />
        </geometry>
      <material name="cool_grey_button">
        <color rgba="0.32 0.34 0.35 1" />
        </material>
      </visual>
    <visual name="rubber_skirt">
      <origin xyz="0 0 -0.013" rpy="0 0 0" />
      <geometry>
        <cylinder radius="0.012" length="0.008" />
        </geometry>
      <material name="soft_dark_rubber">
        <color rgba="0.04 0.04 0.042 1" />
        </material>
      </visual>
    <collision name="cap">
      <origin xyz="0 0 -0.005" rpy="0 0 0" />
      <geometry>
        <cylinder radius="0.018" length="0.01" />
        </geometry>
      </collision>
    <collision name="rubber_skirt">
      <origin xyz="0 0 -0.013" rpy="0 0 0" />
      <geometry>
        <cylinder radius="0.012" length="0.008" />
        </geometry>
      </collision>
    </link>
  <link name="button_3">
    <visual name="cap">
      <origin xyz="0 0 -0.005" rpy="0 0 0" />
      <geometry>
        <cylinder radius="0.018" length="0.01" />
        </geometry>
      <material name="cool_grey_button">
        <color rgba="0.32 0.34 0.35 1" />
        </material>
      </visual>
    <visual name="rubber_skirt">
      <origin xyz="0 0 -0.013" rpy="0 0 0" />
      <geometry>
        <cylinder radius="0.012" length="0.008" />
        </geometry>
      <material name="soft_dark_rubber">
        <color rgba="0.04 0.04 0.042 1" />
        </material>
      </visual>
    <collision name="cap">
      <origin xyz="0 0 -0.005" rpy="0 0 0" />
      <geometry>
        <cylinder radius="0.018" length="0.01" />
        </geometry>
      </collision>
    <collision name="rubber_skirt">
      <origin xyz="0 0 -0.013" rpy="0 0 0" />
      <geometry>
        <cylinder radius="0.012" length="0.008" />
        </geometry>
      </collision>
    </link>
  <joint name="base_to_inner_stage_0" type="prismatic">
    <origin xyz="-0.85 0 0.59" rpy="0 0 0" />
    <parent link="base_frame" />
    <child link="inner_stage_0" />
    <axis xyz="0 0 1" />
    <limit effort="900" velocity="0.06" lower="0" upper="0.38" />
    <mimic joint="base_to_inner_stage_1" />
    </joint>
  <joint name="base_to_inner_stage_1" type="prismatic">
    <origin xyz="0 0 0.59" rpy="0 0 0" />
    <parent link="base_frame" />
    <child link="inner_stage_1" />
    <axis xyz="0 0 1" />
    <limit effort="900" velocity="0.06" lower="0" upper="0.38" />
    </joint>
  <joint name="base_to_inner_stage_2" type="prismatic">
    <origin xyz="0.85 0 0.59" rpy="0 0 0" />
    <parent link="base_frame" />
    <child link="inner_stage_2" />
    <axis xyz="0 0 1" />
    <limit effort="900" velocity="0.06" lower="0" upper="0.38" />
    <mimic joint="base_to_inner_stage_1" />
    </joint>
  <joint name="inner_stage_1_to_desktop_frame" type="fixed">
    <origin xyz="0 0 0.07" rpy="0 0 0" />
    <parent link="inner_stage_1" />
    <child link="desktop_frame" />
    </joint>
  <joint name="desktop_frame_to_paddle_housing" type="fixed">
    <origin xyz="0 -0.472 0.055" rpy="0 0 0" />
    <parent link="desktop_frame" />
    <child link="paddle_housing" />
    </joint>
  <joint name="paddle_housing_to_paddle" type="revolute">
    <origin xyz="0 -0.04 -0.035" rpy="0 0 0" />
    <parent link="paddle_housing" />
    <child link="paddle" />
    <axis xyz="1 0 0" />
    <limit effort="1.5" velocity="2" lower="-0.3" upper="0.3" />
    </joint>
  <joint name="desktop_frame_to_handset" type="fixed">
    <origin xyz="0.48 -0.472 0.0575" rpy="0 0 0" />
    <parent link="desktop_frame" />
    <child link="handset" />
    </joint>
  <joint name="handset_to_button_0" type="prismatic">
    <origin xyz="-0.045 -0.024 -0.0175" rpy="0 0 0" />
    <parent link="handset" />
    <child link="button_0" />
    <axis xyz="0 0 1" />
    <limit effort="2" velocity="0.04" lower="0" upper="0.006" />
    </joint>
  <joint name="handset_to_button_1" type="prismatic">
    <origin xyz="0.045 -0.024 -0.0175" rpy="0 0 0" />
    <parent link="handset" />
    <child link="button_1" />
    <axis xyz="0 0 1" />
    <limit effort="2" velocity="0.04" lower="0" upper="0.006" />
    </joint>
  <joint name="handset_to_button_2" type="prismatic">
    <origin xyz="-0.045 0.024 -0.0175" rpy="0 0 0" />
    <parent link="handset" />
    <child link="button_2" />
    <axis xyz="0 0 1" />
    <limit effort="2" velocity="0.04" lower="0" upper="0.006" />
    </joint>
  <joint name="handset_to_button_3" type="prismatic">
    <origin xyz="0.045 0.024 -0.0175" rpy="0 0 0" />
    <parent link="handset" />
    <child link="button_3" />
    <axis xyz="0 0 1" />
    <limit effort="2" velocity="0.04" lower="0" upper="0.006" />
    </joint>
  </robot>
