<robot name="single_door_medicine_cabinet">
  <material name="warm_white_painted_steel">
    <color rgba="0.86 0.88 0.84 1" />
    </material>
  <material name="matte_off_white_interior">
    <color rgba="0.93 0.94 0.91 1" />
    </material>
  <material name="painted_wall_backer">
    <color rgba="0.78 0.8 0.76 1" />
    </material>
  <material name="cool_blue_mirror_glass">
    <color rgba="0.62 0.78 0.88 0.55" />
    </material>
  <material name="dark_door_shadow_gap">
    <color rgba="0.08 0.09 0.09 1" />
    </material>
  <material name="brushed_nickel_hardware">
    <color rgba="0.72 0.72 0.68 1" />
    </material>
  <material name="satin_chrome_finger_pull">
    <color rgba="0.8 0.78 0.72 1" />
    </material>
  <link name="carcass">
    <visual name="wall_mount_plate">
      <origin xyz="0 0.063 0" rpy="0 0 0" />
      <geometry>
        <box size="0.49 0.006 0.69" />
        </geometry>
      <material name="painted_wall_backer">
        <color rgba="0.78 0.8 0.76 1" />
        </material>
      </visual>
    <visual name="back_panel">
      <origin xyz="0 0.053 0" rpy="0 0 0" />
      <geometry>
        <box size="0.42 0.014 0.62" />
        </geometry>
      <material name="warm_white_painted_steel">
        <color rgba="0.86 0.88 0.84 1" />
        </material>
      </visual>
    <visual name="hinge_side_panel">
      <origin xyz="-0.203 0 0" rpy="0 0 0" />
      <geometry>
        <box size="0.014 0.12 0.62" />
        </geometry>
      <material name="warm_white_painted_steel">
        <color rgba="0.86 0.88 0.84 1" />
        </material>
      </visual>
    <visual name="free_side_panel">
      <origin xyz="0.203 0 0" rpy="0 0 0" />
      <geometry>
        <box size="0.014 0.12 0.62" />
        </geometry>
      <material name="warm_white_painted_steel">
        <color rgba="0.86 0.88 0.84 1" />
        </material>
      </visual>
    <visual name="top_panel">
      <origin xyz="0 0 0.303" rpy="0 0 0" />
      <geometry>
        <box size="0.42 0.12 0.014" />
        </geometry>
      <material name="warm_white_painted_steel">
        <color rgba="0.86 0.88 0.84 1" />
        </material>
      </visual>
    <visual name="bottom_panel">
      <origin xyz="0 0 -0.303" rpy="0 0 0" />
      <geometry>
        <box size="0.42 0.12 0.014" />
        </geometry>
      <material name="warm_white_painted_steel">
        <color rgba="0.86 0.88 0.84 1" />
        </material>
      </visual>
    <visual name="fixed_shelf_0">
      <origin xyz="0 0.004 -0.105" rpy="0 0 0" />
      <geometry>
        <box size="0.392 0.092 0.006" />
        </geometry>
      <material name="matte_off_white_interior">
        <color rgba="0.93 0.94 0.91 1" />
        </material>
      </visual>
    <visual name="fixed_shelf_1">
      <origin xyz="0 0.004 0.105" rpy="0 0 0" />
      <geometry>
        <box size="0.392 0.092 0.006" />
        </geometry>
      <material name="matte_off_white_interior">
        <color rgba="0.93 0.94 0.91 1" />
        </material>
      </visual>
    <visual name="lower_hinge_leaf">
      <origin xyz="-0.21 -0.06 -0.215" rpy="0 0 0" />
      <geometry>
        <box size="0.026 0.012 0.086" />
        </geometry>
      <material name="brushed_nickel_hardware">
        <color rgba="0.72 0.72 0.68 1" />
        </material>
      </visual>
    <visual name="lower_hinge_knuckle_0">
      <origin xyz="-0.222 -0.072 -0.243" rpy="0 0 0" />
      <geometry>
        <cylinder radius="0.006" length="0.028" />
        </geometry>
      <material name="brushed_nickel_hardware">
        <color rgba="0.72 0.72 0.68 1" />
        </material>
      </visual>
    <visual name="lower_hinge_knuckle_1">
      <origin xyz="-0.222 -0.072 -0.187" rpy="0 0 0" />
      <geometry>
        <cylinder radius="0.006" length="0.028" />
        </geometry>
      <material name="brushed_nickel_hardware">
        <color rgba="0.72 0.72 0.68 1" />
        </material>
      </visual>
    <visual name="lower_hinge_pin">
      <origin xyz="-0.222 -0.072 -0.215" rpy="0 0 0" />
      <geometry>
        <cylinder radius="0.0022" length="0.086" />
        </geometry>
      <material name="brushed_nickel_hardware">
        <color rgba="0.72 0.72 0.68 1" />
        </material>
      </visual>
    <visual name="upper_hinge_leaf">
      <origin xyz="-0.21 -0.06 0.215" rpy="0 0 0" />
      <geometry>
        <box size="0.026 0.012 0.086" />
        </geometry>
      <material name="brushed_nickel_hardware">
        <color rgba="0.72 0.72 0.68 1" />
        </material>
      </visual>
    <visual name="upper_hinge_knuckle_0">
      <origin xyz="-0.222 -0.072 0.187" rpy="0 0 0" />
      <geometry>
        <cylinder radius="0.006" length="0.028" />
        </geometry>
      <material name="brushed_nickel_hardware">
        <color rgba="0.72 0.72 0.68 1" />
        </material>
      </visual>
    <visual name="upper_hinge_knuckle_1">
      <origin xyz="-0.222 -0.072 0.243" rpy="0 0 0" />
      <geometry>
        <cylinder radius="0.006" length="0.028" />
        </geometry>
      <material name="brushed_nickel_hardware">
        <color rgba="0.72 0.72 0.68 1" />
        </material>
      </visual>
    <visual name="upper_hinge_pin">
      <origin xyz="-0.222 -0.072 0.215" rpy="0 0 0" />
      <geometry>
        <cylinder radius="0.0022" length="0.086" />
        </geometry>
      <material name="brushed_nickel_hardware">
        <color rgba="0.72 0.72 0.68 1" />
        </material>
      </visual>
    <collision name="wall_mount_plate">
      <origin xyz="0 0.063 0" rpy="0 0 0" />
      <geometry>
        <box size="0.49 0.006 0.69" />
        </geometry>
      </collision>
    <collision name="back_panel">
      <origin xyz="0 0.053 0" rpy="0 0 0" />
      <geometry>
        <box size="0.42 0.014 0.62" />
        </geometry>
      </collision>
    <collision name="hinge_side_panel">
      <origin xyz="-0.203 0 0" rpy="0 0 0" />
      <geometry>
        <box size="0.014 0.12 0.62" />
        </geometry>
      </collision>
    <collision name="free_side_panel">
      <origin xyz="0.203 0 0" rpy="0 0 0" />
      <geometry>
        <box size="0.014 0.12 0.62" />
        </geometry>
      </collision>
    <collision name="top_panel">
      <origin xyz="0 0 0.303" rpy="0 0 0" />
      <geometry>
        <box size="0.42 0.12 0.014" />
        </geometry>
      </collision>
    <collision name="bottom_panel">
      <origin xyz="0 0 -0.303" rpy="0 0 0" />
      <geometry>
        <box size="0.42 0.12 0.014" />
        </geometry>
      </collision>
    <collision name="fixed_shelf_0">
      <origin xyz="0 0.004 -0.105" rpy="0 0 0" />
      <geometry>
        <box size="0.392 0.092 0.006" />
        </geometry>
      </collision>
    <collision name="fixed_shelf_1">
      <origin xyz="0 0.004 0.105" rpy="0 0 0" />
      <geometry>
        <box size="0.392 0.092 0.006" />
        </geometry>
      </collision>
    <collision name="lower_hinge_leaf">
      <origin xyz="-0.21 -0.06 -0.215" rpy="0 0 0" />
      <geometry>
        <box size="0.026 0.012 0.086" />
        </geometry>
      </collision>
    <collision name="lower_hinge_knuckle_0">
      <origin xyz="-0.222 -0.072 -0.243" rpy="0 0 0" />
      <geometry>
        <cylinder radius="0.006" length="0.028" />
        </geometry>
      </collision>
    <collision name="lower_hinge_knuckle_1">
      <origin xyz="-0.222 -0.072 -0.187" rpy="0 0 0" />
      <geometry>
        <cylinder radius="0.006" length="0.028" />
        </geometry>
      </collision>
    <collision name="lower_hinge_pin">
      <origin xyz="-0.222 -0.072 -0.215" rpy="0 0 0" />
      <geometry>
        <cylinder radius="0.0022" length="0.086" />
        </geometry>
      </collision>
    <collision name="upper_hinge_leaf">
      <origin xyz="-0.21 -0.06 0.215" rpy="0 0 0" />
      <geometry>
        <box size="0.026 0.012 0.086" />
        </geometry>
      </collision>
    <collision name="upper_hinge_knuckle_0">
      <origin xyz="-0.222 -0.072 0.187" rpy="0 0 0" />
      <geometry>
        <cylinder radius="0.006" length="0.028" />
        </geometry>
      </collision>
    <collision name="upper_hinge_knuckle_1">
      <origin xyz="-0.222 -0.072 0.243" rpy="0 0 0" />
      <geometry>
        <cylinder radius="0.006" length="0.028" />
        </geometry>
      </collision>
    <collision name="upper_hinge_pin">
      <origin xyz="-0.222 -0.072 0.215" rpy="0 0 0" />
      <geometry>
        <cylinder radius="0.0022" length="0.086" />
        </geometry>
      </collision>
    </link>
  <link name="door">
    <visual name="door_backing">
      <origin xyz="0.22 0 0" rpy="0 0 0" />
      <geometry>
        <box size="0.436 0.012 0.636" />
        </geometry>
      <material name="dark_door_shadow_gap">
        <color rgba="0.08 0.09 0.09 1" />
        </material>
      </visual>
    <visual name="top_door_rail">
      <origin xyz="0.22 -0.009 0.303" rpy="0 0 0" />
      <geometry>
        <box size="0.436 0.006 0.03" />
        </geometry>
      <material name="warm_white_painted_steel">
        <color rgba="0.86 0.88 0.84 1" />
        </material>
      </visual>
    <visual name="bottom_door_rail">
      <origin xyz="0.22 -0.009 -0.303" rpy="0 0 0" />
      <geometry>
        <box size="0.436 0.006 0.03" />
        </geometry>
      <material name="warm_white_painted_steel">
        <color rgba="0.86 0.88 0.84 1" />
        </material>
      </visual>
    <visual name="hinge_door_stile">
      <origin xyz="0.017 -0.009 0" rpy="0 0 0" />
      <geometry>
        <box size="0.03 0.006 0.636" />
        </geometry>
      <material name="warm_white_painted_steel">
        <color rgba="0.86 0.88 0.84 1" />
        </material>
      </visual>
    <visual name="free_door_stile">
      <origin xyz="0.423 -0.009 0" rpy="0 0 0" />
      <geometry>
        <box size="0.03 0.006 0.636" />
        </geometry>
      <material name="warm_white_painted_steel">
        <color rgba="0.86 0.88 0.84 1" />
        </material>
      </visual>
    <visual name="mirror_glass">
      <origin xyz="0.22 -0.01 0" rpy="0 0 0" />
      <geometry>
        <box size="0.376 0.004 0.576" />
        </geometry>
      <material name="cool_blue_mirror_glass">
        <color rgba="0.62 0.78 0.88 0.55" />
        </material>
      </visual>
    <visual name="lower_door_hinge_leaf">
      <origin xyz="0.016 -0.007 -0.215" rpy="0 0 0" />
      <geometry>
        <box size="0.036 0.006 0.08" />
        </geometry>
      <material name="brushed_nickel_hardware">
        <color rgba="0.72 0.72 0.68 1" />
        </material>
      </visual>
    <visual name="lower_hinge_knuckle">
      <origin xyz="0 0 -0.215" rpy="0 0 0" />
      <geometry>
        <cylinder radius="0.006" length="0.03" />
        </geometry>
      <material name="brushed_nickel_hardware">
        <color rgba="0.72 0.72 0.68 1" />
        </material>
      </visual>
    <visual name="upper_door_hinge_leaf">
      <origin xyz="0.016 -0.007 0.215" rpy="0 0 0" />
      <geometry>
        <box size="0.036 0.006 0.08" />
        </geometry>
      <material name="brushed_nickel_hardware">
        <color rgba="0.72 0.72 0.68 1" />
        </material>
      </visual>
    <visual name="upper_hinge_knuckle">
      <origin xyz="0 0 0.215" rpy="0 0 0" />
      <geometry>
        <cylinder radius="0.006" length="0.03" />
        </geometry>
      <material name="brushed_nickel_hardware">
        <color rgba="0.72 0.72 0.68 1" />
        </material>
      </visual>
    <visual name="pull_pivot_mount">
      <origin xyz="0.419 -0.015 0" rpy="1.5708 0 0" />
      <geometry>
        <cylinder radius="0.011" length="0.006" />
        </geometry>
      <material name="satin_chrome_finger_pull">
        <color rgba="0.8 0.78 0.72 1" />
        </material>
      </visual>
    <collision name="door_backing">
      <origin xyz="0.22 0 0" rpy="0 0 0" />
      <geometry>
        <box size="0.436 0.012 0.636" />
        </geometry>
      </collision>
    <collision name="top_door_rail">
      <origin xyz="0.22 -0.009 0.303" rpy="0 0 0" />
      <geometry>
        <box size="0.436 0.006 0.03" />
        </geometry>
      </collision>
    <collision name="bottom_door_rail">
      <origin xyz="0.22 -0.009 -0.303" rpy="0 0 0" />
      <geometry>
        <box size="0.436 0.006 0.03" />
        </geometry>
      </collision>
    <collision name="hinge_door_stile">
      <origin xyz="0.017 -0.009 0" rpy="0 0 0" />
      <geometry>
        <box size="0.03 0.006 0.636" />
        </geometry>
      </collision>
    <collision name="free_door_stile">
      <origin xyz="0.423 -0.009 0" rpy="0 0 0" />
      <geometry>
        <box size="0.03 0.006 0.636" />
        </geometry>
      </collision>
    <collision name="mirror_glass">
      <origin xyz="0.22 -0.01 0" rpy="0 0 0" />
      <geometry>
        <box size="0.376 0.004 0.576" />
        </geometry>
      </collision>
    <collision name="lower_door_hinge_leaf">
      <origin xyz="0.016 -0.007 -0.215" rpy="0 0 0" />
      <geometry>
        <box size="0.036 0.006 0.08" />
        </geometry>
      </collision>
    <collision name="lower_hinge_knuckle">
      <origin xyz="0 0 -0.215" rpy="0 0 0" />
      <geometry>
        <cylinder radius="0.006" length="0.03" />
        </geometry>
      </collision>
    <collision name="upper_door_hinge_leaf">
      <origin xyz="0.016 -0.007 0.215" rpy="0 0 0" />
      <geometry>
        <box size="0.036 0.006 0.08" />
        </geometry>
      </collision>
    <collision name="upper_hinge_knuckle">
      <origin xyz="0 0 0.215" rpy="0 0 0" />
      <geometry>
        <cylinder radius="0.006" length="0.03" />
        </geometry>
      </collision>
    <collision name="pull_pivot_mount">
      <origin xyz="0.419 -0.015 0" rpy="1.5708 0 0" />
      <geometry>
        <cylinder radius="0.011" length="0.006" />
        </geometry>
      </collision>
    </link>
  <link name="finger_pull">
    <visual name="pull_spindle">
      <origin xyz="0 -0.002 0" rpy="1.5708 0 0" />
      <geometry>
        <cylinder radius="0.003" length="0.018" />
        </geometry>
      <material name="satin_chrome_finger_pull">
        <color rgba="0.8 0.78 0.72 1" />
        </material>
      </visual>
    <visual name="pull_hub">
      <origin xyz="0 -0.009 0" rpy="1.5708 0 0" />
      <geometry>
        <cylinder radius="0.01" length="0.006" />
        </geometry>
      <material name="satin_chrome_finger_pull">
        <color rgba="0.8 0.78 0.72 1" />
        </material>
      </visual>
    <visual name="pull_tab">
      <origin xyz="0 -0.011 -0.042" rpy="0 0 0" />
      <geometry>
        <box size="0.014 0.006 0.07" />
        </geometry>
      <material name="satin_chrome_finger_pull">
        <color rgba="0.8 0.78 0.72 1" />
        </material>
      </visual>
    <visual name="rounded_pull_tip">
      <origin xyz="0 -0.011 -0.077" rpy="0 0 0" />
      <geometry>
        <sphere radius="0.0085" />
        </geometry>
      <material name="satin_chrome_finger_pull">
        <color rgba="0.8 0.78 0.72 1" />
        </material>
      </visual>
    <collision name="pull_spindle">
      <origin xyz="0 -0.002 0" rpy="1.5708 0 0" />
      <geometry>
        <cylinder radius="0.003" length="0.018" />
        </geometry>
      </collision>
    <collision name="pull_hub">
      <origin xyz="0 -0.009 0" rpy="1.5708 0 0" />
      <geometry>
        <cylinder radius="0.01" length="0.006" />
        </geometry>
      </collision>
    <collision name="pull_tab">
      <origin xyz="0 -0.011 -0.042" rpy="0 0 0" />
      <geometry>
        <box size="0.014 0.006 0.07" />
        </geometry>
      </collision>
    <collision name="rounded_pull_tip">
      <origin xyz="0 -0.011 -0.077" rpy="0 0 0" />
      <geometry>
        <sphere radius="0.0085" />
        </geometry>
      </collision>
    </link>
  <joint name="carcass_to_door" type="revolute">
    <origin xyz="-0.222 -0.072 0" rpy="0 0 0" />
    <parent link="carcass" />
    <child link="door" />
    <axis xyz="0 0 -1" />
    <limit effort="8" velocity="2" lower="0" upper="1.75" />
    </joint>
  <joint name="door_to_finger_pull" type="revolute">
    <origin xyz="0.419 -0.015 0" rpy="0 0 0" />
    <parent link="door" />
    <child link="finger_pull" />
    <axis xyz="0 -1 0" />
    <limit effort="0.35" velocity="1" lower="-0.3" upper="0.3" />
    </joint>
  </robot>
