<robot name="trunnion_table_module">
  <material name="dark_iron">
    <color rgba="0.1 0.11 0.12 1" />
    </material>
  <material name="parkerized_steel">
    <color rgba="0.2 0.23 0.25 1" />
    </material>
  <material name="blued_steel">
    <color rgba="0.12 0.2 0.28 1" />
    </material>
  <material name="machined_steel">
    <color rgba="0.62 0.64 0.62 1" />
    </material>
  <material name="slot_dark">
    <color rgba="0.015 0.017 0.018 1" />
    </material>
  <link name="foundation">
    <visual name="floor_plinth">
      <origin xyz="0 0 0.04" rpy="0 0 0" />
      <geometry>
        <cylinder radius="0.4" length="0.08" />
        </geometry>
      <material name="dark_iron">
        <color rgba="0.1 0.11 0.12 1" />
        </material>
      </visual>
    <visual name="bearing_track">
      <origin xyz="0 0 0.086" rpy="0 0 0" />
      <geometry>
        <cylinder radius="0.3" length="0.012" />
        </geometry>
      <material name="parkerized_steel">
        <color rgba="0.2 0.23 0.25 1" />
        </material>
      </visual>
    <visual name="mount_bolt_0">
      <origin xyz="0.315 0 0.082" rpy="0 0 0" />
      <geometry>
        <cylinder radius="0.018" length="0.004" />
        </geometry>
      <material name="slot_dark">
        <color rgba="0.015 0.017 0.018 1" />
        </material>
      </visual>
    <visual name="mount_bolt_1">
      <origin xyz="1.92882e-17 0.315 0.082" rpy="0 0 0" />
      <geometry>
        <cylinder radius="0.018" length="0.004" />
        </geometry>
      <material name="slot_dark">
        <color rgba="0.015 0.017 0.018 1" />
        </material>
      </visual>
    <visual name="mount_bolt_2">
      <origin xyz="-0.315 3.85764e-17 0.082" rpy="0 0 0" />
      <geometry>
        <cylinder radius="0.018" length="0.004" />
        </geometry>
      <material name="slot_dark">
        <color rgba="0.015 0.017 0.018 1" />
        </material>
      </visual>
    <visual name="mount_bolt_3">
      <origin xyz="-5.78646e-17 -0.315 0.082" rpy="0 0 0" />
      <geometry>
        <cylinder radius="0.018" length="0.004" />
        </geometry>
      <material name="slot_dark">
        <color rgba="0.015 0.017 0.018 1" />
        </material>
      </visual>
    <collision name="floor_plinth">
      <origin xyz="0 0 0.04" rpy="0 0 0" />
      <geometry>
        <cylinder radius="0.4" length="0.08" />
        </geometry>
      </collision>
    <collision name="bearing_track">
      <origin xyz="0 0 0.086" rpy="0 0 0" />
      <geometry>
        <cylinder radius="0.3" length="0.012" />
        </geometry>
      </collision>
    <collision name="mount_bolt_0">
      <origin xyz="0.315 0 0.082" rpy="0 0 0" />
      <geometry>
        <cylinder radius="0.018" length="0.004" />
        </geometry>
      </collision>
    <collision name="mount_bolt_1">
      <origin xyz="1.92882e-17 0.315 0.082" rpy="0 0 0" />
      <geometry>
        <cylinder radius="0.018" length="0.004" />
        </geometry>
      </collision>
    <collision name="mount_bolt_2">
      <origin xyz="-0.315 3.85764e-17 0.082" rpy="0 0 0" />
      <geometry>
        <cylinder radius="0.018" length="0.004" />
        </geometry>
      </collision>
    <collision name="mount_bolt_3">
      <origin xyz="-5.78646e-17 -0.315 0.082" rpy="0 0 0" />
      <geometry>
        <cylinder radius="0.018" length="0.004" />
        </geometry>
      </collision>
    </link>
  <link name="base_stage">
    <visual name="turntable_disc">
      <origin xyz="0 0 0.0325" rpy="0 0 0" />
      <geometry>
        <cylinder radius="0.32" length="0.065" />
        </geometry>
      <material name="blued_steel">
        <color rgba="0.12 0.2 0.28 1" />
        </material>
      </visual>
    <visual name="top_step">
      <origin xyz="0 0 0.079" rpy="0 0 0" />
      <geometry>
        <cylinder radius="0.255" length="0.028" />
        </geometry>
      <material name="parkerized_steel">
        <color rgba="0.2 0.23 0.25 1" />
        </material>
      </visual>
    <visual name="cheek_0">
      <geometry>
        <mesh filename="assets/meshes/side_cheek_0.obj" />
        </geometry>
      <material name="blued_steel">
        <color rgba="0.12 0.2 0.28 1" />
        </material>
      </visual>
    <visual name="bearing_ring_0">
      <geometry>
        <mesh filename="assets/meshes/bearing_ring_0.obj" />
        </geometry>
      <material name="parkerized_steel">
        <color rgba="0.2 0.23 0.25 1" />
        </material>
      </visual>
    <visual name="cheek_1">
      <geometry>
        <mesh filename="assets/meshes/side_cheek_1.obj" />
        </geometry>
      <material name="blued_steel">
        <color rgba="0.12 0.2 0.28 1" />
        </material>
      </visual>
    <visual name="bearing_ring_1">
      <geometry>
        <mesh filename="assets/meshes/bearing_ring_1.obj" />
        </geometry>
      <material name="parkerized_steel">
        <color rgba="0.2 0.23 0.25 1" />
        </material>
      </visual>
    <visual name="tie_bar_0">
      <origin xyz="0 -0.215 0.11" rpy="0 0 0" />
      <geometry>
        <box size="0.61 0.035 0.065" />
        </geometry>
      <material name="blued_steel">
        <color rgba="0.12 0.2 0.28 1" />
        </material>
      </visual>
    <visual name="tie_bar_1">
      <origin xyz="0 0.215 0.11" rpy="0 0 0" />
      <geometry>
        <box size="0.61 0.035 0.065" />
        </geometry>
      <material name="blued_steel">
        <color rgba="0.12 0.2 0.28 1" />
        </material>
      </visual>
    <collision name="turntable_disc">
      <origin xyz="0 0 0.0325" rpy="0 0 0" />
      <geometry>
        <cylinder radius="0.32" length="0.065" />
        </geometry>
      </collision>
    <collision name="top_step">
      <origin xyz="0 0 0.079" rpy="0 0 0" />
      <geometry>
        <cylinder radius="0.255" length="0.028" />
        </geometry>
      </collision>
    <collision name="cheek_0">
      <geometry>
        <mesh filename="assets/meshes/side_cheek_0.obj" />
        </geometry>
      </collision>
    <collision name="bearing_ring_0">
      <geometry>
        <mesh filename="assets/meshes/bearing_ring_0.obj" />
        </geometry>
      </collision>
    <collision name="cheek_1">
      <geometry>
        <mesh filename="assets/meshes/side_cheek_1.obj" />
        </geometry>
      </collision>
    <collision name="bearing_ring_1">
      <geometry>
        <mesh filename="assets/meshes/bearing_ring_1.obj" />
        </geometry>
      </collision>
    <collision name="tie_bar_0">
      <origin xyz="0 -0.215 0.11" rpy="0 0 0" />
      <geometry>
        <box size="0.61 0.035 0.065" />
        </geometry>
      </collision>
    <collision name="tie_bar_1">
      <origin xyz="0 0.215 0.11" rpy="0 0 0" />
      <geometry>
        <box size="0.61 0.035 0.065" />
        </geometry>
      </collision>
    </link>
  <link name="workplate">
    <visual name="plate">
      <geometry>
        <cylinder radius="0.2" length="0.045" />
        </geometry>
      <material name="machined_steel">
        <color rgba="0.62 0.64 0.62 1" />
        </material>
      </visual>
    <visual name="shaft">
      <origin xyz="0 0 0" rpy="0 1.5708 0" />
      <geometry>
        <cylinder radius="0.028" length="0.6" />
        </geometry>
      <material name="parkerized_steel">
        <color rgba="0.2 0.23 0.25 1" />
        </material>
      </visual>
    <visual name="center_hub">
      <origin xyz="0 0 0.0395" rpy="0 0 0" />
      <geometry>
        <cylinder radius="0.072" length="0.034" />
        </geometry>
      <material name="machined_steel">
        <color rgba="0.62 0.64 0.62 1" />
        </material>
      </visual>
    <visual name="long_slot_0">
      <origin xyz="-0.075 0 0.025" rpy="0 0 0" />
      <geometry>
        <box size="0.018 0.34 0.006" />
        </geometry>
      <material name="slot_dark">
        <color rgba="0.015 0.017 0.018 1" />
        </material>
      </visual>
    <visual name="long_slot_1">
      <origin xyz="0.075 0 0.025" rpy="0 0 0" />
      <geometry>
        <box size="0.018 0.34 0.006" />
        </geometry>
      <material name="slot_dark">
        <color rgba="0.015 0.017 0.018 1" />
        </material>
      </visual>
    <visual name="cross_slot">
      <origin xyz="0 0 0.026" rpy="0 0 0" />
      <geometry>
        <box size="0.33 0.018 0.006" />
        </geometry>
      <material name="slot_dark">
        <color rgba="0.015 0.017 0.018 1" />
        </material>
      </visual>
    <visual name="bolt_hole_0">
      <origin xyz="0.14 0 0.025" rpy="0 0 0" />
      <geometry>
        <cylinder radius="0.011" length="0.006" />
        </geometry>
      <material name="slot_dark">
        <color rgba="0.015 0.017 0.018 1" />
        </material>
      </visual>
    <visual name="bolt_hole_1">
      <origin xyz="0.07 0.121244 0.025" rpy="0 0 0" />
      <geometry>
        <cylinder radius="0.011" length="0.006" />
        </geometry>
      <material name="slot_dark">
        <color rgba="0.015 0.017 0.018 1" />
        </material>
      </visual>
    <visual name="bolt_hole_2">
      <origin xyz="-0.07 0.121244 0.025" rpy="0 0 0" />
      <geometry>
        <cylinder radius="0.011" length="0.006" />
        </geometry>
      <material name="slot_dark">
        <color rgba="0.015 0.017 0.018 1" />
        </material>
      </visual>
    <visual name="bolt_hole_3">
      <origin xyz="-0.14 1.71451e-17 0.025" rpy="0 0 0" />
      <geometry>
        <cylinder radius="0.011" length="0.006" />
        </geometry>
      <material name="slot_dark">
        <color rgba="0.015 0.017 0.018 1" />
        </material>
      </visual>
    <visual name="bolt_hole_4">
      <origin xyz="-0.07 -0.121244 0.025" rpy="0 0 0" />
      <geometry>
        <cylinder radius="0.011" length="0.006" />
        </geometry>
      <material name="slot_dark">
        <color rgba="0.015 0.017 0.018 1" />
        </material>
      </visual>
    <visual name="bolt_hole_5">
      <origin xyz="0.07 -0.121244 0.025" rpy="0 0 0" />
      <geometry>
        <cylinder radius="0.011" length="0.006" />
        </geometry>
      <material name="slot_dark">
        <color rgba="0.015 0.017 0.018 1" />
        </material>
      </visual>
    <collision name="plate">
      <geometry>
        <cylinder radius="0.2" length="0.045" />
        </geometry>
      </collision>
    <collision name="shaft">
      <origin xyz="0 0 0" rpy="0 1.5708 0" />
      <geometry>
        <cylinder radius="0.028" length="0.6" />
        </geometry>
      </collision>
    <collision name="center_hub">
      <origin xyz="0 0 0.0395" rpy="0 0 0" />
      <geometry>
        <cylinder radius="0.072" length="0.034" />
        </geometry>
      </collision>
    <collision name="long_slot_0">
      <origin xyz="-0.075 0 0.025" rpy="0 0 0" />
      <geometry>
        <box size="0.018 0.34 0.006" />
        </geometry>
      </collision>
    <collision name="long_slot_1">
      <origin xyz="0.075 0 0.025" rpy="0 0 0" />
      <geometry>
        <box size="0.018 0.34 0.006" />
        </geometry>
      </collision>
    <collision name="cross_slot">
      <origin xyz="0 0 0.026" rpy="0 0 0" />
      <geometry>
        <box size="0.33 0.018 0.006" />
        </geometry>
      </collision>
    <collision name="bolt_hole_0">
      <origin xyz="0.14 0 0.025" rpy="0 0 0" />
      <geometry>
        <cylinder radius="0.011" length="0.006" />
        </geometry>
      </collision>
    <collision name="bolt_hole_1">
      <origin xyz="0.07 0.121244 0.025" rpy="0 0 0" />
      <geometry>
        <cylinder radius="0.011" length="0.006" />
        </geometry>
      </collision>
    <collision name="bolt_hole_2">
      <origin xyz="-0.07 0.121244 0.025" rpy="0 0 0" />
      <geometry>
        <cylinder radius="0.011" length="0.006" />
        </geometry>
      </collision>
    <collision name="bolt_hole_3">
      <origin xyz="-0.14 1.71451e-17 0.025" rpy="0 0 0" />
      <geometry>
        <cylinder radius="0.011" length="0.006" />
        </geometry>
      </collision>
    <collision name="bolt_hole_4">
      <origin xyz="-0.07 -0.121244 0.025" rpy="0 0 0" />
      <geometry>
        <cylinder radius="0.011" length="0.006" />
        </geometry>
      </collision>
    <collision name="bolt_hole_5">
      <origin xyz="0.07 -0.121244 0.025" rpy="0 0 0" />
      <geometry>
        <cylinder radius="0.011" length="0.006" />
        </geometry>
      </collision>
    </link>
  <joint name="foundation_to_base" type="revolute">
    <origin xyz="0 0 0.092" rpy="0 0 0" />
    <parent link="foundation" />
    <child link="base_stage" />
    <axis xyz="0 0 1" />
    <limit effort="250" velocity="1.2" lower="-3.14159" upper="3.14159" />
    </joint>
  <joint name="base_to_workplate" type="revolute">
    <origin xyz="0 0 0.3" rpy="0 0 0" />
    <parent link="base_stage" />
    <child link="workplate" />
    <axis xyz="1 0 0" />
    <limit effort="180" velocity="1" lower="-1.05" upper="1.05" />
    </joint>
  </robot>
