<robot name="calibration_sewing_box">
  <material name="powder_coat">
    <color rgba="0.18 0.22 0.26 1" />
    </material>
  <material name="machined_datum">
    <color rgba="0.72 0.74 0.72 1" />
    </material>
  <material name="dark_gap">
    <color rgba="0.015 0.017 0.018 1" />
    </material>
  <material name="hinge_steel">
    <color rgba="0.58 0.6 0.62 1" />
    </material>
  <material name="engraving_black">
    <color rgba="0.02 0.02 0.018 1" />
    </material>
  <material name="screw_black">
    <color rgba="0.08 0.08 0.075 1" />
    </material>
  <material name="interior_blue">
    <color rgba="0.08 0.16 0.24 1" />
    </material>
  <link name="body">
    <visual name="floor">
      <origin xyz="0 0 0.006" rpy="0 0 0" />
      <geometry>
        <box size="0.32 0.22 0.012" />
        </geometry>
      <material name="powder_coat" />
      </visual>
    <visual name="front_wall">
      <origin xyz="0.154 0 0.061" rpy="0 0 0" />
      <geometry>
        <box size="0.012 0.22 0.098" />
        </geometry>
      <material name="powder_coat" />
      </visual>
    <visual name="rear_wall">
      <origin xyz="-0.154 0 0.061" rpy="0 0 0" />
      <geometry>
        <box size="0.012 0.22 0.098" />
        </geometry>
      <material name="powder_coat" />
      </visual>
    <visual name="side_wall_0">
      <origin xyz="0 0.104 0.061" rpy="0 0 0" />
      <geometry>
        <box size="0.32 0.012 0.098" />
        </geometry>
      <material name="powder_coat" />
      </visual>
    <visual name="side_wall_1">
      <origin xyz="0 -0.104 0.061" rpy="0 0 0" />
      <geometry>
        <box size="0.32 0.012 0.098" />
        </geometry>
      <material name="powder_coat" />
      </visual>
    <visual name="datum_rail_0">
      <origin xyz="0 0.101 0.109" rpy="0 0 0" />
      <geometry>
        <box size="0.32 0.018 0.002" />
        </geometry>
      <material name="machined_datum" />
      </visual>
    <visual name="datum_rail_1">
      <origin xyz="0 -0.101 0.109" rpy="0 0 0" />
      <geometry>
        <box size="0.32 0.018 0.002" />
        </geometry>
      <material name="machined_datum" />
      </visual>
    <visual name="datum_rail_front">
      <origin xyz="0.151 0 0.109" rpy="0 0 0" />
      <geometry>
        <box size="0.018 0.22 0.002" />
        </geometry>
      <material name="machined_datum" />
      </visual>
    <visual name="datum_rail_rear">
      <origin xyz="-0.151 0 0.109" rpy="0 0 0" />
      <geometry>
        <box size="0.018 0.22 0.002" />
        </geometry>
      <material name="machined_datum" />
      </visual>
    <visual name="front_gap_strip">
      <origin xyz="0.143 0 0.11" rpy="0 0 0" />
      <geometry>
        <box size="0.014 0.205 0.001" />
        </geometry>
      <material name="dark_gap" />
      </visual>
    <visual name="side_gap_strip_0">
      <origin xyz="0 0.095 0.11" rpy="0 0 0" />
      <geometry>
        <box size="0.3 0.008 0.001" />
        </geometry>
      <material name="dark_gap" />
      </visual>
    <visual name="side_gap_strip_1">
      <origin xyz="0 -0.095 0.11" rpy="0 0 0" />
      <geometry>
        <box size="0.3 0.008 0.001" />
        </geometry>
      <material name="dark_gap" />
      </visual>
    <visual name="center_divider">
      <origin xyz="0.02 0 0.0345" rpy="0 0 0" />
      <geometry>
        <box size="0.012 0.178 0.045" />
        </geometry>
      <material name="interior_blue" />
      </visual>
    <visual name="needle_divider">
      <origin xyz="-0.03 -0.04 0.0295" rpy="0 0 0" />
      <geometry>
        <box size="0.205 0.012 0.035" />
        </geometry>
      <material name="interior_blue" />
      </visual>
    <visual name="spool_post_0">
      <origin xyz="-0.095 -0.065 0.0345" rpy="0 0 0" />
      <geometry>
        <cylinder radius="0.006" length="0.045" />
        </geometry>
      <material name="interior_blue" />
      </visual>
    <visual name="spool_post_1">
      <origin xyz="-0.095 0 0.0345" rpy="0 0 0" />
      <geometry>
        <cylinder radius="0.006" length="0.045" />
        </geometry>
      <material name="interior_blue" />
      </visual>
    <visual name="spool_post_2">
      <origin xyz="-0.095 0.065 0.0345" rpy="0 0 0" />
      <geometry>
        <cylinder radius="0.006" length="0.045" />
        </geometry>
      <material name="interior_blue" />
      </visual>
    <visual name="stop_boss_0">
      <origin xyz="0.164 -0.073 0.075" rpy="0 0 0" />
      <geometry>
        <box size="0.008 0.032 0.026" />
        </geometry>
      <material name="machined_datum" />
      </visual>
    <visual name="stop_boss_1">
      <origin xyz="0.164 0.073 0.075" rpy="0 0 0" />
      <geometry>
        <box size="0.008 0.032 0.026" />
        </geometry>
      <material name="machined_datum" />
      </visual>
    <visual name="body_knuckle_0">
      <origin xyz="-0.17 -0.078 0.123" rpy="1.5708 0 0" />
      <geometry>
        <cylinder radius="0.007" length="0.034" />
        </geometry>
      <material name="hinge_steel" />
      </visual>
    <visual name="body_hinge_arm_0">
      <origin xyz="-0.164 -0.078 0.116" rpy="0 0 0" />
      <geometry>
        <box size="0.024 0.034 0.012" />
        </geometry>
      <material name="hinge_steel" />
      </visual>
    <visual name="body_knuckle_1">
      <origin xyz="-0.17 0 0.123" rpy="1.5708 0 0" />
      <geometry>
        <cylinder radius="0.007" length="0.042" />
        </geometry>
      <material name="hinge_steel" />
      </visual>
    <visual name="body_hinge_arm_1">
      <origin xyz="-0.164 0 0.116" rpy="0 0 0" />
      <geometry>
        <box size="0.024 0.042 0.012" />
        </geometry>
      <material name="hinge_steel" />
      </visual>
    <visual name="body_knuckle_2">
      <origin xyz="-0.17 0.078 0.123" rpy="1.5708 0 0" />
      <geometry>
        <cylinder radius="0.007" length="0.034" />
        </geometry>
      <material name="hinge_steel" />
      </visual>
    <visual name="body_hinge_arm_2">
      <origin xyz="-0.164 0.078 0.116" rpy="0 0 0" />
      <geometry>
        <box size="0.024 0.034 0.012" />
        </geometry>
      <material name="hinge_steel" />
      </visual>
    <visual name="rim_tick_0">
      <origin xyz="-0.092 -0.101 0.1104" rpy="0 0 0" />
      <geometry>
        <box size="0.002 0.02 0.001" />
        </geometry>
      <material name="engraving_black" />
      </visual>
    <visual name="rim_tick_1">
      <origin xyz="-0.046 -0.101 0.1104" rpy="0 0 0" />
      <geometry>
        <box size="0.002 0.02 0.001" />
        </geometry>
      <material name="engraving_black" />
      </visual>
    <visual name="rim_tick_2">
      <origin xyz="0 -0.101 0.1104" rpy="0 0 0" />
      <geometry>
        <box size="0.002 0.02 0.001" />
        </geometry>
      <material name="engraving_black" />
      </visual>
    <visual name="rim_tick_3">
      <origin xyz="0.046 -0.101 0.1104" rpy="0 0 0" />
      <geometry>
        <box size="0.002 0.02 0.001" />
        </geometry>
      <material name="engraving_black" />
      </visual>
    <visual name="rim_tick_4">
      <origin xyz="0.092 -0.101 0.1104" rpy="0 0 0" />
      <geometry>
        <box size="0.002 0.02 0.001" />
        </geometry>
      <material name="engraving_black" />
      </visual>
    <collision name="floor">
      <origin xyz="0 0 0.006" rpy="0 0 0" />
      <geometry>
        <box size="0.32 0.22 0.012" />
        </geometry>
      </collision>
    <collision name="front_wall">
      <origin xyz="0.154 0 0.061" rpy="0 0 0" />
      <geometry>
        <box size="0.012 0.22 0.098" />
        </geometry>
      </collision>
    <collision name="rear_wall">
      <origin xyz="-0.154 0 0.061" rpy="0 0 0" />
      <geometry>
        <box size="0.012 0.22 0.098" />
        </geometry>
      </collision>
    <collision name="side_wall_0">
      <origin xyz="0 0.104 0.061" rpy="0 0 0" />
      <geometry>
        <box size="0.32 0.012 0.098" />
        </geometry>
      </collision>
    <collision name="side_wall_1">
      <origin xyz="0 -0.104 0.061" rpy="0 0 0" />
      <geometry>
        <box size="0.32 0.012 0.098" />
        </geometry>
      </collision>
    <collision name="datum_rail_0">
      <origin xyz="0 0.101 0.109" rpy="0 0 0" />
      <geometry>
        <box size="0.32 0.018 0.002" />
        </geometry>
      </collision>
    <collision name="datum_rail_1">
      <origin xyz="0 -0.101 0.109" rpy="0 0 0" />
      <geometry>
        <box size="0.32 0.018 0.002" />
        </geometry>
      </collision>
    <collision name="datum_rail_front">
      <origin xyz="0.151 0 0.109" rpy="0 0 0" />
      <geometry>
        <box size="0.018 0.22 0.002" />
        </geometry>
      </collision>
    <collision name="datum_rail_rear">
      <origin xyz="-0.151 0 0.109" rpy="0 0 0" />
      <geometry>
        <box size="0.018 0.22 0.002" />
        </geometry>
      </collision>
    <collision name="front_gap_strip">
      <origin xyz="0.143 0 0.11" rpy="0 0 0" />
      <geometry>
        <box size="0.014 0.205 0.001" />
        </geometry>
      </collision>
    <collision name="side_gap_strip_0">
      <origin xyz="0 0.095 0.11" rpy="0 0 0" />
      <geometry>
        <box size="0.3 0.008 0.001" />
        </geometry>
      </collision>
    <collision name="side_gap_strip_1">
      <origin xyz="0 -0.095 0.11" rpy="0 0 0" />
      <geometry>
        <box size="0.3 0.008 0.001" />
        </geometry>
      </collision>
    <collision name="center_divider">
      <origin xyz="0.02 0 0.0345" rpy="0 0 0" />
      <geometry>
        <box size="0.012 0.178 0.045" />
        </geometry>
      </collision>
    <collision name="needle_divider">
      <origin xyz="-0.03 -0.04 0.0295" rpy="0 0 0" />
      <geometry>
        <box size="0.205 0.012 0.035" />
        </geometry>
      </collision>
    <collision name="spool_post_0">
      <origin xyz="-0.095 -0.065 0.0345" rpy="0 0 0" />
      <geometry>
        <cylinder radius="0.006" length="0.045" />
        </geometry>
      </collision>
    <collision name="spool_post_1">
      <origin xyz="-0.095 0 0.0345" rpy="0 0 0" />
      <geometry>
        <cylinder radius="0.006" length="0.045" />
        </geometry>
      </collision>
    <collision name="spool_post_2">
      <origin xyz="-0.095 0.065 0.0345" rpy="0 0 0" />
      <geometry>
        <cylinder radius="0.006" length="0.045" />
        </geometry>
      </collision>
    <collision name="stop_boss_0">
      <origin xyz="0.164 -0.073 0.075" rpy="0 0 0" />
      <geometry>
        <box size="0.008 0.032 0.026" />
        </geometry>
      </collision>
    <collision name="stop_boss_1">
      <origin xyz="0.164 0.073 0.075" rpy="0 0 0" />
      <geometry>
        <box size="0.008 0.032 0.026" />
        </geometry>
      </collision>
    <collision name="body_knuckle_0">
      <origin xyz="-0.17 -0.078 0.123" rpy="1.5708 0 0" />
      <geometry>
        <cylinder radius="0.007" length="0.034" />
        </geometry>
      </collision>
    <collision name="body_hinge_arm_0">
      <origin xyz="-0.164 -0.078 0.116" rpy="0 0 0" />
      <geometry>
        <box size="0.024 0.034 0.012" />
        </geometry>
      </collision>
    <collision name="body_knuckle_1">
      <origin xyz="-0.17 0 0.123" rpy="1.5708 0 0" />
      <geometry>
        <cylinder radius="0.007" length="0.042" />
        </geometry>
      </collision>
    <collision name="body_hinge_arm_1">
      <origin xyz="-0.164 0 0.116" rpy="0 0 0" />
      <geometry>
        <box size="0.024 0.042 0.012" />
        </geometry>
      </collision>
    <collision name="body_knuckle_2">
      <origin xyz="-0.17 0.078 0.123" rpy="1.5708 0 0" />
      <geometry>
        <cylinder radius="0.007" length="0.034" />
        </geometry>
      </collision>
    <collision name="body_hinge_arm_2">
      <origin xyz="-0.164 0.078 0.116" rpy="0 0 0" />
      <geometry>
        <box size="0.024 0.034 0.012" />
        </geometry>
      </collision>
    <collision name="rim_tick_0">
      <origin xyz="-0.092 -0.101 0.1104" rpy="0 0 0" />
      <geometry>
        <box size="0.002 0.02 0.001" />
        </geometry>
      </collision>
    <collision name="rim_tick_1">
      <origin xyz="-0.046 -0.101 0.1104" rpy="0 0 0" />
      <geometry>
        <box size="0.002 0.02 0.001" />
        </geometry>
      </collision>
    <collision name="rim_tick_2">
      <origin xyz="0 -0.101 0.1104" rpy="0 0 0" />
      <geometry>
        <box size="0.002 0.02 0.001" />
        </geometry>
      </collision>
    <collision name="rim_tick_3">
      <origin xyz="0.046 -0.101 0.1104" rpy="0 0 0" />
      <geometry>
        <box size="0.002 0.02 0.001" />
        </geometry>
      </collision>
    <collision name="rim_tick_4">
      <origin xyz="0.092 -0.101 0.1104" rpy="0 0 0" />
      <geometry>
        <box size="0.002 0.02 0.001" />
        </geometry>
      </collision>
    </link>
  <link name="lid">
    <visual name="lid_panel">
      <origin xyz="0.181 0 -0.003" rpy="0 0 0" />
      <geometry>
        <box size="0.33 0.232 0.014" />
        </geometry>
      <material name="powder_coat" />
      </visual>
    <visual name="top_datum_plate">
      <origin xyz="0.205 0 0.005" rpy="0 0 0" />
      <geometry>
        <box size="0.18 0.082 0.002" />
        </geometry>
      <material name="machined_datum" />
      </visual>
    <visual name="front_lip">
      <origin xyz="0.34 0 -0.018" rpy="0 0 0" />
      <geometry>
        <box size="0.01 0.22 0.02" />
        </geometry>
      <material name="powder_coat" />
      </visual>
    <visual name="underside_rib_0">
      <origin xyz="0.175 0.055 -0.014" rpy="0 0 0" />
      <geometry>
        <box size="0.21 0.01 0.008" />
        </geometry>
      <material name="powder_coat" />
      </visual>
    <visual name="underside_rib_1">
      <origin xyz="0.175 -0.055 -0.014" rpy="0 0 0" />
      <geometry>
        <box size="0.21 0.01 0.008" />
        </geometry>
      <material name="powder_coat" />
      </visual>
    <visual name="underside_rib_front">
      <origin xyz="0.285 0 -0.014" rpy="0 0 0" />
      <geometry>
        <box size="0.01 0.15 0.008" />
        </geometry>
      <material name="powder_coat" />
      </visual>
    <visual name="lid_knuckle_0">
      <origin xyz="0 -0.041 0" rpy="1.5708 0 0" />
      <geometry>
        <cylinder radius="0.007" length="0.034" />
        </geometry>
      <material name="hinge_steel" />
      </visual>
    <visual name="lid_hinge_arm_0">
      <origin xyz="0.008 -0.041 -0.003" rpy="0 0 0" />
      <geometry>
        <box size="0.018 0.034 0.012" />
        </geometry>
      <material name="hinge_steel" />
      </visual>
    <visual name="lid_knuckle_1">
      <origin xyz="0 0.041 0" rpy="1.5708 0 0" />
      <geometry>
        <cylinder radius="0.007" length="0.034" />
        </geometry>
      <material name="hinge_steel" />
      </visual>
    <visual name="lid_hinge_arm_1">
      <origin xyz="0.008 0.041 -0.003" rpy="0 0 0" />
      <geometry>
        <box size="0.018 0.034 0.012" />
        </geometry>
      <material name="hinge_steel" />
      </visual>
    <visual name="index_mark_0">
      <origin xyz="0.205 -0.032 0.006" rpy="0 0 0" />
      <geometry>
        <box size="0.04 0.0015 0.001" />
        </geometry>
      <material name="engraving_black" />
      </visual>
    <visual name="index_mark_1">
      <origin xyz="0.205 -0.016 0.006" rpy="0 0 0" />
      <geometry>
        <box size="0.04 0.0015 0.001" />
        </geometry>
      <material name="engraving_black" />
      </visual>
    <visual name="index_mark_2">
      <origin xyz="0.205 0 0.006" rpy="0 0 0" />
      <geometry>
        <box size="0.04 0.0015 0.001" />
        </geometry>
      <material name="engraving_black" />
      </visual>
    <visual name="index_mark_3">
      <origin xyz="0.205 0.016 0.006" rpy="0 0 0" />
      <geometry>
        <box size="0.04 0.0015 0.001" />
        </geometry>
      <material name="engraving_black" />
      </visual>
    <visual name="index_mark_4">
      <origin xyz="0.205 0.032 0.006" rpy="0 0 0" />
      <geometry>
        <box size="0.04 0.0015 0.001" />
        </geometry>
      <material name="engraving_black" />
      </visual>
    <collision name="lid_panel">
      <origin xyz="0.181 0 -0.003" rpy="0 0 0" />
      <geometry>
        <box size="0.33 0.232 0.014" />
        </geometry>
      </collision>
    <collision name="top_datum_plate">
      <origin xyz="0.205 0 0.005" rpy="0 0 0" />
      <geometry>
        <box size="0.18 0.082 0.002" />
        </geometry>
      </collision>
    <collision name="front_lip">
      <origin xyz="0.34 0 -0.018" rpy="0 0 0" />
      <geometry>
        <box size="0.01 0.22 0.02" />
        </geometry>
      </collision>
    <collision name="underside_rib_0">
      <origin xyz="0.175 0.055 -0.014" rpy="0 0 0" />
      <geometry>
        <box size="0.21 0.01 0.008" />
        </geometry>
      </collision>
    <collision name="underside_rib_1">
      <origin xyz="0.175 -0.055 -0.014" rpy="0 0 0" />
      <geometry>
        <box size="0.21 0.01 0.008" />
        </geometry>
      </collision>
    <collision name="underside_rib_front">
      <origin xyz="0.285 0 -0.014" rpy="0 0 0" />
      <geometry>
        <box size="0.01 0.15 0.008" />
        </geometry>
      </collision>
    <collision name="lid_knuckle_0">
      <origin xyz="0 -0.041 0" rpy="1.5708 0 0" />
      <geometry>
        <cylinder radius="0.007" length="0.034" />
        </geometry>
      </collision>
    <collision name="lid_hinge_arm_0">
      <origin xyz="0.008 -0.041 -0.003" rpy="0 0 0" />
      <geometry>
        <box size="0.018 0.034 0.012" />
        </geometry>
      </collision>
    <collision name="lid_knuckle_1">
      <origin xyz="0 0.041 0" rpy="1.5708 0 0" />
      <geometry>
        <cylinder radius="0.007" length="0.034" />
        </geometry>
      </collision>
    <collision name="lid_hinge_arm_1">
      <origin xyz="0.008 0.041 -0.003" rpy="0 0 0" />
      <geometry>
        <box size="0.018 0.034 0.012" />
        </geometry>
      </collision>
    <collision name="index_mark_0">
      <origin xyz="0.205 -0.032 0.006" rpy="0 0 0" />
      <geometry>
        <box size="0.04 0.0015 0.001" />
        </geometry>
      </collision>
    <collision name="index_mark_1">
      <origin xyz="0.205 -0.016 0.006" rpy="0 0 0" />
      <geometry>
        <box size="0.04 0.0015 0.001" />
        </geometry>
      </collision>
    <collision name="index_mark_2">
      <origin xyz="0.205 0 0.006" rpy="0 0 0" />
      <geometry>
        <box size="0.04 0.0015 0.001" />
        </geometry>
      </collision>
    <collision name="index_mark_3">
      <origin xyz="0.205 0.016 0.006" rpy="0 0 0" />
      <geometry>
        <box size="0.04 0.0015 0.001" />
        </geometry>
      </collision>
    <collision name="index_mark_4">
      <origin xyz="0.205 0.032 0.006" rpy="0 0 0" />
      <geometry>
        <box size="0.04 0.0015 0.001" />
        </geometry>
      </collision>
    </link>
  <link name="stop_screw_0">
    <visual name="screw_shank">
      <origin xyz="0.006 0 0" rpy="0 1.5708 0" />
      <geometry>
        <cylinder radius="0.004" length="0.012" />
        </geometry>
      <material name="hinge_steel" />
      </visual>
    <visual name="knurled_head">
      <origin xyz="0.016 0 0" rpy="0 1.5708 0" />
      <geometry>
        <cylinder radius="0.012" length="0.008" />
        </geometry>
      <material name="screw_black" />
      </visual>
    <visual name="screw_index">
      <origin xyz="0.0205 0 0" rpy="0 0 0" />
      <geometry>
        <box size="0.001 0.017 0.001" />
        </geometry>
      <material name="engraving_black" />
      </visual>
    <collision name="screw_shank">
      <origin xyz="0.006 0 0" rpy="0 1.5708 0" />
      <geometry>
        <cylinder radius="0.004" length="0.012" />
        </geometry>
      </collision>
    <collision name="knurled_head">
      <origin xyz="0.016 0 0" rpy="0 1.5708 0" />
      <geometry>
        <cylinder radius="0.012" length="0.008" />
        </geometry>
      </collision>
    <collision name="screw_index">
      <origin xyz="0.0205 0 0" rpy="0 0 0" />
      <geometry>
        <box size="0.001 0.017 0.001" />
        </geometry>
      </collision>
    </link>
  <link name="stop_screw_1">
    <visual name="screw_shank">
      <origin xyz="0.006 0 0" rpy="0 1.5708 0" />
      <geometry>
        <cylinder radius="0.004" length="0.012" />
        </geometry>
      <material name="hinge_steel" />
      </visual>
    <visual name="knurled_head">
      <origin xyz="0.016 0 0" rpy="0 1.5708 0" />
      <geometry>
        <cylinder radius="0.012" length="0.008" />
        </geometry>
      <material name="screw_black" />
      </visual>
    <visual name="screw_index">
      <origin xyz="0.0205 0 0" rpy="0 0 0" />
      <geometry>
        <box size="0.001 0.017 0.001" />
        </geometry>
      <material name="engraving_black" />
      </visual>
    <collision name="screw_shank">
      <origin xyz="0.006 0 0" rpy="0 1.5708 0" />
      <geometry>
        <cylinder radius="0.004" length="0.012" />
        </geometry>
      </collision>
    <collision name="knurled_head">
      <origin xyz="0.016 0 0" rpy="0 1.5708 0" />
      <geometry>
        <cylinder radius="0.012" length="0.008" />
        </geometry>
      </collision>
    <collision name="screw_index">
      <origin xyz="0.0205 0 0" rpy="0 0 0" />
      <geometry>
        <box size="0.001 0.017 0.001" />
        </geometry>
      </collision>
    </link>
  <joint name="body_to_lid" type="revolute">
    <origin xyz="-0.17 0 0.123" rpy="0 0 0" />
    <parent link="body" />
    <child link="lid" />
    <axis xyz="0 -1 0" />
    <limit effort="6" velocity="2" lower="0" upper="1.75" />
    </joint>
  <joint name="stop_screw_0_spin" type="revolute">
    <origin xyz="0.168 -0.073 0.075" rpy="0 0 0" />
    <parent link="body" />
    <child link="stop_screw_0" />
    <axis xyz="1 0 0" />
    <limit effort="0.5" velocity="6" lower="-3.14159" upper="3.14159" />
    </joint>
  <joint name="stop_screw_1_spin" type="revolute">
    <origin xyz="0.168 0.073 0.075" rpy="0 0 0" />
    <parent link="body" />
    <child link="stop_screw_1" />
    <axis xyz="1 0 0" />
    <limit effort="0.5" velocity="6" lower="-3.14159" upper="3.14159" />
    </joint>
  </robot>
