<robot name="folding_adjustable_weight_bench">
  <link name="center_frame">
    <visual name="base_rail_0">
      <origin xyz="-0.035 -0.19 0.075" rpy="0 1.5708 0" />
      <geometry>
        <cylinder radius="0.022" length="1.29" />
        </geometry>
      <material name="satin_black_steel">
        <color rgba="0.03 0.035 0.035 1" />
        </material>
      </visual>
    <visual name="base_rail_1">
      <origin xyz="-0.035 0.19 0.075" rpy="0 1.5708 0" />
      <geometry>
        <cylinder radius="0.022" length="1.29" />
        </geometry>
      <material name="satin_black_steel">
        <color rgba="0.03 0.035 0.035 1" />
        </material>
      </visual>
    <visual name="rear_cross_tube">
      <origin xyz="-0.65 0 0.075" rpy="0 1.5708 1.5708" />
      <geometry>
        <cylinder radius="0.023" length="0.46" />
        </geometry>
      <material name="satin_black_steel">
        <color rgba="0.03 0.035 0.035 1" />
        </material>
      </visual>
    <visual name="front_cross_tube">
      <origin xyz="0.57 0 0.075" rpy="0 1.5708 1.5708" />
      <geometry>
        <cylinder radius="0.023" length="0.46" />
        </geometry>
      <material name="satin_black_steel">
        <color rgba="0.03 0.035 0.035 1" />
        </material>
      </visual>
    <visual name="center_spine">
      <origin xyz="-0.035 0 0.1875" rpy="0 1.42664 0" />
      <geometry>
        <cylinder radius="0.023" length="0.939747" />
        </geometry>
      <material name="satin_black_steel">
        <color rgba="0.03 0.035 0.035 1" />
        </material>
      </visual>
    <visual name="rear_mast">
      <origin xyz="-0.2825 0 0.22" rpy="0 0.826697 0" />
      <geometry>
        <cylinder radius="0.022" length="0.428165" />
        </geometry>
      <material name="satin_black_steel">
        <color rgba="0.03 0.035 0.035 1" />
        </material>
      </visual>
    <visual name="front_mast">
      <origin xyz="0.1825 0 0.235" rpy="0 0.936554 3.14159" />
      <geometry>
        <cylinder radius="0.022" length="0.540023" />
        </geometry>
      <material name="satin_black_steel">
        <color rgba="0.03 0.035 0.035 1" />
        </material>
      </visual>
    <visual name="rear_mast_crossbar">
      <origin xyz="-0.44 0 0.075" rpy="0 1.5708 1.5708" />
      <geometry>
        <cylinder radius="0.018" length="0.38" />
        </geometry>
      <material name="satin_black_steel">
        <color rgba="0.03 0.035 0.035 1" />
        </material>
      </visual>
    <visual name="front_mast_crossbar">
      <origin xyz="0.4 0 0.075" rpy="0 1.5708 1.5708" />
      <geometry>
        <cylinder radius="0.018" length="0.38" />
        </geometry>
      <material name="satin_black_steel">
        <color rgba="0.03 0.035 0.035 1" />
        </material>
      </visual>
    <visual name="mid_cross_tube">
      <origin xyz="-0.18 0 0.315" rpy="0 1.5708 1.5708" />
      <geometry>
        <cylinder radius="0.018" length="0.38" />
        </geometry>
      <material name="satin_black_steel">
        <color rgba="0.03 0.035 0.035 1" />
        </material>
      </visual>
    <visual name="spine_saddle_plate">
      <origin xyz="-0.5 0 0.098" rpy="0 0 0" />
      <geometry>
        <box size="0.09 0.43 0.045" />
        </geometry>
      <material name="dark_powdercoat">
        <color rgba="0.01 0.012 0.012 1" />
        </material>
      </visual>
    <visual name="back_hinge_axle">
      <origin xyz="-0.09 0 0.43" rpy="0 1.5708 1.5708" />
      <geometry>
        <cylinder radius="0.011" length="0.47" />
        </geometry>
      <material name="brushed_pin_metal">
        <color rgba="0.65 0.66 0.63 1" />
        </material>
      </visual>
    <visual name="seat_hinge_axle">
      <origin xyz="-0.035 0 0.43" rpy="0 1.5708 1.5708" />
      <geometry>
        <cylinder radius="0.01" length="0.43" />
        </geometry>
      <material name="brushed_pin_metal">
        <color rgba="0.65 0.66 0.63 1" />
        </material>
      </visual>
    <visual name="support_pivot_axle">
      <origin xyz="-0.64 0 0.13" rpy="0 1.5708 1.5708" />
      <geometry>
        <cylinder radius="0.01" length="0.26" />
        </geometry>
      <material name="brushed_pin_metal">
        <color rgba="0.65 0.66 0.63 1" />
        </material>
      </visual>
    <visual name="front_wheel_axle">
      <origin xyz="0.69 0 0.085" rpy="0 1.5708 1.5708" />
      <geometry>
        <cylinder radius="0.009" length="0.65" />
        </geometry>
      <material name="brushed_pin_metal">
        <color rgba="0.65 0.66 0.63 1" />
        </material>
      </visual>
    <visual name="back_hinge_side_support_0">
      <origin xyz="-0.135 -0.2142 0.3725" rpy="0 0.724648 -0.486491" />
      <geometry>
        <cylinder radius="0.012" length="0.153593" />
        </geometry>
      <material name="satin_black_steel">
        <color rgba="0.03 0.035 0.035 1" />
        </material>
      </visual>
    <visual name="back_hinge_side_support_1">
      <origin xyz="-0.135 0.2142 0.3725" rpy="0 0.724648 0.486491" />
      <geometry>
        <cylinder radius="0.012" length="0.153593" />
        </geometry>
      <material name="satin_black_steel">
        <color rgba="0.03 0.035 0.035 1" />
        </material>
      </visual>
    <visual name="seat_hinge_side_support_0">
      <origin xyz="-0.0025 -0.20492 0.38" rpy="0 0.611174 -2.75897" />
      <geometry>
        <cylinder radius="0.012" length="0.122104" />
        </geometry>
      <material name="satin_black_steel">
        <color rgba="0.03 0.035 0.035 1" />
        </material>
      </visual>
    <visual name="seat_hinge_side_support_1">
      <origin xyz="-0.0025 0.20492 0.38" rpy="0 0.611174 2.75897" />
      <geometry>
        <cylinder radius="0.012" length="0.122104" />
        </geometry>
      <material name="satin_black_steel">
        <color rgba="0.03 0.035 0.035 1" />
        </material>
      </visual>
    <visual name="wheel_axle_bracket">
      <origin xyz="0.63 0 0.08" rpy="0 1.48766 0" />
      <geometry>
        <cylinder radius="0.011" length="0.120416" />
        </geometry>
      <material name="satin_black_steel">
        <color rgba="0.03 0.035 0.035 1" />
        </material>
      </visual>
    <visual name="seat_support_crossbar">
      <origin xyz="0.03 0 0.33" rpy="0 1.5708 1.5708" />
      <geometry>
        <cylinder radius="0.014" length="0.384" />
        </geometry>
      <material name="satin_black_steel">
        <color rgba="0.03 0.035 0.035 1" />
        </material>
      </visual>
    <visual name="support_pivot_lug_0">
      <origin xyz="-0.64 -0.13 0.098" rpy="0 0 0" />
      <geometry>
        <box size="0.06 0.018 0.08" />
        </geometry>
      <material name="satin_black_steel">
        <color rgba="0.03 0.035 0.035 1" />
        </material>
      </visual>
    <visual name="support_pivot_lug_1">
      <origin xyz="-0.64 0.13 0.098" rpy="0 0 0" />
      <geometry>
        <box size="0.06 0.018 0.08" />
        </geometry>
      <material name="satin_black_steel">
        <color rgba="0.03 0.035 0.035 1" />
        </material>
      </visual>
    <visual name="rear_foot_0">
      <origin xyz="-0.65 -0.245 0.04" rpy="0 0 0" />
      <geometry>
        <box size="0.075 0.035 0.024" />
        </geometry>
      <material name="matte_black_rubber">
        <color rgba="0.005 0.005 0.004 1" />
        </material>
      </visual>
    <visual name="rear_foot_1">
      <origin xyz="-0.65 0.245 0.04" rpy="0 0 0" />
      <geometry>
        <box size="0.075 0.035 0.024" />
        </geometry>
      <material name="matte_black_rubber">
        <color rgba="0.005 0.005 0.004 1" />
        </material>
      </visual>
    <visual name="front_foot_0">
      <origin xyz="0.57 -0.245 0.04" rpy="0 0 0" />
      <geometry>
        <box size="0.075 0.035 0.024" />
        </geometry>
      <material name="matte_black_rubber">
        <color rgba="0.005 0.005 0.004 1" />
        </material>
      </visual>
    <visual name="front_foot_1">
      <origin xyz="0.57 0.245 0.04" rpy="0 0 0" />
      <geometry>
        <box size="0.075 0.035 0.024" />
        </geometry>
      <material name="matte_black_rubber">
        <color rgba="0.005 0.005 0.004 1" />
        </material>
      </visual>
    <visual name="selector_ladder">
      <origin xyz="-0.34 -0.165 0.2875" rpy="0 1.14535 0" />
      <geometry>
        <cylinder radius="0.014" length="0.351319" />
        </geometry>
      <material name="dark_powdercoat">
        <color rgba="0.01 0.012 0.012 1" />
        </material>
      </visual>
    <visual name="selector_hole_0">
      <origin xyz="-0.45 -0.165 0.238" rpy="1.5708 0 0" />
      <geometry>
        <cylinder radius="0.014" length="0.02" />
        </geometry>
      <material name="brushed_pin_metal">
        <color rgba="0.65 0.66 0.63 1" />
        </material>
      </visual>
    <visual name="selector_hole_1">
      <origin xyz="-0.37 -0.165 0.274" rpy="1.5708 0 0" />
      <geometry>
        <cylinder radius="0.014" length="0.02" />
        </geometry>
      <material name="brushed_pin_metal">
        <color rgba="0.65 0.66 0.63 1" />
        </material>
      </visual>
    <visual name="selector_hole_2">
      <origin xyz="-0.29 -0.165 0.31" rpy="1.5708 0 0" />
      <geometry>
        <cylinder radius="0.014" length="0.02" />
        </geometry>
      <material name="brushed_pin_metal">
        <color rgba="0.65 0.66 0.63 1" />
        </material>
      </visual>
    <visual name="selector_hole_3">
      <origin xyz="-0.21 -0.165 0.346" rpy="1.5708 0 0" />
      <geometry>
        <cylinder radius="0.014" length="0.02" />
        </geometry>
      <material name="brushed_pin_metal">
        <color rgba="0.65 0.66 0.63 1" />
        </material>
      </visual>
    <visual name="selector_mount_tab">
      <origin xyz="-0.18 -0.168 0.336" rpy="0 0 0" />
      <geometry>
        <box size="0.06 0.045 0.05" />
        </geometry>
      <material name="dark_powdercoat">
        <color rgba="0.01 0.012 0.012 1" />
        </material>
      </visual>
    <collision name="base_rail_0">
      <origin xyz="-0.035 -0.19 0.075" rpy="0 1.5708 0" />
      <geometry>
        <cylinder radius="0.022" length="1.29" />
        </geometry>
      </collision>
    <collision name="base_rail_1">
      <origin xyz="-0.035 0.19 0.075" rpy="0 1.5708 0" />
      <geometry>
        <cylinder radius="0.022" length="1.29" />
        </geometry>
      </collision>
    <collision name="rear_cross_tube">
      <origin xyz="-0.65 0 0.075" rpy="0 1.5708 1.5708" />
      <geometry>
        <cylinder radius="0.023" length="0.46" />
        </geometry>
      </collision>
    <collision name="front_cross_tube">
      <origin xyz="0.57 0 0.075" rpy="0 1.5708 1.5708" />
      <geometry>
        <cylinder radius="0.023" length="0.46" />
        </geometry>
      </collision>
    <collision name="center_spine">
      <origin xyz="-0.035 0 0.1875" rpy="0 1.42664 0" />
      <geometry>
        <cylinder radius="0.023" length="0.939747" />
        </geometry>
      </collision>
    <collision name="rear_mast">
      <origin xyz="-0.2825 0 0.22" rpy="0 0.826697 0" />
      <geometry>
        <cylinder radius="0.022" length="0.428165" />
        </geometry>
      </collision>
    <collision name="front_mast">
      <origin xyz="0.1825 0 0.235" rpy="0 0.936554 3.14159" />
      <geometry>
        <cylinder radius="0.022" length="0.540023" />
        </geometry>
      </collision>
    <collision name="rear_mast_crossbar">
      <origin xyz="-0.44 0 0.075" rpy="0 1.5708 1.5708" />
      <geometry>
        <cylinder radius="0.018" length="0.38" />
        </geometry>
      </collision>
    <collision name="front_mast_crossbar">
      <origin xyz="0.4 0 0.075" rpy="0 1.5708 1.5708" />
      <geometry>
        <cylinder radius="0.018" length="0.38" />
        </geometry>
      </collision>
    <collision name="mid_cross_tube">
      <origin xyz="-0.18 0 0.315" rpy="0 1.5708 1.5708" />
      <geometry>
        <cylinder radius="0.018" length="0.38" />
        </geometry>
      </collision>
    <collision name="spine_saddle_plate">
      <origin xyz="-0.5 0 0.098" rpy="0 0 0" />
      <geometry>
        <box size="0.09 0.43 0.045" />
        </geometry>
      </collision>
    <collision name="back_hinge_axle">
      <origin xyz="-0.09 0 0.43" rpy="0 1.5708 1.5708" />
      <geometry>
        <cylinder radius="0.011" length="0.47" />
        </geometry>
      </collision>
    <collision name="seat_hinge_axle">
      <origin xyz="-0.035 0 0.43" rpy="0 1.5708 1.5708" />
      <geometry>
        <cylinder radius="0.01" length="0.43" />
        </geometry>
      </collision>
    <collision name="support_pivot_axle">
      <origin xyz="-0.64 0 0.13" rpy="0 1.5708 1.5708" />
      <geometry>
        <cylinder radius="0.01" length="0.26" />
        </geometry>
      </collision>
    <collision name="front_wheel_axle">
      <origin xyz="0.69 0 0.085" rpy="0 1.5708 1.5708" />
      <geometry>
        <cylinder radius="0.009" length="0.65" />
        </geometry>
      </collision>
    <collision name="back_hinge_side_support_0">
      <origin xyz="-0.135 -0.2142 0.3725" rpy="0 0.724648 -0.486491" />
      <geometry>
        <cylinder radius="0.012" length="0.153593" />
        </geometry>
      </collision>
    <collision name="back_hinge_side_support_1">
      <origin xyz="-0.135 0.2142 0.3725" rpy="0 0.724648 0.486491" />
      <geometry>
        <cylinder radius="0.012" length="0.153593" />
        </geometry>
      </collision>
    <collision name="seat_hinge_side_support_0">
      <origin xyz="-0.0025 -0.20492 0.38" rpy="0 0.611174 -2.75897" />
      <geometry>
        <cylinder radius="0.012" length="0.122104" />
        </geometry>
      </collision>
    <collision name="seat_hinge_side_support_1">
      <origin xyz="-0.0025 0.20492 0.38" rpy="0 0.611174 2.75897" />
      <geometry>
        <cylinder radius="0.012" length="0.122104" />
        </geometry>
      </collision>
    <collision name="wheel_axle_bracket">
      <origin xyz="0.63 0 0.08" rpy="0 1.48766 0" />
      <geometry>
        <cylinder radius="0.011" length="0.120416" />
        </geometry>
      </collision>
    <collision name="seat_support_crossbar">
      <origin xyz="0.03 0 0.33" rpy="0 1.5708 1.5708" />
      <geometry>
        <cylinder radius="0.014" length="0.384" />
        </geometry>
      </collision>
    <collision name="support_pivot_lug_0">
      <origin xyz="-0.64 -0.13 0.098" rpy="0 0 0" />
      <geometry>
        <box size="0.06 0.018 0.08" />
        </geometry>
      </collision>
    <collision name="support_pivot_lug_1">
      <origin xyz="-0.64 0.13 0.098" rpy="0 0 0" />
      <geometry>
        <box size="0.06 0.018 0.08" />
        </geometry>
      </collision>
    <collision name="rear_foot_0">
      <origin xyz="-0.65 -0.245 0.04" rpy="0 0 0" />
      <geometry>
        <box size="0.075 0.035 0.024" />
        </geometry>
      </collision>
    <collision name="rear_foot_1">
      <origin xyz="-0.65 0.245 0.04" rpy="0 0 0" />
      <geometry>
        <box size="0.075 0.035 0.024" />
        </geometry>
      </collision>
    <collision name="front_foot_0">
      <origin xyz="0.57 -0.245 0.04" rpy="0 0 0" />
      <geometry>
        <box size="0.075 0.035 0.024" />
        </geometry>
      </collision>
    <collision name="front_foot_1">
      <origin xyz="0.57 0.245 0.04" rpy="0 0 0" />
      <geometry>
        <box size="0.075 0.035 0.024" />
        </geometry>
      </collision>
    <collision name="selector_ladder">
      <origin xyz="-0.34 -0.165 0.2875" rpy="0 1.14535 0" />
      <geometry>
        <cylinder radius="0.014" length="0.351319" />
        </geometry>
      </collision>
    <collision name="selector_hole_0">
      <origin xyz="-0.45 -0.165 0.238" rpy="1.5708 0 0" />
      <geometry>
        <cylinder radius="0.014" length="0.02" />
        </geometry>
      </collision>
    <collision name="selector_hole_1">
      <origin xyz="-0.37 -0.165 0.274" rpy="1.5708 0 0" />
      <geometry>
        <cylinder radius="0.014" length="0.02" />
        </geometry>
      </collision>
    <collision name="selector_hole_2">
      <origin xyz="-0.29 -0.165 0.31" rpy="1.5708 0 0" />
      <geometry>
        <cylinder radius="0.014" length="0.02" />
        </geometry>
      </collision>
    <collision name="selector_hole_3">
      <origin xyz="-0.21 -0.165 0.346" rpy="1.5708 0 0" />
      <geometry>
        <cylinder radius="0.014" length="0.02" />
        </geometry>
      </collision>
    <collision name="selector_mount_tab">
      <origin xyz="-0.18 -0.168 0.336" rpy="0 0 0" />
      <geometry>
        <box size="0.06 0.045 0.05" />
        </geometry>
      </collision>
    </link>
  <link name="backrest">
    <visual name="back_pad">
      <origin xyz="-0.405 0 0.06" rpy="0 0 0" />
      <geometry>
        <mesh filename="assets/meshes/backrest_pad_mesh.obj" />
        </geometry>
      <material name="black_grained_vinyl">
        <color rgba="0.02 0.022 0.024 1" />
        </material>
      </visual>
    <visual name="back_seam_0">
      <origin xyz="-0.405 0.118 0.0995" rpy="0 0 0" />
      <geometry>
        <box size="0.7 0.014 0.008" />
        </geometry>
      <material name="slightly_gloss_seam">
        <color rgba="0 0 0 1" />
        </material>
      </visual>
    <visual name="back_seam_1">
      <origin xyz="-0.405 -0.118 0.0995" rpy="0 0 0" />
      <geometry>
        <box size="0.7 0.014 0.008" />
        </geometry>
      <material name="slightly_gloss_seam">
        <color rgba="0 0 0 1" />
        </material>
      </visual>
    <visual name="back_under_rail_0">
      <origin xyz="-0.385 -0.105 0.012" rpy="0 1.5708 0" />
      <geometry>
        <cylinder radius="0.014" length="0.72" />
        </geometry>
      <material name="satin_black_steel">
        <color rgba="0.03 0.035 0.035 1" />
        </material>
      </visual>
    <visual name="back_under_rail_1">
      <origin xyz="-0.385 0.105 0.012" rpy="0 1.5708 0" />
      <geometry>
        <cylinder radius="0.014" length="0.72" />
        </geometry>
      <material name="satin_black_steel">
        <color rgba="0.03 0.035 0.035 1" />
        </material>
      </visual>
    <visual name="back_cross_bracket">
      <origin xyz="-0.52 0 0.012" rpy="0 1.5708 1.5708" />
      <geometry>
        <cylinder radius="0.012" length="0.25" />
        </geometry>
      <material name="satin_black_steel">
        <color rgba="0.03 0.035 0.035 1" />
        </material>
      </visual>
    <visual name="back_hinge_sleeve">
      <origin xyz="0 0 0" rpy="0 1.5708 1.5708" />
      <geometry>
        <cylinder radius="0.018" length="0.41" />
        </geometry>
      <material name="satin_black_steel">
        <color rgba="0.03 0.035 0.035 1" />
        </material>
      </visual>
    <visual name="back_hinge_tab_0">
      <origin xyz="-0.026 -0.105 0.025" rpy="0 0 0" />
      <geometry>
        <box size="0.036 0.034 0.02" />
        </geometry>
      <material name="satin_black_steel">
        <color rgba="0.03 0.035 0.035 1" />
        </material>
      </visual>
    <visual name="back_hinge_tab_1">
      <origin xyz="-0.026 0.105 0.025" rpy="0 0 0" />
      <geometry>
        <box size="0.036 0.034 0.02" />
        </geometry>
      <material name="satin_black_steel">
        <color rgba="0.03 0.035 0.035 1" />
        </material>
      </visual>
    <visual name="pop_pin_plate">
      <origin xyz="-0.28 -0.168 -0.02" rpy="0 0 0" />
      <geometry>
        <box size="0.28 0.014 0.055" />
        </geometry>
      <material name="dark_powdercoat">
        <color rgba="0.01 0.012 0.012 1" />
        </material>
      </visual>
    <visual name="pop_pin_standoff">
      <origin xyz="-0.28 -0.1365 -0.01" rpy="0 1.5708 -1.5708" />
      <geometry>
        <cylinder radius="0.01" length="0.063" />
        </geometry>
      <material name="satin_black_steel">
        <color rgba="0.03 0.035 0.035 1" />
        </material>
      </visual>
    <visual name="pop_pin_boss">
      <origin xyz="-0.28 -0.178 -0.02" rpy="1.5708 0 0" />
      <geometry>
        <cylinder radius="0.019" length="0.018" />
        </geometry>
      <material name="brushed_pin_metal">
        <color rgba="0.65 0.66 0.63 1" />
        </material>
      </visual>
    <collision name="back_pad">
      <origin xyz="-0.405 0 0.06" rpy="0 0 0" />
      <geometry>
        <mesh filename="assets/meshes/backrest_pad_mesh.obj" />
        </geometry>
      </collision>
    <collision name="back_seam_0">
      <origin xyz="-0.405 0.118 0.0995" rpy="0 0 0" />
      <geometry>
        <box size="0.7 0.014 0.008" />
        </geometry>
      </collision>
    <collision name="back_seam_1">
      <origin xyz="-0.405 -0.118 0.0995" rpy="0 0 0" />
      <geometry>
        <box size="0.7 0.014 0.008" />
        </geometry>
      </collision>
    <collision name="back_under_rail_0">
      <origin xyz="-0.385 -0.105 0.012" rpy="0 1.5708 0" />
      <geometry>
        <cylinder radius="0.014" length="0.72" />
        </geometry>
      </collision>
    <collision name="back_under_rail_1">
      <origin xyz="-0.385 0.105 0.012" rpy="0 1.5708 0" />
      <geometry>
        <cylinder radius="0.014" length="0.72" />
        </geometry>
      </collision>
    <collision name="back_cross_bracket">
      <origin xyz="-0.52 0 0.012" rpy="0 1.5708 1.5708" />
      <geometry>
        <cylinder radius="0.012" length="0.25" />
        </geometry>
      </collision>
    <collision name="back_hinge_sleeve">
      <origin xyz="0 0 0" rpy="0 1.5708 1.5708" />
      <geometry>
        <cylinder radius="0.018" length="0.41" />
        </geometry>
      </collision>
    <collision name="back_hinge_tab_0">
      <origin xyz="-0.026 -0.105 0.025" rpy="0 0 0" />
      <geometry>
        <box size="0.036 0.034 0.02" />
        </geometry>
      </collision>
    <collision name="back_hinge_tab_1">
      <origin xyz="-0.026 0.105 0.025" rpy="0 0 0" />
      <geometry>
        <box size="0.036 0.034 0.02" />
        </geometry>
      </collision>
    <collision name="pop_pin_plate">
      <origin xyz="-0.28 -0.168 -0.02" rpy="0 0 0" />
      <geometry>
        <box size="0.28 0.014 0.055" />
        </geometry>
      </collision>
    <collision name="pop_pin_standoff">
      <origin xyz="-0.28 -0.1365 -0.01" rpy="0 1.5708 -1.5708" />
      <geometry>
        <cylinder radius="0.01" length="0.063" />
        </geometry>
      </collision>
    <collision name="pop_pin_boss">
      <origin xyz="-0.28 -0.178 -0.02" rpy="1.5708 0 0" />
      <geometry>
        <cylinder radius="0.019" length="0.018" />
        </geometry>
      </collision>
    </link>
  <link name="seat_pad">
    <visual name="seat_cushion">
      <origin xyz="0.245 0 0.058" rpy="0 0 0" />
      <geometry>
        <mesh filename="assets/meshes/seat_pad_mesh.obj" />
        </geometry>
      <material name="black_grained_vinyl">
        <color rgba="0.02 0.022 0.024 1" />
        </material>
      </visual>
    <visual name="seat_seam_0">
      <origin xyz="0.255 0.118 0.0995" rpy="0 0 0" />
      <geometry>
        <box size="0.37 0.014 0.008" />
        </geometry>
      <material name="slightly_gloss_seam">
        <color rgba="0 0 0 1" />
        </material>
      </visual>
    <visual name="seat_seam_1">
      <origin xyz="0.255 -0.118 0.0995" rpy="0 0 0" />
      <geometry>
        <box size="0.37 0.014 0.008" />
        </geometry>
      <material name="slightly_gloss_seam">
        <color rgba="0 0 0 1" />
        </material>
      </visual>
    <visual name="seat_under_rail_0">
      <origin xyz="0.23 -0.1 0.012" rpy="0 1.5708 0" />
      <geometry>
        <cylinder radius="0.014" length="0.41" />
        </geometry>
      <material name="satin_black_steel">
        <color rgba="0.03 0.035 0.035 1" />
        </material>
      </visual>
    <visual name="seat_under_rail_1">
      <origin xyz="0.23 0.1 0.012" rpy="0 1.5708 0" />
      <geometry>
        <cylinder radius="0.014" length="0.41" />
        </geometry>
      <material name="satin_black_steel">
        <color rgba="0.03 0.035 0.035 1" />
        </material>
      </visual>
    <visual name="seat_cross_bracket">
      <origin xyz="0.25 0 0.012" rpy="0 1.5708 1.5708" />
      <geometry>
        <cylinder radius="0.012" length="0.24" />
        </geometry>
      <material name="satin_black_steel">
        <color rgba="0.03 0.035 0.035 1" />
        </material>
      </visual>
    <visual name="seat_hinge_sleeve">
      <origin xyz="0 0 0" rpy="0 1.5708 1.5708" />
      <geometry>
        <cylinder radius="0.017" length="0.37" />
        </geometry>
      <material name="satin_black_steel">
        <color rgba="0.03 0.035 0.035 1" />
        </material>
      </visual>
    <visual name="seat_hinge_tab_0">
      <origin xyz="0.02 -0.1 0.022" rpy="0 0 0" />
      <geometry>
        <box size="0.04 0.032 0.02" />
        </geometry>
      <material name="satin_black_steel">
        <color rgba="0.03 0.035 0.035 1" />
        </material>
      </visual>
    <visual name="seat_hinge_tab_1">
      <origin xyz="0.02 0.1 0.022" rpy="0 0 0" />
      <geometry>
        <box size="0.04 0.032 0.02" />
        </geometry>
      <material name="satin_black_steel">
        <color rgba="0.03 0.035 0.035 1" />
        </material>
      </visual>
    <collision name="seat_cushion">
      <origin xyz="0.245 0 0.058" rpy="0 0 0" />
      <geometry>
        <mesh filename="assets/meshes/seat_pad_mesh.obj" />
        </geometry>
      </collision>
    <collision name="seat_seam_0">
      <origin xyz="0.255 0.118 0.0995" rpy="0 0 0" />
      <geometry>
        <box size="0.37 0.014 0.008" />
        </geometry>
      </collision>
    <collision name="seat_seam_1">
      <origin xyz="0.255 -0.118 0.0995" rpy="0 0 0" />
      <geometry>
        <box size="0.37 0.014 0.008" />
        </geometry>
      </collision>
    <collision name="seat_under_rail_0">
      <origin xyz="0.23 -0.1 0.012" rpy="0 1.5708 0" />
      <geometry>
        <cylinder radius="0.014" length="0.41" />
        </geometry>
      </collision>
    <collision name="seat_under_rail_1">
      <origin xyz="0.23 0.1 0.012" rpy="0 1.5708 0" />
      <geometry>
        <cylinder radius="0.014" length="0.41" />
        </geometry>
      </collision>
    <collision name="seat_cross_bracket">
      <origin xyz="0.25 0 0.012" rpy="0 1.5708 1.5708" />
      <geometry>
        <cylinder radius="0.012" length="0.24" />
        </geometry>
      </collision>
    <collision name="seat_hinge_sleeve">
      <origin xyz="0 0 0" rpy="0 1.5708 1.5708" />
      <geometry>
        <cylinder radius="0.017" length="0.37" />
        </geometry>
      </collision>
    <collision name="seat_hinge_tab_0">
      <origin xyz="0.02 -0.1 0.022" rpy="0 0 0" />
      <geometry>
        <box size="0.04 0.032 0.02" />
        </geometry>
      </collision>
    <collision name="seat_hinge_tab_1">
      <origin xyz="0.02 0.1 0.022" rpy="0 0 0" />
      <geometry>
        <box size="0.04 0.032 0.02" />
        </geometry>
      </collision>
    </link>
  <link name="rear_support">
    <visual name="lower_bushing">
      <origin xyz="0 0 0" rpy="0 1.5708 1.5708" />
      <geometry>
        <cylinder radius="0.018" length="0.23" />
        </geometry>
      <material name="satin_black_steel">
        <color rgba="0.03 0.035 0.035 1" />
        </material>
      </visual>
    <visual name="lower_link_tab_0">
      <origin xyz="0.02 -0.075 0.02" rpy="0 0 0" />
      <geometry>
        <box size="0.032 0.02 0.018" />
        </geometry>
      <material name="satin_black_steel">
        <color rgba="0.03 0.035 0.035 1" />
        </material>
      </visual>
    <visual name="side_link_0">
      <origin xyz="0.1315 -0.075 0.1315" rpy="0 0.785398 0" />
      <geometry>
        <cylinder radius="0.013" length="0.321026" />
        </geometry>
      <material name="satin_black_steel">
        <color rgba="0.03 0.035 0.035 1" />
        </material>
      </visual>
    <visual name="lower_link_tab_1">
      <origin xyz="0.02 0.075 0.02" rpy="0 0 0" />
      <geometry>
        <box size="0.032 0.02 0.018" />
        </geometry>
      <material name="satin_black_steel">
        <color rgba="0.03 0.035 0.035 1" />
        </material>
      </visual>
    <visual name="side_link_1">
      <origin xyz="0.1315 0.075 0.1315" rpy="0 0.785398 0" />
      <geometry>
        <cylinder radius="0.013" length="0.321026" />
        </geometry>
      <material name="satin_black_steel">
        <color rgba="0.03 0.035 0.035 1" />
        </material>
      </visual>
    <visual name="upper_roller">
      <origin xyz="0.245 0 0.245" rpy="0 1.5708 1.5708" />
      <geometry>
        <cylinder radius="0.017" length="0.21" />
        </geometry>
      <material name="brushed_pin_metal">
        <color rgba="0.65 0.66 0.63 1" />
        </material>
      </visual>
    <collision name="lower_bushing">
      <origin xyz="0 0 0" rpy="0 1.5708 1.5708" />
      <geometry>
        <cylinder radius="0.018" length="0.23" />
        </geometry>
      </collision>
    <collision name="lower_link_tab_0">
      <origin xyz="0.02 -0.075 0.02" rpy="0 0 0" />
      <geometry>
        <box size="0.032 0.02 0.018" />
        </geometry>
      </collision>
    <collision name="side_link_0">
      <origin xyz="0.1315 -0.075 0.1315" rpy="0 0.785398 0" />
      <geometry>
        <cylinder radius="0.013" length="0.321026" />
        </geometry>
      </collision>
    <collision name="lower_link_tab_1">
      <origin xyz="0.02 0.075 0.02" rpy="0 0 0" />
      <geometry>
        <box size="0.032 0.02 0.018" />
        </geometry>
      </collision>
    <collision name="side_link_1">
      <origin xyz="0.1315 0.075 0.1315" rpy="0 0.785398 0" />
      <geometry>
        <cylinder radius="0.013" length="0.321026" />
        </geometry>
      </collision>
    <collision name="upper_roller">
      <origin xyz="0.245 0 0.245" rpy="0 1.5708 1.5708" />
      <geometry>
        <cylinder radius="0.017" length="0.21" />
        </geometry>
      </collision>
    </link>
  <link name="front_wheel_0">
    <visual name="tire">
      <origin xyz="0 0 0" rpy="0 0 1.5708" />
      <geometry>
        <mesh filename="assets/meshes/front_transport_tire.obj" />
        </geometry>
      <material name="matte_black_rubber">
        <color rgba="0.005 0.005 0.004 1" />
        </material>
      </visual>
    <visual name="rim">
      <origin xyz="0 0 0" rpy="0 0 1.5708" />
      <geometry>
        <mesh filename="assets/meshes/front_transport_wheel.obj" />
        </geometry>
      <material name="brushed_pin_metal">
        <color rgba="0.65 0.66 0.63 1" />
        </material>
      </visual>
    <visual name="axle_bushing">
      <origin xyz="0 0 0" rpy="1.5708 0 0" />
      <geometry>
        <cylinder radius="0.013" length="0.052" />
        </geometry>
      <material name="brushed_pin_metal">
        <color rgba="0.65 0.66 0.63 1" />
        </material>
      </visual>
    <collision name="tire">
      <origin xyz="0 0 0" rpy="0 0 1.5708" />
      <geometry>
        <mesh filename="assets/meshes/front_transport_tire.obj" />
        </geometry>
      </collision>
    <collision name="rim">
      <origin xyz="0 0 0" rpy="0 0 1.5708" />
      <geometry>
        <mesh filename="assets/meshes/front_transport_wheel.obj" />
        </geometry>
      </collision>
    <collision name="axle_bushing">
      <origin xyz="0 0 0" rpy="1.5708 0 0" />
      <geometry>
        <cylinder radius="0.013" length="0.052" />
        </geometry>
      </collision>
    </link>
  <link name="front_wheel_1">
    <visual name="tire">
      <origin xyz="0 0 0" rpy="0 0 1.5708" />
      <geometry>
        <mesh filename="assets/meshes/front_transport_tire.obj" />
        </geometry>
      <material name="matte_black_rubber">
        <color rgba="0.005 0.005 0.004 1" />
        </material>
      </visual>
    <visual name="rim">
      <origin xyz="0 0 0" rpy="0 0 1.5708" />
      <geometry>
        <mesh filename="assets/meshes/front_transport_wheel.obj" />
        </geometry>
      <material name="brushed_pin_metal">
        <color rgba="0.65 0.66 0.63 1" />
        </material>
      </visual>
    <visual name="axle_bushing">
      <origin xyz="0 0 0" rpy="1.5708 0 0" />
      <geometry>
        <cylinder radius="0.013" length="0.052" />
        </geometry>
      <material name="brushed_pin_metal">
        <color rgba="0.65 0.66 0.63 1" />
        </material>
      </visual>
    <collision name="tire">
      <origin xyz="0 0 0" rpy="0 0 1.5708" />
      <geometry>
        <mesh filename="assets/meshes/front_transport_tire.obj" />
        </geometry>
      </collision>
    <collision name="rim">
      <origin xyz="0 0 0" rpy="0 0 1.5708" />
      <geometry>
        <mesh filename="assets/meshes/front_transport_wheel.obj" />
        </geometry>
      </collision>
    <collision name="axle_bushing">
      <origin xyz="0 0 0" rpy="1.5708 0 0" />
      <geometry>
        <cylinder radius="0.013" length="0.052" />
        </geometry>
      </collision>
    </link>
  <link name="pop_pin">
    <visual name="pin_shaft">
      <origin xyz="0 -0.026 0" rpy="1.5708 0 0" />
      <geometry>
        <cylinder radius="0.006" length="0.055" />
        </geometry>
      <material name="brushed_pin_metal">
        <color rgba="0.65 0.66 0.63 1" />
        </material>
      </visual>
    <visual name="knob_cap">
      <origin xyz="0 -0.066 0" rpy="1.5708 0 0" />
      <geometry>
        <mesh filename="assets/meshes/pop_pin_knob_mesh.obj" />
        </geometry>
      <material name="red_pop_pin_knob">
        <color rgba="0.85 0.04 0.025 1" />
        </material>
      </visual>
    <collision name="pin_shaft">
      <origin xyz="0 -0.026 0" rpy="1.5708 0 0" />
      <geometry>
        <cylinder radius="0.006" length="0.055" />
        </geometry>
      </collision>
    <collision name="knob_cap">
      <origin xyz="0 -0.066 0" rpy="1.5708 0 0" />
      <geometry>
        <mesh filename="assets/meshes/pop_pin_knob_mesh.obj" />
        </geometry>
      </collision>
    </link>
  <joint name="frame_to_wheel_0" type="continuous">
    <origin xyz="0.69 -0.285 0.085" rpy="0 0 0" />
    <parent link="center_frame" />
    <child link="front_wheel_0" />
    <axis xyz="0 1 0" />
    <limit effort="8" velocity="18" />
    </joint>
  <joint name="frame_to_wheel_1" type="continuous">
    <origin xyz="0.69 0.285 0.085" rpy="0 0 0" />
    <parent link="center_frame" />
    <child link="front_wheel_1" />
    <axis xyz="0 1 0" />
    <limit effort="8" velocity="18" />
    </joint>
  <joint name="frame_to_backrest" type="revolute">
    <origin xyz="-0.09 0 0.43" rpy="0 0 0" />
    <parent link="center_frame" />
    <child link="backrest" />
    <axis xyz="0 1 0" />
    <limit effort="90" velocity="1.4" lower="0" upper="1.2" />
    </joint>
  <joint name="frame_to_seat" type="revolute">
    <origin xyz="-0.035 0 0.43" rpy="0 0 0" />
    <parent link="center_frame" />
    <child link="seat_pad" />
    <axis xyz="0 -1 0" />
    <limit effort="50" velocity="1.2" lower="0" upper="0.45" />
    </joint>
  <joint name="frame_to_rear_support" type="revolute">
    <origin xyz="-0.64 0 0.13" rpy="0 0 0" />
    <parent link="center_frame" />
    <child link="rear_support" />
    <axis xyz="0 1 0" />
    <limit effort="45" velocity="1.1" lower="-0.3" upper="0.85" />
    </joint>
  <joint name="backrest_to_pop_pin" type="prismatic">
    <origin xyz="-0.28 -0.182 -0.02" rpy="0 0 0" />
    <parent link="backrest" />
    <child link="pop_pin" />
    <axis xyz="0 -1 0" />
    <limit effort="18" velocity="0.18" lower="0" upper="0.035" />
    </joint>
  </robot>
