<robot name="tripod_mounted_device">
  <material name="matte_black">
    <color rgba="0.015 0.015 0.018 1" />
    </material>
  <material name="dark_metal">
    <color rgba="0.06 0.065 0.07 1" />
    </material>
  <material name="satin_aluminum">
    <color rgba="0.68 0.7 0.7 1" />
    </material>
  <material name="black_rubber">
    <color rgba="0.005 0.005 0.004 1" />
    </material>
  <material name="plate_gray">
    <color rgba="0.12 0.125 0.13 1" />
    </material>
  <material name="screw_metal">
    <color rgba="0.85 0.82 0.72 1" />
    </material>
  <material name="lens_glass">
    <color rgba="0.05 0.09 0.12 1" />
    </material>
  <link name="crown">
    <visual name="center_hub">
      <origin xyz="0 0 0.9" rpy="0 0 0" />
      <geometry>
        <cylinder radius="0.055" length="0.08" />
        </geometry>
      <material name="dark_metal">
        <color rgba="0.06 0.065 0.07 1" />
        </material>
      </visual>
    <visual name="top_collar">
      <origin xyz="0 0 0.931" rpy="0 0 0" />
      <geometry>
        <cylinder radius="0.068" length="0.018" />
        </geometry>
      <material name="matte_black">
        <color rgba="0.015 0.015 0.018 1" />
        </material>
      </visual>
    <visual name="hinge_strut_0">
      <origin xyz="3.18408e-18 0.052 0.858" rpy="0 0 1.5708" />
      <geometry>
        <box size="0.105 0.03 0.024" />
        </geometry>
      <material name="dark_metal">
        <color rgba="0.06 0.065 0.07 1" />
        </material>
      </visual>
    <visual name="hinge_crossbar_0">
      <origin xyz="3.30655e-18 0.054 0.848" rpy="0 0 1.5708" />
      <geometry>
        <box size="0.052 0.108 0.018" />
        </geometry>
      <material name="dark_metal">
        <color rgba="0.06 0.065 0.07 1" />
        </material>
      </visual>
    <visual name="hinge_bridge_0_0">
      <origin xyz="0.043 0.097 0.858" rpy="0 0 1.5708" />
      <geometry>
        <box size="0.052 0.02 0.026" />
        </geometry>
      <material name="dark_metal">
        <color rgba="0.06 0.065 0.07 1" />
        </material>
      </visual>
    <visual name="hinge_cheek_0_0">
      <origin xyz="0.043 0.115 0.9" rpy="0 0 1.5708" />
      <geometry>
        <box size="0.04 0.016 0.075" />
        </geometry>
      <material name="dark_metal">
        <color rgba="0.06 0.065 0.07 1" />
        </material>
      </visual>
    <visual name="hinge_bridge_0_1">
      <origin xyz="-0.043 0.097 0.858" rpy="0 0 1.5708" />
      <geometry>
        <box size="0.052 0.02 0.026" />
        </geometry>
      <material name="dark_metal">
        <color rgba="0.06 0.065 0.07 1" />
        </material>
      </visual>
    <visual name="hinge_cheek_0_1">
      <origin xyz="-0.043 0.115 0.9" rpy="0 0 1.5708" />
      <geometry>
        <box size="0.04 0.016 0.075" />
        </geometry>
      <material name="dark_metal">
        <color rgba="0.06 0.065 0.07 1" />
        </material>
      </visual>
    <visual name="hinge_strut_1">
      <origin xyz="-0.0450333 -0.026 0.858" rpy="0 0 3.66519" />
      <geometry>
        <box size="0.105 0.03 0.024" />
        </geometry>
      <material name="dark_metal">
        <color rgba="0.06 0.065 0.07 1" />
        </material>
      </visual>
    <visual name="hinge_crossbar_1">
      <origin xyz="-0.0467654 -0.027 0.848" rpy="0 0 3.66519" />
      <geometry>
        <box size="0.052 0.108 0.018" />
        </geometry>
      <material name="dark_metal">
        <color rgba="0.06 0.065 0.07 1" />
        </material>
      </visual>
    <visual name="hinge_bridge_1_0">
      <origin xyz="-0.105504 -0.0112609 0.858" rpy="0 0 3.66519" />
      <geometry>
        <box size="0.052 0.02 0.026" />
        </geometry>
      <material name="dark_metal">
        <color rgba="0.06 0.065 0.07 1" />
        </material>
      </visual>
    <visual name="hinge_cheek_1_0">
      <origin xyz="-0.121093 -0.0202609 0.9" rpy="0 0 3.66519" />
      <geometry>
        <box size="0.04 0.016 0.075" />
        </geometry>
      <material name="dark_metal">
        <color rgba="0.06 0.065 0.07 1" />
        </material>
      </visual>
    <visual name="hinge_bridge_1_1">
      <origin xyz="-0.0625045 -0.0857391 0.858" rpy="0 0 3.66519" />
      <geometry>
        <box size="0.052 0.02 0.026" />
        </geometry>
      <material name="dark_metal">
        <color rgba="0.06 0.065 0.07 1" />
        </material>
      </visual>
    <visual name="hinge_cheek_1_1">
      <origin xyz="-0.0780929 -0.0947391 0.9" rpy="0 0 3.66519" />
      <geometry>
        <box size="0.04 0.016 0.075" />
        </geometry>
      <material name="dark_metal">
        <color rgba="0.06 0.065 0.07 1" />
        </material>
      </visual>
    <visual name="hinge_strut_2">
      <origin xyz="0.0450333 -0.026 0.858" rpy="0 0 5.75959" />
      <geometry>
        <box size="0.105 0.03 0.024" />
        </geometry>
      <material name="dark_metal">
        <color rgba="0.06 0.065 0.07 1" />
        </material>
      </visual>
    <visual name="hinge_crossbar_2">
      <origin xyz="0.0467654 -0.027 0.848" rpy="0 0 5.75959" />
      <geometry>
        <box size="0.052 0.108 0.018" />
        </geometry>
      <material name="dark_metal">
        <color rgba="0.06 0.065 0.07 1" />
        </material>
      </visual>
    <visual name="hinge_bridge_2_0">
      <origin xyz="0.0625045 -0.0857391 0.858" rpy="0 0 5.75959" />
      <geometry>
        <box size="0.052 0.02 0.026" />
        </geometry>
      <material name="dark_metal">
        <color rgba="0.06 0.065 0.07 1" />
        </material>
      </visual>
    <visual name="hinge_cheek_2_0">
      <origin xyz="0.0780929 -0.0947391 0.9" rpy="0 0 5.75959" />
      <geometry>
        <box size="0.04 0.016 0.075" />
        </geometry>
      <material name="dark_metal">
        <color rgba="0.06 0.065 0.07 1" />
        </material>
      </visual>
    <visual name="hinge_bridge_2_1">
      <origin xyz="0.105504 -0.0112609 0.858" rpy="0 0 5.75959" />
      <geometry>
        <box size="0.052 0.02 0.026" />
        </geometry>
      <material name="dark_metal">
        <color rgba="0.06 0.065 0.07 1" />
        </material>
      </visual>
    <visual name="hinge_cheek_2_1">
      <origin xyz="0.121093 -0.0202609 0.9" rpy="0 0 5.75959" />
      <geometry>
        <box size="0.04 0.016 0.075" />
        </geometry>
      <material name="dark_metal">
        <color rgba="0.06 0.065 0.07 1" />
        </material>
      </visual>
    <collision name="center_hub">
      <origin xyz="0 0 0.9" rpy="0 0 0" />
      <geometry>
        <cylinder radius="0.055" length="0.08" />
        </geometry>
      </collision>
    <collision name="top_collar">
      <origin xyz="0 0 0.931" rpy="0 0 0" />
      <geometry>
        <cylinder radius="0.068" length="0.018" />
        </geometry>
      </collision>
    <collision name="hinge_strut_0">
      <origin xyz="3.18408e-18 0.052 0.858" rpy="0 0 1.5708" />
      <geometry>
        <box size="0.105 0.03 0.024" />
        </geometry>
      </collision>
    <collision name="hinge_crossbar_0">
      <origin xyz="3.30655e-18 0.054 0.848" rpy="0 0 1.5708" />
      <geometry>
        <box size="0.052 0.108 0.018" />
        </geometry>
      </collision>
    <collision name="hinge_bridge_0_0">
      <origin xyz="0.043 0.097 0.858" rpy="0 0 1.5708" />
      <geometry>
        <box size="0.052 0.02 0.026" />
        </geometry>
      </collision>
    <collision name="hinge_cheek_0_0">
      <origin xyz="0.043 0.115 0.9" rpy="0 0 1.5708" />
      <geometry>
        <box size="0.04 0.016 0.075" />
        </geometry>
      </collision>
    <collision name="hinge_bridge_0_1">
      <origin xyz="-0.043 0.097 0.858" rpy="0 0 1.5708" />
      <geometry>
        <box size="0.052 0.02 0.026" />
        </geometry>
      </collision>
    <collision name="hinge_cheek_0_1">
      <origin xyz="-0.043 0.115 0.9" rpy="0 0 1.5708" />
      <geometry>
        <box size="0.04 0.016 0.075" />
        </geometry>
      </collision>
    <collision name="hinge_strut_1">
      <origin xyz="-0.0450333 -0.026 0.858" rpy="0 0 3.66519" />
      <geometry>
        <box size="0.105 0.03 0.024" />
        </geometry>
      </collision>
    <collision name="hinge_crossbar_1">
      <origin xyz="-0.0467654 -0.027 0.848" rpy="0 0 3.66519" />
      <geometry>
        <box size="0.052 0.108 0.018" />
        </geometry>
      </collision>
    <collision name="hinge_bridge_1_0">
      <origin xyz="-0.105504 -0.0112609 0.858" rpy="0 0 3.66519" />
      <geometry>
        <box size="0.052 0.02 0.026" />
        </geometry>
      </collision>
    <collision name="hinge_cheek_1_0">
      <origin xyz="-0.121093 -0.0202609 0.9" rpy="0 0 3.66519" />
      <geometry>
        <box size="0.04 0.016 0.075" />
        </geometry>
      </collision>
    <collision name="hinge_bridge_1_1">
      <origin xyz="-0.0625045 -0.0857391 0.858" rpy="0 0 3.66519" />
      <geometry>
        <box size="0.052 0.02 0.026" />
        </geometry>
      </collision>
    <collision name="hinge_cheek_1_1">
      <origin xyz="-0.0780929 -0.0947391 0.9" rpy="0 0 3.66519" />
      <geometry>
        <box size="0.04 0.016 0.075" />
        </geometry>
      </collision>
    <collision name="hinge_strut_2">
      <origin xyz="0.0450333 -0.026 0.858" rpy="0 0 5.75959" />
      <geometry>
        <box size="0.105 0.03 0.024" />
        </geometry>
      </collision>
    <collision name="hinge_crossbar_2">
      <origin xyz="0.0467654 -0.027 0.848" rpy="0 0 5.75959" />
      <geometry>
        <box size="0.052 0.108 0.018" />
        </geometry>
      </collision>
    <collision name="hinge_bridge_2_0">
      <origin xyz="0.0625045 -0.0857391 0.858" rpy="0 0 5.75959" />
      <geometry>
        <box size="0.052 0.02 0.026" />
        </geometry>
      </collision>
    <collision name="hinge_cheek_2_0">
      <origin xyz="0.0780929 -0.0947391 0.9" rpy="0 0 5.75959" />
      <geometry>
        <box size="0.04 0.016 0.075" />
        </geometry>
      </collision>
    <collision name="hinge_bridge_2_1">
      <origin xyz="0.105504 -0.0112609 0.858" rpy="0 0 5.75959" />
      <geometry>
        <box size="0.052 0.02 0.026" />
        </geometry>
      </collision>
    <collision name="hinge_cheek_2_1">
      <origin xyz="0.121093 -0.0202609 0.9" rpy="0 0 5.75959" />
      <geometry>
        <box size="0.04 0.016 0.075" />
        </geometry>
      </collision>
    </link>
  <link name="leg_0">
    <visual name="hinge_barrel">
      <origin xyz="0 0 0" rpy="-1.5708 0 0" />
      <geometry>
        <cylinder radius="0.021" length="0.07" />
        </geometry>
      <material name="dark_metal">
        <color rgba="0.06 0.065 0.07 1" />
        </material>
      </visual>
    <visual name="leg_knuckle">
      <origin xyz="0.018 0 -0.016" rpy="0 0 0" />
      <geometry>
        <sphere radius="0.024" />
        </geometry>
      <material name="dark_metal">
        <color rgba="0.06 0.065 0.07 1" />
        </material>
      </visual>
    <visual name="upper_tube">
      <origin xyz="0.1515 0 -0.2355" rpy="0 2.59517 0" />
      <geometry>
        <cylinder radius="0.017" length="0.513819" />
        </geometry>
      <material name="matte_black">
        <color rgba="0.015 0.015 0.018 1" />
        </material>
      </visual>
    <visual name="lower_tube">
      <origin xyz="0.39 0 -0.63" rpy="0 2.5948 0" />
      <geometry>
        <cylinder radius="0.013" length="0.538516" />
        </geometry>
      <material name="satin_aluminum">
        <color rgba="0.68 0.7 0.7 1" />
        </material>
      </visual>
    <visual name="rubber_foot">
      <origin xyz="0.53 0 -0.86" rpy="0 0 0" />
      <geometry>
        <sphere radius="0.026" />
        </geometry>
      <material name="black_rubber">
        <color rgba="0.005 0.005 0.004 1" />
        </material>
      </visual>
    <collision name="hinge_barrel">
      <origin xyz="0 0 0" rpy="-1.5708 0 0" />
      <geometry>
        <cylinder radius="0.021" length="0.07" />
        </geometry>
      </collision>
    <collision name="leg_knuckle">
      <origin xyz="0.018 0 -0.016" rpy="0 0 0" />
      <geometry>
        <sphere radius="0.024" />
        </geometry>
      </collision>
    <collision name="upper_tube">
      <origin xyz="0.1515 0 -0.2355" rpy="0 2.59517 0" />
      <geometry>
        <cylinder radius="0.017" length="0.513819" />
        </geometry>
      </collision>
    <collision name="lower_tube">
      <origin xyz="0.39 0 -0.63" rpy="0 2.5948 0" />
      <geometry>
        <cylinder radius="0.013" length="0.538516" />
        </geometry>
      </collision>
    <collision name="rubber_foot">
      <origin xyz="0.53 0 -0.86" rpy="0 0 0" />
      <geometry>
        <sphere radius="0.026" />
        </geometry>
      </collision>
    </link>
  <link name="leg_1">
    <visual name="hinge_barrel">
      <origin xyz="0 0 0" rpy="-1.5708 0 0" />
      <geometry>
        <cylinder radius="0.021" length="0.07" />
        </geometry>
      <material name="dark_metal">
        <color rgba="0.06 0.065 0.07 1" />
        </material>
      </visual>
    <visual name="leg_knuckle">
      <origin xyz="0.018 0 -0.016" rpy="0 0 0" />
      <geometry>
        <sphere radius="0.024" />
        </geometry>
      <material name="dark_metal">
        <color rgba="0.06 0.065 0.07 1" />
        </material>
      </visual>
    <visual name="upper_tube">
      <origin xyz="0.1515 0 -0.2355" rpy="0 2.59517 0" />
      <geometry>
        <cylinder radius="0.017" length="0.513819" />
        </geometry>
      <material name="matte_black">
        <color rgba="0.015 0.015 0.018 1" />
        </material>
      </visual>
    <visual name="lower_tube">
      <origin xyz="0.39 0 -0.63" rpy="0 2.5948 0" />
      <geometry>
        <cylinder radius="0.013" length="0.538516" />
        </geometry>
      <material name="satin_aluminum">
        <color rgba="0.68 0.7 0.7 1" />
        </material>
      </visual>
    <visual name="rubber_foot">
      <origin xyz="0.53 0 -0.86" rpy="0 0 0" />
      <geometry>
        <sphere radius="0.026" />
        </geometry>
      <material name="black_rubber">
        <color rgba="0.005 0.005 0.004 1" />
        </material>
      </visual>
    <collision name="hinge_barrel">
      <origin xyz="0 0 0" rpy="-1.5708 0 0" />
      <geometry>
        <cylinder radius="0.021" length="0.07" />
        </geometry>
      </collision>
    <collision name="leg_knuckle">
      <origin xyz="0.018 0 -0.016" rpy="0 0 0" />
      <geometry>
        <sphere radius="0.024" />
        </geometry>
      </collision>
    <collision name="upper_tube">
      <origin xyz="0.1515 0 -0.2355" rpy="0 2.59517 0" />
      <geometry>
        <cylinder radius="0.017" length="0.513819" />
        </geometry>
      </collision>
    <collision name="lower_tube">
      <origin xyz="0.39 0 -0.63" rpy="0 2.5948 0" />
      <geometry>
        <cylinder radius="0.013" length="0.538516" />
        </geometry>
      </collision>
    <collision name="rubber_foot">
      <origin xyz="0.53 0 -0.86" rpy="0 0 0" />
      <geometry>
        <sphere radius="0.026" />
        </geometry>
      </collision>
    </link>
  <link name="leg_2">
    <visual name="hinge_barrel">
      <origin xyz="0 0 0" rpy="-1.5708 0 0" />
      <geometry>
        <cylinder radius="0.021" length="0.07" />
        </geometry>
      <material name="dark_metal">
        <color rgba="0.06 0.065 0.07 1" />
        </material>
      </visual>
    <visual name="leg_knuckle">
      <origin xyz="0.018 0 -0.016" rpy="0 0 0" />
      <geometry>
        <sphere radius="0.024" />
        </geometry>
      <material name="dark_metal">
        <color rgba="0.06 0.065 0.07 1" />
        </material>
      </visual>
    <visual name="upper_tube">
      <origin xyz="0.1515 0 -0.2355" rpy="0 2.59517 0" />
      <geometry>
        <cylinder radius="0.017" length="0.513819" />
        </geometry>
      <material name="matte_black">
        <color rgba="0.015 0.015 0.018 1" />
        </material>
      </visual>
    <visual name="lower_tube">
      <origin xyz="0.39 0 -0.63" rpy="0 2.5948 0" />
      <geometry>
        <cylinder radius="0.013" length="0.538516" />
        </geometry>
      <material name="satin_aluminum">
        <color rgba="0.68 0.7 0.7 1" />
        </material>
      </visual>
    <visual name="rubber_foot">
      <origin xyz="0.53 0 -0.86" rpy="0 0 0" />
      <geometry>
        <sphere radius="0.026" />
        </geometry>
      <material name="black_rubber">
        <color rgba="0.005 0.005 0.004 1" />
        </material>
      </visual>
    <collision name="hinge_barrel">
      <origin xyz="0 0 0" rpy="-1.5708 0 0" />
      <geometry>
        <cylinder radius="0.021" length="0.07" />
        </geometry>
      </collision>
    <collision name="leg_knuckle">
      <origin xyz="0.018 0 -0.016" rpy="0 0 0" />
      <geometry>
        <sphere radius="0.024" />
        </geometry>
      </collision>
    <collision name="upper_tube">
      <origin xyz="0.1515 0 -0.2355" rpy="0 2.59517 0" />
      <geometry>
        <cylinder radius="0.017" length="0.513819" />
        </geometry>
      </collision>
    <collision name="lower_tube">
      <origin xyz="0.39 0 -0.63" rpy="0 2.5948 0" />
      <geometry>
        <cylinder radius="0.013" length="0.538516" />
        </geometry>
      </collision>
    <collision name="rubber_foot">
      <origin xyz="0.53 0 -0.86" rpy="0 0 0" />
      <geometry>
        <sphere radius="0.026" />
        </geometry>
      </collision>
    </link>
  <link name="head">
    <visual name="pan_disk">
      <origin xyz="0 0 0.0175" rpy="0 0 0" />
      <geometry>
        <cylinder radius="0.062" length="0.035" />
        </geometry>
      <material name="matte_black">
        <color rgba="0.015 0.015 0.018 1" />
        </material>
      </visual>
    <visual name="short_neck">
      <origin xyz="0 0 0.0625" rpy="0 0 0" />
      <geometry>
        <cylinder radius="0.032" length="0.055" />
        </geometry>
      <material name="dark_metal">
        <color rgba="0.06 0.065 0.07 1" />
        </material>
      </visual>
    <visual name="yoke_base">
      <origin xyz="0 0 0.095" rpy="0 0 0" />
      <geometry>
        <box size="0.07 0.13 0.018" />
        </geometry>
      <material name="dark_metal">
        <color rgba="0.06 0.065 0.07 1" />
        </material>
      </visual>
    <visual name="yoke_arm_0">
      <origin xyz="0 -0.061 0.135" rpy="0 0 0" />
      <geometry>
        <box size="0.04 0.014 0.085" />
        </geometry>
      <material name="dark_metal">
        <color rgba="0.06 0.065 0.07 1" />
        </material>
      </visual>
    <visual name="yoke_arm_1">
      <origin xyz="0 0.061 0.135" rpy="0 0 0" />
      <geometry>
        <box size="0.04 0.014 0.085" />
        </geometry>
      <material name="dark_metal">
        <color rgba="0.06 0.065 0.07 1" />
        </material>
      </visual>
    <collision name="pan_disk">
      <origin xyz="0 0 0.0175" rpy="0 0 0" />
      <geometry>
        <cylinder radius="0.062" length="0.035" />
        </geometry>
      </collision>
    <collision name="short_neck">
      <origin xyz="0 0 0.0625" rpy="0 0 0" />
      <geometry>
        <cylinder radius="0.032" length="0.055" />
        </geometry>
      </collision>
    <collision name="yoke_base">
      <origin xyz="0 0 0.095" rpy="0 0 0" />
      <geometry>
        <box size="0.07 0.13 0.018" />
        </geometry>
      </collision>
    <collision name="yoke_arm_0">
      <origin xyz="0 -0.061 0.135" rpy="0 0 0" />
      <geometry>
        <box size="0.04 0.014 0.085" />
        </geometry>
      </collision>
    <collision name="yoke_arm_1">
      <origin xyz="0 0.061 0.135" rpy="0 0 0" />
      <geometry>
        <box size="0.04 0.014 0.085" />
        </geometry>
      </collision>
    </link>
  <link name="device_plate">
    <visual name="tilt_axle">
      <origin xyz="0 0 0" rpy="-1.5708 0 0" />
      <geometry>
        <cylinder radius="0.01" length="0.108" />
        </geometry>
      <material name="screw_metal">
        <color rgba="0.85 0.82 0.72 1" />
        </material>
      </visual>
    <visual name="tilt_boss">
      <origin xyz="0 0 0.011" rpy="0 0 0" />
      <geometry>
        <box size="0.035 0.035 0.03" />
        </geometry>
      <material name="plate_gray">
        <color rgba="0.12 0.125 0.13 1" />
        </material>
      </visual>
    <visual name="mounting_plate">
      <origin xyz="0 0 0.026" rpy="0 0 0" />
      <geometry>
        <box size="0.17 0.096 0.012" />
        </geometry>
      <material name="plate_gray">
        <color rgba="0.12 0.125 0.13 1" />
        </material>
      </visual>
    <visual name="grip_pad_0">
      <origin xyz="-0.045 0 0.035" rpy="0 0 0" />
      <geometry>
        <box size="0.045 0.01 0.006" />
        </geometry>
      <material name="black_rubber">
        <color rgba="0.005 0.005 0.004 1" />
        </material>
      </visual>
    <visual name="grip_pad_1">
      <origin xyz="0.045 0 0.035" rpy="0 0 0" />
      <geometry>
        <box size="0.045 0.01 0.006" />
        </geometry>
      <material name="black_rubber">
        <color rgba="0.005 0.005 0.004 1" />
        </material>
      </visual>
    <visual name="mounting_screw">
      <origin xyz="0 0 0.039" rpy="0 0 0" />
      <geometry>
        <cylinder radius="0.008" length="0.014" />
        </geometry>
      <material name="screw_metal">
        <color rgba="0.85 0.82 0.72 1" />
        </material>
      </visual>
    <visual name="device_body">
      <origin xyz="0 0 0.058" rpy="0 0 0" />
      <geometry>
        <box size="0.12 0.07 0.052" />
        </geometry>
      <material name="matte_black">
        <color rgba="0.015 0.015 0.018 1" />
        </material>
      </visual>
    <visual name="device_lens">
      <origin xyz="0.074 0 0.058" rpy="0 1.5708 0" />
      <geometry>
        <cylinder radius="0.022" length="0.028" />
        </geometry>
      <material name="lens_glass">
        <color rgba="0.05 0.09 0.12 1" />
        </material>
      </visual>
    <collision name="tilt_axle">
      <origin xyz="0 0 0" rpy="-1.5708 0 0" />
      <geometry>
        <cylinder radius="0.01" length="0.108" />
        </geometry>
      </collision>
    <collision name="tilt_boss">
      <origin xyz="0 0 0.011" rpy="0 0 0" />
      <geometry>
        <box size="0.035 0.035 0.03" />
        </geometry>
      </collision>
    <collision name="mounting_plate">
      <origin xyz="0 0 0.026" rpy="0 0 0" />
      <geometry>
        <box size="0.17 0.096 0.012" />
        </geometry>
      </collision>
    <collision name="grip_pad_0">
      <origin xyz="-0.045 0 0.035" rpy="0 0 0" />
      <geometry>
        <box size="0.045 0.01 0.006" />
        </geometry>
      </collision>
    <collision name="grip_pad_1">
      <origin xyz="0.045 0 0.035" rpy="0 0 0" />
      <geometry>
        <box size="0.045 0.01 0.006" />
        </geometry>
      </collision>
    <collision name="mounting_screw">
      <origin xyz="0 0 0.039" rpy="0 0 0" />
      <geometry>
        <cylinder radius="0.008" length="0.014" />
        </geometry>
      </collision>
    <collision name="device_body">
      <origin xyz="0 0 0.058" rpy="0 0 0" />
      <geometry>
        <box size="0.12 0.07 0.052" />
        </geometry>
      </collision>
    <collision name="device_lens">
      <origin xyz="0.074 0 0.058" rpy="0 1.5708 0" />
      <geometry>
        <cylinder radius="0.022" length="0.028" />
        </geometry>
      </collision>
    </link>
  <joint name="crown_to_leg_0" type="revolute">
    <origin xyz="7.04172e-18 0.115 0.9" rpy="0 0 1.5708" />
    <parent link="crown" />
    <child link="leg_0" />
    <axis xyz="0 -1 0" />
    <limit effort="35" velocity="1.5" lower="0" upper="1.2" />
    </joint>
  <joint name="crown_to_leg_1" type="revolute">
    <origin xyz="-0.0995929 -0.0575 0.9" rpy="0 0 3.66519" />
    <parent link="crown" />
    <child link="leg_1" />
    <axis xyz="0 -1 0" />
    <limit effort="35" velocity="1.5" lower="0" upper="1.2" />
    </joint>
  <joint name="crown_to_leg_2" type="revolute">
    <origin xyz="0.0995929 -0.0575 0.9" rpy="0 0 5.75959" />
    <parent link="crown" />
    <child link="leg_2" />
    <axis xyz="0 -1 0" />
    <limit effort="35" velocity="1.5" lower="0" upper="1.2" />
    </joint>
  <joint name="crown_to_head" type="continuous">
    <origin xyz="0 0 0.94" rpy="0 0 0" />
    <parent link="crown" />
    <child link="head" />
    <axis xyz="0 0 1" />
    <limit effort="10" velocity="2" />
    </joint>
  <joint name="head_to_device_plate" type="revolute">
    <origin xyz="0 0 0.145" rpy="0 0 0" />
    <parent link="head" />
    <child link="device_plate" />
    <axis xyz="0 1 0" />
    <limit effort="6" velocity="1.5" lower="-0.75" upper="0.75" />
    </joint>
  </robot>
