<robot name="under_slung_elbow_arm">
  <link name="top_support">
    <visual name="ceiling_plate">
      <origin xyz="0 0 0.195" rpy="0 0 0" />
      <geometry>
        <box size="0.42 0.32 0.04" />
        </geometry>
      <material name="matte_graphite">
        <color rgba="0.1 0.11 0.12 1" />
        </material>
      </visual>
    <visual name="motor_can">
      <origin xyz="0 0 0.116" rpy="0 0 0" />
      <geometry>
        <cylinder radius="0.13" length="0.122" />
        </geometry>
      <material name="matte_graphite">
        <color rgba="0.1 0.11 0.12 1" />
        </material>
      </visual>
    <visual name="lower_bearing">
      <origin xyz="0 0 0.029" rpy="0 0 0" />
      <geometry>
        <cylinder radius="0.105" length="0.058" />
        </geometry>
      <material name="brushed_steel">
        <color rgba="0.64 0.65 0.62 1" />
        </material>
      </visual>
    <visual name="mount_bolt_0">
      <origin xyz="-0.155 -0.115 0.224" rpy="0 0 0" />
      <geometry>
        <cylinder radius="0.018" length="0.02" />
        </geometry>
      <material name="dark_socket_bolts">
        <color rgba="0.03 0.03 0.035 1" />
        </material>
      </visual>
    <visual name="mount_bolt_1">
      <origin xyz="-0.155 0.115 0.224" rpy="0 0 0" />
      <geometry>
        <cylinder radius="0.018" length="0.02" />
        </geometry>
      <material name="dark_socket_bolts">
        <color rgba="0.03 0.03 0.035 1" />
        </material>
      </visual>
    <visual name="mount_bolt_2">
      <origin xyz="0.155 -0.115 0.224" rpy="0 0 0" />
      <geometry>
        <cylinder radius="0.018" length="0.02" />
        </geometry>
      <material name="dark_socket_bolts">
        <color rgba="0.03 0.03 0.035 1" />
        </material>
      </visual>
    <visual name="mount_bolt_3">
      <origin xyz="0.155 0.115 0.224" rpy="0 0 0" />
      <geometry>
        <cylinder radius="0.018" length="0.02" />
        </geometry>
      <material name="dark_socket_bolts">
        <color rgba="0.03 0.03 0.035 1" />
        </material>
      </visual>
    <collision name="ceiling_plate">
      <origin xyz="0 0 0.195" rpy="0 0 0" />
      <geometry>
        <box size="0.42 0.32 0.04" />
        </geometry>
      </collision>
    <collision name="motor_can">
      <origin xyz="0 0 0.116" rpy="0 0 0" />
      <geometry>
        <cylinder radius="0.13" length="0.122" />
        </geometry>
      </collision>
    <collision name="lower_bearing">
      <origin xyz="0 0 0.029" rpy="0 0 0" />
      <geometry>
        <cylinder radius="0.105" length="0.058" />
        </geometry>
      </collision>
    <collision name="mount_bolt_0">
      <origin xyz="-0.155 -0.115 0.224" rpy="0 0 0" />
      <geometry>
        <cylinder radius="0.018" length="0.02" />
        </geometry>
      </collision>
    <collision name="mount_bolt_1">
      <origin xyz="-0.155 0.115 0.224" rpy="0 0 0" />
      <geometry>
        <cylinder radius="0.018" length="0.02" />
        </geometry>
      </collision>
    <collision name="mount_bolt_2">
      <origin xyz="0.155 -0.115 0.224" rpy="0 0 0" />
      <geometry>
        <cylinder radius="0.018" length="0.02" />
        </geometry>
      </collision>
    <collision name="mount_bolt_3">
      <origin xyz="0.155 0.115 0.224" rpy="0 0 0" />
      <geometry>
        <cylinder radius="0.018" length="0.02" />
        </geometry>
      </collision>
    </link>
  <link name="upper_arm">
    <visual name="shoulder_hub">
      <origin xyz="0 0 -0.036" rpy="0 0 0" />
      <geometry>
        <cylinder radius="0.088" length="0.072" />
        </geometry>
      <material name="brushed_steel">
        <color rgba="0.64 0.65 0.62 1" />
        </material>
      </visual>
    <visual name="upper_beam">
      <origin xyz="0.23 0 -0.05" rpy="0 0 0" />
      <geometry>
        <box size="0.46 0.106 0.05" />
        </geometry>
      <material name="powder_coated_blue">
        <color rgba="0.05 0.22 0.48 1" />
        </material>
      </visual>
    <visual name="upper_side_rail_0">
      <origin xyz="0.23 0.052 -0.05" rpy="0 0 0" />
      <geometry>
        <box size="0.33 0.028 0.056" />
        </geometry>
      <material name="matte_graphite">
        <color rgba="0.1 0.11 0.12 1" />
        </material>
      </visual>
    <visual name="upper_side_rail_1">
      <origin xyz="0.23 -0.052 -0.05" rpy="0 0 0" />
      <geometry>
        <box size="0.33 0.028 0.056" />
        </geometry>
      <material name="matte_graphite">
        <color rgba="0.1 0.11 0.12 1" />
        </material>
      </visual>
    <visual name="elbow_carrier">
      <origin xyz="0.46 0 -0.043" rpy="0 0 0" />
      <geometry>
        <cylinder radius="0.078" length="0.074" />
        </geometry>
      <material name="brushed_steel">
        <color rgba="0.64 0.65 0.62 1" />
        </material>
      </visual>
    <visual name="elbow_pin_cap">
      <origin xyz="0.46 0 -0.039" rpy="0 0 0" />
      <geometry>
        <cylinder radius="0.028" length="0.078" />
        </geometry>
      <material name="dark_socket_bolts">
        <color rgba="0.03 0.03 0.035 1" />
        </material>
      </visual>
    <collision name="shoulder_hub">
      <origin xyz="0 0 -0.036" rpy="0 0 0" />
      <geometry>
        <cylinder radius="0.088" length="0.072" />
        </geometry>
      </collision>
    <collision name="upper_beam">
      <origin xyz="0.23 0 -0.05" rpy="0 0 0" />
      <geometry>
        <box size="0.46 0.106 0.05" />
        </geometry>
      </collision>
    <collision name="upper_side_rail_0">
      <origin xyz="0.23 0.052 -0.05" rpy="0 0 0" />
      <geometry>
        <box size="0.33 0.028 0.056" />
        </geometry>
      </collision>
    <collision name="upper_side_rail_1">
      <origin xyz="0.23 -0.052 -0.05" rpy="0 0 0" />
      <geometry>
        <box size="0.33 0.028 0.056" />
        </geometry>
      </collision>
    <collision name="elbow_carrier">
      <origin xyz="0.46 0 -0.043" rpy="0 0 0" />
      <geometry>
        <cylinder radius="0.078" length="0.074" />
        </geometry>
      </collision>
    <collision name="elbow_pin_cap">
      <origin xyz="0.46 0 -0.039" rpy="0 0 0" />
      <geometry>
        <cylinder radius="0.028" length="0.078" />
        </geometry>
      </collision>
    </link>
  <link name="forearm">
    <visual name="elbow_hub">
      <origin xyz="0 0 -0.03" rpy="0 0 0" />
      <geometry>
        <cylinder radius="0.066" length="0.06" />
        </geometry>
      <material name="brushed_steel">
        <color rgba="0.64 0.65 0.62 1" />
        </material>
      </visual>
    <visual name="forearm_beam">
      <origin xyz="0.17 0 -0.035" rpy="0 0 0" />
      <geometry>
        <box size="0.34 0.078 0.04" />
        </geometry>
      <material name="powder_coated_blue">
        <color rgba="0.05 0.22 0.48 1" />
        </material>
      </visual>
    <visual name="forearm_side_rail_0">
      <origin xyz="0.18 0.038 -0.035" rpy="0 0 0" />
      <geometry>
        <box size="0.255 0.02 0.046" />
        </geometry>
      <material name="matte_graphite">
        <color rgba="0.1 0.11 0.12 1" />
        </material>
      </visual>
    <visual name="forearm_side_rail_1">
      <origin xyz="0.18 -0.038 -0.035" rpy="0 0 0" />
      <geometry>
        <box size="0.255 0.02 0.046" />
        </geometry>
      <material name="matte_graphite">
        <color rgba="0.1 0.11 0.12 1" />
        </material>
      </visual>
    <collision name="elbow_hub">
      <origin xyz="0 0 -0.03" rpy="0 0 0" />
      <geometry>
        <cylinder radius="0.066" length="0.06" />
        </geometry>
      </collision>
    <collision name="forearm_beam">
      <origin xyz="0.17 0 -0.035" rpy="0 0 0" />
      <geometry>
        <box size="0.34 0.078 0.04" />
        </geometry>
      </collision>
    <collision name="forearm_side_rail_0">
      <origin xyz="0.18 0.038 -0.035" rpy="0 0 0" />
      <geometry>
        <box size="0.255 0.02 0.046" />
        </geometry>
      </collision>
    <collision name="forearm_side_rail_1">
      <origin xyz="0.18 -0.038 -0.035" rpy="0 0 0" />
      <geometry>
        <box size="0.255 0.02 0.046" />
        </geometry>
      </collision>
    </link>
  <link name="output_face">
    <visual name="wrist_block">
      <origin xyz="0.02 0 0" rpy="0 0 0" />
      <geometry>
        <box size="0.04 0.074 0.05" />
        </geometry>
      <material name="brushed_steel">
        <color rgba="0.64 0.65 0.62 1" />
        </material>
      </visual>
    <visual name="tool_flange">
      <origin xyz="0.054 0 0" rpy="0 1.5708 0" />
      <geometry>
        <cylinder radius="0.064" length="0.03" />
        </geometry>
      <material name="tool_face_black">
        <color rgba="0.015 0.016 0.017 1" />
        </material>
      </visual>
    <visual name="face_bolt_0">
      <origin xyz="0.072 -0.038 -0.038" rpy="0 1.5708 0" />
      <geometry>
        <cylinder radius="0.0065" length="0.006" />
        </geometry>
      <material name="brushed_steel">
        <color rgba="0.64 0.65 0.62 1" />
        </material>
      </visual>
    <visual name="face_bolt_1">
      <origin xyz="0.072 -0.038 0.038" rpy="0 1.5708 0" />
      <geometry>
        <cylinder radius="0.0065" length="0.006" />
        </geometry>
      <material name="brushed_steel">
        <color rgba="0.64 0.65 0.62 1" />
        </material>
      </visual>
    <visual name="face_bolt_2">
      <origin xyz="0.072 0.038 -0.038" rpy="0 1.5708 0" />
      <geometry>
        <cylinder radius="0.0065" length="0.006" />
        </geometry>
      <material name="brushed_steel">
        <color rgba="0.64 0.65 0.62 1" />
        </material>
      </visual>
    <visual name="face_bolt_3">
      <origin xyz="0.072 0.038 0.038" rpy="0 1.5708 0" />
      <geometry>
        <cylinder radius="0.0065" length="0.006" />
        </geometry>
      <material name="brushed_steel">
        <color rgba="0.64 0.65 0.62 1" />
        </material>
      </visual>
    <collision name="wrist_block">
      <origin xyz="0.02 0 0" rpy="0 0 0" />
      <geometry>
        <box size="0.04 0.074 0.05" />
        </geometry>
      </collision>
    <collision name="tool_flange">
      <origin xyz="0.054 0 0" rpy="0 1.5708 0" />
      <geometry>
        <cylinder radius="0.064" length="0.03" />
        </geometry>
      </collision>
    <collision name="face_bolt_0">
      <origin xyz="0.072 -0.038 -0.038" rpy="0 1.5708 0" />
      <geometry>
        <cylinder radius="0.0065" length="0.006" />
        </geometry>
      </collision>
    <collision name="face_bolt_1">
      <origin xyz="0.072 -0.038 0.038" rpy="0 1.5708 0" />
      <geometry>
        <cylinder radius="0.0065" length="0.006" />
        </geometry>
      </collision>
    <collision name="face_bolt_2">
      <origin xyz="0.072 0.038 -0.038" rpy="0 1.5708 0" />
      <geometry>
        <cylinder radius="0.0065" length="0.006" />
        </geometry>
      </collision>
    <collision name="face_bolt_3">
      <origin xyz="0.072 0.038 0.038" rpy="0 1.5708 0" />
      <geometry>
        <cylinder radius="0.0065" length="0.006" />
        </geometry>
      </collision>
    </link>
  <joint name="shoulder_yaw" type="revolute">
    <parent link="top_support" />
    <child link="upper_arm" />
    <axis xyz="0 0 1" />
    <limit effort="90" velocity="1.8" lower="-2.62" upper="2.62" />
    </joint>
  <joint name="elbow_yaw" type="revolute">
    <origin xyz="0.46 0 -0.08" rpy="0 0 0" />
    <parent link="upper_arm" />
    <child link="forearm" />
    <axis xyz="0 0 1" />
    <limit effort="65" velocity="2" lower="-2.35" upper="2.35" />
    </joint>
  <joint name="forearm_to_output" type="fixed">
    <origin xyz="0.34 0 -0.035" rpy="0 0 0" />
    <parent link="forearm" />
    <child link="output_face" />
    </joint>
  </robot>
