<robot name="hanging_beam_slide">
  <link name="beam">
    <visual name="beam_body">
      <origin xyz="0 0 0.6" rpy="0 0 0" />
      <geometry>
        <box size="1.22 0.1 0.08" />
        </geometry>
      <material name="safety_yellow_paint">
        <color rgba="0.92 0.66 0.08 1" />
        </material>
      </visual>
    <visual name="side_rail_pos">
      <origin xyz="0 0.055 0.6" rpy="0 0 0" />
      <geometry>
        <box size="1.16 0.01 0.05" />
        </geometry>
      <material name="brushed_steel">
        <color rgba="0.62 0.64 0.63 1" />
        </material>
      </visual>
    <visual name="side_rail_neg">
      <origin xyz="0 -0.055 0.6" rpy="0 0 0" />
      <geometry>
        <box size="1.16 0.01 0.05" />
        </geometry>
      <material name="brushed_steel">
        <color rgba="0.62 0.64 0.63 1" />
        </material>
      </visual>
    <visual name="lower_rail">
      <origin xyz="0 0 0.552" rpy="0 0 0" />
      <geometry>
        <box size="1.16 0.032 0.012" />
        </geometry>
      <material name="brushed_steel">
        <color rgba="0.62 0.64 0.63 1" />
        </material>
      </visual>
    <visual name="travel_stop_0">
      <origin xyz="-0.54 0 0.535" rpy="0 0 0" />
      <geometry>
        <box size="0.035 0.16 0.05" />
        </geometry>
      <material name="charcoal_machine_paint">
        <color rgba="0.08 0.09 0.1 1" />
        </material>
      </visual>
    <visual name="stop_bumper_0">
      <origin xyz="-0.5373 0 0.501" rpy="0 0 0" />
      <geometry>
        <box size="0.02 0.122 0.018" />
        </geometry>
      <material name="black_rubber">
        <color rgba="0.01 0.012 0.012 1" />
        </material>
      </visual>
    <visual name="travel_stop_1">
      <origin xyz="0.54 0 0.535" rpy="0 0 0" />
      <geometry>
        <box size="0.035 0.16 0.05" />
        </geometry>
      <material name="charcoal_machine_paint">
        <color rgba="0.08 0.09 0.1 1" />
        </material>
      </visual>
    <visual name="stop_bumper_1">
      <origin xyz="0.5373 0 0.501" rpy="0 0 0" />
      <geometry>
        <box size="0.02 0.122 0.018" />
        </geometry>
      <material name="black_rubber">
        <color rgba="0.01 0.012 0.012 1" />
        </material>
      </visual>
    <visual name="ceiling_plate">
      <origin xyz="0 0 0.83" rpy="0 0 0" />
      <geometry>
        <box size="1.2 0.4 0.02" />
        </geometry>
      <material name="charcoal_machine_paint">
        <color rgba="0.08 0.09 0.1 1" />
        </material>
      </visual>
    <visual name="hanger_0">
      <origin xyz="-0.565 0.16 0.73" rpy="0 0 0" />
      <geometry>
        <box size="0.04 0.04 0.18" />
        </geometry>
      <material name="charcoal_machine_paint">
        <color rgba="0.08 0.09 0.1 1" />
        </material>
      </visual>
    <visual name="hanger_pad_0">
      <origin xyz="-0.565 0.105 0.646" rpy="0 0 0" />
      <geometry>
        <box size="0.08 0.22 0.012" />
        </geometry>
      <material name="brushed_steel">
        <color rgba="0.62 0.64 0.63 1" />
        </material>
      </visual>
    <visual name="hanger_1">
      <origin xyz="0.565 0.16 0.73" rpy="0 0 0" />
      <geometry>
        <box size="0.04 0.04 0.18" />
        </geometry>
      <material name="charcoal_machine_paint">
        <color rgba="0.08 0.09 0.1 1" />
        </material>
      </visual>
    <visual name="hanger_pad_1">
      <origin xyz="0.565 0.105 0.646" rpy="0 0 0" />
      <geometry>
        <box size="0.08 0.22 0.012" />
        </geometry>
      <material name="brushed_steel">
        <color rgba="0.62 0.64 0.63 1" />
        </material>
      </visual>
    <collision name="beam_body">
      <origin xyz="0 0 0.6" rpy="0 0 0" />
      <geometry>
        <box size="1.22 0.1 0.08" />
        </geometry>
      </collision>
    <collision name="side_rail_pos">
      <origin xyz="0 0.055 0.6" rpy="0 0 0" />
      <geometry>
        <box size="1.16 0.01 0.05" />
        </geometry>
      </collision>
    <collision name="side_rail_neg">
      <origin xyz="0 -0.055 0.6" rpy="0 0 0" />
      <geometry>
        <box size="1.16 0.01 0.05" />
        </geometry>
      </collision>
    <collision name="lower_rail">
      <origin xyz="0 0 0.552" rpy="0 0 0" />
      <geometry>
        <box size="1.16 0.032 0.012" />
        </geometry>
      </collision>
    <collision name="travel_stop_0">
      <origin xyz="-0.54 0 0.535" rpy="0 0 0" />
      <geometry>
        <box size="0.035 0.16 0.05" />
        </geometry>
      </collision>
    <collision name="stop_bumper_0">
      <origin xyz="-0.5373 0 0.501" rpy="0 0 0" />
      <geometry>
        <box size="0.02 0.122 0.018" />
        </geometry>
      </collision>
    <collision name="travel_stop_1">
      <origin xyz="0.54 0 0.535" rpy="0 0 0" />
      <geometry>
        <box size="0.035 0.16 0.05" />
        </geometry>
      </collision>
    <collision name="stop_bumper_1">
      <origin xyz="0.5373 0 0.501" rpy="0 0 0" />
      <geometry>
        <box size="0.02 0.122 0.018" />
        </geometry>
      </collision>
    <collision name="ceiling_plate">
      <origin xyz="0 0 0.83" rpy="0 0 0" />
      <geometry>
        <box size="1.2 0.4 0.02" />
        </geometry>
      </collision>
    <collision name="hanger_0">
      <origin xyz="-0.565 0.16 0.73" rpy="0 0 0" />
      <geometry>
        <box size="0.04 0.04 0.18" />
        </geometry>
      </collision>
    <collision name="hanger_pad_0">
      <origin xyz="-0.565 0.105 0.646" rpy="0 0 0" />
      <geometry>
        <box size="0.08 0.22 0.012" />
        </geometry>
      </collision>
    <collision name="hanger_1">
      <origin xyz="0.565 0.16 0.73" rpy="0 0 0" />
      <geometry>
        <box size="0.04 0.04 0.18" />
        </geometry>
      </collision>
    <collision name="hanger_pad_1">
      <origin xyz="0.565 0.105 0.646" rpy="0 0 0" />
      <geometry>
        <box size="0.08 0.22 0.012" />
        </geometry>
      </collision>
    </link>
  <link name="carriage">
    <visual name="side_plate_pos">
      <origin xyz="0 0.088 0" rpy="0 0 0" />
      <geometry>
        <box size="0.2 0.016 0.17" />
        </geometry>
      <material name="charcoal_machine_paint">
        <color rgba="0.08 0.09 0.1 1" />
        </material>
      </visual>
    <visual name="side_plate_neg">
      <origin xyz="0 -0.088 0" rpy="0 0 0" />
      <geometry>
        <box size="0.2 0.016 0.17" />
        </geometry>
      <material name="charcoal_machine_paint">
        <color rgba="0.08 0.09 0.1 1" />
        </material>
      </visual>
    <visual name="top_bridge">
      <origin xyz="0 0 0.094" rpy="0 0 0" />
      <geometry>
        <box size="0.2 0.192 0.018" />
        </geometry>
      <material name="charcoal_machine_paint">
        <color rgba="0.08 0.09 0.1 1" />
        </material>
      </visual>
    <visual name="bottom_bridge">
      <origin xyz="0 0 -0.092" rpy="0 0 0" />
      <geometry>
        <box size="0.2 0.192 0.014" />
        </geometry>
      <material name="charcoal_machine_paint">
        <color rgba="0.08 0.09 0.1 1" />
        </material>
      </visual>
    <visual name="front_face">
      <origin xyz="0 -0.102 0" rpy="0 0 0" />
      <geometry>
        <box size="0.19 0.014 0.16" />
        </geometry>
      <material name="safety_yellow_paint">
        <color rgba="0.92 0.66 0.08 1" />
        </material>
      </visual>
    <visual name="rear_service_cover">
      <origin xyz="0 0.101 0" rpy="0 0 0" />
      <geometry>
        <box size="0.14 0.01 0.112" />
        </geometry>
      <material name="brushed_steel">
        <color rgba="0.62 0.64 0.63 1" />
        </material>
      </visual>
    <visual name="wear_pad_pos">
      <origin xyz="0 0.07 0" rpy="0 0 0" />
      <geometry>
        <box size="0.126 0.02 0.06" />
        </geometry>
      <material name="oiled_bronze">
        <color rgba="0.56 0.38 0.18 1" />
        </material>
      </visual>
    <visual name="wear_pad_neg">
      <origin xyz="0 -0.07 0" rpy="0 0 0" />
      <geometry>
        <box size="0.126 0.02 0.06" />
        </geometry>
      <material name="oiled_bronze">
        <color rgba="0.56 0.38 0.18 1" />
        </material>
      </visual>
    <visual name="wiper_pos_0">
      <origin xyz="-0.106 0.074 0" rpy="0 0 0" />
      <geometry>
        <box size="0.012 0.012 0.09" />
        </geometry>
      <material name="black_rubber">
        <color rgba="0.01 0.012 0.012 1" />
        </material>
      </visual>
    <visual name="wiper_neg_0">
      <origin xyz="-0.106 -0.074 0" rpy="0 0 0" />
      <geometry>
        <box size="0.012 0.012 0.09" />
        </geometry>
      <material name="black_rubber">
        <color rgba="0.01 0.012 0.012 1" />
        </material>
      </visual>
    <visual name="wiper_pos_1">
      <origin xyz="0.106 0.074 0" rpy="0 0 0" />
      <geometry>
        <box size="0.012 0.012 0.09" />
        </geometry>
      <material name="black_rubber">
        <color rgba="0.01 0.012 0.012 1" />
        </material>
      </visual>
    <visual name="wiper_neg_1">
      <origin xyz="0.106 -0.074 0" rpy="0 0 0" />
      <geometry>
        <box size="0.012 0.012 0.09" />
        </geometry>
      <material name="black_rubber">
        <color rgba="0.01 0.012 0.012 1" />
        </material>
      </visual>
    <visual name="bearing_flange">
      <origin xyz="0 -0.1215 0" rpy="-1.5708 0 0" />
      <geometry>
        <cylinder radius="0.04" length="0.025" />
        </geometry>
      <material name="brushed_steel">
        <color rgba="0.62 0.64 0.63 1" />
        </material>
      </visual>
    <visual name="shoulder_bolt_neg_bot">
      <origin xyz="-0.06 -0.1125 -0.047" rpy="-1.5708 0 0" />
      <geometry>
        <cylinder radius="0.008" length="0.007" />
        </geometry>
      <material name="brushed_steel">
        <color rgba="0.62 0.64 0.63 1" />
        </material>
      </visual>
    <visual name="shoulder_bolt_neg_top">
      <origin xyz="-0.06 -0.1125 0.047" rpy="-1.5708 0 0" />
      <geometry>
        <cylinder radius="0.008" length="0.007" />
        </geometry>
      <material name="brushed_steel">
        <color rgba="0.62 0.64 0.63 1" />
        </material>
      </visual>
    <visual name="shoulder_bolt_pos_bot">
      <origin xyz="0.06 -0.1125 -0.047" rpy="-1.5708 0 0" />
      <geometry>
        <cylinder radius="0.008" length="0.007" />
        </geometry>
      <material name="brushed_steel">
        <color rgba="0.62 0.64 0.63 1" />
        </material>
      </visual>
    <visual name="shoulder_bolt_pos_top">
      <origin xyz="0.06 -0.1125 0.047" rpy="-1.5708 0 0" />
      <geometry>
        <cylinder radius="0.008" length="0.007" />
        </geometry>
      <material name="brushed_steel">
        <color rgba="0.62 0.64 0.63 1" />
        </material>
      </visual>
    <visual name="top_guard">
      <origin xyz="0 -0.198 0.07" rpy="0 0 0" />
      <geometry>
        <box size="0.145 0.19 0.012" />
        </geometry>
      <material name="safety_yellow_paint">
        <color rgba="0.92 0.66 0.08 1" />
        </material>
      </visual>
    <visual name="bottom_guard">
      <origin xyz="0 -0.198 -0.07" rpy="0 0 0" />
      <geometry>
        <box size="0.145 0.19 0.012" />
        </geometry>
      <material name="safety_yellow_paint">
        <color rgba="0.92 0.66 0.08 1" />
        </material>
      </visual>
    <visual name="guard_side_pos">
      <origin xyz="0.068 -0.198 0" rpy="0 0 0" />
      <geometry>
        <box size="0.01 0.19 0.152" />
        </geometry>
      <material name="safety_yellow_paint">
        <color rgba="0.92 0.66 0.08 1" />
        </material>
      </visual>
    <visual name="guard_side_neg">
      <origin xyz="-0.068 -0.198 0" rpy="0 0 0" />
      <geometry>
        <box size="0.01 0.19 0.152" />
        </geometry>
      <material name="safety_yellow_paint">
        <color rgba="0.92 0.66 0.08 1" />
        </material>
      </visual>
    <collision name="side_plate_pos">
      <origin xyz="0 0.088 0" rpy="0 0 0" />
      <geometry>
        <box size="0.2 0.016 0.17" />
        </geometry>
      </collision>
    <collision name="side_plate_neg">
      <origin xyz="0 -0.088 0" rpy="0 0 0" />
      <geometry>
        <box size="0.2 0.016 0.17" />
        </geometry>
      </collision>
    <collision name="top_bridge">
      <origin xyz="0 0 0.094" rpy="0 0 0" />
      <geometry>
        <box size="0.2 0.192 0.018" />
        </geometry>
      </collision>
    <collision name="bottom_bridge">
      <origin xyz="0 0 -0.092" rpy="0 0 0" />
      <geometry>
        <box size="0.2 0.192 0.014" />
        </geometry>
      </collision>
    <collision name="front_face">
      <origin xyz="0 -0.102 0" rpy="0 0 0" />
      <geometry>
        <box size="0.19 0.014 0.16" />
        </geometry>
      </collision>
    <collision name="rear_service_cover">
      <origin xyz="0 0.101 0" rpy="0 0 0" />
      <geometry>
        <box size="0.14 0.01 0.112" />
        </geometry>
      </collision>
    <collision name="wear_pad_pos">
      <origin xyz="0 0.07 0" rpy="0 0 0" />
      <geometry>
        <box size="0.126 0.02 0.06" />
        </geometry>
      </collision>
    <collision name="wear_pad_neg">
      <origin xyz="0 -0.07 0" rpy="0 0 0" />
      <geometry>
        <box size="0.126 0.02 0.06" />
        </geometry>
      </collision>
    <collision name="wiper_pos_0">
      <origin xyz="-0.106 0.074 0" rpy="0 0 0" />
      <geometry>
        <box size="0.012 0.012 0.09" />
        </geometry>
      </collision>
    <collision name="wiper_neg_0">
      <origin xyz="-0.106 -0.074 0" rpy="0 0 0" />
      <geometry>
        <box size="0.012 0.012 0.09" />
        </geometry>
      </collision>
    <collision name="wiper_pos_1">
      <origin xyz="0.106 0.074 0" rpy="0 0 0" />
      <geometry>
        <box size="0.012 0.012 0.09" />
        </geometry>
      </collision>
    <collision name="wiper_neg_1">
      <origin xyz="0.106 -0.074 0" rpy="0 0 0" />
      <geometry>
        <box size="0.012 0.012 0.09" />
        </geometry>
      </collision>
    <collision name="bearing_flange">
      <origin xyz="0 -0.1215 0" rpy="-1.5708 0 0" />
      <geometry>
        <cylinder radius="0.04" length="0.025" />
        </geometry>
      </collision>
    <collision name="shoulder_bolt_neg_bot">
      <origin xyz="-0.06 -0.1125 -0.047" rpy="-1.5708 0 0" />
      <geometry>
        <cylinder radius="0.008" length="0.007" />
        </geometry>
      </collision>
    <collision name="shoulder_bolt_neg_top">
      <origin xyz="-0.06 -0.1125 0.047" rpy="-1.5708 0 0" />
      <geometry>
        <cylinder radius="0.008" length="0.007" />
        </geometry>
      </collision>
    <collision name="shoulder_bolt_pos_bot">
      <origin xyz="0.06 -0.1125 -0.047" rpy="-1.5708 0 0" />
      <geometry>
        <cylinder radius="0.008" length="0.007" />
        </geometry>
      </collision>
    <collision name="shoulder_bolt_pos_top">
      <origin xyz="0.06 -0.1125 0.047" rpy="-1.5708 0 0" />
      <geometry>
        <cylinder radius="0.008" length="0.007" />
        </geometry>
      </collision>
    <collision name="top_guard">
      <origin xyz="0 -0.198 0.07" rpy="0 0 0" />
      <geometry>
        <box size="0.145 0.19 0.012" />
        </geometry>
      </collision>
    <collision name="bottom_guard">
      <origin xyz="0 -0.198 -0.07" rpy="0 0 0" />
      <geometry>
        <box size="0.145 0.19 0.012" />
        </geometry>
      </collision>
    <collision name="guard_side_pos">
      <origin xyz="0.068 -0.198 0" rpy="0 0 0" />
      <geometry>
        <box size="0.01 0.19 0.152" />
        </geometry>
      </collision>
    <collision name="guard_side_neg">
      <origin xyz="-0.068 -0.198 0" rpy="0 0 0" />
      <geometry>
        <box size="0.01 0.19 0.152" />
        </geometry>
      </collision>
    </link>
  <link name="roller">
    <visual name="roller_body">
      <origin xyz="0 0 0" rpy="-1.5708 0 0" />
      <geometry>
        <cylinder radius="0.045" length="0.11" />
        </geometry>
      <material name="blue_polyurethane">
        <color rgba="0.05 0.2 0.55 1" />
        </material>
      </visual>
    <visual name="axle_pin">
      <origin xyz="0 0 0" rpy="-1.5708 0 0" />
      <geometry>
        <cylinder radius="0.013" length="0.142" />
        </geometry>
      <material name="brushed_steel">
        <color rgba="0.62 0.64 0.63 1" />
        </material>
      </visual>
    <visual name="inner_end_cap">
      <origin xyz="0 0.064 0" rpy="-1.5708 0 0" />
      <geometry>
        <cylinder radius="0.034" length="0.014" />
        </geometry>
      <material name="brushed_steel">
        <color rgba="0.62 0.64 0.63 1" />
        </material>
      </visual>
    <visual name="outer_end_cap">
      <origin xyz="0 -0.061 0" rpy="-1.5708 0 0" />
      <geometry>
        <cylinder radius="0.034" length="0.014" />
        </geometry>
      <material name="brushed_steel">
        <color rgba="0.62 0.64 0.63 1" />
        </material>
      </visual>
    <visual name="machined_end_cap">
      <origin xyz="0 -0.0745 0" rpy="-1.5708 0 0" />
      <geometry>
        <cylinder radius="0.024" length="0.014" />
        </geometry>
      <material name="brushed_steel">
        <color rgba="0.62 0.64 0.63 1" />
        </material>
      </visual>
    <visual name="index_stripe">
      <origin xyz="0 0 0.0465" rpy="0 0 0" />
      <geometry>
        <box size="0.01 0.08 0.006" />
        </geometry>
      <material name="white_index_mark">
        <color rgba="0.95 0.94 0.86 1" />
        </material>
      </visual>
    <collision name="roller_body">
      <origin xyz="0 0 0" rpy="-1.5708 0 0" />
      <geometry>
        <cylinder radius="0.045" length="0.11" />
        </geometry>
      </collision>
    <collision name="axle_pin">
      <origin xyz="0 0 0" rpy="-1.5708 0 0" />
      <geometry>
        <cylinder radius="0.013" length="0.142" />
        </geometry>
      </collision>
    <collision name="inner_end_cap">
      <origin xyz="0 0.064 0" rpy="-1.5708 0 0" />
      <geometry>
        <cylinder radius="0.034" length="0.014" />
        </geometry>
      </collision>
    <collision name="outer_end_cap">
      <origin xyz="0 -0.061 0" rpy="-1.5708 0 0" />
      <geometry>
        <cylinder radius="0.034" length="0.014" />
        </geometry>
      </collision>
    <collision name="machined_end_cap">
      <origin xyz="0 -0.0745 0" rpy="-1.5708 0 0" />
      <geometry>
        <cylinder radius="0.024" length="0.014" />
        </geometry>
      </collision>
    <collision name="index_stripe">
      <origin xyz="0 0 0.0465" rpy="0 0 0" />
      <geometry>
        <box size="0.01 0.08 0.006" />
        </geometry>
      </collision>
    </link>
  <joint name="beam_to_carriage" type="prismatic">
    <origin xyz="-0.35 0 0.6" rpy="0 0 0" />
    <parent link="beam" />
    <child link="carriage" />
    <axis xyz="1 0 0" />
    <limit effort="250" velocity="0.45" lower="0" upper="0.7" />
    </joint>
  <joint name="carriage_to_roller" type="revolute">
    <origin xyz="0 -0.205 0" rpy="0 0 0" />
    <parent link="carriage" />
    <child link="roller" />
    <axis xyz="0 1 0" />
    <limit effort="18" velocity="18" lower="-3.14159" upper="3.14159" />
    </joint>
  </robot>
