<robot name="outdoor_poster_easel">
  <link name="front_frame">
    <visual name="front_leg_0">
      <origin xyz="-0.295 0 0.755" rpy="0 0.0906599 0" />
      <geometry>
        <box size="0.035 0.028 1.4359" />
        </geometry>
      <material name="brushed_aluminium">
        <color rgba="0.78 0.8 0.78 1" />
        </material>
      </visual>
    <visual name="front_leg_1">
      <origin xyz="0.295 0 0.755" rpy="0 -0.0906599 0" />
      <geometry>
        <box size="0.035 0.028 1.4359" />
        </geometry>
      <material name="brushed_aluminium">
        <color rgba="0.78 0.8 0.78 1" />
        </material>
      </visual>
    <visual name="lower_crossbar">
      <origin xyz="0 0 0.12" rpy="0 0 0" />
      <geometry>
        <box size="0.72 0.03 0.035" />
        </geometry>
      <material name="brushed_aluminium">
        <color rgba="0.78 0.8 0.78 1" />
        </material>
      </visual>
    <visual name="middle_crossbar">
      <origin xyz="0 0 0.86" rpy="0 0 0" />
      <geometry>
        <box size="0.62 0.026 0.03" />
        </geometry>
      <material name="brushed_aluminium">
        <color rgba="0.78 0.8 0.78 1" />
        </material>
      </visual>
    <visual name="crown_block">
      <origin xyz="0 -0.002 1.47" rpy="0 0 0" />
      <geometry>
        <box size="0.74 0.04 0.05" />
        </geometry>
      <material name="brushed_aluminium">
        <color rgba="0.78 0.8 0.78 1" />
        </material>
      </visual>
    <visual name="front_foot_0">
      <origin xyz="-0.36 0 0.022" rpy="0 0 0" />
      <geometry>
        <box size="0.16 0.07 0.035" />
        </geometry>
      <material name="black_plastic">
        <color rgba="0.015 0.015 0.014 1" />
        </material>
      </visual>
    <visual name="front_foot_1">
      <origin xyz="0.36 0 0.022" rpy="0 0 0" />
      <geometry>
        <box size="0.16 0.07 0.035" />
        </geometry>
      <material name="black_plastic">
        <color rgba="0.015 0.015 0.014 1" />
        </material>
      </visual>
    <visual name="poster_panel">
      <origin xyz="0 0.012 0.91" rpy="0 0 0" />
      <geometry>
        <box size="0.52 0.006 0.82" />
        </geometry>
      <material name="white_poster">
        <color rgba="0.96 0.95 0.89 1" />
        </material>
      </visual>
    <visual name="poster_header">
      <origin xyz="0 0.0145 1.18" rpy="0 0 0" />
      <geometry>
        <box size="0.46 0.002 0.055" />
        </geometry>
      <material name="blue_poster_graphic">
        <color rgba="0.05 0.2 0.65 1" />
        </material>
      </visual>
    <visual name="poster_stripe">
      <origin xyz="0 0.0145 0.83" rpy="0 0 0" />
      <geometry>
        <box size="0.38 0.002 0.04" />
        </geometry>
      <material name="orange_poster_graphic">
        <color rgba="0.95 0.38 0.09 1" />
        </material>
      </visual>
    <visual name="slot_0">
      <origin xyz="-0.31 0.015 0.69" rpy="0 0 0" />
      <geometry>
        <box size="0.014 0.006 0.52" />
        </geometry>
      <material name="black_plastic">
        <color rgba="0.015 0.015 0.014 1" />
        </material>
      </visual>
    <visual name="slot_1">
      <origin xyz="0.31 0.015 0.69" rpy="0 0 0" />
      <geometry>
        <box size="0.014 0.006 0.52" />
        </geometry>
      <material name="black_plastic">
        <color rgba="0.015 0.015 0.014 1" />
        </material>
      </visual>
    <visual name="crown_cheek_0">
      <origin xyz="-0.085 -0.028 1.47" rpy="0 0 0" />
      <geometry>
        <box size="0.026 0.08 0.07" />
        </geometry>
      <material name="brushed_aluminium">
        <color rgba="0.78 0.8 0.78 1" />
        </material>
      </visual>
    <visual name="crown_cheek_1">
      <origin xyz="0.085 -0.028 1.47" rpy="0 0 0" />
      <geometry>
        <box size="0.026 0.08 0.07" />
        </geometry>
      <material name="brushed_aluminium">
        <color rgba="0.78 0.8 0.78 1" />
        </material>
      </visual>
    <visual name="crown_pin">
      <origin xyz="0 -0.052 1.47" rpy="0 1.5708 0" />
      <geometry>
        <cylinder radius="0.012" length="0.24" />
        </geometry>
      <material name="brushed_aluminium">
        <color rgba="0.78 0.8 0.78 1" />
        </material>
      </visual>
    <visual name="clamp_stanchion_0">
      <origin xyz="-0.33 0.032 1.39" rpy="0 0 0" />
      <geometry>
        <box size="0.034 0.03 0.165" />
        </geometry>
      <material name="brushed_aluminium">
        <color rgba="0.78 0.8 0.78 1" />
        </material>
      </visual>
    <visual name="clamp_stanchion_1">
      <origin xyz="0.33 0.032 1.39" rpy="0 0 0" />
      <geometry>
        <box size="0.034 0.03 0.165" />
        </geometry>
      <material name="brushed_aluminium">
        <color rgba="0.78 0.8 0.78 1" />
        </material>
      </visual>
    <collision name="front_leg_0">
      <origin xyz="-0.295 0 0.755" rpy="0 0.0906599 0" />
      <geometry>
        <box size="0.035 0.028 1.4359" />
        </geometry>
      </collision>
    <collision name="front_leg_1">
      <origin xyz="0.295 0 0.755" rpy="0 -0.0906599 0" />
      <geometry>
        <box size="0.035 0.028 1.4359" />
        </geometry>
      </collision>
    <collision name="lower_crossbar">
      <origin xyz="0 0 0.12" rpy="0 0 0" />
      <geometry>
        <box size="0.72 0.03 0.035" />
        </geometry>
      </collision>
    <collision name="middle_crossbar">
      <origin xyz="0 0 0.86" rpy="0 0 0" />
      <geometry>
        <box size="0.62 0.026 0.03" />
        </geometry>
      </collision>
    <collision name="crown_block">
      <origin xyz="0 -0.002 1.47" rpy="0 0 0" />
      <geometry>
        <box size="0.74 0.04 0.05" />
        </geometry>
      </collision>
    <collision name="front_foot_0">
      <origin xyz="-0.36 0 0.022" rpy="0 0 0" />
      <geometry>
        <box size="0.16 0.07 0.035" />
        </geometry>
      </collision>
    <collision name="front_foot_1">
      <origin xyz="0.36 0 0.022" rpy="0 0 0" />
      <geometry>
        <box size="0.16 0.07 0.035" />
        </geometry>
      </collision>
    <collision name="poster_panel">
      <origin xyz="0 0.012 0.91" rpy="0 0 0" />
      <geometry>
        <box size="0.52 0.006 0.82" />
        </geometry>
      </collision>
    <collision name="poster_header">
      <origin xyz="0 0.0145 1.18" rpy="0 0 0" />
      <geometry>
        <box size="0.46 0.002 0.055" />
        </geometry>
      </collision>
    <collision name="poster_stripe">
      <origin xyz="0 0.0145 0.83" rpy="0 0 0" />
      <geometry>
        <box size="0.38 0.002 0.04" />
        </geometry>
      </collision>
    <collision name="slot_0">
      <origin xyz="-0.31 0.015 0.69" rpy="0 0 0" />
      <geometry>
        <box size="0.014 0.006 0.52" />
        </geometry>
      </collision>
    <collision name="slot_1">
      <origin xyz="0.31 0.015 0.69" rpy="0 0 0" />
      <geometry>
        <box size="0.014 0.006 0.52" />
        </geometry>
      </collision>
    <collision name="crown_cheek_0">
      <origin xyz="-0.085 -0.028 1.47" rpy="0 0 0" />
      <geometry>
        <box size="0.026 0.08 0.07" />
        </geometry>
      </collision>
    <collision name="crown_cheek_1">
      <origin xyz="0.085 -0.028 1.47" rpy="0 0 0" />
      <geometry>
        <box size="0.026 0.08 0.07" />
        </geometry>
      </collision>
    <collision name="crown_pin">
      <origin xyz="0 -0.052 1.47" rpy="0 1.5708 0" />
      <geometry>
        <cylinder radius="0.012" length="0.24" />
        </geometry>
      </collision>
    <collision name="clamp_stanchion_0">
      <origin xyz="-0.33 0.032 1.39" rpy="0 0 0" />
      <geometry>
        <box size="0.034 0.03 0.165" />
        </geometry>
      </collision>
    <collision name="clamp_stanchion_1">
      <origin xyz="0.33 0.032 1.39" rpy="0 0 0" />
      <geometry>
        <box size="0.034 0.03 0.165" />
        </geometry>
      </collision>
    </link>
  <link name="rear_leg">
    <visual name="rear_hinge_sleeve">
      <origin xyz="0 0 0" rpy="0 1.5708 0" />
      <geometry>
        <cylinder radius="0.024" length="0.11" />
        </geometry>
      <material name="brushed_aluminium">
        <color rgba="0.78 0.8 0.78 1" />
        </material>
      </visual>
    <visual name="rear_yoke_neck">
      <origin xyz="0 -0.022 -0.04" rpy="0 0 0" />
      <geometry>
        <box size="0.07 0.06 0.105" />
        </geometry>
      <material name="brushed_aluminium">
        <color rgba="0.78 0.8 0.78 1" />
        </material>
      </visual>
    <visual name="rear_leg_bar">
      <origin xyz="0 -0.35 -0.76" rpy="2.73147 0 0" />
      <geometry>
        <box size="0.034 0.028 1.50479" />
        </geometry>
      <material name="brushed_aluminium">
        <color rgba="0.78 0.8 0.78 1" />
        </material>
      </visual>
    <visual name="rear_foot">
      <origin xyz="0 -0.65 -1.45" rpy="0 0 0" />
      <geometry>
        <box size="0.18 0.06 0.03" />
        </geometry>
      <material name="black_plastic">
        <color rgba="0.015 0.015 0.014 1" />
        </material>
      </visual>
    <collision name="rear_hinge_sleeve">
      <origin xyz="0 0 0" rpy="0 1.5708 0" />
      <geometry>
        <cylinder radius="0.024" length="0.11" />
        </geometry>
      </collision>
    <collision name="rear_yoke_neck">
      <origin xyz="0 -0.022 -0.04" rpy="0 0 0" />
      <geometry>
        <box size="0.07 0.06 0.105" />
        </geometry>
      </collision>
    <collision name="rear_leg_bar">
      <origin xyz="0 -0.35 -0.76" rpy="2.73147 0 0" />
      <geometry>
        <box size="0.034 0.028 1.50479" />
        </geometry>
      </collision>
    <collision name="rear_foot">
      <origin xyz="0 -0.65 -1.45" rpy="0 0 0" />
      <geometry>
        <box size="0.18 0.06 0.03" />
        </geometry>
      </collision>
    </link>
  <link name="lip_tray">
    <visual name="tray_shelf">
      <origin xyz="0 0.095 -0.01" rpy="0 0 0" />
      <geometry>
        <box size="0.68 0.12 0.02" />
        </geometry>
      <material name="brushed_aluminium">
        <color rgba="0.78 0.8 0.78 1" />
        </material>
      </visual>
    <visual name="back_lip">
      <origin xyz="0 0.044 0.03" rpy="0 0 0" />
      <geometry>
        <box size="0.64 0.026 0.06" />
        </geometry>
      <material name="brushed_aluminium">
        <color rgba="0.78 0.8 0.78 1" />
        </material>
      </visual>
    <visual name="front_lip">
      <origin xyz="0 0.154 0.012" rpy="0 0 0" />
      <geometry>
        <box size="0.68 0.018 0.045" />
        </geometry>
      <material name="brushed_aluminium">
        <color rgba="0.78 0.8 0.78 1" />
        </material>
      </visual>
    <visual name="slider_plate_0">
      <origin xyz="-0.31 0.026 0.035" rpy="0 0 0" />
      <geometry>
        <box size="0.06 0.018 0.11" />
        </geometry>
      <material name="brushed_aluminium">
        <color rgba="0.78 0.8 0.78 1" />
        </material>
      </visual>
    <visual name="slider_plate_1">
      <origin xyz="0.31 0.026 0.035" rpy="0 0 0" />
      <geometry>
        <box size="0.06 0.018 0.11" />
        </geometry>
      <material name="brushed_aluminium">
        <color rgba="0.78 0.8 0.78 1" />
        </material>
      </visual>
    <visual name="thumb_knob_0">
      <origin xyz="-0.31 0.05 0.04" rpy="-1.5708 0 0" />
      <geometry>
        <cylinder radius="0.024" length="0.02" />
        </geometry>
      <material name="black_plastic">
        <color rgba="0.015 0.015 0.014 1" />
        </material>
      </visual>
    <visual name="thumb_knob_1">
      <origin xyz="0.31 0.05 0.04" rpy="-1.5708 0 0" />
      <geometry>
        <cylinder radius="0.024" length="0.02" />
        </geometry>
      <material name="black_plastic">
        <color rgba="0.015 0.015 0.014 1" />
        </material>
      </visual>
    <collision name="tray_shelf">
      <origin xyz="0 0.095 -0.01" rpy="0 0 0" />
      <geometry>
        <box size="0.68 0.12 0.02" />
        </geometry>
      </collision>
    <collision name="back_lip">
      <origin xyz="0 0.044 0.03" rpy="0 0 0" />
      <geometry>
        <box size="0.64 0.026 0.06" />
        </geometry>
      </collision>
    <collision name="front_lip">
      <origin xyz="0 0.154 0.012" rpy="0 0 0" />
      <geometry>
        <box size="0.68 0.018 0.045" />
        </geometry>
      </collision>
    <collision name="slider_plate_0">
      <origin xyz="-0.31 0.026 0.035" rpy="0 0 0" />
      <geometry>
        <box size="0.06 0.018 0.11" />
        </geometry>
      </collision>
    <collision name="slider_plate_1">
      <origin xyz="0.31 0.026 0.035" rpy="0 0 0" />
      <geometry>
        <box size="0.06 0.018 0.11" />
        </geometry>
      </collision>
    <collision name="thumb_knob_0">
      <origin xyz="-0.31 0.05 0.04" rpy="-1.5708 0 0" />
      <geometry>
        <cylinder radius="0.024" length="0.02" />
        </geometry>
      </collision>
    <collision name="thumb_knob_1">
      <origin xyz="0.31 0.05 0.04" rpy="-1.5708 0 0" />
      <geometry>
        <cylinder radius="0.024" length="0.02" />
        </geometry>
      </collision>
    </link>
  <link name="top_clamp">
    <visual name="clamp_hinge_tube">
      <origin xyz="0 0 0" rpy="0 1.5708 0" />
      <geometry>
        <cylinder radius="0.018" length="0.56" />
        </geometry>
      <material name="brushed_aluminium">
        <color rgba="0.78 0.8 0.78 1" />
        </material>
      </visual>
    <visual name="clamp_arm_0">
      <origin xyz="-0.26 0 -0.06" rpy="0 0 0" />
      <geometry>
        <box size="0.035 0.018 0.12" />
        </geometry>
      <material name="brushed_aluminium">
        <color rgba="0.78 0.8 0.78 1" />
        </material>
      </visual>
    <visual name="clamp_arm_1">
      <origin xyz="0.26 0 -0.06" rpy="0 0 0" />
      <geometry>
        <box size="0.035 0.018 0.12" />
        </geometry>
      <material name="brushed_aluminium">
        <color rgba="0.78 0.8 0.78 1" />
        </material>
      </visual>
    <visual name="clamp_bar">
      <origin xyz="0 0 -0.065" rpy="0 0 0" />
      <geometry>
        <box size="0.62 0.02 0.045" />
        </geometry>
      <material name="brushed_aluminium">
        <color rgba="0.78 0.8 0.78 1" />
        </material>
      </visual>
    <visual name="rubber_pad">
      <origin xyz="0 -0.014 -0.065" rpy="0 0 0" />
      <geometry>
        <box size="0.58 0.016 0.04" />
        </geometry>
      <material name="soft_black_rubber">
        <color rgba="0.005 0.005 0.004 1" />
        </material>
      </visual>
    <collision name="clamp_hinge_tube">
      <origin xyz="0 0 0" rpy="0 1.5708 0" />
      <geometry>
        <cylinder radius="0.018" length="0.56" />
        </geometry>
      </collision>
    <collision name="clamp_arm_0">
      <origin xyz="-0.26 0 -0.06" rpy="0 0 0" />
      <geometry>
        <box size="0.035 0.018 0.12" />
        </geometry>
      </collision>
    <collision name="clamp_arm_1">
      <origin xyz="0.26 0 -0.06" rpy="0 0 0" />
      <geometry>
        <box size="0.035 0.018 0.12" />
        </geometry>
      </collision>
    <collision name="clamp_bar">
      <origin xyz="0 0 -0.065" rpy="0 0 0" />
      <geometry>
        <box size="0.62 0.02 0.045" />
        </geometry>
      </collision>
    <collision name="rubber_pad">
      <origin xyz="0 -0.014 -0.065" rpy="0 0 0" />
      <geometry>
        <box size="0.58 0.016 0.04" />
        </geometry>
      </collision>
    </link>
  <joint name="crown_hinge" type="revolute">
    <origin xyz="0 -0.052 1.47" rpy="0 0 0" />
    <parent link="front_frame" />
    <child link="rear_leg" />
    <axis xyz="1 0 0" />
    <limit effort="12" velocity="1.5" lower="0" upper="1.35" />
    </joint>
  <joint name="tray_slide" type="prismatic">
    <origin xyz="0 0 0.5" rpy="0 0 0" />
    <parent link="front_frame" />
    <child link="lip_tray" />
    <axis xyz="0 0 1" />
    <limit effort="35" velocity="0.18" lower="0" upper="0.32" />
    </joint>
  <joint name="clamp_hinge" type="revolute">
    <origin xyz="0 0.035 1.38" rpy="0 0 0" />
    <parent link="front_frame" />
    <child link="top_clamp" />
    <axis xyz="1 0 0" />
    <limit effort="6" velocity="2" lower="0" upper="1.1" />
    </joint>
  </robot>
