<robot name="service_tool_finger_pair">
  <material name="blackened_steel">
    <color rgba="0.06 0.065 0.07 1" />
    </material>
  <material name="brushed_steel">
    <color rgba="0.62 0.64 0.64 1" />
    </material>
  <material name="anodized_blue">
    <color rgba="0.05 0.18 0.36 1" />
    </material>
  <material name="matte_rubber">
    <color rgba="0.015 0.015 0.013 1" />
    </material>
  <material name="dark_bolt_heads">
    <color rgba="0.02 0.022 0.025 1" />
    </material>
  <link name="base">
    <visual name="dense_body">
      <origin xyz="0 0 0.03" rpy="0 0 0" />
      <geometry>
        <box size="0.17 0.18 0.06" />
        </geometry>
      <material name="blackened_steel">
        <color rgba="0.06 0.065 0.07 1" />
        </material>
      </visual>
    <visual name="top_plate">
      <origin xyz="0.004 0 0.063" rpy="0 0 0" />
      <geometry>
        <box size="0.138 0.148 0.01" />
        </geometry>
      <material name="brushed_steel">
        <color rgba="0.62 0.64 0.64 1" />
        </material>
      </visual>
    <visual name="top_bolt_-0.048_-0.064">
      <origin xyz="-0.048 -0.064 0.066" rpy="0 0 0" />
      <geometry>
        <cylinder radius="0.006" length="0.007" />
        </geometry>
      <material name="dark_bolt_heads">
        <color rgba="0.02 0.022 0.025 1" />
        </material>
      </visual>
    <visual name="top_bolt_-0.048_0.064">
      <origin xyz="-0.048 0.064 0.066" rpy="0 0 0" />
      <geometry>
        <cylinder radius="0.006" length="0.007" />
        </geometry>
      <material name="dark_bolt_heads">
        <color rgba="0.02 0.022 0.025 1" />
        </material>
      </visual>
    <visual name="top_bolt_0.050_-0.064">
      <origin xyz="0.05 -0.064 0.066" rpy="0 0 0" />
      <geometry>
        <cylinder radius="0.006" length="0.007" />
        </geometry>
      <material name="dark_bolt_heads">
        <color rgba="0.02 0.022 0.025 1" />
        </material>
      </visual>
    <visual name="top_bolt_0.050_0.064">
      <origin xyz="0.05 0.064 0.066" rpy="0 0 0" />
      <geometry>
        <cylinder radius="0.006" length="0.007" />
        </geometry>
      <material name="dark_bolt_heads">
        <color rgba="0.02 0.022 0.025 1" />
        </material>
      </visual>
    <visual name="mount_pad_p">
      <origin xyz="0.055 0.05 0.062" rpy="0 0 0" />
      <geometry>
        <box size="0.062 0.07 0.008" />
        </geometry>
      <material name="brushed_steel">
        <color rgba="0.62 0.64 0.64 1" />
        </material>
      </visual>
    <visual name="base_plate_p_inner">
      <origin xyz="0.055 0.03 0.085" rpy="0 0 0" />
      <geometry>
        <box size="0.05 0.01 0.054" />
        </geometry>
      <material name="brushed_steel">
        <color rgba="0.62 0.64 0.64 1" />
        </material>
      </visual>
    <visual name="base_pin_cap_p_inner">
      <origin xyz="0.055 0.03 0.085" rpy="0 0 0" />
      <geometry>
        <cylinder radius="0.0085" length="0.058" />
        </geometry>
      <material name="dark_bolt_heads">
        <color rgba="0.02 0.022 0.025 1" />
        </material>
      </visual>
    <visual name="base_plate_p_outer">
      <origin xyz="0.055 0.07 0.085" rpy="0 0 0" />
      <geometry>
        <box size="0.05 0.01 0.054" />
        </geometry>
      <material name="brushed_steel">
        <color rgba="0.62 0.64 0.64 1" />
        </material>
      </visual>
    <visual name="base_pin_cap_p_outer">
      <origin xyz="0.055 0.07 0.085" rpy="0 0 0" />
      <geometry>
        <cylinder radius="0.0085" length="0.058" />
        </geometry>
      <material name="dark_bolt_heads">
        <color rgba="0.02 0.022 0.025 1" />
        </material>
      </visual>
    <visual name="mount_pad_n">
      <origin xyz="0.055 -0.05 0.062" rpy="0 0 0" />
      <geometry>
        <box size="0.062 0.07 0.008" />
        </geometry>
      <material name="brushed_steel">
        <color rgba="0.62 0.64 0.64 1" />
        </material>
      </visual>
    <visual name="base_plate_n_inner">
      <origin xyz="0.055 -0.07 0.085" rpy="0 0 0" />
      <geometry>
        <box size="0.05 0.01 0.054" />
        </geometry>
      <material name="brushed_steel">
        <color rgba="0.62 0.64 0.64 1" />
        </material>
      </visual>
    <visual name="base_pin_cap_n_inner">
      <origin xyz="0.055 -0.07 0.085" rpy="0 0 0" />
      <geometry>
        <cylinder radius="0.0085" length="0.058" />
        </geometry>
      <material name="dark_bolt_heads">
        <color rgba="0.02 0.022 0.025 1" />
        </material>
      </visual>
    <visual name="base_plate_n_outer">
      <origin xyz="0.055 -0.03 0.085" rpy="0 0 0" />
      <geometry>
        <box size="0.05 0.01 0.054" />
        </geometry>
      <material name="brushed_steel">
        <color rgba="0.62 0.64 0.64 1" />
        </material>
      </visual>
    <visual name="base_pin_cap_n_outer">
      <origin xyz="0.055 -0.03 0.085" rpy="0 0 0" />
      <geometry>
        <cylinder radius="0.0085" length="0.058" />
        </geometry>
      <material name="dark_bolt_heads">
        <color rgba="0.02 0.022 0.025 1" />
        </material>
      </visual>
    <collision name="dense_body">
      <origin xyz="0 0 0.03" rpy="0 0 0" />
      <geometry>
        <box size="0.17 0.18 0.06" />
        </geometry>
      </collision>
    <collision name="top_plate">
      <origin xyz="0.004 0 0.063" rpy="0 0 0" />
      <geometry>
        <box size="0.138 0.148 0.01" />
        </geometry>
      </collision>
    <collision name="top_bolt_-0.048_-0.064">
      <origin xyz="-0.048 -0.064 0.066" rpy="0 0 0" />
      <geometry>
        <cylinder radius="0.006" length="0.007" />
        </geometry>
      </collision>
    <collision name="top_bolt_-0.048_0.064">
      <origin xyz="-0.048 0.064 0.066" rpy="0 0 0" />
      <geometry>
        <cylinder radius="0.006" length="0.007" />
        </geometry>
      </collision>
    <collision name="top_bolt_0.050_-0.064">
      <origin xyz="0.05 -0.064 0.066" rpy="0 0 0" />
      <geometry>
        <cylinder radius="0.006" length="0.007" />
        </geometry>
      </collision>
    <collision name="top_bolt_0.050_0.064">
      <origin xyz="0.05 0.064 0.066" rpy="0 0 0" />
      <geometry>
        <cylinder radius="0.006" length="0.007" />
        </geometry>
      </collision>
    <collision name="mount_pad_p">
      <origin xyz="0.055 0.05 0.062" rpy="0 0 0" />
      <geometry>
        <box size="0.062 0.07 0.008" />
        </geometry>
      </collision>
    <collision name="base_plate_p_inner">
      <origin xyz="0.055 0.03 0.085" rpy="0 0 0" />
      <geometry>
        <box size="0.05 0.01 0.054" />
        </geometry>
      </collision>
    <collision name="base_pin_cap_p_inner">
      <origin xyz="0.055 0.03 0.085" rpy="0 0 0" />
      <geometry>
        <cylinder radius="0.0085" length="0.058" />
        </geometry>
      </collision>
    <collision name="base_plate_p_outer">
      <origin xyz="0.055 0.07 0.085" rpy="0 0 0" />
      <geometry>
        <box size="0.05 0.01 0.054" />
        </geometry>
      </collision>
    <collision name="base_pin_cap_p_outer">
      <origin xyz="0.055 0.07 0.085" rpy="0 0 0" />
      <geometry>
        <cylinder radius="0.0085" length="0.058" />
        </geometry>
      </collision>
    <collision name="mount_pad_n">
      <origin xyz="0.055 -0.05 0.062" rpy="0 0 0" />
      <geometry>
        <box size="0.062 0.07 0.008" />
        </geometry>
      </collision>
    <collision name="base_plate_n_inner">
      <origin xyz="0.055 -0.07 0.085" rpy="0 0 0" />
      <geometry>
        <box size="0.05 0.01 0.054" />
        </geometry>
      </collision>
    <collision name="base_pin_cap_n_inner">
      <origin xyz="0.055 -0.07 0.085" rpy="0 0 0" />
      <geometry>
        <cylinder radius="0.0085" length="0.058" />
        </geometry>
      </collision>
    <collision name="base_plate_n_outer">
      <origin xyz="0.055 -0.03 0.085" rpy="0 0 0" />
      <geometry>
        <box size="0.05 0.01 0.054" />
        </geometry>
      </collision>
    <collision name="base_pin_cap_n_outer">
      <origin xyz="0.055 -0.03 0.085" rpy="0 0 0" />
      <geometry>
        <cylinder radius="0.0085" length="0.058" />
        </geometry>
      </collision>
    </link>
  <link name="finger_0_link_0">
    <visual name="proximal_tongue">
      <geometry>
        <box size="0.04 0.02 0.026" />
        </geometry>
      <material name="anodized_blue">
        <color rgba="0.05 0.18 0.36 1" />
        </material>
      </visual>
    <visual name="proximal_bushing">
      <geometry>
        <cylinder radius="0.0115" length="0.03" />
        </geometry>
      <material name="brushed_steel">
        <color rgba="0.62 0.64 0.64 1" />
        </material>
      </visual>
    <visual name="center_web">
      <origin xyz="0.0575 0 0" rpy="0 0 0" />
      <geometry>
        <box size="0.079 0.018 0.018" />
        </geometry>
      <material name="anodized_blue">
        <color rgba="0.05 0.18 0.36 1" />
        </material>
      </visual>
    <visual name="distal_bridge">
      <origin xyz="0.102 0 0" rpy="0 0 0" />
      <geometry>
        <box size="0.018 0.048 0.024" />
        </geometry>
      <material name="anodized_blue">
        <color rgba="0.05 0.18 0.36 1" />
        </material>
      </visual>
    <visual name="distal_plate_side_0">
      <origin xyz="0.14 -0.02 0" rpy="0 0 0" />
      <geometry>
        <box size="0.074 0.008 0.032" />
        </geometry>
      <material name="brushed_steel">
        <color rgba="0.62 0.64 0.64 1" />
        </material>
      </visual>
    <visual name="distal_boss_side_0">
      <origin xyz="0.15 -0.02 0" rpy="0 0 0" />
      <geometry>
        <cylinder radius="0.0085" length="0.034" />
        </geometry>
      <material name="brushed_steel">
        <color rgba="0.62 0.64 0.64 1" />
        </material>
      </visual>
    <visual name="distal_plate_side_1">
      <origin xyz="0.14 0.02 0" rpy="0 0 0" />
      <geometry>
        <box size="0.074 0.008 0.032" />
        </geometry>
      <material name="brushed_steel">
        <color rgba="0.62 0.64 0.64 1" />
        </material>
      </visual>
    <visual name="distal_boss_side_1">
      <origin xyz="0.15 0.02 0" rpy="0 0 0" />
      <geometry>
        <cylinder radius="0.0085" length="0.034" />
        </geometry>
      <material name="brushed_steel">
        <color rgba="0.62 0.64 0.64 1" />
        </material>
      </visual>
    <collision name="proximal_tongue">
      <geometry>
        <box size="0.04 0.02 0.026" />
        </geometry>
      </collision>
    <collision name="proximal_bushing">
      <geometry>
        <cylinder radius="0.0115" length="0.03" />
        </geometry>
      </collision>
    <collision name="center_web">
      <origin xyz="0.0575 0 0" rpy="0 0 0" />
      <geometry>
        <box size="0.079 0.018 0.018" />
        </geometry>
      </collision>
    <collision name="distal_bridge">
      <origin xyz="0.102 0 0" rpy="0 0 0" />
      <geometry>
        <box size="0.018 0.048 0.024" />
        </geometry>
      </collision>
    <collision name="distal_plate_side_0">
      <origin xyz="0.14 -0.02 0" rpy="0 0 0" />
      <geometry>
        <box size="0.074 0.008 0.032" />
        </geometry>
      </collision>
    <collision name="distal_boss_side_0">
      <origin xyz="0.15 -0.02 0" rpy="0 0 0" />
      <geometry>
        <cylinder radius="0.0085" length="0.034" />
        </geometry>
      </collision>
    <collision name="distal_plate_side_1">
      <origin xyz="0.14 0.02 0" rpy="0 0 0" />
      <geometry>
        <box size="0.074 0.008 0.032" />
        </geometry>
      </collision>
    <collision name="distal_boss_side_1">
      <origin xyz="0.15 0.02 0" rpy="0 0 0" />
      <geometry>
        <cylinder radius="0.0085" length="0.034" />
        </geometry>
      </collision>
    </link>
  <link name="finger_0_link_1">
    <visual name="proximal_tongue">
      <geometry>
        <box size="0.04 0.02 0.026" />
        </geometry>
      <material name="anodized_blue">
        <color rgba="0.05 0.18 0.36 1" />
        </material>
      </visual>
    <visual name="proximal_bushing">
      <geometry>
        <cylinder radius="0.0115" length="0.03" />
        </geometry>
      <material name="brushed_steel">
        <color rgba="0.62 0.64 0.64 1" />
        </material>
      </visual>
    <visual name="center_web">
      <origin xyz="0.0485 0 0" rpy="0 0 0" />
      <geometry>
        <box size="0.061 0.018 0.018" />
        </geometry>
      <material name="anodized_blue">
        <color rgba="0.05 0.18 0.36 1" />
        </material>
      </visual>
    <visual name="distal_bridge">
      <origin xyz="0.084 0 0" rpy="0 0 0" />
      <geometry>
        <box size="0.018 0.048 0.024" />
        </geometry>
      <material name="anodized_blue">
        <color rgba="0.05 0.18 0.36 1" />
        </material>
      </visual>
    <visual name="distal_plate_side_0">
      <origin xyz="0.122 -0.02 0" rpy="0 0 0" />
      <geometry>
        <box size="0.074 0.008 0.032" />
        </geometry>
      <material name="brushed_steel">
        <color rgba="0.62 0.64 0.64 1" />
        </material>
      </visual>
    <visual name="distal_boss_side_0">
      <origin xyz="0.132 -0.02 0" rpy="0 0 0" />
      <geometry>
        <cylinder radius="0.0085" length="0.034" />
        </geometry>
      <material name="brushed_steel">
        <color rgba="0.62 0.64 0.64 1" />
        </material>
      </visual>
    <visual name="distal_plate_side_1">
      <origin xyz="0.122 0.02 0" rpy="0 0 0" />
      <geometry>
        <box size="0.074 0.008 0.032" />
        </geometry>
      <material name="brushed_steel">
        <color rgba="0.62 0.64 0.64 1" />
        </material>
      </visual>
    <visual name="distal_boss_side_1">
      <origin xyz="0.132 0.02 0" rpy="0 0 0" />
      <geometry>
        <cylinder radius="0.0085" length="0.034" />
        </geometry>
      <material name="brushed_steel">
        <color rgba="0.62 0.64 0.64 1" />
        </material>
      </visual>
    <collision name="proximal_tongue">
      <geometry>
        <box size="0.04 0.02 0.026" />
        </geometry>
      </collision>
    <collision name="proximal_bushing">
      <geometry>
        <cylinder radius="0.0115" length="0.03" />
        </geometry>
      </collision>
    <collision name="center_web">
      <origin xyz="0.0485 0 0" rpy="0 0 0" />
      <geometry>
        <box size="0.061 0.018 0.018" />
        </geometry>
      </collision>
    <collision name="distal_bridge">
      <origin xyz="0.084 0 0" rpy="0 0 0" />
      <geometry>
        <box size="0.018 0.048 0.024" />
        </geometry>
      </collision>
    <collision name="distal_plate_side_0">
      <origin xyz="0.122 -0.02 0" rpy="0 0 0" />
      <geometry>
        <box size="0.074 0.008 0.032" />
        </geometry>
      </collision>
    <collision name="distal_boss_side_0">
      <origin xyz="0.132 -0.02 0" rpy="0 0 0" />
      <geometry>
        <cylinder radius="0.0085" length="0.034" />
        </geometry>
      </collision>
    <collision name="distal_plate_side_1">
      <origin xyz="0.122 0.02 0" rpy="0 0 0" />
      <geometry>
        <box size="0.074 0.008 0.032" />
        </geometry>
      </collision>
    <collision name="distal_boss_side_1">
      <origin xyz="0.132 0.02 0" rpy="0 0 0" />
      <geometry>
        <cylinder radius="0.0085" length="0.034" />
        </geometry>
      </collision>
    </link>
  <link name="finger_0_link_2">
    <visual name="proximal_tongue">
      <geometry>
        <box size="0.04 0.02 0.026" />
        </geometry>
      <material name="anodized_blue">
        <color rgba="0.05 0.18 0.36 1" />
        </material>
      </visual>
    <visual name="proximal_bushing">
      <geometry>
        <cylinder radius="0.0115" length="0.03" />
        </geometry>
      <material name="brushed_steel">
        <color rgba="0.62 0.64 0.64 1" />
        </material>
      </visual>
    <visual name="center_web">
      <origin xyz="0.055 0 0" rpy="0 0 0" />
      <geometry>
        <box size="0.074 0.018 0.018" />
        </geometry>
      <material name="anodized_blue">
        <color rgba="0.05 0.18 0.36 1" />
        </material>
      </visual>
    <visual name="tip_nose">
      <origin xyz="0.108 0 0" rpy="0 0 0" />
      <geometry>
        <box size="0.052 0.03 0.022" />
        </geometry>
      <material name="anodized_blue">
        <color rgba="0.05 0.18 0.36 1" />
        </material>
      </visual>
    <visual name="rubber_pad">
      <origin xyz="0.134 0 0" rpy="0 0 0" />
      <geometry>
        <box size="0.02 0.038 0.026" />
        </geometry>
      <material name="matte_rubber">
        <color rgba="0.015 0.015 0.013 1" />
        </material>
      </visual>
    <visual name="rounded_tip">
      <origin xyz="0.143 0 0" rpy="1.5708 0 0" />
      <geometry>
        <cylinder radius="0.014" length="0.04" />
        </geometry>
      <material name="matte_rubber">
        <color rgba="0.015 0.015 0.013 1" />
        </material>
      </visual>
    <collision name="proximal_tongue">
      <geometry>
        <box size="0.04 0.02 0.026" />
        </geometry>
      </collision>
    <collision name="proximal_bushing">
      <geometry>
        <cylinder radius="0.0115" length="0.03" />
        </geometry>
      </collision>
    <collision name="center_web">
      <origin xyz="0.055 0 0" rpy="0 0 0" />
      <geometry>
        <box size="0.074 0.018 0.018" />
        </geometry>
      </collision>
    <collision name="tip_nose">
      <origin xyz="0.108 0 0" rpy="0 0 0" />
      <geometry>
        <box size="0.052 0.03 0.022" />
        </geometry>
      </collision>
    <collision name="rubber_pad">
      <origin xyz="0.134 0 0" rpy="0 0 0" />
      <geometry>
        <box size="0.02 0.038 0.026" />
        </geometry>
      </collision>
    <collision name="rounded_tip">
      <origin xyz="0.143 0 0" rpy="1.5708 0 0" />
      <geometry>
        <cylinder radius="0.014" length="0.04" />
        </geometry>
      </collision>
    </link>
  <link name="finger_1_link_0">
    <visual name="proximal_tongue">
      <geometry>
        <box size="0.04 0.02 0.026" />
        </geometry>
      <material name="anodized_blue">
        <color rgba="0.05 0.18 0.36 1" />
        </material>
      </visual>
    <visual name="proximal_bushing">
      <geometry>
        <cylinder radius="0.0115" length="0.03" />
        </geometry>
      <material name="brushed_steel">
        <color rgba="0.62 0.64 0.64 1" />
        </material>
      </visual>
    <visual name="center_web">
      <origin xyz="0.0575 0 0" rpy="0 0 0" />
      <geometry>
        <box size="0.079 0.018 0.018" />
        </geometry>
      <material name="anodized_blue">
        <color rgba="0.05 0.18 0.36 1" />
        </material>
      </visual>
    <visual name="distal_bridge">
      <origin xyz="0.102 0 0" rpy="0 0 0" />
      <geometry>
        <box size="0.018 0.048 0.024" />
        </geometry>
      <material name="anodized_blue">
        <color rgba="0.05 0.18 0.36 1" />
        </material>
      </visual>
    <visual name="distal_plate_side_0">
      <origin xyz="0.14 -0.02 0" rpy="0 0 0" />
      <geometry>
        <box size="0.074 0.008 0.032" />
        </geometry>
      <material name="brushed_steel">
        <color rgba="0.62 0.64 0.64 1" />
        </material>
      </visual>
    <visual name="distal_boss_side_0">
      <origin xyz="0.15 -0.02 0" rpy="0 0 0" />
      <geometry>
        <cylinder radius="0.0085" length="0.034" />
        </geometry>
      <material name="brushed_steel">
        <color rgba="0.62 0.64 0.64 1" />
        </material>
      </visual>
    <visual name="distal_plate_side_1">
      <origin xyz="0.14 0.02 0" rpy="0 0 0" />
      <geometry>
        <box size="0.074 0.008 0.032" />
        </geometry>
      <material name="brushed_steel">
        <color rgba="0.62 0.64 0.64 1" />
        </material>
      </visual>
    <visual name="distal_boss_side_1">
      <origin xyz="0.15 0.02 0" rpy="0 0 0" />
      <geometry>
        <cylinder radius="0.0085" length="0.034" />
        </geometry>
      <material name="brushed_steel">
        <color rgba="0.62 0.64 0.64 1" />
        </material>
      </visual>
    <collision name="proximal_tongue">
      <geometry>
        <box size="0.04 0.02 0.026" />
        </geometry>
      </collision>
    <collision name="proximal_bushing">
      <geometry>
        <cylinder radius="0.0115" length="0.03" />
        </geometry>
      </collision>
    <collision name="center_web">
      <origin xyz="0.0575 0 0" rpy="0 0 0" />
      <geometry>
        <box size="0.079 0.018 0.018" />
        </geometry>
      </collision>
    <collision name="distal_bridge">
      <origin xyz="0.102 0 0" rpy="0 0 0" />
      <geometry>
        <box size="0.018 0.048 0.024" />
        </geometry>
      </collision>
    <collision name="distal_plate_side_0">
      <origin xyz="0.14 -0.02 0" rpy="0 0 0" />
      <geometry>
        <box size="0.074 0.008 0.032" />
        </geometry>
      </collision>
    <collision name="distal_boss_side_0">
      <origin xyz="0.15 -0.02 0" rpy="0 0 0" />
      <geometry>
        <cylinder radius="0.0085" length="0.034" />
        </geometry>
      </collision>
    <collision name="distal_plate_side_1">
      <origin xyz="0.14 0.02 0" rpy="0 0 0" />
      <geometry>
        <box size="0.074 0.008 0.032" />
        </geometry>
      </collision>
    <collision name="distal_boss_side_1">
      <origin xyz="0.15 0.02 0" rpy="0 0 0" />
      <geometry>
        <cylinder radius="0.0085" length="0.034" />
        </geometry>
      </collision>
    </link>
  <link name="finger_1_link_1">
    <visual name="proximal_tongue">
      <geometry>
        <box size="0.04 0.02 0.026" />
        </geometry>
      <material name="anodized_blue">
        <color rgba="0.05 0.18 0.36 1" />
        </material>
      </visual>
    <visual name="proximal_bushing">
      <geometry>
        <cylinder radius="0.0115" length="0.03" />
        </geometry>
      <material name="brushed_steel">
        <color rgba="0.62 0.64 0.64 1" />
        </material>
      </visual>
    <visual name="center_web">
      <origin xyz="0.0485 0 0" rpy="0 0 0" />
      <geometry>
        <box size="0.061 0.018 0.018" />
        </geometry>
      <material name="anodized_blue">
        <color rgba="0.05 0.18 0.36 1" />
        </material>
      </visual>
    <visual name="distal_bridge">
      <origin xyz="0.084 0 0" rpy="0 0 0" />
      <geometry>
        <box size="0.018 0.048 0.024" />
        </geometry>
      <material name="anodized_blue">
        <color rgba="0.05 0.18 0.36 1" />
        </material>
      </visual>
    <visual name="distal_plate_side_0">
      <origin xyz="0.122 -0.02 0" rpy="0 0 0" />
      <geometry>
        <box size="0.074 0.008 0.032" />
        </geometry>
      <material name="brushed_steel">
        <color rgba="0.62 0.64 0.64 1" />
        </material>
      </visual>
    <visual name="distal_boss_side_0">
      <origin xyz="0.132 -0.02 0" rpy="0 0 0" />
      <geometry>
        <cylinder radius="0.0085" length="0.034" />
        </geometry>
      <material name="brushed_steel">
        <color rgba="0.62 0.64 0.64 1" />
        </material>
      </visual>
    <visual name="distal_plate_side_1">
      <origin xyz="0.122 0.02 0" rpy="0 0 0" />
      <geometry>
        <box size="0.074 0.008 0.032" />
        </geometry>
      <material name="brushed_steel">
        <color rgba="0.62 0.64 0.64 1" />
        </material>
      </visual>
    <visual name="distal_boss_side_1">
      <origin xyz="0.132 0.02 0" rpy="0 0 0" />
      <geometry>
        <cylinder radius="0.0085" length="0.034" />
        </geometry>
      <material name="brushed_steel">
        <color rgba="0.62 0.64 0.64 1" />
        </material>
      </visual>
    <collision name="proximal_tongue">
      <geometry>
        <box size="0.04 0.02 0.026" />
        </geometry>
      </collision>
    <collision name="proximal_bushing">
      <geometry>
        <cylinder radius="0.0115" length="0.03" />
        </geometry>
      </collision>
    <collision name="center_web">
      <origin xyz="0.0485 0 0" rpy="0 0 0" />
      <geometry>
        <box size="0.061 0.018 0.018" />
        </geometry>
      </collision>
    <collision name="distal_bridge">
      <origin xyz="0.084 0 0" rpy="0 0 0" />
      <geometry>
        <box size="0.018 0.048 0.024" />
        </geometry>
      </collision>
    <collision name="distal_plate_side_0">
      <origin xyz="0.122 -0.02 0" rpy="0 0 0" />
      <geometry>
        <box size="0.074 0.008 0.032" />
        </geometry>
      </collision>
    <collision name="distal_boss_side_0">
      <origin xyz="0.132 -0.02 0" rpy="0 0 0" />
      <geometry>
        <cylinder radius="0.0085" length="0.034" />
        </geometry>
      </collision>
    <collision name="distal_plate_side_1">
      <origin xyz="0.122 0.02 0" rpy="0 0 0" />
      <geometry>
        <box size="0.074 0.008 0.032" />
        </geometry>
      </collision>
    <collision name="distal_boss_side_1">
      <origin xyz="0.132 0.02 0" rpy="0 0 0" />
      <geometry>
        <cylinder radius="0.0085" length="0.034" />
        </geometry>
      </collision>
    </link>
  <link name="finger_1_link_2">
    <visual name="proximal_tongue">
      <geometry>
        <box size="0.04 0.02 0.026" />
        </geometry>
      <material name="anodized_blue">
        <color rgba="0.05 0.18 0.36 1" />
        </material>
      </visual>
    <visual name="proximal_bushing">
      <geometry>
        <cylinder radius="0.0115" length="0.03" />
        </geometry>
      <material name="brushed_steel">
        <color rgba="0.62 0.64 0.64 1" />
        </material>
      </visual>
    <visual name="center_web">
      <origin xyz="0.055 0 0" rpy="0 0 0" />
      <geometry>
        <box size="0.074 0.018 0.018" />
        </geometry>
      <material name="anodized_blue">
        <color rgba="0.05 0.18 0.36 1" />
        </material>
      </visual>
    <visual name="tip_nose">
      <origin xyz="0.108 0 0" rpy="0 0 0" />
      <geometry>
        <box size="0.052 0.03 0.022" />
        </geometry>
      <material name="anodized_blue">
        <color rgba="0.05 0.18 0.36 1" />
        </material>
      </visual>
    <visual name="rubber_pad">
      <origin xyz="0.134 0 0" rpy="0 0 0" />
      <geometry>
        <box size="0.02 0.038 0.026" />
        </geometry>
      <material name="matte_rubber">
        <color rgba="0.015 0.015 0.013 1" />
        </material>
      </visual>
    <visual name="rounded_tip">
      <origin xyz="0.143 0 0" rpy="1.5708 0 0" />
      <geometry>
        <cylinder radius="0.014" length="0.04" />
        </geometry>
      <material name="matte_rubber">
        <color rgba="0.015 0.015 0.013 1" />
        </material>
      </visual>
    <collision name="proximal_tongue">
      <geometry>
        <box size="0.04 0.02 0.026" />
        </geometry>
      </collision>
    <collision name="proximal_bushing">
      <geometry>
        <cylinder radius="0.0115" length="0.03" />
        </geometry>
      </collision>
    <collision name="center_web">
      <origin xyz="0.055 0 0" rpy="0 0 0" />
      <geometry>
        <box size="0.074 0.018 0.018" />
        </geometry>
      </collision>
    <collision name="tip_nose">
      <origin xyz="0.108 0 0" rpy="0 0 0" />
      <geometry>
        <box size="0.052 0.03 0.022" />
        </geometry>
      </collision>
    <collision name="rubber_pad">
      <origin xyz="0.134 0 0" rpy="0 0 0" />
      <geometry>
        <box size="0.02 0.038 0.026" />
        </geometry>
      </collision>
    <collision name="rounded_tip">
      <origin xyz="0.143 0 0" rpy="1.5708 0 0" />
      <geometry>
        <cylinder radius="0.014" length="0.04" />
        </geometry>
      </collision>
    </link>
  <joint name="finger_0_joint_0" type="revolute">
    <origin xyz="0.055 0.05 0.085" rpy="0 0 0" />
    <parent link="base" />
    <child link="finger_0_link_0" />
    <axis xyz="0 0 1" />
    <limit effort="18" velocity="2.5" lower="-0.7" upper="0.7" />
    </joint>
  <joint name="finger_0_joint_1" type="revolute">
    <origin xyz="0.15 0 0" rpy="0 0 0" />
    <parent link="finger_0_link_0" />
    <child link="finger_0_link_1" />
    <axis xyz="0 0 1" />
    <limit effort="12" velocity="2.8" lower="-0.95" upper="0.95" />
    </joint>
  <joint name="finger_0_joint_2" type="revolute">
    <origin xyz="0.132 0 0" rpy="0 0 0" />
    <parent link="finger_0_link_1" />
    <child link="finger_0_link_2" />
    <axis xyz="0 0 1" />
    <limit effort="8" velocity="3" lower="-1.05" upper="0.85" />
    </joint>
  <joint name="finger_1_joint_0" type="revolute">
    <origin xyz="0.055 -0.05 0.085" rpy="0 0 0" />
    <parent link="base" />
    <child link="finger_1_link_0" />
    <axis xyz="0 0 1" />
    <limit effort="18" velocity="2.5" lower="-0.7" upper="0.7" />
    </joint>
  <joint name="finger_1_joint_1" type="revolute">
    <origin xyz="0.15 0 0" rpy="0 0 0" />
    <parent link="finger_1_link_0" />
    <child link="finger_1_link_1" />
    <axis xyz="0 0 1" />
    <limit effort="12" velocity="2.8" lower="-0.95" upper="0.95" />
    </joint>
  <joint name="finger_1_joint_2" type="revolute">
    <origin xyz="0.132 0 0" rpy="0 0 0" />
    <parent link="finger_1_link_1" />
    <child link="finger_1_link_2" />
    <axis xyz="0 0 1" />
    <limit effort="8" velocity="3" lower="-1.05" upper="0.85" />
    </joint>
  </robot>
