<robot name="detached_round_belfry">
  <material name="warm_limestone">
    <color rgba="0.62 0.59 0.51 1" />
    </material>
  <material name="shadowed_stone">
    <color rgba="0.42 0.4 0.36 1" />
    </material>
  <material name="aged_oak">
    <color rgba="0.45 0.28 0.13 1" />
    </material>
  <material name="cast_bronze">
    <color rgba="0.68 0.43 0.18 1" />
    </material>
  <material name="dark_wrought_iron">
    <color rgba="0.08 0.08 0.075 1" />
    </material>
  <link name="tower">
    <visual name="tower_shell">
      <geometry>
        <mesh filename="assets/meshes/tower_shell.obj" />
        </geometry>
      <material name="warm_limestone">
        <color rgba="0.62 0.59 0.51 1" />
        </material>
      </visual>
    <visual name="stone_course_0">
      <geometry>
        <mesh filename="assets/meshes/stone_course_0.obj" />
        </geometry>
      <material name="warm_limestone">
        <color rgba="0.62 0.59 0.51 1" />
        </material>
      </visual>
    <visual name="stone_course_1">
      <geometry>
        <mesh filename="assets/meshes/stone_course_1.obj" />
        </geometry>
      <material name="warm_limestone">
        <color rgba="0.62 0.59 0.51 1" />
        </material>
      </visual>
    <visual name="stone_course_2">
      <geometry>
        <mesh filename="assets/meshes/stone_course_2.obj" />
        </geometry>
      <material name="warm_limestone">
        <color rgba="0.62 0.59 0.51 1" />
        </material>
      </visual>
    <visual name="stone_course_3">
      <geometry>
        <mesh filename="assets/meshes/stone_course_3.obj" />
        </geometry>
      <material name="shadowed_stone">
        <color rgba="0.42 0.4 0.36 1" />
        </material>
      </visual>
    <visual name="stone_course_4">
      <geometry>
        <mesh filename="assets/meshes/stone_course_4.obj" />
        </geometry>
      <material name="shadowed_stone">
        <color rgba="0.42 0.4 0.36 1" />
        </material>
      </visual>
    <visual name="stone_course_5">
      <geometry>
        <mesh filename="assets/meshes/stone_course_5.obj" />
        </geometry>
      <material name="warm_limestone">
        <color rgba="0.62 0.59 0.51 1" />
        </material>
      </visual>
    <visual name="stone_course_6">
      <geometry>
        <mesh filename="assets/meshes/stone_course_6.obj" />
        </geometry>
      <material name="warm_limestone">
        <color rgba="0.62 0.59 0.51 1" />
        </material>
      </visual>
    <visual name="tie_beam_pos">
      <origin xyz="0.78 0 4.25" rpy="0 0 0" />
      <geometry>
        <box size="0.38 0.95 0.18" />
        </geometry>
      <material name="aged_oak">
        <color rgba="0.45 0.28 0.13 1" />
        </material>
      </visual>
    <visual name="tie_beam_neg">
      <origin xyz="-0.78 0 4.25" rpy="0 0 0" />
      <geometry>
        <box size="0.38 0.95 0.18" />
        </geometry>
      <material name="aged_oak">
        <color rgba="0.45 0.28 0.13 1" />
        </material>
      </visual>
    <visual name="bearing_pos">
      <origin xyz="0.51 0 4.25" rpy="0 0 0" />
      <geometry>
        <box size="0.22 0.7 0.36" />
        </geometry>
      <material name="aged_oak">
        <color rgba="0.45 0.28 0.13 1" />
        </material>
      </visual>
    <visual name="bearing_neg">
      <origin xyz="-0.51 0 4.25" rpy="0 0 0" />
      <geometry>
        <box size="0.22 0.7 0.36" />
        </geometry>
      <material name="aged_oak">
        <color rgba="0.45 0.28 0.13 1" />
        </material>
      </visual>
    <collision name="tower_shell">
      <geometry>
        <mesh filename="assets/meshes/tower_shell.obj" />
        </geometry>
      </collision>
    <collision name="stone_course_0">
      <geometry>
        <mesh filename="assets/meshes/stone_course_0.obj" />
        </geometry>
      </collision>
    <collision name="stone_course_1">
      <geometry>
        <mesh filename="assets/meshes/stone_course_1.obj" />
        </geometry>
      </collision>
    <collision name="stone_course_2">
      <geometry>
        <mesh filename="assets/meshes/stone_course_2.obj" />
        </geometry>
      </collision>
    <collision name="stone_course_3">
      <geometry>
        <mesh filename="assets/meshes/stone_course_3.obj" />
        </geometry>
      </collision>
    <collision name="stone_course_4">
      <geometry>
        <mesh filename="assets/meshes/stone_course_4.obj" />
        </geometry>
      </collision>
    <collision name="stone_course_5">
      <geometry>
        <mesh filename="assets/meshes/stone_course_5.obj" />
        </geometry>
      </collision>
    <collision name="stone_course_6">
      <geometry>
        <mesh filename="assets/meshes/stone_course_6.obj" />
        </geometry>
      </collision>
    <collision name="tie_beam_pos">
      <origin xyz="0.78 0 4.25" rpy="0 0 0" />
      <geometry>
        <box size="0.38 0.95 0.18" />
        </geometry>
      </collision>
    <collision name="tie_beam_neg">
      <origin xyz="-0.78 0 4.25" rpy="0 0 0" />
      <geometry>
        <box size="0.38 0.95 0.18" />
        </geometry>
      </collision>
    <collision name="bearing_pos">
      <origin xyz="0.51 0 4.25" rpy="0 0 0" />
      <geometry>
        <box size="0.22 0.7 0.36" />
        </geometry>
      </collision>
    <collision name="bearing_neg">
      <origin xyz="-0.51 0 4.25" rpy="0 0 0" />
      <geometry>
        <box size="0.22 0.7 0.36" />
        </geometry>
      </collision>
    </link>
  <link name="bell_yoke">
    <visual name="trunnion_pin">
      <origin xyz="0 0 0" rpy="0 1.5708 0" />
      <geometry>
        <cylinder radius="0.055" length="1.12" />
        </geometry>
      <material name="dark_wrought_iron">
        <color rgba="0.08 0.08 0.075 1" />
        </material>
      </visual>
    <visual name="wooden_yoke">
      <geometry>
        <box size="0.78 0.2 0.2" />
        </geometry>
      <material name="aged_oak">
        <color rgba="0.45 0.28 0.13 1" />
        </material>
      </visual>
    <visual name="strap_0">
      <origin xyz="0.24 0 -0.25" rpy="0 0 0" />
      <geometry>
        <box size="0.08 0.13 0.42" />
        </geometry>
      <material name="dark_wrought_iron">
        <color rgba="0.08 0.08 0.075 1" />
        </material>
      </visual>
    <visual name="strap_1">
      <origin xyz="-0.24 0 -0.25" rpy="0 0 0" />
      <geometry>
        <box size="0.08 0.13 0.42" />
        </geometry>
      <material name="dark_wrought_iron">
        <color rgba="0.08 0.08 0.075 1" />
        </material>
      </visual>
    <visual name="bell_crown">
      <origin xyz="0 0 -0.31" rpy="0 0 0" />
      <geometry>
        <cylinder radius="0.18" length="0.16" />
        </geometry>
      <material name="cast_bronze">
        <color rgba="0.68 0.43 0.18 1" />
        </material>
      </visual>
    <visual name="hanger_pos">
      <origin xyz="0.12 0 -0.39" rpy="0 0 0" />
      <geometry>
        <box size="0.08 0.1 0.22" />
        </geometry>
      <material name="dark_wrought_iron">
        <color rgba="0.08 0.08 0.075 1" />
        </material>
      </visual>
    <visual name="hanger_neg">
      <origin xyz="-0.12 0 -0.39" rpy="0 0 0" />
      <geometry>
        <box size="0.08 0.1 0.22" />
        </geometry>
      <material name="dark_wrought_iron">
        <color rgba="0.08 0.08 0.075 1" />
        </material>
      </visual>
    <visual name="bell_shell">
      <geometry>
        <mesh filename="assets/meshes/bell_shell.obj" />
        </geometry>
      <material name="cast_bronze">
        <color rgba="0.68 0.43 0.18 1" />
        </material>
      </visual>
    <collision name="trunnion_pin">
      <origin xyz="0 0 0" rpy="0 1.5708 0" />
      <geometry>
        <cylinder radius="0.055" length="1.12" />
        </geometry>
      </collision>
    <collision name="wooden_yoke">
      <geometry>
        <box size="0.78 0.2 0.2" />
        </geometry>
      </collision>
    <collision name="strap_0">
      <origin xyz="0.24 0 -0.25" rpy="0 0 0" />
      <geometry>
        <box size="0.08 0.13 0.42" />
        </geometry>
      </collision>
    <collision name="strap_1">
      <origin xyz="-0.24 0 -0.25" rpy="0 0 0" />
      <geometry>
        <box size="0.08 0.13 0.42" />
        </geometry>
      </collision>
    <collision name="bell_crown">
      <origin xyz="0 0 -0.31" rpy="0 0 0" />
      <geometry>
        <cylinder radius="0.18" length="0.16" />
        </geometry>
      </collision>
    <collision name="hanger_pos">
      <origin xyz="0.12 0 -0.39" rpy="0 0 0" />
      <geometry>
        <box size="0.08 0.1 0.22" />
        </geometry>
      </collision>
    <collision name="hanger_neg">
      <origin xyz="-0.12 0 -0.39" rpy="0 0 0" />
      <geometry>
        <box size="0.08 0.1 0.22" />
        </geometry>
      </collision>
    <collision name="bell_shell">
      <geometry>
        <mesh filename="assets/meshes/bell_shell.obj" />
        </geometry>
      </collision>
    </link>
  <link name="clapper">
    <visual name="clapper_pin">
      <origin xyz="0 0 0" rpy="0 1.5708 0" />
      <geometry>
        <cylinder radius="0.025" length="0.28" />
        </geometry>
      <material name="dark_wrought_iron">
        <color rgba="0.08 0.08 0.075 1" />
        </material>
      </visual>
    <visual name="clapper_rod">
      <origin xyz="0 0 -0.34" rpy="0 0 0" />
      <geometry>
        <cylinder radius="0.02" length="0.68" />
        </geometry>
      <material name="dark_wrought_iron">
        <color rgba="0.08 0.08 0.075 1" />
        </material>
      </visual>
    <visual name="clapper_ball">
      <origin xyz="0 0 -0.72" rpy="0 0 0" />
      <geometry>
        <sphere radius="0.115" />
        </geometry>
      <material name="dark_wrought_iron">
        <color rgba="0.08 0.08 0.075 1" />
        </material>
      </visual>
    <collision name="clapper_pin">
      <origin xyz="0 0 0" rpy="0 1.5708 0" />
      <geometry>
        <cylinder radius="0.025" length="0.28" />
        </geometry>
      </collision>
    <collision name="clapper_rod">
      <origin xyz="0 0 -0.34" rpy="0 0 0" />
      <geometry>
        <cylinder radius="0.02" length="0.68" />
        </geometry>
      </collision>
    <collision name="clapper_ball">
      <origin xyz="0 0 -0.72" rpy="0 0 0" />
      <geometry>
        <sphere radius="0.115" />
        </geometry>
      </collision>
    </link>
  <joint name="bell_swing" type="revolute">
    <origin xyz="0 0 4.25" rpy="0 0 0" />
    <parent link="tower" />
    <child link="bell_yoke" />
    <axis xyz="1 0 0" />
    <limit effort="350" velocity="1.3" lower="-0.32" upper="0.32" />
    </joint>
  <joint name="clapper_pin" type="revolute">
    <origin xyz="0 0 -0.42" rpy="0 0 0" />
    <parent link="bell_yoke" />
    <child link="clapper" />
    <axis xyz="1 0 0" />
    <limit effort="18" velocity="3" lower="-0.55" upper="0.55" />
    </joint>
  </robot>
