<robot name="professional_camera_flash">
  <material name="satin_black">
    <color rgba="0.025 0.027 0.03 1" />
    </material>
  <material name="dark_plastic">
    <color rgba="0.055 0.058 0.064 1" />
    </material>
  <material name="button_rubber">
    <color rgba="0.09 0.092 0.098 1" />
    </material>
  <material name="panel_black">
    <color rgba="0.01 0.012 0.014 1" />
    </material>
  <material name="screen_glass">
    <color rgba="0.1 0.18 0.2 0.75" />
    </material>
  <material name="diffuser">
    <color rgba="0.92 0.9 0.78 0.65" />
    </material>
  <material name="brushed_metal">
    <color rgba="0.62 0.64 0.66 1" />
    </material>
  <material name="label_grey">
    <color rgba="0.42 0.43 0.45 1" />
    </material>
  <link name="body">
    <visual name="body_shell">
      <geometry>
        <mesh filename="assets/meshes/flash_body_shell.obj" />
        </geometry>
      <material name="satin_black">
        <color rgba="0.025 0.027 0.03 1" />
        </material>
      </visual>
    <visual name="mount_foot_plate">
      <origin xyz="0 0 0.006" rpy="0 0 0" />
      <geometry>
        <box size="0.06 0.088 0.012" />
        </geometry>
      <material name="dark_plastic">
        <color rgba="0.055 0.058 0.064 1" />
        </material>
      </visual>
    <visual name="mount_rail_0">
      <origin xyz="0 0.036 0.0025" rpy="0 0 0" />
      <geometry>
        <box size="0.068 0.012 0.005" />
        </geometry>
      <material name="brushed_metal">
        <color rgba="0.62 0.64 0.66 1" />
        </material>
      </visual>
    <visual name="mount_rail_1">
      <origin xyz="0 -0.036 0.0025" rpy="0 0 0" />
      <geometry>
        <box size="0.068 0.012 0.005" />
        </geometry>
      <material name="brushed_metal">
        <color rgba="0.62 0.64 0.66 1" />
        </material>
      </visual>
    <visual name="hotshoe_contact">
      <origin xyz="0 0 -0.00125" rpy="0 0 0" />
      <geometry>
        <box size="0.036 0.036 0.0025" />
        </geometry>
      <material name="brushed_metal">
        <color rgba="0.62 0.64 0.66 1" />
        </material>
      </visual>
    <visual name="rear_panel">
      <origin xyz="-0.0238 0 0.075" rpy="0 0 0" />
      <geometry>
        <box size="0.003 0.056 0.094" />
        </geometry>
      <material name="panel_black">
        <color rgba="0.01 0.012 0.014 1" />
        </material>
      </visual>
    <visual name="screen">
      <origin xyz="-0.0274 0 0.09" rpy="0 0 0" />
      <geometry>
        <box size="0.001 0.029 0.02" />
        </geometry>
      <material name="screen_glass">
        <color rgba="0.1 0.18 0.2 0.75" />
        </material>
      </visual>
    <visual name="screen_bezel">
      <origin xyz="-0.0262 0 0.09" rpy="0 0 0" />
      <geometry>
        <box size="0.0018 0.034 0.025" />
        </geometry>
      <material name="label_grey">
        <color rgba="0.42 0.43 0.45 1" />
        </material>
      </visual>
    <visual name="swivel_socket">
      <origin xyz="0 0 0.123" rpy="0 0 0" />
      <geometry>
        <cylinder radius="0.026" length="0.006" />
        </geometry>
      <material name="dark_plastic">
        <color rgba="0.055 0.058 0.064 1" />
        </material>
      </visual>
    <collision name="body_shell">
      <geometry>
        <mesh filename="assets/meshes/flash_body_shell.obj" />
        </geometry>
      </collision>
    <collision name="mount_foot_plate">
      <origin xyz="0 0 0.006" rpy="0 0 0" />
      <geometry>
        <box size="0.06 0.088 0.012" />
        </geometry>
      </collision>
    <collision name="mount_rail_0">
      <origin xyz="0 0.036 0.0025" rpy="0 0 0" />
      <geometry>
        <box size="0.068 0.012 0.005" />
        </geometry>
      </collision>
    <collision name="mount_rail_1">
      <origin xyz="0 -0.036 0.0025" rpy="0 0 0" />
      <geometry>
        <box size="0.068 0.012 0.005" />
        </geometry>
      </collision>
    <collision name="hotshoe_contact">
      <origin xyz="0 0 -0.00125" rpy="0 0 0" />
      <geometry>
        <box size="0.036 0.036 0.0025" />
        </geometry>
      </collision>
    <collision name="rear_panel">
      <origin xyz="-0.0238 0 0.075" rpy="0 0 0" />
      <geometry>
        <box size="0.003 0.056 0.094" />
        </geometry>
      </collision>
    <collision name="screen">
      <origin xyz="-0.0274 0 0.09" rpy="0 0 0" />
      <geometry>
        <box size="0.001 0.029 0.02" />
        </geometry>
      </collision>
    <collision name="screen_bezel">
      <origin xyz="-0.0262 0 0.09" rpy="0 0 0" />
      <geometry>
        <box size="0.0018 0.034 0.025" />
        </geometry>
      </collision>
    <collision name="swivel_socket">
      <origin xyz="0 0 0.123" rpy="0 0 0" />
      <geometry>
        <cylinder radius="0.026" length="0.006" />
        </geometry>
      </collision>
    </link>
  <link name="yoke">
    <visual name="swivel_disc">
      <origin xyz="0 0 0.005" rpy="0 0 0" />
      <geometry>
        <cylinder radius="0.025" length="0.01" />
        </geometry>
      <material name="dark_plastic">
        <color rgba="0.055 0.058 0.064 1" />
        </material>
      </visual>
    <visual name="swivel_neck">
      <origin xyz="0 0 0.02" rpy="0 0 0" />
      <geometry>
        <cylinder radius="0.015" length="0.02" />
        </geometry>
      <material name="dark_plastic">
        <color rgba="0.055 0.058 0.064 1" />
        </material>
      </visual>
    <visual name="yoke_bridge">
      <origin xyz="0.024 0 0.026" rpy="0 0 0" />
      <geometry>
        <box size="0.038 0.09 0.014" />
        </geometry>
      <material name="dark_plastic">
        <color rgba="0.055 0.058 0.064 1" />
        </material>
      </visual>
    <visual name="yoke_arm_0">
      <origin xyz="0.034 -0.04 0.055" rpy="0 0 0" />
      <geometry>
        <box size="0.02 0.008 0.075" />
        </geometry>
      <material name="dark_plastic">
        <color rgba="0.055 0.058 0.064 1" />
        </material>
      </visual>
    <visual name="axis_boss_0">
      <origin xyz="0.036 -0.046 0.055" rpy="1.5708 0 0" />
      <geometry>
        <cylinder radius="0.011" length="0.005" />
        </geometry>
      <material name="brushed_metal">
        <color rgba="0.62 0.64 0.66 1" />
        </material>
      </visual>
    <visual name="yoke_arm_1">
      <origin xyz="0.034 0.04 0.055" rpy="0 0 0" />
      <geometry>
        <box size="0.02 0.008 0.075" />
        </geometry>
      <material name="dark_plastic">
        <color rgba="0.055 0.058 0.064 1" />
        </material>
      </visual>
    <visual name="axis_boss_1">
      <origin xyz="0.036 0.046 0.055" rpy="1.5708 0 0" />
      <geometry>
        <cylinder radius="0.011" length="0.005" />
        </geometry>
      <material name="brushed_metal">
        <color rgba="0.62 0.64 0.66 1" />
        </material>
      </visual>
    <collision name="swivel_disc">
      <origin xyz="0 0 0.005" rpy="0 0 0" />
      <geometry>
        <cylinder radius="0.025" length="0.01" />
        </geometry>
      </collision>
    <collision name="swivel_neck">
      <origin xyz="0 0 0.02" rpy="0 0 0" />
      <geometry>
        <cylinder radius="0.015" length="0.02" />
        </geometry>
      </collision>
    <collision name="yoke_bridge">
      <origin xyz="0.024 0 0.026" rpy="0 0 0" />
      <geometry>
        <box size="0.038 0.09 0.014" />
        </geometry>
      </collision>
    <collision name="yoke_arm_0">
      <origin xyz="0.034 -0.04 0.055" rpy="0 0 0" />
      <geometry>
        <box size="0.02 0.008 0.075" />
        </geometry>
      </collision>
    <collision name="axis_boss_0">
      <origin xyz="0.036 -0.046 0.055" rpy="1.5708 0 0" />
      <geometry>
        <cylinder radius="0.011" length="0.005" />
        </geometry>
      </collision>
    <collision name="yoke_arm_1">
      <origin xyz="0.034 0.04 0.055" rpy="0 0 0" />
      <geometry>
        <box size="0.02 0.008 0.075" />
        </geometry>
      </collision>
    <collision name="axis_boss_1">
      <origin xyz="0.036 0.046 0.055" rpy="1.5708 0 0" />
      <geometry>
        <cylinder radius="0.011" length="0.005" />
        </geometry>
      </collision>
    </link>
  <link name="head">
    <visual name="head_shell">
      <geometry>
        <mesh filename="assets/meshes/flash_head_shell.obj" />
        </geometry>
      <material name="satin_black">
        <color rgba="0.025 0.027 0.03 1" />
        </material>
      </visual>
    <visual name="front_diffuser">
      <origin xyz="0.0845 0 0" rpy="0 0 0" />
      <geometry>
        <box size="0.004 0.052 0.036" />
        </geometry>
      <material name="diffuser">
        <color rgba="0.92 0.9 0.78 0.65" />
        </material>
      </visual>
    <visual name="fresnel_face">
      <origin xyz="0.0875 0 0" rpy="0 0 0" />
      <geometry>
        <box size="0.002 0.05 0.032" />
        </geometry>
      <material name="diffuser">
        <color rgba="0.92 0.9 0.78 0.65" />
        </material>
      </visual>
    <visual name="tilt_axle">
      <origin xyz="0 0 0" rpy="1.5708 0 0" />
      <geometry>
        <cylinder radius="0.0055" length="0.072" />
        </geometry>
      <material name="brushed_metal">
        <color rgba="0.62 0.64 0.66 1" />
        </material>
      </visual>
    <visual name="trunnion_cap_0">
      <origin xyz="0 -0.034 0" rpy="1.5708 0 0" />
      <geometry>
        <cylinder radius="0.009" length="0.004" />
        </geometry>
      <material name="brushed_metal">
        <color rgba="0.62 0.64 0.66 1" />
        </material>
      </visual>
    <visual name="trunnion_cap_1">
      <origin xyz="0 0.034 0" rpy="1.5708 0 0" />
      <geometry>
        <cylinder radius="0.009" length="0.004" />
        </geometry>
      <material name="brushed_metal">
        <color rgba="0.62 0.64 0.66 1" />
        </material>
      </visual>
    <collision name="head_shell">
      <geometry>
        <mesh filename="assets/meshes/flash_head_shell.obj" />
        </geometry>
      </collision>
    <collision name="front_diffuser">
      <origin xyz="0.0845 0 0" rpy="0 0 0" />
      <geometry>
        <box size="0.004 0.052 0.036" />
        </geometry>
      </collision>
    <collision name="fresnel_face">
      <origin xyz="0.0875 0 0" rpy="0 0 0" />
      <geometry>
        <box size="0.002 0.05 0.032" />
        </geometry>
      </collision>
    <collision name="tilt_axle">
      <origin xyz="0 0 0" rpy="1.5708 0 0" />
      <geometry>
        <cylinder radius="0.0055" length="0.072" />
        </geometry>
      </collision>
    <collision name="trunnion_cap_0">
      <origin xyz="0 -0.034 0" rpy="1.5708 0 0" />
      <geometry>
        <cylinder radius="0.009" length="0.004" />
        </geometry>
      </collision>
    <collision name="trunnion_cap_1">
      <origin xyz="0 0.034 0" rpy="1.5708 0 0" />
      <geometry>
        <cylinder radius="0.009" length="0.004" />
        </geometry>
      </collision>
    </link>
  <link name="button_0">
    <visual name="button_cap">
      <origin xyz="-0.0015 0 0" rpy="0 0 0" />
      <geometry>
        <box size="0.003 0.014 0.008" />
        </geometry>
      <material name="button_rubber">
        <color rgba="0.09 0.092 0.098 1" />
        </material>
      </visual>
    <visual name="button_mark">
      <origin xyz="-0.0035 0 0" rpy="0 0 0" />
      <geometry>
        <box size="0.001 0.0077 0.0028" />
        </geometry>
      <material name="label_grey">
        <color rgba="0.42 0.43 0.45 1" />
        </material>
      </visual>
    <collision name="button_cap">
      <origin xyz="-0.0015 0 0" rpy="0 0 0" />
      <geometry>
        <box size="0.003 0.014 0.008" />
        </geometry>
      </collision>
    <collision name="button_mark">
      <origin xyz="-0.0035 0 0" rpy="0 0 0" />
      <geometry>
        <box size="0.001 0.0077 0.0028" />
        </geometry>
      </collision>
    </link>
  <link name="button_1">
    <visual name="button_cap">
      <origin xyz="-0.0015 0 0" rpy="0 0 0" />
      <geometry>
        <box size="0.003 0.014 0.008" />
        </geometry>
      <material name="button_rubber">
        <color rgba="0.09 0.092 0.098 1" />
        </material>
      </visual>
    <visual name="button_mark">
      <origin xyz="-0.0035 0 0" rpy="0 0 0" />
      <geometry>
        <box size="0.001 0.0077 0.0028" />
        </geometry>
      <material name="label_grey">
        <color rgba="0.42 0.43 0.45 1" />
        </material>
      </visual>
    <collision name="button_cap">
      <origin xyz="-0.0015 0 0" rpy="0 0 0" />
      <geometry>
        <box size="0.003 0.014 0.008" />
        </geometry>
      </collision>
    <collision name="button_mark">
      <origin xyz="-0.0035 0 0" rpy="0 0 0" />
      <geometry>
        <box size="0.001 0.0077 0.0028" />
        </geometry>
      </collision>
    </link>
  <link name="button_2">
    <visual name="button_cap">
      <origin xyz="-0.0015 0 0" rpy="0 0 0" />
      <geometry>
        <box size="0.003 0.01 0.012" />
        </geometry>
      <material name="button_rubber">
        <color rgba="0.09 0.092 0.098 1" />
        </material>
      </visual>
    <visual name="button_mark">
      <origin xyz="-0.0035 0 0" rpy="0 0 0" />
      <geometry>
        <box size="0.001 0.0055 0.0042" />
        </geometry>
      <material name="label_grey">
        <color rgba="0.42 0.43 0.45 1" />
        </material>
      </visual>
    <collision name="button_cap">
      <origin xyz="-0.0015 0 0" rpy="0 0 0" />
      <geometry>
        <box size="0.003 0.01 0.012" />
        </geometry>
      </collision>
    <collision name="button_mark">
      <origin xyz="-0.0035 0 0" rpy="0 0 0" />
      <geometry>
        <box size="0.001 0.0055 0.0042" />
        </geometry>
      </collision>
    </link>
  <link name="button_3">
    <visual name="button_cap">
      <origin xyz="-0.0015 0 0" rpy="0 0 0" />
      <geometry>
        <box size="0.003 0.01 0.012" />
        </geometry>
      <material name="button_rubber">
        <color rgba="0.09 0.092 0.098 1" />
        </material>
      </visual>
    <visual name="button_mark">
      <origin xyz="-0.0035 0 0" rpy="0 0 0" />
      <geometry>
        <box size="0.001 0.0055 0.0042" />
        </geometry>
      <material name="label_grey">
        <color rgba="0.42 0.43 0.45 1" />
        </material>
      </visual>
    <collision name="button_cap">
      <origin xyz="-0.0015 0 0" rpy="0 0 0" />
      <geometry>
        <box size="0.003 0.01 0.012" />
        </geometry>
      </collision>
    <collision name="button_mark">
      <origin xyz="-0.0035 0 0" rpy="0 0 0" />
      <geometry>
        <box size="0.001 0.0055 0.0042" />
        </geometry>
      </collision>
    </link>
  <link name="button_4">
    <visual name="button_cap">
      <origin xyz="-0.0015 0 0" rpy="0 0 0" />
      <geometry>
        <box size="0.003 0.013 0.008" />
        </geometry>
      <material name="button_rubber">
        <color rgba="0.09 0.092 0.098 1" />
        </material>
      </visual>
    <visual name="button_mark">
      <origin xyz="-0.0035 0 0" rpy="0 0 0" />
      <geometry>
        <box size="0.001 0.00715 0.0028" />
        </geometry>
      <material name="label_grey">
        <color rgba="0.42 0.43 0.45 1" />
        </material>
      </visual>
    <collision name="button_cap">
      <origin xyz="-0.0015 0 0" rpy="0 0 0" />
      <geometry>
        <box size="0.003 0.013 0.008" />
        </geometry>
      </collision>
    <collision name="button_mark">
      <origin xyz="-0.0035 0 0" rpy="0 0 0" />
      <geometry>
        <box size="0.001 0.00715 0.0028" />
        </geometry>
      </collision>
    </link>
  <link name="button_5">
    <visual name="button_cap">
      <origin xyz="-0.0015 0 0" rpy="0 0 0" />
      <geometry>
        <box size="0.003 0.013 0.008" />
        </geometry>
      <material name="button_rubber">
        <color rgba="0.09 0.092 0.098 1" />
        </material>
      </visual>
    <visual name="button_mark">
      <origin xyz="-0.0035 0 0" rpy="0 0 0" />
      <geometry>
        <box size="0.001 0.00715 0.0028" />
        </geometry>
      <material name="label_grey">
        <color rgba="0.42 0.43 0.45 1" />
        </material>
      </visual>
    <collision name="button_cap">
      <origin xyz="-0.0015 0 0" rpy="0 0 0" />
      <geometry>
        <box size="0.003 0.013 0.008" />
        </geometry>
      </collision>
    <collision name="button_mark">
      <origin xyz="-0.0035 0 0" rpy="0 0 0" />
      <geometry>
        <box size="0.001 0.00715 0.0028" />
        </geometry>
      </collision>
    </link>
  <link name="button_6">
    <visual name="button_cap">
      <origin xyz="-0.0015 0 0" rpy="0 0 0" />
      <geometry>
        <box size="0.003 0.012 0.007" />
        </geometry>
      <material name="button_rubber">
        <color rgba="0.09 0.092 0.098 1" />
        </material>
      </visual>
    <visual name="button_mark">
      <origin xyz="-0.0035 0 0" rpy="0 0 0" />
      <geometry>
        <box size="0.001 0.0066 0.00245" />
        </geometry>
      <material name="label_grey">
        <color rgba="0.42 0.43 0.45 1" />
        </material>
      </visual>
    <collision name="button_cap">
      <origin xyz="-0.0015 0 0" rpy="0 0 0" />
      <geometry>
        <box size="0.003 0.012 0.007" />
        </geometry>
      </collision>
    <collision name="button_mark">
      <origin xyz="-0.0035 0 0" rpy="0 0 0" />
      <geometry>
        <box size="0.001 0.0066 0.00245" />
        </geometry>
      </collision>
    </link>
  <link name="button_7">
    <visual name="button_cap">
      <origin xyz="-0.0015 0 0" rpy="0 0 0" />
      <geometry>
        <box size="0.003 0.012 0.007" />
        </geometry>
      <material name="button_rubber">
        <color rgba="0.09 0.092 0.098 1" />
        </material>
      </visual>
    <visual name="button_mark">
      <origin xyz="-0.0035 0 0" rpy="0 0 0" />
      <geometry>
        <box size="0.001 0.0066 0.00245" />
        </geometry>
      <material name="label_grey">
        <color rgba="0.42 0.43 0.45 1" />
        </material>
      </visual>
    <collision name="button_cap">
      <origin xyz="-0.0015 0 0" rpy="0 0 0" />
      <geometry>
        <box size="0.003 0.012 0.007" />
        </geometry>
      </collision>
    <collision name="button_mark">
      <origin xyz="-0.0035 0 0" rpy="0 0 0" />
      <geometry>
        <box size="0.001 0.0066 0.00245" />
        </geometry>
      </collision>
    </link>
  <joint name="body_to_yoke" type="revolute">
    <origin xyz="0 0 0.126" rpy="0 0 0" />
    <parent link="body" />
    <child link="yoke" />
    <axis xyz="0 0 1" />
    <limit effort="4" velocity="2.4" lower="-3.14159" upper="3.14159" />
    </joint>
  <joint name="yoke_to_head" type="revolute">
    <origin xyz="0.036 0 0.055" rpy="0 0 0" />
    <parent link="yoke" />
    <child link="head" />
    <axis xyz="0 -1 0" />
    <limit effort="3" velocity="2" lower="-0.25" upper="1.35" />
    </joint>
  <joint name="body_to_button_0" type="prismatic">
    <origin xyz="-0.0253 0 0.116" rpy="0 0 0" />
    <parent link="body" />
    <child link="button_0" />
    <axis xyz="1 0 0" />
    <limit effort="0.6" velocity="0.06" lower="0" upper="0.0025" />
    </joint>
  <joint name="body_to_button_1" type="prismatic">
    <origin xyz="-0.0253 0 0.064" rpy="0 0 0" />
    <parent link="body" />
    <child link="button_1" />
    <axis xyz="1 0 0" />
    <limit effort="0.6" velocity="0.06" lower="0" upper="0.0025" />
    </joint>
  <joint name="body_to_button_2" type="prismatic">
    <origin xyz="-0.0253 -0.023 0.09" rpy="0 0 0" />
    <parent link="body" />
    <child link="button_2" />
    <axis xyz="1 0 0" />
    <limit effort="0.6" velocity="0.06" lower="0" upper="0.0025" />
    </joint>
  <joint name="body_to_button_3" type="prismatic">
    <origin xyz="-0.0253 0.023 0.09" rpy="0 0 0" />
    <parent link="body" />
    <child link="button_3" />
    <axis xyz="1 0 0" />
    <limit effort="0.6" velocity="0.06" lower="0" upper="0.0025" />
    </joint>
  <joint name="body_to_button_4" type="prismatic">
    <origin xyz="-0.0253 -0.018 0.048" rpy="0 0 0" />
    <parent link="body" />
    <child link="button_4" />
    <axis xyz="1 0 0" />
    <limit effort="0.6" velocity="0.06" lower="0" upper="0.0025" />
    </joint>
  <joint name="body_to_button_5" type="prismatic">
    <origin xyz="-0.0253 0.018 0.048" rpy="0 0 0" />
    <parent link="body" />
    <child link="button_5" />
    <axis xyz="1 0 0" />
    <limit effort="0.6" velocity="0.06" lower="0" upper="0.0025" />
    </joint>
  <joint name="body_to_button_6" type="prismatic">
    <origin xyz="-0.0253 -0.016 0.03" rpy="0 0 0" />
    <parent link="body" />
    <child link="button_6" />
    <axis xyz="1 0 0" />
    <limit effort="0.6" velocity="0.06" lower="0" upper="0.0025" />
    </joint>
  <joint name="body_to_button_7" type="prismatic">
    <origin xyz="-0.0253 0.016 0.03" rpy="0 0 0" />
    <parent link="body" />
    <child link="button_7" />
    <axis xyz="1 0 0" />
    <limit effort="0.6" velocity="0.06" lower="0" upper="0.0025" />
    </joint>
  </robot>
