<robot name="two_door_shaker_base_cabinet">
  <material name="warm_maple">
    <color rgba="0.72 0.52 0.34 1" />
    </material>
  <material name="painted_ivory">
    <color rgba="0.86 0.84 0.76 1" />
    </material>
  <material name="recessed_panel_shadow">
    <color rgba="0.78 0.76 0.68 1" />
    </material>
  <material name="aged_brass_hinges">
    <color rgba="0.72 0.52 0.18 1" />
    </material>
  <material name="dark_reveal">
    <color rgba="0.08 0.07 0.055 1" />
    </material>
  <material name="brushed_dark_knob">
    <color rgba="0.18 0.16 0.14 1" />
    </material>
  <link name="carcass">
    <visual name="side_panel_0">
      <origin xyz="-0.4825 0 0.4" rpy="0 0 0" />
      <geometry>
        <box size="0.035 0.55 0.8" />
        </geometry>
      <material name="warm_maple">
        <color rgba="0.72 0.52 0.34 1" />
        </material>
      </visual>
    <visual name="side_panel_1">
      <origin xyz="0.4825 0 0.4" rpy="0 0 0" />
      <geometry>
        <box size="0.035 0.55 0.8" />
        </geometry>
      <material name="warm_maple">
        <color rgba="0.72 0.52 0.34 1" />
        </material>
      </visual>
    <visual name="bottom_panel">
      <origin xyz="0 0 0.0175" rpy="0 0 0" />
      <geometry>
        <box size="1 0.55 0.035" />
        </geometry>
      <material name="warm_maple">
        <color rgba="0.72 0.52 0.34 1" />
        </material>
      </visual>
    <visual name="top_panel">
      <origin xyz="0 0 0.7825" rpy="0 0 0" />
      <geometry>
        <box size="1 0.55 0.035" />
        </geometry>
      <material name="warm_maple">
        <color rgba="0.72 0.52 0.34 1" />
        </material>
      </visual>
    <visual name="back_panel">
      <origin xyz="0 0.2625 0.4" rpy="0 0 0" />
      <geometry>
        <box size="1 0.025 0.8" />
        </geometry>
      <material name="warm_maple">
        <color rgba="0.72 0.52 0.34 1" />
        </material>
      </visual>
    <visual name="open_shadow">
      <origin xyz="0 -0.269 0.4" rpy="0 0 0" />
      <geometry>
        <box size="0.93 0.006 0.73" />
        </geometry>
      <material name="dark_reveal">
        <color rgba="0.08 0.07 0.055 1" />
        </material>
      </visual>
    <visual name="hinge_side_plate_0_0">
      <origin xyz="-0.502 -0.261 0.22" rpy="0 0 0" />
      <geometry>
        <box size="0.006 0.064 0.126" />
        </geometry>
      <material name="aged_brass_hinges">
        <color rgba="0.72 0.52 0.18 1" />
        </material>
      </visual>
    <visual name="hinge_fixed_knuckle_0_0_0">
      <origin xyz="-0.493 -0.291 0.1675" rpy="0 0 0" />
      <geometry>
        <cylinder radius="0.008" length="0.025" />
        </geometry>
      <material name="aged_brass_hinges">
        <color rgba="0.72 0.52 0.18 1" />
        </material>
      </visual>
    <visual name="hinge_fixed_knuckle_0_0_1">
      <origin xyz="-0.493 -0.291 0.22" rpy="0 0 0" />
      <geometry>
        <cylinder radius="0.008" length="0.025" />
        </geometry>
      <material name="aged_brass_hinges">
        <color rgba="0.72 0.52 0.18 1" />
        </material>
      </visual>
    <visual name="hinge_fixed_knuckle_0_0_2">
      <origin xyz="-0.493 -0.291 0.2725" rpy="0 0 0" />
      <geometry>
        <cylinder radius="0.008" length="0.025" />
        </geometry>
      <material name="aged_brass_hinges">
        <color rgba="0.72 0.52 0.18 1" />
        </material>
      </visual>
    <visual name="hinge_side_plate_0_1">
      <origin xyz="-0.502 -0.261 0.58" rpy="0 0 0" />
      <geometry>
        <box size="0.006 0.064 0.126" />
        </geometry>
      <material name="aged_brass_hinges">
        <color rgba="0.72 0.52 0.18 1" />
        </material>
      </visual>
    <visual name="hinge_fixed_knuckle_0_1_0">
      <origin xyz="-0.493 -0.291 0.5275" rpy="0 0 0" />
      <geometry>
        <cylinder radius="0.008" length="0.025" />
        </geometry>
      <material name="aged_brass_hinges">
        <color rgba="0.72 0.52 0.18 1" />
        </material>
      </visual>
    <visual name="hinge_fixed_knuckle_0_1_1">
      <origin xyz="-0.493 -0.291 0.58" rpy="0 0 0" />
      <geometry>
        <cylinder radius="0.008" length="0.025" />
        </geometry>
      <material name="aged_brass_hinges">
        <color rgba="0.72 0.52 0.18 1" />
        </material>
      </visual>
    <visual name="hinge_fixed_knuckle_0_1_2">
      <origin xyz="-0.493 -0.291 0.6325" rpy="0 0 0" />
      <geometry>
        <cylinder radius="0.008" length="0.025" />
        </geometry>
      <material name="aged_brass_hinges">
        <color rgba="0.72 0.52 0.18 1" />
        </material>
      </visual>
    <visual name="hinge_side_plate_1_0">
      <origin xyz="0.502 -0.261 0.22" rpy="0 0 0" />
      <geometry>
        <box size="0.006 0.064 0.126" />
        </geometry>
      <material name="aged_brass_hinges">
        <color rgba="0.72 0.52 0.18 1" />
        </material>
      </visual>
    <visual name="hinge_fixed_knuckle_1_0_0">
      <origin xyz="0.493 -0.291 0.1675" rpy="0 0 0" />
      <geometry>
        <cylinder radius="0.008" length="0.025" />
        </geometry>
      <material name="aged_brass_hinges">
        <color rgba="0.72 0.52 0.18 1" />
        </material>
      </visual>
    <visual name="hinge_fixed_knuckle_1_0_1">
      <origin xyz="0.493 -0.291 0.22" rpy="0 0 0" />
      <geometry>
        <cylinder radius="0.008" length="0.025" />
        </geometry>
      <material name="aged_brass_hinges">
        <color rgba="0.72 0.52 0.18 1" />
        </material>
      </visual>
    <visual name="hinge_fixed_knuckle_1_0_2">
      <origin xyz="0.493 -0.291 0.2725" rpy="0 0 0" />
      <geometry>
        <cylinder radius="0.008" length="0.025" />
        </geometry>
      <material name="aged_brass_hinges">
        <color rgba="0.72 0.52 0.18 1" />
        </material>
      </visual>
    <visual name="hinge_side_plate_1_1">
      <origin xyz="0.502 -0.261 0.58" rpy="0 0 0" />
      <geometry>
        <box size="0.006 0.064 0.126" />
        </geometry>
      <material name="aged_brass_hinges">
        <color rgba="0.72 0.52 0.18 1" />
        </material>
      </visual>
    <visual name="hinge_fixed_knuckle_1_1_0">
      <origin xyz="0.493 -0.291 0.5275" rpy="0 0 0" />
      <geometry>
        <cylinder radius="0.008" length="0.025" />
        </geometry>
      <material name="aged_brass_hinges">
        <color rgba="0.72 0.52 0.18 1" />
        </material>
      </visual>
    <visual name="hinge_fixed_knuckle_1_1_1">
      <origin xyz="0.493 -0.291 0.58" rpy="0 0 0" />
      <geometry>
        <cylinder radius="0.008" length="0.025" />
        </geometry>
      <material name="aged_brass_hinges">
        <color rgba="0.72 0.52 0.18 1" />
        </material>
      </visual>
    <visual name="hinge_fixed_knuckle_1_1_2">
      <origin xyz="0.493 -0.291 0.6325" rpy="0 0 0" />
      <geometry>
        <cylinder radius="0.008" length="0.025" />
        </geometry>
      <material name="aged_brass_hinges">
        <color rgba="0.72 0.52 0.18 1" />
        </material>
      </visual>
    <collision name="side_panel_0">
      <origin xyz="-0.4825 0 0.4" rpy="0 0 0" />
      <geometry>
        <box size="0.035 0.55 0.8" />
        </geometry>
      </collision>
    <collision name="side_panel_1">
      <origin xyz="0.4825 0 0.4" rpy="0 0 0" />
      <geometry>
        <box size="0.035 0.55 0.8" />
        </geometry>
      </collision>
    <collision name="bottom_panel">
      <origin xyz="0 0 0.0175" rpy="0 0 0" />
      <geometry>
        <box size="1 0.55 0.035" />
        </geometry>
      </collision>
    <collision name="top_panel">
      <origin xyz="0 0 0.7825" rpy="0 0 0" />
      <geometry>
        <box size="1 0.55 0.035" />
        </geometry>
      </collision>
    <collision name="back_panel">
      <origin xyz="0 0.2625 0.4" rpy="0 0 0" />
      <geometry>
        <box size="1 0.025 0.8" />
        </geometry>
      </collision>
    <collision name="open_shadow">
      <origin xyz="0 -0.269 0.4" rpy="0 0 0" />
      <geometry>
        <box size="0.93 0.006 0.73" />
        </geometry>
      </collision>
    <collision name="hinge_side_plate_0_0">
      <origin xyz="-0.502 -0.261 0.22" rpy="0 0 0" />
      <geometry>
        <box size="0.006 0.064 0.126" />
        </geometry>
      </collision>
    <collision name="hinge_fixed_knuckle_0_0_0">
      <origin xyz="-0.493 -0.291 0.1675" rpy="0 0 0" />
      <geometry>
        <cylinder radius="0.008" length="0.025" />
        </geometry>
      </collision>
    <collision name="hinge_fixed_knuckle_0_0_1">
      <origin xyz="-0.493 -0.291 0.22" rpy="0 0 0" />
      <geometry>
        <cylinder radius="0.008" length="0.025" />
        </geometry>
      </collision>
    <collision name="hinge_fixed_knuckle_0_0_2">
      <origin xyz="-0.493 -0.291 0.2725" rpy="0 0 0" />
      <geometry>
        <cylinder radius="0.008" length="0.025" />
        </geometry>
      </collision>
    <collision name="hinge_side_plate_0_1">
      <origin xyz="-0.502 -0.261 0.58" rpy="0 0 0" />
      <geometry>
        <box size="0.006 0.064 0.126" />
        </geometry>
      </collision>
    <collision name="hinge_fixed_knuckle_0_1_0">
      <origin xyz="-0.493 -0.291 0.5275" rpy="0 0 0" />
      <geometry>
        <cylinder radius="0.008" length="0.025" />
        </geometry>
      </collision>
    <collision name="hinge_fixed_knuckle_0_1_1">
      <origin xyz="-0.493 -0.291 0.58" rpy="0 0 0" />
      <geometry>
        <cylinder radius="0.008" length="0.025" />
        </geometry>
      </collision>
    <collision name="hinge_fixed_knuckle_0_1_2">
      <origin xyz="-0.493 -0.291 0.6325" rpy="0 0 0" />
      <geometry>
        <cylinder radius="0.008" length="0.025" />
        </geometry>
      </collision>
    <collision name="hinge_side_plate_1_0">
      <origin xyz="0.502 -0.261 0.22" rpy="0 0 0" />
      <geometry>
        <box size="0.006 0.064 0.126" />
        </geometry>
      </collision>
    <collision name="hinge_fixed_knuckle_1_0_0">
      <origin xyz="0.493 -0.291 0.1675" rpy="0 0 0" />
      <geometry>
        <cylinder radius="0.008" length="0.025" />
        </geometry>
      </collision>
    <collision name="hinge_fixed_knuckle_1_0_1">
      <origin xyz="0.493 -0.291 0.22" rpy="0 0 0" />
      <geometry>
        <cylinder radius="0.008" length="0.025" />
        </geometry>
      </collision>
    <collision name="hinge_fixed_knuckle_1_0_2">
      <origin xyz="0.493 -0.291 0.2725" rpy="0 0 0" />
      <geometry>
        <cylinder radius="0.008" length="0.025" />
        </geometry>
      </collision>
    <collision name="hinge_side_plate_1_1">
      <origin xyz="0.502 -0.261 0.58" rpy="0 0 0" />
      <geometry>
        <box size="0.006 0.064 0.126" />
        </geometry>
      </collision>
    <collision name="hinge_fixed_knuckle_1_1_0">
      <origin xyz="0.493 -0.291 0.5275" rpy="0 0 0" />
      <geometry>
        <cylinder radius="0.008" length="0.025" />
        </geometry>
      </collision>
    <collision name="hinge_fixed_knuckle_1_1_1">
      <origin xyz="0.493 -0.291 0.58" rpy="0 0 0" />
      <geometry>
        <cylinder radius="0.008" length="0.025" />
        </geometry>
      </collision>
    <collision name="hinge_fixed_knuckle_1_1_2">
      <origin xyz="0.493 -0.291 0.6325" rpy="0 0 0" />
      <geometry>
        <cylinder radius="0.008" length="0.025" />
        </geometry>
      </collision>
    </link>
  <link name="door_0">
    <visual name="door_slab">
      <origin xyz="0.25 0 0.4" rpy="0 0 0" />
      <geometry>
        <box size="0.472 0.022 0.72" />
        </geometry>
      <material name="painted_ivory">
        <color rgba="0.86 0.84 0.76 1" />
        </material>
      </visual>
    <visual name="outer_stile">
      <origin xyz="0.045 -0.0145 0.4" rpy="0 0 0" />
      <geometry>
        <box size="0.062 0.011 0.72" />
        </geometry>
      <material name="painted_ivory">
        <color rgba="0.86 0.84 0.76 1" />
        </material>
      </visual>
    <visual name="inner_stile">
      <origin xyz="0.455 -0.0145 0.4" rpy="0 0 0" />
      <geometry>
        <box size="0.062 0.011 0.72" />
        </geometry>
      <material name="painted_ivory">
        <color rgba="0.86 0.84 0.76 1" />
        </material>
      </visual>
    <visual name="top_rail">
      <origin xyz="0.25 -0.0145 0.725" rpy="0 0 0" />
      <geometry>
        <box size="0.472 0.011 0.07" />
        </geometry>
      <material name="painted_ivory">
        <color rgba="0.86 0.84 0.76 1" />
        </material>
      </visual>
    <visual name="bottom_rail">
      <origin xyz="0.25 -0.0145 0.075" rpy="0 0 0" />
      <geometry>
        <box size="0.472 0.011 0.07" />
        </geometry>
      <material name="painted_ivory">
        <color rgba="0.86 0.84 0.76 1" />
        </material>
      </visual>
    <visual name="recessed_panel">
      <origin xyz="0.25 -0.012 0.4" rpy="0 0 0" />
      <geometry>
        <box size="0.348 0.006 0.58" />
        </geometry>
      <material name="recessed_panel_shadow">
        <color rgba="0.78 0.76 0.68 1" />
        </material>
      </visual>
    <visual name="hinge_leaf_0">
      <origin xyz="0.041 -0.01 0.22" rpy="0 0 0" />
      <geometry>
        <box size="0.065 0.005 0.118" />
        </geometry>
      <material name="aged_brass_hinges">
        <color rgba="0.72 0.52 0.18 1" />
        </material>
      </visual>
    <visual name="hinge_door_knuckle_0_0">
      <origin xyz="0 0 0.1935" rpy="0 0 0" />
      <geometry>
        <cylinder radius="0.009" length="0.022" />
        </geometry>
      <material name="aged_brass_hinges">
        <color rgba="0.72 0.52 0.18 1" />
        </material>
      </visual>
    <visual name="hinge_knuckle_bridge_0_0">
      <origin xyz="0.012 -0.0075 0.1935" rpy="0 0 0" />
      <geometry>
        <box size="0.014 0.008 0.018" />
        </geometry>
      <material name="aged_brass_hinges">
        <color rgba="0.72 0.52 0.18 1" />
        </material>
      </visual>
    <visual name="hinge_door_knuckle_0_1">
      <origin xyz="0 0 0.2465" rpy="0 0 0" />
      <geometry>
        <cylinder radius="0.009" length="0.022" />
        </geometry>
      <material name="aged_brass_hinges">
        <color rgba="0.72 0.52 0.18 1" />
        </material>
      </visual>
    <visual name="hinge_knuckle_bridge_0_1">
      <origin xyz="0.012 -0.0075 0.2465" rpy="0 0 0" />
      <geometry>
        <box size="0.014 0.008 0.018" />
        </geometry>
      <material name="aged_brass_hinges">
        <color rgba="0.72 0.52 0.18 1" />
        </material>
      </visual>
    <visual name="hinge_leaf_1">
      <origin xyz="0.041 -0.01 0.58" rpy="0 0 0" />
      <geometry>
        <box size="0.065 0.005 0.118" />
        </geometry>
      <material name="aged_brass_hinges">
        <color rgba="0.72 0.52 0.18 1" />
        </material>
      </visual>
    <visual name="hinge_door_knuckle_1_0">
      <origin xyz="0 0 0.5535" rpy="0 0 0" />
      <geometry>
        <cylinder radius="0.009" length="0.022" />
        </geometry>
      <material name="aged_brass_hinges">
        <color rgba="0.72 0.52 0.18 1" />
        </material>
      </visual>
    <visual name="hinge_knuckle_bridge_1_0">
      <origin xyz="0.012 -0.0075 0.5535" rpy="0 0 0" />
      <geometry>
        <box size="0.014 0.008 0.018" />
        </geometry>
      <material name="aged_brass_hinges">
        <color rgba="0.72 0.52 0.18 1" />
        </material>
      </visual>
    <visual name="hinge_door_knuckle_1_1">
      <origin xyz="0 0 0.6065" rpy="0 0 0" />
      <geometry>
        <cylinder radius="0.009" length="0.022" />
        </geometry>
      <material name="aged_brass_hinges">
        <color rgba="0.72 0.52 0.18 1" />
        </material>
      </visual>
    <visual name="hinge_knuckle_bridge_1_1">
      <origin xyz="0.012 -0.0075 0.6065" rpy="0 0 0" />
      <geometry>
        <box size="0.014 0.008 0.018" />
        </geometry>
      <material name="aged_brass_hinges">
        <color rgba="0.72 0.52 0.18 1" />
        </material>
      </visual>
    <collision name="door_slab">
      <origin xyz="0.25 0 0.4" rpy="0 0 0" />
      <geometry>
        <box size="0.472 0.022 0.72" />
        </geometry>
      </collision>
    <collision name="outer_stile">
      <origin xyz="0.045 -0.0145 0.4" rpy="0 0 0" />
      <geometry>
        <box size="0.062 0.011 0.72" />
        </geometry>
      </collision>
    <collision name="inner_stile">
      <origin xyz="0.455 -0.0145 0.4" rpy="0 0 0" />
      <geometry>
        <box size="0.062 0.011 0.72" />
        </geometry>
      </collision>
    <collision name="top_rail">
      <origin xyz="0.25 -0.0145 0.725" rpy="0 0 0" />
      <geometry>
        <box size="0.472 0.011 0.07" />
        </geometry>
      </collision>
    <collision name="bottom_rail">
      <origin xyz="0.25 -0.0145 0.075" rpy="0 0 0" />
      <geometry>
        <box size="0.472 0.011 0.07" />
        </geometry>
      </collision>
    <collision name="recessed_panel">
      <origin xyz="0.25 -0.012 0.4" rpy="0 0 0" />
      <geometry>
        <box size="0.348 0.006 0.58" />
        </geometry>
      </collision>
    <collision name="hinge_leaf_0">
      <origin xyz="0.041 -0.01 0.22" rpy="0 0 0" />
      <geometry>
        <box size="0.065 0.005 0.118" />
        </geometry>
      </collision>
    <collision name="hinge_door_knuckle_0_0">
      <origin xyz="0 0 0.1935" rpy="0 0 0" />
      <geometry>
        <cylinder radius="0.009" length="0.022" />
        </geometry>
      </collision>
    <collision name="hinge_knuckle_bridge_0_0">
      <origin xyz="0.012 -0.0075 0.1935" rpy="0 0 0" />
      <geometry>
        <box size="0.014 0.008 0.018" />
        </geometry>
      </collision>
    <collision name="hinge_door_knuckle_0_1">
      <origin xyz="0 0 0.2465" rpy="0 0 0" />
      <geometry>
        <cylinder radius="0.009" length="0.022" />
        </geometry>
      </collision>
    <collision name="hinge_knuckle_bridge_0_1">
      <origin xyz="0.012 -0.0075 0.2465" rpy="0 0 0" />
      <geometry>
        <box size="0.014 0.008 0.018" />
        </geometry>
      </collision>
    <collision name="hinge_leaf_1">
      <origin xyz="0.041 -0.01 0.58" rpy="0 0 0" />
      <geometry>
        <box size="0.065 0.005 0.118" />
        </geometry>
      </collision>
    <collision name="hinge_door_knuckle_1_0">
      <origin xyz="0 0 0.5535" rpy="0 0 0" />
      <geometry>
        <cylinder radius="0.009" length="0.022" />
        </geometry>
      </collision>
    <collision name="hinge_knuckle_bridge_1_0">
      <origin xyz="0.012 -0.0075 0.5535" rpy="0 0 0" />
      <geometry>
        <box size="0.014 0.008 0.018" />
        </geometry>
      </collision>
    <collision name="hinge_door_knuckle_1_1">
      <origin xyz="0 0 0.6065" rpy="0 0 0" />
      <geometry>
        <cylinder radius="0.009" length="0.022" />
        </geometry>
      </collision>
    <collision name="hinge_knuckle_bridge_1_1">
      <origin xyz="0.012 -0.0075 0.6065" rpy="0 0 0" />
      <geometry>
        <box size="0.014 0.008 0.018" />
        </geometry>
      </collision>
    </link>
  <link name="door_1">
    <visual name="door_slab">
      <origin xyz="-0.25 0 0.4" rpy="0 0 0" />
      <geometry>
        <box size="0.472 0.022 0.72" />
        </geometry>
      <material name="painted_ivory">
        <color rgba="0.86 0.84 0.76 1" />
        </material>
      </visual>
    <visual name="outer_stile">
      <origin xyz="-0.045 -0.0145 0.4" rpy="0 0 0" />
      <geometry>
        <box size="0.062 0.011 0.72" />
        </geometry>
      <material name="painted_ivory">
        <color rgba="0.86 0.84 0.76 1" />
        </material>
      </visual>
    <visual name="inner_stile">
      <origin xyz="-0.455 -0.0145 0.4" rpy="0 0 0" />
      <geometry>
        <box size="0.062 0.011 0.72" />
        </geometry>
      <material name="painted_ivory">
        <color rgba="0.86 0.84 0.76 1" />
        </material>
      </visual>
    <visual name="top_rail">
      <origin xyz="-0.25 -0.0145 0.725" rpy="0 0 0" />
      <geometry>
        <box size="0.472 0.011 0.07" />
        </geometry>
      <material name="painted_ivory">
        <color rgba="0.86 0.84 0.76 1" />
        </material>
      </visual>
    <visual name="bottom_rail">
      <origin xyz="-0.25 -0.0145 0.075" rpy="0 0 0" />
      <geometry>
        <box size="0.472 0.011 0.07" />
        </geometry>
      <material name="painted_ivory">
        <color rgba="0.86 0.84 0.76 1" />
        </material>
      </visual>
    <visual name="recessed_panel">
      <origin xyz="-0.25 -0.012 0.4" rpy="0 0 0" />
      <geometry>
        <box size="0.348 0.006 0.58" />
        </geometry>
      <material name="recessed_panel_shadow">
        <color rgba="0.78 0.76 0.68 1" />
        </material>
      </visual>
    <visual name="hinge_leaf_0">
      <origin xyz="-0.041 -0.01 0.22" rpy="0 0 0" />
      <geometry>
        <box size="0.065 0.005 0.118" />
        </geometry>
      <material name="aged_brass_hinges">
        <color rgba="0.72 0.52 0.18 1" />
        </material>
      </visual>
    <visual name="hinge_door_knuckle_0_0">
      <origin xyz="0 0 0.1935" rpy="0 0 0" />
      <geometry>
        <cylinder radius="0.009" length="0.022" />
        </geometry>
      <material name="aged_brass_hinges">
        <color rgba="0.72 0.52 0.18 1" />
        </material>
      </visual>
    <visual name="hinge_knuckle_bridge_0_0">
      <origin xyz="-0.012 -0.0075 0.1935" rpy="0 0 0" />
      <geometry>
        <box size="0.014 0.008 0.018" />
        </geometry>
      <material name="aged_brass_hinges">
        <color rgba="0.72 0.52 0.18 1" />
        </material>
      </visual>
    <visual name="hinge_door_knuckle_0_1">
      <origin xyz="0 0 0.2465" rpy="0 0 0" />
      <geometry>
        <cylinder radius="0.009" length="0.022" />
        </geometry>
      <material name="aged_brass_hinges">
        <color rgba="0.72 0.52 0.18 1" />
        </material>
      </visual>
    <visual name="hinge_knuckle_bridge_0_1">
      <origin xyz="-0.012 -0.0075 0.2465" rpy="0 0 0" />
      <geometry>
        <box size="0.014 0.008 0.018" />
        </geometry>
      <material name="aged_brass_hinges">
        <color rgba="0.72 0.52 0.18 1" />
        </material>
      </visual>
    <visual name="hinge_leaf_1">
      <origin xyz="-0.041 -0.01 0.58" rpy="0 0 0" />
      <geometry>
        <box size="0.065 0.005 0.118" />
        </geometry>
      <material name="aged_brass_hinges">
        <color rgba="0.72 0.52 0.18 1" />
        </material>
      </visual>
    <visual name="hinge_door_knuckle_1_0">
      <origin xyz="0 0 0.5535" rpy="0 0 0" />
      <geometry>
        <cylinder radius="0.009" length="0.022" />
        </geometry>
      <material name="aged_brass_hinges">
        <color rgba="0.72 0.52 0.18 1" />
        </material>
      </visual>
    <visual name="hinge_knuckle_bridge_1_0">
      <origin xyz="-0.012 -0.0075 0.5535" rpy="0 0 0" />
      <geometry>
        <box size="0.014 0.008 0.018" />
        </geometry>
      <material name="aged_brass_hinges">
        <color rgba="0.72 0.52 0.18 1" />
        </material>
      </visual>
    <visual name="hinge_door_knuckle_1_1">
      <origin xyz="0 0 0.6065" rpy="0 0 0" />
      <geometry>
        <cylinder radius="0.009" length="0.022" />
        </geometry>
      <material name="aged_brass_hinges">
        <color rgba="0.72 0.52 0.18 1" />
        </material>
      </visual>
    <visual name="hinge_knuckle_bridge_1_1">
      <origin xyz="-0.012 -0.0075 0.6065" rpy="0 0 0" />
      <geometry>
        <box size="0.014 0.008 0.018" />
        </geometry>
      <material name="aged_brass_hinges">
        <color rgba="0.72 0.52 0.18 1" />
        </material>
      </visual>
    <collision name="door_slab">
      <origin xyz="-0.25 0 0.4" rpy="0 0 0" />
      <geometry>
        <box size="0.472 0.022 0.72" />
        </geometry>
      </collision>
    <collision name="outer_stile">
      <origin xyz="-0.045 -0.0145 0.4" rpy="0 0 0" />
      <geometry>
        <box size="0.062 0.011 0.72" />
        </geometry>
      </collision>
    <collision name="inner_stile">
      <origin xyz="-0.455 -0.0145 0.4" rpy="0 0 0" />
      <geometry>
        <box size="0.062 0.011 0.72" />
        </geometry>
      </collision>
    <collision name="top_rail">
      <origin xyz="-0.25 -0.0145 0.725" rpy="0 0 0" />
      <geometry>
        <box size="0.472 0.011 0.07" />
        </geometry>
      </collision>
    <collision name="bottom_rail">
      <origin xyz="-0.25 -0.0145 0.075" rpy="0 0 0" />
      <geometry>
        <box size="0.472 0.011 0.07" />
        </geometry>
      </collision>
    <collision name="recessed_panel">
      <origin xyz="-0.25 -0.012 0.4" rpy="0 0 0" />
      <geometry>
        <box size="0.348 0.006 0.58" />
        </geometry>
      </collision>
    <collision name="hinge_leaf_0">
      <origin xyz="-0.041 -0.01 0.22" rpy="0 0 0" />
      <geometry>
        <box size="0.065 0.005 0.118" />
        </geometry>
      </collision>
    <collision name="hinge_door_knuckle_0_0">
      <origin xyz="0 0 0.1935" rpy="0 0 0" />
      <geometry>
        <cylinder radius="0.009" length="0.022" />
        </geometry>
      </collision>
    <collision name="hinge_knuckle_bridge_0_0">
      <origin xyz="-0.012 -0.0075 0.1935" rpy="0 0 0" />
      <geometry>
        <box size="0.014 0.008 0.018" />
        </geometry>
      </collision>
    <collision name="hinge_door_knuckle_0_1">
      <origin xyz="0 0 0.2465" rpy="0 0 0" />
      <geometry>
        <cylinder radius="0.009" length="0.022" />
        </geometry>
      </collision>
    <collision name="hinge_knuckle_bridge_0_1">
      <origin xyz="-0.012 -0.0075 0.2465" rpy="0 0 0" />
      <geometry>
        <box size="0.014 0.008 0.018" />
        </geometry>
      </collision>
    <collision name="hinge_leaf_1">
      <origin xyz="-0.041 -0.01 0.58" rpy="0 0 0" />
      <geometry>
        <box size="0.065 0.005 0.118" />
        </geometry>
      </collision>
    <collision name="hinge_door_knuckle_1_0">
      <origin xyz="0 0 0.5535" rpy="0 0 0" />
      <geometry>
        <cylinder radius="0.009" length="0.022" />
        </geometry>
      </collision>
    <collision name="hinge_knuckle_bridge_1_0">
      <origin xyz="-0.012 -0.0075 0.5535" rpy="0 0 0" />
      <geometry>
        <box size="0.014 0.008 0.018" />
        </geometry>
      </collision>
    <collision name="hinge_door_knuckle_1_1">
      <origin xyz="0 0 0.6065" rpy="0 0 0" />
      <geometry>
        <cylinder radius="0.009" length="0.022" />
        </geometry>
      </collision>
    <collision name="hinge_knuckle_bridge_1_1">
      <origin xyz="-0.012 -0.0075 0.6065" rpy="0 0 0" />
      <geometry>
        <box size="0.014 0.008 0.018" />
        </geometry>
      </collision>
    </link>
  <link name="knob_0">
    <visual name="stem">
      <origin xyz="0 -0.0095 0" rpy="1.5708 0 0" />
      <geometry>
        <cylinder radius="0.01" length="0.019" />
        </geometry>
      <material name="brushed_dark_knob">
        <color rgba="0.18 0.16 0.14 1" />
        </material>
      </visual>
    <visual name="round_pull">
      <origin xyz="0 -0.034 0" rpy="0 0 0" />
      <geometry>
        <sphere radius="0.024" />
        </geometry>
      <material name="brushed_dark_knob">
        <color rgba="0.18 0.16 0.14 1" />
        </material>
      </visual>
    <visual name="turn_marker">
      <origin xyz="0 -0.056 0" rpy="0 0 0" />
      <geometry>
        <box size="0.032 0.003 0.006" />
        </geometry>
      <material name="aged_brass_hinges">
        <color rgba="0.72 0.52 0.18 1" />
        </material>
      </visual>
    <collision name="stem">
      <origin xyz="0 -0.0095 0" rpy="1.5708 0 0" />
      <geometry>
        <cylinder radius="0.01" length="0.019" />
        </geometry>
      </collision>
    <collision name="round_pull">
      <origin xyz="0 -0.034 0" rpy="0 0 0" />
      <geometry>
        <sphere radius="0.024" />
        </geometry>
      </collision>
    <collision name="turn_marker">
      <origin xyz="0 -0.056 0" rpy="0 0 0" />
      <geometry>
        <box size="0.032 0.003 0.006" />
        </geometry>
      </collision>
    </link>
  <link name="knob_1">
    <visual name="stem">
      <origin xyz="0 -0.0095 0" rpy="1.5708 0 0" />
      <geometry>
        <cylinder radius="0.01" length="0.019" />
        </geometry>
      <material name="brushed_dark_knob">
        <color rgba="0.18 0.16 0.14 1" />
        </material>
      </visual>
    <visual name="round_pull">
      <origin xyz="0 -0.034 0" rpy="0 0 0" />
      <geometry>
        <sphere radius="0.024" />
        </geometry>
      <material name="brushed_dark_knob">
        <color rgba="0.18 0.16 0.14 1" />
        </material>
      </visual>
    <visual name="turn_marker">
      <origin xyz="0 -0.056 0" rpy="0 0 0" />
      <geometry>
        <box size="0.032 0.003 0.006" />
        </geometry>
      <material name="aged_brass_hinges">
        <color rgba="0.72 0.52 0.18 1" />
        </material>
      </visual>
    <collision name="stem">
      <origin xyz="0 -0.0095 0" rpy="1.5708 0 0" />
      <geometry>
        <cylinder radius="0.01" length="0.019" />
        </geometry>
      </collision>
    <collision name="round_pull">
      <origin xyz="0 -0.034 0" rpy="0 0 0" />
      <geometry>
        <sphere radius="0.024" />
        </geometry>
      </collision>
    <collision name="turn_marker">
      <origin xyz="0 -0.056 0" rpy="0 0 0" />
      <geometry>
        <box size="0.032 0.003 0.006" />
        </geometry>
      </collision>
    </link>
  <joint name="carcass_to_door_0" type="revolute">
    <origin xyz="-0.493 -0.291 0" rpy="0 0 0" />
    <parent link="carcass" />
    <child link="door_0" />
    <axis xyz="0 0 -1" />
    <limit effort="24" velocity="1.4" lower="0" upper="1.7" />
    </joint>
  <joint name="carcass_to_door_1" type="revolute">
    <origin xyz="0.493 -0.291 0" rpy="0 0 0" />
    <parent link="carcass" />
    <child link="door_1" />
    <axis xyz="0 0 1" />
    <limit effort="24" velocity="1.4" lower="0" upper="1.7" />
    </joint>
  <joint name="door_0_to_knob_0" type="continuous">
    <origin xyz="0.426 -0.02 0.415" rpy="0 0 0" />
    <parent link="door_0" />
    <child link="knob_0" />
    <axis xyz="0 -1 0" />
    <limit effort="0.8" velocity="3" />
    </joint>
  <joint name="door_1_to_knob_1" type="continuous">
    <origin xyz="-0.426 -0.02 0.415" rpy="0 0 0" />
    <parent link="door_1" />
    <child link="knob_1" />
    <axis xyz="0 -1 0" />
    <limit effort="0.8" velocity="3" />
    </joint>
  </robot>
