<robot name="industrial_safety_wheelie_bin">
  <material name="impact_hdpe_green">
    <color rgba="0.05 0.24 0.16 1" />
    </material>
  <material name="dark_hdpe">
    <color rgba="0.02 0.035 0.032 1" />
    </material>
  <material name="safety_yellow">
    <color rgba="1 0.78 0.02 1" />
    </material>
  <material name="galvanized_steel">
    <color rgba="0.62 0.66 0.64 1" />
    </material>
  <material name="black_rubber">
    <color rgba="0.015 0.014 0.012 1" />
    </material>
  <material name="lockout_red">
    <color rgba="0.78 0.04 0.025 1" />
    </material>
  <link name="body">
    <visual name="hollow_shell">
      <geometry>
        <mesh filename="assets/meshes/tapered_hollow_bin_shell.obj" />
        </geometry>
      <material name="impact_hdpe_green">
        <color rgba="0.05 0.24 0.16 1" />
        </material>
      </visual>
    <visual name="front_rim">
      <origin xyz="0.395 0 1.005" rpy="0 0 0" />
      <geometry>
        <box size="0.05 0.69 0.052" />
        </geometry>
      <material name="impact_hdpe_green">
        <color rgba="0.05 0.24 0.16 1" />
        </material>
      </visual>
    <visual name="rear_rim">
      <origin xyz="-0.395 0 0.98" rpy="0 0 0" />
      <geometry>
        <box size="0.05 0.69 0.04" />
        </geometry>
      <material name="impact_hdpe_green">
        <color rgba="0.05 0.24 0.16 1" />
        </material>
      </visual>
    <visual name="side_rim_0">
      <origin xyz="0 0.35 1.005" rpy="0 0 0" />
      <geometry>
        <box size="0.76 0.05 0.052" />
        </geometry>
      <material name="impact_hdpe_green">
        <color rgba="0.05 0.24 0.16 1" />
        </material>
      </visual>
    <visual name="side_rim_1">
      <origin xyz="0 -0.35 1.005" rpy="0 0 0" />
      <geometry>
        <box size="0.76 0.05 0.052" />
        </geometry>
      <material name="impact_hdpe_green">
        <color rgba="0.05 0.24 0.16 1" />
        </material>
      </visual>
    <visual name="front_wear_band">
      <origin xyz="0.355 0 0.76" rpy="0 0 0" />
      <geometry>
        <box size="0.055 0.57 0.06" />
        </geometry>
      <material name="dark_hdpe">
        <color rgba="0.02 0.035 0.032 1" />
        </material>
      </visual>
    <visual name="rear_wear_band">
      <origin xyz="-0.345 0 0.71" rpy="0 0 0" />
      <geometry>
        <box size="0.055 0.54 0.06" />
        </geometry>
      <material name="dark_hdpe">
        <color rgba="0.02 0.035 0.032 1" />
        </material>
      </visual>
    <visual name="side_rib_0">
      <origin xyz="0.02 0.315 0.59" rpy="0 0 0" />
      <geometry>
        <box size="0.045 0.05 0.65" />
        </geometry>
      <material name="dark_hdpe">
        <color rgba="0.02 0.035 0.032 1" />
        </material>
      </visual>
    <visual name="side_rib_1">
      <origin xyz="0.02 -0.315 0.59" rpy="0 0 0" />
      <geometry>
        <box size="0.045 0.05 0.65" />
        </geometry>
      <material name="dark_hdpe">
        <color rgba="0.02 0.035 0.032 1" />
        </material>
      </visual>
    <visual name="front_lift_pad">
      <origin xyz="0.392 0 0.93" rpy="0 0 0" />
      <geometry>
        <box size="0.035 0.25 0.105" />
        </geometry>
      <material name="safety_yellow">
        <color rgba="1 0.78 0.02 1" />
        </material>
      </visual>
    <visual name="front_foot_0">
      <origin xyz="0.22 0.21 0.025" rpy="0 0 0" />
      <geometry>
        <box size="0.185 0.09 0.04" />
        </geometry>
      <material name="black_rubber">
        <color rgba="0.015 0.014 0.012 1" />
        </material>
      </visual>
    <visual name="front_foot_riser_0">
      <origin xyz="0.235 0.21 0.082" rpy="0 0 0" />
      <geometry>
        <box size="0.105 0.07 0.09" />
        </geometry>
      <material name="dark_hdpe">
        <color rgba="0.02 0.035 0.032 1" />
        </material>
      </visual>
    <visual name="front_foot_1">
      <origin xyz="0.22 -0.21 0.025" rpy="0 0 0" />
      <geometry>
        <box size="0.185 0.09 0.04" />
        </geometry>
      <material name="black_rubber">
        <color rgba="0.015 0.014 0.012 1" />
        </material>
      </visual>
    <visual name="front_foot_riser_1">
      <origin xyz="0.235 -0.21 0.082" rpy="0 0 0" />
      <geometry>
        <box size="0.105 0.07 0.09" />
        </geometry>
      <material name="dark_hdpe">
        <color rgba="0.02 0.035 0.032 1" />
        </material>
      </visual>
    <visual name="rear_axle">
      <origin xyz="-0.43 0 0.17" rpy="-1.5708 0 0" />
      <geometry>
        <cylinder radius="0.024" length="0.9" />
        </geometry>
      <material name="galvanized_steel">
        <color rgba="0.62 0.66 0.64 1" />
        </material>
      </visual>
    <visual name="axle_saddle_0">
      <origin xyz="-0.355 0.245 0.17" rpy="0 0 0" />
      <geometry>
        <box size="0.185 0.07 0.065" />
        </geometry>
      <material name="galvanized_steel">
        <color rgba="0.62 0.66 0.64 1" />
        </material>
      </visual>
    <visual name="axle_gusset_0">
      <origin xyz="-0.355 0.245 0.235" rpy="0 -0.48 0" />
      <geometry>
        <box size="0.185 0.026 0.105" />
        </geometry>
      <material name="galvanized_steel">
        <color rgba="0.62 0.66 0.64 1" />
        </material>
      </visual>
    <visual name="axle_saddle_1">
      <origin xyz="-0.355 -0.245 0.17" rpy="0 0 0" />
      <geometry>
        <box size="0.185 0.07 0.065" />
        </geometry>
      <material name="galvanized_steel">
        <color rgba="0.62 0.66 0.64 1" />
        </material>
      </visual>
    <visual name="axle_gusset_1">
      <origin xyz="-0.355 -0.245 0.235" rpy="0 -0.48 0" />
      <geometry>
        <box size="0.185 0.026 0.105" />
        </geometry>
      <material name="galvanized_steel">
        <color rgba="0.62 0.66 0.64 1" />
        </material>
      </visual>
    <visual name="wheel_guard_plate_0">
      <origin xyz="-0.43 0.505 0.235" rpy="0 0 0" />
      <geometry>
        <box size="0.255 0.03 0.225" />
        </geometry>
      <material name="safety_yellow">
        <color rgba="1 0.78 0.02 1" />
        </material>
      </visual>
    <visual name="wheel_guard_top_0">
      <origin xyz="-0.43 0.41 0.355" rpy="0 0 0" />
      <geometry>
        <box size="0.245 0.24 0.028" />
        </geometry>
      <material name="safety_yellow">
        <color rgba="1 0.78 0.02 1" />
        </material>
      </visual>
    <visual name="guard_bridge_0">
      <origin xyz="-0.335 0.3 0.25" rpy="0 0 0" />
      <geometry>
        <box size="0.08 0.13 0.22" />
        </geometry>
      <material name="galvanized_steel">
        <color rgba="0.62 0.66 0.64 1" />
        </material>
      </visual>
    <visual name="wheel_guard_plate_1">
      <origin xyz="-0.43 -0.505 0.235" rpy="0 0 0" />
      <geometry>
        <box size="0.255 0.03 0.225" />
        </geometry>
      <material name="safety_yellow">
        <color rgba="1 0.78 0.02 1" />
        </material>
      </visual>
    <visual name="wheel_guard_top_1">
      <origin xyz="-0.43 -0.41 0.355" rpy="0 0 0" />
      <geometry>
        <box size="0.245 0.24 0.028" />
        </geometry>
      <material name="safety_yellow">
        <color rgba="1 0.78 0.02 1" />
        </material>
      </visual>
    <visual name="guard_bridge_1">
      <origin xyz="-0.335 -0.3 0.25" rpy="0 0 0" />
      <geometry>
        <box size="0.08 0.13 0.22" />
        </geometry>
      <material name="galvanized_steel">
        <color rgba="0.62 0.66 0.64 1" />
        </material>
      </visual>
    <visual name="rear_hinge_strap">
      <origin xyz="-0.407 0 0.97" rpy="0 0 0" />
      <geometry>
        <box size="0.05 0.69 0.06" />
        </geometry>
      <material name="galvanized_steel">
        <color rgba="0.62 0.66 0.64 1" />
        </material>
      </visual>
    <visual name="hinge_knuckle_0">
      <origin xyz="-0.41 -0.285 1.035" rpy="-1.5708 0 0" />
      <geometry>
        <cylinder radius="0.026" length="0.14" />
        </geometry>
      <material name="galvanized_steel">
        <color rgba="0.62 0.66 0.64 1" />
        </material>
      </visual>
    <visual name="hinge_web_0">
      <origin xyz="-0.41 -0.285 1.01" rpy="0 0 0" />
      <geometry>
        <box size="0.022 0.1008 0.06" />
        </geometry>
      <material name="galvanized_steel">
        <color rgba="0.62 0.66 0.64 1" />
        </material>
      </visual>
    <visual name="hinge_knuckle_1">
      <origin xyz="-0.41 0 1.035" rpy="-1.5708 0 0" />
      <geometry>
        <cylinder radius="0.026" length="0.15" />
        </geometry>
      <material name="galvanized_steel">
        <color rgba="0.62 0.66 0.64 1" />
        </material>
      </visual>
    <visual name="hinge_web_1">
      <origin xyz="-0.41 0 1.01" rpy="0 0 0" />
      <geometry>
        <box size="0.022 0.108 0.06" />
        </geometry>
      <material name="galvanized_steel">
        <color rgba="0.62 0.66 0.64 1" />
        </material>
      </visual>
    <visual name="hinge_knuckle_2">
      <origin xyz="-0.41 0.285 1.035" rpy="-1.5708 0 0" />
      <geometry>
        <cylinder radius="0.026" length="0.14" />
        </geometry>
      <material name="galvanized_steel">
        <color rgba="0.62 0.66 0.64 1" />
        </material>
      </visual>
    <visual name="hinge_web_2">
      <origin xyz="-0.41 0.285 1.01" rpy="0 0 0" />
      <geometry>
        <box size="0.022 0.1008 0.06" />
        </geometry>
      <material name="galvanized_steel">
        <color rgba="0.62 0.66 0.64 1" />
        </material>
      </visual>
    <visual name="overtravel_stop_0">
      <origin xyz="-0.46 0.27 1.08" rpy="0 0 0" />
      <geometry>
        <box size="0.06 0.08 0.19" />
        </geometry>
      <material name="safety_yellow">
        <color rgba="1 0.78 0.02 1" />
        </material>
      </visual>
    <visual name="stop_bumper_0">
      <origin xyz="-0.428 0.27 1.162" rpy="0 0 0" />
      <geometry>
        <box size="0.032 0.07 0.055" />
        </geometry>
      <material name="black_rubber">
        <color rgba="0.015 0.014 0.012 1" />
        </material>
      </visual>
    <visual name="rear_brace_0">
      <origin xyz="-0.36 0.27 0.965" rpy="0 -0.65 0" />
      <geometry>
        <box size="0.215 0.034 0.038" />
        </geometry>
      <material name="galvanized_steel">
        <color rgba="0.62 0.66 0.64 1" />
        </material>
      </visual>
    <visual name="overtravel_stop_1">
      <origin xyz="-0.46 -0.27 1.08" rpy="0 0 0" />
      <geometry>
        <box size="0.06 0.08 0.19" />
        </geometry>
      <material name="safety_yellow">
        <color rgba="1 0.78 0.02 1" />
        </material>
      </visual>
    <visual name="stop_bumper_1">
      <origin xyz="-0.428 -0.27 1.162" rpy="0 0 0" />
      <geometry>
        <box size="0.032 0.07 0.055" />
        </geometry>
      <material name="black_rubber">
        <color rgba="0.015 0.014 0.012 1" />
        </material>
      </visual>
    <visual name="rear_brace_1">
      <origin xyz="-0.36 -0.27 0.965" rpy="0 -0.65 0" />
      <geometry>
        <box size="0.215 0.034 0.038" />
        </geometry>
      <material name="galvanized_steel">
        <color rgba="0.62 0.66 0.64 1" />
        </material>
      </visual>
    <visual name="hinge_bolt_0">
      <origin xyz="-0.434 -0.25 0.985" rpy="0 1.5708 0" />
      <geometry>
        <cylinder radius="0.014" length="0.01" />
        </geometry>
      <material name="galvanized_steel">
        <color rgba="0.62 0.66 0.64 1" />
        </material>
      </visual>
    <visual name="hinge_bolt_1">
      <origin xyz="-0.434 0 0.985" rpy="0 1.5708 0" />
      <geometry>
        <cylinder radius="0.014" length="0.01" />
        </geometry>
      <material name="galvanized_steel">
        <color rgba="0.62 0.66 0.64 1" />
        </material>
      </visual>
    <visual name="hinge_bolt_2">
      <origin xyz="-0.434 0.25 0.985" rpy="0 1.5708 0" />
      <geometry>
        <cylinder radius="0.014" length="0.01" />
        </geometry>
      <material name="galvanized_steel">
        <color rgba="0.62 0.66 0.64 1" />
        </material>
      </visual>
    <visual name="lock_clevis_0">
      <origin xyz="0.44 0.047 0.955" rpy="0 0 0" />
      <geometry>
        <box size="0.07 0.024 0.08" />
        </geometry>
      <material name="safety_yellow">
        <color rgba="1 0.78 0.02 1" />
        </material>
      </visual>
    <visual name="lock_clevis_1">
      <origin xyz="0.44 -0.047 0.955" rpy="0 0 0" />
      <geometry>
        <box size="0.07 0.024 0.08" />
        </geometry>
      <material name="safety_yellow">
        <color rgba="1 0.78 0.02 1" />
        </material>
      </visual>
    <visual name="lock_keeper">
      <origin xyz="0.395 0 0.96" rpy="0 0 0" />
      <geometry>
        <box size="0.028 0.115 0.04" />
        </geometry>
      <material name="galvanized_steel">
        <color rgba="0.62 0.66 0.64 1" />
        </material>
      </visual>
    <collision name="hollow_shell">
      <geometry>
        <mesh filename="assets/meshes/tapered_hollow_bin_shell.obj" />
        </geometry>
      </collision>
    <collision name="front_rim">
      <origin xyz="0.395 0 1.005" rpy="0 0 0" />
      <geometry>
        <box size="0.05 0.69 0.052" />
        </geometry>
      </collision>
    <collision name="rear_rim">
      <origin xyz="-0.395 0 0.98" rpy="0 0 0" />
      <geometry>
        <box size="0.05 0.69 0.04" />
        </geometry>
      </collision>
    <collision name="side_rim_0">
      <origin xyz="0 0.35 1.005" rpy="0 0 0" />
      <geometry>
        <box size="0.76 0.05 0.052" />
        </geometry>
      </collision>
    <collision name="side_rim_1">
      <origin xyz="0 -0.35 1.005" rpy="0 0 0" />
      <geometry>
        <box size="0.76 0.05 0.052" />
        </geometry>
      </collision>
    <collision name="front_wear_band">
      <origin xyz="0.355 0 0.76" rpy="0 0 0" />
      <geometry>
        <box size="0.055 0.57 0.06" />
        </geometry>
      </collision>
    <collision name="rear_wear_band">
      <origin xyz="-0.345 0 0.71" rpy="0 0 0" />
      <geometry>
        <box size="0.055 0.54 0.06" />
        </geometry>
      </collision>
    <collision name="side_rib_0">
      <origin xyz="0.02 0.315 0.59" rpy="0 0 0" />
      <geometry>
        <box size="0.045 0.05 0.65" />
        </geometry>
      </collision>
    <collision name="side_rib_1">
      <origin xyz="0.02 -0.315 0.59" rpy="0 0 0" />
      <geometry>
        <box size="0.045 0.05 0.65" />
        </geometry>
      </collision>
    <collision name="front_lift_pad">
      <origin xyz="0.392 0 0.93" rpy="0 0 0" />
      <geometry>
        <box size="0.035 0.25 0.105" />
        </geometry>
      </collision>
    <collision name="front_foot_0">
      <origin xyz="0.22 0.21 0.025" rpy="0 0 0" />
      <geometry>
        <box size="0.185 0.09 0.04" />
        </geometry>
      </collision>
    <collision name="front_foot_riser_0">
      <origin xyz="0.235 0.21 0.082" rpy="0 0 0" />
      <geometry>
        <box size="0.105 0.07 0.09" />
        </geometry>
      </collision>
    <collision name="front_foot_1">
      <origin xyz="0.22 -0.21 0.025" rpy="0 0 0" />
      <geometry>
        <box size="0.185 0.09 0.04" />
        </geometry>
      </collision>
    <collision name="front_foot_riser_1">
      <origin xyz="0.235 -0.21 0.082" rpy="0 0 0" />
      <geometry>
        <box size="0.105 0.07 0.09" />
        </geometry>
      </collision>
    <collision name="rear_axle">
      <origin xyz="-0.43 0 0.17" rpy="-1.5708 0 0" />
      <geometry>
        <cylinder radius="0.024" length="0.9" />
        </geometry>
      </collision>
    <collision name="axle_saddle_0">
      <origin xyz="-0.355 0.245 0.17" rpy="0 0 0" />
      <geometry>
        <box size="0.185 0.07 0.065" />
        </geometry>
      </collision>
    <collision name="axle_gusset_0">
      <origin xyz="-0.355 0.245 0.235" rpy="0 -0.48 0" />
      <geometry>
        <box size="0.185 0.026 0.105" />
        </geometry>
      </collision>
    <collision name="axle_saddle_1">
      <origin xyz="-0.355 -0.245 0.17" rpy="0 0 0" />
      <geometry>
        <box size="0.185 0.07 0.065" />
        </geometry>
      </collision>
    <collision name="axle_gusset_1">
      <origin xyz="-0.355 -0.245 0.235" rpy="0 -0.48 0" />
      <geometry>
        <box size="0.185 0.026 0.105" />
        </geometry>
      </collision>
    <collision name="wheel_guard_plate_0">
      <origin xyz="-0.43 0.505 0.235" rpy="0 0 0" />
      <geometry>
        <box size="0.255 0.03 0.225" />
        </geometry>
      </collision>
    <collision name="wheel_guard_top_0">
      <origin xyz="-0.43 0.41 0.355" rpy="0 0 0" />
      <geometry>
        <box size="0.245 0.24 0.028" />
        </geometry>
      </collision>
    <collision name="guard_bridge_0">
      <origin xyz="-0.335 0.3 0.25" rpy="0 0 0" />
      <geometry>
        <box size="0.08 0.13 0.22" />
        </geometry>
      </collision>
    <collision name="wheel_guard_plate_1">
      <origin xyz="-0.43 -0.505 0.235" rpy="0 0 0" />
      <geometry>
        <box size="0.255 0.03 0.225" />
        </geometry>
      </collision>
    <collision name="wheel_guard_top_1">
      <origin xyz="-0.43 -0.41 0.355" rpy="0 0 0" />
      <geometry>
        <box size="0.245 0.24 0.028" />
        </geometry>
      </collision>
    <collision name="guard_bridge_1">
      <origin xyz="-0.335 -0.3 0.25" rpy="0 0 0" />
      <geometry>
        <box size="0.08 0.13 0.22" />
        </geometry>
      </collision>
    <collision name="rear_hinge_strap">
      <origin xyz="-0.407 0 0.97" rpy="0 0 0" />
      <geometry>
        <box size="0.05 0.69 0.06" />
        </geometry>
      </collision>
    <collision name="hinge_knuckle_0">
      <origin xyz="-0.41 -0.285 1.035" rpy="-1.5708 0 0" />
      <geometry>
        <cylinder radius="0.026" length="0.14" />
        </geometry>
      </collision>
    <collision name="hinge_web_0">
      <origin xyz="-0.41 -0.285 1.01" rpy="0 0 0" />
      <geometry>
        <box size="0.022 0.1008 0.06" />
        </geometry>
      </collision>
    <collision name="hinge_knuckle_1">
      <origin xyz="-0.41 0 1.035" rpy="-1.5708 0 0" />
      <geometry>
        <cylinder radius="0.026" length="0.15" />
        </geometry>
      </collision>
    <collision name="hinge_web_1">
      <origin xyz="-0.41 0 1.01" rpy="0 0 0" />
      <geometry>
        <box size="0.022 0.108 0.06" />
        </geometry>
      </collision>
    <collision name="hinge_knuckle_2">
      <origin xyz="-0.41 0.285 1.035" rpy="-1.5708 0 0" />
      <geometry>
        <cylinder radius="0.026" length="0.14" />
        </geometry>
      </collision>
    <collision name="hinge_web_2">
      <origin xyz="-0.41 0.285 1.01" rpy="0 0 0" />
      <geometry>
        <box size="0.022 0.1008 0.06" />
        </geometry>
      </collision>
    <collision name="overtravel_stop_0">
      <origin xyz="-0.46 0.27 1.08" rpy="0 0 0" />
      <geometry>
        <box size="0.06 0.08 0.19" />
        </geometry>
      </collision>
    <collision name="stop_bumper_0">
      <origin xyz="-0.428 0.27 1.162" rpy="0 0 0" />
      <geometry>
        <box size="0.032 0.07 0.055" />
        </geometry>
      </collision>
    <collision name="rear_brace_0">
      <origin xyz="-0.36 0.27 0.965" rpy="0 -0.65 0" />
      <geometry>
        <box size="0.215 0.034 0.038" />
        </geometry>
      </collision>
    <collision name="overtravel_stop_1">
      <origin xyz="-0.46 -0.27 1.08" rpy="0 0 0" />
      <geometry>
        <box size="0.06 0.08 0.19" />
        </geometry>
      </collision>
    <collision name="stop_bumper_1">
      <origin xyz="-0.428 -0.27 1.162" rpy="0 0 0" />
      <geometry>
        <box size="0.032 0.07 0.055" />
        </geometry>
      </collision>
    <collision name="rear_brace_1">
      <origin xyz="-0.36 -0.27 0.965" rpy="0 -0.65 0" />
      <geometry>
        <box size="0.215 0.034 0.038" />
        </geometry>
      </collision>
    <collision name="hinge_bolt_0">
      <origin xyz="-0.434 -0.25 0.985" rpy="0 1.5708 0" />
      <geometry>
        <cylinder radius="0.014" length="0.01" />
        </geometry>
      </collision>
    <collision name="hinge_bolt_1">
      <origin xyz="-0.434 0 0.985" rpy="0 1.5708 0" />
      <geometry>
        <cylinder radius="0.014" length="0.01" />
        </geometry>
      </collision>
    <collision name="hinge_bolt_2">
      <origin xyz="-0.434 0.25 0.985" rpy="0 1.5708 0" />
      <geometry>
        <cylinder radius="0.014" length="0.01" />
        </geometry>
      </collision>
    <collision name="lock_clevis_0">
      <origin xyz="0.44 0.047 0.955" rpy="0 0 0" />
      <geometry>
        <box size="0.07 0.024 0.08" />
        </geometry>
      </collision>
    <collision name="lock_clevis_1">
      <origin xyz="0.44 -0.047 0.955" rpy="0 0 0" />
      <geometry>
        <box size="0.07 0.024 0.08" />
        </geometry>
      </collision>
    <collision name="lock_keeper">
      <origin xyz="0.395 0 0.96" rpy="0 0 0" />
      <geometry>
        <box size="0.028 0.115 0.04" />
        </geometry>
      </collision>
    </link>
  <link name="wheel_0">
    <visual name="tire">
      <geometry>
        <mesh filename="assets/meshes/heavy_duty_tire.obj" />
        </geometry>
      <material name="black_rubber">
        <color rgba="0.015 0.014 0.012 1" />
        </material>
      </visual>
    <visual name="rim">
      <geometry>
        <mesh filename="assets/meshes/steel_wheel_rim.obj" />
        </geometry>
      <material name="galvanized_steel">
        <color rgba="0.62 0.66 0.64 1" />
        </material>
      </visual>
    <collision name="tire">
      <geometry>
        <mesh filename="assets/meshes/heavy_duty_tire.obj" />
        </geometry>
      </collision>
    <collision name="rim">
      <geometry>
        <mesh filename="assets/meshes/steel_wheel_rim.obj" />
        </geometry>
      </collision>
    </link>
  <link name="wheel_1">
    <visual name="tire">
      <geometry>
        <mesh filename="assets/meshes/heavy_duty_tire.obj" />
        </geometry>
      <material name="black_rubber">
        <color rgba="0.015 0.014 0.012 1" />
        </material>
      </visual>
    <visual name="rim">
      <geometry>
        <mesh filename="assets/meshes/steel_wheel_rim.obj" />
        </geometry>
      <material name="galvanized_steel">
        <color rgba="0.62 0.66 0.64 1" />
        </material>
      </visual>
    <collision name="tire">
      <geometry>
        <mesh filename="assets/meshes/heavy_duty_tire.obj" />
        </geometry>
      </collision>
    <collision name="rim">
      <geometry>
        <mesh filename="assets/meshes/steel_wheel_rim.obj" />
        </geometry>
      </collision>
    </link>
  <link name="lid">
    <visual name="lid_panel">
      <origin xyz="0.425 0 0.044" rpy="0 0 0" />
      <geometry>
        <box size="0.81 0.75 0.044" />
        </geometry>
      <material name="impact_hdpe_green">
        <color rgba="0.05 0.24 0.16 1" />
        </material>
      </visual>
    <visual name="lid_front_lip">
      <origin xyz="0.855 0 0.015" rpy="0 0 0" />
      <geometry>
        <box size="0.05 0.745 0.08" />
        </geometry>
      <material name="dark_hdpe">
        <color rgba="0.02 0.035 0.032 1" />
        </material>
      </visual>
    <visual name="lid_side_lip_0">
      <origin xyz="0.455 0.4 0.018" rpy="0 0 0" />
      <geometry>
        <box size="0.73 0.05 0.056" />
        </geometry>
      <material name="dark_hdpe">
        <color rgba="0.02 0.035 0.032 1" />
        </material>
      </visual>
    <visual name="lid_side_lip_1">
      <origin xyz="0.455 -0.4 0.018" rpy="0 0 0" />
      <geometry>
        <box size="0.73 0.05 0.056" />
        </geometry>
      <material name="dark_hdpe">
        <color rgba="0.02 0.035 0.032 1" />
        </material>
      </visual>
    <visual name="lid_rear_leaf">
      <origin xyz="0.04 -0.145 0.035" rpy="0 0 0" />
      <geometry>
        <box size="0.08 0.12 0.05" />
        </geometry>
      <material name="galvanized_steel">
        <color rgba="0.62 0.66 0.64 1" />
        </material>
      </visual>
    <visual name="lid_rear_leaf_1">
      <origin xyz="0.04 0.145 0.035" rpy="0 0 0" />
      <geometry>
        <box size="0.08 0.12 0.05" />
        </geometry>
      <material name="galvanized_steel">
        <color rgba="0.62 0.66 0.64 1" />
        </material>
      </visual>
    <visual name="lid_knuckle_0">
      <origin xyz="0 -0.145 0" rpy="-1.5708 0 0" />
      <geometry>
        <cylinder radius="0.022" length="0.12" />
        </geometry>
      <material name="galvanized_steel">
        <color rgba="0.62 0.66 0.64 1" />
        </material>
      </visual>
    <visual name="lid_knuckle_1">
      <origin xyz="0 0.145 0" rpy="-1.5708 0 0" />
      <geometry>
        <cylinder radius="0.022" length="0.12" />
        </geometry>
      <material name="galvanized_steel">
        <color rgba="0.62 0.66 0.64 1" />
        </material>
      </visual>
    <visual name="lid_cross_rib_0">
      <origin xyz="0.43 -0.22 0.078" rpy="0 0 0" />
      <geometry>
        <box size="0.585 0.03 0.04" />
        </geometry>
      <material name="dark_hdpe">
        <color rgba="0.02 0.035 0.032 1" />
        </material>
      </visual>
    <visual name="lid_bolt_0">
      <origin xyz="0.18 -0.22 0.097" rpy="0 0 0" />
      <geometry>
        <cylinder radius="0.013" length="0.008" />
        </geometry>
      <material name="galvanized_steel">
        <color rgba="0.62 0.66 0.64 1" />
        </material>
      </visual>
    <visual name="lid_cross_rib_1">
      <origin xyz="0.43 0 0.078" rpy="0 0 0" />
      <geometry>
        <box size="0.585 0.03 0.04" />
        </geometry>
      <material name="dark_hdpe">
        <color rgba="0.02 0.035 0.032 1" />
        </material>
      </visual>
    <visual name="lid_bolt_1">
      <origin xyz="0.18 0 0.097" rpy="0 0 0" />
      <geometry>
        <cylinder radius="0.013" length="0.008" />
        </geometry>
      <material name="galvanized_steel">
        <color rgba="0.62 0.66 0.64 1" />
        </material>
      </visual>
    <visual name="lid_cross_rib_2">
      <origin xyz="0.43 0.22 0.078" rpy="0 0 0" />
      <geometry>
        <box size="0.585 0.03 0.04" />
        </geometry>
      <material name="dark_hdpe">
        <color rgba="0.02 0.035 0.032 1" />
        </material>
      </visual>
    <visual name="lid_bolt_2">
      <origin xyz="0.18 0.22 0.097" rpy="0 0 0" />
      <geometry>
        <cylinder radius="0.013" length="0.008" />
        </geometry>
      <material name="galvanized_steel">
        <color rgba="0.62 0.66 0.64 1" />
        </material>
      </visual>
    <visual name="lock_strike">
      <origin xyz="0.79 0 0.054" rpy="0 0 0" />
      <geometry>
        <box size="0.035 0.15 0.03" />
        </geometry>
      <material name="galvanized_steel">
        <color rgba="0.62 0.66 0.64 1" />
        </material>
      </visual>
    <visual name="warning_strip">
      <origin xyz="0.535 0 0.071" rpy="0 0 0" />
      <geometry>
        <box size="0.36 0.035 0.008" />
        </geometry>
      <material name="safety_yellow">
        <color rgba="1 0.78 0.02 1" />
        </material>
      </visual>
    <collision name="lid_panel">
      <origin xyz="0.425 0 0.044" rpy="0 0 0" />
      <geometry>
        <box size="0.81 0.75 0.044" />
        </geometry>
      </collision>
    <collision name="lid_front_lip">
      <origin xyz="0.855 0 0.015" rpy="0 0 0" />
      <geometry>
        <box size="0.05 0.745 0.08" />
        </geometry>
      </collision>
    <collision name="lid_side_lip_0">
      <origin xyz="0.455 0.4 0.018" rpy="0 0 0" />
      <geometry>
        <box size="0.73 0.05 0.056" />
        </geometry>
      </collision>
    <collision name="lid_side_lip_1">
      <origin xyz="0.455 -0.4 0.018" rpy="0 0 0" />
      <geometry>
        <box size="0.73 0.05 0.056" />
        </geometry>
      </collision>
    <collision name="lid_rear_leaf">
      <origin xyz="0.04 -0.145 0.035" rpy="0 0 0" />
      <geometry>
        <box size="0.08 0.12 0.05" />
        </geometry>
      </collision>
    <collision name="lid_rear_leaf_1">
      <origin xyz="0.04 0.145 0.035" rpy="0 0 0" />
      <geometry>
        <box size="0.08 0.12 0.05" />
        </geometry>
      </collision>
    <collision name="lid_knuckle_0">
      <origin xyz="0 -0.145 0" rpy="-1.5708 0 0" />
      <geometry>
        <cylinder radius="0.022" length="0.12" />
        </geometry>
      </collision>
    <collision name="lid_knuckle_1">
      <origin xyz="0 0.145 0" rpy="-1.5708 0 0" />
      <geometry>
        <cylinder radius="0.022" length="0.12" />
        </geometry>
      </collision>
    <collision name="lid_cross_rib_0">
      <origin xyz="0.43 -0.22 0.078" rpy="0 0 0" />
      <geometry>
        <box size="0.585 0.03 0.04" />
        </geometry>
      </collision>
    <collision name="lid_bolt_0">
      <origin xyz="0.18 -0.22 0.097" rpy="0 0 0" />
      <geometry>
        <cylinder radius="0.013" length="0.008" />
        </geometry>
      </collision>
    <collision name="lid_cross_rib_1">
      <origin xyz="0.43 0 0.078" rpy="0 0 0" />
      <geometry>
        <box size="0.585 0.03 0.04" />
        </geometry>
      </collision>
    <collision name="lid_bolt_1">
      <origin xyz="0.18 0 0.097" rpy="0 0 0" />
      <geometry>
        <cylinder radius="0.013" length="0.008" />
        </geometry>
      </collision>
    <collision name="lid_cross_rib_2">
      <origin xyz="0.43 0.22 0.078" rpy="0 0 0" />
      <geometry>
        <box size="0.585 0.03 0.04" />
        </geometry>
      </collision>
    <collision name="lid_bolt_2">
      <origin xyz="0.18 0.22 0.097" rpy="0 0 0" />
      <geometry>
        <cylinder radius="0.013" length="0.008" />
        </geometry>
      </collision>
    <collision name="lock_strike">
      <origin xyz="0.79 0 0.054" rpy="0 0 0" />
      <geometry>
        <box size="0.035 0.15 0.03" />
        </geometry>
      </collision>
    <collision name="warning_strip">
      <origin xyz="0.535 0 0.071" rpy="0 0 0" />
      <geometry>
        <box size="0.36 0.035 0.008" />
        </geometry>
      </collision>
    </link>
  <link name="lock_tab">
    <visual name="pivot_barrel">
      <origin xyz="0 0 0" rpy="-1.5708 0 0" />
      <geometry>
        <cylinder radius="0.017" length="0.07" />
        </geometry>
      <material name="galvanized_steel">
        <color rgba="0.62 0.66 0.64 1" />
        </material>
      </visual>
    <visual name="lock_plate">
      <origin xyz="0.018 0 -0.088" rpy="0 0 0" />
      <geometry>
        <box size="0.035 0.056 0.145" />
        </geometry>
      <material name="lockout_red">
        <color rgba="0.78 0.04 0.025 1" />
        </material>
      </visual>
    <visual name="pull_tab">
      <origin xyz="0.02 0 -0.168" rpy="0 0 0" />
      <geometry>
        <box size="0.046 0.075 0.03" />
        </geometry>
      <material name="safety_yellow">
        <color rgba="1 0.78 0.02 1" />
        </material>
      </visual>
    <visual name="lock_bolt">
      <origin xyz="0.04 0 -0.088" rpy="-1.5708 0 0" />
      <geometry>
        <cylinder radius="0.011" length="0.064" />
        </geometry>
      <material name="galvanized_steel">
        <color rgba="0.62 0.66 0.64 1" />
        </material>
      </visual>
    <collision name="pivot_barrel">
      <origin xyz="0 0 0" rpy="-1.5708 0 0" />
      <geometry>
        <cylinder radius="0.017" length="0.07" />
        </geometry>
      </collision>
    <collision name="lock_plate">
      <origin xyz="0.018 0 -0.088" rpy="0 0 0" />
      <geometry>
        <box size="0.035 0.056 0.145" />
        </geometry>
      </collision>
    <collision name="pull_tab">
      <origin xyz="0.02 0 -0.168" rpy="0 0 0" />
      <geometry>
        <box size="0.046 0.075 0.03" />
        </geometry>
      </collision>
    <collision name="lock_bolt">
      <origin xyz="0.04 0 -0.088" rpy="-1.5708 0 0" />
      <geometry>
        <cylinder radius="0.011" length="0.064" />
        </geometry>
      </collision>
    </link>
  <joint name="body_to_wheel_0" type="continuous">
    <origin xyz="-0.43 0.43 0.17" rpy="0 0 1.5708" />
    <parent link="body" />
    <child link="wheel_0" />
    <axis xyz="1 0 0" />
    <limit effort="60" velocity="18" />
    </joint>
  <joint name="body_to_wheel_1" type="continuous">
    <origin xyz="-0.43 -0.43 0.17" rpy="0 0 1.5708" />
    <parent link="body" />
    <child link="wheel_1" />
    <axis xyz="1 0 0" />
    <limit effort="60" velocity="18" />
    </joint>
  <joint name="body_to_lid" type="revolute">
    <origin xyz="-0.41 0 1.035" rpy="0 0 0" />
    <parent link="body" />
    <child link="lid" />
    <axis xyz="0 -1 0" />
    <limit effort="24" velocity="1.4" lower="0" upper="1.95477" />
    </joint>
  <joint name="body_to_lock_tab" type="revolute">
    <origin xyz="0.455 0 0.955" rpy="0 0 0" />
    <parent link="body" />
    <child link="lock_tab" />
    <axis xyz="0 1 0" />
    <limit effort="4" velocity="2" lower="-0.349066" upper="1.309" />
    </joint>
  </robot>
