<robot name="compact_8x21_theatre_binocular">
  <material name="satin_black">
    <color rgba="0.005 0.005 0.006 1" />
    </material>
  <material name="soft_black_rubber">
    <color rgba="0.015 0.014 0.013 1" />
    </material>
  <material name="dark_graphite">
    <color rgba="0.1 0.105 0.11 1" />
    </material>
  <material name="blue_coated_glass">
    <color rgba="0.05 0.18 0.3 0.62" />
    </material>
  <material name="brushed_black_metal">
    <color rgba="0.025 0.025 0.028 1" />
    </material>
  <link name="barrel_0">
    <visual name="main_tube_0">
      <origin xyz="0.002 -0.032 0" rpy="0 1.5708 0" />
      <geometry>
        <cylinder radius="0.0128" length="0.074" />
        </geometry>
      <material name="satin_black">
        <color rgba="0.005 0.005 0.006 1" />
        </material>
      </visual>
    <visual name="objective_bezel_0">
      <origin xyz="0.045 -0.032 0" rpy="0 0 0" />
      <geometry>
        <mesh filename="assets/meshes/objective_bezel_0.obj" />
        </geometry>
      <material name="dark_graphite">
        <color rgba="0.1 0.105 0.11 1" />
        </material>
      </visual>
    <visual name="objective_lens_0">
      <origin xyz="0.053 -0.032 0" rpy="0 1.5708 0" />
      <geometry>
        <cylinder radius="0.0109" length="0.002" />
        </geometry>
      <material name="blue_coated_glass">
        <color rgba="0.05 0.18 0.3 0.62" />
        </material>
      </visual>
    <visual name="ocular_socket_0">
      <origin xyz="-0.043 -0.032 0" rpy="0 0 0" />
      <geometry>
        <mesh filename="assets/meshes/ocular_socket_0.obj" />
        </geometry>
      <material name="dark_graphite">
        <color rgba="0.1 0.105 0.11 1" />
        </material>
      </visual>
    <visual name="ocular_lens_0">
      <origin xyz="-0.05275 -0.032 0" rpy="0 1.5708 0" />
      <geometry>
        <cylinder radius="0.0079" length="0.0015" />
        </geometry>
      <material name="blue_coated_glass">
        <color rgba="0.05 0.18 0.3 0.62" />
        </material>
      </visual>
    <visual name="top_grip_0">
      <origin xyz="0.004 -0.032 0.0135" rpy="0 0 0" />
      <geometry>
        <box size="0.05 0.004 0.0035" />
        </geometry>
      <material name="soft_black_rubber">
        <color rgba="0.015 0.014 0.013 1" />
        </material>
      </visual>
    <visual name="side_grip_0">
      <origin xyz="0.004 -0.03152 -0.0005" rpy="0 0 0" />
      <geometry>
        <box size="0.048 0.0035 0.012" />
        </geometry>
      <material name="soft_black_rubber">
        <color rgba="0.015 0.014 0.013 1" />
        </material>
      </visual>
    <visual name="bridge_leaf_0">
      <origin xyz="-0.002 -0.014 0" rpy="0 0 0" />
      <geometry>
        <box size="0.074 0.024 0.009" />
        </geometry>
      <material name="brushed_black_metal">
        <color rgba="0.025 0.025 0.028 1" />
        </material>
      </visual>
    <visual name="hinge_barrel_0">
      <origin xyz="-0.026 -0.001 0" rpy="0 1.5708 0" />
      <geometry>
        <cylinder radius="0.0048" length="0.03" />
        </geometry>
      <material name="brushed_black_metal">
        <color rgba="0.025 0.025 0.028 1" />
        </material>
      </visual>
    <visual name="hinge_knuckle_0">
      <origin xyz="0.026 -0.001 0" rpy="0 1.5708 0" />
      <geometry>
        <cylinder radius="0.0048" length="0.03" />
        </geometry>
      <material name="brushed_black_metal">
        <color rgba="0.025 0.025 0.028 1" />
        </material>
      </visual>
    <visual name="focus_pedestal">
      <origin xyz="-0.028 -0.004 0.016" rpy="0 0 0" />
      <geometry>
        <box size="0.036 0.016 0.008" />
        </geometry>
      <material name="brushed_black_metal">
        <color rgba="0.025 0.025 0.028 1" />
        </material>
      </visual>
    <visual name="focus_support">
      <origin xyz="-0.028 -0.006 0.009" rpy="0 0 0" />
      <geometry>
        <box size="0.03 0.01 0.012" />
        </geometry>
      <material name="brushed_black_metal">
        <color rgba="0.025 0.025 0.028 1" />
        </material>
      </visual>
    <visual name="focus_fork">
      <origin xyz="-0.03 -0.011 0.024" rpy="0 0 0" />
      <geometry>
        <box size="0.007 0.004 0.022" />
        </geometry>
      <material name="brushed_black_metal">
        <color rgba="0.025 0.025 0.028 1" />
        </material>
      </visual>
    <visual name="focus_axle">
      <origin xyz="-0.03 0 0.034" rpy="-1.5708 0 0" />
      <geometry>
        <cylinder radius="0.003" length="0.026" />
        </geometry>
      <material name="brushed_black_metal">
        <color rgba="0.025 0.025 0.028 1" />
        </material>
      </visual>
    <collision name="main_tube_0">
      <origin xyz="0.002 -0.032 0" rpy="0 1.5708 0" />
      <geometry>
        <cylinder radius="0.0128" length="0.074" />
        </geometry>
      </collision>
    <collision name="objective_bezel_0">
      <origin xyz="0.045 -0.032 0" rpy="0 0 0" />
      <geometry>
        <mesh filename="assets/meshes/objective_bezel_0.obj" />
        </geometry>
      </collision>
    <collision name="objective_lens_0">
      <origin xyz="0.053 -0.032 0" rpy="0 1.5708 0" />
      <geometry>
        <cylinder radius="0.0109" length="0.002" />
        </geometry>
      </collision>
    <collision name="ocular_socket_0">
      <origin xyz="-0.043 -0.032 0" rpy="0 0 0" />
      <geometry>
        <mesh filename="assets/meshes/ocular_socket_0.obj" />
        </geometry>
      </collision>
    <collision name="ocular_lens_0">
      <origin xyz="-0.05275 -0.032 0" rpy="0 1.5708 0" />
      <geometry>
        <cylinder radius="0.0079" length="0.0015" />
        </geometry>
      </collision>
    <collision name="top_grip_0">
      <origin xyz="0.004 -0.032 0.0135" rpy="0 0 0" />
      <geometry>
        <box size="0.05 0.004 0.0035" />
        </geometry>
      </collision>
    <collision name="side_grip_0">
      <origin xyz="0.004 -0.03152 -0.0005" rpy="0 0 0" />
      <geometry>
        <box size="0.048 0.0035 0.012" />
        </geometry>
      </collision>
    <collision name="bridge_leaf_0">
      <origin xyz="-0.002 -0.014 0" rpy="0 0 0" />
      <geometry>
        <box size="0.074 0.024 0.009" />
        </geometry>
      </collision>
    <collision name="hinge_barrel_0">
      <origin xyz="-0.026 -0.001 0" rpy="0 1.5708 0" />
      <geometry>
        <cylinder radius="0.0048" length="0.03" />
        </geometry>
      </collision>
    <collision name="hinge_knuckle_0">
      <origin xyz="0.026 -0.001 0" rpy="0 1.5708 0" />
      <geometry>
        <cylinder radius="0.0048" length="0.03" />
        </geometry>
      </collision>
    <collision name="focus_pedestal">
      <origin xyz="-0.028 -0.004 0.016" rpy="0 0 0" />
      <geometry>
        <box size="0.036 0.016 0.008" />
        </geometry>
      </collision>
    <collision name="focus_support">
      <origin xyz="-0.028 -0.006 0.009" rpy="0 0 0" />
      <geometry>
        <box size="0.03 0.01 0.012" />
        </geometry>
      </collision>
    <collision name="focus_fork">
      <origin xyz="-0.03 -0.011 0.024" rpy="0 0 0" />
      <geometry>
        <box size="0.007 0.004 0.022" />
        </geometry>
      </collision>
    <collision name="focus_axle">
      <origin xyz="-0.03 0 0.034" rpy="-1.5708 0 0" />
      <geometry>
        <cylinder radius="0.003" length="0.026" />
        </geometry>
      </collision>
    </link>
  <link name="barrel_1">
    <visual name="main_tube_1">
      <origin xyz="0.002 0.032 0" rpy="0 1.5708 0" />
      <geometry>
        <cylinder radius="0.0128" length="0.074" />
        </geometry>
      <material name="satin_black">
        <color rgba="0.005 0.005 0.006 1" />
        </material>
      </visual>
    <visual name="objective_bezel_1">
      <origin xyz="0.045 0.032 0" rpy="0 0 0" />
      <geometry>
        <mesh filename="assets/meshes/objective_bezel_1.obj" />
        </geometry>
      <material name="dark_graphite">
        <color rgba="0.1 0.105 0.11 1" />
        </material>
      </visual>
    <visual name="objective_lens_1">
      <origin xyz="0.053 0.032 0" rpy="0 1.5708 0" />
      <geometry>
        <cylinder radius="0.0109" length="0.002" />
        </geometry>
      <material name="blue_coated_glass">
        <color rgba="0.05 0.18 0.3 0.62" />
        </material>
      </visual>
    <visual name="ocular_socket_1">
      <origin xyz="-0.043 0.032 0" rpy="0 0 0" />
      <geometry>
        <mesh filename="assets/meshes/ocular_socket_1.obj" />
        </geometry>
      <material name="dark_graphite">
        <color rgba="0.1 0.105 0.11 1" />
        </material>
      </visual>
    <visual name="ocular_lens_1">
      <origin xyz="-0.05275 0.032 0" rpy="0 1.5708 0" />
      <geometry>
        <cylinder radius="0.0079" length="0.0015" />
        </geometry>
      <material name="blue_coated_glass">
        <color rgba="0.05 0.18 0.3 0.62" />
        </material>
      </visual>
    <visual name="top_grip_1">
      <origin xyz="0.004 0.032 0.0135" rpy="0 0 0" />
      <geometry>
        <box size="0.05 0.004 0.0035" />
        </geometry>
      <material name="soft_black_rubber">
        <color rgba="0.015 0.014 0.013 1" />
        </material>
      </visual>
    <visual name="side_grip_1">
      <origin xyz="0.004 0.03152 -0.0005" rpy="0 0 0" />
      <geometry>
        <box size="0.048 0.0035 0.012" />
        </geometry>
      <material name="soft_black_rubber">
        <color rgba="0.015 0.014 0.013 1" />
        </material>
      </visual>
    <visual name="bridge_leaf_1">
      <origin xyz="-0.002 0.014 0" rpy="0 0 0" />
      <geometry>
        <box size="0.074 0.024 0.009" />
        </geometry>
      <material name="brushed_black_metal">
        <color rgba="0.025 0.025 0.028 1" />
        </material>
      </visual>
    <visual name="hinge_barrel_1">
      <origin xyz="0 0.001 0" rpy="0 1.5708 0" />
      <geometry>
        <cylinder radius="0.0048" length="0.02" />
        </geometry>
      <material name="brushed_black_metal">
        <color rgba="0.025 0.025 0.028 1" />
        </material>
      </visual>
    <collision name="main_tube_1">
      <origin xyz="0.002 0.032 0" rpy="0 1.5708 0" />
      <geometry>
        <cylinder radius="0.0128" length="0.074" />
        </geometry>
      </collision>
    <collision name="objective_bezel_1">
      <origin xyz="0.045 0.032 0" rpy="0 0 0" />
      <geometry>
        <mesh filename="assets/meshes/objective_bezel_1.obj" />
        </geometry>
      </collision>
    <collision name="objective_lens_1">
      <origin xyz="0.053 0.032 0" rpy="0 1.5708 0" />
      <geometry>
        <cylinder radius="0.0109" length="0.002" />
        </geometry>
      </collision>
    <collision name="ocular_socket_1">
      <origin xyz="-0.043 0.032 0" rpy="0 0 0" />
      <geometry>
        <mesh filename="assets/meshes/ocular_socket_1.obj" />
        </geometry>
      </collision>
    <collision name="ocular_lens_1">
      <origin xyz="-0.05275 0.032 0" rpy="0 1.5708 0" />
      <geometry>
        <cylinder radius="0.0079" length="0.0015" />
        </geometry>
      </collision>
    <collision name="top_grip_1">
      <origin xyz="0.004 0.032 0.0135" rpy="0 0 0" />
      <geometry>
        <box size="0.05 0.004 0.0035" />
        </geometry>
      </collision>
    <collision name="side_grip_1">
      <origin xyz="0.004 0.03152 -0.0005" rpy="0 0 0" />
      <geometry>
        <box size="0.048 0.0035 0.012" />
        </geometry>
      </collision>
    <collision name="bridge_leaf_1">
      <origin xyz="-0.002 0.014 0" rpy="0 0 0" />
      <geometry>
        <box size="0.074 0.024 0.009" />
        </geometry>
      </collision>
    <collision name="hinge_barrel_1">
      <origin xyz="0 0.001 0" rpy="0 1.5708 0" />
      <geometry>
        <cylinder radius="0.0048" length="0.02" />
        </geometry>
      </collision>
    </link>
  <link name="center_knob">
    <visual name="ribbed_wheel">
      <origin xyz="0 0 0" rpy="-1.5708 0 0" />
      <geometry>
        <mesh filename="assets/meshes/center_focus_knob.obj" />
        </geometry>
      <material name="soft_black_rubber">
        <color rgba="0.015 0.014 0.013 1" />
        </material>
      </visual>
    <collision name="ribbed_wheel">
      <origin xyz="0 0 0" rpy="-1.5708 0 0" />
      <geometry>
        <mesh filename="assets/meshes/center_focus_knob.obj" />
        </geometry>
      </collision>
    </link>
  <link name="eyecup_0">
    <visual name="twist_sleeve_0">
      <origin xyz="-0.0065 0 0" rpy="0 0 0" />
      <geometry>
        <mesh filename="assets/meshes/twist_eyecup_0.obj" />
        </geometry>
      <material name="soft_black_rubber">
        <color rgba="0.015 0.014 0.013 1" />
        </material>
      </visual>
    <visual name="eye_lip_0">
      <origin xyz="-0.0165 0 0" rpy="0 0 0" />
      <geometry>
        <mesh filename="assets/meshes/eye_lip_0.obj" />
        </geometry>
      <material name="soft_black_rubber">
        <color rgba="0.015 0.014 0.013 1" />
        </material>
      </visual>
    <collision name="twist_sleeve_0">
      <origin xyz="-0.0065 0 0" rpy="0 0 0" />
      <geometry>
        <mesh filename="assets/meshes/twist_eyecup_0.obj" />
        </geometry>
      </collision>
    <collision name="eye_lip_0">
      <origin xyz="-0.0165 0 0" rpy="0 0 0" />
      <geometry>
        <mesh filename="assets/meshes/eye_lip_0.obj" />
        </geometry>
      </collision>
    </link>
  <link name="eyecup_1">
    <visual name="twist_sleeve_1">
      <origin xyz="-0.0065 0 0" rpy="0 0 0" />
      <geometry>
        <mesh filename="assets/meshes/twist_eyecup_1.obj" />
        </geometry>
      <material name="soft_black_rubber">
        <color rgba="0.015 0.014 0.013 1" />
        </material>
      </visual>
    <visual name="eye_lip_1">
      <origin xyz="-0.0165 0 0" rpy="0 0 0" />
      <geometry>
        <mesh filename="assets/meshes/eye_lip_1.obj" />
        </geometry>
      <material name="soft_black_rubber">
        <color rgba="0.015 0.014 0.013 1" />
        </material>
      </visual>
    <collision name="twist_sleeve_1">
      <origin xyz="-0.0065 0 0" rpy="0 0 0" />
      <geometry>
        <mesh filename="assets/meshes/twist_eyecup_1.obj" />
        </geometry>
      </collision>
    <collision name="eye_lip_1">
      <origin xyz="-0.0165 0 0" rpy="0 0 0" />
      <geometry>
        <mesh filename="assets/meshes/eye_lip_1.obj" />
        </geometry>
      </collision>
    </link>
  <joint name="central_hinge" type="revolute">
    <parent link="barrel_0" />
    <child link="barrel_1" />
    <axis xyz="1 0 0" />
    <limit effort="3" velocity="1" lower="-0.18" upper="0.18" />
    </joint>
  <joint name="focus_knob_joint" type="revolute">
    <origin xyz="-0.03 0 0.034" rpy="0 0 0" />
    <parent link="barrel_0" />
    <child link="center_knob" />
    <axis xyz="0 1 0" />
    <limit effort="0.4" velocity="4" lower="-3.14159" upper="3.14159" />
    </joint>
  <joint name="eyecup_0_twist" type="revolute">
    <origin xyz="-0.052 -0.032 0" rpy="0 0 0" />
    <parent link="barrel_0" />
    <child link="eyecup_0" />
    <axis xyz="1 0 0" />
    <limit effort="0.25" velocity="3" lower="0" upper="1.8326" />
    </joint>
  <joint name="eyecup_1_twist" type="revolute">
    <origin xyz="-0.052 0.032 0" rpy="0 0 0" />
    <parent link="barrel_1" />
    <child link="eyecup_1" />
    <axis xyz="1 0 0" />
    <limit effort="0.25" velocity="3" lower="0" upper="1.8326" />
    </joint>
  </robot>
