<robot name="medieval_iron_cannon">
  <material name="blackened_iron">
    <color rgba="0.05 0.052 0.05 1" />
    </material>
  <material name="sooty_bore">
    <color rgba="0.005 0.004 0.003 1" />
    </material>
  <material name="iron_tire">
    <color rgba="0.025 0.026 0.026 1" />
    </material>
  <material name="aged_oak">
    <color rgba="0.48 0.28 0.12 1" />
    </material>
  <material name="worn_end_grain">
    <color rgba="0.58 0.39 0.2 1" />
    </material>
  <link name="carriage">
    <visual name="side_rail_0">
      <origin xyz="-0.175 -0.31 0.45" rpy="0 -0.271884 0" />
      <geometry>
        <box size="1.72 0.14 0.17" />
        </geometry>
      <material name="aged_oak">
        <color rgba="0.48 0.28 0.12 1" />
        </material>
      </visual>
    <visual name="cheek_block_0">
      <origin xyz="0.02 -0.31 0.555" rpy="0 -0.271884 0" />
      <geometry>
        <box size="0.38 0.15 0.16" />
        </geometry>
      <material name="aged_oak">
        <color rgba="0.48 0.28 0.12 1" />
        </material>
      </visual>
    <visual name="trunnion_saddle_0">
      <origin xyz="0 -0.31 0.665" rpy="0 0 0" />
      <geometry>
        <box size="0.24 0.17 0.16" />
        </geometry>
      <material name="aged_oak">
        <color rgba="0.48 0.28 0.12 1" />
        </material>
      </visual>
    <visual name="side_rail_1">
      <origin xyz="-0.175 0.31 0.45" rpy="0 -0.271884 0" />
      <geometry>
        <box size="1.72 0.14 0.17" />
        </geometry>
      <material name="aged_oak">
        <color rgba="0.48 0.28 0.12 1" />
        </material>
      </visual>
    <visual name="cheek_block_1">
      <origin xyz="0.02 0.31 0.555" rpy="0 -0.271884 0" />
      <geometry>
        <box size="0.38 0.15 0.16" />
        </geometry>
      <material name="aged_oak">
        <color rgba="0.48 0.28 0.12 1" />
        </material>
      </visual>
    <visual name="trunnion_saddle_1">
      <origin xyz="0 0.31 0.665" rpy="0 0 0" />
      <geometry>
        <box size="0.24 0.17 0.16" />
        </geometry>
      <material name="aged_oak">
        <color rgba="0.48 0.28 0.12 1" />
        </material>
      </visual>
    <visual name="front_transom">
      <origin xyz="0.48 0 0.5" rpy="0 -0.271884 0" />
      <geometry>
        <box size="0.22 0.86 0.13" />
        </geometry>
      <material name="aged_oak">
        <color rgba="0.48 0.28 0.12 1" />
        </material>
      </visual>
    <visual name="rear_transom">
      <origin xyz="-0.72 0 0.3" rpy="0 -0.271884 0" />
      <geometry>
        <box size="0.2 0.82 0.13" />
        </geometry>
      <material name="aged_oak">
        <color rgba="0.48 0.28 0.12 1" />
        </material>
      </visual>
    <visual name="rear_skid">
      <origin xyz="-1.02 0 0.07" rpy="0 0 0" />
      <geometry>
        <box size="0.36 0.74 0.14" />
        </geometry>
      <material name="worn_end_grain">
        <color rgba="0.58 0.39 0.2 1" />
        </material>
      </visual>
    <visual name="trail_tongue">
      <origin xyz="-0.7 0 0.23" rpy="0 -0.271884 0" />
      <geometry>
        <box size="0.52 0.18 0.12" />
        </geometry>
      <material name="aged_oak">
        <color rgba="0.48 0.28 0.12 1" />
        </material>
      </visual>
    <visual name="wheel_axle">
      <origin xyz="-0.24 0 0.43" rpy="-1.5708 0 0" />
      <geometry>
        <cylinder radius="0.0575" length="1.42" />
        </geometry>
      <material name="aged_oak">
        <color rgba="0.48 0.28 0.12 1" />
        </material>
      </visual>
    <visual name="axle_cap_0">
      <origin xyz="-0.24 -0.705 0.43" rpy="-1.5708 0 0" />
      <geometry>
        <cylinder radius="0.08" length="0.05" />
        </geometry>
      <material name="iron_tire">
        <color rgba="0.025 0.026 0.026 1" />
        </material>
      </visual>
    <visual name="axle_cap_1">
      <origin xyz="-0.24 0.705 0.43" rpy="-1.5708 0 0" />
      <geometry>
        <cylinder radius="0.08" length="0.05" />
        </geometry>
      <material name="iron_tire">
        <color rgba="0.025 0.026 0.026 1" />
        </material>
      </visual>
    <collision name="side_rail_0">
      <origin xyz="-0.175 -0.31 0.45" rpy="0 -0.271884 0" />
      <geometry>
        <box size="1.72 0.14 0.17" />
        </geometry>
      </collision>
    <collision name="cheek_block_0">
      <origin xyz="0.02 -0.31 0.555" rpy="0 -0.271884 0" />
      <geometry>
        <box size="0.38 0.15 0.16" />
        </geometry>
      </collision>
    <collision name="trunnion_saddle_0">
      <origin xyz="0 -0.31 0.665" rpy="0 0 0" />
      <geometry>
        <box size="0.24 0.17 0.16" />
        </geometry>
      </collision>
    <collision name="side_rail_1">
      <origin xyz="-0.175 0.31 0.45" rpy="0 -0.271884 0" />
      <geometry>
        <box size="1.72 0.14 0.17" />
        </geometry>
      </collision>
    <collision name="cheek_block_1">
      <origin xyz="0.02 0.31 0.555" rpy="0 -0.271884 0" />
      <geometry>
        <box size="0.38 0.15 0.16" />
        </geometry>
      </collision>
    <collision name="trunnion_saddle_1">
      <origin xyz="0 0.31 0.665" rpy="0 0 0" />
      <geometry>
        <box size="0.24 0.17 0.16" />
        </geometry>
      </collision>
    <collision name="front_transom">
      <origin xyz="0.48 0 0.5" rpy="0 -0.271884 0" />
      <geometry>
        <box size="0.22 0.86 0.13" />
        </geometry>
      </collision>
    <collision name="rear_transom">
      <origin xyz="-0.72 0 0.3" rpy="0 -0.271884 0" />
      <geometry>
        <box size="0.2 0.82 0.13" />
        </geometry>
      </collision>
    <collision name="rear_skid">
      <origin xyz="-1.02 0 0.07" rpy="0 0 0" />
      <geometry>
        <box size="0.36 0.74 0.14" />
        </geometry>
      </collision>
    <collision name="trail_tongue">
      <origin xyz="-0.7 0 0.23" rpy="0 -0.271884 0" />
      <geometry>
        <box size="0.52 0.18 0.12" />
        </geometry>
      </collision>
    <collision name="wheel_axle">
      <origin xyz="-0.24 0 0.43" rpy="-1.5708 0 0" />
      <geometry>
        <cylinder radius="0.0575" length="1.42" />
        </geometry>
      </collision>
    <collision name="axle_cap_0">
      <origin xyz="-0.24 -0.705 0.43" rpy="-1.5708 0 0" />
      <geometry>
        <cylinder radius="0.08" length="0.05" />
        </geometry>
      </collision>
    <collision name="axle_cap_1">
      <origin xyz="-0.24 0.705 0.43" rpy="-1.5708 0 0" />
      <geometry>
        <cylinder radius="0.08" length="0.05" />
        </geometry>
      </collision>
    </link>
  <link name="barrel">
    <visual name="barrel_shell">
      <geometry>
        <mesh filename="assets/meshes/barrel_shell.obj" />
        </geometry>
      <material name="blackened_iron">
        <color rgba="0.05 0.052 0.05 1" />
        </material>
      </visual>
    <visual name="trunnion_pin">
      <origin xyz="0 0 0" rpy="-1.5708 0 0" />
      <geometry>
        <cylinder radius="0.075" length="0.92" />
        </geometry>
      <material name="blackened_iron">
        <color rgba="0.05 0.052 0.05 1" />
        </material>
      </visual>
    <visual name="cascabel_neck">
      <origin xyz="-0.8 0 0" rpy="0 1.5708 0" />
      <geometry>
        <cylinder radius="0.085" length="0.16" />
        </geometry>
      <material name="blackened_iron">
        <color rgba="0.05 0.052 0.05 1" />
        </material>
      </visual>
    <visual name="cascabel_knob">
      <origin xyz="-0.91 0 0" rpy="0 0 0" />
      <geometry>
        <sphere radius="0.105" />
        </geometry>
      <material name="blackened_iron">
        <color rgba="0.05 0.052 0.05 1" />
        </material>
      </visual>
    <visual name="dark_muzzle_bore">
      <origin xyz="1.31 0 0" rpy="0 1.5708 0" />
      <geometry>
        <cylinder radius="0.08" length="0.11" />
        </geometry>
      <material name="sooty_bore">
        <color rgba="0.005 0.004 0.003 1" />
        </material>
      </visual>
    <collision name="barrel_shell">
      <geometry>
        <mesh filename="assets/meshes/barrel_shell.obj" />
        </geometry>
      </collision>
    <collision name="trunnion_pin">
      <origin xyz="0 0 0" rpy="-1.5708 0 0" />
      <geometry>
        <cylinder radius="0.075" length="0.92" />
        </geometry>
      </collision>
    <collision name="cascabel_neck">
      <origin xyz="-0.8 0 0" rpy="0 1.5708 0" />
      <geometry>
        <cylinder radius="0.085" length="0.16" />
        </geometry>
      </collision>
    <collision name="cascabel_knob">
      <origin xyz="-0.91 0 0" rpy="0 0 0" />
      <geometry>
        <sphere radius="0.105" />
        </geometry>
      </collision>
    <collision name="dark_muzzle_bore">
      <origin xyz="1.31 0 0" rpy="0 1.5708 0" />
      <geometry>
        <cylinder radius="0.08" length="0.11" />
        </geometry>
      </collision>
    </link>
  <link name="wheel_0">
    <visual name="spoked_wheel">
      <origin xyz="0 0 0" rpy="0 0 1.5708" />
      <geometry>
        <mesh filename="assets/meshes/wooden_spoked_wheel.obj" />
        </geometry>
      <material name="aged_oak">
        <color rgba="0.48 0.28 0.12 1" />
        </material>
      </visual>
    <visual name="iron_hoop">
      <origin xyz="0 0 0" rpy="0 0 1.5708" />
      <geometry>
        <mesh filename="assets/meshes/iron_wheel_hoop.obj" />
        </geometry>
      <material name="iron_tire">
        <color rgba="0.025 0.026 0.026 1" />
        </material>
      </visual>
    <collision name="spoked_wheel">
      <origin xyz="0 0 0" rpy="0 0 1.5708" />
      <geometry>
        <mesh filename="assets/meshes/wooden_spoked_wheel.obj" />
        </geometry>
      </collision>
    <collision name="iron_hoop">
      <origin xyz="0 0 0" rpy="0 0 1.5708" />
      <geometry>
        <mesh filename="assets/meshes/iron_wheel_hoop.obj" />
        </geometry>
      </collision>
    </link>
  <link name="wheel_1">
    <visual name="spoked_wheel">
      <origin xyz="0 0 0" rpy="0 0 1.5708" />
      <geometry>
        <mesh filename="assets/meshes/wooden_spoked_wheel.obj" />
        </geometry>
      <material name="aged_oak">
        <color rgba="0.48 0.28 0.12 1" />
        </material>
      </visual>
    <visual name="iron_hoop">
      <origin xyz="0 0 0" rpy="0 0 1.5708" />
      <geometry>
        <mesh filename="assets/meshes/iron_wheel_hoop.obj" />
        </geometry>
      <material name="iron_tire">
        <color rgba="0.025 0.026 0.026 1" />
        </material>
      </visual>
    <collision name="spoked_wheel">
      <origin xyz="0 0 0" rpy="0 0 1.5708" />
      <geometry>
        <mesh filename="assets/meshes/wooden_spoked_wheel.obj" />
        </geometry>
      </collision>
    <collision name="iron_hoop">
      <origin xyz="0 0 0" rpy="0 0 1.5708" />
      <geometry>
        <mesh filename="assets/meshes/iron_wheel_hoop.obj" />
        </geometry>
      </collision>
    </link>
  <joint name="carriage_to_wheel_0" type="continuous">
    <origin xyz="-0.24 -0.6 0.43" rpy="0 0 0" />
    <parent link="carriage" />
    <child link="wheel_0" />
    <axis xyz="0 1 0" />
    <limit effort="120" velocity="6" />
    </joint>
  <joint name="carriage_to_wheel_1" type="continuous">
    <origin xyz="-0.24 0.6 0.43" rpy="0 0 0" />
    <parent link="carriage" />
    <child link="wheel_1" />
    <axis xyz="0 1 0" />
    <limit effort="120" velocity="6" />
    </joint>
  <joint name="carriage_to_barrel" type="revolute">
    <origin xyz="0 0 0.82" rpy="0 -0.0872665 0" />
    <parent link="carriage" />
    <child link="barrel" />
    <axis xyz="0 -1 0" />
    <limit effort="500" velocity="0.6" lower="-0.18" upper="0.38" />
    </joint>
  </robot>
