<robot name="utility_blimp">
  <material name="warm_grey_fabric">
    <color rgba="0.74 0.75 0.7 1" />
    </material>
  <material name="dull_yellow_panel">
    <color rgba="0.78 0.64 0.28 1" />
    </material>
  <material name="dark_gondola">
    <color rgba="0.12 0.15 0.17 1" />
    </material>
  <material name="blue_grey_glass">
    <color rgba="0.2 0.37 0.5 0.72" />
    </material>
  <material name="brushed_metal">
    <color rgba="0.48 0.5 0.49 1" />
    </material>
  <material name="dark_rubber">
    <color rgba="0.02 0.02 0.018 1" />
    </material>
  <material name="tailplane_grey">
    <color rgba="0.56 0.58 0.55 1" />
    </material>
  <material name="safety_orange">
    <color rgba="0.85 0.25 0.08 1" />
    </material>
  <link name="hull">
    <visual name="envelope_barrel">
      <origin xyz="0 0 0" rpy="0 1.5708 0" />
      <geometry>
        <cylinder radius="1.8" length="7.7" />
        </geometry>
      <material name="warm_grey_fabric">
        <color rgba="0.74 0.75 0.7 1" />
        </material>
      </visual>
    <visual name="nose_cap">
      <origin xyz="3.85 0 0" rpy="0 0 0" />
      <geometry>
        <sphere radius="1.8" />
        </geometry>
      <material name="warm_grey_fabric">
        <color rgba="0.74 0.75 0.7 1" />
        </material>
      </visual>
    <visual name="tail_cap">
      <origin xyz="-3.85 0 0" rpy="0 0 0" />
      <geometry>
        <sphere radius="1.8" />
        </geometry>
      <material name="warm_grey_fabric">
        <color rgba="0.74 0.75 0.7 1" />
        </material>
      </visual>
    <visual name="keel_band">
      <origin xyz="0 0 -1.82" rpy="0 0 0" />
      <geometry>
        <box size="6.8 0.09 0.08" />
        </geometry>
      <material name="dull_yellow_panel">
        <color rgba="0.78 0.64 0.28 1" />
        </material>
      </visual>
    <visual name="gondola_cabin">
      <origin xyz="0.1 0 -2.38" rpy="0 0 0" />
      <geometry>
        <box size="2.7 0.95 0.72" />
        </geometry>
      <material name="dark_gondola">
        <color rgba="0.12 0.15 0.17 1" />
        </material>
      </visual>
    <visual name="side_window_0">
      <origin xyz="0.85 0.484 -2.25" rpy="0 0 0" />
      <geometry>
        <box size="0.46 0.018 0.22" />
        </geometry>
      <material name="blue_grey_glass">
        <color rgba="0.2 0.37 0.5 0.72" />
        </material>
      </visual>
    <visual name="side_window_1">
      <origin xyz="0.25 0.484 -2.25" rpy="0 0 0" />
      <geometry>
        <box size="0.46 0.018 0.22" />
        </geometry>
      <material name="blue_grey_glass">
        <color rgba="0.2 0.37 0.5 0.72" />
        </material>
      </visual>
    <visual name="side_window_2">
      <origin xyz="-0.35 0.484 -2.25" rpy="0 0 0" />
      <geometry>
        <box size="0.46 0.018 0.22" />
        </geometry>
      <material name="blue_grey_glass">
        <color rgba="0.2 0.37 0.5 0.72" />
        </material>
      </visual>
    <visual name="side_window_3">
      <origin xyz="0.85 -0.484 -2.25" rpy="0 0 0" />
      <geometry>
        <box size="0.46 0.018 0.22" />
        </geometry>
      <material name="blue_grey_glass">
        <color rgba="0.2 0.37 0.5 0.72" />
        </material>
      </visual>
    <visual name="side_window_4">
      <origin xyz="0.25 -0.484 -2.25" rpy="0 0 0" />
      <geometry>
        <box size="0.46 0.018 0.22" />
        </geometry>
      <material name="blue_grey_glass">
        <color rgba="0.2 0.37 0.5 0.72" />
        </material>
      </visual>
    <visual name="side_window_5">
      <origin xyz="-0.35 -0.484 -2.25" rpy="0 0 0" />
      <geometry>
        <box size="0.46 0.018 0.22" />
        </geometry>
      <material name="blue_grey_glass">
        <color rgba="0.2 0.37 0.5 0.72" />
        </material>
      </visual>
    <visual name="front_windscreen">
      <origin xyz="1.446 0 -2.24" rpy="0 0 1.5708" />
      <geometry>
        <box size="0.52 0.022 0.23" />
        </geometry>
      <material name="blue_grey_glass">
        <color rgba="0.2 0.37 0.5 0.72" />
        </material>
      </visual>
    <visual name="cabin_strut_0_0">
      <origin xyz="-0.83125 -0.27 -1.84" rpy="0 0.691457 0.648535" />
      <geometry>
        <cylinder radius="0.035" length="0.53734" />
        </geometry>
      <material name="brushed_metal">
        <color rgba="0.48 0.5 0.49 1" />
        </material>
      </visual>
    <visual name="cabin_strut_0_1">
      <origin xyz="-0.83125 0.27 -1.84" rpy="0 0.691457 -0.648535" />
      <geometry>
        <cylinder radius="0.035" length="0.53734" />
        </geometry>
      <material name="brushed_metal">
        <color rgba="0.48 0.5 0.49 1" />
        </material>
      </visual>
    <visual name="cabin_strut_1_0">
      <origin xyz="0.83125 -0.27 -1.84" rpy="0 0.691457 2.49306" />
      <geometry>
        <cylinder radius="0.035" length="0.53734" />
        </geometry>
      <material name="brushed_metal">
        <color rgba="0.48 0.5 0.49 1" />
        </material>
      </visual>
    <visual name="cabin_strut_1_1">
      <origin xyz="0.83125 0.27 -1.84" rpy="0 0.691457 -2.49306" />
      <geometry>
        <cylinder radius="0.035" length="0.53734" />
        </geometry>
      <material name="brushed_metal">
        <color rgba="0.48 0.5 0.49 1" />
        </material>
      </visual>
    <visual name="center_keel_strut">
      <origin xyz="0 0 -1.87" rpy="0 0 0" />
      <geometry>
        <cylinder radius="0.045" length="0.37" />
        </geometry>
      <material name="brushed_metal">
        <color rgba="0.48 0.5 0.49 1" />
        </material>
      </visual>
    <visual name="engine_pod_0">
      <origin xyz="0.02 -2.22 -1.22" rpy="0 1.5708 0" />
      <geometry>
        <cylinder radius="0.27" length="0.84" />
        </geometry>
      <material name="brushed_metal">
        <color rgba="0.48 0.5 0.49 1" />
        </material>
      </visual>
    <visual name="engine_bearing_0">
      <origin xyz="-0.43 -2.22 -1.22" rpy="0 1.5708 0" />
      <geometry>
        <cylinder radius="0.19" length="0.1" />
        </geometry>
      <material name="dark_gondola">
        <color rgba="0.12 0.15 0.17 1" />
        </material>
      </visual>
    <visual name="pod_upper_strut_0">
      <origin xyz="0.13 -1.64 -1.09" rpy="0 1.53993 -1.72579" />
      <geometry>
        <cylinder radius="0.035" length="0.748074" />
        </geometry>
      <material name="brushed_metal">
        <color rgba="0.48 0.5 0.49 1" />
        </material>
      </visual>
    <visual name="pod_lower_strut_0">
      <origin xyz="-0.115 -1.25 -1.745" rpy="0 1.11972 -1.48199" />
      <geometry>
        <cylinder radius="0.032" length="1.72868" />
        </geometry>
      <material name="brushed_metal">
        <color rgba="0.48 0.5 0.49 1" />
        </material>
      </visual>
    <visual name="engine_pod_1">
      <origin xyz="0.02 2.22 -1.22" rpy="0 1.5708 0" />
      <geometry>
        <cylinder radius="0.27" length="0.84" />
        </geometry>
      <material name="brushed_metal">
        <color rgba="0.48 0.5 0.49 1" />
        </material>
      </visual>
    <visual name="engine_bearing_1">
      <origin xyz="-0.43 2.22 -1.22" rpy="0 1.5708 0" />
      <geometry>
        <cylinder radius="0.19" length="0.1" />
        </geometry>
      <material name="dark_gondola">
        <color rgba="0.12 0.15 0.17 1" />
        </material>
      </visual>
    <visual name="pod_upper_strut_1">
      <origin xyz="0.13 1.64 -1.09" rpy="0 1.53993 1.72579" />
      <geometry>
        <cylinder radius="0.035" length="0.748074" />
        </geometry>
      <material name="brushed_metal">
        <color rgba="0.48 0.5 0.49 1" />
        </material>
      </visual>
    <visual name="pod_lower_strut_1">
      <origin xyz="-0.115 1.25 -1.745" rpy="0 1.11972 1.48199" />
      <geometry>
        <cylinder radius="0.032" length="1.72868" />
        </geometry>
      <material name="brushed_metal">
        <color rgba="0.48 0.5 0.49 1" />
        </material>
      </visual>
    <visual name="upper_fin">
      <origin xyz="-5.04 0 1.92" rpy="0 0 0" />
      <geometry>
        <box size="0.78 0.13 1.05" />
        </geometry>
      <material name="tailplane_grey">
        <color rgba="0.56 0.58 0.55 1" />
        </material>
      </visual>
    <visual name="lower_fin">
      <origin xyz="-5.02 0 -1.76" rpy="0 0 0" />
      <geometry>
        <box size="0.76 0.13 0.82" />
        </geometry>
      <material name="tailplane_grey">
        <color rgba="0.56 0.58 0.55 1" />
        </material>
      </visual>
    <visual name="tailplane_0">
      <origin xyz="-5.05 -1.56 0" rpy="0 0 0" />
      <geometry>
        <box size="0.76 1.26 0.1" />
        </geometry>
      <material name="tailplane_grey">
        <color rgba="0.56 0.58 0.55 1" />
        </material>
      </visual>
    <visual name="tailplane_1">
      <origin xyz="-5.05 1.56 0" rpy="0 0 0" />
      <geometry>
        <box size="0.76 1.26 0.1" />
        </geometry>
      <material name="tailplane_grey">
        <color rgba="0.56 0.58 0.55 1" />
        </material>
      </visual>
    <visual name="wheel_fork_bridge">
      <origin xyz="-1.07 0 -2.72" rpy="0 0 0" />
      <geometry>
        <box size="0.3 0.42 0.07" />
        </geometry>
      <material name="brushed_metal">
        <color rgba="0.48 0.5 0.49 1" />
        </material>
      </visual>
    <visual name="wheel_fork_cheek_0">
      <origin xyz="-1.07 -0.18 -2.88" rpy="0 0 0" />
      <geometry>
        <box size="0.16 0.055 0.36" />
        </geometry>
      <material name="brushed_metal">
        <color rgba="0.48 0.5 0.49 1" />
        </material>
      </visual>
    <visual name="wheel_fork_cheek_1">
      <origin xyz="-1.07 0.18 -2.88" rpy="0 0 0" />
      <geometry>
        <box size="0.16 0.055 0.36" />
        </geometry>
      <material name="brushed_metal">
        <color rgba="0.48 0.5 0.49 1" />
        </material>
      </visual>
    <visual name="wheel_axle">
      <origin xyz="-1.07 0 -3.01" rpy="1.5708 0 0" />
      <geometry>
        <cylinder radius="0.024" length="0.47" />
        </geometry>
      <material name="brushed_metal">
        <color rgba="0.48 0.5 0.49 1" />
        </material>
      </visual>
    <collision name="envelope_barrel">
      <origin xyz="0 0 0" rpy="0 1.5708 0" />
      <geometry>
        <cylinder radius="1.8" length="7.7" />
        </geometry>
      </collision>
    <collision name="nose_cap">
      <origin xyz="3.85 0 0" rpy="0 0 0" />
      <geometry>
        <sphere radius="1.8" />
        </geometry>
      </collision>
    <collision name="tail_cap">
      <origin xyz="-3.85 0 0" rpy="0 0 0" />
      <geometry>
        <sphere radius="1.8" />
        </geometry>
      </collision>
    <collision name="keel_band">
      <origin xyz="0 0 -1.82" rpy="0 0 0" />
      <geometry>
        <box size="6.8 0.09 0.08" />
        </geometry>
      </collision>
    <collision name="gondola_cabin">
      <origin xyz="0.1 0 -2.38" rpy="0 0 0" />
      <geometry>
        <box size="2.7 0.95 0.72" />
        </geometry>
      </collision>
    <collision name="side_window_0">
      <origin xyz="0.85 0.484 -2.25" rpy="0 0 0" />
      <geometry>
        <box size="0.46 0.018 0.22" />
        </geometry>
      </collision>
    <collision name="side_window_1">
      <origin xyz="0.25 0.484 -2.25" rpy="0 0 0" />
      <geometry>
        <box size="0.46 0.018 0.22" />
        </geometry>
      </collision>
    <collision name="side_window_2">
      <origin xyz="-0.35 0.484 -2.25" rpy="0 0 0" />
      <geometry>
        <box size="0.46 0.018 0.22" />
        </geometry>
      </collision>
    <collision name="side_window_3">
      <origin xyz="0.85 -0.484 -2.25" rpy="0 0 0" />
      <geometry>
        <box size="0.46 0.018 0.22" />
        </geometry>
      </collision>
    <collision name="side_window_4">
      <origin xyz="0.25 -0.484 -2.25" rpy="0 0 0" />
      <geometry>
        <box size="0.46 0.018 0.22" />
        </geometry>
      </collision>
    <collision name="side_window_5">
      <origin xyz="-0.35 -0.484 -2.25" rpy="0 0 0" />
      <geometry>
        <box size="0.46 0.018 0.22" />
        </geometry>
      </collision>
    <collision name="front_windscreen">
      <origin xyz="1.446 0 -2.24" rpy="0 0 1.5708" />
      <geometry>
        <box size="0.52 0.022 0.23" />
        </geometry>
      </collision>
    <collision name="cabin_strut_0_0">
      <origin xyz="-0.83125 -0.27 -1.84" rpy="0 0.691457 0.648535" />
      <geometry>
        <cylinder radius="0.035" length="0.53734" />
        </geometry>
      </collision>
    <collision name="cabin_strut_0_1">
      <origin xyz="-0.83125 0.27 -1.84" rpy="0 0.691457 -0.648535" />
      <geometry>
        <cylinder radius="0.035" length="0.53734" />
        </geometry>
      </collision>
    <collision name="cabin_strut_1_0">
      <origin xyz="0.83125 -0.27 -1.84" rpy="0 0.691457 2.49306" />
      <geometry>
        <cylinder radius="0.035" length="0.53734" />
        </geometry>
      </collision>
    <collision name="cabin_strut_1_1">
      <origin xyz="0.83125 0.27 -1.84" rpy="0 0.691457 -2.49306" />
      <geometry>
        <cylinder radius="0.035" length="0.53734" />
        </geometry>
      </collision>
    <collision name="center_keel_strut">
      <origin xyz="0 0 -1.87" rpy="0 0 0" />
      <geometry>
        <cylinder radius="0.045" length="0.37" />
        </geometry>
      </collision>
    <collision name="engine_pod_0">
      <origin xyz="0.02 -2.22 -1.22" rpy="0 1.5708 0" />
      <geometry>
        <cylinder radius="0.27" length="0.84" />
        </geometry>
      </collision>
    <collision name="engine_bearing_0">
      <origin xyz="-0.43 -2.22 -1.22" rpy="0 1.5708 0" />
      <geometry>
        <cylinder radius="0.19" length="0.1" />
        </geometry>
      </collision>
    <collision name="pod_upper_strut_0">
      <origin xyz="0.13 -1.64 -1.09" rpy="0 1.53993 -1.72579" />
      <geometry>
        <cylinder radius="0.035" length="0.748074" />
        </geometry>
      </collision>
    <collision name="pod_lower_strut_0">
      <origin xyz="-0.115 -1.25 -1.745" rpy="0 1.11972 -1.48199" />
      <geometry>
        <cylinder radius="0.032" length="1.72868" />
        </geometry>
      </collision>
    <collision name="engine_pod_1">
      <origin xyz="0.02 2.22 -1.22" rpy="0 1.5708 0" />
      <geometry>
        <cylinder radius="0.27" length="0.84" />
        </geometry>
      </collision>
    <collision name="engine_bearing_1">
      <origin xyz="-0.43 2.22 -1.22" rpy="0 1.5708 0" />
      <geometry>
        <cylinder radius="0.19" length="0.1" />
        </geometry>
      </collision>
    <collision name="pod_upper_strut_1">
      <origin xyz="0.13 1.64 -1.09" rpy="0 1.53993 1.72579" />
      <geometry>
        <cylinder radius="0.035" length="0.748074" />
        </geometry>
      </collision>
    <collision name="pod_lower_strut_1">
      <origin xyz="-0.115 1.25 -1.745" rpy="0 1.11972 1.48199" />
      <geometry>
        <cylinder radius="0.032" length="1.72868" />
        </geometry>
      </collision>
    <collision name="upper_fin">
      <origin xyz="-5.04 0 1.92" rpy="0 0 0" />
      <geometry>
        <box size="0.78 0.13 1.05" />
        </geometry>
      </collision>
    <collision name="lower_fin">
      <origin xyz="-5.02 0 -1.76" rpy="0 0 0" />
      <geometry>
        <box size="0.76 0.13 0.82" />
        </geometry>
      </collision>
    <collision name="tailplane_0">
      <origin xyz="-5.05 -1.56 0" rpy="0 0 0" />
      <geometry>
        <box size="0.76 1.26 0.1" />
        </geometry>
      </collision>
    <collision name="tailplane_1">
      <origin xyz="-5.05 1.56 0" rpy="0 0 0" />
      <geometry>
        <box size="0.76 1.26 0.1" />
        </geometry>
      </collision>
    <collision name="wheel_fork_bridge">
      <origin xyz="-1.07 0 -2.72" rpy="0 0 0" />
      <geometry>
        <box size="0.3 0.42 0.07" />
        </geometry>
      </collision>
    <collision name="wheel_fork_cheek_0">
      <origin xyz="-1.07 -0.18 -2.88" rpy="0 0 0" />
      <geometry>
        <box size="0.16 0.055 0.36" />
        </geometry>
      </collision>
    <collision name="wheel_fork_cheek_1">
      <origin xyz="-1.07 0.18 -2.88" rpy="0 0 0" />
      <geometry>
        <box size="0.16 0.055 0.36" />
        </geometry>
      </collision>
    <collision name="wheel_axle">
      <origin xyz="-1.07 0 -3.01" rpy="1.5708 0 0" />
      <geometry>
        <cylinder radius="0.024" length="0.47" />
        </geometry>
      </collision>
    </link>
  <link name="propeller_0">
    <visual name="propeller_shaft">
      <origin xyz="-0.09 0 0" rpy="0 1.5708 0" />
      <geometry>
        <cylinder radius="0.045" length="0.18" />
        </geometry>
      <material name="brushed_metal">
        <color rgba="0.48 0.5 0.49 1" />
        </material>
      </visual>
    <visual name="rotor_blades">
      <origin xyz="-0.2 0 0" rpy="0 1.5708 0" />
      <geometry>
        <mesh filename="assets/meshes/propeller_rotor_0.obj" />
        </geometry>
      <material name="dark_rubber">
        <color rgba="0.02 0.02 0.018 1" />
        </material>
      </visual>
    <collision name="propeller_shaft">
      <origin xyz="-0.09 0 0" rpy="0 1.5708 0" />
      <geometry>
        <cylinder radius="0.045" length="0.18" />
        </geometry>
      </collision>
    <collision name="rotor_blades">
      <origin xyz="-0.2 0 0" rpy="0 1.5708 0" />
      <geometry>
        <mesh filename="assets/meshes/propeller_rotor_0.obj" />
        </geometry>
      </collision>
    </link>
  <link name="propeller_1">
    <visual name="propeller_shaft">
      <origin xyz="-0.09 0 0" rpy="0 1.5708 0" />
      <geometry>
        <cylinder radius="0.045" length="0.18" />
        </geometry>
      <material name="brushed_metal">
        <color rgba="0.48 0.5 0.49 1" />
        </material>
      </visual>
    <visual name="rotor_blades">
      <origin xyz="-0.2 0 0" rpy="0 1.5708 0" />
      <geometry>
        <mesh filename="assets/meshes/propeller_rotor_1.obj" />
        </geometry>
      <material name="dark_rubber">
        <color rgba="0.02 0.02 0.018 1" />
        </material>
      </visual>
    <collision name="propeller_shaft">
      <origin xyz="-0.09 0 0" rpy="0 1.5708 0" />
      <geometry>
        <cylinder radius="0.045" length="0.18" />
        </geometry>
      </collision>
    <collision name="rotor_blades">
      <origin xyz="-0.2 0 0" rpy="0 1.5708 0" />
      <geometry>
        <mesh filename="assets/meshes/propeller_rotor_1.obj" />
        </geometry>
      </collision>
    </link>
  <link name="rudder">
    <visual name="rudder_panel">
      <origin xyz="-0.26 0 0" rpy="0 0 0" />
      <geometry>
        <box size="0.52 0.11 0.96" />
        </geometry>
      <material name="safety_orange">
        <color rgba="0.85 0.25 0.08 1" />
        </material>
      </visual>
    <collision name="rudder_panel">
      <origin xyz="-0.26 0 0" rpy="0 0 0" />
      <geometry>
        <box size="0.52 0.11 0.96" />
        </geometry>
      </collision>
    </link>
  <link name="elevator_0">
    <visual name="elevator_panel">
      <origin xyz="-0.27 0 0" rpy="0 0 0" />
      <geometry>
        <box size="0.54 1.26 0.095" />
        </geometry>
      <material name="safety_orange">
        <color rgba="0.85 0.25 0.08 1" />
        </material>
      </visual>
    <collision name="elevator_panel">
      <origin xyz="-0.27 0 0" rpy="0 0 0" />
      <geometry>
        <box size="0.54 1.26 0.095" />
        </geometry>
      </collision>
    </link>
  <link name="elevator_1">
    <visual name="elevator_panel">
      <origin xyz="-0.27 0 0" rpy="0 0 0" />
      <geometry>
        <box size="0.54 1.26 0.095" />
        </geometry>
      <material name="safety_orange">
        <color rgba="0.85 0.25 0.08 1" />
        </material>
      </visual>
    <collision name="elevator_panel">
      <origin xyz="-0.27 0 0" rpy="0 0 0" />
      <geometry>
        <box size="0.54 1.26 0.095" />
        </geometry>
      </collision>
    </link>
  <link name="mooring_wheel">
    <visual name="axle_sleeve">
      <origin xyz="0 0 0" rpy="1.5708 0 0" />
      <geometry>
        <cylinder radius="0.038" length="0.135" />
        </geometry>
      <material name="brushed_metal">
        <color rgba="0.48 0.5 0.49 1" />
        </material>
      </visual>
    <visual name="tire">
      <origin xyz="0 0 0" rpy="0 0 1.5708" />
      <geometry>
        <mesh filename="assets/meshes/mooring_tire.obj" />
        </geometry>
      <material name="dark_rubber">
        <color rgba="0.02 0.02 0.018 1" />
        </material>
      </visual>
    <visual name="rim">
      <origin xyz="0 0 0" rpy="0 0 1.5708" />
      <geometry>
        <mesh filename="assets/meshes/mooring_wheel_rim.obj" />
        </geometry>
      <material name="brushed_metal">
        <color rgba="0.48 0.5 0.49 1" />
        </material>
      </visual>
    <collision name="axle_sleeve">
      <origin xyz="0 0 0" rpy="1.5708 0 0" />
      <geometry>
        <cylinder radius="0.038" length="0.135" />
        </geometry>
      </collision>
    <collision name="tire">
      <origin xyz="0 0 0" rpy="0 0 1.5708" />
      <geometry>
        <mesh filename="assets/meshes/mooring_tire.obj" />
        </geometry>
      </collision>
    <collision name="rim">
      <origin xyz="0 0 0" rpy="0 0 1.5708" />
      <geometry>
        <mesh filename="assets/meshes/mooring_wheel_rim.obj" />
        </geometry>
      </collision>
    </link>
  <joint name="hull_to_propeller_0" type="continuous">
    <origin xyz="-0.43 -2.22 -1.22" rpy="0 0 0" />
    <parent link="hull" />
    <child link="propeller_0" />
    <axis xyz="1 0 0" />
    <limit effort="12" velocity="80" />
    </joint>
  <joint name="hull_to_propeller_1" type="continuous">
    <origin xyz="-0.43 2.22 -1.22" rpy="0 0 0" />
    <parent link="hull" />
    <child link="propeller_1" />
    <axis xyz="1 0 0" />
    <limit effort="12" velocity="80" />
    </joint>
  <joint name="hull_to_rudder" type="revolute">
    <origin xyz="-5.43 0 1.92" rpy="0 0 0" />
    <parent link="hull" />
    <child link="rudder" />
    <axis xyz="0 0 1" />
    <limit effort="18" velocity="1.4" lower="-0.55" upper="0.55" />
    </joint>
  <joint name="hull_to_elevator_0" type="revolute">
    <origin xyz="-5.43 -1.56 0" rpy="0 0 0" />
    <parent link="hull" />
    <child link="elevator_0" />
    <axis xyz="0 1 0" />
    <limit effort="14" velocity="1.6" lower="-0.42" upper="0.42" />
    </joint>
  <joint name="hull_to_elevator_1" type="revolute">
    <origin xyz="-5.43 1.56 0" rpy="0 0 0" />
    <parent link="hull" />
    <child link="elevator_1" />
    <axis xyz="0 1 0" />
    <limit effort="14" velocity="1.6" lower="-0.42" upper="0.42" />
    </joint>
  <joint name="hull_to_mooring_wheel" type="continuous">
    <origin xyz="-1.07 0 -3.01" rpy="0 0 0" />
    <parent link="hull" />
    <child link="mooring_wheel" />
    <axis xyz="0 1 0" />
    <limit effort="4" velocity="12" />
    </joint>
  </robot>
