<robot name="detailed_top_freezer_refrigerator">
  <material name="warm_white_enamel">
    <color rgba="0.92 0.91 0.86 1" />
    </material>
  <material name="satin_stainless">
    <color rgba="0.72 0.73 0.7 1" />
    </material>
  <material name="charcoal_shadow">
    <color rgba="0.025 0.027 0.03 1" />
    </material>
  <material name="white_plastic_liner">
    <color rgba="0.96 0.96 0.92 1" />
    </material>
  <material name="soft_black_gasket">
    <color rgba="0.015 0.015 0.014 1" />
    </material>
  <material name="slightly_blue_glass">
    <color rgba="0.7 0.88 0.95 0.42" />
    </material>
  <material name="clear_crisper_plastic">
    <color rgba="0.72 0.9 1 0.38" />
    </material>
  <material name="brushed_dark_trim">
    <color rgba="0.18 0.19 0.19 1" />
    </material>
  <link name="cabinet">
    <visual name="side_wall_0">
      <origin xyz="-0.4075 0 0.92" rpy="0 0 0" />
      <geometry>
        <box size="0.045 0.72 1.84" />
        </geometry>
      <material name="warm_white_enamel">
        <color rgba="0.92 0.91 0.86 1" />
        </material>
      </visual>
    <visual name="side_wall_1">
      <origin xyz="0.4075 0 0.92" rpy="0 0 0" />
      <geometry>
        <box size="0.045 0.72 1.84" />
        </geometry>
      <material name="warm_white_enamel">
        <color rgba="0.92 0.91 0.86 1" />
        </material>
      </visual>
    <visual name="back_wall">
      <origin xyz="0 0.3375 0.92" rpy="0 0 0" />
      <geometry>
        <box size="0.86 0.045 1.84" />
        </geometry>
      <material name="warm_white_enamel">
        <color rgba="0.92 0.91 0.86 1" />
        </material>
      </visual>
    <visual name="top_cap">
      <origin xyz="0 0 1.8175" rpy="0 0 0" />
      <geometry>
        <box size="0.86 0.72 0.045" />
        </geometry>
      <material name="warm_white_enamel">
        <color rgba="0.92 0.91 0.86 1" />
        </material>
      </visual>
    <visual name="bottom_pan">
      <origin xyz="0 0 0.0225" rpy="0 0 0" />
      <geometry>
        <box size="0.86 0.72 0.045" />
        </geometry>
      <material name="warm_white_enamel">
        <color rgba="0.92 0.91 0.86 1" />
        </material>
      </visual>
    <visual name="freezer_divider">
      <origin xyz="0 0 1.255" rpy="0 0 0" />
      <geometry>
        <box size="0.86 0.72 0.052" />
        </geometry>
      <material name="warm_white_enamel">
        <color rgba="0.92 0.91 0.86 1" />
        </material>
      </visual>
    <visual name="toe_kick">
      <origin xyz="0 -0.322 0.06" rpy="0 0 0" />
      <geometry>
        <box size="0.86 0.075 0.115" />
        </geometry>
      <material name="brushed_dark_trim">
        <color rgba="0.18 0.19 0.19 1" />
        </material>
      </visual>
    <visual name="toe_grille">
      <origin xyz="0 -0.354 0.07" rpy="1.5708 0 0" />
      <geometry>
        <mesh filename="assets/meshes/toe_grille.obj" />
        </geometry>
      <material name="brushed_dark_trim">
        <color rgba="0.18 0.19 0.19 1" />
        </material>
      </visual>
    <visual name="lower_glass_shelf">
      <origin xyz="0 0.06 0.765" rpy="0 0 0" />
      <geometry>
        <box size="0.77 0.49 0.016" />
        </geometry>
      <material name="slightly_blue_glass">
        <color rgba="0.7 0.88 0.95 0.42" />
        </material>
      </visual>
    <visual name="upper_glass_shelf">
      <origin xyz="0 0.07 1.07" rpy="0 0 0" />
      <geometry>
        <box size="0.77 0.47 0.016" />
        </geometry>
      <material name="slightly_blue_glass">
        <color rgba="0.7 0.88 0.95 0.42" />
        </material>
      </visual>
    <visual name="freezer_shelf">
      <origin xyz="0 0.07 1.545" rpy="0 0 0" />
      <geometry>
        <box size="0.77 0.43 0.014" />
        </geometry>
      <material name="slightly_blue_glass">
        <color rgba="0.7 0.88 0.95 0.42" />
        </material>
      </visual>
    <visual name="crisper_rail_0">
      <origin xyz="-0.376 0.08 0.354" rpy="0 0 0" />
      <geometry>
        <box size="0.018 0.54 0.02" />
        </geometry>
      <material name="white_plastic_liner">
        <color rgba="0.96 0.96 0.92 1" />
        </material>
      </visual>
    <visual name="crisper_rail_1">
      <origin xyz="-0.028 0.08 0.354" rpy="0 0 0" />
      <geometry>
        <box size="0.018 0.54 0.02" />
        </geometry>
      <material name="white_plastic_liner">
        <color rgba="0.96 0.96 0.92 1" />
        </material>
      </visual>
    <visual name="crisper_rail_2">
      <origin xyz="0.028 0.08 0.354" rpy="0 0 0" />
      <geometry>
        <box size="0.018 0.54 0.02" />
        </geometry>
      <material name="white_plastic_liner">
        <color rgba="0.96 0.96 0.92 1" />
        </material>
      </visual>
    <visual name="crisper_rail_3">
      <origin xyz="0.376 0.08 0.354" rpy="0 0 0" />
      <geometry>
        <box size="0.018 0.54 0.02" />
        </geometry>
      <material name="white_plastic_liner">
        <color rgba="0.96 0.96 0.92 1" />
        </material>
      </visual>
    <visual name="center_crisper_rail">
      <origin xyz="0 0.08 0.354" rpy="0 0 0" />
      <geometry>
        <box size="0.018 0.54 0.02" />
        </geometry>
      <material name="white_plastic_liner">
        <color rgba="0.96 0.96 0.92 1" />
        </material>
      </visual>
    <visual name="thermostat_housing">
      <origin xyz="-0.065 -0.155 1.215" rpy="0 0 0" />
      <geometry>
        <box size="0.42 0.06 0.055" />
        </geometry>
      <material name="white_plastic_liner">
        <color rgba="0.96 0.96 0.92 1" />
        </material>
      </visual>
    <visual name="hinge_barrel_0">
      <origin xyz="-0.448 -0.398 0.44" rpy="0 0 0" />
      <geometry>
        <cylinder radius="0.017" length="0.16" />
        </geometry>
      <material name="satin_stainless">
        <color rgba="0.72 0.73 0.7 1" />
        </material>
      </visual>
    <visual name="hinge_leaf_0">
      <origin xyz="-0.439 -0.378 0.44" rpy="0 0 0" />
      <geometry>
        <box size="0.018 0.04 0.12" />
        </geometry>
      <material name="satin_stainless">
        <color rgba="0.72 0.73 0.7 1" />
        </material>
      </visual>
    <visual name="hinge_barrel_1">
      <origin xyz="-0.448 -0.398 1.05" rpy="0 0 0" />
      <geometry>
        <cylinder radius="0.017" length="0.16" />
        </geometry>
      <material name="satin_stainless">
        <color rgba="0.72 0.73 0.7 1" />
        </material>
      </visual>
    <visual name="hinge_leaf_1">
      <origin xyz="-0.439 -0.378 1.05" rpy="0 0 0" />
      <geometry>
        <box size="0.018 0.04 0.12" />
        </geometry>
      <material name="satin_stainless">
        <color rgba="0.72 0.73 0.7 1" />
        </material>
      </visual>
    <visual name="hinge_barrel_2">
      <origin xyz="-0.448 -0.398 1.48" rpy="0 0 0" />
      <geometry>
        <cylinder radius="0.017" length="0.16" />
        </geometry>
      <material name="satin_stainless">
        <color rgba="0.72 0.73 0.7 1" />
        </material>
      </visual>
    <visual name="hinge_leaf_2">
      <origin xyz="-0.439 -0.378 1.48" rpy="0 0 0" />
      <geometry>
        <box size="0.018 0.04 0.12" />
        </geometry>
      <material name="satin_stainless">
        <color rgba="0.72 0.73 0.7 1" />
        </material>
      </visual>
    <visual name="hinge_barrel_3">
      <origin xyz="-0.448 -0.398 1.72" rpy="0 0 0" />
      <geometry>
        <cylinder radius="0.017" length="0.16" />
        </geometry>
      <material name="satin_stainless">
        <color rgba="0.72 0.73 0.7 1" />
        </material>
      </visual>
    <visual name="hinge_leaf_3">
      <origin xyz="-0.439 -0.378 1.72" rpy="0 0 0" />
      <geometry>
        <box size="0.018 0.04 0.12" />
        </geometry>
      <material name="satin_stainless">
        <color rgba="0.72 0.73 0.7 1" />
        </material>
      </visual>
    <collision name="side_wall_0">
      <origin xyz="-0.4075 0 0.92" rpy="0 0 0" />
      <geometry>
        <box size="0.045 0.72 1.84" />
        </geometry>
      </collision>
    <collision name="side_wall_1">
      <origin xyz="0.4075 0 0.92" rpy="0 0 0" />
      <geometry>
        <box size="0.045 0.72 1.84" />
        </geometry>
      </collision>
    <collision name="back_wall">
      <origin xyz="0 0.3375 0.92" rpy="0 0 0" />
      <geometry>
        <box size="0.86 0.045 1.84" />
        </geometry>
      </collision>
    <collision name="top_cap">
      <origin xyz="0 0 1.8175" rpy="0 0 0" />
      <geometry>
        <box size="0.86 0.72 0.045" />
        </geometry>
      </collision>
    <collision name="bottom_pan">
      <origin xyz="0 0 0.0225" rpy="0 0 0" />
      <geometry>
        <box size="0.86 0.72 0.045" />
        </geometry>
      </collision>
    <collision name="freezer_divider">
      <origin xyz="0 0 1.255" rpy="0 0 0" />
      <geometry>
        <box size="0.86 0.72 0.052" />
        </geometry>
      </collision>
    <collision name="toe_kick">
      <origin xyz="0 -0.322 0.06" rpy="0 0 0" />
      <geometry>
        <box size="0.86 0.075 0.115" />
        </geometry>
      </collision>
    <collision name="toe_grille">
      <origin xyz="0 -0.354 0.07" rpy="1.5708 0 0" />
      <geometry>
        <mesh filename="assets/meshes/toe_grille.obj" />
        </geometry>
      </collision>
    <collision name="lower_glass_shelf">
      <origin xyz="0 0.06 0.765" rpy="0 0 0" />
      <geometry>
        <box size="0.77 0.49 0.016" />
        </geometry>
      </collision>
    <collision name="upper_glass_shelf">
      <origin xyz="0 0.07 1.07" rpy="0 0 0" />
      <geometry>
        <box size="0.77 0.47 0.016" />
        </geometry>
      </collision>
    <collision name="freezer_shelf">
      <origin xyz="0 0.07 1.545" rpy="0 0 0" />
      <geometry>
        <box size="0.77 0.43 0.014" />
        </geometry>
      </collision>
    <collision name="crisper_rail_0">
      <origin xyz="-0.376 0.08 0.354" rpy="0 0 0" />
      <geometry>
        <box size="0.018 0.54 0.02" />
        </geometry>
      </collision>
    <collision name="crisper_rail_1">
      <origin xyz="-0.028 0.08 0.354" rpy="0 0 0" />
      <geometry>
        <box size="0.018 0.54 0.02" />
        </geometry>
      </collision>
    <collision name="crisper_rail_2">
      <origin xyz="0.028 0.08 0.354" rpy="0 0 0" />
      <geometry>
        <box size="0.018 0.54 0.02" />
        </geometry>
      </collision>
    <collision name="crisper_rail_3">
      <origin xyz="0.376 0.08 0.354" rpy="0 0 0" />
      <geometry>
        <box size="0.018 0.54 0.02" />
        </geometry>
      </collision>
    <collision name="center_crisper_rail">
      <origin xyz="0 0.08 0.354" rpy="0 0 0" />
      <geometry>
        <box size="0.018 0.54 0.02" />
        </geometry>
      </collision>
    <collision name="thermostat_housing">
      <origin xyz="-0.065 -0.155 1.215" rpy="0 0 0" />
      <geometry>
        <box size="0.42 0.06 0.055" />
        </geometry>
      </collision>
    <collision name="hinge_barrel_0">
      <origin xyz="-0.448 -0.398 0.44" rpy="0 0 0" />
      <geometry>
        <cylinder radius="0.017" length="0.16" />
        </geometry>
      </collision>
    <collision name="hinge_leaf_0">
      <origin xyz="-0.439 -0.378 0.44" rpy="0 0 0" />
      <geometry>
        <box size="0.018 0.04 0.12" />
        </geometry>
      </collision>
    <collision name="hinge_barrel_1">
      <origin xyz="-0.448 -0.398 1.05" rpy="0 0 0" />
      <geometry>
        <cylinder radius="0.017" length="0.16" />
        </geometry>
      </collision>
    <collision name="hinge_leaf_1">
      <origin xyz="-0.439 -0.378 1.05" rpy="0 0 0" />
      <geometry>
        <box size="0.018 0.04 0.12" />
        </geometry>
      </collision>
    <collision name="hinge_barrel_2">
      <origin xyz="-0.448 -0.398 1.48" rpy="0 0 0" />
      <geometry>
        <cylinder radius="0.017" length="0.16" />
        </geometry>
      </collision>
    <collision name="hinge_leaf_2">
      <origin xyz="-0.439 -0.378 1.48" rpy="0 0 0" />
      <geometry>
        <box size="0.018 0.04 0.12" />
        </geometry>
      </collision>
    <collision name="hinge_barrel_3">
      <origin xyz="-0.448 -0.398 1.72" rpy="0 0 0" />
      <geometry>
        <cylinder radius="0.017" length="0.16" />
        </geometry>
      </collision>
    <collision name="hinge_leaf_3">
      <origin xyz="-0.439 -0.378 1.72" rpy="0 0 0" />
      <geometry>
        <box size="0.018 0.04 0.12" />
        </geometry>
      </collision>
    </link>
  <link name="fridge_door">
    <visual name="outer_panel">
      <origin xyz="0.438 0 0" rpy="1.5708 0 0" />
      <geometry>
        <mesh filename="assets/meshes/fridge_door_panel.obj" />
        </geometry>
      <material name="warm_white_enamel">
        <color rgba="0.92 0.91 0.86 1" />
        </material>
      </visual>
    <visual name="pressed_center">
      <origin xyz="0.438 -0.035 0" rpy="0 0 0" />
      <geometry>
        <box size="0.775 0.006 1.015" />
        </geometry>
      <material name="soft_highlight">
        <color rgba="1 1 0.96 1" />
        </material>
      </visual>
    <visual name="handle_backplate">
      <origin xyz="0.798 -0.039 0" rpy="0 0 0" />
      <geometry>
        <box size="0.05 0.012 0.985" />
        </geometry>
      <material name="satin_stainless">
        <color rgba="0.72 0.73 0.7 1" />
        </material>
      </visual>
    <visual name="handle_grip">
      <origin xyz="0.788 -0.1 -0.02" rpy="0 0 0" />
      <geometry>
        <cylinder radius="0.018" length="0.71" />
        </geometry>
      <material name="satin_stainless">
        <color rgba="0.72 0.73 0.7 1" />
        </material>
      </visual>
    <visual name="handle_standoff_0">
      <origin xyz="0.788 -0.071 -0.355" rpy="1.5708 0 0" />
      <geometry>
        <cylinder radius="0.012" length="0.07" />
        </geometry>
      <material name="satin_stainless">
        <color rgba="0.72 0.73 0.7 1" />
        </material>
      </visual>
    <visual name="handle_standoff_1">
      <origin xyz="0.788 -0.071 0.315" rpy="1.5708 0 0" />
      <geometry>
        <cylinder radius="0.012" length="0.07" />
        </geometry>
      <material name="satin_stainless">
        <color rgba="0.72 0.73 0.7 1" />
        </material>
      </visual>
    <visual name="door_bin_back_0">
      <origin xyz="0.438 0.038 -0.205" rpy="0 0 0" />
      <geometry>
        <box size="0.62 0.012 0.075" />
        </geometry>
      <material name="white_plastic_liner">
        <color rgba="0.96 0.96 0.92 1" />
        </material>
      </visual>
    <visual name="door_bin_lip_0">
      <origin xyz="0.438 0.124 -0.225" rpy="0 0 0" />
      <geometry>
        <box size="0.62 0.016 0.06" />
        </geometry>
      <material name="clear_crisper_plastic">
        <color rgba="0.72 0.9 1 0.38" />
        </material>
      </visual>
    <visual name="door_bin_side_0_0">
      <origin xyz="0.128 0.08 -0.215" rpy="0 0 0" />
      <geometry>
        <box size="0.015 0.095 0.08" />
        </geometry>
      <material name="clear_crisper_plastic">
        <color rgba="0.72 0.9 1 0.38" />
        </material>
      </visual>
    <visual name="door_bin_side_0_1">
      <origin xyz="0.748 0.08 -0.215" rpy="0 0 0" />
      <geometry>
        <box size="0.015 0.095 0.08" />
        </geometry>
      <material name="clear_crisper_plastic">
        <color rgba="0.72 0.9 1 0.38" />
        </material>
      </visual>
    <visual name="door_bin_back_1">
      <origin xyz="0.438 0.038 0.115" rpy="0 0 0" />
      <geometry>
        <box size="0.62 0.012 0.075" />
        </geometry>
      <material name="white_plastic_liner">
        <color rgba="0.96 0.96 0.92 1" />
        </material>
      </visual>
    <visual name="door_bin_lip_1">
      <origin xyz="0.438 0.124 0.095" rpy="0 0 0" />
      <geometry>
        <box size="0.62 0.016 0.06" />
        </geometry>
      <material name="clear_crisper_plastic">
        <color rgba="0.72 0.9 1 0.38" />
        </material>
      </visual>
    <visual name="door_bin_side_1_0">
      <origin xyz="0.128 0.08 0.105" rpy="0 0 0" />
      <geometry>
        <box size="0.015 0.095 0.08" />
        </geometry>
      <material name="clear_crisper_plastic">
        <color rgba="0.72 0.9 1 0.38" />
        </material>
      </visual>
    <visual name="door_bin_side_1_1">
      <origin xyz="0.748 0.08 0.105" rpy="0 0 0" />
      <geometry>
        <box size="0.015 0.095 0.08" />
        </geometry>
      <material name="clear_crisper_plastic">
        <color rgba="0.72 0.9 1 0.38" />
        </material>
      </visual>
    <visual name="door_bin_back_2">
      <origin xyz="0.438 0.038 0.405" rpy="0 0 0" />
      <geometry>
        <box size="0.62 0.012 0.075" />
        </geometry>
      <material name="white_plastic_liner">
        <color rgba="0.96 0.96 0.92 1" />
        </material>
      </visual>
    <visual name="door_bin_lip_2">
      <origin xyz="0.438 0.124 0.385" rpy="0 0 0" />
      <geometry>
        <box size="0.62 0.016 0.06" />
        </geometry>
      <material name="clear_crisper_plastic">
        <color rgba="0.72 0.9 1 0.38" />
        </material>
      </visual>
    <visual name="door_bin_side_2_0">
      <origin xyz="0.128 0.08 0.395" rpy="0 0 0" />
      <geometry>
        <box size="0.015 0.095 0.08" />
        </geometry>
      <material name="clear_crisper_plastic">
        <color rgba="0.72 0.9 1 0.38" />
        </material>
      </visual>
    <visual name="door_bin_side_2_1">
      <origin xyz="0.748 0.08 0.395" rpy="0 0 0" />
      <geometry>
        <box size="0.015 0.095 0.08" />
        </geometry>
      <material name="clear_crisper_plastic">
        <color rgba="0.72 0.9 1 0.38" />
        </material>
      </visual>
    <visual name="gasket_top">
      <origin xyz="0.438 0.038 0.5125" rpy="0 0 0" />
      <geometry>
        <box size="0.72 0.01 0.026" />
        </geometry>
      <material name="soft_black_gasket">
        <color rgba="0.015 0.015 0.014 1" />
        </material>
      </visual>
    <visual name="gasket_bottom">
      <origin xyz="0.438 0.038 -0.5125" rpy="0 0 0" />
      <geometry>
        <box size="0.72 0.01 0.026" />
        </geometry>
      <material name="soft_black_gasket">
        <color rgba="0.015 0.015 0.014 1" />
        </material>
      </visual>
    <visual name="gasket_hinge">
      <origin xyz="0.098 0.038 0" rpy="0 0 0" />
      <geometry>
        <box size="0.026 0.01 1.025" />
        </geometry>
      <material name="soft_black_gasket">
        <color rgba="0.015 0.015 0.014 1" />
        </material>
      </visual>
    <visual name="gasket_latch">
      <origin xyz="0.823 0.038 0" rpy="0 0 0" />
      <geometry>
        <box size="0.026 0.01 1.025" />
        </geometry>
      <material name="soft_black_gasket">
        <color rgba="0.015 0.015 0.014 1" />
        </material>
      </visual>
    <collision name="outer_panel">
      <origin xyz="0.438 0 0" rpy="1.5708 0 0" />
      <geometry>
        <mesh filename="assets/meshes/fridge_door_panel.obj" />
        </geometry>
      </collision>
    <collision name="pressed_center">
      <origin xyz="0.438 -0.035 0" rpy="0 0 0" />
      <geometry>
        <box size="0.775 0.006 1.015" />
        </geometry>
      </collision>
    <collision name="handle_backplate">
      <origin xyz="0.798 -0.039 0" rpy="0 0 0" />
      <geometry>
        <box size="0.05 0.012 0.985" />
        </geometry>
      </collision>
    <collision name="handle_grip">
      <origin xyz="0.788 -0.1 -0.02" rpy="0 0 0" />
      <geometry>
        <cylinder radius="0.018" length="0.71" />
        </geometry>
      </collision>
    <collision name="handle_standoff_0">
      <origin xyz="0.788 -0.071 -0.355" rpy="1.5708 0 0" />
      <geometry>
        <cylinder radius="0.012" length="0.07" />
        </geometry>
      </collision>
    <collision name="handle_standoff_1">
      <origin xyz="0.788 -0.071 0.315" rpy="1.5708 0 0" />
      <geometry>
        <cylinder radius="0.012" length="0.07" />
        </geometry>
      </collision>
    <collision name="door_bin_back_0">
      <origin xyz="0.438 0.038 -0.205" rpy="0 0 0" />
      <geometry>
        <box size="0.62 0.012 0.075" />
        </geometry>
      </collision>
    <collision name="door_bin_lip_0">
      <origin xyz="0.438 0.124 -0.225" rpy="0 0 0" />
      <geometry>
        <box size="0.62 0.016 0.06" />
        </geometry>
      </collision>
    <collision name="door_bin_side_0_0">
      <origin xyz="0.128 0.08 -0.215" rpy="0 0 0" />
      <geometry>
        <box size="0.015 0.095 0.08" />
        </geometry>
      </collision>
    <collision name="door_bin_side_0_1">
      <origin xyz="0.748 0.08 -0.215" rpy="0 0 0" />
      <geometry>
        <box size="0.015 0.095 0.08" />
        </geometry>
      </collision>
    <collision name="door_bin_back_1">
      <origin xyz="0.438 0.038 0.115" rpy="0 0 0" />
      <geometry>
        <box size="0.62 0.012 0.075" />
        </geometry>
      </collision>
    <collision name="door_bin_lip_1">
      <origin xyz="0.438 0.124 0.095" rpy="0 0 0" />
      <geometry>
        <box size="0.62 0.016 0.06" />
        </geometry>
      </collision>
    <collision name="door_bin_side_1_0">
      <origin xyz="0.128 0.08 0.105" rpy="0 0 0" />
      <geometry>
        <box size="0.015 0.095 0.08" />
        </geometry>
      </collision>
    <collision name="door_bin_side_1_1">
      <origin xyz="0.748 0.08 0.105" rpy="0 0 0" />
      <geometry>
        <box size="0.015 0.095 0.08" />
        </geometry>
      </collision>
    <collision name="door_bin_back_2">
      <origin xyz="0.438 0.038 0.405" rpy="0 0 0" />
      <geometry>
        <box size="0.62 0.012 0.075" />
        </geometry>
      </collision>
    <collision name="door_bin_lip_2">
      <origin xyz="0.438 0.124 0.385" rpy="0 0 0" />
      <geometry>
        <box size="0.62 0.016 0.06" />
        </geometry>
      </collision>
    <collision name="door_bin_side_2_0">
      <origin xyz="0.128 0.08 0.395" rpy="0 0 0" />
      <geometry>
        <box size="0.015 0.095 0.08" />
        </geometry>
      </collision>
    <collision name="door_bin_side_2_1">
      <origin xyz="0.748 0.08 0.395" rpy="0 0 0" />
      <geometry>
        <box size="0.015 0.095 0.08" />
        </geometry>
      </collision>
    <collision name="gasket_top">
      <origin xyz="0.438 0.038 0.5125" rpy="0 0 0" />
      <geometry>
        <box size="0.72 0.01 0.026" />
        </geometry>
      </collision>
    <collision name="gasket_bottom">
      <origin xyz="0.438 0.038 -0.5125" rpy="0 0 0" />
      <geometry>
        <box size="0.72 0.01 0.026" />
        </geometry>
      </collision>
    <collision name="gasket_hinge">
      <origin xyz="0.098 0.038 0" rpy="0 0 0" />
      <geometry>
        <box size="0.026 0.01 1.025" />
        </geometry>
      </collision>
    <collision name="gasket_latch">
      <origin xyz="0.823 0.038 0" rpy="0 0 0" />
      <geometry>
        <box size="0.026 0.01 1.025" />
        </geometry>
      </collision>
    </link>
  <link name="freezer_door">
    <visual name="outer_panel">
      <origin xyz="0.438 0 0" rpy="1.5708 0 0" />
      <geometry>
        <mesh filename="assets/meshes/freezer_door_panel.obj" />
        </geometry>
      <material name="warm_white_enamel">
        <color rgba="0.92 0.91 0.86 1" />
        </material>
      </visual>
    <visual name="pressed_center">
      <origin xyz="0.438 -0.035 0" rpy="0 0 0" />
      <geometry>
        <box size="0.77 0.006 0.43" />
        </geometry>
      <material name="subtle_upper_highlight">
        <color rgba="0.98 0.98 0.94 1" />
        </material>
      </visual>
    <visual name="handle_backplate">
      <origin xyz="0.798 -0.039 -0.01" rpy="0 0 0" />
      <geometry>
        <box size="0.05 0.012 0.36" />
        </geometry>
      <material name="satin_stainless">
        <color rgba="0.72 0.73 0.7 1" />
        </material>
      </visual>
    <visual name="handle_grip">
      <origin xyz="0.788 -0.1 -0.005" rpy="0 0 0" />
      <geometry>
        <cylinder radius="0.017" length="0.3" />
        </geometry>
      <material name="satin_stainless">
        <color rgba="0.72 0.73 0.7 1" />
        </material>
      </visual>
    <visual name="handle_standoff_0">
      <origin xyz="0.788 -0.071 -0.13" rpy="1.5708 0 0" />
      <geometry>
        <cylinder radius="0.011" length="0.07" />
        </geometry>
      <material name="satin_stainless">
        <color rgba="0.72 0.73 0.7 1" />
        </material>
      </visual>
    <visual name="handle_standoff_1">
      <origin xyz="0.788 -0.071 0.115" rpy="1.5708 0 0" />
      <geometry>
        <cylinder radius="0.011" length="0.07" />
        </geometry>
      <material name="satin_stainless">
        <color rgba="0.72 0.73 0.7 1" />
        </material>
      </visual>
    <visual name="door_bin_back">
      <origin xyz="0.438 0.038 -0.1" rpy="0 0 0" />
      <geometry>
        <box size="0.58 0.012 0.07" />
        </geometry>
      <material name="white_plastic_liner">
        <color rgba="0.96 0.96 0.92 1" />
        </material>
      </visual>
    <visual name="door_bin_lip">
      <origin xyz="0.438 0.118 -0.115" rpy="0 0 0" />
      <geometry>
        <box size="0.58 0.016 0.055" />
        </geometry>
      <material name="clear_crisper_plastic">
        <color rgba="0.72 0.9 1 0.38" />
        </material>
      </visual>
    <visual name="door_bin_side_0">
      <origin xyz="0.148 0.078 -0.11" rpy="0 0 0" />
      <geometry>
        <box size="0.015 0.092 0.07" />
        </geometry>
      <material name="clear_crisper_plastic">
        <color rgba="0.72 0.9 1 0.38" />
        </material>
      </visual>
    <visual name="door_bin_side_1">
      <origin xyz="0.728 0.078 -0.11" rpy="0 0 0" />
      <geometry>
        <box size="0.015 0.092 0.07" />
        </geometry>
      <material name="clear_crisper_plastic">
        <color rgba="0.72 0.9 1 0.38" />
        </material>
      </visual>
    <visual name="gasket_top">
      <origin xyz="0.438 0.038 0.2175" rpy="0 0 0" />
      <geometry>
        <box size="0.72 0.01 0.024" />
        </geometry>
      <material name="soft_black_gasket">
        <color rgba="0.015 0.015 0.014 1" />
        </material>
      </visual>
    <visual name="gasket_bottom">
      <origin xyz="0.438 0.038 -0.2175" rpy="0 0 0" />
      <geometry>
        <box size="0.72 0.01 0.024" />
        </geometry>
      <material name="soft_black_gasket">
        <color rgba="0.015 0.015 0.014 1" />
        </material>
      </visual>
    <visual name="gasket_hinge">
      <origin xyz="0.098 0.038 0" rpy="0 0 0" />
      <geometry>
        <box size="0.024 0.01 0.435" />
        </geometry>
      <material name="soft_black_gasket">
        <color rgba="0.015 0.015 0.014 1" />
        </material>
      </visual>
    <visual name="gasket_latch">
      <origin xyz="0.823 0.038 0" rpy="0 0 0" />
      <geometry>
        <box size="0.024 0.01 0.435" />
        </geometry>
      <material name="soft_black_gasket">
        <color rgba="0.015 0.015 0.014 1" />
        </material>
      </visual>
    <collision name="outer_panel">
      <origin xyz="0.438 0 0" rpy="1.5708 0 0" />
      <geometry>
        <mesh filename="assets/meshes/freezer_door_panel.obj" />
        </geometry>
      </collision>
    <collision name="pressed_center">
      <origin xyz="0.438 -0.035 0" rpy="0 0 0" />
      <geometry>
        <box size="0.77 0.006 0.43" />
        </geometry>
      </collision>
    <collision name="handle_backplate">
      <origin xyz="0.798 -0.039 -0.01" rpy="0 0 0" />
      <geometry>
        <box size="0.05 0.012 0.36" />
        </geometry>
      </collision>
    <collision name="handle_grip">
      <origin xyz="0.788 -0.1 -0.005" rpy="0 0 0" />
      <geometry>
        <cylinder radius="0.017" length="0.3" />
        </geometry>
      </collision>
    <collision name="handle_standoff_0">
      <origin xyz="0.788 -0.071 -0.13" rpy="1.5708 0 0" />
      <geometry>
        <cylinder radius="0.011" length="0.07" />
        </geometry>
      </collision>
    <collision name="handle_standoff_1">
      <origin xyz="0.788 -0.071 0.115" rpy="1.5708 0 0" />
      <geometry>
        <cylinder radius="0.011" length="0.07" />
        </geometry>
      </collision>
    <collision name="door_bin_back">
      <origin xyz="0.438 0.038 -0.1" rpy="0 0 0" />
      <geometry>
        <box size="0.58 0.012 0.07" />
        </geometry>
      </collision>
    <collision name="door_bin_lip">
      <origin xyz="0.438 0.118 -0.115" rpy="0 0 0" />
      <geometry>
        <box size="0.58 0.016 0.055" />
        </geometry>
      </collision>
    <collision name="door_bin_side_0">
      <origin xyz="0.148 0.078 -0.11" rpy="0 0 0" />
      <geometry>
        <box size="0.015 0.092 0.07" />
        </geometry>
      </collision>
    <collision name="door_bin_side_1">
      <origin xyz="0.728 0.078 -0.11" rpy="0 0 0" />
      <geometry>
        <box size="0.015 0.092 0.07" />
        </geometry>
      </collision>
    <collision name="gasket_top">
      <origin xyz="0.438 0.038 0.2175" rpy="0 0 0" />
      <geometry>
        <box size="0.72 0.01 0.024" />
        </geometry>
      </collision>
    <collision name="gasket_bottom">
      <origin xyz="0.438 0.038 -0.2175" rpy="0 0 0" />
      <geometry>
        <box size="0.72 0.01 0.024" />
        </geometry>
      </collision>
    <collision name="gasket_hinge">
      <origin xyz="0.098 0.038 0" rpy="0 0 0" />
      <geometry>
        <box size="0.024 0.01 0.435" />
        </geometry>
      </collision>
    <collision name="gasket_latch">
      <origin xyz="0.823 0.038 0" rpy="0 0 0" />
      <geometry>
        <box size="0.024 0.01 0.435" />
        </geometry>
      </collision>
    </link>
  <link name="crisper_drawer_0">
    <visual name="bottom">
      <origin xyz="0 0 -0.075" rpy="0 0 0" />
      <geometry>
        <box size="0.335 0.39 0.012" />
        </geometry>
      <material name="clear_crisper_plastic">
        <color rgba="0.72 0.9 1 0.38" />
        </material>
      </visual>
    <visual name="front_wall">
      <origin xyz="0 -0.195 0" rpy="0 0 0" />
      <geometry>
        <box size="0.335 0.018 0.155" />
        </geometry>
      <material name="clear_crisper_plastic">
        <color rgba="0.72 0.9 1 0.38" />
        </material>
      </visual>
    <visual name="back_wall">
      <origin xyz="0 0.195 -0.01" rpy="0 0 0" />
      <geometry>
        <box size="0.335 0.014 0.13" />
        </geometry>
      <material name="clear_crisper_plastic">
        <color rgba="0.72 0.9 1 0.38" />
        </material>
      </visual>
    <visual name="side_wall_0">
      <origin xyz="-0.167 0 -0.005" rpy="0 0 0" />
      <geometry>
        <box size="0.014 0.39 0.145" />
        </geometry>
      <material name="clear_crisper_plastic">
        <color rgba="0.72 0.9 1 0.38" />
        </material>
      </visual>
    <visual name="side_wall_1">
      <origin xyz="0.167 0 -0.005" rpy="0 0 0" />
      <geometry>
        <box size="0.014 0.39 0.145" />
        </geometry>
      <material name="clear_crisper_plastic">
        <color rgba="0.72 0.9 1 0.38" />
        </material>
      </visual>
    <visual name="pull_lip">
      <origin xyz="0 -0.212 0.045" rpy="0 0 0" />
      <geometry>
        <box size="0.24 0.02 0.025" />
        </geometry>
      <material name="brushed_dark_trim">
        <color rgba="0.18 0.19 0.19 1" />
        </material>
      </visual>
    <visual name="top_rim">
      <origin xyz="0 0 0.076" rpy="0 0 0" />
      <geometry>
        <box size="0.35 0.018 0.018" />
        </geometry>
      <material name="clear_crisper_plastic">
        <color rgba="0.72 0.9 1 0.38" />
        </material>
      </visual>
    <collision name="bottom">
      <origin xyz="0 0 -0.075" rpy="0 0 0" />
      <geometry>
        <box size="0.335 0.39 0.012" />
        </geometry>
      </collision>
    <collision name="front_wall">
      <origin xyz="0 -0.195 0" rpy="0 0 0" />
      <geometry>
        <box size="0.335 0.018 0.155" />
        </geometry>
      </collision>
    <collision name="back_wall">
      <origin xyz="0 0.195 -0.01" rpy="0 0 0" />
      <geometry>
        <box size="0.335 0.014 0.13" />
        </geometry>
      </collision>
    <collision name="side_wall_0">
      <origin xyz="-0.167 0 -0.005" rpy="0 0 0" />
      <geometry>
        <box size="0.014 0.39 0.145" />
        </geometry>
      </collision>
    <collision name="side_wall_1">
      <origin xyz="0.167 0 -0.005" rpy="0 0 0" />
      <geometry>
        <box size="0.014 0.39 0.145" />
        </geometry>
      </collision>
    <collision name="pull_lip">
      <origin xyz="0 -0.212 0.045" rpy="0 0 0" />
      <geometry>
        <box size="0.24 0.02 0.025" />
        </geometry>
      </collision>
    <collision name="top_rim">
      <origin xyz="0 0 0.076" rpy="0 0 0" />
      <geometry>
        <box size="0.35 0.018 0.018" />
        </geometry>
      </collision>
    </link>
  <link name="crisper_drawer_1">
    <visual name="bottom">
      <origin xyz="0 0 -0.075" rpy="0 0 0" />
      <geometry>
        <box size="0.335 0.39 0.012" />
        </geometry>
      <material name="clear_crisper_plastic">
        <color rgba="0.72 0.9 1 0.38" />
        </material>
      </visual>
    <visual name="front_wall">
      <origin xyz="0 -0.195 0" rpy="0 0 0" />
      <geometry>
        <box size="0.335 0.018 0.155" />
        </geometry>
      <material name="clear_crisper_plastic">
        <color rgba="0.72 0.9 1 0.38" />
        </material>
      </visual>
    <visual name="back_wall">
      <origin xyz="0 0.195 -0.01" rpy="0 0 0" />
      <geometry>
        <box size="0.335 0.014 0.13" />
        </geometry>
      <material name="clear_crisper_plastic">
        <color rgba="0.72 0.9 1 0.38" />
        </material>
      </visual>
    <visual name="side_wall_0">
      <origin xyz="-0.167 0 -0.005" rpy="0 0 0" />
      <geometry>
        <box size="0.014 0.39 0.145" />
        </geometry>
      <material name="clear_crisper_plastic">
        <color rgba="0.72 0.9 1 0.38" />
        </material>
      </visual>
    <visual name="side_wall_1">
      <origin xyz="0.167 0 -0.005" rpy="0 0 0" />
      <geometry>
        <box size="0.014 0.39 0.145" />
        </geometry>
      <material name="clear_crisper_plastic">
        <color rgba="0.72 0.9 1 0.38" />
        </material>
      </visual>
    <visual name="pull_lip">
      <origin xyz="0 -0.212 0.045" rpy="0 0 0" />
      <geometry>
        <box size="0.24 0.02 0.025" />
        </geometry>
      <material name="brushed_dark_trim">
        <color rgba="0.18 0.19 0.19 1" />
        </material>
      </visual>
    <visual name="top_rim">
      <origin xyz="0 0 0.076" rpy="0 0 0" />
      <geometry>
        <box size="0.35 0.018 0.018" />
        </geometry>
      <material name="clear_crisper_plastic">
        <color rgba="0.72 0.9 1 0.38" />
        </material>
      </visual>
    <collision name="bottom">
      <origin xyz="0 0 -0.075" rpy="0 0 0" />
      <geometry>
        <box size="0.335 0.39 0.012" />
        </geometry>
      </collision>
    <collision name="front_wall">
      <origin xyz="0 -0.195 0" rpy="0 0 0" />
      <geometry>
        <box size="0.335 0.018 0.155" />
        </geometry>
      </collision>
    <collision name="back_wall">
      <origin xyz="0 0.195 -0.01" rpy="0 0 0" />
      <geometry>
        <box size="0.335 0.014 0.13" />
        </geometry>
      </collision>
    <collision name="side_wall_0">
      <origin xyz="-0.167 0 -0.005" rpy="0 0 0" />
      <geometry>
        <box size="0.014 0.39 0.145" />
        </geometry>
      </collision>
    <collision name="side_wall_1">
      <origin xyz="0.167 0 -0.005" rpy="0 0 0" />
      <geometry>
        <box size="0.014 0.39 0.145" />
        </geometry>
      </collision>
    <collision name="pull_lip">
      <origin xyz="0 -0.212 0.045" rpy="0 0 0" />
      <geometry>
        <box size="0.24 0.02 0.025" />
        </geometry>
      </collision>
    <collision name="top_rim">
      <origin xyz="0 0 0.076" rpy="0 0 0" />
      <geometry>
        <box size="0.35 0.018 0.018" />
        </geometry>
      </collision>
    </link>
  <link name="thermostat_dial">
    <visual name="dial_cap">
      <origin xyz="0 0 0" rpy="1.5708 0 0" />
      <geometry>
        <mesh filename="assets/meshes/thermostat_dial.obj" />
        </geometry>
      <material name="brushed_dark_trim">
        <color rgba="0.18 0.19 0.19 1" />
        </material>
      </visual>
    <collision name="dial_cap">
      <origin xyz="0 0 0" rpy="1.5708 0 0" />
      <geometry>
        <mesh filename="assets/meshes/thermostat_dial.obj" />
        </geometry>
      </collision>
    </link>
  <joint name="cabinet_to_fridge_door" type="revolute">
    <origin xyz="-0.448 -0.398 0.685" rpy="0 0 0" />
    <parent link="cabinet" />
    <child link="fridge_door" />
    <axis xyz="0 0 -1" />
    <limit effort="80" velocity="1.6" lower="0" upper="1.75" />
    </joint>
  <joint name="cabinet_to_freezer_door" type="revolute">
    <origin xyz="-0.448 -0.398 1.535" rpy="0 0 0" />
    <parent link="cabinet" />
    <child link="freezer_door" />
    <axis xyz="0 0 -1" />
    <limit effort="60" velocity="1.8" lower="0" upper="1.75" />
    </joint>
  <joint name="cabinet_to_crisper_0" type="prismatic">
    <origin xyz="-0.195 0.055 0.445" rpy="0 0 0" />
    <parent link="cabinet" />
    <child link="crisper_drawer_0" />
    <axis xyz="0 -1 0" />
    <limit effort="45" velocity="0.35" lower="0" upper="0.32" />
    </joint>
  <joint name="cabinet_to_crisper_1" type="prismatic">
    <origin xyz="0.195 0.055 0.445" rpy="0 0 0" />
    <parent link="cabinet" />
    <child link="crisper_drawer_1" />
    <axis xyz="0 -1 0" />
    <limit effort="45" velocity="0.35" lower="0" upper="0.32" />
    </joint>
  <joint name="cabinet_to_thermostat_dial" type="revolute">
    <origin xyz="-0.205 -0.195 1.185" rpy="0 0 0" />
    <parent link="cabinet" />
    <child link="thermostat_dial" />
    <axis xyz="0 -1 0" />
    <limit effort="0.8" velocity="2" lower="-2.35" upper="2.35" />
    </joint>
  </robot>
