<robot name="traction_passenger_elevator">
  <material name="galvanized_steel">
    <color rgba="0.58 0.62 0.64 1" />
    </material>
  <material name="brushed_stainless">
    <color rgba="0.78 0.8 0.8 1" />
    </material>
  <material name="dark_rubber">
    <color rgba="0.04 0.045 0.05 1" />
    </material>
  <material name="smoked_glass">
    <color rgba="0.08 0.13 0.16 0.72" />
    </material>
  <material name="pale_shaft_wall">
    <color rgba="0.72 0.76 0.78 0.42" />
    </material>
  <material name="machined_rail">
    <color rgba="0.42 0.44 0.45 1" />
    </material>
  <material name="black_hoist_cable">
    <color rgba="0.01 0.01 0.012 1" />
    </material>
  <material name="safety_yellow">
    <color rgba="0.95 0.72 0.08 1" />
    </material>
  <link name="shaft">
    <visual name="pit_floor">
      <origin xyz="0 0 0.08" rpy="0 0 0" />
      <geometry>
        <box size="3.35 3.15 0.16" />
        </geometry>
      <material name="pale_shaft_wall">
        <color rgba="0.72 0.76 0.78 0.42" />
        </material>
      </visual>
    <visual name="rear_wall">
      <origin xyz="0 1.52 4" rpy="0 0 0" />
      <geometry>
        <box size="3.35 0.12 8" />
        </geometry>
      <material name="pale_shaft_wall">
        <color rgba="0.72 0.76 0.78 0.42" />
        </material>
      </visual>
    <visual name="side_wall_0">
      <origin xyz="-1.675 0 4" rpy="0 0 0" />
      <geometry>
        <box size="0.12 3.15 8" />
        </geometry>
      <material name="pale_shaft_wall">
        <color rgba="0.72 0.76 0.78 0.42" />
        </material>
      </visual>
    <visual name="side_wall_1">
      <origin xyz="1.675 0 4" rpy="0 0 0" />
      <geometry>
        <box size="0.12 3.15 8" />
        </geometry>
      <material name="pale_shaft_wall">
        <color rgba="0.72 0.76 0.78 0.42" />
        </material>
      </visual>
    <visual name="overhead_slab">
      <origin xyz="0 0 8.09" rpy="0 0 0" />
      <geometry>
        <box size="3.35 3.15 0.18" />
        </geometry>
      <material name="pale_shaft_wall">
        <color rgba="0.72 0.76 0.78 0.42" />
        </material>
      </visual>
    <visual name="landing_jamb_0">
      <origin xyz="-1.12 -1.52 1.25" rpy="0 0 0" />
      <geometry>
        <box size="0.14 0.14 2.35" />
        </geometry>
      <material name="galvanized_steel">
        <color rgba="0.58 0.62 0.64 1" />
        </material>
      </visual>
    <visual name="landing_jamb_1">
      <origin xyz="1.12 -1.52 1.25" rpy="0 0 0" />
      <geometry>
        <box size="0.14 0.14 2.35" />
        </geometry>
      <material name="galvanized_steel">
        <color rgba="0.58 0.62 0.64 1" />
        </material>
      </visual>
    <visual name="landing_header">
      <origin xyz="0 -1.52 2.38" rpy="0 0 0" />
      <geometry>
        <box size="2.38 0.14 0.18" />
        </geometry>
      <material name="galvanized_steel">
        <color rgba="0.58 0.62 0.64 1" />
        </material>
      </visual>
    <visual name="landing_sill">
      <origin xyz="0 -1.5 0.2" rpy="0 0 0" />
      <geometry>
        <box size="2.38 0.18 0.08" />
        </geometry>
      <material name="dark_rubber">
        <color rgba="0.04 0.045 0.05 1" />
        </material>
      </visual>
    <visual name="guide_rail_0">
      <origin xyz="-1.22 0.35 3.93" rpy="0 0 0" />
      <geometry>
        <box size="0.07 0.09 7.7" />
        </geometry>
      <material name="machined_rail">
        <color rgba="0.42 0.44 0.45 1" />
        </material>
      </visual>
    <visual name="guide_rail_1">
      <origin xyz="1.22 0.35 3.93" rpy="0 0 0" />
      <geometry>
        <box size="0.07 0.09 7.7" />
        </geometry>
      <material name="machined_rail">
        <color rgba="0.42 0.44 0.45 1" />
        </material>
      </visual>
    <visual name="counter_rail_0">
      <origin xyz="1.48 0.45 3.86" rpy="0 0 0" />
      <geometry>
        <box size="0.12 0.1 7.4" />
        </geometry>
      <material name="machined_rail">
        <color rgba="0.42 0.44 0.45 1" />
        </material>
      </visual>
    <visual name="counter_rail_1">
      <origin xyz="1.48 1.45 3.86" rpy="0 0 0" />
      <geometry>
        <box size="0.12 0.1 7.4" />
        </geometry>
      <material name="machined_rail">
        <color rgba="0.42 0.44 0.45 1" />
        </material>
      </visual>
    <visual name="machine_beam">
      <origin xyz="0.28 1.45 7.58" rpy="0 0 0" />
      <geometry>
        <box size="3 0.26 0.22" />
        </geometry>
      <material name="galvanized_steel">
        <color rgba="0.58 0.62 0.64 1" />
        </material>
      </visual>
    <visual name="traction_sheave">
      <origin xyz="-0.38 1.3 7.58" rpy="1.5708 0 0" />
      <geometry>
        <cylinder radius="0.32" length="0.1" />
        </geometry>
      <material name="machined_rail">
        <color rgba="0.42 0.44 0.45 1" />
        </material>
      </visual>
    <visual name="sheave_axle">
      <origin xyz="-0.38 1.38 7.58" rpy="1.5708 0 0" />
      <geometry>
        <cylinder radius="0.055" length="0.62" />
        </geometry>
      <material name="galvanized_steel">
        <color rgba="0.58 0.62 0.64 1" />
        </material>
      </visual>
    <visual name="deflector_sheave">
      <origin xyz="1.34 1.39 7.58" rpy="1.5708 0 0" />
      <geometry>
        <cylinder radius="0.22" length="0.08" />
        </geometry>
      <material name="machined_rail">
        <color rgba="0.42 0.44 0.45 1" />
        </material>
      </visual>
    <visual name="car_rope_0">
      <origin xyz="-0.64 1.3 4.9" rpy="0 0 0" />
      <geometry>
        <cylinder radius="0.014" length="5.35" />
        </geometry>
      <material name="black_hoist_cable">
        <color rgba="0.01 0.01 0.012 1" />
        </material>
      </visual>
    <visual name="car_rope_1">
      <origin xyz="-0.5 1.3 4.9" rpy="0 0 0" />
      <geometry>
        <cylinder radius="0.014" length="5.35" />
        </geometry>
      <material name="black_hoist_cable">
        <color rgba="0.01 0.01 0.012 1" />
        </material>
      </visual>
    <visual name="counter_rope_0">
      <origin xyz="1.29 1.44 5.1" rpy="0 0 0" />
      <geometry>
        <cylinder radius="0.014" length="4.85" />
        </geometry>
      <material name="black_hoist_cable">
        <color rgba="0.01 0.01 0.012 1" />
        </material>
      </visual>
    <visual name="counter_rope_1">
      <origin xyz="1.39 1.44 5.1" rpy="0 0 0" />
      <geometry>
        <cylinder radius="0.014" length="4.85" />
        </geometry>
      <material name="black_hoist_cable">
        <color rgba="0.01 0.01 0.012 1" />
        </material>
      </visual>
    <collision name="pit_floor">
      <origin xyz="0 0 0.08" rpy="0 0 0" />
      <geometry>
        <box size="3.35 3.15 0.16" />
        </geometry>
      </collision>
    <collision name="rear_wall">
      <origin xyz="0 1.52 4" rpy="0 0 0" />
      <geometry>
        <box size="3.35 0.12 8" />
        </geometry>
      </collision>
    <collision name="side_wall_0">
      <origin xyz="-1.675 0 4" rpy="0 0 0" />
      <geometry>
        <box size="0.12 3.15 8" />
        </geometry>
      </collision>
    <collision name="side_wall_1">
      <origin xyz="1.675 0 4" rpy="0 0 0" />
      <geometry>
        <box size="0.12 3.15 8" />
        </geometry>
      </collision>
    <collision name="overhead_slab">
      <origin xyz="0 0 8.09" rpy="0 0 0" />
      <geometry>
        <box size="3.35 3.15 0.18" />
        </geometry>
      </collision>
    <collision name="landing_jamb_0">
      <origin xyz="-1.12 -1.52 1.25" rpy="0 0 0" />
      <geometry>
        <box size="0.14 0.14 2.35" />
        </geometry>
      </collision>
    <collision name="landing_jamb_1">
      <origin xyz="1.12 -1.52 1.25" rpy="0 0 0" />
      <geometry>
        <box size="0.14 0.14 2.35" />
        </geometry>
      </collision>
    <collision name="landing_header">
      <origin xyz="0 -1.52 2.38" rpy="0 0 0" />
      <geometry>
        <box size="2.38 0.14 0.18" />
        </geometry>
      </collision>
    <collision name="landing_sill">
      <origin xyz="0 -1.5 0.2" rpy="0 0 0" />
      <geometry>
        <box size="2.38 0.18 0.08" />
        </geometry>
      </collision>
    <collision name="guide_rail_0">
      <origin xyz="-1.22 0.35 3.93" rpy="0 0 0" />
      <geometry>
        <box size="0.07 0.09 7.7" />
        </geometry>
      </collision>
    <collision name="guide_rail_1">
      <origin xyz="1.22 0.35 3.93" rpy="0 0 0" />
      <geometry>
        <box size="0.07 0.09 7.7" />
        </geometry>
      </collision>
    <collision name="counter_rail_0">
      <origin xyz="1.48 0.45 3.86" rpy="0 0 0" />
      <geometry>
        <box size="0.12 0.1 7.4" />
        </geometry>
      </collision>
    <collision name="counter_rail_1">
      <origin xyz="1.48 1.45 3.86" rpy="0 0 0" />
      <geometry>
        <box size="0.12 0.1 7.4" />
        </geometry>
      </collision>
    <collision name="machine_beam">
      <origin xyz="0.28 1.45 7.58" rpy="0 0 0" />
      <geometry>
        <box size="3 0.26 0.22" />
        </geometry>
      </collision>
    <collision name="traction_sheave">
      <origin xyz="-0.38 1.3 7.58" rpy="1.5708 0 0" />
      <geometry>
        <cylinder radius="0.32" length="0.1" />
        </geometry>
      </collision>
    <collision name="sheave_axle">
      <origin xyz="-0.38 1.38 7.58" rpy="1.5708 0 0" />
      <geometry>
        <cylinder radius="0.055" length="0.62" />
        </geometry>
      </collision>
    <collision name="deflector_sheave">
      <origin xyz="1.34 1.39 7.58" rpy="1.5708 0 0" />
      <geometry>
        <cylinder radius="0.22" length="0.08" />
        </geometry>
      </collision>
    <collision name="car_rope_0">
      <origin xyz="-0.64 1.3 4.9" rpy="0 0 0" />
      <geometry>
        <cylinder radius="0.014" length="5.35" />
        </geometry>
      </collision>
    <collision name="car_rope_1">
      <origin xyz="-0.5 1.3 4.9" rpy="0 0 0" />
      <geometry>
        <cylinder radius="0.014" length="5.35" />
        </geometry>
      </collision>
    <collision name="counter_rope_0">
      <origin xyz="1.29 1.44 5.1" rpy="0 0 0" />
      <geometry>
        <cylinder radius="0.014" length="4.85" />
        </geometry>
      </collision>
    <collision name="counter_rope_1">
      <origin xyz="1.39 1.44 5.1" rpy="0 0 0" />
      <geometry>
        <cylinder radius="0.014" length="4.85" />
        </geometry>
      </collision>
    </link>
  <link name="car">
    <visual name="car_floor">
      <origin xyz="0 0 0.06" rpy="0 0 0" />
      <geometry>
        <box size="2.1 1.65 0.12" />
        </geometry>
      <material name="dark_rubber">
        <color rgba="0.04 0.045 0.05 1" />
        </material>
      </visual>
    <visual name="car_roof">
      <origin xyz="0 0 2.42" rpy="0 0 0" />
      <geometry>
        <box size="2.1 1.65 0.12" />
        </geometry>
      <material name="galvanized_steel">
        <color rgba="0.58 0.62 0.64 1" />
        </material>
      </visual>
    <visual name="rear_panel">
      <origin xyz="0 0.825 1.24" rpy="0 0 0" />
      <geometry>
        <box size="2.1 0.08 2.36" />
        </geometry>
      <material name="brushed_stainless">
        <color rgba="0.78 0.8 0.8 1" />
        </material>
      </visual>
    <visual name="side_panel_0">
      <origin xyz="-1.05 0 1.24" rpy="0 0 0" />
      <geometry>
        <box size="0.08 1.65 2.36" />
        </geometry>
      <material name="brushed_stainless">
        <color rgba="0.78 0.8 0.8 1" />
        </material>
      </visual>
    <visual name="side_panel_1">
      <origin xyz="1.05 0 1.24" rpy="0 0 0" />
      <geometry>
        <box size="0.08 1.65 2.36" />
        </geometry>
      <material name="brushed_stainless">
        <color rgba="0.78 0.8 0.8 1" />
        </material>
      </visual>
    <visual name="front_jamb_0">
      <origin xyz="-0.88 -0.825 1.17" rpy="0 0 0" />
      <geometry>
        <box size="0.34 0.08 2.22" />
        </geometry>
      <material name="brushed_stainless">
        <color rgba="0.78 0.8 0.8 1" />
        </material>
      </visual>
    <visual name="front_jamb_1">
      <origin xyz="0.88 -0.825 1.17" rpy="0 0 0" />
      <geometry>
        <box size="0.34 0.08 2.22" />
        </geometry>
      <material name="brushed_stainless">
        <color rgba="0.78 0.8 0.8 1" />
        </material>
      </visual>
    <visual name="front_header">
      <origin xyz="0 -0.825 2.22" rpy="0 0 0" />
      <geometry>
        <box size="1.42 0.08 0.24" />
        </geometry>
      <material name="brushed_stainless">
        <color rgba="0.78 0.8 0.8 1" />
        </material>
      </visual>
    <visual name="door_sill">
      <origin xyz="0 -0.825 0.14" rpy="0 0 0" />
      <geometry>
        <box size="1.42 0.08 0.08" />
        </geometry>
      <material name="machined_rail">
        <color rgba="0.42 0.44 0.45 1" />
        </material>
      </visual>
    <visual name="door_track">
      <origin xyz="0 -0.8625 2.09" rpy="0 0 0" />
      <geometry>
        <box size="1.44 0.06 0.08" />
        </geometry>
      <material name="machined_rail">
        <color rgba="0.42 0.44 0.45 1" />
        </material>
      </visual>
    <visual name="rope_hitch">
      <origin xyz="0 0.8 2.52" rpy="0 0 0" />
      <geometry>
        <box size="1.45 0.05 0.08" />
        </geometry>
      <material name="galvanized_steel">
        <color rgba="0.58 0.62 0.64 1" />
        </material>
      </visual>
    <visual name="handrail">
      <origin xyz="0 0.775 1.05" rpy="0 1.5708 0" />
      <geometry>
        <cylinder radius="0.035" length="1.25" />
        </geometry>
      <material name="machined_rail">
        <color rgba="0.42 0.44 0.45 1" />
        </material>
      </visual>
    <visual name="guide_shoe_0">
      <origin xyz="-1.1375 0.35 1.35" rpy="0 0 0" />
      <geometry>
        <box size="0.095 0.2 0.3" />
        </geometry>
      <material name="safety_yellow">
        <color rgba="0.95 0.72 0.08 1" />
        </material>
      </visual>
    <visual name="guide_shoe_1">
      <origin xyz="1.1375 0.35 1.35" rpy="0 0 0" />
      <geometry>
        <box size="0.095 0.2 0.3" />
        </geometry>
      <material name="safety_yellow">
        <color rgba="0.95 0.72 0.08 1" />
        </material>
      </visual>
    <collision name="car_floor">
      <origin xyz="0 0 0.06" rpy="0 0 0" />
      <geometry>
        <box size="2.1 1.65 0.12" />
        </geometry>
      </collision>
    <collision name="car_roof">
      <origin xyz="0 0 2.42" rpy="0 0 0" />
      <geometry>
        <box size="2.1 1.65 0.12" />
        </geometry>
      </collision>
    <collision name="rear_panel">
      <origin xyz="0 0.825 1.24" rpy="0 0 0" />
      <geometry>
        <box size="2.1 0.08 2.36" />
        </geometry>
      </collision>
    <collision name="side_panel_0">
      <origin xyz="-1.05 0 1.24" rpy="0 0 0" />
      <geometry>
        <box size="0.08 1.65 2.36" />
        </geometry>
      </collision>
    <collision name="side_panel_1">
      <origin xyz="1.05 0 1.24" rpy="0 0 0" />
      <geometry>
        <box size="0.08 1.65 2.36" />
        </geometry>
      </collision>
    <collision name="front_jamb_0">
      <origin xyz="-0.88 -0.825 1.17" rpy="0 0 0" />
      <geometry>
        <box size="0.34 0.08 2.22" />
        </geometry>
      </collision>
    <collision name="front_jamb_1">
      <origin xyz="0.88 -0.825 1.17" rpy="0 0 0" />
      <geometry>
        <box size="0.34 0.08 2.22" />
        </geometry>
      </collision>
    <collision name="front_header">
      <origin xyz="0 -0.825 2.22" rpy="0 0 0" />
      <geometry>
        <box size="1.42 0.08 0.24" />
        </geometry>
      </collision>
    <collision name="door_sill">
      <origin xyz="0 -0.825 0.14" rpy="0 0 0" />
      <geometry>
        <box size="1.42 0.08 0.08" />
        </geometry>
      </collision>
    <collision name="door_track">
      <origin xyz="0 -0.8625 2.09" rpy="0 0 0" />
      <geometry>
        <box size="1.44 0.06 0.08" />
        </geometry>
      </collision>
    <collision name="rope_hitch">
      <origin xyz="0 0.8 2.52" rpy="0 0 0" />
      <geometry>
        <box size="1.45 0.05 0.08" />
        </geometry>
      </collision>
    <collision name="handrail">
      <origin xyz="0 0.775 1.05" rpy="0 1.5708 0" />
      <geometry>
        <cylinder radius="0.035" length="1.25" />
        </geometry>
      </collision>
    <collision name="guide_shoe_0">
      <origin xyz="-1.1375 0.35 1.35" rpy="0 0 0" />
      <geometry>
        <box size="0.095 0.2 0.3" />
        </geometry>
      </collision>
    <collision name="guide_shoe_1">
      <origin xyz="1.1375 0.35 1.35" rpy="0 0 0" />
      <geometry>
        <box size="0.095 0.2 0.3" />
        </geometry>
      </collision>
    </link>
  <link name="counterweight">
    <visual name="weight_stack">
      <origin xyz="0 0 0.79" rpy="0 0 0" />
      <geometry>
        <box size="0.34 0.82 1.58" />
        </geometry>
      <material name="dark_rubber">
        <color rgba="0.04 0.045 0.05 1" />
        </material>
      </visual>
    <visual name="top_frame">
      <origin xyz="0 0 1.62" rpy="0 0 0" />
      <geometry>
        <box size="0.42 0.9 0.08" />
        </geometry>
      <material name="galvanized_steel">
        <color rgba="0.58 0.62 0.64 1" />
        </material>
      </visual>
    <visual name="bottom_frame">
      <origin xyz="0 0 -0.04" rpy="0 0 0" />
      <geometry>
        <box size="0.42 0.9 0.08" />
        </geometry>
      <material name="galvanized_steel">
        <color rgba="0.58 0.62 0.64 1" />
        </material>
      </visual>
    <visual name="side_frame_0">
      <origin xyz="-0.23 0 0.8" rpy="0 0 0" />
      <geometry>
        <box size="0.06 0.96 1.7" />
        </geometry>
      <material name="galvanized_steel">
        <color rgba="0.58 0.62 0.64 1" />
        </material>
      </visual>
    <visual name="side_frame_1">
      <origin xyz="0.23 0 0.8" rpy="0 0 0" />
      <geometry>
        <box size="0.06 0.96 1.7" />
        </geometry>
      <material name="galvanized_steel">
        <color rgba="0.58 0.62 0.64 1" />
        </material>
      </visual>
    <visual name="rope_socket">
      <origin xyz="0 0 1.7" rpy="0 0 0" />
      <geometry>
        <box size="0.18 0.18 0.1" />
        </geometry>
      <material name="safety_yellow">
        <color rgba="0.95 0.72 0.08 1" />
        </material>
      </visual>
    <collision name="weight_stack">
      <origin xyz="0 0 0.79" rpy="0 0 0" />
      <geometry>
        <box size="0.34 0.82 1.58" />
        </geometry>
      </collision>
    <collision name="top_frame">
      <origin xyz="0 0 1.62" rpy="0 0 0" />
      <geometry>
        <box size="0.42 0.9 0.08" />
        </geometry>
      </collision>
    <collision name="bottom_frame">
      <origin xyz="0 0 -0.04" rpy="0 0 0" />
      <geometry>
        <box size="0.42 0.9 0.08" />
        </geometry>
      </collision>
    <collision name="side_frame_0">
      <origin xyz="-0.23 0 0.8" rpy="0 0 0" />
      <geometry>
        <box size="0.06 0.96 1.7" />
        </geometry>
      </collision>
    <collision name="side_frame_1">
      <origin xyz="0.23 0 0.8" rpy="0 0 0" />
      <geometry>
        <box size="0.06 0.96 1.7" />
        </geometry>
      </collision>
    <collision name="rope_socket">
      <origin xyz="0 0 1.7" rpy="0 0 0" />
      <geometry>
        <box size="0.18 0.18 0.1" />
        </geometry>
      </collision>
    </link>
  <link name="door_0">
    <visual name="door_leaf">
      <origin xyz="0 -0.005 1.1" rpy="0 0 0" />
      <geometry>
        <box size="0.55 0.045 1.92" />
        </geometry>
      <material name="brushed_stainless">
        <color rgba="0.78 0.8 0.8 1" />
        </material>
      </visual>
    <visual name="vision_panel">
      <origin xyz="-0.08 -0.025 1.53" rpy="0 0 0" />
      <geometry>
        <box size="0.18 0.008 0.34" />
        </geometry>
      <material name="smoked_glass">
        <color rgba="0.08 0.13 0.16 0.72" />
        </material>
      </visual>
    <visual name="hanger">
      <origin xyz="0 0.005 2.1" rpy="0 0 0" />
      <geometry>
        <box size="0.52 0.035 0.08" />
        </geometry>
      <material name="machined_rail">
        <color rgba="0.42 0.44 0.45 1" />
        </material>
      </visual>
    <collision name="door_leaf">
      <origin xyz="0 -0.005 1.1" rpy="0 0 0" />
      <geometry>
        <box size="0.55 0.045 1.92" />
        </geometry>
      </collision>
    <collision name="vision_panel">
      <origin xyz="-0.08 -0.025 1.53" rpy="0 0 0" />
      <geometry>
        <box size="0.18 0.008 0.34" />
        </geometry>
      </collision>
    <collision name="hanger">
      <origin xyz="0 0.005 2.1" rpy="0 0 0" />
      <geometry>
        <box size="0.52 0.035 0.08" />
        </geometry>
      </collision>
    </link>
  <link name="door_1">
    <visual name="door_leaf">
      <origin xyz="0 -0.005 1.1" rpy="0 0 0" />
      <geometry>
        <box size="0.55 0.045 1.92" />
        </geometry>
      <material name="brushed_stainless">
        <color rgba="0.78 0.8 0.8 1" />
        </material>
      </visual>
    <visual name="vision_panel">
      <origin xyz="0.08 -0.025 1.53" rpy="0 0 0" />
      <geometry>
        <box size="0.18 0.008 0.34" />
        </geometry>
      <material name="smoked_glass">
        <color rgba="0.08 0.13 0.16 0.72" />
        </material>
      </visual>
    <visual name="hanger">
      <origin xyz="0 0.005 2.1" rpy="0 0 0" />
      <geometry>
        <box size="0.52 0.035 0.08" />
        </geometry>
      <material name="machined_rail">
        <color rgba="0.42 0.44 0.45 1" />
        </material>
      </visual>
    <collision name="door_leaf">
      <origin xyz="0 -0.005 1.1" rpy="0 0 0" />
      <geometry>
        <box size="0.55 0.045 1.92" />
        </geometry>
      </collision>
    <collision name="vision_panel">
      <origin xyz="0.08 -0.025 1.53" rpy="0 0 0" />
      <geometry>
        <box size="0.18 0.008 0.34" />
        </geometry>
      </collision>
    <collision name="hanger">
      <origin xyz="0 0.005 2.1" rpy="0 0 0" />
      <geometry>
        <box size="0.52 0.035 0.08" />
        </geometry>
      </collision>
    </link>
  <joint name="car_lift" type="prismatic">
    <origin xyz="0 0 0.58" rpy="0 0 0" />
    <parent link="shaft" />
    <child link="car" />
    <axis xyz="0 0 1" />
    <limit effort="22000" velocity="1.6" lower="0" upper="4.5" />
    </joint>
  <joint name="counterweight_lift" type="prismatic">
    <origin xyz="1.34 0.95 0.66" rpy="0 0 0" />
    <parent link="shaft" />
    <child link="counterweight" />
    <axis xyz="0 0 1" />
    <limit effort="12000" velocity="1.6" lower="0" upper="4.5" />
    <mimic joint="car_lift" multiplier="-1" offset="4.5" />
    </joint>
  <joint name="door_0_slide" type="prismatic">
    <origin xyz="-0.276 -0.915 0" rpy="0 0 0" />
    <parent link="car" />
    <child link="door_0" />
    <axis xyz="-1 0 0" />
    <limit effort="550" velocity="0.65" lower="0" upper="0.45" />
    </joint>
  <joint name="door_1_slide" type="prismatic">
    <origin xyz="0.276 -0.915 0" rpy="0 0 0" />
    <parent link="car" />
    <child link="door_1" />
    <axis xyz="1 0 0" />
    <limit effort="550" velocity="0.65" lower="0" upper="0.45" />
    </joint>
  </robot>
