<robot name="folding_inspection_boom">
  <material name="powder_coat_yellow">
    <color rgba="0.95 0.72 0.12 1" />
    </material>
  <material name="dark_steel">
    <color rgba="0.06 0.07 0.075 1" />
    </material>
  <material name="rubber_black">
    <color rgba="0.015 0.015 0.014 1" />
    </material>
  <material name="brushed_steel">
    <color rgba="0.55 0.58 0.6 1" />
    </material>
  <material name="glass_blue">
    <color rgba="0.15 0.45 0.85 0.72" />
    </material>
  <link name="base">
    <visual name="floor_plate">
      <origin xyz="0.1 0 0.02" rpy="0 0 0" />
      <geometry>
        <box size="0.46 0.3 0.04" />
        </geometry>
      <material name="dark_steel" />
      </visual>
    <visual name="pedestal">
      <origin xyz="-0.055 0 0.255" rpy="0 0 0" />
      <geometry>
        <box size="0.13 0.16 0.47" />
        </geometry>
      <material name="powder_coat_yellow" />
      </visual>
    <visual name="root_yoke_cheek_0">
      <origin xyz="0 0.075 0.55" rpy="0 0 0" />
      <geometry>
        <box size="0.14 0.025 0.2" />
        </geometry>
      <material name="powder_coat_yellow" />
      </visual>
    <visual name="root_yoke_cheek_1">
      <origin xyz="0 -0.075 0.55" rpy="0 0 0" />
      <geometry>
        <box size="0.14 0.025 0.2" />
        </geometry>
      <material name="powder_coat_yellow" />
      </visual>
    <visual name="root_boss_0">
      <origin xyz="0 0.091 0.55" rpy="1.5708 0 0" />
      <geometry>
        <cylinder radius="0.02" length="0.028" />
        </geometry>
      <material name="brushed_steel" />
      </visual>
    <visual name="root_boss_1">
      <origin xyz="0 -0.091 0.55" rpy="1.5708 0 0" />
      <geometry>
        <cylinder radius="0.02" length="0.028" />
        </geometry>
      <material name="brushed_steel" />
      </visual>
    <visual name="lower_stop_post">
      <origin xyz="0.22 0 0.25" rpy="0 0 0" />
      <geometry>
        <box size="0.055 0.07 0.46" />
        </geometry>
      <material name="dark_steel" />
      </visual>
    <visual name="lower_stop_pad">
      <origin xyz="0.22 0 0.49" rpy="0 0 0" />
      <geometry>
        <box size="0.08 0.085 0.02" />
        </geometry>
      <material name="rubber_black" />
      </visual>
    <visual name="upper_stop_pad">
      <origin xyz="-0.018 0 0.66" rpy="0 0 0" />
      <geometry>
        <box size="0.055 0.15 0.035" />
        </geometry>
      <material name="rubber_black" />
      </visual>
    <collision name="floor_plate">
      <origin xyz="0.1 0 0.02" rpy="0 0 0" />
      <geometry>
        <box size="0.46 0.3 0.04" />
        </geometry>
      </collision>
    <collision name="pedestal">
      <origin xyz="-0.055 0 0.255" rpy="0 0 0" />
      <geometry>
        <box size="0.13 0.16 0.47" />
        </geometry>
      </collision>
    <collision name="root_yoke_cheek_0">
      <origin xyz="0 0.075 0.55" rpy="0 0 0" />
      <geometry>
        <box size="0.14 0.025 0.2" />
        </geometry>
      </collision>
    <collision name="root_yoke_cheek_1">
      <origin xyz="0 -0.075 0.55" rpy="0 0 0" />
      <geometry>
        <box size="0.14 0.025 0.2" />
        </geometry>
      </collision>
    <collision name="root_boss_0">
      <origin xyz="0 0.091 0.55" rpy="1.5708 0 0" />
      <geometry>
        <cylinder radius="0.02" length="0.028" />
        </geometry>
      </collision>
    <collision name="root_boss_1">
      <origin xyz="0 -0.091 0.55" rpy="1.5708 0 0" />
      <geometry>
        <cylinder radius="0.02" length="0.028" />
        </geometry>
      </collision>
    <collision name="lower_stop_post">
      <origin xyz="0.22 0 0.25" rpy="0 0 0" />
      <geometry>
        <box size="0.055 0.07 0.46" />
        </geometry>
      </collision>
    <collision name="lower_stop_pad">
      <origin xyz="0.22 0 0.49" rpy="0 0 0" />
      <geometry>
        <box size="0.08 0.085 0.02" />
        </geometry>
      </collision>
    <collision name="upper_stop_pad">
      <origin xyz="-0.018 0 0.66" rpy="0 0 0" />
      <geometry>
        <box size="0.055 0.15 0.035" />
        </geometry>
      </collision>
    </link>
  <link name="outer_boom">
    <visual name="root_knuckle">
      <origin xyz="0 0 0" rpy="1.5708 0 0" />
      <geometry>
        <cylinder radius="0.044" length="0.112" />
        </geometry>
      <material name="dark_steel" />
      </visual>
    <visual name="top_wall">
      <origin xyz="0.45 0 0.044" rpy="0 0 0" />
      <geometry>
        <box size="0.82 0.1 0.012" />
        </geometry>
      <material name="powder_coat_yellow" />
      </visual>
    <visual name="bottom_wall">
      <origin xyz="0.45 0 -0.044" rpy="0 0 0" />
      <geometry>
        <box size="0.82 0.1 0.012" />
        </geometry>
      <material name="powder_coat_yellow" />
      </visual>
    <visual name="side_wall_0">
      <origin xyz="0.45 0.044 0" rpy="0 0 0" />
      <geometry>
        <box size="0.82 0.012 0.1" />
        </geometry>
      <material name="powder_coat_yellow" />
      </visual>
    <visual name="side_wall_1">
      <origin xyz="0.45 -0.044 0" rpy="0 0 0" />
      <geometry>
        <box size="0.82 0.012 0.1" />
        </geometry>
      <material name="powder_coat_yellow" />
      </visual>
    <visual name="root_collar">
      <origin xyz="0.085 0 0" rpy="0 0 0" />
      <geometry>
        <box size="0.06 0.116 0.116" />
        </geometry>
      <material name="dark_steel" />
      </visual>
    <visual name="mouth_stop_top">
      <origin xyz="0.86 0 0.052" rpy="0 0 0" />
      <geometry>
        <box size="0.035 0.116 0.012" />
        </geometry>
      <material name="dark_steel" />
      </visual>
    <visual name="mouth_stop_bottom">
      <origin xyz="0.86 0 -0.052" rpy="0 0 0" />
      <geometry>
        <box size="0.035 0.116 0.012" />
        </geometry>
      <material name="dark_steel" />
      </visual>
    <visual name="mouth_stop_side_0">
      <origin xyz="0.86 0.052 0" rpy="0 0 0" />
      <geometry>
        <box size="0.035 0.012 0.116" />
        </geometry>
      <material name="dark_steel" />
      </visual>
    <visual name="mouth_stop_side_1">
      <origin xyz="0.86 -0.052 0" rpy="0 0 0" />
      <geometry>
        <box size="0.035 0.012 0.116" />
        </geometry>
      <material name="dark_steel" />
      </visual>
    <visual name="slide_stop_screw">
      <origin xyz="0.72 0 0.06" rpy="0 0 0" />
      <geometry>
        <cylinder radius="0.008" length="0.02" />
        </geometry>
      <material name="brushed_steel" />
      </visual>
    <collision name="root_knuckle">
      <origin xyz="0 0 0" rpy="1.5708 0 0" />
      <geometry>
        <cylinder radius="0.044" length="0.112" />
        </geometry>
      </collision>
    <collision name="top_wall">
      <origin xyz="0.45 0 0.044" rpy="0 0 0" />
      <geometry>
        <box size="0.82 0.1 0.012" />
        </geometry>
      </collision>
    <collision name="bottom_wall">
      <origin xyz="0.45 0 -0.044" rpy="0 0 0" />
      <geometry>
        <box size="0.82 0.1 0.012" />
        </geometry>
      </collision>
    <collision name="side_wall_0">
      <origin xyz="0.45 0.044 0" rpy="0 0 0" />
      <geometry>
        <box size="0.82 0.012 0.1" />
        </geometry>
      </collision>
    <collision name="side_wall_1">
      <origin xyz="0.45 -0.044 0" rpy="0 0 0" />
      <geometry>
        <box size="0.82 0.012 0.1" />
        </geometry>
      </collision>
    <collision name="root_collar">
      <origin xyz="0.085 0 0" rpy="0 0 0" />
      <geometry>
        <box size="0.06 0.116 0.116" />
        </geometry>
      </collision>
    <collision name="mouth_stop_top">
      <origin xyz="0.86 0 0.052" rpy="0 0 0" />
      <geometry>
        <box size="0.035 0.116 0.012" />
        </geometry>
      </collision>
    <collision name="mouth_stop_bottom">
      <origin xyz="0.86 0 -0.052" rpy="0 0 0" />
      <geometry>
        <box size="0.035 0.116 0.012" />
        </geometry>
      </collision>
    <collision name="mouth_stop_side_0">
      <origin xyz="0.86 0.052 0" rpy="0 0 0" />
      <geometry>
        <box size="0.035 0.012 0.116" />
        </geometry>
      </collision>
    <collision name="mouth_stop_side_1">
      <origin xyz="0.86 -0.052 0" rpy="0 0 0" />
      <geometry>
        <box size="0.035 0.012 0.116" />
        </geometry>
      </collision>
    <collision name="slide_stop_screw">
      <origin xyz="0.72 0 0.06" rpy="0 0 0" />
      <geometry>
        <cylinder radius="0.008" length="0.02" />
        </geometry>
      </collision>
    </link>
  <link name="extension">
    <visual name="inner_beam">
      <origin xyz="-0.24 0 0" rpy="0 0 0" />
      <geometry>
        <box size="0.62 0.052 0.052" />
        </geometry>
      <material name="brushed_steel" />
      </visual>
    <visual name="hidden_stop_collar">
      <origin xyz="-0.535 0 0" rpy="0 0 0" />
      <geometry>
        <box size="0.032 0.076 0.076" />
        </geometry>
      <material name="dark_steel" />
      </visual>
    <visual name="slide_wear_pad_0">
      <origin xyz="-0.25 0.032 0" rpy="0 0 0" />
      <geometry>
        <box size="0.16 0.012 0.03" />
        </geometry>
      <material name="rubber_black" />
      </visual>
    <visual name="slide_wear_pad_1">
      <origin xyz="-0.25 -0.032 0" rpy="0 0 0" />
      <geometry>
        <box size="0.16 0.012 0.03" />
        </geometry>
      <material name="rubber_black" />
      </visual>
    <visual name="slide_wear_pad_2">
      <origin xyz="-0.25 0 0.032" rpy="0 0 0" />
      <geometry>
        <box size="0.16 0.03 0.012" />
        </geometry>
      <material name="rubber_black" />
      </visual>
    <visual name="slide_wear_pad_3">
      <origin xyz="-0.25 0 -0.032" rpy="0 0 0" />
      <geometry>
        <box size="0.16 0.03 0.012" />
        </geometry>
      <material name="rubber_black" />
      </visual>
    <visual name="outer_stop_bumper">
      <origin xyz="0.055 0 0" rpy="0 0 0" />
      <geometry>
        <box size="0.03 0.086 0.086" />
        </geometry>
      <material name="rubber_black" />
      </visual>
    <visual name="end_fork_bridge">
      <origin xyz="0.0875 0 0" rpy="0 0 0" />
      <geometry>
        <box size="0.035 0.082 0.06" />
        </geometry>
      <material name="dark_steel" />
      </visual>
    <visual name="end_fork_cheek_0">
      <origin xyz="0.14 0.047 0" rpy="0 0 0" />
      <geometry>
        <box size="0.08 0.014 0.076" />
        </geometry>
      <material name="dark_steel" />
      </visual>
    <visual name="end_fork_cheek_1">
      <origin xyz="0.14 -0.047 0" rpy="0 0 0" />
      <geometry>
        <box size="0.08 0.014 0.076" />
        </geometry>
      <material name="dark_steel" />
      </visual>
    <visual name="rotary_stop_0">
      <origin xyz="0.14 0.047 0.045" rpy="0 0 0" />
      <geometry>
        <box size="0.03 0.03 0.018" />
        </geometry>
      <material name="rubber_black" />
      </visual>
    <visual name="rotary_stop_1">
      <origin xyz="0.14 -0.047 0.045" rpy="0 0 0" />
      <geometry>
        <box size="0.03 0.03 0.018" />
        </geometry>
      <material name="rubber_black" />
      </visual>
    <collision name="inner_beam">
      <origin xyz="-0.24 0 0" rpy="0 0 0" />
      <geometry>
        <box size="0.62 0.052 0.052" />
        </geometry>
      </collision>
    <collision name="hidden_stop_collar">
      <origin xyz="-0.535 0 0" rpy="0 0 0" />
      <geometry>
        <box size="0.032 0.076 0.076" />
        </geometry>
      </collision>
    <collision name="slide_wear_pad_0">
      <origin xyz="-0.25 0.032 0" rpy="0 0 0" />
      <geometry>
        <box size="0.16 0.012 0.03" />
        </geometry>
      </collision>
    <collision name="slide_wear_pad_1">
      <origin xyz="-0.25 -0.032 0" rpy="0 0 0" />
      <geometry>
        <box size="0.16 0.012 0.03" />
        </geometry>
      </collision>
    <collision name="slide_wear_pad_2">
      <origin xyz="-0.25 0 0.032" rpy="0 0 0" />
      <geometry>
        <box size="0.16 0.03 0.012" />
        </geometry>
      </collision>
    <collision name="slide_wear_pad_3">
      <origin xyz="-0.25 0 -0.032" rpy="0 0 0" />
      <geometry>
        <box size="0.16 0.03 0.012" />
        </geometry>
      </collision>
    <collision name="outer_stop_bumper">
      <origin xyz="0.055 0 0" rpy="0 0 0" />
      <geometry>
        <box size="0.03 0.086 0.086" />
        </geometry>
      </collision>
    <collision name="end_fork_bridge">
      <origin xyz="0.0875 0 0" rpy="0 0 0" />
      <geometry>
        <box size="0.035 0.082 0.06" />
        </geometry>
      </collision>
    <collision name="end_fork_cheek_0">
      <origin xyz="0.14 0.047 0" rpy="0 0 0" />
      <geometry>
        <box size="0.08 0.014 0.076" />
        </geometry>
      </collision>
    <collision name="end_fork_cheek_1">
      <origin xyz="0.14 -0.047 0" rpy="0 0 0" />
      <geometry>
        <box size="0.08 0.014 0.076" />
        </geometry>
      </collision>
    <collision name="rotary_stop_0">
      <origin xyz="0.14 0.047 0.045" rpy="0 0 0" />
      <geometry>
        <box size="0.03 0.03 0.018" />
        </geometry>
      </collision>
    <collision name="rotary_stop_1">
      <origin xyz="0.14 -0.047 0.045" rpy="0 0 0" />
      <geometry>
        <box size="0.03 0.03 0.018" />
        </geometry>
      </collision>
    </link>
  <link name="end_head">
    <visual name="rotary_collar">
      <origin xyz="0 0 0" rpy="0 1.5708 0" />
      <geometry>
        <cylinder radius="0.03" length="0.07" />
        </geometry>
      <material name="dark_steel" />
      </visual>
    <visual name="rotary_stop_tab">
      <origin xyz="-0.006 0 0.039" rpy="0 0 0" />
      <geometry>
        <box size="0.025 0.018 0.022" />
        </geometry>
      <material name="dark_steel" />
      </visual>
    <visual name="inspection_head_body">
      <origin xyz="0.07 0 0" rpy="0 0 0" />
      <geometry>
        <box size="0.09 0.09 0.06" />
        </geometry>
      <material name="dark_steel" />
      </visual>
    <visual name="lens_window">
      <origin xyz="0.122 0 0" rpy="0 1.5708 0" />
      <geometry>
        <cylinder radius="0.026" length="0.014" />
        </geometry>
      <material name="glass_blue" />
      </visual>
    <visual name="protective_skid">
      <origin xyz="0.074 0 -0.035" rpy="0 0 0" />
      <geometry>
        <box size="0.038 0.11 0.012" />
        </geometry>
      <material name="rubber_black" />
      </visual>
    <collision name="rotary_collar">
      <origin xyz="0 0 0" rpy="0 1.5708 0" />
      <geometry>
        <cylinder radius="0.03" length="0.07" />
        </geometry>
      </collision>
    <collision name="rotary_stop_tab">
      <origin xyz="-0.006 0 0.039" rpy="0 0 0" />
      <geometry>
        <box size="0.025 0.018 0.022" />
        </geometry>
      </collision>
    <collision name="inspection_head_body">
      <origin xyz="0.07 0 0" rpy="0 0 0" />
      <geometry>
        <box size="0.09 0.09 0.06" />
        </geometry>
      </collision>
    <collision name="lens_window">
      <origin xyz="0.122 0 0" rpy="0 1.5708 0" />
      <geometry>
        <cylinder radius="0.026" length="0.014" />
        </geometry>
      </collision>
    <collision name="protective_skid">
      <origin xyz="0.074 0 -0.035" rpy="0 0 0" />
      <geometry>
        <box size="0.038 0.11 0.012" />
        </geometry>
      </collision>
    </link>
  <joint name="root_hinge" type="revolute">
    <origin xyz="0 0 0.55" rpy="0 0 0" />
    <parent link="base" />
    <child link="outer_boom" />
    <axis xyz="0 -1 0" />
    <limit effort="120" velocity="0.9" lower="0" upper="1.75" />
    </joint>
  <joint name="boom_slide" type="prismatic">
    <origin xyz="0.86 0 0" rpy="0 0 0" />
    <parent link="outer_boom" />
    <child link="extension" />
    <axis xyz="1 0 0" />
    <limit effort="80" velocity="0.25" lower="0" upper="0.45" />
    </joint>
  <joint name="end_rotary" type="revolute">
    <origin xyz="0.14 0 0" rpy="0 0 0" />
    <parent link="extension" />
    <child link="end_head" />
    <axis xyz="1 0 0" />
    <limit effort="12" velocity="2" lower="-2.6" upper="2.6" />
    </joint>
  </robot>
