<robot name="service_bay_tv_wall_bracket">
  <material name="powder_coated_black_steel">
    <color rgba="0.015 0.016 0.017 1" />
    </material>
  <material name="worn_pin_steel">
    <color rgba="0.42 0.43 0.42 1" />
    </material>
  <material name="service_bay_wall">
    <color rgba="0.48 0.49 0.47 1" />
    </material>
  <material name="blackened_bolt_heads">
    <color rgba="0.03 0.03 0.028 1" />
    </material>
  <link name="wall_mount">
    <visual name="wall_backer">
      <origin xyz="-0.09 0 0" rpy="0 0 0" />
      <geometry>
        <box size="0.04 0.42 0.75" />
        </geometry>
      <material name="service_bay_wall">
        <color rgba="0.48 0.49 0.47 1" />
        </material>
      </visual>
    <visual name="upper_wall_standoff">
      <origin xyz="-0.038 0 0.17" rpy="0 0 0" />
      <geometry>
        <box size="0.12 0.145 0.075" />
        </geometry>
      <material name="powder_coated_black_steel">
        <color rgba="0.015 0.016 0.017 1" />
        </material>
      </visual>
    <visual name="lower_wall_standoff">
      <origin xyz="-0.038 0 -0.17" rpy="0 0 0" />
      <geometry>
        <box size="0.12 0.145 0.075" />
        </geometry>
      <material name="powder_coated_black_steel">
        <color rgba="0.015 0.016 0.017 1" />
        </material>
      </visual>
    <visual name="upper_wall_hinge_lug">
      <origin xyz="0 0 0.17" rpy="0 0 0" />
      <geometry>
        <cylinder radius="0.06" length="0.1" />
        </geometry>
      <material name="powder_coated_black_steel">
        <color rgba="0.015 0.016 0.017 1" />
        </material>
      </visual>
    <visual name="lower_wall_hinge_lug">
      <origin xyz="0 0 -0.17" rpy="0 0 0" />
      <geometry>
        <cylinder radius="0.06" length="0.1" />
        </geometry>
      <material name="powder_coated_black_steel">
        <color rgba="0.015 0.016 0.017 1" />
        </material>
      </visual>
    <visual name="wall_hinge_pin">
      <geometry>
        <cylinder radius="0.02" length="0.44" />
        </geometry>
      <material name="worn_pin_steel">
        <color rgba="0.42 0.43 0.42 1" />
        </material>
      </visual>
    <visual name="wall_bolt_0">
      <origin xyz="-0.064 -0.145 0.285" rpy="0 1.5708 0" />
      <geometry>
        <cylinder radius="0.02" length="0.014" />
        </geometry>
      <material name="blackened_bolt_heads">
        <color rgba="0.03 0.03 0.028 1" />
        </material>
      </visual>
    <visual name="wall_bolt_1">
      <origin xyz="-0.064 0.145 0.285" rpy="0 1.5708 0" />
      <geometry>
        <cylinder radius="0.02" length="0.014" />
        </geometry>
      <material name="blackened_bolt_heads">
        <color rgba="0.03 0.03 0.028 1" />
        </material>
      </visual>
    <visual name="wall_bolt_2">
      <origin xyz="-0.064 -0.145 -0.285" rpy="0 1.5708 0" />
      <geometry>
        <cylinder radius="0.02" length="0.014" />
        </geometry>
      <material name="blackened_bolt_heads">
        <color rgba="0.03 0.03 0.028 1" />
        </material>
      </visual>
    <visual name="wall_bolt_3">
      <origin xyz="-0.064 0.145 -0.285" rpy="0 1.5708 0" />
      <geometry>
        <cylinder radius="0.02" length="0.014" />
        </geometry>
      <material name="blackened_bolt_heads">
        <color rgba="0.03 0.03 0.028 1" />
        </material>
      </visual>
    <collision name="wall_backer">
      <origin xyz="-0.09 0 0" rpy="0 0 0" />
      <geometry>
        <box size="0.04 0.42 0.75" />
        </geometry>
      </collision>
    <collision name="upper_wall_standoff">
      <origin xyz="-0.038 0 0.17" rpy="0 0 0" />
      <geometry>
        <box size="0.12 0.145 0.075" />
        </geometry>
      </collision>
    <collision name="lower_wall_standoff">
      <origin xyz="-0.038 0 -0.17" rpy="0 0 0" />
      <geometry>
        <box size="0.12 0.145 0.075" />
        </geometry>
      </collision>
    <collision name="upper_wall_hinge_lug">
      <origin xyz="0 0 0.17" rpy="0 0 0" />
      <geometry>
        <cylinder radius="0.06" length="0.1" />
        </geometry>
      </collision>
    <collision name="lower_wall_hinge_lug">
      <origin xyz="0 0 -0.17" rpy="0 0 0" />
      <geometry>
        <cylinder radius="0.06" length="0.1" />
        </geometry>
      </collision>
    <collision name="wall_hinge_pin">
      <geometry>
        <cylinder radius="0.02" length="0.44" />
        </geometry>
      </collision>
    <collision name="wall_bolt_0">
      <origin xyz="-0.064 -0.145 0.285" rpy="0 1.5708 0" />
      <geometry>
        <cylinder radius="0.02" length="0.014" />
        </geometry>
      </collision>
    <collision name="wall_bolt_1">
      <origin xyz="-0.064 0.145 0.285" rpy="0 1.5708 0" />
      <geometry>
        <cylinder radius="0.02" length="0.014" />
        </geometry>
      </collision>
    <collision name="wall_bolt_2">
      <origin xyz="-0.064 -0.145 -0.285" rpy="0 1.5708 0" />
      <geometry>
        <cylinder radius="0.02" length="0.014" />
        </geometry>
      </collision>
    <collision name="wall_bolt_3">
      <origin xyz="-0.064 0.145 -0.285" rpy="0 1.5708 0" />
      <geometry>
        <cylinder radius="0.02" length="0.014" />
        </geometry>
      </collision>
    </link>
  <link name="primary_arm">
    <visual name="wall_pivot_barrel">
      <geometry>
        <cylinder radius="0.048" length="0.17" />
        </geometry>
      <material name="worn_pin_steel">
        <color rgba="0.42 0.43 0.42 1" />
        </material>
      </visual>
    <visual name="upper_primary_plate">
      <origin xyz="0.265 0 0.095" rpy="0 0 0" />
      <geometry>
        <box size="0.45 0.056 0.035" />
        </geometry>
      <material name="powder_coated_black_steel">
        <color rgba="0.015 0.016 0.017 1" />
        </material>
      </visual>
    <visual name="lower_primary_plate">
      <origin xyz="0.265 0 -0.095" rpy="0 0 0" />
      <geometry>
        <box size="0.45 0.056 0.035" />
        </geometry>
      <material name="powder_coated_black_steel">
        <color rgba="0.015 0.016 0.017 1" />
        </material>
      </visual>
    <visual name="upper_elbow_lug">
      <origin xyz="0.52 0 0.155" rpy="0 0 0" />
      <geometry>
        <cylinder radius="0.045" length="0.09" />
        </geometry>
      <material name="powder_coated_black_steel">
        <color rgba="0.015 0.016 0.017 1" />
        </material>
      </visual>
    <visual name="lower_elbow_lug">
      <origin xyz="0.52 0 -0.155" rpy="0 0 0" />
      <geometry>
        <cylinder radius="0.045" length="0.09" />
        </geometry>
      <material name="powder_coated_black_steel">
        <color rgba="0.015 0.016 0.017 1" />
        </material>
      </visual>
    <visual name="primary_side_web">
      <origin xyz="0.285 0.035 0" rpy="0 0 0" />
      <geometry>
        <box size="0.36 0.018 0.195" />
        </geometry>
      <material name="powder_coated_black_steel">
        <color rgba="0.015 0.016 0.017 1" />
        </material>
      </visual>
    <visual name="elbow_pin">
      <origin xyz="0.52 0 0" rpy="0 0 0" />
      <geometry>
        <cylinder radius="0.016" length="0.36" />
        </geometry>
      <material name="worn_pin_steel">
        <color rgba="0.42 0.43 0.42 1" />
        </material>
      </visual>
    <collision name="wall_pivot_barrel">
      <geometry>
        <cylinder radius="0.048" length="0.17" />
        </geometry>
      </collision>
    <collision name="upper_primary_plate">
      <origin xyz="0.265 0 0.095" rpy="0 0 0" />
      <geometry>
        <box size="0.45 0.056 0.035" />
        </geometry>
      </collision>
    <collision name="lower_primary_plate">
      <origin xyz="0.265 0 -0.095" rpy="0 0 0" />
      <geometry>
        <box size="0.45 0.056 0.035" />
        </geometry>
      </collision>
    <collision name="upper_elbow_lug">
      <origin xyz="0.52 0 0.155" rpy="0 0 0" />
      <geometry>
        <cylinder radius="0.045" length="0.09" />
        </geometry>
      </collision>
    <collision name="lower_elbow_lug">
      <origin xyz="0.52 0 -0.155" rpy="0 0 0" />
      <geometry>
        <cylinder radius="0.045" length="0.09" />
        </geometry>
      </collision>
    <collision name="primary_side_web">
      <origin xyz="0.285 0.035 0" rpy="0 0 0" />
      <geometry>
        <box size="0.36 0.018 0.195" />
        </geometry>
      </collision>
    <collision name="elbow_pin">
      <origin xyz="0.52 0 0" rpy="0 0 0" />
      <geometry>
        <cylinder radius="0.016" length="0.36" />
        </geometry>
      </collision>
    </link>
  <link name="secondary_arm">
    <visual name="elbow_pivot_barrel">
      <geometry>
        <cylinder radius="0.038" length="0.14" />
        </geometry>
      <material name="worn_pin_steel">
        <color rgba="0.42 0.43 0.42 1" />
        </material>
      </visual>
    <visual name="upper_secondary_plate">
      <origin xyz="0.19 0 0.08" rpy="0 0 0" />
      <geometry>
        <box size="0.32 0.044 0.03" />
        </geometry>
      <material name="powder_coated_black_steel">
        <color rgba="0.015 0.016 0.017 1" />
        </material>
      </visual>
    <visual name="lower_secondary_plate">
      <origin xyz="0.19 0 -0.08" rpy="0 0 0" />
      <geometry>
        <box size="0.32 0.044 0.03" />
        </geometry>
      <material name="powder_coated_black_steel">
        <color rgba="0.015 0.016 0.017 1" />
        </material>
      </visual>
    <visual name="upper_head_lug">
      <origin xyz="0.38 0 0.13" rpy="0 0 0" />
      <geometry>
        <cylinder radius="0.036" length="0.08" />
        </geometry>
      <material name="powder_coated_black_steel">
        <color rgba="0.015 0.016 0.017 1" />
        </material>
      </visual>
    <visual name="lower_head_lug">
      <origin xyz="0.38 0 -0.13" rpy="0 0 0" />
      <geometry>
        <cylinder radius="0.036" length="0.08" />
        </geometry>
      <material name="powder_coated_black_steel">
        <color rgba="0.015 0.016 0.017 1" />
        </material>
      </visual>
    <visual name="secondary_side_web">
      <origin xyz="0.2 -0.029 0" rpy="0 0 0" />
      <geometry>
        <box size="0.245 0.015 0.165" />
        </geometry>
      <material name="powder_coated_black_steel">
        <color rgba="0.015 0.016 0.017 1" />
        </material>
      </visual>
    <visual name="head_pin">
      <origin xyz="0.38 0 0" rpy="0 0 0" />
      <geometry>
        <cylinder radius="0.014" length="0.3" />
        </geometry>
      <material name="worn_pin_steel">
        <color rgba="0.42 0.43 0.42 1" />
        </material>
      </visual>
    <collision name="elbow_pivot_barrel">
      <geometry>
        <cylinder radius="0.038" length="0.14" />
        </geometry>
      </collision>
    <collision name="upper_secondary_plate">
      <origin xyz="0.19 0 0.08" rpy="0 0 0" />
      <geometry>
        <box size="0.32 0.044 0.03" />
        </geometry>
      </collision>
    <collision name="lower_secondary_plate">
      <origin xyz="0.19 0 -0.08" rpy="0 0 0" />
      <geometry>
        <box size="0.32 0.044 0.03" />
        </geometry>
      </collision>
    <collision name="upper_head_lug">
      <origin xyz="0.38 0 0.13" rpy="0 0 0" />
      <geometry>
        <cylinder radius="0.036" length="0.08" />
        </geometry>
      </collision>
    <collision name="lower_head_lug">
      <origin xyz="0.38 0 -0.13" rpy="0 0 0" />
      <geometry>
        <cylinder radius="0.036" length="0.08" />
        </geometry>
      </collision>
    <collision name="secondary_side_web">
      <origin xyz="0.2 -0.029 0" rpy="0 0 0" />
      <geometry>
        <box size="0.245 0.015 0.165" />
        </geometry>
      </collision>
    <collision name="head_pin">
      <origin xyz="0.38 0 0" rpy="0 0 0" />
      <geometry>
        <cylinder radius="0.014" length="0.3" />
        </geometry>
      </collision>
    </link>
  <link name="swivel_yoke">
    <visual name="head_swivel_barrel">
      <geometry>
        <cylinder radius="0.034" length="0.12" />
        </geometry>
      <material name="worn_pin_steel">
        <color rgba="0.42 0.43 0.42 1" />
        </material>
      </visual>
    <visual name="short_head_stem">
      <origin xyz="0.075 0 0" rpy="0 0 0" />
      <geometry>
        <box size="0.11 0.08 0.07" />
        </geometry>
      <material name="powder_coated_black_steel">
        <color rgba="0.015 0.016 0.017 1" />
        </material>
      </visual>
    <visual name="tilt_yoke_bridge">
      <origin xyz="0.12 0 0" rpy="0 0 0" />
      <geometry>
        <box size="0.07 0.31 0.045" />
        </geometry>
      <material name="powder_coated_black_steel">
        <color rgba="0.015 0.016 0.017 1" />
        </material>
      </visual>
    <visual name="tilt_cheek_0">
      <origin xyz="0.175 0.14 0" rpy="0 0 0" />
      <geometry>
        <box size="0.06 0.032 0.25" />
        </geometry>
      <material name="powder_coated_black_steel">
        <color rgba="0.015 0.016 0.017 1" />
        </material>
      </visual>
    <visual name="tilt_cheek_1">
      <origin xyz="0.175 -0.14 0" rpy="0 0 0" />
      <geometry>
        <box size="0.06 0.032 0.25" />
        </geometry>
      <material name="powder_coated_black_steel">
        <color rgba="0.015 0.016 0.017 1" />
        </material>
      </visual>
    <visual name="tilt_pin">
      <origin xyz="0.18 0 0" rpy="-1.5708 0 0" />
      <geometry>
        <cylinder radius="0.016" length="0.32" />
        </geometry>
      <material name="worn_pin_steel">
        <color rgba="0.42 0.43 0.42 1" />
        </material>
      </visual>
    <collision name="head_swivel_barrel">
      <geometry>
        <cylinder radius="0.034" length="0.12" />
        </geometry>
      </collision>
    <collision name="short_head_stem">
      <origin xyz="0.075 0 0" rpy="0 0 0" />
      <geometry>
        <box size="0.11 0.08 0.07" />
        </geometry>
      </collision>
    <collision name="tilt_yoke_bridge">
      <origin xyz="0.12 0 0" rpy="0 0 0" />
      <geometry>
        <box size="0.07 0.31 0.045" />
        </geometry>
      </collision>
    <collision name="tilt_cheek_0">
      <origin xyz="0.175 0.14 0" rpy="0 0 0" />
      <geometry>
        <box size="0.06 0.032 0.25" />
        </geometry>
      </collision>
    <collision name="tilt_cheek_1">
      <origin xyz="0.175 -0.14 0" rpy="0 0 0" />
      <geometry>
        <box size="0.06 0.032 0.25" />
        </geometry>
      </collision>
    <collision name="tilt_pin">
      <origin xyz="0.18 0 0" rpy="-1.5708 0 0" />
      <geometry>
        <cylinder radius="0.016" length="0.32" />
        </geometry>
      </collision>
    </link>
  <link name="mounting_frame">
    <visual name="tilt_tube">
      <origin xyz="0 0 0" rpy="-1.5708 0 0" />
      <geometry>
        <cylinder radius="0.028" length="0.22" />
        </geometry>
      <material name="worn_pin_steel">
        <color rgba="0.42 0.43 0.42 1" />
        </material>
      </visual>
    <visual name="tilt_back_plate">
      <origin xyz="0.045 0 0" rpy="0 0 0" />
      <geometry>
        <box size="0.05 0.16 0.18" />
        </geometry>
      <material name="powder_coated_black_steel">
        <color rgba="0.015 0.016 0.017 1" />
        </material>
      </visual>
    <visual name="upper_frame_rail">
      <origin xyz="0.075 0 0.24" rpy="0 0 0" />
      <geometry>
        <box size="0.04 0.43 0.04" />
        </geometry>
      <material name="powder_coated_black_steel">
        <color rgba="0.015 0.016 0.017 1" />
        </material>
      </visual>
    <visual name="lower_frame_rail">
      <origin xyz="0.075 0 -0.24" rpy="0 0 0" />
      <geometry>
        <box size="0.04 0.43 0.04" />
        </geometry>
      <material name="powder_coated_black_steel">
        <color rgba="0.015 0.016 0.017 1" />
        </material>
      </visual>
    <visual name="frame_side_0">
      <origin xyz="0.075 0.2 0" rpy="0 0 0" />
      <geometry>
        <box size="0.04 0.035 0.5" />
        </geometry>
      <material name="powder_coated_black_steel">
        <color rgba="0.015 0.016 0.017 1" />
        </material>
      </visual>
    <visual name="frame_side_1">
      <origin xyz="0.075 -0.2 0" rpy="0 0 0" />
      <geometry>
        <box size="0.04 0.035 0.5" />
        </geometry>
      <material name="powder_coated_black_steel">
        <color rgba="0.015 0.016 0.017 1" />
        </material>
      </visual>
    <visual name="center_frame_tie">
      <origin xyz="0.075 0 0" rpy="0 0 0" />
      <geometry>
        <box size="0.04 0.39 0.045" />
        </geometry>
      <material name="powder_coated_black_steel">
        <color rgba="0.015 0.016 0.017 1" />
        </material>
      </visual>
    <visual name="vesa_bolt_0">
      <origin xyz="0.101 -0.2 0.15" rpy="0 1.5708 0" />
      <geometry>
        <cylinder radius="0.015" length="0.016" />
        </geometry>
      <material name="blackened_bolt_heads">
        <color rgba="0.03 0.03 0.028 1" />
        </material>
      </visual>
    <visual name="vesa_bolt_1">
      <origin xyz="0.101 0.2 0.15" rpy="0 1.5708 0" />
      <geometry>
        <cylinder radius="0.015" length="0.016" />
        </geometry>
      <material name="blackened_bolt_heads">
        <color rgba="0.03 0.03 0.028 1" />
        </material>
      </visual>
    <visual name="vesa_bolt_2">
      <origin xyz="0.101 -0.2 -0.15" rpy="0 1.5708 0" />
      <geometry>
        <cylinder radius="0.015" length="0.016" />
        </geometry>
      <material name="blackened_bolt_heads">
        <color rgba="0.03 0.03 0.028 1" />
        </material>
      </visual>
    <visual name="vesa_bolt_3">
      <origin xyz="0.101 0.2 -0.15" rpy="0 1.5708 0" />
      <geometry>
        <cylinder radius="0.015" length="0.016" />
        </geometry>
      <material name="blackened_bolt_heads">
        <color rgba="0.03 0.03 0.028 1" />
        </material>
      </visual>
    <collision name="tilt_tube">
      <origin xyz="0 0 0" rpy="-1.5708 0 0" />
      <geometry>
        <cylinder radius="0.028" length="0.22" />
        </geometry>
      </collision>
    <collision name="tilt_back_plate">
      <origin xyz="0.045 0 0" rpy="0 0 0" />
      <geometry>
        <box size="0.05 0.16 0.18" />
        </geometry>
      </collision>
    <collision name="upper_frame_rail">
      <origin xyz="0.075 0 0.24" rpy="0 0 0" />
      <geometry>
        <box size="0.04 0.43 0.04" />
        </geometry>
      </collision>
    <collision name="lower_frame_rail">
      <origin xyz="0.075 0 -0.24" rpy="0 0 0" />
      <geometry>
        <box size="0.04 0.43 0.04" />
        </geometry>
      </collision>
    <collision name="frame_side_0">
      <origin xyz="0.075 0.2 0" rpy="0 0 0" />
      <geometry>
        <box size="0.04 0.035 0.5" />
        </geometry>
      </collision>
    <collision name="frame_side_1">
      <origin xyz="0.075 -0.2 0" rpy="0 0 0" />
      <geometry>
        <box size="0.04 0.035 0.5" />
        </geometry>
      </collision>
    <collision name="center_frame_tie">
      <origin xyz="0.075 0 0" rpy="0 0 0" />
      <geometry>
        <box size="0.04 0.39 0.045" />
        </geometry>
      </collision>
    <collision name="vesa_bolt_0">
      <origin xyz="0.101 -0.2 0.15" rpy="0 1.5708 0" />
      <geometry>
        <cylinder radius="0.015" length="0.016" />
        </geometry>
      </collision>
    <collision name="vesa_bolt_1">
      <origin xyz="0.101 0.2 0.15" rpy="0 1.5708 0" />
      <geometry>
        <cylinder radius="0.015" length="0.016" />
        </geometry>
      </collision>
    <collision name="vesa_bolt_2">
      <origin xyz="0.101 -0.2 -0.15" rpy="0 1.5708 0" />
      <geometry>
        <cylinder radius="0.015" length="0.016" />
        </geometry>
      </collision>
    <collision name="vesa_bolt_3">
      <origin xyz="0.101 0.2 -0.15" rpy="0 1.5708 0" />
      <geometry>
        <cylinder radius="0.015" length="0.016" />
        </geometry>
      </collision>
    </link>
  <joint name="wall_to_primary" type="revolute">
    <parent link="wall_mount" />
    <child link="primary_arm" />
    <axis xyz="0 0 1" />
    <limit effort="120" velocity="1.2" lower="-1.25" upper="1.25" />
    </joint>
  <joint name="primary_to_secondary" type="revolute">
    <origin xyz="0.52 0 0" rpy="0 0 0" />
    <parent link="primary_arm" />
    <child link="secondary_arm" />
    <axis xyz="0 0 1" />
    <limit effort="90" velocity="1.4" lower="-1.9" upper="1.9" />
    </joint>
  <joint name="secondary_to_swivel" type="revolute">
    <origin xyz="0.38 0 0" rpy="0 0 0" />
    <parent link="secondary_arm" />
    <child link="swivel_yoke" />
    <axis xyz="0 0 1" />
    <limit effort="55" velocity="1.6" lower="-1.35" upper="1.35" />
    </joint>
  <joint name="swivel_to_frame" type="revolute">
    <origin xyz="0.18 0 0" rpy="0 0 0" />
    <parent link="swivel_yoke" />
    <child link="mounting_frame" />
    <axis xyz="0 1 0" />
    <limit effort="35" velocity="1" lower="-0.35" upper="0.25" />
    </joint>
  </robot>
