<robot name="compact_lab_monocular_microscope">
  <link name="stand">
    <visual name="heavy_base">
      <geometry>
        <mesh filename="assets/meshes/heavy_rounded_base.obj" />
        </geometry>
      <material name="charcoal_cast_metal">
        <color rgba="0.08 0.085 0.09 1" />
        </material>
      </visual>
    <visual name="swept_arm">
      <geometry>
        <mesh filename="assets/meshes/swept_cast_arm.obj" />
        </geometry>
      <material name="warm_white_enamel">
        <color rgba="0.82 0.8 0.72 1" />
        </material>
      </visual>
    <visual name="stage_support_bed">
      <origin xyz="0 -0.035 0.176" rpy="0 0 0" />
      <geometry>
        <box size="0.15 0.088 0.012" />
        </geometry>
      <material name="matte_black">
        <color rgba="0.005 0.005 0.006 1" />
        </material>
      </visual>
    <visual name="stage_bracket">
      <origin xyz="0 0.005 0.164" rpy="0 0 0" />
      <geometry>
        <box size="0.05 0.09 0.018" />
        </geometry>
      <material name="warm_white_enamel">
        <color rgba="0.82 0.8 0.72 1" />
        </material>
      </visual>
    <visual name="focus_guide_face">
      <origin xyz="0 0.007 0.239" rpy="0 0 0" />
      <geometry>
        <box size="0.078 0.006 0.063" />
        </geometry>
      <material name="satin_chrome">
        <color rgba="0.7 0.72 0.7 1" />
        </material>
      </visual>
    <visual name="focus_guide_tab_0">
      <origin xyz="-0.044 0.049 0.239" rpy="0 0 0" />
      <geometry>
        <box size="0.014 0.082 0.063" />
        </geometry>
      <material name="warm_white_enamel">
        <color rgba="0.82 0.8 0.72 1" />
        </material>
      </visual>
    <visual name="focus_guide_tab_1">
      <origin xyz="0.044 0.049 0.239" rpy="0 0 0" />
      <geometry>
        <box size="0.014 0.082 0.063" />
        </geometry>
      <material name="warm_white_enamel">
        <color rgba="0.82 0.8 0.72 1" />
        </material>
      </visual>
    <visual name="stage_rail_0">
      <origin xyz="0 -0.067 0.186" rpy="0 0 0" />
      <geometry>
        <box size="0.16 0.01 0.008" />
        </geometry>
      <material name="satin_chrome">
        <color rgba="0.7 0.72 0.7 1" />
        </material>
      </visual>
    <visual name="stage_rail_1">
      <origin xyz="0 -0.003 0.186" rpy="0 0 0" />
      <geometry>
        <box size="0.16 0.01 0.008" />
        </geometry>
      <material name="satin_chrome">
        <color rgba="0.7 0.72 0.7 1" />
        </material>
      </visual>
    <visual name="coarse_bushing">
      <origin xyz="0.069 0.05 0.29" rpy="0 1.5708 0" />
      <geometry>
        <cylinder radius="0.029" length="0.018" />
        </geometry>
      <material name="satin_chrome">
        <color rgba="0.7 0.72 0.7 1" />
        </material>
      </visual>
    <visual name="fine_bushing">
      <origin xyz="0.069 0.05 0.225" rpy="0 1.5708 0" />
      <geometry>
        <cylinder radius="0.018" length="0.018" />
        </geometry>
      <material name="satin_chrome">
        <color rgba="0.7 0.72 0.7 1" />
        </material>
      </visual>
    <collision name="heavy_base">
      <geometry>
        <mesh filename="assets/meshes/heavy_rounded_base.obj" />
        </geometry>
      </collision>
    <collision name="swept_arm">
      <geometry>
        <mesh filename="assets/meshes/swept_cast_arm.obj" />
        </geometry>
      </collision>
    <collision name="stage_support_bed">
      <origin xyz="0 -0.035 0.176" rpy="0 0 0" />
      <geometry>
        <box size="0.15 0.088 0.012" />
        </geometry>
      </collision>
    <collision name="stage_bracket">
      <origin xyz="0 0.005 0.164" rpy="0 0 0" />
      <geometry>
        <box size="0.05 0.09 0.018" />
        </geometry>
      </collision>
    <collision name="focus_guide_face">
      <origin xyz="0 0.007 0.239" rpy="0 0 0" />
      <geometry>
        <box size="0.078 0.006 0.063" />
        </geometry>
      </collision>
    <collision name="focus_guide_tab_0">
      <origin xyz="-0.044 0.049 0.239" rpy="0 0 0" />
      <geometry>
        <box size="0.014 0.082 0.063" />
        </geometry>
      </collision>
    <collision name="focus_guide_tab_1">
      <origin xyz="0.044 0.049 0.239" rpy="0 0 0" />
      <geometry>
        <box size="0.014 0.082 0.063" />
        </geometry>
      </collision>
    <collision name="stage_rail_0">
      <origin xyz="0 -0.067 0.186" rpy="0 0 0" />
      <geometry>
        <box size="0.16 0.01 0.008" />
        </geometry>
      </collision>
    <collision name="stage_rail_1">
      <origin xyz="0 -0.003 0.186" rpy="0 0 0" />
      <geometry>
        <box size="0.16 0.01 0.008" />
        </geometry>
      </collision>
    <collision name="coarse_bushing">
      <origin xyz="0.069 0.05 0.29" rpy="0 1.5708 0" />
      <geometry>
        <cylinder radius="0.029" length="0.018" />
        </geometry>
      </collision>
    <collision name="fine_bushing">
      <origin xyz="0.069 0.05 0.225" rpy="0 1.5708 0" />
      <geometry>
        <cylinder radius="0.018" length="0.018" />
        </geometry>
      </collision>
    </link>
  <link name="stage_carriage">
    <visual name="stage_plate">
      <geometry>
        <mesh filename="assets/meshes/moving_stage_plate.obj" />
        </geometry>
      <material name="blackened_stage">
        <color rgba="0.015 0.017 0.018 1" />
        </material>
      </visual>
    <visual name="specimen_slide">
      <origin xyz="0 -0.004 0.008" rpy="0 0 0" />
      <geometry>
        <box size="0.075 0.026 0.004" />
        </geometry>
      <material name="pale_slide_glass">
        <color rgba="0.65 0.85 0.95 0.38" />
        </material>
      </visual>
    <visual name="slide_clip_0">
      <origin xyz="-0.044 -0.004 0.012" rpy="0 0 0" />
      <geometry>
        <box size="0.03 0.006 0.004" />
        </geometry>
      <material name="satin_chrome">
        <color rgba="0.7 0.72 0.7 1" />
        </material>
      </visual>
    <visual name="slide_clip_1">
      <origin xyz="0.044 -0.004 0.012" rpy="0 0 0" />
      <geometry>
        <box size="0.03 0.006 0.004" />
        </geometry>
      <material name="satin_chrome">
        <color rgba="0.7 0.72 0.7 1" />
        </material>
      </visual>
    <collision name="stage_plate">
      <geometry>
        <mesh filename="assets/meshes/moving_stage_plate.obj" />
        </geometry>
      </collision>
    <collision name="specimen_slide">
      <origin xyz="0 -0.004 0.008" rpy="0 0 0" />
      <geometry>
        <box size="0.075 0.026 0.004" />
        </geometry>
      </collision>
    <collision name="slide_clip_0">
      <origin xyz="-0.044 -0.004 0.012" rpy="0 0 0" />
      <geometry>
        <box size="0.03 0.006 0.004" />
        </geometry>
      </collision>
    <collision name="slide_clip_1">
      <origin xyz="0.044 -0.004 0.012" rpy="0 0 0" />
      <geometry>
        <box size="0.03 0.006 0.004" />
        </geometry>
      </collision>
    </link>
  <link name="optical_body">
    <visual name="slide_carriage">
      <origin xyz="0 0.078 -0.07" rpy="0 0 0" />
      <geometry>
        <box size="0.074 0.026 0.075" />
        </geometry>
      <material name="warm_white_enamel">
        <color rgba="0.82 0.8 0.72 1" />
        </material>
      </visual>
    <visual name="carriage_bridge">
      <origin xyz="0 0.037 -0.022" rpy="0 0 0" />
      <geometry>
        <box size="0.058 0.086 0.03" />
        </geometry>
      <material name="warm_white_enamel">
        <color rgba="0.82 0.8 0.72 1" />
        </material>
      </visual>
    <visual name="body_tube">
      <geometry>
        <cylinder radius="0.025" length="0.1" />
        </geometry>
      <material name="matte_black">
        <color rgba="0.005 0.005 0.006 1" />
        </material>
      </visual>
    <visual name="nose_socket">
      <origin xyz="0 0 -0.036" rpy="0 0 0" />
      <geometry>
        <cylinder radius="0.031" length="0.026" />
        </geometry>
      <material name="warm_white_enamel">
        <color rgba="0.82 0.8 0.72 1" />
        </material>
      </visual>
    <visual name="monocular_head">
      <origin xyz="0 0.03 0.078" rpy="-0.78 0 0" />
      <geometry>
        <cylinder radius="0.026" length="0.08" />
        </geometry>
      <material name="warm_white_enamel">
        <color rgba="0.82 0.8 0.72 1" />
        </material>
      </visual>
    <visual name="eyepiece">
      <origin xyz="0 0.07 0.118" rpy="-0.78 0 0" />
      <geometry>
        <cylinder radius="0.018" length="0.055" />
        </geometry>
      <material name="matte_black">
        <color rgba="0.005 0.005 0.006 1" />
        </material>
      </visual>
    <collision name="slide_carriage">
      <origin xyz="0 0.078 -0.07" rpy="0 0 0" />
      <geometry>
        <box size="0.074 0.026 0.075" />
        </geometry>
      </collision>
    <collision name="carriage_bridge">
      <origin xyz="0 0.037 -0.022" rpy="0 0 0" />
      <geometry>
        <box size="0.058 0.086 0.03" />
        </geometry>
      </collision>
    <collision name="body_tube">
      <geometry>
        <cylinder radius="0.025" length="0.1" />
        </geometry>
      </collision>
    <collision name="nose_socket">
      <origin xyz="0 0 -0.036" rpy="0 0 0" />
      <geometry>
        <cylinder radius="0.031" length="0.026" />
        </geometry>
      </collision>
    <collision name="monocular_head">
      <origin xyz="0 0.03 0.078" rpy="-0.78 0 0" />
      <geometry>
        <cylinder radius="0.026" length="0.08" />
        </geometry>
      </collision>
    <collision name="eyepiece">
      <origin xyz="0 0.07 0.118" rpy="-0.78 0 0" />
      <geometry>
        <cylinder radius="0.018" length="0.055" />
        </geometry>
      </collision>
    </link>
  <link name="objective_turret">
    <visual name="turret_disk">
      <geometry>
        <cylinder radius="0.034" length="0.018" />
        </geometry>
      <material name="satin_chrome">
        <color rgba="0.7 0.72 0.7 1" />
        </material>
      </visual>
    <visual name="objective_0">
      <origin xyz="0 -0.02 -0.028" rpy="0 0 0" />
      <geometry>
        <cylinder radius="0.007" length="0.038" />
        </geometry>
      <material name="matte_black">
        <color rgba="0.005 0.005 0.006 1" />
        </material>
      </visual>
    <visual name="objective_1">
      <origin xyz="0.018 0.01 -0.025" rpy="0 0 0" />
      <geometry>
        <cylinder radius="0.006" length="0.032" />
        </geometry>
      <material name="satin_chrome">
        <color rgba="0.7 0.72 0.7 1" />
        </material>
      </visual>
    <visual name="objective_2">
      <origin xyz="-0.018 0.01 -0.023" rpy="0 0 0" />
      <geometry>
        <cylinder radius="0.009" length="0.028" />
        </geometry>
      <material name="satin_chrome">
        <color rgba="0.7 0.72 0.7 1" />
        </material>
      </visual>
    <collision name="turret_disk">
      <geometry>
        <cylinder radius="0.034" length="0.018" />
        </geometry>
      </collision>
    <collision name="objective_0">
      <origin xyz="0 -0.02 -0.028" rpy="0 0 0" />
      <geometry>
        <cylinder radius="0.007" length="0.038" />
        </geometry>
      </collision>
    <collision name="objective_1">
      <origin xyz="0.018 0.01 -0.025" rpy="0 0 0" />
      <geometry>
        <cylinder radius="0.006" length="0.032" />
        </geometry>
      </collision>
    <collision name="objective_2">
      <origin xyz="-0.018 0.01 -0.023" rpy="0 0 0" />
      <geometry>
        <cylinder radius="0.009" length="0.028" />
        </geometry>
      </collision>
    </link>
  <link name="coarse_knob">
    <visual name="coarse_dial">
      <geometry>
        <mesh filename="assets/meshes/coarse_focus_knob.obj" />
        </geometry>
      <material name="matte_black">
        <color rgba="0.005 0.005 0.006 1" />
        </material>
      </visual>
    <visual name="coarse_stem">
      <origin xyz="0 0 -0.02" rpy="0 0 0" />
      <geometry>
        <cylinder radius="0.012" length="0.014" />
        </geometry>
      <material name="satin_chrome">
        <color rgba="0.7 0.72 0.7 1" />
        </material>
      </visual>
    <collision name="coarse_dial">
      <geometry>
        <mesh filename="assets/meshes/coarse_focus_knob.obj" />
        </geometry>
      </collision>
    <collision name="coarse_stem">
      <origin xyz="0 0 -0.02" rpy="0 0 0" />
      <geometry>
        <cylinder radius="0.012" length="0.014" />
        </geometry>
      </collision>
    </link>
  <link name="fine_knob">
    <visual name="fine_dial">
      <geometry>
        <mesh filename="assets/meshes/fine_focus_knob.obj" />
        </geometry>
      <material name="matte_black">
        <color rgba="0.005 0.005 0.006 1" />
        </material>
      </visual>
    <visual name="fine_stem">
      <origin xyz="0 0 -0.016" rpy="0 0 0" />
      <geometry>
        <cylinder radius="0.007" length="0.012" />
        </geometry>
      <material name="satin_chrome">
        <color rgba="0.7 0.72 0.7 1" />
        </material>
      </visual>
    <collision name="fine_dial">
      <geometry>
        <mesh filename="assets/meshes/fine_focus_knob.obj" />
        </geometry>
      </collision>
    <collision name="fine_stem">
      <origin xyz="0 0 -0.016" rpy="0 0 0" />
      <geometry>
        <cylinder radius="0.007" length="0.012" />
        </geometry>
      </collision>
    </link>
  <joint name="stand_to_stage" type="prismatic">
    <origin xyz="0 -0.035 0.196" rpy="0 0 0" />
    <parent link="stand" />
    <child link="stage_carriage" />
    <axis xyz="1 0 0" />
    <limit effort="30" velocity="0.08" lower="-0.035" upper="0.035" />
    </joint>
  <joint name="stand_to_optical" type="prismatic">
    <origin xyz="0 -0.055 0.315" rpy="0 0 0" />
    <parent link="stand" />
    <child link="optical_body" />
    <axis xyz="0 0 1" />
    <limit effort="45" velocity="0.04" lower="0" upper="0.06" />
    </joint>
  <joint name="optical_to_turret" type="continuous">
    <origin xyz="0 0 -0.058" rpy="0 0 0" />
    <parent link="optical_body" />
    <child link="objective_turret" />
    <axis xyz="0 0 1" />
    <limit effort="1.5" velocity="2" />
    </joint>
  <joint name="stand_to_coarse" type="continuous">
    <origin xyz="0.087 0.05 0.29" rpy="0 1.5708 0" />
    <parent link="stand" />
    <child link="coarse_knob" />
    <axis xyz="0 0 1" />
    <limit effort="2" velocity="5" />
    </joint>
  <joint name="stand_to_fine" type="continuous">
    <origin xyz="0.085 0.05 0.225" rpy="0 1.5708 0" />
    <parent link="stand" />
    <child link="fine_knob" />
    <axis xyz="0 0 1" />
    <limit effort="0.8" velocity="6" />
    </joint>
  </robot>
