<robot name="counterbalanced_monitor_mount_study">
  <material name="hard_anodized_aluminum">
    <color rgba="0.32 0.34 0.36 1" />
    </material>
  <material name="black_oxide_steel">
    <color rgba="0.055 0.06 0.065 1" />
    </material>
  <material name="bearing_steel">
    <color rgba="0.72 0.74 0.76 1" />
    </material>
  <material name="matte_access_covers">
    <color rgba="0.15 0.16 0.17 1" />
    </material>
  <material name="spring_housing_gray">
    <color rgba="0.42 0.43 0.44 1" />
    </material>
  <material name="oilite_bronze_bushings">
    <color rgba="0.7 0.48 0.22 1" />
    </material>
  <material name="cable_passage_black">
    <color rgba="0.015 0.017 0.02 1" />
    </material>
  <link name="wall_bracket">
    <inertial>
      <origin xyz="0.055 0 0.3" rpy="0 0 0" />
      <mass value="4.5" />
      <inertia ixx="0.14475" ixy="0" ixz="0" iyy="0.11355" iyz="0" izz="0.0555" />
      </inertial>
    <visual name="wall_plate">
      <origin xyz="0 0 0.3" rpy="0 0 0" />
      <geometry>
        <box size="0.026 0.34 0.46" />
        </geometry>
      <material name="hard_anodized_aluminum">
        <color rgba="0.32 0.34 0.36 1" />
        </material>
      </visual>
    <visual name="lower_flange">
      <origin xyz="0.067 0 0.082" rpy="0 0 0" />
      <geometry>
        <box size="0.16 0.3 0.024" />
        </geometry>
      <material name="hard_anodized_aluminum">
        <color rgba="0.32 0.34 0.36 1" />
        </material>
      </visual>
    <visual name="upper_flange">
      <origin xyz="0.062 0 0.518" rpy="0 0 0" />
      <geometry>
        <box size="0.145 0.26 0.022" />
        </geometry>
      <material name="hard_anodized_aluminum">
        <color rgba="0.32 0.34 0.36 1" />
        </material>
      </visual>
    <visual name="side_gusset_0">
      <origin xyz="0.056 0.122 0.3" rpy="0 0 0" />
      <geometry>
        <box size="0.12 0.022 0.285" />
        </geometry>
      <material name="hard_anodized_aluminum">
        <color rgba="0.32 0.34 0.36 1" />
        </material>
      </visual>
    <visual name="side_gusset_1">
      <origin xyz="0.056 -0.122 0.3" rpy="0 0 0" />
      <geometry>
        <box size="0.12 0.022 0.285" />
        </geometry>
      <material name="hard_anodized_aluminum">
        <color rgba="0.32 0.34 0.36 1" />
        </material>
      </visual>
    <visual name="fixed_bearing_cup">
      <origin xyz="0.088 0 0.318" rpy="0 0 0" />
      <geometry>
        <cylinder radius="0.061" length="0.088" />
        </geometry>
      <material name="black_oxide_steel">
        <color rgba="0.055 0.06 0.065 1" />
        </material>
      </visual>
    <visual name="pan_spindle_socket">
      <origin xyz="0.088 0 0.318" rpy="0 0 0" />
      <geometry>
        <cylinder radius="0.042" length="0.19" />
        </geometry>
      <material name="bearing_steel">
        <color rgba="0.72 0.74 0.76 1" />
        </material>
      </visual>
    <visual name="upper_thrust_race">
      <origin xyz="0.088 0 0.413" rpy="0 0 0" />
      <geometry>
        <cylinder radius="0.071" length="0.014" />
        </geometry>
      <material name="black_oxide_steel">
        <color rgba="0.055 0.06 0.065 1" />
        </material>
      </visual>
    <visual name="lower_thrust_race">
      <origin xyz="0.088 0 0.223" rpy="0 0 0" />
      <geometry>
        <cylinder radius="0.071" length="0.014" />
        </geometry>
      <material name="black_oxide_steel">
        <color rgba="0.055 0.06 0.065 1" />
        </material>
      </visual>
    <visual name="removable_rear_cover">
      <origin xyz="0.018 0 0.3" rpy="0 0 0" />
      <geometry>
        <box size="0.018 0.18 0.118" />
        </geometry>
      <material name="matte_access_covers">
        <color rgba="0.15 0.16 0.17 1" />
        </material>
      </visual>
    <visual name="vertical_cable_window">
      <origin xyz="0.014 0 0.168" rpy="0 0 0" />
      <geometry>
        <box size="0.012 0.1 0.026" />
        </geometry>
      <material name="cable_passage_black">
        <color rgba="0.015 0.017 0.02 1" />
        </material>
      </visual>
    <visual name="mounting_hole_0">
      <origin xyz="0.015 0.115 0.46" rpy="0 1.5708 0" />
      <geometry>
        <cylinder radius="0.018" length="0.008" />
        </geometry>
      <material name="black_oxide_steel">
        <color rgba="0.055 0.06 0.065 1" />
        </material>
      </visual>
    <visual name="cap_screw_0">
      <origin xyz="0.02 0.115 0.46" rpy="0 1.5708 0" />
      <geometry>
        <cylinder radius="0.006" length="0.01" />
        </geometry>
      <material name="bearing_steel">
        <color rgba="0.72 0.74 0.76 1" />
        </material>
      </visual>
    <visual name="mounting_hole_1">
      <origin xyz="0.015 -0.115 0.46" rpy="0 1.5708 0" />
      <geometry>
        <cylinder radius="0.018" length="0.008" />
        </geometry>
      <material name="black_oxide_steel">
        <color rgba="0.055 0.06 0.065 1" />
        </material>
      </visual>
    <visual name="cap_screw_1">
      <origin xyz="0.02 -0.115 0.46" rpy="0 1.5708 0" />
      <geometry>
        <cylinder radius="0.006" length="0.01" />
        </geometry>
      <material name="bearing_steel">
        <color rgba="0.72 0.74 0.76 1" />
        </material>
      </visual>
    <visual name="mounting_hole_2">
      <origin xyz="0.015 0.115 0.14" rpy="0 1.5708 0" />
      <geometry>
        <cylinder radius="0.018" length="0.008" />
        </geometry>
      <material name="black_oxide_steel">
        <color rgba="0.055 0.06 0.065 1" />
        </material>
      </visual>
    <visual name="cap_screw_2">
      <origin xyz="0.02 0.115 0.14" rpy="0 1.5708 0" />
      <geometry>
        <cylinder radius="0.006" length="0.01" />
        </geometry>
      <material name="bearing_steel">
        <color rgba="0.72 0.74 0.76 1" />
        </material>
      </visual>
    <visual name="mounting_hole_3">
      <origin xyz="0.015 -0.115 0.14" rpy="0 1.5708 0" />
      <geometry>
        <cylinder radius="0.018" length="0.008" />
        </geometry>
      <material name="black_oxide_steel">
        <color rgba="0.055 0.06 0.065 1" />
        </material>
      </visual>
    <visual name="cap_screw_3">
      <origin xyz="0.02 -0.115 0.14" rpy="0 1.5708 0" />
      <geometry>
        <cylinder radius="0.006" length="0.01" />
        </geometry>
      <material name="bearing_steel">
        <color rgba="0.72 0.74 0.76 1" />
        </material>
      </visual>
    <collision name="wall_plate">
      <origin xyz="0 0 0.3" rpy="0 0 0" />
      <geometry>
        <box size="0.026 0.34 0.46" />
        </geometry>
      </collision>
    <collision name="lower_flange">
      <origin xyz="0.067 0 0.082" rpy="0 0 0" />
      <geometry>
        <box size="0.16 0.3 0.024" />
        </geometry>
      </collision>
    <collision name="upper_flange">
      <origin xyz="0.062 0 0.518" rpy="0 0 0" />
      <geometry>
        <box size="0.145 0.26 0.022" />
        </geometry>
      </collision>
    <collision name="side_gusset_0">
      <origin xyz="0.056 0.122 0.3" rpy="0 0 0" />
      <geometry>
        <box size="0.12 0.022 0.285" />
        </geometry>
      </collision>
    <collision name="side_gusset_1">
      <origin xyz="0.056 -0.122 0.3" rpy="0 0 0" />
      <geometry>
        <box size="0.12 0.022 0.285" />
        </geometry>
      </collision>
    <collision name="fixed_bearing_cup">
      <origin xyz="0.088 0 0.318" rpy="0 0 0" />
      <geometry>
        <cylinder radius="0.061" length="0.088" />
        </geometry>
      </collision>
    <collision name="pan_spindle_socket">
      <origin xyz="0.088 0 0.318" rpy="0 0 0" />
      <geometry>
        <cylinder radius="0.042" length="0.19" />
        </geometry>
      </collision>
    <collision name="upper_thrust_race">
      <origin xyz="0.088 0 0.413" rpy="0 0 0" />
      <geometry>
        <cylinder radius="0.071" length="0.014" />
        </geometry>
      </collision>
    <collision name="lower_thrust_race">
      <origin xyz="0.088 0 0.223" rpy="0 0 0" />
      <geometry>
        <cylinder radius="0.071" length="0.014" />
        </geometry>
      </collision>
    <collision name="removable_rear_cover">
      <origin xyz="0.018 0 0.3" rpy="0 0 0" />
      <geometry>
        <box size="0.018 0.18 0.118" />
        </geometry>
      </collision>
    <collision name="vertical_cable_window">
      <origin xyz="0.014 0 0.168" rpy="0 0 0" />
      <geometry>
        <box size="0.012 0.1 0.026" />
        </geometry>
      </collision>
    <collision name="mounting_hole_0">
      <origin xyz="0.015 0.115 0.46" rpy="0 1.5708 0" />
      <geometry>
        <cylinder radius="0.018" length="0.008" />
        </geometry>
      </collision>
    <collision name="cap_screw_0">
      <origin xyz="0.02 0.115 0.46" rpy="0 1.5708 0" />
      <geometry>
        <cylinder radius="0.006" length="0.01" />
        </geometry>
      </collision>
    <collision name="mounting_hole_1">
      <origin xyz="0.015 -0.115 0.46" rpy="0 1.5708 0" />
      <geometry>
        <cylinder radius="0.018" length="0.008" />
        </geometry>
      </collision>
    <collision name="cap_screw_1">
      <origin xyz="0.02 -0.115 0.46" rpy="0 1.5708 0" />
      <geometry>
        <cylinder radius="0.006" length="0.01" />
        </geometry>
      </collision>
    <collision name="mounting_hole_2">
      <origin xyz="0.015 0.115 0.14" rpy="0 1.5708 0" />
      <geometry>
        <cylinder radius="0.018" length="0.008" />
        </geometry>
      </collision>
    <collision name="cap_screw_2">
      <origin xyz="0.02 0.115 0.14" rpy="0 1.5708 0" />
      <geometry>
        <cylinder radius="0.006" length="0.01" />
        </geometry>
      </collision>
    <collision name="mounting_hole_3">
      <origin xyz="0.015 -0.115 0.14" rpy="0 1.5708 0" />
      <geometry>
        <cylinder radius="0.018" length="0.008" />
        </geometry>
      </collision>
    <collision name="cap_screw_3">
      <origin xyz="0.02 -0.115 0.14" rpy="0 1.5708 0" />
      <geometry>
        <cylinder radius="0.006" length="0.01" />
        </geometry>
      </collision>
    </link>
  <link name="pan_carriage">
    <inertial>
      <origin xyz="0.045 0 0.03" rpy="0 0 0" />
      <mass value="2.2" />
      <inertia ixx="0.0168483" ixy="0" ixz="0" iyy="0.0168483" iyz="0" izz="0.00891" />
      </inertial>
    <visual name="rotating_spindle">
      <geometry>
        <cylinder radius="0.038" length="0.21" />
        </geometry>
      <material name="bearing_steel">
        <color rgba="0.72 0.74 0.76 1" />
        </material>
      </visual>
    <visual name="friction_collar_top">
      <origin xyz="0 0 0.118" rpy="0 0 0" />
      <geometry>
        <cylinder radius="0.066" length="0.026" />
        </geometry>
      <material name="black_oxide_steel">
        <color rgba="0.055 0.06 0.065 1" />
        </material>
      </visual>
    <visual name="friction_collar_bottom">
      <origin xyz="0 0 -0.118" rpy="0 0 0" />
      <geometry>
        <cylinder radius="0.066" length="0.026" />
        </geometry>
      <material name="black_oxide_steel">
        <color rgba="0.055 0.06 0.065 1" />
        </material>
      </visual>
    <visual name="shoulder_bridge">
      <origin xyz="0.036 0 0.135" rpy="0 0 0" />
      <geometry>
        <box size="0.076 0.106 0.052" />
        </geometry>
      <material name="hard_anodized_aluminum">
        <color rgba="0.32 0.34 0.36 1" />
        </material>
      </visual>
    <visual name="shoulder_cheek_0">
      <origin xyz="0.112 0.056 0.135" rpy="0 0 0" />
      <geometry>
        <box size="0.085 0.014 0.118" />
        </geometry>
      <material name="hard_anodized_aluminum">
        <color rgba="0.32 0.34 0.36 1" />
        </material>
      </visual>
    <visual name="shoulder_cheek_1">
      <origin xyz="0.112 -0.056 0.135" rpy="0 0 0" />
      <geometry>
        <box size="0.085 0.014 0.118" />
        </geometry>
      <material name="hard_anodized_aluminum">
        <color rgba="0.32 0.34 0.36 1" />
        </material>
      </visual>
    <visual name="shoulder_cross_pin">
      <origin xyz="0.115 0 0.135" rpy="1.5708 0 0" />
      <geometry>
        <cylinder radius="0.031" length="0.138" />
        </geometry>
      <material name="bearing_steel">
        <color rgba="0.72 0.74 0.76 1" />
        </material>
      </visual>
    <visual name="shoulder_lock_nut_0">
      <origin xyz="0.115 0.069 0.135" rpy="1.5708 0 0" />
      <geometry>
        <cylinder radius="0.043" length="0.018" />
        </geometry>
      <material name="black_oxide_steel">
        <color rgba="0.055 0.06 0.065 1" />
        </material>
      </visual>
    <visual name="shoulder_lock_nut_1">
      <origin xyz="0.115 -0.069 0.135" rpy="1.5708 0 0" />
      <geometry>
        <cylinder radius="0.043" length="0.018" />
        </geometry>
      <material name="black_oxide_steel">
        <color rgba="0.055 0.06 0.065 1" />
        </material>
      </visual>
    <visual name="base_cable_exit">
      <origin xyz="0.032 0 0.157" rpy="0 0 0" />
      <geometry>
        <box size="0.06 0.05 0.018" />
        </geometry>
      <material name="cable_passage_black">
        <color rgba="0.015 0.017 0.02 1" />
        </material>
      </visual>
    <collision name="rotating_spindle">
      <geometry>
        <cylinder radius="0.038" length="0.21" />
        </geometry>
      </collision>
    <collision name="friction_collar_top">
      <origin xyz="0 0 0.118" rpy="0 0 0" />
      <geometry>
        <cylinder radius="0.066" length="0.026" />
        </geometry>
      </collision>
    <collision name="friction_collar_bottom">
      <origin xyz="0 0 -0.118" rpy="0 0 0" />
      <geometry>
        <cylinder radius="0.066" length="0.026" />
        </geometry>
      </collision>
    <collision name="shoulder_bridge">
      <origin xyz="0.036 0 0.135" rpy="0 0 0" />
      <geometry>
        <box size="0.076 0.106 0.052" />
        </geometry>
      </collision>
    <collision name="shoulder_cheek_0">
      <origin xyz="0.112 0.056 0.135" rpy="0 0 0" />
      <geometry>
        <box size="0.085 0.014 0.118" />
        </geometry>
      </collision>
    <collision name="shoulder_cheek_1">
      <origin xyz="0.112 -0.056 0.135" rpy="0 0 0" />
      <geometry>
        <box size="0.085 0.014 0.118" />
        </geometry>
      </collision>
    <collision name="shoulder_cross_pin">
      <origin xyz="0.115 0 0.135" rpy="1.5708 0 0" />
      <geometry>
        <cylinder radius="0.031" length="0.138" />
        </geometry>
      </collision>
    <collision name="shoulder_lock_nut_0">
      <origin xyz="0.115 0.069 0.135" rpy="1.5708 0 0" />
      <geometry>
        <cylinder radius="0.043" length="0.018" />
        </geometry>
      </collision>
    <collision name="shoulder_lock_nut_1">
      <origin xyz="0.115 -0.069 0.135" rpy="1.5708 0 0" />
      <geometry>
        <cylinder radius="0.043" length="0.018" />
        </geometry>
      </collision>
    <collision name="base_cable_exit">
      <origin xyz="0.032 0 0.157" rpy="0 0 0" />
      <geometry>
        <box size="0.06 0.05 0.018" />
        </geometry>
      </collision>
    </link>
  <link name="primary_arm">
    <inertial>
      <origin xyz="0.285 0 0.005" rpy="0 0 0" />
      <mass value="1.9" />
      <inertia ixx="0.00647979" ixy="0" ixz="0" iyy="0.0589198" iyz="0" izz="0.0577917" />
      </inertial>
    <visual name="shoulder_bushing">
      <origin xyz="0 0 0" rpy="1.5708 0 0" />
      <geometry>
        <cylinder radius="0.03" length="0.074" />
        </geometry>
      <material name="oilite_bronze_bushings">
        <color rgba="0.7 0.48 0.22 1" />
        </material>
      </visual>
    <visual name="shoulder_knuckle">
      <origin xyz="0 0 0" rpy="1.5708 0 0" />
      <geometry>
        <cylinder radius="0.038" length="0.05" />
        </geometry>
      <material name="black_oxide_steel">
        <color rgba="0.055 0.06 0.065 1" />
        </material>
      </visual>
    <visual name="side_rail_0">
      <origin xyz="0.28 0.043 0" rpy="0 0 0" />
      <geometry>
        <box size="0.5 0.018 0.04" />
        </geometry>
      <material name="hard_anodized_aluminum">
        <color rgba="0.32 0.34 0.36 1" />
        </material>
      </visual>
    <visual name="side_rail_1">
      <origin xyz="0.28 -0.043 0" rpy="0 0 0" />
      <geometry>
        <box size="0.5 0.018 0.04" />
        </geometry>
      <material name="hard_anodized_aluminum">
        <color rgba="0.32 0.34 0.36 1" />
        </material>
      </visual>
    <visual name="cross_tie_0">
      <origin xyz="0.07 0 0" rpy="0 0 0" />
      <geometry>
        <box size="0.034 0.104 0.03" />
        </geometry>
      <material name="hard_anodized_aluminum">
        <color rgba="0.32 0.34 0.36 1" />
        </material>
      </visual>
    <visual name="cross_tie_1">
      <origin xyz="0.275 0 0" rpy="0 0 0" />
      <geometry>
        <box size="0.034 0.104 0.03" />
        </geometry>
      <material name="hard_anodized_aluminum">
        <color rgba="0.32 0.34 0.36 1" />
        </material>
      </visual>
    <visual name="cross_tie_2">
      <origin xyz="0.49 0 0" rpy="0 0 0" />
      <geometry>
        <box size="0.034 0.104 0.03" />
        </geometry>
      <material name="hard_anodized_aluminum">
        <color rgba="0.32 0.34 0.36 1" />
        </material>
      </visual>
    <visual name="spring_tube">
      <origin xyz="0.276 0 0.04" rpy="0 1.5708 0" />
      <geometry>
        <cylinder radius="0.026" length="0.405" />
        </geometry>
      <material name="spring_housing_gray">
        <color rgba="0.42 0.43 0.44 1" />
        </material>
      </visual>
    <visual name="spring_access_cover">
      <origin xyz="0.286 0 0.065" rpy="0 0 0" />
      <geometry>
        <box size="0.27 0.052 0.014" />
        </geometry>
      <material name="matte_access_covers">
        <color rgba="0.15 0.16 0.17 1" />
        </material>
      </visual>
    <visual name="underside_cable_tray">
      <origin xyz="0.305 0 -0.031" rpy="0 0 0" />
      <geometry>
        <box size="0.36 0.026 0.014" />
        </geometry>
      <material name="cable_passage_black">
        <color rgba="0.015 0.017 0.02 1" />
        </material>
      </visual>
    <visual name="gas_spring_rod">
      <origin xyz="0.282 0 -0.062" rpy="0 1.5708 0" />
      <geometry>
        <cylinder radius="0.013" length="0.375" />
        </geometry>
      <material name="black_oxide_steel">
        <color rgba="0.055 0.06 0.065 1" />
        </material>
      </visual>
    <visual name="spring_anchor_0">
      <origin xyz="0.098 0 -0.036" rpy="0 0 0" />
      <geometry>
        <box size="0.04 0.08 0.052" />
        </geometry>
      <material name="black_oxide_steel">
        <color rgba="0.055 0.06 0.065 1" />
        </material>
      </visual>
    <visual name="spring_anchor_1">
      <origin xyz="0.466 0 -0.036" rpy="0 0 0" />
      <geometry>
        <box size="0.04 0.08 0.052" />
        </geometry>
      <material name="black_oxide_steel">
        <color rgba="0.055 0.06 0.065 1" />
        </material>
      </visual>
    <visual name="elbow_outer_barrel">
      <origin xyz="0.548 0 0" rpy="0 0 0" />
      <geometry>
        <cylinder radius="0.036" length="0.096" />
        </geometry>
      <material name="black_oxide_steel">
        <color rgba="0.055 0.06 0.065 1" />
        </material>
      </visual>
    <visual name="elbow_pin">
      <origin xyz="0.548 0 0" rpy="0 0 0" />
      <geometry>
        <cylinder radius="0.025" length="0.128" />
        </geometry>
      <material name="bearing_steel">
        <color rgba="0.72 0.74 0.76 1" />
        </material>
      </visual>
    <visual name="upper_elbow_strap">
      <origin xyz="0.528 0 0.056" rpy="0 0 0" />
      <geometry>
        <box size="0.06 0.102 0.02" />
        </geometry>
      <material name="hard_anodized_aluminum">
        <color rgba="0.32 0.34 0.36 1" />
        </material>
      </visual>
    <visual name="lower_elbow_strap">
      <origin xyz="0.528 0 -0.056" rpy="0 0 0" />
      <geometry>
        <box size="0.06 0.102 0.02" />
        </geometry>
      <material name="hard_anodized_aluminum">
        <color rgba="0.32 0.34 0.36 1" />
        </material>
      </visual>
    <visual name="elbow_web_0">
      <origin xyz="0.52 0.04 0" rpy="0 0 0" />
      <geometry>
        <box size="0.084 0.014 0.04" />
        </geometry>
      <material name="hard_anodized_aluminum">
        <color rgba="0.32 0.34 0.36 1" />
        </material>
      </visual>
    <visual name="elbow_web_1">
      <origin xyz="0.52 -0.04 0" rpy="0 0 0" />
      <geometry>
        <box size="0.084 0.014 0.04" />
        </geometry>
      <material name="hard_anodized_aluminum">
        <color rgba="0.32 0.34 0.36 1" />
        </material>
      </visual>
    <collision name="shoulder_bushing">
      <origin xyz="0 0 0" rpy="1.5708 0 0" />
      <geometry>
        <cylinder radius="0.03" length="0.074" />
        </geometry>
      </collision>
    <collision name="shoulder_knuckle">
      <origin xyz="0 0 0" rpy="1.5708 0 0" />
      <geometry>
        <cylinder radius="0.038" length="0.05" />
        </geometry>
      </collision>
    <collision name="side_rail_0">
      <origin xyz="0.28 0.043 0" rpy="0 0 0" />
      <geometry>
        <box size="0.5 0.018 0.04" />
        </geometry>
      </collision>
    <collision name="side_rail_1">
      <origin xyz="0.28 -0.043 0" rpy="0 0 0" />
      <geometry>
        <box size="0.5 0.018 0.04" />
        </geometry>
      </collision>
    <collision name="cross_tie_0">
      <origin xyz="0.07 0 0" rpy="0 0 0" />
      <geometry>
        <box size="0.034 0.104 0.03" />
        </geometry>
      </collision>
    <collision name="cross_tie_1">
      <origin xyz="0.275 0 0" rpy="0 0 0" />
      <geometry>
        <box size="0.034 0.104 0.03" />
        </geometry>
      </collision>
    <collision name="cross_tie_2">
      <origin xyz="0.49 0 0" rpy="0 0 0" />
      <geometry>
        <box size="0.034 0.104 0.03" />
        </geometry>
      </collision>
    <collision name="spring_tube">
      <origin xyz="0.276 0 0.04" rpy="0 1.5708 0" />
      <geometry>
        <cylinder radius="0.026" length="0.405" />
        </geometry>
      </collision>
    <collision name="spring_access_cover">
      <origin xyz="0.286 0 0.065" rpy="0 0 0" />
      <geometry>
        <box size="0.27 0.052 0.014" />
        </geometry>
      </collision>
    <collision name="underside_cable_tray">
      <origin xyz="0.305 0 -0.031" rpy="0 0 0" />
      <geometry>
        <box size="0.36 0.026 0.014" />
        </geometry>
      </collision>
    <collision name="gas_spring_rod">
      <origin xyz="0.282 0 -0.062" rpy="0 1.5708 0" />
      <geometry>
        <cylinder radius="0.013" length="0.375" />
        </geometry>
      </collision>
    <collision name="spring_anchor_0">
      <origin xyz="0.098 0 -0.036" rpy="0 0 0" />
      <geometry>
        <box size="0.04 0.08 0.052" />
        </geometry>
      </collision>
    <collision name="spring_anchor_1">
      <origin xyz="0.466 0 -0.036" rpy="0 0 0" />
      <geometry>
        <box size="0.04 0.08 0.052" />
        </geometry>
      </collision>
    <collision name="elbow_outer_barrel">
      <origin xyz="0.548 0 0" rpy="0 0 0" />
      <geometry>
        <cylinder radius="0.036" length="0.096" />
        </geometry>
      </collision>
    <collision name="elbow_pin">
      <origin xyz="0.548 0 0" rpy="0 0 0" />
      <geometry>
        <cylinder radius="0.025" length="0.128" />
        </geometry>
      </collision>
    <collision name="upper_elbow_strap">
      <origin xyz="0.528 0 0.056" rpy="0 0 0" />
      <geometry>
        <box size="0.06 0.102 0.02" />
        </geometry>
      </collision>
    <collision name="lower_elbow_strap">
      <origin xyz="0.528 0 -0.056" rpy="0 0 0" />
      <geometry>
        <box size="0.06 0.102 0.02" />
        </geometry>
      </collision>
    <collision name="elbow_web_0">
      <origin xyz="0.52 0.04 0" rpy="0 0 0" />
      <geometry>
        <box size="0.084 0.014 0.04" />
        </geometry>
      </collision>
    <collision name="elbow_web_1">
      <origin xyz="0.52 -0.04 0" rpy="0 0 0" />
      <geometry>
        <box size="0.084 0.014 0.04" />
        </geometry>
      </collision>
    </link>
  <link name="secondary_arm">
    <inertial>
      <origin xyz="0.25 0 0.02" rpy="0 0 0" />
      <mass value="1.2" />
      <inertia ixx="0.0025625" ixy="0" ixz="0" iyy="0.027065" iyz="0" izz="0.0265025" />
      </inertial>
    <visual name="elbow_inner_sleeve">
      <geometry>
        <cylinder radius="0.03" length="0.09" />
        </geometry>
      <material name="oilite_bronze_bushings">
        <color rgba="0.7 0.48 0.22 1" />
        </material>
      </visual>
    <visual name="elbow_friction_disk_top">
      <origin xyz="0 0 0.057" rpy="0 0 0" />
      <geometry>
        <cylinder radius="0.04" length="0.024" />
        </geometry>
      <material name="black_oxide_steel">
        <color rgba="0.055 0.06 0.065 1" />
        </material>
      </visual>
    <visual name="elbow_friction_disk_bottom">
      <origin xyz="0 0 -0.057" rpy="0 0 0" />
      <geometry>
        <cylinder radius="0.04" length="0.024" />
        </geometry>
      <material name="black_oxide_steel">
        <color rgba="0.055 0.06 0.065 1" />
        </material>
      </visual>
    <visual name="machined_box_beam">
      <origin xyz="0.237 0 0" rpy="0 0 0" />
      <geometry>
        <box size="0.435 0.04 0.052" />
        </geometry>
      <material name="hard_anodized_aluminum">
        <color rgba="0.32 0.34 0.36 1" />
        </material>
      </visual>
    <visual name="side_cable_slot">
      <origin xyz="0.255 -0.033 0.01" rpy="0 0 0" />
      <geometry>
        <box size="0.32 0.026 0.018" />
        </geometry>
      <material name="cable_passage_black">
        <color rgba="0.015 0.017 0.02 1" />
        </material>
      </visual>
    <visual name="secondary_spring_case">
      <origin xyz="0.237 0 0.055" rpy="0 1.5708 0" />
      <geometry>
        <cylinder radius="0.019" length="0.315" />
        </geometry>
      <material name="spring_housing_gray">
        <color rgba="0.42 0.43 0.44 1" />
        </material>
      </visual>
    <visual name="top_access_cover">
      <origin xyz="0.25 0 0.08" rpy="0 0 0" />
      <geometry>
        <box size="0.21 0.044 0.012" />
        </geometry>
      <material name="matte_access_covers">
        <color rgba="0.15 0.16 0.17 1" />
        </material>
      </visual>
    <visual name="spring_case_mount_0">
      <origin xyz="0.08 0 0.038" rpy="0 0 0" />
      <geometry>
        <box size="0.038 0.07 0.04" />
        </geometry>
      <material name="black_oxide_steel">
        <color rgba="0.055 0.06 0.065 1" />
        </material>
      </visual>
    <visual name="spring_case_mount_1">
      <origin xyz="0.38 0 0.038" rpy="0 0 0" />
      <geometry>
        <box size="0.038 0.07 0.04" />
        </geometry>
      <material name="black_oxide_steel">
        <color rgba="0.055 0.06 0.065 1" />
        </material>
      </visual>
    <visual name="head_pan_barrel">
      <origin xyz="0.49 0 0" rpy="0 0 0" />
      <geometry>
        <cylinder radius="0.031" length="0.102" />
        </geometry>
      <material name="black_oxide_steel">
        <color rgba="0.055 0.06 0.065 1" />
        </material>
      </visual>
    <visual name="head_pan_pin">
      <origin xyz="0.49 0 0" rpy="0 0 0" />
      <geometry>
        <cylinder radius="0.022" length="0.126" />
        </geometry>
      <material name="bearing_steel">
        <color rgba="0.72 0.74 0.76 1" />
        </material>
      </visual>
    <visual name="head_end_bridge">
      <origin xyz="0.437 0 0" rpy="0 0 0" />
      <geometry>
        <box size="0.044 0.09 0.03" />
        </geometry>
      <material name="hard_anodized_aluminum">
        <color rgba="0.32 0.34 0.36 1" />
        </material>
      </visual>
    <collision name="elbow_inner_sleeve">
      <geometry>
        <cylinder radius="0.03" length="0.09" />
        </geometry>
      </collision>
    <collision name="elbow_friction_disk_top">
      <origin xyz="0 0 0.057" rpy="0 0 0" />
      <geometry>
        <cylinder radius="0.04" length="0.024" />
        </geometry>
      </collision>
    <collision name="elbow_friction_disk_bottom">
      <origin xyz="0 0 -0.057" rpy="0 0 0" />
      <geometry>
        <cylinder radius="0.04" length="0.024" />
        </geometry>
      </collision>
    <collision name="machined_box_beam">
      <origin xyz="0.237 0 0" rpy="0 0 0" />
      <geometry>
        <box size="0.435 0.04 0.052" />
        </geometry>
      </collision>
    <collision name="side_cable_slot">
      <origin xyz="0.255 -0.033 0.01" rpy="0 0 0" />
      <geometry>
        <box size="0.32 0.026 0.018" />
        </geometry>
      </collision>
    <collision name="secondary_spring_case">
      <origin xyz="0.237 0 0.055" rpy="0 1.5708 0" />
      <geometry>
        <cylinder radius="0.019" length="0.315" />
        </geometry>
      </collision>
    <collision name="top_access_cover">
      <origin xyz="0.25 0 0.08" rpy="0 0 0" />
      <geometry>
        <box size="0.21 0.044 0.012" />
        </geometry>
      </collision>
    <collision name="spring_case_mount_0">
      <origin xyz="0.08 0 0.038" rpy="0 0 0" />
      <geometry>
        <box size="0.038 0.07 0.04" />
        </geometry>
      </collision>
    <collision name="spring_case_mount_1">
      <origin xyz="0.38 0 0.038" rpy="0 0 0" />
      <geometry>
        <box size="0.038 0.07 0.04" />
        </geometry>
      </collision>
    <collision name="head_pan_barrel">
      <origin xyz="0.49 0 0" rpy="0 0 0" />
      <geometry>
        <cylinder radius="0.031" length="0.102" />
        </geometry>
      </collision>
    <collision name="head_pan_pin">
      <origin xyz="0.49 0 0" rpy="0 0 0" />
      <geometry>
        <cylinder radius="0.022" length="0.126" />
        </geometry>
      </collision>
    <collision name="head_end_bridge">
      <origin xyz="0.437 0 0" rpy="0 0 0" />
      <geometry>
        <box size="0.044 0.09 0.03" />
        </geometry>
      </collision>
    </link>
  <link name="head_knuckle">
    <inertial>
      <origin xyz="0.07 0 0" rpy="0 0 0" />
      <mass value="0.75" />
      <inertia ixx="0.00230625" ixy="0" ixz="0" iyy="0.00343125" iyz="0" izz="0.002925" />
      </inertial>
    <visual name="pan_bushing">
      <geometry>
        <cylinder radius="0.027" length="0.088" />
        </geometry>
      <material name="oilite_bronze_bushings">
        <color rgba="0.7 0.48 0.22 1" />
        </material>
      </visual>
    <visual name="pan_friction_collar_top">
      <origin xyz="0 0 0.057" rpy="0 0 0" />
      <geometry>
        <cylinder radius="0.043" length="0.026" />
        </geometry>
      <material name="black_oxide_steel">
        <color rgba="0.055 0.06 0.065 1" />
        </material>
      </visual>
    <visual name="pan_friction_collar_bottom">
      <origin xyz="0 0 -0.057" rpy="0 0 0" />
      <geometry>
        <cylinder radius="0.043" length="0.026" />
        </geometry>
      <material name="black_oxide_steel">
        <color rgba="0.055 0.06 0.065 1" />
        </material>
      </visual>
    <visual name="tilt_yoke_bridge">
      <origin xyz="0.047 0 0" rpy="0 0 0" />
      <geometry>
        <box size="0.092 0.09 0.04" />
        </geometry>
      <material name="hard_anodized_aluminum">
        <color rgba="0.32 0.34 0.36 1" />
        </material>
      </visual>
    <visual name="tilt_cheek_0">
      <origin xyz="0.13 0.044 0" rpy="0 0 0" />
      <geometry>
        <box size="0.075 0.014 0.12" />
        </geometry>
      <material name="hard_anodized_aluminum">
        <color rgba="0.32 0.34 0.36 1" />
        </material>
      </visual>
    <visual name="tilt_cheek_1">
      <origin xyz="0.13 -0.044 0" rpy="0 0 0" />
      <geometry>
        <box size="0.075 0.014 0.12" />
        </geometry>
      <material name="hard_anodized_aluminum">
        <color rgba="0.32 0.34 0.36 1" />
        </material>
      </visual>
    <visual name="tilt_cross_pin">
      <origin xyz="0.13 0 0" rpy="1.5708 0 0" />
      <geometry>
        <cylinder radius="0.024" length="0.112" />
        </geometry>
      <material name="bearing_steel">
        <color rgba="0.72 0.74 0.76 1" />
        </material>
      </visual>
    <visual name="tilt_lock_knob_0">
      <origin xyz="0.13 0.057 0" rpy="1.5708 0 0" />
      <geometry>
        <cylinder radius="0.033" length="0.012" />
        </geometry>
      <material name="black_oxide_steel">
        <color rgba="0.055 0.06 0.065 1" />
        </material>
      </visual>
    <visual name="tilt_lock_knob_1">
      <origin xyz="0.13 -0.057 0" rpy="1.5708 0 0" />
      <geometry>
        <cylinder radius="0.033" length="0.012" />
        </geometry>
      <material name="black_oxide_steel">
        <color rgba="0.055 0.06 0.065 1" />
        </material>
      </visual>
    <collision name="pan_bushing">
      <geometry>
        <cylinder radius="0.027" length="0.088" />
        </geometry>
      </collision>
    <collision name="pan_friction_collar_top">
      <origin xyz="0 0 0.057" rpy="0 0 0" />
      <geometry>
        <cylinder radius="0.043" length="0.026" />
        </geometry>
      </collision>
    <collision name="pan_friction_collar_bottom">
      <origin xyz="0 0 -0.057" rpy="0 0 0" />
      <geometry>
        <cylinder radius="0.043" length="0.026" />
        </geometry>
      </collision>
    <collision name="tilt_yoke_bridge">
      <origin xyz="0.047 0 0" rpy="0 0 0" />
      <geometry>
        <box size="0.092 0.09 0.04" />
        </geometry>
      </collision>
    <collision name="tilt_cheek_0">
      <origin xyz="0.13 0.044 0" rpy="0 0 0" />
      <geometry>
        <box size="0.075 0.014 0.12" />
        </geometry>
      </collision>
    <collision name="tilt_cheek_1">
      <origin xyz="0.13 -0.044 0" rpy="0 0 0" />
      <geometry>
        <box size="0.075 0.014 0.12" />
        </geometry>
      </collision>
    <collision name="tilt_cross_pin">
      <origin xyz="0.13 0 0" rpy="1.5708 0 0" />
      <geometry>
        <cylinder radius="0.024" length="0.112" />
        </geometry>
      </collision>
    <collision name="tilt_lock_knob_0">
      <origin xyz="0.13 0.057 0" rpy="1.5708 0 0" />
      <geometry>
        <cylinder radius="0.033" length="0.012" />
        </geometry>
      </collision>
    <collision name="tilt_lock_knob_1">
      <origin xyz="0.13 -0.057 0" rpy="1.5708 0 0" />
      <geometry>
        <cylinder radius="0.033" length="0.012" />
        </geometry>
      </collision>
    </link>
  <link name="tilt_head">
    <inertial>
      <origin xyz="0.075 0 0" rpy="0 0 0" />
      <mass value="0.85" />
      <inertia ixx="0.00460417" ixy="0" ixz="0" iyy="0.00343542" iyz="0" izz="0.00394542" />
      </inertial>
    <visual name="tilt_trunnion">
      <origin xyz="0 0 0" rpy="1.5708 0 0" />
      <geometry>
        <cylinder radius="0.026" length="0.068" />
        </geometry>
      <material name="oilite_bronze_bushings">
        <color rgba="0.7 0.48 0.22 1" />
        </material>
      </visual>
    <visual name="trunnion_block">
      <origin xyz="0.048 0 0" rpy="0 0 0" />
      <geometry>
        <box size="0.1 0.032 0.05" />
        </geometry>
      <material name="black_oxide_steel">
        <color rgba="0.055 0.06 0.065 1" />
        </material>
      </visual>
    <visual name="mounting_plate">
      <origin xyz="0.105 0 0" rpy="0 0 0" />
      <geometry>
        <box size="0.018 0.184 0.164" />
        </geometry>
      <material name="hard_anodized_aluminum">
        <color rgba="0.32 0.34 0.36 1" />
        </material>
      </visual>
    <visual name="upper_web">
      <origin xyz="0.076 0 0.037" rpy="0 0 0" />
      <geometry>
        <box size="0.05 0.118 0.02" />
        </geometry>
      <material name="hard_anodized_aluminum">
        <color rgba="0.32 0.34 0.36 1" />
        </material>
      </visual>
    <visual name="lower_web">
      <origin xyz="0.076 0 -0.037" rpy="0 0 0" />
      <geometry>
        <box size="0.05 0.118 0.02" />
        </geometry>
      <material name="hard_anodized_aluminum">
        <color rgba="0.32 0.34 0.36 1" />
        </material>
      </visual>
    <visual name="center_cable_passage">
      <origin xyz="0.119 0 0" rpy="0 0 0" />
      <geometry>
        <box size="0.024 0.024 0.136" />
        </geometry>
      <material name="cable_passage_black">
        <color rgba="0.015 0.017 0.02 1" />
        </material>
      </visual>
    <visual name="vesa_slot_0">
      <origin xyz="0.117 0.05 0.05" rpy="0 1.5708 0" />
      <geometry>
        <cylinder radius="0.011" length="0.01" />
        </geometry>
      <material name="black_oxide_steel">
        <color rgba="0.055 0.06 0.065 1" />
        </material>
      </visual>
    <visual name="threaded_insert_0">
      <origin xyz="0.125 0.05 0.05" rpy="0 1.5708 0" />
      <geometry>
        <cylinder radius="0.0055" length="0.014" />
        </geometry>
      <material name="bearing_steel">
        <color rgba="0.72 0.74 0.76 1" />
        </material>
      </visual>
    <visual name="vesa_slot_1">
      <origin xyz="0.117 -0.05 0.05" rpy="0 1.5708 0" />
      <geometry>
        <cylinder radius="0.011" length="0.01" />
        </geometry>
      <material name="black_oxide_steel">
        <color rgba="0.055 0.06 0.065 1" />
        </material>
      </visual>
    <visual name="threaded_insert_1">
      <origin xyz="0.125 -0.05 0.05" rpy="0 1.5708 0" />
      <geometry>
        <cylinder radius="0.0055" length="0.014" />
        </geometry>
      <material name="bearing_steel">
        <color rgba="0.72 0.74 0.76 1" />
        </material>
      </visual>
    <visual name="vesa_slot_2">
      <origin xyz="0.117 0.05 -0.05" rpy="0 1.5708 0" />
      <geometry>
        <cylinder radius="0.011" length="0.01" />
        </geometry>
      <material name="black_oxide_steel">
        <color rgba="0.055 0.06 0.065 1" />
        </material>
      </visual>
    <visual name="threaded_insert_2">
      <origin xyz="0.125 0.05 -0.05" rpy="0 1.5708 0" />
      <geometry>
        <cylinder radius="0.0055" length="0.014" />
        </geometry>
      <material name="bearing_steel">
        <color rgba="0.72 0.74 0.76 1" />
        </material>
      </visual>
    <visual name="vesa_slot_3">
      <origin xyz="0.117 -0.05 -0.05" rpy="0 1.5708 0" />
      <geometry>
        <cylinder radius="0.011" length="0.01" />
        </geometry>
      <material name="black_oxide_steel">
        <color rgba="0.055 0.06 0.065 1" />
        </material>
      </visual>
    <visual name="threaded_insert_3">
      <origin xyz="0.125 -0.05 -0.05" rpy="0 1.5708 0" />
      <geometry>
        <cylinder radius="0.0055" length="0.014" />
        </geometry>
      <material name="bearing_steel">
        <color rgba="0.72 0.74 0.76 1" />
        </material>
      </visual>
    <visual name="top_access_lid">
      <origin xyz="0.118 0 0.073" rpy="0 0 0" />
      <geometry>
        <box size="0.013 0.12 0.018" />
        </geometry>
      <material name="matte_access_covers">
        <color rgba="0.15 0.16 0.17 1" />
        </material>
      </visual>
    <collision name="tilt_trunnion">
      <origin xyz="0 0 0" rpy="1.5708 0 0" />
      <geometry>
        <cylinder radius="0.026" length="0.068" />
        </geometry>
      </collision>
    <collision name="trunnion_block">
      <origin xyz="0.048 0 0" rpy="0 0 0" />
      <geometry>
        <box size="0.1 0.032 0.05" />
        </geometry>
      </collision>
    <collision name="mounting_plate">
      <origin xyz="0.105 0 0" rpy="0 0 0" />
      <geometry>
        <box size="0.018 0.184 0.164" />
        </geometry>
      </collision>
    <collision name="upper_web">
      <origin xyz="0.076 0 0.037" rpy="0 0 0" />
      <geometry>
        <box size="0.05 0.118 0.02" />
        </geometry>
      </collision>
    <collision name="lower_web">
      <origin xyz="0.076 0 -0.037" rpy="0 0 0" />
      <geometry>
        <box size="0.05 0.118 0.02" />
        </geometry>
      </collision>
    <collision name="center_cable_passage">
      <origin xyz="0.119 0 0" rpy="0 0 0" />
      <geometry>
        <box size="0.024 0.024 0.136" />
        </geometry>
      </collision>
    <collision name="vesa_slot_0">
      <origin xyz="0.117 0.05 0.05" rpy="0 1.5708 0" />
      <geometry>
        <cylinder radius="0.011" length="0.01" />
        </geometry>
      </collision>
    <collision name="threaded_insert_0">
      <origin xyz="0.125 0.05 0.05" rpy="0 1.5708 0" />
      <geometry>
        <cylinder radius="0.0055" length="0.014" />
        </geometry>
      </collision>
    <collision name="vesa_slot_1">
      <origin xyz="0.117 -0.05 0.05" rpy="0 1.5708 0" />
      <geometry>
        <cylinder radius="0.011" length="0.01" />
        </geometry>
      </collision>
    <collision name="threaded_insert_1">
      <origin xyz="0.125 -0.05 0.05" rpy="0 1.5708 0" />
      <geometry>
        <cylinder radius="0.0055" length="0.014" />
        </geometry>
      </collision>
    <collision name="vesa_slot_2">
      <origin xyz="0.117 0.05 -0.05" rpy="0 1.5708 0" />
      <geometry>
        <cylinder radius="0.011" length="0.01" />
        </geometry>
      </collision>
    <collision name="threaded_insert_2">
      <origin xyz="0.125 0.05 -0.05" rpy="0 1.5708 0" />
      <geometry>
        <cylinder radius="0.0055" length="0.014" />
        </geometry>
      </collision>
    <collision name="vesa_slot_3">
      <origin xyz="0.117 -0.05 -0.05" rpy="0 1.5708 0" />
      <geometry>
        <cylinder radius="0.011" length="0.01" />
        </geometry>
      </collision>
    <collision name="threaded_insert_3">
      <origin xyz="0.125 -0.05 -0.05" rpy="0 1.5708 0" />
      <geometry>
        <cylinder radius="0.0055" length="0.014" />
        </geometry>
      </collision>
    <collision name="top_access_lid">
      <origin xyz="0.118 0 0.073" rpy="0 0 0" />
      <geometry>
        <box size="0.013 0.12 0.018" />
        </geometry>
      </collision>
    </link>
  <joint name="wall_pan" type="continuous">
    <origin xyz="0.088 0 0.318" rpy="0 0 0" />
    <parent link="wall_bracket" />
    <child link="pan_carriage" />
    <axis xyz="0 0 1" />
    <limit effort="35" velocity="1.4" />
    <dynamics damping="0.18" friction="0.12" />
    </joint>
  <joint name="shoulder_lift" type="revolute">
    <origin xyz="0.115 0 0.135" rpy="0 0 0" />
    <parent link="pan_carriage" />
    <child link="primary_arm" />
    <axis xyz="0 -1 0" />
    <limit effort="70" velocity="0.9" lower="-0.45" upper="0.95" />
    <dynamics damping="0.55" friction="0.18" />
    </joint>
  <joint name="elbow_fold" type="revolute">
    <origin xyz="0.548 0 0" rpy="0 0 -0.593412" />
    <parent link="primary_arm" />
    <child link="secondary_arm" />
    <axis xyz="0 0 1" />
    <limit effort="55" velocity="1.2" lower="-2.25" upper="1.65" />
    <dynamics damping="0.35" friction="0.16" />
    </joint>
  <joint name="head_pan" type="revolute">
    <origin xyz="0.49 0 0" rpy="0 0 0" />
    <parent link="secondary_arm" />
    <child link="head_knuckle" />
    <axis xyz="0 0 1" />
    <limit effort="18" velocity="1.4" lower="-1.75" upper="1.75" />
    <dynamics damping="0.2" friction="0.12" />
    </joint>
  <joint name="head_tilt" type="revolute">
    <origin xyz="0.13 0 0" rpy="0 0 0" />
    <parent link="head_knuckle" />
    <child link="tilt_head" />
    <axis xyz="0 1 0" />
    <limit effort="15" velocity="1" lower="-0.75" upper="0.75" />
    <dynamics damping="0.35" friction="0.22" />
    </joint>
  </robot>
