<robot name="travel_over_ear_headphones">
  <material name="satin_black">
    <color rgba="0.018 0.019 0.021 1" />
    </material>
  <material name="matte_black">
    <color rgba="0.035 0.036 0.038 1" />
    </material>
  <material name="soft_foam">
    <color rgba="0.01 0.01 0.011 1" />
    </material>
  <material name="charcoal">
    <color rgba="0.11 0.115 0.12 1" />
    </material>
  <material name="brushed_metal">
    <color rgba="0.58 0.6 0.62 1" />
    </material>
  <material name="dark_cloth">
    <color rgba="0.02 0.021 0.024 1" />
    </material>
  <link name="band">
    <visual name="outer_headband">
      <geometry>
        <mesh filename="assets/meshes/outer_headband.obj" />
        </geometry>
      <material name="satin_black">
        <color rgba="0.018 0.019 0.021 1" />
        </material>
      </visual>
    <visual name="head_pad">
      <geometry>
        <mesh filename="assets/meshes/head_pad.obj" />
        </geometry>
      <material name="soft_foam">
        <color rgba="0.01 0.01 0.011 1" />
        </material>
      </visual>
    <visual name="sleeve_front_0">
      <origin xyz="-0.095 0.016 0.194" rpy="0 0 0" />
      <geometry>
        <box size="0.034 0.006 0.08" />
        </geometry>
      <material name="satin_black">
        <color rgba="0.018 0.019 0.021 1" />
        </material>
      </visual>
    <visual name="sleeve_rear_0">
      <origin xyz="-0.095 -0.016 0.194" rpy="0 0 0" />
      <geometry>
        <box size="0.034 0.006 0.08" />
        </geometry>
      <material name="satin_black">
        <color rgba="0.018 0.019 0.021 1" />
        </material>
      </visual>
    <visual name="sleeve_top_0">
      <origin xyz="-0.095 0 0.238" rpy="0 0 0" />
      <geometry>
        <box size="0.036 0.038 0.014" />
        </geometry>
      <material name="satin_black">
        <color rgba="0.018 0.019 0.021 1" />
        </material>
      </visual>
    <visual name="sleeve_lip_front_0">
      <origin xyz="-0.095 0.016 0.153" rpy="0 0 0" />
      <geometry>
        <box size="0.036 0.006 0.01" />
        </geometry>
      <material name="satin_black">
        <color rgba="0.018 0.019 0.021 1" />
        </material>
      </visual>
    <visual name="sleeve_lip_rear_0">
      <origin xyz="-0.095 -0.016 0.153" rpy="0 0 0" />
      <geometry>
        <box size="0.036 0.006 0.01" />
        </geometry>
      <material name="satin_black">
        <color rgba="0.018 0.019 0.021 1" />
        </material>
      </visual>
    <visual name="scale_mark_0">
      <origin xyz="-0.095 0.0205 0.205" rpy="0 0 0" />
      <geometry>
        <box size="0.02 0.003 0.006" />
        </geometry>
      <material name="brushed_metal">
        <color rgba="0.58 0.6 0.62 1" />
        </material>
      </visual>
    <visual name="sleeve_front_1">
      <origin xyz="0.095 0.016 0.194" rpy="0 0 0" />
      <geometry>
        <box size="0.034 0.006 0.08" />
        </geometry>
      <material name="satin_black">
        <color rgba="0.018 0.019 0.021 1" />
        </material>
      </visual>
    <visual name="sleeve_rear_1">
      <origin xyz="0.095 -0.016 0.194" rpy="0 0 0" />
      <geometry>
        <box size="0.034 0.006 0.08" />
        </geometry>
      <material name="satin_black">
        <color rgba="0.018 0.019 0.021 1" />
        </material>
      </visual>
    <visual name="sleeve_top_1">
      <origin xyz="0.095 0 0.238" rpy="0 0 0" />
      <geometry>
        <box size="0.036 0.038 0.014" />
        </geometry>
      <material name="satin_black">
        <color rgba="0.018 0.019 0.021 1" />
        </material>
      </visual>
    <visual name="sleeve_lip_front_1">
      <origin xyz="0.095 0.016 0.153" rpy="0 0 0" />
      <geometry>
        <box size="0.036 0.006 0.01" />
        </geometry>
      <material name="satin_black">
        <color rgba="0.018 0.019 0.021 1" />
        </material>
      </visual>
    <visual name="sleeve_lip_rear_1">
      <origin xyz="0.095 -0.016 0.153" rpy="0 0 0" />
      <geometry>
        <box size="0.036 0.006 0.01" />
        </geometry>
      <material name="satin_black">
        <color rgba="0.018 0.019 0.021 1" />
        </material>
      </visual>
    <visual name="scale_mark_1">
      <origin xyz="0.095 0.0205 0.205" rpy="0 0 0" />
      <geometry>
        <box size="0.02 0.003 0.006" />
        </geometry>
      <material name="brushed_metal">
        <color rgba="0.58 0.6 0.62 1" />
        </material>
      </visual>
    <collision name="outer_headband">
      <geometry>
        <mesh filename="assets/meshes/outer_headband.obj" />
        </geometry>
      </collision>
    <collision name="head_pad">
      <geometry>
        <mesh filename="assets/meshes/head_pad.obj" />
        </geometry>
      </collision>
    <collision name="sleeve_front_0">
      <origin xyz="-0.095 0.016 0.194" rpy="0 0 0" />
      <geometry>
        <box size="0.034 0.006 0.08" />
        </geometry>
      </collision>
    <collision name="sleeve_rear_0">
      <origin xyz="-0.095 -0.016 0.194" rpy="0 0 0" />
      <geometry>
        <box size="0.034 0.006 0.08" />
        </geometry>
      </collision>
    <collision name="sleeve_top_0">
      <origin xyz="-0.095 0 0.238" rpy="0 0 0" />
      <geometry>
        <box size="0.036 0.038 0.014" />
        </geometry>
      </collision>
    <collision name="sleeve_lip_front_0">
      <origin xyz="-0.095 0.016 0.153" rpy="0 0 0" />
      <geometry>
        <box size="0.036 0.006 0.01" />
        </geometry>
      </collision>
    <collision name="sleeve_lip_rear_0">
      <origin xyz="-0.095 -0.016 0.153" rpy="0 0 0" />
      <geometry>
        <box size="0.036 0.006 0.01" />
        </geometry>
      </collision>
    <collision name="scale_mark_0">
      <origin xyz="-0.095 0.0205 0.205" rpy="0 0 0" />
      <geometry>
        <box size="0.02 0.003 0.006" />
        </geometry>
      </collision>
    <collision name="sleeve_front_1">
      <origin xyz="0.095 0.016 0.194" rpy="0 0 0" />
      <geometry>
        <box size="0.034 0.006 0.08" />
        </geometry>
      </collision>
    <collision name="sleeve_rear_1">
      <origin xyz="0.095 -0.016 0.194" rpy="0 0 0" />
      <geometry>
        <box size="0.034 0.006 0.08" />
        </geometry>
      </collision>
    <collision name="sleeve_top_1">
      <origin xyz="0.095 0 0.238" rpy="0 0 0" />
      <geometry>
        <box size="0.036 0.038 0.014" />
        </geometry>
      </collision>
    <collision name="sleeve_lip_front_1">
      <origin xyz="0.095 0.016 0.153" rpy="0 0 0" />
      <geometry>
        <box size="0.036 0.006 0.01" />
        </geometry>
      </collision>
    <collision name="sleeve_lip_rear_1">
      <origin xyz="0.095 -0.016 0.153" rpy="0 0 0" />
      <geometry>
        <box size="0.036 0.006 0.01" />
        </geometry>
      </collision>
    <collision name="scale_mark_1">
      <origin xyz="0.095 0.0205 0.205" rpy="0 0 0" />
      <geometry>
        <box size="0.02 0.003 0.006" />
        </geometry>
      </collision>
    </link>
  <link name="extension_0">
    <visual name="slider_blade">
      <origin xyz="0 0 0.006" rpy="0 0 0" />
      <geometry>
        <box size="0.014 0.0265 0.08" />
        </geometry>
      <material name="brushed_metal">
        <color rgba="0.58 0.6 0.62 1" />
        </material>
      </visual>
    <visual name="yoke_stem">
      <origin xyz="0 0 -0.029" rpy="0 0 0" />
      <geometry>
        <box size="0.02 0.014 0.036" />
        </geometry>
      <material name="brushed_metal">
        <color rgba="0.58 0.6 0.62 1" />
        </material>
      </visual>
    <visual name="yoke_bridge">
      <origin xyz="0 0 -0.047" rpy="0 0 0" />
      <geometry>
        <box size="0.037 0.1 0.012" />
        </geometry>
      <material name="brushed_metal">
        <color rgba="0.58 0.6 0.62 1" />
        </material>
      </visual>
    <visual name="front_yoke_cheek">
      <origin xyz="0 0.046 -0.06" rpy="0 0 0" />
      <geometry>
        <box size="0.038 0.007 0.044" />
        </geometry>
      <material name="brushed_metal">
        <color rgba="0.58 0.6 0.62 1" />
        </material>
      </visual>
    <visual name="rear_yoke_cheek">
      <origin xyz="0 -0.046 -0.06" rpy="0 0 0" />
      <geometry>
        <box size="0.038 0.007 0.044" />
        </geometry>
      <material name="brushed_metal">
        <color rgba="0.58 0.6 0.62 1" />
        </material>
      </visual>
    <visual name="front_hinge_cap">
      <origin xyz="0 0.052 -0.06" rpy="1.5708 0 0" />
      <geometry>
        <cylinder radius="0.0075" length="0.008" />
        </geometry>
      <material name="charcoal">
        <color rgba="0.11 0.115 0.12 1" />
        </material>
      </visual>
    <visual name="rear_hinge_cap">
      <origin xyz="0 -0.052 -0.06" rpy="1.5708 0 0" />
      <geometry>
        <cylinder radius="0.0075" length="0.008" />
        </geometry>
      <material name="charcoal">
        <color rgba="0.11 0.115 0.12 1" />
        </material>
      </visual>
    <visual name="detent_mark_0">
      <origin xyz="0 0.0057 0.03" rpy="0 0 0" />
      <geometry>
        <box size="0.012 0.0018 0.0035" />
        </geometry>
      <material name="matte_black">
        <color rgba="0.035 0.036 0.038 1" />
        </material>
      </visual>
    <visual name="detent_mark_1">
      <origin xyz="0 0.0057 0.013" rpy="0 0 0" />
      <geometry>
        <box size="0.012 0.0018 0.0035" />
        </geometry>
      <material name="matte_black">
        <color rgba="0.035 0.036 0.038 1" />
        </material>
      </visual>
    <visual name="detent_mark_2">
      <origin xyz="0 0.0057 -0.004" rpy="0 0 0" />
      <geometry>
        <box size="0.012 0.0018 0.0035" />
        </geometry>
      <material name="matte_black">
        <color rgba="0.035 0.036 0.038 1" />
        </material>
      </visual>
    <collision name="slider_blade">
      <origin xyz="0 0 0.006" rpy="0 0 0" />
      <geometry>
        <box size="0.014 0.0265 0.08" />
        </geometry>
      </collision>
    <collision name="yoke_stem">
      <origin xyz="0 0 -0.029" rpy="0 0 0" />
      <geometry>
        <box size="0.02 0.014 0.036" />
        </geometry>
      </collision>
    <collision name="yoke_bridge">
      <origin xyz="0 0 -0.047" rpy="0 0 0" />
      <geometry>
        <box size="0.037 0.1 0.012" />
        </geometry>
      </collision>
    <collision name="front_yoke_cheek">
      <origin xyz="0 0.046 -0.06" rpy="0 0 0" />
      <geometry>
        <box size="0.038 0.007 0.044" />
        </geometry>
      </collision>
    <collision name="rear_yoke_cheek">
      <origin xyz="0 -0.046 -0.06" rpy="0 0 0" />
      <geometry>
        <box size="0.038 0.007 0.044" />
        </geometry>
      </collision>
    <collision name="front_hinge_cap">
      <origin xyz="0 0.052 -0.06" rpy="1.5708 0 0" />
      <geometry>
        <cylinder radius="0.0075" length="0.008" />
        </geometry>
      </collision>
    <collision name="rear_hinge_cap">
      <origin xyz="0 -0.052 -0.06" rpy="1.5708 0 0" />
      <geometry>
        <cylinder radius="0.0075" length="0.008" />
        </geometry>
      </collision>
    <collision name="detent_mark_0">
      <origin xyz="0 0.0057 0.03" rpy="0 0 0" />
      <geometry>
        <box size="0.012 0.0018 0.0035" />
        </geometry>
      </collision>
    <collision name="detent_mark_1">
      <origin xyz="0 0.0057 0.013" rpy="0 0 0" />
      <geometry>
        <box size="0.012 0.0018 0.0035" />
        </geometry>
      </collision>
    <collision name="detent_mark_2">
      <origin xyz="0 0.0057 -0.004" rpy="0 0 0" />
      <geometry>
        <box size="0.012 0.0018 0.0035" />
        </geometry>
      </collision>
    </link>
  <link name="earcup_0">
    <visual name="cup_shell">
      <origin xyz="0 0.004 -0.063" rpy="0 0 0" />
      <geometry>
        <mesh filename="assets/meshes/earcup_0_housing.obj" />
        </geometry>
      <material name="charcoal">
        <color rgba="0.11 0.115 0.12 1" />
        </material>
      </visual>
    <visual name="ear_cushion">
      <origin xyz="0 -0.027 -0.063" rpy="0 0 0" />
      <geometry>
        <mesh filename="assets/meshes/earcup_0_cushion.obj" />
        </geometry>
      <material name="soft_foam">
        <color rgba="0.01 0.01 0.011 1" />
        </material>
      </visual>
    <visual name="speaker_cloth">
      <origin xyz="0 -0.039 -0.063" rpy="0 0 0" />
      <geometry>
        <mesh filename="assets/meshes/earcup_0_speaker_cloth.obj" />
        </geometry>
      <material name="dark_cloth">
        <color rgba="0.02 0.021 0.024 1" />
        </material>
      </visual>
    <visual name="hinge_lug">
      <origin xyz="0 0 -0.015" rpy="0 0 0" />
      <geometry>
        <box size="0.026 0.033 0.018" />
        </geometry>
      <material name="charcoal">
        <color rgba="0.11 0.115 0.12 1" />
        </material>
      </visual>
    <visual name="hinge_barrel">
      <origin xyz="0 0 0" rpy="1.5708 0 0" />
      <geometry>
        <cylinder radius="0.0105" length="0.087" />
        </geometry>
      <material name="matte_black">
        <color rgba="0.035 0.036 0.038 1" />
        </material>
      </visual>
    <visual name="outer_trim">
      <origin xyz="0 0.021 -0.109" rpy="0 0 0" />
      <geometry>
        <box size="0.052 0.006 0.008" />
        </geometry>
      <material name="matte_black">
        <color rgba="0.035 0.036 0.038 1" />
        </material>
      </visual>
    <collision name="cup_shell">
      <origin xyz="0 0.004 -0.063" rpy="0 0 0" />
      <geometry>
        <mesh filename="assets/meshes/earcup_0_housing.obj" />
        </geometry>
      </collision>
    <collision name="ear_cushion">
      <origin xyz="0 -0.027 -0.063" rpy="0 0 0" />
      <geometry>
        <mesh filename="assets/meshes/earcup_0_cushion.obj" />
        </geometry>
      </collision>
    <collision name="speaker_cloth">
      <origin xyz="0 -0.039 -0.063" rpy="0 0 0" />
      <geometry>
        <mesh filename="assets/meshes/earcup_0_speaker_cloth.obj" />
        </geometry>
      </collision>
    <collision name="hinge_lug">
      <origin xyz="0 0 -0.015" rpy="0 0 0" />
      <geometry>
        <box size="0.026 0.033 0.018" />
        </geometry>
      </collision>
    <collision name="hinge_barrel">
      <origin xyz="0 0 0" rpy="1.5708 0 0" />
      <geometry>
        <cylinder radius="0.0105" length="0.087" />
        </geometry>
      </collision>
    <collision name="outer_trim">
      <origin xyz="0 0.021 -0.109" rpy="0 0 0" />
      <geometry>
        <box size="0.052 0.006 0.008" />
        </geometry>
      </collision>
    </link>
  <link name="extension_1">
    <visual name="slider_blade">
      <origin xyz="0 0 0.006" rpy="0 0 0" />
      <geometry>
        <box size="0.014 0.0265 0.08" />
        </geometry>
      <material name="brushed_metal">
        <color rgba="0.58 0.6 0.62 1" />
        </material>
      </visual>
    <visual name="yoke_stem">
      <origin xyz="0 0 -0.029" rpy="0 0 0" />
      <geometry>
        <box size="0.02 0.014 0.036" />
        </geometry>
      <material name="brushed_metal">
        <color rgba="0.58 0.6 0.62 1" />
        </material>
      </visual>
    <visual name="yoke_bridge">
      <origin xyz="0 0 -0.047" rpy="0 0 0" />
      <geometry>
        <box size="0.037 0.1 0.012" />
        </geometry>
      <material name="brushed_metal">
        <color rgba="0.58 0.6 0.62 1" />
        </material>
      </visual>
    <visual name="front_yoke_cheek">
      <origin xyz="0 0.046 -0.06" rpy="0 0 0" />
      <geometry>
        <box size="0.038 0.007 0.044" />
        </geometry>
      <material name="brushed_metal">
        <color rgba="0.58 0.6 0.62 1" />
        </material>
      </visual>
    <visual name="rear_yoke_cheek">
      <origin xyz="0 -0.046 -0.06" rpy="0 0 0" />
      <geometry>
        <box size="0.038 0.007 0.044" />
        </geometry>
      <material name="brushed_metal">
        <color rgba="0.58 0.6 0.62 1" />
        </material>
      </visual>
    <visual name="front_hinge_cap">
      <origin xyz="0 0.052 -0.06" rpy="1.5708 0 0" />
      <geometry>
        <cylinder radius="0.0075" length="0.008" />
        </geometry>
      <material name="charcoal">
        <color rgba="0.11 0.115 0.12 1" />
        </material>
      </visual>
    <visual name="rear_hinge_cap">
      <origin xyz="0 -0.052 -0.06" rpy="1.5708 0 0" />
      <geometry>
        <cylinder radius="0.0075" length="0.008" />
        </geometry>
      <material name="charcoal">
        <color rgba="0.11 0.115 0.12 1" />
        </material>
      </visual>
    <visual name="detent_mark_0">
      <origin xyz="0 0.0057 0.03" rpy="0 0 0" />
      <geometry>
        <box size="0.012 0.0018 0.0035" />
        </geometry>
      <material name="matte_black">
        <color rgba="0.035 0.036 0.038 1" />
        </material>
      </visual>
    <visual name="detent_mark_1">
      <origin xyz="0 0.0057 0.013" rpy="0 0 0" />
      <geometry>
        <box size="0.012 0.0018 0.0035" />
        </geometry>
      <material name="matte_black">
        <color rgba="0.035 0.036 0.038 1" />
        </material>
      </visual>
    <visual name="detent_mark_2">
      <origin xyz="0 0.0057 -0.004" rpy="0 0 0" />
      <geometry>
        <box size="0.012 0.0018 0.0035" />
        </geometry>
      <material name="matte_black">
        <color rgba="0.035 0.036 0.038 1" />
        </material>
      </visual>
    <collision name="slider_blade">
      <origin xyz="0 0 0.006" rpy="0 0 0" />
      <geometry>
        <box size="0.014 0.0265 0.08" />
        </geometry>
      </collision>
    <collision name="yoke_stem">
      <origin xyz="0 0 -0.029" rpy="0 0 0" />
      <geometry>
        <box size="0.02 0.014 0.036" />
        </geometry>
      </collision>
    <collision name="yoke_bridge">
      <origin xyz="0 0 -0.047" rpy="0 0 0" />
      <geometry>
        <box size="0.037 0.1 0.012" />
        </geometry>
      </collision>
    <collision name="front_yoke_cheek">
      <origin xyz="0 0.046 -0.06" rpy="0 0 0" />
      <geometry>
        <box size="0.038 0.007 0.044" />
        </geometry>
      </collision>
    <collision name="rear_yoke_cheek">
      <origin xyz="0 -0.046 -0.06" rpy="0 0 0" />
      <geometry>
        <box size="0.038 0.007 0.044" />
        </geometry>
      </collision>
    <collision name="front_hinge_cap">
      <origin xyz="0 0.052 -0.06" rpy="1.5708 0 0" />
      <geometry>
        <cylinder radius="0.0075" length="0.008" />
        </geometry>
      </collision>
    <collision name="rear_hinge_cap">
      <origin xyz="0 -0.052 -0.06" rpy="1.5708 0 0" />
      <geometry>
        <cylinder radius="0.0075" length="0.008" />
        </geometry>
      </collision>
    <collision name="detent_mark_0">
      <origin xyz="0 0.0057 0.03" rpy="0 0 0" />
      <geometry>
        <box size="0.012 0.0018 0.0035" />
        </geometry>
      </collision>
    <collision name="detent_mark_1">
      <origin xyz="0 0.0057 0.013" rpy="0 0 0" />
      <geometry>
        <box size="0.012 0.0018 0.0035" />
        </geometry>
      </collision>
    <collision name="detent_mark_2">
      <origin xyz="0 0.0057 -0.004" rpy="0 0 0" />
      <geometry>
        <box size="0.012 0.0018 0.0035" />
        </geometry>
      </collision>
    </link>
  <link name="earcup_1">
    <visual name="cup_shell">
      <origin xyz="0 0.004 -0.063" rpy="0 0 0" />
      <geometry>
        <mesh filename="assets/meshes/earcup_1_housing.obj" />
        </geometry>
      <material name="charcoal">
        <color rgba="0.11 0.115 0.12 1" />
        </material>
      </visual>
    <visual name="ear_cushion">
      <origin xyz="0 -0.027 -0.063" rpy="0 0 0" />
      <geometry>
        <mesh filename="assets/meshes/earcup_1_cushion.obj" />
        </geometry>
      <material name="soft_foam">
        <color rgba="0.01 0.01 0.011 1" />
        </material>
      </visual>
    <visual name="speaker_cloth">
      <origin xyz="0 -0.039 -0.063" rpy="0 0 0" />
      <geometry>
        <mesh filename="assets/meshes/earcup_1_speaker_cloth.obj" />
        </geometry>
      <material name="dark_cloth">
        <color rgba="0.02 0.021 0.024 1" />
        </material>
      </visual>
    <visual name="hinge_lug">
      <origin xyz="0 0 -0.015" rpy="0 0 0" />
      <geometry>
        <box size="0.026 0.033 0.018" />
        </geometry>
      <material name="charcoal">
        <color rgba="0.11 0.115 0.12 1" />
        </material>
      </visual>
    <visual name="hinge_barrel">
      <origin xyz="0 0 0" rpy="1.5708 0 0" />
      <geometry>
        <cylinder radius="0.0105" length="0.087" />
        </geometry>
      <material name="matte_black">
        <color rgba="0.035 0.036 0.038 1" />
        </material>
      </visual>
    <visual name="outer_trim">
      <origin xyz="0 0.021 -0.109" rpy="0 0 0" />
      <geometry>
        <box size="0.052 0.006 0.008" />
        </geometry>
      <material name="matte_black">
        <color rgba="0.035 0.036 0.038 1" />
        </material>
      </visual>
    <collision name="cup_shell">
      <origin xyz="0 0.004 -0.063" rpy="0 0 0" />
      <geometry>
        <mesh filename="assets/meshes/earcup_1_housing.obj" />
        </geometry>
      </collision>
    <collision name="ear_cushion">
      <origin xyz="0 -0.027 -0.063" rpy="0 0 0" />
      <geometry>
        <mesh filename="assets/meshes/earcup_1_cushion.obj" />
        </geometry>
      </collision>
    <collision name="speaker_cloth">
      <origin xyz="0 -0.039 -0.063" rpy="0 0 0" />
      <geometry>
        <mesh filename="assets/meshes/earcup_1_speaker_cloth.obj" />
        </geometry>
      </collision>
    <collision name="hinge_lug">
      <origin xyz="0 0 -0.015" rpy="0 0 0" />
      <geometry>
        <box size="0.026 0.033 0.018" />
        </geometry>
      </collision>
    <collision name="hinge_barrel">
      <origin xyz="0 0 0" rpy="1.5708 0 0" />
      <geometry>
        <cylinder radius="0.0105" length="0.087" />
        </geometry>
      </collision>
    <collision name="outer_trim">
      <origin xyz="0 0.021 -0.109" rpy="0 0 0" />
      <geometry>
        <box size="0.052 0.006 0.008" />
        </geometry>
      </collision>
    </link>
  <joint name="band_to_extension_0" type="prismatic">
    <origin xyz="-0.095 0 0.178" rpy="0 0 0" />
    <parent link="band" />
    <child link="extension_0" />
    <axis xyz="0 0 -1" />
    <limit effort="35" velocity="0.1" lower="0" upper="0.044" />
    </joint>
  <joint name="extension_to_earcup_0" type="revolute">
    <origin xyz="0 0 -0.06" rpy="0 0 0" />
    <parent link="extension_0" />
    <child link="earcup_0" />
    <axis xyz="0 -1 0" />
    <limit effort="8" velocity="2.4" lower="0" upper="0.7" />
    </joint>
  <joint name="band_to_extension_1" type="prismatic">
    <origin xyz="0.095 0 0.178" rpy="0 0 0" />
    <parent link="band" />
    <child link="extension_1" />
    <axis xyz="0 0 -1" />
    <limit effort="35" velocity="0.1" lower="0" upper="0.044" />
    </joint>
  <joint name="extension_to_earcup_1" type="revolute">
    <origin xyz="0 0 -0.06" rpy="0 0 0" />
    <parent link="extension_1" />
    <child link="earcup_1" />
    <axis xyz="0 1 0" />
    <limit effort="8" velocity="2.4" lower="0" upper="0.7" />
    </joint>
  </robot>
