<robot name="heavy_duty_knee_scooter">
  <material name="powder_coated_blue">
    <color rgba="0.05 0.18 0.55 1" />
    </material>
  <material name="satin_metal">
    <color rgba="0.62 0.65 0.67 1" />
    </material>
  <material name="dark_hardware">
    <color rgba="0.05 0.055 0.06 1" />
    </material>
  <material name="black_rubber">
    <color rgba="0.005 0.005 0.004 1" />
    </material>
  <material name="padded_vinyl">
    <color rgba="0.035 0.035 0.045 1" />
    </material>
  <material name="stand_safety_orange">
    <color rgba="0.95 0.43 0.06 1" />
    </material>
  <link name="frame">
    <visual name="side_rail_0">
      <origin xyz="-0.06 0.19 0.245" rpy="0 1.5708 0" />
      <geometry>
        <cylinder radius="0.018" length="0.98" />
        </geometry>
      <material name="powder_coated_blue">
        <color rgba="0.05 0.18 0.55 1" />
        </material>
      </visual>
    <visual name="rear_dropout_0">
      <origin xyz="-0.46 0.2052 0.1815" rpy="0 2.90664 1.5708" />
      <geometry>
        <cylinder radius="0.013" length="0.130588" />
        </geometry>
      <material name="satin_metal">
        <color rgba="0.62 0.65 0.67 1" />
        </material>
      </visual>
    <visual name="front_downbrace_0">
      <origin xyz="0.415 0.11495 0.265" rpy="0 1.35907 -0.938365" />
      <geometry>
        <cylinder radius="0.014" length="0.190342" />
        </geometry>
      <material name="powder_coated_blue">
        <color rgba="0.05 0.18 0.55 1" />
        </material>
      </visual>
    <visual name="side_rail_1">
      <origin xyz="-0.06 -0.19 0.245" rpy="0 1.5708 0" />
      <geometry>
        <cylinder radius="0.018" length="0.98" />
        </geometry>
      <material name="powder_coated_blue">
        <color rgba="0.05 0.18 0.55 1" />
        </material>
      </visual>
    <visual name="rear_dropout_1">
      <origin xyz="-0.46 -0.2052 0.1815" rpy="0 2.90664 -1.5708" />
      <geometry>
        <cylinder radius="0.013" length="0.130588" />
        </geometry>
      <material name="satin_metal">
        <color rgba="0.62 0.65 0.67 1" />
        </material>
      </visual>
    <visual name="front_downbrace_1">
      <origin xyz="0.415 -0.11495 0.265" rpy="0 1.35907 0.938365" />
      <geometry>
        <cylinder radius="0.014" length="0.190342" />
        </geometry>
      <material name="powder_coated_blue">
        <color rgba="0.05 0.18 0.55 1" />
        </material>
      </visual>
    <visual name="rear_cross_tube">
      <origin xyz="-0.5 0 0.245" rpy="0 1.5708 1.5708" />
      <geometry>
        <cylinder radius="0.016" length="0.38" />
        </geometry>
      <material name="powder_coated_blue">
        <color rgba="0.05 0.18 0.55 1" />
        </material>
      </visual>
    <visual name="mid_cross_tube">
      <origin xyz="-0.1 0 0.245" rpy="0 1.5708 1.5708" />
      <geometry>
        <cylinder radius="0.016" length="0.38" />
        </geometry>
      <material name="powder_coated_blue">
        <color rgba="0.05 0.18 0.55 1" />
        </material>
      </visual>
    <visual name="front_cross_tube">
      <origin xyz="0.34 0 0.245" rpy="0 1.5708 1.5708" />
      <geometry>
        <cylinder radius="0.016" length="0.38" />
        </geometry>
      <material name="powder_coated_blue">
        <color rgba="0.05 0.18 0.55 1" />
        </material>
      </visual>
    <visual name="rear_pad_cross_tube">
      <origin xyz="-0.32 0 0.245" rpy="0 1.5708 1.5708" />
      <geometry>
        <cylinder radius="0.014" length="0.38" />
        </geometry>
      <material name="powder_coated_blue">
        <color rgba="0.05 0.18 0.55 1" />
        </material>
      </visual>
    <visual name="front_pad_cross_tube">
      <origin xyz="0.05 0 0.245" rpy="0 1.5708 1.5708" />
      <geometry>
        <cylinder radius="0.014" length="0.38" />
        </geometry>
      <material name="powder_coated_blue">
        <color rgba="0.05 0.18 0.55 1" />
        </material>
      </visual>
    <visual name="rear_axle_stub_0">
      <origin xyz="-0.46 0.24 0.115" rpy="0 1.5708 1.5708" />
      <geometry>
        <cylinder radius="0.012" length="0.044" />
        </geometry>
      <material name="satin_metal">
        <color rgba="0.62 0.65 0.67 1" />
        </material>
      </visual>
    <visual name="rear_axle_stub_1">
      <origin xyz="-0.46 -0.24 0.115" rpy="0 1.5708 -1.5708" />
      <geometry>
        <cylinder radius="0.012" length="0.044" />
        </geometry>
      <material name="satin_metal">
        <color rgba="0.62 0.65 0.67 1" />
        </material>
      </visual>
    <visual name="head_socket">
      <origin xyz="0.47 0 0.275" rpy="0 0 0" />
      <geometry>
        <cylinder radius="0.035" length="0.11" />
        </geometry>
      <material name="satin_metal">
        <color rgba="0.62 0.65 0.67 1" />
        </material>
      </visual>
    <visual name="head_tube_left_gusset">
      <origin xyz="0.45 0.1155 0.28" rpy="0 1.14484 -1.30852" />
      <geometry>
        <cylinder radius="0.012" length="0.169414" />
        </geometry>
      <material name="powder_coated_blue">
        <color rgba="0.05 0.18 0.55 1" />
        </material>
      </visual>
    <visual name="head_tube_right_gusset">
      <origin xyz="0.45 -0.1155 0.28" rpy="0 1.14484 1.30852" />
      <geometry>
        <cylinder radius="0.012" length="0.169414" />
        </geometry>
      <material name="powder_coated_blue">
        <color rgba="0.05 0.18 0.55 1" />
        </material>
      </visual>
    <visual name="rear_pad_post_0">
      <origin xyz="-0.32 0.115 0.38" rpy="0 0 0" />
      <geometry>
        <cylinder radius="0.014" length="0.27" />
        </geometry>
      <material name="satin_metal">
        <color rgba="0.62 0.65 0.67 1" />
        </material>
      </visual>
    <visual name="rear_pad_post_1">
      <origin xyz="-0.32 -0.115 0.38" rpy="0 0 0" />
      <geometry>
        <cylinder radius="0.014" length="0.27" />
        </geometry>
      <material name="satin_metal">
        <color rgba="0.62 0.65 0.67 1" />
        </material>
      </visual>
    <visual name="front_pad_post_0">
      <origin xyz="0.05 0.115 0.38" rpy="0 0 0" />
      <geometry>
        <cylinder radius="0.014" length="0.27" />
        </geometry>
      <material name="satin_metal">
        <color rgba="0.62 0.65 0.67 1" />
        </material>
      </visual>
    <visual name="front_pad_post_1">
      <origin xyz="0.05 -0.115 0.38" rpy="0 0 0" />
      <geometry>
        <cylinder radius="0.014" length="0.27" />
        </geometry>
      <material name="satin_metal">
        <color rgba="0.62 0.65 0.67 1" />
        </material>
      </visual>
    <visual name="pad_support_plate">
      <origin xyz="-0.135 0 0.522" rpy="0 0 0" />
      <geometry>
        <box size="0.5 0.3 0.03" />
        </geometry>
      <material name="dark_hardware">
        <color rgba="0.05 0.055 0.06 1" />
        </material>
      </visual>
    <visual name="knee_pad">
      <origin xyz="-0.135 0 0.572" rpy="0 0 0" />
      <geometry>
        <box size="0.52 0.32 0.07" />
        </geometry>
      <material name="padded_vinyl">
        <color rgba="0.035 0.035 0.045 1" />
        </material>
      </visual>
    <visual name="stand_hinge_leaf_rear">
      <origin xyz="0.045 -0.23 0.205" rpy="0 1.5708 0" />
      <geometry>
        <cylinder radius="0.017" length="0.026" />
        </geometry>
      <material name="satin_metal">
        <color rgba="0.62 0.65 0.67 1" />
        </material>
      </visual>
    <visual name="stand_hinge_leaf_front">
      <origin xyz="0.115 -0.23 0.205" rpy="0 1.5708 0" />
      <geometry>
        <cylinder radius="0.017" length="0.026" />
        </geometry>
      <material name="satin_metal">
        <color rgba="0.62 0.65 0.67 1" />
        </material>
      </visual>
    <visual name="stand_hinge_bracket">
      <origin xyz="0.08 -0.205 0.218" rpy="0 0 0" />
      <geometry>
        <box size="0.09 0.024 0.045" />
        </geometry>
      <material name="satin_metal">
        <color rgba="0.62 0.65 0.67 1" />
        </material>
      </visual>
    <collision name="side_rail_0">
      <origin xyz="-0.06 0.19 0.245" rpy="0 1.5708 0" />
      <geometry>
        <cylinder radius="0.018" length="0.98" />
        </geometry>
      </collision>
    <collision name="rear_dropout_0">
      <origin xyz="-0.46 0.2052 0.1815" rpy="0 2.90664 1.5708" />
      <geometry>
        <cylinder radius="0.013" length="0.130588" />
        </geometry>
      </collision>
    <collision name="front_downbrace_0">
      <origin xyz="0.415 0.11495 0.265" rpy="0 1.35907 -0.938365" />
      <geometry>
        <cylinder radius="0.014" length="0.190342" />
        </geometry>
      </collision>
    <collision name="side_rail_1">
      <origin xyz="-0.06 -0.19 0.245" rpy="0 1.5708 0" />
      <geometry>
        <cylinder radius="0.018" length="0.98" />
        </geometry>
      </collision>
    <collision name="rear_dropout_1">
      <origin xyz="-0.46 -0.2052 0.1815" rpy="0 2.90664 -1.5708" />
      <geometry>
        <cylinder radius="0.013" length="0.130588" />
        </geometry>
      </collision>
    <collision name="front_downbrace_1">
      <origin xyz="0.415 -0.11495 0.265" rpy="0 1.35907 0.938365" />
      <geometry>
        <cylinder radius="0.014" length="0.190342" />
        </geometry>
      </collision>
    <collision name="rear_cross_tube">
      <origin xyz="-0.5 0 0.245" rpy="0 1.5708 1.5708" />
      <geometry>
        <cylinder radius="0.016" length="0.38" />
        </geometry>
      </collision>
    <collision name="mid_cross_tube">
      <origin xyz="-0.1 0 0.245" rpy="0 1.5708 1.5708" />
      <geometry>
        <cylinder radius="0.016" length="0.38" />
        </geometry>
      </collision>
    <collision name="front_cross_tube">
      <origin xyz="0.34 0 0.245" rpy="0 1.5708 1.5708" />
      <geometry>
        <cylinder radius="0.016" length="0.38" />
        </geometry>
      </collision>
    <collision name="rear_pad_cross_tube">
      <origin xyz="-0.32 0 0.245" rpy="0 1.5708 1.5708" />
      <geometry>
        <cylinder radius="0.014" length="0.38" />
        </geometry>
      </collision>
    <collision name="front_pad_cross_tube">
      <origin xyz="0.05 0 0.245" rpy="0 1.5708 1.5708" />
      <geometry>
        <cylinder radius="0.014" length="0.38" />
        </geometry>
      </collision>
    <collision name="rear_axle_stub_0">
      <origin xyz="-0.46 0.24 0.115" rpy="0 1.5708 1.5708" />
      <geometry>
        <cylinder radius="0.012" length="0.044" />
        </geometry>
      </collision>
    <collision name="rear_axle_stub_1">
      <origin xyz="-0.46 -0.24 0.115" rpy="0 1.5708 -1.5708" />
      <geometry>
        <cylinder radius="0.012" length="0.044" />
        </geometry>
      </collision>
    <collision name="head_socket">
      <origin xyz="0.47 0 0.275" rpy="0 0 0" />
      <geometry>
        <cylinder radius="0.035" length="0.11" />
        </geometry>
      </collision>
    <collision name="head_tube_left_gusset">
      <origin xyz="0.45 0.1155 0.28" rpy="0 1.14484 -1.30852" />
      <geometry>
        <cylinder radius="0.012" length="0.169414" />
        </geometry>
      </collision>
    <collision name="head_tube_right_gusset">
      <origin xyz="0.45 -0.1155 0.28" rpy="0 1.14484 1.30852" />
      <geometry>
        <cylinder radius="0.012" length="0.169414" />
        </geometry>
      </collision>
    <collision name="rear_pad_post_0">
      <origin xyz="-0.32 0.115 0.38" rpy="0 0 0" />
      <geometry>
        <cylinder radius="0.014" length="0.27" />
        </geometry>
      </collision>
    <collision name="rear_pad_post_1">
      <origin xyz="-0.32 -0.115 0.38" rpy="0 0 0" />
      <geometry>
        <cylinder radius="0.014" length="0.27" />
        </geometry>
      </collision>
    <collision name="front_pad_post_0">
      <origin xyz="0.05 0.115 0.38" rpy="0 0 0" />
      <geometry>
        <cylinder radius="0.014" length="0.27" />
        </geometry>
      </collision>
    <collision name="front_pad_post_1">
      <origin xyz="0.05 -0.115 0.38" rpy="0 0 0" />
      <geometry>
        <cylinder radius="0.014" length="0.27" />
        </geometry>
      </collision>
    <collision name="pad_support_plate">
      <origin xyz="-0.135 0 0.522" rpy="0 0 0" />
      <geometry>
        <box size="0.5 0.3 0.03" />
        </geometry>
      </collision>
    <collision name="knee_pad">
      <origin xyz="-0.135 0 0.572" rpy="0 0 0" />
      <geometry>
        <box size="0.52 0.32 0.07" />
        </geometry>
      </collision>
    <collision name="stand_hinge_leaf_rear">
      <origin xyz="0.045 -0.23 0.205" rpy="0 1.5708 0" />
      <geometry>
        <cylinder radius="0.017" length="0.026" />
        </geometry>
      </collision>
    <collision name="stand_hinge_leaf_front">
      <origin xyz="0.115 -0.23 0.205" rpy="0 1.5708 0" />
      <geometry>
        <cylinder radius="0.017" length="0.026" />
        </geometry>
      </collision>
    <collision name="stand_hinge_bracket">
      <origin xyz="0.08 -0.205 0.218" rpy="0 0 0" />
      <geometry>
        <box size="0.09 0.024 0.045" />
        </geometry>
      </collision>
    </link>
  <link name="steering_fork">
    <visual name="steerer_tube">
      <origin xyz="0 0 0.34" rpy="0 0 0" />
      <geometry>
        <cylinder radius="0.018" length="0.79" />
        </geometry>
      <material name="satin_metal">
        <color rgba="0.62 0.65 0.67 1" />
        </material>
      </visual>
    <visual name="lower_bearing_collar">
      <origin xyz="0 0 -0.08" rpy="0 0 0" />
      <geometry>
        <cylinder radius="0.032" length="0.05" />
        </geometry>
      <material name="dark_hardware">
        <color rgba="0.05 0.055 0.06 1" />
        </material>
      </visual>
    <visual name="handlebar">
      <origin xyz="0 0 0.72" rpy="0 1.5708 1.5708" />
      <geometry>
        <cylinder radius="0.017" length="0.6" />
        </geometry>
      <material name="satin_metal">
        <color rgba="0.62 0.65 0.67 1" />
        </material>
      </visual>
    <visual name="grip_0">
      <origin xyz="0 0.345 0.72" rpy="0 1.5708 1.5708" />
      <geometry>
        <cylinder radius="0.02" length="0.09" />
        </geometry>
      <material name="black_rubber">
        <color rgba="0.005 0.005 0.004 1" />
        </material>
      </visual>
    <visual name="grip_1">
      <origin xyz="0 -0.345 0.72" rpy="0 1.5708 -1.5708" />
      <geometry>
        <cylinder radius="0.02" length="0.09" />
        </geometry>
      <material name="black_rubber">
        <color rgba="0.005 0.005 0.004 1" />
        </material>
      </visual>
    <visual name="crown_stem_bridge">
      <origin xyz="0.045 0 -0.082" rpy="0 1.5708 0" />
      <geometry>
        <cylinder radius="0.018" length="0.09" />
        </geometry>
      <material name="powder_coated_blue">
        <color rgba="0.05 0.18 0.55 1" />
        </material>
      </visual>
    <visual name="fork_crown">
      <origin xyz="0.09 0 -0.055" rpy="0 1.5708 1.5708" />
      <geometry>
        <cylinder radius="0.018" length="0.29" />
        </geometry>
      <material name="powder_coated_blue">
        <color rgba="0.05 0.18 0.55 1" />
        </material>
      </visual>
    <visual name="fork_leg_0">
      <origin xyz="0.1025 0.135 -0.1075" rpy="0 2.90785 0" />
      <geometry>
        <cylinder radius="0.016" length="0.107935" />
        </geometry>
      <material name="powder_coated_blue">
        <color rgba="0.05 0.18 0.55 1" />
        </material>
      </visual>
    <visual name="axle_block_0">
      <origin xyz="0.115 0.135 -0.16" rpy="0 0 0" />
      <geometry>
        <box size="0.04 0.02 0.042" />
        </geometry>
      <material name="powder_coated_blue">
        <color rgba="0.05 0.18 0.55 1" />
        </material>
      </visual>
    <visual name="fork_leg_1">
      <origin xyz="0.1025 -0.135 -0.1075" rpy="0 2.90785 0" />
      <geometry>
        <cylinder radius="0.016" length="0.107935" />
        </geometry>
      <material name="powder_coated_blue">
        <color rgba="0.05 0.18 0.55 1" />
        </material>
      </visual>
    <visual name="axle_block_1">
      <origin xyz="0.115 -0.135 -0.16" rpy="0 0 0" />
      <geometry>
        <box size="0.04 0.02 0.042" />
        </geometry>
      <material name="powder_coated_blue">
        <color rgba="0.05 0.18 0.55 1" />
        </material>
      </visual>
    <visual name="fork_axle_stub_0">
      <origin xyz="0.115 0.1635 -0.16" rpy="-1.5708 0 0" />
      <geometry>
        <cylinder radius="0.011" length="0.057" />
        </geometry>
      <material name="satin_metal">
        <color rgba="0.62 0.65 0.67 1" />
        </material>
      </visual>
    <visual name="fork_axle_stub_1">
      <origin xyz="0.115 -0.1635 -0.16" rpy="1.5708 0 0" />
      <geometry>
        <cylinder radius="0.011" length="0.057" />
        </geometry>
      <material name="satin_metal">
        <color rgba="0.62 0.65 0.67 1" />
        </material>
      </visual>
    <collision name="steerer_tube">
      <origin xyz="0 0 0.34" rpy="0 0 0" />
      <geometry>
        <cylinder radius="0.018" length="0.79" />
        </geometry>
      </collision>
    <collision name="lower_bearing_collar">
      <origin xyz="0 0 -0.08" rpy="0 0 0" />
      <geometry>
        <cylinder radius="0.032" length="0.05" />
        </geometry>
      </collision>
    <collision name="handlebar">
      <origin xyz="0 0 0.72" rpy="0 1.5708 1.5708" />
      <geometry>
        <cylinder radius="0.017" length="0.6" />
        </geometry>
      </collision>
    <collision name="grip_0">
      <origin xyz="0 0.345 0.72" rpy="0 1.5708 1.5708" />
      <geometry>
        <cylinder radius="0.02" length="0.09" />
        </geometry>
      </collision>
    <collision name="grip_1">
      <origin xyz="0 -0.345 0.72" rpy="0 1.5708 -1.5708" />
      <geometry>
        <cylinder radius="0.02" length="0.09" />
        </geometry>
      </collision>
    <collision name="crown_stem_bridge">
      <origin xyz="0.045 0 -0.082" rpy="0 1.5708 0" />
      <geometry>
        <cylinder radius="0.018" length="0.09" />
        </geometry>
      </collision>
    <collision name="fork_crown">
      <origin xyz="0.09 0 -0.055" rpy="0 1.5708 1.5708" />
      <geometry>
        <cylinder radius="0.018" length="0.29" />
        </geometry>
      </collision>
    <collision name="fork_leg_0">
      <origin xyz="0.1025 0.135 -0.1075" rpy="0 2.90785 0" />
      <geometry>
        <cylinder radius="0.016" length="0.107935" />
        </geometry>
      </collision>
    <collision name="axle_block_0">
      <origin xyz="0.115 0.135 -0.16" rpy="0 0 0" />
      <geometry>
        <box size="0.04 0.02 0.042" />
        </geometry>
      </collision>
    <collision name="fork_leg_1">
      <origin xyz="0.1025 -0.135 -0.1075" rpy="0 2.90785 0" />
      <geometry>
        <cylinder radius="0.016" length="0.107935" />
        </geometry>
      </collision>
    <collision name="axle_block_1">
      <origin xyz="0.115 -0.135 -0.16" rpy="0 0 0" />
      <geometry>
        <box size="0.04 0.02 0.042" />
        </geometry>
      </collision>
    <collision name="fork_axle_stub_0">
      <origin xyz="0.115 0.1635 -0.16" rpy="-1.5708 0 0" />
      <geometry>
        <cylinder radius="0.011" length="0.057" />
        </geometry>
      </collision>
    <collision name="fork_axle_stub_1">
      <origin xyz="0.115 -0.1635 -0.16" rpy="1.5708 0 0" />
      <geometry>
        <cylinder radius="0.011" length="0.057" />
        </geometry>
      </collision>
    </link>
  <link name="front_wheel_0">
    <visual name="tire">
      <origin xyz="0 0 0" rpy="0 0 1.5708" />
      <geometry>
        <mesh filename="assets/meshes/utility_tire.obj" />
        </geometry>
      <material name="black_rubber">
        <color rgba="0.005 0.005 0.004 1" />
        </material>
      </visual>
    <visual name="rim">
      <origin xyz="0 0 0" rpy="0 0 1.5708" />
      <geometry>
        <mesh filename="assets/meshes/utility_rim.obj" />
        </geometry>
      <material name="satin_metal">
        <color rgba="0.62 0.65 0.67 1" />
        </material>
      </visual>
    <visual name="hub_cap">
      <origin xyz="0 0 0" rpy="1.5708 0 0" />
      <geometry>
        <cylinder radius="0.0253" length="0.0594" />
        </geometry>
      <material name="satin_metal">
        <color rgba="0.62 0.65 0.67 1" />
        </material>
      </visual>
    <collision name="tire">
      <origin xyz="0 0 0" rpy="0 0 1.5708" />
      <geometry>
        <mesh filename="assets/meshes/utility_tire.obj" />
        </geometry>
      </collision>
    <collision name="rim">
      <origin xyz="0 0 0" rpy="0 0 1.5708" />
      <geometry>
        <mesh filename="assets/meshes/utility_rim.obj" />
        </geometry>
      </collision>
    <collision name="hub_cap">
      <origin xyz="0 0 0" rpy="1.5708 0 0" />
      <geometry>
        <cylinder radius="0.0253" length="0.0594" />
        </geometry>
      </collision>
    </link>
  <link name="front_wheel_1">
    <visual name="tire">
      <origin xyz="0 0 0" rpy="0 0 1.5708" />
      <geometry>
        <mesh filename="assets/meshes/utility_tire.obj" />
        </geometry>
      <material name="black_rubber">
        <color rgba="0.005 0.005 0.004 1" />
        </material>
      </visual>
    <visual name="rim">
      <origin xyz="0 0 0" rpy="0 0 1.5708" />
      <geometry>
        <mesh filename="assets/meshes/utility_rim.obj" />
        </geometry>
      <material name="satin_metal">
        <color rgba="0.62 0.65 0.67 1" />
        </material>
      </visual>
    <visual name="hub_cap">
      <origin xyz="0 0 0" rpy="1.5708 0 0" />
      <geometry>
        <cylinder radius="0.0253" length="0.0594" />
        </geometry>
      <material name="satin_metal">
        <color rgba="0.62 0.65 0.67 1" />
        </material>
      </visual>
    <collision name="tire">
      <origin xyz="0 0 0" rpy="0 0 1.5708" />
      <geometry>
        <mesh filename="assets/meshes/utility_tire.obj" />
        </geometry>
      </collision>
    <collision name="rim">
      <origin xyz="0 0 0" rpy="0 0 1.5708" />
      <geometry>
        <mesh filename="assets/meshes/utility_rim.obj" />
        </geometry>
      </collision>
    <collision name="hub_cap">
      <origin xyz="0 0 0" rpy="1.5708 0 0" />
      <geometry>
        <cylinder radius="0.0253" length="0.0594" />
        </geometry>
      </collision>
    </link>
  <link name="rear_wheel_0">
    <visual name="tire">
      <origin xyz="0 0 0" rpy="0 0 1.5708" />
      <geometry>
        <mesh filename="assets/meshes/utility_tire.obj" />
        </geometry>
      <material name="black_rubber">
        <color rgba="0.005 0.005 0.004 1" />
        </material>
      </visual>
    <visual name="rim">
      <origin xyz="0 0 0" rpy="0 0 1.5708" />
      <geometry>
        <mesh filename="assets/meshes/utility_rim.obj" />
        </geometry>
      <material name="satin_metal">
        <color rgba="0.62 0.65 0.67 1" />
        </material>
      </visual>
    <visual name="hub_cap">
      <origin xyz="0 0 0" rpy="1.5708 0 0" />
      <geometry>
        <cylinder radius="0.0253" length="0.0594" />
        </geometry>
      <material name="satin_metal">
        <color rgba="0.62 0.65 0.67 1" />
        </material>
      </visual>
    <collision name="tire">
      <origin xyz="0 0 0" rpy="0 0 1.5708" />
      <geometry>
        <mesh filename="assets/meshes/utility_tire.obj" />
        </geometry>
      </collision>
    <collision name="rim">
      <origin xyz="0 0 0" rpy="0 0 1.5708" />
      <geometry>
        <mesh filename="assets/meshes/utility_rim.obj" />
        </geometry>
      </collision>
    <collision name="hub_cap">
      <origin xyz="0 0 0" rpy="1.5708 0 0" />
      <geometry>
        <cylinder radius="0.0253" length="0.0594" />
        </geometry>
      </collision>
    </link>
  <link name="rear_wheel_1">
    <visual name="tire">
      <origin xyz="0 0 0" rpy="0 0 1.5708" />
      <geometry>
        <mesh filename="assets/meshes/utility_tire.obj" />
        </geometry>
      <material name="black_rubber">
        <color rgba="0.005 0.005 0.004 1" />
        </material>
      </visual>
    <visual name="rim">
      <origin xyz="0 0 0" rpy="0 0 1.5708" />
      <geometry>
        <mesh filename="assets/meshes/utility_rim.obj" />
        </geometry>
      <material name="satin_metal">
        <color rgba="0.62 0.65 0.67 1" />
        </material>
      </visual>
    <visual name="hub_cap">
      <origin xyz="0 0 0" rpy="1.5708 0 0" />
      <geometry>
        <cylinder radius="0.0253" length="0.0594" />
        </geometry>
      <material name="satin_metal">
        <color rgba="0.62 0.65 0.67 1" />
        </material>
      </visual>
    <collision name="tire">
      <origin xyz="0 0 0" rpy="0 0 1.5708" />
      <geometry>
        <mesh filename="assets/meshes/utility_tire.obj" />
        </geometry>
      </collision>
    <collision name="rim">
      <origin xyz="0 0 0" rpy="0 0 1.5708" />
      <geometry>
        <mesh filename="assets/meshes/utility_rim.obj" />
        </geometry>
      </collision>
    <collision name="hub_cap">
      <origin xyz="0 0 0" rpy="1.5708 0 0" />
      <geometry>
        <cylinder radius="0.0253" length="0.0594" />
        </geometry>
      </collision>
    </link>
  <link name="side_stand">
    <visual name="hinge_knuckle">
      <origin xyz="0 0 0" rpy="0 1.5708 0" />
      <geometry>
        <cylinder radius="0.015" length="0.032" />
        </geometry>
      <material name="satin_metal">
        <color rgba="0.62 0.65 0.67 1" />
        </material>
      </visual>
    <visual name="stand_leg">
      <origin xyz="0.01 -0.0625 -0.1" rpy="0 2.5773 -1.41214" />
      <geometry>
        <cylinder radius="0.011" length="0.236696" />
        </geometry>
      <material name="stand_safety_orange">
        <color rgba="0.95 0.43 0.06 1" />
        </material>
      </visual>
    <visual name="stand_foot">
      <origin xyz="0.02 -0.125 -0.2" rpy="0 0 0.12" />
      <geometry>
        <box size="0.12 0.048 0.012" />
        </geometry>
      <material name="dark_hardware">
        <color rgba="0.05 0.055 0.06 1" />
        </material>
      </visual>
    <collision name="hinge_knuckle">
      <origin xyz="0 0 0" rpy="0 1.5708 0" />
      <geometry>
        <cylinder radius="0.015" length="0.032" />
        </geometry>
      </collision>
    <collision name="stand_leg">
      <origin xyz="0.01 -0.0625 -0.1" rpy="0 2.5773 -1.41214" />
      <geometry>
        <cylinder radius="0.011" length="0.236696" />
        </geometry>
      </collision>
    <collision name="stand_foot">
      <origin xyz="0.02 -0.125 -0.2" rpy="0 0 0.12" />
      <geometry>
        <box size="0.12 0.048 0.012" />
        </geometry>
      </collision>
    </link>
  <joint name="frame_to_fork" type="revolute">
    <origin xyz="0.47 0 0.275" rpy="0 0 0" />
    <parent link="frame" />
    <child link="steering_fork" />
    <axis xyz="0 0 1" />
    <limit effort="25" velocity="2.5" lower="-0.75" upper="0.75" />
    </joint>
  <joint name="fork_to_front_wheel_0" type="continuous">
    <origin xyz="0.115 0.205 -0.16" rpy="0 0 0" />
    <parent link="steering_fork" />
    <child link="front_wheel_0" />
    <axis xyz="0 1 0" />
    <limit effort="3" velocity="18" />
    </joint>
  <joint name="fork_to_front_wheel_1" type="continuous">
    <origin xyz="0.115 -0.205 -0.16" rpy="0 0 0" />
    <parent link="steering_fork" />
    <child link="front_wheel_1" />
    <axis xyz="0 1 0" />
    <limit effort="3" velocity="18" />
    </joint>
  <joint name="frame_to_rear_wheel_0" type="continuous">
    <origin xyz="-0.46 0.29 0.115" rpy="0 0 0" />
    <parent link="frame" />
    <child link="rear_wheel_0" />
    <axis xyz="0 1 0" />
    <limit effort="3" velocity="18" />
    </joint>
  <joint name="frame_to_rear_wheel_1" type="continuous">
    <origin xyz="-0.46 -0.29 0.115" rpy="0 0 0" />
    <parent link="frame" />
    <child link="rear_wheel_1" />
    <axis xyz="0 1 0" />
    <limit effort="3" velocity="18" />
    </joint>
  <joint name="frame_to_side_stand" type="revolute">
    <origin xyz="0.08 -0.23 0.205" rpy="0 0 0" />
    <parent link="frame" />
    <child link="side_stand" />
    <axis xyz="1 0 0" />
    <limit effort="8" velocity="2" lower="-1.25" upper="0" />
    </joint>
  </robot>
