<robot name="cordless_drill_press_stand">
  <material name="deep_blue_painted_steel">
    <color rgba="0.05 0.09 0.16 1" />
    </material>
  <material name="brushed_steel">
    <color rgba="0.64 0.66 0.65 1" />
    </material>
  <material name="dark_oxide_steel">
    <color rgba="0.1 0.11 0.12 1" />
    </material>
  <material name="black_plastic">
    <color rgba="0.01 0.01 0.012 1" />
    </material>
  <material name="red_quick_release">
    <color rgba="0.7 0.05 0.03 1" />
    </material>
  <material name="anodized_fence_yellow">
    <color rgba="0.86 0.62 0.12 1" />
    </material>
  <material name="oilite_bronze">
    <color rgba="0.62 0.38 0.15 1" />
    </material>
  <link name="base">
    <visual name="base_plate">
      <origin xyz="0 0 0.015" rpy="0 0 0" />
      <geometry>
        <box size="0.56 0.36 0.03" />
        </geometry>
      <material name="deep_blue_painted_steel">
        <color rgba="0.05 0.09 0.16 1" />
        </material>
      </visual>
    <visual name="steel_column">
      <origin xyz="0 0.105 0.405" rpy="0 0 0" />
      <geometry>
        <cylinder radius="0.025" length="0.75" />
        </geometry>
      <material name="brushed_steel">
        <color rgba="0.64 0.66 0.65 1" />
        </material>
      </visual>
    <visual name="column_flange">
      <origin xyz="0 0.105 0.037" rpy="0 0 0" />
      <geometry>
        <cylinder radius="0.058" length="0.014" />
        </geometry>
      <material name="dark_oxide_steel">
        <color rgba="0.1 0.11 0.12 1" />
        </material>
      </visual>
    <visual name="base_bolt_0_0">
      <origin xyz="-0.232 -0.142 0.0325" rpy="0 0 0" />
      <geometry>
        <cylinder radius="0.008" length="0.005" />
        </geometry>
      <material name="dark_oxide_steel">
        <color rgba="0.1 0.11 0.12 1" />
        </material>
      </visual>
    <visual name="base_bolt_0_1">
      <origin xyz="-0.232 0.142 0.0325" rpy="0 0 0" />
      <geometry>
        <cylinder radius="0.008" length="0.005" />
        </geometry>
      <material name="dark_oxide_steel">
        <color rgba="0.1 0.11 0.12 1" />
        </material>
      </visual>
    <visual name="base_bolt_1_0">
      <origin xyz="0.232 -0.142 0.0325" rpy="0 0 0" />
      <geometry>
        <cylinder radius="0.008" length="0.005" />
        </geometry>
      <material name="dark_oxide_steel">
        <color rgba="0.1 0.11 0.12 1" />
        </material>
      </visual>
    <visual name="base_bolt_1_1">
      <origin xyz="0.232 0.142 0.0325" rpy="0 0 0" />
      <geometry>
        <cylinder radius="0.008" length="0.005" />
        </geometry>
      <material name="dark_oxide_steel">
        <color rgba="0.1 0.11 0.12 1" />
        </material>
      </visual>
    <visual name="front_fence_rail">
      <origin xyz="0 -0.145 0.034" rpy="0 0 0" />
      <geometry>
        <box size="0.44 0.01 0.008" />
        </geometry>
      <material name="dark_oxide_steel">
        <color rgba="0.1 0.11 0.12 1" />
        </material>
      </visual>
    <visual name="rear_fence_rail">
      <origin xyz="0 -0.095 0.034" rpy="0 0 0" />
      <geometry>
        <box size="0.44 0.01 0.008" />
        </geometry>
      <material name="dark_oxide_steel">
        <color rgba="0.1 0.11 0.12 1" />
        </material>
      </visual>
    <collision name="base_plate">
      <origin xyz="0 0 0.015" rpy="0 0 0" />
      <geometry>
        <box size="0.56 0.36 0.03" />
        </geometry>
      </collision>
    <collision name="steel_column">
      <origin xyz="0 0.105 0.405" rpy="0 0 0" />
      <geometry>
        <cylinder radius="0.025" length="0.75" />
        </geometry>
      </collision>
    <collision name="column_flange">
      <origin xyz="0 0.105 0.037" rpy="0 0 0" />
      <geometry>
        <cylinder radius="0.058" length="0.014" />
        </geometry>
      </collision>
    <collision name="base_bolt_0_0">
      <origin xyz="-0.232 -0.142 0.0325" rpy="0 0 0" />
      <geometry>
        <cylinder radius="0.008" length="0.005" />
        </geometry>
      </collision>
    <collision name="base_bolt_0_1">
      <origin xyz="-0.232 0.142 0.0325" rpy="0 0 0" />
      <geometry>
        <cylinder radius="0.008" length="0.005" />
        </geometry>
      </collision>
    <collision name="base_bolt_1_0">
      <origin xyz="0.232 -0.142 0.0325" rpy="0 0 0" />
      <geometry>
        <cylinder radius="0.008" length="0.005" />
        </geometry>
      </collision>
    <collision name="base_bolt_1_1">
      <origin xyz="0.232 0.142 0.0325" rpy="0 0 0" />
      <geometry>
        <cylinder radius="0.008" length="0.005" />
        </geometry>
      </collision>
    <collision name="front_fence_rail">
      <origin xyz="0 -0.145 0.034" rpy="0 0 0" />
      <geometry>
        <box size="0.44 0.01 0.008" />
        </geometry>
      </collision>
    <collision name="rear_fence_rail">
      <origin xyz="0 -0.095 0.034" rpy="0 0 0" />
      <geometry>
        <box size="0.44 0.01 0.008" />
        </geometry>
      </collision>
    </link>
  <link name="head_carriage">
    <visual name="carriage_body">
      <geometry>
        <mesh filename="assets/meshes/carriage_body.obj" />
        </geometry>
      <material name="dark_oxide_steel">
        <color rgba="0.1 0.11 0.12 1" />
        </material>
      </visual>
    <visual name="locking_collar">
      <geometry>
        <mesh filename="assets/meshes/locking_collar.obj" />
        </geometry>
      <material name="black_plastic">
        <color rgba="0.01 0.01 0.012 1" />
        </material>
      </visual>
    <visual name="lower_bushing">
      <origin xyz="0 0 -0.056" rpy="0 0 0" />
      <geometry>
        <mesh filename="assets/meshes/lower_bushing.obj" />
        </geometry>
      <material name="oilite_bronze">
        <color rgba="0.62 0.38 0.15 1" />
        </material>
      </visual>
    <visual name="upper_bushing">
      <origin xyz="0 0 0.056" rpy="0 0 0" />
      <geometry>
        <mesh filename="assets/meshes/upper_bushing.obj" />
        </geometry>
      <material name="oilite_bronze">
        <color rgba="0.62 0.38 0.15 1" />
        </material>
      </visual>
    <collision name="carriage_body">
      <geometry>
        <mesh filename="assets/meshes/carriage_body.obj" />
        </geometry>
      </collision>
    <collision name="locking_collar">
      <geometry>
        <mesh filename="assets/meshes/locking_collar.obj" />
        </geometry>
      </collision>
    <collision name="lower_bushing">
      <origin xyz="0 0 -0.056" rpy="0 0 0" />
      <geometry>
        <mesh filename="assets/meshes/lower_bushing.obj" />
        </geometry>
      </collision>
    <collision name="upper_bushing">
      <origin xyz="0 0 0.056" rpy="0 0 0" />
      <geometry>
        <mesh filename="assets/meshes/upper_bushing.obj" />
        </geometry>
      </collision>
    </link>
  <link name="collar_knob">
    <visual name="clamp_screw">
      <origin xyz="0.025 0 0" rpy="0 1.5708 0" />
      <geometry>
        <cylinder radius="0.006" length="0.05" />
        </geometry>
      <material name="brushed_steel">
        <color rgba="0.64 0.66 0.65 1" />
        </material>
      </visual>
    <visual name="knob_cap">
      <origin xyz="0.05 0 0" rpy="0 1.5708 0" />
      <geometry>
        <mesh filename="assets/meshes/collar_knob_cap.obj" />
        </geometry>
      <material name="black_plastic">
        <color rgba="0.01 0.01 0.012 1" />
        </material>
      </visual>
    <collision name="clamp_screw">
      <origin xyz="0.025 0 0" rpy="0 1.5708 0" />
      <geometry>
        <cylinder radius="0.006" length="0.05" />
        </geometry>
      </collision>
    <collision name="knob_cap">
      <origin xyz="0.05 0 0" rpy="0 1.5708 0" />
      <geometry>
        <mesh filename="assets/meshes/collar_knob_cap.obj" />
        </geometry>
      </collision>
    </link>
  <link name="chuck">
    <visual name="spindle_shank">
      <origin xyz="0 0 -0.025" rpy="0 0 0" />
      <geometry>
        <cylinder radius="0.012" length="0.05" />
        </geometry>
      <material name="brushed_steel">
        <color rgba="0.64 0.66 0.65 1" />
        </material>
      </visual>
    <visual name="release_sleeve">
      <origin xyz="0 0 -0.05" rpy="0 0 0" />
      <geometry>
        <cylinder radius="0.024" length="0.03" />
        </geometry>
      <material name="red_quick_release">
        <color rgba="0.7 0.05 0.03 1" />
        </material>
      </visual>
    <visual name="chuck_body">
      <geometry>
        <mesh filename="assets/meshes/tapered_chuck.obj" />
        </geometry>
      <material name="brushed_steel">
        <color rgba="0.64 0.66 0.65 1" />
        </material>
      </visual>
    <visual name="jaw_socket">
      <origin xyz="0 0 -0.146" rpy="0 0 0" />
      <geometry>
        <cylinder radius="0.011" length="0.012" />
        </geometry>
      <material name="dark_oxide_steel">
        <color rgba="0.1 0.11 0.12 1" />
        </material>
      </visual>
    <visual name="jaw_0">
      <origin xyz="0.007 0 -0.157" rpy="0 -0.18 0" />
      <geometry>
        <box size="0.006 0.0035 0.034" />
        </geometry>
      <material name="dark_oxide_steel">
        <color rgba="0.1 0.11 0.12 1" />
        </material>
      </visual>
    <visual name="jaw_1">
      <origin xyz="-0.0035 0.00606218 -0.157" rpy="0.155885 0.09 2.0944" />
      <geometry>
        <box size="0.006 0.0035 0.034" />
        </geometry>
      <material name="dark_oxide_steel">
        <color rgba="0.1 0.11 0.12 1" />
        </material>
      </visual>
    <visual name="jaw_2">
      <origin xyz="-0.0035 -0.00606218 -0.157" rpy="-0.155885 0.09 4.18879" />
      <geometry>
        <box size="0.006 0.0035 0.034" />
        </geometry>
      <material name="dark_oxide_steel">
        <color rgba="0.1 0.11 0.12 1" />
        </material>
      </visual>
    <collision name="spindle_shank">
      <origin xyz="0 0 -0.025" rpy="0 0 0" />
      <geometry>
        <cylinder radius="0.012" length="0.05" />
        </geometry>
      </collision>
    <collision name="release_sleeve">
      <origin xyz="0 0 -0.05" rpy="0 0 0" />
      <geometry>
        <cylinder radius="0.024" length="0.03" />
        </geometry>
      </collision>
    <collision name="chuck_body">
      <geometry>
        <mesh filename="assets/meshes/tapered_chuck.obj" />
        </geometry>
      </collision>
    <collision name="jaw_socket">
      <origin xyz="0 0 -0.146" rpy="0 0 0" />
      <geometry>
        <cylinder radius="0.011" length="0.012" />
        </geometry>
      </collision>
    <collision name="jaw_0">
      <origin xyz="0.007 0 -0.157" rpy="0 -0.18 0" />
      <geometry>
        <box size="0.006 0.0035 0.034" />
        </geometry>
      </collision>
    <collision name="jaw_1">
      <origin xyz="-0.0035 0.00606218 -0.157" rpy="0.155885 0.09 2.0944" />
      <geometry>
        <box size="0.006 0.0035 0.034" />
        </geometry>
      </collision>
    <collision name="jaw_2">
      <origin xyz="-0.0035 -0.00606218 -0.157" rpy="-0.155885 0.09 4.18879" />
      <geometry>
        <box size="0.006 0.0035 0.034" />
        </geometry>
      </collision>
    </link>
  <link name="fence_guide">
    <visual name="slide_shoe">
      <origin xyz="0 0 0.006" rpy="0 0 0" />
      <geometry>
        <box size="0.125 0.07 0.012" />
        </geometry>
      <material name="dark_oxide_steel">
        <color rgba="0.1 0.11 0.12 1" />
        </material>
      </visual>
    <visual name="guide_plate">
      <origin xyz="0 0.03 0.0595" rpy="0 0 0" />
      <geometry>
        <box size="0.3 0.014 0.095" />
        </geometry>
      <material name="anodized_fence_yellow">
        <color rgba="0.86 0.62 0.12 1" />
        </material>
      </visual>
    <visual name="lower_rib">
      <origin xyz="0 0.017 0.019" rpy="0 0 0" />
      <geometry>
        <box size="0.28 0.012 0.018" />
        </geometry>
      <material name="anodized_fence_yellow">
        <color rgba="0.86 0.62 0.12 1" />
        </material>
      </visual>
    <collision name="slide_shoe">
      <origin xyz="0 0 0.006" rpy="0 0 0" />
      <geometry>
        <box size="0.125 0.07 0.012" />
        </geometry>
      </collision>
    <collision name="guide_plate">
      <origin xyz="0 0.03 0.0595" rpy="0 0 0" />
      <geometry>
        <box size="0.3 0.014 0.095" />
        </geometry>
      </collision>
    <collision name="lower_rib">
      <origin xyz="0 0.017 0.019" rpy="0 0 0" />
      <geometry>
        <box size="0.28 0.012 0.018" />
        </geometry>
      </collision>
    </link>
  <joint name="base_to_head_carriage" type="prismatic">
    <origin xyz="0 0.105 0.34" rpy="0 0 0" />
    <parent link="base" />
    <child link="head_carriage" />
    <axis xyz="0 0 1" />
    <limit effort="160" velocity="0.18" lower="0" upper="0.22" />
    </joint>
  <joint name="head_to_collar_knob" type="revolute">
    <origin xyz="0.092 0 0.075" rpy="0 0 0" />
    <parent link="head_carriage" />
    <child link="collar_knob" />
    <axis xyz="1 0 0" />
    <limit effort="2" velocity="8" lower="-3.14159" upper="3.14159" />
    </joint>
  <joint name="head_to_chuck" type="revolute">
    <origin xyz="0 -0.145 -0.058" rpy="0 0 0" />
    <parent link="head_carriage" />
    <child link="chuck" />
    <axis xyz="0 0 1" />
    <limit effort="12" velocity="25" lower="-3.14159" upper="3.14159" />
    </joint>
  <joint name="base_to_fence_guide" type="prismatic">
    <origin xyz="0 -0.12 0.038" rpy="0 0 0" />
    <parent link="base" />
    <child link="fence_guide" />
    <axis xyz="1 0 0" />
    <limit effort="45" velocity="0.25" lower="-0.16" upper="0.16" />
    </joint>
  </robot>
