<robot name="flush_sunroof_cassette">
  <material name="brushed_aluminium">
    <color rgba="0.72 0.74 0.73 1" />
    </material>
  <material name="dark_anodized_track">
    <color rgba="0.08 0.09 0.1 1" />
    </material>
  <material name="black_rubber_seal">
    <color rgba="0.015 0.014 0.013 1" />
    </material>
  <material name="smoked_blue_glass">
    <color rgba="0.12 0.24 0.32 0.44" />
    </material>
  <material name="black_ceramic_frit">
    <color rgba="0.01 0.012 0.014 1" />
    </material>
  <material name="hinge_stainless">
    <color rgba="0.55 0.57 0.58 1" />
    </material>
  <link name="cassette">
    <visual name="front_frame">
      <origin xyz="-0.575 0 0" rpy="0 0 0" />
      <geometry>
        <box size="0.2 0.86 0.062" />
        </geometry>
      <material name="brushed_aluminium">
        <color rgba="0.72 0.74 0.73 1" />
        </material>
      </visual>
    <visual name="rear_frame">
      <origin xyz="0.935 0 0" rpy="0 0 0" />
      <geometry>
        <box size="0.2 0.86 0.062" />
        </geometry>
      <material name="brushed_aluminium">
        <color rgba="0.72 0.74 0.73 1" />
        </material>
      </visual>
    <visual name="side_frame_0">
      <origin xyz="0.18 0.36 0" rpy="0 0 0" />
      <geometry>
        <box size="1.322 0.14 0.062" />
        </geometry>
      <material name="brushed_aluminium">
        <color rgba="0.72 0.74 0.73 1" />
        </material>
      </visual>
    <visual name="side_frame_1">
      <origin xyz="0.18 -0.36 0" rpy="0 0 0" />
      <geometry>
        <box size="1.322 0.14 0.062" />
        </geometry>
      <material name="brushed_aluminium">
        <color rgba="0.72 0.74 0.73 1" />
        </material>
      </visual>
    <visual name="side_seal_0">
      <origin xyz="0 0.3 0.034" rpy="0 0 0" />
      <geometry>
        <box size="0.97 0.026 0.006" />
        </geometry>
      <material name="black_rubber_seal">
        <color rgba="0.015 0.014 0.013 1" />
        </material>
      </visual>
    <visual name="side_seal_1">
      <origin xyz="0 -0.3 0.034" rpy="0 0 0" />
      <geometry>
        <box size="0.97 0.026 0.006" />
        </geometry>
      <material name="black_rubber_seal">
        <color rgba="0.015 0.014 0.013 1" />
        </material>
      </visual>
    <visual name="front_seal">
      <origin xyz="-0.485 0 0.034" rpy="0 0 0" />
      <geometry>
        <box size="0.028 0.632 0.006" />
        </geometry>
      <material name="black_rubber_seal">
        <color rgba="0.015 0.014 0.013 1" />
        </material>
      </visual>
    <visual name="rear_seal">
      <origin xyz="0.485 0 0.034" rpy="0 0 0" />
      <geometry>
        <box size="0.028 0.632 0.006" />
        </geometry>
      <material name="black_rubber_seal">
        <color rgba="0.015 0.014 0.013 1" />
        </material>
      </visual>
    <visual name="guide_rail_0">
      <origin xyz="0.19 0.274 -0.021" rpy="0 0 0" />
      <geometry>
        <box size="1.272 0.032 0.018" />
        </geometry>
      <material name="dark_anodized_track">
        <color rgba="0.08 0.09 0.1 1" />
        </material>
      </visual>
    <visual name="guide_rail_1">
      <origin xyz="0.19 -0.274 -0.021" rpy="0 0 0" />
      <geometry>
        <box size="1.272 0.032 0.018" />
        </geometry>
      <material name="dark_anodized_track">
        <color rgba="0.08 0.09 0.1 1" />
        </material>
      </visual>
    <visual name="center_drain_trough">
      <origin xyz="0.165 0 -0.021" rpy="0 0 0" />
      <geometry>
        <box size="1.31 0.018 0.014" />
        </geometry>
      <material name="dark_anodized_track">
        <color rgba="0.08 0.09 0.1 1" />
        </material>
      </visual>
    <collision name="front_frame">
      <origin xyz="-0.575 0 0" rpy="0 0 0" />
      <geometry>
        <box size="0.2 0.86 0.062" />
        </geometry>
      </collision>
    <collision name="rear_frame">
      <origin xyz="0.935 0 0" rpy="0 0 0" />
      <geometry>
        <box size="0.2 0.86 0.062" />
        </geometry>
      </collision>
    <collision name="side_frame_0">
      <origin xyz="0.18 0.36 0" rpy="0 0 0" />
      <geometry>
        <box size="1.322 0.14 0.062" />
        </geometry>
      </collision>
    <collision name="side_frame_1">
      <origin xyz="0.18 -0.36 0" rpy="0 0 0" />
      <geometry>
        <box size="1.322 0.14 0.062" />
        </geometry>
      </collision>
    <collision name="side_seal_0">
      <origin xyz="0 0.3 0.034" rpy="0 0 0" />
      <geometry>
        <box size="0.97 0.026 0.006" />
        </geometry>
      </collision>
    <collision name="side_seal_1">
      <origin xyz="0 -0.3 0.034" rpy="0 0 0" />
      <geometry>
        <box size="0.97 0.026 0.006" />
        </geometry>
      </collision>
    <collision name="front_seal">
      <origin xyz="-0.485 0 0.034" rpy="0 0 0" />
      <geometry>
        <box size="0.028 0.632 0.006" />
        </geometry>
      </collision>
    <collision name="rear_seal">
      <origin xyz="0.485 0 0.034" rpy="0 0 0" />
      <geometry>
        <box size="0.028 0.632 0.006" />
        </geometry>
      </collision>
    <collision name="guide_rail_0">
      <origin xyz="0.19 0.274 -0.021" rpy="0 0 0" />
      <geometry>
        <box size="1.272 0.032 0.018" />
        </geometry>
      </collision>
    <collision name="guide_rail_1">
      <origin xyz="0.19 -0.274 -0.021" rpy="0 0 0" />
      <geometry>
        <box size="1.272 0.032 0.018" />
        </geometry>
      </collision>
    <collision name="center_drain_trough">
      <origin xyz="0.165 0 -0.021" rpy="0 0 0" />
      <geometry>
        <box size="1.31 0.018 0.014" />
        </geometry>
      </collision>
    </link>
  <link name="slide_carriage">
    <visual name="hinge_pin">
      <origin xyz="-0.01 0 0.017" rpy="1.5708 0 0" />
      <geometry>
        <cylinder radius="0.01" length="0.54" />
        </geometry>
      <material name="hinge_stainless">
        <color rgba="0.55 0.57 0.58 1" />
        </material>
      </visual>
    <visual name="front_cross_tie">
      <origin xyz="0.026 0 -0.022" rpy="0 0 0" />
      <geometry>
        <box size="0.055 0.49 0.018" />
        </geometry>
      <material name="dark_anodized_track">
        <color rgba="0.08 0.09 0.1 1" />
        </material>
      </visual>
    <visual name="rear_cross_tie">
      <origin xyz="0.76 0 -0.022" rpy="0 0 0" />
      <geometry>
        <box size="0.055 0.49 0.016" />
        </geometry>
      <material name="dark_anodized_track">
        <color rgba="0.08 0.09 0.1 1" />
        </material>
      </visual>
    <visual name="guide_shoe_0">
      <origin xyz="0.39 0.245 -0.022" rpy="0 0 0" />
      <geometry>
        <box size="0.72 0.03 0.014" />
        </geometry>
      <material name="dark_anodized_track">
        <color rgba="0.08 0.09 0.1 1" />
        </material>
      </visual>
    <visual name="guide_shoe_1">
      <origin xyz="0.39 -0.245 -0.022" rpy="0 0 0" />
      <geometry>
        <box size="0.72 0.03 0.014" />
        </geometry>
      <material name="dark_anodized_track">
        <color rgba="0.08 0.09 0.1 1" />
        </material>
      </visual>
    <visual name="hinge_block_0">
      <origin xyz="0.018 0.26 -0.004" rpy="0 0 0" />
      <geometry>
        <box size="0.06 0.04 0.034" />
        </geometry>
      <material name="hinge_stainless">
        <color rgba="0.55 0.57 0.58 1" />
        </material>
      </visual>
    <visual name="hinge_block_1">
      <origin xyz="0.018 -0.26 -0.004" rpy="0 0 0" />
      <geometry>
        <box size="0.06 0.04 0.034" />
        </geometry>
      <material name="hinge_stainless">
        <color rgba="0.55 0.57 0.58 1" />
        </material>
      </visual>
    <collision name="hinge_pin">
      <origin xyz="-0.01 0 0.017" rpy="1.5708 0 0" />
      <geometry>
        <cylinder radius="0.01" length="0.54" />
        </geometry>
      </collision>
    <collision name="front_cross_tie">
      <origin xyz="0.026 0 -0.022" rpy="0 0 0" />
      <geometry>
        <box size="0.055 0.49 0.018" />
        </geometry>
      </collision>
    <collision name="rear_cross_tie">
      <origin xyz="0.76 0 -0.022" rpy="0 0 0" />
      <geometry>
        <box size="0.055 0.49 0.016" />
        </geometry>
      </collision>
    <collision name="guide_shoe_0">
      <origin xyz="0.39 0.245 -0.022" rpy="0 0 0" />
      <geometry>
        <box size="0.72 0.03 0.014" />
        </geometry>
      </collision>
    <collision name="guide_shoe_1">
      <origin xyz="0.39 -0.245 -0.022" rpy="0 0 0" />
      <geometry>
        <box size="0.72 0.03 0.014" />
        </geometry>
      </collision>
    <collision name="hinge_block_0">
      <origin xyz="0.018 0.26 -0.004" rpy="0 0 0" />
      <geometry>
        <box size="0.06 0.04 0.034" />
        </geometry>
      </collision>
    <collision name="hinge_block_1">
      <origin xyz="0.018 -0.26 -0.004" rpy="0 0 0" />
      <geometry>
        <box size="0.06 0.04 0.034" />
        </geometry>
      </collision>
    </link>
  <link name="glass_panel">
    <visual name="glass_sheet">
      <origin xyz="0.44 0 -0.008" rpy="0 0 0" />
      <geometry>
        <box size="0.808 0.448 0.014" />
        </geometry>
      <material name="smoked_blue_glass">
        <color rgba="0.12 0.24 0.32 0.44" />
        </material>
      </visual>
    <visual name="side_frit_0">
      <origin xyz="0.44 0.23 0.001" rpy="0 0 0" />
      <geometry>
        <box size="0.86 0.04 0.004" />
        </geometry>
      <material name="black_ceramic_frit">
        <color rgba="0.01 0.012 0.014 1" />
        </material>
      </visual>
    <visual name="side_frit_1">
      <origin xyz="0.44 -0.23 0.001" rpy="0 0 0" />
      <geometry>
        <box size="0.86 0.04 0.004" />
        </geometry>
      <material name="black_ceramic_frit">
        <color rgba="0.01 0.012 0.014 1" />
        </material>
      </visual>
    <visual name="front_frit">
      <origin xyz="0.023 0 0.001" rpy="0 0 0" />
      <geometry>
        <box size="0.026 0.5 0.004" />
        </geometry>
      <material name="black_ceramic_frit">
        <color rgba="0.01 0.012 0.014 1" />
        </material>
      </visual>
    <visual name="rear_frit">
      <origin xyz="0.857 0 0.001" rpy="0 0 0" />
      <geometry>
        <box size="0.026 0.5 0.004" />
        </geometry>
      <material name="black_ceramic_frit">
        <color rgba="0.01 0.012 0.014 1" />
        </material>
      </visual>
    <visual name="glass_hinge_leaf">
      <origin xyz="0.028 0 -0.02" rpy="0 0 0" />
      <geometry>
        <box size="0.035 0.47 0.01" />
        </geometry>
      <material name="hinge_stainless">
        <color rgba="0.55 0.57 0.58 1" />
        </material>
      </visual>
    <collision name="glass_sheet">
      <origin xyz="0.44 0 -0.008" rpy="0 0 0" />
      <geometry>
        <box size="0.808 0.448 0.014" />
        </geometry>
      </collision>
    <collision name="side_frit_0">
      <origin xyz="0.44 0.23 0.001" rpy="0 0 0" />
      <geometry>
        <box size="0.86 0.04 0.004" />
        </geometry>
      </collision>
    <collision name="side_frit_1">
      <origin xyz="0.44 -0.23 0.001" rpy="0 0 0" />
      <geometry>
        <box size="0.86 0.04 0.004" />
        </geometry>
      </collision>
    <collision name="front_frit">
      <origin xyz="0.023 0 0.001" rpy="0 0 0" />
      <geometry>
        <box size="0.026 0.5 0.004" />
        </geometry>
      </collision>
    <collision name="rear_frit">
      <origin xyz="0.857 0 0.001" rpy="0 0 0" />
      <geometry>
        <box size="0.026 0.5 0.004" />
        </geometry>
      </collision>
    <collision name="glass_hinge_leaf">
      <origin xyz="0.028 0 -0.02" rpy="0 0 0" />
      <geometry>
        <box size="0.035 0.47 0.01" />
        </geometry>
      </collision>
    </link>
  <joint name="rail_slide" type="prismatic">
    <origin xyz="-0.43 0 0.017" rpy="0 0 0" />
    <parent link="cassette" />
    <child link="slide_carriage" />
    <axis xyz="1 0 0" />
    <limit effort="70" velocity="0.35" lower="0" upper="0.36" />
    </joint>
  <joint name="panel_tilt" type="revolute">
    <origin xyz="-0.01 0 0.017" rpy="0 0 0" />
    <parent link="slide_carriage" />
    <child link="glass_panel" />
    <axis xyz="0 -1 0" />
    <limit effort="18" velocity="0.8" lower="0" upper="0.16" />
    </joint>
  </robot>
