<robot name="narrow_office_hand_truck">
  <material name="powder_blue">
    <color rgba="0.07 0.28 0.55 1" />
    </material>
  <material name="dark_steel">
    <color rgba="0.12 0.13 0.14 1" />
    </material>
  <material name="black_rubber">
    <color rgba="0.025 0.025 0.023 1" />
    </material>
  <material name="galvanized">
    <color rgba="0.62 0.65 0.66 1" />
    </material>
  <material name="scuffed_plate">
    <color rgba="0.45 0.46 0.43 1" />
    </material>
  <link name="frame">
    <inertial>
      <origin xyz="0.03 0 0.58" rpy="0 0 0" />
      <mass value="7" />
      <inertia ixx="0.913792" ixy="0" ixz="0" iyy="0.903058" iyz="0" izz="0.246983" />
      </inertial>
    <visual name="main_tube">
      <geometry>
        <mesh filename="assets/meshes/one_piece_tubular_back.obj" />
        </geometry>
      <material name="powder_blue">
        <color rgba="0.07 0.28 0.55 1" />
        </material>
      </visual>
    <visual name="lower_crossbar">
      <origin xyz="-0.035 0 0.31" rpy="1.5708 0 0" />
      <geometry>
        <cylinder radius="0.014" length="0.41" />
        </geometry>
      <material name="powder_blue">
        <color rgba="0.07 0.28 0.55 1" />
        </material>
      </visual>
    <visual name="middle_crossbar">
      <origin xyz="-0.025 0 0.61" rpy="1.5708 0 0" />
      <geometry>
        <cylinder radius="0.012" length="0.39" />
        </geometry>
      <material name="powder_blue">
        <color rgba="0.07 0.28 0.55 1" />
        </material>
      </visual>
    <visual name="upper_crossbar">
      <origin xyz="-0.018 0 0.875" rpy="1.5708 0 0" />
      <geometry>
        <cylinder radius="0.012" length="0.35" />
        </geometry>
      <material name="powder_blue">
        <color rgba="0.07 0.28 0.55 1" />
        </material>
      </visual>
    <visual name="brace_0">
      <geometry>
        <mesh filename="assets/meshes/left_lower_brace.obj" />
        </geometry>
      <material name="powder_blue">
        <color rgba="0.07 0.28 0.55 1" />
        </material>
      </visual>
    <visual name="brace_1">
      <geometry>
        <mesh filename="assets/meshes/right_lower_brace.obj" />
        </geometry>
      <material name="powder_blue">
        <color rgba="0.07 0.28 0.55 1" />
        </material>
      </visual>
    <visual name="toe_plate">
      <origin xyz="0.178 0 0.04" rpy="0 0 0" />
      <geometry>
        <box size="0.33 0.43 0.024" />
        </geometry>
      <material name="scuffed_plate">
        <color rgba="0.45 0.46 0.43 1" />
        </material>
      </visual>
    <visual name="upturned_lip">
      <origin xyz="0.335 0 0.073" rpy="0 0 0" />
      <geometry>
        <box size="0.02 0.43 0.045" />
        </geometry>
      <material name="scuffed_plate">
        <color rgba="0.45 0.46 0.43 1" />
        </material>
      </visual>
    <visual name="toe_plate_mount">
      <origin xyz="0.015 0 0.085" rpy="0 0 0" />
      <geometry>
        <box size="0.038 0.43 0.09" />
        </geometry>
      <material name="powder_blue">
        <color rgba="0.07 0.28 0.55 1" />
        </material>
      </visual>
    <visual name="rear_axle">
      <origin xyz="-0.185 0 0.122" rpy="1.5708 0 0" />
      <geometry>
        <cylinder radius="0.015" length="0.63" />
        </geometry>
      <material name="dark_steel">
        <color rgba="0.12 0.13 0.14 1" />
        </material>
      </visual>
    <visual name="axle_plate_0">
      <origin xyz="-0.145 -0.212 0.155" rpy="0 0 0" />
      <geometry>
        <box size="0.085 0.04 0.105" />
        </geometry>
      <material name="dark_steel">
        <color rgba="0.12 0.13 0.14 1" />
        </material>
      </visual>
    <visual name="axle_plate_1">
      <origin xyz="-0.145 0.212 0.155" rpy="0 0 0" />
      <geometry>
        <box size="0.085 0.04 0.105" />
        </geometry>
      <material name="dark_steel">
        <color rgba="0.12 0.13 0.14 1" />
        </material>
      </visual>
    <visual name="axle_stay_0">
      <geometry>
        <mesh filename="assets/meshes/left_axle_stay.obj" />
        </geometry>
      <material name="powder_blue">
        <color rgba="0.07 0.28 0.55 1" />
        </material>
      </visual>
    <visual name="axle_stay_1">
      <geometry>
        <mesh filename="assets/meshes/right_axle_stay.obj" />
        </geometry>
      <material name="powder_blue">
        <color rgba="0.07 0.28 0.55 1" />
        </material>
      </visual>
    <visual name="stand_hinge_ear_0">
      <origin xyz="-0.06 -0.168 0.25" rpy="0 0 0" />
      <geometry>
        <box size="0.045 0.02 0.06" />
        </geometry>
      <material name="dark_steel">
        <color rgba="0.12 0.13 0.14 1" />
        </material>
      </visual>
    <visual name="stand_hinge_ear_1">
      <origin xyz="-0.06 0.168 0.25" rpy="0 0 0" />
      <geometry>
        <box size="0.045 0.02 0.06" />
        </geometry>
      <material name="dark_steel">
        <color rgba="0.12 0.13 0.14 1" />
        </material>
      </visual>
    <visual name="hinge_bolt_0">
      <origin xyz="-0.06 -0.185 0.25" rpy="1.5708 0 0" />
      <geometry>
        <cylinder radius="0.012" length="0.03" />
        </geometry>
      <material name="galvanized">
        <color rgba="0.62 0.65 0.66 1" />
        </material>
      </visual>
    <visual name="hinge_bolt_1">
      <origin xyz="-0.06 0.185 0.25" rpy="1.5708 0 0" />
      <geometry>
        <cylinder radius="0.012" length="0.03" />
        </geometry>
      <material name="galvanized">
        <color rgba="0.62 0.65 0.66 1" />
        </material>
      </visual>
    <collision name="main_tube">
      <geometry>
        <mesh filename="assets/meshes/one_piece_tubular_back.obj" />
        </geometry>
      </collision>
    <collision name="lower_crossbar">
      <origin xyz="-0.035 0 0.31" rpy="1.5708 0 0" />
      <geometry>
        <cylinder radius="0.014" length="0.41" />
        </geometry>
      </collision>
    <collision name="middle_crossbar">
      <origin xyz="-0.025 0 0.61" rpy="1.5708 0 0" />
      <geometry>
        <cylinder radius="0.012" length="0.39" />
        </geometry>
      </collision>
    <collision name="upper_crossbar">
      <origin xyz="-0.018 0 0.875" rpy="1.5708 0 0" />
      <geometry>
        <cylinder radius="0.012" length="0.35" />
        </geometry>
      </collision>
    <collision name="brace_0">
      <geometry>
        <mesh filename="assets/meshes/left_lower_brace.obj" />
        </geometry>
      </collision>
    <collision name="brace_1">
      <geometry>
        <mesh filename="assets/meshes/right_lower_brace.obj" />
        </geometry>
      </collision>
    <collision name="toe_plate">
      <origin xyz="0.178 0 0.04" rpy="0 0 0" />
      <geometry>
        <box size="0.33 0.43 0.024" />
        </geometry>
      </collision>
    <collision name="upturned_lip">
      <origin xyz="0.335 0 0.073" rpy="0 0 0" />
      <geometry>
        <box size="0.02 0.43 0.045" />
        </geometry>
      </collision>
    <collision name="toe_plate_mount">
      <origin xyz="0.015 0 0.085" rpy="0 0 0" />
      <geometry>
        <box size="0.038 0.43 0.09" />
        </geometry>
      </collision>
    <collision name="rear_axle">
      <origin xyz="-0.185 0 0.122" rpy="1.5708 0 0" />
      <geometry>
        <cylinder radius="0.015" length="0.63" />
        </geometry>
      </collision>
    <collision name="axle_plate_0">
      <origin xyz="-0.145 -0.212 0.155" rpy="0 0 0" />
      <geometry>
        <box size="0.085 0.04 0.105" />
        </geometry>
      </collision>
    <collision name="axle_plate_1">
      <origin xyz="-0.145 0.212 0.155" rpy="0 0 0" />
      <geometry>
        <box size="0.085 0.04 0.105" />
        </geometry>
      </collision>
    <collision name="axle_stay_0">
      <geometry>
        <mesh filename="assets/meshes/left_axle_stay.obj" />
        </geometry>
      </collision>
    <collision name="axle_stay_1">
      <geometry>
        <mesh filename="assets/meshes/right_axle_stay.obj" />
        </geometry>
      </collision>
    <collision name="stand_hinge_ear_0">
      <origin xyz="-0.06 -0.168 0.25" rpy="0 0 0" />
      <geometry>
        <box size="0.045 0.02 0.06" />
        </geometry>
      </collision>
    <collision name="stand_hinge_ear_1">
      <origin xyz="-0.06 0.168 0.25" rpy="0 0 0" />
      <geometry>
        <box size="0.045 0.02 0.06" />
        </geometry>
      </collision>
    <collision name="hinge_bolt_0">
      <origin xyz="-0.06 -0.185 0.25" rpy="1.5708 0 0" />
      <geometry>
        <cylinder radius="0.012" length="0.03" />
        </geometry>
      </collision>
    <collision name="hinge_bolt_1">
      <origin xyz="-0.06 0.185 0.25" rpy="1.5708 0 0" />
      <geometry>
        <cylinder radius="0.012" length="0.03" />
        </geometry>
      </collision>
    </link>
  <link name="wheel_0">
    <inertial>
      <origin xyz="0 0 0" rpy="1.5708 0 0" />
      <mass value="0.75" />
      <inertia ixx="0.00267569" ixy="0" ixz="0" iyy="0.00267569" iyz="0" izz="0.00495938" />
      </inertial>
    <visual name="tire">
      <origin xyz="0 0 0" rpy="0 0 1.5708" />
      <geometry>
        <mesh filename="assets/meshes/small_utility_tire.obj" />
        </geometry>
      <material name="black_rubber">
        <color rgba="0.025 0.025 0.023 1" />
        </material>
      </visual>
    <visual name="rim">
      <origin xyz="0 0 0" rpy="0 0 1.5708" />
      <geometry>
        <mesh filename="assets/meshes/painted_small_wheel.obj" />
        </geometry>
      <material name="galvanized">
        <color rgba="0.62 0.65 0.66 1" />
        </material>
      </visual>
    <collision name="tire">
      <origin xyz="0 0 0" rpy="0 0 1.5708" />
      <geometry>
        <mesh filename="assets/meshes/small_utility_tire.obj" />
        </geometry>
      </collision>
    <collision name="rim">
      <origin xyz="0 0 0" rpy="0 0 1.5708" />
      <geometry>
        <mesh filename="assets/meshes/painted_small_wheel.obj" />
        </geometry>
      </collision>
    </link>
  <link name="wheel_1">
    <inertial>
      <origin xyz="0 0 0" rpy="1.5708 0 0" />
      <mass value="0.75" />
      <inertia ixx="0.00267569" ixy="0" ixz="0" iyy="0.00267569" iyz="0" izz="0.00495938" />
      </inertial>
    <visual name="tire">
      <origin xyz="0 0 0" rpy="0 0 1.5708" />
      <geometry>
        <mesh filename="assets/meshes/small_utility_tire.obj" />
        </geometry>
      <material name="black_rubber">
        <color rgba="0.025 0.025 0.023 1" />
        </material>
      </visual>
    <visual name="rim">
      <origin xyz="0 0 0" rpy="0 0 1.5708" />
      <geometry>
        <mesh filename="assets/meshes/painted_small_wheel.obj" />
        </geometry>
      <material name="galvanized">
        <color rgba="0.62 0.65 0.66 1" />
        </material>
      </visual>
    <collision name="tire">
      <origin xyz="0 0 0" rpy="0 0 1.5708" />
      <geometry>
        <mesh filename="assets/meshes/small_utility_tire.obj" />
        </geometry>
      </collision>
    <collision name="rim">
      <origin xyz="0 0 0" rpy="0 0 1.5708" />
      <geometry>
        <mesh filename="assets/meshes/painted_small_wheel.obj" />
        </geometry>
      </collision>
    </link>
  <link name="parking_stand">
    <inertial>
      <origin xyz="0.13 0 -0.025" rpy="0 0 0" />
      <mass value="0.6" />
      <inertia ixx="0.005365" ixy="0" ixz="0" iyy="0.00389" iyz="0" izz="0.008765" />
      </inertial>
    <visual name="hinge_sleeve">
      <origin xyz="0 0 0" rpy="1.5708 0 0" />
      <geometry>
        <cylinder radius="0.014" length="0.316" />
        </geometry>
      <material name="dark_steel">
        <color rgba="0.12 0.13 0.14 1" />
        </material>
      </visual>
    <visual name="u_leg">
      <geometry>
        <mesh filename="assets/meshes/parking_stand_u.obj" />
        </geometry>
      <material name="dark_steel">
        <color rgba="0.12 0.13 0.14 1" />
        </material>
      </visual>
    <visual name="rubber_foot">
      <origin xyz="0.246 0 -0.04" rpy="1.5708 0 0" />
      <geometry>
        <cylinder radius="0.014" length="0.31" />
        </geometry>
      <material name="black_rubber">
        <color rgba="0.025 0.025 0.023 1" />
        </material>
      </visual>
    <collision name="hinge_sleeve">
      <origin xyz="0 0 0" rpy="1.5708 0 0" />
      <geometry>
        <cylinder radius="0.014" length="0.316" />
        </geometry>
      </collision>
    <collision name="u_leg">
      <geometry>
        <mesh filename="assets/meshes/parking_stand_u.obj" />
        </geometry>
      </collision>
    <collision name="rubber_foot">
      <origin xyz="0.246 0 -0.04" rpy="1.5708 0 0" />
      <geometry>
        <cylinder radius="0.014" length="0.31" />
        </geometry>
      </collision>
    </link>
  <joint name="wheel_0_spin" type="continuous">
    <origin xyz="-0.185 -0.315 0.122" rpy="0 0 0" />
    <parent link="frame" />
    <child link="wheel_0" />
    <axis xyz="0 1 0" />
    <limit effort="6" velocity="18" />
    </joint>
  <joint name="wheel_1_spin" type="continuous">
    <origin xyz="-0.185 0.315 0.122" rpy="0 0 0" />
    <parent link="frame" />
    <child link="wheel_1" />
    <axis xyz="0 1 0" />
    <limit effort="6" velocity="18" />
    </joint>
  <joint name="stand_hinge" type="revolute">
    <origin xyz="-0.06 0 0.25" rpy="0 0 0" />
    <parent link="frame" />
    <child link="parking_stand" />
    <axis xyz="0 1 0" />
    <limit effort="8" velocity="2.5" lower="0" upper="1.25" />
    </joint>
  </robot>
