<robot name="curved_lid_display_freezer">
  <material name="warm_white_powder_coat">
    <color rgba="0.92 0.94 0.9 1" />
    </material>
  <material name="pale_blue_liner">
    <color rgba="0.78 0.9 0.95 1" />
    </material>
  <material name="brushed_aluminum">
    <color rgba="0.7 0.72 0.7 1" />
    </material>
  <material name="black_rubber">
    <color rgba="0.02 0.02 0.018 1" />
    </material>
  <material name="dark_control_glass">
    <color rgba="0.04 0.05 0.055 1" />
    </material>
  <material name="green_display">
    <color rgba="0.1 0.85 0.38 1" />
    </material>
  <material name="amber_indicator">
    <color rgba="1 0.58 0.1 1" />
    </material>
  <material name="slightly_blue_glass">
    <color rgba="0.55 0.82 1 0.38" />
    </material>
  <link name="insulated_tub">
    <visual name="recessed_plinth">
      <origin xyz="0 0 0.04" rpy="0 0 0" />
      <geometry>
        <box size="1.62 0.74 0.08" />
        </geometry>
      <material name="black_rubber">
        <color rgba="0.02 0.02 0.018 1" />
        </material>
      </visual>
    <visual name="insulated_bottom">
      <origin xyz="0 0 0.13" rpy="0 0 0" />
      <geometry>
        <box size="1.7 0.82 0.1" />
        </geometry>
      <material name="warm_white_powder_coat">
        <color rgba="0.92 0.94 0.9 1" />
        </material>
      </visual>
    <visual name="front_wall">
      <origin xyz="0 -0.375 0.495" rpy="0 0 0" />
      <geometry>
        <box size="1.7 0.07 0.63" />
        </geometry>
      <material name="warm_white_powder_coat">
        <color rgba="0.92 0.94 0.9 1" />
        </material>
      </visual>
    <visual name="rear_wall">
      <origin xyz="0 0.375 0.495" rpy="0 0 0" />
      <geometry>
        <box size="1.7 0.07 0.63" />
        </geometry>
      <material name="warm_white_powder_coat">
        <color rgba="0.92 0.94 0.9 1" />
        </material>
      </visual>
    <visual name="side_wall_0">
      <origin xyz="-0.815 0 0.495" rpy="0 0 0" />
      <geometry>
        <box size="0.07 0.82 0.63" />
        </geometry>
      <material name="warm_white_powder_coat">
        <color rgba="0.92 0.94 0.9 1" />
        </material>
      </visual>
    <visual name="side_wall_1">
      <origin xyz="0.815 0 0.495" rpy="0 0 0" />
      <geometry>
        <box size="0.07 0.82 0.63" />
        </geometry>
      <material name="warm_white_powder_coat">
        <color rgba="0.92 0.94 0.9 1" />
        </material>
      </visual>
    <visual name="well_floor_liner">
      <origin xyz="0 0 0.19" rpy="0 0 0" />
      <geometry>
        <box size="1.5 0.67 0.015" />
        </geometry>
      <material name="pale_blue_liner">
        <color rgba="0.78 0.9 0.95 1" />
        </material>
      </visual>
    <visual name="front_liner">
      <origin xyz="0 -0.333 0.475" rpy="0 0 0" />
      <geometry>
        <box size="1.5 0.014 0.56" />
        </geometry>
      <material name="pale_blue_liner">
        <color rgba="0.78 0.9 0.95 1" />
        </material>
      </visual>
    <visual name="rear_liner">
      <origin xyz="0 0.333 0.475" rpy="0 0 0" />
      <geometry>
        <box size="1.5 0.014 0.56" />
        </geometry>
      <material name="pale_blue_liner">
        <color rgba="0.78 0.9 0.95 1" />
        </material>
      </visual>
    <visual name="side_liner_0">
      <origin xyz="-0.742 0 0.475" rpy="0 0 0" />
      <geometry>
        <box size="0.014 0.62 0.56" />
        </geometry>
      <material name="pale_blue_liner">
        <color rgba="0.78 0.9 0.95 1" />
        </material>
      </visual>
    <visual name="side_liner_1">
      <origin xyz="0.742 0 0.475" rpy="0 0 0" />
      <geometry>
        <box size="0.014 0.62 0.56" />
        </geometry>
      <material name="pale_blue_liner">
        <color rgba="0.78 0.9 0.95 1" />
        </material>
      </visual>
    <visual name="front_top_frame">
      <origin xyz="0 -0.365 0.842" rpy="0 0 0" />
      <geometry>
        <box size="1.74 0.09 0.065" />
        </geometry>
      <material name="brushed_aluminum">
        <color rgba="0.7 0.72 0.7 1" />
        </material>
      </visual>
    <visual name="rear_top_frame">
      <origin xyz="0 0.365 0.842" rpy="0 0 0" />
      <geometry>
        <box size="1.74 0.09 0.065" />
        </geometry>
      <material name="brushed_aluminum">
        <color rgba="0.7 0.72 0.7 1" />
        </material>
      </visual>
    <visual name="end_top_frame_0">
      <origin xyz="-0.825 0 0.842" rpy="0 0 0" />
      <geometry>
        <box size="0.09 0.82 0.065" />
        </geometry>
      <material name="brushed_aluminum">
        <color rgba="0.7 0.72 0.7 1" />
        </material>
      </visual>
    <visual name="end_top_frame_1">
      <origin xyz="0.825 0 0.842" rpy="0 0 0" />
      <geometry>
        <box size="0.09 0.82 0.065" />
        </geometry>
      <material name="brushed_aluminum">
        <color rgba="0.7 0.72 0.7 1" />
        </material>
      </visual>
    <visual name="front_lower_track">
      <origin xyz="0 -0.337 0.876" rpy="0 0 0" />
      <geometry>
        <box size="1.6 0.025 0.016" />
        </geometry>
      <material name="black_rubber">
        <color rgba="0.02 0.02 0.018 1" />
        </material>
      </visual>
    <visual name="rear_lower_track">
      <origin xyz="0 0.337 0.876" rpy="0 0 0" />
      <geometry>
        <box size="1.6 0.025 0.016" />
        </geometry>
      <material name="black_rubber">
        <color rgba="0.02 0.02 0.018 1" />
        </material>
      </visual>
    <visual name="front_upper_rail">
      <origin xyz="0 -0.39 0.886" rpy="0 0 0" />
      <geometry>
        <box size="1.6 0.03 0.026" />
        </geometry>
      <material name="brushed_aluminum">
        <color rgba="0.7 0.72 0.7 1" />
        </material>
      </visual>
    <visual name="rear_upper_rail">
      <origin xyz="0 0.39 0.886" rpy="0 0 0" />
      <geometry>
        <box size="1.6 0.03 0.026" />
        </geometry>
      <material name="brushed_aluminum">
        <color rgba="0.7 0.72 0.7 1" />
        </material>
      </visual>
    <visual name="front_upper_track">
      <origin xyz="0 -0.39 0.904" rpy="0 0 0" />
      <geometry>
        <box size="1.6 0.024 0.01" />
        </geometry>
      <material name="black_rubber">
        <color rgba="0.02 0.02 0.018 1" />
        </material>
      </visual>
    <visual name="rear_upper_track">
      <origin xyz="0 0.39 0.904" rpy="0 0 0" />
      <geometry>
        <box size="1.6 0.024 0.01" />
        </geometry>
      <material name="black_rubber">
        <color rgba="0.02 0.02 0.018 1" />
        </material>
      </visual>
    <visual name="control_fascia">
      <origin xyz="0 -0.419 0.655" rpy="0 0 0" />
      <geometry>
        <box size="0.74 0.018 0.14" />
        </geometry>
      <material name="dark_control_glass">
        <color rgba="0.04 0.05 0.055 1" />
        </material>
      </visual>
    <visual name="temperature_display">
      <origin xyz="-0.205 -0.431 0.668" rpy="0 0 0" />
      <geometry>
        <box size="0.15 0.006 0.045" />
        </geometry>
      <material name="green_display">
        <color rgba="0.1 0.85 0.38 1" />
        </material>
      </visual>
    <visual name="power_indicator">
      <origin xyz="0.055 -0.431 0.668" rpy="0 0 0" />
      <geometry>
        <box size="0.035 0.006 0.035" />
        </geometry>
      <material name="amber_indicator">
        <color rgba="1 0.58 0.1 1" />
        </material>
      </visual>
    <visual name="label_plate_0">
      <origin xyz="0.155 -0.431 0.668" rpy="0 0 0" />
      <geometry>
        <box size="0.055 0.006 0.028" />
        </geometry>
      <material name="black_rubber">
        <color rgba="0.02 0.02 0.018 1" />
        </material>
      </visual>
    <visual name="label_plate_1">
      <origin xyz="0.235 -0.431 0.668" rpy="0 0 0" />
      <geometry>
        <box size="0.055 0.006 0.028" />
        </geometry>
      <material name="black_rubber">
        <color rgba="0.02 0.02 0.018 1" />
        </material>
      </visual>
    <visual name="trim_hinge_pin">
      <origin xyz="0 -0.433 0.306" rpy="0 1.5708 0" />
      <geometry>
        <cylinder radius="0.01" length="0.66" />
        </geometry>
      <material name="brushed_aluminum">
        <color rgba="0.7 0.72 0.7 1" />
        </material>
      </visual>
    <visual name="hinge_leaf">
      <origin xyz="0 -0.417 0.3" rpy="0 0 0" />
      <geometry>
        <box size="0.68 0.014 0.02" />
        </geometry>
      <material name="brushed_aluminum">
        <color rgba="0.7 0.72 0.7 1" />
        </material>
      </visual>
    <collision name="recessed_plinth">
      <origin xyz="0 0 0.04" rpy="0 0 0" />
      <geometry>
        <box size="1.62 0.74 0.08" />
        </geometry>
      </collision>
    <collision name="insulated_bottom">
      <origin xyz="0 0 0.13" rpy="0 0 0" />
      <geometry>
        <box size="1.7 0.82 0.1" />
        </geometry>
      </collision>
    <collision name="front_wall">
      <origin xyz="0 -0.375 0.495" rpy="0 0 0" />
      <geometry>
        <box size="1.7 0.07 0.63" />
        </geometry>
      </collision>
    <collision name="rear_wall">
      <origin xyz="0 0.375 0.495" rpy="0 0 0" />
      <geometry>
        <box size="1.7 0.07 0.63" />
        </geometry>
      </collision>
    <collision name="side_wall_0">
      <origin xyz="-0.815 0 0.495" rpy="0 0 0" />
      <geometry>
        <box size="0.07 0.82 0.63" />
        </geometry>
      </collision>
    <collision name="side_wall_1">
      <origin xyz="0.815 0 0.495" rpy="0 0 0" />
      <geometry>
        <box size="0.07 0.82 0.63" />
        </geometry>
      </collision>
    <collision name="well_floor_liner">
      <origin xyz="0 0 0.19" rpy="0 0 0" />
      <geometry>
        <box size="1.5 0.67 0.015" />
        </geometry>
      </collision>
    <collision name="front_liner">
      <origin xyz="0 -0.333 0.475" rpy="0 0 0" />
      <geometry>
        <box size="1.5 0.014 0.56" />
        </geometry>
      </collision>
    <collision name="rear_liner">
      <origin xyz="0 0.333 0.475" rpy="0 0 0" />
      <geometry>
        <box size="1.5 0.014 0.56" />
        </geometry>
      </collision>
    <collision name="side_liner_0">
      <origin xyz="-0.742 0 0.475" rpy="0 0 0" />
      <geometry>
        <box size="0.014 0.62 0.56" />
        </geometry>
      </collision>
    <collision name="side_liner_1">
      <origin xyz="0.742 0 0.475" rpy="0 0 0" />
      <geometry>
        <box size="0.014 0.62 0.56" />
        </geometry>
      </collision>
    <collision name="front_top_frame">
      <origin xyz="0 -0.365 0.842" rpy="0 0 0" />
      <geometry>
        <box size="1.74 0.09 0.065" />
        </geometry>
      </collision>
    <collision name="rear_top_frame">
      <origin xyz="0 0.365 0.842" rpy="0 0 0" />
      <geometry>
        <box size="1.74 0.09 0.065" />
        </geometry>
      </collision>
    <collision name="end_top_frame_0">
      <origin xyz="-0.825 0 0.842" rpy="0 0 0" />
      <geometry>
        <box size="0.09 0.82 0.065" />
        </geometry>
      </collision>
    <collision name="end_top_frame_1">
      <origin xyz="0.825 0 0.842" rpy="0 0 0" />
      <geometry>
        <box size="0.09 0.82 0.065" />
        </geometry>
      </collision>
    <collision name="front_lower_track">
      <origin xyz="0 -0.337 0.876" rpy="0 0 0" />
      <geometry>
        <box size="1.6 0.025 0.016" />
        </geometry>
      </collision>
    <collision name="rear_lower_track">
      <origin xyz="0 0.337 0.876" rpy="0 0 0" />
      <geometry>
        <box size="1.6 0.025 0.016" />
        </geometry>
      </collision>
    <collision name="front_upper_rail">
      <origin xyz="0 -0.39 0.886" rpy="0 0 0" />
      <geometry>
        <box size="1.6 0.03 0.026" />
        </geometry>
      </collision>
    <collision name="rear_upper_rail">
      <origin xyz="0 0.39 0.886" rpy="0 0 0" />
      <geometry>
        <box size="1.6 0.03 0.026" />
        </geometry>
      </collision>
    <collision name="front_upper_track">
      <origin xyz="0 -0.39 0.904" rpy="0 0 0" />
      <geometry>
        <box size="1.6 0.024 0.01" />
        </geometry>
      </collision>
    <collision name="rear_upper_track">
      <origin xyz="0 0.39 0.904" rpy="0 0 0" />
      <geometry>
        <box size="1.6 0.024 0.01" />
        </geometry>
      </collision>
    <collision name="control_fascia">
      <origin xyz="0 -0.419 0.655" rpy="0 0 0" />
      <geometry>
        <box size="0.74 0.018 0.14" />
        </geometry>
      </collision>
    <collision name="temperature_display">
      <origin xyz="-0.205 -0.431 0.668" rpy="0 0 0" />
      <geometry>
        <box size="0.15 0.006 0.045" />
        </geometry>
      </collision>
    <collision name="power_indicator">
      <origin xyz="0.055 -0.431 0.668" rpy="0 0 0" />
      <geometry>
        <box size="0.035 0.006 0.035" />
        </geometry>
      </collision>
    <collision name="label_plate_0">
      <origin xyz="0.155 -0.431 0.668" rpy="0 0 0" />
      <geometry>
        <box size="0.055 0.006 0.028" />
        </geometry>
      </collision>
    <collision name="label_plate_1">
      <origin xyz="0.235 -0.431 0.668" rpy="0 0 0" />
      <geometry>
        <box size="0.055 0.006 0.028" />
        </geometry>
      </collision>
    <collision name="trim_hinge_pin">
      <origin xyz="0 -0.433 0.306" rpy="0 1.5708 0" />
      <geometry>
        <cylinder radius="0.01" length="0.66" />
        </geometry>
      </collision>
    <collision name="hinge_leaf">
      <origin xyz="0 -0.417 0.3" rpy="0 0 0" />
      <geometry>
        <box size="0.68 0.014 0.02" />
        </geometry>
      </collision>
    </link>
  <link name="front_lid">
    <visual name="curved_glass">
      <geometry>
        <mesh filename="assets/meshes/front_lid_curved_glass.obj" />
        </geometry>
      <material name="slightly_blue_glass">
        <color rgba="0.55 0.82 1 0.38" />
        </material>
      </visual>
    <visual name="front_runner">
      <origin xyz="0 -0.337 0.013" rpy="0 0 0" />
      <geometry>
        <box size="0.82 0.024 0.026" />
        </geometry>
      <material name="brushed_aluminum">
        <color rgba="0.7 0.72 0.7 1" />
        </material>
      </visual>
    <visual name="rear_runner">
      <origin xyz="0 0.337 0.013" rpy="0 0 0" />
      <geometry>
        <box size="0.82 0.024 0.026" />
        </geometry>
      <material name="brushed_aluminum">
        <color rgba="0.7 0.72 0.7 1" />
        </material>
      </visual>
    <visual name="end_frame_0">
      <origin xyz="-0.41 0 0.06" rpy="0 0 0" />
      <geometry>
        <box size="0.028 0.704 0.06" />
        </geometry>
      <material name="brushed_aluminum">
        <color rgba="0.7 0.72 0.7 1" />
        </material>
      </visual>
    <visual name="end_frame_1">
      <origin xyz="0.41 0 0.06" rpy="0 0 0" />
      <geometry>
        <box size="0.028 0.704 0.06" />
        </geometry>
      <material name="brushed_aluminum">
        <color rgba="0.7 0.72 0.7 1" />
        </material>
      </visual>
    <visual name="pull_grip">
      <origin xyz="0.388 0 0.086" rpy="0 0 0" />
      <geometry>
        <box size="0.035 0.38 0.042" />
        </geometry>
      <material name="black_rubber">
        <color rgba="0.02 0.02 0.018 1" />
        </material>
      </visual>
    <visual name="edge_gasket">
      <origin xyz="0.404 0 0.055" rpy="0 0 0" />
      <geometry>
        <box size="0.018 0.709 0.03" />
        </geometry>
      <material name="black_rubber">
        <color rgba="0.02 0.02 0.018 1" />
        </material>
      </visual>
    <collision name="curved_glass">
      <geometry>
        <mesh filename="assets/meshes/front_lid_curved_glass.obj" />
        </geometry>
      </collision>
    <collision name="front_runner">
      <origin xyz="0 -0.337 0.013" rpy="0 0 0" />
      <geometry>
        <box size="0.82 0.024 0.026" />
        </geometry>
      </collision>
    <collision name="rear_runner">
      <origin xyz="0 0.337 0.013" rpy="0 0 0" />
      <geometry>
        <box size="0.82 0.024 0.026" />
        </geometry>
      </collision>
    <collision name="end_frame_0">
      <origin xyz="-0.41 0 0.06" rpy="0 0 0" />
      <geometry>
        <box size="0.028 0.704 0.06" />
        </geometry>
      </collision>
    <collision name="end_frame_1">
      <origin xyz="0.41 0 0.06" rpy="0 0 0" />
      <geometry>
        <box size="0.028 0.704 0.06" />
        </geometry>
      </collision>
    <collision name="pull_grip">
      <origin xyz="0.388 0 0.086" rpy="0 0 0" />
      <geometry>
        <box size="0.035 0.38 0.042" />
        </geometry>
      </collision>
    <collision name="edge_gasket">
      <origin xyz="0.404 0 0.055" rpy="0 0 0" />
      <geometry>
        <box size="0.018 0.709 0.03" />
        </geometry>
      </collision>
    </link>
  <link name="rear_lid">
    <visual name="curved_glass">
      <geometry>
        <mesh filename="assets/meshes/rear_lid_curved_glass.obj" />
        </geometry>
      <material name="slightly_blue_glass">
        <color rgba="0.55 0.82 1 0.38" />
        </material>
      </visual>
    <visual name="front_runner">
      <origin xyz="0 -0.39 0.013" rpy="0 0 0" />
      <geometry>
        <box size="0.82 0.024 0.026" />
        </geometry>
      <material name="brushed_aluminum">
        <color rgba="0.7 0.72 0.7 1" />
        </material>
      </visual>
    <visual name="rear_runner">
      <origin xyz="0 0.39 0.013" rpy="0 0 0" />
      <geometry>
        <box size="0.82 0.024 0.026" />
        </geometry>
      <material name="brushed_aluminum">
        <color rgba="0.7 0.72 0.7 1" />
        </material>
      </visual>
    <visual name="end_frame_0">
      <origin xyz="-0.41 0 0.06" rpy="0 0 0" />
      <geometry>
        <box size="0.028 0.81 0.06" />
        </geometry>
      <material name="brushed_aluminum">
        <color rgba="0.7 0.72 0.7 1" />
        </material>
      </visual>
    <visual name="end_frame_1">
      <origin xyz="0.41 0 0.06" rpy="0 0 0" />
      <geometry>
        <box size="0.028 0.81 0.06" />
        </geometry>
      <material name="brushed_aluminum">
        <color rgba="0.7 0.72 0.7 1" />
        </material>
      </visual>
    <visual name="pull_grip">
      <origin xyz="-0.388 0 0.086" rpy="0 0 0" />
      <geometry>
        <box size="0.035 0.38 0.042" />
        </geometry>
      <material name="black_rubber">
        <color rgba="0.02 0.02 0.018 1" />
        </material>
      </visual>
    <visual name="edge_gasket">
      <origin xyz="-0.404 0 0.055" rpy="0 0 0" />
      <geometry>
        <box size="0.018 0.815 0.03" />
        </geometry>
      <material name="black_rubber">
        <color rgba="0.02 0.02 0.018 1" />
        </material>
      </visual>
    <visual name="front_track_shoe">
      <origin xyz="0 -0.39 -0.043" rpy="0 0 0" />
      <geometry>
        <box size="0.82 0.024 0.086" />
        </geometry>
      <material name="brushed_aluminum">
        <color rgba="0.7 0.72 0.7 1" />
        </material>
      </visual>
    <visual name="rear_track_shoe">
      <origin xyz="0 0.39 -0.043" rpy="0 0 0" />
      <geometry>
        <box size="0.82 0.024 0.086" />
        </geometry>
      <material name="brushed_aluminum">
        <color rgba="0.7 0.72 0.7 1" />
        </material>
      </visual>
    <collision name="curved_glass">
      <geometry>
        <mesh filename="assets/meshes/rear_lid_curved_glass.obj" />
        </geometry>
      </collision>
    <collision name="front_runner">
      <origin xyz="0 -0.39 0.013" rpy="0 0 0" />
      <geometry>
        <box size="0.82 0.024 0.026" />
        </geometry>
      </collision>
    <collision name="rear_runner">
      <origin xyz="0 0.39 0.013" rpy="0 0 0" />
      <geometry>
        <box size="0.82 0.024 0.026" />
        </geometry>
      </collision>
    <collision name="end_frame_0">
      <origin xyz="-0.41 0 0.06" rpy="0 0 0" />
      <geometry>
        <box size="0.028 0.81 0.06" />
        </geometry>
      </collision>
    <collision name="end_frame_1">
      <origin xyz="0.41 0 0.06" rpy="0 0 0" />
      <geometry>
        <box size="0.028 0.81 0.06" />
        </geometry>
      </collision>
    <collision name="pull_grip">
      <origin xyz="-0.388 0 0.086" rpy="0 0 0" />
      <geometry>
        <box size="0.035 0.38 0.042" />
        </geometry>
      </collision>
    <collision name="edge_gasket">
      <origin xyz="-0.404 0 0.055" rpy="0 0 0" />
      <geometry>
        <box size="0.018 0.815 0.03" />
        </geometry>
      </collision>
    <collision name="front_track_shoe">
      <origin xyz="0 -0.39 -0.043" rpy="0 0 0" />
      <geometry>
        <box size="0.82 0.024 0.086" />
        </geometry>
      </collision>
    <collision name="rear_track_shoe">
      <origin xyz="0 0.39 -0.043" rpy="0 0 0" />
      <geometry>
        <box size="0.82 0.024 0.086" />
        </geometry>
      </collision>
    </link>
  <link name="trim_panel">
    <visual name="panel_face">
      <origin xyz="0 -0.014 0.128" rpy="0 0 0" />
      <geometry>
        <box size="0.62 0.028 0.255" />
        </geometry>
      <material name="warm_white_powder_coat">
        <color rgba="0.92 0.94 0.9 1" />
        </material>
      </visual>
    <visual name="lower_hinge_lip">
      <origin xyz="0 -0.027 0.013" rpy="0 0 0" />
      <geometry>
        <box size="0.62 0.026 0.026" />
        </geometry>
      <material name="brushed_aluminum">
        <color rgba="0.7 0.72 0.7 1" />
        </material>
      </visual>
    <visual name="vent_recess">
      <origin xyz="0 -0.031 0.132" rpy="0 0 0" />
      <geometry>
        <box size="0.5 0.006 0.09" />
        </geometry>
      <material name="dark_control_glass">
        <color rgba="0.04 0.05 0.055 1" />
        </material>
      </visual>
    <visual name="vent_slat_0">
      <origin xyz="0 -0.035 0.105" rpy="0 0 0" />
      <geometry>
        <box size="0.45 0.006 0.008" />
        </geometry>
      <material name="brushed_aluminum">
        <color rgba="0.7 0.72 0.7 1" />
        </material>
      </visual>
    <visual name="vent_slat_1">
      <origin xyz="0 -0.035 0.132" rpy="0 0 0" />
      <geometry>
        <box size="0.45 0.006 0.008" />
        </geometry>
      <material name="brushed_aluminum">
        <color rgba="0.7 0.72 0.7 1" />
        </material>
      </visual>
    <visual name="vent_slat_2">
      <origin xyz="0 -0.035 0.159" rpy="0 0 0" />
      <geometry>
        <box size="0.45 0.006 0.008" />
        </geometry>
      <material name="brushed_aluminum">
        <color rgba="0.7 0.72 0.7 1" />
        </material>
      </visual>
    <collision name="panel_face">
      <origin xyz="0 -0.014 0.128" rpy="0 0 0" />
      <geometry>
        <box size="0.62 0.028 0.255" />
        </geometry>
      </collision>
    <collision name="lower_hinge_lip">
      <origin xyz="0 -0.027 0.013" rpy="0 0 0" />
      <geometry>
        <box size="0.62 0.026 0.026" />
        </geometry>
      </collision>
    <collision name="vent_recess">
      <origin xyz="0 -0.031 0.132" rpy="0 0 0" />
      <geometry>
        <box size="0.5 0.006 0.09" />
        </geometry>
      </collision>
    <collision name="vent_slat_0">
      <origin xyz="0 -0.035 0.105" rpy="0 0 0" />
      <geometry>
        <box size="0.45 0.006 0.008" />
        </geometry>
      </collision>
    <collision name="vent_slat_1">
      <origin xyz="0 -0.035 0.132" rpy="0 0 0" />
      <geometry>
        <box size="0.45 0.006 0.008" />
        </geometry>
      </collision>
    <collision name="vent_slat_2">
      <origin xyz="0 -0.035 0.159" rpy="0 0 0" />
      <geometry>
        <box size="0.45 0.006 0.008" />
        </geometry>
      </collision>
    </link>
  <joint name="front_lid_slide" type="prismatic">
    <origin xyz="-0.43 0 0.884" rpy="0 0 0" />
    <parent link="insulated_tub" />
    <child link="front_lid" />
    <axis xyz="1 0 0" />
    <limit effort="70" velocity="0.35" lower="0" upper="0.36" />
    </joint>
  <joint name="rear_lid_slide" type="prismatic">
    <origin xyz="0.43 0 0.995" rpy="0 0 0" />
    <parent link="insulated_tub" />
    <child link="rear_lid" />
    <axis xyz="-1 0 0" />
    <limit effort="70" velocity="0.35" lower="0" upper="0.36" />
    </joint>
  <joint name="trim_panel_hinge" type="revolute">
    <origin xyz="0 -0.41 0.315" rpy="0 0 0" />
    <parent link="insulated_tub" />
    <child link="trim_panel" />
    <axis xyz="1 0 0" />
    <limit effort="8" velocity="1.2" lower="0" upper="1.3" />
    </joint>
  </robot>
