<robot name="weatherproof_skateboard">
  <material name="sealed_teal_composite">
    <color rgba="0.02 0.22 0.24 1" />
    </material>
  <material name="coarse_black_grip">
    <color rgba="0.015 0.016 0.014 1" />
    </material>
  <material name="black_uv_rubber">
    <color rgba="0.005 0.006 0.006 1" />
    </material>
  <material name="matte_epdm_gasket">
    <color rgba="0.02 0.018 0.015 1" />
    </material>
  <material name="anodized_aluminum">
    <color rgba="0.55 0.6 0.62 1" />
    </material>
  <material name="brushed_stainless">
    <color rgba="0.82 0.8 0.76 1" />
    </material>
  <material name="storm_gray_urethane">
    <color rgba="0.14 0.16 0.17 1" />
    </material>
  <material name="sealed_bearing_blue">
    <color rgba="0.02 0.08 0.18 1" />
    </material>
  <link name="deck">
    <visual name="sealed_deck_shell">
      <geometry>
        <mesh filename="assets/meshes/sealed_crowned_deck.obj" />
        </geometry>
      <material name="sealed_teal_composite">
        <color rgba="0.02 0.22 0.24 1" />
        </material>
      </visual>
    <visual name="rail_0_bumper">
      <origin xyz="0 -0.119 0.015" rpy="0 0 0" />
      <geometry>
        <box size="0.735 0.016 0.026" />
        </geometry>
      <material name="black_uv_rubber">
        <color rgba="0.005 0.006 0.006 1" />
        </material>
      </visual>
    <visual name="rail_0_drip_lip">
      <origin xyz="0 -0.10948 0" rpy="0 0 0" />
      <geometry>
        <box size="0.65 0.009 0.006" />
        </geometry>
      <material name="black_uv_rubber">
        <color rgba="0.005 0.006 0.006 1" />
        </material>
      </visual>
    <visual name="rail_1_bumper">
      <origin xyz="0 0.119 0.015" rpy="0 0 0" />
      <geometry>
        <box size="0.735 0.016 0.026" />
        </geometry>
      <material name="black_uv_rubber">
        <color rgba="0.005 0.006 0.006 1" />
        </material>
      </visual>
    <visual name="rail_1_drip_lip">
      <origin xyz="0 0.10948 0" rpy="0 0 0" />
      <geometry>
        <box size="0.65 0.009 0.006" />
        </geometry>
      <material name="black_uv_rubber">
        <color rgba="0.005 0.006 0.006 1" />
        </material>
      </visual>
    <visual name="rear_grip">
      <origin xyz="-0.205 0 0.026" rpy="0 0 0" />
      <geometry>
        <box size="0.27 0.19 0.003" />
        </geometry>
      <material name="coarse_black_grip">
        <color rgba="0.015 0.016 0.014 1" />
        </material>
      </visual>
    <visual name="front_grip">
      <origin xyz="0.205 0 0.026" rpy="0 0 0" />
      <geometry>
        <box size="0.27 0.19 0.003" />
        </geometry>
      <material name="coarse_black_grip">
        <color rgba="0.015 0.016 0.014 1" />
        </material>
      </visual>
    <visual name="center_grip_bridge">
      <origin xyz="0 0 0.0265" rpy="0 0 0" />
      <geometry>
        <box size="0.135 0.06 0.0025" />
        </geometry>
      <material name="coarse_black_grip">
        <color rgba="0.015 0.016 0.014 1" />
        </material>
      </visual>
    <visual name="front_sealed_pad">
      <origin xyz="0.255 0 -0.003" rpy="0 0 0" />
      <geometry>
        <box size="0.138 0.082 0.006" />
        </geometry>
      <material name="matte_epdm_gasket">
        <color rgba="0.02 0.018 0.015 1" />
        </material>
      </visual>
    <visual name="front_baseplate">
      <origin xyz="0.255 0 -0.01" rpy="0 0 0" />
      <geometry>
        <box size="0.112 0.064 0.008" />
        </geometry>
      <material name="brushed_stainless">
        <color rgba="0.82 0.8 0.76 1" />
        </material>
      </visual>
    <visual name="front_pivot_cup">
      <origin xyz="0.255 0 -0.018" rpy="1.5708 0 0" />
      <geometry>
        <cylinder radius="0.02" length="0.008" />
        </geometry>
      <material name="matte_epdm_gasket">
        <color rgba="0.02 0.018 0.015 1" />
        </material>
      </visual>
    <visual name="front_bolt_shank_0">
      <origin xyz="0.217 -0.024 0.008" rpy="0 0 0" />
      <geometry>
        <cylinder radius="0.006" length="0.034" />
        </geometry>
      <material name="brushed_stainless">
        <color rgba="0.82 0.8 0.76 1" />
        </material>
      </visual>
    <visual name="front_sealed_bolt_0">
      <origin xyz="0.217 -0.024 0.0265" rpy="0 0 0" />
      <geometry>
        <cylinder radius="0.01" length="0.004" />
        </geometry>
      <material name="brushed_stainless">
        <color rgba="0.82 0.8 0.76 1" />
        </material>
      </visual>
    <visual name="front_washer_0">
      <origin xyz="0.217 -0.024 -0.0155" rpy="0 0 0" />
      <geometry>
        <cylinder radius="0.009" length="0.003" />
        </geometry>
      <material name="brushed_stainless">
        <color rgba="0.82 0.8 0.76 1" />
        </material>
      </visual>
    <visual name="front_bolt_shank_1">
      <origin xyz="0.217 0.024 0.008" rpy="0 0 0" />
      <geometry>
        <cylinder radius="0.006" length="0.034" />
        </geometry>
      <material name="brushed_stainless">
        <color rgba="0.82 0.8 0.76 1" />
        </material>
      </visual>
    <visual name="front_sealed_bolt_1">
      <origin xyz="0.217 0.024 0.0265" rpy="0 0 0" />
      <geometry>
        <cylinder radius="0.01" length="0.004" />
        </geometry>
      <material name="brushed_stainless">
        <color rgba="0.82 0.8 0.76 1" />
        </material>
      </visual>
    <visual name="front_washer_1">
      <origin xyz="0.217 0.024 -0.0155" rpy="0 0 0" />
      <geometry>
        <cylinder radius="0.009" length="0.003" />
        </geometry>
      <material name="brushed_stainless">
        <color rgba="0.82 0.8 0.76 1" />
        </material>
      </visual>
    <visual name="front_bolt_shank_2">
      <origin xyz="0.293 -0.024 0.008" rpy="0 0 0" />
      <geometry>
        <cylinder radius="0.006" length="0.034" />
        </geometry>
      <material name="brushed_stainless">
        <color rgba="0.82 0.8 0.76 1" />
        </material>
      </visual>
    <visual name="front_sealed_bolt_2">
      <origin xyz="0.293 -0.024 0.0265" rpy="0 0 0" />
      <geometry>
        <cylinder radius="0.01" length="0.004" />
        </geometry>
      <material name="brushed_stainless">
        <color rgba="0.82 0.8 0.76 1" />
        </material>
      </visual>
    <visual name="front_washer_2">
      <origin xyz="0.293 -0.024 -0.0155" rpy="0 0 0" />
      <geometry>
        <cylinder radius="0.009" length="0.003" />
        </geometry>
      <material name="brushed_stainless">
        <color rgba="0.82 0.8 0.76 1" />
        </material>
      </visual>
    <visual name="front_bolt_shank_3">
      <origin xyz="0.293 0.024 0.008" rpy="0 0 0" />
      <geometry>
        <cylinder radius="0.006" length="0.034" />
        </geometry>
      <material name="brushed_stainless">
        <color rgba="0.82 0.8 0.76 1" />
        </material>
      </visual>
    <visual name="front_sealed_bolt_3">
      <origin xyz="0.293 0.024 0.0265" rpy="0 0 0" />
      <geometry>
        <cylinder radius="0.01" length="0.004" />
        </geometry>
      <material name="brushed_stainless">
        <color rgba="0.82 0.8 0.76 1" />
        </material>
      </visual>
    <visual name="front_washer_3">
      <origin xyz="0.293 0.024 -0.0155" rpy="0 0 0" />
      <geometry>
        <cylinder radius="0.009" length="0.003" />
        </geometry>
      <material name="brushed_stainless">
        <color rgba="0.82 0.8 0.76 1" />
        </material>
      </visual>
    <visual name="rear_sealed_pad">
      <origin xyz="-0.255 0 -0.003" rpy="0 0 0" />
      <geometry>
        <box size="0.138 0.082 0.006" />
        </geometry>
      <material name="matte_epdm_gasket">
        <color rgba="0.02 0.018 0.015 1" />
        </material>
      </visual>
    <visual name="rear_baseplate">
      <origin xyz="-0.255 0 -0.01" rpy="0 0 0" />
      <geometry>
        <box size="0.112 0.064 0.008" />
        </geometry>
      <material name="brushed_stainless">
        <color rgba="0.82 0.8 0.76 1" />
        </material>
      </visual>
    <visual name="rear_pivot_cup">
      <origin xyz="-0.255 0 -0.018" rpy="1.5708 0 0" />
      <geometry>
        <cylinder radius="0.02" length="0.008" />
        </geometry>
      <material name="matte_epdm_gasket">
        <color rgba="0.02 0.018 0.015 1" />
        </material>
      </visual>
    <visual name="rear_bolt_shank_0">
      <origin xyz="-0.293 -0.024 0.008" rpy="0 0 0" />
      <geometry>
        <cylinder radius="0.006" length="0.034" />
        </geometry>
      <material name="brushed_stainless">
        <color rgba="0.82 0.8 0.76 1" />
        </material>
      </visual>
    <visual name="rear_sealed_bolt_0">
      <origin xyz="-0.293 -0.024 0.0265" rpy="0 0 0" />
      <geometry>
        <cylinder radius="0.01" length="0.004" />
        </geometry>
      <material name="brushed_stainless">
        <color rgba="0.82 0.8 0.76 1" />
        </material>
      </visual>
    <visual name="rear_washer_0">
      <origin xyz="-0.293 -0.024 -0.0155" rpy="0 0 0" />
      <geometry>
        <cylinder radius="0.009" length="0.003" />
        </geometry>
      <material name="brushed_stainless">
        <color rgba="0.82 0.8 0.76 1" />
        </material>
      </visual>
    <visual name="rear_bolt_shank_1">
      <origin xyz="-0.293 0.024 0.008" rpy="0 0 0" />
      <geometry>
        <cylinder radius="0.006" length="0.034" />
        </geometry>
      <material name="brushed_stainless">
        <color rgba="0.82 0.8 0.76 1" />
        </material>
      </visual>
    <visual name="rear_sealed_bolt_1">
      <origin xyz="-0.293 0.024 0.0265" rpy="0 0 0" />
      <geometry>
        <cylinder radius="0.01" length="0.004" />
        </geometry>
      <material name="brushed_stainless">
        <color rgba="0.82 0.8 0.76 1" />
        </material>
      </visual>
    <visual name="rear_washer_1">
      <origin xyz="-0.293 0.024 -0.0155" rpy="0 0 0" />
      <geometry>
        <cylinder radius="0.009" length="0.003" />
        </geometry>
      <material name="brushed_stainless">
        <color rgba="0.82 0.8 0.76 1" />
        </material>
      </visual>
    <visual name="rear_bolt_shank_2">
      <origin xyz="-0.217 -0.024 0.008" rpy="0 0 0" />
      <geometry>
        <cylinder radius="0.006" length="0.034" />
        </geometry>
      <material name="brushed_stainless">
        <color rgba="0.82 0.8 0.76 1" />
        </material>
      </visual>
    <visual name="rear_sealed_bolt_2">
      <origin xyz="-0.217 -0.024 0.0265" rpy="0 0 0" />
      <geometry>
        <cylinder radius="0.01" length="0.004" />
        </geometry>
      <material name="brushed_stainless">
        <color rgba="0.82 0.8 0.76 1" />
        </material>
      </visual>
    <visual name="rear_washer_2">
      <origin xyz="-0.217 -0.024 -0.0155" rpy="0 0 0" />
      <geometry>
        <cylinder radius="0.009" length="0.003" />
        </geometry>
      <material name="brushed_stainless">
        <color rgba="0.82 0.8 0.76 1" />
        </material>
      </visual>
    <visual name="rear_bolt_shank_3">
      <origin xyz="-0.217 0.024 0.008" rpy="0 0 0" />
      <geometry>
        <cylinder radius="0.006" length="0.034" />
        </geometry>
      <material name="brushed_stainless">
        <color rgba="0.82 0.8 0.76 1" />
        </material>
      </visual>
    <visual name="rear_sealed_bolt_3">
      <origin xyz="-0.217 0.024 0.0265" rpy="0 0 0" />
      <geometry>
        <cylinder radius="0.01" length="0.004" />
        </geometry>
      <material name="brushed_stainless">
        <color rgba="0.82 0.8 0.76 1" />
        </material>
      </visual>
    <visual name="rear_washer_3">
      <origin xyz="-0.217 0.024 -0.0155" rpy="0 0 0" />
      <geometry>
        <cylinder radius="0.009" length="0.003" />
        </geometry>
      <material name="brushed_stainless">
        <color rgba="0.82 0.8 0.76 1" />
        </material>
      </visual>
    <collision name="sealed_deck_shell">
      <geometry>
        <mesh filename="assets/meshes/sealed_crowned_deck.obj" />
        </geometry>
      </collision>
    <collision name="rail_0_bumper">
      <origin xyz="0 -0.119 0.015" rpy="0 0 0" />
      <geometry>
        <box size="0.735 0.016 0.026" />
        </geometry>
      </collision>
    <collision name="rail_0_drip_lip">
      <origin xyz="0 -0.10948 0" rpy="0 0 0" />
      <geometry>
        <box size="0.65 0.009 0.006" />
        </geometry>
      </collision>
    <collision name="rail_1_bumper">
      <origin xyz="0 0.119 0.015" rpy="0 0 0" />
      <geometry>
        <box size="0.735 0.016 0.026" />
        </geometry>
      </collision>
    <collision name="rail_1_drip_lip">
      <origin xyz="0 0.10948 0" rpy="0 0 0" />
      <geometry>
        <box size="0.65 0.009 0.006" />
        </geometry>
      </collision>
    <collision name="rear_grip">
      <origin xyz="-0.205 0 0.026" rpy="0 0 0" />
      <geometry>
        <box size="0.27 0.19 0.003" />
        </geometry>
      </collision>
    <collision name="front_grip">
      <origin xyz="0.205 0 0.026" rpy="0 0 0" />
      <geometry>
        <box size="0.27 0.19 0.003" />
        </geometry>
      </collision>
    <collision name="center_grip_bridge">
      <origin xyz="0 0 0.0265" rpy="0 0 0" />
      <geometry>
        <box size="0.135 0.06 0.0025" />
        </geometry>
      </collision>
    <collision name="front_sealed_pad">
      <origin xyz="0.255 0 -0.003" rpy="0 0 0" />
      <geometry>
        <box size="0.138 0.082 0.006" />
        </geometry>
      </collision>
    <collision name="front_baseplate">
      <origin xyz="0.255 0 -0.01" rpy="0 0 0" />
      <geometry>
        <box size="0.112 0.064 0.008" />
        </geometry>
      </collision>
    <collision name="front_pivot_cup">
      <origin xyz="0.255 0 -0.018" rpy="1.5708 0 0" />
      <geometry>
        <cylinder radius="0.02" length="0.008" />
        </geometry>
      </collision>
    <collision name="front_bolt_shank_0">
      <origin xyz="0.217 -0.024 0.008" rpy="0 0 0" />
      <geometry>
        <cylinder radius="0.006" length="0.034" />
        </geometry>
      </collision>
    <collision name="front_sealed_bolt_0">
      <origin xyz="0.217 -0.024 0.0265" rpy="0 0 0" />
      <geometry>
        <cylinder radius="0.01" length="0.004" />
        </geometry>
      </collision>
    <collision name="front_washer_0">
      <origin xyz="0.217 -0.024 -0.0155" rpy="0 0 0" />
      <geometry>
        <cylinder radius="0.009" length="0.003" />
        </geometry>
      </collision>
    <collision name="front_bolt_shank_1">
      <origin xyz="0.217 0.024 0.008" rpy="0 0 0" />
      <geometry>
        <cylinder radius="0.006" length="0.034" />
        </geometry>
      </collision>
    <collision name="front_sealed_bolt_1">
      <origin xyz="0.217 0.024 0.0265" rpy="0 0 0" />
      <geometry>
        <cylinder radius="0.01" length="0.004" />
        </geometry>
      </collision>
    <collision name="front_washer_1">
      <origin xyz="0.217 0.024 -0.0155" rpy="0 0 0" />
      <geometry>
        <cylinder radius="0.009" length="0.003" />
        </geometry>
      </collision>
    <collision name="front_bolt_shank_2">
      <origin xyz="0.293 -0.024 0.008" rpy="0 0 0" />
      <geometry>
        <cylinder radius="0.006" length="0.034" />
        </geometry>
      </collision>
    <collision name="front_sealed_bolt_2">
      <origin xyz="0.293 -0.024 0.0265" rpy="0 0 0" />
      <geometry>
        <cylinder radius="0.01" length="0.004" />
        </geometry>
      </collision>
    <collision name="front_washer_2">
      <origin xyz="0.293 -0.024 -0.0155" rpy="0 0 0" />
      <geometry>
        <cylinder radius="0.009" length="0.003" />
        </geometry>
      </collision>
    <collision name="front_bolt_shank_3">
      <origin xyz="0.293 0.024 0.008" rpy="0 0 0" />
      <geometry>
        <cylinder radius="0.006" length="0.034" />
        </geometry>
      </collision>
    <collision name="front_sealed_bolt_3">
      <origin xyz="0.293 0.024 0.0265" rpy="0 0 0" />
      <geometry>
        <cylinder radius="0.01" length="0.004" />
        </geometry>
      </collision>
    <collision name="front_washer_3">
      <origin xyz="0.293 0.024 -0.0155" rpy="0 0 0" />
      <geometry>
        <cylinder radius="0.009" length="0.003" />
        </geometry>
      </collision>
    <collision name="rear_sealed_pad">
      <origin xyz="-0.255 0 -0.003" rpy="0 0 0" />
      <geometry>
        <box size="0.138 0.082 0.006" />
        </geometry>
      </collision>
    <collision name="rear_baseplate">
      <origin xyz="-0.255 0 -0.01" rpy="0 0 0" />
      <geometry>
        <box size="0.112 0.064 0.008" />
        </geometry>
      </collision>
    <collision name="rear_pivot_cup">
      <origin xyz="-0.255 0 -0.018" rpy="1.5708 0 0" />
      <geometry>
        <cylinder radius="0.02" length="0.008" />
        </geometry>
      </collision>
    <collision name="rear_bolt_shank_0">
      <origin xyz="-0.293 -0.024 0.008" rpy="0 0 0" />
      <geometry>
        <cylinder radius="0.006" length="0.034" />
        </geometry>
      </collision>
    <collision name="rear_sealed_bolt_0">
      <origin xyz="-0.293 -0.024 0.0265" rpy="0 0 0" />
      <geometry>
        <cylinder radius="0.01" length="0.004" />
        </geometry>
      </collision>
    <collision name="rear_washer_0">
      <origin xyz="-0.293 -0.024 -0.0155" rpy="0 0 0" />
      <geometry>
        <cylinder radius="0.009" length="0.003" />
        </geometry>
      </collision>
    <collision name="rear_bolt_shank_1">
      <origin xyz="-0.293 0.024 0.008" rpy="0 0 0" />
      <geometry>
        <cylinder radius="0.006" length="0.034" />
        </geometry>
      </collision>
    <collision name="rear_sealed_bolt_1">
      <origin xyz="-0.293 0.024 0.0265" rpy="0 0 0" />
      <geometry>
        <cylinder radius="0.01" length="0.004" />
        </geometry>
      </collision>
    <collision name="rear_washer_1">
      <origin xyz="-0.293 0.024 -0.0155" rpy="0 0 0" />
      <geometry>
        <cylinder radius="0.009" length="0.003" />
        </geometry>
      </collision>
    <collision name="rear_bolt_shank_2">
      <origin xyz="-0.217 -0.024 0.008" rpy="0 0 0" />
      <geometry>
        <cylinder radius="0.006" length="0.034" />
        </geometry>
      </collision>
    <collision name="rear_sealed_bolt_2">
      <origin xyz="-0.217 -0.024 0.0265" rpy="0 0 0" />
      <geometry>
        <cylinder radius="0.01" length="0.004" />
        </geometry>
      </collision>
    <collision name="rear_washer_2">
      <origin xyz="-0.217 -0.024 -0.0155" rpy="0 0 0" />
      <geometry>
        <cylinder radius="0.009" length="0.003" />
        </geometry>
      </collision>
    <collision name="rear_bolt_shank_3">
      <origin xyz="-0.217 0.024 0.008" rpy="0 0 0" />
      <geometry>
        <cylinder radius="0.006" length="0.034" />
        </geometry>
      </collision>
    <collision name="rear_sealed_bolt_3">
      <origin xyz="-0.217 0.024 0.0265" rpy="0 0 0" />
      <geometry>
        <cylinder radius="0.01" length="0.004" />
        </geometry>
      </collision>
    <collision name="rear_washer_3">
      <origin xyz="-0.217 0.024 -0.0155" rpy="0 0 0" />
      <geometry>
        <cylinder radius="0.009" length="0.003" />
        </geometry>
      </collision>
    </link>
  <link name="front_truck">
    <visual name="axle">
      <origin xyz="0 0 -0.034" rpy="-1.5708 0 0" />
      <geometry>
        <cylinder radius="0.0055" length="0.386" />
        </geometry>
      <material name="brushed_stainless">
        <color rgba="0.82 0.8 0.76 1" />
        </material>
      </visual>
    <visual name="hanger_body">
      <origin xyz="0 0 -0.036" rpy="0 0 0" />
      <geometry>
        <box size="0.088 0.172 0.03" />
        </geometry>
      <material name="anodized_aluminum">
        <color rgba="0.55 0.6 0.62 1" />
        </material>
      </visual>
    <visual name="hanger_yoke">
      <origin xyz="0 0 -0.03" rpy="0 0 0" />
      <geometry>
        <box size="0.038 0.222 0.02" />
        </geometry>
      <material name="anodized_aluminum">
        <color rgba="0.55 0.6 0.62 1" />
        </material>
      </visual>
    <visual name="kingpin">
      <origin xyz="0 0 0" rpy="0 -0.347062 0" />
      <geometry>
        <cylinder radius="0.012" length="0.048" />
        </geometry>
      <material name="brushed_stainless">
        <color rgba="0.82 0.8 0.76 1" />
        </material>
      </visual>
    <visual name="top_bushing">
      <origin xyz="-0.00306122 0 0.00846339" rpy="0 -0.347062 0" />
      <geometry>
        <cylinder radius="0.022" length="0.015" />
        </geometry>
      <material name="black_uv_rubber">
        <color rgba="0.005 0.006 0.006 1" />
        </material>
      </visual>
    <visual name="bottom_bushing">
      <origin xyz="0.00408163 0 -0.0112845" rpy="0 -0.347062 0" />
      <geometry>
        <cylinder radius="0.023" length="0.017" />
        </geometry>
      <material name="storm_gray_urethane">
        <color rgba="0.14 0.16 0.17 1" />
        </material>
      </visual>
    <visual name="top_cup_washer">
      <origin xyz="-0.00578231 0 0.0159864" rpy="0 -0.347062 0" />
      <geometry>
        <cylinder radius="0.024" length="0.0035" />
        </geometry>
      <material name="brushed_stainless">
        <color rgba="0.82 0.8 0.76 1" />
        </material>
      </visual>
    <visual name="bottom_cup_washer">
      <origin xyz="0.00884354 0 -0.0244498" rpy="0 -0.347062 0" />
      <geometry>
        <cylinder radius="0.024" length="0.0035" />
        </geometry>
      <material name="brushed_stainless">
        <color rgba="0.82 0.8 0.76 1" />
        </material>
      </visual>
    <visual name="inner_spacer_0">
      <origin xyz="0 -0.136 -0.034" rpy="-1.5708 0 0" />
      <geometry>
        <cylinder radius="0.013" length="0.004" />
        </geometry>
      <material name="brushed_stainless">
        <color rgba="0.82 0.8 0.76 1" />
        </material>
      </visual>
    <visual name="axle_nut_0">
      <origin xyz="0 -0.186 -0.034" rpy="-1.5708 0 0" />
      <geometry>
        <cylinder radius="0.014" length="0.007" />
        </geometry>
      <material name="brushed_stainless">
        <color rgba="0.82 0.8 0.76 1" />
        </material>
      </visual>
    <visual name="inner_spacer_1">
      <origin xyz="0 0.136 -0.034" rpy="-1.5708 0 0" />
      <geometry>
        <cylinder radius="0.013" length="0.004" />
        </geometry>
      <material name="brushed_stainless">
        <color rgba="0.82 0.8 0.76 1" />
        </material>
      </visual>
    <visual name="axle_nut_1">
      <origin xyz="0 0.186 -0.034" rpy="-1.5708 0 0" />
      <geometry>
        <cylinder radius="0.014" length="0.007" />
        </geometry>
      <material name="brushed_stainless">
        <color rgba="0.82 0.8 0.76 1" />
        </material>
      </visual>
    <collision name="axle">
      <origin xyz="0 0 -0.034" rpy="-1.5708 0 0" />
      <geometry>
        <cylinder radius="0.0055" length="0.386" />
        </geometry>
      </collision>
    <collision name="hanger_body">
      <origin xyz="0 0 -0.036" rpy="0 0 0" />
      <geometry>
        <box size="0.088 0.172 0.03" />
        </geometry>
      </collision>
    <collision name="hanger_yoke">
      <origin xyz="0 0 -0.03" rpy="0 0 0" />
      <geometry>
        <box size="0.038 0.222 0.02" />
        </geometry>
      </collision>
    <collision name="kingpin">
      <origin xyz="0 0 0" rpy="0 -0.347062 0" />
      <geometry>
        <cylinder radius="0.012" length="0.048" />
        </geometry>
      </collision>
    <collision name="top_bushing">
      <origin xyz="-0.00306122 0 0.00846339" rpy="0 -0.347062 0" />
      <geometry>
        <cylinder radius="0.022" length="0.015" />
        </geometry>
      </collision>
    <collision name="bottom_bushing">
      <origin xyz="0.00408163 0 -0.0112845" rpy="0 -0.347062 0" />
      <geometry>
        <cylinder radius="0.023" length="0.017" />
        </geometry>
      </collision>
    <collision name="top_cup_washer">
      <origin xyz="-0.00578231 0 0.0159864" rpy="0 -0.347062 0" />
      <geometry>
        <cylinder radius="0.024" length="0.0035" />
        </geometry>
      </collision>
    <collision name="bottom_cup_washer">
      <origin xyz="0.00884354 0 -0.0244498" rpy="0 -0.347062 0" />
      <geometry>
        <cylinder radius="0.024" length="0.0035" />
        </geometry>
      </collision>
    <collision name="inner_spacer_0">
      <origin xyz="0 -0.136 -0.034" rpy="-1.5708 0 0" />
      <geometry>
        <cylinder radius="0.013" length="0.004" />
        </geometry>
      </collision>
    <collision name="axle_nut_0">
      <origin xyz="0 -0.186 -0.034" rpy="-1.5708 0 0" />
      <geometry>
        <cylinder radius="0.014" length="0.007" />
        </geometry>
      </collision>
    <collision name="inner_spacer_1">
      <origin xyz="0 0.136 -0.034" rpy="-1.5708 0 0" />
      <geometry>
        <cylinder radius="0.013" length="0.004" />
        </geometry>
      </collision>
    <collision name="axle_nut_1">
      <origin xyz="0 0.186 -0.034" rpy="-1.5708 0 0" />
      <geometry>
        <cylinder radius="0.014" length="0.007" />
        </geometry>
      </collision>
    </link>
  <link name="front_wheel_0">
    <visual name="tire">
      <origin xyz="0 0 0" rpy="0 0 1.5708" />
      <geometry>
        <mesh filename="assets/meshes/outdoor_urethane_tire.obj" />
        </geometry>
      <material name="storm_gray_urethane">
        <color rgba="0.14 0.16 0.17 1" />
        </material>
      </visual>
    <visual name="wheel_core">
      <origin xyz="0 0 0" rpy="0 0 1.5708" />
      <geometry>
        <mesh filename="assets/meshes/sealed_wheel_core.obj" />
        </geometry>
      <material name="anodized_aluminum">
        <color rgba="0.55 0.6 0.62 1" />
        </material>
      </visual>
    <visual name="bearing_shield_0">
      <origin xyz="0 -0.014 0" rpy="-1.5708 0 0" />
      <geometry>
        <cylinder radius="0.0145" length="0.0025" />
        </geometry>
      <material name="sealed_bearing_blue">
        <color rgba="0.02 0.08 0.18 1" />
        </material>
      </visual>
    <visual name="bearing_shield_1">
      <origin xyz="0 0.014 0" rpy="-1.5708 0 0" />
      <geometry>
        <cylinder radius="0.0145" length="0.0025" />
        </geometry>
      <material name="sealed_bearing_blue">
        <color rgba="0.02 0.08 0.18 1" />
        </material>
      </visual>
    <collision name="tire">
      <origin xyz="0 0 0" rpy="0 0 1.5708" />
      <geometry>
        <mesh filename="assets/meshes/outdoor_urethane_tire.obj" />
        </geometry>
      </collision>
    <collision name="wheel_core">
      <origin xyz="0 0 0" rpy="0 0 1.5708" />
      <geometry>
        <mesh filename="assets/meshes/sealed_wheel_core.obj" />
        </geometry>
      </collision>
    <collision name="bearing_shield_0">
      <origin xyz="0 -0.014 0" rpy="-1.5708 0 0" />
      <geometry>
        <cylinder radius="0.0145" length="0.0025" />
        </geometry>
      </collision>
    <collision name="bearing_shield_1">
      <origin xyz="0 0.014 0" rpy="-1.5708 0 0" />
      <geometry>
        <cylinder radius="0.0145" length="0.0025" />
        </geometry>
      </collision>
    </link>
  <link name="front_wheel_1">
    <visual name="tire">
      <origin xyz="0 0 0" rpy="0 0 1.5708" />
      <geometry>
        <mesh filename="assets/meshes/outdoor_urethane_tire.obj" />
        </geometry>
      <material name="storm_gray_urethane">
        <color rgba="0.14 0.16 0.17 1" />
        </material>
      </visual>
    <visual name="wheel_core">
      <origin xyz="0 0 0" rpy="0 0 1.5708" />
      <geometry>
        <mesh filename="assets/meshes/sealed_wheel_core.obj" />
        </geometry>
      <material name="anodized_aluminum">
        <color rgba="0.55 0.6 0.62 1" />
        </material>
      </visual>
    <visual name="bearing_shield_0">
      <origin xyz="0 -0.014 0" rpy="-1.5708 0 0" />
      <geometry>
        <cylinder radius="0.0145" length="0.0025" />
        </geometry>
      <material name="sealed_bearing_blue">
        <color rgba="0.02 0.08 0.18 1" />
        </material>
      </visual>
    <visual name="bearing_shield_1">
      <origin xyz="0 0.014 0" rpy="-1.5708 0 0" />
      <geometry>
        <cylinder radius="0.0145" length="0.0025" />
        </geometry>
      <material name="sealed_bearing_blue">
        <color rgba="0.02 0.08 0.18 1" />
        </material>
      </visual>
    <collision name="tire">
      <origin xyz="0 0 0" rpy="0 0 1.5708" />
      <geometry>
        <mesh filename="assets/meshes/outdoor_urethane_tire.obj" />
        </geometry>
      </collision>
    <collision name="wheel_core">
      <origin xyz="0 0 0" rpy="0 0 1.5708" />
      <geometry>
        <mesh filename="assets/meshes/sealed_wheel_core.obj" />
        </geometry>
      </collision>
    <collision name="bearing_shield_0">
      <origin xyz="0 -0.014 0" rpy="-1.5708 0 0" />
      <geometry>
        <cylinder radius="0.0145" length="0.0025" />
        </geometry>
      </collision>
    <collision name="bearing_shield_1">
      <origin xyz="0 0.014 0" rpy="-1.5708 0 0" />
      <geometry>
        <cylinder radius="0.0145" length="0.0025" />
        </geometry>
      </collision>
    </link>
  <link name="rear_truck">
    <visual name="axle">
      <origin xyz="0 0 -0.034" rpy="-1.5708 0 0" />
      <geometry>
        <cylinder radius="0.0055" length="0.386" />
        </geometry>
      <material name="brushed_stainless">
        <color rgba="0.82 0.8 0.76 1" />
        </material>
      </visual>
    <visual name="hanger_body">
      <origin xyz="0 0 -0.036" rpy="0 0 0" />
      <geometry>
        <box size="0.088 0.172 0.03" />
        </geometry>
      <material name="anodized_aluminum">
        <color rgba="0.55 0.6 0.62 1" />
        </material>
      </visual>
    <visual name="hanger_yoke">
      <origin xyz="0 0 -0.03" rpy="0 0 0" />
      <geometry>
        <box size="0.038 0.222 0.02" />
        </geometry>
      <material name="anodized_aluminum">
        <color rgba="0.55 0.6 0.62 1" />
        </material>
      </visual>
    <visual name="kingpin">
      <origin xyz="0 0 0" rpy="0 0.347062 0" />
      <geometry>
        <cylinder radius="0.012" length="0.048" />
        </geometry>
      <material name="brushed_stainless">
        <color rgba="0.82 0.8 0.76 1" />
        </material>
      </visual>
    <visual name="top_bushing">
      <origin xyz="0.00306122 0 0.00846339" rpy="0 0.347062 0" />
      <geometry>
        <cylinder radius="0.022" length="0.015" />
        </geometry>
      <material name="black_uv_rubber">
        <color rgba="0.005 0.006 0.006 1" />
        </material>
      </visual>
    <visual name="bottom_bushing">
      <origin xyz="-0.00408163 0 -0.0112845" rpy="0 0.347062 0" />
      <geometry>
        <cylinder radius="0.023" length="0.017" />
        </geometry>
      <material name="storm_gray_urethane">
        <color rgba="0.14 0.16 0.17 1" />
        </material>
      </visual>
    <visual name="top_cup_washer">
      <origin xyz="0.00578231 0 0.0159864" rpy="0 0.347062 0" />
      <geometry>
        <cylinder radius="0.024" length="0.0035" />
        </geometry>
      <material name="brushed_stainless">
        <color rgba="0.82 0.8 0.76 1" />
        </material>
      </visual>
    <visual name="bottom_cup_washer">
      <origin xyz="-0.00884354 0 -0.0244498" rpy="0 0.347062 0" />
      <geometry>
        <cylinder radius="0.024" length="0.0035" />
        </geometry>
      <material name="brushed_stainless">
        <color rgba="0.82 0.8 0.76 1" />
        </material>
      </visual>
    <visual name="inner_spacer_0">
      <origin xyz="0 -0.136 -0.034" rpy="-1.5708 0 0" />
      <geometry>
        <cylinder radius="0.013" length="0.004" />
        </geometry>
      <material name="brushed_stainless">
        <color rgba="0.82 0.8 0.76 1" />
        </material>
      </visual>
    <visual name="axle_nut_0">
      <origin xyz="0 -0.186 -0.034" rpy="-1.5708 0 0" />
      <geometry>
        <cylinder radius="0.014" length="0.007" />
        </geometry>
      <material name="brushed_stainless">
        <color rgba="0.82 0.8 0.76 1" />
        </material>
      </visual>
    <visual name="inner_spacer_1">
      <origin xyz="0 0.136 -0.034" rpy="-1.5708 0 0" />
      <geometry>
        <cylinder radius="0.013" length="0.004" />
        </geometry>
      <material name="brushed_stainless">
        <color rgba="0.82 0.8 0.76 1" />
        </material>
      </visual>
    <visual name="axle_nut_1">
      <origin xyz="0 0.186 -0.034" rpy="-1.5708 0 0" />
      <geometry>
        <cylinder radius="0.014" length="0.007" />
        </geometry>
      <material name="brushed_stainless">
        <color rgba="0.82 0.8 0.76 1" />
        </material>
      </visual>
    <collision name="axle">
      <origin xyz="0 0 -0.034" rpy="-1.5708 0 0" />
      <geometry>
        <cylinder radius="0.0055" length="0.386" />
        </geometry>
      </collision>
    <collision name="hanger_body">
      <origin xyz="0 0 -0.036" rpy="0 0 0" />
      <geometry>
        <box size="0.088 0.172 0.03" />
        </geometry>
      </collision>
    <collision name="hanger_yoke">
      <origin xyz="0 0 -0.03" rpy="0 0 0" />
      <geometry>
        <box size="0.038 0.222 0.02" />
        </geometry>
      </collision>
    <collision name="kingpin">
      <origin xyz="0 0 0" rpy="0 0.347062 0" />
      <geometry>
        <cylinder radius="0.012" length="0.048" />
        </geometry>
      </collision>
    <collision name="top_bushing">
      <origin xyz="0.00306122 0 0.00846339" rpy="0 0.347062 0" />
      <geometry>
        <cylinder radius="0.022" length="0.015" />
        </geometry>
      </collision>
    <collision name="bottom_bushing">
      <origin xyz="-0.00408163 0 -0.0112845" rpy="0 0.347062 0" />
      <geometry>
        <cylinder radius="0.023" length="0.017" />
        </geometry>
      </collision>
    <collision name="top_cup_washer">
      <origin xyz="0.00578231 0 0.0159864" rpy="0 0.347062 0" />
      <geometry>
        <cylinder radius="0.024" length="0.0035" />
        </geometry>
      </collision>
    <collision name="bottom_cup_washer">
      <origin xyz="-0.00884354 0 -0.0244498" rpy="0 0.347062 0" />
      <geometry>
        <cylinder radius="0.024" length="0.0035" />
        </geometry>
      </collision>
    <collision name="inner_spacer_0">
      <origin xyz="0 -0.136 -0.034" rpy="-1.5708 0 0" />
      <geometry>
        <cylinder radius="0.013" length="0.004" />
        </geometry>
      </collision>
    <collision name="axle_nut_0">
      <origin xyz="0 -0.186 -0.034" rpy="-1.5708 0 0" />
      <geometry>
        <cylinder radius="0.014" length="0.007" />
        </geometry>
      </collision>
    <collision name="inner_spacer_1">
      <origin xyz="0 0.136 -0.034" rpy="-1.5708 0 0" />
      <geometry>
        <cylinder radius="0.013" length="0.004" />
        </geometry>
      </collision>
    <collision name="axle_nut_1">
      <origin xyz="0 0.186 -0.034" rpy="-1.5708 0 0" />
      <geometry>
        <cylinder radius="0.014" length="0.007" />
        </geometry>
      </collision>
    </link>
  <link name="rear_wheel_0">
    <visual name="tire">
      <origin xyz="0 0 0" rpy="0 0 1.5708" />
      <geometry>
        <mesh filename="assets/meshes/outdoor_urethane_tire.obj" />
        </geometry>
      <material name="storm_gray_urethane">
        <color rgba="0.14 0.16 0.17 1" />
        </material>
      </visual>
    <visual name="wheel_core">
      <origin xyz="0 0 0" rpy="0 0 1.5708" />
      <geometry>
        <mesh filename="assets/meshes/sealed_wheel_core.obj" />
        </geometry>
      <material name="anodized_aluminum">
        <color rgba="0.55 0.6 0.62 1" />
        </material>
      </visual>
    <visual name="bearing_shield_0">
      <origin xyz="0 -0.014 0" rpy="-1.5708 0 0" />
      <geometry>
        <cylinder radius="0.0145" length="0.0025" />
        </geometry>
      <material name="sealed_bearing_blue">
        <color rgba="0.02 0.08 0.18 1" />
        </material>
      </visual>
    <visual name="bearing_shield_1">
      <origin xyz="0 0.014 0" rpy="-1.5708 0 0" />
      <geometry>
        <cylinder radius="0.0145" length="0.0025" />
        </geometry>
      <material name="sealed_bearing_blue">
        <color rgba="0.02 0.08 0.18 1" />
        </material>
      </visual>
    <collision name="tire">
      <origin xyz="0 0 0" rpy="0 0 1.5708" />
      <geometry>
        <mesh filename="assets/meshes/outdoor_urethane_tire.obj" />
        </geometry>
      </collision>
    <collision name="wheel_core">
      <origin xyz="0 0 0" rpy="0 0 1.5708" />
      <geometry>
        <mesh filename="assets/meshes/sealed_wheel_core.obj" />
        </geometry>
      </collision>
    <collision name="bearing_shield_0">
      <origin xyz="0 -0.014 0" rpy="-1.5708 0 0" />
      <geometry>
        <cylinder radius="0.0145" length="0.0025" />
        </geometry>
      </collision>
    <collision name="bearing_shield_1">
      <origin xyz="0 0.014 0" rpy="-1.5708 0 0" />
      <geometry>
        <cylinder radius="0.0145" length="0.0025" />
        </geometry>
      </collision>
    </link>
  <link name="rear_wheel_1">
    <visual name="tire">
      <origin xyz="0 0 0" rpy="0 0 1.5708" />
      <geometry>
        <mesh filename="assets/meshes/outdoor_urethane_tire.obj" />
        </geometry>
      <material name="storm_gray_urethane">
        <color rgba="0.14 0.16 0.17 1" />
        </material>
      </visual>
    <visual name="wheel_core">
      <origin xyz="0 0 0" rpy="0 0 1.5708" />
      <geometry>
        <mesh filename="assets/meshes/sealed_wheel_core.obj" />
        </geometry>
      <material name="anodized_aluminum">
        <color rgba="0.55 0.6 0.62 1" />
        </material>
      </visual>
    <visual name="bearing_shield_0">
      <origin xyz="0 -0.014 0" rpy="-1.5708 0 0" />
      <geometry>
        <cylinder radius="0.0145" length="0.0025" />
        </geometry>
      <material name="sealed_bearing_blue">
        <color rgba="0.02 0.08 0.18 1" />
        </material>
      </visual>
    <visual name="bearing_shield_1">
      <origin xyz="0 0.014 0" rpy="-1.5708 0 0" />
      <geometry>
        <cylinder radius="0.0145" length="0.0025" />
        </geometry>
      <material name="sealed_bearing_blue">
        <color rgba="0.02 0.08 0.18 1" />
        </material>
      </visual>
    <collision name="tire">
      <origin xyz="0 0 0" rpy="0 0 1.5708" />
      <geometry>
        <mesh filename="assets/meshes/outdoor_urethane_tire.obj" />
        </geometry>
      </collision>
    <collision name="wheel_core">
      <origin xyz="0 0 0" rpy="0 0 1.5708" />
      <geometry>
        <mesh filename="assets/meshes/sealed_wheel_core.obj" />
        </geometry>
      </collision>
    <collision name="bearing_shield_0">
      <origin xyz="0 -0.014 0" rpy="-1.5708 0 0" />
      <geometry>
        <cylinder radius="0.0145" length="0.0025" />
        </geometry>
      </collision>
    <collision name="bearing_shield_1">
      <origin xyz="0 0.014 0" rpy="-1.5708 0 0" />
      <geometry>
        <cylinder radius="0.0145" length="0.0025" />
        </geometry>
      </collision>
    </link>
  <joint name="deck_to_front_truck" type="revolute">
    <origin xyz="0.255 0 -0.04" rpy="0 0 0" />
    <parent link="deck" />
    <child link="front_truck" />
    <axis xyz="-0.340136 0 0.940376" />
    <limit effort="28" velocity="2.2" lower="-0.38" upper="0.38" />
    <dynamics damping="0.6" friction="0.08" />
    </joint>
  <joint name="front_wheel_0_spin" type="continuous">
    <origin xyz="0 -0.16 -0.034" rpy="0 0 0" />
    <parent link="front_truck" />
    <child link="front_wheel_0" />
    <axis xyz="0 1 0" />
    <limit effort="2" velocity="60" />
    <dynamics damping="0.015" friction="0.01" />
    </joint>
  <joint name="front_wheel_1_spin" type="continuous">
    <origin xyz="0 0.16 -0.034" rpy="0 0 0" />
    <parent link="front_truck" />
    <child link="front_wheel_1" />
    <axis xyz="0 1 0" />
    <limit effort="2" velocity="60" />
    <dynamics damping="0.015" friction="0.01" />
    </joint>
  <joint name="deck_to_rear_truck" type="revolute">
    <origin xyz="-0.255 0 -0.04" rpy="0 0 0" />
    <parent link="deck" />
    <child link="rear_truck" />
    <axis xyz="0.340136 0 0.940376" />
    <limit effort="28" velocity="2.2" lower="-0.38" upper="0.38" />
    <dynamics damping="0.6" friction="0.08" />
    </joint>
  <joint name="rear_wheel_0_spin" type="continuous">
    <origin xyz="0 -0.16 -0.034" rpy="0 0 0" />
    <parent link="rear_truck" />
    <child link="rear_wheel_0" />
    <axis xyz="0 1 0" />
    <limit effort="2" velocity="60" />
    <dynamics damping="0.015" friction="0.01" />
    </joint>
  <joint name="rear_wheel_1_spin" type="continuous">
    <origin xyz="0 0.16 -0.034" rpy="0 0 0" />
    <parent link="rear_truck" />
    <child link="rear_wheel_1" />
    <axis xyz="0 1 0" />
    <limit effort="2" velocity="60" />
    <dynamics damping="0.015" friction="0.01" />
    </joint>
  </robot>
