<robot name="simple_rice_cooker">
  <link name="body">
    <visual name="body_shell">
      <geometry>
        <mesh filename="assets/meshes/body_shell.obj" />
        </geometry>
      <material name="warm_white_plastic">
        <color rgba="0.92 0.89 0.82 1" />
        </material>
      </visual>
    <visual name="lower_band">
      <origin xyz="0 0 0.031" rpy="0 0 0" />
      <geometry>
        <cylinder radius="0.1295" length="0.044" />
        </geometry>
      <material name="satin_light_gray">
        <color rgba="0.62 0.64 0.63 1" />
        </material>
      </visual>
    <visual name="foot_ring">
      <origin xyz="0 0 0.006" rpy="0 0 0" />
      <geometry>
        <cylinder radius="0.116" length="0.012" />
        </geometry>
      <material name="soft_black">
        <color rgba="0.015 0.015 0.014 1" />
        </material>
      </visual>
    <visual name="top_rim">
      <origin xyz="0 0 0.216" rpy="0 0 0" />
      <geometry>
        <mesh filename="assets/meshes/top_rim.obj" />
        </geometry>
      <material name="satin_light_gray">
        <color rgba="0.62 0.64 0.63 1" />
        </material>
      </visual>
    <visual name="front_panel">
      <origin xyz="0 -0.142 0.112" rpy="1.5708 0 0" />
      <geometry>
        <mesh filename="assets/meshes/front_panel.obj" />
        </geometry>
      <material name="charcoal_panel">
        <color rgba="0.1 0.11 0.12 1" />
        </material>
      </visual>
    <visual name="latch_zone">
      <origin xyz="0 -0.146 0.166" rpy="1.5708 0 0" />
      <geometry>
        <mesh filename="assets/meshes/latch_zone.obj" />
        </geometry>
      <material name="satin_light_gray">
        <color rgba="0.62 0.64 0.63 1" />
        </material>
      </visual>
    <visual name="hinge_mount_0">
      <origin xyz="-0.076 0.13 0.213" rpy="0 0 0" />
      <geometry>
        <box size="0.035 0.055 0.014" />
        </geometry>
      <material name="satin_light_gray">
        <color rgba="0.62 0.64 0.63 1" />
        </material>
      </visual>
    <visual name="hinge_cheek_0">
      <origin xyz="-0.076 0.158 0.232" rpy="0 0 0" />
      <geometry>
        <box size="0.027 0.03 0.032" />
        </geometry>
      <material name="satin_light_gray">
        <color rgba="0.62 0.64 0.63 1" />
        </material>
      </visual>
    <visual name="hinge_mount_1">
      <origin xyz="0.076 0.13 0.213" rpy="0 0 0" />
      <geometry>
        <box size="0.035 0.055 0.014" />
        </geometry>
      <material name="satin_light_gray">
        <color rgba="0.62 0.64 0.63 1" />
        </material>
      </visual>
    <visual name="hinge_cheek_1">
      <origin xyz="0.076 0.158 0.232" rpy="0 0 0" />
      <geometry>
        <box size="0.027 0.03 0.032" />
        </geometry>
      <material name="satin_light_gray">
        <color rgba="0.62 0.64 0.63 1" />
        </material>
      </visual>
    <collision name="body_shell">
      <geometry>
        <mesh filename="assets/meshes/body_shell.obj" />
        </geometry>
      </collision>
    <collision name="lower_band">
      <origin xyz="0 0 0.031" rpy="0 0 0" />
      <geometry>
        <cylinder radius="0.1295" length="0.044" />
        </geometry>
      </collision>
    <collision name="foot_ring">
      <origin xyz="0 0 0.006" rpy="0 0 0" />
      <geometry>
        <cylinder radius="0.116" length="0.012" />
        </geometry>
      </collision>
    <collision name="top_rim">
      <origin xyz="0 0 0.216" rpy="0 0 0" />
      <geometry>
        <mesh filename="assets/meshes/top_rim.obj" />
        </geometry>
      </collision>
    <collision name="front_panel">
      <origin xyz="0 -0.142 0.112" rpy="1.5708 0 0" />
      <geometry>
        <mesh filename="assets/meshes/front_panel.obj" />
        </geometry>
      </collision>
    <collision name="latch_zone">
      <origin xyz="0 -0.146 0.166" rpy="1.5708 0 0" />
      <geometry>
        <mesh filename="assets/meshes/latch_zone.obj" />
        </geometry>
      </collision>
    <collision name="hinge_mount_0">
      <origin xyz="-0.076 0.13 0.213" rpy="0 0 0" />
      <geometry>
        <box size="0.035 0.055 0.014" />
        </geometry>
      </collision>
    <collision name="hinge_cheek_0">
      <origin xyz="-0.076 0.158 0.232" rpy="0 0 0" />
      <geometry>
        <box size="0.027 0.03 0.032" />
        </geometry>
      </collision>
    <collision name="hinge_mount_1">
      <origin xyz="0.076 0.13 0.213" rpy="0 0 0" />
      <geometry>
        <box size="0.035 0.055 0.014" />
        </geometry>
      </collision>
    <collision name="hinge_cheek_1">
      <origin xyz="0.076 0.158 0.232" rpy="0 0 0" />
      <geometry>
        <box size="0.027 0.03 0.032" />
        </geometry>
      </collision>
    </link>
  <link name="lid">
    <visual name="lid_dome">
      <geometry>
        <mesh filename="assets/meshes/lid_dome.obj" />
        </geometry>
      <material name="warm_white_plastic">
        <color rgba="0.92 0.89 0.82 1" />
        </material>
      </visual>
    <visual name="lid_rim">
      <origin xyz="0 -0.153 -0.006" rpy="0 0 0" />
      <geometry>
        <mesh filename="assets/meshes/lid_rim.obj" />
        </geometry>
      <material name="satin_light_gray">
        <color rgba="0.62 0.64 0.63 1" />
        </material>
      </visual>
    <visual name="hinge_barrel">
      <origin xyz="0 0 0" rpy="0 1.5708 0" />
      <geometry>
        <cylinder radius="0.011" length="0.105" />
        </geometry>
      <material name="satin_light_gray">
        <color rgba="0.62 0.64 0.63 1" />
        </material>
      </visual>
    <visual name="hinge_leaf">
      <origin xyz="0 -0.008 -0.004" rpy="0 0 0" />
      <geometry>
        <box size="0.112 0.03 0.012" />
        </geometry>
      <material name="warm_white_plastic">
        <color rgba="0.92 0.89 0.82 1" />
        </material>
      </visual>
    <visual name="steam_vent">
      <origin xyz="0 -0.153 0.058" rpy="0 0 0" />
      <geometry>
        <cylinder radius="0.012" length="0.006" />
        </geometry>
      <material name="soft_black">
        <color rgba="0.015 0.015 0.014 1" />
        </material>
      </visual>
    <collision name="lid_dome">
      <geometry>
        <mesh filename="assets/meshes/lid_dome.obj" />
        </geometry>
      </collision>
    <collision name="lid_rim">
      <origin xyz="0 -0.153 -0.006" rpy="0 0 0" />
      <geometry>
        <mesh filename="assets/meshes/lid_rim.obj" />
        </geometry>
      </collision>
    <collision name="hinge_barrel">
      <origin xyz="0 0 0" rpy="0 1.5708 0" />
      <geometry>
        <cylinder radius="0.011" length="0.105" />
        </geometry>
      </collision>
    <collision name="hinge_leaf">
      <origin xyz="0 -0.008 -0.004" rpy="0 0 0" />
      <geometry>
        <box size="0.112 0.03 0.012" />
        </geometry>
      </collision>
    <collision name="steam_vent">
      <origin xyz="0 -0.153 0.058" rpy="0 0 0" />
      <geometry>
        <cylinder radius="0.012" length="0.006" />
        </geometry>
      </collision>
    </link>
  <link name="latch_button">
    <visual name="button_cap">
      <origin xyz="0 0 0" rpy="1.5708 0 0" />
      <geometry>
        <mesh filename="assets/meshes/latch_button_cap.obj" />
        </geometry>
      <material name="button_light_gray">
        <color rgba="0.78 0.8 0.78 1" />
        </material>
      </visual>
    <visual name="button_mark">
      <origin xyz="0 -0.0083 0" rpy="0 0 0" />
      <geometry>
        <box size="0.02 0.0008 0.003" />
        </geometry>
      <material name="charcoal_panel">
        <color rgba="0.1 0.11 0.12 1" />
        </material>
      </visual>
    <collision name="button_cap">
      <origin xyz="0 0 0" rpy="1.5708 0 0" />
      <geometry>
        <mesh filename="assets/meshes/latch_button_cap.obj" />
        </geometry>
      </collision>
    <collision name="button_mark">
      <origin xyz="0 -0.0083 0" rpy="0 0 0" />
      <geometry>
        <box size="0.02 0.0008 0.003" />
        </geometry>
      </collision>
    </link>
  <link name="menu_button_0">
    <visual name="button_cap">
      <origin xyz="0 0 0" rpy="1.5708 0 0" />
      <geometry>
        <mesh filename="assets/meshes/menu_button_0_cap.obj" />
        </geometry>
      <material name="button_light_gray">
        <color rgba="0.78 0.8 0.78 1" />
        </material>
      </visual>
    <visual name="button_mark">
      <origin xyz="0 -0.0062 0" rpy="0 0 0" />
      <geometry>
        <box size="0.014 0.0007 0.0025" />
        </geometry>
      <material name="printed_white">
        <color rgba="0.95 0.95 0.9 1" />
        </material>
      </visual>
    <collision name="button_cap">
      <origin xyz="0 0 0" rpy="1.5708 0 0" />
      <geometry>
        <mesh filename="assets/meshes/menu_button_0_cap.obj" />
        </geometry>
      </collision>
    <collision name="button_mark">
      <origin xyz="0 -0.0062 0" rpy="0 0 0" />
      <geometry>
        <box size="0.014 0.0007 0.0025" />
        </geometry>
      </collision>
    </link>
  <link name="menu_button_1">
    <visual name="button_cap">
      <origin xyz="0 0 0" rpy="1.5708 0 0" />
      <geometry>
        <mesh filename="assets/meshes/menu_button_1_cap.obj" />
        </geometry>
      <material name="button_light_gray">
        <color rgba="0.78 0.8 0.78 1" />
        </material>
      </visual>
    <visual name="button_mark">
      <origin xyz="0 -0.0062 0" rpy="0 0 0" />
      <geometry>
        <box size="0.014 0.0007 0.0025" />
        </geometry>
      <material name="printed_white">
        <color rgba="0.95 0.95 0.9 1" />
        </material>
      </visual>
    <collision name="button_cap">
      <origin xyz="0 0 0" rpy="1.5708 0 0" />
      <geometry>
        <mesh filename="assets/meshes/menu_button_1_cap.obj" />
        </geometry>
      </collision>
    <collision name="button_mark">
      <origin xyz="0 -0.0062 0" rpy="0 0 0" />
      <geometry>
        <box size="0.014 0.0007 0.0025" />
        </geometry>
      </collision>
    </link>
  <joint name="body_to_lid" type="revolute">
    <origin xyz="0 0.153 0.232" rpy="0 0 0" />
    <parent link="body" />
    <child link="lid" />
    <axis xyz="-1 0 0" />
    <limit effort="8" velocity="2" lower="0" upper="1.2" />
    </joint>
  <joint name="body_to_latch_button" type="prismatic">
    <origin xyz="0 -0.148 0.166" rpy="0 0 0" />
    <parent link="body" />
    <child link="latch_button" />
    <axis xyz="0 1 0" />
    <limit effort="2" velocity="0.12" lower="0" upper="0.006" />
    </joint>
  <joint name="body_to_menu_button_0" type="prismatic">
    <origin xyz="-0.026 -0.146 0.092" rpy="0 0 0" />
    <parent link="body" />
    <child link="menu_button_0" />
    <axis xyz="0 1 0" />
    <limit effort="1.2" velocity="0.1" lower="0" upper="0.0045" />
    </joint>
  <joint name="body_to_menu_button_1" type="prismatic">
    <origin xyz="0.026 -0.146 0.092" rpy="0 0 0" />
    <parent link="body" />
    <child link="menu_button_1" />
    <axis xyz="0 1 0" />
    <limit effort="1.2" velocity="0.1" lower="0" upper="0.0045" />
    </joint>
  </robot>
