<robot name="platter_trunnion_table">
  <material name="painted_casting">
    <color rgba="0.18 0.25 0.3 1" />
    </material>
  <material name="dark_iron">
    <color rgba="0.05 0.06 0.065 1" />
    </material>
  <material name="brushed_steel">
    <color rgba="0.62 0.64 0.66 1" />
    </material>
  <material name="oiled_bearing">
    <color rgba="0.02 0.022 0.024 1" />
    </material>
  <material name="table_blue">
    <color rgba="0.13 0.22 0.33 1" />
    </material>
  <material name="slot_black">
    <color rgba="0.005 0.006 0.007 1" />
    </material>
  <link name="base">
    <visual name="floor_plinth">
      <origin xyz="0 0 0.04" rpy="0 0 0" />
      <geometry>
        <cylinder radius="0.58" length="0.08" />
        </geometry>
      <material name="dark_iron">
        <color rgba="0.05 0.06 0.065 1" />
        </material>
      </visual>
    <visual name="fixed_pedestal">
      <origin xyz="0 0 0.16" rpy="0 0 0" />
      <geometry>
        <cylinder radius="0.24" length="0.16" />
        </geometry>
      <material name="painted_casting">
        <color rgba="0.18 0.25 0.3 1" />
        </material>
      </visual>
    <visual name="stationary_bearing_race">
      <origin xyz="0 0 0.2275" rpy="0 0 0" />
      <geometry>
        <cylinder radius="0.36" length="0.025" />
        </geometry>
      <material name="oiled_bearing">
        <color rgba="0.02 0.022 0.024 1" />
        </material>
      </visual>
    <collision name="floor_plinth">
      <origin xyz="0 0 0.04" rpy="0 0 0" />
      <geometry>
        <cylinder radius="0.58" length="0.08" />
        </geometry>
      </collision>
    <collision name="fixed_pedestal">
      <origin xyz="0 0 0.16" rpy="0 0 0" />
      <geometry>
        <cylinder radius="0.24" length="0.16" />
        </geometry>
      </collision>
    <collision name="stationary_bearing_race">
      <origin xyz="0 0 0.2275" rpy="0 0 0" />
      <geometry>
        <cylinder radius="0.36" length="0.025" />
        </geometry>
      </collision>
    </link>
  <link name="platter">
    <visual name="rotary_platter">
      <origin xyz="0 0 0.04" rpy="0 0 0" />
      <geometry>
        <cylinder radius="0.49" length="0.08" />
        </geometry>
      <material name="painted_casting">
        <color rgba="0.18 0.25 0.3 1" />
        </material>
      </visual>
    <visual name="top_bearing_race">
      <origin xyz="0 0 0.089" rpy="0 0 0" />
      <geometry>
        <cylinder radius="0.31" length="0.018" />
        </geometry>
      <material name="oiled_bearing">
        <color rgba="0.02 0.022 0.024 1" />
        </material>
      </visual>
    <visual name="support_tie_bar">
      <origin xyz="0 0 0.0975" rpy="0 0 0" />
      <geometry>
        <box size="0.68 0.16 0.035" />
        </geometry>
      <material name="dark_iron">
        <color rgba="0.05 0.06 0.065 1" />
        </material>
      </visual>
    <visual name="support_pos_column">
      <origin xyz="0.36 0 0.27" rpy="0 0 0" />
      <geometry>
        <box size="0.08 0.18 0.38" />
        </geometry>
      <material name="painted_casting">
        <color rgba="0.18 0.25 0.3 1" />
        </material>
      </visual>
    <visual name="support_pos_saddle">
      <origin xyz="0.36 0 0.4775" rpy="0 0 0" />
      <geometry>
        <box size="0.1 0.16 0.035" />
        </geometry>
      <material name="oiled_bearing">
        <color rgba="0.02 0.022 0.024 1" />
        </material>
      </visual>
    <visual name="support_pos_front_cheek">
      <origin xyz="0.36 0.075 0.54" rpy="0 0 0" />
      <geometry>
        <box size="0.1 0.035 0.14" />
        </geometry>
      <material name="painted_casting">
        <color rgba="0.18 0.25 0.3 1" />
        </material>
      </visual>
    <visual name="support_pos_rear_cheek">
      <origin xyz="0.36 -0.075 0.54" rpy="0 0 0" />
      <geometry>
        <box size="0.1 0.035 0.14" />
        </geometry>
      <material name="painted_casting">
        <color rgba="0.18 0.25 0.3 1" />
        </material>
      </visual>
    <visual name="support_neg_column">
      <origin xyz="-0.36 0 0.27" rpy="0 0 0" />
      <geometry>
        <box size="0.08 0.18 0.38" />
        </geometry>
      <material name="painted_casting">
        <color rgba="0.18 0.25 0.3 1" />
        </material>
      </visual>
    <visual name="support_neg_saddle">
      <origin xyz="-0.36 0 0.4775" rpy="0 0 0" />
      <geometry>
        <box size="0.1 0.16 0.035" />
        </geometry>
      <material name="oiled_bearing">
        <color rgba="0.02 0.022 0.024 1" />
        </material>
      </visual>
    <visual name="support_neg_front_cheek">
      <origin xyz="-0.36 0.075 0.54" rpy="0 0 0" />
      <geometry>
        <box size="0.1 0.035 0.14" />
        </geometry>
      <material name="painted_casting">
        <color rgba="0.18 0.25 0.3 1" />
        </material>
      </visual>
    <visual name="support_neg_rear_cheek">
      <origin xyz="-0.36 -0.075 0.54" rpy="0 0 0" />
      <geometry>
        <box size="0.1 0.035 0.14" />
        </geometry>
      <material name="painted_casting">
        <color rgba="0.18 0.25 0.3 1" />
        </material>
      </visual>
    <collision name="rotary_platter">
      <origin xyz="0 0 0.04" rpy="0 0 0" />
      <geometry>
        <cylinder radius="0.49" length="0.08" />
        </geometry>
      </collision>
    <collision name="top_bearing_race">
      <origin xyz="0 0 0.089" rpy="0 0 0" />
      <geometry>
        <cylinder radius="0.31" length="0.018" />
        </geometry>
      </collision>
    <collision name="support_tie_bar">
      <origin xyz="0 0 0.0975" rpy="0 0 0" />
      <geometry>
        <box size="0.68 0.16 0.035" />
        </geometry>
      </collision>
    <collision name="support_pos_column">
      <origin xyz="0.36 0 0.27" rpy="0 0 0" />
      <geometry>
        <box size="0.08 0.18 0.38" />
        </geometry>
      </collision>
    <collision name="support_pos_saddle">
      <origin xyz="0.36 0 0.4775" rpy="0 0 0" />
      <geometry>
        <box size="0.1 0.16 0.035" />
        </geometry>
      </collision>
    <collision name="support_pos_front_cheek">
      <origin xyz="0.36 0.075 0.54" rpy="0 0 0" />
      <geometry>
        <box size="0.1 0.035 0.14" />
        </geometry>
      </collision>
    <collision name="support_pos_rear_cheek">
      <origin xyz="0.36 -0.075 0.54" rpy="0 0 0" />
      <geometry>
        <box size="0.1 0.035 0.14" />
        </geometry>
      </collision>
    <collision name="support_neg_column">
      <origin xyz="-0.36 0 0.27" rpy="0 0 0" />
      <geometry>
        <box size="0.08 0.18 0.38" />
        </geometry>
      </collision>
    <collision name="support_neg_saddle">
      <origin xyz="-0.36 0 0.4775" rpy="0 0 0" />
      <geometry>
        <box size="0.1 0.16 0.035" />
        </geometry>
      </collision>
    <collision name="support_neg_front_cheek">
      <origin xyz="-0.36 0.075 0.54" rpy="0 0 0" />
      <geometry>
        <box size="0.1 0.035 0.14" />
        </geometry>
      </collision>
    <collision name="support_neg_rear_cheek">
      <origin xyz="-0.36 -0.075 0.54" rpy="0 0 0" />
      <geometry>
        <box size="0.1 0.035 0.14" />
        </geometry>
      </collision>
    </link>
  <link name="work_table">
    <visual name="trunnion_shaft">
      <origin xyz="0 0 0" rpy="0 1.5708 0" />
      <geometry>
        <cylinder radius="0.025" length="0.8" />
        </geometry>
      <material name="brushed_steel">
        <color rgba="0.62 0.64 0.66 1" />
        </material>
      </visual>
    <visual name="table_plate">
      <origin xyz="0 0 0.055" rpy="0 0 0" />
      <geometry>
        <box size="0.5 0.34 0.05" />
        </geometry>
      <material name="table_blue">
        <color rgba="0.13 0.22 0.33 1" />
        </material>
      </visual>
    <visual name="shaft_clamp_pos">
      <origin xyz="0.16 0 0.025" rpy="0 0 0" />
      <geometry>
        <box size="0.08 0.11 0.07" />
        </geometry>
      <material name="painted_casting">
        <color rgba="0.18 0.25 0.3 1" />
        </material>
      </visual>
    <visual name="shaft_clamp_neg">
      <origin xyz="-0.16 0 0.025" rpy="0 0 0" />
      <geometry>
        <box size="0.08 0.11 0.07" />
        </geometry>
      <material name="painted_casting">
        <color rgba="0.18 0.25 0.3 1" />
        </material>
      </visual>
    <visual name="tee_slot_000">
      <origin xyz="0 -0.105 0.083" rpy="0 0 0" />
      <geometry>
        <box size="0.46 0.012 0.006" />
        </geometry>
      <material name="slot_black">
        <color rgba="0.005 0.006 0.007 1" />
        </material>
      </visual>
    <visual name="tee_slot_105">
      <origin xyz="0 0 0.083" rpy="0 0 0" />
      <geometry>
        <box size="0.46 0.012 0.006" />
        </geometry>
      <material name="slot_black">
        <color rgba="0.005 0.006 0.007 1" />
        </material>
      </visual>
    <visual name="tee_slot_210">
      <origin xyz="0 0.105 0.083" rpy="0 0 0" />
      <geometry>
        <box size="0.46 0.012 0.006" />
        </geometry>
      <material name="slot_black">
        <color rgba="0.005 0.006 0.007 1" />
        </material>
      </visual>
    <visual name="front_table_lip">
      <origin xyz="0 0.179 0.087" rpy="0 0 0" />
      <geometry>
        <box size="0.52 0.018 0.018" />
        </geometry>
      <material name="brushed_steel">
        <color rgba="0.62 0.64 0.66 1" />
        </material>
      </visual>
    <visual name="rear_table_lip">
      <origin xyz="0 -0.179 0.087" rpy="0 0 0" />
      <geometry>
        <box size="0.52 0.018 0.018" />
        </geometry>
      <material name="brushed_steel">
        <color rgba="0.62 0.64 0.66 1" />
        </material>
      </visual>
    <collision name="trunnion_shaft">
      <origin xyz="0 0 0" rpy="0 1.5708 0" />
      <geometry>
        <cylinder radius="0.025" length="0.8" />
        </geometry>
      </collision>
    <collision name="table_plate">
      <origin xyz="0 0 0.055" rpy="0 0 0" />
      <geometry>
        <box size="0.5 0.34 0.05" />
        </geometry>
      </collision>
    <collision name="shaft_clamp_pos">
      <origin xyz="0.16 0 0.025" rpy="0 0 0" />
      <geometry>
        <box size="0.08 0.11 0.07" />
        </geometry>
      </collision>
    <collision name="shaft_clamp_neg">
      <origin xyz="-0.16 0 0.025" rpy="0 0 0" />
      <geometry>
        <box size="0.08 0.11 0.07" />
        </geometry>
      </collision>
    <collision name="tee_slot_000">
      <origin xyz="0 -0.105 0.083" rpy="0 0 0" />
      <geometry>
        <box size="0.46 0.012 0.006" />
        </geometry>
      </collision>
    <collision name="tee_slot_105">
      <origin xyz="0 0 0.083" rpy="0 0 0" />
      <geometry>
        <box size="0.46 0.012 0.006" />
        </geometry>
      </collision>
    <collision name="tee_slot_210">
      <origin xyz="0 0.105 0.083" rpy="0 0 0" />
      <geometry>
        <box size="0.46 0.012 0.006" />
        </geometry>
      </collision>
    <collision name="front_table_lip">
      <origin xyz="0 0.179 0.087" rpy="0 0 0" />
      <geometry>
        <box size="0.52 0.018 0.018" />
        </geometry>
      </collision>
    <collision name="rear_table_lip">
      <origin xyz="0 -0.179 0.087" rpy="0 0 0" />
      <geometry>
        <box size="0.52 0.018 0.018" />
        </geometry>
      </collision>
    </link>
  <joint name="platter_rotation" type="revolute">
    <origin xyz="0 0 0.24" rpy="0 0 0" />
    <parent link="base" />
    <child link="platter" />
    <axis xyz="0 0 1" />
    <limit effort="250" velocity="1" lower="-3.14159" upper="3.14159" />
    </joint>
  <joint name="trunnion_tilt" type="revolute">
    <origin xyz="0 0 0.52" rpy="0 0 0" />
    <parent link="platter" />
    <child link="work_table" />
    <axis xyz="1 0 0" />
    <limit effort="160" velocity="0.8" lower="-0.65" upper="0.65" />
    </joint>
  </robot>
