<robot name="cost_optimized_stationary_bike">
  <material name="powder_coated_steel">
    <color rgba="0.06 0.07 0.075 1" />
    </material>
  <material name="matte_black_plastic">
    <color rgba="0.015 0.016 0.017 1" />
    </material>
  <material name="graphite_housing">
    <color rgba="0.18 0.19 0.2 1" />
    </material>
  <material name="molded_seam_shadow">
    <color rgba="0.02 0.02 0.022 1" />
    </material>
  <material name="brushed_bearing_steel">
    <color rgba="0.62 0.64 0.62 1" />
    </material>
  <material name="soft_rubber">
    <color rgba="0.03 0.03 0.028 1" />
    </material>
  <material name="textured_saddle_foam">
    <color rgba="0.025 0.025 0.023 1" />
    </material>
  <material name="assembly_mark_yellow">
    <color rgba="0.95 0.68 0.08 1" />
    </material>
  <link name="frame">
    <visual name="base_rail_0">
      <origin xyz="0 -0.22 0.05" rpy="0 0 0" />
      <geometry>
        <box size="1.2 0.045 0.06" />
        </geometry>
      <material name="powder_coated_steel">
        <color rgba="0.06 0.07 0.075 1" />
        </material>
      </visual>
    <visual name="base_rail_1">
      <origin xyz="0 0.22 0.05" rpy="0 0 0" />
      <geometry>
        <box size="1.2 0.045 0.06" />
        </geometry>
      <material name="powder_coated_steel">
        <color rgba="0.06 0.07 0.075 1" />
        </material>
      </visual>
    <visual name="front_cross_foot">
      <origin xyz="-0.545 0 0.05" rpy="0 0 0" />
      <geometry>
        <box size="0.095 0.62 0.06" />
        </geometry>
      <material name="powder_coated_steel">
        <color rgba="0.06 0.07 0.075 1" />
        </material>
      </visual>
    <visual name="rear_cross_foot">
      <origin xyz="0.545 0 0.05" rpy="0 0 0" />
      <geometry>
        <box size="0.095 0.62 0.06" />
        </geometry>
      <material name="powder_coated_steel">
        <color rgba="0.06 0.07 0.075 1" />
        </material>
      </visual>
    <visual name="rubber_foot_0">
      <origin xyz="-0.545 -0.335 0.023" rpy="0 0 0" />
      <geometry>
        <box size="0.12 0.055 0.026" />
        </geometry>
      <material name="soft_rubber">
        <color rgba="0.03 0.03 0.028 1" />
        </material>
      </visual>
    <visual name="rubber_foot_1">
      <origin xyz="-0.545 0.335 0.023" rpy="0 0 0" />
      <geometry>
        <box size="0.12 0.055 0.026" />
        </geometry>
      <material name="soft_rubber">
        <color rgba="0.03 0.03 0.028 1" />
        </material>
      </visual>
    <visual name="rubber_foot_2">
      <origin xyz="0.545 -0.335 0.023" rpy="0 0 0" />
      <geometry>
        <box size="0.12 0.055 0.026" />
        </geometry>
      <material name="soft_rubber">
        <color rgba="0.03 0.03 0.028 1" />
        </material>
      </visual>
    <visual name="rubber_foot_3">
      <origin xyz="0.545 0.335 0.023" rpy="0 0 0" />
      <geometry>
        <box size="0.12 0.055 0.026" />
        </geometry>
      <material name="soft_rubber">
        <color rgba="0.03 0.03 0.028 1" />
        </material>
      </visual>
    <visual name="main_tube">
      <origin xyz="0.1775 0 0.3525" rpy="0 -2.44915 0" />
      <geometry>
        <box size="0.838004 0.07 0.082" />
        </geometry>
      <material name="powder_coated_steel">
        <color rgba="0.06 0.07 0.075 1" />
        </material>
      </visual>
    <visual name="front_upright">
      <origin xyz="-0.525 0 0.4" rpy="0 -1.60204 0" />
      <geometry>
        <box size="0.640312 0.07 0.075" />
        </geometry>
      <material name="powder_coated_steel">
        <color rgba="0.06 0.07 0.075 1" />
        </material>
      </visual>
    <visual name="seat_strut">
      <origin xyz="0.345 0 0.31" rpy="0 -2.11759 0" />
      <geometry>
        <box size="0.538516 0.06 0.07" />
        </geometry>
      <material name="powder_coated_steel">
        <color rgba="0.06 0.07 0.075 1" />
        </material>
      </visual>
    <visual name="housing_bridge">
      <origin xyz="-0.3775 0 0.2625" rpy="0 -0.303734 0" />
      <geometry>
        <box size="0.35107 0.055 0.06" />
        </geometry>
      <material name="powder_coated_steel">
        <color rgba="0.06 0.07 0.075 1" />
        </material>
      </visual>
    <visual name="housing_mount_plate">
      <origin xyz="-0.245 0 0.158" rpy="0 0 0" />
      <geometry>
        <box size="0.18 0.095 0.03" />
        </geometry>
      <material name="powder_coated_steel">
        <color rgba="0.06 0.07 0.075 1" />
        </material>
      </visual>
    <visual name="flywheel_cover">
      <origin xyz="-0.25 0 0.43" rpy="1.5708 0 0" />
      <geometry>
        <cylinder radius="0.275" length="0.15" />
        </geometry>
      <material name="graphite_housing">
        <color rgba="0.18 0.19 0.2 1" />
        </material>
      </visual>
    <visual name="cover_seam_0">
      <origin xyz="-0.25 -0.082 0.43" rpy="1.5708 0 0" />
      <geometry>
        <cylinder radius="0.279" length="0.012" />
        </geometry>
      <material name="molded_seam_shadow">
        <color rgba="0.02 0.02 0.022 1" />
        </material>
      </visual>
    <visual name="cover_seam_1">
      <origin xyz="-0.25 0.082 0.43" rpy="1.5708 0 0" />
      <geometry>
        <cylinder radius="0.279" length="0.012" />
        </geometry>
      <material name="molded_seam_shadow">
        <color rgba="0.02 0.02 0.022 1" />
        </material>
      </visual>
    <visual name="bearing_boss">
      <origin xyz="-0.25 0 0.43" rpy="1.5708 0 0" />
      <geometry>
        <cylinder radius="0.062" length="0.19" />
        </geometry>
      <material name="graphite_housing">
        <color rgba="0.18 0.19 0.2 1" />
        </material>
      </visual>
    <visual name="bearing_insert">
      <origin xyz="-0.25 0 0.43" rpy="1.5708 0 0" />
      <geometry>
        <cylinder radius="0.036" length="0.205" />
        </geometry>
      <material name="brushed_bearing_steel">
        <color rgba="0.62 0.64 0.62 1" />
        </material>
      </visual>
    <visual name="cover_screw_boss_0">
      <origin xyz="-0.25 0.088 0.645" rpy="1.5708 0 0" />
      <geometry>
        <cylinder radius="0.018" length="0.01" />
        </geometry>
      <material name="molded_seam_shadow">
        <color rgba="0.02 0.02 0.022 1" />
        </material>
      </visual>
    <visual name="cover_screw_boss_1">
      <origin xyz="-0.435 0.088 0.525" rpy="1.5708 0 0" />
      <geometry>
        <cylinder radius="0.018" length="0.01" />
        </geometry>
      <material name="molded_seam_shadow">
        <color rgba="0.02 0.02 0.022 1" />
        </material>
      </visual>
    <visual name="cover_screw_boss_2">
      <origin xyz="-0.42 0.088 0.31" rpy="1.5708 0 0" />
      <geometry>
        <cylinder radius="0.018" length="0.01" />
        </geometry>
      <material name="molded_seam_shadow">
        <color rgba="0.02 0.02 0.022 1" />
        </material>
      </visual>
    <visual name="cover_screw_boss_3">
      <origin xyz="-0.095 0.088 0.275" rpy="1.5708 0 0" />
      <geometry>
        <cylinder radius="0.018" length="0.01" />
        </geometry>
      <material name="molded_seam_shadow">
        <color rgba="0.02 0.02 0.022 1" />
        </material>
      </visual>
    <visual name="saddle_sleeve_wall_x0">
      <origin xyz="0.177 0 0.68" rpy="0 0 0" />
      <geometry>
        <box size="0.008 0.064 0.32" />
        </geometry>
      <material name="powder_coated_steel">
        <color rgba="0.06 0.07 0.075 1" />
        </material>
      </visual>
    <visual name="saddle_sleeve_wall_x1">
      <origin xyz="0.233 0 0.68" rpy="0 0 0" />
      <geometry>
        <box size="0.008 0.064 0.32" />
        </geometry>
      <material name="powder_coated_steel">
        <color rgba="0.06 0.07 0.075 1" />
        </material>
      </visual>
    <visual name="saddle_sleeve_wall_y0">
      <origin xyz="0.205 -0.028 0.68" rpy="0 0 0" />
      <geometry>
        <box size="0.064 0.008 0.32" />
        </geometry>
      <material name="powder_coated_steel">
        <color rgba="0.06 0.07 0.075 1" />
        </material>
      </visual>
    <visual name="saddle_sleeve_wall_y1">
      <origin xyz="0.205 0.028 0.68" rpy="0 0 0" />
      <geometry>
        <box size="0.064 0.008 0.32" />
        </geometry>
      <material name="powder_coated_steel">
        <color rgba="0.06 0.07 0.075 1" />
        </material>
      </visual>
    <visual name="saddle_collar_wall_x0">
      <origin xyz="0.174 0 0.8" rpy="0 0 0" />
      <geometry>
        <box size="0.012 0.1 0.075" />
        </geometry>
      <material name="powder_coated_steel">
        <color rgba="0.06 0.07 0.075 1" />
        </material>
      </visual>
    <visual name="saddle_collar_wall_x1">
      <origin xyz="0.236 0 0.8" rpy="0 0 0" />
      <geometry>
        <box size="0.012 0.1 0.075" />
        </geometry>
      <material name="powder_coated_steel">
        <color rgba="0.06 0.07 0.075 1" />
        </material>
      </visual>
    <visual name="saddle_collar_wall_y0">
      <origin xyz="0.205 -0.031 0.8" rpy="0 0 0" />
      <geometry>
        <box size="0.1 0.012 0.075" />
        </geometry>
      <material name="powder_coated_steel">
        <color rgba="0.06 0.07 0.075 1" />
        </material>
      </visual>
    <visual name="saddle_collar_wall_y1">
      <origin xyz="0.205 0.031 0.8" rpy="0 0 0" />
      <geometry>
        <box size="0.1 0.012 0.075" />
        </geometry>
      <material name="powder_coated_steel">
        <color rgba="0.06 0.07 0.075 1" />
        </material>
      </visual>
    <visual name="saddle_clamp_boss">
      <origin xyz="0.205 0.067 0.795" rpy="1.5708 0 0" />
      <geometry>
        <cylinder radius="0.02" length="0.046" />
        </geometry>
      <material name="powder_coated_steel">
        <color rgba="0.06 0.07 0.075 1" />
        </material>
      </visual>
    <visual name="saddle_pad_upper">
      <origin xyz="0.205 0.046 0.832" rpy="0 0 0" />
      <geometry>
        <box size="0.08 0.012 0.024" />
        </geometry>
      <material name="powder_coated_steel">
        <color rgba="0.06 0.07 0.075 1" />
        </material>
      </visual>
    <visual name="saddle_pad_lower">
      <origin xyz="0.205 0.046 0.758" rpy="0 0 0" />
      <geometry>
        <box size="0.08 0.012 0.024" />
        </geometry>
      <material name="powder_coated_steel">
        <color rgba="0.06 0.07 0.075 1" />
        </material>
      </visual>
    <visual name="saddle_boss_web_0">
      <origin xyz="0.189 0.046 0.795" rpy="0 0 0" />
      <geometry>
        <box size="0.01 0.014 0.052" />
        </geometry>
      <material name="powder_coated_steel">
        <color rgba="0.06 0.07 0.075 1" />
        </material>
      </visual>
    <visual name="saddle_boss_web_1">
      <origin xyz="0.221 0.046 0.795" rpy="0 0 0" />
      <geometry>
        <box size="0.01 0.014 0.052" />
        </geometry>
      <material name="powder_coated_steel">
        <color rgba="0.06 0.07 0.075 1" />
        </material>
      </visual>
    <visual name="bar_sleeve_wall_x0">
      <origin xyz="-0.563 0 0.865" rpy="0 0 0" />
      <geometry>
        <box size="0.008 0.064 0.3" />
        </geometry>
      <material name="powder_coated_steel">
        <color rgba="0.06 0.07 0.075 1" />
        </material>
      </visual>
    <visual name="bar_sleeve_wall_x1">
      <origin xyz="-0.507 0 0.865" rpy="0 0 0" />
      <geometry>
        <box size="0.008 0.064 0.3" />
        </geometry>
      <material name="powder_coated_steel">
        <color rgba="0.06 0.07 0.075 1" />
        </material>
      </visual>
    <visual name="bar_sleeve_wall_y0">
      <origin xyz="-0.535 -0.028 0.865" rpy="0 0 0" />
      <geometry>
        <box size="0.064 0.008 0.3" />
        </geometry>
      <material name="powder_coated_steel">
        <color rgba="0.06 0.07 0.075 1" />
        </material>
      </visual>
    <visual name="bar_sleeve_wall_y1">
      <origin xyz="-0.535 0.028 0.865" rpy="0 0 0" />
      <geometry>
        <box size="0.064 0.008 0.3" />
        </geometry>
      <material name="powder_coated_steel">
        <color rgba="0.06 0.07 0.075 1" />
        </material>
      </visual>
    <visual name="bar_collar_wall_x0">
      <origin xyz="-0.566 0 0.985" rpy="0 0 0" />
      <geometry>
        <box size="0.012 0.1 0.075" />
        </geometry>
      <material name="powder_coated_steel">
        <color rgba="0.06 0.07 0.075 1" />
        </material>
      </visual>
    <visual name="bar_collar_wall_x1">
      <origin xyz="-0.504 0 0.985" rpy="0 0 0" />
      <geometry>
        <box size="0.012 0.1 0.075" />
        </geometry>
      <material name="powder_coated_steel">
        <color rgba="0.06 0.07 0.075 1" />
        </material>
      </visual>
    <visual name="bar_collar_wall_y0">
      <origin xyz="-0.535 -0.031 0.985" rpy="0 0 0" />
      <geometry>
        <box size="0.1 0.012 0.075" />
        </geometry>
      <material name="powder_coated_steel">
        <color rgba="0.06 0.07 0.075 1" />
        </material>
      </visual>
    <visual name="bar_collar_wall_y1">
      <origin xyz="-0.535 0.031 0.985" rpy="0 0 0" />
      <geometry>
        <box size="0.1 0.012 0.075" />
        </geometry>
      <material name="powder_coated_steel">
        <color rgba="0.06 0.07 0.075 1" />
        </material>
      </visual>
    <visual name="bar_clamp_boss">
      <origin xyz="-0.535 0.067 0.985" rpy="1.5708 0 0" />
      <geometry>
        <cylinder radius="0.02" length="0.046" />
        </geometry>
      <material name="powder_coated_steel">
        <color rgba="0.06 0.07 0.075 1" />
        </material>
      </visual>
    <visual name="bar_pad_upper">
      <origin xyz="-0.535 0.046 1.017" rpy="0 0 0" />
      <geometry>
        <box size="0.08 0.012 0.024" />
        </geometry>
      <material name="powder_coated_steel">
        <color rgba="0.06 0.07 0.075 1" />
        </material>
      </visual>
    <visual name="bar_pad_lower">
      <origin xyz="-0.535 0.046 0.943" rpy="0 0 0" />
      <geometry>
        <box size="0.08 0.012 0.024" />
        </geometry>
      <material name="powder_coated_steel">
        <color rgba="0.06 0.07 0.075 1" />
        </material>
      </visual>
    <visual name="bar_boss_web_0">
      <origin xyz="-0.551 0.046 0.985" rpy="0 0 0" />
      <geometry>
        <box size="0.01 0.014 0.052" />
        </geometry>
      <material name="powder_coated_steel">
        <color rgba="0.06 0.07 0.075 1" />
        </material>
      </visual>
    <visual name="bar_boss_web_1">
      <origin xyz="-0.519 0.046 0.985" rpy="0 0 0" />
      <geometry>
        <box size="0.01 0.014 0.052" />
        </geometry>
      <material name="powder_coated_steel">
        <color rgba="0.06 0.07 0.075 1" />
        </material>
      </visual>
    <visual name="resistance_boss">
      <origin xyz="-0.25 0 0.705" rpy="0 0 0" />
      <geometry>
        <cylinder radius="0.042" length="0.035" />
        </geometry>
      <material name="graphite_housing">
        <color rgba="0.18 0.19 0.2 1" />
        </material>
      </visual>
    <visual name="resistance_index_mark">
      <origin xyz="-0.25 0.04 0.725" rpy="0 0 0" />
      <geometry>
        <box size="0.008 0.006 0.005" />
        </geometry>
      <material name="assembly_mark_yellow">
        <color rgba="0.95 0.68 0.08 1" />
        </material>
      </visual>
    <collision name="base_rail_0">
      <origin xyz="0 -0.22 0.05" rpy="0 0 0" />
      <geometry>
        <box size="1.2 0.045 0.06" />
        </geometry>
      </collision>
    <collision name="base_rail_1">
      <origin xyz="0 0.22 0.05" rpy="0 0 0" />
      <geometry>
        <box size="1.2 0.045 0.06" />
        </geometry>
      </collision>
    <collision name="front_cross_foot">
      <origin xyz="-0.545 0 0.05" rpy="0 0 0" />
      <geometry>
        <box size="0.095 0.62 0.06" />
        </geometry>
      </collision>
    <collision name="rear_cross_foot">
      <origin xyz="0.545 0 0.05" rpy="0 0 0" />
      <geometry>
        <box size="0.095 0.62 0.06" />
        </geometry>
      </collision>
    <collision name="rubber_foot_0">
      <origin xyz="-0.545 -0.335 0.023" rpy="0 0 0" />
      <geometry>
        <box size="0.12 0.055 0.026" />
        </geometry>
      </collision>
    <collision name="rubber_foot_1">
      <origin xyz="-0.545 0.335 0.023" rpy="0 0 0" />
      <geometry>
        <box size="0.12 0.055 0.026" />
        </geometry>
      </collision>
    <collision name="rubber_foot_2">
      <origin xyz="0.545 -0.335 0.023" rpy="0 0 0" />
      <geometry>
        <box size="0.12 0.055 0.026" />
        </geometry>
      </collision>
    <collision name="rubber_foot_3">
      <origin xyz="0.545 0.335 0.023" rpy="0 0 0" />
      <geometry>
        <box size="0.12 0.055 0.026" />
        </geometry>
      </collision>
    <collision name="main_tube">
      <origin xyz="0.1775 0 0.3525" rpy="0 -2.44915 0" />
      <geometry>
        <box size="0.838004 0.07 0.082" />
        </geometry>
      </collision>
    <collision name="front_upright">
      <origin xyz="-0.525 0 0.4" rpy="0 -1.60204 0" />
      <geometry>
        <box size="0.640312 0.07 0.075" />
        </geometry>
      </collision>
    <collision name="seat_strut">
      <origin xyz="0.345 0 0.31" rpy="0 -2.11759 0" />
      <geometry>
        <box size="0.538516 0.06 0.07" />
        </geometry>
      </collision>
    <collision name="housing_bridge">
      <origin xyz="-0.3775 0 0.2625" rpy="0 -0.303734 0" />
      <geometry>
        <box size="0.35107 0.055 0.06" />
        </geometry>
      </collision>
    <collision name="housing_mount_plate">
      <origin xyz="-0.245 0 0.158" rpy="0 0 0" />
      <geometry>
        <box size="0.18 0.095 0.03" />
        </geometry>
      </collision>
    <collision name="flywheel_cover">
      <origin xyz="-0.25 0 0.43" rpy="1.5708 0 0" />
      <geometry>
        <cylinder radius="0.275" length="0.15" />
        </geometry>
      </collision>
    <collision name="cover_seam_0">
      <origin xyz="-0.25 -0.082 0.43" rpy="1.5708 0 0" />
      <geometry>
        <cylinder radius="0.279" length="0.012" />
        </geometry>
      </collision>
    <collision name="cover_seam_1">
      <origin xyz="-0.25 0.082 0.43" rpy="1.5708 0 0" />
      <geometry>
        <cylinder radius="0.279" length="0.012" />
        </geometry>
      </collision>
    <collision name="bearing_boss">
      <origin xyz="-0.25 0 0.43" rpy="1.5708 0 0" />
      <geometry>
        <cylinder radius="0.062" length="0.19" />
        </geometry>
      </collision>
    <collision name="bearing_insert">
      <origin xyz="-0.25 0 0.43" rpy="1.5708 0 0" />
      <geometry>
        <cylinder radius="0.036" length="0.205" />
        </geometry>
      </collision>
    <collision name="cover_screw_boss_0">
      <origin xyz="-0.25 0.088 0.645" rpy="1.5708 0 0" />
      <geometry>
        <cylinder radius="0.018" length="0.01" />
        </geometry>
      </collision>
    <collision name="cover_screw_boss_1">
      <origin xyz="-0.435 0.088 0.525" rpy="1.5708 0 0" />
      <geometry>
        <cylinder radius="0.018" length="0.01" />
        </geometry>
      </collision>
    <collision name="cover_screw_boss_2">
      <origin xyz="-0.42 0.088 0.31" rpy="1.5708 0 0" />
      <geometry>
        <cylinder radius="0.018" length="0.01" />
        </geometry>
      </collision>
    <collision name="cover_screw_boss_3">
      <origin xyz="-0.095 0.088 0.275" rpy="1.5708 0 0" />
      <geometry>
        <cylinder radius="0.018" length="0.01" />
        </geometry>
      </collision>
    <collision name="saddle_sleeve_wall_x0">
      <origin xyz="0.177 0 0.68" rpy="0 0 0" />
      <geometry>
        <box size="0.008 0.064 0.32" />
        </geometry>
      </collision>
    <collision name="saddle_sleeve_wall_x1">
      <origin xyz="0.233 0 0.68" rpy="0 0 0" />
      <geometry>
        <box size="0.008 0.064 0.32" />
        </geometry>
      </collision>
    <collision name="saddle_sleeve_wall_y0">
      <origin xyz="0.205 -0.028 0.68" rpy="0 0 0" />
      <geometry>
        <box size="0.064 0.008 0.32" />
        </geometry>
      </collision>
    <collision name="saddle_sleeve_wall_y1">
      <origin xyz="0.205 0.028 0.68" rpy="0 0 0" />
      <geometry>
        <box size="0.064 0.008 0.32" />
        </geometry>
      </collision>
    <collision name="saddle_collar_wall_x0">
      <origin xyz="0.174 0 0.8" rpy="0 0 0" />
      <geometry>
        <box size="0.012 0.1 0.075" />
        </geometry>
      </collision>
    <collision name="saddle_collar_wall_x1">
      <origin xyz="0.236 0 0.8" rpy="0 0 0" />
      <geometry>
        <box size="0.012 0.1 0.075" />
        </geometry>
      </collision>
    <collision name="saddle_collar_wall_y0">
      <origin xyz="0.205 -0.031 0.8" rpy="0 0 0" />
      <geometry>
        <box size="0.1 0.012 0.075" />
        </geometry>
      </collision>
    <collision name="saddle_collar_wall_y1">
      <origin xyz="0.205 0.031 0.8" rpy="0 0 0" />
      <geometry>
        <box size="0.1 0.012 0.075" />
        </geometry>
      </collision>
    <collision name="saddle_clamp_boss">
      <origin xyz="0.205 0.067 0.795" rpy="1.5708 0 0" />
      <geometry>
        <cylinder radius="0.02" length="0.046" />
        </geometry>
      </collision>
    <collision name="saddle_pad_upper">
      <origin xyz="0.205 0.046 0.832" rpy="0 0 0" />
      <geometry>
        <box size="0.08 0.012 0.024" />
        </geometry>
      </collision>
    <collision name="saddle_pad_lower">
      <origin xyz="0.205 0.046 0.758" rpy="0 0 0" />
      <geometry>
        <box size="0.08 0.012 0.024" />
        </geometry>
      </collision>
    <collision name="saddle_boss_web_0">
      <origin xyz="0.189 0.046 0.795" rpy="0 0 0" />
      <geometry>
        <box size="0.01 0.014 0.052" />
        </geometry>
      </collision>
    <collision name="saddle_boss_web_1">
      <origin xyz="0.221 0.046 0.795" rpy="0 0 0" />
      <geometry>
        <box size="0.01 0.014 0.052" />
        </geometry>
      </collision>
    <collision name="bar_sleeve_wall_x0">
      <origin xyz="-0.563 0 0.865" rpy="0 0 0" />
      <geometry>
        <box size="0.008 0.064 0.3" />
        </geometry>
      </collision>
    <collision name="bar_sleeve_wall_x1">
      <origin xyz="-0.507 0 0.865" rpy="0 0 0" />
      <geometry>
        <box size="0.008 0.064 0.3" />
        </geometry>
      </collision>
    <collision name="bar_sleeve_wall_y0">
      <origin xyz="-0.535 -0.028 0.865" rpy="0 0 0" />
      <geometry>
        <box size="0.064 0.008 0.3" />
        </geometry>
      </collision>
    <collision name="bar_sleeve_wall_y1">
      <origin xyz="-0.535 0.028 0.865" rpy="0 0 0" />
      <geometry>
        <box size="0.064 0.008 0.3" />
        </geometry>
      </collision>
    <collision name="bar_collar_wall_x0">
      <origin xyz="-0.566 0 0.985" rpy="0 0 0" />
      <geometry>
        <box size="0.012 0.1 0.075" />
        </geometry>
      </collision>
    <collision name="bar_collar_wall_x1">
      <origin xyz="-0.504 0 0.985" rpy="0 0 0" />
      <geometry>
        <box size="0.012 0.1 0.075" />
        </geometry>
      </collision>
    <collision name="bar_collar_wall_y0">
      <origin xyz="-0.535 -0.031 0.985" rpy="0 0 0" />
      <geometry>
        <box size="0.1 0.012 0.075" />
        </geometry>
      </collision>
    <collision name="bar_collar_wall_y1">
      <origin xyz="-0.535 0.031 0.985" rpy="0 0 0" />
      <geometry>
        <box size="0.1 0.012 0.075" />
        </geometry>
      </collision>
    <collision name="bar_clamp_boss">
      <origin xyz="-0.535 0.067 0.985" rpy="1.5708 0 0" />
      <geometry>
        <cylinder radius="0.02" length="0.046" />
        </geometry>
      </collision>
    <collision name="bar_pad_upper">
      <origin xyz="-0.535 0.046 1.017" rpy="0 0 0" />
      <geometry>
        <box size="0.08 0.012 0.024" />
        </geometry>
      </collision>
    <collision name="bar_pad_lower">
      <origin xyz="-0.535 0.046 0.943" rpy="0 0 0" />
      <geometry>
        <box size="0.08 0.012 0.024" />
        </geometry>
      </collision>
    <collision name="bar_boss_web_0">
      <origin xyz="-0.551 0.046 0.985" rpy="0 0 0" />
      <geometry>
        <box size="0.01 0.014 0.052" />
        </geometry>
      </collision>
    <collision name="bar_boss_web_1">
      <origin xyz="-0.519 0.046 0.985" rpy="0 0 0" />
      <geometry>
        <box size="0.01 0.014 0.052" />
        </geometry>
      </collision>
    <collision name="resistance_boss">
      <origin xyz="-0.25 0 0.705" rpy="0 0 0" />
      <geometry>
        <cylinder radius="0.042" length="0.035" />
        </geometry>
      </collision>
    <collision name="resistance_index_mark">
      <origin xyz="-0.25 0.04 0.725" rpy="0 0 0" />
      <geometry>
        <box size="0.008 0.006 0.005" />
        </geometry>
      </collision>
    </link>
  <link name="saddle_post">
    <visual name="inner_post">
      <origin xyz="0 0 0.07" rpy="0 0 0" />
      <geometry>
        <box size="0.04 0.04 0.62" />
        </geometry>
      <material name="powder_coated_steel">
        <color rgba="0.06 0.07 0.075 1" />
        </material>
      </visual>
    <visual name="glide_pad_0">
      <origin xyz="0 0.0215 -0.16" rpy="0 0 0" />
      <geometry>
        <box size="0.03 0.005 0.08" />
        </geometry>
      <material name="matte_black_plastic">
        <color rgba="0.015 0.016 0.017 1" />
        </material>
      </visual>
    <visual name="glide_pad_1">
      <origin xyz="0 -0.0215 -0.16" rpy="0 0 0" />
      <geometry>
        <box size="0.03 0.005 0.08" />
        </geometry>
      <material name="matte_black_plastic">
        <color rgba="0.015 0.016 0.017 1" />
        </material>
      </visual>
    <visual name="saddle_rail">
      <origin xyz="0.07 0 0.365" rpy="0 0 0" />
      <geometry>
        <box size="0.19 0.05 0.026" />
        </geometry>
      <material name="powder_coated_steel">
        <color rgba="0.06 0.07 0.075 1" />
        </material>
      </visual>
    <visual name="rail_riser">
      <origin xyz="0.02 0 0.335" rpy="0 0 0" />
      <geometry>
        <box size="0.06 0.04 0.09" />
        </geometry>
      <material name="powder_coated_steel">
        <color rgba="0.06 0.07 0.075 1" />
        </material>
      </visual>
    <visual name="saddle_pad">
      <origin xyz="0.075 0 0.378" rpy="0 0 0" />
      <geometry>
        <mesh filename="assets/meshes/saddle_pad.obj" />
        </geometry>
      <material name="textured_saddle_foam">
        <color rgba="0.025 0.025 0.023 1" />
        </material>
      </visual>
    <collision name="inner_post">
      <origin xyz="0 0 0.07" rpy="0 0 0" />
      <geometry>
        <box size="0.04 0.04 0.62" />
        </geometry>
      </collision>
    <collision name="glide_pad_0">
      <origin xyz="0 0.0215 -0.16" rpy="0 0 0" />
      <geometry>
        <box size="0.03 0.005 0.08" />
        </geometry>
      </collision>
    <collision name="glide_pad_1">
      <origin xyz="0 -0.0215 -0.16" rpy="0 0 0" />
      <geometry>
        <box size="0.03 0.005 0.08" />
        </geometry>
      </collision>
    <collision name="saddle_rail">
      <origin xyz="0.07 0 0.365" rpy="0 0 0" />
      <geometry>
        <box size="0.19 0.05 0.026" />
        </geometry>
      </collision>
    <collision name="rail_riser">
      <origin xyz="0.02 0 0.335" rpy="0 0 0" />
      <geometry>
        <box size="0.06 0.04 0.09" />
        </geometry>
      </collision>
    <collision name="saddle_pad">
      <origin xyz="0.075 0 0.378" rpy="0 0 0" />
      <geometry>
        <mesh filename="assets/meshes/saddle_pad.obj" />
        </geometry>
      </collision>
    </link>
  <link name="handle_post">
    <visual name="inner_post">
      <origin xyz="0 0 0.035" rpy="0 0 0" />
      <geometry>
        <box size="0.04 0.04 0.56" />
        </geometry>
      <material name="powder_coated_steel">
        <color rgba="0.06 0.07 0.075 1" />
        </material>
      </visual>
    <visual name="glide_pad_0">
      <origin xyz="0 0.0215 -0.16" rpy="0 0 0" />
      <geometry>
        <box size="0.03 0.005 0.08" />
        </geometry>
      <material name="matte_black_plastic">
        <color rgba="0.015 0.016 0.017 1" />
        </material>
      </visual>
    <visual name="glide_pad_1">
      <origin xyz="0 -0.0215 -0.16" rpy="0 0 0" />
      <geometry>
        <box size="0.03 0.005 0.08" />
        </geometry>
      <material name="matte_black_plastic">
        <color rgba="0.015 0.016 0.017 1" />
        </material>
      </visual>
    <visual name="bar_stem">
      <origin xyz="0 0 0.335" rpy="0 0 0" />
      <geometry>
        <box size="0.06 0.05 0.13" />
        </geometry>
      <material name="powder_coated_steel">
        <color rgba="0.06 0.07 0.075 1" />
        </material>
      </visual>
    <visual name="handlebar">
      <origin xyz="0 0 0.405" rpy="1.5708 0 0" />
      <geometry>
        <cylinder radius="0.018" length="0.62" />
        </geometry>
      <material name="powder_coated_steel">
        <color rgba="0.06 0.07 0.075 1" />
        </material>
      </visual>
    <visual name="grip_0">
      <origin xyz="0 -0.315 0.405" rpy="1.5708 0 0" />
      <geometry>
        <cylinder radius="0.023" length="0.15" />
        </geometry>
      <material name="soft_rubber">
        <color rgba="0.03 0.03 0.028 1" />
        </material>
      </visual>
    <visual name="grip_1">
      <origin xyz="0 0.315 0.405" rpy="1.5708 0 0" />
      <geometry>
        <cylinder radius="0.023" length="0.15" />
        </geometry>
      <material name="soft_rubber">
        <color rgba="0.03 0.03 0.028 1" />
        </material>
      </visual>
    <collision name="inner_post">
      <origin xyz="0 0 0.035" rpy="0 0 0" />
      <geometry>
        <box size="0.04 0.04 0.56" />
        </geometry>
      </collision>
    <collision name="glide_pad_0">
      <origin xyz="0 0.0215 -0.16" rpy="0 0 0" />
      <geometry>
        <box size="0.03 0.005 0.08" />
        </geometry>
      </collision>
    <collision name="glide_pad_1">
      <origin xyz="0 -0.0215 -0.16" rpy="0 0 0" />
      <geometry>
        <box size="0.03 0.005 0.08" />
        </geometry>
      </collision>
    <collision name="bar_stem">
      <origin xyz="0 0 0.335" rpy="0 0 0" />
      <geometry>
        <box size="0.06 0.05 0.13" />
        </geometry>
      </collision>
    <collision name="handlebar">
      <origin xyz="0 0 0.405" rpy="1.5708 0 0" />
      <geometry>
        <cylinder radius="0.018" length="0.62" />
        </geometry>
      </collision>
    <collision name="grip_0">
      <origin xyz="0 -0.315 0.405" rpy="1.5708 0 0" />
      <geometry>
        <cylinder radius="0.023" length="0.15" />
        </geometry>
      </collision>
    <collision name="grip_1">
      <origin xyz="0 0.315 0.405" rpy="1.5708 0 0" />
      <geometry>
        <cylinder radius="0.023" length="0.15" />
        </geometry>
      </collision>
    </link>
  <link name="crank">
    <visual name="axle_shaft">
      <origin xyz="0 0 0" rpy="1.5708 0 0" />
      <geometry>
        <cylinder radius="0.014" length="0.25" />
        </geometry>
      <material name="brushed_bearing_steel">
        <color rgba="0.62 0.64 0.62 1" />
        </material>
      </visual>
    <visual name="right_hub">
      <origin xyz="0 0.118 0" rpy="1.5708 0 0" />
      <geometry>
        <cylinder radius="0.045" length="0.034" />
        </geometry>
      <material name="brushed_bearing_steel">
        <color rgba="0.62 0.64 0.62 1" />
        </material>
      </visual>
    <visual name="left_hub">
      <origin xyz="0 -0.118 0" rpy="1.5708 0 0" />
      <geometry>
        <cylinder radius="0.045" length="0.034" />
        </geometry>
      <material name="brushed_bearing_steel">
        <color rgba="0.62 0.64 0.62 1" />
        </material>
      </visual>
    <visual name="right_arm">
      <origin xyz="0 0.119 -0.105" rpy="0 0 0" />
      <geometry>
        <box size="0.036 0.018 0.21" />
        </geometry>
      <material name="brushed_bearing_steel">
        <color rgba="0.62 0.64 0.62 1" />
        </material>
      </visual>
    <visual name="left_arm">
      <origin xyz="0 -0.119 0.105" rpy="0 0 0" />
      <geometry>
        <box size="0.036 0.018 0.21" />
        </geometry>
      <material name="brushed_bearing_steel">
        <color rgba="0.62 0.64 0.62 1" />
        </material>
      </visual>
    <visual name="right_pedal_boss">
      <origin xyz="0 0.139 -0.21" rpy="1.5708 0 0" />
      <geometry>
        <cylinder radius="0.025" length="0.028" />
        </geometry>
      <material name="brushed_bearing_steel">
        <color rgba="0.62 0.64 0.62 1" />
        </material>
      </visual>
    <visual name="left_pedal_boss">
      <origin xyz="0 -0.139 0.21" rpy="1.5708 0 0" />
      <geometry>
        <cylinder radius="0.025" length="0.028" />
        </geometry>
      <material name="brushed_bearing_steel">
        <color rgba="0.62 0.64 0.62 1" />
        </material>
      </visual>
    <collision name="axle_shaft">
      <origin xyz="0 0 0" rpy="1.5708 0 0" />
      <geometry>
        <cylinder radius="0.014" length="0.25" />
        </geometry>
      </collision>
    <collision name="right_hub">
      <origin xyz="0 0.118 0" rpy="1.5708 0 0" />
      <geometry>
        <cylinder radius="0.045" length="0.034" />
        </geometry>
      </collision>
    <collision name="left_hub">
      <origin xyz="0 -0.118 0" rpy="1.5708 0 0" />
      <geometry>
        <cylinder radius="0.045" length="0.034" />
        </geometry>
      </collision>
    <collision name="right_arm">
      <origin xyz="0 0.119 -0.105" rpy="0 0 0" />
      <geometry>
        <box size="0.036 0.018 0.21" />
        </geometry>
      </collision>
    <collision name="left_arm">
      <origin xyz="0 -0.119 0.105" rpy="0 0 0" />
      <geometry>
        <box size="0.036 0.018 0.21" />
        </geometry>
      </collision>
    <collision name="right_pedal_boss">
      <origin xyz="0 0.139 -0.21" rpy="1.5708 0 0" />
      <geometry>
        <cylinder radius="0.025" length="0.028" />
        </geometry>
      </collision>
    <collision name="left_pedal_boss">
      <origin xyz="0 -0.139 0.21" rpy="1.5708 0 0" />
      <geometry>
        <cylinder radius="0.025" length="0.028" />
        </geometry>
      </collision>
    </link>
  <link name="right_pedal">
    <visual name="spindle">
      <origin xyz="0 0.018 0" rpy="1.5708 0 0" />
      <geometry>
        <cylinder radius="0.006" length="0.09" />
        </geometry>
      <material name="brushed_bearing_steel">
        <color rgba="0.62 0.64 0.62 1" />
        </material>
      </visual>
    <visual name="platform">
      <origin xyz="0 0.06 0" rpy="0 0 0" />
      <geometry>
        <box size="0.12 0.06 0.03" />
        </geometry>
      <material name="matte_black_plastic">
        <color rgba="0.015 0.016 0.017 1" />
        </material>
      </visual>
    <visual name="tread_bar">
      <origin xyz="0 0.06 0.02" rpy="0 0 0" />
      <geometry>
        <box size="0.11 0.016 0.01" />
        </geometry>
      <material name="molded_seam_shadow">
        <color rgba="0.02 0.02 0.022 1" />
        </material>
      </visual>
    <collision name="spindle">
      <origin xyz="0 0.018 0" rpy="1.5708 0 0" />
      <geometry>
        <cylinder radius="0.006" length="0.09" />
        </geometry>
      </collision>
    <collision name="platform">
      <origin xyz="0 0.06 0" rpy="0 0 0" />
      <geometry>
        <box size="0.12 0.06 0.03" />
        </geometry>
      </collision>
    <collision name="tread_bar">
      <origin xyz="0 0.06 0.02" rpy="0 0 0" />
      <geometry>
        <box size="0.11 0.016 0.01" />
        </geometry>
      </collision>
    </link>
  <link name="left_pedal">
    <visual name="spindle">
      <origin xyz="0 -0.018 0" rpy="1.5708 0 0" />
      <geometry>
        <cylinder radius="0.006" length="0.09" />
        </geometry>
      <material name="brushed_bearing_steel">
        <color rgba="0.62 0.64 0.62 1" />
        </material>
      </visual>
    <visual name="platform">
      <origin xyz="0 -0.06 0" rpy="0 0 0" />
      <geometry>
        <box size="0.12 0.06 0.03" />
        </geometry>
      <material name="matte_black_plastic">
        <color rgba="0.015 0.016 0.017 1" />
        </material>
      </visual>
    <visual name="tread_bar">
      <origin xyz="0 -0.06 0.02" rpy="0 0 0" />
      <geometry>
        <box size="0.11 0.016 0.01" />
        </geometry>
      <material name="molded_seam_shadow">
        <color rgba="0.02 0.02 0.022 1" />
        </material>
      </visual>
    <collision name="spindle">
      <origin xyz="0 -0.018 0" rpy="1.5708 0 0" />
      <geometry>
        <cylinder radius="0.006" length="0.09" />
        </geometry>
      </collision>
    <collision name="platform">
      <origin xyz="0 -0.06 0" rpy="0 0 0" />
      <geometry>
        <box size="0.12 0.06 0.03" />
        </geometry>
      </collision>
    <collision name="tread_bar">
      <origin xyz="0 -0.06 0.02" rpy="0 0 0" />
      <geometry>
        <box size="0.11 0.016 0.01" />
        </geometry>
      </collision>
    </link>
  <link name="saddle_knob">
    <visual name="screw_shank">
      <origin xyz="0 -0.022 0" rpy="1.5708 0 0" />
      <geometry>
        <cylinder radius="0.006" length="0.05" />
        </geometry>
      <material name="brushed_bearing_steel">
        <color rgba="0.62 0.64 0.62 1" />
        </material>
      </visual>
    <visual name="knob_cap">
      <origin xyz="0 0.013 0" rpy="1.5708 0 0" />
      <geometry>
        <cylinder radius="0.03" length="0.026" />
        </geometry>
      <material name="matte_black_plastic">
        <color rgba="0.015 0.016 0.017 1" />
        </material>
      </visual>
    <visual name="grip_lobe_0">
      <origin xyz="0.034 0.013 0" rpy="0 -0 0" />
      <geometry>
        <box size="0.014 0.03 0.01" />
        </geometry>
      <material name="matte_black_plastic">
        <color rgba="0.015 0.016 0.017 1" />
        </material>
      </visual>
    <visual name="grip_lobe_1">
      <origin xyz="0.017 0.013 0.0294449" rpy="0 -1.0472 0" />
      <geometry>
        <box size="0.014 0.03 0.01" />
        </geometry>
      <material name="matte_black_plastic">
        <color rgba="0.015 0.016 0.017 1" />
        </material>
      </visual>
    <visual name="grip_lobe_2">
      <origin xyz="-0.017 0.013 0.0294449" rpy="0 -2.0944 0" />
      <geometry>
        <box size="0.014 0.03 0.01" />
        </geometry>
      <material name="matte_black_plastic">
        <color rgba="0.015 0.016 0.017 1" />
        </material>
      </visual>
    <visual name="grip_lobe_3">
      <origin xyz="-0.034 0.013 4.1638e-18" rpy="0 -3.14159 0" />
      <geometry>
        <box size="0.014 0.03 0.01" />
        </geometry>
      <material name="matte_black_plastic">
        <color rgba="0.015 0.016 0.017 1" />
        </material>
      </visual>
    <visual name="grip_lobe_4">
      <origin xyz="-0.017 0.013 -0.0294449" rpy="0 -4.18879 0" />
      <geometry>
        <box size="0.014 0.03 0.01" />
        </geometry>
      <material name="matte_black_plastic">
        <color rgba="0.015 0.016 0.017 1" />
        </material>
      </visual>
    <visual name="grip_lobe_5">
      <origin xyz="0.017 0.013 -0.0294449" rpy="0 -5.23599 0" />
      <geometry>
        <box size="0.014 0.03 0.01" />
        </geometry>
      <material name="matte_black_plastic">
        <color rgba="0.015 0.016 0.017 1" />
        </material>
      </visual>
    <collision name="screw_shank">
      <origin xyz="0 -0.022 0" rpy="1.5708 0 0" />
      <geometry>
        <cylinder radius="0.006" length="0.05" />
        </geometry>
      </collision>
    <collision name="knob_cap">
      <origin xyz="0 0.013 0" rpy="1.5708 0 0" />
      <geometry>
        <cylinder radius="0.03" length="0.026" />
        </geometry>
      </collision>
    <collision name="grip_lobe_0">
      <origin xyz="0.034 0.013 0" rpy="0 -0 0" />
      <geometry>
        <box size="0.014 0.03 0.01" />
        </geometry>
      </collision>
    <collision name="grip_lobe_1">
      <origin xyz="0.017 0.013 0.0294449" rpy="0 -1.0472 0" />
      <geometry>
        <box size="0.014 0.03 0.01" />
        </geometry>
      </collision>
    <collision name="grip_lobe_2">
      <origin xyz="-0.017 0.013 0.0294449" rpy="0 -2.0944 0" />
      <geometry>
        <box size="0.014 0.03 0.01" />
        </geometry>
      </collision>
    <collision name="grip_lobe_3">
      <origin xyz="-0.034 0.013 4.1638e-18" rpy="0 -3.14159 0" />
      <geometry>
        <box size="0.014 0.03 0.01" />
        </geometry>
      </collision>
    <collision name="grip_lobe_4">
      <origin xyz="-0.017 0.013 -0.0294449" rpy="0 -4.18879 0" />
      <geometry>
        <box size="0.014 0.03 0.01" />
        </geometry>
      </collision>
    <collision name="grip_lobe_5">
      <origin xyz="0.017 0.013 -0.0294449" rpy="0 -5.23599 0" />
      <geometry>
        <box size="0.014 0.03 0.01" />
        </geometry>
      </collision>
    </link>
  <link name="bar_knob">
    <visual name="screw_shank">
      <origin xyz="0 -0.022 0" rpy="1.5708 0 0" />
      <geometry>
        <cylinder radius="0.006" length="0.05" />
        </geometry>
      <material name="brushed_bearing_steel">
        <color rgba="0.62 0.64 0.62 1" />
        </material>
      </visual>
    <visual name="knob_cap">
      <origin xyz="0 0.013 0" rpy="1.5708 0 0" />
      <geometry>
        <cylinder radius="0.03" length="0.026" />
        </geometry>
      <material name="matte_black_plastic">
        <color rgba="0.015 0.016 0.017 1" />
        </material>
      </visual>
    <visual name="grip_lobe_0">
      <origin xyz="0.034 0.013 0" rpy="0 -0 0" />
      <geometry>
        <box size="0.014 0.03 0.01" />
        </geometry>
      <material name="matte_black_plastic">
        <color rgba="0.015 0.016 0.017 1" />
        </material>
      </visual>
    <visual name="grip_lobe_1">
      <origin xyz="0.017 0.013 0.0294449" rpy="0 -1.0472 0" />
      <geometry>
        <box size="0.014 0.03 0.01" />
        </geometry>
      <material name="matte_black_plastic">
        <color rgba="0.015 0.016 0.017 1" />
        </material>
      </visual>
    <visual name="grip_lobe_2">
      <origin xyz="-0.017 0.013 0.0294449" rpy="0 -2.0944 0" />
      <geometry>
        <box size="0.014 0.03 0.01" />
        </geometry>
      <material name="matte_black_plastic">
        <color rgba="0.015 0.016 0.017 1" />
        </material>
      </visual>
    <visual name="grip_lobe_3">
      <origin xyz="-0.034 0.013 4.1638e-18" rpy="0 -3.14159 0" />
      <geometry>
        <box size="0.014 0.03 0.01" />
        </geometry>
      <material name="matte_black_plastic">
        <color rgba="0.015 0.016 0.017 1" />
        </material>
      </visual>
    <visual name="grip_lobe_4">
      <origin xyz="-0.017 0.013 -0.0294449" rpy="0 -4.18879 0" />
      <geometry>
        <box size="0.014 0.03 0.01" />
        </geometry>
      <material name="matte_black_plastic">
        <color rgba="0.015 0.016 0.017 1" />
        </material>
      </visual>
    <visual name="grip_lobe_5">
      <origin xyz="0.017 0.013 -0.0294449" rpy="0 -5.23599 0" />
      <geometry>
        <box size="0.014 0.03 0.01" />
        </geometry>
      <material name="matte_black_plastic">
        <color rgba="0.015 0.016 0.017 1" />
        </material>
      </visual>
    <collision name="screw_shank">
      <origin xyz="0 -0.022 0" rpy="1.5708 0 0" />
      <geometry>
        <cylinder radius="0.006" length="0.05" />
        </geometry>
      </collision>
    <collision name="knob_cap">
      <origin xyz="0 0.013 0" rpy="1.5708 0 0" />
      <geometry>
        <cylinder radius="0.03" length="0.026" />
        </geometry>
      </collision>
    <collision name="grip_lobe_0">
      <origin xyz="0.034 0.013 0" rpy="0 -0 0" />
      <geometry>
        <box size="0.014 0.03 0.01" />
        </geometry>
      </collision>
    <collision name="grip_lobe_1">
      <origin xyz="0.017 0.013 0.0294449" rpy="0 -1.0472 0" />
      <geometry>
        <box size="0.014 0.03 0.01" />
        </geometry>
      </collision>
    <collision name="grip_lobe_2">
      <origin xyz="-0.017 0.013 0.0294449" rpy="0 -2.0944 0" />
      <geometry>
        <box size="0.014 0.03 0.01" />
        </geometry>
      </collision>
    <collision name="grip_lobe_3">
      <origin xyz="-0.034 0.013 4.1638e-18" rpy="0 -3.14159 0" />
      <geometry>
        <box size="0.014 0.03 0.01" />
        </geometry>
      </collision>
    <collision name="grip_lobe_4">
      <origin xyz="-0.017 0.013 -0.0294449" rpy="0 -4.18879 0" />
      <geometry>
        <box size="0.014 0.03 0.01" />
        </geometry>
      </collision>
    <collision name="grip_lobe_5">
      <origin xyz="0.017 0.013 -0.0294449" rpy="0 -5.23599 0" />
      <geometry>
        <box size="0.014 0.03 0.01" />
        </geometry>
      </collision>
    </link>
  <link name="resistance_knob">
    <visual name="dial_grip">
      <origin xyz="0 0 0.015" rpy="0 0 0" />
      <geometry>
        <cylinder radius="0.036" length="0.03" />
        </geometry>
      <material name="matte_black_plastic">
        <color rgba="0.015 0.016 0.017 1" />
        </material>
      </visual>
    <visual name="dial_pointer">
      <origin xyz="0 0 0.031" rpy="0 0 0" />
      <geometry>
        <box size="0.01 0.05 0.006" />
        </geometry>
      <material name="assembly_mark_yellow">
        <color rgba="0.95 0.68 0.08 1" />
        </material>
      </visual>
    <collision name="dial_grip">
      <origin xyz="0 0 0.015" rpy="0 0 0" />
      <geometry>
        <cylinder radius="0.036" length="0.03" />
        </geometry>
      </collision>
    <collision name="dial_pointer">
      <origin xyz="0 0 0.031" rpy="0 0 0" />
      <geometry>
        <box size="0.01 0.05 0.006" />
        </geometry>
      </collision>
    </link>
  <joint name="frame_to_saddle_post" type="prismatic">
    <origin xyz="0.205 0 0.84" rpy="0 0 0" />
    <parent link="frame" />
    <child link="saddle_post" />
    <axis xyz="0 0 1" />
    <limit effort="120" velocity="0.2" lower="0" upper="0.16" />
    </joint>
  <joint name="frame_to_handle_post" type="prismatic">
    <origin xyz="-0.535 0 1.015" rpy="0 0 0" />
    <parent link="frame" />
    <child link="handle_post" />
    <axis xyz="0 0 1" />
    <limit effort="100" velocity="0.18" lower="0" upper="0.14" />
    </joint>
  <joint name="frame_to_crank" type="continuous">
    <origin xyz="-0.25 0 0.43" rpy="0 0 0" />
    <parent link="frame" />
    <child link="crank" />
    <axis xyz="0 1 0" />
    <limit effort="60" velocity="8" />
    </joint>
  <joint name="crank_to_right_pedal" type="continuous">
    <origin xyz="0 0.158 -0.21" rpy="0 0 0" />
    <parent link="crank" />
    <child link="right_pedal" />
    <axis xyz="0 1 0" />
    <limit effort="8" velocity="12" />
    </joint>
  <joint name="crank_to_left_pedal" type="continuous">
    <origin xyz="0 -0.158 0.21" rpy="0 0 0" />
    <parent link="crank" />
    <child link="left_pedal" />
    <axis xyz="0 1 0" />
    <limit effort="8" velocity="12" />
    </joint>
  <joint name="frame_to_saddle_knob" type="continuous">
    <origin xyz="0.205 0.089 0.795" rpy="0 0 0" />
    <parent link="frame" />
    <child link="saddle_knob" />
    <axis xyz="0 1 0" />
    <limit effort="4" velocity="6" />
    </joint>
  <joint name="frame_to_bar_knob" type="continuous">
    <origin xyz="-0.535 0.089 0.985" rpy="0 0 0" />
    <parent link="frame" />
    <child link="bar_knob" />
    <axis xyz="0 1 0" />
    <limit effort="4" velocity="6" />
    </joint>
  <joint name="frame_to_resistance_knob" type="continuous">
    <origin xyz="-0.25 0 0.7225" rpy="0 0 0" />
    <parent link="frame" />
    <child link="resistance_knob" />
    <axis xyz="0 0 1" />
    <limit effort="3" velocity="4" />
    </joint>
  </robot>
