<robot name="inspection_shuttle">
  <material name="brushed_steel">
    <color rgba="0.62 0.64 0.64 1" />
    </material>
  <material name="darkened_steel">
    <color rgba="0.12 0.13 0.14 1" />
    </material>
  <material name="anodized_blue">
    <color rgba="0.1 0.25 0.5 1" />
    </material>
  <material name="oilite_bronze">
    <color rgba="0.78 0.58 0.25 1" />
    </material>
  <material name="black_oxide">
    <color rgba="0.02 0.02 0.018 1" />
    </material>
  <material name="inspection_orange">
    <color rgba="0.95 0.36 0.08 1" />
    </material>
  <link name="guide">
    <visual name="base_plate">
      <origin xyz="0 0 0.0175" rpy="0 0 0" />
      <geometry>
        <box size="0.82 0.3 0.035" />
        </geometry>
      <material name="darkened_steel">
        <color rgba="0.12 0.13 0.14 1" />
        </material>
      </visual>
    <visual name="center_way">
      <origin xyz="0 0 0.039" rpy="0 0 0" />
      <geometry>
        <box size="0.72 0.018 0.008" />
        </geometry>
      <material name="black_oxide">
        <color rgba="0.02 0.02 0.018 1" />
        </material>
      </visual>
    <visual name="rail_0">
      <origin xyz="0 0.07 0.0575" rpy="0 0 0" />
      <geometry>
        <box size="0.7 0.025 0.045" />
        </geometry>
      <material name="brushed_steel">
        <color rgba="0.62 0.64 0.64 1" />
        </material>
      </visual>
    <visual name="rail_bolt_0_0">
      <origin xyz="-0.29 0.07 0.083" rpy="0 0 0" />
      <geometry>
        <cylinder radius="0.008" length="0.006" />
        </geometry>
      <material name="black_oxide">
        <color rgba="0.02 0.02 0.018 1" />
        </material>
      </visual>
    <visual name="rail_bolt_0_1">
      <origin xyz="0.29 0.07 0.083" rpy="0 0 0" />
      <geometry>
        <cylinder radius="0.008" length="0.006" />
        </geometry>
      <material name="black_oxide">
        <color rgba="0.02 0.02 0.018 1" />
        </material>
      </visual>
    <visual name="rail_1">
      <origin xyz="0 -0.07 0.0575" rpy="0 0 0" />
      <geometry>
        <box size="0.7 0.025 0.045" />
        </geometry>
      <material name="brushed_steel">
        <color rgba="0.62 0.64 0.64 1" />
        </material>
      </visual>
    <visual name="rail_bolt_1_0">
      <origin xyz="-0.29 -0.07 0.083" rpy="0 0 0" />
      <geometry>
        <cylinder radius="0.008" length="0.006" />
        </geometry>
      <material name="black_oxide">
        <color rgba="0.02 0.02 0.018 1" />
        </material>
      </visual>
    <visual name="rail_bolt_1_1">
      <origin xyz="0.29 -0.07 0.083" rpy="0 0 0" />
      <geometry>
        <cylinder radius="0.008" length="0.006" />
        </geometry>
      <material name="black_oxide">
        <color rgba="0.02 0.02 0.018 1" />
        </material>
      </visual>
    <visual name="end_stop_0">
      <origin xyz="-0.38 0 0.0725" rpy="0 0 0" />
      <geometry>
        <box size="0.03 0.22 0.075" />
        </geometry>
      <material name="brushed_steel">
        <color rgba="0.62 0.64 0.64 1" />
        </material>
      </visual>
    <visual name="stop_bolt_0">
      <origin xyz="-0.38 0.095 0.115" rpy="1.5708 0 0" />
      <geometry>
        <cylinder radius="0.012" length="0.01" />
        </geometry>
      <material name="black_oxide">
        <color rgba="0.02 0.02 0.018 1" />
        </material>
      </visual>
    <visual name="end_stop_1">
      <origin xyz="0.38 0 0.0725" rpy="0 0 0" />
      <geometry>
        <box size="0.03 0.22 0.075" />
        </geometry>
      <material name="brushed_steel">
        <color rgba="0.62 0.64 0.64 1" />
        </material>
      </visual>
    <visual name="stop_bolt_1">
      <origin xyz="0.38 0.095 0.115" rpy="1.5708 0 0" />
      <geometry>
        <cylinder radius="0.012" length="0.01" />
        </geometry>
      <material name="black_oxide">
        <color rgba="0.02 0.02 0.018 1" />
        </material>
      </visual>
    <collision name="base_plate">
      <origin xyz="0 0 0.0175" rpy="0 0 0" />
      <geometry>
        <box size="0.82 0.3 0.035" />
        </geometry>
      </collision>
    <collision name="center_way">
      <origin xyz="0 0 0.039" rpy="0 0 0" />
      <geometry>
        <box size="0.72 0.018 0.008" />
        </geometry>
      </collision>
    <collision name="rail_0">
      <origin xyz="0 0.07 0.0575" rpy="0 0 0" />
      <geometry>
        <box size="0.7 0.025 0.045" />
        </geometry>
      </collision>
    <collision name="rail_bolt_0_0">
      <origin xyz="-0.29 0.07 0.083" rpy="0 0 0" />
      <geometry>
        <cylinder radius="0.008" length="0.006" />
        </geometry>
      </collision>
    <collision name="rail_bolt_0_1">
      <origin xyz="0.29 0.07 0.083" rpy="0 0 0" />
      <geometry>
        <cylinder radius="0.008" length="0.006" />
        </geometry>
      </collision>
    <collision name="rail_1">
      <origin xyz="0 -0.07 0.0575" rpy="0 0 0" />
      <geometry>
        <box size="0.7 0.025 0.045" />
        </geometry>
      </collision>
    <collision name="rail_bolt_1_0">
      <origin xyz="-0.29 -0.07 0.083" rpy="0 0 0" />
      <geometry>
        <cylinder radius="0.008" length="0.006" />
        </geometry>
      </collision>
    <collision name="rail_bolt_1_1">
      <origin xyz="0.29 -0.07 0.083" rpy="0 0 0" />
      <geometry>
        <cylinder radius="0.008" length="0.006" />
        </geometry>
      </collision>
    <collision name="end_stop_0">
      <origin xyz="-0.38 0 0.0725" rpy="0 0 0" />
      <geometry>
        <box size="0.03 0.22 0.075" />
        </geometry>
      </collision>
    <collision name="stop_bolt_0">
      <origin xyz="-0.38 0.095 0.115" rpy="1.5708 0 0" />
      <geometry>
        <cylinder radius="0.012" length="0.01" />
        </geometry>
      </collision>
    <collision name="end_stop_1">
      <origin xyz="0.38 0 0.0725" rpy="0 0 0" />
      <geometry>
        <box size="0.03 0.22 0.075" />
        </geometry>
      </collision>
    <collision name="stop_bolt_1">
      <origin xyz="0.38 0.095 0.115" rpy="1.5708 0 0" />
      <geometry>
        <cylinder radius="0.012" length="0.01" />
        </geometry>
      </collision>
    </link>
  <link name="shuttle">
    <visual name="carriage_plate">
      <origin xyz="0 0 0.1005" rpy="0 0 0" />
      <geometry>
        <box size="0.22 0.18 0.025" />
        </geometry>
      <material name="anodized_blue">
        <color rgba="0.1 0.25 0.5 1" />
        </material>
      </visual>
    <visual name="wear_pad_0">
      <origin xyz="0 0.07 0.084" rpy="0 0 0" />
      <geometry>
        <box size="0.18 0.024 0.008" />
        </geometry>
      <material name="oilite_bronze">
        <color rgba="0.78 0.58 0.25 1" />
        </material>
      </visual>
    <visual name="wear_pad_1">
      <origin xyz="0 -0.07 0.084" rpy="0 0 0" />
      <geometry>
        <box size="0.18 0.024 0.008" />
        </geometry>
      <material name="oilite_bronze">
        <color rgba="0.78 0.58 0.25 1" />
        </material>
      </visual>
    <visual name="carriage_flange_0">
      <origin xyz="0 0.105 0.064" rpy="0 0 0" />
      <geometry>
        <box size="0.18 0.016 0.048" />
        </geometry>
      <material name="anodized_blue">
        <color rgba="0.1 0.25 0.5 1" />
        </material>
      </visual>
    <visual name="flange_web_0">
      <origin xyz="0 0.093 0.094" rpy="0 0 0" />
      <geometry>
        <box size="0.18 0.018 0.02" />
        </geometry>
      <material name="anodized_blue">
        <color rgba="0.1 0.25 0.5 1" />
        </material>
      </visual>
    <visual name="flange_bolt_0_0">
      <origin xyz="-0.065 0.116 0.06" rpy="1.5708 0 0" />
      <geometry>
        <cylinder radius="0.007" length="0.007" />
        </geometry>
      <material name="black_oxide">
        <color rgba="0.02 0.02 0.018 1" />
        </material>
      </visual>
    <visual name="flange_bolt_0_1">
      <origin xyz="0.065 0.116 0.06" rpy="1.5708 0 0" />
      <geometry>
        <cylinder radius="0.007" length="0.007" />
        </geometry>
      <material name="black_oxide">
        <color rgba="0.02 0.02 0.018 1" />
        </material>
      </visual>
    <visual name="carriage_flange_1">
      <origin xyz="0 -0.105 0.064" rpy="0 0 0" />
      <geometry>
        <box size="0.18 0.016 0.048" />
        </geometry>
      <material name="anodized_blue">
        <color rgba="0.1 0.25 0.5 1" />
        </material>
      </visual>
    <visual name="flange_web_1">
      <origin xyz="0 -0.093 0.094" rpy="0 0 0" />
      <geometry>
        <box size="0.18 0.018 0.02" />
        </geometry>
      <material name="anodized_blue">
        <color rgba="0.1 0.25 0.5 1" />
        </material>
      </visual>
    <visual name="flange_bolt_1_0">
      <origin xyz="-0.065 -0.116 0.06" rpy="1.5708 0 0" />
      <geometry>
        <cylinder radius="0.007" length="0.007" />
        </geometry>
      <material name="black_oxide">
        <color rgba="0.02 0.02 0.018 1" />
        </material>
      </visual>
    <visual name="flange_bolt_1_1">
      <origin xyz="0.065 -0.116 0.06" rpy="1.5708 0 0" />
      <geometry>
        <cylinder radius="0.007" length="0.007" />
        </geometry>
      <material name="black_oxide">
        <color rgba="0.02 0.02 0.018 1" />
        </material>
      </visual>
    <visual name="side_shelf">
      <origin xyz="0.045 -0.105 0.125" rpy="0 0 0" />
      <geometry>
        <box size="0.095 0.045 0.025" />
        </geometry>
      <material name="anodized_blue">
        <color rgba="0.1 0.25 0.5 1" />
        </material>
      </visual>
    <visual name="pivot_block">
      <origin xyz="0.045 -0.145 0.1455" rpy="0 0 0" />
      <geometry>
        <box size="0.075 0.05 0.065" />
        </geometry>
      <material name="anodized_blue">
        <color rgba="0.1 0.25 0.5 1" />
        </material>
      </visual>
    <visual name="block_bolt_0">
      <origin xyz="0.018 -0.174 0.146" rpy="1.5708 0 0" />
      <geometry>
        <cylinder radius="0.01" length="0.008" />
        </geometry>
      <material name="black_oxide">
        <color rgba="0.02 0.02 0.018 1" />
        </material>
      </visual>
    <visual name="block_bolt_1">
      <origin xyz="0.072 -0.174 0.146" rpy="1.5708 0 0" />
      <geometry>
        <cylinder radius="0.01" length="0.008" />
        </geometry>
      <material name="black_oxide">
        <color rgba="0.02 0.02 0.018 1" />
        </material>
      </visual>
    <visual name="pivot_bearing">
      <origin xyz="0.045 -0.145 0.183" rpy="0 0 0" />
      <geometry>
        <cylinder radius="0.024" length="0.01" />
        </geometry>
      <material name="brushed_steel">
        <color rgba="0.62 0.64 0.64 1" />
        </material>
      </visual>
    <collision name="carriage_plate">
      <origin xyz="0 0 0.1005" rpy="0 0 0" />
      <geometry>
        <box size="0.22 0.18 0.025" />
        </geometry>
      </collision>
    <collision name="wear_pad_0">
      <origin xyz="0 0.07 0.084" rpy="0 0 0" />
      <geometry>
        <box size="0.18 0.024 0.008" />
        </geometry>
      </collision>
    <collision name="wear_pad_1">
      <origin xyz="0 -0.07 0.084" rpy="0 0 0" />
      <geometry>
        <box size="0.18 0.024 0.008" />
        </geometry>
      </collision>
    <collision name="carriage_flange_0">
      <origin xyz="0 0.105 0.064" rpy="0 0 0" />
      <geometry>
        <box size="0.18 0.016 0.048" />
        </geometry>
      </collision>
    <collision name="flange_web_0">
      <origin xyz="0 0.093 0.094" rpy="0 0 0" />
      <geometry>
        <box size="0.18 0.018 0.02" />
        </geometry>
      </collision>
    <collision name="flange_bolt_0_0">
      <origin xyz="-0.065 0.116 0.06" rpy="1.5708 0 0" />
      <geometry>
        <cylinder radius="0.007" length="0.007" />
        </geometry>
      </collision>
    <collision name="flange_bolt_0_1">
      <origin xyz="0.065 0.116 0.06" rpy="1.5708 0 0" />
      <geometry>
        <cylinder radius="0.007" length="0.007" />
        </geometry>
      </collision>
    <collision name="carriage_flange_1">
      <origin xyz="0 -0.105 0.064" rpy="0 0 0" />
      <geometry>
        <box size="0.18 0.016 0.048" />
        </geometry>
      </collision>
    <collision name="flange_web_1">
      <origin xyz="0 -0.093 0.094" rpy="0 0 0" />
      <geometry>
        <box size="0.18 0.018 0.02" />
        </geometry>
      </collision>
    <collision name="flange_bolt_1_0">
      <origin xyz="-0.065 -0.116 0.06" rpy="1.5708 0 0" />
      <geometry>
        <cylinder radius="0.007" length="0.007" />
        </geometry>
      </collision>
    <collision name="flange_bolt_1_1">
      <origin xyz="0.065 -0.116 0.06" rpy="1.5708 0 0" />
      <geometry>
        <cylinder radius="0.007" length="0.007" />
        </geometry>
      </collision>
    <collision name="side_shelf">
      <origin xyz="0.045 -0.105 0.125" rpy="0 0 0" />
      <geometry>
        <box size="0.095 0.045 0.025" />
        </geometry>
      </collision>
    <collision name="pivot_block">
      <origin xyz="0.045 -0.145 0.1455" rpy="0 0 0" />
      <geometry>
        <box size="0.075 0.05 0.065" />
        </geometry>
      </collision>
    <collision name="block_bolt_0">
      <origin xyz="0.018 -0.174 0.146" rpy="1.5708 0 0" />
      <geometry>
        <cylinder radius="0.01" length="0.008" />
        </geometry>
      </collision>
    <collision name="block_bolt_1">
      <origin xyz="0.072 -0.174 0.146" rpy="1.5708 0 0" />
      <geometry>
        <cylinder radius="0.01" length="0.008" />
        </geometry>
      </collision>
    <collision name="pivot_bearing">
      <origin xyz="0.045 -0.145 0.183" rpy="0 0 0" />
      <geometry>
        <cylinder radius="0.024" length="0.01" />
        </geometry>
      </collision>
    </link>
  <link name="link_paddle">
    <visual name="link_hub">
      <origin xyz="0 0 0.007" rpy="0 0 0" />
      <geometry>
        <cylinder radius="0.028" length="0.014" />
        </geometry>
      <material name="brushed_steel">
        <color rgba="0.62 0.64 0.64 1" />
        </material>
      </visual>
    <visual name="arm_bar">
      <origin xyz="0 -0.077 0.007" rpy="0 0 0" />
      <geometry>
        <box size="0.026 0.135 0.014" />
        </geometry>
      <material name="brushed_steel">
        <color rgba="0.62 0.64 0.64 1" />
        </material>
      </visual>
    <visual name="paddle_plate">
      <origin xyz="0 -0.168 0.007" rpy="0 0 0" />
      <geometry>
        <box size="0.09 0.055 0.01" />
        </geometry>
      <material name="inspection_orange">
        <color rgba="0.95 0.36 0.08 1" />
        </material>
      </visual>
    <visual name="paddle_round_0">
      <origin xyz="-0.045 -0.168 0.007" rpy="0 0 0" />
      <geometry>
        <cylinder radius="0.0275" length="0.01" />
        </geometry>
      <material name="inspection_orange">
        <color rgba="0.95 0.36 0.08 1" />
        </material>
      </visual>
    <visual name="paddle_round_1">
      <origin xyz="0.045 -0.168 0.007" rpy="0 0 0" />
      <geometry>
        <cylinder radius="0.0275" length="0.01" />
        </geometry>
      <material name="inspection_orange">
        <color rgba="0.95 0.36 0.08 1" />
        </material>
      </visual>
    <visual name="shoulder_cap">
      <origin xyz="0 0 0.017" rpy="0 0 0" />
      <geometry>
        <cylinder radius="0.017" length="0.006" />
        </geometry>
      <material name="black_oxide">
        <color rgba="0.02 0.02 0.018 1" />
        </material>
      </visual>
    <visual name="inspection_tip">
      <origin xyz="0 -0.168 0.015" rpy="0 0 0" />
      <geometry>
        <cylinder radius="0.004" length="0.02" />
        </geometry>
      <material name="black_oxide">
        <color rgba="0.02 0.02 0.018 1" />
        </material>
      </visual>
    <collision name="link_hub">
      <origin xyz="0 0 0.007" rpy="0 0 0" />
      <geometry>
        <cylinder radius="0.028" length="0.014" />
        </geometry>
      </collision>
    <collision name="arm_bar">
      <origin xyz="0 -0.077 0.007" rpy="0 0 0" />
      <geometry>
        <box size="0.026 0.135 0.014" />
        </geometry>
      </collision>
    <collision name="paddle_plate">
      <origin xyz="0 -0.168 0.007" rpy="0 0 0" />
      <geometry>
        <box size="0.09 0.055 0.01" />
        </geometry>
      </collision>
    <collision name="paddle_round_0">
      <origin xyz="-0.045 -0.168 0.007" rpy="0 0 0" />
      <geometry>
        <cylinder radius="0.0275" length="0.01" />
        </geometry>
      </collision>
    <collision name="paddle_round_1">
      <origin xyz="0.045 -0.168 0.007" rpy="0 0 0" />
      <geometry>
        <cylinder radius="0.0275" length="0.01" />
        </geometry>
      </collision>
    <collision name="shoulder_cap">
      <origin xyz="0 0 0.017" rpy="0 0 0" />
      <geometry>
        <cylinder radius="0.017" length="0.006" />
        </geometry>
      </collision>
    <collision name="inspection_tip">
      <origin xyz="0 -0.168 0.015" rpy="0 0 0" />
      <geometry>
        <cylinder radius="0.004" length="0.02" />
        </geometry>
      </collision>
    </link>
  <joint name="guide_to_shuttle" type="prismatic">
    <origin xyz="-0.18 0 0" rpy="0 0 0" />
    <parent link="guide" />
    <child link="shuttle" />
    <axis xyz="1 0 0" />
    <limit effort="120" velocity="0.35" lower="0" upper="0.36" />
    </joint>
  <joint name="shuttle_to_link" type="revolute">
    <origin xyz="0.045 -0.145 0.188" rpy="0 0 0" />
    <parent link="shuttle" />
    <child link="link_paddle" />
    <axis xyz="0 0 1" />
    <limit effort="8" velocity="2" lower="0" upper="1.1" />
    </joint>
  </robot>
