<robot name="column_radial_arm">
  <material name="cast_iron">
    <color rgba="0.2 0.22 0.24 1" />
    </material>
  <material name="dark_oxide">
    <color rgba="0.06 0.065 0.07 1" />
    </material>
  <material name="oiled_steel">
    <color rgba="0.42 0.44 0.46 1" />
    </material>
  <material name="painted_gray">
    <color rgba="0.54 0.57 0.6 1" />
    </material>
  <material name="safety_yellow">
    <color rgba="0.95 0.67 0.1 1" />
    </material>
  <link name="column">
    <visual name="base_plate">
      <origin xyz="0 0 0.0175" rpy="0 0 0" />
      <geometry>
        <box size="0.38 0.28 0.035" />
        </geometry>
      <material name="cast_iron">
        <color rgba="0.2 0.22 0.24 1" />
        </material>
      </visual>
    <visual name="vertical_post">
      <origin xyz="0 0 0.395" rpy="0 0 0" />
      <geometry>
        <cylinder radius="0.034" length="0.72" />
        </geometry>
      <material name="oiled_steel">
        <color rgba="0.42 0.44 0.46 1" />
        </material>
      </visual>
    <visual name="lower_bearing_race">
      <origin xyz="0 0 0.581" rpy="0 0 0" />
      <geometry>
        <cylinder radius="0.086" length="0.022" />
        </geometry>
      <material name="dark_oxide">
        <color rgba="0.06 0.065 0.07 1" />
        </material>
      </visual>
    <visual name="post_foot">
      <origin xyz="0 0 0.072" rpy="0 0 0" />
      <geometry>
        <cylinder radius="0.065" length="0.075" />
        </geometry>
      <material name="cast_iron">
        <color rgba="0.2 0.22 0.24 1" />
        </material>
      </visual>
    <visual name="web_gusset_0">
      <origin xyz="0.055 0 0.12" rpy="0 0 0" />
      <geometry>
        <box size="0.105 0.01 0.15" />
        </geometry>
      <material name="cast_iron">
        <color rgba="0.2 0.22 0.24 1" />
        </material>
      </visual>
    <visual name="web_gusset_1">
      <origin xyz="0.055 0 0.12" rpy="0 0 1.5708" />
      <geometry>
        <box size="0.105 0.01 0.15" />
        </geometry>
      <material name="cast_iron">
        <color rgba="0.2 0.22 0.24 1" />
        </material>
      </visual>
    <visual name="web_gusset_2">
      <origin xyz="0.055 0 0.12" rpy="0 0 3.14159" />
      <geometry>
        <box size="0.105 0.01 0.15" />
        </geometry>
      <material name="cast_iron">
        <color rgba="0.2 0.22 0.24 1" />
        </material>
      </visual>
    <visual name="web_gusset_3">
      <origin xyz="0.055 0 0.12" rpy="0 0 4.71239" />
      <geometry>
        <box size="0.105 0.01 0.15" />
        </geometry>
      <material name="cast_iron">
        <color rgba="0.2 0.22 0.24 1" />
        </material>
      </visual>
    <visual name="anchor_bolt_0">
      <origin xyz="-0.145 -0.095 0.04" rpy="0 0 0" />
      <geometry>
        <cylinder radius="0.014" length="0.01" />
        </geometry>
      <material name="dark_oxide">
        <color rgba="0.06 0.065 0.07 1" />
        </material>
      </visual>
    <visual name="anchor_bolt_1">
      <origin xyz="-0.145 0.095 0.04" rpy="0 0 0" />
      <geometry>
        <cylinder radius="0.014" length="0.01" />
        </geometry>
      <material name="dark_oxide">
        <color rgba="0.06 0.065 0.07 1" />
        </material>
      </visual>
    <visual name="anchor_bolt_2">
      <origin xyz="0.145 -0.095 0.04" rpy="0 0 0" />
      <geometry>
        <cylinder radius="0.014" length="0.01" />
        </geometry>
      <material name="dark_oxide">
        <color rgba="0.06 0.065 0.07 1" />
        </material>
      </visual>
    <visual name="anchor_bolt_3">
      <origin xyz="0.145 0.095 0.04" rpy="0 0 0" />
      <geometry>
        <cylinder radius="0.014" length="0.01" />
        </geometry>
      <material name="dark_oxide">
        <color rgba="0.06 0.065 0.07 1" />
        </material>
      </visual>
    <collision name="base_plate">
      <origin xyz="0 0 0.0175" rpy="0 0 0" />
      <geometry>
        <box size="0.38 0.28 0.035" />
        </geometry>
      </collision>
    <collision name="vertical_post">
      <origin xyz="0 0 0.395" rpy="0 0 0" />
      <geometry>
        <cylinder radius="0.034" length="0.72" />
        </geometry>
      </collision>
    <collision name="lower_bearing_race">
      <origin xyz="0 0 0.581" rpy="0 0 0" />
      <geometry>
        <cylinder radius="0.086" length="0.022" />
        </geometry>
      </collision>
    <collision name="post_foot">
      <origin xyz="0 0 0.072" rpy="0 0 0" />
      <geometry>
        <cylinder radius="0.065" length="0.075" />
        </geometry>
      </collision>
    <collision name="web_gusset_0">
      <origin xyz="0.055 0 0.12" rpy="0 0 0" />
      <geometry>
        <box size="0.105 0.01 0.15" />
        </geometry>
      </collision>
    <collision name="web_gusset_1">
      <origin xyz="0.055 0 0.12" rpy="0 0 1.5708" />
      <geometry>
        <box size="0.105 0.01 0.15" />
        </geometry>
      </collision>
    <collision name="web_gusset_2">
      <origin xyz="0.055 0 0.12" rpy="0 0 3.14159" />
      <geometry>
        <box size="0.105 0.01 0.15" />
        </geometry>
      </collision>
    <collision name="web_gusset_3">
      <origin xyz="0.055 0 0.12" rpy="0 0 4.71239" />
      <geometry>
        <box size="0.105 0.01 0.15" />
        </geometry>
      </collision>
    <collision name="anchor_bolt_0">
      <origin xyz="-0.145 -0.095 0.04" rpy="0 0 0" />
      <geometry>
        <cylinder radius="0.014" length="0.01" />
        </geometry>
      </collision>
    <collision name="anchor_bolt_1">
      <origin xyz="-0.145 0.095 0.04" rpy="0 0 0" />
      <geometry>
        <cylinder radius="0.014" length="0.01" />
        </geometry>
      </collision>
    <collision name="anchor_bolt_2">
      <origin xyz="0.145 -0.095 0.04" rpy="0 0 0" />
      <geometry>
        <cylinder radius="0.014" length="0.01" />
        </geometry>
      </collision>
    <collision name="anchor_bolt_3">
      <origin xyz="0.145 0.095 0.04" rpy="0 0 0" />
      <geometry>
        <cylinder radius="0.014" length="0.01" />
        </geometry>
      </collision>
    </link>
  <link name="turret">
    <visual name="turret_sleeve">
      <geometry>
        <mesh filename="assets/meshes/turret_sleeve.obj" />
        </geometry>
      <material name="painted_gray">
        <color rgba="0.54 0.57 0.6 1" />
        </material>
      </visual>
    <visual name="beam_socket">
      <origin xyz="0.095 0 0.025" rpy="0 0 0" />
      <geometry>
        <box size="0.065 0.15 0.105" />
        </geometry>
      <material name="painted_gray">
        <color rgba="0.54 0.57 0.6 1" />
        </material>
      </visual>
    <visual name="bearing_cap">
      <origin xyz="0 0 0.111" rpy="0 0 0" />
      <geometry>
        <cylinder radius="0.052" length="0.024" />
        </geometry>
      <material name="dark_oxide">
        <color rgba="0.06 0.065 0.07 1" />
        </material>
      </visual>
    <visual name="beam_top">
      <origin xyz="0.365 0 0.083" rpy="0 0 0" />
      <geometry>
        <box size="0.61 0.11 0.018" />
        </geometry>
      <material name="painted_gray">
        <color rgba="0.54 0.57 0.6 1" />
        </material>
      </visual>
    <visual name="beam_side_0">
      <origin xyz="0.37 -0.048 0.04" rpy="0 0 0" />
      <geometry>
        <box size="0.59 0.014 0.07" />
        </geometry>
      <material name="painted_gray">
        <color rgba="0.54 0.57 0.6 1" />
        </material>
      </visual>
    <visual name="beam_lip_0">
      <origin xyz="0.38 -0.02976 0" rpy="0 0 0" />
      <geometry>
        <box size="0.57 0.024 0.012" />
        </geometry>
      <material name="painted_gray">
        <color rgba="0.54 0.57 0.6 1" />
        </material>
      </visual>
    <visual name="beam_side_1">
      <origin xyz="0.37 0.048 0.04" rpy="0 0 0" />
      <geometry>
        <box size="0.59 0.014 0.07" />
        </geometry>
      <material name="painted_gray">
        <color rgba="0.54 0.57 0.6 1" />
        </material>
      </visual>
    <visual name="beam_lip_1">
      <origin xyz="0.38 0.02976 0" rpy="0 0 0" />
      <geometry>
        <box size="0.57 0.024 0.012" />
        </geometry>
      <material name="painted_gray">
        <color rgba="0.54 0.57 0.6 1" />
        </material>
      </visual>
    <visual name="socket_face">
      <origin xyz="0.145 0 0.035" rpy="0 0 0" />
      <geometry>
        <box size="0.07 0.135 0.105" />
        </geometry>
      <material name="painted_gray">
        <color rgba="0.54 0.57 0.6 1" />
        </material>
      </visual>
    <visual name="clamp_cross_pin">
      <origin xyz="0.125 0 0.09" rpy="1.5708 0 0" />
      <geometry>
        <cylinder radius="0.018" length="0.17" />
        </geometry>
      <material name="dark_oxide">
        <color rgba="0.06 0.065 0.07 1" />
        </material>
      </visual>
    <collision name="turret_sleeve">
      <geometry>
        <mesh filename="assets/meshes/turret_sleeve.obj" />
        </geometry>
      </collision>
    <collision name="beam_socket">
      <origin xyz="0.095 0 0.025" rpy="0 0 0" />
      <geometry>
        <box size="0.065 0.15 0.105" />
        </geometry>
      </collision>
    <collision name="bearing_cap">
      <origin xyz="0 0 0.111" rpy="0 0 0" />
      <geometry>
        <cylinder radius="0.052" length="0.024" />
        </geometry>
      </collision>
    <collision name="beam_top">
      <origin xyz="0.365 0 0.083" rpy="0 0 0" />
      <geometry>
        <box size="0.61 0.11 0.018" />
        </geometry>
      </collision>
    <collision name="beam_side_0">
      <origin xyz="0.37 -0.048 0.04" rpy="0 0 0" />
      <geometry>
        <box size="0.59 0.014 0.07" />
        </geometry>
      </collision>
    <collision name="beam_lip_0">
      <origin xyz="0.38 -0.02976 0" rpy="0 0 0" />
      <geometry>
        <box size="0.57 0.024 0.012" />
        </geometry>
      </collision>
    <collision name="beam_side_1">
      <origin xyz="0.37 0.048 0.04" rpy="0 0 0" />
      <geometry>
        <box size="0.59 0.014 0.07" />
        </geometry>
      </collision>
    <collision name="beam_lip_1">
      <origin xyz="0.38 0.02976 0" rpy="0 0 0" />
      <geometry>
        <box size="0.57 0.024 0.012" />
        </geometry>
      </collision>
    <collision name="socket_face">
      <origin xyz="0.145 0 0.035" rpy="0 0 0" />
      <geometry>
        <box size="0.07 0.135 0.105" />
        </geometry>
      </collision>
    <collision name="clamp_cross_pin">
      <origin xyz="0.125 0 0.09" rpy="1.5708 0 0" />
      <geometry>
        <cylinder radius="0.018" length="0.17" />
        </geometry>
      </collision>
    </link>
  <link name="carriage">
    <visual name="slider_tongue">
      <origin xyz="0.06 0 -0.012" rpy="0 0 0" />
      <geometry>
        <box size="0.12 0.018 0.024" />
        </geometry>
      <material name="oiled_steel">
        <color rgba="0.42 0.44 0.46 1" />
        </material>
      </visual>
    <visual name="saddle_plate">
      <origin xyz="0.06 0 -0.032" rpy="0 0 0" />
      <geometry>
        <box size="0.12 0.134 0.018" />
        </geometry>
      <material name="cast_iron">
        <color rgba="0.2 0.22 0.24 1" />
        </material>
      </visual>
    <visual name="side_cheek_0">
      <origin xyz="0.06 -0.063 -0.006" rpy="0 0 0" />
      <geometry>
        <box size="0.105 0.016 0.052" />
        </geometry>
      <material name="cast_iron">
        <color rgba="0.2 0.22 0.24 1" />
        </material>
      </visual>
    <visual name="guide_roller_0_0">
      <origin xyz="0.02 -0.063 0.011" rpy="1.5708 0 0" />
      <geometry>
        <cylinder radius="0.01" length="0.018" />
        </geometry>
      <material name="dark_oxide">
        <color rgba="0.06 0.065 0.07 1" />
        </material>
      </visual>
    <visual name="guide_roller_0_1">
      <origin xyz="0.1 -0.063 0.011" rpy="1.5708 0 0" />
      <geometry>
        <cylinder radius="0.01" length="0.018" />
        </geometry>
      <material name="dark_oxide">
        <color rgba="0.06 0.065 0.07 1" />
        </material>
      </visual>
    <visual name="side_cheek_1">
      <origin xyz="0.06 0.063 -0.006" rpy="0 0 0" />
      <geometry>
        <box size="0.105 0.016 0.052" />
        </geometry>
      <material name="cast_iron">
        <color rgba="0.2 0.22 0.24 1" />
        </material>
      </visual>
    <visual name="guide_roller_1_0">
      <origin xyz="0.02 0.063 0.011" rpy="1.5708 0 0" />
      <geometry>
        <cylinder radius="0.01" length="0.018" />
        </geometry>
      <material name="dark_oxide">
        <color rgba="0.06 0.065 0.07 1" />
        </material>
      </visual>
    <visual name="guide_roller_1_1">
      <origin xyz="0.1 0.063 0.011" rpy="1.5708 0 0" />
      <geometry>
        <cylinder radius="0.01" length="0.018" />
        </geometry>
      <material name="dark_oxide">
        <color rgba="0.06 0.065 0.07 1" />
        </material>
      </visual>
    <visual name="head_stem">
      <origin xyz="0.112 0 -0.061" rpy="0 0 0" />
      <geometry>
        <box size="0.03 0.07 0.045" />
        </geometry>
      <material name="cast_iron">
        <color rgba="0.2 0.22 0.24 1" />
        </material>
      </visual>
    <visual name="head_plate">
      <origin xyz="0.122 0 -0.089" rpy="0 0 0" />
      <geometry>
        <box size="0.095 0.12 0.014" />
        </geometry>
      <material name="safety_yellow">
        <color rgba="0.95 0.67 0.1 1" />
        </material>
      </visual>
    <visual name="head_bolt_0">
      <origin xyz="0.092 -0.04 -0.08" rpy="0 0 0" />
      <geometry>
        <cylinder radius="0.007" length="0.006" />
        </geometry>
      <material name="dark_oxide">
        <color rgba="0.06 0.065 0.07 1" />
        </material>
      </visual>
    <visual name="head_bolt_1">
      <origin xyz="0.092 0.04 -0.08" rpy="0 0 0" />
      <geometry>
        <cylinder radius="0.007" length="0.006" />
        </geometry>
      <material name="dark_oxide">
        <color rgba="0.06 0.065 0.07 1" />
        </material>
      </visual>
    <visual name="head_bolt_2">
      <origin xyz="0.152 -0.04 -0.08" rpy="0 0 0" />
      <geometry>
        <cylinder radius="0.007" length="0.006" />
        </geometry>
      <material name="dark_oxide">
        <color rgba="0.06 0.065 0.07 1" />
        </material>
      </visual>
    <visual name="head_bolt_3">
      <origin xyz="0.152 0.04 -0.08" rpy="0 0 0" />
      <geometry>
        <cylinder radius="0.007" length="0.006" />
        </geometry>
      <material name="dark_oxide">
        <color rgba="0.06 0.065 0.07 1" />
        </material>
      </visual>
    <collision name="slider_tongue">
      <origin xyz="0.06 0 -0.012" rpy="0 0 0" />
      <geometry>
        <box size="0.12 0.018 0.024" />
        </geometry>
      </collision>
    <collision name="saddle_plate">
      <origin xyz="0.06 0 -0.032" rpy="0 0 0" />
      <geometry>
        <box size="0.12 0.134 0.018" />
        </geometry>
      </collision>
    <collision name="side_cheek_0">
      <origin xyz="0.06 -0.063 -0.006" rpy="0 0 0" />
      <geometry>
        <box size="0.105 0.016 0.052" />
        </geometry>
      </collision>
    <collision name="guide_roller_0_0">
      <origin xyz="0.02 -0.063 0.011" rpy="1.5708 0 0" />
      <geometry>
        <cylinder radius="0.01" length="0.018" />
        </geometry>
      </collision>
    <collision name="guide_roller_0_1">
      <origin xyz="0.1 -0.063 0.011" rpy="1.5708 0 0" />
      <geometry>
        <cylinder radius="0.01" length="0.018" />
        </geometry>
      </collision>
    <collision name="side_cheek_1">
      <origin xyz="0.06 0.063 -0.006" rpy="0 0 0" />
      <geometry>
        <box size="0.105 0.016 0.052" />
        </geometry>
      </collision>
    <collision name="guide_roller_1_0">
      <origin xyz="0.02 0.063 0.011" rpy="1.5708 0 0" />
      <geometry>
        <cylinder radius="0.01" length="0.018" />
        </geometry>
      </collision>
    <collision name="guide_roller_1_1">
      <origin xyz="0.1 0.063 0.011" rpy="1.5708 0 0" />
      <geometry>
        <cylinder radius="0.01" length="0.018" />
        </geometry>
      </collision>
    <collision name="head_stem">
      <origin xyz="0.112 0 -0.061" rpy="0 0 0" />
      <geometry>
        <box size="0.03 0.07 0.045" />
        </geometry>
      </collision>
    <collision name="head_plate">
      <origin xyz="0.122 0 -0.089" rpy="0 0 0" />
      <geometry>
        <box size="0.095 0.12 0.014" />
        </geometry>
      </collision>
    <collision name="head_bolt_0">
      <origin xyz="0.092 -0.04 -0.08" rpy="0 0 0" />
      <geometry>
        <cylinder radius="0.007" length="0.006" />
        </geometry>
      </collision>
    <collision name="head_bolt_1">
      <origin xyz="0.092 0.04 -0.08" rpy="0 0 0" />
      <geometry>
        <cylinder radius="0.007" length="0.006" />
        </geometry>
      </collision>
    <collision name="head_bolt_2">
      <origin xyz="0.152 -0.04 -0.08" rpy="0 0 0" />
      <geometry>
        <cylinder radius="0.007" length="0.006" />
        </geometry>
      </collision>
    <collision name="head_bolt_3">
      <origin xyz="0.152 0.04 -0.08" rpy="0 0 0" />
      <geometry>
        <cylinder radius="0.007" length="0.006" />
        </geometry>
      </collision>
    </link>
  <joint name="column_to_turret" type="revolute">
    <origin xyz="0 0 0.69" rpy="0 0 0" />
    <parent link="column" />
    <child link="turret" />
    <axis xyz="0 0 1" />
    <limit effort="160" velocity="0.7" lower="-2" upper="2" />
    </joint>
  <joint name="turret_to_carriage" type="prismatic">
    <origin xyz="0.19 0 0" rpy="0 0 0" />
    <parent link="turret" />
    <child link="carriage" />
    <axis xyz="1 0 0" />
    <limit effort="90" velocity="0.18" lower="0" upper="0.14" />
    </joint>
  </robot>
