<robot name="home_care_overbed_table">
  <material name="warm_laminate">
    <color rgba="0.74 0.58 0.38 1" />
    </material>
  <material name="dark_edge_banding">
    <color rgba="0.18 0.15 0.12 1" />
    </material>
  <material name="brushed_chrome">
    <color rgba="0.7 0.72 0.72 1" />
    </material>
  <material name="medical_gray">
    <color rgba="0.55 0.57 0.58 1" />
    </material>
  <material name="soft_black_rubber">
    <color rgba="0.02 0.02 0.018 1" />
    </material>
  <material name="knob_gray_plastic">
    <color rgba="0.18 0.19 0.2 1" />
    </material>
  <material name="spring_clip_metal">
    <color rgba="0.42 0.44 0.45 1" />
    </material>
  <link name="base">
    <visual name="offset_floor_beam">
      <origin xyz="0.08 0 0.045" rpy="0 0 0" />
      <geometry>
        <box size="0.9 0.08 0.06" />
        </geometry>
      <material name="medical_gray">
        <color rgba="0.55 0.57 0.58 1" />
        </material>
      </visual>
    <visual name="pedestal_cross_foot">
      <origin xyz="-0.32 0 0.0475" rpy="0 0 0" />
      <geometry>
        <box size="0.15 0.58 0.055" />
        </geometry>
      <material name="medical_gray">
        <color rgba="0.55 0.57 0.58 1" />
        </material>
      </visual>
    <visual name="patient_caster_crossbar">
      <origin xyz="0.46 0 0.092" rpy="0 0 0" />
      <geometry>
        <box size="0.095 0.44 0.034" />
        </geometry>
      <material name="medical_gray">
        <color rgba="0.55 0.57 0.58 1" />
        </material>
      </visual>
    <visual name="outer_sleeve_side_0">
      <origin xyz="-0.3515 0 0.3475" rpy="0 0 0" />
      <geometry>
        <box size="0.012 0.075 0.545" />
        </geometry>
      <material name="brushed_chrome">
        <color rgba="0.7 0.72 0.72 1" />
        </material>
      </visual>
    <visual name="outer_sleeve_side_1">
      <origin xyz="-0.2885 0 0.3475" rpy="0 0 0" />
      <geometry>
        <box size="0.012 0.075 0.545" />
        </geometry>
      <material name="brushed_chrome">
        <color rgba="0.7 0.72 0.72 1" />
        </material>
      </visual>
    <visual name="outer_sleeve_face_0">
      <origin xyz="-0.32 -0.0315 0.3475" rpy="0 0 0" />
      <geometry>
        <box size="0.075 0.012 0.545" />
        </geometry>
      <material name="brushed_chrome">
        <color rgba="0.7 0.72 0.72 1" />
        </material>
      </visual>
    <visual name="outer_sleeve_face_1">
      <origin xyz="-0.32 0.0315 0.3475" rpy="0 0 0" />
      <geometry>
        <box size="0.075 0.012 0.545" />
        </geometry>
      <material name="brushed_chrome">
        <color rgba="0.7 0.72 0.72 1" />
        </material>
      </visual>
    <visual name="sleeve_socket_plate">
      <origin xyz="-0.32 0 0.075" rpy="0 0 0" />
      <geometry>
        <box size="0.105 0.105 0.014" />
        </geometry>
      <material name="medical_gray">
        <color rgba="0.55 0.57 0.58 1" />
        </material>
      </visual>
    <visual name="rear_glide_0">
      <origin xyz="-0.36 -0.23 0.012" rpy="1.5708 0 0" />
      <geometry>
        <cylinder radius="0.03" length="0.018" />
        </geometry>
      <material name="soft_black_rubber">
        <color rgba="0.02 0.02 0.018 1" />
        </material>
      </visual>
    <visual name="rear_glide_1">
      <origin xyz="-0.36 0.23 0.012" rpy="1.5708 0 0" />
      <geometry>
        <cylinder radius="0.03" length="0.018" />
        </geometry>
      <material name="soft_black_rubber">
        <color rgba="0.02 0.02 0.018 1" />
        </material>
      </visual>
    <visual name="caster_fork_inner_0">
      <origin xyz="0.46 -0.198 0.061" rpy="0 0 0" />
      <geometry>
        <box size="0.065 0.006 0.06" />
        </geometry>
      <material name="medical_gray">
        <color rgba="0.55 0.57 0.58 1" />
        </material>
      </visual>
    <visual name="caster_fork_outer_0">
      <origin xyz="0.46 -0.162 0.061" rpy="0 0 0" />
      <geometry>
        <box size="0.065 0.006 0.06" />
        </geometry>
      <material name="medical_gray">
        <color rgba="0.55 0.57 0.58 1" />
        </material>
      </visual>
    <visual name="caster_fork_bridge_0">
      <origin xyz="0.46 -0.18 0.095" rpy="0 0 0" />
      <geometry>
        <box size="0.065 0.042 0.008" />
        </geometry>
      <material name="medical_gray">
        <color rgba="0.55 0.57 0.58 1" />
        </material>
      </visual>
    <visual name="caster_axle_cap_inner_0">
      <origin xyz="0.46 -0.201 0.043" rpy="1.5708 0 0" />
      <geometry>
        <cylinder radius="0.008" length="0.008" />
        </geometry>
      <material name="brushed_chrome">
        <color rgba="0.7 0.72 0.72 1" />
        </material>
      </visual>
    <visual name="caster_axle_cap_outer_0">
      <origin xyz="0.46 -0.159 0.043" rpy="1.5708 0 0" />
      <geometry>
        <cylinder radius="0.008" length="0.008" />
        </geometry>
      <material name="brushed_chrome">
        <color rgba="0.7 0.72 0.72 1" />
        </material>
      </visual>
    <visual name="caster_fork_inner_1">
      <origin xyz="0.46 0.162 0.061" rpy="0 0 0" />
      <geometry>
        <box size="0.065 0.006 0.06" />
        </geometry>
      <material name="medical_gray">
        <color rgba="0.55 0.57 0.58 1" />
        </material>
      </visual>
    <visual name="caster_fork_outer_1">
      <origin xyz="0.46 0.198 0.061" rpy="0 0 0" />
      <geometry>
        <box size="0.065 0.006 0.06" />
        </geometry>
      <material name="medical_gray">
        <color rgba="0.55 0.57 0.58 1" />
        </material>
      </visual>
    <visual name="caster_fork_bridge_1">
      <origin xyz="0.46 0.18 0.095" rpy="0 0 0" />
      <geometry>
        <box size="0.065 0.042 0.008" />
        </geometry>
      <material name="medical_gray">
        <color rgba="0.55 0.57 0.58 1" />
        </material>
      </visual>
    <visual name="caster_axle_cap_inner_1">
      <origin xyz="0.46 0.159 0.043" rpy="1.5708 0 0" />
      <geometry>
        <cylinder radius="0.008" length="0.008" />
        </geometry>
      <material name="brushed_chrome">
        <color rgba="0.7 0.72 0.72 1" />
        </material>
      </visual>
    <visual name="caster_axle_cap_outer_1">
      <origin xyz="0.46 0.201 0.043" rpy="1.5708 0 0" />
      <geometry>
        <cylinder radius="0.008" length="0.008" />
        </geometry>
      <material name="brushed_chrome">
        <color rgba="0.7 0.72 0.72 1" />
        </material>
      </visual>
    <collision name="offset_floor_beam">
      <origin xyz="0.08 0 0.045" rpy="0 0 0" />
      <geometry>
        <box size="0.9 0.08 0.06" />
        </geometry>
      </collision>
    <collision name="pedestal_cross_foot">
      <origin xyz="-0.32 0 0.0475" rpy="0 0 0" />
      <geometry>
        <box size="0.15 0.58 0.055" />
        </geometry>
      </collision>
    <collision name="patient_caster_crossbar">
      <origin xyz="0.46 0 0.092" rpy="0 0 0" />
      <geometry>
        <box size="0.095 0.44 0.034" />
        </geometry>
      </collision>
    <collision name="outer_sleeve_side_0">
      <origin xyz="-0.3515 0 0.3475" rpy="0 0 0" />
      <geometry>
        <box size="0.012 0.075 0.545" />
        </geometry>
      </collision>
    <collision name="outer_sleeve_side_1">
      <origin xyz="-0.2885 0 0.3475" rpy="0 0 0" />
      <geometry>
        <box size="0.012 0.075 0.545" />
        </geometry>
      </collision>
    <collision name="outer_sleeve_face_0">
      <origin xyz="-0.32 -0.0315 0.3475" rpy="0 0 0" />
      <geometry>
        <box size="0.075 0.012 0.545" />
        </geometry>
      </collision>
    <collision name="outer_sleeve_face_1">
      <origin xyz="-0.32 0.0315 0.3475" rpy="0 0 0" />
      <geometry>
        <box size="0.075 0.012 0.545" />
        </geometry>
      </collision>
    <collision name="sleeve_socket_plate">
      <origin xyz="-0.32 0 0.075" rpy="0 0 0" />
      <geometry>
        <box size="0.105 0.105 0.014" />
        </geometry>
      </collision>
    <collision name="rear_glide_0">
      <origin xyz="-0.36 -0.23 0.012" rpy="1.5708 0 0" />
      <geometry>
        <cylinder radius="0.03" length="0.018" />
        </geometry>
      </collision>
    <collision name="rear_glide_1">
      <origin xyz="-0.36 0.23 0.012" rpy="1.5708 0 0" />
      <geometry>
        <cylinder radius="0.03" length="0.018" />
        </geometry>
      </collision>
    <collision name="caster_fork_inner_0">
      <origin xyz="0.46 -0.198 0.061" rpy="0 0 0" />
      <geometry>
        <box size="0.065 0.006 0.06" />
        </geometry>
      </collision>
    <collision name="caster_fork_outer_0">
      <origin xyz="0.46 -0.162 0.061" rpy="0 0 0" />
      <geometry>
        <box size="0.065 0.006 0.06" />
        </geometry>
      </collision>
    <collision name="caster_fork_bridge_0">
      <origin xyz="0.46 -0.18 0.095" rpy="0 0 0" />
      <geometry>
        <box size="0.065 0.042 0.008" />
        </geometry>
      </collision>
    <collision name="caster_axle_cap_inner_0">
      <origin xyz="0.46 -0.201 0.043" rpy="1.5708 0 0" />
      <geometry>
        <cylinder radius="0.008" length="0.008" />
        </geometry>
      </collision>
    <collision name="caster_axle_cap_outer_0">
      <origin xyz="0.46 -0.159 0.043" rpy="1.5708 0 0" />
      <geometry>
        <cylinder radius="0.008" length="0.008" />
        </geometry>
      </collision>
    <collision name="caster_fork_inner_1">
      <origin xyz="0.46 0.162 0.061" rpy="0 0 0" />
      <geometry>
        <box size="0.065 0.006 0.06" />
        </geometry>
      </collision>
    <collision name="caster_fork_outer_1">
      <origin xyz="0.46 0.198 0.061" rpy="0 0 0" />
      <geometry>
        <box size="0.065 0.006 0.06" />
        </geometry>
      </collision>
    <collision name="caster_fork_bridge_1">
      <origin xyz="0.46 0.18 0.095" rpy="0 0 0" />
      <geometry>
        <box size="0.065 0.042 0.008" />
        </geometry>
      </collision>
    <collision name="caster_axle_cap_inner_1">
      <origin xyz="0.46 0.159 0.043" rpy="1.5708 0 0" />
      <geometry>
        <cylinder radius="0.008" length="0.008" />
        </geometry>
      </collision>
    <collision name="caster_axle_cap_outer_1">
      <origin xyz="0.46 0.201 0.043" rpy="1.5708 0 0" />
      <geometry>
        <cylinder radius="0.008" length="0.008" />
        </geometry>
      </collision>
    </link>
  <link name="height_collar">
    <visual name="collar_side_0">
      <origin xyz="-0.0475 0 0" rpy="0 0 0" />
      <geometry>
        <box size="0.02 0.115 0.065" />
        </geometry>
      <material name="medical_gray">
        <color rgba="0.55 0.57 0.58 1" />
        </material>
      </visual>
    <visual name="collar_side_1">
      <origin xyz="0.0475 0 0" rpy="0 0 0" />
      <geometry>
        <box size="0.02 0.115 0.065" />
        </geometry>
      <material name="medical_gray">
        <color rgba="0.55 0.57 0.58 1" />
        </material>
      </visual>
    <visual name="collar_face_0">
      <origin xyz="0 -0.0475 0" rpy="0 0 0" />
      <geometry>
        <box size="0.115 0.02 0.065" />
        </geometry>
      <material name="medical_gray">
        <color rgba="0.55 0.57 0.58 1" />
        </material>
      </visual>
    <visual name="collar_face_1">
      <origin xyz="0 0.0475 0" rpy="0 0 0" />
      <geometry>
        <box size="0.115 0.02 0.065" />
        </geometry>
      <material name="medical_gray">
        <color rgba="0.55 0.57 0.58 1" />
        </material>
      </visual>
    <visual name="threaded_hub">
      <origin xyz="0 -0.075 0" rpy="1.5708 0 0" />
      <geometry>
        <cylinder radius="0.012" length="0.035" />
        </geometry>
      <material name="brushed_chrome">
        <color rgba="0.7 0.72 0.72 1" />
        </material>
      </visual>
    <collision name="collar_side_0">
      <origin xyz="-0.0475 0 0" rpy="0 0 0" />
      <geometry>
        <box size="0.02 0.115 0.065" />
        </geometry>
      </collision>
    <collision name="collar_side_1">
      <origin xyz="0.0475 0 0" rpy="0 0 0" />
      <geometry>
        <box size="0.02 0.115 0.065" />
        </geometry>
      </collision>
    <collision name="collar_face_0">
      <origin xyz="0 -0.0475 0" rpy="0 0 0" />
      <geometry>
        <box size="0.115 0.02 0.065" />
        </geometry>
      </collision>
    <collision name="collar_face_1">
      <origin xyz="0 0.0475 0" rpy="0 0 0" />
      <geometry>
        <box size="0.115 0.02 0.065" />
        </geometry>
      </collision>
    <collision name="threaded_hub">
      <origin xyz="0 -0.075 0" rpy="1.5708 0 0" />
      <geometry>
        <cylinder radius="0.012" length="0.035" />
        </geometry>
      </collision>
    </link>
  <link name="collar_knob">
    <visual name="knob_core">
      <origin xyz="0 -0.0145 0" rpy="1.5708 0 0" />
      <geometry>
        <cylinder radius="0.022" length="0.029" />
        </geometry>
      <material name="knob_gray_plastic">
        <color rgba="0.18 0.19 0.2 1" />
        </material>
      </visual>
    <visual name="knob_lobe_0">
      <origin xyz="0.02 -0.0155 0" rpy="1.5708 0 0" />
      <geometry>
        <cylinder radius="0.0075" length="0.031" />
        </geometry>
      <material name="knob_gray_plastic">
        <color rgba="0.18 0.19 0.2 1" />
        </material>
      </visual>
    <visual name="knob_lobe_1">
      <origin xyz="0.01 -0.0155 0.0173205" rpy="1.5708 0 0" />
      <geometry>
        <cylinder radius="0.0075" length="0.031" />
        </geometry>
      <material name="knob_gray_plastic">
        <color rgba="0.18 0.19 0.2 1" />
        </material>
      </visual>
    <visual name="knob_lobe_2">
      <origin xyz="-0.01 -0.0155 0.0173205" rpy="1.5708 0 0" />
      <geometry>
        <cylinder radius="0.0075" length="0.031" />
        </geometry>
      <material name="knob_gray_plastic">
        <color rgba="0.18 0.19 0.2 1" />
        </material>
      </visual>
    <visual name="knob_lobe_3">
      <origin xyz="-0.02 -0.0155 2.44929e-18" rpy="1.5708 0 0" />
      <geometry>
        <cylinder radius="0.0075" length="0.031" />
        </geometry>
      <material name="knob_gray_plastic">
        <color rgba="0.18 0.19 0.2 1" />
        </material>
      </visual>
    <visual name="knob_lobe_4">
      <origin xyz="-0.01 -0.0155 -0.0173205" rpy="1.5708 0 0" />
      <geometry>
        <cylinder radius="0.0075" length="0.031" />
        </geometry>
      <material name="knob_gray_plastic">
        <color rgba="0.18 0.19 0.2 1" />
        </material>
      </visual>
    <visual name="knob_lobe_5">
      <origin xyz="0.01 -0.0155 -0.0173205" rpy="1.5708 0 0" />
      <geometry>
        <cylinder radius="0.0075" length="0.031" />
        </geometry>
      <material name="knob_gray_plastic">
        <color rgba="0.18 0.19 0.2 1" />
        </material>
      </visual>
    <visual name="knob_face_cap">
      <origin xyz="0 -0.0315 0" rpy="1.5708 0 0" />
      <geometry>
        <cylinder radius="0.017" length="0.004" />
        </geometry>
      <material name="medical_gray">
        <color rgba="0.55 0.57 0.58 1" />
        </material>
      </visual>
    <collision name="knob_core">
      <origin xyz="0 -0.0145 0" rpy="1.5708 0 0" />
      <geometry>
        <cylinder radius="0.022" length="0.029" />
        </geometry>
      </collision>
    <collision name="knob_lobe_0">
      <origin xyz="0.02 -0.0155 0" rpy="1.5708 0 0" />
      <geometry>
        <cylinder radius="0.0075" length="0.031" />
        </geometry>
      </collision>
    <collision name="knob_lobe_1">
      <origin xyz="0.01 -0.0155 0.0173205" rpy="1.5708 0 0" />
      <geometry>
        <cylinder radius="0.0075" length="0.031" />
        </geometry>
      </collision>
    <collision name="knob_lobe_2">
      <origin xyz="-0.01 -0.0155 0.0173205" rpy="1.5708 0 0" />
      <geometry>
        <cylinder radius="0.0075" length="0.031" />
        </geometry>
      </collision>
    <collision name="knob_lobe_3">
      <origin xyz="-0.02 -0.0155 2.44929e-18" rpy="1.5708 0 0" />
      <geometry>
        <cylinder radius="0.0075" length="0.031" />
        </geometry>
      </collision>
    <collision name="knob_lobe_4">
      <origin xyz="-0.01 -0.0155 -0.0173205" rpy="1.5708 0 0" />
      <geometry>
        <cylinder radius="0.0075" length="0.031" />
        </geometry>
      </collision>
    <collision name="knob_lobe_5">
      <origin xyz="0.01 -0.0155 -0.0173205" rpy="1.5708 0 0" />
      <geometry>
        <cylinder radius="0.0075" length="0.031" />
        </geometry>
      </collision>
    <collision name="knob_face_cap">
      <origin xyz="0 -0.0315 0" rpy="1.5708 0 0" />
      <geometry>
        <cylinder radius="0.017" length="0.004" />
        </geometry>
      </collision>
    </link>
  <link name="mast">
    <visual name="inner_post">
      <geometry>
        <box size="0.051 0.051 0.64" />
        </geometry>
      <material name="brushed_chrome">
        <color rgba="0.7 0.72 0.72 1" />
        </material>
      </visual>
    <collision name="inner_post">
      <geometry>
        <box size="0.051 0.051 0.64" />
        </geometry>
      </collision>
    </link>
  <link name="tray">
    <visual name="laminate_top">
      <origin xyz="0.455 0 0.016" rpy="0 0 0" />
      <geometry>
        <box size="0.82 0.42 0.032" />
        </geometry>
      <material name="warm_laminate">
        <color rgba="0.74 0.58 0.38 1" />
        </material>
      </visual>
    <visual name="front_edge_band">
      <origin xyz="0.455 -0.219 0.022" rpy="0 0 0" />
      <geometry>
        <box size="0.83 0.018 0.044" />
        </geometry>
      <material name="dark_edge_banding">
        <color rgba="0.18 0.15 0.12 1" />
        </material>
      </visual>
    <visual name="rear_edge_band">
      <origin xyz="0.455 0.217 0.018" rpy="0 0 0" />
      <geometry>
        <box size="0.83 0.014 0.036" />
        </geometry>
      <material name="dark_edge_banding">
        <color rgba="0.18 0.15 0.12 1" />
        </material>
      </visual>
    <visual name="pedestal_edge_band">
      <origin xyz="0.045 0 0.018" rpy="0 0 0" />
      <geometry>
        <box size="0.018 0.42 0.036" />
        </geometry>
      <material name="dark_edge_banding">
        <color rgba="0.18 0.15 0.12 1" />
        </material>
      </visual>
    <visual name="patient_edge_band">
      <origin xyz="0.865 0 0.018" rpy="0 0 0" />
      <geometry>
        <box size="0.018 0.42 0.036" />
        </geometry>
      <material name="dark_edge_banding">
        <color rgba="0.18 0.15 0.12 1" />
        </material>
      </visual>
    <visual name="cantilever_arm">
      <origin xyz="0.25 0 -0.018" rpy="0 0 0" />
      <geometry>
        <box size="0.455 0.045 0.036" />
        </geometry>
      <material name="brushed_chrome">
        <color rgba="0.7 0.72 0.72 1" />
        </material>
      </visual>
    <visual name="mast_mount_plate">
      <origin xyz="0.0255 0 -0.02" rpy="0 0 0" />
      <geometry>
        <box size="0.006 0.065 0.18" />
        </geometry>
      <material name="brushed_chrome">
        <color rgba="0.7 0.72 0.72 1" />
        </material>
      </visual>
    <visual name="clip_hinge_block_0">
      <origin xyz="0.235 -0.226 0.042" rpy="0 0 0" />
      <geometry>
        <box size="0.035 0.018 0.02" />
        </geometry>
      <material name="spring_clip_metal">
        <color rgba="0.42 0.44 0.45 1" />
        </material>
      </visual>
    <visual name="clip_hinge_block_1">
      <origin xyz="0.675 -0.226 0.042" rpy="0 0 0" />
      <geometry>
        <box size="0.035 0.018 0.02" />
        </geometry>
      <material name="spring_clip_metal">
        <color rgba="0.42 0.44 0.45 1" />
        </material>
      </visual>
    <collision name="laminate_top">
      <origin xyz="0.455 0 0.016" rpy="0 0 0" />
      <geometry>
        <box size="0.82 0.42 0.032" />
        </geometry>
      </collision>
    <collision name="front_edge_band">
      <origin xyz="0.455 -0.219 0.022" rpy="0 0 0" />
      <geometry>
        <box size="0.83 0.018 0.044" />
        </geometry>
      </collision>
    <collision name="rear_edge_band">
      <origin xyz="0.455 0.217 0.018" rpy="0 0 0" />
      <geometry>
        <box size="0.83 0.014 0.036" />
        </geometry>
      </collision>
    <collision name="pedestal_edge_band">
      <origin xyz="0.045 0 0.018" rpy="0 0 0" />
      <geometry>
        <box size="0.018 0.42 0.036" />
        </geometry>
      </collision>
    <collision name="patient_edge_band">
      <origin xyz="0.865 0 0.018" rpy="0 0 0" />
      <geometry>
        <box size="0.018 0.42 0.036" />
        </geometry>
      </collision>
    <collision name="cantilever_arm">
      <origin xyz="0.25 0 -0.018" rpy="0 0 0" />
      <geometry>
        <box size="0.455 0.045 0.036" />
        </geometry>
      </collision>
    <collision name="mast_mount_plate">
      <origin xyz="0.0255 0 -0.02" rpy="0 0 0" />
      <geometry>
        <box size="0.006 0.065 0.18" />
        </geometry>
      </collision>
    <collision name="clip_hinge_block_0">
      <origin xyz="0.235 -0.226 0.042" rpy="0 0 0" />
      <geometry>
        <box size="0.035 0.018 0.02" />
        </geometry>
      </collision>
    <collision name="clip_hinge_block_1">
      <origin xyz="0.675 -0.226 0.042" rpy="0 0 0" />
      <geometry>
        <box size="0.035 0.018 0.02" />
        </geometry>
      </collision>
    </link>
  <link name="clip_bar">
    <visual name="hinge_pin">
      <origin xyz="0 0 0" rpy="0 1.5708 0" />
      <geometry>
        <cylinder radius="0.005" length="0.62" />
        </geometry>
      <material name="spring_clip_metal">
        <color rgba="0.42 0.44 0.45 1" />
        </material>
      </visual>
    <visual name="short_support_0">
      <origin xyz="-0.22 0.034 0.002" rpy="0 0 0" />
      <geometry>
        <box size="0.025 0.068 0.006" />
        </geometry>
      <material name="spring_clip_metal">
        <color rgba="0.42 0.44 0.45 1" />
        </material>
      </visual>
    <visual name="short_support_1">
      <origin xyz="0.22 0.034 0.002" rpy="0 0 0" />
      <geometry>
        <box size="0.025 0.068 0.006" />
        </geometry>
      <material name="spring_clip_metal">
        <color rgba="0.42 0.44 0.45 1" />
        </material>
      </visual>
    <visual name="chart_clip_bar">
      <origin xyz="0 0.076 0.012" rpy="0 0 0" />
      <geometry>
        <box size="0.6 0.016 0.014" />
        </geometry>
      <material name="spring_clip_metal">
        <color rgba="0.42 0.44 0.45 1" />
        </material>
      </visual>
    <collision name="hinge_pin">
      <origin xyz="0 0 0" rpy="0 1.5708 0" />
      <geometry>
        <cylinder radius="0.005" length="0.62" />
        </geometry>
      </collision>
    <collision name="short_support_0">
      <origin xyz="-0.22 0.034 0.002" rpy="0 0 0" />
      <geometry>
        <box size="0.025 0.068 0.006" />
        </geometry>
      </collision>
    <collision name="short_support_1">
      <origin xyz="0.22 0.034 0.002" rpy="0 0 0" />
      <geometry>
        <box size="0.025 0.068 0.006" />
        </geometry>
      </collision>
    <collision name="chart_clip_bar">
      <origin xyz="0 0.076 0.012" rpy="0 0 0" />
      <geometry>
        <box size="0.6 0.016 0.014" />
        </geometry>
      </collision>
    </link>
  <link name="front_caster_0">
    <visual name="rubber_tire">
      <origin xyz="0 0 0" rpy="1.5708 0 0" />
      <geometry>
        <cylinder radius="0.03" length="0.024" />
        </geometry>
      <material name="soft_black_rubber">
        <color rgba="0.02 0.02 0.018 1" />
        </material>
      </visual>
    <visual name="wheel_hub">
      <origin xyz="0 0 0" rpy="1.5708 0 0" />
      <geometry>
        <cylinder radius="0.014" length="0.03" />
        </geometry>
      <material name="brushed_chrome">
        <color rgba="0.7 0.72 0.72 1" />
        </material>
      </visual>
    <collision name="rubber_tire">
      <origin xyz="0 0 0" rpy="1.5708 0 0" />
      <geometry>
        <cylinder radius="0.03" length="0.024" />
        </geometry>
      </collision>
    <collision name="wheel_hub">
      <origin xyz="0 0 0" rpy="1.5708 0 0" />
      <geometry>
        <cylinder radius="0.014" length="0.03" />
        </geometry>
      </collision>
    </link>
  <link name="front_caster_1">
    <visual name="rubber_tire">
      <origin xyz="0 0 0" rpy="1.5708 0 0" />
      <geometry>
        <cylinder radius="0.03" length="0.024" />
        </geometry>
      <material name="soft_black_rubber">
        <color rgba="0.02 0.02 0.018 1" />
        </material>
      </visual>
    <visual name="wheel_hub">
      <origin xyz="0 0 0" rpy="1.5708 0 0" />
      <geometry>
        <cylinder radius="0.014" length="0.03" />
        </geometry>
      <material name="brushed_chrome">
        <color rgba="0.7 0.72 0.72 1" />
        </material>
      </visual>
    <collision name="rubber_tire">
      <origin xyz="0 0 0" rpy="1.5708 0 0" />
      <geometry>
        <cylinder radius="0.03" length="0.024" />
        </geometry>
      </collision>
    <collision name="wheel_hub">
      <origin xyz="0 0 0" rpy="1.5708 0 0" />
      <geometry>
        <cylinder radius="0.014" length="0.03" />
        </geometry>
      </collision>
    </link>
  <joint name="base_to_front_caster_0" type="continuous">
    <origin xyz="0.46 -0.18 0.043" rpy="0 0 0" />
    <parent link="base" />
    <child link="front_caster_0" />
    <axis xyz="0 1 0" />
    <limit effort="2" velocity="18" />
    </joint>
  <joint name="base_to_front_caster_1" type="continuous">
    <origin xyz="0.46 0.18 0.043" rpy="0 0 0" />
    <parent link="base" />
    <child link="front_caster_1" />
    <axis xyz="0 1 0" />
    <limit effort="2" velocity="18" />
    </joint>
  <joint name="base_to_height_collar" type="fixed">
    <origin xyz="-0.32 0 0.62" rpy="0 0 0" />
    <parent link="base" />
    <child link="height_collar" />
    </joint>
  <joint name="collar_to_knob" type="continuous">
    <origin xyz="0 -0.0925 0" rpy="0 0 0" />
    <parent link="height_collar" />
    <child link="collar_knob" />
    <axis xyz="0 -1 0" />
    <limit effort="1.5" velocity="8" />
    </joint>
  <joint name="base_to_mast" type="prismatic">
    <origin xyz="-0.32 0 0.62" rpy="0 0 0" />
    <parent link="base" />
    <child link="mast" />
    <axis xyz="0 0 1" />
    <limit effort="90" velocity="0.2" lower="0" upper="0.22" />
    </joint>
  <joint name="mast_to_tray" type="fixed">
    <origin xyz="0 0 0.22" rpy="0 0 0" />
    <parent link="mast" />
    <child link="tray" />
    </joint>
  <joint name="tray_to_clip_bar" type="revolute">
    <origin xyz="0.455 -0.226 0.057" rpy="0 0 0" />
    <parent link="tray" />
    <child link="clip_bar" />
    <axis xyz="1 0 0" />
    <limit effort="1" velocity="3" lower="0" upper="1.15" />
    </joint>
  </robot>
