<robot name="wall_mounted_folding_arm">
  <material name="graphite_powder_coat">
    <color rgba="0.1 0.11 0.12 1" />
    </material>
  <material name="matte_black_slider">
    <color rgba="0.015 0.016 0.017 1" />
    </material>
  <material name="brushed_steel">
    <color rgba="0.58 0.58 0.54 1" />
    </material>
  <material name="painted_wall_plate">
    <color rgba="0.73 0.75 0.76 1" />
    </material>
  <material name="black_rubber_pads">
    <color rgba="0.025 0.023 0.02 1" />
    </material>
  <material name="zinc_fasteners">
    <color rgba="0.72 0.7 0.64 1" />
    </material>
  <link name="wall_bracket">
    <visual name="wall_plate">
      <origin xyz="-0.092 0 0" rpy="0 0 0" />
      <geometry>
        <box size="0.026 0.32 0.34" />
        </geometry>
      <material name="painted_wall_plate">
        <color rgba="0.73 0.75 0.76 1" />
        </material>
      </visual>
    <visual name="rear_bridge">
      <origin xyz="-0.07 0 0" rpy="0 0 0" />
      <geometry>
        <box size="0.03 0.15 0.118" />
        </geometry>
      <material name="graphite_powder_coat">
        <color rgba="0.1 0.11 0.12 1" />
        </material>
      </visual>
    <visual name="upper_cheek">
      <origin xyz="0.01 0 0.054" rpy="0 0 0" />
      <geometry>
        <box size="0.15 0.15 0.012" />
        </geometry>
      <material name="graphite_powder_coat">
        <color rgba="0.1 0.11 0.12 1" />
        </material>
      </visual>
    <visual name="lower_cheek">
      <origin xyz="0.01 0 -0.054" rpy="0 0 0" />
      <geometry>
        <box size="0.15 0.15 0.012" />
        </geometry>
      <material name="graphite_powder_coat">
        <color rgba="0.1 0.11 0.12 1" />
        </material>
      </visual>
    <visual name="side_web_0">
      <origin xyz="-0.07 -0.082 0" rpy="0 0 0" />
      <geometry>
        <box size="0.03 0.014 0.118" />
        </geometry>
      <material name="graphite_powder_coat">
        <color rgba="0.1 0.11 0.12 1" />
        </material>
      </visual>
    <visual name="side_web_1">
      <origin xyz="-0.07 0.082 0" rpy="0 0 0" />
      <geometry>
        <box size="0.03 0.014 0.118" />
        </geometry>
      <material name="graphite_powder_coat">
        <color rgba="0.1 0.11 0.12 1" />
        </material>
      </visual>
    <visual name="bolt_head_0">
      <origin xyz="-0.075 -0.108 -0.115" rpy="0 1.5708 0" />
      <geometry>
        <cylinder radius="0.014" length="0.008" />
        </geometry>
      <material name="zinc_fasteners">
        <color rgba="0.72 0.7 0.64 1" />
        </material>
      </visual>
    <visual name="bolt_head_1">
      <origin xyz="-0.075 0.108 -0.115" rpy="0 1.5708 0" />
      <geometry>
        <cylinder radius="0.014" length="0.008" />
        </geometry>
      <material name="zinc_fasteners">
        <color rgba="0.72 0.7 0.64 1" />
        </material>
      </visual>
    <visual name="bolt_head_2">
      <origin xyz="-0.075 -0.108 0.115" rpy="0 1.5708 0" />
      <geometry>
        <cylinder radius="0.014" length="0.008" />
        </geometry>
      <material name="zinc_fasteners">
        <color rgba="0.72 0.7 0.64 1" />
        </material>
      </visual>
    <visual name="bolt_head_3">
      <origin xyz="-0.075 0.108 0.115" rpy="0 1.5708 0" />
      <geometry>
        <cylinder radius="0.014" length="0.008" />
        </geometry>
      <material name="zinc_fasteners">
        <color rgba="0.72 0.7 0.64 1" />
        </material>
      </visual>
    <visual name="root_pin_cap">
      <origin xyz="0 0 0.068" rpy="0 0 0" />
      <geometry>
        <cylinder radius="0.018" length="0.018" />
        </geometry>
      <material name="brushed_steel">
        <color rgba="0.58 0.58 0.54 1" />
        </material>
      </visual>
    <visual name="root_pin">
      <geometry>
        <cylinder radius="0.014" length="0.132" />
        </geometry>
      <material name="brushed_steel">
        <color rgba="0.58 0.58 0.54 1" />
        </material>
      </visual>
    <visual name="root_stop_tab">
      <origin xyz="0.046 0.064 0.067" rpy="0 0 0" />
      <geometry>
        <box size="0.034 0.026 0.018" />
        </geometry>
      <material name="brushed_steel">
        <color rgba="0.58 0.58 0.54 1" />
        </material>
      </visual>
    <collision name="wall_plate">
      <origin xyz="-0.092 0 0" rpy="0 0 0" />
      <geometry>
        <box size="0.026 0.32 0.34" />
        </geometry>
      </collision>
    <collision name="rear_bridge">
      <origin xyz="-0.07 0 0" rpy="0 0 0" />
      <geometry>
        <box size="0.03 0.15 0.118" />
        </geometry>
      </collision>
    <collision name="upper_cheek">
      <origin xyz="0.01 0 0.054" rpy="0 0 0" />
      <geometry>
        <box size="0.15 0.15 0.012" />
        </geometry>
      </collision>
    <collision name="lower_cheek">
      <origin xyz="0.01 0 -0.054" rpy="0 0 0" />
      <geometry>
        <box size="0.15 0.15 0.012" />
        </geometry>
      </collision>
    <collision name="side_web_0">
      <origin xyz="-0.07 -0.082 0" rpy="0 0 0" />
      <geometry>
        <box size="0.03 0.014 0.118" />
        </geometry>
      </collision>
    <collision name="side_web_1">
      <origin xyz="-0.07 0.082 0" rpy="0 0 0" />
      <geometry>
        <box size="0.03 0.014 0.118" />
        </geometry>
      </collision>
    <collision name="bolt_head_0">
      <origin xyz="-0.075 -0.108 -0.115" rpy="0 1.5708 0" />
      <geometry>
        <cylinder radius="0.014" length="0.008" />
        </geometry>
      </collision>
    <collision name="bolt_head_1">
      <origin xyz="-0.075 0.108 -0.115" rpy="0 1.5708 0" />
      <geometry>
        <cylinder radius="0.014" length="0.008" />
        </geometry>
      </collision>
    <collision name="bolt_head_2">
      <origin xyz="-0.075 -0.108 0.115" rpy="0 1.5708 0" />
      <geometry>
        <cylinder radius="0.014" length="0.008" />
        </geometry>
      </collision>
    <collision name="bolt_head_3">
      <origin xyz="-0.075 0.108 0.115" rpy="0 1.5708 0" />
      <geometry>
        <cylinder radius="0.014" length="0.008" />
        </geometry>
      </collision>
    <collision name="root_pin_cap">
      <origin xyz="0 0 0.068" rpy="0 0 0" />
      <geometry>
        <cylinder radius="0.018" length="0.018" />
        </geometry>
      </collision>
    <collision name="root_pin">
      <geometry>
        <cylinder radius="0.014" length="0.132" />
        </geometry>
      </collision>
    <collision name="root_stop_tab">
      <origin xyz="0.046 0.064 0.067" rpy="0 0 0" />
      <geometry>
        <box size="0.034 0.026 0.018" />
        </geometry>
      </collision>
    </link>
  <link name="first_link">
    <visual name="upper_strap">
      <origin xyz="0.22 0 0.032" rpy="0 0 0" />
      <geometry>
        <box size="0.36 0.088 0.01" />
        </geometry>
      <material name="graphite_powder_coat">
        <color rgba="0.1 0.11 0.12 1" />
        </material>
      </visual>
    <visual name="lower_strap">
      <origin xyz="0.22 0 -0.032" rpy="0 0 0" />
      <geometry>
        <box size="0.36 0.088 0.01" />
        </geometry>
      <material name="graphite_powder_coat">
        <color rgba="0.1 0.11 0.12 1" />
        </material>
      </visual>
    <visual name="upper_root_boss">
      <origin xyz="0 0 0.032" rpy="0 0 0" />
      <geometry>
        <cylinder radius="0.042" length="0.01" />
        </geometry>
      <material name="graphite_powder_coat">
        <color rgba="0.1 0.11 0.12 1" />
        </material>
      </visual>
    <visual name="lower_root_boss">
      <origin xyz="0 0 -0.032" rpy="0 0 0" />
      <geometry>
        <cylinder radius="0.042" length="0.01" />
        </geometry>
      <material name="graphite_powder_coat">
        <color rgba="0.1 0.11 0.12 1" />
        </material>
      </visual>
    <visual name="upper_elbow_boss">
      <origin xyz="0.42 0 0.032" rpy="0 0 0" />
      <geometry>
        <cylinder radius="0.044" length="0.01" />
        </geometry>
      <material name="graphite_powder_coat">
        <color rgba="0.1 0.11 0.12 1" />
        </material>
      </visual>
    <visual name="lower_elbow_boss">
      <origin xyz="0.42 0 -0.032" rpy="0 0 0" />
      <geometry>
        <cylinder radius="0.044" length="0.01" />
        </geometry>
      <material name="graphite_powder_coat">
        <color rgba="0.1 0.11 0.12 1" />
        </material>
      </visual>
    <visual name="near_formed_edge">
      <origin xyz="0.205 -0.047 0.041" rpy="0 0 0" />
      <geometry>
        <box size="0.3 0.006 0.008" />
        </geometry>
      <material name="graphite_powder_coat">
        <color rgba="0.1 0.11 0.12 1" />
        </material>
      </visual>
    <visual name="far_formed_edge">
      <origin xyz="0.205 0.047 0.041" rpy="0 0 0" />
      <geometry>
        <box size="0.3 0.006 0.008" />
        </geometry>
      <material name="graphite_powder_coat">
        <color rgba="0.1 0.11 0.12 1" />
        </material>
      </visual>
    <visual name="box_spacer_0">
      <origin xyz="0.13 0 0" rpy="0 0 0" />
      <geometry>
        <box size="0.018 0.072 0.07" />
        </geometry>
      <material name="graphite_powder_coat">
        <color rgba="0.1 0.11 0.12 1" />
        </material>
      </visual>
    <visual name="box_spacer_1">
      <origin xyz="0.285 0 0" rpy="0 0 0" />
      <geometry>
        <box size="0.018 0.072 0.07" />
        </geometry>
      <material name="graphite_powder_coat">
        <color rgba="0.1 0.11 0.12 1" />
        </material>
      </visual>
    <visual name="pin_sleeve_0">
      <origin xyz="0 -0.035 0" rpy="0 0 0" />
      <geometry>
        <box size="0.022 0.01 0.07" />
        </geometry>
      <material name="brushed_steel">
        <color rgba="0.58 0.58 0.54 1" />
        </material>
      </visual>
    <visual name="elbow_pin">
      <origin xyz="0.42 0 0" rpy="0 0 0" />
      <geometry>
        <cylinder radius="0.014" length="0.08" />
        </geometry>
      <material name="brushed_steel">
        <color rgba="0.58 0.58 0.54 1" />
        </material>
      </visual>
    <visual name="root_stop_lug">
      <origin xyz="0.063 -0.054 0.039" rpy="0 0 0" />
      <geometry>
        <box size="0.03 0.02 0.014" />
        </geometry>
      <material name="brushed_steel">
        <color rgba="0.58 0.58 0.54 1" />
        </material>
      </visual>
    <collision name="upper_strap">
      <origin xyz="0.22 0 0.032" rpy="0 0 0" />
      <geometry>
        <box size="0.36 0.088 0.01" />
        </geometry>
      </collision>
    <collision name="lower_strap">
      <origin xyz="0.22 0 -0.032" rpy="0 0 0" />
      <geometry>
        <box size="0.36 0.088 0.01" />
        </geometry>
      </collision>
    <collision name="upper_root_boss">
      <origin xyz="0 0 0.032" rpy="0 0 0" />
      <geometry>
        <cylinder radius="0.042" length="0.01" />
        </geometry>
      </collision>
    <collision name="lower_root_boss">
      <origin xyz="0 0 -0.032" rpy="0 0 0" />
      <geometry>
        <cylinder radius="0.042" length="0.01" />
        </geometry>
      </collision>
    <collision name="upper_elbow_boss">
      <origin xyz="0.42 0 0.032" rpy="0 0 0" />
      <geometry>
        <cylinder radius="0.044" length="0.01" />
        </geometry>
      </collision>
    <collision name="lower_elbow_boss">
      <origin xyz="0.42 0 -0.032" rpy="0 0 0" />
      <geometry>
        <cylinder radius="0.044" length="0.01" />
        </geometry>
      </collision>
    <collision name="near_formed_edge">
      <origin xyz="0.205 -0.047 0.041" rpy="0 0 0" />
      <geometry>
        <box size="0.3 0.006 0.008" />
        </geometry>
      </collision>
    <collision name="far_formed_edge">
      <origin xyz="0.205 0.047 0.041" rpy="0 0 0" />
      <geometry>
        <box size="0.3 0.006 0.008" />
        </geometry>
      </collision>
    <collision name="box_spacer_0">
      <origin xyz="0.13 0 0" rpy="0 0 0" />
      <geometry>
        <box size="0.018 0.072 0.07" />
        </geometry>
      </collision>
    <collision name="box_spacer_1">
      <origin xyz="0.285 0 0" rpy="0 0 0" />
      <geometry>
        <box size="0.018 0.072 0.07" />
        </geometry>
      </collision>
    <collision name="pin_sleeve_0">
      <origin xyz="0 -0.035 0" rpy="0 0 0" />
      <geometry>
        <box size="0.022 0.01 0.07" />
        </geometry>
      </collision>
    <collision name="elbow_pin">
      <origin xyz="0.42 0 0" rpy="0 0 0" />
      <geometry>
        <cylinder radius="0.014" length="0.08" />
        </geometry>
      </collision>
    <collision name="root_stop_lug">
      <origin xyz="0.063 -0.054 0.039" rpy="0 0 0" />
      <geometry>
        <box size="0.03 0.02 0.014" />
        </geometry>
      </collision>
    </link>
  <link name="distal_link">
    <visual name="elbow_tongue_boss">
      <geometry>
        <cylinder radius="0.026" length="0.034" />
        </geometry>
      <material name="graphite_powder_coat">
        <color rgba="0.1 0.11 0.12 1" />
        </material>
      </visual>
    <visual name="elbow_tongue">
      <origin xyz="0.064 0 0" rpy="0 0 0" />
      <geometry>
        <box size="0.086 0.042 0.018" />
        </geometry>
      <material name="graphite_powder_coat">
        <color rgba="0.1 0.11 0.12 1" />
        </material>
      </visual>
    <visual name="offset_bridge">
      <origin xyz="0.076 0.066 0" rpy="0 0 0" />
      <geometry>
        <box size="0.056 0.154 0.018" />
        </geometry>
      <material name="graphite_powder_coat">
        <color rgba="0.1 0.11 0.12 1" />
        </material>
      </visual>
    <visual name="slide_web">
      <origin xyz="0.235 0.12 0" rpy="0 0 0" />
      <geometry>
        <box size="0.365 0.07 0.014" />
        </geometry>
      <material name="graphite_powder_coat">
        <color rgba="0.1 0.11 0.12 1" />
        </material>
      </visual>
    <visual name="inner_formed_rail">
      <origin xyz="0.235 0.08 0.022" rpy="0 0 0" />
      <geometry>
        <box size="0.365 0.01 0.044" />
        </geometry>
      <material name="graphite_powder_coat">
        <color rgba="0.1 0.11 0.12 1" />
        </material>
      </visual>
    <visual name="inner_keeper_strip">
      <origin xyz="0.285 0.08 0.049" rpy="0 0 0" />
      <geometry>
        <box size="0.245 0.012 0.012" />
        </geometry>
      <material name="graphite_powder_coat">
        <color rgba="0.1 0.11 0.12 1" />
        </material>
      </visual>
    <visual name="outer_formed_rail">
      <origin xyz="0.235 0.16 0.022" rpy="0 0 0" />
      <geometry>
        <box size="0.365 0.01 0.044" />
        </geometry>
      <material name="graphite_powder_coat">
        <color rgba="0.1 0.11 0.12 1" />
        </material>
      </visual>
    <visual name="outer_keeper_strip">
      <origin xyz="0.285 0.16 0.049" rpy="0 0 0" />
      <geometry>
        <box size="0.245 0.012 0.012" />
        </geometry>
      <material name="graphite_powder_coat">
        <color rgba="0.1 0.11 0.12 1" />
        </material>
      </visual>
    <visual name="end_stop">
      <origin xyz="0.414 0.175 0.025" rpy="0 0 0" />
      <geometry>
        <box size="0.02 0.02 0.055" />
        </geometry>
      <material name="brushed_steel">
        <color rgba="0.58 0.58 0.54 1" />
        </material>
      </visual>
    <visual name="elbow_stop_tab">
      <origin xyz="0.098 0.04 0.018" rpy="0 0 0" />
      <geometry>
        <box size="0.034 0.018 0.018" />
        </geometry>
      <material name="brushed_steel">
        <color rgba="0.58 0.58 0.54 1" />
        </material>
      </visual>
    <collision name="elbow_tongue_boss">
      <geometry>
        <cylinder radius="0.026" length="0.034" />
        </geometry>
      </collision>
    <collision name="elbow_tongue">
      <origin xyz="0.064 0 0" rpy="0 0 0" />
      <geometry>
        <box size="0.086 0.042 0.018" />
        </geometry>
      </collision>
    <collision name="offset_bridge">
      <origin xyz="0.076 0.066 0" rpy="0 0 0" />
      <geometry>
        <box size="0.056 0.154 0.018" />
        </geometry>
      </collision>
    <collision name="slide_web">
      <origin xyz="0.235 0.12 0" rpy="0 0 0" />
      <geometry>
        <box size="0.365 0.07 0.014" />
        </geometry>
      </collision>
    <collision name="inner_formed_rail">
      <origin xyz="0.235 0.08 0.022" rpy="0 0 0" />
      <geometry>
        <box size="0.365 0.01 0.044" />
        </geometry>
      </collision>
    <collision name="inner_keeper_strip">
      <origin xyz="0.285 0.08 0.049" rpy="0 0 0" />
      <geometry>
        <box size="0.245 0.012 0.012" />
        </geometry>
      </collision>
    <collision name="outer_formed_rail">
      <origin xyz="0.235 0.16 0.022" rpy="0 0 0" />
      <geometry>
        <box size="0.365 0.01 0.044" />
        </geometry>
      </collision>
    <collision name="outer_keeper_strip">
      <origin xyz="0.285 0.16 0.049" rpy="0 0 0" />
      <geometry>
        <box size="0.245 0.012 0.012" />
        </geometry>
      </collision>
    <collision name="end_stop">
      <origin xyz="0.414 0.175 0.025" rpy="0 0 0" />
      <geometry>
        <box size="0.02 0.02 0.055" />
        </geometry>
      </collision>
    <collision name="elbow_stop_tab">
      <origin xyz="0.098 0.04 0.018" rpy="0 0 0" />
      <geometry>
        <box size="0.034 0.018 0.018" />
        </geometry>
      </collision>
    </link>
  <link name="nose_carriage">
    <visual name="inner_slide">
      <origin xyz="-0.105 0 0.028" rpy="0 0 0" />
      <geometry>
        <box size="0.29 0.052 0.018" />
        </geometry>
      <material name="matte_black_slider">
        <color rgba="0.015 0.016 0.017 1" />
        </material>
      </visual>
    <visual name="inner_slider_pad">
      <origin xyz="-0.08 -0.03 0.029" rpy="0 0 0" />
      <geometry>
        <box size="0.18 0.01 0.014" />
        </geometry>
      <material name="black_rubber_pads">
        <color rgba="0.025 0.023 0.02 1" />
        </material>
      </visual>
    <visual name="outer_slider_pad">
      <origin xyz="-0.08 0.03 0.029" rpy="0 0 0" />
      <geometry>
        <box size="0.18 0.01 0.014" />
        </geometry>
      <material name="black_rubber_pads">
        <color rgba="0.025 0.023 0.02 1" />
        </material>
      </visual>
    <visual name="nose_body">
      <origin xyz="0.092 0 0.03" rpy="0 0 0" />
      <geometry>
        <box size="0.13 0.09 0.06" />
        </geometry>
      <material name="matte_black_slider">
        <color rgba="0.015 0.016 0.017 1" />
        </material>
      </visual>
    <visual name="front_plate">
      <origin xyz="0.163 0 0.033" rpy="0 0 0" />
      <geometry>
        <box size="0.012 0.108 0.07" />
        </geometry>
      <material name="brushed_steel">
        <color rgba="0.58 0.58 0.54 1" />
        </material>
      </visual>
    <visual name="underside_pad">
      <origin xyz="0.1 0 -0.007" rpy="0 0 0" />
      <geometry>
        <box size="0.075 0.03 0.014" />
        </geometry>
      <material name="black_rubber_pads">
        <color rgba="0.025 0.023 0.02 1" />
        </material>
      </visual>
    <collision name="inner_slide">
      <origin xyz="-0.105 0 0.028" rpy="0 0 0" />
      <geometry>
        <box size="0.29 0.052 0.018" />
        </geometry>
      </collision>
    <collision name="inner_slider_pad">
      <origin xyz="-0.08 -0.03 0.029" rpy="0 0 0" />
      <geometry>
        <box size="0.18 0.01 0.014" />
        </geometry>
      </collision>
    <collision name="outer_slider_pad">
      <origin xyz="-0.08 0.03 0.029" rpy="0 0 0" />
      <geometry>
        <box size="0.18 0.01 0.014" />
        </geometry>
      </collision>
    <collision name="nose_body">
      <origin xyz="0.092 0 0.03" rpy="0 0 0" />
      <geometry>
        <box size="0.13 0.09 0.06" />
        </geometry>
      </collision>
    <collision name="front_plate">
      <origin xyz="0.163 0 0.033" rpy="0 0 0" />
      <geometry>
        <box size="0.012 0.108 0.07" />
        </geometry>
      </collision>
    <collision name="underside_pad">
      <origin xyz="0.1 0 -0.007" rpy="0 0 0" />
      <geometry>
        <box size="0.075 0.03 0.014" />
        </geometry>
      </collision>
    </link>
  <joint name="root_pivot" type="revolute">
    <parent link="wall_bracket" />
    <child link="first_link" />
    <axis xyz="0 0 1" />
    <limit effort="90" velocity="1.2" lower="0" upper="1.55" />
    </joint>
  <joint name="elbow_pivot" type="revolute">
    <origin xyz="0.42 0 0" rpy="0 0 0" />
    <parent link="first_link" />
    <child link="distal_link" />
    <axis xyz="0 0 1" />
    <limit effort="70" velocity="1.4" lower="-2.62" upper="0.22" />
    </joint>
  <joint name="nose_slide" type="prismatic">
    <origin xyz="0.4 0.12 0" rpy="0 0 0" />
    <parent link="distal_link" />
    <child link="nose_carriage" />
    <axis xyz="1 0 0" />
    <limit effort="120" velocity="0.25" lower="0" upper="0.2" />
    </joint>
  </robot>
