<robot name="field_service_robotic_leg">
  <material name="oiled_ochre_armor">
    <color rgba="0.74 0.57 0.2 1" />
    </material>
  <material name="matte_graphite">
    <color rgba="0.06 0.065 0.07 1" />
    </material>
  <material name="brushed_steel">
    <color rgba="0.64 0.66 0.64 1" />
    </material>
  <material name="worn_black_rubber">
    <color rgba="0.015 0.014 0.012 1" />
    </material>
  <material name="blue_service_covers">
    <color rgba="0.08 0.18 0.3 1" />
    </material>
  <link name="hip_mount">
    <visual name="top_plate">
      <origin xyz="0 0 0.18" rpy="0 0 0" />
      <geometry>
        <box size="0.36 0.56 0.08" />
        </geometry>
      <material name="matte_graphite">
        <color rgba="0.06 0.065 0.07 1" />
        </material>
      </visual>
    <visual name="yoke_cheek_0">
      <origin xyz="0 0.22 0" rpy="0 0 0" />
      <geometry>
        <box size="0.26 0.06 0.3" />
        </geometry>
      <material name="matte_graphite">
        <color rgba="0.06 0.065 0.07 1" />
        </material>
      </visual>
    <visual name="yoke_cheek_1">
      <origin xyz="0 -0.22 0" rpy="0 0 0" />
      <geometry>
        <box size="0.26 0.06 0.3" />
        </geometry>
      <material name="matte_graphite">
        <color rgba="0.06 0.065 0.07 1" />
        </material>
      </visual>
    <visual name="rear_weldment">
      <origin xyz="-0.155 0 0.055" rpy="0 0 0" />
      <geometry>
        <box size="0.11 0.48 0.18" />
        </geometry>
      <material name="matte_graphite">
        <color rgba="0.06 0.065 0.07 1" />
        </material>
      </visual>
    <visual name="hip_pin">
      <origin xyz="0 0 0" rpy="1.5708 0 0" />
      <geometry>
        <cylinder radius="0.045" length="0.58" />
        </geometry>
      <material name="brushed_steel">
        <color rgba="0.64 0.66 0.64 1" />
        </material>
      </visual>
    <visual name="bearing_cap_0">
      <origin xyz="0 0.305 0" rpy="1.5708 0 0" />
      <geometry>
        <cylinder radius="0.075" length="0.045" />
        </geometry>
      <material name="brushed_steel">
        <color rgba="0.64 0.66 0.64 1" />
        </material>
      </visual>
    <visual name="bearing_cap_1">
      <origin xyz="0 -0.305 0" rpy="1.5708 0 0" />
      <geometry>
        <cylinder radius="0.075" length="0.045" />
        </geometry>
      <material name="brushed_steel">
        <color rgba="0.64 0.66 0.64 1" />
        </material>
      </visual>
    <visual name="inspection_cover">
      <origin xyz="0.055 0 0.232" rpy="0 0 0" />
      <geometry>
        <box size="0.18 0.3 0.025" />
        </geometry>
      <material name="blue_service_covers">
        <color rgba="0.08 0.18 0.3 1" />
        </material>
      </visual>
    <visual name="top_bolt_0">
      <origin xyz="-0.1 -0.19 0.225" rpy="0 0 0" />
      <geometry>
        <cylinder radius="0.013" length="0.014" />
        </geometry>
      <material name="brushed_steel">
        <color rgba="0.64 0.66 0.64 1" />
        </material>
      </visual>
    <visual name="top_bolt_1">
      <origin xyz="-0.1 0.19 0.225" rpy="0 0 0" />
      <geometry>
        <cylinder radius="0.013" length="0.014" />
        </geometry>
      <material name="brushed_steel">
        <color rgba="0.64 0.66 0.64 1" />
        </material>
      </visual>
    <visual name="top_bolt_2">
      <origin xyz="0.11 -0.19 0.225" rpy="0 0 0" />
      <geometry>
        <cylinder radius="0.013" length="0.014" />
        </geometry>
      <material name="brushed_steel">
        <color rgba="0.64 0.66 0.64 1" />
        </material>
      </visual>
    <visual name="top_bolt_3">
      <origin xyz="0.11 0.19 0.225" rpy="0 0 0" />
      <geometry>
        <cylinder radius="0.013" length="0.014" />
        </geometry>
      <material name="brushed_steel">
        <color rgba="0.64 0.66 0.64 1" />
        </material>
      </visual>
    <collision name="top_plate">
      <origin xyz="0 0 0.18" rpy="0 0 0" />
      <geometry>
        <box size="0.36 0.56 0.08" />
        </geometry>
      </collision>
    <collision name="yoke_cheek_0">
      <origin xyz="0 0.22 0" rpy="0 0 0" />
      <geometry>
        <box size="0.26 0.06 0.3" />
        </geometry>
      </collision>
    <collision name="yoke_cheek_1">
      <origin xyz="0 -0.22 0" rpy="0 0 0" />
      <geometry>
        <box size="0.26 0.06 0.3" />
        </geometry>
      </collision>
    <collision name="rear_weldment">
      <origin xyz="-0.155 0 0.055" rpy="0 0 0" />
      <geometry>
        <box size="0.11 0.48 0.18" />
        </geometry>
      </collision>
    <collision name="hip_pin">
      <origin xyz="0 0 0" rpy="1.5708 0 0" />
      <geometry>
        <cylinder radius="0.045" length="0.58" />
        </geometry>
      </collision>
    <collision name="bearing_cap_0">
      <origin xyz="0 0.305 0" rpy="1.5708 0 0" />
      <geometry>
        <cylinder radius="0.075" length="0.045" />
        </geometry>
      </collision>
    <collision name="bearing_cap_1">
      <origin xyz="0 -0.305 0" rpy="1.5708 0 0" />
      <geometry>
        <cylinder radius="0.075" length="0.045" />
        </geometry>
      </collision>
    <collision name="inspection_cover">
      <origin xyz="0.055 0 0.232" rpy="0 0 0" />
      <geometry>
        <box size="0.18 0.3 0.025" />
        </geometry>
      </collision>
    <collision name="top_bolt_0">
      <origin xyz="-0.1 -0.19 0.225" rpy="0 0 0" />
      <geometry>
        <cylinder radius="0.013" length="0.014" />
        </geometry>
      </collision>
    <collision name="top_bolt_1">
      <origin xyz="-0.1 0.19 0.225" rpy="0 0 0" />
      <geometry>
        <cylinder radius="0.013" length="0.014" />
        </geometry>
      </collision>
    <collision name="top_bolt_2">
      <origin xyz="0.11 -0.19 0.225" rpy="0 0 0" />
      <geometry>
        <cylinder radius="0.013" length="0.014" />
        </geometry>
      </collision>
    <collision name="top_bolt_3">
      <origin xyz="0.11 0.19 0.225" rpy="0 0 0" />
      <geometry>
        <cylinder radius="0.013" length="0.014" />
        </geometry>
      </collision>
    </link>
  <link name="thigh">
    <visual name="hip_hub">
      <origin xyz="0 0 0" rpy="1.5708 0 0" />
      <geometry>
        <cylinder radius="0.075" length="0.26" />
        </geometry>
      <material name="brushed_steel">
        <color rgba="0.64 0.66 0.64 1" />
        </material>
      </visual>
    <visual name="upper_web">
      <origin xyz="0.02 0 -0.155" rpy="0 0 0" />
      <geometry>
        <box size="0.13 0.22 0.2" />
        </geometry>
      <material name="matte_graphite">
        <color rgba="0.06 0.065 0.07 1" />
        </material>
      </visual>
    <visual name="thigh_shell">
      <origin xyz="0.02 0 -0.315" rpy="0 0 0" />
      <geometry>
        <box size="0.18 0.26 0.37" />
        </geometry>
      <material name="oiled_ochre_armor">
        <color rgba="0.74 0.57 0.2 1" />
        </material>
      </visual>
    <visual name="actuator_bay">
      <origin xyz="0.132 0 -0.325" rpy="0 0 0" />
      <geometry>
        <box size="0.05 0.19 0.3" />
        </geometry>
      <material name="blue_service_covers">
        <color rgba="0.08 0.18 0.3 1" />
        </material>
      </visual>
    <visual name="side_rail_0">
      <origin xyz="0.015 0.145 -0.39" rpy="0 0 0" />
      <geometry>
        <box size="0.09 0.036 0.39" />
        </geometry>
      <material name="matte_graphite">
        <color rgba="0.06 0.065 0.07 1" />
        </material>
      </visual>
    <visual name="side_rail_1">
      <origin xyz="0.015 -0.145 -0.39" rpy="0 0 0" />
      <geometry>
        <box size="0.09 0.036 0.39" />
        </geometry>
      <material name="matte_graphite">
        <color rgba="0.06 0.065 0.07 1" />
        </material>
      </visual>
    <visual name="knee_fork_0">
      <origin xyz="0.02 0.16 -0.62" rpy="0 0 0" />
      <geometry>
        <box size="0.18 0.055 0.23" />
        </geometry>
      <material name="matte_graphite">
        <color rgba="0.06 0.065 0.07 1" />
        </material>
      </visual>
    <visual name="knee_fork_1">
      <origin xyz="0.02 -0.16 -0.62" rpy="0 0 0" />
      <geometry>
        <box size="0.18 0.055 0.23" />
        </geometry>
      <material name="matte_graphite">
        <color rgba="0.06 0.065 0.07 1" />
        </material>
      </visual>
    <visual name="knee_pin">
      <origin xyz="0.02 0 -0.62" rpy="1.5708 0 0" />
      <geometry>
        <cylinder radius="0.045" length="0.42" />
        </geometry>
      <material name="brushed_steel">
        <color rgba="0.64 0.66 0.64 1" />
        </material>
      </visual>
    <visual name="knee_cap_0">
      <origin xyz="0.02 0.225 -0.62" rpy="1.5708 0 0" />
      <geometry>
        <cylinder radius="0.07" length="0.035" />
        </geometry>
      <material name="brushed_steel">
        <color rgba="0.64 0.66 0.64 1" />
        </material>
      </visual>
    <visual name="knee_cap_1">
      <origin xyz="0.02 -0.225 -0.62" rpy="1.5708 0 0" />
      <geometry>
        <cylinder radius="0.07" length="0.035" />
        </geometry>
      <material name="brushed_steel">
        <color rgba="0.64 0.66 0.64 1" />
        </material>
      </visual>
    <visual name="bay_bolt_0">
      <origin xyz="0.158 -0.065 -0.235" rpy="0 1.5708 0" />
      <geometry>
        <cylinder radius="0.01" length="0.014" />
        </geometry>
      <material name="brushed_steel">
        <color rgba="0.64 0.66 0.64 1" />
        </material>
      </visual>
    <visual name="bay_bolt_1">
      <origin xyz="0.158 0.065 -0.235" rpy="0 1.5708 0" />
      <geometry>
        <cylinder radius="0.01" length="0.014" />
        </geometry>
      <material name="brushed_steel">
        <color rgba="0.64 0.66 0.64 1" />
        </material>
      </visual>
    <visual name="bay_bolt_2">
      <origin xyz="0.158 -0.065 -0.455" rpy="0 1.5708 0" />
      <geometry>
        <cylinder radius="0.01" length="0.014" />
        </geometry>
      <material name="brushed_steel">
        <color rgba="0.64 0.66 0.64 1" />
        </material>
      </visual>
    <visual name="bay_bolt_3">
      <origin xyz="0.158 0.065 -0.455" rpy="0 1.5708 0" />
      <geometry>
        <cylinder radius="0.01" length="0.014" />
        </geometry>
      <material name="brushed_steel">
        <color rgba="0.64 0.66 0.64 1" />
        </material>
      </visual>
    <collision name="hip_hub">
      <origin xyz="0 0 0" rpy="1.5708 0 0" />
      <geometry>
        <cylinder radius="0.075" length="0.26" />
        </geometry>
      </collision>
    <collision name="upper_web">
      <origin xyz="0.02 0 -0.155" rpy="0 0 0" />
      <geometry>
        <box size="0.13 0.22 0.2" />
        </geometry>
      </collision>
    <collision name="thigh_shell">
      <origin xyz="0.02 0 -0.315" rpy="0 0 0" />
      <geometry>
        <box size="0.18 0.26 0.37" />
        </geometry>
      </collision>
    <collision name="actuator_bay">
      <origin xyz="0.132 0 -0.325" rpy="0 0 0" />
      <geometry>
        <box size="0.05 0.19 0.3" />
        </geometry>
      </collision>
    <collision name="side_rail_0">
      <origin xyz="0.015 0.145 -0.39" rpy="0 0 0" />
      <geometry>
        <box size="0.09 0.036 0.39" />
        </geometry>
      </collision>
    <collision name="side_rail_1">
      <origin xyz="0.015 -0.145 -0.39" rpy="0 0 0" />
      <geometry>
        <box size="0.09 0.036 0.39" />
        </geometry>
      </collision>
    <collision name="knee_fork_0">
      <origin xyz="0.02 0.16 -0.62" rpy="0 0 0" />
      <geometry>
        <box size="0.18 0.055 0.23" />
        </geometry>
      </collision>
    <collision name="knee_fork_1">
      <origin xyz="0.02 -0.16 -0.62" rpy="0 0 0" />
      <geometry>
        <box size="0.18 0.055 0.23" />
        </geometry>
      </collision>
    <collision name="knee_pin">
      <origin xyz="0.02 0 -0.62" rpy="1.5708 0 0" />
      <geometry>
        <cylinder radius="0.045" length="0.42" />
        </geometry>
      </collision>
    <collision name="knee_cap_0">
      <origin xyz="0.02 0.225 -0.62" rpy="1.5708 0 0" />
      <geometry>
        <cylinder radius="0.07" length="0.035" />
        </geometry>
      </collision>
    <collision name="knee_cap_1">
      <origin xyz="0.02 -0.225 -0.62" rpy="1.5708 0 0" />
      <geometry>
        <cylinder radius="0.07" length="0.035" />
        </geometry>
      </collision>
    <collision name="bay_bolt_0">
      <origin xyz="0.158 -0.065 -0.235" rpy="0 1.5708 0" />
      <geometry>
        <cylinder radius="0.01" length="0.014" />
        </geometry>
      </collision>
    <collision name="bay_bolt_1">
      <origin xyz="0.158 0.065 -0.235" rpy="0 1.5708 0" />
      <geometry>
        <cylinder radius="0.01" length="0.014" />
        </geometry>
      </collision>
    <collision name="bay_bolt_2">
      <origin xyz="0.158 -0.065 -0.455" rpy="0 1.5708 0" />
      <geometry>
        <cylinder radius="0.01" length="0.014" />
        </geometry>
      </collision>
    <collision name="bay_bolt_3">
      <origin xyz="0.158 0.065 -0.455" rpy="0 1.5708 0" />
      <geometry>
        <cylinder radius="0.01" length="0.014" />
        </geometry>
      </collision>
    </link>
  <link name="shin">
    <visual name="knee_hub">
      <origin xyz="0 0 0" rpy="1.5708 0 0" />
      <geometry>
        <cylinder radius="0.072" length="0.24" />
        </geometry>
      <material name="brushed_steel">
        <color rgba="0.64 0.66 0.64 1" />
        </material>
      </visual>
    <visual name="upper_web">
      <origin xyz="0.025 0 -0.14" rpy="0 0 0" />
      <geometry>
        <box size="0.12 0.2 0.17" />
        </geometry>
      <material name="matte_graphite">
        <color rgba="0.06 0.065 0.07 1" />
        </material>
      </visual>
    <visual name="shin_shell">
      <origin xyz="0.035 0 -0.315" rpy="0 0 0" />
      <geometry>
        <box size="0.16 0.22 0.37" />
        </geometry>
      <material name="oiled_ochre_armor">
        <color rgba="0.74 0.57 0.2 1" />
        </material>
      </visual>
    <visual name="drive_cover">
      <origin xyz="-0.067 0 -0.32" rpy="0 0 0" />
      <geometry>
        <box size="0.045 0.18 0.3" />
        </geometry>
      <material name="blue_service_covers">
        <color rgba="0.08 0.18 0.3 1" />
        </material>
      </visual>
    <visual name="front_wear_strip">
      <origin xyz="0.128 0 -0.35" rpy="0 0 0" />
      <geometry>
        <box size="0.035 0.16 0.3" />
        </geometry>
      <material name="worn_black_rubber">
        <color rgba="0.015 0.014 0.012 1" />
        </material>
      </visual>
    <visual name="edge_rail_0">
      <origin xyz="0.035 0.128 -0.39" rpy="0 0 0" />
      <geometry>
        <box size="0.08 0.04 0.36" />
        </geometry>
      <material name="matte_graphite">
        <color rgba="0.06 0.065 0.07 1" />
        </material>
      </visual>
    <visual name="edge_rail_1">
      <origin xyz="0.035 -0.128 -0.39" rpy="0 0 0" />
      <geometry>
        <box size="0.08 0.04 0.36" />
        </geometry>
      <material name="matte_graphite">
        <color rgba="0.06 0.065 0.07 1" />
        </material>
      </visual>
    <visual name="ankle_fork_0">
      <origin xyz="0.04 0.15 -0.58" rpy="0 0 0" />
      <geometry>
        <box size="0.16 0.05 0.22" />
        </geometry>
      <material name="matte_graphite">
        <color rgba="0.06 0.065 0.07 1" />
        </material>
      </visual>
    <visual name="ankle_fork_1">
      <origin xyz="0.04 -0.15 -0.58" rpy="0 0 0" />
      <geometry>
        <box size="0.16 0.05 0.22" />
        </geometry>
      <material name="matte_graphite">
        <color rgba="0.06 0.065 0.07 1" />
        </material>
      </visual>
    <visual name="ankle_pin">
      <origin xyz="0.04 0 -0.58" rpy="1.5708 0 0" />
      <geometry>
        <cylinder radius="0.04" length="0.38" />
        </geometry>
      <material name="brushed_steel">
        <color rgba="0.64 0.66 0.64 1" />
        </material>
      </visual>
    <visual name="cover_bolt_0">
      <origin xyz="-0.096 -0.065 -0.25" rpy="0 1.5708 0" />
      <geometry>
        <cylinder radius="0.009" length="0.014" />
        </geometry>
      <material name="brushed_steel">
        <color rgba="0.64 0.66 0.64 1" />
        </material>
      </visual>
    <visual name="cover_bolt_1">
      <origin xyz="-0.096 0.065 -0.25" rpy="0 1.5708 0" />
      <geometry>
        <cylinder radius="0.009" length="0.014" />
        </geometry>
      <material name="brushed_steel">
        <color rgba="0.64 0.66 0.64 1" />
        </material>
      </visual>
    <visual name="cover_bolt_2">
      <origin xyz="-0.096 -0.065 -0.43" rpy="0 1.5708 0" />
      <geometry>
        <cylinder radius="0.009" length="0.014" />
        </geometry>
      <material name="brushed_steel">
        <color rgba="0.64 0.66 0.64 1" />
        </material>
      </visual>
    <visual name="cover_bolt_3">
      <origin xyz="-0.096 0.065 -0.43" rpy="0 1.5708 0" />
      <geometry>
        <cylinder radius="0.009" length="0.014" />
        </geometry>
      <material name="brushed_steel">
        <color rgba="0.64 0.66 0.64 1" />
        </material>
      </visual>
    <collision name="knee_hub">
      <origin xyz="0 0 0" rpy="1.5708 0 0" />
      <geometry>
        <cylinder radius="0.072" length="0.24" />
        </geometry>
      </collision>
    <collision name="upper_web">
      <origin xyz="0.025 0 -0.14" rpy="0 0 0" />
      <geometry>
        <box size="0.12 0.2 0.17" />
        </geometry>
      </collision>
    <collision name="shin_shell">
      <origin xyz="0.035 0 -0.315" rpy="0 0 0" />
      <geometry>
        <box size="0.16 0.22 0.37" />
        </geometry>
      </collision>
    <collision name="drive_cover">
      <origin xyz="-0.067 0 -0.32" rpy="0 0 0" />
      <geometry>
        <box size="0.045 0.18 0.3" />
        </geometry>
      </collision>
    <collision name="front_wear_strip">
      <origin xyz="0.128 0 -0.35" rpy="0 0 0" />
      <geometry>
        <box size="0.035 0.16 0.3" />
        </geometry>
      </collision>
    <collision name="edge_rail_0">
      <origin xyz="0.035 0.128 -0.39" rpy="0 0 0" />
      <geometry>
        <box size="0.08 0.04 0.36" />
        </geometry>
      </collision>
    <collision name="edge_rail_1">
      <origin xyz="0.035 -0.128 -0.39" rpy="0 0 0" />
      <geometry>
        <box size="0.08 0.04 0.36" />
        </geometry>
      </collision>
    <collision name="ankle_fork_0">
      <origin xyz="0.04 0.15 -0.58" rpy="0 0 0" />
      <geometry>
        <box size="0.16 0.05 0.22" />
        </geometry>
      </collision>
    <collision name="ankle_fork_1">
      <origin xyz="0.04 -0.15 -0.58" rpy="0 0 0" />
      <geometry>
        <box size="0.16 0.05 0.22" />
        </geometry>
      </collision>
    <collision name="ankle_pin">
      <origin xyz="0.04 0 -0.58" rpy="1.5708 0 0" />
      <geometry>
        <cylinder radius="0.04" length="0.38" />
        </geometry>
      </collision>
    <collision name="cover_bolt_0">
      <origin xyz="-0.096 -0.065 -0.25" rpy="0 1.5708 0" />
      <geometry>
        <cylinder radius="0.009" length="0.014" />
        </geometry>
      </collision>
    <collision name="cover_bolt_1">
      <origin xyz="-0.096 0.065 -0.25" rpy="0 1.5708 0" />
      <geometry>
        <cylinder radius="0.009" length="0.014" />
        </geometry>
      </collision>
    <collision name="cover_bolt_2">
      <origin xyz="-0.096 -0.065 -0.43" rpy="0 1.5708 0" />
      <geometry>
        <cylinder radius="0.009" length="0.014" />
        </geometry>
      </collision>
    <collision name="cover_bolt_3">
      <origin xyz="-0.096 0.065 -0.43" rpy="0 1.5708 0" />
      <geometry>
        <cylinder radius="0.009" length="0.014" />
        </geometry>
      </collision>
    </link>
  <link name="foot">
    <visual name="ankle_hub">
      <origin xyz="0 0 0" rpy="1.5708 0 0" />
      <geometry>
        <cylinder radius="0.065" length="0.22" />
        </geometry>
      <material name="brushed_steel">
        <color rgba="0.64 0.66 0.64 1" />
        </material>
      </visual>
    <visual name="ankle_neck">
      <origin xyz="0.02 0 -0.12" rpy="0 0 0" />
      <geometry>
        <box size="0.12 0.17 0.15" />
        </geometry>
      <material name="matte_graphite">
        <color rgba="0.06 0.065 0.07 1" />
        </material>
      </visual>
    <visual name="sole_carrier">
      <origin xyz="0.12 0 -0.22" rpy="0 0 0" />
      <geometry>
        <box size="0.54 0.26 0.1" />
        </geometry>
      <material name="matte_graphite">
        <color rgba="0.06 0.065 0.07 1" />
        </material>
      </visual>
    <visual name="heel_wear_pad">
      <origin xyz="-0.08 0 -0.288" rpy="0 0 0" />
      <geometry>
        <box size="0.2 0.25 0.045" />
        </geometry>
      <material name="worn_black_rubber">
        <color rgba="0.015 0.014 0.012 1" />
        </material>
      </visual>
    <visual name="toe_wear_pad">
      <origin xyz="0.24 0 -0.288" rpy="0 0 0" />
      <geometry>
        <box size="0.26 0.25 0.045" />
        </geometry>
      <material name="worn_black_rubber">
        <color rgba="0.015 0.014 0.012 1" />
        </material>
      </visual>
    <visual name="toe_bumper">
      <origin xyz="0.405 0 -0.215" rpy="0 0 0" />
      <geometry>
        <box size="0.1 0.22 0.055" />
        </geometry>
      <material name="oiled_ochre_armor">
        <color rgba="0.74 0.57 0.2 1" />
        </material>
      </visual>
    <visual name="sole_bolt_0">
      <origin xyz="0.02 -0.09 -0.164" rpy="0 0 0" />
      <geometry>
        <cylinder radius="0.01" length="0.014" />
        </geometry>
      <material name="brushed_steel">
        <color rgba="0.64 0.66 0.64 1" />
        </material>
      </visual>
    <visual name="sole_bolt_1">
      <origin xyz="0.02 0.09 -0.164" rpy="0 0 0" />
      <geometry>
        <cylinder radius="0.01" length="0.014" />
        </geometry>
      <material name="brushed_steel">
        <color rgba="0.64 0.66 0.64 1" />
        </material>
      </visual>
    <visual name="sole_bolt_2">
      <origin xyz="0.28 -0.09 -0.164" rpy="0 0 0" />
      <geometry>
        <cylinder radius="0.01" length="0.014" />
        </geometry>
      <material name="brushed_steel">
        <color rgba="0.64 0.66 0.64 1" />
        </material>
      </visual>
    <visual name="sole_bolt_3">
      <origin xyz="0.28 0.09 -0.164" rpy="0 0 0" />
      <geometry>
        <cylinder radius="0.01" length="0.014" />
        </geometry>
      <material name="brushed_steel">
        <color rgba="0.64 0.66 0.64 1" />
        </material>
      </visual>
    <collision name="ankle_hub">
      <origin xyz="0 0 0" rpy="1.5708 0 0" />
      <geometry>
        <cylinder radius="0.065" length="0.22" />
        </geometry>
      </collision>
    <collision name="ankle_neck">
      <origin xyz="0.02 0 -0.12" rpy="0 0 0" />
      <geometry>
        <box size="0.12 0.17 0.15" />
        </geometry>
      </collision>
    <collision name="sole_carrier">
      <origin xyz="0.12 0 -0.22" rpy="0 0 0" />
      <geometry>
        <box size="0.54 0.26 0.1" />
        </geometry>
      </collision>
    <collision name="heel_wear_pad">
      <origin xyz="-0.08 0 -0.288" rpy="0 0 0" />
      <geometry>
        <box size="0.2 0.25 0.045" />
        </geometry>
      </collision>
    <collision name="toe_wear_pad">
      <origin xyz="0.24 0 -0.288" rpy="0 0 0" />
      <geometry>
        <box size="0.26 0.25 0.045" />
        </geometry>
      </collision>
    <collision name="toe_bumper">
      <origin xyz="0.405 0 -0.215" rpy="0 0 0" />
      <geometry>
        <box size="0.1 0.22 0.055" />
        </geometry>
      </collision>
    <collision name="sole_bolt_0">
      <origin xyz="0.02 -0.09 -0.164" rpy="0 0 0" />
      <geometry>
        <cylinder radius="0.01" length="0.014" />
        </geometry>
      </collision>
    <collision name="sole_bolt_1">
      <origin xyz="0.02 0.09 -0.164" rpy="0 0 0" />
      <geometry>
        <cylinder radius="0.01" length="0.014" />
        </geometry>
      </collision>
    <collision name="sole_bolt_2">
      <origin xyz="0.28 -0.09 -0.164" rpy="0 0 0" />
      <geometry>
        <cylinder radius="0.01" length="0.014" />
        </geometry>
      </collision>
    <collision name="sole_bolt_3">
      <origin xyz="0.28 0.09 -0.164" rpy="0 0 0" />
      <geometry>
        <cylinder radius="0.01" length="0.014" />
        </geometry>
      </collision>
    </link>
  <joint name="hip_pitch" type="revolute">
    <parent link="hip_mount" />
    <child link="thigh" />
    <axis xyz="0 1 0" />
    <limit effort="900" velocity="1.2" lower="-0.75" upper="0.85" />
    </joint>
  <joint name="knee_pitch" type="revolute">
    <origin xyz="0.02 0 -0.62" rpy="0 0 0" />
    <parent link="thigh" />
    <child link="shin" />
    <axis xyz="0 -1 0" />
    <limit effort="1050" velocity="1.4" lower="0" upper="1.55" />
    </joint>
  <joint name="ankle_pitch" type="revolute">
    <origin xyz="0.04 0 -0.58" rpy="0 0 0" />
    <parent link="shin" />
    <child link="foot" />
    <axis xyz="0 1 0" />
    <limit effort="650" velocity="1.6" lower="-0.65" upper="0.65" />
    </joint>
  </robot>
