<robot name="calibrated_stick_vacuum">
  <material name="graphite_polymer">
    <color rgba="0.055 0.058 0.064 1" />
    </material>
  <material name="satin_black">
    <color rgba="0.01 0.012 0.014 1" />
    </material>
  <material name="black_rubber">
    <color rgba="0.018 0.016 0.014 1" />
    </material>
  <material name="datum_gray">
    <color rgba="0.62 0.66 0.66 1" />
    </material>
  <material name="etched_white">
    <color rgba="0.92 0.95 0.92 1" />
    </material>
  <material name="calibration_blue">
    <color rgba="0.08 0.45 0.82 1" />
    </material>
  <material name="brushed_steel">
    <color rgba="0.58 0.6 0.62 1" />
    </material>
  <link name="body">
    <visual name="body_shell">
      <origin xyz="0 0 0.33" rpy="0 0 0" />
      <geometry>
        <mesh filename="assets/meshes/body_shell.obj" />
        </geometry>
      <material name="graphite_polymer">
        <color rgba="0.055 0.058 0.064 1" />
        </material>
      </visual>
    <visual name="fold_socket">
      <origin xyz="0 0 0.075" rpy="0 0 0" />
      <geometry>
        <box size="0.07 0.09 0.09" />
        </geometry>
      <material name="graphite_polymer">
        <color rgba="0.055 0.058 0.064 1" />
        </material>
      </visual>
    <visual name="fold_cheek_0">
      <origin xyz="0 0.043 0" rpy="0 0 0" />
      <geometry>
        <box size="0.05 0.014 0.088" />
        </geometry>
      <material name="satin_black">
        <color rgba="0.01 0.012 0.014 1" />
        </material>
      </visual>
    <visual name="fold_cheek_1">
      <origin xyz="0 -0.043 0" rpy="0 0 0" />
      <geometry>
        <box size="0.05 0.014 0.088" />
        </geometry>
      <material name="satin_black">
        <color rgba="0.01 0.012 0.014 1" />
        </material>
      </visual>
    <visual name="fold_pin">
      <origin xyz="0 0 0" rpy="-1.5708 0 0" />
      <geometry>
        <cylinder radius="0.009" length="0.104" />
        </geometry>
      <material name="brushed_steel">
        <color rgba="0.58 0.6 0.62 1" />
        </material>
      </visual>
    <visual name="dial_mount_web">
      <origin xyz="0 -0.0575 0.016" rpy="0 0 0" />
      <geometry>
        <box size="0.048 0.025 0.04" />
        </geometry>
      <material name="satin_black">
        <color rgba="0.01 0.012 0.014 1" />
        </material>
      </visual>
    <visual name="dial_boss">
      <origin xyz="0 -0.065 0.016" rpy="-1.5708 0 0" />
      <geometry>
        <cylinder radius="0.025" length="0.01" />
        </geometry>
      <material name="satin_black">
        <color rgba="0.01 0.012 0.014 1" />
        </material>
      </visual>
    <visual name="handle_grip">
      <origin xyz="0.082 0 0.235" rpy="0 0 0" />
      <geometry>
        <box size="0.035 0.05 0.15" />
        </geometry>
      <material name="satin_black">
        <color rgba="0.01 0.012 0.014 1" />
        </material>
      </visual>
    <visual name="handle_bridge_top">
      <origin xyz="0.045 0 0.31" rpy="0 0 0" />
      <geometry>
        <box size="0.09 0.04 0.034" />
        </geometry>
      <material name="satin_black">
        <color rgba="0.01 0.012 0.014 1" />
        </material>
      </visual>
    <visual name="handle_bridge_low">
      <origin xyz="0.048 0 0.15" rpy="0 0 0" />
      <geometry>
        <box size="0.095 0.042 0.044" />
        </geometry>
      <material name="satin_black">
        <color rgba="0.01 0.012 0.014 1" />
        </material>
      </visual>
    <visual name="battery_pack">
      <origin xyz="0.058 0 0.105" rpy="0 0 0" />
      <geometry>
        <box size="0.08 0.06 0.09" />
        </geometry>
      <material name="black_rubber">
        <color rgba="0.018 0.016 0.014 1" />
        </material>
      </visual>
    <visual name="fold_index_0">
      <origin xyz="-0.03 0.045 0.075" rpy="0 0 0" />
      <geometry>
        <box size="0.003 0.0022 0.013" />
        </geometry>
      <material name="datum_gray">
        <color rgba="0.62 0.66 0.66 1" />
        </material>
      </visual>
    <visual name="fold_index_1">
      <origin xyz="-0.015 0.045 0.075" rpy="0 0 0" />
      <geometry>
        <box size="0.003 0.0022 0.013" />
        </geometry>
      <material name="datum_gray">
        <color rgba="0.62 0.66 0.66 1" />
        </material>
      </visual>
    <visual name="fold_index_2">
      <origin xyz="0 0.045 0.075" rpy="0 0 0" />
      <geometry>
        <box size="0.003 0.0022 0.02" />
        </geometry>
      <material name="etched_white">
        <color rgba="0.92 0.95 0.92 1" />
        </material>
      </visual>
    <visual name="fold_index_3">
      <origin xyz="0.015 0.045 0.075" rpy="0 0 0" />
      <geometry>
        <box size="0.003 0.0022 0.013" />
        </geometry>
      <material name="datum_gray">
        <color rgba="0.62 0.66 0.66 1" />
        </material>
      </visual>
    <visual name="fold_index_4">
      <origin xyz="0.03 0.045 0.075" rpy="0 0 0" />
      <geometry>
        <box size="0.003 0.0022 0.013" />
        </geometry>
      <material name="datum_gray">
        <color rgba="0.62 0.66 0.66 1" />
        </material>
      </visual>
    <collision name="body_shell">
      <origin xyz="0 0 0.33" rpy="0 0 0" />
      <geometry>
        <mesh filename="assets/meshes/body_shell.obj" />
        </geometry>
      </collision>
    <collision name="fold_socket">
      <origin xyz="0 0 0.075" rpy="0 0 0" />
      <geometry>
        <box size="0.07 0.09 0.09" />
        </geometry>
      </collision>
    <collision name="fold_cheek_0">
      <origin xyz="0 0.043 0" rpy="0 0 0" />
      <geometry>
        <box size="0.05 0.014 0.088" />
        </geometry>
      </collision>
    <collision name="fold_cheek_1">
      <origin xyz="0 -0.043 0" rpy="0 0 0" />
      <geometry>
        <box size="0.05 0.014 0.088" />
        </geometry>
      </collision>
    <collision name="fold_pin">
      <origin xyz="0 0 0" rpy="-1.5708 0 0" />
      <geometry>
        <cylinder radius="0.009" length="0.104" />
        </geometry>
      </collision>
    <collision name="dial_mount_web">
      <origin xyz="0 -0.0575 0.016" rpy="0 0 0" />
      <geometry>
        <box size="0.048 0.025 0.04" />
        </geometry>
      </collision>
    <collision name="dial_boss">
      <origin xyz="0 -0.065 0.016" rpy="-1.5708 0 0" />
      <geometry>
        <cylinder radius="0.025" length="0.01" />
        </geometry>
      </collision>
    <collision name="handle_grip">
      <origin xyz="0.082 0 0.235" rpy="0 0 0" />
      <geometry>
        <box size="0.035 0.05 0.15" />
        </geometry>
      </collision>
    <collision name="handle_bridge_top">
      <origin xyz="0.045 0 0.31" rpy="0 0 0" />
      <geometry>
        <box size="0.09 0.04 0.034" />
        </geometry>
      </collision>
    <collision name="handle_bridge_low">
      <origin xyz="0.048 0 0.15" rpy="0 0 0" />
      <geometry>
        <box size="0.095 0.042 0.044" />
        </geometry>
      </collision>
    <collision name="battery_pack">
      <origin xyz="0.058 0 0.105" rpy="0 0 0" />
      <geometry>
        <box size="0.08 0.06 0.09" />
        </geometry>
      </collision>
    <collision name="fold_index_0">
      <origin xyz="-0.03 0.045 0.075" rpy="0 0 0" />
      <geometry>
        <box size="0.003 0.0022 0.013" />
        </geometry>
      </collision>
    <collision name="fold_index_1">
      <origin xyz="-0.015 0.045 0.075" rpy="0 0 0" />
      <geometry>
        <box size="0.003 0.0022 0.013" />
        </geometry>
      </collision>
    <collision name="fold_index_2">
      <origin xyz="0 0.045 0.075" rpy="0 0 0" />
      <geometry>
        <box size="0.003 0.0022 0.02" />
        </geometry>
      </collision>
    <collision name="fold_index_3">
      <origin xyz="0.015 0.045 0.075" rpy="0 0 0" />
      <geometry>
        <box size="0.003 0.0022 0.013" />
        </geometry>
      </collision>
    <collision name="fold_index_4">
      <origin xyz="0.03 0.045 0.075" rpy="0 0 0" />
      <geometry>
        <box size="0.003 0.0022 0.013" />
        </geometry>
      </collision>
    </link>
  <link name="alignment_dial">
    <visual name="dial_cap">
      <origin xyz="0 0 0" rpy="1.5708 0 0" />
      <geometry>
        <mesh filename="assets/meshes/alignment_dial_cap.obj" />
        </geometry>
      <material name="satin_black">
        <color rgba="0.01 0.012 0.014 1" />
        </material>
      </visual>
    <visual name="dial_pointer">
      <origin xyz="0.005 -0.0144 0" rpy="0 0 0" />
      <geometry>
        <box size="0.02 0.002 0.004" />
        </geometry>
      <material name="calibration_blue">
        <color rgba="0.08 0.45 0.82 1" />
        </material>
      </visual>
    <collision name="dial_cap">
      <origin xyz="0 0 0" rpy="1.5708 0 0" />
      <geometry>
        <mesh filename="assets/meshes/alignment_dial_cap.obj" />
        </geometry>
      </collision>
    <collision name="dial_pointer">
      <origin xyz="0.005 -0.0144 0" rpy="0 0 0" />
      <geometry>
        <box size="0.02 0.002 0.004" />
        </geometry>
      </collision>
    </link>
  <link name="wand">
    <visual name="fold_barrel">
      <origin xyz="0 0 0" rpy="-1.5708 0 0" />
      <geometry>
        <cylinder radius="0.017" length="0.06" />
        </geometry>
      <material name="graphite_polymer">
        <color rgba="0.055 0.058 0.064 1" />
        </material>
      </visual>
    <visual name="upper_socket">
      <origin xyz="0 0 -0.045" rpy="0 0 0" />
      <geometry>
        <box size="0.032 0.034 0.06" />
        </geometry>
      <material name="graphite_polymer">
        <color rgba="0.055 0.058 0.064 1" />
        </material>
      </visual>
    <visual name="wand_tube">
      <origin xyz="0 0 -0.45" rpy="0 0 0" />
      <geometry>
        <box size="0.038 0.026 0.82" />
        </geometry>
      <material name="graphite_polymer">
        <color rgba="0.055 0.058 0.064 1" />
        </material>
      </visual>
    <visual name="straight_datum_rail">
      <origin xyz="-0.0208 0 -0.475" rpy="0 0 0" />
      <geometry>
        <box size="0.004 0.028 0.73" />
        </geometry>
      <material name="datum_gray">
        <color rgba="0.62 0.66 0.66 1" />
        </material>
      </visual>
    <visual name="wand_index_0">
      <origin xyz="-0.0214 0 -0.15" rpy="0 0 0" />
      <geometry>
        <box size="0.003 0.029 0.006" />
        </geometry>
      <material name="etched_white">
        <color rgba="0.92 0.95 0.92 1" />
        </material>
      </visual>
    <visual name="wand_index_1">
      <origin xyz="-0.0214 0 -0.172" rpy="0 0 0" />
      <geometry>
        <box size="0.003 0.029 0.006" />
        </geometry>
      <material name="datum_gray">
        <color rgba="0.62 0.66 0.66 1" />
        </material>
      </visual>
    <visual name="wand_index_2">
      <origin xyz="-0.0214 0 -0.194" rpy="0 0 0" />
      <geometry>
        <box size="0.003 0.029 0.006" />
        </geometry>
      <material name="datum_gray">
        <color rgba="0.62 0.66 0.66 1" />
        </material>
      </visual>
    <visual name="wand_index_3">
      <origin xyz="-0.0214 0 -0.216" rpy="0 0 0" />
      <geometry>
        <box size="0.003 0.029 0.006" />
        </geometry>
      <material name="datum_gray">
        <color rgba="0.62 0.66 0.66 1" />
        </material>
      </visual>
    <visual name="lower_socket">
      <origin xyz="-0.004 0 -0.858" rpy="0 0 0" />
      <geometry>
        <box size="0.042 0.034 0.052" />
        </geometry>
      <material name="graphite_polymer">
        <color rgba="0.055 0.058 0.064 1" />
        </material>
      </visual>
    <visual name="nozzle_cheek_0">
      <origin xyz="-0.006 0.043 -0.91" rpy="0 0 0" />
      <geometry>
        <box size="0.052 0.014 0.086" />
        </geometry>
      <material name="satin_black">
        <color rgba="0.01 0.012 0.014 1" />
        </material>
      </visual>
    <visual name="nozzle_cheek_1">
      <origin xyz="-0.006 -0.043 -0.91" rpy="0 0 0" />
      <geometry>
        <box size="0.052 0.014 0.086" />
        </geometry>
      <material name="satin_black">
        <color rgba="0.01 0.012 0.014 1" />
        </material>
      </visual>
    <visual name="nozzle_fork_bridge">
      <origin xyz="-0.012 0 -0.862" rpy="0 0 0" />
      <geometry>
        <box size="0.042 0.09 0.03" />
        </geometry>
      <material name="satin_black">
        <color rgba="0.01 0.012 0.014 1" />
        </material>
      </visual>
    <visual name="nozzle_pin">
      <origin xyz="0 0 -0.91" rpy="-1.5708 0 0" />
      <geometry>
        <cylinder radius="0.0085" length="0.104" />
        </geometry>
      <material name="brushed_steel">
        <color rgba="0.58 0.6 0.62 1" />
        </material>
      </visual>
    <collision name="fold_barrel">
      <origin xyz="0 0 0" rpy="-1.5708 0 0" />
      <geometry>
        <cylinder radius="0.017" length="0.06" />
        </geometry>
      </collision>
    <collision name="upper_socket">
      <origin xyz="0 0 -0.045" rpy="0 0 0" />
      <geometry>
        <box size="0.032 0.034 0.06" />
        </geometry>
      </collision>
    <collision name="wand_tube">
      <origin xyz="0 0 -0.45" rpy="0 0 0" />
      <geometry>
        <box size="0.038 0.026 0.82" />
        </geometry>
      </collision>
    <collision name="straight_datum_rail">
      <origin xyz="-0.0208 0 -0.475" rpy="0 0 0" />
      <geometry>
        <box size="0.004 0.028 0.73" />
        </geometry>
      </collision>
    <collision name="wand_index_0">
      <origin xyz="-0.0214 0 -0.15" rpy="0 0 0" />
      <geometry>
        <box size="0.003 0.029 0.006" />
        </geometry>
      </collision>
    <collision name="wand_index_1">
      <origin xyz="-0.0214 0 -0.172" rpy="0 0 0" />
      <geometry>
        <box size="0.003 0.029 0.006" />
        </geometry>
      </collision>
    <collision name="wand_index_2">
      <origin xyz="-0.0214 0 -0.194" rpy="0 0 0" />
      <geometry>
        <box size="0.003 0.029 0.006" />
        </geometry>
      </collision>
    <collision name="wand_index_3">
      <origin xyz="-0.0214 0 -0.216" rpy="0 0 0" />
      <geometry>
        <box size="0.003 0.029 0.006" />
        </geometry>
      </collision>
    <collision name="lower_socket">
      <origin xyz="-0.004 0 -0.858" rpy="0 0 0" />
      <geometry>
        <box size="0.042 0.034 0.052" />
        </geometry>
      </collision>
    <collision name="nozzle_cheek_0">
      <origin xyz="-0.006 0.043 -0.91" rpy="0 0 0" />
      <geometry>
        <box size="0.052 0.014 0.086" />
        </geometry>
      </collision>
    <collision name="nozzle_cheek_1">
      <origin xyz="-0.006 -0.043 -0.91" rpy="0 0 0" />
      <geometry>
        <box size="0.052 0.014 0.086" />
        </geometry>
      </collision>
    <collision name="nozzle_fork_bridge">
      <origin xyz="-0.012 0 -0.862" rpy="0 0 0" />
      <geometry>
        <box size="0.042 0.09 0.03" />
        </geometry>
      </collision>
    <collision name="nozzle_pin">
      <origin xyz="0 0 -0.91" rpy="-1.5708 0 0" />
      <geometry>
        <cylinder radius="0.0085" length="0.104" />
        </geometry>
      </collision>
    </link>
  <link name="floor_head">
    <visual name="nozzle_trunnion">
      <origin xyz="0 0 0" rpy="-1.5708 0 0" />
      <geometry>
        <cylinder radius="0.016" length="0.064" />
        </geometry>
      <material name="graphite_polymer">
        <color rgba="0.055 0.058 0.064 1" />
        </material>
      </visual>
    <visual name="trunnion_neck">
      <origin xyz="0.008 0 -0.038" rpy="0 0 0" />
      <geometry>
        <box size="0.044 0.05 0.056" />
        </geometry>
      <material name="graphite_polymer">
        <color rgba="0.055 0.058 0.064 1" />
        </material>
      </visual>
    <visual name="floor_head_shell">
      <origin xyz="0.125 0 -0.085" rpy="0 0 0" />
      <geometry>
        <mesh filename="assets/meshes/floor_head_shell.obj" />
        </geometry>
      <material name="graphite_polymer">
        <color rgba="0.055 0.058 0.064 1" />
        </material>
      </visual>
    <visual name="top_datum_pad">
      <origin xyz="0.145 0 -0.0592" rpy="0 0 0" />
      <geometry>
        <box size="0.125 0.05 0.004" />
        </geometry>
      <material name="datum_gray">
        <color rgba="0.62 0.66 0.66 1" />
        </material>
      </visual>
    <visual name="front_datum_pad">
      <origin xyz="0.225 0 -0.0592" rpy="0 0 0" />
      <geometry>
        <box size="0.06 0.032 0.004" />
        </geometry>
      <material name="calibration_blue">
        <color rgba="0.08 0.45 0.82 1" />
        </material>
      </visual>
    <visual name="height_dial_pad">
      <origin xyz="0.125 -0.085 -0.0585" rpy="0 0 0" />
      <geometry>
        <cylinder radius="0.032" length="0.003" />
        </geometry>
      <material name="satin_black">
        <color rgba="0.01 0.012 0.014 1" />
        </material>
      </visual>
    <visual name="skid_rail_0">
      <origin xyz="0.128 0.119 -0.114" rpy="0 0 0" />
      <geometry>
        <box size="0.235 0.014 0.012" />
        </geometry>
      <material name="black_rubber">
        <color rgba="0.018 0.016 0.014 1" />
        </material>
      </visual>
    <visual name="skid_rail_1">
      <origin xyz="0.128 -0.119 -0.114" rpy="0 0 0" />
      <geometry>
        <box size="0.235 0.014 0.012" />
        </geometry>
      <material name="black_rubber">
        <color rgba="0.018 0.016 0.014 1" />
        </material>
      </visual>
    <visual name="front_bumper">
      <origin xyz="0.26 0 -0.094" rpy="0 0 0" />
      <geometry>
        <box size="0.018 0.235 0.026" />
        </geometry>
      <material name="black_rubber">
        <color rgba="0.018 0.016 0.014 1" />
        </material>
      </visual>
    <visual name="brush_roll">
      <origin xyz="0.184 0 -0.112" rpy="-1.5708 0 0" />
      <geometry>
        <cylinder radius="0.015" length="0.235" />
        </geometry>
      <material name="black_rubber">
        <color rgba="0.018 0.016 0.014 1" />
        </material>
      </visual>
    <visual name="height_index_0">
      <origin xyz="0.125 -0.118 -0.0595" rpy="0 0 0" />
      <geometry>
        <box size="0.018 0.003 0.002" />
        </geometry>
      <material name="etched_white">
        <color rgba="0.92 0.95 0.92 1" />
        </material>
      </visual>
    <visual name="height_index_1">
      <origin xyz="0.125 -0.094 -0.0595" rpy="0 0 0" />
      <geometry>
        <box size="0.012 0.003 0.002" />
        </geometry>
      <material name="datum_gray">
        <color rgba="0.62 0.66 0.66 1" />
        </material>
      </visual>
    <visual name="height_index_2">
      <origin xyz="0.125 -0.07 -0.0595" rpy="0 0 0" />
      <geometry>
        <box size="0.012 0.003 0.002" />
        </geometry>
      <material name="datum_gray">
        <color rgba="0.62 0.66 0.66 1" />
        </material>
      </visual>
    <visual name="height_index_3">
      <origin xyz="0.125 -0.046 -0.0595" rpy="0 0 0" />
      <geometry>
        <box size="0.012 0.003 0.002" />
        </geometry>
      <material name="datum_gray">
        <color rgba="0.62 0.66 0.66 1" />
        </material>
      </visual>
    <collision name="nozzle_trunnion">
      <origin xyz="0 0 0" rpy="-1.5708 0 0" />
      <geometry>
        <cylinder radius="0.016" length="0.064" />
        </geometry>
      </collision>
    <collision name="trunnion_neck">
      <origin xyz="0.008 0 -0.038" rpy="0 0 0" />
      <geometry>
        <box size="0.044 0.05 0.056" />
        </geometry>
      </collision>
    <collision name="floor_head_shell">
      <origin xyz="0.125 0 -0.085" rpy="0 0 0" />
      <geometry>
        <mesh filename="assets/meshes/floor_head_shell.obj" />
        </geometry>
      </collision>
    <collision name="top_datum_pad">
      <origin xyz="0.145 0 -0.0592" rpy="0 0 0" />
      <geometry>
        <box size="0.125 0.05 0.004" />
        </geometry>
      </collision>
    <collision name="front_datum_pad">
      <origin xyz="0.225 0 -0.0592" rpy="0 0 0" />
      <geometry>
        <box size="0.06 0.032 0.004" />
        </geometry>
      </collision>
    <collision name="height_dial_pad">
      <origin xyz="0.125 -0.085 -0.0585" rpy="0 0 0" />
      <geometry>
        <cylinder radius="0.032" length="0.003" />
        </geometry>
      </collision>
    <collision name="skid_rail_0">
      <origin xyz="0.128 0.119 -0.114" rpy="0 0 0" />
      <geometry>
        <box size="0.235 0.014 0.012" />
        </geometry>
      </collision>
    <collision name="skid_rail_1">
      <origin xyz="0.128 -0.119 -0.114" rpy="0 0 0" />
      <geometry>
        <box size="0.235 0.014 0.012" />
        </geometry>
      </collision>
    <collision name="front_bumper">
      <origin xyz="0.26 0 -0.094" rpy="0 0 0" />
      <geometry>
        <box size="0.018 0.235 0.026" />
        </geometry>
      </collision>
    <collision name="brush_roll">
      <origin xyz="0.184 0 -0.112" rpy="-1.5708 0 0" />
      <geometry>
        <cylinder radius="0.015" length="0.235" />
        </geometry>
      </collision>
    <collision name="height_index_0">
      <origin xyz="0.125 -0.118 -0.0595" rpy="0 0 0" />
      <geometry>
        <box size="0.018 0.003 0.002" />
        </geometry>
      </collision>
    <collision name="height_index_1">
      <origin xyz="0.125 -0.094 -0.0595" rpy="0 0 0" />
      <geometry>
        <box size="0.012 0.003 0.002" />
        </geometry>
      </collision>
    <collision name="height_index_2">
      <origin xyz="0.125 -0.07 -0.0595" rpy="0 0 0" />
      <geometry>
        <box size="0.012 0.003 0.002" />
        </geometry>
      </collision>
    <collision name="height_index_3">
      <origin xyz="0.125 -0.046 -0.0595" rpy="0 0 0" />
      <geometry>
        <box size="0.012 0.003 0.002" />
        </geometry>
      </collision>
    </link>
  <link name="height_dial">
    <visual name="height_cap">
      <geometry>
        <mesh filename="assets/meshes/height_dial_cap.obj" />
        </geometry>
      <material name="satin_black">
        <color rgba="0.01 0.012 0.014 1" />
        </material>
      </visual>
    <visual name="height_pointer">
      <origin xyz="0.007 0 0.013" rpy="0 0 0" />
      <geometry>
        <box size="0.024 0.004 0.002" />
        </geometry>
      <material name="calibration_blue">
        <color rgba="0.08 0.45 0.82 1" />
        </material>
      </visual>
    <collision name="height_cap">
      <geometry>
        <mesh filename="assets/meshes/height_dial_cap.obj" />
        </geometry>
      </collision>
    <collision name="height_pointer">
      <origin xyz="0.007 0 0.013" rpy="0 0 0" />
      <geometry>
        <box size="0.024 0.004 0.002" />
        </geometry>
      </collision>
    </link>
  <joint name="body_to_wand" type="revolute">
    <parent link="body" />
    <child link="wand" />
    <axis xyz="0 1 0" />
    <limit effort="12" velocity="1.2" lower="0" upper="1.65" />
    </joint>
  <joint name="body_to_alignment_dial" type="revolute">
    <origin xyz="0 -0.07 0.016" rpy="0 0 0" />
    <parent link="body" />
    <child link="alignment_dial" />
    <axis xyz="0 1 0" />
    <limit effort="0.4" velocity="1.8" lower="-3.14159" upper="3.14159" />
    </joint>
  <joint name="wand_to_floor_head" type="revolute">
    <origin xyz="0 0 -0.91" rpy="0 0 0" />
    <parent link="wand" />
    <child link="floor_head" />
    <axis xyz="0 -1 0" />
    <limit effort="8" velocity="1.4" lower="-0.55" upper="0.75" />
    </joint>
  <joint name="floor_head_to_height_dial" type="revolute">
    <origin xyz="0.125 -0.085 -0.057" rpy="0 0 0" />
    <parent link="floor_head" />
    <child link="height_dial" />
    <axis xyz="0 0 1" />
    <limit effort="0.35" velocity="1.5" lower="-2.2" upper="2.2" />
    </joint>
  </robot>
