<robot name="detailed_transport_wheelchair">
  <material name="brushed_aluminum">
    <color rgba="0.72 0.74 0.73 1" />
    </material>
  <material name="dark_hinge_metal">
    <color rgba="0.18 0.19 0.19 1" />
    </material>
  <material name="matte_black_rubber">
    <color rgba="0.012 0.012 0.01 1" />
    </material>
  <material name="wipe_clean_blue_fabric">
    <color rgba="0.02 0.12 0.27 1" />
    </material>
  <material name="black_molded_plastic">
    <color rgba="0.02 0.02 0.018 1" />
    </material>
  <material name="warm_grey_plastic">
    <color rgba="0.45 0.46 0.45 1" />
    </material>
  <material name="amber_reflector">
    <color rgba="1 0.5 0.08 1" />
    </material>
  <link name="frame">
    <visual name="left_lower_rail">
      <origin xyz="0.02 0.25 0.205" rpy="0 1.52396 0" />
      <geometry>
        <cylinder radius="0.012" length="0.640703" />
        </geometry>
      <material name="brushed_aluminum">
        <color rgba="0.72 0.74 0.73 1" />
        </material>
      </visual>
    <visual name="left_seat_rail">
      <origin xyz="0.025 0.25 0.5" rpy="0 1.5708 0" />
      <geometry>
        <cylinder radius="0.012" length="0.57" />
        </geometry>
      <material name="brushed_aluminum">
        <color rgba="0.72 0.74 0.73 1" />
        </material>
      </visual>
    <visual name="left_rear_upright">
      <origin xyz="-0.28 0.25 0.35" rpy="0 0.124355 0" />
      <geometry>
        <cylinder radius="0.012" length="0.32249" />
        </geometry>
      <material name="brushed_aluminum">
        <color rgba="0.72 0.74 0.73 1" />
        </material>
      </visual>
    <visual name="left_front_upright">
      <origin xyz="0.32 0.25 0.36" rpy="0 0.0713075 3.14159" />
      <geometry>
        <cylinder radius="0.012" length="0.280713" />
        </geometry>
      <material name="brushed_aluminum">
        <color rgba="0.72 0.74 0.73 1" />
        </material>
      </visual>
    <visual name="left_diagonal_brace">
      <origin xyz="0 0.25 0.35" rpy="0 1.10715 0" />
      <geometry>
        <cylinder radius="0.008" length="0.67082" />
        </geometry>
      <material name="brushed_aluminum">
        <color rgba="0.72 0.74 0.73 1" />
        </material>
      </visual>
    <visual name="left_arm_support">
      <origin xyz="-0.04 0.25 0.5875" rpy="0 1.09297 0" />
      <geometry>
        <cylinder radius="0.008" length="0.315317" />
        </geometry>
      <material name="brushed_aluminum">
        <color rgba="0.72 0.74 0.73 1" />
        </material>
      </visual>
    <visual name="left_front_arm_post">
      <origin xyz="0.22 0.25 0.58" rpy="0 0 0" />
      <geometry>
        <cylinder radius="0.008" length="0.16" />
        </geometry>
      <material name="brushed_aluminum">
        <color rgba="0.72 0.74 0.73 1" />
        </material>
      </visual>
    <visual name="left_arm_pad">
      <origin xyz="0.06 0.2725 0.675" rpy="0 0 0" />
      <geometry>
        <box size="0.39 0.07 0.04" />
        </geometry>
      <material name="black_molded_plastic">
        <color rgba="0.02 0.02 0.018 1" />
        </material>
      </visual>
    <visual name="left_footrest_bracket">
      <origin xyz="0.33 0.26625 0.415" rpy="0 2.84723 0.682317" />
      <geometry>
        <cylinder radius="0.008" length="0.177641" />
        </geometry>
      <material name="brushed_aluminum">
        <color rgba="0.72 0.74 0.73 1" />
        </material>
      </visual>
    <visual name="left_caster_outrigger">
      <origin xyz="0.345 0.2675 0.21" rpy="0 1.98015 0.86217" />
      <geometry>
        <cylinder radius="0.012" length="0.0502494" />
        </geometry>
      <material name="brushed_aluminum">
        <color rgba="0.72 0.74 0.73 1" />
        </material>
      </visual>
    <visual name="right_lower_rail">
      <origin xyz="0.02 -0.25 0.205" rpy="0 1.52396 0" />
      <geometry>
        <cylinder radius="0.012" length="0.640703" />
        </geometry>
      <material name="brushed_aluminum">
        <color rgba="0.72 0.74 0.73 1" />
        </material>
      </visual>
    <visual name="right_seat_rail">
      <origin xyz="0.025 -0.25 0.5" rpy="0 1.5708 0" />
      <geometry>
        <cylinder radius="0.012" length="0.57" />
        </geometry>
      <material name="brushed_aluminum">
        <color rgba="0.72 0.74 0.73 1" />
        </material>
      </visual>
    <visual name="right_rear_upright">
      <origin xyz="-0.28 -0.25 0.35" rpy="0 0.124355 0" />
      <geometry>
        <cylinder radius="0.012" length="0.32249" />
        </geometry>
      <material name="brushed_aluminum">
        <color rgba="0.72 0.74 0.73 1" />
        </material>
      </visual>
    <visual name="right_front_upright">
      <origin xyz="0.32 -0.25 0.36" rpy="0 0.0713075 3.14159" />
      <geometry>
        <cylinder radius="0.012" length="0.280713" />
        </geometry>
      <material name="brushed_aluminum">
        <color rgba="0.72 0.74 0.73 1" />
        </material>
      </visual>
    <visual name="right_diagonal_brace">
      <origin xyz="0 -0.25 0.35" rpy="0 1.10715 0" />
      <geometry>
        <cylinder radius="0.008" length="0.67082" />
        </geometry>
      <material name="brushed_aluminum">
        <color rgba="0.72 0.74 0.73 1" />
        </material>
      </visual>
    <visual name="right_arm_support">
      <origin xyz="-0.04 -0.25 0.5875" rpy="0 1.09297 0" />
      <geometry>
        <cylinder radius="0.008" length="0.315317" />
        </geometry>
      <material name="brushed_aluminum">
        <color rgba="0.72 0.74 0.73 1" />
        </material>
      </visual>
    <visual name="right_front_arm_post">
      <origin xyz="0.22 -0.25 0.58" rpy="0 0 0" />
      <geometry>
        <cylinder radius="0.008" length="0.16" />
        </geometry>
      <material name="brushed_aluminum">
        <color rgba="0.72 0.74 0.73 1" />
        </material>
      </visual>
    <visual name="right_arm_pad">
      <origin xyz="0.06 -0.2725 0.675" rpy="0 0 0" />
      <geometry>
        <box size="0.39 0.07 0.04" />
        </geometry>
      <material name="black_molded_plastic">
        <color rgba="0.02 0.02 0.018 1" />
        </material>
      </visual>
    <visual name="right_footrest_bracket">
      <origin xyz="0.33 -0.26625 0.415" rpy="0 2.84723 -0.682317" />
      <geometry>
        <cylinder radius="0.008" length="0.177641" />
        </geometry>
      <material name="brushed_aluminum">
        <color rgba="0.72 0.74 0.73 1" />
        </material>
      </visual>
    <visual name="right_caster_outrigger">
      <origin xyz="0.345 -0.2675 0.21" rpy="0 1.98015 -0.86217" />
      <geometry>
        <cylinder radius="0.012" length="0.0502494" />
        </geometry>
      <material name="brushed_aluminum">
        <color rgba="0.72 0.74 0.73 1" />
        </material>
      </visual>
    <visual name="rear_cross_tube">
      <origin xyz="-0.28 0 0.19" rpy="0 1.5708 1.5708" />
      <geometry>
        <cylinder radius="0.012" length="0.5" />
        </geometry>
      <material name="brushed_aluminum">
        <color rgba="0.72 0.74 0.73 1" />
        </material>
      </visual>
    <visual name="back_hinge_sleeve">
      <origin xyz="-0.25 0 0.5" rpy="0 1.5708 1.5708" />
      <geometry>
        <cylinder radius="0.012" length="0.5" />
        </geometry>
      <material name="dark_hinge_metal">
        <color rgba="0.18 0.19 0.19 1" />
        </material>
      </visual>
    <visual name="front_cross_tube">
      <origin xyz="0.3 0 0.49" rpy="0 1.5708 1.5708" />
      <geometry>
        <cylinder radius="0.012" length="0.5" />
        </geometry>
      <material name="brushed_aluminum">
        <color rgba="0.72 0.74 0.73 1" />
        </material>
      </visual>
    <visual name="lower_cross_tube">
      <origin xyz="0 0 0.435" rpy="0 1.5708 1.5708" />
      <geometry>
        <cylinder radius="0.008" length="0.5" />
        </geometry>
      <material name="brushed_aluminum">
        <color rgba="0.72 0.74 0.73 1" />
        </material>
      </visual>
    <visual name="folding_cross_a">
      <origin xyz="0 0 0.43" rpy="0 1.26393 1.48014" />
      <geometry>
        <cylinder radius="0.008" length="0.463465" />
        </geometry>
      <material name="brushed_aluminum">
        <color rgba="0.72 0.74 0.73 1" />
        </material>
      </visual>
    <visual name="folding_cross_b">
      <origin xyz="0 0 0.43" rpy="0 1.26393 -1.48014" />
      <geometry>
        <cylinder radius="0.008" length="0.463465" />
        </geometry>
      <material name="brushed_aluminum">
        <color rgba="0.72 0.74 0.73 1" />
        </material>
      </visual>
    <visual name="scissor_center_pivot">
      <origin xyz="0 0 0.435" rpy="0 1.5708 0" />
      <geometry>
        <cylinder radius="0.02" length="0.03" />
        </geometry>
      <material name="dark_hinge_metal">
        <color rgba="0.18 0.19 0.19 1" />
        </material>
      </visual>
    <visual name="seat_sling">
      <origin xyz="0.035 0 0.486" rpy="0 0 0" />
      <geometry>
        <box size="0.55 0.485 0.03" />
        </geometry>
      <material name="wipe_clean_blue_fabric">
        <color rgba="0.02 0.12 0.27 1" />
        </material>
      </visual>
    <visual name="left_seat_edge_binding">
      <origin xyz="0.035 0.242 0.508" rpy="0 0 0" />
      <geometry>
        <box size="0.54 0.035 0.012" />
        </geometry>
      <material name="black_molded_plastic">
        <color rgba="0.02 0.02 0.018 1" />
        </material>
      </visual>
    <visual name="right_seat_edge_binding">
      <origin xyz="0.035 -0.242 0.508" rpy="0 0 0" />
      <geometry>
        <box size="0.54 0.035 0.012" />
        </geometry>
      <material name="black_molded_plastic">
        <color rgba="0.02 0.02 0.018 1" />
        </material>
      </visual>
    <visual name="left_rear_axle">
      <origin xyz="-0.28 0.279 0.19" rpy="0 1.5708 1.5708" />
      <geometry>
        <cylinder radius="0.0125" length="0.118" />
        </geometry>
      <material name="dark_hinge_metal">
        <color rgba="0.18 0.19 0.19 1" />
        </material>
      </visual>
    <visual name="right_rear_axle">
      <origin xyz="-0.28 -0.279 0.19" rpy="0 1.5708 -1.5708" />
      <geometry>
        <cylinder radius="0.0125" length="0.118" />
        </geometry>
      <material name="dark_hinge_metal">
        <color rgba="0.18 0.19 0.19 1" />
        </material>
      </visual>
    <visual name="left_footrest_socket">
      <origin xyz="0.335 0.16 0.37" rpy="0 0 0" />
      <geometry>
        <cylinder radius="0.017" length="0.11" />
        </geometry>
      <material name="dark_hinge_metal">
        <color rgba="0.18 0.19 0.19 1" />
        </material>
      </visual>
    <visual name="left_socket_mount">
      <origin xyz="0.3265 0.205 0.4" rpy="0 1.5708 1.75749" />
      <geometry>
        <cylinder radius="0.008" length="0.0915915" />
        </geometry>
      <material name="brushed_aluminum">
        <color rgba="0.72 0.74 0.73 1" />
        </material>
      </visual>
    <visual name="left_footrest_latch">
      <origin xyz="0.333 0.16 0.417" rpy="0 0 0" />
      <geometry>
        <box size="0.03 0.05 0.018" />
        </geometry>
      <material name="warm_grey_plastic">
        <color rgba="0.45 0.46 0.45 1" />
        </material>
      </visual>
    <visual name="right_footrest_socket">
      <origin xyz="0.335 -0.16 0.37" rpy="0 0 0" />
      <geometry>
        <cylinder radius="0.017" length="0.11" />
        </geometry>
      <material name="dark_hinge_metal">
        <color rgba="0.18 0.19 0.19 1" />
        </material>
      </visual>
    <visual name="right_socket_mount">
      <origin xyz="0.3265 -0.205 0.4" rpy="0 1.5708 -1.75749" />
      <geometry>
        <cylinder radius="0.008" length="0.0915915" />
        </geometry>
      <material name="brushed_aluminum">
        <color rgba="0.72 0.74 0.73 1" />
        </material>
      </visual>
    <visual name="right_footrest_latch">
      <origin xyz="0.333 -0.16 0.417" rpy="0 0 0" />
      <geometry>
        <box size="0.03 0.05 0.018" />
        </geometry>
      <material name="warm_grey_plastic">
        <color rgba="0.45 0.46 0.45 1" />
        </material>
      </visual>
    <visual name="left_rear_reflector">
      <origin xyz="-0.29 0.262 0.31" rpy="0 0 0" />
      <geometry>
        <box size="0.012 0.004 0.045" />
        </geometry>
      <material name="amber_reflector">
        <color rgba="1 0.5 0.08 1" />
        </material>
      </visual>
    <visual name="right_rear_reflector">
      <origin xyz="-0.29 -0.262 0.31" rpy="0 0 0" />
      <geometry>
        <box size="0.012 0.004 0.045" />
        </geometry>
      <material name="amber_reflector">
        <color rgba="1 0.5 0.08 1" />
        </material>
      </visual>
    <visual name="left_antitip_bar">
      <origin xyz="-0.38 0.235 0.145" rpy="0 2.07584 -2.95624" />
      <geometry>
        <cylinder radius="0.008" length="0.186011" />
        </geometry>
      <material name="brushed_aluminum">
        <color rgba="0.72 0.74 0.73 1" />
        </material>
      </visual>
    <visual name="right_antitip_bar">
      <origin xyz="-0.38 -0.235 0.145" rpy="0 2.07584 2.95624" />
      <geometry>
        <cylinder radius="0.008" length="0.186011" />
        </geometry>
      <material name="brushed_aluminum">
        <color rgba="0.72 0.74 0.73 1" />
        </material>
      </visual>
    <collision name="left_lower_rail">
      <origin xyz="0.02 0.25 0.205" rpy="0 1.52396 0" />
      <geometry>
        <cylinder radius="0.012" length="0.640703" />
        </geometry>
      </collision>
    <collision name="left_seat_rail">
      <origin xyz="0.025 0.25 0.5" rpy="0 1.5708 0" />
      <geometry>
        <cylinder radius="0.012" length="0.57" />
        </geometry>
      </collision>
    <collision name="left_rear_upright">
      <origin xyz="-0.28 0.25 0.35" rpy="0 0.124355 0" />
      <geometry>
        <cylinder radius="0.012" length="0.32249" />
        </geometry>
      </collision>
    <collision name="left_front_upright">
      <origin xyz="0.32 0.25 0.36" rpy="0 0.0713075 3.14159" />
      <geometry>
        <cylinder radius="0.012" length="0.280713" />
        </geometry>
      </collision>
    <collision name="left_diagonal_brace">
      <origin xyz="0 0.25 0.35" rpy="0 1.10715 0" />
      <geometry>
        <cylinder radius="0.008" length="0.67082" />
        </geometry>
      </collision>
    <collision name="left_arm_support">
      <origin xyz="-0.04 0.25 0.5875" rpy="0 1.09297 0" />
      <geometry>
        <cylinder radius="0.008" length="0.315317" />
        </geometry>
      </collision>
    <collision name="left_front_arm_post">
      <origin xyz="0.22 0.25 0.58" rpy="0 0 0" />
      <geometry>
        <cylinder radius="0.008" length="0.16" />
        </geometry>
      </collision>
    <collision name="left_arm_pad">
      <origin xyz="0.06 0.2725 0.675" rpy="0 0 0" />
      <geometry>
        <box size="0.39 0.07 0.04" />
        </geometry>
      </collision>
    <collision name="left_footrest_bracket">
      <origin xyz="0.33 0.26625 0.415" rpy="0 2.84723 0.682317" />
      <geometry>
        <cylinder radius="0.008" length="0.177641" />
        </geometry>
      </collision>
    <collision name="left_caster_outrigger">
      <origin xyz="0.345 0.2675 0.21" rpy="0 1.98015 0.86217" />
      <geometry>
        <cylinder radius="0.012" length="0.0502494" />
        </geometry>
      </collision>
    <collision name="right_lower_rail">
      <origin xyz="0.02 -0.25 0.205" rpy="0 1.52396 0" />
      <geometry>
        <cylinder radius="0.012" length="0.640703" />
        </geometry>
      </collision>
    <collision name="right_seat_rail">
      <origin xyz="0.025 -0.25 0.5" rpy="0 1.5708 0" />
      <geometry>
        <cylinder radius="0.012" length="0.57" />
        </geometry>
      </collision>
    <collision name="right_rear_upright">
      <origin xyz="-0.28 -0.25 0.35" rpy="0 0.124355 0" />
      <geometry>
        <cylinder radius="0.012" length="0.32249" />
        </geometry>
      </collision>
    <collision name="right_front_upright">
      <origin xyz="0.32 -0.25 0.36" rpy="0 0.0713075 3.14159" />
      <geometry>
        <cylinder radius="0.012" length="0.280713" />
        </geometry>
      </collision>
    <collision name="right_diagonal_brace">
      <origin xyz="0 -0.25 0.35" rpy="0 1.10715 0" />
      <geometry>
        <cylinder radius="0.008" length="0.67082" />
        </geometry>
      </collision>
    <collision name="right_arm_support">
      <origin xyz="-0.04 -0.25 0.5875" rpy="0 1.09297 0" />
      <geometry>
        <cylinder radius="0.008" length="0.315317" />
        </geometry>
      </collision>
    <collision name="right_front_arm_post">
      <origin xyz="0.22 -0.25 0.58" rpy="0 0 0" />
      <geometry>
        <cylinder radius="0.008" length="0.16" />
        </geometry>
      </collision>
    <collision name="right_arm_pad">
      <origin xyz="0.06 -0.2725 0.675" rpy="0 0 0" />
      <geometry>
        <box size="0.39 0.07 0.04" />
        </geometry>
      </collision>
    <collision name="right_footrest_bracket">
      <origin xyz="0.33 -0.26625 0.415" rpy="0 2.84723 -0.682317" />
      <geometry>
        <cylinder radius="0.008" length="0.177641" />
        </geometry>
      </collision>
    <collision name="right_caster_outrigger">
      <origin xyz="0.345 -0.2675 0.21" rpy="0 1.98015 -0.86217" />
      <geometry>
        <cylinder radius="0.012" length="0.0502494" />
        </geometry>
      </collision>
    <collision name="rear_cross_tube">
      <origin xyz="-0.28 0 0.19" rpy="0 1.5708 1.5708" />
      <geometry>
        <cylinder radius="0.012" length="0.5" />
        </geometry>
      </collision>
    <collision name="back_hinge_sleeve">
      <origin xyz="-0.25 0 0.5" rpy="0 1.5708 1.5708" />
      <geometry>
        <cylinder radius="0.012" length="0.5" />
        </geometry>
      </collision>
    <collision name="front_cross_tube">
      <origin xyz="0.3 0 0.49" rpy="0 1.5708 1.5708" />
      <geometry>
        <cylinder radius="0.012" length="0.5" />
        </geometry>
      </collision>
    <collision name="lower_cross_tube">
      <origin xyz="0 0 0.435" rpy="0 1.5708 1.5708" />
      <geometry>
        <cylinder radius="0.008" length="0.5" />
        </geometry>
      </collision>
    <collision name="folding_cross_a">
      <origin xyz="0 0 0.43" rpy="0 1.26393 1.48014" />
      <geometry>
        <cylinder radius="0.008" length="0.463465" />
        </geometry>
      </collision>
    <collision name="folding_cross_b">
      <origin xyz="0 0 0.43" rpy="0 1.26393 -1.48014" />
      <geometry>
        <cylinder radius="0.008" length="0.463465" />
        </geometry>
      </collision>
    <collision name="scissor_center_pivot">
      <origin xyz="0 0 0.435" rpy="0 1.5708 0" />
      <geometry>
        <cylinder radius="0.02" length="0.03" />
        </geometry>
      </collision>
    <collision name="seat_sling">
      <origin xyz="0.035 0 0.486" rpy="0 0 0" />
      <geometry>
        <box size="0.55 0.485 0.03" />
        </geometry>
      </collision>
    <collision name="left_seat_edge_binding">
      <origin xyz="0.035 0.242 0.508" rpy="0 0 0" />
      <geometry>
        <box size="0.54 0.035 0.012" />
        </geometry>
      </collision>
    <collision name="right_seat_edge_binding">
      <origin xyz="0.035 -0.242 0.508" rpy="0 0 0" />
      <geometry>
        <box size="0.54 0.035 0.012" />
        </geometry>
      </collision>
    <collision name="left_rear_axle">
      <origin xyz="-0.28 0.279 0.19" rpy="0 1.5708 1.5708" />
      <geometry>
        <cylinder radius="0.0125" length="0.118" />
        </geometry>
      </collision>
    <collision name="right_rear_axle">
      <origin xyz="-0.28 -0.279 0.19" rpy="0 1.5708 -1.5708" />
      <geometry>
        <cylinder radius="0.0125" length="0.118" />
        </geometry>
      </collision>
    <collision name="left_footrest_socket">
      <origin xyz="0.335 0.16 0.37" rpy="0 0 0" />
      <geometry>
        <cylinder radius="0.017" length="0.11" />
        </geometry>
      </collision>
    <collision name="left_socket_mount">
      <origin xyz="0.3265 0.205 0.4" rpy="0 1.5708 1.75749" />
      <geometry>
        <cylinder radius="0.008" length="0.0915915" />
        </geometry>
      </collision>
    <collision name="left_footrest_latch">
      <origin xyz="0.333 0.16 0.417" rpy="0 0 0" />
      <geometry>
        <box size="0.03 0.05 0.018" />
        </geometry>
      </collision>
    <collision name="right_footrest_socket">
      <origin xyz="0.335 -0.16 0.37" rpy="0 0 0" />
      <geometry>
        <cylinder radius="0.017" length="0.11" />
        </geometry>
      </collision>
    <collision name="right_socket_mount">
      <origin xyz="0.3265 -0.205 0.4" rpy="0 1.5708 -1.75749" />
      <geometry>
        <cylinder radius="0.008" length="0.0915915" />
        </geometry>
      </collision>
    <collision name="right_footrest_latch">
      <origin xyz="0.333 -0.16 0.417" rpy="0 0 0" />
      <geometry>
        <box size="0.03 0.05 0.018" />
        </geometry>
      </collision>
    <collision name="left_rear_reflector">
      <origin xyz="-0.29 0.262 0.31" rpy="0 0 0" />
      <geometry>
        <box size="0.012 0.004 0.045" />
        </geometry>
      </collision>
    <collision name="right_rear_reflector">
      <origin xyz="-0.29 -0.262 0.31" rpy="0 0 0" />
      <geometry>
        <box size="0.012 0.004 0.045" />
        </geometry>
      </collision>
    <collision name="left_antitip_bar">
      <origin xyz="-0.38 0.235 0.145" rpy="0 2.07584 -2.95624" />
      <geometry>
        <cylinder radius="0.008" length="0.186011" />
        </geometry>
      </collision>
    <collision name="right_antitip_bar">
      <origin xyz="-0.38 -0.235 0.145" rpy="0 2.07584 2.95624" />
      <geometry>
        <cylinder radius="0.008" length="0.186011" />
        </geometry>
      </collision>
    </link>
  <link name="backrest">
    <visual name="hinge_pin">
      <origin xyz="0 0 0" rpy="0 1.5708 1.5708" />
      <geometry>
        <cylinder radius="0.014" length="0.54" />
        </geometry>
      <material name="dark_hinge_metal">
        <color rgba="0.18 0.19 0.19 1" />
        </material>
      </visual>
    <visual name="left_back_post">
      <origin xyz="-0.0375 0.235 0.2275" rpy="0 0.163366 3.14159" />
      <geometry>
        <cylinder radius="0.012" length="0.46114" />
        </geometry>
      <material name="brushed_aluminum">
        <color rgba="0.72 0.74 0.73 1" />
        </material>
      </visual>
    <visual name="left_push_handle_tube">
      <geometry>
        <mesh filename="assets/meshes/left_push_handle_tube_mesh.obj" />
        </geometry>
      <material name="brushed_aluminum">
        <color rgba="0.72 0.74 0.73 1" />
        </material>
      </visual>
    <visual name="left_push_grip">
      <origin xyz="-0.28 0.235 0.555" rpy="0 1.5708 3.14159" />
      <geometry>
        <cylinder radius="0.018" length="0.12" />
        </geometry>
      <material name="matte_black_rubber">
        <color rgba="0.012 0.012 0.01 1" />
        </material>
      </visual>
    <visual name="left_brake_perch">
      <origin xyz="-0.214 0.235 0.548" rpy="0 0 0" />
      <geometry>
        <box size="0.03 0.03 0.03" />
        </geometry>
      <material name="dark_hinge_metal">
        <color rgba="0.18 0.19 0.19 1" />
        </material>
      </visual>
    <visual name="right_back_post">
      <origin xyz="-0.0375 -0.235 0.2275" rpy="0 0.163366 3.14159" />
      <geometry>
        <cylinder radius="0.012" length="0.46114" />
        </geometry>
      <material name="brushed_aluminum">
        <color rgba="0.72 0.74 0.73 1" />
        </material>
      </visual>
    <visual name="right_push_handle_tube">
      <geometry>
        <mesh filename="assets/meshes/right_push_handle_tube_mesh.obj" />
        </geometry>
      <material name="brushed_aluminum">
        <color rgba="0.72 0.74 0.73 1" />
        </material>
      </visual>
    <visual name="right_push_grip">
      <origin xyz="-0.28 -0.235 0.555" rpy="0 1.5708 3.14159" />
      <geometry>
        <cylinder radius="0.018" length="0.12" />
        </geometry>
      <material name="matte_black_rubber">
        <color rgba="0.012 0.012 0.01 1" />
        </material>
      </visual>
    <visual name="right_brake_perch">
      <origin xyz="-0.214 -0.235 0.548" rpy="0 0 0" />
      <geometry>
        <box size="0.03 0.03 0.03" />
        </geometry>
      <material name="dark_hinge_metal">
        <color rgba="0.18 0.19 0.19 1" />
        </material>
      </visual>
    <visual name="back_sling">
      <origin xyz="-0.06 0 0.25" rpy="0 0 0" />
      <geometry>
        <box size="0.035 0.47 0.385" />
        </geometry>
      <material name="wipe_clean_blue_fabric">
        <color rgba="0.02 0.12 0.27 1" />
        </material>
      </visual>
    <visual name="top_back_binding">
      <origin xyz="-0.075 0 0.455" rpy="0 0 0" />
      <geometry>
        <box size="0.03 0.49 0.03" />
        </geometry>
      <material name="black_molded_plastic">
        <color rgba="0.02 0.02 0.018 1" />
        </material>
      </visual>
    <visual name="lumbar_patch">
      <origin xyz="-0.08 0 0.22" rpy="0 0 0" />
      <geometry>
        <box size="0.032 0.07 0.04" />
        </geometry>
      <material name="wipe_clean_blue_fabric">
        <color rgba="0.02 0.12 0.27 1" />
        </material>
      </visual>
    <collision name="hinge_pin">
      <origin xyz="0 0 0" rpy="0 1.5708 1.5708" />
      <geometry>
        <cylinder radius="0.014" length="0.54" />
        </geometry>
      </collision>
    <collision name="left_back_post">
      <origin xyz="-0.0375 0.235 0.2275" rpy="0 0.163366 3.14159" />
      <geometry>
        <cylinder radius="0.012" length="0.46114" />
        </geometry>
      </collision>
    <collision name="left_push_handle_tube">
      <geometry>
        <mesh filename="assets/meshes/left_push_handle_tube_mesh.obj" />
        </geometry>
      </collision>
    <collision name="left_push_grip">
      <origin xyz="-0.28 0.235 0.555" rpy="0 1.5708 3.14159" />
      <geometry>
        <cylinder radius="0.018" length="0.12" />
        </geometry>
      </collision>
    <collision name="left_brake_perch">
      <origin xyz="-0.214 0.235 0.548" rpy="0 0 0" />
      <geometry>
        <box size="0.03 0.03 0.03" />
        </geometry>
      </collision>
    <collision name="right_back_post">
      <origin xyz="-0.0375 -0.235 0.2275" rpy="0 0.163366 3.14159" />
      <geometry>
        <cylinder radius="0.012" length="0.46114" />
        </geometry>
      </collision>
    <collision name="right_push_handle_tube">
      <geometry>
        <mesh filename="assets/meshes/right_push_handle_tube_mesh.obj" />
        </geometry>
      </collision>
    <collision name="right_push_grip">
      <origin xyz="-0.28 -0.235 0.555" rpy="0 1.5708 3.14159" />
      <geometry>
        <cylinder radius="0.018" length="0.12" />
        </geometry>
      </collision>
    <collision name="right_brake_perch">
      <origin xyz="-0.214 -0.235 0.548" rpy="0 0 0" />
      <geometry>
        <box size="0.03 0.03 0.03" />
        </geometry>
      </collision>
    <collision name="back_sling">
      <origin xyz="-0.06 0 0.25" rpy="0 0 0" />
      <geometry>
        <box size="0.035 0.47 0.385" />
        </geometry>
      </collision>
    <collision name="top_back_binding">
      <origin xyz="-0.075 0 0.455" rpy="0 0 0" />
      <geometry>
        <box size="0.03 0.49 0.03" />
        </geometry>
      </collision>
    <collision name="lumbar_patch">
      <origin xyz="-0.08 0 0.22" rpy="0 0 0" />
      <geometry>
        <box size="0.032 0.07 0.04" />
        </geometry>
      </collision>
    </link>
  <link name="left_brake_lever">
    <visual name="pivot_pin">
      <origin xyz="0 0 0" rpy="0 1.5708 1.5708" />
      <geometry>
        <cylinder radius="0.006" length="0.036" />
        </geometry>
      <material name="dark_hinge_metal">
        <color rgba="0.18 0.19 0.19 1" />
        </material>
      </visual>
    <visual name="lever_blade">
      <origin xyz="0.025 0 -0.0475" rpy="0 2.60987 0" />
      <geometry>
        <cylinder radius="0.0045" length="0.0986154" />
        </geometry>
      <material name="dark_hinge_metal">
        <color rgba="0.18 0.19 0.19 1" />
        </material>
      </visual>
    <visual name="finger_pull">
      <origin xyz="0.07 0 -0.096" rpy="0 0.45 0" />
      <geometry>
        <box size="0.07 0.018 0.014" />
        </geometry>
      <material name="black_molded_plastic">
        <color rgba="0.02 0.02 0.018 1" />
        </material>
      </visual>
    <collision name="pivot_pin">
      <origin xyz="0 0 0" rpy="0 1.5708 1.5708" />
      <geometry>
        <cylinder radius="0.006" length="0.036" />
        </geometry>
      </collision>
    <collision name="lever_blade">
      <origin xyz="0.025 0 -0.0475" rpy="0 2.60987 0" />
      <geometry>
        <cylinder radius="0.0045" length="0.0986154" />
        </geometry>
      </collision>
    <collision name="finger_pull">
      <origin xyz="0.07 0 -0.096" rpy="0 0.45 0" />
      <geometry>
        <box size="0.07 0.018 0.014" />
        </geometry>
      </collision>
    </link>
  <link name="right_brake_lever">
    <visual name="pivot_pin">
      <origin xyz="0 0 0" rpy="0 1.5708 -1.5708" />
      <geometry>
        <cylinder radius="0.006" length="0.036" />
        </geometry>
      <material name="dark_hinge_metal">
        <color rgba="0.18 0.19 0.19 1" />
        </material>
      </visual>
    <visual name="lever_blade">
      <origin xyz="0.025 0 -0.0475" rpy="0 2.60987 0" />
      <geometry>
        <cylinder radius="0.0045" length="0.0986154" />
        </geometry>
      <material name="dark_hinge_metal">
        <color rgba="0.18 0.19 0.19 1" />
        </material>
      </visual>
    <visual name="finger_pull">
      <origin xyz="0.07 0 -0.096" rpy="0 0.45 0" />
      <geometry>
        <box size="0.07 0.018 0.014" />
        </geometry>
      <material name="black_molded_plastic">
        <color rgba="0.02 0.02 0.018 1" />
        </material>
      </visual>
    <collision name="pivot_pin">
      <origin xyz="0 0 0" rpy="0 1.5708 -1.5708" />
      <geometry>
        <cylinder radius="0.006" length="0.036" />
        </geometry>
      </collision>
    <collision name="lever_blade">
      <origin xyz="0.025 0 -0.0475" rpy="0 2.60987 0" />
      <geometry>
        <cylinder radius="0.0045" length="0.0986154" />
        </geometry>
      </collision>
    <collision name="finger_pull">
      <origin xyz="0.07 0 -0.096" rpy="0 0.45 0" />
      <geometry>
        <box size="0.07 0.018 0.014" />
        </geometry>
      </collision>
    </link>
  <link name="left_rear_wheel">
    <visual name="tire">
      <origin xyz="0 0 0" rpy="0 0 1.5708" />
      <geometry>
        <mesh filename="assets/meshes/left_rear_tire.obj" />
        </geometry>
      <material name="matte_black_rubber">
        <color rgba="0.012 0.012 0.01 1" />
        </material>
      </visual>
    <visual name="rim">
      <origin xyz="0 0 0" rpy="0 0 1.5708" />
      <geometry>
        <mesh filename="assets/meshes/left_rear_rim.obj" />
        </geometry>
      <material name="warm_grey_plastic">
        <color rgba="0.45 0.46 0.45 1" />
        </material>
      </visual>
    <visual name="outer_cap">
      <origin xyz="0 0.022 0" rpy="0 1.5708 1.5708" />
      <geometry>
        <cylinder radius="0.0279" length="0.022" />
        </geometry>
      <material name="dark_hinge_metal">
        <color rgba="0.18 0.19 0.19 1" />
        </material>
      </visual>
    <collision name="tire">
      <origin xyz="0 0 0" rpy="0 0 1.5708" />
      <geometry>
        <mesh filename="assets/meshes/left_rear_tire.obj" />
        </geometry>
      </collision>
    <collision name="rim">
      <origin xyz="0 0 0" rpy="0 0 1.5708" />
      <geometry>
        <mesh filename="assets/meshes/left_rear_rim.obj" />
        </geometry>
      </collision>
    <collision name="outer_cap">
      <origin xyz="0 0.022 0" rpy="0 1.5708 1.5708" />
      <geometry>
        <cylinder radius="0.0279" length="0.022" />
        </geometry>
      </collision>
    </link>
  <link name="right_rear_wheel">
    <visual name="tire">
      <origin xyz="0 0 0" rpy="0 0 1.5708" />
      <geometry>
        <mesh filename="assets/meshes/right_rear_tire.obj" />
        </geometry>
      <material name="matte_black_rubber">
        <color rgba="0.012 0.012 0.01 1" />
        </material>
      </visual>
    <visual name="rim">
      <origin xyz="0 0 0" rpy="0 0 1.5708" />
      <geometry>
        <mesh filename="assets/meshes/right_rear_rim.obj" />
        </geometry>
      <material name="warm_grey_plastic">
        <color rgba="0.45 0.46 0.45 1" />
        </material>
      </visual>
    <visual name="outer_cap">
      <origin xyz="0 -0.022 0" rpy="0 1.5708 -1.5708" />
      <geometry>
        <cylinder radius="0.0279" length="0.022" />
        </geometry>
      <material name="dark_hinge_metal">
        <color rgba="0.18 0.19 0.19 1" />
        </material>
      </visual>
    <collision name="tire">
      <origin xyz="0 0 0" rpy="0 0 1.5708" />
      <geometry>
        <mesh filename="assets/meshes/right_rear_tire.obj" />
        </geometry>
      </collision>
    <collision name="rim">
      <origin xyz="0 0 0" rpy="0 0 1.5708" />
      <geometry>
        <mesh filename="assets/meshes/right_rear_rim.obj" />
        </geometry>
      </collision>
    <collision name="outer_cap">
      <origin xyz="0 -0.022 0" rpy="0 1.5708 -1.5708" />
      <geometry>
        <cylinder radius="0.0279" length="0.022" />
        </geometry>
      </collision>
    </link>
  <link name="left_caster_fork">
    <visual name="swivel_stem">
      <origin xyz="0 0 -0.0035" rpy="0 3.14159 0" />
      <geometry>
        <cylinder radius="0.013" length="0.063" />
        </geometry>
      <material name="dark_hinge_metal">
        <color rgba="0.18 0.19 0.19 1" />
        </material>
      </visual>
    <visual name="fork_crown">
      <origin xyz="0.01 0 -0.03" rpy="0 0 0" />
      <geometry>
        <box size="0.07 0.09 0.018" />
        </geometry>
      <material name="brushed_aluminum">
        <color rgba="0.72 0.74 0.73 1" />
        </material>
      </visual>
    <visual name="inner_fork_arm">
      <origin xyz="0.0575 -0.032 -0.0575" rpy="0 2.08525 0" />
      <geometry>
        <cylinder radius="0.0065" length="0.132098" />
        </geometry>
      <material name="brushed_aluminum">
        <color rgba="0.72 0.74 0.73 1" />
        </material>
      </visual>
    <visual name="outer_fork_arm">
      <origin xyz="0.0575 0.032 -0.0575" rpy="0 2.08525 0" />
      <geometry>
        <cylinder radius="0.0065" length="0.132098" />
        </geometry>
      <material name="brushed_aluminum">
        <color rgba="0.72 0.74 0.73 1" />
        </material>
      </visual>
    <visual name="caster_axle_pin">
      <origin xyz="0.115 0 -0.09" rpy="0 1.5708 1.5708" />
      <geometry>
        <cylinder radius="0.006" length="0.08" />
        </geometry>
      <material name="dark_hinge_metal">
        <color rgba="0.18 0.19 0.19 1" />
        </material>
      </visual>
    <visual name="swivel_bearing_cap">
      <origin xyz="0 0 0.012" rpy="0 0 0" />
      <geometry>
        <cylinder radius="0.028" length="0.01" />
        </geometry>
      <material name="warm_grey_plastic">
        <color rgba="0.45 0.46 0.45 1" />
        </material>
      </visual>
    <collision name="swivel_stem">
      <origin xyz="0 0 -0.0035" rpy="0 3.14159 0" />
      <geometry>
        <cylinder radius="0.013" length="0.063" />
        </geometry>
      </collision>
    <collision name="fork_crown">
      <origin xyz="0.01 0 -0.03" rpy="0 0 0" />
      <geometry>
        <box size="0.07 0.09 0.018" />
        </geometry>
      </collision>
    <collision name="inner_fork_arm">
      <origin xyz="0.0575 -0.032 -0.0575" rpy="0 2.08525 0" />
      <geometry>
        <cylinder radius="0.0065" length="0.132098" />
        </geometry>
      </collision>
    <collision name="outer_fork_arm">
      <origin xyz="0.0575 0.032 -0.0575" rpy="0 2.08525 0" />
      <geometry>
        <cylinder radius="0.0065" length="0.132098" />
        </geometry>
      </collision>
    <collision name="caster_axle_pin">
      <origin xyz="0.115 0 -0.09" rpy="0 1.5708 1.5708" />
      <geometry>
        <cylinder radius="0.006" length="0.08" />
        </geometry>
      </collision>
    <collision name="swivel_bearing_cap">
      <origin xyz="0 0 0.012" rpy="0 0 0" />
      <geometry>
        <cylinder radius="0.028" length="0.01" />
        </geometry>
      </collision>
    </link>
  <link name="left_front_wheel">
    <visual name="tire">
      <origin xyz="0 0 0" rpy="0 0 1.5708" />
      <geometry>
        <mesh filename="assets/meshes/left_front_tire.obj" />
        </geometry>
      <material name="matte_black_rubber">
        <color rgba="0.012 0.012 0.01 1" />
        </material>
      </visual>
    <visual name="rim">
      <origin xyz="0 0 0" rpy="0 0 1.5708" />
      <geometry>
        <mesh filename="assets/meshes/left_front_rim.obj" />
        </geometry>
      <material name="warm_grey_plastic">
        <color rgba="0.45 0.46 0.45 1" />
        </material>
      </visual>
    <visual name="outer_cap">
      <origin xyz="0 0.0166 0" rpy="0 1.5708 1.5708" />
      <geometry>
        <cylinder radius="0.01314" length="0.01912" />
        </geometry>
      <material name="dark_hinge_metal">
        <color rgba="0.18 0.19 0.19 1" />
        </material>
      </visual>
    <collision name="tire">
      <origin xyz="0 0 0" rpy="0 0 1.5708" />
      <geometry>
        <mesh filename="assets/meshes/left_front_tire.obj" />
        </geometry>
      </collision>
    <collision name="rim">
      <origin xyz="0 0 0" rpy="0 0 1.5708" />
      <geometry>
        <mesh filename="assets/meshes/left_front_rim.obj" />
        </geometry>
      </collision>
    <collision name="outer_cap">
      <origin xyz="0 0.0166 0" rpy="0 1.5708 1.5708" />
      <geometry>
        <cylinder radius="0.01314" length="0.01912" />
        </geometry>
      </collision>
    </link>
  <link name="right_caster_fork">
    <visual name="swivel_stem">
      <origin xyz="0 0 -0.0035" rpy="0 3.14159 0" />
      <geometry>
        <cylinder radius="0.013" length="0.063" />
        </geometry>
      <material name="dark_hinge_metal">
        <color rgba="0.18 0.19 0.19 1" />
        </material>
      </visual>
    <visual name="fork_crown">
      <origin xyz="0.01 0 -0.03" rpy="0 0 0" />
      <geometry>
        <box size="0.07 0.09 0.018" />
        </geometry>
      <material name="brushed_aluminum">
        <color rgba="0.72 0.74 0.73 1" />
        </material>
      </visual>
    <visual name="inner_fork_arm">
      <origin xyz="0.0575 -0.032 -0.0575" rpy="0 2.08525 0" />
      <geometry>
        <cylinder radius="0.0065" length="0.132098" />
        </geometry>
      <material name="brushed_aluminum">
        <color rgba="0.72 0.74 0.73 1" />
        </material>
      </visual>
    <visual name="outer_fork_arm">
      <origin xyz="0.0575 0.032 -0.0575" rpy="0 2.08525 0" />
      <geometry>
        <cylinder radius="0.0065" length="0.132098" />
        </geometry>
      <material name="brushed_aluminum">
        <color rgba="0.72 0.74 0.73 1" />
        </material>
      </visual>
    <visual name="caster_axle_pin">
      <origin xyz="0.115 0 -0.09" rpy="0 1.5708 1.5708" />
      <geometry>
        <cylinder radius="0.006" length="0.08" />
        </geometry>
      <material name="dark_hinge_metal">
        <color rgba="0.18 0.19 0.19 1" />
        </material>
      </visual>
    <visual name="swivel_bearing_cap">
      <origin xyz="0 0 0.012" rpy="0 0 0" />
      <geometry>
        <cylinder radius="0.028" length="0.01" />
        </geometry>
      <material name="warm_grey_plastic">
        <color rgba="0.45 0.46 0.45 1" />
        </material>
      </visual>
    <collision name="swivel_stem">
      <origin xyz="0 0 -0.0035" rpy="0 3.14159 0" />
      <geometry>
        <cylinder radius="0.013" length="0.063" />
        </geometry>
      </collision>
    <collision name="fork_crown">
      <origin xyz="0.01 0 -0.03" rpy="0 0 0" />
      <geometry>
        <box size="0.07 0.09 0.018" />
        </geometry>
      </collision>
    <collision name="inner_fork_arm">
      <origin xyz="0.0575 -0.032 -0.0575" rpy="0 2.08525 0" />
      <geometry>
        <cylinder radius="0.0065" length="0.132098" />
        </geometry>
      </collision>
    <collision name="outer_fork_arm">
      <origin xyz="0.0575 0.032 -0.0575" rpy="0 2.08525 0" />
      <geometry>
        <cylinder radius="0.0065" length="0.132098" />
        </geometry>
      </collision>
    <collision name="caster_axle_pin">
      <origin xyz="0.115 0 -0.09" rpy="0 1.5708 1.5708" />
      <geometry>
        <cylinder radius="0.006" length="0.08" />
        </geometry>
      </collision>
    <collision name="swivel_bearing_cap">
      <origin xyz="0 0 0.012" rpy="0 0 0" />
      <geometry>
        <cylinder radius="0.028" length="0.01" />
        </geometry>
      </collision>
    </link>
  <link name="right_front_wheel">
    <visual name="tire">
      <origin xyz="0 0 0" rpy="0 0 1.5708" />
      <geometry>
        <mesh filename="assets/meshes/right_front_tire.obj" />
        </geometry>
      <material name="matte_black_rubber">
        <color rgba="0.012 0.012 0.01 1" />
        </material>
      </visual>
    <visual name="rim">
      <origin xyz="0 0 0" rpy="0 0 1.5708" />
      <geometry>
        <mesh filename="assets/meshes/right_front_rim.obj" />
        </geometry>
      <material name="warm_grey_plastic">
        <color rgba="0.45 0.46 0.45 1" />
        </material>
      </visual>
    <visual name="outer_cap">
      <origin xyz="0 -0.0166 0" rpy="0 1.5708 -1.5708" />
      <geometry>
        <cylinder radius="0.01314" length="0.01912" />
        </geometry>
      <material name="dark_hinge_metal">
        <color rgba="0.18 0.19 0.19 1" />
        </material>
      </visual>
    <collision name="tire">
      <origin xyz="0 0 0" rpy="0 0 1.5708" />
      <geometry>
        <mesh filename="assets/meshes/right_front_tire.obj" />
        </geometry>
      </collision>
    <collision name="rim">
      <origin xyz="0 0 0" rpy="0 0 1.5708" />
      <geometry>
        <mesh filename="assets/meshes/right_front_rim.obj" />
        </geometry>
      </collision>
    <collision name="outer_cap">
      <origin xyz="0 -0.0166 0" rpy="0 1.5708 -1.5708" />
      <geometry>
        <cylinder radius="0.01314" length="0.01912" />
        </geometry>
      </collision>
    </link>
  <link name="left_footrest">
    <visual name="socket_pin">
      <origin xyz="0 0 -0.03" rpy="0 3.14159 0" />
      <geometry>
        <cylinder radius="0.012" length="0.17" />
        </geometry>
      <material name="dark_hinge_metal">
        <color rgba="0.18 0.19 0.19 1" />
        </material>
      </visual>
    <visual name="upper_hanger_tube">
      <origin xyz="0.04 0 -0.14" rpy="0 2.58994 0" />
      <geometry>
        <cylinder radius="0.008" length="0.152643" />
        </geometry>
      <material name="brushed_aluminum">
        <color rgba="0.72 0.74 0.73 1" />
        </material>
      </visual>
    <visual name="lower_hanger_tube">
      <origin xyz="0.16 0 -0.2525" rpy="0 2.10661 0" />
      <geometry>
        <cylinder radius="0.008" length="0.186078" />
        </geometry>
      <material name="brushed_aluminum">
        <color rgba="0.72 0.74 0.73 1" />
        </material>
      </visual>
    <visual name="footplate_hinge_pin">
      <origin xyz="0.22 0 -0.3" rpy="0 1.5708 1.5708" />
      <geometry>
        <cylinder radius="0.006" length="0.17" />
        </geometry>
      <material name="dark_hinge_metal">
        <color rgba="0.18 0.19 0.19 1" />
        </material>
      </visual>
    <visual name="release_tab">
      <origin xyz="0.052 0 -0.105" rpy="0 0 0" />
      <geometry>
        <box size="0.08 0.042 0.018" />
        </geometry>
      <material name="warm_grey_plastic">
        <color rgba="0.45 0.46 0.45 1" />
        </material>
      </visual>
    <collision name="socket_pin">
      <origin xyz="0 0 -0.03" rpy="0 3.14159 0" />
      <geometry>
        <cylinder radius="0.012" length="0.17" />
        </geometry>
      </collision>
    <collision name="upper_hanger_tube">
      <origin xyz="0.04 0 -0.14" rpy="0 2.58994 0" />
      <geometry>
        <cylinder radius="0.008" length="0.152643" />
        </geometry>
      </collision>
    <collision name="lower_hanger_tube">
      <origin xyz="0.16 0 -0.2525" rpy="0 2.10661 0" />
      <geometry>
        <cylinder radius="0.008" length="0.186078" />
        </geometry>
      </collision>
    <collision name="footplate_hinge_pin">
      <origin xyz="0.22 0 -0.3" rpy="0 1.5708 1.5708" />
      <geometry>
        <cylinder radius="0.006" length="0.17" />
        </geometry>
      </collision>
    <collision name="release_tab">
      <origin xyz="0.052 0 -0.105" rpy="0 0 0" />
      <geometry>
        <box size="0.08 0.042 0.018" />
        </geometry>
      </collision>
    </link>
  <link name="left_footplate">
    <visual name="plate">
      <origin xyz="0.105 0 -0.01" rpy="0 0 0" />
      <geometry>
        <box size="0.205 0.15 0.016" />
        </geometry>
      <material name="black_molded_plastic">
        <color rgba="0.02 0.02 0.018 1" />
        </material>
      </visual>
    <visual name="tread_rib_0">
      <origin xyz="0.045 0 0" rpy="0 0 0" />
      <geometry>
        <box size="0.01 0.132 0.006" />
        </geometry>
      <material name="warm_grey_plastic">
        <color rgba="0.45 0.46 0.45 1" />
        </material>
      </visual>
    <visual name="tread_rib_1">
      <origin xyz="0.09 0 0" rpy="0 0 0" />
      <geometry>
        <box size="0.01 0.132 0.006" />
        </geometry>
      <material name="warm_grey_plastic">
        <color rgba="0.45 0.46 0.45 1" />
        </material>
      </visual>
    <visual name="tread_rib_2">
      <origin xyz="0.135 0 0" rpy="0 0 0" />
      <geometry>
        <box size="0.01 0.132 0.006" />
        </geometry>
      <material name="warm_grey_plastic">
        <color rgba="0.45 0.46 0.45 1" />
        </material>
      </visual>
    <visual name="tread_rib_3">
      <origin xyz="0.175 0 0" rpy="0 0 0" />
      <geometry>
        <box size="0.01 0.132 0.006" />
        </geometry>
      <material name="warm_grey_plastic">
        <color rgba="0.45 0.46 0.45 1" />
        </material>
      </visual>
    <visual name="hinge_sleeve">
      <origin xyz="0 0 0" rpy="0 1.5708 1.5708" />
      <geometry>
        <cylinder radius="0.01" length="0.17" />
        </geometry>
      <material name="dark_hinge_metal">
        <color rgba="0.18 0.19 0.19 1" />
        </material>
      </visual>
    <visual name="heel_loop">
      <geometry>
        <mesh filename="assets/meshes/heel_loop_mesh.obj" />
        </geometry>
      <material name="black_molded_plastic">
        <color rgba="0.02 0.02 0.018 1" />
        </material>
      </visual>
    <collision name="plate">
      <origin xyz="0.105 0 -0.01" rpy="0 0 0" />
      <geometry>
        <box size="0.205 0.15 0.016" />
        </geometry>
      </collision>
    <collision name="tread_rib_0">
      <origin xyz="0.045 0 0" rpy="0 0 0" />
      <geometry>
        <box size="0.01 0.132 0.006" />
        </geometry>
      </collision>
    <collision name="tread_rib_1">
      <origin xyz="0.09 0 0" rpy="0 0 0" />
      <geometry>
        <box size="0.01 0.132 0.006" />
        </geometry>
      </collision>
    <collision name="tread_rib_2">
      <origin xyz="0.135 0 0" rpy="0 0 0" />
      <geometry>
        <box size="0.01 0.132 0.006" />
        </geometry>
      </collision>
    <collision name="tread_rib_3">
      <origin xyz="0.175 0 0" rpy="0 0 0" />
      <geometry>
        <box size="0.01 0.132 0.006" />
        </geometry>
      </collision>
    <collision name="hinge_sleeve">
      <origin xyz="0 0 0" rpy="0 1.5708 1.5708" />
      <geometry>
        <cylinder radius="0.01" length="0.17" />
        </geometry>
      </collision>
    <collision name="heel_loop">
      <geometry>
        <mesh filename="assets/meshes/heel_loop_mesh.obj" />
        </geometry>
      </collision>
    </link>
  <link name="right_footrest">
    <visual name="socket_pin">
      <origin xyz="0 0 -0.03" rpy="0 3.14159 0" />
      <geometry>
        <cylinder radius="0.012" length="0.17" />
        </geometry>
      <material name="dark_hinge_metal">
        <color rgba="0.18 0.19 0.19 1" />
        </material>
      </visual>
    <visual name="upper_hanger_tube">
      <origin xyz="0.04 0 -0.14" rpy="0 2.58994 0" />
      <geometry>
        <cylinder radius="0.008" length="0.152643" />
        </geometry>
      <material name="brushed_aluminum">
        <color rgba="0.72 0.74 0.73 1" />
        </material>
      </visual>
    <visual name="lower_hanger_tube">
      <origin xyz="0.16 0 -0.2525" rpy="0 2.10661 0" />
      <geometry>
        <cylinder radius="0.008" length="0.186078" />
        </geometry>
      <material name="brushed_aluminum">
        <color rgba="0.72 0.74 0.73 1" />
        </material>
      </visual>
    <visual name="footplate_hinge_pin">
      <origin xyz="0.22 0 -0.3" rpy="0 1.5708 1.5708" />
      <geometry>
        <cylinder radius="0.006" length="0.17" />
        </geometry>
      <material name="dark_hinge_metal">
        <color rgba="0.18 0.19 0.19 1" />
        </material>
      </visual>
    <visual name="release_tab">
      <origin xyz="0.052 0 -0.105" rpy="0 0 0" />
      <geometry>
        <box size="0.08 0.042 0.018" />
        </geometry>
      <material name="warm_grey_plastic">
        <color rgba="0.45 0.46 0.45 1" />
        </material>
      </visual>
    <collision name="socket_pin">
      <origin xyz="0 0 -0.03" rpy="0 3.14159 0" />
      <geometry>
        <cylinder radius="0.012" length="0.17" />
        </geometry>
      </collision>
    <collision name="upper_hanger_tube">
      <origin xyz="0.04 0 -0.14" rpy="0 2.58994 0" />
      <geometry>
        <cylinder radius="0.008" length="0.152643" />
        </geometry>
      </collision>
    <collision name="lower_hanger_tube">
      <origin xyz="0.16 0 -0.2525" rpy="0 2.10661 0" />
      <geometry>
        <cylinder radius="0.008" length="0.186078" />
        </geometry>
      </collision>
    <collision name="footplate_hinge_pin">
      <origin xyz="0.22 0 -0.3" rpy="0 1.5708 1.5708" />
      <geometry>
        <cylinder radius="0.006" length="0.17" />
        </geometry>
      </collision>
    <collision name="release_tab">
      <origin xyz="0.052 0 -0.105" rpy="0 0 0" />
      <geometry>
        <box size="0.08 0.042 0.018" />
        </geometry>
      </collision>
    </link>
  <link name="right_footplate">
    <visual name="plate">
      <origin xyz="0.105 0 -0.01" rpy="0 0 0" />
      <geometry>
        <box size="0.205 0.15 0.016" />
        </geometry>
      <material name="black_molded_plastic">
        <color rgba="0.02 0.02 0.018 1" />
        </material>
      </visual>
    <visual name="tread_rib_0">
      <origin xyz="0.045 0 0" rpy="0 0 0" />
      <geometry>
        <box size="0.01 0.132 0.006" />
        </geometry>
      <material name="warm_grey_plastic">
        <color rgba="0.45 0.46 0.45 1" />
        </material>
      </visual>
    <visual name="tread_rib_1">
      <origin xyz="0.09 0 0" rpy="0 0 0" />
      <geometry>
        <box size="0.01 0.132 0.006" />
        </geometry>
      <material name="warm_grey_plastic">
        <color rgba="0.45 0.46 0.45 1" />
        </material>
      </visual>
    <visual name="tread_rib_2">
      <origin xyz="0.135 0 0" rpy="0 0 0" />
      <geometry>
        <box size="0.01 0.132 0.006" />
        </geometry>
      <material name="warm_grey_plastic">
        <color rgba="0.45 0.46 0.45 1" />
        </material>
      </visual>
    <visual name="tread_rib_3">
      <origin xyz="0.175 0 0" rpy="0 0 0" />
      <geometry>
        <box size="0.01 0.132 0.006" />
        </geometry>
      <material name="warm_grey_plastic">
        <color rgba="0.45 0.46 0.45 1" />
        </material>
      </visual>
    <visual name="hinge_sleeve">
      <origin xyz="0 0 0" rpy="0 1.5708 1.5708" />
      <geometry>
        <cylinder radius="0.01" length="0.17" />
        </geometry>
      <material name="dark_hinge_metal">
        <color rgba="0.18 0.19 0.19 1" />
        </material>
      </visual>
    <visual name="heel_loop">
      <geometry>
        <mesh filename="assets/meshes/heel_loop_mesh.obj" />
        </geometry>
      <material name="black_molded_plastic">
        <color rgba="0.02 0.02 0.018 1" />
        </material>
      </visual>
    <collision name="plate">
      <origin xyz="0.105 0 -0.01" rpy="0 0 0" />
      <geometry>
        <box size="0.205 0.15 0.016" />
        </geometry>
      </collision>
    <collision name="tread_rib_0">
      <origin xyz="0.045 0 0" rpy="0 0 0" />
      <geometry>
        <box size="0.01 0.132 0.006" />
        </geometry>
      </collision>
    <collision name="tread_rib_1">
      <origin xyz="0.09 0 0" rpy="0 0 0" />
      <geometry>
        <box size="0.01 0.132 0.006" />
        </geometry>
      </collision>
    <collision name="tread_rib_2">
      <origin xyz="0.135 0 0" rpy="0 0 0" />
      <geometry>
        <box size="0.01 0.132 0.006" />
        </geometry>
      </collision>
    <collision name="tread_rib_3">
      <origin xyz="0.175 0 0" rpy="0 0 0" />
      <geometry>
        <box size="0.01 0.132 0.006" />
        </geometry>
      </collision>
    <collision name="hinge_sleeve">
      <origin xyz="0 0 0" rpy="0 1.5708 1.5708" />
      <geometry>
        <cylinder radius="0.01" length="0.17" />
        </geometry>
      </collision>
    <collision name="heel_loop">
      <geometry>
        <mesh filename="assets/meshes/heel_loop_mesh.obj" />
        </geometry>
      </collision>
    </link>
  <joint name="frame_to_backrest" type="revolute">
    <origin xyz="-0.25 0 0.5" rpy="0 0 0" />
    <parent link="frame" />
    <child link="backrest" />
    <axis xyz="0 1 0" />
    <limit effort="30" velocity="1.2" lower="0" upper="1.45" />
    </joint>
  <joint name="backrest_to_left_brake_lever" type="revolute">
    <origin xyz="-0.214 0.235 0.548" rpy="0 0 0" />
    <parent link="backrest" />
    <child link="left_brake_lever" />
    <axis xyz="0 1 0" />
    <limit effort="4" velocity="3" lower="0" upper="0.55" />
    </joint>
  <joint name="backrest_to_right_brake_lever" type="revolute">
    <origin xyz="-0.214 -0.235 0.548" rpy="0 0 0" />
    <parent link="backrest" />
    <child link="right_brake_lever" />
    <axis xyz="0 -1 0" />
    <limit effort="4" velocity="3" lower="0" upper="0.55" />
    </joint>
  <joint name="frame_to_left_rear_wheel" type="continuous">
    <origin xyz="-0.28 0.315 0.19" rpy="0 0 0" />
    <parent link="frame" />
    <child link="left_rear_wheel" />
    <axis xyz="0 1 0" />
    <limit effort="8" velocity="18" />
    </joint>
  <joint name="frame_to_right_rear_wheel" type="continuous">
    <origin xyz="-0.28 -0.315 0.19" rpy="0 0 0" />
    <parent link="frame" />
    <child link="right_rear_wheel" />
    <axis xyz="0 1 0" />
    <limit effort="8" velocity="18" />
    </joint>
  <joint name="frame_to_left_caster_fork" type="revolute">
    <origin xyz="0.365 0.285 0.19" rpy="0 0 0" />
    <parent link="frame" />
    <child link="left_caster_fork" />
    <axis xyz="0 0 1" />
    <limit effort="5" velocity="8" lower="-3.14159" upper="3.14159" />
    </joint>
  <joint name="left_caster_fork_to_front_wheel" type="continuous">
    <origin xyz="0.115 0 -0.09" rpy="0 0 0" />
    <parent link="left_caster_fork" />
    <child link="left_front_wheel" />
    <axis xyz="0 1 0" />
    <limit effort="4" velocity="24" />
    </joint>
  <joint name="frame_to_right_caster_fork" type="revolute">
    <origin xyz="0.365 -0.285 0.19" rpy="0 0 0" />
    <parent link="frame" />
    <child link="right_caster_fork" />
    <axis xyz="0 0 1" />
    <limit effort="5" velocity="8" lower="-3.14159" upper="3.14159" />
    </joint>
  <joint name="right_caster_fork_to_front_wheel" type="continuous">
    <origin xyz="0.115 0 -0.09" rpy="0 0 0" />
    <parent link="right_caster_fork" />
    <child link="right_front_wheel" />
    <axis xyz="0 1 0" />
    <limit effort="4" velocity="24" />
    </joint>
  <joint name="frame_to_left_footrest" type="revolute">
    <origin xyz="0.335 0.16 0.37" rpy="0 0 0" />
    <parent link="frame" />
    <child link="left_footrest" />
    <axis xyz="0 0 1" />
    <limit effort="18" velocity="1.6" lower="0" upper="1.2" />
    </joint>
  <joint name="left_footrest_to_footplate" type="revolute">
    <origin xyz="0.22 0 -0.3" rpy="0 0 0" />
    <parent link="left_footrest" />
    <child link="left_footplate" />
    <axis xyz="0 -1 0" />
    <limit effort="8" velocity="2.5" lower="0" upper="1.55" />
    </joint>
  <joint name="frame_to_right_footrest" type="revolute">
    <origin xyz="0.335 -0.16 0.37" rpy="0 0 0" />
    <parent link="frame" />
    <child link="right_footrest" />
    <axis xyz="0 0 -1" />
    <limit effort="18" velocity="1.6" lower="0" upper="1.2" />
    </joint>
  <joint name="right_footrest_to_footplate" type="revolute">
    <origin xyz="0.22 0 -0.3" rpy="0 0 0" />
    <parent link="right_footrest" />
    <child link="right_footplate" />
    <axis xyz="0 -1 0" />
    <limit effort="8" velocity="2.5" lower="0" upper="1.55" />
    </joint>
  </robot>
