<robot name="linear_slide_module">
  <link name="guide_rail">
    <visual name="base_plate">
      <origin xyz="0 0 0.006" rpy="0 0 0" />
      <geometry>
        <box size="0.62 0.16 0.012" />
        </geometry>
      <material name="dark_anodized_aluminum">
        <color rgba="0.05 0.055 0.06 1" />
        </material>
      </visual>
    <visual name="center_rail">
      <origin xyz="0 0 0.031" rpy="0 0 0" />
      <geometry>
        <box size="0.56 0.055 0.038" />
        </geometry>
      <material name="satin_steel">
        <color rgba="0.62 0.64 0.66 1" />
        </material>
      </visual>
    <visual name="rail_crown">
      <origin xyz="0 0 0.056" rpy="0 0 0" />
      <geometry>
        <box size="0.56 0.035 0.012" />
        </geometry>
      <material name="satin_steel">
        <color rgba="0.62 0.64 0.66 1" />
        </material>
      </visual>
    <visual name="race_pos">
      <origin xyz="0 0.033 0.046" rpy="0 1.5708 0" />
      <geometry>
        <cylinder radius="0.006" length="0.56" />
        </geometry>
      <material name="satin_steel">
        <color rgba="0.62 0.64 0.66 1" />
        </material>
      </visual>
    <visual name="race_neg">
      <origin xyz="0 -0.033 0.046" rpy="0 1.5708 0" />
      <geometry>
        <cylinder radius="0.006" length="0.56" />
        </geometry>
      <material name="satin_steel">
        <color rgba="0.62 0.64 0.66 1" />
        </material>
      </visual>
    <visual name="end_stop_0">
      <origin xyz="-0.295 0 0.04" rpy="0 0 0" />
      <geometry>
        <box size="0.025 0.14 0.056" />
        </geometry>
      <material name="dark_anodized_aluminum">
        <color rgba="0.05 0.055 0.06 1" />
        </material>
      </visual>
    <visual name="end_stop_1">
      <origin xyz="0.295 0 0.04" rpy="0 0 0" />
      <geometry>
        <box size="0.025 0.14 0.056" />
        </geometry>
      <material name="dark_anodized_aluminum">
        <color rgba="0.05 0.055 0.06 1" />
        </material>
      </visual>
    <visual name="base_screw_-0.22_-0.06">
      <origin xyz="-0.22 -0.06 0.014" rpy="0 0 0" />
      <geometry>
        <cylinder radius="0.008" length="0.004" />
        </geometry>
      <material name="black_plastic">
        <color rgba="0.015 0.015 0.017 1" />
        </material>
      </visual>
    <visual name="base_screw_-0.22_+0.06">
      <origin xyz="-0.22 0.06 0.014" rpy="0 0 0" />
      <geometry>
        <cylinder radius="0.008" length="0.004" />
        </geometry>
      <material name="black_plastic">
        <color rgba="0.015 0.015 0.017 1" />
        </material>
      </visual>
    <visual name="base_screw_+0.22_-0.06">
      <origin xyz="0.22 -0.06 0.014" rpy="0 0 0" />
      <geometry>
        <cylinder radius="0.008" length="0.004" />
        </geometry>
      <material name="black_plastic">
        <color rgba="0.015 0.015 0.017 1" />
        </material>
      </visual>
    <visual name="base_screw_+0.22_+0.06">
      <origin xyz="0.22 0.06 0.014" rpy="0 0 0" />
      <geometry>
        <cylinder radius="0.008" length="0.004" />
        </geometry>
      <material name="black_plastic">
        <color rgba="0.015 0.015 0.017 1" />
        </material>
      </visual>
    <collision name="base_plate">
      <origin xyz="0 0 0.006" rpy="0 0 0" />
      <geometry>
        <box size="0.62 0.16 0.012" />
        </geometry>
      </collision>
    <collision name="center_rail">
      <origin xyz="0 0 0.031" rpy="0 0 0" />
      <geometry>
        <box size="0.56 0.055 0.038" />
        </geometry>
      </collision>
    <collision name="rail_crown">
      <origin xyz="0 0 0.056" rpy="0 0 0" />
      <geometry>
        <box size="0.56 0.035 0.012" />
        </geometry>
      </collision>
    <collision name="race_pos">
      <origin xyz="0 0.033 0.046" rpy="0 1.5708 0" />
      <geometry>
        <cylinder radius="0.006" length="0.56" />
        </geometry>
      </collision>
    <collision name="race_neg">
      <origin xyz="0 -0.033 0.046" rpy="0 1.5708 0" />
      <geometry>
        <cylinder radius="0.006" length="0.56" />
        </geometry>
      </collision>
    <collision name="end_stop_0">
      <origin xyz="-0.295 0 0.04" rpy="0 0 0" />
      <geometry>
        <box size="0.025 0.14 0.056" />
        </geometry>
      </collision>
    <collision name="end_stop_1">
      <origin xyz="0.295 0 0.04" rpy="0 0 0" />
      <geometry>
        <box size="0.025 0.14 0.056" />
        </geometry>
      </collision>
    <collision name="base_screw_-0.22_-0.06">
      <origin xyz="-0.22 -0.06 0.014" rpy="0 0 0" />
      <geometry>
        <cylinder radius="0.008" length="0.004" />
        </geometry>
      </collision>
    <collision name="base_screw_-0.22_+0.06">
      <origin xyz="-0.22 0.06 0.014" rpy="0 0 0" />
      <geometry>
        <cylinder radius="0.008" length="0.004" />
        </geometry>
      </collision>
    <collision name="base_screw_+0.22_-0.06">
      <origin xyz="0.22 -0.06 0.014" rpy="0 0 0" />
      <geometry>
        <cylinder radius="0.008" length="0.004" />
        </geometry>
      </collision>
    <collision name="base_screw_+0.22_+0.06">
      <origin xyz="0.22 0.06 0.014" rpy="0 0 0" />
      <geometry>
        <cylinder radius="0.008" length="0.004" />
        </geometry>
      </collision>
    </link>
  <link name="carriage">
    <visual name="top_bridge">
      <geometry>
        <box size="0.14 0.12 0.035" />
        </geometry>
      <material name="brushed_carriage_aluminum">
        <color rgba="0.78 0.8 0.78 1" />
        </material>
      </visual>
    <visual name="side_cheek_pos">
      <origin xyz="0 0.051 -0.0425" rpy="0 0 0" />
      <geometry>
        <box size="0.14 0.024 0.05" />
        </geometry>
      <material name="brushed_carriage_aluminum">
        <color rgba="0.78 0.8 0.78 1" />
        </material>
      </visual>
    <visual name="side_cheek_neg">
      <origin xyz="0 -0.051 -0.0425" rpy="0 0 0" />
      <geometry>
        <box size="0.14 0.024 0.05" />
        </geometry>
      <material name="brushed_carriage_aluminum">
        <color rgba="0.78 0.8 0.78 1" />
        </material>
      </visual>
    <visual name="mount_plate">
      <origin xyz="0 0 0.0235" rpy="0 0 0" />
      <geometry>
        <box size="0.16 0.095 0.012" />
        </geometry>
      <material name="brushed_carriage_aluminum">
        <color rgba="0.78 0.8 0.78 1" />
        </material>
      </visual>
    <visual name="plate_screw_-0.055_-0.032">
      <origin xyz="-0.055 -0.032 0.0315" rpy="0 0 0" />
      <geometry>
        <cylinder radius="0.0075" length="0.004" />
        </geometry>
      <material name="black_plastic">
        <color rgba="0.015 0.015 0.017 1" />
        </material>
      </visual>
    <visual name="plate_screw_-0.055_+0.032">
      <origin xyz="-0.055 0.032 0.0315" rpy="0 0 0" />
      <geometry>
        <cylinder radius="0.0075" length="0.004" />
        </geometry>
      <material name="black_plastic">
        <color rgba="0.015 0.015 0.017 1" />
        </material>
      </visual>
    <visual name="plate_screw_+0.055_-0.032">
      <origin xyz="0.055 -0.032 0.0315" rpy="0 0 0" />
      <geometry>
        <cylinder radius="0.0075" length="0.004" />
        </geometry>
      <material name="black_plastic">
        <color rgba="0.015 0.015 0.017 1" />
        </material>
      </visual>
    <visual name="plate_screw_+0.055_+0.032">
      <origin xyz="0.055 0.032 0.0315" rpy="0 0 0" />
      <geometry>
        <cylinder radius="0.0075" length="0.004" />
        </geometry>
      <material name="black_plastic">
        <color rgba="0.015 0.015 0.017 1" />
        </material>
      </visual>
    <collision name="top_bridge">
      <geometry>
        <box size="0.14 0.12 0.035" />
        </geometry>
      </collision>
    <collision name="side_cheek_pos">
      <origin xyz="0 0.051 -0.0425" rpy="0 0 0" />
      <geometry>
        <box size="0.14 0.024 0.05" />
        </geometry>
      </collision>
    <collision name="side_cheek_neg">
      <origin xyz="0 -0.051 -0.0425" rpy="0 0 0" />
      <geometry>
        <box size="0.14 0.024 0.05" />
        </geometry>
      </collision>
    <collision name="mount_plate">
      <origin xyz="0 0 0.0235" rpy="0 0 0" />
      <geometry>
        <box size="0.16 0.095 0.012" />
        </geometry>
      </collision>
    <collision name="plate_screw_-0.055_-0.032">
      <origin xyz="-0.055 -0.032 0.0315" rpy="0 0 0" />
      <geometry>
        <cylinder radius="0.0075" length="0.004" />
        </geometry>
      </collision>
    <collision name="plate_screw_-0.055_+0.032">
      <origin xyz="-0.055 0.032 0.0315" rpy="0 0 0" />
      <geometry>
        <cylinder radius="0.0075" length="0.004" />
        </geometry>
      </collision>
    <collision name="plate_screw_+0.055_-0.032">
      <origin xyz="0.055 -0.032 0.0315" rpy="0 0 0" />
      <geometry>
        <cylinder radius="0.0075" length="0.004" />
        </geometry>
      </collision>
    <collision name="plate_screw_+0.055_+0.032">
      <origin xyz="0.055 0.032 0.0315" rpy="0 0 0" />
      <geometry>
        <cylinder radius="0.0075" length="0.004" />
        </geometry>
      </collision>
    </link>
  <joint name="rail_to_carriage" type="prismatic">
    <origin xyz="-0.18 0 0.095" rpy="0 0 0" />
    <parent link="guide_rail" />
    <child link="carriage" />
    <axis xyz="1 0 0" />
    <limit effort="120" velocity="0.35" lower="0" upper="0.32" />
    </joint>
  </robot>
