<robot name="toy_utility_wagon_car">
  <material name="painted_red">
    <color rgba="0.78 0.06 0.04 1" />
    </material>
  <material name="dark_chassis">
    <color rgba="0.03 0.035 0.04 1" />
    </material>
  <material name="rubber_black">
    <color rgba="0.01 0.01 0.012 1" />
    </material>
  <material name="cream_wheel">
    <color rgba="0.93 0.84 0.62 1" />
    </material>
  <material name="axle_silver">
    <color rgba="0.58 0.6 0.62 1" />
    </material>
  <material name="pale_blue_glass">
    <color rgba="0.55 0.78 0.92 0.42" />
    </material>
  <link name="body">
    <visual name="chassis">
      <origin xyz="0 0 0.145" rpy="0 0 0" />
      <geometry>
        <box size="0.78 0.38 0.05" />
        </geometry>
      <material name="dark_chassis">
        <color rgba="0.03 0.035 0.04 1" />
        </material>
      </visual>
    <visual name="engine_side_0">
      <origin xyz="0.255 0.177 0.255" rpy="0 0 0" />
      <geometry>
        <box size="0.28 0.025 0.13" />
        </geometry>
      <material name="painted_red">
        <color rgba="0.78 0.06 0.04 1" />
        </material>
      </visual>
    <visual name="engine_side_1">
      <origin xyz="0.255 -0.177 0.255" rpy="0 0 0" />
      <geometry>
        <box size="0.28 0.025 0.13" />
        </geometry>
      <material name="painted_red">
        <color rgba="0.78 0.06 0.04 1" />
        </material>
      </visual>
    <visual name="front_nose">
      <origin xyz="0.39 0 0.235" rpy="0 0 0" />
      <geometry>
        <box size="0.035 0.36 0.11" />
        </geometry>
      <material name="painted_red">
        <color rgba="0.78 0.06 0.04 1" />
        </material>
      </visual>
    <visual name="cabin_base">
      <origin xyz="0.02 0 0.265" rpy="0 0 0" />
      <geometry>
        <box size="0.19 0.36 0.1" />
        </geometry>
      <material name="painted_red">
        <color rgba="0.78 0.06 0.04 1" />
        </material>
      </visual>
    <visual name="cabin_roof">
      <origin xyz="0 0 0.51" rpy="0 0 0" />
      <geometry>
        <box size="0.22 0.35 0.04" />
        </geometry>
      <material name="painted_red">
        <color rgba="0.78 0.06 0.04 1" />
        </material>
      </visual>
    <visual name="cabin_pillar_0">
      <origin xyz="0.105 0.155 0.405" rpy="0 0 0" />
      <geometry>
        <box size="0.025 0.035 0.22" />
        </geometry>
      <material name="painted_red">
        <color rgba="0.78 0.06 0.04 1" />
        </material>
      </visual>
    <visual name="cabin_pillar_1">
      <origin xyz="0.105 -0.155 0.405" rpy="0 0 0" />
      <geometry>
        <box size="0.025 0.035 0.22" />
        </geometry>
      <material name="painted_red">
        <color rgba="0.78 0.06 0.04 1" />
        </material>
      </visual>
    <visual name="cabin_pillar_2">
      <origin xyz="-0.105 0.155 0.405" rpy="0 0 0" />
      <geometry>
        <box size="0.025 0.035 0.22" />
        </geometry>
      <material name="painted_red">
        <color rgba="0.78 0.06 0.04 1" />
        </material>
      </visual>
    <visual name="cabin_pillar_3">
      <origin xyz="-0.105 -0.155 0.405" rpy="0 0 0" />
      <geometry>
        <box size="0.025 0.035 0.22" />
        </geometry>
      <material name="painted_red">
        <color rgba="0.78 0.06 0.04 1" />
        </material>
      </visual>
    <visual name="windshield">
      <origin xyz="0.116 0 0.405" rpy="0 0 0" />
      <geometry>
        <box size="0.01 0.285 0.155" />
        </geometry>
      <material name="pale_blue_glass">
        <color rgba="0.55 0.78 0.92 0.42" />
        </material>
      </visual>
    <visual name="rear_window">
      <origin xyz="-0.116 0 0.405" rpy="0 0 0" />
      <geometry>
        <box size="0.01 0.285 0.15" />
        </geometry>
      <material name="pale_blue_glass">
        <color rgba="0.55 0.78 0.92 0.42" />
        </material>
      </visual>
    <visual name="cargo_floor">
      <origin xyz="-0.245 0 0.1875" rpy="0 0 0" />
      <geometry>
        <box size="0.31 0.34 0.035" />
        </geometry>
      <material name="painted_red">
        <color rgba="0.78 0.06 0.04 1" />
        </material>
      </visual>
    <visual name="cargo_side_0">
      <origin xyz="-0.245 0.185 0.27" rpy="0 0 0" />
      <geometry>
        <box size="0.3 0.035 0.16" />
        </geometry>
      <material name="painted_red">
        <color rgba="0.78 0.06 0.04 1" />
        </material>
      </visual>
    <visual name="cargo_side_1">
      <origin xyz="-0.245 -0.185 0.27" rpy="0 0 0" />
      <geometry>
        <box size="0.3 0.035 0.16" />
        </geometry>
      <material name="painted_red">
        <color rgba="0.78 0.06 0.04 1" />
        </material>
      </visual>
    <visual name="cargo_bulkhead">
      <origin xyz="-0.087 0 0.28" rpy="0 0 0" />
      <geometry>
        <box size="0.025 0.36 0.18" />
        </geometry>
      <material name="painted_red">
        <color rgba="0.78 0.06 0.04 1" />
        </material>
      </visual>
    <visual name="axle_0">
      <origin xyz="0.28 0 0.105" rpy="1.5708 0 0" />
      <geometry>
        <cylinder radius="0.015" length="0.43" />
        </geometry>
      <material name="axle_silver">
        <color rgba="0.58 0.6 0.62 1" />
        </material>
      </visual>
    <visual name="axle_1">
      <origin xyz="-0.28 0 0.105" rpy="1.5708 0 0" />
      <geometry>
        <cylinder radius="0.015" length="0.43" />
        </geometry>
      <material name="axle_silver">
        <color rgba="0.58 0.6 0.62 1" />
        </material>
      </visual>
    <visual name="fender_cap_0">
      <origin xyz="0.28 0.255 0.21" rpy="0 0 0" />
      <geometry>
        <box size="0.18 0.085 0.025" />
        </geometry>
      <material name="painted_red">
        <color rgba="0.78 0.06 0.04 1" />
        </material>
      </visual>
    <visual name="fender_bracket_0">
      <origin xyz="0.28 0.202 0.18" rpy="0 0 0" />
      <geometry>
        <box size="0.18 0.03 0.075" />
        </geometry>
      <material name="painted_red">
        <color rgba="0.78 0.06 0.04 1" />
        </material>
      </visual>
    <visual name="fender_cap_1">
      <origin xyz="0.28 -0.255 0.21" rpy="0 0 0" />
      <geometry>
        <box size="0.18 0.085 0.025" />
        </geometry>
      <material name="painted_red">
        <color rgba="0.78 0.06 0.04 1" />
        </material>
      </visual>
    <visual name="fender_bracket_1">
      <origin xyz="0.28 -0.202 0.18" rpy="0 0 0" />
      <geometry>
        <box size="0.18 0.03 0.075" />
        </geometry>
      <material name="painted_red">
        <color rgba="0.78 0.06 0.04 1" />
        </material>
      </visual>
    <visual name="fender_cap_2">
      <origin xyz="-0.28 0.255 0.21" rpy="0 0 0" />
      <geometry>
        <box size="0.18 0.085 0.025" />
        </geometry>
      <material name="painted_red">
        <color rgba="0.78 0.06 0.04 1" />
        </material>
      </visual>
    <visual name="fender_bracket_2">
      <origin xyz="-0.28 0.202 0.18" rpy="0 0 0" />
      <geometry>
        <box size="0.18 0.03 0.075" />
        </geometry>
      <material name="painted_red">
        <color rgba="0.78 0.06 0.04 1" />
        </material>
      </visual>
    <visual name="fender_cap_3">
      <origin xyz="-0.28 -0.255 0.21" rpy="0 0 0" />
      <geometry>
        <box size="0.18 0.085 0.025" />
        </geometry>
      <material name="painted_red">
        <color rgba="0.78 0.06 0.04 1" />
        </material>
      </visual>
    <visual name="fender_bracket_3">
      <origin xyz="-0.28 -0.202 0.18" rpy="0 0 0" />
      <geometry>
        <box size="0.18 0.03 0.075" />
        </geometry>
      <material name="painted_red">
        <color rgba="0.78 0.06 0.04 1" />
        </material>
      </visual>
    <visual name="gate_hinge_pin">
      <origin xyz="-0.402 0 0.1885" rpy="1.5708 0 0" />
      <geometry>
        <cylinder radius="0.0065" length="0.34" />
        </geometry>
      <material name="axle_silver">
        <color rgba="0.58 0.6 0.62 1" />
        </material>
      </visual>
    <collision name="chassis">
      <origin xyz="0 0 0.145" rpy="0 0 0" />
      <geometry>
        <box size="0.78 0.38 0.05" />
        </geometry>
      </collision>
    <collision name="engine_side_0">
      <origin xyz="0.255 0.177 0.255" rpy="0 0 0" />
      <geometry>
        <box size="0.28 0.025 0.13" />
        </geometry>
      </collision>
    <collision name="engine_side_1">
      <origin xyz="0.255 -0.177 0.255" rpy="0 0 0" />
      <geometry>
        <box size="0.28 0.025 0.13" />
        </geometry>
      </collision>
    <collision name="front_nose">
      <origin xyz="0.39 0 0.235" rpy="0 0 0" />
      <geometry>
        <box size="0.035 0.36 0.11" />
        </geometry>
      </collision>
    <collision name="cabin_base">
      <origin xyz="0.02 0 0.265" rpy="0 0 0" />
      <geometry>
        <box size="0.19 0.36 0.1" />
        </geometry>
      </collision>
    <collision name="cabin_roof">
      <origin xyz="0 0 0.51" rpy="0 0 0" />
      <geometry>
        <box size="0.22 0.35 0.04" />
        </geometry>
      </collision>
    <collision name="cabin_pillar_0">
      <origin xyz="0.105 0.155 0.405" rpy="0 0 0" />
      <geometry>
        <box size="0.025 0.035 0.22" />
        </geometry>
      </collision>
    <collision name="cabin_pillar_1">
      <origin xyz="0.105 -0.155 0.405" rpy="0 0 0" />
      <geometry>
        <box size="0.025 0.035 0.22" />
        </geometry>
      </collision>
    <collision name="cabin_pillar_2">
      <origin xyz="-0.105 0.155 0.405" rpy="0 0 0" />
      <geometry>
        <box size="0.025 0.035 0.22" />
        </geometry>
      </collision>
    <collision name="cabin_pillar_3">
      <origin xyz="-0.105 -0.155 0.405" rpy="0 0 0" />
      <geometry>
        <box size="0.025 0.035 0.22" />
        </geometry>
      </collision>
    <collision name="windshield">
      <origin xyz="0.116 0 0.405" rpy="0 0 0" />
      <geometry>
        <box size="0.01 0.285 0.155" />
        </geometry>
      </collision>
    <collision name="rear_window">
      <origin xyz="-0.116 0 0.405" rpy="0 0 0" />
      <geometry>
        <box size="0.01 0.285 0.15" />
        </geometry>
      </collision>
    <collision name="cargo_floor">
      <origin xyz="-0.245 0 0.1875" rpy="0 0 0" />
      <geometry>
        <box size="0.31 0.34 0.035" />
        </geometry>
      </collision>
    <collision name="cargo_side_0">
      <origin xyz="-0.245 0.185 0.27" rpy="0 0 0" />
      <geometry>
        <box size="0.3 0.035 0.16" />
        </geometry>
      </collision>
    <collision name="cargo_side_1">
      <origin xyz="-0.245 -0.185 0.27" rpy="0 0 0" />
      <geometry>
        <box size="0.3 0.035 0.16" />
        </geometry>
      </collision>
    <collision name="cargo_bulkhead">
      <origin xyz="-0.087 0 0.28" rpy="0 0 0" />
      <geometry>
        <box size="0.025 0.36 0.18" />
        </geometry>
      </collision>
    <collision name="axle_0">
      <origin xyz="0.28 0 0.105" rpy="1.5708 0 0" />
      <geometry>
        <cylinder radius="0.015" length="0.43" />
        </geometry>
      </collision>
    <collision name="axle_1">
      <origin xyz="-0.28 0 0.105" rpy="1.5708 0 0" />
      <geometry>
        <cylinder radius="0.015" length="0.43" />
        </geometry>
      </collision>
    <collision name="fender_cap_0">
      <origin xyz="0.28 0.255 0.21" rpy="0 0 0" />
      <geometry>
        <box size="0.18 0.085 0.025" />
        </geometry>
      </collision>
    <collision name="fender_bracket_0">
      <origin xyz="0.28 0.202 0.18" rpy="0 0 0" />
      <geometry>
        <box size="0.18 0.03 0.075" />
        </geometry>
      </collision>
    <collision name="fender_cap_1">
      <origin xyz="0.28 -0.255 0.21" rpy="0 0 0" />
      <geometry>
        <box size="0.18 0.085 0.025" />
        </geometry>
      </collision>
    <collision name="fender_bracket_1">
      <origin xyz="0.28 -0.202 0.18" rpy="0 0 0" />
      <geometry>
        <box size="0.18 0.03 0.075" />
        </geometry>
      </collision>
    <collision name="fender_cap_2">
      <origin xyz="-0.28 0.255 0.21" rpy="0 0 0" />
      <geometry>
        <box size="0.18 0.085 0.025" />
        </geometry>
      </collision>
    <collision name="fender_bracket_2">
      <origin xyz="-0.28 0.202 0.18" rpy="0 0 0" />
      <geometry>
        <box size="0.18 0.03 0.075" />
        </geometry>
      </collision>
    <collision name="fender_cap_3">
      <origin xyz="-0.28 -0.255 0.21" rpy="0 0 0" />
      <geometry>
        <box size="0.18 0.085 0.025" />
        </geometry>
      </collision>
    <collision name="fender_bracket_3">
      <origin xyz="-0.28 -0.202 0.18" rpy="0 0 0" />
      <geometry>
        <box size="0.18 0.03 0.075" />
        </geometry>
      </collision>
    <collision name="gate_hinge_pin">
      <origin xyz="-0.402 0 0.1885" rpy="1.5708 0 0" />
      <geometry>
        <cylinder radius="0.0065" length="0.34" />
        </geometry>
      </collision>
    </link>
  <link name="hood">
    <visual name="hood_panel">
      <origin xyz="0.135 0 0" rpy="0 0 0" />
      <geometry>
        <box size="0.27 0.35 0.025" />
        </geometry>
      <material name="painted_red">
        <color rgba="0.78 0.06 0.04 1" />
        </material>
      </visual>
    <visual name="hood_handle">
      <origin xyz="0.245 0 0.0185" rpy="0 0 0" />
      <geometry>
        <box size="0.02 0.24 0.012" />
        </geometry>
      <material name="axle_silver">
        <color rgba="0.58 0.6 0.62 1" />
        </material>
      </visual>
    <collision name="hood_panel">
      <origin xyz="0.135 0 0" rpy="0 0 0" />
      <geometry>
        <box size="0.27 0.35 0.025" />
        </geometry>
      </collision>
    <collision name="hood_handle">
      <origin xyz="0.245 0 0.0185" rpy="0 0 0" />
      <geometry>
        <box size="0.02 0.24 0.012" />
        </geometry>
      </collision>
    </link>
  <link name="rear_gate">
    <visual name="gate_panel">
      <origin xyz="-0.0125 0 0.08" rpy="0 0 0" />
      <geometry>
        <box size="0.025 0.35 0.16" />
        </geometry>
      <material name="painted_red">
        <color rgba="0.78 0.06 0.04 1" />
        </material>
      </visual>
    <visual name="gate_latch_bar">
      <origin xyz="-0.028 0 0.135" rpy="0 0 0" />
      <geometry>
        <box size="0.01 0.22 0.018" />
        </geometry>
      <material name="axle_silver">
        <color rgba="0.58 0.6 0.62 1" />
        </material>
      </visual>
    <collision name="gate_panel">
      <origin xyz="-0.0125 0 0.08" rpy="0 0 0" />
      <geometry>
        <box size="0.025 0.35 0.16" />
        </geometry>
      </collision>
    <collision name="gate_latch_bar">
      <origin xyz="-0.028 0 0.135" rpy="0 0 0" />
      <geometry>
        <box size="0.01 0.22 0.018" />
        </geometry>
      </collision>
    </link>
  <link name="wheel_front_left">
    <visual name="tire">
      <geometry>
        <mesh filename="assets/meshes/utility_tire.obj" />
        </geometry>
      <material name="rubber_black">
        <color rgba="0.01 0.01 0.012 1" />
        </material>
      </visual>
    <visual name="wheel_center">
      <geometry>
        <mesh filename="assets/meshes/cream_wheel.obj" />
        </geometry>
      <material name="cream_wheel">
        <color rgba="0.93 0.84 0.62 1" />
        </material>
      </visual>
    <collision name="tire">
      <geometry>
        <mesh filename="assets/meshes/utility_tire.obj" />
        </geometry>
      </collision>
    <collision name="wheel_center">
      <geometry>
        <mesh filename="assets/meshes/cream_wheel.obj" />
        </geometry>
      </collision>
    </link>
  <link name="wheel_front_right">
    <visual name="tire">
      <geometry>
        <mesh filename="assets/meshes/utility_tire.obj" />
        </geometry>
      <material name="rubber_black">
        <color rgba="0.01 0.01 0.012 1" />
        </material>
      </visual>
    <visual name="wheel_center">
      <geometry>
        <mesh filename="assets/meshes/cream_wheel.obj" />
        </geometry>
      <material name="cream_wheel">
        <color rgba="0.93 0.84 0.62 1" />
        </material>
      </visual>
    <collision name="tire">
      <geometry>
        <mesh filename="assets/meshes/utility_tire.obj" />
        </geometry>
      </collision>
    <collision name="wheel_center">
      <geometry>
        <mesh filename="assets/meshes/cream_wheel.obj" />
        </geometry>
      </collision>
    </link>
  <link name="wheel_rear_left">
    <visual name="tire">
      <geometry>
        <mesh filename="assets/meshes/utility_tire.obj" />
        </geometry>
      <material name="rubber_black">
        <color rgba="0.01 0.01 0.012 1" />
        </material>
      </visual>
    <visual name="wheel_center">
      <geometry>
        <mesh filename="assets/meshes/cream_wheel.obj" />
        </geometry>
      <material name="cream_wheel">
        <color rgba="0.93 0.84 0.62 1" />
        </material>
      </visual>
    <collision name="tire">
      <geometry>
        <mesh filename="assets/meshes/utility_tire.obj" />
        </geometry>
      </collision>
    <collision name="wheel_center">
      <geometry>
        <mesh filename="assets/meshes/cream_wheel.obj" />
        </geometry>
      </collision>
    </link>
  <link name="wheel_rear_right">
    <visual name="tire">
      <geometry>
        <mesh filename="assets/meshes/utility_tire.obj" />
        </geometry>
      <material name="rubber_black">
        <color rgba="0.01 0.01 0.012 1" />
        </material>
      </visual>
    <visual name="wheel_center">
      <geometry>
        <mesh filename="assets/meshes/cream_wheel.obj" />
        </geometry>
      <material name="cream_wheel">
        <color rgba="0.93 0.84 0.62 1" />
        </material>
      </visual>
    <collision name="tire">
      <geometry>
        <mesh filename="assets/meshes/utility_tire.obj" />
        </geometry>
      </collision>
    <collision name="wheel_center">
      <geometry>
        <mesh filename="assets/meshes/cream_wheel.obj" />
        </geometry>
      </collision>
    </link>
  <joint name="body_to_wheel_front_left" type="continuous">
    <origin xyz="0.28 0.255 0.105" rpy="0 0 1.5708" />
    <parent link="body" />
    <child link="wheel_front_left" />
    <axis xyz="1 0 0" />
    <limit effort="2" velocity="20" />
    </joint>
  <joint name="body_to_wheel_front_right" type="continuous">
    <origin xyz="0.28 -0.255 0.105" rpy="0 0 1.5708" />
    <parent link="body" />
    <child link="wheel_front_right" />
    <axis xyz="1 0 0" />
    <limit effort="2" velocity="20" />
    </joint>
  <joint name="body_to_wheel_rear_left" type="continuous">
    <origin xyz="-0.28 0.255 0.105" rpy="0 0 1.5708" />
    <parent link="body" />
    <child link="wheel_rear_left" />
    <axis xyz="1 0 0" />
    <limit effort="2" velocity="20" />
    </joint>
  <joint name="body_to_wheel_rear_right" type="continuous">
    <origin xyz="-0.28 -0.255 0.105" rpy="0 0 1.5708" />
    <parent link="body" />
    <child link="wheel_rear_right" />
    <axis xyz="1 0 0" />
    <limit effort="2" velocity="20" />
    </joint>
  <joint name="body_to_hood" type="revolute">
    <origin xyz="0.12 0 0.335" rpy="0 0 0" />
    <parent link="body" />
    <child link="hood" />
    <axis xyz="0 -1 0" />
    <limit effort="3" velocity="2.5" lower="0" upper="1.15" />
    </joint>
  <joint name="body_to_rear_gate" type="revolute">
    <origin xyz="-0.402 0 0.195" rpy="0 0 0" />
    <parent link="body" />
    <child link="rear_gate" />
    <axis xyz="0 -1 0" />
    <limit effort="3" velocity="2.5" lower="0" upper="1.55" />
    </joint>
  </robot>
