<robot name="under_slung_four_joint_chain">
  <material name="dark_powder_coated_steel">
    <color rgba="0.08 0.09 0.1 1" />
    </material>
  <material name="blue_anodized_links">
    <color rgba="0.05 0.2 0.42 1" />
    </material>
  <material name="matte_black_end_tab">
    <color rgba="0.02 0.02 0.018 1" />
    </material>
  <material name="brushed_stainless_pins">
    <color rgba="0.72 0.72 0.68 1" />
    </material>
  <link name="support">
    <visual name="top_plate">
      <origin xyz="0 0 0.007" rpy="0 0 0" />
      <geometry>
        <box size="0.17 0.12 0.014" />
        </geometry>
      <material name="dark_powder_coated_steel">
        <color rgba="0.08 0.09 0.1 1" />
        </material>
      </visual>
    <visual name="mounting_block">
      <origin xyz="0 0 -0.015" rpy="0 0 0" />
      <geometry>
        <box size="0.07 0.062 0.03" />
        </geometry>
      <material name="dark_powder_coated_steel">
        <color rgba="0.08 0.09 0.1 1" />
        </material>
      </visual>
    <visual name="cheek_0">
      <origin xyz="0 -0.034 -0.055" rpy="0 0 0" />
      <geometry>
        <box size="0.052 0.012 0.105" />
        </geometry>
      <material name="dark_powder_coated_steel">
        <color rgba="0.08 0.09 0.1 1" />
        </material>
      </visual>
    <visual name="cheek_1">
      <origin xyz="0 0.034 -0.055" rpy="0 0 0" />
      <geometry>
        <box size="0.052 0.012 0.105" />
        </geometry>
      <material name="dark_powder_coated_steel">
        <color rgba="0.08 0.09 0.1 1" />
        </material>
      </visual>
    <visual name="joint_0_pin">
      <origin xyz="0 0 -0.09" rpy="1.5708 0 0" />
      <geometry>
        <cylinder radius="0.008" length="0.086" />
        </geometry>
      <material name="brushed_stainless_pins">
        <color rgba="0.72 0.72 0.68 1" />
        </material>
      </visual>
    <collision name="top_plate">
      <origin xyz="0 0 0.007" rpy="0 0 0" />
      <geometry>
        <box size="0.17 0.12 0.014" />
        </geometry>
      </collision>
    <collision name="mounting_block">
      <origin xyz="0 0 -0.015" rpy="0 0 0" />
      <geometry>
        <box size="0.07 0.062 0.03" />
        </geometry>
      </collision>
    <collision name="cheek_0">
      <origin xyz="0 -0.034 -0.055" rpy="0 0 0" />
      <geometry>
        <box size="0.052 0.012 0.105" />
        </geometry>
      </collision>
    <collision name="cheek_1">
      <origin xyz="0 0.034 -0.055" rpy="0 0 0" />
      <geometry>
        <box size="0.052 0.012 0.105" />
        </geometry>
      </collision>
    <collision name="joint_0_pin">
      <origin xyz="0 0 -0.09" rpy="1.5708 0 0" />
      <geometry>
        <cylinder radius="0.008" length="0.086" />
        </geometry>
      </collision>
    </link>
  <link name="link_0">
    <visual name="proximal_eye">
      <origin xyz="0 -0.011 0" rpy="1.5708 0 0" />
      <geometry>
        <cylinder radius="0.03" length="0.012" />
        </geometry>
      <material name="blue_anodized_links">
        <color rgba="0.05 0.2 0.42 1" />
        </material>
      </visual>
    <visual name="web">
      <origin xyz="0 -0.011 -0.11" rpy="0 0 0" />
      <geometry>
        <box size="0.03 0.012 0.17" />
        </geometry>
      <material name="blue_anodized_links">
        <color rgba="0.05 0.2 0.42 1" />
        </material>
      </visual>
    <visual name="distal_eye">
      <origin xyz="0 -0.011 -0.22" rpy="1.5708 0 0" />
      <geometry>
        <cylinder radius="0.03" length="0.012" />
        </geometry>
      <material name="blue_anodized_links">
        <color rgba="0.05 0.2 0.42 1" />
        </material>
      </visual>
    <visual name="distal_pin">
      <origin xyz="0 0 -0.22" rpy="1.5708 0 0" />
      <geometry>
        <cylinder radius="0.008" length="0.06" />
        </geometry>
      <material name="brushed_stainless_pins">
        <color rgba="0.72 0.72 0.68 1" />
        </material>
      </visual>
    <collision name="proximal_eye">
      <origin xyz="0 -0.011 0" rpy="1.5708 0 0" />
      <geometry>
        <cylinder radius="0.03" length="0.012" />
        </geometry>
      </collision>
    <collision name="web">
      <origin xyz="0 -0.011 -0.11" rpy="0 0 0" />
      <geometry>
        <box size="0.03 0.012 0.17" />
        </geometry>
      </collision>
    <collision name="distal_eye">
      <origin xyz="0 -0.011 -0.22" rpy="1.5708 0 0" />
      <geometry>
        <cylinder radius="0.03" length="0.012" />
        </geometry>
      </collision>
    <collision name="distal_pin">
      <origin xyz="0 0 -0.22" rpy="1.5708 0 0" />
      <geometry>
        <cylinder radius="0.008" length="0.06" />
        </geometry>
      </collision>
    </link>
  <link name="link_1">
    <visual name="proximal_eye">
      <origin xyz="0 0.011 0" rpy="1.5708 0 0" />
      <geometry>
        <cylinder radius="0.03" length="0.012" />
        </geometry>
      <material name="blue_anodized_links">
        <color rgba="0.05 0.2 0.42 1" />
        </material>
      </visual>
    <visual name="web">
      <origin xyz="0 0.011 -0.0975" rpy="0 0 0" />
      <geometry>
        <box size="0.03 0.012 0.145" />
        </geometry>
      <material name="blue_anodized_links">
        <color rgba="0.05 0.2 0.42 1" />
        </material>
      </visual>
    <visual name="distal_eye">
      <origin xyz="0 0.011 -0.195" rpy="1.5708 0 0" />
      <geometry>
        <cylinder radius="0.03" length="0.012" />
        </geometry>
      <material name="blue_anodized_links">
        <color rgba="0.05 0.2 0.42 1" />
        </material>
      </visual>
    <visual name="distal_pin">
      <origin xyz="0 0 -0.195" rpy="1.5708 0 0" />
      <geometry>
        <cylinder radius="0.008" length="0.06" />
        </geometry>
      <material name="brushed_stainless_pins">
        <color rgba="0.72 0.72 0.68 1" />
        </material>
      </visual>
    <collision name="proximal_eye">
      <origin xyz="0 0.011 0" rpy="1.5708 0 0" />
      <geometry>
        <cylinder radius="0.03" length="0.012" />
        </geometry>
      </collision>
    <collision name="web">
      <origin xyz="0 0.011 -0.0975" rpy="0 0 0" />
      <geometry>
        <box size="0.03 0.012 0.145" />
        </geometry>
      </collision>
    <collision name="distal_eye">
      <origin xyz="0 0.011 -0.195" rpy="1.5708 0 0" />
      <geometry>
        <cylinder radius="0.03" length="0.012" />
        </geometry>
      </collision>
    <collision name="distal_pin">
      <origin xyz="0 0 -0.195" rpy="1.5708 0 0" />
      <geometry>
        <cylinder radius="0.008" length="0.06" />
        </geometry>
      </collision>
    </link>
  <link name="link_2">
    <visual name="proximal_eye">
      <origin xyz="0 -0.011 0" rpy="1.5708 0 0" />
      <geometry>
        <cylinder radius="0.03" length="0.012" />
        </geometry>
      <material name="blue_anodized_links">
        <color rgba="0.05 0.2 0.42 1" />
        </material>
      </visual>
    <visual name="web">
      <origin xyz="0 -0.011 -0.0875" rpy="0 0 0" />
      <geometry>
        <box size="0.03 0.012 0.125" />
        </geometry>
      <material name="blue_anodized_links">
        <color rgba="0.05 0.2 0.42 1" />
        </material>
      </visual>
    <visual name="distal_eye">
      <origin xyz="0 -0.011 -0.175" rpy="1.5708 0 0" />
      <geometry>
        <cylinder radius="0.03" length="0.012" />
        </geometry>
      <material name="blue_anodized_links">
        <color rgba="0.05 0.2 0.42 1" />
        </material>
      </visual>
    <visual name="distal_pin">
      <origin xyz="0 0 -0.175" rpy="1.5708 0 0" />
      <geometry>
        <cylinder radius="0.008" length="0.06" />
        </geometry>
      <material name="brushed_stainless_pins">
        <color rgba="0.72 0.72 0.68 1" />
        </material>
      </visual>
    <collision name="proximal_eye">
      <origin xyz="0 -0.011 0" rpy="1.5708 0 0" />
      <geometry>
        <cylinder radius="0.03" length="0.012" />
        </geometry>
      </collision>
    <collision name="web">
      <origin xyz="0 -0.011 -0.0875" rpy="0 0 0" />
      <geometry>
        <box size="0.03 0.012 0.125" />
        </geometry>
      </collision>
    <collision name="distal_eye">
      <origin xyz="0 -0.011 -0.175" rpy="1.5708 0 0" />
      <geometry>
        <cylinder radius="0.03" length="0.012" />
        </geometry>
      </collision>
    <collision name="distal_pin">
      <origin xyz="0 0 -0.175" rpy="1.5708 0 0" />
      <geometry>
        <cylinder radius="0.008" length="0.06" />
        </geometry>
      </collision>
    </link>
  <link name="end_tab">
    <visual name="proximal_eye">
      <origin xyz="0 0.011 0" rpy="1.5708 0 0" />
      <geometry>
        <cylinder radius="0.03" length="0.012" />
        </geometry>
      <material name="matte_black_end_tab">
        <color rgba="0.02 0.02 0.018 1" />
        </material>
      </visual>
    <visual name="neck">
      <origin xyz="0 0.011 -0.048" rpy="0 0 0" />
      <geometry>
        <box size="0.026 0.012 0.07" />
        </geometry>
      <material name="matte_black_end_tab">
        <color rgba="0.02 0.02 0.018 1" />
        </material>
      </visual>
    <visual name="tab_plate">
      <origin xyz="0 0.011 -0.096" rpy="0 0 0" />
      <geometry>
        <box size="0.064 0.012 0.044" />
        </geometry>
      <material name="matte_black_end_tab">
        <color rgba="0.02 0.02 0.018 1" />
        </material>
      </visual>
    <collision name="proximal_eye">
      <origin xyz="0 0.011 0" rpy="1.5708 0 0" />
      <geometry>
        <cylinder radius="0.03" length="0.012" />
        </geometry>
      </collision>
    <collision name="neck">
      <origin xyz="0 0.011 -0.048" rpy="0 0 0" />
      <geometry>
        <box size="0.026 0.012 0.07" />
        </geometry>
      </collision>
    <collision name="tab_plate">
      <origin xyz="0 0.011 -0.096" rpy="0 0 0" />
      <geometry>
        <box size="0.064 0.012 0.044" />
        </geometry>
      </collision>
    </link>
  <joint name="support_to_link_0" type="revolute">
    <origin xyz="0 0 -0.09" rpy="0 0 0" />
    <parent link="support" />
    <child link="link_0" />
    <axis xyz="0 1 0" />
    <limit effort="8" velocity="3.5" lower="-1.45" upper="1.45" />
    </joint>
  <joint name="link_0_to_link_1" type="revolute">
    <origin xyz="0 0 -0.22" rpy="0 0 0" />
    <parent link="link_0" />
    <child link="link_1" />
    <axis xyz="0 1 0" />
    <limit effort="8" velocity="3.5" lower="-1.45" upper="1.45" />
    </joint>
  <joint name="link_1_to_link_2" type="revolute">
    <origin xyz="0 0 -0.195" rpy="0 0 0" />
    <parent link="link_1" />
    <child link="link_2" />
    <axis xyz="0 1 0" />
    <limit effort="8" velocity="3.5" lower="-1.45" upper="1.45" />
    </joint>
  <joint name="link_2_to_end_tab" type="revolute">
    <origin xyz="0 0 -0.175" rpy="0 0 0" />
    <parent link="link_2" />
    <child link="end_tab" />
    <axis xyz="0 1 0" />
    <limit effort="4" velocity="3.5" lower="-1.35" upper="1.35" />
    </joint>
  </robot>
