<robot name="handheld_camcorder">
  <link name="body">
    <visual name="body_shell">
      <geometry>
        <box size="0.17 0.07 0.078" />
        </geometry>
      <material name="matte_graphite">
        <color rgba="0.045 0.047 0.05 1" />
        </material>
      </visual>
    <visual name="top_hump">
      <origin xyz="-0.01 0 0.046" rpy="0 0 0" />
      <geometry>
        <box size="0.13 0.04 0.014" />
        </geometry>
      <material name="dark_plastic">
        <color rgba="0.015 0.016 0.018 1" />
        </material>
      </visual>
    <visual name="rear_eyecup">
      <origin xyz="-0.1 0 0.014" rpy="0 1.5708 0" />
      <geometry>
        <cylinder radius="0.018" length="0.03" />
        </geometry>
      <material name="satin_black">
        <color rgba="0.005 0.006 0.007 1" />
        </material>
      </visual>
    <visual name="front_mount">
      <origin xyz="0.091 0 0" rpy="0 1.5708 0" />
      <geometry>
        <cylinder radius="0.036" length="0.012" />
        </geometry>
      <material name="dark_plastic">
        <color rgba="0.015 0.016 0.018 1" />
        </material>
      </visual>
    <visual name="front_shadow">
      <origin xyz="0.092 0 0" rpy="0 1.5708 0" />
      <geometry>
        <cylinder radius="0.03" length="0.006" />
        </geometry>
      <material name="satin_black">
        <color rgba="0.005 0.006 0.007 1" />
        </material>
      </visual>
    <visual name="hand_strap">
      <geometry>
        <mesh filename="assets/meshes/side_hand_strap.obj" />
        </geometry>
      <material name="soft_black_rubber">
        <color rgba="0.01 0.01 0.009 1" />
        </material>
      </visual>
    <visual name="strap_anchor_0">
      <origin xyz="-0.066 0.039 -0.012" rpy="0 0 0" />
      <geometry>
        <box size="0.02 0.014 0.024" />
        </geometry>
      <material name="dark_plastic">
        <color rgba="0.015 0.016 0.018 1" />
        </material>
      </visual>
    <visual name="strap_anchor_1">
      <origin xyz="0.066 0.039 -0.012" rpy="0 0 0" />
      <geometry>
        <box size="0.02 0.014 0.024" />
        </geometry>
      <material name="dark_plastic">
        <color rgba="0.015 0.016 0.018 1" />
        </material>
      </visual>
    <visual name="display_hinge_leaf_0">
      <origin xyz="-0.062 -0.0375 -0.028" rpy="0 0 0" />
      <geometry>
        <box size="0.014 0.01 0.018" />
        </geometry>
      <material name="dark_plastic">
        <color rgba="0.015 0.016 0.018 1" />
        </material>
      </visual>
    <visual name="display_hinge_knuckle_0">
      <origin xyz="-0.062 -0.041 -0.028" rpy="0 0 0" />
      <geometry>
        <cylinder radius="0.0042" length="0.018" />
        </geometry>
      <material name="brushed_dark_silver">
        <color rgba="0.45 0.47 0.48 1" />
        </material>
      </visual>
    <visual name="display_hinge_leaf_1">
      <origin xyz="-0.062 -0.0375 0.028" rpy="0 0 0" />
      <geometry>
        <box size="0.014 0.01 0.018" />
        </geometry>
      <material name="dark_plastic">
        <color rgba="0.015 0.016 0.018 1" />
        </material>
      </visual>
    <visual name="display_hinge_knuckle_1">
      <origin xyz="-0.062 -0.041 0.028" rpy="0 0 0" />
      <geometry>
        <cylinder radius="0.0042" length="0.018" />
        </geometry>
      <material name="brushed_dark_silver">
        <color rgba="0.45 0.47 0.48 1" />
        </material>
      </visual>
    <collision name="body_shell">
      <geometry>
        <box size="0.17 0.07 0.078" />
        </geometry>
      </collision>
    <collision name="top_hump">
      <origin xyz="-0.01 0 0.046" rpy="0 0 0" />
      <geometry>
        <box size="0.13 0.04 0.014" />
        </geometry>
      </collision>
    <collision name="rear_eyecup">
      <origin xyz="-0.1 0 0.014" rpy="0 1.5708 0" />
      <geometry>
        <cylinder radius="0.018" length="0.03" />
        </geometry>
      </collision>
    <collision name="front_mount">
      <origin xyz="0.091 0 0" rpy="0 1.5708 0" />
      <geometry>
        <cylinder radius="0.036" length="0.012" />
        </geometry>
      </collision>
    <collision name="front_shadow">
      <origin xyz="0.092 0 0" rpy="0 1.5708 0" />
      <geometry>
        <cylinder radius="0.03" length="0.006" />
        </geometry>
      </collision>
    <collision name="hand_strap">
      <geometry>
        <mesh filename="assets/meshes/side_hand_strap.obj" />
        </geometry>
      </collision>
    <collision name="strap_anchor_0">
      <origin xyz="-0.066 0.039 -0.012" rpy="0 0 0" />
      <geometry>
        <box size="0.02 0.014 0.024" />
        </geometry>
      </collision>
    <collision name="strap_anchor_1">
      <origin xyz="0.066 0.039 -0.012" rpy="0 0 0" />
      <geometry>
        <box size="0.02 0.014 0.024" />
        </geometry>
      </collision>
    <collision name="display_hinge_leaf_0">
      <origin xyz="-0.062 -0.0375 -0.028" rpy="0 0 0" />
      <geometry>
        <box size="0.014 0.01 0.018" />
        </geometry>
      </collision>
    <collision name="display_hinge_knuckle_0">
      <origin xyz="-0.062 -0.041 -0.028" rpy="0 0 0" />
      <geometry>
        <cylinder radius="0.0042" length="0.018" />
        </geometry>
      </collision>
    <collision name="display_hinge_leaf_1">
      <origin xyz="-0.062 -0.0375 0.028" rpy="0 0 0" />
      <geometry>
        <box size="0.014 0.01 0.018" />
        </geometry>
      </collision>
    <collision name="display_hinge_knuckle_1">
      <origin xyz="-0.062 -0.041 0.028" rpy="0 0 0" />
      <geometry>
        <cylinder radius="0.0042" length="0.018" />
        </geometry>
      </collision>
    </link>
  <link name="lens_barrel">
    <visual name="barrel_shell">
      <origin xyz="0.027 0 0" rpy="0 1.5708 0" />
      <geometry>
        <cylinder radius="0.027" length="0.054" />
        </geometry>
      <material name="satin_black">
        <color rgba="0.005 0.006 0.007 1" />
        </material>
      </visual>
    <visual name="grip_ring">
      <origin xyz="0.02 0 0" rpy="0 1.5708 0" />
      <geometry>
        <cylinder radius="0.03" length="0.024" />
        </geometry>
      <material name="dark_plastic">
        <color rgba="0.015 0.016 0.018 1" />
        </material>
      </visual>
    <visual name="front_rim">
      <origin xyz="0.05 0 0" rpy="0 1.5708 0" />
      <geometry>
        <cylinder radius="0.032" length="0.01" />
        </geometry>
      <material name="dark_plastic">
        <color rgba="0.015 0.016 0.018 1" />
        </material>
      </visual>
    <visual name="front_glass">
      <origin xyz="0.0565 0 0" rpy="0 1.5708 0" />
      <geometry>
        <cylinder radius="0.023" length="0.003" />
        </geometry>
      <material name="blue_coated_glass">
        <color rgba="0.025 0.07 0.105 0.78" />
        </material>
      </visual>
    <visual name="lens_index">
      <origin xyz="0.025 0 0.031" rpy="0 0 0" />
      <geometry>
        <box size="0.014 0.004 0.0022" />
        </geometry>
      <material name="white_print">
        <color rgba="0.88 0.88 0.82 1" />
        </material>
      </visual>
    <collision name="barrel_shell">
      <origin xyz="0.027 0 0" rpy="0 1.5708 0" />
      <geometry>
        <cylinder radius="0.027" length="0.054" />
        </geometry>
      </collision>
    <collision name="grip_ring">
      <origin xyz="0.02 0 0" rpy="0 1.5708 0" />
      <geometry>
        <cylinder radius="0.03" length="0.024" />
        </geometry>
      </collision>
    <collision name="front_rim">
      <origin xyz="0.05 0 0" rpy="0 1.5708 0" />
      <geometry>
        <cylinder radius="0.032" length="0.01" />
        </geometry>
      </collision>
    <collision name="front_glass">
      <origin xyz="0.0565 0 0" rpy="0 1.5708 0" />
      <geometry>
        <cylinder radius="0.023" length="0.003" />
        </geometry>
      </collision>
    <collision name="lens_index">
      <origin xyz="0.025 0 0.031" rpy="0 0 0" />
      <geometry>
        <box size="0.014 0.004 0.0022" />
        </geometry>
      </collision>
    </link>
  <link name="display_panel">
    <visual name="panel_case">
      <origin xyz="0.052 -0.008 0" rpy="0 0 0" />
      <geometry>
        <box size="0.096 0.008 0.06" />
        </geometry>
      <material name="dark_plastic">
        <color rgba="0.015 0.016 0.018 1" />
        </material>
      </visual>
    <visual name="screen_glass">
      <origin xyz="0.057 -0.0129 0" rpy="0 0 0" />
      <geometry>
        <box size="0.078 0.0018 0.044" />
        </geometry>
      <material name="dark_lcd_glass">
        <color rgba="0.01 0.025 0.045 1" />
        </material>
      </visual>
    <visual name="panel_hinge_leaf">
      <origin xyz="0.004 -0.006 0" rpy="0 0 0" />
      <geometry>
        <box size="0.01 0.006 0.06" />
        </geometry>
      <material name="dark_plastic">
        <color rgba="0.015 0.016 0.018 1" />
        </material>
      </visual>
    <visual name="panel_hinge_knuckle">
      <geometry>
        <cylinder radius="0.0035" length="0.034" />
        </geometry>
      <material name="brushed_dark_silver">
        <color rgba="0.45 0.47 0.48 1" />
        </material>
      </visual>
    <collision name="panel_case">
      <origin xyz="0.052 -0.008 0" rpy="0 0 0" />
      <geometry>
        <box size="0.096 0.008 0.06" />
        </geometry>
      </collision>
    <collision name="screen_glass">
      <origin xyz="0.057 -0.0129 0" rpy="0 0 0" />
      <geometry>
        <box size="0.078 0.0018 0.044" />
        </geometry>
      </collision>
    <collision name="panel_hinge_leaf">
      <origin xyz="0.004 -0.006 0" rpy="0 0 0" />
      <geometry>
        <box size="0.01 0.006 0.06" />
        </geometry>
      </collision>
    <collision name="panel_hinge_knuckle">
      <geometry>
        <cylinder radius="0.0035" length="0.034" />
        </geometry>
      </collision>
    </link>
  <joint name="body_to_lens" type="continuous">
    <origin xyz="0.097 0 0" rpy="0 0 0" />
    <parent link="body" />
    <child link="lens_barrel" />
    <axis xyz="1 0 0" />
    <limit effort="0.4" velocity="6" />
    </joint>
  <joint name="body_to_display" type="revolute">
    <origin xyz="-0.062 -0.041 0" rpy="0 0 0" />
    <parent link="body" />
    <child link="display_panel" />
    <axis xyz="0 0 -1" />
    <limit effort="0.8" velocity="2" lower="0" upper="1.75" />
    </joint>
  </robot>
