<robot name="top_freezer_refrigerator">
  <material name="painted_case">
    <color rgba="0.82 0.84 0.84 1" />
    </material>
  <material name="brushed_stainless">
    <color rgba="0.7 0.73 0.74 1" />
    </material>
  <material name="dark_liner">
    <color rgba="0.1 0.11 0.12 1" />
    </material>
  <material name="white_liner">
    <color rgba="0.9 0.92 0.92 1" />
    </material>
  <material name="black_rubber">
    <color rgba="0.03 0.035 0.04 1" />
    </material>
  <material name="handle_metal">
    <color rgba="0.56 0.58 0.59 1" />
    </material>
  <link name="cabinet">
    <visual name="hinge_side_wall">
      <origin xyz="-0.3775 0 0.875" rpy="0 0 0" />
      <geometry>
        <box size="0.045 0.68 1.75" />
        </geometry>
      <material name="painted_case">
        <color rgba="0.82 0.84 0.84 1" />
        </material>
      </visual>
    <visual name="opening_side_wall">
      <origin xyz="0.3775 0 0.875" rpy="0 0 0" />
      <geometry>
        <box size="0.045 0.68 1.75" />
        </geometry>
      <material name="painted_case">
        <color rgba="0.82 0.84 0.84 1" />
        </material>
      </visual>
    <visual name="back_wall">
      <origin xyz="0 0.3175 0.875" rpy="0 0 0" />
      <geometry>
        <box size="0.8 0.045 1.75" />
        </geometry>
      <material name="painted_case">
        <color rgba="0.82 0.84 0.84 1" />
        </material>
      </visual>
    <visual name="top_cap">
      <origin xyz="0 0 1.7275" rpy="0 0 0" />
      <geometry>
        <box size="0.8 0.68 0.045" />
        </geometry>
      <material name="painted_case">
        <color rgba="0.82 0.84 0.84 1" />
        </material>
      </visual>
    <visual name="bottom_cap">
      <origin xyz="0 0 0.0225" rpy="0 0 0" />
      <geometry>
        <box size="0.8 0.68 0.045" />
        </geometry>
      <material name="painted_case">
        <color rgba="0.82 0.84 0.84 1" />
        </material>
      </visual>
    <visual name="center_divider">
      <origin xyz="0 0 1.205" rpy="0 0 0" />
      <geometry>
        <box size="0.8 0.68 0.035" />
        </geometry>
      <material name="painted_case">
        <color rgba="0.82 0.84 0.84 1" />
        </material>
      </visual>
    <visual name="food_liner_back">
      <origin xyz="0 0.289 0.625" rpy="0 0 0" />
      <geometry>
        <box size="0.7 0.018 1.05" />
        </geometry>
      <material name="white_liner">
        <color rgba="0.9 0.92 0.92 1" />
        </material>
      </visual>
    <visual name="freezer_liner_back">
      <origin xyz="0 0.289 1.465" rpy="0 0 0" />
      <geometry>
        <box size="0.7 0.018 0.43" />
        </geometry>
      <material name="white_liner">
        <color rgba="0.9 0.92 0.92 1" />
        </material>
      </visual>
    <visual name="food_shelf_0">
      <origin xyz="0 0.02 0.48" rpy="0 0 0" />
      <geometry>
        <box size="0.71 0.58 0.018" />
        </geometry>
      <material name="white_liner">
        <color rgba="0.9 0.92 0.92 1" />
        </material>
      </visual>
    <visual name="food_shelf_1">
      <origin xyz="0 0.02 0.78" rpy="0 0 0" />
      <geometry>
        <box size="0.71 0.58 0.018" />
        </geometry>
      <material name="white_liner">
        <color rgba="0.9 0.92 0.92 1" />
        </material>
      </visual>
    <visual name="food_shelf_2">
      <origin xyz="0 0.02 1.03" rpy="0 0 0" />
      <geometry>
        <box size="0.71 0.58 0.018" />
        </geometry>
      <material name="white_liner">
        <color rgba="0.9 0.92 0.92 1" />
        </material>
      </visual>
    <visual name="toe_recess">
      <origin xyz="0 -0.342 0.045" rpy="0 0 0" />
      <geometry>
        <box size="0.68 0.02 0.06" />
        </geometry>
      <material name="dark_liner">
        <color rgba="0.1 0.11 0.12 1" />
        </material>
      </visual>
    <visual name="toe_grille_slat_0">
      <origin xyz="0 -0.35 0.028" rpy="0 0 0" />
      <geometry>
        <box size="0.58 0.012 0.006" />
        </geometry>
      <material name="black_rubber">
        <color rgba="0.03 0.035 0.04 1" />
        </material>
      </visual>
    <visual name="toe_grille_slat_1">
      <origin xyz="0 -0.35 0.046" rpy="0 0 0" />
      <geometry>
        <box size="0.58 0.012 0.006" />
        </geometry>
      <material name="black_rubber">
        <color rgba="0.03 0.035 0.04 1" />
        </material>
      </visual>
    <visual name="toe_grille_slat_2">
      <origin xyz="0 -0.35 0.064" rpy="0 0 0" />
      <geometry>
        <box size="0.58 0.012 0.006" />
        </geometry>
      <material name="black_rubber">
        <color rgba="0.03 0.035 0.04 1" />
        </material>
      </visual>
    <visual name="hinge_plate_0">
      <origin xyz="-0.42 -0.352 0.3" rpy="0 0 0" />
      <geometry>
        <box size="0.05 0.026 0.105" />
        </geometry>
      <material name="handle_metal">
        <color rgba="0.56 0.58 0.59 1" />
        </material>
      </visual>
    <visual name="hinge_plate_1">
      <origin xyz="-0.42 -0.352 0.94" rpy="0 0 0" />
      <geometry>
        <box size="0.05 0.026 0.105" />
        </geometry>
      <material name="handle_metal">
        <color rgba="0.56 0.58 0.59 1" />
        </material>
      </visual>
    <visual name="hinge_plate_2">
      <origin xyz="-0.42 -0.352 1.37" rpy="0 0 0" />
      <geometry>
        <box size="0.05 0.026 0.105" />
        </geometry>
      <material name="handle_metal">
        <color rgba="0.56 0.58 0.59 1" />
        </material>
      </visual>
    <visual name="hinge_plate_3">
      <origin xyz="-0.42 -0.352 1.63" rpy="0 0 0" />
      <geometry>
        <box size="0.05 0.026 0.105" />
        </geometry>
      <material name="handle_metal">
        <color rgba="0.56 0.58 0.59 1" />
        </material>
      </visual>
    <collision name="hinge_side_wall">
      <origin xyz="-0.3775 0 0.875" rpy="0 0 0" />
      <geometry>
        <box size="0.045 0.68 1.75" />
        </geometry>
      </collision>
    <collision name="opening_side_wall">
      <origin xyz="0.3775 0 0.875" rpy="0 0 0" />
      <geometry>
        <box size="0.045 0.68 1.75" />
        </geometry>
      </collision>
    <collision name="back_wall">
      <origin xyz="0 0.3175 0.875" rpy="0 0 0" />
      <geometry>
        <box size="0.8 0.045 1.75" />
        </geometry>
      </collision>
    <collision name="top_cap">
      <origin xyz="0 0 1.7275" rpy="0 0 0" />
      <geometry>
        <box size="0.8 0.68 0.045" />
        </geometry>
      </collision>
    <collision name="bottom_cap">
      <origin xyz="0 0 0.0225" rpy="0 0 0" />
      <geometry>
        <box size="0.8 0.68 0.045" />
        </geometry>
      </collision>
    <collision name="center_divider">
      <origin xyz="0 0 1.205" rpy="0 0 0" />
      <geometry>
        <box size="0.8 0.68 0.035" />
        </geometry>
      </collision>
    <collision name="food_liner_back">
      <origin xyz="0 0.289 0.625" rpy="0 0 0" />
      <geometry>
        <box size="0.7 0.018 1.05" />
        </geometry>
      </collision>
    <collision name="freezer_liner_back">
      <origin xyz="0 0.289 1.465" rpy="0 0 0" />
      <geometry>
        <box size="0.7 0.018 0.43" />
        </geometry>
      </collision>
    <collision name="food_shelf_0">
      <origin xyz="0 0.02 0.48" rpy="0 0 0" />
      <geometry>
        <box size="0.71 0.58 0.018" />
        </geometry>
      </collision>
    <collision name="food_shelf_1">
      <origin xyz="0 0.02 0.78" rpy="0 0 0" />
      <geometry>
        <box size="0.71 0.58 0.018" />
        </geometry>
      </collision>
    <collision name="food_shelf_2">
      <origin xyz="0 0.02 1.03" rpy="0 0 0" />
      <geometry>
        <box size="0.71 0.58 0.018" />
        </geometry>
      </collision>
    <collision name="toe_recess">
      <origin xyz="0 -0.342 0.045" rpy="0 0 0" />
      <geometry>
        <box size="0.68 0.02 0.06" />
        </geometry>
      </collision>
    <collision name="toe_grille_slat_0">
      <origin xyz="0 -0.35 0.028" rpy="0 0 0" />
      <geometry>
        <box size="0.58 0.012 0.006" />
        </geometry>
      </collision>
    <collision name="toe_grille_slat_1">
      <origin xyz="0 -0.35 0.046" rpy="0 0 0" />
      <geometry>
        <box size="0.58 0.012 0.006" />
        </geometry>
      </collision>
    <collision name="toe_grille_slat_2">
      <origin xyz="0 -0.35 0.064" rpy="0 0 0" />
      <geometry>
        <box size="0.58 0.012 0.006" />
        </geometry>
      </collision>
    <collision name="hinge_plate_0">
      <origin xyz="-0.42 -0.352 0.3" rpy="0 0 0" />
      <geometry>
        <box size="0.05 0.026 0.105" />
        </geometry>
      </collision>
    <collision name="hinge_plate_1">
      <origin xyz="-0.42 -0.352 0.94" rpy="0 0 0" />
      <geometry>
        <box size="0.05 0.026 0.105" />
        </geometry>
      </collision>
    <collision name="hinge_plate_2">
      <origin xyz="-0.42 -0.352 1.37" rpy="0 0 0" />
      <geometry>
        <box size="0.05 0.026 0.105" />
        </geometry>
      </collision>
    <collision name="hinge_plate_3">
      <origin xyz="-0.42 -0.352 1.63" rpy="0 0 0" />
      <geometry>
        <box size="0.05 0.026 0.105" />
        </geometry>
      </collision>
    </link>
  <link name="food_door">
    <visual name="door_panel">
      <origin xyz="0.385 0 0.5375" rpy="0 0 0" />
      <geometry>
        <mesh filename="assets/meshes/food_door_panel_mesh.obj" />
        </geometry>
      <material name="brushed_stainless">
        <color rgba="0.7 0.73 0.74 1" />
        </material>
      </visual>
    <visual name="magnetic_gasket">
      <origin xyz="0.742 0.0385 0.5375" rpy="0 0 0" />
      <geometry>
        <box size="0.018 0.01 1.015" />
        </geometry>
      <material name="black_rubber">
        <color rgba="0.03 0.035 0.04 1" />
        </material>
      </visual>
    <visual name="handle_grip">
      <origin xyz="0.69 -0.071 0.56" rpy="0 0 0" />
      <geometry>
        <box size="0.034 0.034 0.68" />
        </geometry>
      <material name="handle_metal">
        <color rgba="0.56 0.58 0.59 1" />
        </material>
      </visual>
    <visual name="handle_post_0">
      <origin xyz="0.69 -0.046 0.3016" rpy="0 0 0" />
      <geometry>
        <box size="0.052 0.056 0.07" />
        </geometry>
      <material name="handle_metal">
        <color rgba="0.56 0.58 0.59 1" />
        </material>
      </visual>
    <visual name="handle_post_1">
      <origin xyz="0.69 -0.046 0.8184" rpy="0 0 0" />
      <geometry>
        <box size="0.052 0.056 0.07" />
        </geometry>
      <material name="handle_metal">
        <color rgba="0.56 0.58 0.59 1" />
        </material>
      </visual>
    <visual name="hinge_barrel_0">
      <origin xyz="0 0 0.22" rpy="0 0 0" />
      <geometry>
        <cylinder radius="0.02" length="0.17" />
        </geometry>
      <material name="handle_metal">
        <color rgba="0.56 0.58 0.59 1" />
        </material>
      </visual>
    <visual name="hinge_barrel_1">
      <origin xyz="0 0 0.84" rpy="0 0 0" />
      <geometry>
        <cylinder radius="0.02" length="0.18" />
        </geometry>
      <material name="handle_metal">
        <color rgba="0.56 0.58 0.59 1" />
        </material>
      </visual>
    <collision name="door_panel">
      <origin xyz="0.385 0 0.5375" rpy="0 0 0" />
      <geometry>
        <mesh filename="assets/meshes/food_door_panel_mesh.obj" />
        </geometry>
      </collision>
    <collision name="magnetic_gasket">
      <origin xyz="0.742 0.0385 0.5375" rpy="0 0 0" />
      <geometry>
        <box size="0.018 0.01 1.015" />
        </geometry>
      </collision>
    <collision name="handle_grip">
      <origin xyz="0.69 -0.071 0.56" rpy="0 0 0" />
      <geometry>
        <box size="0.034 0.034 0.68" />
        </geometry>
      </collision>
    <collision name="handle_post_0">
      <origin xyz="0.69 -0.046 0.3016" rpy="0 0 0" />
      <geometry>
        <box size="0.052 0.056 0.07" />
        </geometry>
      </collision>
    <collision name="handle_post_1">
      <origin xyz="0.69 -0.046 0.8184" rpy="0 0 0" />
      <geometry>
        <box size="0.052 0.056 0.07" />
        </geometry>
      </collision>
    <collision name="hinge_barrel_0">
      <origin xyz="0 0 0.22" rpy="0 0 0" />
      <geometry>
        <cylinder radius="0.02" length="0.17" />
        </geometry>
      </collision>
    <collision name="hinge_barrel_1">
      <origin xyz="0 0 0.84" rpy="0 0 0" />
      <geometry>
        <cylinder radius="0.02" length="0.18" />
        </geometry>
      </collision>
    </link>
  <link name="freezer_door">
    <visual name="door_panel">
      <origin xyz="0.385 0 0.2275" rpy="0 0 0" />
      <geometry>
        <mesh filename="assets/meshes/freezer_door_panel_mesh.obj" />
        </geometry>
      <material name="brushed_stainless">
        <color rgba="0.7 0.73 0.74 1" />
        </material>
      </visual>
    <visual name="magnetic_gasket">
      <origin xyz="0.742 0.0385 0.2275" rpy="0 0 0" />
      <geometry>
        <box size="0.018 0.01 0.395" />
        </geometry>
      <material name="black_rubber">
        <color rgba="0.03 0.035 0.04 1" />
        </material>
      </visual>
    <visual name="handle_grip">
      <origin xyz="0.69 -0.071 0.225" rpy="0 0 0" />
      <geometry>
        <box size="0.034 0.034 0.265" />
        </geometry>
      <material name="handle_metal">
        <color rgba="0.56 0.58 0.59 1" />
        </material>
      </visual>
    <visual name="handle_post_0">
      <origin xyz="0.69 -0.046 0.1243" rpy="0 0 0" />
      <geometry>
        <box size="0.052 0.056 0.07" />
        </geometry>
      <material name="handle_metal">
        <color rgba="0.56 0.58 0.59 1" />
        </material>
      </visual>
    <visual name="handle_post_1">
      <origin xyz="0.69 -0.046 0.3257" rpy="0 0 0" />
      <geometry>
        <box size="0.052 0.056 0.07" />
        </geometry>
      <material name="handle_metal">
        <color rgba="0.56 0.58 0.59 1" />
        </material>
      </visual>
    <visual name="hinge_barrel_0">
      <origin xyz="0 0 0.115" rpy="0 0 0" />
      <geometry>
        <cylinder radius="0.02" length="0.105" />
        </geometry>
      <material name="handle_metal">
        <color rgba="0.56 0.58 0.59 1" />
        </material>
      </visual>
    <visual name="hinge_barrel_1">
      <origin xyz="0 0 0.345" rpy="0 0 0" />
      <geometry>
        <cylinder radius="0.02" length="0.105" />
        </geometry>
      <material name="handle_metal">
        <color rgba="0.56 0.58 0.59 1" />
        </material>
      </visual>
    <collision name="door_panel">
      <origin xyz="0.385 0 0.2275" rpy="0 0 0" />
      <geometry>
        <mesh filename="assets/meshes/freezer_door_panel_mesh.obj" />
        </geometry>
      </collision>
    <collision name="magnetic_gasket">
      <origin xyz="0.742 0.0385 0.2275" rpy="0 0 0" />
      <geometry>
        <box size="0.018 0.01 0.395" />
        </geometry>
      </collision>
    <collision name="handle_grip">
      <origin xyz="0.69 -0.071 0.225" rpy="0 0 0" />
      <geometry>
        <box size="0.034 0.034 0.265" />
        </geometry>
      </collision>
    <collision name="handle_post_0">
      <origin xyz="0.69 -0.046 0.1243" rpy="0 0 0" />
      <geometry>
        <box size="0.052 0.056 0.07" />
        </geometry>
      </collision>
    <collision name="handle_post_1">
      <origin xyz="0.69 -0.046 0.3257" rpy="0 0 0" />
      <geometry>
        <box size="0.052 0.056 0.07" />
        </geometry>
      </collision>
    <collision name="hinge_barrel_0">
      <origin xyz="0 0 0.115" rpy="0 0 0" />
      <geometry>
        <cylinder radius="0.02" length="0.105" />
        </geometry>
      </collision>
    <collision name="hinge_barrel_1">
      <origin xyz="0 0 0.345" rpy="0 0 0" />
      <geometry>
        <cylinder radius="0.02" length="0.105" />
        </geometry>
      </collision>
    </link>
  <joint name="cabinet_to_food_door" type="revolute">
    <origin xyz="-0.4 -0.385 0.095" rpy="0 0 0" />
    <parent link="cabinet" />
    <child link="food_door" />
    <axis xyz="0 0 -1" />
    <limit effort="45" velocity="1.6" lower="0" upper="2.05" />
    </joint>
  <joint name="cabinet_to_freezer_door" type="revolute">
    <origin xyz="-0.4 -0.385 1.235" rpy="0 0 0" />
    <parent link="cabinet" />
    <child link="freezer_door" />
    <axis xyz="0 0 -1" />
    <limit effort="45" velocity="1.6" lower="0" upper="2.05" />
    </joint>
  </robot>
