<robot name="document_management_scanner">
  <link name="body">
    <visual name="chassis">
      <origin xyz="0 0 0.05" rpy="0 0 0" />
      <geometry>
        <box size="0.8 0.45 0.1" />
        </geometry>
      <material name="warm_gray_plastic">
        <color rgba="0.7 0.72 0.72 1" />
        </material>
      </visual>
    <visual name="scanner_bed_bezel">
      <origin xyz="-0.075 -0.005 0.102" rpy="0 0 0" />
      <geometry>
        <box size="0.62 0.38 0.004" />
        </geometry>
      <material name="dark_gray_plastic">
        <color rgba="0.1 0.11 0.12 1" />
        </material>
      </visual>
    <visual name="glass">
      <origin xyz="-0.075 -0.02 0.1035" rpy="0 0 0" />
      <geometry>
        <box size="0.53 0.3 0.003" />
        </geometry>
      <material name="slightly_blue_scanner_glass">
        <color rgba="0.62 0.82 0.94 0.55" />
        </material>
      </visual>
    <visual name="control_panel">
      <origin xyz="0.305 -0.16 0.103" rpy="0 0 0" />
      <geometry>
        <box size="0.16 0.085 0.006" />
        </geometry>
      <material name="dark_gray_plastic">
        <color rgba="0.1 0.11 0.12 1" />
        </material>
      </visual>
    <visual name="feed_slot_panel">
      <origin xyz="-0.03 -0.226 0.075" rpy="0 0 0" />
      <geometry>
        <box size="0.56 0.004 0.02" />
        </geometry>
      <material name="black_rubber">
        <color rgba="0.015 0.015 0.018 1" />
        </material>
      </visual>
    <visual name="front_tray_hinge_mount">
      <origin xyz="-0.03 -0.228 0.089" rpy="0 0 0" />
      <geometry>
        <box size="0.56 0.01 0.018" />
        </geometry>
      <material name="dark_gray_plastic">
        <color rgba="0.1 0.11 0.12 1" />
        </material>
      </visual>
    <visual name="rear_hinge_leaf_0">
      <origin xyz="-0.255 0.211 0.1015" rpy="0 0 0" />
      <geometry>
        <box size="0.12 0.068 0.006" />
        </geometry>
      <material name="brushed_hinge_metal">
        <color rgba="0.55 0.56 0.58 1" />
        </material>
      </visual>
    <visual name="rear_hinge_bracket_0">
      <origin xyz="-0.255 0.247 0.1075" rpy="0 0 0" />
      <geometry>
        <box size="0.07 0.012 0.015" />
        </geometry>
      <material name="brushed_hinge_metal">
        <color rgba="0.55 0.56 0.58 1" />
        </material>
      </visual>
    <visual name="rear_hinge_leaf_1">
      <origin xyz="0.105 0.211 0.1015" rpy="0 0 0" />
      <geometry>
        <box size="0.12 0.068 0.006" />
        </geometry>
      <material name="brushed_hinge_metal">
        <color rgba="0.55 0.56 0.58 1" />
        </material>
      </visual>
    <visual name="rear_hinge_bracket_1">
      <origin xyz="0.105 0.247 0.1075" rpy="0 0 0" />
      <geometry>
        <box size="0.07 0.012 0.015" />
        </geometry>
      <material name="brushed_hinge_metal">
        <color rgba="0.55 0.56 0.58 1" />
        </material>
      </visual>
    <visual name="rubber_foot_0">
      <origin xyz="-0.315 0.17 0.007" rpy="0 0 0" />
      <geometry>
        <box size="0.08 0.06 0.014" />
        </geometry>
      <material name="black_rubber">
        <color rgba="0.015 0.015 0.018 1" />
        </material>
      </visual>
    <visual name="rubber_foot_2">
      <origin xyz="-0.315 -0.17 0.007" rpy="0 0 0" />
      <geometry>
        <box size="0.08 0.06 0.014" />
        </geometry>
      <material name="black_rubber">
        <color rgba="0.015 0.015 0.018 1" />
        </material>
      </visual>
    <visual name="rubber_foot_1">
      <origin xyz="0.315 0.17 0.007" rpy="0 0 0" />
      <geometry>
        <box size="0.08 0.06 0.014" />
        </geometry>
      <material name="black_rubber">
        <color rgba="0.015 0.015 0.018 1" />
        </material>
      </visual>
    <visual name="rubber_foot_3">
      <origin xyz="0.315 -0.17 0.007" rpy="0 0 0" />
      <geometry>
        <box size="0.08 0.06 0.014" />
        </geometry>
      <material name="black_rubber">
        <color rgba="0.015 0.015 0.018 1" />
        </material>
      </visual>
    <collision name="chassis">
      <origin xyz="0 0 0.05" rpy="0 0 0" />
      <geometry>
        <box size="0.8 0.45 0.1" />
        </geometry>
      </collision>
    <collision name="scanner_bed_bezel">
      <origin xyz="-0.075 -0.005 0.102" rpy="0 0 0" />
      <geometry>
        <box size="0.62 0.38 0.004" />
        </geometry>
      </collision>
    <collision name="glass">
      <origin xyz="-0.075 -0.02 0.1035" rpy="0 0 0" />
      <geometry>
        <box size="0.53 0.3 0.003" />
        </geometry>
      </collision>
    <collision name="control_panel">
      <origin xyz="0.305 -0.16 0.103" rpy="0 0 0" />
      <geometry>
        <box size="0.16 0.085 0.006" />
        </geometry>
      </collision>
    <collision name="feed_slot_panel">
      <origin xyz="-0.03 -0.226 0.075" rpy="0 0 0" />
      <geometry>
        <box size="0.56 0.004 0.02" />
        </geometry>
      </collision>
    <collision name="front_tray_hinge_mount">
      <origin xyz="-0.03 -0.228 0.089" rpy="0 0 0" />
      <geometry>
        <box size="0.56 0.01 0.018" />
        </geometry>
      </collision>
    <collision name="rear_hinge_leaf_0">
      <origin xyz="-0.255 0.211 0.1015" rpy="0 0 0" />
      <geometry>
        <box size="0.12 0.068 0.006" />
        </geometry>
      </collision>
    <collision name="rear_hinge_bracket_0">
      <origin xyz="-0.255 0.247 0.1075" rpy="0 0 0" />
      <geometry>
        <box size="0.07 0.012 0.015" />
        </geometry>
      </collision>
    <collision name="rear_hinge_leaf_1">
      <origin xyz="0.105 0.211 0.1015" rpy="0 0 0" />
      <geometry>
        <box size="0.12 0.068 0.006" />
        </geometry>
      </collision>
    <collision name="rear_hinge_bracket_1">
      <origin xyz="0.105 0.247 0.1075" rpy="0 0 0" />
      <geometry>
        <box size="0.07 0.012 0.015" />
        </geometry>
      </collision>
    <collision name="rubber_foot_0">
      <origin xyz="-0.315 0.17 0.007" rpy="0 0 0" />
      <geometry>
        <box size="0.08 0.06 0.014" />
        </geometry>
      </collision>
    <collision name="rubber_foot_2">
      <origin xyz="-0.315 -0.17 0.007" rpy="0 0 0" />
      <geometry>
        <box size="0.08 0.06 0.014" />
        </geometry>
      </collision>
    <collision name="rubber_foot_1">
      <origin xyz="0.315 0.17 0.007" rpy="0 0 0" />
      <geometry>
        <box size="0.08 0.06 0.014" />
        </geometry>
      </collision>
    <collision name="rubber_foot_3">
      <origin xyz="0.315 -0.17 0.007" rpy="0 0 0" />
      <geometry>
        <box size="0.08 0.06 0.014" />
        </geometry>
      </collision>
    </link>
  <link name="lid">
    <visual name="lid_shell">
      <origin xyz="-0.075 -0.218 0" rpy="0 0 0" />
      <geometry>
        <box size="0.62 0.43 0.026" />
        </geometry>
      <material name="warm_gray_plastic">
        <color rgba="0.7 0.72 0.72 1" />
        </material>
      </visual>
    <visual name="reflective_panel">
      <origin xyz="-0.075 -0.218 -0.014" rpy="0 0 0" />
      <geometry>
        <box size="0.53 0.34 0.002" />
        </geometry>
      <material name="reflective_white_lid_liner">
        <color rgba="0.93 0.95 0.93 1" />
        </material>
      </visual>
    <visual name="rear_lid_rib">
      <origin xyz="-0.075 -0.01 -0.001" rpy="0 0 0" />
      <geometry>
        <box size="0.62 0.014 0.03" />
        </geometry>
      <material name="dark_gray_plastic">
        <color rgba="0.1 0.11 0.12 1" />
        </material>
      </visual>
    <visual name="rear_barrel_0">
      <origin xyz="-0.255 0 0" rpy="0 1.5708 0" />
      <geometry>
        <cylinder radius="0.011" length="0.115" />
        </geometry>
      <material name="brushed_hinge_metal">
        <color rgba="0.55 0.56 0.58 1" />
        </material>
      </visual>
    <visual name="lid_hinge_leaf_0">
      <origin xyz="-0.255 -0.014 -0.003" rpy="0 0 0" />
      <geometry>
        <box size="0.08 0.02 0.01" />
        </geometry>
      <material name="brushed_hinge_metal">
        <color rgba="0.55 0.56 0.58 1" />
        </material>
      </visual>
    <visual name="rear_barrel_1">
      <origin xyz="0.105 0 0" rpy="0 1.5708 0" />
      <geometry>
        <cylinder radius="0.011" length="0.115" />
        </geometry>
      <material name="brushed_hinge_metal">
        <color rgba="0.55 0.56 0.58 1" />
        </material>
      </visual>
    <visual name="lid_hinge_leaf_1">
      <origin xyz="0.105 -0.014 -0.003" rpy="0 0 0" />
      <geometry>
        <box size="0.08 0.02 0.01" />
        </geometry>
      <material name="brushed_hinge_metal">
        <color rgba="0.55 0.56 0.58 1" />
        </material>
      </visual>
    <collision name="lid_shell">
      <origin xyz="-0.075 -0.218 0" rpy="0 0 0" />
      <geometry>
        <box size="0.62 0.43 0.026" />
        </geometry>
      </collision>
    <collision name="reflective_panel">
      <origin xyz="-0.075 -0.218 -0.014" rpy="0 0 0" />
      <geometry>
        <box size="0.53 0.34 0.002" />
        </geometry>
      </collision>
    <collision name="rear_lid_rib">
      <origin xyz="-0.075 -0.01 -0.001" rpy="0 0 0" />
      <geometry>
        <box size="0.62 0.014 0.03" />
        </geometry>
      </collision>
    <collision name="rear_barrel_0">
      <origin xyz="-0.255 0 0" rpy="0 1.5708 0" />
      <geometry>
        <cylinder radius="0.011" length="0.115" />
        </geometry>
      </collision>
    <collision name="lid_hinge_leaf_0">
      <origin xyz="-0.255 -0.014 -0.003" rpy="0 0 0" />
      <geometry>
        <box size="0.08 0.02 0.01" />
        </geometry>
      </collision>
    <collision name="rear_barrel_1">
      <origin xyz="0.105 0 0" rpy="0 1.5708 0" />
      <geometry>
        <cylinder radius="0.011" length="0.115" />
        </geometry>
      </collision>
    <collision name="lid_hinge_leaf_1">
      <origin xyz="0.105 -0.014 -0.003" rpy="0 0 0" />
      <geometry>
        <box size="0.08 0.02 0.01" />
        </geometry>
      </collision>
    </link>
  <link name="feed_tray">
    <visual name="tray_panel">
      <origin xyz="-0.03 -0.16 0.005" rpy="0 0 0" />
      <geometry>
        <box size="0.56 0.3 0.01" />
        </geometry>
      <material name="warm_gray_plastic">
        <color rgba="0.7 0.72 0.72 1" />
        </material>
      </visual>
    <visual name="tray_hinge_barrel">
      <origin xyz="-0.03 0 0" rpy="0 1.5708 0" />
      <geometry>
        <cylinder radius="0.01" length="0.58" />
        </geometry>
      <material name="brushed_hinge_metal">
        <color rgba="0.55 0.56 0.58 1" />
        </material>
      </visual>
    <visual name="paper_guide_0">
      <origin xyz="-0.285 -0.17 0.018" rpy="0 0 0" />
      <geometry>
        <box size="0.014 0.25 0.016" />
        </geometry>
      <material name="dark_gray_plastic">
        <color rgba="0.1 0.11 0.12 1" />
        </material>
      </visual>
    <visual name="paper_guide_1">
      <origin xyz="0.225 -0.17 0.018" rpy="0 0 0" />
      <geometry>
        <box size="0.014 0.25 0.016" />
        </geometry>
      <material name="dark_gray_plastic">
        <color rgba="0.1 0.11 0.12 1" />
        </material>
      </visual>
    <visual name="paper_stop_lip">
      <origin xyz="-0.03 -0.305 0.023" rpy="0 0 0" />
      <geometry>
        <box size="0.54 0.014 0.026" />
        </geometry>
      <material name="dark_gray_plastic">
        <color rgba="0.1 0.11 0.12 1" />
        </material>
      </visual>
    <visual name="paper_entry_marker">
      <origin xyz="-0.03 -0.055 0.015" rpy="0 0 0" />
      <geometry>
        <box size="0.42 0.003 0.01" />
        </geometry>
      <material name="black_rubber">
        <color rgba="0.015 0.015 0.018 1" />
        </material>
      </visual>
    <collision name="tray_panel">
      <origin xyz="-0.03 -0.16 0.005" rpy="0 0 0" />
      <geometry>
        <box size="0.56 0.3 0.01" />
        </geometry>
      </collision>
    <collision name="tray_hinge_barrel">
      <origin xyz="-0.03 0 0" rpy="0 1.5708 0" />
      <geometry>
        <cylinder radius="0.01" length="0.58" />
        </geometry>
      </collision>
    <collision name="paper_guide_0">
      <origin xyz="-0.285 -0.17 0.018" rpy="0 0 0" />
      <geometry>
        <box size="0.014 0.25 0.016" />
        </geometry>
      </collision>
    <collision name="paper_guide_1">
      <origin xyz="0.225 -0.17 0.018" rpy="0 0 0" />
      <geometry>
        <box size="0.014 0.25 0.016" />
        </geometry>
      </collision>
    <collision name="paper_stop_lip">
      <origin xyz="-0.03 -0.305 0.023" rpy="0 0 0" />
      <geometry>
        <box size="0.54 0.014 0.026" />
        </geometry>
      </collision>
    <collision name="paper_entry_marker">
      <origin xyz="-0.03 -0.055 0.015" rpy="0 0 0" />
      <geometry>
        <box size="0.42 0.003 0.01" />
        </geometry>
      </collision>
    </link>
  <link name="start_button">
    <visual name="button_cap">
      <origin xyz="0 0 0.003" rpy="0 0 0" />
      <geometry>
        <box size="0.04 0.03 0.006" />
        </geometry>
      <material name="blue_start_button">
        <color rgba="0.08 0.36 0.78 1" />
        </material>
      </visual>
    <collision name="button_cap">
      <origin xyz="0 0 0.003" rpy="0 0 0" />
      <geometry>
        <box size="0.04 0.03 0.006" />
        </geometry>
      </collision>
    </link>
  <link name="mode_button">
    <visual name="button_cap">
      <origin xyz="0 0 0.0025" rpy="0 0 0" />
      <geometry>
        <box size="0.03 0.026 0.005" />
        </geometry>
      <material name="dark_mode_button">
        <color rgba="0.05 0.05 0.06 1" />
        </material>
      </visual>
    <collision name="button_cap">
      <origin xyz="0 0 0.0025" rpy="0 0 0" />
      <geometry>
        <box size="0.03 0.026 0.005" />
        </geometry>
      </collision>
    </link>
  <joint name="lid_hinge" type="revolute">
    <origin xyz="0 0.24 0.122" rpy="0 0 0" />
    <parent link="body" />
    <child link="lid" />
    <axis xyz="-1 0 0" />
    <limit effort="10" velocity="1.8" lower="0" upper="1.25" />
    </joint>
  <joint name="tray_hinge" type="revolute">
    <origin xyz="0 -0.241 0.095" rpy="0 0 0" />
    <parent link="body" />
    <child link="feed_tray" />
    <axis xyz="-1 0 0" />
    <limit effort="4" velocity="2" lower="-1.35" upper="0" />
    </joint>
  <joint name="start_button_press" type="prismatic">
    <origin xyz="0.275 -0.16 0.106" rpy="0 0 0" />
    <parent link="body" />
    <child link="start_button" />
    <axis xyz="0 0 -1" />
    <limit effort="1" velocity="0.05" lower="0" upper="0.004" />
    </joint>
  <joint name="mode_button_press" type="prismatic">
    <origin xyz="0.34 -0.16 0.106" rpy="0 0 0" />
    <parent link="body" />
    <child link="mode_button" />
    <axis xyz="0 0 -1" />
    <limit effort="0.8" velocity="0.05" lower="0" upper="0.003" />
    </joint>
  </robot>
