<robot name="compact_knee_scooter">
  <material name="powder_coated_black">
    <color rgba="0.015 0.017 0.018 1" />
    </material>
  <material name="brushed_aluminum">
    <color rgba="0.62 0.64 0.62 1" />
    </material>
  <material name="dark_hardware">
    <color rgba="0.05 0.05 0.055 1" />
    </material>
  <material name="soft_black_rubber">
    <color rgba="0.004 0.004 0.004 1" />
    </material>
  <material name="blue_vinyl_pad">
    <color rgba="0.02 0.1 0.28 1" />
    </material>
  <material name="black_composite_lever">
    <color rgba="0.01 0.012 0.013 1" />
    </material>
  <link name="central_frame">
    <visual name="main_tube">
      <origin xyz="0.03 0 0.28" rpy="0 1.5708 0" />
      <geometry>
        <cylinder radius="0.024" length="0.68" />
        </geometry>
      <material name="powder_coated_black">
        <color rgba="0.015 0.017 0.018 1" />
        </material>
      </visual>
    <visual name="rear_cross_tube">
      <origin xyz="-0.3 0 0.13" rpy="1.5708 0 0" />
      <geometry>
        <cylinder radius="0.018" length="0.42" />
        </geometry>
      <material name="powder_coated_black">
        <color rgba="0.015 0.017 0.018 1" />
        </material>
      </visual>
    <visual name="rear_down_post">
      <origin xyz="-0.3 0 0.19" rpy="0 0 0" />
      <geometry>
        <cylinder radius="0.018" length="0.22" />
        </geometry>
      <material name="powder_coated_black">
        <color rgba="0.015 0.017 0.018 1" />
        </material>
      </visual>
    <visual name="pad_post">
      <origin xyz="-0.08 0 0.39" rpy="0 0 0" />
      <geometry>
        <cylinder radius="0.022" length="0.22" />
        </geometry>
      <material name="powder_coated_black">
        <color rgba="0.015 0.017 0.018 1" />
        </material>
      </visual>
    <visual name="pad_mount_plate">
      <origin xyz="-0.08 0 0.49" rpy="0 0 0" />
      <geometry>
        <box size="0.22 0.055 0.02" />
        </geometry>
      <material name="brushed_aluminum">
        <color rgba="0.62 0.64 0.62 1" />
        </material>
      </visual>
    <visual name="rear_dropout_0">
      <origin xyz="-0.3 0.21 0.095" rpy="0 0 0" />
      <geometry>
        <box size="0.07 0.03 0.125" />
        </geometry>
      <material name="powder_coated_black">
        <color rgba="0.015 0.017 0.018 1" />
        </material>
      </visual>
    <visual name="rear_axle_pin_0">
      <origin xyz="-0.3 0.2213 0.075" rpy="1.5708 0 0" />
      <geometry>
        <cylinder radius="0.01" length="0.018" />
        </geometry>
      <material name="dark_hardware">
        <color rgba="0.05 0.05 0.055 1" />
        </material>
      </visual>
    <visual name="rear_dropout_1">
      <origin xyz="-0.3 -0.21 0.095" rpy="0 0 0" />
      <geometry>
        <box size="0.07 0.03 0.125" />
        </geometry>
      <material name="powder_coated_black">
        <color rgba="0.015 0.017 0.018 1" />
        </material>
      </visual>
    <visual name="rear_axle_pin_1">
      <origin xyz="-0.3 -0.2213 0.075" rpy="1.5708 0 0" />
      <geometry>
        <cylinder radius="0.01" length="0.018" />
        </geometry>
      <material name="dark_hardware">
        <color rgba="0.05 0.05 0.055 1" />
        </material>
      </visual>
    <visual name="head_bridge">
      <origin xyz="0.375 0 0.29" rpy="0 0 0" />
      <geometry>
        <box size="0.032 0.032 0.04" />
        </geometry>
      <material name="powder_coated_black">
        <color rgba="0.015 0.017 0.018 1" />
        </material>
      </visual>
    <visual name="head_front_plate">
      <origin xyz="0.386 0 0.36" rpy="0 0 0" />
      <geometry>
        <box size="0.012 0.086 0.16" />
        </geometry>
      <material name="powder_coated_black">
        <color rgba="0.015 0.017 0.018 1" />
        </material>
      </visual>
    <visual name="head_rear_plate">
      <origin xyz="0.474 0 0.36" rpy="0 0 0" />
      <geometry>
        <box size="0.012 0.086 0.16" />
        </geometry>
      <material name="powder_coated_black">
        <color rgba="0.015 0.017 0.018 1" />
        </material>
      </visual>
    <visual name="head_side_plate_0">
      <origin xyz="0.43 0.044 0.36" rpy="0 0 0" />
      <geometry>
        <box size="0.104 0.012 0.16" />
        </geometry>
      <material name="powder_coated_black">
        <color rgba="0.015 0.017 0.018 1" />
        </material>
      </visual>
    <visual name="head_side_plate_1">
      <origin xyz="0.43 -0.044 0.36" rpy="0 0 0" />
      <geometry>
        <box size="0.104 0.012 0.16" />
        </geometry>
      <material name="powder_coated_black">
        <color rgba="0.015 0.017 0.018 1" />
        </material>
      </visual>
    <collision name="main_tube">
      <origin xyz="0.03 0 0.28" rpy="0 1.5708 0" />
      <geometry>
        <cylinder radius="0.024" length="0.68" />
        </geometry>
      </collision>
    <collision name="rear_cross_tube">
      <origin xyz="-0.3 0 0.13" rpy="1.5708 0 0" />
      <geometry>
        <cylinder radius="0.018" length="0.42" />
        </geometry>
      </collision>
    <collision name="rear_down_post">
      <origin xyz="-0.3 0 0.19" rpy="0 0 0" />
      <geometry>
        <cylinder radius="0.018" length="0.22" />
        </geometry>
      </collision>
    <collision name="pad_post">
      <origin xyz="-0.08 0 0.39" rpy="0 0 0" />
      <geometry>
        <cylinder radius="0.022" length="0.22" />
        </geometry>
      </collision>
    <collision name="pad_mount_plate">
      <origin xyz="-0.08 0 0.49" rpy="0 0 0" />
      <geometry>
        <box size="0.22 0.055 0.02" />
        </geometry>
      </collision>
    <collision name="rear_dropout_0">
      <origin xyz="-0.3 0.21 0.095" rpy="0 0 0" />
      <geometry>
        <box size="0.07 0.03 0.125" />
        </geometry>
      </collision>
    <collision name="rear_axle_pin_0">
      <origin xyz="-0.3 0.2213 0.075" rpy="1.5708 0 0" />
      <geometry>
        <cylinder radius="0.01" length="0.018" />
        </geometry>
      </collision>
    <collision name="rear_dropout_1">
      <origin xyz="-0.3 -0.21 0.095" rpy="0 0 0" />
      <geometry>
        <box size="0.07 0.03 0.125" />
        </geometry>
      </collision>
    <collision name="rear_axle_pin_1">
      <origin xyz="-0.3 -0.2213 0.075" rpy="1.5708 0 0" />
      <geometry>
        <cylinder radius="0.01" length="0.018" />
        </geometry>
      </collision>
    <collision name="head_bridge">
      <origin xyz="0.375 0 0.29" rpy="0 0 0" />
      <geometry>
        <box size="0.032 0.032 0.04" />
        </geometry>
      </collision>
    <collision name="head_front_plate">
      <origin xyz="0.386 0 0.36" rpy="0 0 0" />
      <geometry>
        <box size="0.012 0.086 0.16" />
        </geometry>
      </collision>
    <collision name="head_rear_plate">
      <origin xyz="0.474 0 0.36" rpy="0 0 0" />
      <geometry>
        <box size="0.012 0.086 0.16" />
        </geometry>
      </collision>
    <collision name="head_side_plate_0">
      <origin xyz="0.43 0.044 0.36" rpy="0 0 0" />
      <geometry>
        <box size="0.104 0.012 0.16" />
        </geometry>
      </collision>
    <collision name="head_side_plate_1">
      <origin xyz="0.43 -0.044 0.36" rpy="0 0 0" />
      <geometry>
        <box size="0.104 0.012 0.16" />
        </geometry>
      </collision>
    </link>
  <link name="knee_pad">
    <visual name="platform_plate">
      <origin xyz="0 0 0.015" rpy="0 0 0" />
      <geometry>
        <box size="0.42 0.23 0.03" />
        </geometry>
      <material name="brushed_aluminum">
        <color rgba="0.62 0.64 0.62 1" />
        </material>
      </visual>
    <visual name="cushion">
      <origin xyz="0 0 0.06" rpy="0 0 0" />
      <geometry>
        <box size="0.395 0.205 0.06" />
        </geometry>
      <material name="blue_vinyl_pad">
        <color rgba="0.02 0.1 0.28 1" />
        </material>
      </visual>
    <collision name="platform_plate">
      <origin xyz="0 0 0.015" rpy="0 0 0" />
      <geometry>
        <box size="0.42 0.23 0.03" />
        </geometry>
      </collision>
    <collision name="cushion">
      <origin xyz="0 0 0.06" rpy="0 0 0" />
      <geometry>
        <box size="0.395 0.205 0.06" />
        </geometry>
      </collision>
    </link>
  <link name="steering_fork">
    <visual name="steering_bearing">
      <geometry>
        <cylinder radius="0.038" length="0.05" />
        </geometry>
      <material name="dark_hardware">
        <color rgba="0.05 0.05 0.055 1" />
        </material>
      </visual>
    <visual name="steering_column">
      <origin xyz="0 0 0.31" rpy="0 0 0" />
      <geometry>
        <cylinder radius="0.017" length="0.62" />
        </geometry>
      <material name="brushed_aluminum">
        <color rgba="0.62 0.64 0.62 1" />
        </material>
      </visual>
    <visual name="lower_steerer">
      <origin xyz="0 0 -0.13" rpy="0 0 0" />
      <geometry>
        <cylinder radius="0.017" length="0.26" />
        </geometry>
      <material name="brushed_aluminum">
        <color rgba="0.62 0.64 0.62 1" />
        </material>
      </visual>
    <visual name="handlebar">
      <origin xyz="0 0 0.62" rpy="1.5708 0 0" />
      <geometry>
        <cylinder radius="0.018" length="0.5" />
        </geometry>
      <material name="brushed_aluminum">
        <color rgba="0.62 0.64 0.62 1" />
        </material>
      </visual>
    <visual name="grip_0">
      <origin xyz="0 0.285 0.62" rpy="1.5708 0 0" />
      <geometry>
        <cylinder radius="0.023" length="0.085" />
        </geometry>
      <material name="soft_black_rubber">
        <color rgba="0.004 0.004 0.004 1" />
        </material>
      </visual>
    <visual name="grip_1">
      <origin xyz="0 -0.285 0.62" rpy="1.5708 0 0" />
      <geometry>
        <cylinder radius="0.023" length="0.085" />
        </geometry>
      <material name="soft_black_rubber">
        <color rgba="0.004 0.004 0.004 1" />
        </material>
      </visual>
    <visual name="fork_crown">
      <origin xyz="0.045 0 -0.222" rpy="0 0 0" />
      <geometry>
        <box size="0.11 0.43 0.034" />
        </geometry>
      <material name="powder_coated_black">
        <color rgba="0.015 0.017 0.018 1" />
        </material>
      </visual>
    <visual name="front_dropout_0">
      <origin xyz="0.06 0.21 -0.28" rpy="0 0 0" />
      <geometry>
        <box size="0.052 0.03 0.17" />
        </geometry>
      <material name="powder_coated_black">
        <color rgba="0.015 0.017 0.018 1" />
        </material>
      </visual>
    <visual name="front_axle_pin_0">
      <origin xyz="0.06 0.2213 -0.285" rpy="1.5708 0 0" />
      <geometry>
        <cylinder radius="0.01" length="0.018" />
        </geometry>
      <material name="dark_hardware">
        <color rgba="0.05 0.05 0.055 1" />
        </material>
      </visual>
    <visual name="brake_clevis_inner_0">
      <origin xyz="-0.03 0.126 0.592" rpy="0 0 0" />
      <geometry>
        <box size="0.026 0.006 0.046" />
        </geometry>
      <material name="dark_hardware">
        <color rgba="0.05 0.05 0.055 1" />
        </material>
      </visual>
    <visual name="brake_clevis_outer_0">
      <origin xyz="-0.03 0.154 0.592" rpy="0 0 0" />
      <geometry>
        <box size="0.026 0.006 0.046" />
        </geometry>
      <material name="dark_hardware">
        <color rgba="0.05 0.05 0.055 1" />
        </material>
      </visual>
    <visual name="brake_clamp_0">
      <origin xyz="-0.018 0.14 0.616" rpy="0 0 0" />
      <geometry>
        <box size="0.022 0.034 0.018" />
        </geometry>
      <material name="dark_hardware">
        <color rgba="0.05 0.05 0.055 1" />
        </material>
      </visual>
    <visual name="front_dropout_1">
      <origin xyz="0.06 -0.21 -0.28" rpy="0 0 0" />
      <geometry>
        <box size="0.052 0.03 0.17" />
        </geometry>
      <material name="powder_coated_black">
        <color rgba="0.015 0.017 0.018 1" />
        </material>
      </visual>
    <visual name="front_axle_pin_1">
      <origin xyz="0.06 -0.2213 -0.285" rpy="1.5708 0 0" />
      <geometry>
        <cylinder radius="0.01" length="0.018" />
        </geometry>
      <material name="dark_hardware">
        <color rgba="0.05 0.05 0.055 1" />
        </material>
      </visual>
    <visual name="brake_clevis_inner_1">
      <origin xyz="-0.03 -0.126 0.592" rpy="0 0 0" />
      <geometry>
        <box size="0.026 0.006 0.046" />
        </geometry>
      <material name="dark_hardware">
        <color rgba="0.05 0.05 0.055 1" />
        </material>
      </visual>
    <visual name="brake_clevis_outer_1">
      <origin xyz="-0.03 -0.154 0.592" rpy="0 0 0" />
      <geometry>
        <box size="0.026 0.006 0.046" />
        </geometry>
      <material name="dark_hardware">
        <color rgba="0.05 0.05 0.055 1" />
        </material>
      </visual>
    <visual name="brake_clamp_1">
      <origin xyz="-0.018 -0.14 0.616" rpy="0 0 0" />
      <geometry>
        <box size="0.022 0.034 0.018" />
        </geometry>
      <material name="dark_hardware">
        <color rgba="0.05 0.05 0.055 1" />
        </material>
      </visual>
    <collision name="steering_bearing">
      <geometry>
        <cylinder radius="0.038" length="0.05" />
        </geometry>
      </collision>
    <collision name="steering_column">
      <origin xyz="0 0 0.31" rpy="0 0 0" />
      <geometry>
        <cylinder radius="0.017" length="0.62" />
        </geometry>
      </collision>
    <collision name="lower_steerer">
      <origin xyz="0 0 -0.13" rpy="0 0 0" />
      <geometry>
        <cylinder radius="0.017" length="0.26" />
        </geometry>
      </collision>
    <collision name="handlebar">
      <origin xyz="0 0 0.62" rpy="1.5708 0 0" />
      <geometry>
        <cylinder radius="0.018" length="0.5" />
        </geometry>
      </collision>
    <collision name="grip_0">
      <origin xyz="0 0.285 0.62" rpy="1.5708 0 0" />
      <geometry>
        <cylinder radius="0.023" length="0.085" />
        </geometry>
      </collision>
    <collision name="grip_1">
      <origin xyz="0 -0.285 0.62" rpy="1.5708 0 0" />
      <geometry>
        <cylinder radius="0.023" length="0.085" />
        </geometry>
      </collision>
    <collision name="fork_crown">
      <origin xyz="0.045 0 -0.222" rpy="0 0 0" />
      <geometry>
        <box size="0.11 0.43 0.034" />
        </geometry>
      </collision>
    <collision name="front_dropout_0">
      <origin xyz="0.06 0.21 -0.28" rpy="0 0 0" />
      <geometry>
        <box size="0.052 0.03 0.17" />
        </geometry>
      </collision>
    <collision name="front_axle_pin_0">
      <origin xyz="0.06 0.2213 -0.285" rpy="1.5708 0 0" />
      <geometry>
        <cylinder radius="0.01" length="0.018" />
        </geometry>
      </collision>
    <collision name="brake_clevis_inner_0">
      <origin xyz="-0.03 0.126 0.592" rpy="0 0 0" />
      <geometry>
        <box size="0.026 0.006 0.046" />
        </geometry>
      </collision>
    <collision name="brake_clevis_outer_0">
      <origin xyz="-0.03 0.154 0.592" rpy="0 0 0" />
      <geometry>
        <box size="0.026 0.006 0.046" />
        </geometry>
      </collision>
    <collision name="brake_clamp_0">
      <origin xyz="-0.018 0.14 0.616" rpy="0 0 0" />
      <geometry>
        <box size="0.022 0.034 0.018" />
        </geometry>
      </collision>
    <collision name="front_dropout_1">
      <origin xyz="0.06 -0.21 -0.28" rpy="0 0 0" />
      <geometry>
        <box size="0.052 0.03 0.17" />
        </geometry>
      </collision>
    <collision name="front_axle_pin_1">
      <origin xyz="0.06 -0.2213 -0.285" rpy="1.5708 0 0" />
      <geometry>
        <cylinder radius="0.01" length="0.018" />
        </geometry>
      </collision>
    <collision name="brake_clevis_inner_1">
      <origin xyz="-0.03 -0.126 0.592" rpy="0 0 0" />
      <geometry>
        <box size="0.026 0.006 0.046" />
        </geometry>
      </collision>
    <collision name="brake_clevis_outer_1">
      <origin xyz="-0.03 -0.154 0.592" rpy="0 0 0" />
      <geometry>
        <box size="0.026 0.006 0.046" />
        </geometry>
      </collision>
    <collision name="brake_clamp_1">
      <origin xyz="-0.018 -0.14 0.616" rpy="0 0 0" />
      <geometry>
        <box size="0.022 0.034 0.018" />
        </geometry>
      </collision>
    </link>
  <link name="rear_wheel_0">
    <visual name="tire">
      <geometry>
        <mesh filename="assets/meshes/scooter_wheel_tire.obj" />
        </geometry>
      <material name="soft_black_rubber">
        <color rgba="0.004 0.004 0.004 1" />
        </material>
      </visual>
    <visual name="rim">
      <geometry>
        <mesh filename="assets/meshes/scooter_wheel_rim.obj" />
        </geometry>
      <material name="brushed_aluminum">
        <color rgba="0.62 0.64 0.62 1" />
        </material>
      </visual>
    <visual name="inner_hub_spacer">
      <origin xyz="-0.01 0 0" rpy="0 1.5708 0" />
      <geometry>
        <cylinder radius="0.018" length="0.02" />
        </geometry>
      <material name="brushed_aluminum">
        <color rgba="0.62 0.64 0.62 1" />
        </material>
      </visual>
    <collision name="tire">
      <geometry>
        <mesh filename="assets/meshes/scooter_wheel_tire.obj" />
        </geometry>
      </collision>
    <collision name="rim">
      <geometry>
        <mesh filename="assets/meshes/scooter_wheel_rim.obj" />
        </geometry>
      </collision>
    <collision name="inner_hub_spacer">
      <origin xyz="-0.01 0 0" rpy="0 1.5708 0" />
      <geometry>
        <cylinder radius="0.018" length="0.02" />
        </geometry>
      </collision>
    </link>
  <link name="rear_wheel_1">
    <visual name="tire">
      <geometry>
        <mesh filename="assets/meshes/scooter_wheel_tire.obj" />
        </geometry>
      <material name="soft_black_rubber">
        <color rgba="0.004 0.004 0.004 1" />
        </material>
      </visual>
    <visual name="rim">
      <geometry>
        <mesh filename="assets/meshes/scooter_wheel_rim.obj" />
        </geometry>
      <material name="brushed_aluminum">
        <color rgba="0.62 0.64 0.62 1" />
        </material>
      </visual>
    <visual name="inner_hub_spacer">
      <origin xyz="0.01 0 0" rpy="0 1.5708 0" />
      <geometry>
        <cylinder radius="0.018" length="0.02" />
        </geometry>
      <material name="brushed_aluminum">
        <color rgba="0.62 0.64 0.62 1" />
        </material>
      </visual>
    <collision name="tire">
      <geometry>
        <mesh filename="assets/meshes/scooter_wheel_tire.obj" />
        </geometry>
      </collision>
    <collision name="rim">
      <geometry>
        <mesh filename="assets/meshes/scooter_wheel_rim.obj" />
        </geometry>
      </collision>
    <collision name="inner_hub_spacer">
      <origin xyz="0.01 0 0" rpy="0 1.5708 0" />
      <geometry>
        <cylinder radius="0.018" length="0.02" />
        </geometry>
      </collision>
    </link>
  <link name="front_wheel_0">
    <visual name="tire">
      <geometry>
        <mesh filename="assets/meshes/scooter_wheel_tire.obj" />
        </geometry>
      <material name="soft_black_rubber">
        <color rgba="0.004 0.004 0.004 1" />
        </material>
      </visual>
    <visual name="rim">
      <geometry>
        <mesh filename="assets/meshes/scooter_wheel_rim.obj" />
        </geometry>
      <material name="brushed_aluminum">
        <color rgba="0.62 0.64 0.62 1" />
        </material>
      </visual>
    <visual name="inner_hub_spacer">
      <origin xyz="-0.01 0 0" rpy="0 1.5708 0" />
      <geometry>
        <cylinder radius="0.018" length="0.02" />
        </geometry>
      <material name="brushed_aluminum">
        <color rgba="0.62 0.64 0.62 1" />
        </material>
      </visual>
    <collision name="tire">
      <geometry>
        <mesh filename="assets/meshes/scooter_wheel_tire.obj" />
        </geometry>
      </collision>
    <collision name="rim">
      <geometry>
        <mesh filename="assets/meshes/scooter_wheel_rim.obj" />
        </geometry>
      </collision>
    <collision name="inner_hub_spacer">
      <origin xyz="-0.01 0 0" rpy="0 1.5708 0" />
      <geometry>
        <cylinder radius="0.018" length="0.02" />
        </geometry>
      </collision>
    </link>
  <link name="front_wheel_1">
    <visual name="tire">
      <geometry>
        <mesh filename="assets/meshes/scooter_wheel_tire.obj" />
        </geometry>
      <material name="soft_black_rubber">
        <color rgba="0.004 0.004 0.004 1" />
        </material>
      </visual>
    <visual name="rim">
      <geometry>
        <mesh filename="assets/meshes/scooter_wheel_rim.obj" />
        </geometry>
      <material name="brushed_aluminum">
        <color rgba="0.62 0.64 0.62 1" />
        </material>
      </visual>
    <visual name="inner_hub_spacer">
      <origin xyz="0.01 0 0" rpy="0 1.5708 0" />
      <geometry>
        <cylinder radius="0.018" length="0.02" />
        </geometry>
      <material name="brushed_aluminum">
        <color rgba="0.62 0.64 0.62 1" />
        </material>
      </visual>
    <collision name="tire">
      <geometry>
        <mesh filename="assets/meshes/scooter_wheel_tire.obj" />
        </geometry>
      </collision>
    <collision name="rim">
      <geometry>
        <mesh filename="assets/meshes/scooter_wheel_rim.obj" />
        </geometry>
      </collision>
    <collision name="inner_hub_spacer">
      <origin xyz="0.01 0 0" rpy="0 1.5708 0" />
      <geometry>
        <cylinder radius="0.018" length="0.02" />
        </geometry>
      </collision>
    </link>
  <link name="brake_lever_0">
    <visual name="pivot_hub">
      <origin xyz="0 0 0" rpy="1.5708 0 0" />
      <geometry>
        <cylinder radius="0.01" length="0.022" />
        </geometry>
      <material name="black_composite_lever">
        <color rgba="0.01 0.012 0.013 1" />
        </material>
      </visual>
    <visual name="lever_neck">
      <origin xyz="-0.015 0 -0.006" rpy="0 0 0" />
      <geometry>
        <box size="0.04 0.01 0.012" />
        </geometry>
      <material name="black_composite_lever">
        <color rgba="0.01 0.012 0.013 1" />
        </material>
      </visual>
    <visual name="lever_blade">
      <origin xyz="-0.03 0 -0.065" rpy="0 0 0" />
      <geometry>
        <box size="0.017 0.01 0.125" />
        </geometry>
      <material name="black_composite_lever">
        <color rgba="0.01 0.012 0.013 1" />
        </material>
      </visual>
    <visual name="rounded_tip">
      <origin xyz="-0.03 0 -0.13" rpy="0 0 0" />
      <geometry>
        <sphere radius="0.014" />
        </geometry>
      <material name="black_composite_lever">
        <color rgba="0.01 0.012 0.013 1" />
        </material>
      </visual>
    <collision name="pivot_hub">
      <origin xyz="0 0 0" rpy="1.5708 0 0" />
      <geometry>
        <cylinder radius="0.01" length="0.022" />
        </geometry>
      </collision>
    <collision name="lever_neck">
      <origin xyz="-0.015 0 -0.006" rpy="0 0 0" />
      <geometry>
        <box size="0.04 0.01 0.012" />
        </geometry>
      </collision>
    <collision name="lever_blade">
      <origin xyz="-0.03 0 -0.065" rpy="0 0 0" />
      <geometry>
        <box size="0.017 0.01 0.125" />
        </geometry>
      </collision>
    <collision name="rounded_tip">
      <origin xyz="-0.03 0 -0.13" rpy="0 0 0" />
      <geometry>
        <sphere radius="0.014" />
        </geometry>
      </collision>
    </link>
  <link name="brake_lever_1">
    <visual name="pivot_hub">
      <origin xyz="0 0 0" rpy="1.5708 0 0" />
      <geometry>
        <cylinder radius="0.01" length="0.022" />
        </geometry>
      <material name="black_composite_lever">
        <color rgba="0.01 0.012 0.013 1" />
        </material>
      </visual>
    <visual name="lever_neck">
      <origin xyz="-0.015 0 -0.006" rpy="0 0 0" />
      <geometry>
        <box size="0.04 0.01 0.012" />
        </geometry>
      <material name="black_composite_lever">
        <color rgba="0.01 0.012 0.013 1" />
        </material>
      </visual>
    <visual name="lever_blade">
      <origin xyz="-0.03 0 -0.065" rpy="0 0 0" />
      <geometry>
        <box size="0.017 0.01 0.125" />
        </geometry>
      <material name="black_composite_lever">
        <color rgba="0.01 0.012 0.013 1" />
        </material>
      </visual>
    <visual name="rounded_tip">
      <origin xyz="-0.03 0 -0.13" rpy="0 0 0" />
      <geometry>
        <sphere radius="0.014" />
        </geometry>
      <material name="black_composite_lever">
        <color rgba="0.01 0.012 0.013 1" />
        </material>
      </visual>
    <collision name="pivot_hub">
      <origin xyz="0 0 0" rpy="1.5708 0 0" />
      <geometry>
        <cylinder radius="0.01" length="0.022" />
        </geometry>
      </collision>
    <collision name="lever_neck">
      <origin xyz="-0.015 0 -0.006" rpy="0 0 0" />
      <geometry>
        <box size="0.04 0.01 0.012" />
        </geometry>
      </collision>
    <collision name="lever_blade">
      <origin xyz="-0.03 0 -0.065" rpy="0 0 0" />
      <geometry>
        <box size="0.017 0.01 0.125" />
        </geometry>
      </collision>
    <collision name="rounded_tip">
      <origin xyz="-0.03 0 -0.13" rpy="0 0 0" />
      <geometry>
        <sphere radius="0.014" />
        </geometry>
      </collision>
    </link>
  <joint name="frame_to_knee_pad" type="fixed">
    <origin xyz="-0.08 0 0.5" rpy="0 0 0" />
    <parent link="central_frame" />
    <child link="knee_pad" />
    </joint>
  <joint name="fork_steer" type="revolute">
    <origin xyz="0.43 0 0.36" rpy="0 0 0" />
    <parent link="central_frame" />
    <child link="steering_fork" />
    <axis xyz="0 0 1" />
    <limit effort="18" velocity="2" lower="-0.65" upper="0.65" />
    </joint>
  <joint name="rear_wheel_0_spin" type="continuous">
    <origin xyz="-0.3 0.25 0.075" rpy="0 0 1.5708" />
    <parent link="central_frame" />
    <child link="rear_wheel_0" />
    <axis xyz="1 0 0" />
    <limit effort="2" velocity="30" />
    </joint>
  <joint name="rear_wheel_1_spin" type="continuous">
    <origin xyz="-0.3 -0.25 0.075" rpy="0 0 1.5708" />
    <parent link="central_frame" />
    <child link="rear_wheel_1" />
    <axis xyz="1 0 0" />
    <limit effort="2" velocity="30" />
    </joint>
  <joint name="front_wheel_0_spin" type="continuous">
    <origin xyz="0.06 0.25 -0.285" rpy="0 0 1.5708" />
    <parent link="steering_fork" />
    <child link="front_wheel_0" />
    <axis xyz="1 0 0" />
    <limit effort="2" velocity="30" />
    </joint>
  <joint name="front_wheel_1_spin" type="continuous">
    <origin xyz="0.06 -0.25 -0.285" rpy="0 0 1.5708" />
    <parent link="steering_fork" />
    <child link="front_wheel_1" />
    <axis xyz="1 0 0" />
    <limit effort="2" velocity="30" />
    </joint>
  <joint name="brake_lever_0_pivot" type="revolute">
    <origin xyz="-0.03 0.14 0.592" rpy="0 0 0" />
    <parent link="steering_fork" />
    <child link="brake_lever_0" />
    <axis xyz="0 1 0" />
    <limit effort="1" velocity="5" lower="0" upper="0.55" />
    </joint>
  <joint name="brake_lever_1_pivot" type="revolute">
    <origin xyz="-0.03 -0.14 0.592" rpy="0 0 0" />
    <parent link="steering_fork" />
    <child link="brake_lever_1" />
    <axis xyz="0 -1 0" />
    <limit effort="1" velocity="5" lower="0" upper="0.55" />
    </joint>
  </robot>
