<robot name="cylinder_bottle_hand_truck">
  <link name="frame">
    <visual name="side_rail_0">
      <geometry>
        <mesh filename="assets/meshes/side_rail_0.obj" />
        </geometry>
      <material name="red_powder_coat">
        <color rgba="0.82 0.06 0.035 1" />
        </material>
      </visual>
    <visual name="side_rail_1">
      <geometry>
        <mesh filename="assets/meshes/side_rail_1.obj" />
        </geometry>
      <material name="red_powder_coat">
        <color rgba="0.82 0.06 0.035 1" />
        </material>
      </visual>
    <visual name="lower_crossbar">
      <origin xyz="0 0.018 0.255" rpy="0 1.5708 0" />
      <geometry>
        <cylinder radius="0.014" length="0.52" />
        </geometry>
      <material name="red_powder_coat">
        <color rgba="0.82 0.06 0.035 1" />
        </material>
      </visual>
    <visual name="mid_crossbar">
      <origin xyz="0 0.012 0.61" rpy="0 1.5708 0" />
      <geometry>
        <cylinder radius="0.012" length="0.52" />
        </geometry>
      <material name="red_powder_coat">
        <color rgba="0.82 0.06 0.035 1" />
        </material>
      </visual>
    <visual name="shoulder_crossbar">
      <origin xyz="0 0.066 1.055" rpy="0 1.5708 0" />
      <geometry>
        <cylinder radius="0.014" length="0.52" />
        </geometry>
      <material name="red_powder_coat">
        <color rgba="0.82 0.06 0.035 1" />
        </material>
      </visual>
    <visual name="rear_handle">
      <origin xyz="0 -0.17 1.36" rpy="0 1.5708 0" />
      <geometry>
        <cylinder radius="0.017" length="0.52" />
        </geometry>
      <material name="red_powder_coat">
        <color rgba="0.82 0.06 0.035 1" />
        </material>
      </visual>
    <visual name="lower_crossbar_mount_0">
      <origin xyz="-0.23 0.048 0.255" rpy="-1.5708 0 0" />
      <geometry>
        <cylinder radius="0.01" length="0.06" />
        </geometry>
      <material name="red_powder_coat">
        <color rgba="0.82 0.06 0.035 1" />
        </material>
      </visual>
    <visual name="mid_crossbar_mount_0">
      <origin xyz="-0.23 0.032 0.61" rpy="-1.5708 0 0" />
      <geometry>
        <cylinder radius="0.009" length="0.04" />
        </geometry>
      <material name="red_powder_coat">
        <color rgba="0.82 0.06 0.035 1" />
        </material>
      </visual>
    <visual name="lower_crossbar_mount_1">
      <origin xyz="0.23 0.048 0.255" rpy="-1.5708 0 0" />
      <geometry>
        <cylinder radius="0.01" length="0.06" />
        </geometry>
      <material name="red_powder_coat">
        <color rgba="0.82 0.06 0.035 1" />
        </material>
      </visual>
    <visual name="mid_crossbar_mount_1">
      <origin xyz="0.23 0.032 0.61" rpy="-1.5708 0 0" />
      <geometry>
        <cylinder radius="0.009" length="0.04" />
        </geometry>
      <material name="red_powder_coat">
        <color rgba="0.82 0.06 0.035 1" />
        </material>
      </visual>
    <visual name="curved_cradle_0">
      <geometry>
        <mesh filename="assets/meshes/curved_cradle_0.obj" />
        </geometry>
      <material name="red_powder_coat">
        <color rgba="0.82 0.06 0.035 1" />
        </material>
      </visual>
    <visual name="curved_cradle_1">
      <geometry>
        <mesh filename="assets/meshes/curved_cradle_1.obj" />
        </geometry>
      <material name="red_powder_coat">
        <color rgba="0.82 0.06 0.035 1" />
        </material>
      </visual>
    <visual name="curved_cradle_2">
      <geometry>
        <mesh filename="assets/meshes/curved_cradle_2.obj" />
        </geometry>
      <material name="red_powder_coat">
        <color rgba="0.82 0.06 0.035 1" />
        </material>
      </visual>
    <visual name="nose_plate">
      <origin xyz="0 0.205 0.0375" rpy="0 0 0" />
      <geometry>
        <box size="0.48 0.32 0.035" />
        </geometry>
      <material name="worn_steel_plate">
        <color rgba="0.34 0.36 0.34 1" />
        </material>
      </visual>
    <visual name="front_lip">
      <origin xyz="0 0.365 0.075" rpy="0 0 0" />
      <geometry>
        <box size="0.46 0.02 0.055" />
        </geometry>
      <material name="worn_steel_plate">
        <color rgba="0.34 0.36 0.34 1" />
        </material>
      </visual>
    <visual name="wheel_axle">
      <origin xyz="0 -0.1 0.18" rpy="0 1.5708 0" />
      <geometry>
        <cylinder radius="0.017" length="0.72" />
        </geometry>
      <material name="dark_hardware">
        <color rgba="0.04 0.045 0.045 1" />
        </material>
      </visual>
    <visual name="axle_mount_0">
      <origin xyz="-0.23 -0.015 0.18" rpy="-1.5708 0 0" />
      <geometry>
        <cylinder radius="0.013" length="0.175" />
        </geometry>
      <material name="dark_hardware">
        <color rgba="0.04 0.045 0.045 1" />
        </material>
      </visual>
    <visual name="axle_mount_1">
      <origin xyz="0.23 -0.015 0.18" rpy="-1.5708 0 0" />
      <geometry>
        <cylinder radius="0.013" length="0.175" />
        </geometry>
      <material name="dark_hardware">
        <color rgba="0.04 0.045 0.045 1" />
        </material>
      </visual>
    <visual name="pivot_pin_0">
      <origin xyz="-0.3 0.07 1.055" rpy="0 1.5708 0" />
      <geometry>
        <cylinder radius="0.018" length="0.08" />
        </geometry>
      <material name="brushed_steel">
        <color rgba="0.58 0.6 0.59 1" />
        </material>
      </visual>
    <visual name="pivot_pin_1">
      <origin xyz="0.3 0.07 1.055" rpy="0 1.5708 0" />
      <geometry>
        <cylinder radius="0.018" length="0.08" />
        </geometry>
      <material name="brushed_steel">
        <color rgba="0.58 0.6 0.59 1" />
        </material>
      </visual>
    <collision name="side_rail_0">
      <geometry>
        <mesh filename="assets/meshes/side_rail_0.obj" />
        </geometry>
      </collision>
    <collision name="side_rail_1">
      <geometry>
        <mesh filename="assets/meshes/side_rail_1.obj" />
        </geometry>
      </collision>
    <collision name="lower_crossbar">
      <origin xyz="0 0.018 0.255" rpy="0 1.5708 0" />
      <geometry>
        <cylinder radius="0.014" length="0.52" />
        </geometry>
      </collision>
    <collision name="mid_crossbar">
      <origin xyz="0 0.012 0.61" rpy="0 1.5708 0" />
      <geometry>
        <cylinder radius="0.012" length="0.52" />
        </geometry>
      </collision>
    <collision name="shoulder_crossbar">
      <origin xyz="0 0.066 1.055" rpy="0 1.5708 0" />
      <geometry>
        <cylinder radius="0.014" length="0.52" />
        </geometry>
      </collision>
    <collision name="rear_handle">
      <origin xyz="0 -0.17 1.36" rpy="0 1.5708 0" />
      <geometry>
        <cylinder radius="0.017" length="0.52" />
        </geometry>
      </collision>
    <collision name="lower_crossbar_mount_0">
      <origin xyz="-0.23 0.048 0.255" rpy="-1.5708 0 0" />
      <geometry>
        <cylinder radius="0.01" length="0.06" />
        </geometry>
      </collision>
    <collision name="mid_crossbar_mount_0">
      <origin xyz="-0.23 0.032 0.61" rpy="-1.5708 0 0" />
      <geometry>
        <cylinder radius="0.009" length="0.04" />
        </geometry>
      </collision>
    <collision name="lower_crossbar_mount_1">
      <origin xyz="0.23 0.048 0.255" rpy="-1.5708 0 0" />
      <geometry>
        <cylinder radius="0.01" length="0.06" />
        </geometry>
      </collision>
    <collision name="mid_crossbar_mount_1">
      <origin xyz="0.23 0.032 0.61" rpy="-1.5708 0 0" />
      <geometry>
        <cylinder radius="0.009" length="0.04" />
        </geometry>
      </collision>
    <collision name="curved_cradle_0">
      <geometry>
        <mesh filename="assets/meshes/curved_cradle_0.obj" />
        </geometry>
      </collision>
    <collision name="curved_cradle_1">
      <geometry>
        <mesh filename="assets/meshes/curved_cradle_1.obj" />
        </geometry>
      </collision>
    <collision name="curved_cradle_2">
      <geometry>
        <mesh filename="assets/meshes/curved_cradle_2.obj" />
        </geometry>
      </collision>
    <collision name="nose_plate">
      <origin xyz="0 0.205 0.0375" rpy="0 0 0" />
      <geometry>
        <box size="0.48 0.32 0.035" />
        </geometry>
      </collision>
    <collision name="front_lip">
      <origin xyz="0 0.365 0.075" rpy="0 0 0" />
      <geometry>
        <box size="0.46 0.02 0.055" />
        </geometry>
      </collision>
    <collision name="wheel_axle">
      <origin xyz="0 -0.1 0.18" rpy="0 1.5708 0" />
      <geometry>
        <cylinder radius="0.017" length="0.72" />
        </geometry>
      </collision>
    <collision name="axle_mount_0">
      <origin xyz="-0.23 -0.015 0.18" rpy="-1.5708 0 0" />
      <geometry>
        <cylinder radius="0.013" length="0.175" />
        </geometry>
      </collision>
    <collision name="axle_mount_1">
      <origin xyz="0.23 -0.015 0.18" rpy="-1.5708 0 0" />
      <geometry>
        <cylinder radius="0.013" length="0.175" />
        </geometry>
      </collision>
    <collision name="pivot_pin_0">
      <origin xyz="-0.3 0.07 1.055" rpy="0 1.5708 0" />
      <geometry>
        <cylinder radius="0.018" length="0.08" />
        </geometry>
      </collision>
    <collision name="pivot_pin_1">
      <origin xyz="0.3 0.07 1.055" rpy="0 1.5708 0" />
      <geometry>
        <cylinder radius="0.018" length="0.08" />
        </geometry>
      </collision>
    </link>
  <link name="cylinder">
    <visual name="foot_ring">
      <origin xyz="0 0 0.02" rpy="0 0 0" />
      <geometry>
        <cylinder radius="0.155" length="0.04" />
        </geometry>
      <material name="dark_hardware">
        <color rgba="0.04 0.045 0.045 1" />
        </material>
      </visual>
    <visual name="cylinder_body">
      <geometry>
        <mesh filename="assets/meshes/cylinder_body.obj" />
        </geometry>
      <material name="green_cylinder">
        <color rgba="0.03 0.34 0.18 1" />
        </material>
      </visual>
    <visual name="valve_neck">
      <origin xyz="0 0 0.965" rpy="0 0 0" />
      <geometry>
        <cylinder radius="0.03" length="0.07" />
        </geometry>
      <material name="brass_valve">
        <color rgba="0.8 0.58 0.24 1" />
        </material>
      </visual>
    <visual name="valve_knob">
      <origin xyz="0 0 1.02" rpy="0 1.5708 0" />
      <geometry>
        <cylinder radius="0.055" length="0.05" />
        </geometry>
      <material name="brass_valve">
        <color rgba="0.8 0.58 0.24 1" />
        </material>
      </visual>
    <collision name="foot_ring">
      <origin xyz="0 0 0.02" rpy="0 0 0" />
      <geometry>
        <cylinder radius="0.155" length="0.04" />
        </geometry>
      </collision>
    <collision name="cylinder_body">
      <geometry>
        <mesh filename="assets/meshes/cylinder_body.obj" />
        </geometry>
      </collision>
    <collision name="valve_neck">
      <origin xyz="0 0 0.965" rpy="0 0 0" />
      <geometry>
        <cylinder radius="0.03" length="0.07" />
        </geometry>
      </collision>
    <collision name="valve_knob">
      <origin xyz="0 0 1.02" rpy="0 1.5708 0" />
      <geometry>
        <cylinder radius="0.055" length="0.05" />
        </geometry>
      </collision>
    </link>
  <link name="retaining_hoop">
    <visual name="front_hoop_tube">
      <geometry>
        <mesh filename="assets/meshes/front_hoop_tube.obj" />
        </geometry>
      <material name="red_powder_coat">
        <color rgba="0.82 0.06 0.035 1" />
        </material>
      </visual>
    <visual name="pivot_sleeve_0">
      <origin xyz="-0.3 0 0" rpy="0 1.5708 0" />
      <geometry>
        <cylinder radius="0.026" length="0.055" />
        </geometry>
      <material name="brushed_steel">
        <color rgba="0.58 0.6 0.59 1" />
        </material>
      </visual>
    <visual name="sleeve_weld_0">
      <origin xyz="-0.3 0.034 -0.02" rpy="0 0 0" />
      <geometry>
        <sphere radius="0.018" />
        </geometry>
      <material name="red_powder_coat">
        <color rgba="0.82 0.06 0.035 1" />
        </material>
      </visual>
    <visual name="pivot_sleeve_1">
      <origin xyz="0.3 0 0" rpy="0 1.5708 0" />
      <geometry>
        <cylinder radius="0.026" length="0.055" />
        </geometry>
      <material name="brushed_steel">
        <color rgba="0.58 0.6 0.59 1" />
        </material>
      </visual>
    <visual name="sleeve_weld_1">
      <origin xyz="0.3 0.034 -0.02" rpy="0 0 0" />
      <geometry>
        <sphere radius="0.018" />
        </geometry>
      <material name="red_powder_coat">
        <color rgba="0.82 0.06 0.035 1" />
        </material>
      </visual>
    <collision name="front_hoop_tube">
      <geometry>
        <mesh filename="assets/meshes/front_hoop_tube.obj" />
        </geometry>
      </collision>
    <collision name="pivot_sleeve_0">
      <origin xyz="-0.3 0 0" rpy="0 1.5708 0" />
      <geometry>
        <cylinder radius="0.026" length="0.055" />
        </geometry>
      </collision>
    <collision name="sleeve_weld_0">
      <origin xyz="-0.3 0.034 -0.02" rpy="0 0 0" />
      <geometry>
        <sphere radius="0.018" />
        </geometry>
      </collision>
    <collision name="pivot_sleeve_1">
      <origin xyz="0.3 0 0" rpy="0 1.5708 0" />
      <geometry>
        <cylinder radius="0.026" length="0.055" />
        </geometry>
      </collision>
    <collision name="sleeve_weld_1">
      <origin xyz="0.3 0.034 -0.02" rpy="0 0 0" />
      <geometry>
        <sphere radius="0.018" />
        </geometry>
      </collision>
    </link>
  <link name="wheel_0">
    <visual name="tire">
      <geometry>
        <mesh filename="assets/meshes/wheel_tire.obj" />
        </geometry>
      <material name="black_rubber">
        <color rgba="0.01 0.01 0.009 1" />
        </material>
      </visual>
    <visual name="hub">
      <geometry>
        <mesh filename="assets/meshes/wheel_hub.obj" />
        </geometry>
      <material name="brushed_steel">
        <color rgba="0.58 0.6 0.59 1" />
        </material>
      </visual>
    <collision name="tire">
      <geometry>
        <mesh filename="assets/meshes/wheel_tire.obj" />
        </geometry>
      </collision>
    <collision name="hub">
      <geometry>
        <mesh filename="assets/meshes/wheel_hub.obj" />
        </geometry>
      </collision>
    </link>
  <link name="wheel_1">
    <visual name="tire">
      <geometry>
        <mesh filename="assets/meshes/wheel_tire.obj" />
        </geometry>
      <material name="black_rubber">
        <color rgba="0.01 0.01 0.009 1" />
        </material>
      </visual>
    <visual name="hub">
      <geometry>
        <mesh filename="assets/meshes/wheel_hub.obj" />
        </geometry>
      <material name="brushed_steel">
        <color rgba="0.58 0.6 0.59 1" />
        </material>
      </visual>
    <collision name="tire">
      <geometry>
        <mesh filename="assets/meshes/wheel_tire.obj" />
        </geometry>
      </collision>
    <collision name="hub">
      <geometry>
        <mesh filename="assets/meshes/wheel_hub.obj" />
        </geometry>
      </collision>
    </link>
  <joint name="frame_to_cylinder" type="fixed">
    <origin xyz="0 0.19 0.055" rpy="0 0 0" />
    <parent link="frame" />
    <child link="cylinder" />
    </joint>
  <joint name="frame_to_hoop" type="revolute">
    <origin xyz="0 0.07 1.055" rpy="0 0 0" />
    <parent link="frame" />
    <child link="retaining_hoop" />
    <axis xyz="1 0 0" />
    <limit effort="18" velocity="1.8" lower="0" upper="1.35" />
    </joint>
  <joint name="frame_to_wheel_0" type="continuous">
    <origin xyz="-0.32 -0.1 0.18" rpy="0 0 0" />
    <parent link="frame" />
    <child link="wheel_0" />
    <axis xyz="1 0 0" />
    <limit effort="25" velocity="18" />
    </joint>
  <joint name="frame_to_wheel_1" type="continuous">
    <origin xyz="0.32 -0.1 0.18" rpy="0 0 0" />
    <parent link="frame" />
    <child link="wheel_1" />
    <axis xyz="1 0 0" />
    <limit effort="25" velocity="18" />
    </joint>
  </robot>
