<robot name="tabletop_adjustable_easel">
  <material name="warm_beech_wood">
    <color rgba="0.72 0.48 0.25 1" />
    </material>
  <material name="darker_endgrain">
    <color rgba="0.45 0.27 0.12 1" />
    </material>
  <material name="dark_recessed_slots">
    <color rgba="0.035 0.032 0.028 1" />
    </material>
  <material name="brushed_steel">
    <color rgba="0.62 0.61 0.56 1" />
    </material>
  <material name="dark_rubber_feet">
    <color rgba="0.025 0.023 0.02 1" />
    </material>
  <link name="frame">
    <visual name="upright_0">
      <origin xyz="-0.115 0 0.22" rpy="0 0 0" />
      <geometry>
        <box size="0.03 0.026 0.36" />
        </geometry>
      <material name="warm_beech_wood">
        <color rgba="0.72 0.48 0.25 1" />
        </material>
      </visual>
    <visual name="slot_track_0">
      <origin xyz="-0.115 0.0145 0.22" rpy="0 0 0" />
      <geometry>
        <box size="0.01 0.003 0.25" />
        </geometry>
      <material name="dark_recessed_slots">
        <color rgba="0.035 0.032 0.028 1" />
        </material>
      </visual>
    <visual name="desktop_foot_0">
      <origin xyz="-0.115 0.025 0.02" rpy="0 0 0" />
      <geometry>
        <box size="0.09 0.16 0.04" />
        </geometry>
      <material name="darker_endgrain">
        <color rgba="0.45 0.27 0.12 1" />
        </material>
      </visual>
    <visual name="upright_1">
      <origin xyz="0.115 0 0.22" rpy="0 0 0" />
      <geometry>
        <box size="0.03 0.026 0.36" />
        </geometry>
      <material name="warm_beech_wood">
        <color rgba="0.72 0.48 0.25 1" />
        </material>
      </visual>
    <visual name="slot_track_1">
      <origin xyz="0.115 0.0145 0.22" rpy="0 0 0" />
      <geometry>
        <box size="0.01 0.003 0.25" />
        </geometry>
      <material name="dark_recessed_slots">
        <color rgba="0.035 0.032 0.028 1" />
        </material>
      </visual>
    <visual name="desktop_foot_1">
      <origin xyz="0.115 0.025 0.02" rpy="0 0 0" />
      <geometry>
        <box size="0.09 0.16 0.04" />
        </geometry>
      <material name="darker_endgrain">
        <color rgba="0.45 0.27 0.12 1" />
        </material>
      </visual>
    <visual name="lower_crossbar">
      <origin xyz="0 0 0.056" rpy="0 0 0" />
      <geometry>
        <box size="0.305 0.03 0.032" />
        </geometry>
      <material name="warm_beech_wood">
        <color rgba="0.72 0.48 0.25 1" />
        </material>
      </visual>
    <visual name="top_crossbar">
      <origin xyz="0 0 0.405" rpy="0 0 0" />
      <geometry>
        <box size="0.285 0.028 0.03" />
        </geometry>
      <material name="warm_beech_wood">
        <color rgba="0.72 0.48 0.25 1" />
        </material>
      </visual>
    <visual name="upper_canvas_stop">
      <origin xyz="0 0.01 0.34" rpy="0 0 0" />
      <geometry>
        <box size="0.205 0.018 0.018" />
        </geometry>
      <material name="warm_beech_wood">
        <color rgba="0.72 0.48 0.25 1" />
        </material>
      </visual>
    <visual name="hinge_leaf_0">
      <origin xyz="-0.0725 -0.021 0.405" rpy="0 0 0" />
      <geometry>
        <box size="0.05 0.02 0.045" />
        </geometry>
      <material name="brushed_steel">
        <color rgba="0.62 0.61 0.56 1" />
        </material>
      </visual>
    <visual name="hinge_barrel_0">
      <origin xyz="-0.0725 -0.034 0.42" rpy="0 1.5708 0" />
      <geometry>
        <cylinder radius="0.012" length="0.065" />
        </geometry>
      <material name="brushed_steel">
        <color rgba="0.62 0.61 0.56 1" />
        </material>
      </visual>
    <visual name="hinge_leaf_1">
      <origin xyz="0.0725 -0.021 0.405" rpy="0 0 0" />
      <geometry>
        <box size="0.05 0.02 0.045" />
        </geometry>
      <material name="brushed_steel">
        <color rgba="0.62 0.61 0.56 1" />
        </material>
      </visual>
    <visual name="hinge_barrel_1">
      <origin xyz="0.0725 -0.034 0.42" rpy="0 1.5708 0" />
      <geometry>
        <cylinder radius="0.012" length="0.065" />
        </geometry>
      <material name="brushed_steel">
        <color rgba="0.62 0.61 0.56 1" />
        </material>
      </visual>
    <collision name="upright_0">
      <origin xyz="-0.115 0 0.22" rpy="0 0 0" />
      <geometry>
        <box size="0.03 0.026 0.36" />
        </geometry>
      </collision>
    <collision name="slot_track_0">
      <origin xyz="-0.115 0.0145 0.22" rpy="0 0 0" />
      <geometry>
        <box size="0.01 0.003 0.25" />
        </geometry>
      </collision>
    <collision name="desktop_foot_0">
      <origin xyz="-0.115 0.025 0.02" rpy="0 0 0" />
      <geometry>
        <box size="0.09 0.16 0.04" />
        </geometry>
      </collision>
    <collision name="upright_1">
      <origin xyz="0.115 0 0.22" rpy="0 0 0" />
      <geometry>
        <box size="0.03 0.026 0.36" />
        </geometry>
      </collision>
    <collision name="slot_track_1">
      <origin xyz="0.115 0.0145 0.22" rpy="0 0 0" />
      <geometry>
        <box size="0.01 0.003 0.25" />
        </geometry>
      </collision>
    <collision name="desktop_foot_1">
      <origin xyz="0.115 0.025 0.02" rpy="0 0 0" />
      <geometry>
        <box size="0.09 0.16 0.04" />
        </geometry>
      </collision>
    <collision name="lower_crossbar">
      <origin xyz="0 0 0.056" rpy="0 0 0" />
      <geometry>
        <box size="0.305 0.03 0.032" />
        </geometry>
      </collision>
    <collision name="top_crossbar">
      <origin xyz="0 0 0.405" rpy="0 0 0" />
      <geometry>
        <box size="0.285 0.028 0.03" />
        </geometry>
      </collision>
    <collision name="upper_canvas_stop">
      <origin xyz="0 0.01 0.34" rpy="0 0 0" />
      <geometry>
        <box size="0.205 0.018 0.018" />
        </geometry>
      </collision>
    <collision name="hinge_leaf_0">
      <origin xyz="-0.0725 -0.021 0.405" rpy="0 0 0" />
      <geometry>
        <box size="0.05 0.02 0.045" />
        </geometry>
      </collision>
    <collision name="hinge_barrel_0">
      <origin xyz="-0.0725 -0.034 0.42" rpy="0 1.5708 0" />
      <geometry>
        <cylinder radius="0.012" length="0.065" />
        </geometry>
      </collision>
    <collision name="hinge_leaf_1">
      <origin xyz="0.0725 -0.021 0.405" rpy="0 0 0" />
      <geometry>
        <box size="0.05 0.02 0.045" />
        </geometry>
      </collision>
    <collision name="hinge_barrel_1">
      <origin xyz="0.0725 -0.034 0.42" rpy="0 1.5708 0" />
      <geometry>
        <cylinder radius="0.012" length="0.065" />
        </geometry>
      </collision>
    </link>
  <link name="rear_leg">
    <visual name="hinge_barrel">
      <origin xyz="0 0 0" rpy="0 1.5708 0" />
      <geometry>
        <cylinder radius="0.0125" length="0.08" />
        </geometry>
      <material name="brushed_steel">
        <color rgba="0.62 0.61 0.56 1" />
        </material>
      </visual>
    <visual name="hinge_yoke">
      <origin xyz="0 -0.019 -0.018" rpy="0 0 0" />
      <geometry>
        <box size="0.058 0.034 0.036" />
        </geometry>
      <material name="brushed_steel">
        <color rgba="0.62 0.61 0.56 1" />
        </material>
      </visual>
    <visual name="leg_strut">
      <origin xyz="0 -0.094 -0.199" rpy="2.7 0 0" />
      <geometry>
        <box size="0.034 0.028 0.38" />
        </geometry>
      <material name="warm_beech_wood">
        <color rgba="0.72 0.48 0.25 1" />
        </material>
      </visual>
    <visual name="rear_foot">
      <origin xyz="0 -0.175 -0.37" rpy="0 0 0" />
      <geometry>
        <box size="0.16 0.052 0.02" />
        </geometry>
      <material name="dark_rubber_feet">
        <color rgba="0.025 0.023 0.02 1" />
        </material>
      </visual>
    <collision name="hinge_barrel">
      <origin xyz="0 0 0" rpy="0 1.5708 0" />
      <geometry>
        <cylinder radius="0.0125" length="0.08" />
        </geometry>
      </collision>
    <collision name="hinge_yoke">
      <origin xyz="0 -0.019 -0.018" rpy="0 0 0" />
      <geometry>
        <box size="0.058 0.034 0.036" />
        </geometry>
      </collision>
    <collision name="leg_strut">
      <origin xyz="0 -0.094 -0.199" rpy="2.7 0 0" />
      <geometry>
        <box size="0.034 0.028 0.38" />
        </geometry>
      </collision>
    <collision name="rear_foot">
      <origin xyz="0 -0.175 -0.37" rpy="0 0 0" />
      <geometry>
        <box size="0.16 0.052 0.02" />
        </geometry>
      </collision>
    </link>
  <link name="ledge">
    <visual name="shelf_plank">
      <origin xyz="0 0.065 -0.01" rpy="0 0 0" />
      <geometry>
        <box size="0.34 0.07 0.022" />
        </geometry>
      <material name="warm_beech_wood">
        <color rgba="0.72 0.48 0.25 1" />
        </material>
      </visual>
    <visual name="front_lip">
      <origin xyz="0 0.104 0.01" rpy="0 0 0" />
      <geometry>
        <box size="0.34 0.018 0.046" />
        </geometry>
      <material name="warm_beech_wood">
        <color rgba="0.72 0.48 0.25 1" />
        </material>
      </visual>
    <visual name="rear_backplate">
      <origin xyz="0 0.028 0.01" rpy="0 0 0" />
      <geometry>
        <box size="0.3 0.018 0.06" />
        </geometry>
      <material name="warm_beech_wood">
        <color rgba="0.72 0.48 0.25 1" />
        </material>
      </visual>
    <visual name="slider_shoe_0">
      <origin xyz="-0.115 0.023 0.004" rpy="0 0 0" />
      <geometry>
        <box size="0.026 0.014 0.075" />
        </geometry>
      <material name="brushed_steel">
        <color rgba="0.62 0.61 0.56 1" />
        </material>
      </visual>
    <visual name="thumb_knob_0">
      <origin xyz="-0.115 0.043 0.004" rpy="1.5708 0 0" />
      <geometry>
        <cylinder radius="0.017" length="0.028" />
        </geometry>
      <material name="brushed_steel">
        <color rgba="0.62 0.61 0.56 1" />
        </material>
      </visual>
    <visual name="slider_shoe_1">
      <origin xyz="0.115 0.023 0.004" rpy="0 0 0" />
      <geometry>
        <box size="0.026 0.014 0.075" />
        </geometry>
      <material name="brushed_steel">
        <color rgba="0.62 0.61 0.56 1" />
        </material>
      </visual>
    <visual name="thumb_knob_1">
      <origin xyz="0.115 0.043 0.004" rpy="1.5708 0 0" />
      <geometry>
        <cylinder radius="0.017" length="0.028" />
        </geometry>
      <material name="brushed_steel">
        <color rgba="0.62 0.61 0.56 1" />
        </material>
      </visual>
    <collision name="shelf_plank">
      <origin xyz="0 0.065 -0.01" rpy="0 0 0" />
      <geometry>
        <box size="0.34 0.07 0.022" />
        </geometry>
      </collision>
    <collision name="front_lip">
      <origin xyz="0 0.104 0.01" rpy="0 0 0" />
      <geometry>
        <box size="0.34 0.018 0.046" />
        </geometry>
      </collision>
    <collision name="rear_backplate">
      <origin xyz="0 0.028 0.01" rpy="0 0 0" />
      <geometry>
        <box size="0.3 0.018 0.06" />
        </geometry>
      </collision>
    <collision name="slider_shoe_0">
      <origin xyz="-0.115 0.023 0.004" rpy="0 0 0" />
      <geometry>
        <box size="0.026 0.014 0.075" />
        </geometry>
      </collision>
    <collision name="thumb_knob_0">
      <origin xyz="-0.115 0.043 0.004" rpy="1.5708 0 0" />
      <geometry>
        <cylinder radius="0.017" length="0.028" />
        </geometry>
      </collision>
    <collision name="slider_shoe_1">
      <origin xyz="0.115 0.023 0.004" rpy="0 0 0" />
      <geometry>
        <box size="0.026 0.014 0.075" />
        </geometry>
      </collision>
    <collision name="thumb_knob_1">
      <origin xyz="0.115 0.043 0.004" rpy="1.5708 0 0" />
      <geometry>
        <cylinder radius="0.017" length="0.028" />
        </geometry>
      </collision>
    </link>
  <joint name="rear_hinge" type="revolute">
    <origin xyz="0 -0.034 0.42" rpy="0 0 0" />
    <parent link="frame" />
    <child link="rear_leg" />
    <axis xyz="1 0 0" />
    <limit effort="3" velocity="1.5" lower="0" upper="0.45" />
    </joint>
  <joint name="ledge_slide" type="prismatic">
    <origin xyz="0 0 0.13" rpy="0 0 0" />
    <parent link="frame" />
    <child link="ledge" />
    <axis xyz="0 0 1" />
    <limit effort="12" velocity="0.18" lower="0" upper="0.17" />
    </joint>
  </robot>
