<robot name="compact_serial_elbow_arm">
  <material name="cast_graphite">
    <color rgba="0.18 0.19 0.2 1" />
    </material>
  <material name="blue_anodized_link">
    <color rgba="0.08 0.2 0.36 1" />
    </material>
  <material name="brushed_steel">
    <color rgba="0.7 0.72 0.7 1" />
    </material>
  <material name="dark_ribbed_metal">
    <color rgba="0.07 0.08 0.09 1" />
    </material>
  <material name="matte_black_pad">
    <color rgba="0.015 0.015 0.014 1" />
    </material>
  <link name="shoulder_housing">
    <visual name="base_plate">
      <origin xyz="0.02 0 0.03" rpy="0 0 0" />
      <geometry>
        <box size="0.58 0.6 0.06" />
        </geometry>
      <material name="cast_graphite">
        <color rgba="0.18 0.19 0.2 1" />
        </material>
      </visual>
    <visual name="cast_pedestal">
      <origin xyz="-0.04 0 0.195" rpy="0 0 0" />
      <geometry>
        <box size="0.25 0.42 0.29" />
        </geometry>
      <material name="cast_graphite">
        <color rgba="0.18 0.19 0.2 1" />
        </material>
      </visual>
    <visual name="shoulder_cheek_pos">
      <origin xyz="-0.02 0.205 0.385" rpy="0 0 0" />
      <geometry>
        <box size="0.16 0.09 0.26" />
        </geometry>
      <material name="cast_graphite">
        <color rgba="0.18 0.19 0.2 1" />
        </material>
      </visual>
    <visual name="shoulder_boss_pos">
      <origin xyz="0 0.205 0.46" rpy="-1.5708 0 0" />
      <geometry>
        <cylinder radius="0.145" length="0.1" />
        </geometry>
      <material name="cast_graphite">
        <color rgba="0.18 0.19 0.2 1" />
        </material>
      </visual>
    <visual name="shoulder_cap_pos">
      <origin xyz="0 0.272 0.46" rpy="-1.5708 0 0" />
      <geometry>
        <cylinder radius="0.1" length="0.035" />
        </geometry>
      <material name="brushed_steel">
        <color rgba="0.7 0.72 0.7 1" />
        </material>
      </visual>
    <visual name="shoulder_cheek_neg">
      <origin xyz="-0.02 -0.205 0.385" rpy="0 0 0" />
      <geometry>
        <box size="0.16 0.09 0.26" />
        </geometry>
      <material name="cast_graphite">
        <color rgba="0.18 0.19 0.2 1" />
        </material>
      </visual>
    <visual name="shoulder_boss_neg">
      <origin xyz="0 -0.205 0.46" rpy="-1.5708 0 0" />
      <geometry>
        <cylinder radius="0.145" length="0.1" />
        </geometry>
      <material name="cast_graphite">
        <color rgba="0.18 0.19 0.2 1" />
        </material>
      </visual>
    <visual name="shoulder_cap_neg">
      <origin xyz="0 -0.272 0.46" rpy="-1.5708 0 0" />
      <geometry>
        <cylinder radius="0.1" length="0.035" />
        </geometry>
      <material name="brushed_steel">
        <color rgba="0.7 0.72 0.7 1" />
        </material>
      </visual>
    <visual name="base_bolt_n_n">
      <origin xyz="-0.2 -0.23 0.063" rpy="0 0 0" />
      <geometry>
        <cylinder radius="0.018" length="0.014" />
        </geometry>
      <material name="brushed_steel">
        <color rgba="0.7 0.72 0.7 1" />
        </material>
      </visual>
    <visual name="base_bolt_n_p">
      <origin xyz="-0.2 0.23 0.063" rpy="0 0 0" />
      <geometry>
        <cylinder radius="0.018" length="0.014" />
        </geometry>
      <material name="brushed_steel">
        <color rgba="0.7 0.72 0.7 1" />
        </material>
      </visual>
    <visual name="base_bolt_p_n">
      <origin xyz="0.24 -0.23 0.063" rpy="0 0 0" />
      <geometry>
        <cylinder radius="0.018" length="0.014" />
        </geometry>
      <material name="brushed_steel">
        <color rgba="0.7 0.72 0.7 1" />
        </material>
      </visual>
    <visual name="base_bolt_p_p">
      <origin xyz="0.24 0.23 0.063" rpy="0 0 0" />
      <geometry>
        <cylinder radius="0.018" length="0.014" />
        </geometry>
      <material name="brushed_steel">
        <color rgba="0.7 0.72 0.7 1" />
        </material>
      </visual>
    <collision name="base_plate">
      <origin xyz="0.02 0 0.03" rpy="0 0 0" />
      <geometry>
        <box size="0.58 0.6 0.06" />
        </geometry>
      </collision>
    <collision name="cast_pedestal">
      <origin xyz="-0.04 0 0.195" rpy="0 0 0" />
      <geometry>
        <box size="0.25 0.42 0.29" />
        </geometry>
      </collision>
    <collision name="shoulder_cheek_pos">
      <origin xyz="-0.02 0.205 0.385" rpy="0 0 0" />
      <geometry>
        <box size="0.16 0.09 0.26" />
        </geometry>
      </collision>
    <collision name="shoulder_boss_pos">
      <origin xyz="0 0.205 0.46" rpy="-1.5708 0 0" />
      <geometry>
        <cylinder radius="0.145" length="0.1" />
        </geometry>
      </collision>
    <collision name="shoulder_cap_pos">
      <origin xyz="0 0.272 0.46" rpy="-1.5708 0 0" />
      <geometry>
        <cylinder radius="0.1" length="0.035" />
        </geometry>
      </collision>
    <collision name="shoulder_cheek_neg">
      <origin xyz="-0.02 -0.205 0.385" rpy="0 0 0" />
      <geometry>
        <box size="0.16 0.09 0.26" />
        </geometry>
      </collision>
    <collision name="shoulder_boss_neg">
      <origin xyz="0 -0.205 0.46" rpy="-1.5708 0 0" />
      <geometry>
        <cylinder radius="0.145" length="0.1" />
        </geometry>
      </collision>
    <collision name="shoulder_cap_neg">
      <origin xyz="0 -0.272 0.46" rpy="-1.5708 0 0" />
      <geometry>
        <cylinder radius="0.1" length="0.035" />
        </geometry>
      </collision>
    <collision name="base_bolt_n_n">
      <origin xyz="-0.2 -0.23 0.063" rpy="0 0 0" />
      <geometry>
        <cylinder radius="0.018" length="0.014" />
        </geometry>
      </collision>
    <collision name="base_bolt_n_p">
      <origin xyz="-0.2 0.23 0.063" rpy="0 0 0" />
      <geometry>
        <cylinder radius="0.018" length="0.014" />
        </geometry>
      </collision>
    <collision name="base_bolt_p_n">
      <origin xyz="0.24 -0.23 0.063" rpy="0 0 0" />
      <geometry>
        <cylinder radius="0.018" length="0.014" />
        </geometry>
      </collision>
    <collision name="base_bolt_p_p">
      <origin xyz="0.24 0.23 0.063" rpy="0 0 0" />
      <geometry>
        <cylinder radius="0.018" length="0.014" />
        </geometry>
      </collision>
    </link>
  <link name="upper_link">
    <visual name="shoulder_collar">
      <origin xyz="0 0 0" rpy="-1.5708 0 0" />
      <geometry>
        <cylinder radius="0.105" length="0.27" />
        </geometry>
      <material name="brushed_steel">
        <color rgba="0.7 0.72 0.7 1" />
        </material>
      </visual>
    <visual name="shoulder_face_pos">
      <origin xyz="0 0.123 0" rpy="-1.5708 0 0" />
      <geometry>
        <cylinder radius="0.123" length="0.025" />
        </geometry>
      <material name="brushed_steel">
        <color rgba="0.7 0.72 0.7 1" />
        </material>
      </visual>
    <visual name="shoulder_face_neg">
      <origin xyz="0 -0.123 0" rpy="-1.5708 0 0" />
      <geometry>
        <cylinder radius="0.123" length="0.025" />
        </geometry>
      <material name="brushed_steel">
        <color rgba="0.7 0.72 0.7 1" />
        </material>
      </visual>
    <visual name="upper_beam">
      <origin xyz="0.35 0 0" rpy="0 0 0" />
      <geometry>
        <box size="0.5 0.1 0.13" />
        </geometry>
      <material name="blue_anodized_link">
        <color rgba="0.08 0.2 0.36 1" />
        </material>
      </visual>
    <visual name="upper_rib_top">
      <origin xyz="0.36 0 0.075" rpy="0 0 0" />
      <geometry>
        <box size="0.45 0.13 0.03" />
        </geometry>
      <material name="blue_anodized_link">
        <color rgba="0.08 0.2 0.36 1" />
        </material>
      </visual>
    <visual name="upper_rib_bottom">
      <origin xyz="0.36 0 -0.075" rpy="0 0 0" />
      <geometry>
        <box size="0.45 0.13 0.03" />
        </geometry>
      <material name="blue_anodized_link">
        <color rgba="0.08 0.2 0.36 1" />
        </material>
      </visual>
    <visual name="upper_side_rib_pos">
      <origin xyz="0.35 0.066 0" rpy="0 0 0" />
      <geometry>
        <box size="0.46 0.04 0.16" />
        </geometry>
      <material name="dark_ribbed_metal">
        <color rgba="0.07 0.08 0.09 1" />
        </material>
      </visual>
    <visual name="elbow_cheek_pos">
      <origin xyz="0.64 0.114 0" rpy="0 0 0" />
      <geometry>
        <box size="0.22 0.06 0.12" />
        </geometry>
      <material name="blue_anodized_link">
        <color rgba="0.08 0.2 0.36 1" />
        </material>
      </visual>
    <visual name="elbow_boss_pos">
      <origin xyz="0.75 0.161 0" rpy="-1.5708 0 0" />
      <geometry>
        <cylinder radius="0.145" length="0.08" />
        </geometry>
      <material name="blue_anodized_link">
        <color rgba="0.08 0.2 0.36 1" />
        </material>
      </visual>
    <visual name="elbow_cap_pos">
      <origin xyz="0.75 0.216 0" rpy="-1.5708 0 0" />
      <geometry>
        <cylinder radius="0.105" length="0.03" />
        </geometry>
      <material name="brushed_steel">
        <color rgba="0.7 0.72 0.7 1" />
        </material>
      </visual>
    <visual name="upper_side_rib_neg">
      <origin xyz="0.35 -0.066 0" rpy="0 0 0" />
      <geometry>
        <box size="0.46 0.04 0.16" />
        </geometry>
      <material name="dark_ribbed_metal">
        <color rgba="0.07 0.08 0.09 1" />
        </material>
      </visual>
    <visual name="elbow_cheek_neg">
      <origin xyz="0.64 -0.114 0" rpy="0 0 0" />
      <geometry>
        <box size="0.22 0.06 0.12" />
        </geometry>
      <material name="blue_anodized_link">
        <color rgba="0.08 0.2 0.36 1" />
        </material>
      </visual>
    <visual name="elbow_boss_neg">
      <origin xyz="0.75 -0.161 0" rpy="-1.5708 0 0" />
      <geometry>
        <cylinder radius="0.145" length="0.08" />
        </geometry>
      <material name="blue_anodized_link">
        <color rgba="0.08 0.2 0.36 1" />
        </material>
      </visual>
    <visual name="elbow_cap_neg">
      <origin xyz="0.75 -0.216 0" rpy="-1.5708 0 0" />
      <geometry>
        <cylinder radius="0.105" length="0.03" />
        </geometry>
      <material name="brushed_steel">
        <color rgba="0.7 0.72 0.7 1" />
        </material>
      </visual>
    <collision name="shoulder_collar">
      <origin xyz="0 0 0" rpy="-1.5708 0 0" />
      <geometry>
        <cylinder radius="0.105" length="0.27" />
        </geometry>
      </collision>
    <collision name="shoulder_face_pos">
      <origin xyz="0 0.123 0" rpy="-1.5708 0 0" />
      <geometry>
        <cylinder radius="0.123" length="0.025" />
        </geometry>
      </collision>
    <collision name="shoulder_face_neg">
      <origin xyz="0 -0.123 0" rpy="-1.5708 0 0" />
      <geometry>
        <cylinder radius="0.123" length="0.025" />
        </geometry>
      </collision>
    <collision name="upper_beam">
      <origin xyz="0.35 0 0" rpy="0 0 0" />
      <geometry>
        <box size="0.5 0.1 0.13" />
        </geometry>
      </collision>
    <collision name="upper_rib_top">
      <origin xyz="0.36 0 0.075" rpy="0 0 0" />
      <geometry>
        <box size="0.45 0.13 0.03" />
        </geometry>
      </collision>
    <collision name="upper_rib_bottom">
      <origin xyz="0.36 0 -0.075" rpy="0 0 0" />
      <geometry>
        <box size="0.45 0.13 0.03" />
        </geometry>
      </collision>
    <collision name="upper_side_rib_pos">
      <origin xyz="0.35 0.066 0" rpy="0 0 0" />
      <geometry>
        <box size="0.46 0.04 0.16" />
        </geometry>
      </collision>
    <collision name="elbow_cheek_pos">
      <origin xyz="0.64 0.114 0" rpy="0 0 0" />
      <geometry>
        <box size="0.22 0.06 0.12" />
        </geometry>
      </collision>
    <collision name="elbow_boss_pos">
      <origin xyz="0.75 0.161 0" rpy="-1.5708 0 0" />
      <geometry>
        <cylinder radius="0.145" length="0.08" />
        </geometry>
      </collision>
    <collision name="elbow_cap_pos">
      <origin xyz="0.75 0.216 0" rpy="-1.5708 0 0" />
      <geometry>
        <cylinder radius="0.105" length="0.03" />
        </geometry>
      </collision>
    <collision name="upper_side_rib_neg">
      <origin xyz="0.35 -0.066 0" rpy="0 0 0" />
      <geometry>
        <box size="0.46 0.04 0.16" />
        </geometry>
      </collision>
    <collision name="elbow_cheek_neg">
      <origin xyz="0.64 -0.114 0" rpy="0 0 0" />
      <geometry>
        <box size="0.22 0.06 0.12" />
        </geometry>
      </collision>
    <collision name="elbow_boss_neg">
      <origin xyz="0.75 -0.161 0" rpy="-1.5708 0 0" />
      <geometry>
        <cylinder radius="0.145" length="0.08" />
        </geometry>
      </collision>
    <collision name="elbow_cap_neg">
      <origin xyz="0.75 -0.216 0" rpy="-1.5708 0 0" />
      <geometry>
        <cylinder radius="0.105" length="0.03" />
        </geometry>
      </collision>
    </link>
  <link name="forearm">
    <visual name="elbow_trunnion">
      <origin xyz="0 0 0" rpy="-1.5708 0 0" />
      <geometry>
        <cylinder radius="0.1" length="0.168" />
        </geometry>
      <material name="brushed_steel">
        <color rgba="0.7 0.72 0.7 1" />
        </material>
      </visual>
    <visual name="forearm_spine">
      <origin xyz="0.24 0 0" rpy="0 0 0" />
      <geometry>
        <box size="0.34 0.16 0.07" />
        </geometry>
      <material name="cast_graphite">
        <color rgba="0.18 0.19 0.2 1" />
        </material>
      </visual>
    <visual name="forearm_side_rib_pos">
      <origin xyz="0.25 0.083 0" rpy="0 0 0" />
      <geometry>
        <box size="0.28 0.035 0.11" />
        </geometry>
      <material name="dark_ribbed_metal">
        <color rgba="0.07 0.08 0.09 1" />
        </material>
      </visual>
    <visual name="forearm_side_rib_neg">
      <origin xyz="0.25 -0.083 0" rpy="0 0 0" />
      <geometry>
        <box size="0.28 0.035 0.11" />
        </geometry>
      <material name="dark_ribbed_metal">
        <color rgba="0.07 0.08 0.09 1" />
        </material>
      </visual>
    <visual name="pad_plate">
      <origin xyz="0.46 0 0" rpy="0 0 0" />
      <geometry>
        <box size="0.12 0.24 0.1" />
        </geometry>
      <material name="cast_graphite">
        <color rgba="0.18 0.19 0.2 1" />
        </material>
      </visual>
    <visual name="rubber_face">
      <origin xyz="0.526 0 0" rpy="0 0 0" />
      <geometry>
        <box size="0.016 0.265 0.12" />
        </geometry>
      <material name="matte_black_pad">
        <color rgba="0.015 0.015 0.014 1" />
        </material>
      </visual>
    <collision name="elbow_trunnion">
      <origin xyz="0 0 0" rpy="-1.5708 0 0" />
      <geometry>
        <cylinder radius="0.1" length="0.168" />
        </geometry>
      </collision>
    <collision name="forearm_spine">
      <origin xyz="0.24 0 0" rpy="0 0 0" />
      <geometry>
        <box size="0.34 0.16 0.07" />
        </geometry>
      </collision>
    <collision name="forearm_side_rib_pos">
      <origin xyz="0.25 0.083 0" rpy="0 0 0" />
      <geometry>
        <box size="0.28 0.035 0.11" />
        </geometry>
      </collision>
    <collision name="forearm_side_rib_neg">
      <origin xyz="0.25 -0.083 0" rpy="0 0 0" />
      <geometry>
        <box size="0.28 0.035 0.11" />
        </geometry>
      </collision>
    <collision name="pad_plate">
      <origin xyz="0.46 0 0" rpy="0 0 0" />
      <geometry>
        <box size="0.12 0.24 0.1" />
        </geometry>
      </collision>
    <collision name="rubber_face">
      <origin xyz="0.526 0 0" rpy="0 0 0" />
      <geometry>
        <box size="0.016 0.265 0.12" />
        </geometry>
      </collision>
    </link>
  <joint name="shoulder_revolute" type="revolute">
    <origin xyz="0 0 0.46" rpy="0 0 0" />
    <parent link="shoulder_housing" />
    <child link="upper_link" />
    <axis xyz="0 -1 0" />
    <limit effort="130" velocity="1.4" lower="0" upper="1.05" />
    </joint>
  <joint name="elbow_revolute" type="revolute">
    <origin xyz="0.75 0 0" rpy="0 0.6 0" />
    <parent link="upper_link" />
    <child link="forearm" />
    <axis xyz="0 -1 0" />
    <limit effort="90" velocity="1.7" lower="0" upper="0.65" />
    </joint>
  </robot>
