<robot name="ladder_frame_lever_chain">
  <material name="bracket_dark">
    <color rgba="0.12 0.13 0.15 1" />
    </material>
  <material name="base_black">
    <color rgba="0.055 0.058 0.065 1" />
    </material>
  <material name="link_steel">
    <color rgba="0.68 0.7 0.72 1" />
    </material>
  <material name="hub_steel">
    <color rgba="0.44 0.46 0.48 1" />
    </material>
  <material name="tab_steel">
    <color rgba="0.74 0.7 0.58 1" />
    </material>
  <material name="bore_shadow">
    <color rgba="0.015 0.016 0.018 1" />
    </material>
  <link name="root_bracket">
    <visual name="floor_plate">
      <origin xyz="-0.02 0 0.0175" rpy="0 0 0" />
      <geometry>
        <box size="0.22 0.16 0.035" />
        </geometry>
      <material name="base_black" />
      </visual>
    <visual name="raised_pad">
      <origin xyz="-0.015 0 0.0475" rpy="0 0 0" />
      <geometry>
        <box size="0.095 0.12 0.025" />
        </geometry>
      <material name="bracket_dark" />
      </visual>
    <visual name="cheek_0">
      <origin xyz="0 -0.036 0.12" rpy="0 0 0" />
      <geometry>
        <box size="0.07 0.014 0.17" />
        </geometry>
      <material name="bracket_dark" />
      </visual>
    <visual name="cheek_boss_0">
      <origin xyz="0 -0.036 0.2" rpy="1.5708 0 0" />
      <geometry>
        <cylinder radius="0.036" length="0.016" />
        </geometry>
      <material name="bracket_dark" />
      </visual>
    <visual name="cheek_bore_0">
      <origin xyz="0 -0.045 0.2" rpy="1.5708 0 0" />
      <geometry>
        <cylinder radius="0.011" length="0.004" />
        </geometry>
      <material name="bore_shadow" />
      </visual>
    <visual name="cheek_1">
      <origin xyz="0 0.036 0.12" rpy="0 0 0" />
      <geometry>
        <box size="0.07 0.014 0.17" />
        </geometry>
      <material name="bracket_dark" />
      </visual>
    <visual name="cheek_boss_1">
      <origin xyz="0 0.036 0.2" rpy="1.5708 0 0" />
      <geometry>
        <cylinder radius="0.036" length="0.016" />
        </geometry>
      <material name="bracket_dark" />
      </visual>
    <visual name="cheek_bore_1">
      <origin xyz="0 0.045 0.2" rpy="1.5708 0 0" />
      <geometry>
        <cylinder radius="0.011" length="0.004" />
        </geometry>
      <material name="bore_shadow" />
      </visual>
    <visual name="rear_web">
      <origin xyz="-0.046 0 0.09" rpy="0 0 0" />
      <geometry>
        <box size="0.026 0.124 0.085" />
        </geometry>
      <material name="bracket_dark" />
      </visual>
    <visual name="ground_side_plate_0">
      <origin xyz="-0.1425 -0.036 0.2" rpy="0 0 0" />
      <geometry>
        <box size="0.285 0.008 0.026" />
        </geometry>
      <material name="bracket_dark" />
      </visual>
    <visual name="ground_tail_boss_0">
      <origin xyz="-0.285 -0.036 0.2" rpy="1.5708 0 0" />
      <geometry>
        <cylinder radius="0.027" length="0.02" />
        </geometry>
      <material name="bracket_dark" />
      </visual>
    <visual name="ground_tail_bore_0">
      <origin xyz="-0.285 -0.045 0.2" rpy="1.5708 0 0" />
      <geometry>
        <cylinder radius="0.009" length="0.004" />
        </geometry>
      <material name="bore_shadow" />
      </visual>
    <visual name="ground_side_plate_1">
      <origin xyz="-0.1425 0.036 0.2" rpy="0 0 0" />
      <geometry>
        <box size="0.285 0.008 0.026" />
        </geometry>
      <material name="bracket_dark" />
      </visual>
    <visual name="ground_tail_boss_1">
      <origin xyz="-0.285 0.036 0.2" rpy="1.5708 0 0" />
      <geometry>
        <cylinder radius="0.027" length="0.02" />
        </geometry>
      <material name="bracket_dark" />
      </visual>
    <visual name="ground_tail_bore_1">
      <origin xyz="-0.285 0.045 0.2" rpy="1.5708 0 0" />
      <geometry>
        <cylinder radius="0.009" length="0.004" />
        </geometry>
      <material name="bore_shadow" />
      </visual>
    <visual name="ground_cross_rung">
      <origin xyz="-0.155 0 0.2" rpy="0 0 0" />
      <geometry>
        <box size="0.03 0.084 0.014" />
        </geometry>
      <material name="bracket_dark" />
      </visual>
    <collision name="floor_plate">
      <origin xyz="-0.02 0 0.0175" rpy="0 0 0" />
      <geometry>
        <box size="0.22 0.16 0.035" />
        </geometry>
      </collision>
    <collision name="raised_pad">
      <origin xyz="-0.015 0 0.0475" rpy="0 0 0" />
      <geometry>
        <box size="0.095 0.12 0.025" />
        </geometry>
      </collision>
    <collision name="cheek_0">
      <origin xyz="0 -0.036 0.12" rpy="0 0 0" />
      <geometry>
        <box size="0.07 0.014 0.17" />
        </geometry>
      </collision>
    <collision name="cheek_boss_0">
      <origin xyz="0 -0.036 0.2" rpy="1.5708 0 0" />
      <geometry>
        <cylinder radius="0.036" length="0.016" />
        </geometry>
      </collision>
    <collision name="cheek_bore_0">
      <origin xyz="0 -0.045 0.2" rpy="1.5708 0 0" />
      <geometry>
        <cylinder radius="0.011" length="0.004" />
        </geometry>
      </collision>
    <collision name="cheek_1">
      <origin xyz="0 0.036 0.12" rpy="0 0 0" />
      <geometry>
        <box size="0.07 0.014 0.17" />
        </geometry>
      </collision>
    <collision name="cheek_boss_1">
      <origin xyz="0 0.036 0.2" rpy="1.5708 0 0" />
      <geometry>
        <cylinder radius="0.036" length="0.016" />
        </geometry>
      </collision>
    <collision name="cheek_bore_1">
      <origin xyz="0 0.045 0.2" rpy="1.5708 0 0" />
      <geometry>
        <cylinder radius="0.011" length="0.004" />
        </geometry>
      </collision>
    <collision name="rear_web">
      <origin xyz="-0.046 0 0.09" rpy="0 0 0" />
      <geometry>
        <box size="0.026 0.124 0.085" />
        </geometry>
      </collision>
    <collision name="ground_side_plate_0">
      <origin xyz="-0.1425 -0.036 0.2" rpy="0 0 0" />
      <geometry>
        <box size="0.285 0.008 0.026" />
        </geometry>
      </collision>
    <collision name="ground_tail_boss_0">
      <origin xyz="-0.285 -0.036 0.2" rpy="1.5708 0 0" />
      <geometry>
        <cylinder radius="0.027" length="0.02" />
        </geometry>
      </collision>
    <collision name="ground_tail_bore_0">
      <origin xyz="-0.285 -0.045 0.2" rpy="1.5708 0 0" />
      <geometry>
        <cylinder radius="0.009" length="0.004" />
        </geometry>
      </collision>
    <collision name="ground_side_plate_1">
      <origin xyz="-0.1425 0.036 0.2" rpy="0 0 0" />
      <geometry>
        <box size="0.285 0.008 0.026" />
        </geometry>
      </collision>
    <collision name="ground_tail_boss_1">
      <origin xyz="-0.285 0.036 0.2" rpy="1.5708 0 0" />
      <geometry>
        <cylinder radius="0.027" length="0.02" />
        </geometry>
      </collision>
    <collision name="ground_tail_bore_1">
      <origin xyz="-0.285 0.045 0.2" rpy="1.5708 0 0" />
      <geometry>
        <cylinder radius="0.009" length="0.004" />
        </geometry>
      </collision>
    <collision name="ground_cross_rung">
      <origin xyz="-0.155 0 0.2" rpy="0 0 0" />
      <geometry>
        <box size="0.03 0.084 0.014" />
        </geometry>
      </collision>
    </link>
  <link name="link_0">
    <visual name="side_plate_0">
      <origin xyz="0.2 -0.018 0" rpy="0 0 0" />
      <geometry>
        <box size="0.4 0.008 0.026" />
        </geometry>
      <material name="link_steel" />
      </visual>
    <visual name="proximal_boss_0">
      <origin xyz="0 -0.018 0" rpy="1.5708 0 0" />
      <geometry>
        <cylinder radius="0.027" length="0.02" />
        </geometry>
      <material name="hub_steel" />
      </visual>
    <visual name="proximal_bore_0">
      <origin xyz="0 -0.0256 0" rpy="1.5708 0 0" />
      <geometry>
        <cylinder radius="0.009" length="0.0025" />
        </geometry>
      <material name="bore_shadow" />
      </visual>
    <visual name="distal_boss_0">
      <origin xyz="0.4 -0.018 0" rpy="1.5708 0 0" />
      <geometry>
        <cylinder radius="0.027" length="0.02" />
        </geometry>
      <material name="hub_steel" />
      </visual>
    <visual name="distal_bore_0">
      <origin xyz="0.4 -0.0256 0" rpy="1.5708 0 0" />
      <geometry>
        <cylinder radius="0.009" length="0.0025" />
        </geometry>
      <material name="bore_shadow" />
      </visual>
    <visual name="side_plate_1">
      <origin xyz="0.2 0.018 0" rpy="0 0 0" />
      <geometry>
        <box size="0.4 0.008 0.026" />
        </geometry>
      <material name="link_steel" />
      </visual>
    <visual name="proximal_boss_1">
      <origin xyz="0 0.018 0" rpy="1.5708 0 0" />
      <geometry>
        <cylinder radius="0.027" length="0.02" />
        </geometry>
      <material name="hub_steel" />
      </visual>
    <visual name="proximal_bore_1">
      <origin xyz="0 0.0256 0" rpy="1.5708 0 0" />
      <geometry>
        <cylinder radius="0.009" length="0.0025" />
        </geometry>
      <material name="bore_shadow" />
      </visual>
    <visual name="distal_boss_1">
      <origin xyz="0.4 0.018 0" rpy="1.5708 0 0" />
      <geometry>
        <cylinder radius="0.027" length="0.02" />
        </geometry>
      <material name="hub_steel" />
      </visual>
    <visual name="distal_bore_1">
      <origin xyz="0.4 0.0256 0" rpy="1.5708 0 0" />
      <geometry>
        <cylinder radius="0.009" length="0.0025" />
        </geometry>
      <material name="bore_shadow" />
      </visual>
    <visual name="cross_rung_0">
      <origin xyz="0.136 0 0" rpy="0 0 0" />
      <geometry>
        <box size="0.03 0.044 0.014" />
        </geometry>
      <material name="hub_steel" />
      </visual>
    <visual name="cross_rung_1">
      <origin xyz="0.28 0 0" rpy="0 0 0" />
      <geometry>
        <box size="0.03 0.044 0.014" />
        </geometry>
      <material name="hub_steel" />
      </visual>
    <collision name="side_plate_0">
      <origin xyz="0.2 -0.018 0" rpy="0 0 0" />
      <geometry>
        <box size="0.4 0.008 0.026" />
        </geometry>
      </collision>
    <collision name="proximal_boss_0">
      <origin xyz="0 -0.018 0" rpy="1.5708 0 0" />
      <geometry>
        <cylinder radius="0.027" length="0.02" />
        </geometry>
      </collision>
    <collision name="proximal_bore_0">
      <origin xyz="0 -0.0256 0" rpy="1.5708 0 0" />
      <geometry>
        <cylinder radius="0.009" length="0.0025" />
        </geometry>
      </collision>
    <collision name="distal_boss_0">
      <origin xyz="0.4 -0.018 0" rpy="1.5708 0 0" />
      <geometry>
        <cylinder radius="0.027" length="0.02" />
        </geometry>
      </collision>
    <collision name="distal_bore_0">
      <origin xyz="0.4 -0.0256 0" rpy="1.5708 0 0" />
      <geometry>
        <cylinder radius="0.009" length="0.0025" />
        </geometry>
      </collision>
    <collision name="side_plate_1">
      <origin xyz="0.2 0.018 0" rpy="0 0 0" />
      <geometry>
        <box size="0.4 0.008 0.026" />
        </geometry>
      </collision>
    <collision name="proximal_boss_1">
      <origin xyz="0 0.018 0" rpy="1.5708 0 0" />
      <geometry>
        <cylinder radius="0.027" length="0.02" />
        </geometry>
      </collision>
    <collision name="proximal_bore_1">
      <origin xyz="0 0.0256 0" rpy="1.5708 0 0" />
      <geometry>
        <cylinder radius="0.009" length="0.0025" />
        </geometry>
      </collision>
    <collision name="distal_boss_1">
      <origin xyz="0.4 0.018 0" rpy="1.5708 0 0" />
      <geometry>
        <cylinder radius="0.027" length="0.02" />
        </geometry>
      </collision>
    <collision name="distal_bore_1">
      <origin xyz="0.4 0.0256 0" rpy="1.5708 0 0" />
      <geometry>
        <cylinder radius="0.009" length="0.0025" />
        </geometry>
      </collision>
    <collision name="cross_rung_0">
      <origin xyz="0.136 0 0" rpy="0 0 0" />
      <geometry>
        <box size="0.03 0.044 0.014" />
        </geometry>
      </collision>
    <collision name="cross_rung_1">
      <origin xyz="0.28 0 0" rpy="0 0 0" />
      <geometry>
        <box size="0.03 0.044 0.014" />
        </geometry>
      </collision>
    </link>
  <link name="link_1">
    <visual name="side_plate_0">
      <origin xyz="0.165 -0.038 0" rpy="0 0 0" />
      <geometry>
        <box size="0.33 0.008 0.026" />
        </geometry>
      <material name="link_steel" />
      </visual>
    <visual name="proximal_boss_0">
      <origin xyz="0 -0.038 0" rpy="1.5708 0 0" />
      <geometry>
        <cylinder radius="0.027" length="0.02" />
        </geometry>
      <material name="hub_steel" />
      </visual>
    <visual name="proximal_bore_0">
      <origin xyz="0 -0.0456 0" rpy="1.5708 0 0" />
      <geometry>
        <cylinder radius="0.009" length="0.0025" />
        </geometry>
      <material name="bore_shadow" />
      </visual>
    <visual name="distal_boss_0">
      <origin xyz="0.33 -0.038 0" rpy="1.5708 0 0" />
      <geometry>
        <cylinder radius="0.027" length="0.02" />
        </geometry>
      <material name="hub_steel" />
      </visual>
    <visual name="distal_bore_0">
      <origin xyz="0.33 -0.0456 0" rpy="1.5708 0 0" />
      <geometry>
        <cylinder radius="0.009" length="0.0025" />
        </geometry>
      <material name="bore_shadow" />
      </visual>
    <visual name="side_plate_1">
      <origin xyz="0.165 0.038 0" rpy="0 0 0" />
      <geometry>
        <box size="0.33 0.008 0.026" />
        </geometry>
      <material name="link_steel" />
      </visual>
    <visual name="proximal_boss_1">
      <origin xyz="0 0.038 0" rpy="1.5708 0 0" />
      <geometry>
        <cylinder radius="0.027" length="0.02" />
        </geometry>
      <material name="hub_steel" />
      </visual>
    <visual name="proximal_bore_1">
      <origin xyz="0 0.0456 0" rpy="1.5708 0 0" />
      <geometry>
        <cylinder radius="0.009" length="0.0025" />
        </geometry>
      <material name="bore_shadow" />
      </visual>
    <visual name="distal_boss_1">
      <origin xyz="0.33 0.038 0" rpy="1.5708 0 0" />
      <geometry>
        <cylinder radius="0.027" length="0.02" />
        </geometry>
      <material name="hub_steel" />
      </visual>
    <visual name="distal_bore_1">
      <origin xyz="0.33 0.0456 0" rpy="1.5708 0 0" />
      <geometry>
        <cylinder radius="0.009" length="0.0025" />
        </geometry>
      <material name="bore_shadow" />
      </visual>
    <visual name="cross_rung_0">
      <origin xyz="0.1122 0 0" rpy="0 0 0" />
      <geometry>
        <box size="0.03 0.084 0.014" />
        </geometry>
      <material name="hub_steel" />
      </visual>
    <visual name="cross_rung_1">
      <origin xyz="0.231 0 0" rpy="0 0 0" />
      <geometry>
        <box size="0.03 0.084 0.014" />
        </geometry>
      <material name="hub_steel" />
      </visual>
    <collision name="side_plate_0">
      <origin xyz="0.165 -0.038 0" rpy="0 0 0" />
      <geometry>
        <box size="0.33 0.008 0.026" />
        </geometry>
      </collision>
    <collision name="proximal_boss_0">
      <origin xyz="0 -0.038 0" rpy="1.5708 0 0" />
      <geometry>
        <cylinder radius="0.027" length="0.02" />
        </geometry>
      </collision>
    <collision name="proximal_bore_0">
      <origin xyz="0 -0.0456 0" rpy="1.5708 0 0" />
      <geometry>
        <cylinder radius="0.009" length="0.0025" />
        </geometry>
      </collision>
    <collision name="distal_boss_0">
      <origin xyz="0.33 -0.038 0" rpy="1.5708 0 0" />
      <geometry>
        <cylinder radius="0.027" length="0.02" />
        </geometry>
      </collision>
    <collision name="distal_bore_0">
      <origin xyz="0.33 -0.0456 0" rpy="1.5708 0 0" />
      <geometry>
        <cylinder radius="0.009" length="0.0025" />
        </geometry>
      </collision>
    <collision name="side_plate_1">
      <origin xyz="0.165 0.038 0" rpy="0 0 0" />
      <geometry>
        <box size="0.33 0.008 0.026" />
        </geometry>
      </collision>
    <collision name="proximal_boss_1">
      <origin xyz="0 0.038 0" rpy="1.5708 0 0" />
      <geometry>
        <cylinder radius="0.027" length="0.02" />
        </geometry>
      </collision>
    <collision name="proximal_bore_1">
      <origin xyz="0 0.0456 0" rpy="1.5708 0 0" />
      <geometry>
        <cylinder radius="0.009" length="0.0025" />
        </geometry>
      </collision>
    <collision name="distal_boss_1">
      <origin xyz="0.33 0.038 0" rpy="1.5708 0 0" />
      <geometry>
        <cylinder radius="0.027" length="0.02" />
        </geometry>
      </collision>
    <collision name="distal_bore_1">
      <origin xyz="0.33 0.0456 0" rpy="1.5708 0 0" />
      <geometry>
        <cylinder radius="0.009" length="0.0025" />
        </geometry>
      </collision>
    <collision name="cross_rung_0">
      <origin xyz="0.1122 0 0" rpy="0 0 0" />
      <geometry>
        <box size="0.03 0.084 0.014" />
        </geometry>
      </collision>
    <collision name="cross_rung_1">
      <origin xyz="0.231 0 0" rpy="0 0 0" />
      <geometry>
        <box size="0.03 0.084 0.014" />
        </geometry>
      </collision>
    </link>
  <link name="tip_link">
    <visual name="side_plate_0">
      <origin xyz="0.135 -0.018 0" rpy="0 0 0" />
      <geometry>
        <box size="0.27 0.008 0.026" />
        </geometry>
      <material name="link_steel" />
      </visual>
    <visual name="proximal_boss_0">
      <origin xyz="0 -0.018 0" rpy="1.5708 0 0" />
      <geometry>
        <cylinder radius="0.027" length="0.02" />
        </geometry>
      <material name="hub_steel" />
      </visual>
    <visual name="proximal_bore_0">
      <origin xyz="0 -0.0256 0" rpy="1.5708 0 0" />
      <geometry>
        <cylinder radius="0.009" length="0.0025" />
        </geometry>
      <material name="bore_shadow" />
      </visual>
    <visual name="distal_boss_0">
      <origin xyz="0.27 -0.018 0" rpy="1.5708 0 0" />
      <geometry>
        <cylinder radius="0.027" length="0.02" />
        </geometry>
      <material name="hub_steel" />
      </visual>
    <visual name="distal_bore_0">
      <origin xyz="0.27 -0.0256 0" rpy="1.5708 0 0" />
      <geometry>
        <cylinder radius="0.009" length="0.0025" />
        </geometry>
      <material name="bore_shadow" />
      </visual>
    <visual name="side_plate_1">
      <origin xyz="0.135 0.018 0" rpy="0 0 0" />
      <geometry>
        <box size="0.27 0.008 0.026" />
        </geometry>
      <material name="link_steel" />
      </visual>
    <visual name="proximal_boss_1">
      <origin xyz="0 0.018 0" rpy="1.5708 0 0" />
      <geometry>
        <cylinder radius="0.027" length="0.02" />
        </geometry>
      <material name="hub_steel" />
      </visual>
    <visual name="proximal_bore_1">
      <origin xyz="0 0.0256 0" rpy="1.5708 0 0" />
      <geometry>
        <cylinder radius="0.009" length="0.0025" />
        </geometry>
      <material name="bore_shadow" />
      </visual>
    <visual name="distal_boss_1">
      <origin xyz="0.27 0.018 0" rpy="1.5708 0 0" />
      <geometry>
        <cylinder radius="0.027" length="0.02" />
        </geometry>
      <material name="hub_steel" />
      </visual>
    <visual name="distal_bore_1">
      <origin xyz="0.27 0.0256 0" rpy="1.5708 0 0" />
      <geometry>
        <cylinder radius="0.009" length="0.0025" />
        </geometry>
      <material name="bore_shadow" />
      </visual>
    <visual name="cross_rung_0">
      <origin xyz="0.0918 0 0" rpy="0 0 0" />
      <geometry>
        <box size="0.03 0.044 0.014" />
        </geometry>
      <material name="hub_steel" />
      </visual>
    <visual name="cross_rung_1">
      <origin xyz="0.189 0 0" rpy="0 0 0" />
      <geometry>
        <box size="0.03 0.044 0.014" />
        </geometry>
      <material name="hub_steel" />
      </visual>
    <visual name="end_tab_neck">
      <origin xyz="0.306 0 0" rpy="0 0 0" />
      <geometry>
        <box size="0.08 0.034 0.016" />
        </geometry>
      <material name="tab_steel" />
      </visual>
    <visual name="end_tab_eye">
      <origin xyz="0.36 0 0" rpy="1.5708 0 0" />
      <geometry>
        <cylinder radius="0.022" length="0.034" />
        </geometry>
      <material name="tab_steel" />
      </visual>
    <visual name="end_tab_hole">
      <origin xyz="0.36 0.018 0" rpy="1.5708 0 0" />
      <geometry>
        <cylinder radius="0.007" length="0.0025" />
        </geometry>
      <material name="bore_shadow" />
      </visual>
    <visual name="end_tab_hole_back">
      <origin xyz="0.36 -0.018 0" rpy="1.5708 0 0" />
      <geometry>
        <cylinder radius="0.007" length="0.0025" />
        </geometry>
      <material name="bore_shadow" />
      </visual>
    <collision name="side_plate_0">
      <origin xyz="0.135 -0.018 0" rpy="0 0 0" />
      <geometry>
        <box size="0.27 0.008 0.026" />
        </geometry>
      </collision>
    <collision name="proximal_boss_0">
      <origin xyz="0 -0.018 0" rpy="1.5708 0 0" />
      <geometry>
        <cylinder radius="0.027" length="0.02" />
        </geometry>
      </collision>
    <collision name="proximal_bore_0">
      <origin xyz="0 -0.0256 0" rpy="1.5708 0 0" />
      <geometry>
        <cylinder radius="0.009" length="0.0025" />
        </geometry>
      </collision>
    <collision name="distal_boss_0">
      <origin xyz="0.27 -0.018 0" rpy="1.5708 0 0" />
      <geometry>
        <cylinder radius="0.027" length="0.02" />
        </geometry>
      </collision>
    <collision name="distal_bore_0">
      <origin xyz="0.27 -0.0256 0" rpy="1.5708 0 0" />
      <geometry>
        <cylinder radius="0.009" length="0.0025" />
        </geometry>
      </collision>
    <collision name="side_plate_1">
      <origin xyz="0.135 0.018 0" rpy="0 0 0" />
      <geometry>
        <box size="0.27 0.008 0.026" />
        </geometry>
      </collision>
    <collision name="proximal_boss_1">
      <origin xyz="0 0.018 0" rpy="1.5708 0 0" />
      <geometry>
        <cylinder radius="0.027" length="0.02" />
        </geometry>
      </collision>
    <collision name="proximal_bore_1">
      <origin xyz="0 0.0256 0" rpy="1.5708 0 0" />
      <geometry>
        <cylinder radius="0.009" length="0.0025" />
        </geometry>
      </collision>
    <collision name="distal_boss_1">
      <origin xyz="0.27 0.018 0" rpy="1.5708 0 0" />
      <geometry>
        <cylinder radius="0.027" length="0.02" />
        </geometry>
      </collision>
    <collision name="distal_bore_1">
      <origin xyz="0.27 0.0256 0" rpy="1.5708 0 0" />
      <geometry>
        <cylinder radius="0.009" length="0.0025" />
        </geometry>
      </collision>
    <collision name="cross_rung_0">
      <origin xyz="0.0918 0 0" rpy="0 0 0" />
      <geometry>
        <box size="0.03 0.044 0.014" />
        </geometry>
      </collision>
    <collision name="cross_rung_1">
      <origin xyz="0.189 0 0" rpy="0 0 0" />
      <geometry>
        <box size="0.03 0.044 0.014" />
        </geometry>
      </collision>
    <collision name="end_tab_neck">
      <origin xyz="0.306 0 0" rpy="0 0 0" />
      <geometry>
        <box size="0.08 0.034 0.016" />
        </geometry>
      </collision>
    <collision name="end_tab_eye">
      <origin xyz="0.36 0 0" rpy="1.5708 0 0" />
      <geometry>
        <cylinder radius="0.022" length="0.034" />
        </geometry>
      </collision>
    <collision name="end_tab_hole">
      <origin xyz="0.36 0.018 0" rpy="1.5708 0 0" />
      <geometry>
        <cylinder radius="0.007" length="0.0025" />
        </geometry>
      </collision>
    <collision name="end_tab_hole_back">
      <origin xyz="0.36 -0.018 0" rpy="1.5708 0 0" />
      <geometry>
        <cylinder radius="0.007" length="0.0025" />
        </geometry>
      </collision>
    </link>
  <joint name="bracket_to_link_0" type="revolute">
    <origin xyz="0 0 0.2" rpy="0 0 0" />
    <parent link="root_bracket" />
    <child link="link_0" />
    <axis xyz="0 -1 0" />
    <limit effort="30" velocity="1.5" lower="-0.7" upper="0.95" />
    </joint>
  <joint name="link_0_to_link_1" type="revolute">
    <origin xyz="0.4 0 0" rpy="0 0 0" />
    <parent link="link_0" />
    <child link="link_1" />
    <axis xyz="0 -1 0" />
    <limit effort="24" velocity="1.6" lower="-1.05" upper="1.05" />
    </joint>
  <joint name="link_1_to_tip_link" type="revolute">
    <origin xyz="0.33 0 0" rpy="0 0 0" />
    <parent link="link_1" />
    <child link="tip_link" />
    <axis xyz="0 -1 0" />
    <limit effort="18" velocity="1.8" lower="-1.1" upper="0.9" />
    </joint>
  </robot>
