<robot name="compact_three_bar_folding_linkage">
  <material name="powder_coated_anchor">
    <color rgba="0.16 0.19 0.21 1" />
    </material>
  <material name="brushed_zinc">
    <color rgba="0.62 0.64 0.61 1" />
    </material>
  <material name="satin_zinc">
    <color rgba="0.53 0.55 0.53 1" />
    </material>
  <material name="black_oxide_pins">
    <color rgba="0.035 0.038 0.04 1" />
    </material>
  <material name="warm_catch_tab">
    <color rgba="0.82 0.6 0.23 1" />
    </material>
  <material name="black_rubber_pad">
    <color rgba="0.015 0.014 0.013 1" />
    </material>
  <link name="anchor_foot">
    <visual name="foot_plate">
      <origin xyz="0.035 0 0.007" rpy="0 0 0" />
      <geometry>
        <box size="0.22 0.13 0.014" />
        </geometry>
      <material name="powder_coated_anchor">
        <color rgba="0.16 0.19 0.21 1" />
        </material>
      </visual>
    <visual name="clevis_base_pad">
      <origin xyz="0 0 0.019" rpy="0 0 0" />
      <geometry>
        <box size="0.07 0.07 0.01" />
        </geometry>
      <material name="powder_coated_anchor">
        <color rgba="0.16 0.19 0.21 1" />
        </material>
      </visual>
    <visual name="clevis_cheek_neg">
      <origin xyz="0 -0.03 0.052" rpy="0 0 0" />
      <geometry>
        <box size="0.052 0.011 0.076" />
        </geometry>
      <material name="powder_coated_anchor">
        <color rgba="0.16 0.19 0.21 1" />
        </material>
      </visual>
    <visual name="clevis_cheek_pos">
      <origin xyz="0 0.03 0.052" rpy="0 0 0" />
      <geometry>
        <box size="0.052 0.011 0.076" />
        </geometry>
      <material name="powder_coated_anchor">
        <color rgba="0.16 0.19 0.21 1" />
        </material>
      </visual>
    <visual name="screw_head_-0.035_-0.043">
      <origin xyz="-0.035 -0.043 0.015" rpy="0 0 0" />
      <geometry>
        <cylinder radius="0.0075" length="0.003" />
        </geometry>
      <material name="black_oxide_pins">
        <color rgba="0.035 0.038 0.04 1" />
        </material>
      </visual>
    <visual name="screw_slot_-0.035_-0.043">
      <origin xyz="-0.035 -0.043 0.017" rpy="0 0 0" />
      <geometry>
        <box size="0.012 0.002 0.0012" />
        </geometry>
      <material name="powder_coated_anchor">
        <color rgba="0.16 0.19 0.21 1" />
        </material>
      </visual>
    <visual name="screw_head_-0.035_+0.043">
      <origin xyz="-0.035 0.043 0.015" rpy="0 0 0" />
      <geometry>
        <cylinder radius="0.0075" length="0.003" />
        </geometry>
      <material name="black_oxide_pins">
        <color rgba="0.035 0.038 0.04 1" />
        </material>
      </visual>
    <visual name="screw_slot_-0.035_+0.043">
      <origin xyz="-0.035 0.043 0.017" rpy="0 0 0" />
      <geometry>
        <box size="0.012 0.002 0.0012" />
        </geometry>
      <material name="powder_coated_anchor">
        <color rgba="0.16 0.19 0.21 1" />
        </material>
      </visual>
    <visual name="screw_head_+0.105_-0.043">
      <origin xyz="0.105 -0.043 0.015" rpy="0 0 0" />
      <geometry>
        <cylinder radius="0.0075" length="0.003" />
        </geometry>
      <material name="black_oxide_pins">
        <color rgba="0.035 0.038 0.04 1" />
        </material>
      </visual>
    <visual name="screw_slot_+0.105_-0.043">
      <origin xyz="0.105 -0.043 0.017" rpy="0 0 0" />
      <geometry>
        <box size="0.012 0.002 0.0012" />
        </geometry>
      <material name="powder_coated_anchor">
        <color rgba="0.16 0.19 0.21 1" />
        </material>
      </visual>
    <visual name="screw_head_+0.105_+0.043">
      <origin xyz="0.105 0.043 0.015" rpy="0 0 0" />
      <geometry>
        <cylinder radius="0.0075" length="0.003" />
        </geometry>
      <material name="black_oxide_pins">
        <color rgba="0.035 0.038 0.04 1" />
        </material>
      </visual>
    <visual name="screw_slot_+0.105_+0.043">
      <origin xyz="0.105 0.043 0.017" rpy="0 0 0" />
      <geometry>
        <box size="0.012 0.002 0.0012" />
        </geometry>
      <material name="powder_coated_anchor">
        <color rgba="0.16 0.19 0.21 1" />
        </material>
      </visual>
    <visual name="root_pin_neg">
      <origin xyz="0 -0.032 0.07" rpy="1.5708 0 0" />
      <geometry>
        <cylinder radius="0.0046" length="0.014" />
        </geometry>
      <material name="black_oxide_pins">
        <color rgba="0.035 0.038 0.04 1" />
        </material>
      </visual>
    <visual name="root_pin_pos">
      <origin xyz="0 0.032 0.07" rpy="1.5708 0 0" />
      <geometry>
        <cylinder radius="0.0046" length="0.014" />
        </geometry>
      <material name="black_oxide_pins">
        <color rgba="0.035 0.038 0.04 1" />
        </material>
      </visual>
    <visual name="root_pin_head_neg">
      <origin xyz="0 -0.039 0.07" rpy="1.5708 0 0" />
      <geometry>
        <cylinder radius="0.014" length="0.005" />
        </geometry>
      <material name="black_oxide_pins">
        <color rgba="0.035 0.038 0.04 1" />
        </material>
      </visual>
    <visual name="root_pin_head_pos">
      <origin xyz="0 0.039 0.07" rpy="1.5708 0 0" />
      <geometry>
        <cylinder radius="0.014" length="0.005" />
        </geometry>
      <material name="black_oxide_pins">
        <color rgba="0.035 0.038 0.04 1" />
        </material>
      </visual>
    <collision name="foot_plate">
      <origin xyz="0.035 0 0.007" rpy="0 0 0" />
      <geometry>
        <box size="0.22 0.13 0.014" />
        </geometry>
      </collision>
    <collision name="clevis_base_pad">
      <origin xyz="0 0 0.019" rpy="0 0 0" />
      <geometry>
        <box size="0.07 0.07 0.01" />
        </geometry>
      </collision>
    <collision name="clevis_cheek_neg">
      <origin xyz="0 -0.03 0.052" rpy="0 0 0" />
      <geometry>
        <box size="0.052 0.011 0.076" />
        </geometry>
      </collision>
    <collision name="clevis_cheek_pos">
      <origin xyz="0 0.03 0.052" rpy="0 0 0" />
      <geometry>
        <box size="0.052 0.011 0.076" />
        </geometry>
      </collision>
    <collision name="screw_head_-0.035_-0.043">
      <origin xyz="-0.035 -0.043 0.015" rpy="0 0 0" />
      <geometry>
        <cylinder radius="0.0075" length="0.003" />
        </geometry>
      </collision>
    <collision name="screw_slot_-0.035_-0.043">
      <origin xyz="-0.035 -0.043 0.017" rpy="0 0 0" />
      <geometry>
        <box size="0.012 0.002 0.0012" />
        </geometry>
      </collision>
    <collision name="screw_head_-0.035_+0.043">
      <origin xyz="-0.035 0.043 0.015" rpy="0 0 0" />
      <geometry>
        <cylinder radius="0.0075" length="0.003" />
        </geometry>
      </collision>
    <collision name="screw_slot_-0.035_+0.043">
      <origin xyz="-0.035 0.043 0.017" rpy="0 0 0" />
      <geometry>
        <box size="0.012 0.002 0.0012" />
        </geometry>
      </collision>
    <collision name="screw_head_+0.105_-0.043">
      <origin xyz="0.105 -0.043 0.015" rpy="0 0 0" />
      <geometry>
        <cylinder radius="0.0075" length="0.003" />
        </geometry>
      </collision>
    <collision name="screw_slot_+0.105_-0.043">
      <origin xyz="0.105 -0.043 0.017" rpy="0 0 0" />
      <geometry>
        <box size="0.012 0.002 0.0012" />
        </geometry>
      </collision>
    <collision name="screw_head_+0.105_+0.043">
      <origin xyz="0.105 0.043 0.015" rpy="0 0 0" />
      <geometry>
        <cylinder radius="0.0075" length="0.003" />
        </geometry>
      </collision>
    <collision name="screw_slot_+0.105_+0.043">
      <origin xyz="0.105 0.043 0.017" rpy="0 0 0" />
      <geometry>
        <box size="0.012 0.002 0.0012" />
        </geometry>
      </collision>
    <collision name="root_pin_neg">
      <origin xyz="0 -0.032 0.07" rpy="1.5708 0 0" />
      <geometry>
        <cylinder radius="0.0046" length="0.014" />
        </geometry>
      </collision>
    <collision name="root_pin_pos">
      <origin xyz="0 0.032 0.07" rpy="1.5708 0 0" />
      <geometry>
        <cylinder radius="0.0046" length="0.014" />
        </geometry>
      </collision>
    <collision name="root_pin_head_neg">
      <origin xyz="0 -0.039 0.07" rpy="1.5708 0 0" />
      <geometry>
        <cylinder radius="0.014" length="0.005" />
        </geometry>
      </collision>
    <collision name="root_pin_head_pos">
      <origin xyz="0 0.039 0.07" rpy="1.5708 0 0" />
      <geometry>
        <cylinder radius="0.014" length="0.005" />
        </geometry>
      </collision>
    </link>
  <link name="bar_0">
    <visual name="bar_plate">
      <geometry>
        <mesh filename="assets/meshes/bar_0_plate_mesh.obj" />
        </geometry>
      <material name="brushed_zinc">
        <color rgba="0.62 0.64 0.61 1" />
        </material>
      </visual>
    <visual name="root_washer_neg">
      <origin xyz="0 -0.01525 0" rpy="1.5708 0 0" />
      <geometry>
        <cylinder radius="0.012" length="0.0185" />
        </geometry>
      <material name="satin_zinc">
        <color rgba="0.53 0.55 0.53 1" />
        </material>
      </visual>
    <visual name="root_washer_pos">
      <origin xyz="0 0.01525 0" rpy="1.5708 0 0" />
      <geometry>
        <cylinder radius="0.012" length="0.0185" />
        </geometry>
      <material name="satin_zinc">
        <color rgba="0.53 0.55 0.53 1" />
        </material>
      </visual>
    <visual name="distal_pin">
      <origin xyz="0.26 0 0" rpy="1.5708 0 0" />
      <geometry>
        <cylinder radius="0.0046" length="0.024" />
        </geometry>
      <material name="black_oxide_pins">
        <color rgba="0.035 0.038 0.04 1" />
        </material>
      </visual>
    <visual name="distal_collar">
      <origin xyz="0.26 -0.0075 0" rpy="1.5708 0 0" />
      <geometry>
        <cylinder radius="0.013" length="0.004" />
        </geometry>
      <material name="satin_zinc">
        <color rgba="0.53 0.55 0.53 1" />
        </material>
      </visual>
    <visual name="distal_pin_head">
      <origin xyz="0.26 -0.015 0" rpy="1.5708 0 0" />
      <geometry>
        <cylinder radius="0.01" length="0.006" />
        </geometry>
      <material name="black_oxide_pins">
        <color rgba="0.035 0.038 0.04 1" />
        </material>
      </visual>
    <collision name="bar_plate">
      <geometry>
        <mesh filename="assets/meshes/bar_0_plate_mesh.obj" />
        </geometry>
      </collision>
    <collision name="root_washer_neg">
      <origin xyz="0 -0.01525 0" rpy="1.5708 0 0" />
      <geometry>
        <cylinder radius="0.012" length="0.0185" />
        </geometry>
      </collision>
    <collision name="root_washer_pos">
      <origin xyz="0 0.01525 0" rpy="1.5708 0 0" />
      <geometry>
        <cylinder radius="0.012" length="0.0185" />
        </geometry>
      </collision>
    <collision name="distal_pin">
      <origin xyz="0.26 0 0" rpy="1.5708 0 0" />
      <geometry>
        <cylinder radius="0.0046" length="0.024" />
        </geometry>
      </collision>
    <collision name="distal_collar">
      <origin xyz="0.26 -0.0075 0" rpy="1.5708 0 0" />
      <geometry>
        <cylinder radius="0.013" length="0.004" />
        </geometry>
      </collision>
    <collision name="distal_pin_head">
      <origin xyz="0.26 -0.015 0" rpy="1.5708 0 0" />
      <geometry>
        <cylinder radius="0.01" length="0.006" />
        </geometry>
      </collision>
    </link>
  <link name="bar_1">
    <visual name="bar_plate">
      <origin xyz="0 0.024 0" rpy="0 0 0" />
      <geometry>
        <mesh filename="assets/meshes/bar_1_plate_mesh.obj" />
        </geometry>
      <material name="satin_zinc">
        <color rgba="0.53 0.55 0.53 1" />
        </material>
      </visual>
    <visual name="proximal_washer">
      <origin xyz="0 0.015 0" rpy="1.5708 0 0" />
      <geometry>
        <cylinder radius="0.011" length="0.006" />
        </geometry>
      <material name="satin_zinc">
        <color rgba="0.53 0.55 0.53 1" />
        </material>
      </visual>
    <visual name="distal_pin">
      <origin xyz="0.18 0.024 0" rpy="1.5708 0 0" />
      <geometry>
        <cylinder radius="0.0046" length="0.024" />
        </geometry>
      <material name="black_oxide_pins">
        <color rgba="0.035 0.038 0.04 1" />
        </material>
      </visual>
    <visual name="distal_collar">
      <origin xyz="0.18 0.0315 0" rpy="1.5708 0 0" />
      <geometry>
        <cylinder radius="0.013" length="0.004" />
        </geometry>
      <material name="satin_zinc">
        <color rgba="0.53 0.55 0.53 1" />
        </material>
      </visual>
    <visual name="distal_pin_head">
      <origin xyz="0.18 0.039 0" rpy="1.5708 0 0" />
      <geometry>
        <cylinder radius="0.01" length="0.006" />
        </geometry>
      <material name="black_oxide_pins">
        <color rgba="0.035 0.038 0.04 1" />
        </material>
      </visual>
    <collision name="bar_plate">
      <origin xyz="0 0.024 0" rpy="0 0 0" />
      <geometry>
        <mesh filename="assets/meshes/bar_1_plate_mesh.obj" />
        </geometry>
      </collision>
    <collision name="proximal_washer">
      <origin xyz="0 0.015 0" rpy="1.5708 0 0" />
      <geometry>
        <cylinder radius="0.011" length="0.006" />
        </geometry>
      </collision>
    <collision name="distal_pin">
      <origin xyz="0.18 0.024 0" rpy="1.5708 0 0" />
      <geometry>
        <cylinder radius="0.0046" length="0.024" />
        </geometry>
      </collision>
    <collision name="distal_collar">
      <origin xyz="0.18 0.0315 0" rpy="1.5708 0 0" />
      <geometry>
        <cylinder radius="0.013" length="0.004" />
        </geometry>
      </collision>
    <collision name="distal_pin_head">
      <origin xyz="0.18 0.039 0" rpy="1.5708 0 0" />
      <geometry>
        <cylinder radius="0.01" length="0.006" />
        </geometry>
      </collision>
    </link>
  <link name="bar_2">
    <visual name="bar_plate">
      <geometry>
        <mesh filename="assets/meshes/bar_2_plate_mesh.obj" />
        </geometry>
      <material name="brushed_zinc">
        <color rgba="0.62 0.64 0.61 1" />
        </material>
      </visual>
    <visual name="proximal_washer">
      <origin xyz="0 0.009 0" rpy="1.5708 0 0" />
      <geometry>
        <cylinder radius="0.011" length="0.006" />
        </geometry>
      <material name="satin_zinc">
        <color rgba="0.53 0.55 0.53 1" />
        </material>
      </visual>
    <visual name="hook_tongue">
      <origin xyz="0.256 0 -0.006" rpy="0 0 0" />
      <geometry>
        <box size="0.078 0.014 0.016" />
        </geometry>
      <material name="warm_catch_tab">
        <color rgba="0.82 0.6 0.23 1" />
        </material>
      </visual>
    <visual name="hook_lip">
      <origin xyz="0.296 0 0.014" rpy="0 0 0" />
      <geometry>
        <box size="0.014 0.014 0.052" />
        </geometry>
      <material name="warm_catch_tab">
        <color rgba="0.82 0.6 0.23 1" />
        </material>
      </visual>
    <visual name="hook_pad">
      <origin xyz="0.287 0 0.013" rpy="0 0 0" />
      <geometry>
        <box size="0.004 0.016 0.034" />
        </geometry>
      <material name="black_rubber_pad">
        <color rgba="0.015 0.014 0.013 1" />
        </material>
      </visual>
    <collision name="bar_plate">
      <geometry>
        <mesh filename="assets/meshes/bar_2_plate_mesh.obj" />
        </geometry>
      </collision>
    <collision name="proximal_washer">
      <origin xyz="0 0.009 0" rpy="1.5708 0 0" />
      <geometry>
        <cylinder radius="0.011" length="0.006" />
        </geometry>
      </collision>
    <collision name="hook_tongue">
      <origin xyz="0.256 0 -0.006" rpy="0 0 0" />
      <geometry>
        <box size="0.078 0.014 0.016" />
        </geometry>
      </collision>
    <collision name="hook_lip">
      <origin xyz="0.296 0 0.014" rpy="0 0 0" />
      <geometry>
        <box size="0.014 0.014 0.052" />
        </geometry>
      </collision>
    <collision name="hook_pad">
      <origin xyz="0.287 0 0.013" rpy="0 0 0" />
      <geometry>
        <box size="0.004 0.016 0.034" />
        </geometry>
      </collision>
    </link>
  <joint name="anchor_to_bar_0" type="revolute">
    <origin xyz="0 0 0.07" rpy="0 -0.35 0" />
    <parent link="anchor_foot" />
    <child link="bar_0" />
    <axis xyz="0 1 0" />
    <limit effort="18" velocity="2" lower="-0.6" upper="0.35" />
    </joint>
  <joint name="bar_0_to_bar_1" type="revolute">
    <origin xyz="0.26 0 0" rpy="0 -2.3 0" />
    <parent link="bar_0" />
    <child link="bar_1" />
    <axis xyz="0 1 0" />
    <limit effort="14" velocity="2.2" lower="0" upper="2.3" />
    </joint>
  <joint name="bar_1_to_bar_2" type="revolute">
    <origin xyz="0.18 0 0" rpy="0 2.8 0" />
    <parent link="bar_1" />
    <child link="bar_2" />
    <axis xyz="0 1 0" />
    <limit effort="12" velocity="2.4" lower="-2.8" upper="0" />
    </joint>
  </robot>
