<robot name="precision_tackle_box">
  <material name="glass_filled_graphite">
    <color rgba="0.07 0.085 0.095 1" />
    </material>
  <material name="satin_blue_lid">
    <color rgba="0.11 0.22 0.32 1" />
    </material>
  <material name="black_nitrile">
    <color rgba="0.005 0.006 0.006 1" />
    </material>
  <material name="brushed_stainless">
    <color rgba="0.7 0.72 0.7 1" />
    </material>
  <material name="calibration_brass">
    <color rgba="0.86 0.63 0.28 1" />
    </material>
  <material name="etched_white">
    <color rgba="0.92 0.92 0.86 1" />
    </material>
  <material name="index_orange">
    <color rgba="1 0.36 0.05 1" />
    </material>
  <link name="base">
    <visual name="base_shell">
      <geometry>
        <mesh filename="assets/meshes/hollow_base_tray.obj" />
        </geometry>
      <material name="glass_filled_graphite">
        <color rgba="0.07 0.085 0.095 1" />
        </material>
      </visual>
    <visual name="gasket_frame">
      <geometry>
        <mesh filename="assets/meshes/raised_gasket_frame.obj" />
        </geometry>
      <material name="black_nitrile">
        <color rgba="0.005 0.006 0.006 1" />
        </material>
      </visual>
    <visual name="base_hinge_leaf">
      <origin xyz="-0.222 0 0.103" rpy="0 0 0" />
      <geometry>
        <box size="0.01 0.2064 0.034" />
        </geometry>
      <material name="brushed_stainless">
        <color rgba="0.7 0.72 0.7 1" />
        </material>
      </visual>
    <visual name="base_hinge_knuckle_0">
      <origin xyz="-0.226 -0.078 0.126" rpy="1.5708 0 0" />
      <geometry>
        <cylinder radius="0.006" length="0.06" />
        </geometry>
      <material name="brushed_stainless">
        <color rgba="0.7 0.72 0.7 1" />
        </material>
      </visual>
    <visual name="base_hinge_knuckle_1">
      <origin xyz="-0.226 0.078 0.126" rpy="1.5708 0 0" />
      <geometry>
        <cylinder radius="0.006" length="0.06" />
        </geometry>
      <material name="brushed_stainless">
        <color rgba="0.7 0.72 0.7 1" />
        </material>
      </visual>
    <visual name="hinge_pin_head_0">
      <origin xyz="-0.226 -0.1134 0.126" rpy="1.5708 0 0" />
      <geometry>
        <cylinder radius="0.0045" length="0.012" />
        </geometry>
      <material name="brushed_stainless">
        <color rgba="0.7 0.72 0.7 1" />
        </material>
      </visual>
    <visual name="hinge_pin_head_1">
      <origin xyz="-0.226 0.1134 0.126" rpy="1.5708 0 0" />
      <geometry>
        <cylinder radius="0.0045" length="0.012" />
        </geometry>
      <material name="brushed_stainless">
        <color rgba="0.7 0.72 0.7 1" />
        </material>
      </visual>
    <visual name="keeper_block_0">
      <origin xyz="0.224 -0.07 0.074" rpy="0 0 0" />
      <geometry>
        <box size="0.008 0.052 0.014" />
        </geometry>
      <material name="brushed_stainless">
        <color rgba="0.7 0.72 0.7 1" />
        </material>
      </visual>
    <visual name="keeper_pin_0">
      <origin xyz="0.229 -0.07 0.084" rpy="1.5708 0 0" />
      <geometry>
        <cylinder radius="0.0035" length="0.052" />
        </geometry>
      <material name="brushed_stainless">
        <color rgba="0.7 0.72 0.7 1" />
        </material>
      </visual>
    <visual name="base_index_mark_0">
      <origin xyz="0.2202 -0.07 0.101" rpy="0 0 0" />
      <geometry>
        <box size="0.0012 0.004 0.02" />
        </geometry>
      <material name="index_orange">
        <color rgba="1 0.36 0.05 1" />
        </material>
      </visual>
    <visual name="datum_stop_0">
      <origin xyz="0.205 -0.07 0.122" rpy="0 0 0" />
      <geometry>
        <box size="0.026 0.018 0.004" />
        </geometry>
      <material name="calibration_brass">
        <color rgba="0.86 0.63 0.28 1" />
        </material>
      </visual>
    <visual name="keeper_block_1">
      <origin xyz="0.224 0.07 0.074" rpy="0 0 0" />
      <geometry>
        <box size="0.008 0.052 0.014" />
        </geometry>
      <material name="brushed_stainless">
        <color rgba="0.7 0.72 0.7 1" />
        </material>
      </visual>
    <visual name="keeper_pin_1">
      <origin xyz="0.229 0.07 0.084" rpy="1.5708 0 0" />
      <geometry>
        <cylinder radius="0.0035" length="0.052" />
        </geometry>
      <material name="brushed_stainless">
        <color rgba="0.7 0.72 0.7 1" />
        </material>
      </visual>
    <visual name="base_index_mark_1">
      <origin xyz="0.2202 0.07 0.101" rpy="0 0 0" />
      <geometry>
        <box size="0.0012 0.004 0.02" />
        </geometry>
      <material name="index_orange">
        <color rgba="1 0.36 0.05 1" />
        </material>
      </visual>
    <visual name="datum_stop_1">
      <origin xyz="0.205 0.07 0.122" rpy="0 0 0" />
      <geometry>
        <box size="0.026 0.018 0.004" />
        </geometry>
      <material name="calibration_brass">
        <color rgba="0.86 0.63 0.28 1" />
        </material>
      </visual>
    <collision name="base_shell">
      <geometry>
        <mesh filename="assets/meshes/hollow_base_tray.obj" />
        </geometry>
      </collision>
    <collision name="gasket_frame">
      <geometry>
        <mesh filename="assets/meshes/raised_gasket_frame.obj" />
        </geometry>
      </collision>
    <collision name="base_hinge_leaf">
      <origin xyz="-0.222 0 0.103" rpy="0 0 0" />
      <geometry>
        <box size="0.01 0.2064 0.034" />
        </geometry>
      </collision>
    <collision name="base_hinge_knuckle_0">
      <origin xyz="-0.226 -0.078 0.126" rpy="1.5708 0 0" />
      <geometry>
        <cylinder radius="0.006" length="0.06" />
        </geometry>
      </collision>
    <collision name="base_hinge_knuckle_1">
      <origin xyz="-0.226 0.078 0.126" rpy="1.5708 0 0" />
      <geometry>
        <cylinder radius="0.006" length="0.06" />
        </geometry>
      </collision>
    <collision name="hinge_pin_head_0">
      <origin xyz="-0.226 -0.1134 0.126" rpy="1.5708 0 0" />
      <geometry>
        <cylinder radius="0.0045" length="0.012" />
        </geometry>
      </collision>
    <collision name="hinge_pin_head_1">
      <origin xyz="-0.226 0.1134 0.126" rpy="1.5708 0 0" />
      <geometry>
        <cylinder radius="0.0045" length="0.012" />
        </geometry>
      </collision>
    <collision name="keeper_block_0">
      <origin xyz="0.224 -0.07 0.074" rpy="0 0 0" />
      <geometry>
        <box size="0.008 0.052 0.014" />
        </geometry>
      </collision>
    <collision name="keeper_pin_0">
      <origin xyz="0.229 -0.07 0.084" rpy="1.5708 0 0" />
      <geometry>
        <cylinder radius="0.0035" length="0.052" />
        </geometry>
      </collision>
    <collision name="base_index_mark_0">
      <origin xyz="0.2202 -0.07 0.101" rpy="0 0 0" />
      <geometry>
        <box size="0.0012 0.004 0.02" />
        </geometry>
      </collision>
    <collision name="datum_stop_0">
      <origin xyz="0.205 -0.07 0.122" rpy="0 0 0" />
      <geometry>
        <box size="0.026 0.018 0.004" />
        </geometry>
      </collision>
    <collision name="keeper_block_1">
      <origin xyz="0.224 0.07 0.074" rpy="0 0 0" />
      <geometry>
        <box size="0.008 0.052 0.014" />
        </geometry>
      </collision>
    <collision name="keeper_pin_1">
      <origin xyz="0.229 0.07 0.084" rpy="1.5708 0 0" />
      <geometry>
        <cylinder radius="0.0035" length="0.052" />
        </geometry>
      </collision>
    <collision name="base_index_mark_1">
      <origin xyz="0.2202 0.07 0.101" rpy="0 0 0" />
      <geometry>
        <box size="0.0012 0.004 0.02" />
        </geometry>
      </collision>
    <collision name="datum_stop_1">
      <origin xyz="0.205 0.07 0.122" rpy="0 0 0" />
      <geometry>
        <box size="0.026 0.018 0.004" />
        </geometry>
      </collision>
    </link>
  <link name="lid">
    <visual name="lid_shell">
      <geometry>
        <mesh filename="assets/meshes/hollow_lid_cap.obj" />
        </geometry>
      <material name="satin_blue_lid">
        <color rgba="0.11 0.22 0.32 1" />
        </material>
      </visual>
    <visual name="lid_hinge_knuckle">
      <origin xyz="0 0 0" rpy="1.5708 0 0" />
      <geometry>
        <cylinder radius="0.006" length="0.078" />
        </geometry>
      <material name="brushed_stainless">
        <color rgba="0.7 0.72 0.7 1" />
        </material>
      </visual>
    <visual name="lid_hinge_leaf">
      <origin xyz="0.018 0 -0.002" rpy="0 0 0" />
      <geometry>
        <box size="0.026 0.084 0.004" />
        </geometry>
      <material name="brushed_stainless">
        <color rgba="0.7 0.72 0.7 1" />
        </material>
      </visual>
    <visual name="top_datum_plate">
      <origin xyz="0.245 0 0.041" rpy="0 0 0" />
      <geometry>
        <box size="0.165 0.068 0.002" />
        </geometry>
      <material name="brushed_stainless">
        <color rgba="0.7 0.72 0.7 1" />
        </material>
      </visual>
    <visual name="datum_cross_x">
      <origin xyz="0.245 0 0.0426" rpy="0 0 0" />
      <geometry>
        <box size="0.15 0.003 0.0012" />
        </geometry>
      <material name="etched_white">
        <color rgba="0.92 0.92 0.86 1" />
        </material>
      </visual>
    <visual name="datum_cross_y">
      <origin xyz="0.245 0 0.0426" rpy="0 0 0" />
      <geometry>
        <box size="0.003 0.06 0.0012" />
        </geometry>
      <material name="etched_white">
        <color rgba="0.92 0.92 0.86 1" />
        </material>
      </visual>
    <visual name="lid_index_mark_0">
      <origin xyz="0.4402 -0.07 0.012" rpy="0 0 0" />
      <geometry>
        <box size="0.0012 0.004 0.02" />
        </geometry>
      <material name="etched_white">
        <color rgba="0.92 0.92 0.86 1" />
        </material>
      </visual>
    <visual name="latch_lug_a_0">
      <origin xyz="0.444 -0.096 0.025" rpy="0 0 0" />
      <geometry>
        <box size="0.008 0.01 0.012" />
        </geometry>
      <material name="brushed_stainless">
        <color rgba="0.7 0.72 0.7 1" />
        </material>
      </visual>
    <visual name="latch_lug_b_0">
      <origin xyz="0.444 -0.044 0.025" rpy="0 0 0" />
      <geometry>
        <box size="0.008 0.01 0.012" />
        </geometry>
      <material name="brushed_stainless">
        <color rgba="0.7 0.72 0.7 1" />
        </material>
      </visual>
    <visual name="lid_index_mark_1">
      <origin xyz="0.4402 0.07 0.012" rpy="0 0 0" />
      <geometry>
        <box size="0.0012 0.004 0.02" />
        </geometry>
      <material name="etched_white">
        <color rgba="0.92 0.92 0.86 1" />
        </material>
      </visual>
    <visual name="latch_lug_a_1">
      <origin xyz="0.444 0.044 0.025" rpy="0 0 0" />
      <geometry>
        <box size="0.008 0.01 0.012" />
        </geometry>
      <material name="brushed_stainless">
        <color rgba="0.7 0.72 0.7 1" />
        </material>
      </visual>
    <visual name="latch_lug_b_1">
      <origin xyz="0.444 0.096 0.025" rpy="0 0 0" />
      <geometry>
        <box size="0.008 0.01 0.012" />
        </geometry>
      <material name="brushed_stainless">
        <color rgba="0.7 0.72 0.7 1" />
        </material>
      </visual>
    <collision name="lid_shell">
      <geometry>
        <mesh filename="assets/meshes/hollow_lid_cap.obj" />
        </geometry>
      </collision>
    <collision name="lid_hinge_knuckle">
      <origin xyz="0 0 0" rpy="1.5708 0 0" />
      <geometry>
        <cylinder radius="0.006" length="0.078" />
        </geometry>
      </collision>
    <collision name="lid_hinge_leaf">
      <origin xyz="0.018 0 -0.002" rpy="0 0 0" />
      <geometry>
        <box size="0.026 0.084 0.004" />
        </geometry>
      </collision>
    <collision name="top_datum_plate">
      <origin xyz="0.245 0 0.041" rpy="0 0 0" />
      <geometry>
        <box size="0.165 0.068 0.002" />
        </geometry>
      </collision>
    <collision name="datum_cross_x">
      <origin xyz="0.245 0 0.0426" rpy="0 0 0" />
      <geometry>
        <box size="0.15 0.003 0.0012" />
        </geometry>
      </collision>
    <collision name="datum_cross_y">
      <origin xyz="0.245 0 0.0426" rpy="0 0 0" />
      <geometry>
        <box size="0.003 0.06 0.0012" />
        </geometry>
      </collision>
    <collision name="lid_index_mark_0">
      <origin xyz="0.4402 -0.07 0.012" rpy="0 0 0" />
      <geometry>
        <box size="0.0012 0.004 0.02" />
        </geometry>
      </collision>
    <collision name="latch_lug_a_0">
      <origin xyz="0.444 -0.096 0.025" rpy="0 0 0" />
      <geometry>
        <box size="0.008 0.01 0.012" />
        </geometry>
      </collision>
    <collision name="latch_lug_b_0">
      <origin xyz="0.444 -0.044 0.025" rpy="0 0 0" />
      <geometry>
        <box size="0.008 0.01 0.012" />
        </geometry>
      </collision>
    <collision name="lid_index_mark_1">
      <origin xyz="0.4402 0.07 0.012" rpy="0 0 0" />
      <geometry>
        <box size="0.0012 0.004 0.02" />
        </geometry>
      </collision>
    <collision name="latch_lug_a_1">
      <origin xyz="0.444 0.044 0.025" rpy="0 0 0" />
      <geometry>
        <box size="0.008 0.01 0.012" />
        </geometry>
      </collision>
    <collision name="latch_lug_b_1">
      <origin xyz="0.444 0.096 0.025" rpy="0 0 0" />
      <geometry>
        <box size="0.008 0.01 0.012" />
        </geometry>
      </collision>
    </link>
  <link name="latch_0">
    <visual name="latch_barrel">
      <origin xyz="0 0 0" rpy="1.5708 0 0" />
      <geometry>
        <cylinder radius="0.0046" length="0.03" />
        </geometry>
      <material name="brushed_stainless">
        <color rgba="0.7 0.72 0.7 1" />
        </material>
      </visual>
    <visual name="latch_plate">
      <origin xyz="0.006 0 -0.032" rpy="0 0 0" />
      <geometry>
        <box size="0.006 0.04 0.058" />
        </geometry>
      <material name="brushed_stainless">
        <color rgba="0.7 0.72 0.7 1" />
        </material>
      </visual>
    <visual name="latch_hook">
      <origin xyz="0.004 0 -0.062" rpy="0 0 0" />
      <geometry>
        <box size="0.012 0.042 0.006" />
        </geometry>
      <material name="brushed_stainless">
        <color rgba="0.7 0.72 0.7 1" />
        </material>
      </visual>
    <visual name="pull_lip">
      <origin xyz="0.011 0 -0.047" rpy="0 0 0" />
      <geometry>
        <box size="0.01 0.036 0.008" />
        </geometry>
      <material name="black_nitrile">
        <color rgba="0.005 0.006 0.006 1" />
        </material>
      </visual>
    <collision name="latch_barrel">
      <origin xyz="0 0 0" rpy="1.5708 0 0" />
      <geometry>
        <cylinder radius="0.0046" length="0.03" />
        </geometry>
      </collision>
    <collision name="latch_plate">
      <origin xyz="0.006 0 -0.032" rpy="0 0 0" />
      <geometry>
        <box size="0.006 0.04 0.058" />
        </geometry>
      </collision>
    <collision name="latch_hook">
      <origin xyz="0.004 0 -0.062" rpy="0 0 0" />
      <geometry>
        <box size="0.012 0.042 0.006" />
        </geometry>
      </collision>
    <collision name="pull_lip">
      <origin xyz="0.011 0 -0.047" rpy="0 0 0" />
      <geometry>
        <box size="0.01 0.036 0.008" />
        </geometry>
      </collision>
    </link>
  <link name="latch_1">
    <visual name="latch_barrel">
      <origin xyz="0 0 0" rpy="1.5708 0 0" />
      <geometry>
        <cylinder radius="0.0046" length="0.03" />
        </geometry>
      <material name="brushed_stainless">
        <color rgba="0.7 0.72 0.7 1" />
        </material>
      </visual>
    <visual name="latch_plate">
      <origin xyz="0.006 0 -0.032" rpy="0 0 0" />
      <geometry>
        <box size="0.006 0.04 0.058" />
        </geometry>
      <material name="brushed_stainless">
        <color rgba="0.7 0.72 0.7 1" />
        </material>
      </visual>
    <visual name="latch_hook">
      <origin xyz="0.004 0 -0.062" rpy="0 0 0" />
      <geometry>
        <box size="0.012 0.042 0.006" />
        </geometry>
      <material name="brushed_stainless">
        <color rgba="0.7 0.72 0.7 1" />
        </material>
      </visual>
    <visual name="pull_lip">
      <origin xyz="0.011 0 -0.047" rpy="0 0 0" />
      <geometry>
        <box size="0.01 0.036 0.008" />
        </geometry>
      <material name="black_nitrile">
        <color rgba="0.005 0.006 0.006 1" />
        </material>
      </visual>
    <collision name="latch_barrel">
      <origin xyz="0 0 0" rpy="1.5708 0 0" />
      <geometry>
        <cylinder radius="0.0046" length="0.03" />
        </geometry>
      </collision>
    <collision name="latch_plate">
      <origin xyz="0.006 0 -0.032" rpy="0 0 0" />
      <geometry>
        <box size="0.006 0.04 0.058" />
        </geometry>
      </collision>
    <collision name="latch_hook">
      <origin xyz="0.004 0 -0.062" rpy="0 0 0" />
      <geometry>
        <box size="0.012 0.042 0.006" />
        </geometry>
      </collision>
    <collision name="pull_lip">
      <origin xyz="0.011 0 -0.047" rpy="0 0 0" />
      <geometry>
        <box size="0.01 0.036 0.008" />
        </geometry>
      </collision>
    </link>
  <link name="adjuster_0">
    <visual name="adjuster_cap">
      <origin xyz="0 0 0.004" rpy="0 0 0" />
      <geometry>
        <cylinder radius="0.012" length="0.008" />
        </geometry>
      <material name="calibration_brass">
        <color rgba="0.86 0.63 0.28 1" />
        </material>
      </visual>
    <visual name="adjuster_witness">
      <origin xyz="0 0 0.0086" rpy="0 0 0" />
      <geometry>
        <box size="0.003 0.019 0.0012" />
        </geometry>
      <material name="etched_white">
        <color rgba="0.92 0.92 0.86 1" />
        </material>
      </visual>
    <collision name="adjuster_cap">
      <origin xyz="0 0 0.004" rpy="0 0 0" />
      <geometry>
        <cylinder radius="0.012" length="0.008" />
        </geometry>
      </collision>
    <collision name="adjuster_witness">
      <origin xyz="0 0 0.0086" rpy="0 0 0" />
      <geometry>
        <box size="0.003 0.019 0.0012" />
        </geometry>
      </collision>
    </link>
  <link name="adjuster_1">
    <visual name="adjuster_cap">
      <origin xyz="0 0 0.004" rpy="0 0 0" />
      <geometry>
        <cylinder radius="0.012" length="0.008" />
        </geometry>
      <material name="calibration_brass">
        <color rgba="0.86 0.63 0.28 1" />
        </material>
      </visual>
    <visual name="adjuster_witness">
      <origin xyz="0 0 0.0086" rpy="0 0 0" />
      <geometry>
        <box size="0.003 0.019 0.0012" />
        </geometry>
      <material name="etched_white">
        <color rgba="0.92 0.92 0.86 1" />
        </material>
      </visual>
    <collision name="adjuster_cap">
      <origin xyz="0 0 0.004" rpy="0 0 0" />
      <geometry>
        <cylinder radius="0.012" length="0.008" />
        </geometry>
      </collision>
    <collision name="adjuster_witness">
      <origin xyz="0 0 0.0086" rpy="0 0 0" />
      <geometry>
        <box size="0.003 0.019 0.0012" />
        </geometry>
      </collision>
    </link>
  <joint name="base_to_lid" type="revolute">
    <origin xyz="-0.226 0 0.126" rpy="0 0 0" />
    <parent link="base" />
    <child link="lid" />
    <axis xyz="0 -1 0" />
    <limit effort="12" velocity="1.8" lower="0" upper="1.45" />
    </joint>
  <joint name="lid_to_latch_0" type="revolute">
    <origin xyz="0.444 -0.07 0.025" rpy="0 0 0" />
    <parent link="lid" />
    <child link="latch_0" />
    <axis xyz="0 -1 0" />
    <limit effort="2.5" velocity="3" lower="0" upper="1.2" />
    </joint>
  <joint name="lid_to_latch_1" type="revolute">
    <origin xyz="0.444 0.07 0.025" rpy="0 0 0" />
    <parent link="lid" />
    <child link="latch_1" />
    <axis xyz="0 -1 0" />
    <limit effort="2.5" velocity="3" lower="0" upper="1.2" />
    </joint>
  <joint name="lid_to_adjuster_0" type="revolute">
    <origin xyz="0.165 -0.052 0.04" rpy="0 0 0" />
    <parent link="lid" />
    <child link="adjuster_0" />
    <axis xyz="0 0 1" />
    <limit effort="0.6" velocity="2" lower="-3.14159" upper="3.14159" />
    </joint>
  <joint name="lid_to_adjuster_1" type="revolute">
    <origin xyz="0.165 0.052 0.04" rpy="0 0 0" />
    <parent link="lid" />
    <child link="adjuster_1" />
    <axis xyz="0 0 1" />
    <limit effort="0.6" velocity="2" lower="-3.14159" upper="3.14159" />
    </joint>
  </robot>
