<robot name="foldable_knee_scooter">
  <material name="powder_coated_blue">
    <color rgba="0.05 0.17 0.34 1" />
    </material>
  <material name="dark_anodized_metal">
    <color rgba="0.03 0.035 0.04 1" />
    </material>
  <material name="brushed_aluminum">
    <color rgba="0.72 0.74 0.72 1" />
    </material>
  <material name="black_rubber">
    <color rgba="0.005 0.005 0.004 1" />
    </material>
  <material name="matte_black_cushion">
    <color rgba="0.015 0.014 0.013 1" />
    </material>
  <material name="soft_gray_grip">
    <color rgba="0.08 0.085 0.085 1" />
    </material>
  <link name="frame">
    <visual name="knee_pad">
      <origin xyz="-0.16 0 0.412" rpy="0 0 0" />
      <geometry>
        <mesh filename="assets/meshes/rounded_knee_pad.obj" />
        </geometry>
      <material name="matte_black_cushion">
        <color rgba="0.015 0.014 0.013 1" />
        </material>
      </visual>
    <visual name="deck_plate">
      <origin xyz="-0.13 0 0.365" rpy="0 0 0" />
      <geometry>
        <box size="0.58 0.19 0.03" />
        </geometry>
      <material name="dark_anodized_metal">
        <color rgba="0.03 0.035 0.04 1" />
        </material>
      </visual>
    <visual name="main_spine">
      <origin xyz="-0.06 0 0.325" rpy="0 0 0" />
      <geometry>
        <box size="0.76 0.06 0.05" />
        </geometry>
      <material name="powder_coated_blue">
        <color rgba="0.05 0.17 0.34 1" />
        </material>
      </visual>
    <visual name="rear_axle">
      <origin xyz="-0.47 0 0.08" rpy="0 1.5708 1.5708" />
      <geometry>
        <cylinder radius="0.011" length="0.47" />
        </geometry>
      <material name="brushed_aluminum">
        <color rgba="0.72 0.74 0.72 1" />
        </material>
      </visual>
    <visual name="rear_crossbar">
      <origin xyz="-0.47 0 0.315" rpy="0 1.5708 1.5708" />
      <geometry>
        <cylinder radius="0.017" length="0.3" />
        </geometry>
      <material name="powder_coated_blue">
        <color rgba="0.05 0.17 0.34 1" />
        </material>
      </visual>
    <visual name="rear_left_support">
      <origin xyz="-0.47 0.125 0.1975" rpy="0 3.14159 0" />
      <geometry>
        <cylinder radius="0.014" length="0.215" />
        </geometry>
      <material name="powder_coated_blue">
        <color rgba="0.05 0.17 0.34 1" />
        </material>
      </visual>
    <visual name="rear_left_brace">
      <origin xyz="-0.415 0.0625 0.24" rpy="0 2.36657 2.29245" />
      <geometry>
        <cylinder radius="0.01" length="0.23796" />
        </geometry>
      <material name="powder_coated_blue">
        <color rgba="0.05 0.17 0.34 1" />
        </material>
      </visual>
    <visual name="rear_right_support">
      <origin xyz="-0.47 -0.125 0.1975" rpy="0 3.14159 0" />
      <geometry>
        <cylinder radius="0.014" length="0.215" />
        </geometry>
      <material name="powder_coated_blue">
        <color rgba="0.05 0.17 0.34 1" />
        </material>
      </visual>
    <visual name="rear_right_brace">
      <origin xyz="-0.415 -0.0625 0.24" rpy="0 2.36657 -2.29245" />
      <geometry>
        <cylinder radius="0.01" length="0.23796" />
        </geometry>
      <material name="powder_coated_blue">
        <color rgba="0.05 0.17 0.34 1" />
        </material>
      </visual>
    <visual name="front_neck_tube">
      <origin xyz="0.4025 0 0.33" rpy="0 1.19029 0" />
      <geometry>
        <cylinder radius="0.022" length="0.0807775" />
        </geometry>
      <material name="powder_coated_blue">
        <color rgba="0.05 0.17 0.34 1" />
        </material>
      </visual>
    <visual name="front_upright">
      <origin xyz="0.44 0 0.435" rpy="0 0 0" />
      <geometry>
        <cylinder radius="0.026" length="0.38" />
        </geometry>
      <material name="dark_anodized_metal">
        <color rgba="0.03 0.035 0.04 1" />
        </material>
      </visual>
    <visual name="upright_brace">
      <origin xyz="0.3475 0 0.445" rpy="0 0.656702 0" />
      <geometry>
        <cylinder radius="0.014" length="0.303026" />
        </geometry>
      <material name="powder_coated_blue">
        <color rgba="0.05 0.17 0.34 1" />
        </material>
      </visual>
    <visual name="clamp_cheek_0">
      <origin xyz="0.44 0.052 0.685" rpy="0 0 0" />
      <geometry>
        <box size="0.022 0.016 0.088" />
        </geometry>
      <material name="brushed_aluminum">
        <color rgba="0.72 0.74 0.72 1" />
        </material>
      </visual>
    <visual name="clamp_cheek_1">
      <origin xyz="0.44 -0.052 0.685" rpy="0 0 0" />
      <geometry>
        <box size="0.022 0.016 0.088" />
        </geometry>
      <material name="brushed_aluminum">
        <color rgba="0.72 0.74 0.72 1" />
        </material>
      </visual>
    <visual name="fold_hinge_pin_0">
      <origin xyz="0.44 0.055 0.685" rpy="0 1.5708 1.5708" />
      <geometry>
        <cylinder radius="0.009" length="0.03" />
        </geometry>
      <material name="brushed_aluminum">
        <color rgba="0.72 0.74 0.72 1" />
        </material>
      </visual>
    <visual name="fold_hinge_pin_1">
      <origin xyz="0.44 -0.055 0.685" rpy="0 1.5708 -1.5708" />
      <geometry>
        <cylinder radius="0.009" length="0.03" />
        </geometry>
      <material name="brushed_aluminum">
        <color rgba="0.72 0.74 0.72 1" />
        </material>
      </visual>
    <visual name="folding_clamp_block">
      <origin xyz="0.44 0 0.624" rpy="0 0 0" />
      <geometry>
        <box size="0.04 0.11 0.04" />
        </geometry>
      <material name="dark_anodized_metal">
        <color rgba="0.03 0.035 0.04 1" />
        </material>
      </visual>
    <collision name="knee_pad">
      <origin xyz="-0.16 0 0.412" rpy="0 0 0" />
      <geometry>
        <mesh filename="assets/meshes/rounded_knee_pad.obj" />
        </geometry>
      </collision>
    <collision name="deck_plate">
      <origin xyz="-0.13 0 0.365" rpy="0 0 0" />
      <geometry>
        <box size="0.58 0.19 0.03" />
        </geometry>
      </collision>
    <collision name="main_spine">
      <origin xyz="-0.06 0 0.325" rpy="0 0 0" />
      <geometry>
        <box size="0.76 0.06 0.05" />
        </geometry>
      </collision>
    <collision name="rear_axle">
      <origin xyz="-0.47 0 0.08" rpy="0 1.5708 1.5708" />
      <geometry>
        <cylinder radius="0.011" length="0.47" />
        </geometry>
      </collision>
    <collision name="rear_crossbar">
      <origin xyz="-0.47 0 0.315" rpy="0 1.5708 1.5708" />
      <geometry>
        <cylinder radius="0.017" length="0.3" />
        </geometry>
      </collision>
    <collision name="rear_left_support">
      <origin xyz="-0.47 0.125 0.1975" rpy="0 3.14159 0" />
      <geometry>
        <cylinder radius="0.014" length="0.215" />
        </geometry>
      </collision>
    <collision name="rear_left_brace">
      <origin xyz="-0.415 0.0625 0.24" rpy="0 2.36657 2.29245" />
      <geometry>
        <cylinder radius="0.01" length="0.23796" />
        </geometry>
      </collision>
    <collision name="rear_right_support">
      <origin xyz="-0.47 -0.125 0.1975" rpy="0 3.14159 0" />
      <geometry>
        <cylinder radius="0.014" length="0.215" />
        </geometry>
      </collision>
    <collision name="rear_right_brace">
      <origin xyz="-0.415 -0.0625 0.24" rpy="0 2.36657 -2.29245" />
      <geometry>
        <cylinder radius="0.01" length="0.23796" />
        </geometry>
      </collision>
    <collision name="front_neck_tube">
      <origin xyz="0.4025 0 0.33" rpy="0 1.19029 0" />
      <geometry>
        <cylinder radius="0.022" length="0.0807775" />
        </geometry>
      </collision>
    <collision name="front_upright">
      <origin xyz="0.44 0 0.435" rpy="0 0 0" />
      <geometry>
        <cylinder radius="0.026" length="0.38" />
        </geometry>
      </collision>
    <collision name="upright_brace">
      <origin xyz="0.3475 0 0.445" rpy="0 0.656702 0" />
      <geometry>
        <cylinder radius="0.014" length="0.303026" />
        </geometry>
      </collision>
    <collision name="clamp_cheek_0">
      <origin xyz="0.44 0.052 0.685" rpy="0 0 0" />
      <geometry>
        <box size="0.022 0.016 0.088" />
        </geometry>
      </collision>
    <collision name="clamp_cheek_1">
      <origin xyz="0.44 -0.052 0.685" rpy="0 0 0" />
      <geometry>
        <box size="0.022 0.016 0.088" />
        </geometry>
      </collision>
    <collision name="fold_hinge_pin_0">
      <origin xyz="0.44 0.055 0.685" rpy="0 1.5708 1.5708" />
      <geometry>
        <cylinder radius="0.009" length="0.03" />
        </geometry>
      </collision>
    <collision name="fold_hinge_pin_1">
      <origin xyz="0.44 -0.055 0.685" rpy="0 1.5708 -1.5708" />
      <geometry>
        <cylinder radius="0.009" length="0.03" />
        </geometry>
      </collision>
    <collision name="folding_clamp_block">
      <origin xyz="0.44 0 0.624" rpy="0 0 0" />
      <geometry>
        <box size="0.04 0.11 0.04" />
        </geometry>
      </collision>
    </link>
  <link name="front_fork">
    <visual name="fork_crown">
      <origin xyz="0 0 -0.02" rpy="0 1.5708 1.5708" />
      <geometry>
        <cylinder radius="0.018" length="0.3" />
        </geometry>
      <material name="brushed_aluminum">
        <color rgba="0.72 0.74 0.72 1" />
        </material>
      </visual>
    <visual name="lower_bearing_collar">
      <origin xyz="0 0 -0.004" rpy="0 0 0" />
      <geometry>
        <cylinder radius="0.034" length="0.008" />
        </geometry>
      <material name="brushed_aluminum">
        <color rgba="0.72 0.74 0.72 1" />
        </material>
      </visual>
    <visual name="steerer_stub">
      <origin xyz="0 0 -0.075" rpy="0 3.14159 0" />
      <geometry>
        <cylinder radius="0.018" length="0.15" />
        </geometry>
      <material name="brushed_aluminum">
        <color rgba="0.72 0.74 0.72 1" />
        </material>
      </visual>
    <visual name="front_axle">
      <origin xyz="0 0 -0.165" rpy="0 1.5708 1.5708" />
      <geometry>
        <cylinder radius="0.011" length="0.47" />
        </geometry>
      <material name="brushed_aluminum">
        <color rgba="0.72 0.74 0.72 1" />
        </material>
      </visual>
    <visual name="fork_left_leg">
      <origin xyz="0 0.125 -0.0925" rpy="0 3.14159 0" />
      <geometry>
        <cylinder radius="0.013" length="0.145" />
        </geometry>
      <material name="brushed_aluminum">
        <color rgba="0.72 0.74 0.72 1" />
        </material>
      </visual>
    <visual name="fork_left_dropout">
      <origin xyz="0 0.1425 -0.165" rpy="0 1.5708 1.5708" />
      <geometry>
        <cylinder radius="0.01" length="0.035" />
        </geometry>
      <material name="brushed_aluminum">
        <color rgba="0.72 0.74 0.72 1" />
        </material>
      </visual>
    <visual name="fork_right_leg">
      <origin xyz="0 -0.125 -0.0925" rpy="0 3.14159 0" />
      <geometry>
        <cylinder radius="0.013" length="0.145" />
        </geometry>
      <material name="brushed_aluminum">
        <color rgba="0.72 0.74 0.72 1" />
        </material>
      </visual>
    <visual name="fork_right_dropout">
      <origin xyz="0 -0.1425 -0.165" rpy="0 1.5708 -1.5708" />
      <geometry>
        <cylinder radius="0.01" length="0.035" />
        </geometry>
      <material name="brushed_aluminum">
        <color rgba="0.72 0.74 0.72 1" />
        </material>
      </visual>
    <collision name="fork_crown">
      <origin xyz="0 0 -0.02" rpy="0 1.5708 1.5708" />
      <geometry>
        <cylinder radius="0.018" length="0.3" />
        </geometry>
      </collision>
    <collision name="lower_bearing_collar">
      <origin xyz="0 0 -0.004" rpy="0 0 0" />
      <geometry>
        <cylinder radius="0.034" length="0.008" />
        </geometry>
      </collision>
    <collision name="steerer_stub">
      <origin xyz="0 0 -0.075" rpy="0 3.14159 0" />
      <geometry>
        <cylinder radius="0.018" length="0.15" />
        </geometry>
      </collision>
    <collision name="front_axle">
      <origin xyz="0 0 -0.165" rpy="0 1.5708 1.5708" />
      <geometry>
        <cylinder radius="0.011" length="0.47" />
        </geometry>
      </collision>
    <collision name="fork_left_leg">
      <origin xyz="0 0.125 -0.0925" rpy="0 3.14159 0" />
      <geometry>
        <cylinder radius="0.013" length="0.145" />
        </geometry>
      </collision>
    <collision name="fork_left_dropout">
      <origin xyz="0 0.1425 -0.165" rpy="0 1.5708 1.5708" />
      <geometry>
        <cylinder radius="0.01" length="0.035" />
        </geometry>
      </collision>
    <collision name="fork_right_leg">
      <origin xyz="0 -0.125 -0.0925" rpy="0 3.14159 0" />
      <geometry>
        <cylinder radius="0.013" length="0.145" />
        </geometry>
      </collision>
    <collision name="fork_right_dropout">
      <origin xyz="0 -0.1425 -0.165" rpy="0 1.5708 -1.5708" />
      <geometry>
        <cylinder radius="0.01" length="0.035" />
        </geometry>
      </collision>
    </link>
  <link name="handlebar_stem">
    <visual name="hinge_barrel">
      <origin xyz="0 0 0" rpy="0 1.5708 1.5708" />
      <geometry>
        <cylinder radius="0.027" length="0.08" />
        </geometry>
      <material name="dark_anodized_metal">
        <color rgba="0.03 0.035 0.04 1" />
        </material>
      </visual>
    <visual name="folding_stem">
      <origin xyz="0 0 0.2975" rpy="0 0 0" />
      <geometry>
        <cylinder radius="0.019" length="0.555" />
        </geometry>
      <material name="brushed_aluminum">
        <color rgba="0.72 0.74 0.72 1" />
        </material>
      </visual>
    <visual name="handlebar_clamp">
      <origin xyz="0 0 0.575" rpy="0 1.5708 1.5708" />
      <geometry>
        <cylinder radius="0.023" length="0.11" />
        </geometry>
      <material name="dark_anodized_metal">
        <color rgba="0.03 0.035 0.04 1" />
        </material>
      </visual>
    <visual name="handlebar_bar">
      <origin xyz="0 0 0.61" rpy="0 1.5708 1.5708" />
      <geometry>
        <cylinder radius="0.016" length="0.63" />
        </geometry>
      <material name="brushed_aluminum">
        <color rgba="0.72 0.74 0.72 1" />
        </material>
      </visual>
    <visual name="left_grip">
      <origin xyz="0 0.2825 0.61" rpy="0 1.5708 1.5708" />
      <geometry>
        <cylinder radius="0.02" length="0.075" />
        </geometry>
      <material name="soft_gray_grip">
        <color rgba="0.08 0.085 0.085 1" />
        </material>
      </visual>
    <visual name="right_grip">
      <origin xyz="0 -0.2825 0.61" rpy="0 1.5708 -1.5708" />
      <geometry>
        <cylinder radius="0.02" length="0.075" />
        </geometry>
      <material name="soft_gray_grip">
        <color rgba="0.08 0.085 0.085 1" />
        </material>
      </visual>
    <collision name="hinge_barrel">
      <origin xyz="0 0 0" rpy="0 1.5708 1.5708" />
      <geometry>
        <cylinder radius="0.027" length="0.08" />
        </geometry>
      </collision>
    <collision name="folding_stem">
      <origin xyz="0 0 0.2975" rpy="0 0 0" />
      <geometry>
        <cylinder radius="0.019" length="0.555" />
        </geometry>
      </collision>
    <collision name="handlebar_clamp">
      <origin xyz="0 0 0.575" rpy="0 1.5708 1.5708" />
      <geometry>
        <cylinder radius="0.023" length="0.11" />
        </geometry>
      </collision>
    <collision name="handlebar_bar">
      <origin xyz="0 0 0.61" rpy="0 1.5708 1.5708" />
      <geometry>
        <cylinder radius="0.016" length="0.63" />
        </geometry>
      </collision>
    <collision name="left_grip">
      <origin xyz="0 0.2825 0.61" rpy="0 1.5708 1.5708" />
      <geometry>
        <cylinder radius="0.02" length="0.075" />
        </geometry>
      </collision>
    <collision name="right_grip">
      <origin xyz="0 -0.2825 0.61" rpy="0 1.5708 -1.5708" />
      <geometry>
        <cylinder radius="0.02" length="0.075" />
        </geometry>
      </collision>
    </link>
  <link name="front_left_wheel">
    <visual name="tire">
      <origin xyz="0 0 0" rpy="0 0 1.5708" />
      <geometry>
        <mesh filename="assets/meshes/small_scooter_tire.obj" />
        </geometry>
      <material name="black_rubber">
        <color rgba="0.005 0.005 0.004 1" />
        </material>
      </visual>
    <visual name="rim">
      <origin xyz="0 0 0" rpy="0 0 1.5708" />
      <geometry>
        <mesh filename="assets/meshes/small_scooter_rim.obj" />
        </geometry>
      <material name="brushed_aluminum">
        <color rgba="0.72 0.74 0.72 1" />
        </material>
      </visual>
    <collision name="tire">
      <origin xyz="0 0 0" rpy="0 0 1.5708" />
      <geometry>
        <mesh filename="assets/meshes/small_scooter_tire.obj" />
        </geometry>
      </collision>
    <collision name="rim">
      <origin xyz="0 0 0" rpy="0 0 1.5708" />
      <geometry>
        <mesh filename="assets/meshes/small_scooter_rim.obj" />
        </geometry>
      </collision>
    </link>
  <link name="front_right_wheel">
    <visual name="tire">
      <origin xyz="0 0 0" rpy="0 0 1.5708" />
      <geometry>
        <mesh filename="assets/meshes/small_scooter_tire.obj" />
        </geometry>
      <material name="black_rubber">
        <color rgba="0.005 0.005 0.004 1" />
        </material>
      </visual>
    <visual name="rim">
      <origin xyz="0 0 0" rpy="0 0 1.5708" />
      <geometry>
        <mesh filename="assets/meshes/small_scooter_rim.obj" />
        </geometry>
      <material name="brushed_aluminum">
        <color rgba="0.72 0.74 0.72 1" />
        </material>
      </visual>
    <collision name="tire">
      <origin xyz="0 0 0" rpy="0 0 1.5708" />
      <geometry>
        <mesh filename="assets/meshes/small_scooter_tire.obj" />
        </geometry>
      </collision>
    <collision name="rim">
      <origin xyz="0 0 0" rpy="0 0 1.5708" />
      <geometry>
        <mesh filename="assets/meshes/small_scooter_rim.obj" />
        </geometry>
      </collision>
    </link>
  <link name="rear_left_wheel">
    <visual name="tire">
      <origin xyz="0 0 0" rpy="0 0 1.5708" />
      <geometry>
        <mesh filename="assets/meshes/small_scooter_tire.obj" />
        </geometry>
      <material name="black_rubber">
        <color rgba="0.005 0.005 0.004 1" />
        </material>
      </visual>
    <visual name="rim">
      <origin xyz="0 0 0" rpy="0 0 1.5708" />
      <geometry>
        <mesh filename="assets/meshes/small_scooter_rim.obj" />
        </geometry>
      <material name="brushed_aluminum">
        <color rgba="0.72 0.74 0.72 1" />
        </material>
      </visual>
    <collision name="tire">
      <origin xyz="0 0 0" rpy="0 0 1.5708" />
      <geometry>
        <mesh filename="assets/meshes/small_scooter_tire.obj" />
        </geometry>
      </collision>
    <collision name="rim">
      <origin xyz="0 0 0" rpy="0 0 1.5708" />
      <geometry>
        <mesh filename="assets/meshes/small_scooter_rim.obj" />
        </geometry>
      </collision>
    </link>
  <link name="rear_right_wheel">
    <visual name="tire">
      <origin xyz="0 0 0" rpy="0 0 1.5708" />
      <geometry>
        <mesh filename="assets/meshes/small_scooter_tire.obj" />
        </geometry>
      <material name="black_rubber">
        <color rgba="0.005 0.005 0.004 1" />
        </material>
      </visual>
    <visual name="rim">
      <origin xyz="0 0 0" rpy="0 0 1.5708" />
      <geometry>
        <mesh filename="assets/meshes/small_scooter_rim.obj" />
        </geometry>
      <material name="brushed_aluminum">
        <color rgba="0.72 0.74 0.72 1" />
        </material>
      </visual>
    <collision name="tire">
      <origin xyz="0 0 0" rpy="0 0 1.5708" />
      <geometry>
        <mesh filename="assets/meshes/small_scooter_tire.obj" />
        </geometry>
      </collision>
    <collision name="rim">
      <origin xyz="0 0 0" rpy="0 0 1.5708" />
      <geometry>
        <mesh filename="assets/meshes/small_scooter_rim.obj" />
        </geometry>
      </collision>
    </link>
  <joint name="steering_axis" type="revolute">
    <origin xyz="0.44 0 0.245" rpy="0 0 0" />
    <parent link="frame" />
    <child link="front_fork" />
    <axis xyz="0 0 1" />
    <limit effort="18" velocity="3" lower="-0.75" upper="0.75" />
    </joint>
  <joint name="stem_fold_hinge" type="revolute">
    <origin xyz="0.44 0 0.685" rpy="0 0 0" />
    <parent link="frame" />
    <child link="handlebar_stem" />
    <axis xyz="0 -1 0" />
    <limit effort="12" velocity="1.5" lower="0" upper="1.35" />
    </joint>
  <joint name="front_left_spin" type="continuous">
    <origin xyz="0 0.19 -0.165" rpy="0 0 0" />
    <parent link="front_fork" />
    <child link="front_left_wheel" />
    <axis xyz="0 1 0" />
    <limit effort="2" velocity="20" />
    </joint>
  <joint name="front_right_spin" type="continuous">
    <origin xyz="0 -0.19 -0.165" rpy="0 0 0" />
    <parent link="front_fork" />
    <child link="front_right_wheel" />
    <axis xyz="0 1 0" />
    <limit effort="2" velocity="20" />
    </joint>
  <joint name="rear_left_spin" type="continuous">
    <origin xyz="-0.47 0.19 0.08" rpy="0 0 0" />
    <parent link="frame" />
    <child link="rear_left_wheel" />
    <axis xyz="0 1 0" />
    <limit effort="2" velocity="20" />
    </joint>
  <joint name="rear_right_spin" type="continuous">
    <origin xyz="-0.47 -0.19 0.08" rpy="0 0 0" />
    <parent link="frame" />
    <child link="rear_right_wheel" />
    <axis xyz="0 1 0" />
    <limit effort="2" velocity="20" />
    </joint>
  </robot>
