<robot name="weatherproof_tackle_box">
  <material name="olive_uv_stabilized_polymer">
    <color rgba="0.12 0.22 0.15 1" />
    </material>
  <material name="dark_lid_polymer">
    <color rgba="0.07 0.14 0.1 1" />
    </material>
  <material name="black_epdm_gasket">
    <color rgba="0.005 0.006 0.005 1" />
    </material>
  <material name="marine_stainless">
    <color rgba="0.74 0.76 0.72 1" />
    </material>
  <material name="black_rubber">
    <color rgba="0.015 0.014 0.012 1" />
    </material>
  <link name="shell">
    <visual name="shell_body">
      <geometry>
        <mesh filename="assets/meshes/shell_body.obj" />
        </geometry>
      <material name="olive_uv_stabilized_polymer" />
      </visual>
    <collision name="shell_body">
      <geometry>
        <mesh filename="assets/meshes/shell_body.obj" />
        </geometry>
      </collision>
    </link>
  <link name="keeper_0">
    <visual name="keeper_plate">
      <origin xyz="-0.13 -0.125 0.136" rpy="0 0 0" />
      <geometry>
        <box size="0.074 0.01 0.034" />
        </geometry>
      <material name="marine_stainless" />
      </visual>
    <visual name="keeper_post">
      <origin xyz="-0.13 -0.14 0.135" rpy="1.5708 0 0" />
      <geometry>
        <cylinder radius="0.007" length="0.038" />
        </geometry>
      <material name="marine_stainless" />
      </visual>
    <collision name="keeper_plate">
      <origin xyz="-0.13 -0.125 0.136" rpy="0 0 0" />
      <geometry>
        <box size="0.074 0.01 0.034" />
        </geometry>
      </collision>
    <collision name="keeper_post">
      <origin xyz="-0.13 -0.14 0.135" rpy="1.5708 0 0" />
      <geometry>
        <cylinder radius="0.007" length="0.038" />
        </geometry>
      </collision>
    </link>
  <link name="keeper_1">
    <visual name="keeper_plate">
      <origin xyz="0.13 -0.125 0.136" rpy="0 0 0" />
      <geometry>
        <box size="0.074 0.01 0.034" />
        </geometry>
      <material name="marine_stainless" />
      </visual>
    <visual name="keeper_post">
      <origin xyz="0.13 -0.14 0.135" rpy="1.5708 0 0" />
      <geometry>
        <cylinder radius="0.007" length="0.038" />
        </geometry>
      <material name="marine_stainless" />
      </visual>
    <collision name="keeper_plate">
      <origin xyz="0.13 -0.125 0.136" rpy="0 0 0" />
      <geometry>
        <box size="0.074 0.01 0.034" />
        </geometry>
      </collision>
    <collision name="keeper_post">
      <origin xyz="0.13 -0.14 0.135" rpy="1.5708 0 0" />
      <geometry>
        <cylinder radius="0.007" length="0.038" />
        </geometry>
      </collision>
    </link>
  <link name="hinge_base">
    <visual name="hinge_base_leaf">
      <origin xyz="0 0.124 0.14" rpy="0 0 0" />
      <geometry>
        <box size="0.43 0.008 0.028" />
        </geometry>
      <material name="marine_stainless" />
      </visual>
    <visual name="hinge_base_bridge_0">
      <origin xyz="-0.145 0.138 0.151" rpy="0 0 0" />
      <geometry>
        <box size="0.125 0.024 0.006" />
        </geometry>
      <material name="marine_stainless" />
      </visual>
    <visual name="hinge_base_web_0">
      <origin xyz="-0.145 0.154 0.172" rpy="0 0 0" />
      <geometry>
        <box size="0.125 0.008 0.048" />
        </geometry>
      <material name="marine_stainless" />
      </visual>
    <visual name="hinge_base_knuckle_0">
      <origin xyz="-0.145 0.15 0.195" rpy="0 1.5708 0" />
      <geometry>
        <cylinder radius="0.0065" length="0.145" />
        </geometry>
      <material name="marine_stainless" />
      </visual>
    <visual name="hinge_base_bridge_1">
      <origin xyz="0.145 0.138 0.151" rpy="0 0 0" />
      <geometry>
        <box size="0.125 0.024 0.006" />
        </geometry>
      <material name="marine_stainless" />
      </visual>
    <visual name="hinge_base_web_1">
      <origin xyz="0.145 0.154 0.172" rpy="0 0 0" />
      <geometry>
        <box size="0.125 0.008 0.048" />
        </geometry>
      <material name="marine_stainless" />
      </visual>
    <visual name="hinge_base_knuckle_1">
      <origin xyz="0.145 0.15 0.195" rpy="0 1.5708 0" />
      <geometry>
        <cylinder radius="0.0065" length="0.145" />
        </geometry>
      <material name="marine_stainless" />
      </visual>
    <collision name="hinge_base_leaf">
      <origin xyz="0 0.124 0.14" rpy="0 0 0" />
      <geometry>
        <box size="0.43 0.008 0.028" />
        </geometry>
      </collision>
    <collision name="hinge_base_bridge_0">
      <origin xyz="-0.145 0.138 0.151" rpy="0 0 0" />
      <geometry>
        <box size="0.125 0.024 0.006" />
        </geometry>
      </collision>
    <collision name="hinge_base_web_0">
      <origin xyz="-0.145 0.154 0.172" rpy="0 0 0" />
      <geometry>
        <box size="0.125 0.008 0.048" />
        </geometry>
      </collision>
    <collision name="hinge_base_knuckle_0">
      <origin xyz="-0.145 0.15 0.195" rpy="0 1.5708 0" />
      <geometry>
        <cylinder radius="0.0065" length="0.145" />
        </geometry>
      </collision>
    <collision name="hinge_base_bridge_1">
      <origin xyz="0.145 0.138 0.151" rpy="0 0 0" />
      <geometry>
        <box size="0.125 0.024 0.006" />
        </geometry>
      </collision>
    <collision name="hinge_base_web_1">
      <origin xyz="0.145 0.154 0.172" rpy="0 0 0" />
      <geometry>
        <box size="0.125 0.008 0.048" />
        </geometry>
      </collision>
    <collision name="hinge_base_knuckle_1">
      <origin xyz="0.145 0.15 0.195" rpy="0 1.5708 0" />
      <geometry>
        <cylinder radius="0.0065" length="0.145" />
        </geometry>
      </collision>
    </link>
  <link name="lid">
    <visual name="lid_body">
      <geometry>
        <mesh filename="assets/meshes/lid_body.obj" />
        </geometry>
      <material name="dark_lid_polymer" />
      </visual>
    <visual name="gasket_ring">
      <geometry>
        <mesh filename="assets/meshes/gasket_ring.obj" />
        </geometry>
      <material name="black_epdm_gasket" />
      </visual>
    <visual name="hinge_lid_leaf">
      <origin xyz="0 0.003 -0.012" rpy="0 0 0" />
      <geometry>
        <box size="0.145 0.026 0.024" />
        </geometry>
      <material name="marine_stainless" />
      </visual>
    <visual name="hinge_lid_knuckle">
      <origin xyz="0 0 0" rpy="0 1.5708 0" />
      <geometry>
        <cylinder radius="0.0063" length="0.145" />
        </geometry>
      <material name="marine_stainless" />
      </visual>
    <collision name="lid_body">
      <geometry>
        <mesh filename="assets/meshes/lid_body.obj" />
        </geometry>
      </collision>
    <collision name="gasket_ring">
      <geometry>
        <mesh filename="assets/meshes/gasket_ring.obj" />
        </geometry>
      </collision>
    <collision name="hinge_lid_leaf">
      <origin xyz="0 0.003 -0.012" rpy="0 0 0" />
      <geometry>
        <box size="0.145 0.026 0.024" />
        </geometry>
      </collision>
    <collision name="hinge_lid_knuckle">
      <origin xyz="0 0 0" rpy="0 1.5708 0" />
      <geometry>
        <cylinder radius="0.0063" length="0.145" />
        </geometry>
      </collision>
    </link>
  <link name="latch_0">
    <visual name="latch_plate">
      <geometry>
        <mesh filename="assets/meshes/latch_plate.obj" />
        </geometry>
      <material name="marine_stainless" />
      </visual>
    <visual name="thumb_pad">
      <origin xyz="0 -0.01 -0.076" rpy="0 0 0" />
      <geometry>
        <box size="0.052 0.01 0.012" />
        </geometry>
      <material name="black_rubber" />
      </visual>
    <collision name="latch_plate">
      <geometry>
        <mesh filename="assets/meshes/latch_plate.obj" />
        </geometry>
      </collision>
    <collision name="thumb_pad">
      <origin xyz="0 -0.01 -0.076" rpy="0 0 0" />
      <geometry>
        <box size="0.052 0.01 0.012" />
        </geometry>
      </collision>
    </link>
  <link name="latch_1">
    <visual name="latch_plate">
      <geometry>
        <mesh filename="assets/meshes/latch_plate.obj" />
        </geometry>
      <material name="marine_stainless" />
      </visual>
    <visual name="thumb_pad">
      <origin xyz="0 -0.01 -0.076" rpy="0 0 0" />
      <geometry>
        <box size="0.052 0.01 0.012" />
        </geometry>
      <material name="black_rubber" />
      </visual>
    <collision name="latch_plate">
      <geometry>
        <mesh filename="assets/meshes/latch_plate.obj" />
        </geometry>
      </collision>
    <collision name="thumb_pad">
      <origin xyz="0 -0.01 -0.076" rpy="0 0 0" />
      <geometry>
        <box size="0.052 0.01 0.012" />
        </geometry>
      </collision>
    </link>
  <joint name="shell_to_keeper_0" type="fixed">
    <parent link="shell" />
    <child link="keeper_0" />
    </joint>
  <joint name="shell_to_keeper_1" type="fixed">
    <parent link="shell" />
    <child link="keeper_1" />
    </joint>
  <joint name="shell_to_hinge_base" type="fixed">
    <parent link="shell" />
    <child link="hinge_base" />
    </joint>
  <joint name="lid_hinge" type="revolute">
    <origin xyz="0 0.15 0.195" rpy="0 0 0" />
    <parent link="shell" />
    <child link="lid" />
    <axis xyz="-1 0 0" />
    <limit effort="16" velocity="2" lower="0" upper="1.75" />
    </joint>
  <joint name="latch_hinge_0" type="revolute">
    <origin xyz="-0.13 -0.311 -0.005" rpy="0 0 0" />
    <parent link="lid" />
    <child link="latch_0" />
    <axis xyz="-1 0 0" />
    <limit effort="4" velocity="4" lower="0" upper="1.25" />
    </joint>
  <joint name="latch_hinge_1" type="revolute">
    <origin xyz="0.13 -0.311 -0.005" rpy="0 0 0" />
    <parent link="lid" />
    <child link="latch_1" />
    <axis xyz="-1 0 0" />
    <limit effort="4" velocity="4" lower="0" upper="1.25" />
    </joint>
  </robot>
