<robot name="compact_speedlight_flash">
  <material name="matte_black">
    <color rgba="0.015 0.014 0.013 1" />
    </material>
  <material name="dark_plastic">
    <color rgba="0.055 0.055 0.052 1" />
    </material>
  <material name="rubber_grip">
    <color rgba="0.02 0.02 0.018 1" />
    </material>
  <material name="brushed_metal">
    <color rgba="0.55 0.54 0.5 1" />
    </material>
  <material name="warm_diffuser">
    <color rgba="1 0.86 0.48 0.78" />
    </material>
  <material name="milky_plastic">
    <color rgba="0.92 0.94 0.9 0.86" />
    </material>
  <material name="red_window">
    <color rgba="0.75 0.05 0.025 0.82" />
    </material>
  <link name="body">
    <visual name="battery_body">
      <origin xyz="0 0 0.065" rpy="0 0 0" />
      <geometry>
        <box size="0.048 0.058 0.105" />
        </geometry>
      <material name="matte_black">
        <color rgba="0.015 0.014 0.013 1" />
        </material>
      </visual>
    <visual name="lower_battery_step">
      <origin xyz="0 0 0.01" rpy="0 0 0" />
      <geometry>
        <box size="0.054 0.064 0.02" />
        </geometry>
      <material name="dark_plastic">
        <color rgba="0.055 0.055 0.052 1" />
        </material>
      </visual>
    <visual name="top_turntable_seat">
      <origin xyz="0 0 0.1215" rpy="0 0 0" />
      <geometry>
        <box size="0.03 0.034 0.008" />
        </geometry>
      <material name="dark_plastic">
        <color rgba="0.055 0.055 0.052 1" />
        </material>
      </visual>
    <visual name="front_battery_door">
      <origin xyz="0.0235 0 0.069" rpy="0 0 0" />
      <geometry>
        <box size="0.003 0.044 0.073" />
        </geometry>
      <material name="rubber_grip">
        <color rgba="0.02 0.02 0.018 1" />
        </material>
      </visual>
    <visual name="focus_assist_window">
      <origin xyz="0.024 0 0.109" rpy="0 0 0" />
      <geometry>
        <box size="0.003 0.022 0.012" />
        </geometry>
      <material name="red_window">
        <color rgba="0.75 0.05 0.025 0.82" />
        </material>
      </visual>
    <visual name="shoe_plate">
      <origin xyz="0 0 -0.003" rpy="0 0 0" />
      <geometry>
        <box size="0.04 0.05 0.006" />
        </geometry>
      <material name="brushed_metal">
        <color rgba="0.55 0.54 0.5 1" />
        </material>
      </visual>
    <visual name="shoe_rail_0">
      <origin xyz="0 0.0215 -0.009" rpy="0 0 0" />
      <geometry>
        <box size="0.046 0.007 0.008" />
        </geometry>
      <material name="brushed_metal">
        <color rgba="0.55 0.54 0.5 1" />
        </material>
      </visual>
    <visual name="shoe_rail_1">
      <origin xyz="0 -0.0215 -0.009" rpy="0 0 0" />
      <geometry>
        <box size="0.046 0.007 0.008" />
        </geometry>
      <material name="brushed_metal">
        <color rgba="0.55 0.54 0.5 1" />
        </material>
      </visual>
    <collision name="battery_body">
      <origin xyz="0 0 0.065" rpy="0 0 0" />
      <geometry>
        <box size="0.048 0.058 0.105" />
        </geometry>
      </collision>
    <collision name="lower_battery_step">
      <origin xyz="0 0 0.01" rpy="0 0 0" />
      <geometry>
        <box size="0.054 0.064 0.02" />
        </geometry>
      </collision>
    <collision name="top_turntable_seat">
      <origin xyz="0 0 0.1215" rpy="0 0 0" />
      <geometry>
        <box size="0.03 0.034 0.008" />
        </geometry>
      </collision>
    <collision name="front_battery_door">
      <origin xyz="0.0235 0 0.069" rpy="0 0 0" />
      <geometry>
        <box size="0.003 0.044 0.073" />
        </geometry>
      </collision>
    <collision name="focus_assist_window">
      <origin xyz="0.024 0 0.109" rpy="0 0 0" />
      <geometry>
        <box size="0.003 0.022 0.012" />
        </geometry>
      </collision>
    <collision name="shoe_plate">
      <origin xyz="0 0 -0.003" rpy="0 0 0" />
      <geometry>
        <box size="0.04 0.05 0.006" />
        </geometry>
      </collision>
    <collision name="shoe_rail_0">
      <origin xyz="0 0.0215 -0.009" rpy="0 0 0" />
      <geometry>
        <box size="0.046 0.007 0.008" />
        </geometry>
      </collision>
    <collision name="shoe_rail_1">
      <origin xyz="0 -0.0215 -0.009" rpy="0 0 0" />
      <geometry>
        <box size="0.046 0.007 0.008" />
        </geometry>
      </collision>
    </link>
  <link name="swivel">
    <visual name="turntable_collar">
      <origin xyz="0 0 0.009" rpy="0 0 0" />
      <geometry>
        <cylinder radius="0.018" length="0.018" />
        </geometry>
      <material name="dark_plastic">
        <color rgba="0.055 0.055 0.052 1" />
        </material>
      </visual>
    <visual name="neck_stem">
      <origin xyz="0 0 0.033" rpy="0 0 0" />
      <geometry>
        <box size="0.022 0.028 0.04" />
        </geometry>
      <material name="dark_plastic">
        <color rgba="0.055 0.055 0.052 1" />
        </material>
      </visual>
    <visual name="yoke_bridge">
      <origin xyz="0 0 0.049" rpy="0 0 0" />
      <geometry>
        <box size="0.024 0.092 0.014" />
        </geometry>
      <material name="dark_plastic">
        <color rgba="0.055 0.055 0.052 1" />
        </material>
      </visual>
    <visual name="yoke_arm_0">
      <origin xyz="0 0.0425 0.064" rpy="0 0 0" />
      <geometry>
        <box size="0.02 0.008 0.05" />
        </geometry>
      <material name="dark_plastic">
        <color rgba="0.055 0.055 0.052 1" />
        </material>
      </visual>
    <visual name="yoke_arm_1">
      <origin xyz="0 -0.0425 0.064" rpy="0 0 0" />
      <geometry>
        <box size="0.02 0.008 0.05" />
        </geometry>
      <material name="dark_plastic">
        <color rgba="0.055 0.055 0.052 1" />
        </material>
      </visual>
    <visual name="tilt_socket_0">
      <origin xyz="0 0.04 0.07" rpy="-1.5708 0 0" />
      <geometry>
        <cylinder radius="0.012" length="0.006" />
        </geometry>
      <material name="dark_plastic">
        <color rgba="0.055 0.055 0.052 1" />
        </material>
      </visual>
    <visual name="tilt_socket_1">
      <origin xyz="0 -0.04 0.07" rpy="-1.5708 0 0" />
      <geometry>
        <cylinder radius="0.012" length="0.006" />
        </geometry>
      <material name="dark_plastic">
        <color rgba="0.055 0.055 0.052 1" />
        </material>
      </visual>
    <collision name="turntable_collar">
      <origin xyz="0 0 0.009" rpy="0 0 0" />
      <geometry>
        <cylinder radius="0.018" length="0.018" />
        </geometry>
      </collision>
    <collision name="neck_stem">
      <origin xyz="0 0 0.033" rpy="0 0 0" />
      <geometry>
        <box size="0.022 0.028 0.04" />
        </geometry>
      </collision>
    <collision name="yoke_bridge">
      <origin xyz="0 0 0.049" rpy="0 0 0" />
      <geometry>
        <box size="0.024 0.092 0.014" />
        </geometry>
      </collision>
    <collision name="yoke_arm_0">
      <origin xyz="0 0.0425 0.064" rpy="0 0 0" />
      <geometry>
        <box size="0.02 0.008 0.05" />
        </geometry>
      </collision>
    <collision name="yoke_arm_1">
      <origin xyz="0 -0.0425 0.064" rpy="0 0 0" />
      <geometry>
        <box size="0.02 0.008 0.05" />
        </geometry>
      </collision>
    <collision name="tilt_socket_0">
      <origin xyz="0 0.04 0.07" rpy="-1.5708 0 0" />
      <geometry>
        <cylinder radius="0.012" length="0.006" />
        </geometry>
      </collision>
    <collision name="tilt_socket_1">
      <origin xyz="0 -0.04 0.07" rpy="-1.5708 0 0" />
      <geometry>
        <cylinder radius="0.012" length="0.006" />
        </geometry>
      </collision>
    </link>
  <link name="head">
    <visual name="bottom_shell">
      <origin xyz="0.037 0 -0.011" rpy="0 0 0" />
      <geometry>
        <box size="0.074 0.074 0.006" />
        </geometry>
      <material name="matte_black">
        <color rgba="0.015 0.014 0.013 1" />
        </material>
      </visual>
    <visual name="side_shell_0">
      <origin xyz="0.037 0.034 0.011" rpy="0 0 0" />
      <geometry>
        <box size="0.074 0.006 0.05" />
        </geometry>
      <material name="matte_black">
        <color rgba="0.015 0.014 0.013 1" />
        </material>
      </visual>
    <visual name="side_shell_1">
      <origin xyz="0.037 -0.034 0.011" rpy="0 0 0" />
      <geometry>
        <box size="0.074 0.006 0.05" />
        </geometry>
      <material name="matte_black">
        <color rgba="0.015 0.014 0.013 1" />
        </material>
      </visual>
    <visual name="rear_shell">
      <origin xyz="0.003 0 0.011" rpy="0 0 0" />
      <geometry>
        <box size="0.006 0.074 0.05" />
        </geometry>
      <material name="matte_black">
        <color rgba="0.015 0.014 0.013 1" />
        </material>
      </visual>
    <visual name="rear_slot_lip">
      <origin xyz="0.0135 0 0.038" rpy="0 0 0" />
      <geometry>
        <box size="0.003 0.074 0.004" />
        </geometry>
      <material name="matte_black">
        <color rgba="0.015 0.014 0.013 1" />
        </material>
      </visual>
    <visual name="front_slot_lip">
      <origin xyz="0.0265 0 0.038" rpy="0 0 0" />
      <geometry>
        <box size="0.003 0.074 0.004" />
        </geometry>
      <material name="matte_black">
        <color rgba="0.015 0.014 0.013 1" />
        </material>
      </visual>
    <visual name="front_bezel_top">
      <origin xyz="0.076 0 0.027" rpy="0 0 0" />
      <geometry>
        <box size="0.004 0.064 0.006" />
        </geometry>
      <material name="matte_black">
        <color rgba="0.015 0.014 0.013 1" />
        </material>
      </visual>
    <visual name="front_bezel_bottom">
      <origin xyz="0.076 0 -0.011" rpy="0 0 0" />
      <geometry>
        <box size="0.004 0.064 0.006" />
        </geometry>
      <material name="matte_black">
        <color rgba="0.015 0.014 0.013 1" />
        </material>
      </visual>
    <visual name="front_bezel_0">
      <origin xyz="0.076 0.031 0.008" rpy="0 0 0" />
      <geometry>
        <box size="0.004 0.006 0.044" />
        </geometry>
      <material name="matte_black">
        <color rgba="0.015 0.014 0.013 1" />
        </material>
      </visual>
    <visual name="front_bezel_1">
      <origin xyz="0.076 -0.031 0.008" rpy="0 0 0" />
      <geometry>
        <box size="0.004 0.006 0.044" />
        </geometry>
      <material name="matte_black">
        <color rgba="0.015 0.014 0.013 1" />
        </material>
      </visual>
    <visual name="lamp_diffuser">
      <origin xyz="0.078 0 0.008" rpy="0 0 0" />
      <geometry>
        <box size="0.004 0.058 0.034" />
        </geometry>
      <material name="warm_diffuser">
        <color rgba="1 0.86 0.48 0.78" />
        </material>
      </visual>
    <visual name="tilt_barrel">
      <origin xyz="0 0 0" rpy="-1.5708 0 0" />
      <geometry>
        <cylinder radius="0.01" length="0.072" />
        </geometry>
      <material name="dark_plastic">
        <color rgba="0.055 0.055 0.052 1" />
        </material>
      </visual>
    <collision name="bottom_shell">
      <origin xyz="0.037 0 -0.011" rpy="0 0 0" />
      <geometry>
        <box size="0.074 0.074 0.006" />
        </geometry>
      </collision>
    <collision name="side_shell_0">
      <origin xyz="0.037 0.034 0.011" rpy="0 0 0" />
      <geometry>
        <box size="0.074 0.006 0.05" />
        </geometry>
      </collision>
    <collision name="side_shell_1">
      <origin xyz="0.037 -0.034 0.011" rpy="0 0 0" />
      <geometry>
        <box size="0.074 0.006 0.05" />
        </geometry>
      </collision>
    <collision name="rear_shell">
      <origin xyz="0.003 0 0.011" rpy="0 0 0" />
      <geometry>
        <box size="0.006 0.074 0.05" />
        </geometry>
      </collision>
    <collision name="rear_slot_lip">
      <origin xyz="0.0135 0 0.038" rpy="0 0 0" />
      <geometry>
        <box size="0.003 0.074 0.004" />
        </geometry>
      </collision>
    <collision name="front_slot_lip">
      <origin xyz="0.0265 0 0.038" rpy="0 0 0" />
      <geometry>
        <box size="0.003 0.074 0.004" />
        </geometry>
      </collision>
    <collision name="front_bezel_top">
      <origin xyz="0.076 0 0.027" rpy="0 0 0" />
      <geometry>
        <box size="0.004 0.064 0.006" />
        </geometry>
      </collision>
    <collision name="front_bezel_bottom">
      <origin xyz="0.076 0 -0.011" rpy="0 0 0" />
      <geometry>
        <box size="0.004 0.064 0.006" />
        </geometry>
      </collision>
    <collision name="front_bezel_0">
      <origin xyz="0.076 0.031 0.008" rpy="0 0 0" />
      <geometry>
        <box size="0.004 0.006 0.044" />
        </geometry>
      </collision>
    <collision name="front_bezel_1">
      <origin xyz="0.076 -0.031 0.008" rpy="0 0 0" />
      <geometry>
        <box size="0.004 0.006 0.044" />
        </geometry>
      </collision>
    <collision name="lamp_diffuser">
      <origin xyz="0.078 0 0.008" rpy="0 0 0" />
      <geometry>
        <box size="0.004 0.058 0.034" />
        </geometry>
      </collision>
    <collision name="tilt_barrel">
      <origin xyz="0 0 0" rpy="-1.5708 0 0" />
      <geometry>
        <cylinder radius="0.01" length="0.072" />
        </geometry>
      </collision>
    </link>
  <link name="bounce_card">
    <visual name="white_card">
      <origin xyz="0 0 -0.019" rpy="0 0 0" />
      <geometry>
        <box size="0.003 0.062 0.048" />
        </geometry>
      <material name="milky_plastic">
        <color rgba="0.92 0.94 0.9 0.86" />
        </material>
      </visual>
    <visual name="pull_tab">
      <origin xyz="0 0 0.006" rpy="0 0 0" />
      <geometry>
        <box size="0.005 0.062 0.004" />
        </geometry>
      <material name="milky_plastic">
        <color rgba="0.92 0.94 0.9 0.86" />
        </material>
      </visual>
    <collision name="white_card">
      <origin xyz="0 0 -0.019" rpy="0 0 0" />
      <geometry>
        <box size="0.003 0.062 0.048" />
        </geometry>
      </collision>
    <collision name="pull_tab">
      <origin xyz="0 0 0.006" rpy="0 0 0" />
      <geometry>
        <box size="0.005 0.062 0.004" />
        </geometry>
      </collision>
    </link>
  <joint name="body_to_swivel" type="revolute">
    <origin xyz="0 0 0.1255" rpy="0 0 0" />
    <parent link="body" />
    <child link="swivel" />
    <axis xyz="0 0 1" />
    <limit effort="1.2" velocity="4" lower="-3.14159" upper="3.14159" />
    </joint>
  <joint name="swivel_to_head" type="revolute">
    <origin xyz="0 0 0.07" rpy="0 0 0" />
    <parent link="swivel" />
    <child link="head" />
    <axis xyz="0 1 0" />
    <limit effort="1" velocity="2.5" lower="-0.35" upper="1.45" />
    </joint>
  <joint name="head_to_bounce_card" type="prismatic">
    <origin xyz="0.02 0 0.036" rpy="0 0 0" />
    <parent link="head" />
    <child link="bounce_card" />
    <axis xyz="0 0 1" />
    <limit effort="0.25" velocity="0.18" lower="0" upper="0.04" />
    </joint>
  </robot>
