<robot name="server_tower_chassis">
  <material name="zinc_plated_steel">
    <color rgba="0.62 0.65 0.66 1" />
    </material>
  <material name="dark_powder_coat">
    <color rgba="0.08 0.09 0.1 1" />
    </material>
  <material name="black_plastic">
    <color rgba="0.015 0.016 0.018 1" />
    </material>
  <material name="blue_release_tabs">
    <color rgba="0.05 0.22 0.75 1" />
    </material>
  <material name="dark_perforated_vent">
    <color rgba="0.02 0.025 0.03 0.82" />
    </material>
  <link name="chassis">
    <visual name="bottom_tray">
      <origin xyz="0 0 0.006" rpy="0 0 0" />
      <geometry>
        <box size="0.72 0.46 0.012" />
        </geometry>
      <material name="zinc_plated_steel">
        <color rgba="0.62 0.65 0.66 1" />
        </material>
      </visual>
    <visual name="top_tray">
      <origin xyz="0 0 1.194" rpy="0 0 0" />
      <geometry>
        <box size="0.72 0.46 0.012" />
        </geometry>
      <material name="zinc_plated_steel">
        <color rgba="0.62 0.65 0.66 1" />
        </material>
      </visual>
    <visual name="rear_plate">
      <origin xyz="0.354 0 0.6" rpy="0 0 0" />
      <geometry>
        <box size="0.012 0.46 1.2" />
        </geometry>
      <material name="dark_powder_coat">
        <color rgba="0.08 0.09 0.1 1" />
        </material>
      </visual>
    <visual name="front_post_0">
      <origin xyz="-0.354 -0.2075 0.6" rpy="0 0 0" />
      <geometry>
        <box size="0.012 0.045 1.2" />
        </geometry>
      <material name="zinc_plated_steel">
        <color rgba="0.62 0.65 0.66 1" />
        </material>
      </visual>
    <visual name="front_post_1">
      <origin xyz="-0.354 0.2075 0.6" rpy="0 0 0" />
      <geometry>
        <box size="0.012 0.045 1.2" />
        </geometry>
      <material name="zinc_plated_steel">
        <color rgba="0.62 0.65 0.66 1" />
        </material>
      </visual>
    <visual name="front_sill">
      <origin xyz="-0.354 0 0.025" rpy="0 0 0" />
      <geometry>
        <box size="0.012 0.46 0.05" />
        </geometry>
      <material name="zinc_plated_steel">
        <color rgba="0.62 0.65 0.66 1" />
        </material>
      </visual>
    <visual name="front_header">
      <origin xyz="-0.354 0 1.175" rpy="0 0 0" />
      <geometry>
        <box size="0.012 0.46 0.05" />
        </geometry>
      <material name="zinc_plated_steel">
        <color rgba="0.62 0.65 0.66 1" />
        </material>
      </visual>
    <visual name="drive_bay_shadow">
      <origin xyz="-0.348 0 0.57" rpy="0 0 0" />
      <geometry>
        <box size="0.008 0.39 0.84" />
        </geometry>
      <material name="black_plastic">
        <color rgba="0.015 0.016 0.018 1" />
        </material>
      </visual>
    <visual name="rail_0_a">
      <origin xyz="0 -0.18 0.222" rpy="0 0 0" />
      <geometry>
        <box size="0.696 0.012 0.014" />
        </geometry>
      <material name="zinc_plated_steel">
        <color rgba="0.62 0.65 0.66 1" />
        </material>
      </visual>
    <visual name="rail_0_b">
      <origin xyz="0 0.18 0.222" rpy="0 0 0" />
      <geometry>
        <box size="0.696 0.012 0.014" />
        </geometry>
      <material name="zinc_plated_steel">
        <color rgba="0.62 0.65 0.66 1" />
        </material>
      </visual>
    <visual name="rail_1_a">
      <origin xyz="0 -0.18 0.332" rpy="0 0 0" />
      <geometry>
        <box size="0.696 0.012 0.014" />
        </geometry>
      <material name="zinc_plated_steel">
        <color rgba="0.62 0.65 0.66 1" />
        </material>
      </visual>
    <visual name="rail_1_b">
      <origin xyz="0 0.18 0.332" rpy="0 0 0" />
      <geometry>
        <box size="0.696 0.012 0.014" />
        </geometry>
      <material name="zinc_plated_steel">
        <color rgba="0.62 0.65 0.66 1" />
        </material>
      </visual>
    <visual name="rail_2_a">
      <origin xyz="0 -0.18 0.442" rpy="0 0 0" />
      <geometry>
        <box size="0.696 0.012 0.014" />
        </geometry>
      <material name="zinc_plated_steel">
        <color rgba="0.62 0.65 0.66 1" />
        </material>
      </visual>
    <visual name="rail_2_b">
      <origin xyz="0 0.18 0.442" rpy="0 0 0" />
      <geometry>
        <box size="0.696 0.012 0.014" />
        </geometry>
      <material name="zinc_plated_steel">
        <color rgba="0.62 0.65 0.66 1" />
        </material>
      </visual>
    <visual name="rail_3_a">
      <origin xyz="0 -0.18 0.552" rpy="0 0 0" />
      <geometry>
        <box size="0.696 0.012 0.014" />
        </geometry>
      <material name="zinc_plated_steel">
        <color rgba="0.62 0.65 0.66 1" />
        </material>
      </visual>
    <visual name="rail_3_b">
      <origin xyz="0 0.18 0.552" rpy="0 0 0" />
      <geometry>
        <box size="0.696 0.012 0.014" />
        </geometry>
      <material name="zinc_plated_steel">
        <color rgba="0.62 0.65 0.66 1" />
        </material>
      </visual>
    <visual name="side0_hinge_leaf_0">
      <origin xyz="0.374 0.2475 0.09" rpy="0 0 0" />
      <geometry>
        <box size="0.028 0.035 0.18" />
        </geometry>
      <material name="dark_powder_coat">
        <color rgba="0.08 0.09 0.1 1" />
        </material>
      </visual>
    <visual name="side0_fixed_knuckle_0">
      <origin xyz="0.374 0.265 0.09" rpy="0 0 0" />
      <geometry>
        <cylinder radius="0.014" length="0.18" />
        </geometry>
      <material name="dark_powder_coat">
        <color rgba="0.08 0.09 0.1 1" />
        </material>
      </visual>
    <visual name="side0_hinge_leaf_1">
      <origin xyz="0.374 0.2475 0.48" rpy="0 0 0" />
      <geometry>
        <box size="0.028 0.035 0.18" />
        </geometry>
      <material name="dark_powder_coat">
        <color rgba="0.08 0.09 0.1 1" />
        </material>
      </visual>
    <visual name="side0_fixed_knuckle_1">
      <origin xyz="0.374 0.265 0.48" rpy="0 0 0" />
      <geometry>
        <cylinder radius="0.014" length="0.18" />
        </geometry>
      <material name="dark_powder_coat">
        <color rgba="0.08 0.09 0.1 1" />
        </material>
      </visual>
    <visual name="side0_hinge_leaf_2">
      <origin xyz="0.374 0.2475 0.87" rpy="0 0 0" />
      <geometry>
        <box size="0.028 0.035 0.18" />
        </geometry>
      <material name="dark_powder_coat">
        <color rgba="0.08 0.09 0.1 1" />
        </material>
      </visual>
    <visual name="side0_fixed_knuckle_2">
      <origin xyz="0.374 0.265 0.87" rpy="0 0 0" />
      <geometry>
        <cylinder radius="0.014" length="0.18" />
        </geometry>
      <material name="dark_powder_coat">
        <color rgba="0.08 0.09 0.1 1" />
        </material>
      </visual>
    <visual name="side1_hinge_leaf_0">
      <origin xyz="0.374 -0.2475 0.09" rpy="0 0 0" />
      <geometry>
        <box size="0.028 0.035 0.18" />
        </geometry>
      <material name="dark_powder_coat">
        <color rgba="0.08 0.09 0.1 1" />
        </material>
      </visual>
    <visual name="side1_fixed_knuckle_0">
      <origin xyz="0.374 -0.265 0.09" rpy="0 0 0" />
      <geometry>
        <cylinder radius="0.014" length="0.18" />
        </geometry>
      <material name="dark_powder_coat">
        <color rgba="0.08 0.09 0.1 1" />
        </material>
      </visual>
    <visual name="side1_hinge_leaf_1">
      <origin xyz="0.374 -0.2475 0.48" rpy="0 0 0" />
      <geometry>
        <box size="0.028 0.035 0.18" />
        </geometry>
      <material name="dark_powder_coat">
        <color rgba="0.08 0.09 0.1 1" />
        </material>
      </visual>
    <visual name="side1_fixed_knuckle_1">
      <origin xyz="0.374 -0.265 0.48" rpy="0 0 0" />
      <geometry>
        <cylinder radius="0.014" length="0.18" />
        </geometry>
      <material name="dark_powder_coat">
        <color rgba="0.08 0.09 0.1 1" />
        </material>
      </visual>
    <visual name="side1_hinge_leaf_2">
      <origin xyz="0.374 -0.2475 0.87" rpy="0 0 0" />
      <geometry>
        <box size="0.028 0.035 0.18" />
        </geometry>
      <material name="dark_powder_coat">
        <color rgba="0.08 0.09 0.1 1" />
        </material>
      </visual>
    <visual name="side1_fixed_knuckle_2">
      <origin xyz="0.374 -0.265 0.87" rpy="0 0 0" />
      <geometry>
        <cylinder radius="0.014" length="0.18" />
        </geometry>
      <material name="dark_powder_coat">
        <color rgba="0.08 0.09 0.1 1" />
        </material>
      </visual>
    <visual name="cable_hinge_tab_0">
      <origin xyz="0.37 -0.173 0.34" rpy="0 0 0" />
      <geometry>
        <box size="0.036 0.04 0.12" />
        </geometry>
      <material name="dark_powder_coat">
        <color rgba="0.08 0.09 0.1 1" />
        </material>
      </visual>
    <visual name="cable_fixed_knuckle_0">
      <origin xyz="0.388 -0.185 0.34" rpy="0 0 0" />
      <geometry>
        <cylinder radius="0.011" length="0.12" />
        </geometry>
      <material name="dark_powder_coat">
        <color rgba="0.08 0.09 0.1 1" />
        </material>
      </visual>
    <visual name="cable_hinge_tab_1">
      <origin xyz="0.37 -0.173 0.56" rpy="0 0 0" />
      <geometry>
        <box size="0.036 0.04 0.12" />
        </geometry>
      <material name="dark_powder_coat">
        <color rgba="0.08 0.09 0.1 1" />
        </material>
      </visual>
    <visual name="cable_fixed_knuckle_1">
      <origin xyz="0.388 -0.185 0.56" rpy="0 0 0" />
      <geometry>
        <cylinder radius="0.011" length="0.12" />
        </geometry>
      <material name="dark_powder_coat">
        <color rgba="0.08 0.09 0.1 1" />
        </material>
      </visual>
    <collision name="bottom_tray">
      <origin xyz="0 0 0.006" rpy="0 0 0" />
      <geometry>
        <box size="0.72 0.46 0.012" />
        </geometry>
      </collision>
    <collision name="top_tray">
      <origin xyz="0 0 1.194" rpy="0 0 0" />
      <geometry>
        <box size="0.72 0.46 0.012" />
        </geometry>
      </collision>
    <collision name="rear_plate">
      <origin xyz="0.354 0 0.6" rpy="0 0 0" />
      <geometry>
        <box size="0.012 0.46 1.2" />
        </geometry>
      </collision>
    <collision name="front_post_0">
      <origin xyz="-0.354 -0.2075 0.6" rpy="0 0 0" />
      <geometry>
        <box size="0.012 0.045 1.2" />
        </geometry>
      </collision>
    <collision name="front_post_1">
      <origin xyz="-0.354 0.2075 0.6" rpy="0 0 0" />
      <geometry>
        <box size="0.012 0.045 1.2" />
        </geometry>
      </collision>
    <collision name="front_sill">
      <origin xyz="-0.354 0 0.025" rpy="0 0 0" />
      <geometry>
        <box size="0.012 0.46 0.05" />
        </geometry>
      </collision>
    <collision name="front_header">
      <origin xyz="-0.354 0 1.175" rpy="0 0 0" />
      <geometry>
        <box size="0.012 0.46 0.05" />
        </geometry>
      </collision>
    <collision name="drive_bay_shadow">
      <origin xyz="-0.348 0 0.57" rpy="0 0 0" />
      <geometry>
        <box size="0.008 0.39 0.84" />
        </geometry>
      </collision>
    <collision name="rail_0_a">
      <origin xyz="0 -0.18 0.222" rpy="0 0 0" />
      <geometry>
        <box size="0.696 0.012 0.014" />
        </geometry>
      </collision>
    <collision name="rail_0_b">
      <origin xyz="0 0.18 0.222" rpy="0 0 0" />
      <geometry>
        <box size="0.696 0.012 0.014" />
        </geometry>
      </collision>
    <collision name="rail_1_a">
      <origin xyz="0 -0.18 0.332" rpy="0 0 0" />
      <geometry>
        <box size="0.696 0.012 0.014" />
        </geometry>
      </collision>
    <collision name="rail_1_b">
      <origin xyz="0 0.18 0.332" rpy="0 0 0" />
      <geometry>
        <box size="0.696 0.012 0.014" />
        </geometry>
      </collision>
    <collision name="rail_2_a">
      <origin xyz="0 -0.18 0.442" rpy="0 0 0" />
      <geometry>
        <box size="0.696 0.012 0.014" />
        </geometry>
      </collision>
    <collision name="rail_2_b">
      <origin xyz="0 0.18 0.442" rpy="0 0 0" />
      <geometry>
        <box size="0.696 0.012 0.014" />
        </geometry>
      </collision>
    <collision name="rail_3_a">
      <origin xyz="0 -0.18 0.552" rpy="0 0 0" />
      <geometry>
        <box size="0.696 0.012 0.014" />
        </geometry>
      </collision>
    <collision name="rail_3_b">
      <origin xyz="0 0.18 0.552" rpy="0 0 0" />
      <geometry>
        <box size="0.696 0.012 0.014" />
        </geometry>
      </collision>
    <collision name="side0_hinge_leaf_0">
      <origin xyz="0.374 0.2475 0.09" rpy="0 0 0" />
      <geometry>
        <box size="0.028 0.035 0.18" />
        </geometry>
      </collision>
    <collision name="side0_fixed_knuckle_0">
      <origin xyz="0.374 0.265 0.09" rpy="0 0 0" />
      <geometry>
        <cylinder radius="0.014" length="0.18" />
        </geometry>
      </collision>
    <collision name="side0_hinge_leaf_1">
      <origin xyz="0.374 0.2475 0.48" rpy="0 0 0" />
      <geometry>
        <box size="0.028 0.035 0.18" />
        </geometry>
      </collision>
    <collision name="side0_fixed_knuckle_1">
      <origin xyz="0.374 0.265 0.48" rpy="0 0 0" />
      <geometry>
        <cylinder radius="0.014" length="0.18" />
        </geometry>
      </collision>
    <collision name="side0_hinge_leaf_2">
      <origin xyz="0.374 0.2475 0.87" rpy="0 0 0" />
      <geometry>
        <box size="0.028 0.035 0.18" />
        </geometry>
      </collision>
    <collision name="side0_fixed_knuckle_2">
      <origin xyz="0.374 0.265 0.87" rpy="0 0 0" />
      <geometry>
        <cylinder radius="0.014" length="0.18" />
        </geometry>
      </collision>
    <collision name="side1_hinge_leaf_0">
      <origin xyz="0.374 -0.2475 0.09" rpy="0 0 0" />
      <geometry>
        <box size="0.028 0.035 0.18" />
        </geometry>
      </collision>
    <collision name="side1_fixed_knuckle_0">
      <origin xyz="0.374 -0.265 0.09" rpy="0 0 0" />
      <geometry>
        <cylinder radius="0.014" length="0.18" />
        </geometry>
      </collision>
    <collision name="side1_hinge_leaf_1">
      <origin xyz="0.374 -0.2475 0.48" rpy="0 0 0" />
      <geometry>
        <box size="0.028 0.035 0.18" />
        </geometry>
      </collision>
    <collision name="side1_fixed_knuckle_1">
      <origin xyz="0.374 -0.265 0.48" rpy="0 0 0" />
      <geometry>
        <cylinder radius="0.014" length="0.18" />
        </geometry>
      </collision>
    <collision name="side1_hinge_leaf_2">
      <origin xyz="0.374 -0.2475 0.87" rpy="0 0 0" />
      <geometry>
        <box size="0.028 0.035 0.18" />
        </geometry>
      </collision>
    <collision name="side1_fixed_knuckle_2">
      <origin xyz="0.374 -0.265 0.87" rpy="0 0 0" />
      <geometry>
        <cylinder radius="0.014" length="0.18" />
        </geometry>
      </collision>
    <collision name="cable_hinge_tab_0">
      <origin xyz="0.37 -0.173 0.34" rpy="0 0 0" />
      <geometry>
        <box size="0.036 0.04 0.12" />
        </geometry>
      </collision>
    <collision name="cable_fixed_knuckle_0">
      <origin xyz="0.388 -0.185 0.34" rpy="0 0 0" />
      <geometry>
        <cylinder radius="0.011" length="0.12" />
        </geometry>
      </collision>
    <collision name="cable_hinge_tab_1">
      <origin xyz="0.37 -0.173 0.56" rpy="0 0 0" />
      <geometry>
        <box size="0.036 0.04 0.12" />
        </geometry>
      </collision>
    <collision name="cable_fixed_knuckle_1">
      <origin xyz="0.388 -0.185 0.56" rpy="0 0 0" />
      <geometry>
        <cylinder radius="0.011" length="0.12" />
        </geometry>
      </collision>
    </link>
  <link name="side_panel_0">
    <visual name="panel_sheet">
      <origin xyz="-0.374 -0.03 0.6" rpy="0 0 0" />
      <geometry>
        <box size="0.72 0.01 1.135" />
        </geometry>
      <material name="zinc_plated_steel">
        <color rgba="0.62 0.65 0.66 1" />
        </material>
      </visual>
    <visual name="hinge_knuckle_0">
      <origin xyz="0 0 0.285" rpy="0 0 0" />
      <geometry>
        <cylinder radius="0.014" length="0.17" />
        </geometry>
      <material name="dark_powder_coat">
        <color rgba="0.08 0.09 0.1 1" />
        </material>
      </visual>
    <visual name="knuckle_leaf_0">
      <origin xyz="-0.024 -0.016 0.285" rpy="0 0 0" />
      <geometry>
        <box size="0.04 0.032 0.17" />
        </geometry>
      <material name="dark_powder_coat">
        <color rgba="0.08 0.09 0.1 1" />
        </material>
      </visual>
    <visual name="hinge_knuckle_1">
      <origin xyz="0 0 0.675" rpy="0 0 0" />
      <geometry>
        <cylinder radius="0.014" length="0.17" />
        </geometry>
      <material name="dark_powder_coat">
        <color rgba="0.08 0.09 0.1 1" />
        </material>
      </visual>
    <visual name="knuckle_leaf_1">
      <origin xyz="-0.024 -0.016 0.675" rpy="0 0 0" />
      <geometry>
        <box size="0.04 0.032 0.17" />
        </geometry>
      <material name="dark_powder_coat">
        <color rgba="0.08 0.09 0.1 1" />
        </material>
      </visual>
    <visual name="hinge_knuckle_2">
      <origin xyz="0 0 1.065" rpy="0 0 0" />
      <geometry>
        <cylinder radius="0.014" length="0.16" />
        </geometry>
      <material name="dark_powder_coat">
        <color rgba="0.08 0.09 0.1 1" />
        </material>
      </visual>
    <visual name="knuckle_leaf_2">
      <origin xyz="-0.024 -0.016 1.065" rpy="0 0 0" />
      <geometry>
        <box size="0.04 0.032 0.16" />
        </geometry>
      <material name="dark_powder_coat">
        <color rgba="0.08 0.09 0.1 1" />
        </material>
      </visual>
    <visual name="front_latch">
      <origin xyz="-0.665 -0.04 0.62" rpy="0 0 0" />
      <geometry>
        <box size="0.03 0.016 0.12" />
        </geometry>
      <material name="black_plastic">
        <color rgba="0.015 0.016 0.018 1" />
        </material>
      </visual>
    <collision name="panel_sheet">
      <origin xyz="-0.374 -0.03 0.6" rpy="0 0 0" />
      <geometry>
        <box size="0.72 0.01 1.135" />
        </geometry>
      </collision>
    <collision name="hinge_knuckle_0">
      <origin xyz="0 0 0.285" rpy="0 0 0" />
      <geometry>
        <cylinder radius="0.014" length="0.17" />
        </geometry>
      </collision>
    <collision name="knuckle_leaf_0">
      <origin xyz="-0.024 -0.016 0.285" rpy="0 0 0" />
      <geometry>
        <box size="0.04 0.032 0.17" />
        </geometry>
      </collision>
    <collision name="hinge_knuckle_1">
      <origin xyz="0 0 0.675" rpy="0 0 0" />
      <geometry>
        <cylinder radius="0.014" length="0.17" />
        </geometry>
      </collision>
    <collision name="knuckle_leaf_1">
      <origin xyz="-0.024 -0.016 0.675" rpy="0 0 0" />
      <geometry>
        <box size="0.04 0.032 0.17" />
        </geometry>
      </collision>
    <collision name="hinge_knuckle_2">
      <origin xyz="0 0 1.065" rpy="0 0 0" />
      <geometry>
        <cylinder radius="0.014" length="0.16" />
        </geometry>
      </collision>
    <collision name="knuckle_leaf_2">
      <origin xyz="-0.024 -0.016 1.065" rpy="0 0 0" />
      <geometry>
        <box size="0.04 0.032 0.16" />
        </geometry>
      </collision>
    <collision name="front_latch">
      <origin xyz="-0.665 -0.04 0.62" rpy="0 0 0" />
      <geometry>
        <box size="0.03 0.016 0.12" />
        </geometry>
      </collision>
    </link>
  <link name="side_panel_1">
    <visual name="panel_sheet">
      <origin xyz="-0.374 0.03 0.6" rpy="0 0 0" />
      <geometry>
        <box size="0.72 0.01 1.135" />
        </geometry>
      <material name="zinc_plated_steel">
        <color rgba="0.62 0.65 0.66 1" />
        </material>
      </visual>
    <visual name="hinge_knuckle_0">
      <origin xyz="0 0 0.285" rpy="0 0 0" />
      <geometry>
        <cylinder radius="0.014" length="0.17" />
        </geometry>
      <material name="dark_powder_coat">
        <color rgba="0.08 0.09 0.1 1" />
        </material>
      </visual>
    <visual name="knuckle_leaf_0">
      <origin xyz="-0.024 0.016 0.285" rpy="0 0 0" />
      <geometry>
        <box size="0.04 0.032 0.17" />
        </geometry>
      <material name="dark_powder_coat">
        <color rgba="0.08 0.09 0.1 1" />
        </material>
      </visual>
    <visual name="hinge_knuckle_1">
      <origin xyz="0 0 0.675" rpy="0 0 0" />
      <geometry>
        <cylinder radius="0.014" length="0.17" />
        </geometry>
      <material name="dark_powder_coat">
        <color rgba="0.08 0.09 0.1 1" />
        </material>
      </visual>
    <visual name="knuckle_leaf_1">
      <origin xyz="-0.024 0.016 0.675" rpy="0 0 0" />
      <geometry>
        <box size="0.04 0.032 0.17" />
        </geometry>
      <material name="dark_powder_coat">
        <color rgba="0.08 0.09 0.1 1" />
        </material>
      </visual>
    <visual name="hinge_knuckle_2">
      <origin xyz="0 0 1.065" rpy="0 0 0" />
      <geometry>
        <cylinder radius="0.014" length="0.16" />
        </geometry>
      <material name="dark_powder_coat">
        <color rgba="0.08 0.09 0.1 1" />
        </material>
      </visual>
    <visual name="knuckle_leaf_2">
      <origin xyz="-0.024 0.016 1.065" rpy="0 0 0" />
      <geometry>
        <box size="0.04 0.032 0.16" />
        </geometry>
      <material name="dark_powder_coat">
        <color rgba="0.08 0.09 0.1 1" />
        </material>
      </visual>
    <visual name="front_latch">
      <origin xyz="-0.665 0.04 0.62" rpy="0 0 0" />
      <geometry>
        <box size="0.03 0.016 0.12" />
        </geometry>
      <material name="black_plastic">
        <color rgba="0.015 0.016 0.018 1" />
        </material>
      </visual>
    <collision name="panel_sheet">
      <origin xyz="-0.374 0.03 0.6" rpy="0 0 0" />
      <geometry>
        <box size="0.72 0.01 1.135" />
        </geometry>
      </collision>
    <collision name="hinge_knuckle_0">
      <origin xyz="0 0 0.285" rpy="0 0 0" />
      <geometry>
        <cylinder radius="0.014" length="0.17" />
        </geometry>
      </collision>
    <collision name="knuckle_leaf_0">
      <origin xyz="-0.024 0.016 0.285" rpy="0 0 0" />
      <geometry>
        <box size="0.04 0.032 0.17" />
        </geometry>
      </collision>
    <collision name="hinge_knuckle_1">
      <origin xyz="0 0 0.675" rpy="0 0 0" />
      <geometry>
        <cylinder radius="0.014" length="0.17" />
        </geometry>
      </collision>
    <collision name="knuckle_leaf_1">
      <origin xyz="-0.024 0.016 0.675" rpy="0 0 0" />
      <geometry>
        <box size="0.04 0.032 0.17" />
        </geometry>
      </collision>
    <collision name="hinge_knuckle_2">
      <origin xyz="0 0 1.065" rpy="0 0 0" />
      <geometry>
        <cylinder radius="0.014" length="0.16" />
        </geometry>
      </collision>
    <collision name="knuckle_leaf_2">
      <origin xyz="-0.024 0.016 1.065" rpy="0 0 0" />
      <geometry>
        <box size="0.04 0.032 0.16" />
        </geometry>
      </collision>
    <collision name="front_latch">
      <origin xyz="-0.665 0.04 0.62" rpy="0 0 0" />
      <geometry>
        <box size="0.03 0.016 0.12" />
        </geometry>
      </collision>
    </link>
  <link name="front_door">
    <visual name="door_panel">
      <origin xyz="0 0.254 0.6" rpy="0 0 0" />
      <geometry>
        <box size="0.014 0.46 1.08" />
        </geometry>
      <material name="dark_powder_coat">
        <color rgba="0.08 0.09 0.1 1" />
        </material>
      </visual>
    <visual name="vent_insert">
      <origin xyz="-0.01 0.254 0.54" rpy="0 0 0" />
      <geometry>
        <box size="0.006 0.37 0.78" />
        </geometry>
      <material name="dark_perforated_vent">
        <color rgba="0.02 0.025 0.03 0.82" />
        </material>
      </visual>
    <visual name="door_pull">
      <origin xyz="-0.017 0.439 0.65" rpy="0 0 0" />
      <geometry>
        <box size="0.018 0.026 0.2" />
        </geometry>
      <material name="black_plastic">
        <color rgba="0.015 0.016 0.018 1" />
        </material>
      </visual>
    <visual name="hinge_knuckle_0">
      <origin xyz="0 0 0.32" rpy="0 0 0" />
      <geometry>
        <cylinder radius="0.012" length="0.16" />
        </geometry>
      <material name="dark_powder_coat">
        <color rgba="0.08 0.09 0.1 1" />
        </material>
      </visual>
    <visual name="knuckle_leaf_0">
      <origin xyz="0 0.018 0.32" rpy="0 0 0" />
      <geometry>
        <box size="0.016 0.036 0.16" />
        </geometry>
      <material name="dark_powder_coat">
        <color rgba="0.08 0.09 0.1 1" />
        </material>
      </visual>
    <visual name="hinge_knuckle_1">
      <origin xyz="0 0 0.72" rpy="0 0 0" />
      <geometry>
        <cylinder radius="0.012" length="0.16" />
        </geometry>
      <material name="dark_powder_coat">
        <color rgba="0.08 0.09 0.1 1" />
        </material>
      </visual>
    <visual name="knuckle_leaf_1">
      <origin xyz="0 0.018 0.72" rpy="0 0 0" />
      <geometry>
        <box size="0.016 0.036 0.16" />
        </geometry>
      <material name="dark_powder_coat">
        <color rgba="0.08 0.09 0.1 1" />
        </material>
      </visual>
    <visual name="hinge_knuckle_2">
      <origin xyz="0 0 1.1" rpy="0 0 0" />
      <geometry>
        <cylinder radius="0.012" length="0.13" />
        </geometry>
      <material name="dark_powder_coat">
        <color rgba="0.08 0.09 0.1 1" />
        </material>
      </visual>
    <visual name="knuckle_leaf_2">
      <origin xyz="0 0.018 1.1" rpy="0 0 0" />
      <geometry>
        <box size="0.016 0.036 0.13" />
        </geometry>
      <material name="dark_powder_coat">
        <color rgba="0.08 0.09 0.1 1" />
        </material>
      </visual>
    <collision name="door_panel">
      <origin xyz="0 0.254 0.6" rpy="0 0 0" />
      <geometry>
        <box size="0.014 0.46 1.08" />
        </geometry>
      </collision>
    <collision name="vent_insert">
      <origin xyz="-0.01 0.254 0.54" rpy="0 0 0" />
      <geometry>
        <box size="0.006 0.37 0.78" />
        </geometry>
      </collision>
    <collision name="door_pull">
      <origin xyz="-0.017 0.439 0.65" rpy="0 0 0" />
      <geometry>
        <box size="0.018 0.026 0.2" />
        </geometry>
      </collision>
    <collision name="hinge_knuckle_0">
      <origin xyz="0 0 0.32" rpy="0 0 0" />
      <geometry>
        <cylinder radius="0.012" length="0.16" />
        </geometry>
      </collision>
    <collision name="knuckle_leaf_0">
      <origin xyz="0 0.018 0.32" rpy="0 0 0" />
      <geometry>
        <box size="0.016 0.036 0.16" />
        </geometry>
      </collision>
    <collision name="hinge_knuckle_1">
      <origin xyz="0 0 0.72" rpy="0 0 0" />
      <geometry>
        <cylinder radius="0.012" length="0.16" />
        </geometry>
      </collision>
    <collision name="knuckle_leaf_1">
      <origin xyz="0 0.018 0.72" rpy="0 0 0" />
      <geometry>
        <box size="0.016 0.036 0.16" />
        </geometry>
      </collision>
    <collision name="hinge_knuckle_2">
      <origin xyz="0 0 1.1" rpy="0 0 0" />
      <geometry>
        <cylinder radius="0.012" length="0.13" />
        </geometry>
      </collision>
    <collision name="knuckle_leaf_2">
      <origin xyz="0 0.018 1.1" rpy="0 0 0" />
      <geometry>
        <box size="0.016 0.036 0.13" />
        </geometry>
      </collision>
    </link>
  <link name="drive_sled_0">
    <visual name="sled_body">
      <origin xyz="0.22 0 0" rpy="0 0 0" />
      <geometry>
        <box size="0.44 0.32 0.07" />
        </geometry>
      <material name="zinc_plated_steel">
        <color rgba="0.62 0.65 0.66 1" />
        </material>
      </visual>
    <visual name="front_face">
      <origin xyz="0.009 0 0" rpy="0 0 0" />
      <geometry>
        <box size="0.018 0.342 0.09" />
        </geometry>
      <material name="dark_powder_coat">
        <color rgba="0.08 0.09 0.1 1" />
        </material>
      </visual>
    <visual name="pull_handle">
      <origin xyz="-0.006 0 0.018" rpy="0 0 0" />
      <geometry>
        <box size="0.025 0.09 0.018" />
        </geometry>
      <material name="black_plastic">
        <color rgba="0.015 0.016 0.018 1" />
        </material>
      </visual>
    <visual name="release_tab">
      <origin xyz="-0.002 -0.135 0.02" rpy="0 0 0" />
      <geometry>
        <box size="0.01 0.05 0.016" />
        </geometry>
      <material name="blue_release_tabs">
        <color rgba="0.05 0.22 0.75 1" />
        </material>
      </visual>
    <visual name="side_runner_a">
      <origin xyz="0.22 -0.166 -0.048" rpy="0 0 0" />
      <geometry>
        <box size="0.44 0.016 0.014" />
        </geometry>
      <material name="dark_powder_coat">
        <color rgba="0.08 0.09 0.1 1" />
        </material>
      </visual>
    <visual name="side_runner_b">
      <origin xyz="0.22 0.166 -0.048" rpy="0 0 0" />
      <geometry>
        <box size="0.44 0.016 0.014" />
        </geometry>
      <material name="dark_powder_coat">
        <color rgba="0.08 0.09 0.1 1" />
        </material>
      </visual>
    <collision name="sled_body">
      <origin xyz="0.22 0 0" rpy="0 0 0" />
      <geometry>
        <box size="0.44 0.32 0.07" />
        </geometry>
      </collision>
    <collision name="front_face">
      <origin xyz="0.009 0 0" rpy="0 0 0" />
      <geometry>
        <box size="0.018 0.342 0.09" />
        </geometry>
      </collision>
    <collision name="pull_handle">
      <origin xyz="-0.006 0 0.018" rpy="0 0 0" />
      <geometry>
        <box size="0.025 0.09 0.018" />
        </geometry>
      </collision>
    <collision name="release_tab">
      <origin xyz="-0.002 -0.135 0.02" rpy="0 0 0" />
      <geometry>
        <box size="0.01 0.05 0.016" />
        </geometry>
      </collision>
    <collision name="side_runner_a">
      <origin xyz="0.22 -0.166 -0.048" rpy="0 0 0" />
      <geometry>
        <box size="0.44 0.016 0.014" />
        </geometry>
      </collision>
    <collision name="side_runner_b">
      <origin xyz="0.22 0.166 -0.048" rpy="0 0 0" />
      <geometry>
        <box size="0.44 0.016 0.014" />
        </geometry>
      </collision>
    </link>
  <link name="drive_sled_1">
    <visual name="sled_body">
      <origin xyz="0.22 0 0" rpy="0 0 0" />
      <geometry>
        <box size="0.44 0.32 0.07" />
        </geometry>
      <material name="zinc_plated_steel">
        <color rgba="0.62 0.65 0.66 1" />
        </material>
      </visual>
    <visual name="front_face">
      <origin xyz="0.009 0 0" rpy="0 0 0" />
      <geometry>
        <box size="0.018 0.342 0.09" />
        </geometry>
      <material name="dark_powder_coat">
        <color rgba="0.08 0.09 0.1 1" />
        </material>
      </visual>
    <visual name="pull_handle">
      <origin xyz="-0.006 0 0.018" rpy="0 0 0" />
      <geometry>
        <box size="0.025 0.09 0.018" />
        </geometry>
      <material name="black_plastic">
        <color rgba="0.015 0.016 0.018 1" />
        </material>
      </visual>
    <visual name="release_tab">
      <origin xyz="-0.002 -0.135 0.02" rpy="0 0 0" />
      <geometry>
        <box size="0.01 0.05 0.016" />
        </geometry>
      <material name="blue_release_tabs">
        <color rgba="0.05 0.22 0.75 1" />
        </material>
      </visual>
    <visual name="side_runner_a">
      <origin xyz="0.22 -0.166 -0.048" rpy="0 0 0" />
      <geometry>
        <box size="0.44 0.016 0.014" />
        </geometry>
      <material name="dark_powder_coat">
        <color rgba="0.08 0.09 0.1 1" />
        </material>
      </visual>
    <visual name="side_runner_b">
      <origin xyz="0.22 0.166 -0.048" rpy="0 0 0" />
      <geometry>
        <box size="0.44 0.016 0.014" />
        </geometry>
      <material name="dark_powder_coat">
        <color rgba="0.08 0.09 0.1 1" />
        </material>
      </visual>
    <collision name="sled_body">
      <origin xyz="0.22 0 0" rpy="0 0 0" />
      <geometry>
        <box size="0.44 0.32 0.07" />
        </geometry>
      </collision>
    <collision name="front_face">
      <origin xyz="0.009 0 0" rpy="0 0 0" />
      <geometry>
        <box size="0.018 0.342 0.09" />
        </geometry>
      </collision>
    <collision name="pull_handle">
      <origin xyz="-0.006 0 0.018" rpy="0 0 0" />
      <geometry>
        <box size="0.025 0.09 0.018" />
        </geometry>
      </collision>
    <collision name="release_tab">
      <origin xyz="-0.002 -0.135 0.02" rpy="0 0 0" />
      <geometry>
        <box size="0.01 0.05 0.016" />
        </geometry>
      </collision>
    <collision name="side_runner_a">
      <origin xyz="0.22 -0.166 -0.048" rpy="0 0 0" />
      <geometry>
        <box size="0.44 0.016 0.014" />
        </geometry>
      </collision>
    <collision name="side_runner_b">
      <origin xyz="0.22 0.166 -0.048" rpy="0 0 0" />
      <geometry>
        <box size="0.44 0.016 0.014" />
        </geometry>
      </collision>
    </link>
  <link name="drive_sled_2">
    <visual name="sled_body">
      <origin xyz="0.22 0 0" rpy="0 0 0" />
      <geometry>
        <box size="0.44 0.32 0.07" />
        </geometry>
      <material name="zinc_plated_steel">
        <color rgba="0.62 0.65 0.66 1" />
        </material>
      </visual>
    <visual name="front_face">
      <origin xyz="0.009 0 0" rpy="0 0 0" />
      <geometry>
        <box size="0.018 0.342 0.09" />
        </geometry>
      <material name="dark_powder_coat">
        <color rgba="0.08 0.09 0.1 1" />
        </material>
      </visual>
    <visual name="pull_handle">
      <origin xyz="-0.006 0 0.018" rpy="0 0 0" />
      <geometry>
        <box size="0.025 0.09 0.018" />
        </geometry>
      <material name="black_plastic">
        <color rgba="0.015 0.016 0.018 1" />
        </material>
      </visual>
    <visual name="release_tab">
      <origin xyz="-0.002 -0.135 0.02" rpy="0 0 0" />
      <geometry>
        <box size="0.01 0.05 0.016" />
        </geometry>
      <material name="blue_release_tabs">
        <color rgba="0.05 0.22 0.75 1" />
        </material>
      </visual>
    <visual name="side_runner_a">
      <origin xyz="0.22 -0.166 -0.048" rpy="0 0 0" />
      <geometry>
        <box size="0.44 0.016 0.014" />
        </geometry>
      <material name="dark_powder_coat">
        <color rgba="0.08 0.09 0.1 1" />
        </material>
      </visual>
    <visual name="side_runner_b">
      <origin xyz="0.22 0.166 -0.048" rpy="0 0 0" />
      <geometry>
        <box size="0.44 0.016 0.014" />
        </geometry>
      <material name="dark_powder_coat">
        <color rgba="0.08 0.09 0.1 1" />
        </material>
      </visual>
    <collision name="sled_body">
      <origin xyz="0.22 0 0" rpy="0 0 0" />
      <geometry>
        <box size="0.44 0.32 0.07" />
        </geometry>
      </collision>
    <collision name="front_face">
      <origin xyz="0.009 0 0" rpy="0 0 0" />
      <geometry>
        <box size="0.018 0.342 0.09" />
        </geometry>
      </collision>
    <collision name="pull_handle">
      <origin xyz="-0.006 0 0.018" rpy="0 0 0" />
      <geometry>
        <box size="0.025 0.09 0.018" />
        </geometry>
      </collision>
    <collision name="release_tab">
      <origin xyz="-0.002 -0.135 0.02" rpy="0 0 0" />
      <geometry>
        <box size="0.01 0.05 0.016" />
        </geometry>
      </collision>
    <collision name="side_runner_a">
      <origin xyz="0.22 -0.166 -0.048" rpy="0 0 0" />
      <geometry>
        <box size="0.44 0.016 0.014" />
        </geometry>
      </collision>
    <collision name="side_runner_b">
      <origin xyz="0.22 0.166 -0.048" rpy="0 0 0" />
      <geometry>
        <box size="0.44 0.016 0.014" />
        </geometry>
      </collision>
    </link>
  <link name="drive_sled_3">
    <visual name="sled_body">
      <origin xyz="0.22 0 0" rpy="0 0 0" />
      <geometry>
        <box size="0.44 0.32 0.07" />
        </geometry>
      <material name="zinc_plated_steel">
        <color rgba="0.62 0.65 0.66 1" />
        </material>
      </visual>
    <visual name="front_face">
      <origin xyz="0.009 0 0" rpy="0 0 0" />
      <geometry>
        <box size="0.018 0.342 0.09" />
        </geometry>
      <material name="dark_powder_coat">
        <color rgba="0.08 0.09 0.1 1" />
        </material>
      </visual>
    <visual name="pull_handle">
      <origin xyz="-0.006 0 0.018" rpy="0 0 0" />
      <geometry>
        <box size="0.025 0.09 0.018" />
        </geometry>
      <material name="black_plastic">
        <color rgba="0.015 0.016 0.018 1" />
        </material>
      </visual>
    <visual name="release_tab">
      <origin xyz="-0.002 -0.135 0.02" rpy="0 0 0" />
      <geometry>
        <box size="0.01 0.05 0.016" />
        </geometry>
      <material name="blue_release_tabs">
        <color rgba="0.05 0.22 0.75 1" />
        </material>
      </visual>
    <visual name="side_runner_a">
      <origin xyz="0.22 -0.166 -0.048" rpy="0 0 0" />
      <geometry>
        <box size="0.44 0.016 0.014" />
        </geometry>
      <material name="dark_powder_coat">
        <color rgba="0.08 0.09 0.1 1" />
        </material>
      </visual>
    <visual name="side_runner_b">
      <origin xyz="0.22 0.166 -0.048" rpy="0 0 0" />
      <geometry>
        <box size="0.44 0.016 0.014" />
        </geometry>
      <material name="dark_powder_coat">
        <color rgba="0.08 0.09 0.1 1" />
        </material>
      </visual>
    <collision name="sled_body">
      <origin xyz="0.22 0 0" rpy="0 0 0" />
      <geometry>
        <box size="0.44 0.32 0.07" />
        </geometry>
      </collision>
    <collision name="front_face">
      <origin xyz="0.009 0 0" rpy="0 0 0" />
      <geometry>
        <box size="0.018 0.342 0.09" />
        </geometry>
      </collision>
    <collision name="pull_handle">
      <origin xyz="-0.006 0 0.018" rpy="0 0 0" />
      <geometry>
        <box size="0.025 0.09 0.018" />
        </geometry>
      </collision>
    <collision name="release_tab">
      <origin xyz="-0.002 -0.135 0.02" rpy="0 0 0" />
      <geometry>
        <box size="0.01 0.05 0.016" />
        </geometry>
      </collision>
    <collision name="side_runner_a">
      <origin xyz="0.22 -0.166 -0.048" rpy="0 0 0" />
      <geometry>
        <box size="0.44 0.016 0.014" />
        </geometry>
      </collision>
    <collision name="side_runner_b">
      <origin xyz="0.22 0.166 -0.048" rpy="0 0 0" />
      <geometry>
        <box size="0.44 0.016 0.014" />
        </geometry>
      </collision>
    </link>
  <link name="cable_bracket">
    <visual name="hinge_knuckle_0">
      <origin xyz="0 0 0.45" rpy="0 0 0" />
      <geometry>
        <cylinder radius="0.011" length="0.1" />
        </geometry>
      <material name="dark_powder_coat">
        <color rgba="0.08 0.09 0.1 1" />
        </material>
      </visual>
    <visual name="hinge_leaf_0">
      <origin xyz="0 0.025 0.45" rpy="0 0 0" />
      <geometry>
        <box size="0.02 0.04 0.1" />
        </geometry>
      <material name="dark_powder_coat">
        <color rgba="0.08 0.09 0.1 1" />
        </material>
      </visual>
    <visual name="lower_bar">
      <origin xyz="0 0.205 0.31" rpy="0 0 0" />
      <geometry>
        <box size="0.014 0.29 0.03" />
        </geometry>
      <material name="black_plastic">
        <color rgba="0.015 0.016 0.018 1" />
        </material>
      </visual>
    <visual name="upper_bar">
      <origin xyz="0 0.205 0.68" rpy="0 0 0" />
      <geometry>
        <box size="0.014 0.29 0.03" />
        </geometry>
      <material name="black_plastic">
        <color rgba="0.015 0.016 0.018 1" />
        </material>
      </visual>
    <visual name="inner_spine">
      <origin xyz="0 0.055 0.495" rpy="0 0 0" />
      <geometry>
        <box size="0.014 0.024 0.39" />
        </geometry>
      <material name="black_plastic">
        <color rgba="0.015 0.016 0.018 1" />
        </material>
      </visual>
    <visual name="outer_spine">
      <origin xyz="0 0.325 0.495" rpy="0 0 0" />
      <geometry>
        <box size="0.014 0.03 0.39" />
        </geometry>
      <material name="black_plastic">
        <color rgba="0.015 0.016 0.018 1" />
        </material>
      </visual>
    <visual name="cable_finger_0">
      <origin xyz="0 0.205 0.39" rpy="0 0 0" />
      <geometry>
        <box size="0.012 0.24 0.018" />
        </geometry>
      <material name="black_plastic">
        <color rgba="0.015 0.016 0.018 1" />
        </material>
      </visual>
    <visual name="cable_finger_1">
      <origin xyz="0 0.205 0.48" rpy="0 0 0" />
      <geometry>
        <box size="0.012 0.24 0.018" />
        </geometry>
      <material name="black_plastic">
        <color rgba="0.015 0.016 0.018 1" />
        </material>
      </visual>
    <visual name="cable_finger_2">
      <origin xyz="0 0.205 0.57" rpy="0 0 0" />
      <geometry>
        <box size="0.012 0.24 0.018" />
        </geometry>
      <material name="black_plastic">
        <color rgba="0.015 0.016 0.018 1" />
        </material>
      </visual>
    <collision name="hinge_knuckle_0">
      <origin xyz="0 0 0.45" rpy="0 0 0" />
      <geometry>
        <cylinder radius="0.011" length="0.1" />
        </geometry>
      </collision>
    <collision name="hinge_leaf_0">
      <origin xyz="0 0.025 0.45" rpy="0 0 0" />
      <geometry>
        <box size="0.02 0.04 0.1" />
        </geometry>
      </collision>
    <collision name="lower_bar">
      <origin xyz="0 0.205 0.31" rpy="0 0 0" />
      <geometry>
        <box size="0.014 0.29 0.03" />
        </geometry>
      </collision>
    <collision name="upper_bar">
      <origin xyz="0 0.205 0.68" rpy="0 0 0" />
      <geometry>
        <box size="0.014 0.29 0.03" />
        </geometry>
      </collision>
    <collision name="inner_spine">
      <origin xyz="0 0.055 0.495" rpy="0 0 0" />
      <geometry>
        <box size="0.014 0.024 0.39" />
        </geometry>
      </collision>
    <collision name="outer_spine">
      <origin xyz="0 0.325 0.495" rpy="0 0 0" />
      <geometry>
        <box size="0.014 0.03 0.39" />
        </geometry>
      </collision>
    <collision name="cable_finger_0">
      <origin xyz="0 0.205 0.39" rpy="0 0 0" />
      <geometry>
        <box size="0.012 0.24 0.018" />
        </geometry>
      </collision>
    <collision name="cable_finger_1">
      <origin xyz="0 0.205 0.48" rpy="0 0 0" />
      <geometry>
        <box size="0.012 0.24 0.018" />
        </geometry>
      </collision>
    <collision name="cable_finger_2">
      <origin xyz="0 0.205 0.57" rpy="0 0 0" />
      <geometry>
        <box size="0.012 0.24 0.018" />
        </geometry>
      </collision>
    </link>
  <joint name="chassis_to_side_panel_0" type="revolute">
    <origin xyz="0.374 0.265 0" rpy="0 0 0" />
    <parent link="chassis" />
    <child link="side_panel_0" />
    <axis xyz="0 0 -1" />
    <limit effort="20" velocity="1.6" lower="0" upper="1.85" />
    </joint>
  <joint name="chassis_to_side_panel_1" type="revolute">
    <origin xyz="0.374 -0.265 0" rpy="0 0 0" />
    <parent link="chassis" />
    <child link="side_panel_1" />
    <axis xyz="0 0 1" />
    <limit effort="20" velocity="1.6" lower="0" upper="1.85" />
    </joint>
  <joint name="chassis_to_front_door" type="revolute">
    <origin xyz="-0.366 -0.254 0" rpy="0 0 0" />
    <parent link="chassis" />
    <child link="front_door" />
    <axis xyz="0 0 1" />
    <limit effort="10" velocity="1.8" lower="0" upper="2.05" />
    </joint>
  <joint name="chassis_to_drive_sled_0" type="prismatic">
    <origin xyz="-0.32 0 0.27" rpy="0 0 0" />
    <parent link="chassis" />
    <child link="drive_sled_0" />
    <axis xyz="-1 0 0" />
    <limit effort="45" velocity="0.35" lower="0" upper="0.28" />
    </joint>
  <joint name="chassis_to_drive_sled_1" type="prismatic">
    <origin xyz="-0.32 0 0.38" rpy="0 0 0" />
    <parent link="chassis" />
    <child link="drive_sled_1" />
    <axis xyz="-1 0 0" />
    <limit effort="45" velocity="0.35" lower="0" upper="0.28" />
    </joint>
  <joint name="chassis_to_drive_sled_2" type="prismatic">
    <origin xyz="-0.32 0 0.49" rpy="0 0 0" />
    <parent link="chassis" />
    <child link="drive_sled_2" />
    <axis xyz="-1 0 0" />
    <limit effort="45" velocity="0.35" lower="0" upper="0.28" />
    </joint>
  <joint name="chassis_to_drive_sled_3" type="prismatic">
    <origin xyz="-0.32 0 0.6" rpy="0 0 0" />
    <parent link="chassis" />
    <child link="drive_sled_3" />
    <axis xyz="-1 0 0" />
    <limit effort="45" velocity="0.35" lower="0" upper="0.28" />
    </joint>
  <joint name="chassis_to_cable_bracket" type="revolute">
    <origin xyz="0.388 -0.185 0" rpy="0 0 0" />
    <parent link="chassis" />
    <child link="cable_bracket" />
    <axis xyz="0 0 -1" />
    <limit effort="6" velocity="1.2" lower="0" upper="1.45" />
    </joint>
  </robot>
