<robot name="pedestal_yaw_module">
  <material name="matte_black">
    <color rgba="0.025 0.028 0.03 1" />
    </material>
  <material name="motor_dark">
    <color rgba="0.12 0.13 0.15 1" />
    </material>
  <material name="cast_aluminum">
    <color rgba="0.58 0.6 0.62 1" />
    </material>
  <material name="brushed_steel">
    <color rgba="0.72 0.74 0.76 1" />
    </material>
  <material name="top_plate_blue">
    <color rgba="0.1 0.22 0.38 1" />
    </material>
  <link name="pedestal">
    <visual name="floor_plate">
      <origin xyz="0 0 0.016" rpy="0 0 0" />
      <geometry>
        <box size="0.32 0.32 0.032" />
        </geometry>
      <material name="matte_black" />
      </visual>
    <visual name="pedestal_column">
      <origin xyz="0 0 0.089" rpy="0 0 0" />
      <geometry>
        <cylinder radius="0.074" length="0.118" />
        </geometry>
      <material name="cast_aluminum" />
      </visual>
    <visual name="motor_base">
      <origin xyz="0 0 0.151" rpy="0 0 0" />
      <geometry>
        <box size="0.205 0.205 0.094" />
        </geometry>
      <material name="motor_dark" />
      </visual>
    <visual name="front_motor_lip">
      <origin xyz="0 -0.104 0.189" rpy="0 0 0" />
      <geometry>
        <box size="0.19 0.034 0.012" />
        </geometry>
      <material name="matte_black" />
      </visual>
    <visual name="bearing_housing">
      <origin xyz="0 0 0.178" rpy="0 0 0" />
      <geometry>
        <mesh filename="assets/meshes/bearing_housing.obj" />
        </geometry>
      <material name="brushed_steel" />
      </visual>
    <visual name="motor_bolt_0">
      <origin xyz="-0.079 -0.079 0.202" rpy="0 0 0" />
      <geometry>
        <cylinder radius="0.009" length="0.008" />
        </geometry>
      <material name="brushed_steel" />
      </visual>
    <visual name="motor_bolt_1">
      <origin xyz="-0.079 0.079 0.202" rpy="0 0 0" />
      <geometry>
        <cylinder radius="0.009" length="0.008" />
        </geometry>
      <material name="brushed_steel" />
      </visual>
    <visual name="motor_bolt_2">
      <origin xyz="0.079 -0.079 0.202" rpy="0 0 0" />
      <geometry>
        <cylinder radius="0.009" length="0.008" />
        </geometry>
      <material name="brushed_steel" />
      </visual>
    <visual name="motor_bolt_3">
      <origin xyz="0.079 0.079 0.202" rpy="0 0 0" />
      <geometry>
        <cylinder radius="0.009" length="0.008" />
        </geometry>
      <material name="brushed_steel" />
      </visual>
    <collision name="floor_plate">
      <origin xyz="0 0 0.016" rpy="0 0 0" />
      <geometry>
        <box size="0.32 0.32 0.032" />
        </geometry>
      </collision>
    <collision name="pedestal_column">
      <origin xyz="0 0 0.089" rpy="0 0 0" />
      <geometry>
        <cylinder radius="0.074" length="0.118" />
        </geometry>
      </collision>
    <collision name="motor_base">
      <origin xyz="0 0 0.151" rpy="0 0 0" />
      <geometry>
        <box size="0.205 0.205 0.094" />
        </geometry>
      </collision>
    <collision name="front_motor_lip">
      <origin xyz="0 -0.104 0.189" rpy="0 0 0" />
      <geometry>
        <box size="0.19 0.034 0.012" />
        </geometry>
      </collision>
    <collision name="bearing_housing">
      <origin xyz="0 0 0.178" rpy="0 0 0" />
      <geometry>
        <mesh filename="assets/meshes/bearing_housing.obj" />
        </geometry>
      </collision>
    <collision name="motor_bolt_0">
      <origin xyz="-0.079 -0.079 0.202" rpy="0 0 0" />
      <geometry>
        <cylinder radius="0.009" length="0.008" />
        </geometry>
      </collision>
    <collision name="motor_bolt_1">
      <origin xyz="-0.079 0.079 0.202" rpy="0 0 0" />
      <geometry>
        <cylinder radius="0.009" length="0.008" />
        </geometry>
      </collision>
    <collision name="motor_bolt_2">
      <origin xyz="0.079 -0.079 0.202" rpy="0 0 0" />
      <geometry>
        <cylinder radius="0.009" length="0.008" />
        </geometry>
      </collision>
    <collision name="motor_bolt_3">
      <origin xyz="0.079 0.079 0.202" rpy="0 0 0" />
      <geometry>
        <cylinder radius="0.009" length="0.008" />
        </geometry>
      </collision>
    </link>
  <link name="top_plate">
    <visual name="shaft">
      <origin xyz="0 0 -0.012" rpy="0 0 0" />
      <geometry>
        <cylinder radius="0.033" length="0.042" />
        </geometry>
      <material name="brushed_steel" />
      </visual>
    <visual name="thrust_washer">
      <origin xyz="0 0 0.005" rpy="0 0 0" />
      <geometry>
        <cylinder radius="0.06" length="0.01" />
        </geometry>
      <material name="brushed_steel" />
      </visual>
    <visual name="rotor_hub">
      <origin xyz="0 0 0.027" rpy="0 0 0" />
      <geometry>
        <cylinder radius="0.05" length="0.038" />
        </geometry>
      <material name="brushed_steel" />
      </visual>
    <visual name="panel">
      <geometry>
        <mesh filename="assets/meshes/top_plate_panel.obj" />
        </geometry>
      <material name="top_plate_blue" />
      </visual>
    <collision name="shaft">
      <origin xyz="0 0 -0.012" rpy="0 0 0" />
      <geometry>
        <cylinder radius="0.033" length="0.042" />
        </geometry>
      </collision>
    <collision name="thrust_washer">
      <origin xyz="0 0 0.005" rpy="0 0 0" />
      <geometry>
        <cylinder radius="0.06" length="0.01" />
        </geometry>
      </collision>
    <collision name="rotor_hub">
      <origin xyz="0 0 0.027" rpy="0 0 0" />
      <geometry>
        <cylinder radius="0.05" length="0.038" />
        </geometry>
      </collision>
    <collision name="panel">
      <geometry>
        <mesh filename="assets/meshes/top_plate_panel.obj" />
        </geometry>
      </collision>
    </link>
  <joint name="yaw_axis" type="revolute">
    <origin xyz="0 0 0.263" rpy="0 0 0" />
    <parent link="pedestal" />
    <child link="top_plate" />
    <axis xyz="0 0 1" />
    <limit effort="45" velocity="2" lower="-3.14159" upper="3.14159" />
    </joint>
  </robot>
