<robot name="push_pull_plunger_chain">
  <material name="brushed_steel">
    <color rgba="0.58 0.6 0.62 1" />
    </material>
  <material name="dark_oiled_steel">
    <color rgba="0.08 0.09 0.1 1" />
    </material>
  <material name="cast_aluminum">
    <color rgba="0.46 0.49 0.51 1" />
    </material>
  <material name="painted_lever_blue">
    <color rgba="0.05 0.19 0.43 1" />
    </material>
  <material name="black_rubber">
    <color rgba="0.015 0.014 0.013 1" />
    </material>
  <link name="housing">
    <visual name="base_plate">
      <origin xyz="-0.045 0 0.015" rpy="0 0 0" />
      <geometry>
        <box size="0.56 0.2 0.03" />
        </geometry>
      <material name="cast_aluminum">
        <color rgba="0.46 0.49 0.51 1" />
        </material>
      </visual>
    <visual name="guide_floor">
      <origin xyz="-0.07 0 0.0425" rpy="0 0 0" />
      <geometry>
        <box size="0.31 0.07 0.025" />
        </geometry>
      <material name="cast_aluminum">
        <color rgba="0.46 0.49 0.51 1" />
        </material>
      </visual>
    <visual name="guide_side_0">
      <origin xyz="-0.07 0.045 0.085" rpy="0 0 0" />
      <geometry>
        <box size="0.31 0.02 0.095" />
        </geometry>
      <material name="cast_aluminum">
        <color rgba="0.46 0.49 0.51 1" />
        </material>
      </visual>
    <visual name="guide_side_1">
      <origin xyz="-0.07 -0.045 0.085" rpy="0 0 0" />
      <geometry>
        <box size="0.31 0.02 0.095" />
        </geometry>
      <material name="cast_aluminum">
        <color rgba="0.46 0.49 0.51 1" />
        </material>
      </visual>
    <visual name="top_bridge_0">
      <origin xyz="-0.2 0 0.142" rpy="0 0 0" />
      <geometry>
        <box size="0.032 0.12 0.025" />
        </geometry>
      <material name="cast_aluminum">
        <color rgba="0.46 0.49 0.51 1" />
        </material>
      </visual>
    <visual name="top_bridge_1">
      <origin xyz="-0.075 0 0.142" rpy="0 0 0" />
      <geometry>
        <box size="0.032 0.12 0.025" />
        </geometry>
      <material name="cast_aluminum">
        <color rgba="0.46 0.49 0.51 1" />
        </material>
      </visual>
    <visual name="top_bridge_2">
      <origin xyz="0.05 0 0.142" rpy="0 0 0" />
      <geometry>
        <box size="0.032 0.12 0.025" />
        </geometry>
      <material name="cast_aluminum">
        <color rgba="0.46 0.49 0.51 1" />
        </material>
      </visual>
    <visual name="pin_cheek_0">
      <origin xyz="0.135 0.075 0.125" rpy="0 0 0" />
      <geometry>
        <box size="0.07 0.02 0.19" />
        </geometry>
      <material name="cast_aluminum">
        <color rgba="0.46 0.49 0.51 1" />
        </material>
      </visual>
    <visual name="pin_cheek_1">
      <origin xyz="0.135 -0.075 0.125" rpy="0 0 0" />
      <geometry>
        <box size="0.07 0.02 0.19" />
        </geometry>
      <material name="cast_aluminum">
        <color rgba="0.46 0.49 0.51 1" />
        </material>
      </visual>
    <visual name="pivot_pin">
      <origin xyz="0.135 0 0.175" rpy="1.5708 0 0" />
      <geometry>
        <cylinder radius="0.01" length="0.214" />
        </geometry>
      <material name="dark_oiled_steel">
        <color rgba="0.08 0.09 0.1 1" />
        </material>
      </visual>
    <visual name="pin_head_0">
      <origin xyz="0.135 0.102 0.175" rpy="1.5708 0 0" />
      <geometry>
        <cylinder radius="0.017" length="0.01" />
        </geometry>
      <material name="dark_oiled_steel">
        <color rgba="0.08 0.09 0.1 1" />
        </material>
      </visual>
    <visual name="pin_head_1">
      <origin xyz="0.135 -0.102 0.175" rpy="1.5708 0 0" />
      <geometry>
        <cylinder radius="0.017" length="0.01" />
        </geometry>
      <material name="dark_oiled_steel">
        <color rgba="0.08 0.09 0.1 1" />
        </material>
      </visual>
    <collision name="base_plate">
      <origin xyz="-0.045 0 0.015" rpy="0 0 0" />
      <geometry>
        <box size="0.56 0.2 0.03" />
        </geometry>
      </collision>
    <collision name="guide_floor">
      <origin xyz="-0.07 0 0.0425" rpy="0 0 0" />
      <geometry>
        <box size="0.31 0.07 0.025" />
        </geometry>
      </collision>
    <collision name="guide_side_0">
      <origin xyz="-0.07 0.045 0.085" rpy="0 0 0" />
      <geometry>
        <box size="0.31 0.02 0.095" />
        </geometry>
      </collision>
    <collision name="guide_side_1">
      <origin xyz="-0.07 -0.045 0.085" rpy="0 0 0" />
      <geometry>
        <box size="0.31 0.02 0.095" />
        </geometry>
      </collision>
    <collision name="top_bridge_0">
      <origin xyz="-0.2 0 0.142" rpy="0 0 0" />
      <geometry>
        <box size="0.032 0.12 0.025" />
        </geometry>
      </collision>
    <collision name="top_bridge_1">
      <origin xyz="-0.075 0 0.142" rpy="0 0 0" />
      <geometry>
        <box size="0.032 0.12 0.025" />
        </geometry>
      </collision>
    <collision name="top_bridge_2">
      <origin xyz="0.05 0 0.142" rpy="0 0 0" />
      <geometry>
        <box size="0.032 0.12 0.025" />
        </geometry>
      </collision>
    <collision name="pin_cheek_0">
      <origin xyz="0.135 0.075 0.125" rpy="0 0 0" />
      <geometry>
        <box size="0.07 0.02 0.19" />
        </geometry>
      </collision>
    <collision name="pin_cheek_1">
      <origin xyz="0.135 -0.075 0.125" rpy="0 0 0" />
      <geometry>
        <box size="0.07 0.02 0.19" />
        </geometry>
      </collision>
    <collision name="pivot_pin">
      <origin xyz="0.135 0 0.175" rpy="1.5708 0 0" />
      <geometry>
        <cylinder radius="0.01" length="0.214" />
        </geometry>
      </collision>
    <collision name="pin_head_0">
      <origin xyz="0.135 0.102 0.175" rpy="1.5708 0 0" />
      <geometry>
        <cylinder radius="0.017" length="0.01" />
        </geometry>
      </collision>
    <collision name="pin_head_1">
      <origin xyz="0.135 -0.102 0.175" rpy="1.5708 0 0" />
      <geometry>
        <cylinder radius="0.017" length="0.01" />
        </geometry>
      </collision>
    </link>
  <link name="plunger">
    <visual name="plunger_rod">
      <origin xyz="-0.17 0 0" rpy="0 1.5708 0" />
      <geometry>
        <cylinder radius="0.013" length="0.32" />
        </geometry>
      <material name="brushed_steel">
        <color rgba="0.58 0.6 0.62 1" />
        </material>
      </visual>
    <visual name="pusher_tip">
      <origin xyz="0 0 0" rpy="0 1.5708 0" />
      <geometry>
        <cylinder radius="0.016" length="0.02" />
        </geometry>
      <material name="brushed_steel">
        <color rgba="0.58 0.6 0.62 1" />
        </material>
      </visual>
    <visual name="push_knob">
      <origin xyz="-0.35 0 0" rpy="0 1.5708 0" />
      <geometry>
        <cylinder radius="0.03" length="0.055" />
        </geometry>
      <material name="black_rubber">
        <color rgba="0.015 0.014 0.013 1" />
        </material>
      </visual>
    <collision name="plunger_rod">
      <origin xyz="-0.17 0 0" rpy="0 1.5708 0" />
      <geometry>
        <cylinder radius="0.013" length="0.32" />
        </geometry>
      </collision>
    <collision name="pusher_tip">
      <origin xyz="0 0 0" rpy="0 1.5708 0" />
      <geometry>
        <cylinder radius="0.016" length="0.02" />
        </geometry>
      </collision>
    <collision name="push_knob">
      <origin xyz="-0.35 0 0" rpy="0 1.5708 0" />
      <geometry>
        <cylinder radius="0.03" length="0.055" />
        </geometry>
      </collision>
    </link>
  <link name="front_lever">
    <visual name="lever_hub">
      <origin xyz="0 0 0" rpy="1.5708 0 0" />
      <geometry>
        <cylinder radius="0.023" length="0.052" />
        </geometry>
      <material name="painted_lever_blue">
        <color rgba="0.05 0.19 0.43 1" />
        </material>
      </visual>
    <visual name="lower_arm">
      <origin xyz="-0.024 0 -0.048" rpy="0 -2.75327 0" />
      <geometry>
        <cylinder radius="0.011" length="0.0575395" />
        </geometry>
      <material name="painted_lever_blue">
        <color rgba="0.05 0.19 0.43 1" />
        </material>
      </visual>
    <visual name="lower_fillet">
      <origin xyz="-0.02 0 -0.02" rpy="0 0 0" />
      <geometry>
        <sphere radius="0.008" />
        </geometry>
      <material name="painted_lever_blue">
        <color rgba="0.05 0.19 0.43 1" />
        </material>
      </visual>
    <visual name="contact_roller">
      <origin xyz="-0.033 0 -0.07" rpy="1.5708 0 0" />
      <geometry>
        <cylinder radius="0.017" length="0.05" />
        </geometry>
      <material name="dark_oiled_steel">
        <color rgba="0.08 0.09 0.1 1" />
        </material>
      </visual>
    <visual name="output_horn">
      <origin xyz="0.0315 0 0.0235" rpy="0 0.97362 0" />
      <geometry>
        <cylinder radius="0.008" length="0.0382324" />
        </geometry>
      <material name="painted_lever_blue">
        <color rgba="0.05 0.19 0.43 1" />
        </material>
      </visual>
    <collision name="lever_hub">
      <origin xyz="0 0 0" rpy="1.5708 0 0" />
      <geometry>
        <cylinder radius="0.023" length="0.052" />
        </geometry>
      </collision>
    <collision name="lower_arm">
      <origin xyz="-0.024 0 -0.048" rpy="0 -2.75327 0" />
      <geometry>
        <cylinder radius="0.011" length="0.0575395" />
        </geometry>
      </collision>
    <collision name="lower_fillet">
      <origin xyz="-0.02 0 -0.02" rpy="0 0 0" />
      <geometry>
        <sphere radius="0.008" />
        </geometry>
      </collision>
    <collision name="contact_roller">
      <origin xyz="-0.033 0 -0.07" rpy="1.5708 0 0" />
      <geometry>
        <cylinder radius="0.017" length="0.05" />
        </geometry>
      </collision>
    <collision name="output_horn">
      <origin xyz="0.0315 0 0.0235" rpy="0 0.97362 0" />
      <geometry>
        <cylinder radius="0.008" length="0.0382324" />
        </geometry>
      </collision>
    </link>
  <joint name="housing_to_plunger" type="prismatic">
    <origin xyz="0.075 0 0.105" rpy="0 0 0" />
    <parent link="housing" />
    <child link="plunger" />
    <axis xyz="1 0 0" />
    <limit effort="90" velocity="0.3" lower="0" upper="0.04" />
    <dynamics damping="2" friction="0.4" />
    </joint>
  <joint name="housing_to_lever" type="revolute">
    <origin xyz="0.135 0 0.175" rpy="0 0 0" />
    <parent link="housing" />
    <child link="front_lever" />
    <axis xyz="0 -1 0" />
    <limit effort="25" velocity="4" lower="0" upper="0.55" />
    <dynamics damping="0.4" friction="0.05" />
    </joint>
  </robot>
