<robot name="vertical_lift_barrier">
  <material name="galvanized_steel">
    <color rgba="0.58 0.61 0.6 1" />
    </material>
  <material name="dark_painted_steel">
    <color rgba="0.08 0.09 0.09 1" />
    </material>
  <material name="safety_yellow">
    <color rgba="0.95 0.68 0.1 1" />
    </material>
  <material name="woven_steel_mesh">
    <color rgba="0.35 0.38 0.38 1" />
    </material>
  <material name="black_rubber">
    <color rgba="0.01 0.01 0.01 1" />
    </material>
  <material name="counterweight_gray">
    <color rgba="0.28 0.29 0.28 1" />
    </material>
  <material name="dark_wire_rope">
    <color rgba="0.02 0.02 0.018 1" />
    </material>
  <link name="frame">
    <visual name="base_sill">
      <origin xyz="0 0 0.04" rpy="0 0 0" />
      <geometry>
        <box size="2.34 0.18 0.08" />
        </geometry>
      <material name="dark_painted_steel">
        <color rgba="0.08 0.09 0.09 1" />
        </material>
      </visual>
    <visual name="top_header">
      <origin xyz="0 0 2.42" rpy="0 0 0" />
      <geometry>
        <box size="2.34 0.18 0.08" />
        </geometry>
      <material name="dark_painted_steel">
        <color rgba="0.08 0.09 0.09 1" />
        </material>
      </visual>
    <visual name="left_outer_web">
      <origin xyz="-1.04 0 1.2" rpy="0 0 0" />
      <geometry>
        <box size="0.08 0.16 2.4" />
        </geometry>
      <material name="galvanized_steel">
        <color rgba="0.58 0.61 0.6 1" />
        </material>
      </visual>
    <visual name="left_front_lip">
      <origin xyz="-0.92 0.06 1.2" rpy="0 0 0" />
      <geometry>
        <box size="0.16 0.025 2.34" />
        </geometry>
      <material name="galvanized_steel">
        <color rgba="0.58 0.61 0.6 1" />
        </material>
      </visual>
    <visual name="left_rear_lip">
      <origin xyz="-0.92 -0.06 1.2" rpy="0 0 0" />
      <geometry>
        <box size="0.16 0.025 2.34" />
        </geometry>
      <material name="galvanized_steel">
        <color rgba="0.58 0.61 0.6 1" />
        </material>
      </visual>
    <visual name="left_wear_strip">
      <origin xyz="-0.9 0.0425 1.2" rpy="0 0 0" />
      <geometry>
        <box size="0.028 0.01 2.2" />
        </geometry>
      <material name="black_rubber">
        <color rgba="0.01 0.01 0.01 1" />
        </material>
      </visual>
    <visual name="right_outer_web">
      <origin xyz="1.04 0 1.2" rpy="0 0 0" />
      <geometry>
        <box size="0.08 0.16 2.4" />
        </geometry>
      <material name="galvanized_steel">
        <color rgba="0.58 0.61 0.6 1" />
        </material>
      </visual>
    <visual name="right_front_lip">
      <origin xyz="0.92 0.06 1.2" rpy="0 0 0" />
      <geometry>
        <box size="0.16 0.025 2.34" />
        </geometry>
      <material name="galvanized_steel">
        <color rgba="0.58 0.61 0.6 1" />
        </material>
      </visual>
    <visual name="right_rear_lip">
      <origin xyz="0.92 -0.06 1.2" rpy="0 0 0" />
      <geometry>
        <box size="0.16 0.025 2.34" />
        </geometry>
      <material name="galvanized_steel">
        <color rgba="0.58 0.61 0.6 1" />
        </material>
      </visual>
    <visual name="right_wear_strip">
      <origin xyz="0.9 0.0425 1.2" rpy="0 0 0" />
      <geometry>
        <box size="0.028 0.01 2.2" />
        </geometry>
      <material name="black_rubber">
        <color rgba="0.01 0.01 0.01 1" />
        </material>
      </visual>
    <visual name="rear_guide_post_1.18_0.39">
      <origin xyz="1.18 0.39 1.225" rpy="0 0 0" />
      <geometry>
        <box size="0.04 0.04 2.35" />
        </geometry>
      <material name="galvanized_steel">
        <color rgba="0.58 0.61 0.6 1" />
        </material>
      </visual>
    <visual name="rear_guide_post_1.18_0.71">
      <origin xyz="1.18 0.71 1.225" rpy="0 0 0" />
      <geometry>
        <box size="0.04 0.04 2.35" />
        </geometry>
      <material name="galvanized_steel">
        <color rgba="0.58 0.61 0.6 1" />
        </material>
      </visual>
    <visual name="rear_guide_post_1.52_0.39">
      <origin xyz="1.52 0.39 1.225" rpy="0 0 0" />
      <geometry>
        <box size="0.04 0.04 2.35" />
        </geometry>
      <material name="galvanized_steel">
        <color rgba="0.58 0.61 0.6 1" />
        </material>
      </visual>
    <visual name="rear_guide_post_1.52_0.71">
      <origin xyz="1.52 0.71 1.225" rpy="0 0 0" />
      <geometry>
        <box size="0.04 0.04 2.35" />
        </geometry>
      <material name="galvanized_steel">
        <color rgba="0.58 0.61 0.6 1" />
        </material>
      </visual>
    <visual name="rear_guide_bottom_cap">
      <origin xyz="1.35 0.55 0.08" rpy="0 0 0" />
      <geometry>
        <box size="0.42 0.36 0.06" />
        </geometry>
      <material name="dark_painted_steel">
        <color rgba="0.08 0.09 0.09 1" />
        </material>
      </visual>
    <visual name="rear_guide_rear_top_cap">
      <origin xyz="1.35 0.75 2.43" rpy="0 0 0" />
      <geometry>
        <box size="0.42 0.04 0.06" />
        </geometry>
      <material name="dark_painted_steel">
        <color rgba="0.08 0.09 0.09 1" />
        </material>
      </visual>
    <visual name="lower_rear_tie_y">
      <origin xyz="1.04 0.27 0.08" rpy="0 0 0" />
      <geometry>
        <box size="0.08 0.62 0.06" />
        </geometry>
      <material name="dark_painted_steel">
        <color rgba="0.08 0.09 0.09 1" />
        </material>
      </visual>
    <visual name="upper_rear_tie_y">
      <origin xyz="1.04 0.27 2.42" rpy="0 0 0" />
      <geometry>
        <box size="0.08 0.62 0.06" />
        </geometry>
      <material name="dark_painted_steel">
        <color rgba="0.08 0.09 0.09 1" />
        </material>
      </visual>
    <visual name="lower_rear_tie_x">
      <origin xyz="1.19 0.55 0.08" rpy="0 0 0" />
      <geometry>
        <box size="0.36 0.08 0.06" />
        </geometry>
      <material name="dark_painted_steel">
        <color rgba="0.08 0.09 0.09 1" />
        </material>
      </visual>
    <visual name="upper_rear_tie_x">
      <origin xyz="1.19 0.55 2.42" rpy="0 0 0" />
      <geometry>
        <box size="0.36 0.08 0.06" />
        </geometry>
      <material name="dark_painted_steel">
        <color rgba="0.08 0.09 0.09 1" />
        </material>
      </visual>
    <visual name="pulley_left_cheek">
      <origin xyz="1.22 0.55 2.61" rpy="0 0 0" />
      <geometry>
        <box size="0.015 0.33 0.36" />
        </geometry>
      <material name="dark_painted_steel">
        <color rgba="0.08 0.09 0.09 1" />
        </material>
      </visual>
    <visual name="pulley_right_cheek">
      <origin xyz="1.48 0.55 2.61" rpy="0 0 0" />
      <geometry>
        <box size="0.015 0.33 0.36" />
        </geometry>
      <material name="dark_painted_steel">
        <color rgba="0.08 0.09 0.09 1" />
        </material>
      </visual>
    <visual name="pulley_yoke_bridge">
      <origin xyz="1.35 0.55 2.825" rpy="0 0 0" />
      <geometry>
        <box size="0.29 0.07 0.07" />
        </geometry>
      <material name="dark_painted_steel">
        <color rgba="0.08 0.09 0.09 1" />
        </material>
      </visual>
    <collision name="base_sill">
      <origin xyz="0 0 0.04" rpy="0 0 0" />
      <geometry>
        <box size="2.34 0.18 0.08" />
        </geometry>
      </collision>
    <collision name="top_header">
      <origin xyz="0 0 2.42" rpy="0 0 0" />
      <geometry>
        <box size="2.34 0.18 0.08" />
        </geometry>
      </collision>
    <collision name="left_outer_web">
      <origin xyz="-1.04 0 1.2" rpy="0 0 0" />
      <geometry>
        <box size="0.08 0.16 2.4" />
        </geometry>
      </collision>
    <collision name="left_front_lip">
      <origin xyz="-0.92 0.06 1.2" rpy="0 0 0" />
      <geometry>
        <box size="0.16 0.025 2.34" />
        </geometry>
      </collision>
    <collision name="left_rear_lip">
      <origin xyz="-0.92 -0.06 1.2" rpy="0 0 0" />
      <geometry>
        <box size="0.16 0.025 2.34" />
        </geometry>
      </collision>
    <collision name="left_wear_strip">
      <origin xyz="-0.9 0.0425 1.2" rpy="0 0 0" />
      <geometry>
        <box size="0.028 0.01 2.2" />
        </geometry>
      </collision>
    <collision name="right_outer_web">
      <origin xyz="1.04 0 1.2" rpy="0 0 0" />
      <geometry>
        <box size="0.08 0.16 2.4" />
        </geometry>
      </collision>
    <collision name="right_front_lip">
      <origin xyz="0.92 0.06 1.2" rpy="0 0 0" />
      <geometry>
        <box size="0.16 0.025 2.34" />
        </geometry>
      </collision>
    <collision name="right_rear_lip">
      <origin xyz="0.92 -0.06 1.2" rpy="0 0 0" />
      <geometry>
        <box size="0.16 0.025 2.34" />
        </geometry>
      </collision>
    <collision name="right_wear_strip">
      <origin xyz="0.9 0.0425 1.2" rpy="0 0 0" />
      <geometry>
        <box size="0.028 0.01 2.2" />
        </geometry>
      </collision>
    <collision name="rear_guide_post_1.18_0.39">
      <origin xyz="1.18 0.39 1.225" rpy="0 0 0" />
      <geometry>
        <box size="0.04 0.04 2.35" />
        </geometry>
      </collision>
    <collision name="rear_guide_post_1.18_0.71">
      <origin xyz="1.18 0.71 1.225" rpy="0 0 0" />
      <geometry>
        <box size="0.04 0.04 2.35" />
        </geometry>
      </collision>
    <collision name="rear_guide_post_1.52_0.39">
      <origin xyz="1.52 0.39 1.225" rpy="0 0 0" />
      <geometry>
        <box size="0.04 0.04 2.35" />
        </geometry>
      </collision>
    <collision name="rear_guide_post_1.52_0.71">
      <origin xyz="1.52 0.71 1.225" rpy="0 0 0" />
      <geometry>
        <box size="0.04 0.04 2.35" />
        </geometry>
      </collision>
    <collision name="rear_guide_bottom_cap">
      <origin xyz="1.35 0.55 0.08" rpy="0 0 0" />
      <geometry>
        <box size="0.42 0.36 0.06" />
        </geometry>
      </collision>
    <collision name="rear_guide_rear_top_cap">
      <origin xyz="1.35 0.75 2.43" rpy="0 0 0" />
      <geometry>
        <box size="0.42 0.04 0.06" />
        </geometry>
      </collision>
    <collision name="lower_rear_tie_y">
      <origin xyz="1.04 0.27 0.08" rpy="0 0 0" />
      <geometry>
        <box size="0.08 0.62 0.06" />
        </geometry>
      </collision>
    <collision name="upper_rear_tie_y">
      <origin xyz="1.04 0.27 2.42" rpy="0 0 0" />
      <geometry>
        <box size="0.08 0.62 0.06" />
        </geometry>
      </collision>
    <collision name="lower_rear_tie_x">
      <origin xyz="1.19 0.55 0.08" rpy="0 0 0" />
      <geometry>
        <box size="0.36 0.08 0.06" />
        </geometry>
      </collision>
    <collision name="upper_rear_tie_x">
      <origin xyz="1.19 0.55 2.42" rpy="0 0 0" />
      <geometry>
        <box size="0.36 0.08 0.06" />
        </geometry>
      </collision>
    <collision name="pulley_left_cheek">
      <origin xyz="1.22 0.55 2.61" rpy="0 0 0" />
      <geometry>
        <box size="0.015 0.33 0.36" />
        </geometry>
      </collision>
    <collision name="pulley_right_cheek">
      <origin xyz="1.48 0.55 2.61" rpy="0 0 0" />
      <geometry>
        <box size="0.015 0.33 0.36" />
        </geometry>
      </collision>
    <collision name="pulley_yoke_bridge">
      <origin xyz="1.35 0.55 2.825" rpy="0 0 0" />
      <geometry>
        <box size="0.29 0.07 0.07" />
        </geometry>
      </collision>
    </link>
  <link name="barrier_panel">
    <visual name="left_slide_rail">
      <origin xyz="-0.89 0 0.625" rpy="0 0 0" />
      <geometry>
        <box size="0.05 0.035 1.25" />
        </geometry>
      <material name="safety_yellow">
        <color rgba="0.95 0.68 0.1 1" />
        </material>
      </visual>
    <visual name="right_slide_rail">
      <origin xyz="0.89 0 0.625" rpy="0 0 0" />
      <geometry>
        <box size="0.05 0.035 1.25" />
        </geometry>
      <material name="safety_yellow">
        <color rgba="0.95 0.68 0.1 1" />
        </material>
      </visual>
    <visual name="left_guide_shoe">
      <origin xyz="-0.89 0.0275 0.25" rpy="0 0 0" />
      <geometry>
        <box size="0.045 0.02 0.14" />
        </geometry>
      <material name="black_rubber">
        <color rgba="0.01 0.01 0.01 1" />
        </material>
      </visual>
    <visual name="right_guide_shoe">
      <origin xyz="0.89 0.0275 0.25" rpy="0 0 0" />
      <geometry>
        <box size="0.045 0.02 0.14" />
        </geometry>
      <material name="black_rubber">
        <color rgba="0.01 0.01 0.01 1" />
        </material>
      </visual>
    <visual name="top_rail">
      <origin xyz="0 0 1.225" rpy="0 0 0" />
      <geometry>
        <box size="1.83 0.035 0.05" />
        </geometry>
      <material name="safety_yellow">
        <color rgba="0.95 0.68 0.1 1" />
        </material>
      </visual>
    <visual name="bottom_rail">
      <origin xyz="0 0 0.03" rpy="0 0 0" />
      <geometry>
        <box size="1.83 0.035 0.06" />
        </geometry>
      <material name="safety_yellow">
        <color rgba="0.95 0.68 0.1 1" />
        </material>
      </visual>
    <visual name="mesh_vertical_0">
      <origin xyz="-0.68 0 0.625" rpy="0 0 0" />
      <geometry>
        <box size="0.012 0.012 1.12" />
        </geometry>
      <material name="woven_steel_mesh">
        <color rgba="0.35 0.38 0.38 1" />
        </material>
      </visual>
    <visual name="mesh_vertical_1">
      <origin xyz="-0.51 0 0.625" rpy="0 0 0" />
      <geometry>
        <box size="0.012 0.012 1.12" />
        </geometry>
      <material name="woven_steel_mesh">
        <color rgba="0.35 0.38 0.38 1" />
        </material>
      </visual>
    <visual name="mesh_vertical_2">
      <origin xyz="-0.34 0 0.625" rpy="0 0 0" />
      <geometry>
        <box size="0.012 0.012 1.12" />
        </geometry>
      <material name="woven_steel_mesh">
        <color rgba="0.35 0.38 0.38 1" />
        </material>
      </visual>
    <visual name="mesh_vertical_3">
      <origin xyz="-0.17 0 0.625" rpy="0 0 0" />
      <geometry>
        <box size="0.012 0.012 1.12" />
        </geometry>
      <material name="woven_steel_mesh">
        <color rgba="0.35 0.38 0.38 1" />
        </material>
      </visual>
    <visual name="mesh_vertical_4">
      <origin xyz="0 0 0.625" rpy="0 0 0" />
      <geometry>
        <box size="0.012 0.012 1.12" />
        </geometry>
      <material name="woven_steel_mesh">
        <color rgba="0.35 0.38 0.38 1" />
        </material>
      </visual>
    <visual name="mesh_vertical_5">
      <origin xyz="0.17 0 0.625" rpy="0 0 0" />
      <geometry>
        <box size="0.012 0.012 1.12" />
        </geometry>
      <material name="woven_steel_mesh">
        <color rgba="0.35 0.38 0.38 1" />
        </material>
      </visual>
    <visual name="mesh_vertical_6">
      <origin xyz="0.34 0 0.625" rpy="0 0 0" />
      <geometry>
        <box size="0.012 0.012 1.12" />
        </geometry>
      <material name="woven_steel_mesh">
        <color rgba="0.35 0.38 0.38 1" />
        </material>
      </visual>
    <visual name="mesh_vertical_7">
      <origin xyz="0.51 0 0.625" rpy="0 0 0" />
      <geometry>
        <box size="0.012 0.012 1.12" />
        </geometry>
      <material name="woven_steel_mesh">
        <color rgba="0.35 0.38 0.38 1" />
        </material>
      </visual>
    <visual name="mesh_vertical_8">
      <origin xyz="0.68 0 0.625" rpy="0 0 0" />
      <geometry>
        <box size="0.012 0.012 1.12" />
        </geometry>
      <material name="woven_steel_mesh">
        <color rgba="0.35 0.38 0.38 1" />
        </material>
      </visual>
    <visual name="mesh_horizontal_0">
      <origin xyz="0 0 0.22" rpy="0 0 0" />
      <geometry>
        <box size="1.73 0.01 0.01" />
        </geometry>
      <material name="woven_steel_mesh">
        <color rgba="0.35 0.38 0.38 1" />
        </material>
      </visual>
    <visual name="mesh_horizontal_1">
      <origin xyz="0 0 0.4" rpy="0 0 0" />
      <geometry>
        <box size="1.73 0.01 0.01" />
        </geometry>
      <material name="woven_steel_mesh">
        <color rgba="0.35 0.38 0.38 1" />
        </material>
      </visual>
    <visual name="mesh_horizontal_2">
      <origin xyz="0 0 0.58" rpy="0 0 0" />
      <geometry>
        <box size="1.73 0.01 0.01" />
        </geometry>
      <material name="woven_steel_mesh">
        <color rgba="0.35 0.38 0.38 1" />
        </material>
      </visual>
    <visual name="mesh_horizontal_3">
      <origin xyz="0 0 0.76" rpy="0 0 0" />
      <geometry>
        <box size="1.73 0.01 0.01" />
        </geometry>
      <material name="woven_steel_mesh">
        <color rgba="0.35 0.38 0.38 1" />
        </material>
      </visual>
    <visual name="mesh_horizontal_4">
      <origin xyz="0 0 0.94" rpy="0 0 0" />
      <geometry>
        <box size="1.73 0.01 0.01" />
        </geometry>
      <material name="woven_steel_mesh">
        <color rgba="0.35 0.38 0.38 1" />
        </material>
      </visual>
    <visual name="mesh_horizontal_5">
      <origin xyz="0 0 1.12" rpy="0 0 0" />
      <geometry>
        <box size="1.73 0.01 0.01" />
        </geometry>
      <material name="woven_steel_mesh">
        <color rgba="0.35 0.38 0.38 1" />
        </material>
      </visual>
    <visual name="cable_tab">
      <origin xyz="0.75 0.035 1.285" rpy="0 0 0" />
      <geometry>
        <box size="0.08 0.04 0.09" />
        </geometry>
      <material name="safety_yellow">
        <color rgba="0.95 0.68 0.1 1" />
        </material>
      </visual>
    <visual name="cable_anchor_pin">
      <origin xyz="0.75 0.069 1.32" rpy="0 1.5708 0" />
      <geometry>
        <cylinder radius="0.014" length="0.1" />
        </geometry>
      <material name="dark_painted_steel">
        <color rgba="0.08 0.09 0.09 1" />
        </material>
      </visual>
    <collision name="left_slide_rail">
      <origin xyz="-0.89 0 0.625" rpy="0 0 0" />
      <geometry>
        <box size="0.05 0.035 1.25" />
        </geometry>
      </collision>
    <collision name="right_slide_rail">
      <origin xyz="0.89 0 0.625" rpy="0 0 0" />
      <geometry>
        <box size="0.05 0.035 1.25" />
        </geometry>
      </collision>
    <collision name="left_guide_shoe">
      <origin xyz="-0.89 0.0275 0.25" rpy="0 0 0" />
      <geometry>
        <box size="0.045 0.02 0.14" />
        </geometry>
      </collision>
    <collision name="right_guide_shoe">
      <origin xyz="0.89 0.0275 0.25" rpy="0 0 0" />
      <geometry>
        <box size="0.045 0.02 0.14" />
        </geometry>
      </collision>
    <collision name="top_rail">
      <origin xyz="0 0 1.225" rpy="0 0 0" />
      <geometry>
        <box size="1.83 0.035 0.05" />
        </geometry>
      </collision>
    <collision name="bottom_rail">
      <origin xyz="0 0 0.03" rpy="0 0 0" />
      <geometry>
        <box size="1.83 0.035 0.06" />
        </geometry>
      </collision>
    <collision name="mesh_vertical_0">
      <origin xyz="-0.68 0 0.625" rpy="0 0 0" />
      <geometry>
        <box size="0.012 0.012 1.12" />
        </geometry>
      </collision>
    <collision name="mesh_vertical_1">
      <origin xyz="-0.51 0 0.625" rpy="0 0 0" />
      <geometry>
        <box size="0.012 0.012 1.12" />
        </geometry>
      </collision>
    <collision name="mesh_vertical_2">
      <origin xyz="-0.34 0 0.625" rpy="0 0 0" />
      <geometry>
        <box size="0.012 0.012 1.12" />
        </geometry>
      </collision>
    <collision name="mesh_vertical_3">
      <origin xyz="-0.17 0 0.625" rpy="0 0 0" />
      <geometry>
        <box size="0.012 0.012 1.12" />
        </geometry>
      </collision>
    <collision name="mesh_vertical_4">
      <origin xyz="0 0 0.625" rpy="0 0 0" />
      <geometry>
        <box size="0.012 0.012 1.12" />
        </geometry>
      </collision>
    <collision name="mesh_vertical_5">
      <origin xyz="0.17 0 0.625" rpy="0 0 0" />
      <geometry>
        <box size="0.012 0.012 1.12" />
        </geometry>
      </collision>
    <collision name="mesh_vertical_6">
      <origin xyz="0.34 0 0.625" rpy="0 0 0" />
      <geometry>
        <box size="0.012 0.012 1.12" />
        </geometry>
      </collision>
    <collision name="mesh_vertical_7">
      <origin xyz="0.51 0 0.625" rpy="0 0 0" />
      <geometry>
        <box size="0.012 0.012 1.12" />
        </geometry>
      </collision>
    <collision name="mesh_vertical_8">
      <origin xyz="0.68 0 0.625" rpy="0 0 0" />
      <geometry>
        <box size="0.012 0.012 1.12" />
        </geometry>
      </collision>
    <collision name="mesh_horizontal_0">
      <origin xyz="0 0 0.22" rpy="0 0 0" />
      <geometry>
        <box size="1.73 0.01 0.01" />
        </geometry>
      </collision>
    <collision name="mesh_horizontal_1">
      <origin xyz="0 0 0.4" rpy="0 0 0" />
      <geometry>
        <box size="1.73 0.01 0.01" />
        </geometry>
      </collision>
    <collision name="mesh_horizontal_2">
      <origin xyz="0 0 0.58" rpy="0 0 0" />
      <geometry>
        <box size="1.73 0.01 0.01" />
        </geometry>
      </collision>
    <collision name="mesh_horizontal_3">
      <origin xyz="0 0 0.76" rpy="0 0 0" />
      <geometry>
        <box size="1.73 0.01 0.01" />
        </geometry>
      </collision>
    <collision name="mesh_horizontal_4">
      <origin xyz="0 0 0.94" rpy="0 0 0" />
      <geometry>
        <box size="1.73 0.01 0.01" />
        </geometry>
      </collision>
    <collision name="mesh_horizontal_5">
      <origin xyz="0 0 1.12" rpy="0 0 0" />
      <geometry>
        <box size="1.73 0.01 0.01" />
        </geometry>
      </collision>
    <collision name="cable_tab">
      <origin xyz="0.75 0.035 1.285" rpy="0 0 0" />
      <geometry>
        <box size="0.08 0.04 0.09" />
        </geometry>
      </collision>
    <collision name="cable_anchor_pin">
      <origin xyz="0.75 0.069 1.32" rpy="0 1.5708 0" />
      <geometry>
        <cylinder radius="0.014" length="0.1" />
        </geometry>
      </collision>
    </link>
  <link name="counterweight">
    <visual name="weight_block">
      <geometry>
        <box size="0.24 0.2 0.45" />
        </geometry>
      <material name="counterweight_gray">
        <color rgba="0.28 0.29 0.28 1" />
        </material>
      </visual>
    <visual name="top_eye">
      <origin xyz="0 0.105 0.275" rpy="0 0 0" />
      <geometry>
        <box size="0.08 0.025 0.11" />
        </geometry>
      <material name="dark_painted_steel">
        <color rgba="0.08 0.09 0.09 1" />
        </material>
      </visual>
    <visual name="weight_cable_pin">
      <origin xyz="0 0.125 0.325" rpy="0 1.5708 0" />
      <geometry>
        <cylinder radius="0.018" length="0.1" />
        </geometry>
      <material name="dark_painted_steel">
        <color rgba="0.08 0.09 0.09 1" />
        </material>
      </visual>
    <collision name="weight_block">
      <geometry>
        <box size="0.24 0.2 0.45" />
        </geometry>
      </collision>
    <collision name="top_eye">
      <origin xyz="0 0.105 0.275" rpy="0 0 0" />
      <geometry>
        <box size="0.08 0.025 0.11" />
        </geometry>
      </collision>
    <collision name="weight_cable_pin">
      <origin xyz="0 0.125 0.325" rpy="0 1.5708 0" />
      <geometry>
        <cylinder radius="0.018" length="0.1" />
        </geometry>
      </collision>
    </link>
  <link name="pulley">
    <visual name="sheave">
      <origin xyz="0 0 0" rpy="0 1.5708 0" />
      <geometry>
        <cylinder radius="0.13" length="0.042" />
        </geometry>
      <material name="dark_painted_steel">
        <color rgba="0.08 0.09 0.09 1" />
        </material>
      </visual>
    <visual name="hub">
      <origin xyz="0 0 0" rpy="0 1.5708 0" />
      <geometry>
        <cylinder radius="0.046" length="0.245" />
        </geometry>
      <material name="dark_painted_steel">
        <color rgba="0.08 0.09 0.09 1" />
        </material>
      </visual>
    <visual name="left_flange">
      <origin xyz="-0.03 0 0" rpy="0 1.5708 0" />
      <geometry>
        <cylinder radius="0.138" length="0.01" />
        </geometry>
      <material name="galvanized_steel">
        <color rgba="0.58 0.61 0.6 1" />
        </material>
      </visual>
    <visual name="right_flange">
      <origin xyz="0.03 0 0" rpy="0 1.5708 0" />
      <geometry>
        <cylinder radius="0.138" length="0.01" />
        </geometry>
      <material name="galvanized_steel">
        <color rgba="0.58 0.61 0.6 1" />
        </material>
      </visual>
    <collision name="sheave">
      <origin xyz="0 0 0" rpy="0 1.5708 0" />
      <geometry>
        <cylinder radius="0.13" length="0.042" />
        </geometry>
      </collision>
    <collision name="hub">
      <origin xyz="0 0 0" rpy="0 1.5708 0" />
      <geometry>
        <cylinder radius="0.046" length="0.245" />
        </geometry>
      </collision>
    <collision name="left_flange">
      <origin xyz="-0.03 0 0" rpy="0 1.5708 0" />
      <geometry>
        <cylinder radius="0.138" length="0.01" />
        </geometry>
      </collision>
    <collision name="right_flange">
      <origin xyz="0.03 0 0" rpy="0 1.5708 0" />
      <geometry>
        <cylinder radius="0.138" length="0.01" />
        </geometry>
      </collision>
    </link>
  <link name="cable">
    <visual name="wire_rope">
      <geometry>
        <mesh filename="assets/meshes/wire_rope_over_pulley.obj" />
        </geometry>
      <material name="dark_wire_rope">
        <color rgba="0.02 0.02 0.018 1" />
        </material>
      </visual>
    <collision name="wire_rope">
      <geometry>
        <mesh filename="assets/meshes/wire_rope_over_pulley.obj" />
        </geometry>
      </collision>
    </link>
  <joint name="panel_lift" type="prismatic">
    <origin xyz="0 0 0.1" rpy="0 0 0" />
    <parent link="frame" />
    <child link="barrier_panel" />
    <axis xyz="0 0 1" />
    <limit effort="900" velocity="0.35" lower="0" upper="0.8" />
    </joint>
  <joint name="counterweight_travel" type="prismatic">
    <origin xyz="1.35 0.55 1.75" rpy="0 0 0" />
    <parent link="frame" />
    <child link="counterweight" />
    <axis xyz="0 0 -1" />
    <limit effort="900" velocity="0.35" lower="0" upper="0.8" />
    <mimic joint="panel_lift" />
    </joint>
  <joint name="pulley_spin" type="continuous">
    <origin xyz="1.35 0.55 2.62" rpy="0 0 0" />
    <parent link="frame" />
    <child link="pulley" />
    <axis xyz="1 0 0" />
    <limit effort="30" velocity="12" />
    </joint>
  <joint name="frame_to_cable" type="fixed">
    <parent link="frame" />
    <child link="cable" />
    </joint>
  </robot>
