<robot name="mesh_office_chair">
  <material name="matte_black">
    <color rgba="0.015 0.016 0.017 1" />
    </material>
  <material name="charcoal_mesh">
    <color rgba="0.02 0.027 0.03 0.72" />
    </material>
  <material name="black_fabric">
    <color rgba="0.035 0.038 0.042 1" />
    </material>
  <material name="dark_plastic">
    <color rgba="0.07 0.075 0.08 1" />
    </material>
  <material name="brushed_chrome">
    <color rgba="0.72 0.72 0.68 1" />
    </material>
  <material name="soft_rubber">
    <color rgba="0.008 0.008 0.009 1" />
    </material>
  <material name="wheel_gray">
    <color rgba="0.32 0.34 0.35 1" />
    </material>
  <link name="base">
    <visual name="base_frame">
      <geometry>
        <mesh filename="assets/meshes/five_star_base.obj" />
        </geometry>
      <material name="dark_plastic">
        <color rgba="0.07 0.075 0.08 1" />
        </material>
      </visual>
    <collision name="base_frame">
      <geometry>
        <mesh filename="assets/meshes/five_star_base.obj" />
        </geometry>
      </collision>
    </link>
  <link name="seat">
    <visual name="seat_frame">
      <geometry>
        <mesh filename="assets/meshes/seat_frame.obj" />
        </geometry>
      <material name="dark_plastic">
        <color rgba="0.07 0.075 0.08 1" />
        </material>
      </visual>
    <visual name="cushion">
      <geometry>
        <mesh filename="assets/meshes/seat_cushion.obj" />
        </geometry>
      <material name="black_fabric">
        <color rgba="0.035 0.038 0.042 1" />
        </material>
      </visual>
    <visual name="inner_mast">
      <geometry>
        <mesh filename="assets/meshes/inner_mast.obj" />
        </geometry>
      <material name="brushed_chrome">
        <color rgba="0.72 0.72 0.68 1" />
        </material>
      </visual>
    <visual name="guide_bushing">
      <geometry>
        <mesh filename="assets/meshes/guide_bushing.obj" />
        </geometry>
      <material name="dark_plastic">
        <color rgba="0.07 0.075 0.08 1" />
        </material>
      </visual>
    <visual name="back_mesh">
      <geometry>
        <mesh filename="assets/meshes/mesh_back.obj" />
        </geometry>
      <material name="charcoal_mesh">
        <color rgba="0.02 0.027 0.03 0.72" />
        </material>
      </visual>
    <collision name="seat_frame">
      <geometry>
        <mesh filename="assets/meshes/seat_frame.obj" />
        </geometry>
      </collision>
    <collision name="cushion">
      <geometry>
        <mesh filename="assets/meshes/seat_cushion.obj" />
        </geometry>
      </collision>
    <collision name="inner_mast">
      <geometry>
        <mesh filename="assets/meshes/inner_mast.obj" />
        </geometry>
      </collision>
    <collision name="guide_bushing">
      <geometry>
        <mesh filename="assets/meshes/guide_bushing.obj" />
        </geometry>
      </collision>
    <collision name="back_mesh">
      <geometry>
        <mesh filename="assets/meshes/mesh_back.obj" />
        </geometry>
      </collision>
    </link>
  <link name="caster_wheel_0">
    <visual name="tire">
      <geometry>
        <mesh filename="assets/meshes/caster_tire_0.obj" />
        </geometry>
      <material name="soft_rubber">
        <color rgba="0.008 0.008 0.009 1" />
        </material>
      </visual>
    <visual name="rim">
      <geometry>
        <mesh filename="assets/meshes/caster_rim_0.obj" />
        </geometry>
      <material name="wheel_gray">
        <color rgba="0.32 0.34 0.35 1" />
        </material>
      </visual>
    <visual name="axle">
      <geometry>
        <mesh filename="assets/meshes/caster_axle_0.obj" />
        </geometry>
      <material name="brushed_chrome">
        <color rgba="0.72 0.72 0.68 1" />
        </material>
      </visual>
    <collision name="tire">
      <geometry>
        <mesh filename="assets/meshes/caster_tire_0.obj" />
        </geometry>
      </collision>
    <collision name="rim">
      <geometry>
        <mesh filename="assets/meshes/caster_rim_0.obj" />
        </geometry>
      </collision>
    <collision name="axle">
      <geometry>
        <mesh filename="assets/meshes/caster_axle_0.obj" />
        </geometry>
      </collision>
    </link>
  <link name="caster_wheel_1">
    <visual name="tire">
      <geometry>
        <mesh filename="assets/meshes/caster_tire_1.obj" />
        </geometry>
      <material name="soft_rubber">
        <color rgba="0.008 0.008 0.009 1" />
        </material>
      </visual>
    <visual name="rim">
      <geometry>
        <mesh filename="assets/meshes/caster_rim_1.obj" />
        </geometry>
      <material name="wheel_gray">
        <color rgba="0.32 0.34 0.35 1" />
        </material>
      </visual>
    <visual name="axle">
      <geometry>
        <mesh filename="assets/meshes/caster_axle_1.obj" />
        </geometry>
      <material name="brushed_chrome">
        <color rgba="0.72 0.72 0.68 1" />
        </material>
      </visual>
    <collision name="tire">
      <geometry>
        <mesh filename="assets/meshes/caster_tire_1.obj" />
        </geometry>
      </collision>
    <collision name="rim">
      <geometry>
        <mesh filename="assets/meshes/caster_rim_1.obj" />
        </geometry>
      </collision>
    <collision name="axle">
      <geometry>
        <mesh filename="assets/meshes/caster_axle_1.obj" />
        </geometry>
      </collision>
    </link>
  <link name="caster_wheel_2">
    <visual name="tire">
      <geometry>
        <mesh filename="assets/meshes/caster_tire_2.obj" />
        </geometry>
      <material name="soft_rubber">
        <color rgba="0.008 0.008 0.009 1" />
        </material>
      </visual>
    <visual name="rim">
      <geometry>
        <mesh filename="assets/meshes/caster_rim_2.obj" />
        </geometry>
      <material name="wheel_gray">
        <color rgba="0.32 0.34 0.35 1" />
        </material>
      </visual>
    <visual name="axle">
      <geometry>
        <mesh filename="assets/meshes/caster_axle_2.obj" />
        </geometry>
      <material name="brushed_chrome">
        <color rgba="0.72 0.72 0.68 1" />
        </material>
      </visual>
    <collision name="tire">
      <geometry>
        <mesh filename="assets/meshes/caster_tire_2.obj" />
        </geometry>
      </collision>
    <collision name="rim">
      <geometry>
        <mesh filename="assets/meshes/caster_rim_2.obj" />
        </geometry>
      </collision>
    <collision name="axle">
      <geometry>
        <mesh filename="assets/meshes/caster_axle_2.obj" />
        </geometry>
      </collision>
    </link>
  <link name="caster_wheel_3">
    <visual name="tire">
      <geometry>
        <mesh filename="assets/meshes/caster_tire_3.obj" />
        </geometry>
      <material name="soft_rubber">
        <color rgba="0.008 0.008 0.009 1" />
        </material>
      </visual>
    <visual name="rim">
      <geometry>
        <mesh filename="assets/meshes/caster_rim_3.obj" />
        </geometry>
      <material name="wheel_gray">
        <color rgba="0.32 0.34 0.35 1" />
        </material>
      </visual>
    <visual name="axle">
      <geometry>
        <mesh filename="assets/meshes/caster_axle_3.obj" />
        </geometry>
      <material name="brushed_chrome">
        <color rgba="0.72 0.72 0.68 1" />
        </material>
      </visual>
    <collision name="tire">
      <geometry>
        <mesh filename="assets/meshes/caster_tire_3.obj" />
        </geometry>
      </collision>
    <collision name="rim">
      <geometry>
        <mesh filename="assets/meshes/caster_rim_3.obj" />
        </geometry>
      </collision>
    <collision name="axle">
      <geometry>
        <mesh filename="assets/meshes/caster_axle_3.obj" />
        </geometry>
      </collision>
    </link>
  <link name="caster_wheel_4">
    <visual name="tire">
      <geometry>
        <mesh filename="assets/meshes/caster_tire_4.obj" />
        </geometry>
      <material name="soft_rubber">
        <color rgba="0.008 0.008 0.009 1" />
        </material>
      </visual>
    <visual name="rim">
      <geometry>
        <mesh filename="assets/meshes/caster_rim_4.obj" />
        </geometry>
      <material name="wheel_gray">
        <color rgba="0.32 0.34 0.35 1" />
        </material>
      </visual>
    <visual name="axle">
      <geometry>
        <mesh filename="assets/meshes/caster_axle_4.obj" />
        </geometry>
      <material name="brushed_chrome">
        <color rgba="0.72 0.72 0.68 1" />
        </material>
      </visual>
    <collision name="tire">
      <geometry>
        <mesh filename="assets/meshes/caster_tire_4.obj" />
        </geometry>
      </collision>
    <collision name="rim">
      <geometry>
        <mesh filename="assets/meshes/caster_rim_4.obj" />
        </geometry>
      </collision>
    <collision name="axle">
      <geometry>
        <mesh filename="assets/meshes/caster_axle_4.obj" />
        </geometry>
      </collision>
    </link>
  <link name="left_armrest">
    <visual name="arm_frame">
      <geometry>
        <mesh filename="assets/meshes/left_armrest_frame.obj" />
        </geometry>
      <material name="dark_plastic">
        <color rgba="0.07 0.075 0.08 1" />
        </material>
      </visual>
    <visual name="pad">
      <geometry>
        <mesh filename="assets/meshes/left_armrest_pad.obj" />
        </geometry>
      <material name="matte_black">
        <color rgba="0.015 0.016 0.017 1" />
        </material>
      </visual>
    <collision name="arm_frame">
      <geometry>
        <mesh filename="assets/meshes/left_armrest_frame.obj" />
        </geometry>
      </collision>
    <collision name="pad">
      <geometry>
        <mesh filename="assets/meshes/left_armrest_pad.obj" />
        </geometry>
      </collision>
    </link>
  <link name="right_armrest">
    <visual name="arm_frame">
      <geometry>
        <mesh filename="assets/meshes/right_armrest_frame.obj" />
        </geometry>
      <material name="dark_plastic">
        <color rgba="0.07 0.075 0.08 1" />
        </material>
      </visual>
    <visual name="pad">
      <geometry>
        <mesh filename="assets/meshes/right_armrest_pad.obj" />
        </geometry>
      <material name="matte_black">
        <color rgba="0.015 0.016 0.017 1" />
        </material>
      </visual>
    <collision name="arm_frame">
      <geometry>
        <mesh filename="assets/meshes/right_armrest_frame.obj" />
        </geometry>
      </collision>
    <collision name="pad">
      <geometry>
        <mesh filename="assets/meshes/right_armrest_pad.obj" />
        </geometry>
      </collision>
    </link>
  <joint name="base_to_seat" type="prismatic">
    <origin xyz="0 0 0.335" rpy="0 0 0" />
    <parent link="base" />
    <child link="seat" />
    <axis xyz="0 0 1" />
    <limit effort="650" velocity="0.18" lower="0" upper="0.12" />
    </joint>
  <joint name="base_to_caster_0" type="continuous">
    <origin xyz="0.392 0 0.052" rpy="0 0 1.5708" />
    <parent link="base" />
    <child link="caster_wheel_0" />
    <axis xyz="1 0 0" />
    <limit effort="1" velocity="30" />
    </joint>
  <joint name="base_to_caster_1" type="continuous">
    <origin xyz="0.121135 0.372814 0.052" rpy="0 0 2.82743" />
    <parent link="base" />
    <child link="caster_wheel_1" />
    <axis xyz="1 0 0" />
    <limit effort="1" velocity="30" />
    </joint>
  <joint name="base_to_caster_2" type="continuous">
    <origin xyz="-0.317135 0.230412 0.052" rpy="0 0 4.08407" />
    <parent link="base" />
    <child link="caster_wheel_2" />
    <axis xyz="1 0 0" />
    <limit effort="1" velocity="30" />
    </joint>
  <joint name="base_to_caster_3" type="continuous">
    <origin xyz="-0.317135 -0.230412 0.052" rpy="0 0 5.34071" />
    <parent link="base" />
    <child link="caster_wheel_3" />
    <axis xyz="1 0 0" />
    <limit effort="1" velocity="30" />
    </joint>
  <joint name="base_to_caster_4" type="continuous">
    <origin xyz="0.121135 -0.372814 0.052" rpy="0 0 6.59734" />
    <parent link="base" />
    <child link="caster_wheel_4" />
    <axis xyz="1 0 0" />
    <limit effort="1" velocity="30" />
    </joint>
  <joint name="seat_to_left_armrest" type="revolute">
    <origin xyz="-0.12 0.29 0.255" rpy="0 0 0" />
    <parent link="seat" />
    <child link="left_armrest" />
    <axis xyz="0 -1 0" />
    <limit effort="9" velocity="2.5" lower="0" upper="1.7" />
    </joint>
  <joint name="seat_to_right_armrest" type="revolute">
    <origin xyz="-0.12 -0.29 0.255" rpy="0 0 0" />
    <parent link="seat" />
    <child link="right_armrest" />
    <axis xyz="0 -1 0" />
    <limit effort="9" velocity="2.5" lower="0" upper="1.7" />
    </joint>
  </robot>
