<robot name="maelzel_pyramid_metronome">
  <material name="dark_walnut">
    <color rgba="0.2 0.095 0.035 1" />
    </material>
  <material name="polished_edges">
    <color rgba="0.3 0.15 0.06 1" />
    </material>
  <material name="aged_brass">
    <color rgba="0.82 0.58 0.22 1" />
    </material>
  <material name="blued_steel">
    <color rgba="0.09 0.1 0.11 1" />
    </material>
  <material name="blackened_weight">
    <color rgba="0.015 0.014 0.012 1" />
    </material>
  <material name="ivory_scale">
    <color rgba="0.88 0.82 0.62 1" />
    </material>
  <material name="engraved_ticks">
    <color rgba="0.02 0.018 0.014 1" />
    </material>
  <link name="housing">
    <visual name="base_plinth">
      <origin xyz="0 0 0.0125" rpy="0 0 0" />
      <geometry>
        <box size="0.16 0.112 0.025" />
        </geometry>
      <material name="polished_edges">
        <color rgba="0.3 0.15 0.06 1" />
        </material>
      </visual>
    <visual name="stepped_base">
      <origin xyz="0 0 0.033" rpy="0 0 0" />
      <geometry>
        <box size="0.138 0.096 0.018" />
        </geometry>
      <material name="dark_walnut">
        <color rgba="0.2 0.095 0.035 1" />
        </material>
      </visual>
    <visual name="tapered_housing">
      <geometry>
        <mesh filename="assets/meshes/tapered_housing.obj" />
        </geometry>
      <material name="dark_walnut">
        <color rgba="0.2 0.095 0.035 1" />
        </material>
      </visual>
    <visual name="rubber_foot_0_0">
      <origin xyz="-0.06 -0.04 0.003" rpy="0 0 0" />
      <geometry>
        <cylinder radius="0.01" length="0.006" />
        </geometry>
      <material name="blackened_weight">
        <color rgba="0.015 0.014 0.012 1" />
        </material>
      </visual>
    <visual name="rubber_foot_0_1">
      <origin xyz="-0.06 0.04 0.003" rpy="0 0 0" />
      <geometry>
        <cylinder radius="0.01" length="0.006" />
        </geometry>
      <material name="blackened_weight">
        <color rgba="0.015 0.014 0.012 1" />
        </material>
      </visual>
    <visual name="rubber_foot_1_0">
      <origin xyz="0.06 -0.04 0.003" rpy="0 0 0" />
      <geometry>
        <cylinder radius="0.01" length="0.006" />
        </geometry>
      <material name="blackened_weight">
        <color rgba="0.015 0.014 0.012 1" />
        </material>
      </visual>
    <visual name="rubber_foot_1_1">
      <origin xyz="0.06 0.04 0.003" rpy="0 0 0" />
      <geometry>
        <cylinder radius="0.01" length="0.006" />
        </geometry>
      <material name="blackened_weight">
        <color rgba="0.015 0.014 0.012 1" />
        </material>
      </visual>
    <visual name="tempo_scale">
      <origin xyz="0.033 -0.045 0.169" rpy="0 0 0" />
      <geometry>
        <box size="0.013 0.003 0.256" />
        </geometry>
      <material name="ivory_scale">
        <color rgba="0.88 0.82 0.62 1" />
        </material>
      </visual>
    <visual name="scale_tick_0">
      <origin xyz="0.033 -0.0465 0.105" rpy="0 0 0" />
      <geometry>
        <box size="0.01 0.0015 0.0022" />
        </geometry>
      <material name="engraved_ticks">
        <color rgba="0.02 0.018 0.014 1" />
        </material>
      </visual>
    <visual name="scale_tick_1">
      <origin xyz="0.033 -0.0465 0.128" rpy="0 0 0" />
      <geometry>
        <box size="0.007 0.0015 0.0022" />
        </geometry>
      <material name="engraved_ticks">
        <color rgba="0.02 0.018 0.014 1" />
        </material>
      </visual>
    <visual name="scale_tick_2">
      <origin xyz="0.033 -0.0465 0.151" rpy="0 0 0" />
      <geometry>
        <box size="0.01 0.0015 0.0022" />
        </geometry>
      <material name="engraved_ticks">
        <color rgba="0.02 0.018 0.014 1" />
        </material>
      </visual>
    <visual name="scale_tick_3">
      <origin xyz="0.033 -0.0465 0.174" rpy="0 0 0" />
      <geometry>
        <box size="0.007 0.0015 0.0022" />
        </geometry>
      <material name="engraved_ticks">
        <color rgba="0.02 0.018 0.014 1" />
        </material>
      </visual>
    <visual name="scale_tick_4">
      <origin xyz="0.033 -0.0465 0.197" rpy="0 0 0" />
      <geometry>
        <box size="0.01 0.0015 0.0022" />
        </geometry>
      <material name="engraved_ticks">
        <color rgba="0.02 0.018 0.014 1" />
        </material>
      </visual>
    <visual name="scale_tick_5">
      <origin xyz="0.033 -0.0465 0.22" rpy="0 0 0" />
      <geometry>
        <box size="0.007 0.0015 0.0022" />
        </geometry>
      <material name="engraved_ticks">
        <color rgba="0.02 0.018 0.014 1" />
        </material>
      </visual>
    <visual name="scale_tick_6">
      <origin xyz="0.033 -0.0465 0.243" rpy="0 0 0" />
      <geometry>
        <box size="0.01 0.0015 0.0022" />
        </geometry>
      <material name="engraved_ticks">
        <color rgba="0.02 0.018 0.014 1" />
        </material>
      </visual>
    <visual name="scale_tick_7">
      <origin xyz="0.033 -0.0465 0.266" rpy="0 0 0" />
      <geometry>
        <box size="0.007 0.0015 0.0022" />
        </geometry>
      <material name="engraved_ticks">
        <color rgba="0.02 0.018 0.014 1" />
        </material>
      </visual>
    <visual name="scale_tick_8">
      <origin xyz="0.033 -0.0465 0.289" rpy="0 0 0" />
      <geometry>
        <box size="0.01 0.0015 0.0022" />
        </geometry>
      <material name="engraved_ticks">
        <color rgba="0.02 0.018 0.014 1" />
        </material>
      </visual>
    <visual name="pivot_bearing">
      <origin xyz="0 -0.039 0.162" rpy="-1.5708 0 0" />
      <geometry>
        <mesh filename="assets/meshes/pivot_bearing.obj" />
        </geometry>
      <material name="aged_brass">
        <color rgba="0.82 0.58 0.22 1" />
        </material>
      </visual>
    <visual name="pivot_bridge">
      <origin xyz="0 -0.039 0.162" rpy="0 0 0" />
      <geometry>
        <box size="0.074 0.006 0.012" />
        </geometry>
      <material name="aged_brass">
        <color rgba="0.82 0.58 0.22 1" />
        </material>
      </visual>
    <visual name="pivot_pin">
      <origin xyz="0 -0.052 0.162" rpy="-1.5708 0 0" />
      <geometry>
        <cylinder radius="0.0032" length="0.024" />
        </geometry>
      <material name="aged_brass">
        <color rgba="0.82 0.58 0.22 1" />
        </material>
      </visual>
    <visual name="key_bushing">
      <origin xyz="0 0.052 0.092" rpy="-1.5708 0 0" />
      <geometry>
        <cylinder radius="0.011" length="0.026" />
        </geometry>
      <material name="aged_brass">
        <color rgba="0.82 0.58 0.22 1" />
        </material>
      </visual>
    <collision name="base_plinth">
      <origin xyz="0 0 0.0125" rpy="0 0 0" />
      <geometry>
        <box size="0.16 0.112 0.025" />
        </geometry>
      </collision>
    <collision name="stepped_base">
      <origin xyz="0 0 0.033" rpy="0 0 0" />
      <geometry>
        <box size="0.138 0.096 0.018" />
        </geometry>
      </collision>
    <collision name="tapered_housing">
      <geometry>
        <mesh filename="assets/meshes/tapered_housing.obj" />
        </geometry>
      </collision>
    <collision name="rubber_foot_0_0">
      <origin xyz="-0.06 -0.04 0.003" rpy="0 0 0" />
      <geometry>
        <cylinder radius="0.01" length="0.006" />
        </geometry>
      </collision>
    <collision name="rubber_foot_0_1">
      <origin xyz="-0.06 0.04 0.003" rpy="0 0 0" />
      <geometry>
        <cylinder radius="0.01" length="0.006" />
        </geometry>
      </collision>
    <collision name="rubber_foot_1_0">
      <origin xyz="0.06 -0.04 0.003" rpy="0 0 0" />
      <geometry>
        <cylinder radius="0.01" length="0.006" />
        </geometry>
      </collision>
    <collision name="rubber_foot_1_1">
      <origin xyz="0.06 0.04 0.003" rpy="0 0 0" />
      <geometry>
        <cylinder radius="0.01" length="0.006" />
        </geometry>
      </collision>
    <collision name="tempo_scale">
      <origin xyz="0.033 -0.045 0.169" rpy="0 0 0" />
      <geometry>
        <box size="0.013 0.003 0.256" />
        </geometry>
      </collision>
    <collision name="scale_tick_0">
      <origin xyz="0.033 -0.0465 0.105" rpy="0 0 0" />
      <geometry>
        <box size="0.01 0.0015 0.0022" />
        </geometry>
      </collision>
    <collision name="scale_tick_1">
      <origin xyz="0.033 -0.0465 0.128" rpy="0 0 0" />
      <geometry>
        <box size="0.007 0.0015 0.0022" />
        </geometry>
      </collision>
    <collision name="scale_tick_2">
      <origin xyz="0.033 -0.0465 0.151" rpy="0 0 0" />
      <geometry>
        <box size="0.01 0.0015 0.0022" />
        </geometry>
      </collision>
    <collision name="scale_tick_3">
      <origin xyz="0.033 -0.0465 0.174" rpy="0 0 0" />
      <geometry>
        <box size="0.007 0.0015 0.0022" />
        </geometry>
      </collision>
    <collision name="scale_tick_4">
      <origin xyz="0.033 -0.0465 0.197" rpy="0 0 0" />
      <geometry>
        <box size="0.01 0.0015 0.0022" />
        </geometry>
      </collision>
    <collision name="scale_tick_5">
      <origin xyz="0.033 -0.0465 0.22" rpy="0 0 0" />
      <geometry>
        <box size="0.007 0.0015 0.0022" />
        </geometry>
      </collision>
    <collision name="scale_tick_6">
      <origin xyz="0.033 -0.0465 0.243" rpy="0 0 0" />
      <geometry>
        <box size="0.01 0.0015 0.0022" />
        </geometry>
      </collision>
    <collision name="scale_tick_7">
      <origin xyz="0.033 -0.0465 0.266" rpy="0 0 0" />
      <geometry>
        <box size="0.007 0.0015 0.0022" />
        </geometry>
      </collision>
    <collision name="scale_tick_8">
      <origin xyz="0.033 -0.0465 0.289" rpy="0 0 0" />
      <geometry>
        <box size="0.01 0.0015 0.0022" />
        </geometry>
      </collision>
    <collision name="pivot_bearing">
      <origin xyz="0 -0.039 0.162" rpy="-1.5708 0 0" />
      <geometry>
        <mesh filename="assets/meshes/pivot_bearing.obj" />
        </geometry>
      </collision>
    <collision name="pivot_bridge">
      <origin xyz="0 -0.039 0.162" rpy="0 0 0" />
      <geometry>
        <box size="0.074 0.006 0.012" />
        </geometry>
      </collision>
    <collision name="pivot_pin">
      <origin xyz="0 -0.052 0.162" rpy="-1.5708 0 0" />
      <geometry>
        <cylinder radius="0.0032" length="0.024" />
        </geometry>
      </collision>
    <collision name="key_bushing">
      <origin xyz="0 0.052 0.092" rpy="-1.5708 0 0" />
      <geometry>
        <cylinder radius="0.011" length="0.026" />
        </geometry>
      </collision>
    </link>
  <link name="pendulum">
    <visual name="pendulum_rod">
      <origin xyz="0 0 0.1095" rpy="0 0 0" />
      <geometry>
        <cylinder radius="0.0038" length="0.207" />
        </geometry>
      <material name="blued_steel">
        <color rgba="0.09 0.1 0.11 1" />
        </material>
      </visual>
    <visual name="lower_rod">
      <origin xyz="0 0 -0.0605" rpy="0 0 0" />
      <geometry>
        <cylinder radius="0.0038" length="0.109" />
        </geometry>
      <material name="blued_steel">
        <color rgba="0.09 0.1 0.11 1" />
        </material>
      </visual>
    <visual name="pivot_hub">
      <origin xyz="0 0 0" rpy="-1.5708 0 0" />
      <geometry>
        <cylinder radius="0.015" length="0.012" />
        </geometry>
      <material name="aged_brass">
        <color rgba="0.82 0.58 0.22 1" />
        </material>
      </visual>
    <visual name="counterweight">
      <origin xyz="0 0 -0.08" rpy="0 0 0" />
      <geometry>
        <cylinder radius="0.018" length="0.042" />
        </geometry>
      <material name="aged_brass">
        <color rgba="0.82 0.58 0.22 1" />
        </material>
      </visual>
    <collision name="pendulum_rod">
      <origin xyz="0 0 0.1095" rpy="0 0 0" />
      <geometry>
        <cylinder radius="0.0038" length="0.207" />
        </geometry>
      </collision>
    <collision name="lower_rod">
      <origin xyz="0 0 -0.0605" rpy="0 0 0" />
      <geometry>
        <cylinder radius="0.0038" length="0.109" />
        </geometry>
      </collision>
    <collision name="pivot_hub">
      <origin xyz="0 0 0" rpy="-1.5708 0 0" />
      <geometry>
        <cylinder radius="0.015" length="0.012" />
        </geometry>
      </collision>
    <collision name="counterweight">
      <origin xyz="0 0 -0.08" rpy="0 0 0" />
      <geometry>
        <cylinder radius="0.018" length="0.042" />
        </geometry>
      </collision>
    </link>
  <link name="cone_weight">
    <visual name="cone_weight_shell">
      <geometry>
        <mesh filename="assets/meshes/cone_weight_shell.obj" />
        </geometry>
      <material name="blackened_weight">
        <color rgba="0.015 0.014 0.012 1" />
        </material>
      </visual>
    <visual name="lower_collar">
      <origin xyz="0 0 -0.039" rpy="0 0 0" />
      <geometry>
        <mesh filename="assets/meshes/lower_collar.obj" />
        </geometry>
      <material name="aged_brass">
        <color rgba="0.82 0.58 0.22 1" />
        </material>
      </visual>
    <collision name="cone_weight_shell">
      <geometry>
        <mesh filename="assets/meshes/cone_weight_shell.obj" />
        </geometry>
      </collision>
    <collision name="lower_collar">
      <origin xyz="0 0 -0.039" rpy="0 0 0" />
      <geometry>
        <mesh filename="assets/meshes/lower_collar.obj" />
        </geometry>
      </collision>
    </link>
  <link name="winding_key">
    <visual name="key_shaft">
      <origin xyz="0 0.021 0" rpy="-1.5708 0 0" />
      <geometry>
        <cylinder radius="0.006" length="0.042" />
        </geometry>
      <material name="aged_brass">
        <color rgba="0.82 0.58 0.22 1" />
        </material>
      </visual>
    <visual name="key_hub">
      <origin xyz="0 0.045 0" rpy="-1.5708 0 0" />
      <geometry>
        <cylinder radius="0.012" length="0.014" />
        </geometry>
      <material name="aged_brass">
        <color rgba="0.82 0.58 0.22 1" />
        </material>
      </visual>
    <visual name="wing_plate">
      <origin xyz="0 0.054 0" rpy="0 0 0" />
      <geometry>
        <box size="0.083 0.01 0.022" />
        </geometry>
      <material name="aged_brass">
        <color rgba="0.82 0.58 0.22 1" />
        </material>
      </visual>
    <visual name="rounded_wing_0">
      <origin xyz="-0.0415 0.054 0" rpy="-1.5708 0 0" />
      <geometry>
        <cylinder radius="0.014" length="0.011" />
        </geometry>
      <material name="aged_brass">
        <color rgba="0.82 0.58 0.22 1" />
        </material>
      </visual>
    <visual name="rounded_wing_1">
      <origin xyz="0.0415 0.054 0" rpy="-1.5708 0 0" />
      <geometry>
        <cylinder radius="0.014" length="0.011" />
        </geometry>
      <material name="aged_brass">
        <color rgba="0.82 0.58 0.22 1" />
        </material>
      </visual>
    <collision name="key_shaft">
      <origin xyz="0 0.021 0" rpy="-1.5708 0 0" />
      <geometry>
        <cylinder radius="0.006" length="0.042" />
        </geometry>
      </collision>
    <collision name="key_hub">
      <origin xyz="0 0.045 0" rpy="-1.5708 0 0" />
      <geometry>
        <cylinder radius="0.012" length="0.014" />
        </geometry>
      </collision>
    <collision name="wing_plate">
      <origin xyz="0 0.054 0" rpy="0 0 0" />
      <geometry>
        <box size="0.083 0.01 0.022" />
        </geometry>
      </collision>
    <collision name="rounded_wing_0">
      <origin xyz="-0.0415 0.054 0" rpy="-1.5708 0 0" />
      <geometry>
        <cylinder radius="0.014" length="0.011" />
        </geometry>
      </collision>
    <collision name="rounded_wing_1">
      <origin xyz="0.0415 0.054 0" rpy="-1.5708 0 0" />
      <geometry>
        <cylinder radius="0.014" length="0.011" />
        </geometry>
      </collision>
    </link>
  <joint name="housing_to_pendulum" type="revolute">
    <origin xyz="0 -0.052 0.162" rpy="0 0 0" />
    <parent link="housing" />
    <child link="pendulum" />
    <axis xyz="0 1 0" />
    <limit effort="0.25" velocity="3" lower="-0.3" upper="0.3" />
    </joint>
  <joint name="pendulum_to_cone_weight" type="prismatic">
    <origin xyz="0 0 0.09" rpy="0 0 0" />
    <parent link="pendulum" />
    <child link="cone_weight" />
    <axis xyz="0 0 1" />
    <limit effort="1.5" velocity="0.08" lower="0" upper="0.065" />
    </joint>
  <joint name="housing_to_winding_key" type="continuous">
    <origin xyz="0 0.065 0.092" rpy="0 0 0" />
    <parent link="housing" />
    <child link="winding_key" />
    <axis xyz="0 1 0" />
    <limit effort="0.6" velocity="8" />
    </joint>
  </robot>
