<robot name="teaching_room_drafting_table">
  <material name="blue_gray_painted_steel">
    <color rgba="0.17 0.23 0.28 1" />
    </material>
  <material name="dark_burnished_steel">
    <color rgba="0.06 0.065 0.07 1" />
    </material>
  <material name="satin_zinc_steel">
    <color rgba="0.55 0.58 0.56 1" />
    </material>
  <material name="black_plastic">
    <color rgba="0.015 0.014 0.012 1" />
    </material>
  <material name="matte_green_drafting_surface">
    <color rgba="0.62 0.7 0.61 1" />
    </material>
  <material name="dark_anodized_tray">
    <color rgba="0.08 0.085 0.09 1" />
    </material>
  <link name="floor_base">
    <visual name="wide_floor_foot">
      <origin xyz="0 0 0.0275" rpy="0 0 0" />
      <geometry>
        <box size="1.35 0.54 0.055" />
        </geometry>
      <material name="blue_gray_painted_steel">
        <color rgba="0.17 0.23 0.28 1" />
        </material>
      </visual>
    <visual name="fore_aft_outrigger">
      <origin xyz="0 0 0.025" rpy="0 0 0" />
      <geometry>
        <box size="0.3 0.86 0.05" />
        </geometry>
      <material name="blue_gray_painted_steel">
        <color rgba="0.17 0.23 0.28 1" />
        </material>
      </visual>
    <visual name="raised_pedestal">
      <origin xyz="0 0 0.095" rpy="0 0 0" />
      <geometry>
        <box size="0.32 0.24 0.08" />
        </geometry>
      <material name="dark_burnished_steel">
        <color rgba="0.06 0.065 0.07 1" />
        </material>
      </visual>
    <collision name="wide_floor_foot">
      <origin xyz="0 0 0.0275" rpy="0 0 0" />
      <geometry>
        <box size="1.35 0.54 0.055" />
        </geometry>
      </collision>
    <collision name="fore_aft_outrigger">
      <origin xyz="0 0 0.025" rpy="0 0 0" />
      <geometry>
        <box size="0.3 0.86 0.05" />
        </geometry>
      </collision>
    <collision name="raised_pedestal">
      <origin xyz="0 0 0.095" rpy="0 0 0" />
      <geometry>
        <box size="0.32 0.24 0.08" />
        </geometry>
      </collision>
    </link>
  <link name="column_sleeve">
    <visual name="front_sleeve_wall">
      <origin xyz="0 0.066 0.31" rpy="0 0 0" />
      <geometry>
        <box size="0.185 0.014 0.62" />
        </geometry>
      <material name="dark_burnished_steel">
        <color rgba="0.06 0.065 0.07 1" />
        </material>
      </visual>
    <visual name="rear_sleeve_wall">
      <origin xyz="0 -0.066 0.31" rpy="0 0 0" />
      <geometry>
        <box size="0.185 0.014 0.62" />
        </geometry>
      <material name="dark_burnished_steel">
        <color rgba="0.06 0.065 0.07 1" />
        </material>
      </visual>
    <visual name="side_sleeve_wall_0">
      <origin xyz="0.0855 0 0.31" rpy="0 0 0" />
      <geometry>
        <box size="0.014 0.132 0.62" />
        </geometry>
      <material name="dark_burnished_steel">
        <color rgba="0.06 0.065 0.07 1" />
        </material>
      </visual>
    <visual name="side_sleeve_wall_1">
      <origin xyz="-0.0855 0 0.31" rpy="0 0 0" />
      <geometry>
        <box size="0.014 0.132 0.62" />
        </geometry>
      <material name="dark_burnished_steel">
        <color rgba="0.06 0.065 0.07 1" />
        </material>
      </visual>
    <visual name="front_top_collar">
      <origin xyz="0 0.079 0.5925" rpy="0 0 0" />
      <geometry>
        <box size="0.215 0.026 0.055" />
        </geometry>
      <material name="satin_zinc_steel">
        <color rgba="0.55 0.58 0.56 1" />
        </material>
      </visual>
    <visual name="rear_top_collar">
      <origin xyz="0 -0.079 0.5925" rpy="0 0 0" />
      <geometry>
        <box size="0.215 0.026 0.055" />
        </geometry>
      <material name="satin_zinc_steel">
        <color rgba="0.55 0.58 0.56 1" />
        </material>
      </visual>
    <visual name="side_top_collar_0">
      <origin xyz="0.098 0 0.5925" rpy="0 0 0" />
      <geometry>
        <box size="0.026 0.158 0.055" />
        </geometry>
      <material name="satin_zinc_steel">
        <color rgba="0.55 0.58 0.56 1" />
        </material>
      </visual>
    <visual name="side_top_collar_1">
      <origin xyz="-0.098 0 0.5925" rpy="0 0 0" />
      <geometry>
        <box size="0.026 0.158 0.055" />
        </geometry>
      <material name="satin_zinc_steel">
        <color rgba="0.55 0.58 0.56 1" />
        </material>
      </visual>
    <collision name="front_sleeve_wall">
      <origin xyz="0 0.066 0.31" rpy="0 0 0" />
      <geometry>
        <box size="0.185 0.014 0.62" />
        </geometry>
      </collision>
    <collision name="rear_sleeve_wall">
      <origin xyz="0 -0.066 0.31" rpy="0 0 0" />
      <geometry>
        <box size="0.185 0.014 0.62" />
        </geometry>
      </collision>
    <collision name="side_sleeve_wall_0">
      <origin xyz="0.0855 0 0.31" rpy="0 0 0" />
      <geometry>
        <box size="0.014 0.132 0.62" />
        </geometry>
      </collision>
    <collision name="side_sleeve_wall_1">
      <origin xyz="-0.0855 0 0.31" rpy="0 0 0" />
      <geometry>
        <box size="0.014 0.132 0.62" />
        </geometry>
      </collision>
    <collision name="front_top_collar">
      <origin xyz="0 0.079 0.5925" rpy="0 0 0" />
      <geometry>
        <box size="0.215 0.026 0.055" />
        </geometry>
      </collision>
    <collision name="rear_top_collar">
      <origin xyz="0 -0.079 0.5925" rpy="0 0 0" />
      <geometry>
        <box size="0.215 0.026 0.055" />
        </geometry>
      </collision>
    <collision name="side_top_collar_0">
      <origin xyz="0.098 0 0.5925" rpy="0 0 0" />
      <geometry>
        <box size="0.026 0.158 0.055" />
        </geometry>
      </collision>
    <collision name="side_top_collar_1">
      <origin xyz="-0.098 0 0.5925" rpy="0 0 0" />
      <geometry>
        <box size="0.026 0.158 0.055" />
        </geometry>
      </collision>
    </link>
  <link name="height_column">
    <visual name="inner_column">
      <origin xyz="0 0 0.07" rpy="0 0 0" />
      <geometry>
        <box size="0.09 0.054 0.98" />
        </geometry>
      <material name="satin_zinc_steel">
        <color rgba="0.55 0.58 0.56 1" />
        </material>
      </visual>
    <visual name="head_mount_plate">
      <origin xyz="0 0 0.56" rpy="0 0 0" />
      <geometry>
        <box size="0.125 0.09 0.035" />
        </geometry>
      <material name="dark_burnished_steel">
        <color rgba="0.06 0.065 0.07 1" />
        </material>
      </visual>
    <visual name="side_guide_pad_0">
      <origin xyz="0.06175 0 -0.32" rpy="0 0 0" />
      <geometry>
        <box size="0.0335 0.03 0.06" />
        </geometry>
      <material name="satin_zinc_steel">
        <color rgba="0.55 0.58 0.56 1" />
        </material>
      </visual>
    <visual name="side_guide_pad_1">
      <origin xyz="-0.06175 0 -0.32" rpy="0 0 0" />
      <geometry>
        <box size="0.0335 0.03 0.06" />
        </geometry>
      <material name="satin_zinc_steel">
        <color rgba="0.55 0.58 0.56 1" />
        </material>
      </visual>
    <visual name="fore_aft_guide_pad_0">
      <origin xyz="0 0.043 -0.32" rpy="0 0 0" />
      <geometry>
        <box size="0.03 0.032 0.06" />
        </geometry>
      <material name="satin_zinc_steel">
        <color rgba="0.55 0.58 0.56 1" />
        </material>
      </visual>
    <visual name="fore_aft_guide_pad_1">
      <origin xyz="0 -0.043 -0.32" rpy="0 0 0" />
      <geometry>
        <box size="0.03 0.032 0.06" />
        </geometry>
      <material name="satin_zinc_steel">
        <color rgba="0.55 0.58 0.56 1" />
        </material>
      </visual>
    <collision name="inner_column">
      <origin xyz="0 0 0.07" rpy="0 0 0" />
      <geometry>
        <box size="0.09 0.054 0.98" />
        </geometry>
      </collision>
    <collision name="head_mount_plate">
      <origin xyz="0 0 0.56" rpy="0 0 0" />
      <geometry>
        <box size="0.125 0.09 0.035" />
        </geometry>
      </collision>
    <collision name="side_guide_pad_0">
      <origin xyz="0.06175 0 -0.32" rpy="0 0 0" />
      <geometry>
        <box size="0.0335 0.03 0.06" />
        </geometry>
      </collision>
    <collision name="side_guide_pad_1">
      <origin xyz="-0.06175 0 -0.32" rpy="0 0 0" />
      <geometry>
        <box size="0.0335 0.03 0.06" />
        </geometry>
      </collision>
    <collision name="fore_aft_guide_pad_0">
      <origin xyz="0 0.043 -0.32" rpy="0 0 0" />
      <geometry>
        <box size="0.03 0.032 0.06" />
        </geometry>
      </collision>
    <collision name="fore_aft_guide_pad_1">
      <origin xyz="0 -0.043 -0.32" rpy="0 0 0" />
      <geometry>
        <box size="0.03 0.032 0.06" />
        </geometry>
      </collision>
    </link>
  <link name="support_head">
    <visual name="separate_head_block">
      <origin xyz="0 0 0.0375" rpy="0 0 0" />
      <geometry>
        <box size="0.22 0.14 0.075" />
        </geometry>
      <material name="dark_burnished_steel">
        <color rgba="0.06 0.065 0.07 1" />
        </material>
      </visual>
    <visual name="short_neck">
      <origin xyz="0 -0.015 0.115" rpy="0 0 0" />
      <geometry>
        <box size="0.1 0.08 0.13" />
        </geometry>
      <material name="dark_burnished_steel">
        <color rgba="0.06 0.065 0.07 1" />
        </material>
      </visual>
    <visual name="lower_yoke_crossbar">
      <origin xyz="0 -0.04 0.145" rpy="0 0 0" />
      <geometry>
        <box size="1.46 0.08 0.05" />
        </geometry>
      <material name="dark_burnished_steel">
        <color rgba="0.06 0.065 0.07 1" />
        </material>
      </visual>
    <visual name="yoke_cheek_0">
      <origin xyz="0.69 -0.04 0.235" rpy="0 0 0" />
      <geometry>
        <box size="0.05 0.105 0.225" />
        </geometry>
      <material name="dark_burnished_steel">
        <color rgba="0.06 0.065 0.07 1" />
        </material>
      </visual>
    <visual name="yoke_cheek_1">
      <origin xyz="-0.69 -0.04 0.235" rpy="0 0 0" />
      <geometry>
        <box size="0.05 0.105 0.225" />
        </geometry>
      <material name="dark_burnished_steel">
        <color rgba="0.06 0.065 0.07 1" />
        </material>
      </visual>
    <visual name="hinge_pin">
      <origin xyz="0 -0.04 0.24" rpy="0 1.5708 0" />
      <geometry>
        <cylinder radius="0.018" length="1.48" />
        </geometry>
      <material name="satin_zinc_steel">
        <color rgba="0.55 0.58 0.56 1" />
        </material>
      </visual>
    <visual name="clamp_side_tab">
      <origin xyz="0.72 -0.04 0.24" rpy="0 0 0" />
      <geometry>
        <box size="0.05 0.095 0.125" />
        </geometry>
      <material name="dark_burnished_steel">
        <color rgba="0.06 0.065 0.07 1" />
        </material>
      </visual>
    <visual name="knob_boss">
      <origin xyz="0.754 -0.04 0.24" rpy="0 1.5708 0" />
      <geometry>
        <cylinder radius="0.033" length="0.018" />
        </geometry>
      <material name="satin_zinc_steel">
        <color rgba="0.55 0.58 0.56 1" />
        </material>
      </visual>
    <collision name="separate_head_block">
      <origin xyz="0 0 0.0375" rpy="0 0 0" />
      <geometry>
        <box size="0.22 0.14 0.075" />
        </geometry>
      </collision>
    <collision name="short_neck">
      <origin xyz="0 -0.015 0.115" rpy="0 0 0" />
      <geometry>
        <box size="0.1 0.08 0.13" />
        </geometry>
      </collision>
    <collision name="lower_yoke_crossbar">
      <origin xyz="0 -0.04 0.145" rpy="0 0 0" />
      <geometry>
        <box size="1.46 0.08 0.05" />
        </geometry>
      </collision>
    <collision name="yoke_cheek_0">
      <origin xyz="0.69 -0.04 0.235" rpy="0 0 0" />
      <geometry>
        <box size="0.05 0.105 0.225" />
        </geometry>
      </collision>
    <collision name="yoke_cheek_1">
      <origin xyz="-0.69 -0.04 0.235" rpy="0 0 0" />
      <geometry>
        <box size="0.05 0.105 0.225" />
        </geometry>
      </collision>
    <collision name="hinge_pin">
      <origin xyz="0 -0.04 0.24" rpy="0 1.5708 0" />
      <geometry>
        <cylinder radius="0.018" length="1.48" />
        </geometry>
      </collision>
    <collision name="clamp_side_tab">
      <origin xyz="0.72 -0.04 0.24" rpy="0 0 0" />
      <geometry>
        <box size="0.05 0.095 0.125" />
        </geometry>
      </collision>
    <collision name="knob_boss">
      <origin xyz="0.754 -0.04 0.24" rpy="0 1.5708 0" />
      <geometry>
        <cylinder radius="0.033" length="0.018" />
        </geometry>
      </collision>
    </link>
  <link name="board">
    <visual name="drawing_board_panel">
      <origin xyz="0 0 0.045" rpy="0 0 0" />
      <geometry>
        <box size="1.2 0.82 0.03" />
        </geometry>
      <material name="matte_green_drafting_surface">
        <color rgba="0.62 0.7 0.61 1" />
        </material>
      </visual>
    <visual name="top_edge_frame">
      <origin xyz="0 0.425 0.065" rpy="0 0 0" />
      <geometry>
        <box size="1.24 0.03 0.04" />
        </geometry>
      <material name="satin_zinc_steel">
        <color rgba="0.55 0.58 0.56 1" />
        </material>
      </visual>
    <visual name="bottom_edge_frame">
      <origin xyz="0 -0.425 0.065" rpy="0 0 0" />
      <geometry>
        <box size="1.24 0.03 0.04" />
        </geometry>
      <material name="satin_zinc_steel">
        <color rgba="0.55 0.58 0.56 1" />
        </material>
      </visual>
    <visual name="side_edge_frame_0">
      <origin xyz="0.615 0 0.065" rpy="0 0 0" />
      <geometry>
        <box size="0.03 0.86 0.04" />
        </geometry>
      <material name="satin_zinc_steel">
        <color rgba="0.55 0.58 0.56 1" />
        </material>
      </visual>
    <visual name="side_edge_frame_1">
      <origin xyz="-0.615 0 0.065" rpy="0 0 0" />
      <geometry>
        <box size="0.03 0.86 0.04" />
        </geometry>
      <material name="satin_zinc_steel">
        <color rgba="0.55 0.58 0.56 1" />
        </material>
      </visual>
    <visual name="hinge_leaf">
      <origin xyz="0 0 0.041" rpy="0 0 0" />
      <geometry>
        <box size="0.52 0.09 0.03" />
        </geometry>
      <material name="dark_burnished_steel">
        <color rgba="0.06 0.065 0.07 1" />
        </material>
      </visual>
    <visual name="hinge_knuckle">
      <origin xyz="0 0 0" rpy="0 1.5708 0" />
      <geometry>
        <cylinder radius="0.026" length="0.52" />
        </geometry>
      <material name="dark_burnished_steel">
        <color rgba="0.06 0.065 0.07 1" />
        </material>
      </visual>
    <visual name="tool_tray_shelf">
      <origin xyz="0 -0.475 0.058" rpy="0 0 0" />
      <geometry>
        <box size="1.15 0.085 0.024" />
        </geometry>
      <material name="dark_anodized_tray">
        <color rgba="0.08 0.085 0.09 1" />
        </material>
      </visual>
    <visual name="tool_tray_back">
      <origin xyz="0 -0.425 0.078" rpy="0 0 0" />
      <geometry>
        <box size="1.15 0.024 0.082" />
        </geometry>
      <material name="dark_anodized_tray">
        <color rgba="0.08 0.085 0.09 1" />
        </material>
      </visual>
    <visual name="tool_tray_lip">
      <origin xyz="0 -0.52 0.078" rpy="0 0 0" />
      <geometry>
        <box size="1.15 0.026 0.072" />
        </geometry>
      <material name="dark_anodized_tray">
        <color rgba="0.08 0.085 0.09 1" />
        </material>
      </visual>
    <collision name="drawing_board_panel">
      <origin xyz="0 0 0.045" rpy="0 0 0" />
      <geometry>
        <box size="1.2 0.82 0.03" />
        </geometry>
      </collision>
    <collision name="top_edge_frame">
      <origin xyz="0 0.425 0.065" rpy="0 0 0" />
      <geometry>
        <box size="1.24 0.03 0.04" />
        </geometry>
      </collision>
    <collision name="bottom_edge_frame">
      <origin xyz="0 -0.425 0.065" rpy="0 0 0" />
      <geometry>
        <box size="1.24 0.03 0.04" />
        </geometry>
      </collision>
    <collision name="side_edge_frame_0">
      <origin xyz="0.615 0 0.065" rpy="0 0 0" />
      <geometry>
        <box size="0.03 0.86 0.04" />
        </geometry>
      </collision>
    <collision name="side_edge_frame_1">
      <origin xyz="-0.615 0 0.065" rpy="0 0 0" />
      <geometry>
        <box size="0.03 0.86 0.04" />
        </geometry>
      </collision>
    <collision name="hinge_leaf">
      <origin xyz="0 0 0.041" rpy="0 0 0" />
      <geometry>
        <box size="0.52 0.09 0.03" />
        </geometry>
      </collision>
    <collision name="hinge_knuckle">
      <origin xyz="0 0 0" rpy="0 1.5708 0" />
      <geometry>
        <cylinder radius="0.026" length="0.52" />
        </geometry>
      </collision>
    <collision name="tool_tray_shelf">
      <origin xyz="0 -0.475 0.058" rpy="0 0 0" />
      <geometry>
        <box size="1.15 0.085 0.024" />
        </geometry>
      </collision>
    <collision name="tool_tray_back">
      <origin xyz="0 -0.425 0.078" rpy="0 0 0" />
      <geometry>
        <box size="1.15 0.024 0.082" />
        </geometry>
      </collision>
    <collision name="tool_tray_lip">
      <origin xyz="0 -0.52 0.078" rpy="0 0 0" />
      <geometry>
        <box size="1.15 0.026 0.072" />
        </geometry>
      </collision>
    </link>
  <link name="clamp_knob">
    <visual name="threaded_shaft">
      <origin xyz="0.0275 0 0" rpy="0 1.5708 0" />
      <geometry>
        <cylinder radius="0.012" length="0.055" />
        </geometry>
      <material name="satin_zinc_steel">
        <color rgba="0.55 0.58 0.56 1" />
        </material>
      </visual>
    <visual name="thread_ridge_0">
      <origin xyz="0.007 0 0" rpy="0 1.5708 0" />
      <geometry>
        <cylinder radius="0.014" length="0.0035" />
        </geometry>
      <material name="satin_zinc_steel">
        <color rgba="0.55 0.58 0.56 1" />
        </material>
      </visual>
    <visual name="thread_ridge_1">
      <origin xyz="0.017 0 0" rpy="0 1.5708 0" />
      <geometry>
        <cylinder radius="0.014" length="0.0035" />
        </geometry>
      <material name="satin_zinc_steel">
        <color rgba="0.55 0.58 0.56 1" />
        </material>
      </visual>
    <visual name="thread_ridge_2">
      <origin xyz="0.027 0 0" rpy="0 1.5708 0" />
      <geometry>
        <cylinder radius="0.014" length="0.0035" />
        </geometry>
      <material name="satin_zinc_steel">
        <color rgba="0.55 0.58 0.56 1" />
        </material>
      </visual>
    <visual name="thread_ridge_3">
      <origin xyz="0.037 0 0" rpy="0 1.5708 0" />
      <geometry>
        <cylinder radius="0.014" length="0.0035" />
        </geometry>
      <material name="satin_zinc_steel">
        <color rgba="0.55 0.58 0.56 1" />
        </material>
      </visual>
    <visual name="thread_ridge_4">
      <origin xyz="0.047 0 0" rpy="0 1.5708 0" />
      <geometry>
        <cylinder radius="0.014" length="0.0035" />
        </geometry>
      <material name="satin_zinc_steel">
        <color rgba="0.55 0.58 0.56 1" />
        </material>
      </visual>
    <visual name="knob_back_washer">
      <origin xyz="0.06 0 0" rpy="0 1.5708 0" />
      <geometry>
        <cylinder radius="0.046" length="0.01" />
        </geometry>
      <material name="black_plastic">
        <color rgba="0.015 0.014 0.012 1" />
        </material>
      </visual>
    <visual name="knob_center_hub">
      <origin xyz="0.085 0 0" rpy="0 1.5708 0" />
      <geometry>
        <cylinder radius="0.04" length="0.045" />
        </geometry>
      <material name="black_plastic">
        <color rgba="0.015 0.014 0.012 1" />
        </material>
      </visual>
    <visual name="knob_lobe_0">
      <origin xyz="0.085 0 0.044" rpy="0 1.5708 0" />
      <geometry>
        <cylinder radius="0.025" length="0.045" />
        </geometry>
      <material name="black_plastic">
        <color rgba="0.015 0.014 0.012 1" />
        </material>
      </visual>
    <visual name="knob_lobe_1">
      <origin xyz="0.085 0.038 0.022" rpy="0 1.5708 0" />
      <geometry>
        <cylinder radius="0.025" length="0.045" />
        </geometry>
      <material name="black_plastic">
        <color rgba="0.015 0.014 0.012 1" />
        </material>
      </visual>
    <visual name="knob_lobe_2">
      <origin xyz="0.085 0.038 -0.022" rpy="0 1.5708 0" />
      <geometry>
        <cylinder radius="0.025" length="0.045" />
        </geometry>
      <material name="black_plastic">
        <color rgba="0.015 0.014 0.012 1" />
        </material>
      </visual>
    <visual name="knob_lobe_3">
      <origin xyz="0.085 0 -0.044" rpy="0 1.5708 0" />
      <geometry>
        <cylinder radius="0.025" length="0.045" />
        </geometry>
      <material name="black_plastic">
        <color rgba="0.015 0.014 0.012 1" />
        </material>
      </visual>
    <visual name="knob_lobe_4">
      <origin xyz="0.085 -0.038 -0.022" rpy="0 1.5708 0" />
      <geometry>
        <cylinder radius="0.025" length="0.045" />
        </geometry>
      <material name="black_plastic">
        <color rgba="0.015 0.014 0.012 1" />
        </material>
      </visual>
    <visual name="knob_lobe_5">
      <origin xyz="0.085 -0.038 0.022" rpy="0 1.5708 0" />
      <geometry>
        <cylinder radius="0.025" length="0.045" />
        </geometry>
      <material name="black_plastic">
        <color rgba="0.015 0.014 0.012 1" />
        </material>
      </visual>
    <visual name="knob_end_cap">
      <origin xyz="0.1105 0 0" rpy="0 1.5708 0" />
      <geometry>
        <cylinder radius="0.03" length="0.006" />
        </geometry>
      <material name="black_plastic">
        <color rgba="0.015 0.014 0.012 1" />
        </material>
      </visual>
    <collision name="threaded_shaft">
      <origin xyz="0.0275 0 0" rpy="0 1.5708 0" />
      <geometry>
        <cylinder radius="0.012" length="0.055" />
        </geometry>
      </collision>
    <collision name="thread_ridge_0">
      <origin xyz="0.007 0 0" rpy="0 1.5708 0" />
      <geometry>
        <cylinder radius="0.014" length="0.0035" />
        </geometry>
      </collision>
    <collision name="thread_ridge_1">
      <origin xyz="0.017 0 0" rpy="0 1.5708 0" />
      <geometry>
        <cylinder radius="0.014" length="0.0035" />
        </geometry>
      </collision>
    <collision name="thread_ridge_2">
      <origin xyz="0.027 0 0" rpy="0 1.5708 0" />
      <geometry>
        <cylinder radius="0.014" length="0.0035" />
        </geometry>
      </collision>
    <collision name="thread_ridge_3">
      <origin xyz="0.037 0 0" rpy="0 1.5708 0" />
      <geometry>
        <cylinder radius="0.014" length="0.0035" />
        </geometry>
      </collision>
    <collision name="thread_ridge_4">
      <origin xyz="0.047 0 0" rpy="0 1.5708 0" />
      <geometry>
        <cylinder radius="0.014" length="0.0035" />
        </geometry>
      </collision>
    <collision name="knob_back_washer">
      <origin xyz="0.06 0 0" rpy="0 1.5708 0" />
      <geometry>
        <cylinder radius="0.046" length="0.01" />
        </geometry>
      </collision>
    <collision name="knob_center_hub">
      <origin xyz="0.085 0 0" rpy="0 1.5708 0" />
      <geometry>
        <cylinder radius="0.04" length="0.045" />
        </geometry>
      </collision>
    <collision name="knob_lobe_0">
      <origin xyz="0.085 0 0.044" rpy="0 1.5708 0" />
      <geometry>
        <cylinder radius="0.025" length="0.045" />
        </geometry>
      </collision>
    <collision name="knob_lobe_1">
      <origin xyz="0.085 0.038 0.022" rpy="0 1.5708 0" />
      <geometry>
        <cylinder radius="0.025" length="0.045" />
        </geometry>
      </collision>
    <collision name="knob_lobe_2">
      <origin xyz="0.085 0.038 -0.022" rpy="0 1.5708 0" />
      <geometry>
        <cylinder radius="0.025" length="0.045" />
        </geometry>
      </collision>
    <collision name="knob_lobe_3">
      <origin xyz="0.085 0 -0.044" rpy="0 1.5708 0" />
      <geometry>
        <cylinder radius="0.025" length="0.045" />
        </geometry>
      </collision>
    <collision name="knob_lobe_4">
      <origin xyz="0.085 -0.038 -0.022" rpy="0 1.5708 0" />
      <geometry>
        <cylinder radius="0.025" length="0.045" />
        </geometry>
      </collision>
    <collision name="knob_lobe_5">
      <origin xyz="0.085 -0.038 0.022" rpy="0 1.5708 0" />
      <geometry>
        <cylinder radius="0.025" length="0.045" />
        </geometry>
      </collision>
    <collision name="knob_end_cap">
      <origin xyz="0.1105 0 0" rpy="0 1.5708 0" />
      <geometry>
        <cylinder radius="0.03" length="0.006" />
        </geometry>
      </collision>
    </link>
  <joint name="base_to_sleeve" type="fixed">
    <origin xyz="0 0 0.135" rpy="0 0 0" />
    <parent link="floor_base" />
    <child link="column_sleeve" />
    </joint>
  <joint name="sleeve_to_column" type="prismatic">
    <origin xyz="0 0 0.62" rpy="0 0 0" />
    <parent link="column_sleeve" />
    <child link="height_column" />
    <axis xyz="0 0 1" />
    <limit effort="120" velocity="0.18" lower="0" upper="0.26" />
    </joint>
  <joint name="column_to_head" type="fixed">
    <origin xyz="0 0 0.5775" rpy="0 0 0" />
    <parent link="height_column" />
    <child link="support_head" />
    </joint>
  <joint name="head_to_board" type="revolute">
    <origin xyz="0 -0.04 0.24" rpy="0.35 0 0" />
    <parent link="support_head" />
    <child link="board" />
    <axis xyz="1 0 0" />
    <limit effort="60" velocity="0.8" lower="-0.2" upper="1" />
    </joint>
  <joint name="head_to_knob" type="continuous">
    <origin xyz="0.763 -0.04 0.24" rpy="0 0 0" />
    <parent link="support_head" />
    <child link="clamp_knob" />
    <axis xyz="1 0 0" />
    <limit effort="2" velocity="8" />
    </joint>
  </robot>
