<robot name="tower_offset_rotary_unit">
  <link name="frame">
    <visual name="ground_plate">
      <origin xyz="0.05 0 0.03" rpy="0 0 0" />
      <geometry>
        <box size="1 0.52 0.06" />
        </geometry>
      <material name="dark_cast_iron">
        <color rgba="0.08 0.09 0.1 1" />
        </material>
      </visual>
    <visual name="lower_bearing">
      <origin xyz="-0.24 0 0.085" rpy="0 0 0" />
      <geometry>
        <cylinder radius="0.135" length="0.05" />
        </geometry>
      <material name="brushed_bearing_metal">
        <color rgba="0.62 0.64 0.62 1" />
        </material>
      </visual>
    <visual name="lower_thrust_washer">
      <origin xyz="-0.24 0 0.12" rpy="0 0 0" />
      <geometry>
        <cylinder radius="0.075" length="0.02" />
        </geometry>
      <material name="black_rubber">
        <color rgba="0.015 0.015 0.014 1" />
        </material>
      </visual>
    <visual name="tower_column">
      <origin xyz="0.35 0 0.4" rpy="0 0 0" />
      <geometry>
        <box size="0.13 0.17 0.68" />
        </geometry>
      <material name="blue_gray_paint">
        <color rgba="0.22 0.3 0.38 1" />
        </material>
      </visual>
    <visual name="upper_head_block">
      <origin xyz="0.35 0 0.79" rpy="0 0 0" />
      <geometry>
        <box size="0.245 0.235 0.1" />
        </geometry>
      <material name="blue_gray_paint">
        <color rgba="0.22 0.3 0.38 1" />
        </material>
      </visual>
    <visual name="upper_bearing">
      <origin xyz="0.35 0 0.861" rpy="0 0 0" />
      <geometry>
        <cylinder radius="0.088" length="0.042" />
        </geometry>
      <material name="brushed_bearing_metal">
        <color rgba="0.62 0.64 0.62 1" />
        </material>
      </visual>
    <collision name="ground_plate">
      <origin xyz="0.05 0 0.03" rpy="0 0 0" />
      <geometry>
        <box size="1 0.52 0.06" />
        </geometry>
      </collision>
    <collision name="lower_bearing">
      <origin xyz="-0.24 0 0.085" rpy="0 0 0" />
      <geometry>
        <cylinder radius="0.135" length="0.05" />
        </geometry>
      </collision>
    <collision name="lower_thrust_washer">
      <origin xyz="-0.24 0 0.12" rpy="0 0 0" />
      <geometry>
        <cylinder radius="0.075" length="0.02" />
        </geometry>
      </collision>
    <collision name="tower_column">
      <origin xyz="0.35 0 0.4" rpy="0 0 0" />
      <geometry>
        <box size="0.13 0.17 0.68" />
        </geometry>
      </collision>
    <collision name="upper_head_block">
      <origin xyz="0.35 0 0.79" rpy="0 0 0" />
      <geometry>
        <box size="0.245 0.235 0.1" />
        </geometry>
      </collision>
    <collision name="upper_bearing">
      <origin xyz="0.35 0 0.861" rpy="0 0 0" />
      <geometry>
        <cylinder radius="0.088" length="0.042" />
        </geometry>
      </collision>
    </link>
  <link name="lower_stage">
    <visual name="lower_table">
      <origin xyz="0 0 0.026" rpy="0 0 0" />
      <geometry>
        <cylinder radius="0.185" length="0.052" />
        </geometry>
      <material name="lower_stage_orange">
        <color rgba="0.93 0.42 0.12 1" />
        </material>
      </visual>
    <visual name="lower_hub">
      <origin xyz="0 0 0.082" rpy="0 0 0" />
      <geometry>
        <cylinder radius="0.072" length="0.06" />
        </geometry>
      <material name="brushed_bearing_metal">
        <color rgba="0.62 0.64 0.62 1" />
        </material>
      </visual>
    <visual name="lower_index">
      <origin xyz="0.08 0 0.057" rpy="0 0 0" />
      <geometry>
        <box size="0.16 0.03 0.014" />
        </geometry>
      <material name="brass_marker">
        <color rgba="0.9 0.68 0.25 1" />
        </material>
      </visual>
    <collision name="lower_table">
      <origin xyz="0 0 0.026" rpy="0 0 0" />
      <geometry>
        <cylinder radius="0.185" length="0.052" />
        </geometry>
      </collision>
    <collision name="lower_hub">
      <origin xyz="0 0 0.082" rpy="0 0 0" />
      <geometry>
        <cylinder radius="0.072" length="0.06" />
        </geometry>
      </collision>
    <collision name="lower_index">
      <origin xyz="0.08 0 0.057" rpy="0 0 0" />
      <geometry>
        <box size="0.16 0.03 0.014" />
        </geometry>
      </collision>
    </link>
  <link name="upper_stage">
    <visual name="upper_table">
      <origin xyz="0 0 0.02" rpy="0 0 0" />
      <geometry>
        <cylinder radius="0.122" length="0.04" />
        </geometry>
      <material name="upper_stage_green">
        <color rgba="0.12 0.58 0.34 1" />
        </material>
      </visual>
    <visual name="upper_hub">
      <origin xyz="0 0 0.065" rpy="0 0 0" />
      <geometry>
        <cylinder radius="0.052" length="0.05" />
        </geometry>
      <material name="brushed_bearing_metal">
        <color rgba="0.62 0.64 0.62 1" />
        </material>
      </visual>
    <visual name="upper_index">
      <origin xyz="0.052 0 0.046" rpy="0 0 0" />
      <geometry>
        <box size="0.105 0.023 0.012" />
        </geometry>
      <material name="brass_marker">
        <color rgba="0.9 0.68 0.25 1" />
        </material>
      </visual>
    <collision name="upper_table">
      <origin xyz="0 0 0.02" rpy="0 0 0" />
      <geometry>
        <cylinder radius="0.122" length="0.04" />
        </geometry>
      </collision>
    <collision name="upper_hub">
      <origin xyz="0 0 0.065" rpy="0 0 0" />
      <geometry>
        <cylinder radius="0.052" length="0.05" />
        </geometry>
      </collision>
    <collision name="upper_index">
      <origin xyz="0.052 0 0.046" rpy="0 0 0" />
      <geometry>
        <box size="0.105 0.023 0.012" />
        </geometry>
      </collision>
    </link>
  <joint name="lower_axis" type="revolute">
    <origin xyz="-0.24 0 0.13" rpy="0 0 0" />
    <parent link="frame" />
    <child link="lower_stage" />
    <axis xyz="0 0 1" />
    <limit effort="12" velocity="3" lower="-3.14159" upper="3.14159" />
    </joint>
  <joint name="upper_axis" type="revolute">
    <origin xyz="0.35 0 0.882" rpy="0 0 0" />
    <parent link="frame" />
    <child link="upper_stage" />
    <axis xyz="0 0 1" />
    <limit effort="5" velocity="4" lower="-3.14159" upper="3.14159" />
    </joint>
  </robot>
