<robot name="freestanding_gas_range">
  <material name="brushed_stainless">
    <color rgba="0.72 0.72 0.68 1" />
    </material>
  <material name="black_enamel">
    <color rgba="0.02 0.02 0.018 1" />
    </material>
  <material name="matte_cast_iron">
    <color rgba="0.005 0.005 0.005 1" />
    </material>
  <material name="smoked_glass">
    <color rgba="0.02 0.03 0.04 0.45" />
    </material>
  <material name="brass_burner">
    <color rgba="0.75 0.52 0.22 1" />
    </material>
  <material name="oven_shadow">
    <color rgba="0 0 0 1" />
    </material>
  <link name="range_body">
    <visual name="cabinet_shell">
      <origin xyz="0 0 0.46" rpy="0 0 0" />
      <geometry>
        <box size="0.76 0.6 0.76" />
        </geometry>
      <material name="brushed_stainless">
        <color rgba="0.72 0.72 0.68 1" />
        </material>
      </visual>
    <visual name="toe_recess">
      <origin xyz="0 -0.317 0.095" rpy="0 0 0" />
      <geometry>
        <box size="0.68 0.035 0.075" />
        </geometry>
      <material name="oven_shadow">
        <color rgba="0 0 0 1" />
        </material>
      </visual>
    <visual name="oven_reveal">
      <origin xyz="0 -0.306 0.455" rpy="0 0 0" />
      <geometry>
        <box size="0.66 0.018 0.53" />
        </geometry>
      <material name="oven_shadow">
        <color rgba="0 0 0 1" />
        </material>
      </visual>
    <visual name="hinge_leaf">
      <origin xyz="0 -0.319 0.157" rpy="0 0 0" />
      <geometry>
        <box size="0.72 0.04 0.028" />
        </geometry>
      <material name="matte_cast_iron">
        <color rgba="0.005 0.005 0.005 1" />
        </material>
      </visual>
    <visual name="cooktop">
      <origin xyz="0 0 0.865" rpy="0 0 0" />
      <geometry>
        <box size="0.79 0.66 0.05" />
        </geometry>
      <material name="black_enamel">
        <color rgba="0.02 0.02 0.018 1" />
        </material>
      </visual>
    <visual name="rear_cooktop_lip">
      <origin xyz="0 0.315 0.9" rpy="0 0 0" />
      <geometry>
        <box size="0.79 0.03 0.06" />
        </geometry>
      <material name="black_enamel">
        <color rgba="0.02 0.02 0.018 1" />
        </material>
      </visual>
    <visual name="backguard_panel">
      <origin xyz="0 0.33 1.005" rpy="0 0 0" />
      <geometry>
        <box size="0.79 0.065 0.235" />
        </geometry>
      <material name="brushed_stainless">
        <color rgba="0.72 0.72 0.68 1" />
        </material>
      </visual>
    <visual name="control_face_band">
      <origin xyz="0 0.294 0.915" rpy="0 0 0" />
      <geometry>
        <box size="0.79 0.012 0.055" />
        </geometry>
      <material name="black_enamel">
        <color rgba="0.02 0.02 0.018 1" />
        </material>
      </visual>
    <visual name="burner_head_0">
      <origin xyz="-0.19 -0.13 0.896" rpy="0 0 0" />
      <geometry>
        <cylinder radius="0.052" length="0.016" />
        </geometry>
      <material name="matte_cast_iron">
        <color rgba="0.005 0.005 0.005 1" />
        </material>
      </visual>
    <visual name="burner_cap_0">
      <origin xyz="-0.19 -0.13 0.911" rpy="0 0 0" />
      <geometry>
        <cylinder radius="0.034" length="0.016" />
        </geometry>
      <material name="brass_burner">
        <color rgba="0.75 0.52 0.22 1" />
        </material>
      </visual>
    <visual name="burner_head_1">
      <origin xyz="0.19 -0.13 0.896" rpy="0 0 0" />
      <geometry>
        <cylinder radius="0.052" length="0.016" />
        </geometry>
      <material name="matte_cast_iron">
        <color rgba="0.005 0.005 0.005 1" />
        </material>
      </visual>
    <visual name="burner_cap_1">
      <origin xyz="0.19 -0.13 0.911" rpy="0 0 0" />
      <geometry>
        <cylinder radius="0.034" length="0.016" />
        </geometry>
      <material name="brass_burner">
        <color rgba="0.75 0.52 0.22 1" />
        </material>
      </visual>
    <visual name="burner_head_2">
      <origin xyz="-0.19 0.115 0.896" rpy="0 0 0" />
      <geometry>
        <cylinder radius="0.052" length="0.016" />
        </geometry>
      <material name="matte_cast_iron">
        <color rgba="0.005 0.005 0.005 1" />
        </material>
      </visual>
    <visual name="burner_cap_2">
      <origin xyz="-0.19 0.115 0.911" rpy="0 0 0" />
      <geometry>
        <cylinder radius="0.034" length="0.016" />
        </geometry>
      <material name="brass_burner">
        <color rgba="0.75 0.52 0.22 1" />
        </material>
      </visual>
    <visual name="burner_head_3">
      <origin xyz="0.19 0.115 0.896" rpy="0 0 0" />
      <geometry>
        <cylinder radius="0.052" length="0.016" />
        </geometry>
      <material name="matte_cast_iron">
        <color rgba="0.005 0.005 0.005 1" />
        </material>
      </visual>
    <visual name="burner_cap_3">
      <origin xyz="0.19 0.115 0.911" rpy="0 0 0" />
      <geometry>
        <cylinder radius="0.034" length="0.016" />
        </geometry>
      <material name="brass_burner">
        <color rgba="0.75 0.52 0.22 1" />
        </material>
      </visual>
    <collision name="cabinet_shell">
      <origin xyz="0 0 0.46" rpy="0 0 0" />
      <geometry>
        <box size="0.76 0.6 0.76" />
        </geometry>
      </collision>
    <collision name="toe_recess">
      <origin xyz="0 -0.317 0.095" rpy="0 0 0" />
      <geometry>
        <box size="0.68 0.035 0.075" />
        </geometry>
      </collision>
    <collision name="oven_reveal">
      <origin xyz="0 -0.306 0.455" rpy="0 0 0" />
      <geometry>
        <box size="0.66 0.018 0.53" />
        </geometry>
      </collision>
    <collision name="hinge_leaf">
      <origin xyz="0 -0.319 0.157" rpy="0 0 0" />
      <geometry>
        <box size="0.72 0.04 0.028" />
        </geometry>
      </collision>
    <collision name="cooktop">
      <origin xyz="0 0 0.865" rpy="0 0 0" />
      <geometry>
        <box size="0.79 0.66 0.05" />
        </geometry>
      </collision>
    <collision name="rear_cooktop_lip">
      <origin xyz="0 0.315 0.9" rpy="0 0 0" />
      <geometry>
        <box size="0.79 0.03 0.06" />
        </geometry>
      </collision>
    <collision name="backguard_panel">
      <origin xyz="0 0.33 1.005" rpy="0 0 0" />
      <geometry>
        <box size="0.79 0.065 0.235" />
        </geometry>
      </collision>
    <collision name="control_face_band">
      <origin xyz="0 0.294 0.915" rpy="0 0 0" />
      <geometry>
        <box size="0.79 0.012 0.055" />
        </geometry>
      </collision>
    <collision name="burner_head_0">
      <origin xyz="-0.19 -0.13 0.896" rpy="0 0 0" />
      <geometry>
        <cylinder radius="0.052" length="0.016" />
        </geometry>
      </collision>
    <collision name="burner_cap_0">
      <origin xyz="-0.19 -0.13 0.911" rpy="0 0 0" />
      <geometry>
        <cylinder radius="0.034" length="0.016" />
        </geometry>
      </collision>
    <collision name="burner_head_1">
      <origin xyz="0.19 -0.13 0.896" rpy="0 0 0" />
      <geometry>
        <cylinder radius="0.052" length="0.016" />
        </geometry>
      </collision>
    <collision name="burner_cap_1">
      <origin xyz="0.19 -0.13 0.911" rpy="0 0 0" />
      <geometry>
        <cylinder radius="0.034" length="0.016" />
        </geometry>
      </collision>
    <collision name="burner_head_2">
      <origin xyz="-0.19 0.115 0.896" rpy="0 0 0" />
      <geometry>
        <cylinder radius="0.052" length="0.016" />
        </geometry>
      </collision>
    <collision name="burner_cap_2">
      <origin xyz="-0.19 0.115 0.911" rpy="0 0 0" />
      <geometry>
        <cylinder radius="0.034" length="0.016" />
        </geometry>
      </collision>
    <collision name="burner_head_3">
      <origin xyz="0.19 0.115 0.896" rpy="0 0 0" />
      <geometry>
        <cylinder radius="0.052" length="0.016" />
        </geometry>
      </collision>
    <collision name="burner_cap_3">
      <origin xyz="0.19 0.115 0.911" rpy="0 0 0" />
      <geometry>
        <cylinder radius="0.034" length="0.016" />
        </geometry>
      </collision>
    </link>
  <link name="grate_0">
    <visual name="rear_rail">
      <origin xyz="0 0.1015 0.012" rpy="0 0 0" />
      <geometry>
        <box size="0.255 0.022 0.024" />
        </geometry>
      <material name="matte_cast_iron">
        <color rgba="0.005 0.005 0.005 1" />
        </material>
      </visual>
    <visual name="front_rail">
      <origin xyz="0 -0.1015 0.012" rpy="0 0 0" />
      <geometry>
        <box size="0.255 0.022 0.024" />
        </geometry>
      <material name="matte_cast_iron">
        <color rgba="0.005 0.005 0.005 1" />
        </material>
      </visual>
    <visual name="side_rail_0">
      <origin xyz="0.1165 0 0.012" rpy="0 0 0" />
      <geometry>
        <box size="0.022 0.225 0.024" />
        </geometry>
      <material name="matte_cast_iron">
        <color rgba="0.005 0.005 0.005 1" />
        </material>
      </visual>
    <visual name="side_rail_1">
      <origin xyz="-0.1165 0 0.012" rpy="0 0 0" />
      <geometry>
        <box size="0.022 0.225 0.024" />
        </geometry>
      <material name="matte_cast_iron">
        <color rgba="0.005 0.005 0.005 1" />
        </material>
      </visual>
    <visual name="rear_finger">
      <origin xyz="0 0.0775 0.014" rpy="0 0 0" />
      <geometry>
        <box size="0.018 0.026 0.02" />
        </geometry>
      <material name="matte_cast_iron">
        <color rgba="0.005 0.005 0.005 1" />
        </material>
      </visual>
    <visual name="front_finger">
      <origin xyz="0 -0.0775 0.014" rpy="0 0 0" />
      <geometry>
        <box size="0.018 0.026 0.02" />
        </geometry>
      <material name="matte_cast_iron">
        <color rgba="0.005 0.005 0.005 1" />
        </material>
      </visual>
    <visual name="side_finger_0">
      <origin xyz="0.086 0 0.014" rpy="0 0 0" />
      <geometry>
        <box size="0.039 0.018 0.02" />
        </geometry>
      <material name="matte_cast_iron">
        <color rgba="0.005 0.005 0.005 1" />
        </material>
      </visual>
    <visual name="side_finger_1">
      <origin xyz="-0.086 0 0.014" rpy="0 0 0" />
      <geometry>
        <box size="0.039 0.018 0.02" />
        </geometry>
      <material name="matte_cast_iron">
        <color rgba="0.005 0.005 0.005 1" />
        </material>
      </visual>
    <collision name="rear_rail">
      <origin xyz="0 0.1015 0.012" rpy="0 0 0" />
      <geometry>
        <box size="0.255 0.022 0.024" />
        </geometry>
      </collision>
    <collision name="front_rail">
      <origin xyz="0 -0.1015 0.012" rpy="0 0 0" />
      <geometry>
        <box size="0.255 0.022 0.024" />
        </geometry>
      </collision>
    <collision name="side_rail_0">
      <origin xyz="0.1165 0 0.012" rpy="0 0 0" />
      <geometry>
        <box size="0.022 0.225 0.024" />
        </geometry>
      </collision>
    <collision name="side_rail_1">
      <origin xyz="-0.1165 0 0.012" rpy="0 0 0" />
      <geometry>
        <box size="0.022 0.225 0.024" />
        </geometry>
      </collision>
    <collision name="rear_finger">
      <origin xyz="0 0.0775 0.014" rpy="0 0 0" />
      <geometry>
        <box size="0.018 0.026 0.02" />
        </geometry>
      </collision>
    <collision name="front_finger">
      <origin xyz="0 -0.0775 0.014" rpy="0 0 0" />
      <geometry>
        <box size="0.018 0.026 0.02" />
        </geometry>
      </collision>
    <collision name="side_finger_0">
      <origin xyz="0.086 0 0.014" rpy="0 0 0" />
      <geometry>
        <box size="0.039 0.018 0.02" />
        </geometry>
      </collision>
    <collision name="side_finger_1">
      <origin xyz="-0.086 0 0.014" rpy="0 0 0" />
      <geometry>
        <box size="0.039 0.018 0.02" />
        </geometry>
      </collision>
    </link>
  <link name="grate_1">
    <visual name="rear_rail">
      <origin xyz="0 0.1015 0.012" rpy="0 0 0" />
      <geometry>
        <box size="0.255 0.022 0.024" />
        </geometry>
      <material name="matte_cast_iron">
        <color rgba="0.005 0.005 0.005 1" />
        </material>
      </visual>
    <visual name="front_rail">
      <origin xyz="0 -0.1015 0.012" rpy="0 0 0" />
      <geometry>
        <box size="0.255 0.022 0.024" />
        </geometry>
      <material name="matte_cast_iron">
        <color rgba="0.005 0.005 0.005 1" />
        </material>
      </visual>
    <visual name="side_rail_0">
      <origin xyz="0.1165 0 0.012" rpy="0 0 0" />
      <geometry>
        <box size="0.022 0.225 0.024" />
        </geometry>
      <material name="matte_cast_iron">
        <color rgba="0.005 0.005 0.005 1" />
        </material>
      </visual>
    <visual name="side_rail_1">
      <origin xyz="-0.1165 0 0.012" rpy="0 0 0" />
      <geometry>
        <box size="0.022 0.225 0.024" />
        </geometry>
      <material name="matte_cast_iron">
        <color rgba="0.005 0.005 0.005 1" />
        </material>
      </visual>
    <visual name="rear_finger">
      <origin xyz="0 0.0775 0.014" rpy="0 0 0" />
      <geometry>
        <box size="0.018 0.026 0.02" />
        </geometry>
      <material name="matte_cast_iron">
        <color rgba="0.005 0.005 0.005 1" />
        </material>
      </visual>
    <visual name="front_finger">
      <origin xyz="0 -0.0775 0.014" rpy="0 0 0" />
      <geometry>
        <box size="0.018 0.026 0.02" />
        </geometry>
      <material name="matte_cast_iron">
        <color rgba="0.005 0.005 0.005 1" />
        </material>
      </visual>
    <visual name="side_finger_0">
      <origin xyz="0.086 0 0.014" rpy="0 0 0" />
      <geometry>
        <box size="0.039 0.018 0.02" />
        </geometry>
      <material name="matte_cast_iron">
        <color rgba="0.005 0.005 0.005 1" />
        </material>
      </visual>
    <visual name="side_finger_1">
      <origin xyz="-0.086 0 0.014" rpy="0 0 0" />
      <geometry>
        <box size="0.039 0.018 0.02" />
        </geometry>
      <material name="matte_cast_iron">
        <color rgba="0.005 0.005 0.005 1" />
        </material>
      </visual>
    <collision name="rear_rail">
      <origin xyz="0 0.1015 0.012" rpy="0 0 0" />
      <geometry>
        <box size="0.255 0.022 0.024" />
        </geometry>
      </collision>
    <collision name="front_rail">
      <origin xyz="0 -0.1015 0.012" rpy="0 0 0" />
      <geometry>
        <box size="0.255 0.022 0.024" />
        </geometry>
      </collision>
    <collision name="side_rail_0">
      <origin xyz="0.1165 0 0.012" rpy="0 0 0" />
      <geometry>
        <box size="0.022 0.225 0.024" />
        </geometry>
      </collision>
    <collision name="side_rail_1">
      <origin xyz="-0.1165 0 0.012" rpy="0 0 0" />
      <geometry>
        <box size="0.022 0.225 0.024" />
        </geometry>
      </collision>
    <collision name="rear_finger">
      <origin xyz="0 0.0775 0.014" rpy="0 0 0" />
      <geometry>
        <box size="0.018 0.026 0.02" />
        </geometry>
      </collision>
    <collision name="front_finger">
      <origin xyz="0 -0.0775 0.014" rpy="0 0 0" />
      <geometry>
        <box size="0.018 0.026 0.02" />
        </geometry>
      </collision>
    <collision name="side_finger_0">
      <origin xyz="0.086 0 0.014" rpy="0 0 0" />
      <geometry>
        <box size="0.039 0.018 0.02" />
        </geometry>
      </collision>
    <collision name="side_finger_1">
      <origin xyz="-0.086 0 0.014" rpy="0 0 0" />
      <geometry>
        <box size="0.039 0.018 0.02" />
        </geometry>
      </collision>
    </link>
  <link name="grate_2">
    <visual name="rear_rail">
      <origin xyz="0 0.1015 0.012" rpy="0 0 0" />
      <geometry>
        <box size="0.255 0.022 0.024" />
        </geometry>
      <material name="matte_cast_iron">
        <color rgba="0.005 0.005 0.005 1" />
        </material>
      </visual>
    <visual name="front_rail">
      <origin xyz="0 -0.1015 0.012" rpy="0 0 0" />
      <geometry>
        <box size="0.255 0.022 0.024" />
        </geometry>
      <material name="matte_cast_iron">
        <color rgba="0.005 0.005 0.005 1" />
        </material>
      </visual>
    <visual name="side_rail_0">
      <origin xyz="0.1165 0 0.012" rpy="0 0 0" />
      <geometry>
        <box size="0.022 0.225 0.024" />
        </geometry>
      <material name="matte_cast_iron">
        <color rgba="0.005 0.005 0.005 1" />
        </material>
      </visual>
    <visual name="side_rail_1">
      <origin xyz="-0.1165 0 0.012" rpy="0 0 0" />
      <geometry>
        <box size="0.022 0.225 0.024" />
        </geometry>
      <material name="matte_cast_iron">
        <color rgba="0.005 0.005 0.005 1" />
        </material>
      </visual>
    <visual name="rear_finger">
      <origin xyz="0 0.0775 0.014" rpy="0 0 0" />
      <geometry>
        <box size="0.018 0.026 0.02" />
        </geometry>
      <material name="matte_cast_iron">
        <color rgba="0.005 0.005 0.005 1" />
        </material>
      </visual>
    <visual name="front_finger">
      <origin xyz="0 -0.0775 0.014" rpy="0 0 0" />
      <geometry>
        <box size="0.018 0.026 0.02" />
        </geometry>
      <material name="matte_cast_iron">
        <color rgba="0.005 0.005 0.005 1" />
        </material>
      </visual>
    <visual name="side_finger_0">
      <origin xyz="0.086 0 0.014" rpy="0 0 0" />
      <geometry>
        <box size="0.039 0.018 0.02" />
        </geometry>
      <material name="matte_cast_iron">
        <color rgba="0.005 0.005 0.005 1" />
        </material>
      </visual>
    <visual name="side_finger_1">
      <origin xyz="-0.086 0 0.014" rpy="0 0 0" />
      <geometry>
        <box size="0.039 0.018 0.02" />
        </geometry>
      <material name="matte_cast_iron">
        <color rgba="0.005 0.005 0.005 1" />
        </material>
      </visual>
    <collision name="rear_rail">
      <origin xyz="0 0.1015 0.012" rpy="0 0 0" />
      <geometry>
        <box size="0.255 0.022 0.024" />
        </geometry>
      </collision>
    <collision name="front_rail">
      <origin xyz="0 -0.1015 0.012" rpy="0 0 0" />
      <geometry>
        <box size="0.255 0.022 0.024" />
        </geometry>
      </collision>
    <collision name="side_rail_0">
      <origin xyz="0.1165 0 0.012" rpy="0 0 0" />
      <geometry>
        <box size="0.022 0.225 0.024" />
        </geometry>
      </collision>
    <collision name="side_rail_1">
      <origin xyz="-0.1165 0 0.012" rpy="0 0 0" />
      <geometry>
        <box size="0.022 0.225 0.024" />
        </geometry>
      </collision>
    <collision name="rear_finger">
      <origin xyz="0 0.0775 0.014" rpy="0 0 0" />
      <geometry>
        <box size="0.018 0.026 0.02" />
        </geometry>
      </collision>
    <collision name="front_finger">
      <origin xyz="0 -0.0775 0.014" rpy="0 0 0" />
      <geometry>
        <box size="0.018 0.026 0.02" />
        </geometry>
      </collision>
    <collision name="side_finger_0">
      <origin xyz="0.086 0 0.014" rpy="0 0 0" />
      <geometry>
        <box size="0.039 0.018 0.02" />
        </geometry>
      </collision>
    <collision name="side_finger_1">
      <origin xyz="-0.086 0 0.014" rpy="0 0 0" />
      <geometry>
        <box size="0.039 0.018 0.02" />
        </geometry>
      </collision>
    </link>
  <link name="grate_3">
    <visual name="rear_rail">
      <origin xyz="0 0.1015 0.012" rpy="0 0 0" />
      <geometry>
        <box size="0.255 0.022 0.024" />
        </geometry>
      <material name="matte_cast_iron">
        <color rgba="0.005 0.005 0.005 1" />
        </material>
      </visual>
    <visual name="front_rail">
      <origin xyz="0 -0.1015 0.012" rpy="0 0 0" />
      <geometry>
        <box size="0.255 0.022 0.024" />
        </geometry>
      <material name="matte_cast_iron">
        <color rgba="0.005 0.005 0.005 1" />
        </material>
      </visual>
    <visual name="side_rail_0">
      <origin xyz="0.1165 0 0.012" rpy="0 0 0" />
      <geometry>
        <box size="0.022 0.225 0.024" />
        </geometry>
      <material name="matte_cast_iron">
        <color rgba="0.005 0.005 0.005 1" />
        </material>
      </visual>
    <visual name="side_rail_1">
      <origin xyz="-0.1165 0 0.012" rpy="0 0 0" />
      <geometry>
        <box size="0.022 0.225 0.024" />
        </geometry>
      <material name="matte_cast_iron">
        <color rgba="0.005 0.005 0.005 1" />
        </material>
      </visual>
    <visual name="rear_finger">
      <origin xyz="0 0.0775 0.014" rpy="0 0 0" />
      <geometry>
        <box size="0.018 0.026 0.02" />
        </geometry>
      <material name="matte_cast_iron">
        <color rgba="0.005 0.005 0.005 1" />
        </material>
      </visual>
    <visual name="front_finger">
      <origin xyz="0 -0.0775 0.014" rpy="0 0 0" />
      <geometry>
        <box size="0.018 0.026 0.02" />
        </geometry>
      <material name="matte_cast_iron">
        <color rgba="0.005 0.005 0.005 1" />
        </material>
      </visual>
    <visual name="side_finger_0">
      <origin xyz="0.086 0 0.014" rpy="0 0 0" />
      <geometry>
        <box size="0.039 0.018 0.02" />
        </geometry>
      <material name="matte_cast_iron">
        <color rgba="0.005 0.005 0.005 1" />
        </material>
      </visual>
    <visual name="side_finger_1">
      <origin xyz="-0.086 0 0.014" rpy="0 0 0" />
      <geometry>
        <box size="0.039 0.018 0.02" />
        </geometry>
      <material name="matte_cast_iron">
        <color rgba="0.005 0.005 0.005 1" />
        </material>
      </visual>
    <collision name="rear_rail">
      <origin xyz="0 0.1015 0.012" rpy="0 0 0" />
      <geometry>
        <box size="0.255 0.022 0.024" />
        </geometry>
      </collision>
    <collision name="front_rail">
      <origin xyz="0 -0.1015 0.012" rpy="0 0 0" />
      <geometry>
        <box size="0.255 0.022 0.024" />
        </geometry>
      </collision>
    <collision name="side_rail_0">
      <origin xyz="0.1165 0 0.012" rpy="0 0 0" />
      <geometry>
        <box size="0.022 0.225 0.024" />
        </geometry>
      </collision>
    <collision name="side_rail_1">
      <origin xyz="-0.1165 0 0.012" rpy="0 0 0" />
      <geometry>
        <box size="0.022 0.225 0.024" />
        </geometry>
      </collision>
    <collision name="rear_finger">
      <origin xyz="0 0.0775 0.014" rpy="0 0 0" />
      <geometry>
        <box size="0.018 0.026 0.02" />
        </geometry>
      </collision>
    <collision name="front_finger">
      <origin xyz="0 -0.0775 0.014" rpy="0 0 0" />
      <geometry>
        <box size="0.018 0.026 0.02" />
        </geometry>
      </collision>
    <collision name="side_finger_0">
      <origin xyz="0.086 0 0.014" rpy="0 0 0" />
      <geometry>
        <box size="0.039 0.018 0.02" />
        </geometry>
      </collision>
    <collision name="side_finger_1">
      <origin xyz="-0.086 0 0.014" rpy="0 0 0" />
      <geometry>
        <box size="0.039 0.018 0.02" />
        </geometry>
      </collision>
    </link>
  <link name="oven_door">
    <visual name="lower_panel">
      <origin xyz="0 -0.02 0.0825" rpy="0 0 0" />
      <geometry>
        <box size="0.67 0.04 0.165" />
        </geometry>
      <material name="brushed_stainless">
        <color rgba="0.72 0.72 0.68 1" />
        </material>
      </visual>
    <visual name="top_panel">
      <origin xyz="0 -0.02 0.485" rpy="0 0 0" />
      <geometry>
        <box size="0.67 0.04 0.08" />
        </geometry>
      <material name="brushed_stainless">
        <color rgba="0.72 0.72 0.68 1" />
        </material>
      </visual>
    <visual name="side_frame_0">
      <origin xyz="-0.3025 -0.02 0.26" rpy="0 0 0" />
      <geometry>
        <box size="0.065 0.04 0.52" />
        </geometry>
      <material name="brushed_stainless">
        <color rgba="0.72 0.72 0.68 1" />
        </material>
      </visual>
    <visual name="side_frame_1">
      <origin xyz="0.3025 -0.02 0.26" rpy="0 0 0" />
      <geometry>
        <box size="0.065 0.04 0.52" />
        </geometry>
      <material name="brushed_stainless">
        <color rgba="0.72 0.72 0.68 1" />
        </material>
      </visual>
    <visual name="window_panel">
      <origin xyz="0 -0.046 0.31" rpy="0 0 0" />
      <geometry>
        <box size="0.54 0.012 0.3" />
        </geometry>
      <material name="smoked_glass">
        <color rgba="0.02 0.03 0.04 0.45" />
        </material>
      </visual>
    <visual name="window_shadow_gasket">
      <origin xyz="0 -0.039 0.31" rpy="0 0 0" />
      <geometry>
        <box size="0.5 0.006 0.26" />
        </geometry>
      <material name="oven_shadow">
        <color rgba="0 0 0 1" />
        </material>
      </visual>
    <visual name="full_width_hinge_barrel">
      <origin xyz="0 -0.03 0" rpy="0 1.5708 0" />
      <geometry>
        <cylinder radius="0.017" length="0.7" />
        </geometry>
      <material name="matte_cast_iron">
        <color rgba="0.005 0.005 0.005 1" />
        </material>
      </visual>
    <visual name="handle_standoff_0">
      <origin xyz="-0.25 -0.057 0.468" rpy="0 0 0" />
      <geometry>
        <box size="0.036 0.045 0.036" />
        </geometry>
      <material name="brushed_stainless">
        <color rgba="0.72 0.72 0.68 1" />
        </material>
      </visual>
    <visual name="handle_standoff_1">
      <origin xyz="0.25 -0.057 0.468" rpy="0 0 0" />
      <geometry>
        <box size="0.036 0.045 0.036" />
        </geometry>
      <material name="brushed_stainless">
        <color rgba="0.72 0.72 0.68 1" />
        </material>
      </visual>
    <visual name="handle_bar">
      <origin xyz="0 -0.087 0.468" rpy="0 1.5708 0" />
      <geometry>
        <cylinder radius="0.018" length="0.61" />
        </geometry>
      <material name="brushed_stainless">
        <color rgba="0.72 0.72 0.68 1" />
        </material>
      </visual>
    <collision name="lower_panel">
      <origin xyz="0 -0.02 0.0825" rpy="0 0 0" />
      <geometry>
        <box size="0.67 0.04 0.165" />
        </geometry>
      </collision>
    <collision name="top_panel">
      <origin xyz="0 -0.02 0.485" rpy="0 0 0" />
      <geometry>
        <box size="0.67 0.04 0.08" />
        </geometry>
      </collision>
    <collision name="side_frame_0">
      <origin xyz="-0.3025 -0.02 0.26" rpy="0 0 0" />
      <geometry>
        <box size="0.065 0.04 0.52" />
        </geometry>
      </collision>
    <collision name="side_frame_1">
      <origin xyz="0.3025 -0.02 0.26" rpy="0 0 0" />
      <geometry>
        <box size="0.065 0.04 0.52" />
        </geometry>
      </collision>
    <collision name="window_panel">
      <origin xyz="0 -0.046 0.31" rpy="0 0 0" />
      <geometry>
        <box size="0.54 0.012 0.3" />
        </geometry>
      </collision>
    <collision name="window_shadow_gasket">
      <origin xyz="0 -0.039 0.31" rpy="0 0 0" />
      <geometry>
        <box size="0.5 0.006 0.26" />
        </geometry>
      </collision>
    <collision name="full_width_hinge_barrel">
      <origin xyz="0 -0.03 0" rpy="0 1.5708 0" />
      <geometry>
        <cylinder radius="0.017" length="0.7" />
        </geometry>
      </collision>
    <collision name="handle_standoff_0">
      <origin xyz="-0.25 -0.057 0.468" rpy="0 0 0" />
      <geometry>
        <box size="0.036 0.045 0.036" />
        </geometry>
      </collision>
    <collision name="handle_standoff_1">
      <origin xyz="0.25 -0.057 0.468" rpy="0 0 0" />
      <geometry>
        <box size="0.036 0.045 0.036" />
        </geometry>
      </collision>
    <collision name="handle_bar">
      <origin xyz="0 -0.087 0.468" rpy="0 1.5708 0" />
      <geometry>
        <cylinder radius="0.018" length="0.61" />
        </geometry>
      </collision>
    </link>
  <link name="knob_0">
    <visual name="knob_cap">
      <origin xyz="0 0 0.015" rpy="0 0 0" />
      <geometry>
        <cylinder radius="0.024" length="0.03" />
        </geometry>
      <material name="black_enamel">
        <color rgba="0.02 0.02 0.018 1" />
        </material>
      </visual>
    <visual name="pointer_mark">
      <origin xyz="0 -0.02 0.032" rpy="0 0 0" />
      <geometry>
        <box size="0.006 0.036 0.004" />
        </geometry>
      <material name="brushed_stainless">
        <color rgba="0.72 0.72 0.68 1" />
        </material>
      </visual>
    <collision name="knob_cap">
      <origin xyz="0 0 0.015" rpy="0 0 0" />
      <geometry>
        <cylinder radius="0.024" length="0.03" />
        </geometry>
      </collision>
    <collision name="pointer_mark">
      <origin xyz="0 -0.02 0.032" rpy="0 0 0" />
      <geometry>
        <box size="0.006 0.036 0.004" />
        </geometry>
      </collision>
    </link>
  <link name="knob_1">
    <visual name="knob_cap">
      <origin xyz="0 0 0.015" rpy="0 0 0" />
      <geometry>
        <cylinder radius="0.024" length="0.03" />
        </geometry>
      <material name="black_enamel">
        <color rgba="0.02 0.02 0.018 1" />
        </material>
      </visual>
    <visual name="pointer_mark">
      <origin xyz="0 -0.02 0.032" rpy="0 0 0" />
      <geometry>
        <box size="0.006 0.036 0.004" />
        </geometry>
      <material name="brushed_stainless">
        <color rgba="0.72 0.72 0.68 1" />
        </material>
      </visual>
    <collision name="knob_cap">
      <origin xyz="0 0 0.015" rpy="0 0 0" />
      <geometry>
        <cylinder radius="0.024" length="0.03" />
        </geometry>
      </collision>
    <collision name="pointer_mark">
      <origin xyz="0 -0.02 0.032" rpy="0 0 0" />
      <geometry>
        <box size="0.006 0.036 0.004" />
        </geometry>
      </collision>
    </link>
  <link name="knob_2">
    <visual name="knob_cap">
      <origin xyz="0 0 0.015" rpy="0 0 0" />
      <geometry>
        <cylinder radius="0.024" length="0.03" />
        </geometry>
      <material name="black_enamel">
        <color rgba="0.02 0.02 0.018 1" />
        </material>
      </visual>
    <visual name="pointer_mark">
      <origin xyz="0 -0.02 0.032" rpy="0 0 0" />
      <geometry>
        <box size="0.006 0.036 0.004" />
        </geometry>
      <material name="brushed_stainless">
        <color rgba="0.72 0.72 0.68 1" />
        </material>
      </visual>
    <collision name="knob_cap">
      <origin xyz="0 0 0.015" rpy="0 0 0" />
      <geometry>
        <cylinder radius="0.024" length="0.03" />
        </geometry>
      </collision>
    <collision name="pointer_mark">
      <origin xyz="0 -0.02 0.032" rpy="0 0 0" />
      <geometry>
        <box size="0.006 0.036 0.004" />
        </geometry>
      </collision>
    </link>
  <link name="knob_3">
    <visual name="knob_cap">
      <origin xyz="0 0 0.015" rpy="0 0 0" />
      <geometry>
        <cylinder radius="0.024" length="0.03" />
        </geometry>
      <material name="black_enamel">
        <color rgba="0.02 0.02 0.018 1" />
        </material>
      </visual>
    <visual name="pointer_mark">
      <origin xyz="0 -0.02 0.032" rpy="0 0 0" />
      <geometry>
        <box size="0.006 0.036 0.004" />
        </geometry>
      <material name="brushed_stainless">
        <color rgba="0.72 0.72 0.68 1" />
        </material>
      </visual>
    <collision name="knob_cap">
      <origin xyz="0 0 0.015" rpy="0 0 0" />
      <geometry>
        <cylinder radius="0.024" length="0.03" />
        </geometry>
      </collision>
    <collision name="pointer_mark">
      <origin xyz="0 -0.02 0.032" rpy="0 0 0" />
      <geometry>
        <box size="0.006 0.036 0.004" />
        </geometry>
      </collision>
    </link>
  <link name="knob_4">
    <visual name="knob_cap">
      <origin xyz="0 0 0.015" rpy="0 0 0" />
      <geometry>
        <cylinder radius="0.024" length="0.03" />
        </geometry>
      <material name="black_enamel">
        <color rgba="0.02 0.02 0.018 1" />
        </material>
      </visual>
    <visual name="pointer_mark">
      <origin xyz="0 -0.02 0.032" rpy="0 0 0" />
      <geometry>
        <box size="0.006 0.036 0.004" />
        </geometry>
      <material name="brushed_stainless">
        <color rgba="0.72 0.72 0.68 1" />
        </material>
      </visual>
    <collision name="knob_cap">
      <origin xyz="0 0 0.015" rpy="0 0 0" />
      <geometry>
        <cylinder radius="0.024" length="0.03" />
        </geometry>
      </collision>
    <collision name="pointer_mark">
      <origin xyz="0 -0.02 0.032" rpy="0 0 0" />
      <geometry>
        <box size="0.006 0.036 0.004" />
        </geometry>
      </collision>
    </link>
  <joint name="body_to_grate_0" type="fixed">
    <origin xyz="-0.19 -0.13 0.89" rpy="0 0 0" />
    <parent link="range_body" />
    <child link="grate_0" />
    </joint>
  <joint name="body_to_grate_1" type="fixed">
    <origin xyz="0.19 -0.13 0.89" rpy="0 0 0" />
    <parent link="range_body" />
    <child link="grate_1" />
    </joint>
  <joint name="body_to_grate_2" type="fixed">
    <origin xyz="-0.19 0.115 0.89" rpy="0 0 0" />
    <parent link="range_body" />
    <child link="grate_2" />
    </joint>
  <joint name="body_to_grate_3" type="fixed">
    <origin xyz="0.19 0.115 0.89" rpy="0 0 0" />
    <parent link="range_body" />
    <child link="grate_3" />
    </joint>
  <joint name="body_to_oven_door" type="revolute">
    <origin xyz="0 -0.325 0.175" rpy="0 0 0" />
    <parent link="range_body" />
    <child link="oven_door" />
    <axis xyz="1 0 0" />
    <limit effort="80" velocity="1.5" lower="0" upper="1.45" />
    </joint>
  <joint name="panel_to_knob_0" type="revolute">
    <origin xyz="-0.28 0.2975 0.98" rpy="1.5708 0 0" />
    <parent link="range_body" />
    <child link="knob_0" />
    <axis xyz="0 0 1" />
    <limit effort="0.5" velocity="3" lower="-2.35" upper="2.35" />
    </joint>
  <joint name="panel_to_knob_1" type="revolute">
    <origin xyz="-0.14 0.2975 0.98" rpy="1.5708 0 0" />
    <parent link="range_body" />
    <child link="knob_1" />
    <axis xyz="0 0 1" />
    <limit effort="0.5" velocity="3" lower="-2.35" upper="2.35" />
    </joint>
  <joint name="panel_to_knob_2" type="revolute">
    <origin xyz="0 0.2975 0.98" rpy="1.5708 0 0" />
    <parent link="range_body" />
    <child link="knob_2" />
    <axis xyz="0 0 1" />
    <limit effort="0.5" velocity="3" lower="-2.35" upper="2.35" />
    </joint>
  <joint name="panel_to_knob_3" type="revolute">
    <origin xyz="0.14 0.2975 0.98" rpy="1.5708 0 0" />
    <parent link="range_body" />
    <child link="knob_3" />
    <axis xyz="0 0 1" />
    <limit effort="0.5" velocity="3" lower="-2.35" upper="2.35" />
    </joint>
  <joint name="panel_to_knob_4" type="revolute">
    <origin xyz="0.28 0.2975 0.98" rpy="1.5708 0 0" />
    <parent link="range_body" />
    <child link="knob_4" />
    <axis xyz="0 0 1" />
    <limit effort="0.5" velocity="3" lower="-2.35" upper="2.35" />
    </joint>
  </robot>
