<robot name="stacked_xz_positioning_stage">
  <material name="brushed_aluminum">
    <color rgba="0.72 0.74 0.74 1" />
    </material>
  <material name="black_anodized">
    <color rgba="0.05 0.055 0.06 1" />
    </material>
  <material name="ground_steel">
    <color rgba="0.42 0.44 0.46 1" />
    </material>
  <material name="lead_screw_steel">
    <color rgba="0.78 0.78 0.74 1" />
    </material>
  <material name="brass_bearing">
    <color rgba="0.8 0.58 0.24 1" />
    </material>
  <material name="blue_fixture_plate">
    <color rgba="0.05 0.22 0.55 1" />
    </material>
  <link name="base">
    <visual name="base_plate">
      <origin xyz="0 0 0.0175" rpy="0 0 0" />
      <geometry>
        <box size="0.7 0.24 0.035" />
        </geometry>
      <material name="black_anodized">
        <color rgba="0.05 0.055 0.06 1" />
        </material>
      </visual>
    <visual name="x_rail_0">
      <origin xyz="0 -0.075 0.0475" rpy="0 0 0" />
      <geometry>
        <box size="0.62 0.026 0.027" />
        </geometry>
      <material name="ground_steel">
        <color rgba="0.42 0.44 0.46 1" />
        </material>
      </visual>
    <visual name="x_rail_1">
      <origin xyz="0 0.075 0.0475" rpy="0 0 0" />
      <geometry>
        <box size="0.62 0.026 0.027" />
        </geometry>
      <material name="ground_steel">
        <color rgba="0.42 0.44 0.46 1" />
        </material>
      </visual>
    <visual name="end_stop_0">
      <origin xyz="-0.335 0 0.04" rpy="0 0 0" />
      <geometry>
        <box size="0.035 0.22 0.08" />
        </geometry>
      <material name="brushed_aluminum">
        <color rgba="0.72 0.74 0.74 1" />
        </material>
      </visual>
    <visual name="end_stop_1">
      <origin xyz="0.335 0 0.04" rpy="0 0 0" />
      <geometry>
        <box size="0.035 0.22 0.08" />
        </geometry>
      <material name="brushed_aluminum">
        <color rgba="0.72 0.74 0.74 1" />
        </material>
      </visual>
    <visual name="x_lead_screw">
      <origin xyz="0 -0.105 0.065" rpy="0 1.5708 0" />
      <geometry>
        <cylinder radius="0.006" length="0.58" />
        </geometry>
      <material name="lead_screw_steel">
        <color rgba="0.78 0.78 0.74 1" />
        </material>
      </visual>
    <visual name="x_screw_block_0">
      <origin xyz="-0.295 -0.105 0.0575" rpy="0 0 0" />
      <geometry>
        <box size="0.026 0.03 0.045" />
        </geometry>
      <material name="brushed_aluminum">
        <color rgba="0.72 0.74 0.74 1" />
        </material>
      </visual>
    <visual name="x_screw_block_1">
      <origin xyz="0.295 -0.105 0.0575" rpy="0 0 0" />
      <geometry>
        <box size="0.026 0.03 0.045" />
        </geometry>
      <material name="brushed_aluminum">
        <color rgba="0.72 0.74 0.74 1" />
        </material>
      </visual>
    <collision name="base_plate">
      <origin xyz="0 0 0.0175" rpy="0 0 0" />
      <geometry>
        <box size="0.7 0.24 0.035" />
        </geometry>
      </collision>
    <collision name="x_rail_0">
      <origin xyz="0 -0.075 0.0475" rpy="0 0 0" />
      <geometry>
        <box size="0.62 0.026 0.027" />
        </geometry>
      </collision>
    <collision name="x_rail_1">
      <origin xyz="0 0.075 0.0475" rpy="0 0 0" />
      <geometry>
        <box size="0.62 0.026 0.027" />
        </geometry>
      </collision>
    <collision name="end_stop_0">
      <origin xyz="-0.335 0 0.04" rpy="0 0 0" />
      <geometry>
        <box size="0.035 0.22 0.08" />
        </geometry>
      </collision>
    <collision name="end_stop_1">
      <origin xyz="0.335 0 0.04" rpy="0 0 0" />
      <geometry>
        <box size="0.035 0.22 0.08" />
        </geometry>
      </collision>
    <collision name="x_lead_screw">
      <origin xyz="0 -0.105 0.065" rpy="0 1.5708 0" />
      <geometry>
        <cylinder radius="0.006" length="0.58" />
        </geometry>
      </collision>
    <collision name="x_screw_block_0">
      <origin xyz="-0.295 -0.105 0.0575" rpy="0 0 0" />
      <geometry>
        <box size="0.026 0.03 0.045" />
        </geometry>
      </collision>
    <collision name="x_screw_block_1">
      <origin xyz="0.295 -0.105 0.0575" rpy="0 0 0" />
      <geometry>
        <box size="0.026 0.03 0.045" />
        </geometry>
      </collision>
    </link>
  <link name="x_carriage">
    <visual name="saddle_plate">
      <origin xyz="0 0 0.025" rpy="0 0 0" />
      <geometry>
        <box size="0.18 0.17 0.03" />
        </geometry>
      <material name="brushed_aluminum">
        <color rgba="0.72 0.74 0.74 1" />
        </material>
      </visual>
    <visual name="x_bearing_0">
      <origin xyz="0 -0.075 0.009" rpy="0 0 0" />
      <geometry>
        <box size="0.16 0.038 0.018" />
        </geometry>
      <material name="brass_bearing">
        <color rgba="0.8 0.58 0.24 1" />
        </material>
      </visual>
    <visual name="x_bearing_1">
      <origin xyz="0 0.075 0.009" rpy="0 0 0" />
      <geometry>
        <box size="0.16 0.038 0.018" />
        </geometry>
      <material name="brass_bearing">
        <color rgba="0.8 0.58 0.24 1" />
        </material>
      </visual>
    <visual name="upright_back">
      <origin xyz="0 0.045 0.2" rpy="0 0 0" />
      <geometry>
        <box size="0.1 0.035 0.32" />
        </geometry>
      <material name="black_anodized">
        <color rgba="0.05 0.055 0.06 1" />
        </material>
      </visual>
    <visual name="z_rail_0">
      <origin xyz="-0.032 0.019 0.205" rpy="0 0 0" />
      <geometry>
        <box size="0.016 0.018 0.27" />
        </geometry>
      <material name="ground_steel">
        <color rgba="0.42 0.44 0.46 1" />
        </material>
      </visual>
    <visual name="z_rail_1">
      <origin xyz="0.032 0.019 0.205" rpy="0 0 0" />
      <geometry>
        <box size="0.016 0.018 0.27" />
        </geometry>
      <material name="ground_steel">
        <color rgba="0.42 0.44 0.46 1" />
        </material>
      </visual>
    <visual name="upright_cap">
      <origin xyz="0 0.045 0.365" rpy="0 0 0" />
      <geometry>
        <box size="0.13 0.055 0.025" />
        </geometry>
      <material name="brushed_aluminum">
        <color rgba="0.72 0.74 0.74 1" />
        </material>
      </visual>
    <visual name="z_lead_screw">
      <origin xyz="0.065 -0.005 0.18" rpy="0 0 0" />
      <geometry>
        <cylinder radius="0.005" length="0.25" />
        </geometry>
      <material name="lead_screw_steel">
        <color rgba="0.78 0.78 0.74 1" />
        </material>
      </visual>
    <visual name="z_screw_lower_block">
      <origin xyz="0.065 -0.005 0.0525" rpy="0 0 0" />
      <geometry>
        <box size="0.025 0.025 0.025" />
        </geometry>
      <material name="brushed_aluminum">
        <color rgba="0.72 0.74 0.74 1" />
        </material>
      </visual>
    <visual name="z_screw_upper_block">
      <origin xyz="0.065 -0.005 0.31" rpy="0 0 0" />
      <geometry>
        <box size="0.025 0.025 0.025" />
        </geometry>
      <material name="brushed_aluminum">
        <color rgba="0.72 0.74 0.74 1" />
        </material>
      </visual>
    <collision name="saddle_plate">
      <origin xyz="0 0 0.025" rpy="0 0 0" />
      <geometry>
        <box size="0.18 0.17 0.03" />
        </geometry>
      </collision>
    <collision name="x_bearing_0">
      <origin xyz="0 -0.075 0.009" rpy="0 0 0" />
      <geometry>
        <box size="0.16 0.038 0.018" />
        </geometry>
      </collision>
    <collision name="x_bearing_1">
      <origin xyz="0 0.075 0.009" rpy="0 0 0" />
      <geometry>
        <box size="0.16 0.038 0.018" />
        </geometry>
      </collision>
    <collision name="upright_back">
      <origin xyz="0 0.045 0.2" rpy="0 0 0" />
      <geometry>
        <box size="0.1 0.035 0.32" />
        </geometry>
      </collision>
    <collision name="z_rail_0">
      <origin xyz="-0.032 0.019 0.205" rpy="0 0 0" />
      <geometry>
        <box size="0.016 0.018 0.27" />
        </geometry>
      </collision>
    <collision name="z_rail_1">
      <origin xyz="0.032 0.019 0.205" rpy="0 0 0" />
      <geometry>
        <box size="0.016 0.018 0.27" />
        </geometry>
      </collision>
    <collision name="upright_cap">
      <origin xyz="0 0.045 0.365" rpy="0 0 0" />
      <geometry>
        <box size="0.13 0.055 0.025" />
        </geometry>
      </collision>
    <collision name="z_lead_screw">
      <origin xyz="0.065 -0.005 0.18" rpy="0 0 0" />
      <geometry>
        <cylinder radius="0.005" length="0.25" />
        </geometry>
      </collision>
    <collision name="z_screw_lower_block">
      <origin xyz="0.065 -0.005 0.0525" rpy="0 0 0" />
      <geometry>
        <box size="0.025 0.025 0.025" />
        </geometry>
      </collision>
    <collision name="z_screw_upper_block">
      <origin xyz="0.065 -0.005 0.31" rpy="0 0 0" />
      <geometry>
        <box size="0.025 0.025 0.025" />
        </geometry>
      </collision>
    </link>
  <link name="z_carriage">
    <visual name="z_slider_block">
      <origin xyz="0 0 0.05" rpy="0 0 0" />
      <geometry>
        <box size="0.11 0.035 0.09" />
        </geometry>
      <material name="brushed_aluminum">
        <color rgba="0.72 0.74 0.74 1" />
        </material>
      </visual>
    <visual name="top_riser">
      <origin xyz="0 -0.03 0.16" rpy="0 0 0" />
      <geometry>
        <box size="0.085 0.04 0.15" />
        </geometry>
      <material name="black_anodized">
        <color rgba="0.05 0.055 0.06 1" />
        </material>
      </visual>
    <visual name="top_plate">
      <origin xyz="0 -0.06 0.2475" rpy="0 0 0" />
      <geometry>
        <box size="0.16 0.14 0.025" />
        </geometry>
      <material name="blue_fixture_plate">
        <color rgba="0.05 0.22 0.55 1" />
        </material>
      </visual>
    <visual name="z_gib_pad">
      <origin xyz="0 0.002 0.03" rpy="0 0 0" />
      <geometry>
        <box size="0.1 0.018 0.022" />
        </geometry>
      <material name="brass_bearing">
        <color rgba="0.8 0.58 0.24 1" />
        </material>
      </visual>
    <collision name="z_slider_block">
      <origin xyz="0 0 0.05" rpy="0 0 0" />
      <geometry>
        <box size="0.11 0.035 0.09" />
        </geometry>
      </collision>
    <collision name="top_riser">
      <origin xyz="0 -0.03 0.16" rpy="0 0 0" />
      <geometry>
        <box size="0.085 0.04 0.15" />
        </geometry>
      </collision>
    <collision name="top_plate">
      <origin xyz="0 -0.06 0.2475" rpy="0 0 0" />
      <geometry>
        <box size="0.16 0.14 0.025" />
        </geometry>
      </collision>
    <collision name="z_gib_pad">
      <origin xyz="0 0.002 0.03" rpy="0 0 0" />
      <geometry>
        <box size="0.1 0.018 0.022" />
        </geometry>
      </collision>
    </link>
  <joint name="x_axis" type="prismatic">
    <origin xyz="0 0 0.061" rpy="0 0 0" />
    <parent link="base" />
    <child link="x_carriage" />
    <axis xyz="1 0 0" />
    <limit effort="120" velocity="0.2" lower="-0.18" upper="0.18" />
    </joint>
  <joint name="z_axis" type="prismatic">
    <origin xyz="0 -0.0075 0.11" rpy="0 0 0" />
    <parent link="x_carriage" />
    <child link="z_carriage" />
    <axis xyz="0 0 1" />
    <limit effort="90" velocity="0.16" lower="0" upper="0.16" />
    </joint>
  </robot>
