<robot name="tube_rotator_module">
  <material name="dark_powdercoat">
    <color rgba="0.08 0.09 0.1 1" />
    </material>
  <material name="machined_steel">
    <color rgba="0.58 0.6 0.62 1" />
    </material>
  <material name="bronze_bearing">
    <color rgba="0.78 0.5 0.18 1" />
    </material>
  <material name="blackened_cap">
    <color rgba="0.015 0.016 0.018 1" />
    </material>
  <material name="brushed_aluminum">
    <color rgba="0.72 0.76 0.78 1" />
    </material>
  <material name="polished_rollers">
    <color rgba="0.82 0.84 0.86 1" />
    </material>
  <link name="fixed_support">
    <visual name="base_rails">
      <geometry>
        <mesh filename="assets/meshes/base_rails.obj" />
        </geometry>
      <material name="dark_powdercoat">
        <color rgba="0.08 0.09 0.1 1" />
        </material>
      </visual>
    <visual name="front_ribs">
      <geometry>
        <mesh filename="assets/meshes/front_ribs.obj" />
        </geometry>
      <material name="dark_powdercoat">
        <color rgba="0.08 0.09 0.1 1" />
        </material>
      </visual>
    <visual name="rear_ribs">
      <geometry>
        <mesh filename="assets/meshes/rear_ribs.obj" />
        </geometry>
      <material name="dark_powdercoat">
        <color rgba="0.08 0.09 0.1 1" />
        </material>
      </visual>
    <visual name="front_bearing">
      <geometry>
        <mesh filename="assets/meshes/front_bearing.obj" />
        </geometry>
      <material name="machined_steel">
        <color rgba="0.58 0.6 0.62 1" />
        </material>
      </visual>
    <visual name="rear_bearing">
      <geometry>
        <mesh filename="assets/meshes/rear_bearing.obj" />
        </geometry>
      <material name="machined_steel">
        <color rgba="0.58 0.6 0.62 1" />
        </material>
      </visual>
    <visual name="front_liner">
      <geometry>
        <mesh filename="assets/meshes/front_liner.obj" />
        </geometry>
      <material name="bronze_bearing">
        <color rgba="0.78 0.5 0.18 1" />
        </material>
      </visual>
    <visual name="rear_liner">
      <geometry>
        <mesh filename="assets/meshes/rear_liner.obj" />
        </geometry>
      <material name="bronze_bearing">
        <color rgba="0.78 0.5 0.18 1" />
        </material>
      </visual>
    <visual name="front_cap">
      <geometry>
        <mesh filename="assets/meshes/front_cap.obj" />
        </geometry>
      <material name="blackened_cap">
        <color rgba="0.015 0.016 0.018 1" />
        </material>
      </visual>
    <visual name="rear_cap">
      <geometry>
        <mesh filename="assets/meshes/rear_cap.obj" />
        </geometry>
      <material name="blackened_cap">
        <color rgba="0.015 0.016 0.018 1" />
        </material>
      </visual>
    <visual name="front_roller_0">
      <geometry>
        <mesh filename="assets/meshes/front_roller_0.obj" />
        </geometry>
      <material name="polished_rollers">
        <color rgba="0.82 0.84 0.86 1" />
        </material>
      </visual>
    <visual name="front_roller_1">
      <geometry>
        <mesh filename="assets/meshes/front_roller_1.obj" />
        </geometry>
      <material name="polished_rollers">
        <color rgba="0.82 0.84 0.86 1" />
        </material>
      </visual>
    <visual name="front_roller_2">
      <geometry>
        <mesh filename="assets/meshes/front_roller_2.obj" />
        </geometry>
      <material name="polished_rollers">
        <color rgba="0.82 0.84 0.86 1" />
        </material>
      </visual>
    <visual name="front_roller_3">
      <geometry>
        <mesh filename="assets/meshes/front_roller_3.obj" />
        </geometry>
      <material name="polished_rollers">
        <color rgba="0.82 0.84 0.86 1" />
        </material>
      </visual>
    <visual name="rear_roller_0">
      <geometry>
        <mesh filename="assets/meshes/rear_roller_0.obj" />
        </geometry>
      <material name="polished_rollers">
        <color rgba="0.82 0.84 0.86 1" />
        </material>
      </visual>
    <visual name="rear_roller_1">
      <geometry>
        <mesh filename="assets/meshes/rear_roller_1.obj" />
        </geometry>
      <material name="polished_rollers">
        <color rgba="0.82 0.84 0.86 1" />
        </material>
      </visual>
    <visual name="rear_roller_2">
      <geometry>
        <mesh filename="assets/meshes/rear_roller_2.obj" />
        </geometry>
      <material name="polished_rollers">
        <color rgba="0.82 0.84 0.86 1" />
        </material>
      </visual>
    <visual name="rear_roller_3">
      <geometry>
        <mesh filename="assets/meshes/rear_roller_3.obj" />
        </geometry>
      <material name="polished_rollers">
        <color rgba="0.82 0.84 0.86 1" />
        </material>
      </visual>
    <collision name="base_rails">
      <geometry>
        <mesh filename="assets/meshes/base_rails.obj" />
        </geometry>
      </collision>
    <collision name="front_ribs">
      <geometry>
        <mesh filename="assets/meshes/front_ribs.obj" />
        </geometry>
      </collision>
    <collision name="rear_ribs">
      <geometry>
        <mesh filename="assets/meshes/rear_ribs.obj" />
        </geometry>
      </collision>
    <collision name="front_bearing">
      <geometry>
        <mesh filename="assets/meshes/front_bearing.obj" />
        </geometry>
      </collision>
    <collision name="rear_bearing">
      <geometry>
        <mesh filename="assets/meshes/rear_bearing.obj" />
        </geometry>
      </collision>
    <collision name="front_liner">
      <geometry>
        <mesh filename="assets/meshes/front_liner.obj" />
        </geometry>
      </collision>
    <collision name="rear_liner">
      <geometry>
        <mesh filename="assets/meshes/rear_liner.obj" />
        </geometry>
      </collision>
    <collision name="front_cap">
      <geometry>
        <mesh filename="assets/meshes/front_cap.obj" />
        </geometry>
      </collision>
    <collision name="rear_cap">
      <geometry>
        <mesh filename="assets/meshes/rear_cap.obj" />
        </geometry>
      </collision>
    <collision name="front_roller_0">
      <geometry>
        <mesh filename="assets/meshes/front_roller_0.obj" />
        </geometry>
      </collision>
    <collision name="front_roller_1">
      <geometry>
        <mesh filename="assets/meshes/front_roller_1.obj" />
        </geometry>
      </collision>
    <collision name="front_roller_2">
      <geometry>
        <mesh filename="assets/meshes/front_roller_2.obj" />
        </geometry>
      </collision>
    <collision name="front_roller_3">
      <geometry>
        <mesh filename="assets/meshes/front_roller_3.obj" />
        </geometry>
      </collision>
    <collision name="rear_roller_0">
      <geometry>
        <mesh filename="assets/meshes/rear_roller_0.obj" />
        </geometry>
      </collision>
    <collision name="rear_roller_1">
      <geometry>
        <mesh filename="assets/meshes/rear_roller_1.obj" />
        </geometry>
      </collision>
    <collision name="rear_roller_2">
      <geometry>
        <mesh filename="assets/meshes/rear_roller_2.obj" />
        </geometry>
      </collision>
    <collision name="rear_roller_3">
      <geometry>
        <mesh filename="assets/meshes/rear_roller_3.obj" />
        </geometry>
      </collision>
    </link>
  <link name="carrier">
    <visual name="carrier_shell">
      <geometry>
        <mesh filename="assets/meshes/carrier_shell.obj" />
        </geometry>
      <material name="brushed_aluminum">
        <color rgba="0.72 0.76 0.78 1" />
        </material>
      </visual>
    <visual name="bracket_body">
      <geometry>
        <mesh filename="assets/meshes/bracket_body.obj" />
        </geometry>
      <material name="brushed_aluminum">
        <color rgba="0.72 0.76 0.78 1" />
        </material>
      </visual>
    <collision name="carrier_shell">
      <geometry>
        <mesh filename="assets/meshes/carrier_shell.obj" />
        </geometry>
      </collision>
    <collision name="bracket_body">
      <geometry>
        <mesh filename="assets/meshes/bracket_body.obj" />
        </geometry>
      </collision>
    </link>
  <joint name="support_to_carrier" type="revolute">
    <origin xyz="0 0 0.32" rpy="0 0 0" />
    <parent link="fixed_support" />
    <child link="carrier" />
    <axis xyz="1 0 0" />
    <limit effort="18" velocity="4" lower="-3.14159" upper="3.14159" />
    </joint>
  </robot>
