<robot name="floor_spotlight">
  <material name="matte_black">
    <color rgba="0.005 0.005 0.004 1" />
    </material>
  <material name="black_hardware">
    <color rgba="0.025 0.025 0.022 1" />
    </material>
  <material name="rubber">
    <color rgba="0 0 0 1" />
    </material>
  <material name="warm_lens_glass">
    <color rgba="1 0.72 0.32 0.45" />
    </material>
  <material name="worn_black_edge">
    <color rgba="0.12 0.115 0.105 1" />
    </material>
  <link name="base">
    <visual name="base_plate">
      <origin xyz="0 0 0.0175" rpy="0 0 0" />
      <geometry>
        <box size="0.56 0.4 0.035" />
        </geometry>
      <material name="matte_black" />
      </visual>
    <visual name="turntable_disk">
      <origin xyz="0 0 0.044" rpy="0 0 0" />
      <geometry>
        <cylinder radius="0.115" length="0.018" />
        </geometry>
      <material name="worn_black_edge" />
      </visual>
    <visual name="base_collar">
      <origin xyz="0 0 0.079" rpy="0 0 0" />
      <geometry>
        <mesh filename="assets/meshes/base_collar.obj" />
        </geometry>
      <material name="black_hardware" />
      </visual>
    <visual name="foot_0">
      <origin xyz="-0.21 -0.145 -0.006" rpy="0 0 0" />
      <geometry>
        <cylinder radius="0.035" length="0.012" />
        </geometry>
      <material name="rubber" />
      </visual>
    <visual name="foot_1">
      <origin xyz="-0.21 0.145 -0.006" rpy="0 0 0" />
      <geometry>
        <cylinder radius="0.035" length="0.012" />
        </geometry>
      <material name="rubber" />
      </visual>
    <visual name="foot_2">
      <origin xyz="0.21 -0.145 -0.006" rpy="0 0 0" />
      <geometry>
        <cylinder radius="0.035" length="0.012" />
        </geometry>
      <material name="rubber" />
      </visual>
    <visual name="foot_3">
      <origin xyz="0.21 0.145 -0.006" rpy="0 0 0" />
      <geometry>
        <cylinder radius="0.035" length="0.012" />
        </geometry>
      <material name="rubber" />
      </visual>
    </link>
  <link name="yoke">
    <visual name="pan_stem">
      <origin xyz="0 0 0.05" rpy="0 0 0" />
      <geometry>
        <cylinder radius="0.028" length="0.13" />
        </geometry>
      <material name="black_hardware" />
      </visual>
    <visual name="lower_bridge">
      <origin xyz="-0.035 0 0.105" rpy="0 0 0" />
      <geometry>
        <box size="0.25 0.52 0.045" />
        </geometry>
      <material name="matte_black" />
      </visual>
    <visual name="arm_0">
      <origin xyz="0 -0.238 0.25" rpy="0 0 0" />
      <geometry>
        <box size="0.07 0.034 0.32" />
        </geometry>
      <material name="matte_black" />
      </visual>
    <visual name="bearing_0">
      <origin xyz="0 -0.238 0.32" rpy="1.5708 0 0" />
      <geometry>
        <cylinder radius="0.058" length="0.034" />
        </geometry>
      <material name="black_hardware" />
      </visual>
    <visual name="arm_1">
      <origin xyz="0 0.238 0.25" rpy="0 0 0" />
      <geometry>
        <box size="0.07 0.034 0.32" />
        </geometry>
      <material name="matte_black" />
      </visual>
    <visual name="bearing_1">
      <origin xyz="0 0.238 0.32" rpy="1.5708 0 0" />
      <geometry>
        <cylinder radius="0.058" length="0.034" />
        </geometry>
      <material name="black_hardware" />
      </visual>
    </link>
  <link name="can">
    <visual name="can_shell">
      <geometry>
        <mesh filename="assets/meshes/can_shell.obj" />
        </geometry>
      <material name="matte_black" />
      </visual>
    <visual name="front_lens">
      <origin xyz="0.333 0 0" rpy="0 1.5708 0" />
      <geometry>
        <cylinder radius="0.128" length="0.012" />
        </geometry>
      <material name="warm_lens_glass" />
      </visual>
    <visual name="trunnion_axle">
      <origin xyz="0 0 0" rpy="1.5708 0 0" />
      <geometry>
        <cylinder radius="0.034" length="0.442" />
        </geometry>
      <material name="black_hardware" />
      </visual>
    <visual name="side_boss_0">
      <origin xyz="0 -0.169 0" rpy="1.5708 0 0" />
      <geometry>
        <cylinder radius="0.064" length="0.02" />
        </geometry>
      <material name="worn_black_edge" />
      </visual>
    <visual name="side_boss_1">
      <origin xyz="0 0.169 0" rpy="1.5708 0 0" />
      <geometry>
        <cylinder radius="0.064" length="0.02" />
        </geometry>
      <material name="worn_black_edge" />
      </visual>
    <visual name="rear_vent_0">
      <origin xyz="-0.306 0 -0.055" rpy="0 0 0" />
      <geometry>
        <box size="0.006 0.09 0.01" />
        </geometry>
      <material name="black_hardware" />
      </visual>
    <visual name="rear_vent_1">
      <origin xyz="-0.306 0 0" rpy="0 0 0" />
      <geometry>
        <box size="0.006 0.09 0.01" />
        </geometry>
      <material name="black_hardware" />
      </visual>
    <visual name="rear_vent_2">
      <origin xyz="-0.306 0 0.055" rpy="0 0 0" />
      <geometry>
        <box size="0.006 0.09 0.01" />
        </geometry>
      <material name="black_hardware" />
      </visual>
    <visual name="hinge_knuckle_0">
      <origin xyz="-0.235 -0.053 0.154" rpy="1.5708 0 0" />
      <geometry>
        <cylinder radius="0.008" length="0.03" />
        </geometry>
      <material name="black_hardware" />
      </visual>
    <visual name="hinge_knuckle_1">
      <origin xyz="-0.235 0.053 0.154" rpy="1.5708 0 0" />
      <geometry>
        <cylinder radius="0.008" length="0.03" />
        </geometry>
      <material name="black_hardware" />
      </visual>
    </link>
  <link name="service_flap">
    <visual name="flap_barrel">
      <origin xyz="0 0 0" rpy="1.5708 0 0" />
      <geometry>
        <cylinder radius="0.008" length="0.062" />
        </geometry>
      <material name="black_hardware" />
      </visual>
    <visual name="flap_hinge_leaf">
      <origin xyz="0.018 0 0.01" rpy="0 0 0" />
      <geometry>
        <box size="0.036 0.058 0.006" />
        </geometry>
      <material name="black_hardware" />
      </visual>
    <visual name="flap_panel">
      <origin xyz="0.078 0 0.011" rpy="0 0 0" />
      <geometry>
        <box size="0.145 0.112 0.006" />
        </geometry>
      <material name="matte_black" />
      </visual>
    <visual name="flap_latch_lip">
      <origin xyz="0.152 0 0.018" rpy="0 0 0" />
      <geometry>
        <box size="0.018 0.06 0.012" />
        </geometry>
      <material name="worn_black_edge" />
      </visual>
    <visual name="flap_side_rib_0">
      <origin xyz="0.08 -0.058 0.017" rpy="0 0 0" />
      <geometry>
        <box size="0.125 0.006 0.008" />
        </geometry>
      <material name="black_hardware" />
      </visual>
    <visual name="flap_side_rib_1">
      <origin xyz="0.08 0.058 0.017" rpy="0 0 0" />
      <geometry>
        <box size="0.125 0.006 0.008" />
        </geometry>
      <material name="black_hardware" />
      </visual>
    </link>
  <joint name="pan_joint" type="revolute">
    <origin xyz="0 0 0.065" rpy="0 0 0" />
    <parent link="base" />
    <child link="yoke" />
    <axis xyz="0 0 1" />
    <limit effort="35" velocity="1.6" lower="-2.35" upper="2.35" />
    </joint>
  <joint name="tilt_hinge" type="revolute">
    <origin xyz="0 0 0.32" rpy="0 0 0" />
    <parent link="yoke" />
    <child link="can" />
    <axis xyz="0 -1 0" />
    <limit effort="24" velocity="1.2" lower="-0.9" upper="1.05" />
    </joint>
  <joint name="flap_hinge" type="revolute">
    <origin xyz="-0.235 0 0.154" rpy="0 0 0" />
    <parent link="can" />
    <child link="service_flap" />
    <axis xyz="0 -1 0" />
    <limit effort="2" velocity="1.5" lower="0" upper="1.35" />
    </joint>
  </robot>
