<robot name="residential_dishwasher">
  <material name="brushed_stainless">
    <color rgba="0.68 0.7 0.68 1" />
    </material>
  <material name="dark_steel">
    <color rgba="0.08 0.085 0.09 1" />
    </material>
  <material name="black_plastic">
    <color rgba="0.015 0.015 0.017 1" />
    </material>
  <material name="molded_gray_liner">
    <color rgba="0.7 0.74 0.76 1" />
    </material>
  <material name="vinyl_wire_rack">
    <color rgba="0.88 0.9 0.88 1" />
    </material>
  <material name="blue_gray_plastic">
    <color rgba="0.35 0.43 0.47 1" />
    </material>
  <material name="charcoal_buttons">
    <color rgba="0.03 0.034 0.04 1" />
    </material>
  <link name="cabinet">
    <visual name="side_panel_0">
      <origin xyz="-0.31 -0.02 0.47" rpy="0 0 0" />
      <geometry>
        <box size="0.025 0.68 0.78" />
        </geometry>
      <material name="dark_steel">
        <color rgba="0.08 0.085 0.09 1" />
        </material>
      </visual>
    <visual name="side_panel_1">
      <origin xyz="0.31 -0.02 0.47" rpy="0 0 0" />
      <geometry>
        <box size="0.025 0.68 0.78" />
        </geometry>
      <material name="dark_steel">
        <color rgba="0.08 0.085 0.09 1" />
        </material>
      </visual>
    <visual name="rear_panel">
      <origin xyz="0 0.315 0.47" rpy="0 0 0" />
      <geometry>
        <box size="0.62 0.025 0.78" />
        </geometry>
      <material name="dark_steel">
        <color rgba="0.08 0.085 0.09 1" />
        </material>
      </visual>
    <visual name="countertop_shadow">
      <origin xyz="0 -0.02 0.862" rpy="0 0 0" />
      <geometry>
        <box size="0.62 0.68 0.035" />
        </geometry>
      <material name="dark_steel">
        <color rgba="0.08 0.085 0.09 1" />
        </material>
      </visual>
    <visual name="toe_kick">
      <origin xyz="0 -0.02 0.04" rpy="0 0 0" />
      <geometry>
        <box size="0.62 0.68 0.08" />
        </geometry>
      <material name="black_plastic">
        <color rgba="0.015 0.015 0.017 1" />
        </material>
      </visual>
    <visual name="tub_wall_0">
      <origin xyz="-0.285 -0.02 0.47" rpy="0 0 0" />
      <geometry>
        <box size="0.025 0.58 0.7" />
        </geometry>
      <material name="molded_gray_liner">
        <color rgba="0.7 0.74 0.76 1" />
        </material>
      </visual>
    <visual name="tub_wall_1">
      <origin xyz="0.285 -0.02 0.47" rpy="0 0 0" />
      <geometry>
        <box size="0.025 0.58 0.7" />
        </geometry>
      <material name="molded_gray_liner">
        <color rgba="0.7 0.74 0.76 1" />
        </material>
      </visual>
    <visual name="tub_rear_wall">
      <origin xyz="0 0.29 0.47" rpy="0 0 0" />
      <geometry>
        <box size="0.56 0.025 0.7" />
        </geometry>
      <material name="molded_gray_liner">
        <color rgba="0.7 0.74 0.76 1" />
        </material>
      </visual>
    <visual name="tub_floor">
      <origin xyz="0 -0.02 0.11" rpy="0 0 0" />
      <geometry>
        <box size="0.56 0.58 0.02" />
        </geometry>
      <material name="molded_gray_liner">
        <color rgba="0.7 0.74 0.76 1" />
        </material>
      </visual>
    <visual name="tub_ceiling">
      <origin xyz="0 -0.02 0.82" rpy="0 0 0" />
      <geometry>
        <box size="0.56 0.58 0.02" />
        </geometry>
      <material name="molded_gray_liner">
        <color rgba="0.7 0.74 0.76 1" />
        </material>
      </visual>
    <visual name="front_gasket_0">
      <origin xyz="-0.285 -0.323 0.47" rpy="0 0 0" />
      <geometry>
        <box size="0.045 0.025 0.72" />
        </geometry>
      <material name="black_plastic">
        <color rgba="0.015 0.015 0.017 1" />
        </material>
      </visual>
    <visual name="front_gasket_1">
      <origin xyz="0.285 -0.323 0.47" rpy="0 0 0" />
      <geometry>
        <box size="0.045 0.025 0.72" />
        </geometry>
      <material name="black_plastic">
        <color rgba="0.015 0.015 0.017 1" />
        </material>
      </visual>
    <visual name="front_gasket_top">
      <origin xyz="0 -0.323 0.82" rpy="0 0 0" />
      <geometry>
        <box size="0.58 0.025 0.035" />
        </geometry>
      <material name="black_plastic">
        <color rgba="0.015 0.015 0.017 1" />
        </material>
      </visual>
    <visual name="front_gasket_bottom">
      <origin xyz="0 -0.323 0.12" rpy="0 0 0" />
      <geometry>
        <box size="0.58 0.025 0.03" />
        </geometry>
      <material name="black_plastic">
        <color rgba="0.015 0.015 0.017 1" />
        </material>
      </visual>
    <visual name="lower_rail_0">
      <origin xyz="-0.255 -0.03 0.204" rpy="0 0 0" />
      <geometry>
        <box size="0.035 0.52 0.012" />
        </geometry>
      <material name="brushed_stainless">
        <color rgba="0.68 0.7 0.68 1" />
        </material>
      </visual>
    <visual name="upper_rail_0">
      <origin xyz="-0.255 -0.03 0.494" rpy="0 0 0" />
      <geometry>
        <box size="0.035 0.5 0.012" />
        </geometry>
      <material name="brushed_stainless">
        <color rgba="0.68 0.7 0.68 1" />
        </material>
      </visual>
    <visual name="lower_roller_0">
      <origin xyz="-0.255 -0.275 0.204" rpy="0 0 0" />
      <geometry>
        <box size="0.035 0.045 0.028" />
        </geometry>
      <material name="brushed_stainless">
        <color rgba="0.68 0.7 0.68 1" />
        </material>
      </visual>
    <visual name="upper_roller_0">
      <origin xyz="-0.255 -0.275 0.494" rpy="0 0 0" />
      <geometry>
        <box size="0.035 0.045 0.028" />
        </geometry>
      <material name="brushed_stainless">
        <color rgba="0.68 0.7 0.68 1" />
        </material>
      </visual>
    <visual name="lower_rail_1">
      <origin xyz="0.255 -0.03 0.204" rpy="0 0 0" />
      <geometry>
        <box size="0.035 0.52 0.012" />
        </geometry>
      <material name="brushed_stainless">
        <color rgba="0.68 0.7 0.68 1" />
        </material>
      </visual>
    <visual name="upper_rail_1">
      <origin xyz="0.255 -0.03 0.494" rpy="0 0 0" />
      <geometry>
        <box size="0.035 0.5 0.012" />
        </geometry>
      <material name="brushed_stainless">
        <color rgba="0.68 0.7 0.68 1" />
        </material>
      </visual>
    <visual name="lower_roller_1">
      <origin xyz="0.255 -0.275 0.204" rpy="0 0 0" />
      <geometry>
        <box size="0.035 0.045 0.028" />
        </geometry>
      <material name="brushed_stainless">
        <color rgba="0.68 0.7 0.68 1" />
        </material>
      </visual>
    <visual name="upper_roller_1">
      <origin xyz="0.255 -0.275 0.494" rpy="0 0 0" />
      <geometry>
        <box size="0.035 0.045 0.028" />
        </geometry>
      <material name="brushed_stainless">
        <color rgba="0.68 0.7 0.68 1" />
        </material>
      </visual>
    <visual name="door_hinge_pin">
      <origin xyz="0 -0.35 0.1" rpy="0 1.5708 0" />
      <geometry>
        <cylinder radius="0.008" length="0.6" />
        </geometry>
      <material name="dark_steel">
        <color rgba="0.08 0.085 0.09 1" />
        </material>
      </visual>
    <visual name="hinge_bracket_0">
      <origin xyz="-0.292 -0.35 0.1" rpy="0 0 0" />
      <geometry>
        <box size="0.04 0.055 0.05" />
        </geometry>
      <material name="dark_steel">
        <color rgba="0.08 0.085 0.09 1" />
        </material>
      </visual>
    <visual name="hinge_bracket_1">
      <origin xyz="0.292 -0.35 0.1" rpy="0 0 0" />
      <geometry>
        <box size="0.04 0.055 0.05" />
        </geometry>
      <material name="dark_steel">
        <color rgba="0.08 0.085 0.09 1" />
        </material>
      </visual>
    <visual name="lower_spray_pedestal">
      <origin xyz="0 -0.02 0.137" rpy="0 0 0" />
      <geometry>
        <cylinder radius="0.018" length="0.034" />
        </geometry>
      <material name="blue_gray_plastic">
        <color rgba="0.35 0.43 0.47 1" />
        </material>
      </visual>
    <visual name="upper_spray_nipple">
      <origin xyz="0 -0.02 0.415" rpy="0 0 0" />
      <geometry>
        <cylinder radius="0.012" length="0.012" />
        </geometry>
      <material name="blue_gray_plastic">
        <color rgba="0.35 0.43 0.47 1" />
        </material>
      </visual>
    <visual name="upper_water_tube">
      <origin xyz="0 0.135 0.409" rpy="-1.5708 0 0" />
      <geometry>
        <cylinder radius="0.01" length="0.31" />
        </geometry>
      <material name="blue_gray_plastic">
        <color rgba="0.35 0.43 0.47 1" />
        </material>
      </visual>
    <collision name="side_panel_0">
      <origin xyz="-0.31 -0.02 0.47" rpy="0 0 0" />
      <geometry>
        <box size="0.025 0.68 0.78" />
        </geometry>
      </collision>
    <collision name="side_panel_1">
      <origin xyz="0.31 -0.02 0.47" rpy="0 0 0" />
      <geometry>
        <box size="0.025 0.68 0.78" />
        </geometry>
      </collision>
    <collision name="rear_panel">
      <origin xyz="0 0.315 0.47" rpy="0 0 0" />
      <geometry>
        <box size="0.62 0.025 0.78" />
        </geometry>
      </collision>
    <collision name="countertop_shadow">
      <origin xyz="0 -0.02 0.862" rpy="0 0 0" />
      <geometry>
        <box size="0.62 0.68 0.035" />
        </geometry>
      </collision>
    <collision name="toe_kick">
      <origin xyz="0 -0.02 0.04" rpy="0 0 0" />
      <geometry>
        <box size="0.62 0.68 0.08" />
        </geometry>
      </collision>
    <collision name="tub_wall_0">
      <origin xyz="-0.285 -0.02 0.47" rpy="0 0 0" />
      <geometry>
        <box size="0.025 0.58 0.7" />
        </geometry>
      </collision>
    <collision name="tub_wall_1">
      <origin xyz="0.285 -0.02 0.47" rpy="0 0 0" />
      <geometry>
        <box size="0.025 0.58 0.7" />
        </geometry>
      </collision>
    <collision name="tub_rear_wall">
      <origin xyz="0 0.29 0.47" rpy="0 0 0" />
      <geometry>
        <box size="0.56 0.025 0.7" />
        </geometry>
      </collision>
    <collision name="tub_floor">
      <origin xyz="0 -0.02 0.11" rpy="0 0 0" />
      <geometry>
        <box size="0.56 0.58 0.02" />
        </geometry>
      </collision>
    <collision name="tub_ceiling">
      <origin xyz="0 -0.02 0.82" rpy="0 0 0" />
      <geometry>
        <box size="0.56 0.58 0.02" />
        </geometry>
      </collision>
    <collision name="front_gasket_0">
      <origin xyz="-0.285 -0.323 0.47" rpy="0 0 0" />
      <geometry>
        <box size="0.045 0.025 0.72" />
        </geometry>
      </collision>
    <collision name="front_gasket_1">
      <origin xyz="0.285 -0.323 0.47" rpy="0 0 0" />
      <geometry>
        <box size="0.045 0.025 0.72" />
        </geometry>
      </collision>
    <collision name="front_gasket_top">
      <origin xyz="0 -0.323 0.82" rpy="0 0 0" />
      <geometry>
        <box size="0.58 0.025 0.035" />
        </geometry>
      </collision>
    <collision name="front_gasket_bottom">
      <origin xyz="0 -0.323 0.12" rpy="0 0 0" />
      <geometry>
        <box size="0.58 0.025 0.03" />
        </geometry>
      </collision>
    <collision name="lower_rail_0">
      <origin xyz="-0.255 -0.03 0.204" rpy="0 0 0" />
      <geometry>
        <box size="0.035 0.52 0.012" />
        </geometry>
      </collision>
    <collision name="upper_rail_0">
      <origin xyz="-0.255 -0.03 0.494" rpy="0 0 0" />
      <geometry>
        <box size="0.035 0.5 0.012" />
        </geometry>
      </collision>
    <collision name="lower_roller_0">
      <origin xyz="-0.255 -0.275 0.204" rpy="0 0 0" />
      <geometry>
        <box size="0.035 0.045 0.028" />
        </geometry>
      </collision>
    <collision name="upper_roller_0">
      <origin xyz="-0.255 -0.275 0.494" rpy="0 0 0" />
      <geometry>
        <box size="0.035 0.045 0.028" />
        </geometry>
      </collision>
    <collision name="lower_rail_1">
      <origin xyz="0.255 -0.03 0.204" rpy="0 0 0" />
      <geometry>
        <box size="0.035 0.52 0.012" />
        </geometry>
      </collision>
    <collision name="upper_rail_1">
      <origin xyz="0.255 -0.03 0.494" rpy="0 0 0" />
      <geometry>
        <box size="0.035 0.5 0.012" />
        </geometry>
      </collision>
    <collision name="lower_roller_1">
      <origin xyz="0.255 -0.275 0.204" rpy="0 0 0" />
      <geometry>
        <box size="0.035 0.045 0.028" />
        </geometry>
      </collision>
    <collision name="upper_roller_1">
      <origin xyz="0.255 -0.275 0.494" rpy="0 0 0" />
      <geometry>
        <box size="0.035 0.045 0.028" />
        </geometry>
      </collision>
    <collision name="door_hinge_pin">
      <origin xyz="0 -0.35 0.1" rpy="0 1.5708 0" />
      <geometry>
        <cylinder radius="0.008" length="0.6" />
        </geometry>
      </collision>
    <collision name="hinge_bracket_0">
      <origin xyz="-0.292 -0.35 0.1" rpy="0 0 0" />
      <geometry>
        <box size="0.04 0.055 0.05" />
        </geometry>
      </collision>
    <collision name="hinge_bracket_1">
      <origin xyz="0.292 -0.35 0.1" rpy="0 0 0" />
      <geometry>
        <box size="0.04 0.055 0.05" />
        </geometry>
      </collision>
    <collision name="lower_spray_pedestal">
      <origin xyz="0 -0.02 0.137" rpy="0 0 0" />
      <geometry>
        <cylinder radius="0.018" length="0.034" />
        </geometry>
      </collision>
    <collision name="upper_spray_nipple">
      <origin xyz="0 -0.02 0.415" rpy="0 0 0" />
      <geometry>
        <cylinder radius="0.012" length="0.012" />
        </geometry>
      </collision>
    <collision name="upper_water_tube">
      <origin xyz="0 0.135 0.409" rpy="-1.5708 0 0" />
      <geometry>
        <cylinder radius="0.01" length="0.31" />
        </geometry>
      </collision>
    </link>
  <link name="door">
    <visual name="stainless_panel">
      <origin xyz="0 -0.3825 -0.0185" rpy="0 0 0" />
      <geometry>
        <box size="0.6 0.715 0.043" />
        </geometry>
      <material name="brushed_stainless">
        <color rgba="0.68 0.7 0.68 1" />
        </material>
      </visual>
    <visual name="inner_liner">
      <origin xyz="0 -0.36 0.009" rpy="0 0 0" />
      <geometry>
        <box size="0.54 0.58 0.018" />
        </geometry>
      <material name="molded_gray_liner">
        <color rgba="0.7 0.74 0.76 1" />
        </material>
      </visual>
    <visual name="control_strip">
      <origin xyz="0 -0.695 0.018" rpy="0 0 0" />
      <geometry>
        <box size="0.56 0.09 0.02" />
        </geometry>
      <material name="black_plastic">
        <color rgba="0.015 0.015 0.017 1" />
        </material>
      </visual>
    <visual name="recess_handle">
      <origin xyz="0 -0.63 -0.043" rpy="0 0 0" />
      <geometry>
        <box size="0.3 0.03 0.016" />
        </geometry>
      <material name="black_plastic">
        <color rgba="0.015 0.015 0.017 1" />
        </material>
      </visual>
    <visual name="door_hinge_knuckle">
      <origin xyz="0 0 0" rpy="0 1.5708 0" />
      <geometry>
        <cylinder radius="0.014" length="0.5" />
        </geometry>
      <material name="brushed_stainless">
        <color rgba="0.68 0.7 0.68 1" />
        </material>
      </visual>
    <visual name="hinge_leaf">
      <origin xyz="0 -0.025 -0.018" rpy="0 0 0" />
      <geometry>
        <box size="0.52 0.05 0.008" />
        </geometry>
      <material name="brushed_stainless">
        <color rgba="0.68 0.7 0.68 1" />
        </material>
      </visual>
    <visual name="detergent_recess">
      <origin xyz="-0.14 -0.315 0.02" rpy="0 0 0" />
      <geometry>
        <box size="0.18 0.13 0.012" />
        </geometry>
      <material name="blue_gray_plastic">
        <color rgba="0.35 0.43 0.47 1" />
        </material>
      </visual>
    <visual name="rinse_aid_cap">
      <origin xyz="0.12 -0.36 0.021" rpy="0 0 0" />
      <geometry>
        <box size="0.11 0.07 0.008" />
        </geometry>
      <material name="blue_gray_plastic">
        <color rgba="0.35 0.43 0.47 1" />
        </material>
      </visual>
    <collision name="stainless_panel">
      <origin xyz="0 -0.3825 -0.0185" rpy="0 0 0" />
      <geometry>
        <box size="0.6 0.715 0.043" />
        </geometry>
      </collision>
    <collision name="inner_liner">
      <origin xyz="0 -0.36 0.009" rpy="0 0 0" />
      <geometry>
        <box size="0.54 0.58 0.018" />
        </geometry>
      </collision>
    <collision name="control_strip">
      <origin xyz="0 -0.695 0.018" rpy="0 0 0" />
      <geometry>
        <box size="0.56 0.09 0.02" />
        </geometry>
      </collision>
    <collision name="recess_handle">
      <origin xyz="0 -0.63 -0.043" rpy="0 0 0" />
      <geometry>
        <box size="0.3 0.03 0.016" />
        </geometry>
      </collision>
    <collision name="door_hinge_knuckle">
      <origin xyz="0 0 0" rpy="0 1.5708 0" />
      <geometry>
        <cylinder radius="0.014" length="0.5" />
        </geometry>
      </collision>
    <collision name="hinge_leaf">
      <origin xyz="0 -0.025 -0.018" rpy="0 0 0" />
      <geometry>
        <box size="0.52 0.05 0.008" />
        </geometry>
      </collision>
    <collision name="detergent_recess">
      <origin xyz="-0.14 -0.315 0.02" rpy="0 0 0" />
      <geometry>
        <box size="0.18 0.13 0.012" />
        </geometry>
      </collision>
    <collision name="rinse_aid_cap">
      <origin xyz="0.12 -0.36 0.021" rpy="0 0 0" />
      <geometry>
        <box size="0.11 0.07 0.008" />
        </geometry>
      </collision>
    </link>
  <link name="button_0">
    <visual name="button_cap">
      <origin xyz="0 0 0.005" rpy="0 0 0" />
      <geometry>
        <box size="0.044 0.026 0.01" />
        </geometry>
      <material name="charcoal_buttons">
        <color rgba="0.03 0.034 0.04 1" />
        </material>
      </visual>
    <collision name="button_cap">
      <origin xyz="0 0 0.005" rpy="0 0 0" />
      <geometry>
        <box size="0.044 0.026 0.01" />
        </geometry>
      </collision>
    </link>
  <link name="button_1">
    <visual name="button_cap">
      <origin xyz="0 0 0.005" rpy="0 0 0" />
      <geometry>
        <box size="0.044 0.026 0.01" />
        </geometry>
      <material name="charcoal_buttons">
        <color rgba="0.03 0.034 0.04 1" />
        </material>
      </visual>
    <collision name="button_cap">
      <origin xyz="0 0 0.005" rpy="0 0 0" />
      <geometry>
        <box size="0.044 0.026 0.01" />
        </geometry>
      </collision>
    </link>
  <link name="button_2">
    <visual name="button_cap">
      <origin xyz="0 0 0.005" rpy="0 0 0" />
      <geometry>
        <box size="0.044 0.026 0.01" />
        </geometry>
      <material name="charcoal_buttons">
        <color rgba="0.03 0.034 0.04 1" />
        </material>
      </visual>
    <collision name="button_cap">
      <origin xyz="0 0 0.005" rpy="0 0 0" />
      <geometry>
        <box size="0.044 0.026 0.01" />
        </geometry>
      </collision>
    </link>
  <link name="button_3">
    <visual name="button_cap">
      <origin xyz="0 0 0.005" rpy="0 0 0" />
      <geometry>
        <box size="0.044 0.026 0.01" />
        </geometry>
      <material name="charcoal_buttons">
        <color rgba="0.03 0.034 0.04 1" />
        </material>
      </visual>
    <collision name="button_cap">
      <origin xyz="0 0 0.005" rpy="0 0 0" />
      <geometry>
        <box size="0.044 0.026 0.01" />
        </geometry>
      </collision>
    </link>
  <link name="button_4">
    <visual name="button_cap">
      <origin xyz="0 0 0.005" rpy="0 0 0" />
      <geometry>
        <box size="0.044 0.026 0.01" />
        </geometry>
      <material name="charcoal_buttons">
        <color rgba="0.03 0.034 0.04 1" />
        </material>
      </visual>
    <collision name="button_cap">
      <origin xyz="0 0 0.005" rpy="0 0 0" />
      <geometry>
        <box size="0.044 0.026 0.01" />
        </geometry>
      </collision>
    </link>
  <link name="button_5">
    <visual name="button_cap">
      <origin xyz="0 0 0.005" rpy="0 0 0" />
      <geometry>
        <box size="0.044 0.026 0.01" />
        </geometry>
      <material name="charcoal_buttons">
        <color rgba="0.03 0.034 0.04 1" />
        </material>
      </visual>
    <collision name="button_cap">
      <origin xyz="0 0 0.005" rpy="0 0 0" />
      <geometry>
        <box size="0.044 0.026 0.01" />
        </geometry>
      </collision>
    </link>
  <link name="cycle_knob">
    <visual name="knob_cap">
      <geometry>
        <mesh filename="assets/meshes/cycle_selector_knob.obj" />
        </geometry>
      <material name="charcoal_buttons">
        <color rgba="0.03 0.034 0.04 1" />
        </material>
      </visual>
    <collision name="knob_cap">
      <geometry>
        <mesh filename="assets/meshes/cycle_selector_knob.obj" />
        </geometry>
      </collision>
    </link>
  <link name="detergent_cover">
    <visual name="cover_panel">
      <origin xyz="0 -0.0525 0.004" rpy="0 0 0" />
      <geometry>
        <box size="0.155 0.105 0.008" />
        </geometry>
      <material name="blue_gray_plastic">
        <color rgba="0.35 0.43 0.47 1" />
        </material>
      </visual>
    <visual name="cover_latch">
      <origin xyz="0 -0.095 0.012" rpy="0 0 0" />
      <geometry>
        <box size="0.05 0.01 0.008" />
        </geometry>
      <material name="charcoal_buttons">
        <color rgba="0.03 0.034 0.04 1" />
        </material>
      </visual>
    <collision name="cover_panel">
      <origin xyz="0 -0.0525 0.004" rpy="0 0 0" />
      <geometry>
        <box size="0.155 0.105 0.008" />
        </geometry>
      </collision>
    <collision name="cover_latch">
      <origin xyz="0 -0.095 0.012" rpy="0 0 0" />
      <geometry>
        <box size="0.05 0.01 0.008" />
        </geometry>
      </collision>
    </link>
  <link name="lower_rack">
    <visual name="wire_basket">
      <geometry>
        <mesh filename="assets/meshes/lower_wire_rack.obj" />
        </geometry>
      <material name="vinyl_wire_rack">
        <color rgba="0.88 0.9 0.88 1" />
        </material>
      </visual>
    <collision name="wire_basket">
      <geometry>
        <mesh filename="assets/meshes/lower_wire_rack.obj" />
        </geometry>
      </collision>
    </link>
  <link name="upper_rack">
    <visual name="wire_basket">
      <geometry>
        <mesh filename="assets/meshes/upper_wire_rack.obj" />
        </geometry>
      <material name="vinyl_wire_rack">
        <color rgba="0.88 0.9 0.88 1" />
        </material>
      </visual>
    <collision name="wire_basket">
      <geometry>
        <mesh filename="assets/meshes/upper_wire_rack.obj" />
        </geometry>
      </collision>
    </link>
  <link name="lower_spray_arm">
    <visual name="spray_blade">
      <geometry>
        <box size="0.42 0.036 0.012" />
        </geometry>
      <material name="blue_gray_plastic">
        <color rgba="0.35 0.43 0.47 1" />
        </material>
      </visual>
    <visual name="cross_blade">
      <origin xyz="0 0 0.002" rpy="0 0 0" />
      <geometry>
        <box size="0.055 0.189 0.01" />
        </geometry>
      <material name="blue_gray_plastic">
        <color rgba="0.35 0.43 0.47 1" />
        </material>
      </visual>
    <visual name="spray_hub">
      <geometry>
        <cylinder radius="0.035" length="0.024" />
        </geometry>
      <material name="blue_gray_plastic">
        <color rgba="0.35 0.43 0.47 1" />
        </material>
      </visual>
    <visual name="jet_nozzle_0">
      <origin xyz="-0.1428 0.013 0.008" rpy="0 0 0" />
      <geometry>
        <box size="0.012 0.01 0.004" />
        </geometry>
      <material name="black_plastic">
        <color rgba="0.015 0.015 0.017 1" />
        </material>
      </visual>
    <visual name="jet_nozzle_1">
      <origin xyz="-0.0714 0.013 0.008" rpy="0 0 0" />
      <geometry>
        <box size="0.012 0.01 0.004" />
        </geometry>
      <material name="black_plastic">
        <color rgba="0.015 0.015 0.017 1" />
        </material>
      </visual>
    <visual name="jet_nozzle_2">
      <origin xyz="0.0714 0.013 0.008" rpy="0 0 0" />
      <geometry>
        <box size="0.012 0.01 0.004" />
        </geometry>
      <material name="black_plastic">
        <color rgba="0.015 0.015 0.017 1" />
        </material>
      </visual>
    <visual name="jet_nozzle_3">
      <origin xyz="0.1428 0.013 0.008" rpy="0 0 0" />
      <geometry>
        <box size="0.012 0.01 0.004" />
        </geometry>
      <material name="black_plastic">
        <color rgba="0.015 0.015 0.017 1" />
        </material>
      </visual>
    <collision name="spray_blade">
      <geometry>
        <box size="0.42 0.036 0.012" />
        </geometry>
      </collision>
    <collision name="cross_blade">
      <origin xyz="0 0 0.002" rpy="0 0 0" />
      <geometry>
        <box size="0.055 0.189 0.01" />
        </geometry>
      </collision>
    <collision name="spray_hub">
      <geometry>
        <cylinder radius="0.035" length="0.024" />
        </geometry>
      </collision>
    <collision name="jet_nozzle_0">
      <origin xyz="-0.1428 0.013 0.008" rpy="0 0 0" />
      <geometry>
        <box size="0.012 0.01 0.004" />
        </geometry>
      </collision>
    <collision name="jet_nozzle_1">
      <origin xyz="-0.0714 0.013 0.008" rpy="0 0 0" />
      <geometry>
        <box size="0.012 0.01 0.004" />
        </geometry>
      </collision>
    <collision name="jet_nozzle_2">
      <origin xyz="0.0714 0.013 0.008" rpy="0 0 0" />
      <geometry>
        <box size="0.012 0.01 0.004" />
        </geometry>
      </collision>
    <collision name="jet_nozzle_3">
      <origin xyz="0.1428 0.013 0.008" rpy="0 0 0" />
      <geometry>
        <box size="0.012 0.01 0.004" />
        </geometry>
      </collision>
    </link>
  <link name="upper_spray_arm">
    <visual name="spray_blade">
      <geometry>
        <box size="0.34 0.036 0.012" />
        </geometry>
      <material name="blue_gray_plastic">
        <color rgba="0.35 0.43 0.47 1" />
        </material>
      </visual>
    <visual name="cross_blade">
      <origin xyz="0 0 0.002" rpy="0 0 0" />
      <geometry>
        <box size="0.055 0.153 0.01" />
        </geometry>
      <material name="blue_gray_plastic">
        <color rgba="0.35 0.43 0.47 1" />
        </material>
      </visual>
    <visual name="spray_hub">
      <geometry>
        <cylinder radius="0.035" length="0.024" />
        </geometry>
      <material name="blue_gray_plastic">
        <color rgba="0.35 0.43 0.47 1" />
        </material>
      </visual>
    <visual name="jet_nozzle_0">
      <origin xyz="-0.1156 0.013 0.008" rpy="0 0 0" />
      <geometry>
        <box size="0.012 0.01 0.004" />
        </geometry>
      <material name="black_plastic">
        <color rgba="0.015 0.015 0.017 1" />
        </material>
      </visual>
    <visual name="jet_nozzle_1">
      <origin xyz="-0.0578 0.013 0.008" rpy="0 0 0" />
      <geometry>
        <box size="0.012 0.01 0.004" />
        </geometry>
      <material name="black_plastic">
        <color rgba="0.015 0.015 0.017 1" />
        </material>
      </visual>
    <visual name="jet_nozzle_2">
      <origin xyz="0.0578 0.013 0.008" rpy="0 0 0" />
      <geometry>
        <box size="0.012 0.01 0.004" />
        </geometry>
      <material name="black_plastic">
        <color rgba="0.015 0.015 0.017 1" />
        </material>
      </visual>
    <visual name="jet_nozzle_3">
      <origin xyz="0.1156 0.013 0.008" rpy="0 0 0" />
      <geometry>
        <box size="0.012 0.01 0.004" />
        </geometry>
      <material name="black_plastic">
        <color rgba="0.015 0.015 0.017 1" />
        </material>
      </visual>
    <collision name="spray_blade">
      <geometry>
        <box size="0.34 0.036 0.012" />
        </geometry>
      </collision>
    <collision name="cross_blade">
      <origin xyz="0 0 0.002" rpy="0 0 0" />
      <geometry>
        <box size="0.055 0.153 0.01" />
        </geometry>
      </collision>
    <collision name="spray_hub">
      <geometry>
        <cylinder radius="0.035" length="0.024" />
        </geometry>
      </collision>
    <collision name="jet_nozzle_0">
      <origin xyz="-0.1156 0.013 0.008" rpy="0 0 0" />
      <geometry>
        <box size="0.012 0.01 0.004" />
        </geometry>
      </collision>
    <collision name="jet_nozzle_1">
      <origin xyz="-0.0578 0.013 0.008" rpy="0 0 0" />
      <geometry>
        <box size="0.012 0.01 0.004" />
        </geometry>
      </collision>
    <collision name="jet_nozzle_2">
      <origin xyz="0.0578 0.013 0.008" rpy="0 0 0" />
      <geometry>
        <box size="0.012 0.01 0.004" />
        </geometry>
      </collision>
    <collision name="jet_nozzle_3">
      <origin xyz="0.1156 0.013 0.008" rpy="0 0 0" />
      <geometry>
        <box size="0.012 0.01 0.004" />
        </geometry>
      </collision>
    </link>
  <joint name="door_hinge" type="revolute">
    <origin xyz="0 -0.35 0.1" rpy="0 0 0" />
    <parent link="cabinet" />
    <child link="door" />
    <axis xyz="1 0 0" />
    <limit effort="80" velocity="1" lower="-1.45" upper="0" />
    </joint>
  <joint name="door_to_button_0" type="prismatic">
    <origin xyz="-0.225 -0.695 0.028" rpy="0 0 0" />
    <parent link="door" />
    <child link="button_0" />
    <axis xyz="0 0 -1" />
    <limit effort="4" velocity="0.08" lower="0" upper="0.006" />
    </joint>
  <joint name="door_to_button_1" type="prismatic">
    <origin xyz="-0.165 -0.695 0.028" rpy="0 0 0" />
    <parent link="door" />
    <child link="button_1" />
    <axis xyz="0 0 -1" />
    <limit effort="4" velocity="0.08" lower="0" upper="0.006" />
    </joint>
  <joint name="door_to_button_2" type="prismatic">
    <origin xyz="-0.105 -0.695 0.028" rpy="0 0 0" />
    <parent link="door" />
    <child link="button_2" />
    <axis xyz="0 0 -1" />
    <limit effort="4" velocity="0.08" lower="0" upper="0.006" />
    </joint>
  <joint name="door_to_button_3" type="prismatic">
    <origin xyz="-0.045 -0.695 0.028" rpy="0 0 0" />
    <parent link="door" />
    <child link="button_3" />
    <axis xyz="0 0 -1" />
    <limit effort="4" velocity="0.08" lower="0" upper="0.006" />
    </joint>
  <joint name="door_to_button_4" type="prismatic">
    <origin xyz="0.015 -0.695 0.028" rpy="0 0 0" />
    <parent link="door" />
    <child link="button_4" />
    <axis xyz="0 0 -1" />
    <limit effort="4" velocity="0.08" lower="0" upper="0.006" />
    </joint>
  <joint name="door_to_button_5" type="prismatic">
    <origin xyz="0.075 -0.695 0.028" rpy="0 0 0" />
    <parent link="door" />
    <child link="button_5" />
    <axis xyz="0 0 -1" />
    <limit effort="4" velocity="0.08" lower="0" upper="0.006" />
    </joint>
  <joint name="door_to_knob" type="continuous">
    <origin xyz="0.195 -0.695 0.028" rpy="0 0 0" />
    <parent link="door" />
    <child link="cycle_knob" />
    <axis xyz="0 0 1" />
    <limit effort="1" velocity="4" />
    </joint>
  <joint name="door_to_cover" type="revolute">
    <origin xyz="-0.14 -0.2625 0.026" rpy="0 0 0" />
    <parent link="door" />
    <child link="detergent_cover" />
    <axis xyz="-1 0 0" />
    <limit effort="1.5" velocity="1.5" lower="0" upper="1.2" />
    </joint>
  <joint name="cabinet_to_lower_rack" type="prismatic">
    <origin xyz="0 -0.02 0.21" rpy="0 0 0" />
    <parent link="cabinet" />
    <child link="lower_rack" />
    <axis xyz="0 -1 0" />
    <limit effort="25" velocity="0.35" lower="0" upper="0.36" />
    </joint>
  <joint name="cabinet_to_upper_rack" type="prismatic">
    <origin xyz="0 -0.02 0.5" rpy="0 0 0" />
    <parent link="cabinet" />
    <child link="upper_rack" />
    <axis xyz="0 -1 0" />
    <limit effort="20" velocity="0.3" lower="0" upper="0.3" />
    </joint>
  <joint name="cabinet_to_lower_spray" type="continuous">
    <origin xyz="0 -0.02 0.165" rpy="0 0 0" />
    <parent link="cabinet" />
    <child link="lower_spray_arm" />
    <axis xyz="0 0 1" />
    <limit effort="0.8" velocity="20" />
    </joint>
  <joint name="cabinet_to_upper_spray" type="continuous">
    <origin xyz="0 -0.02 0.43" rpy="0 0 0" />
    <parent link="cabinet" />
    <child link="upper_spray_arm" />
    <axis xyz="0 0 1" />
    <limit effort="0.8" velocity="20" />
    </joint>
  </robot>
