<robot name="box_style_mechanical_metronome">
  <material name="warm_wood">
    <color rgba="0.46 0.25 0.12 1" />
    </material>
  <material name="dark_front">
    <color rgba="0.16 0.09 0.045 1" />
    </material>
  <material name="brass">
    <color rgba="0.86 0.62 0.23 1" />
    </material>
  <material name="matte_black">
    <color rgba="0.015 0.014 0.013 1" />
    </material>
  <material name="polished_steel">
    <color rgba="0.7 0.7 0.66 1" />
    </material>
  <link name="housing">
    <visual name="base_plinth">
      <origin xyz="0 0 0.013" rpy="0 0 0" />
      <geometry>
        <box size="0.22 0.13 0.026" />
        </geometry>
      <material name="warm_wood">
        <color rgba="0.46 0.25 0.12 1" />
        </material>
      </visual>
    <visual name="upright_box">
      <origin xyz="0 0 0.191" rpy="0 0 0" />
      <geometry>
        <box size="0.18 0.1 0.332" />
        </geometry>
      <material name="warm_wood">
        <color rgba="0.46 0.25 0.12 1" />
        </material>
      </visual>
    <visual name="top_cap">
      <origin xyz="0 0 0.367" rpy="0 0 0" />
      <geometry>
        <box size="0.192 0.112 0.024" />
        </geometry>
      <material name="warm_wood">
        <color rgba="0.46 0.25 0.12 1" />
        </material>
      </visual>
    <visual name="flat_front_face">
      <origin xyz="0 -0.053 0.19" rpy="0 0 0" />
      <geometry>
        <box size="0.156 0.012 0.284" />
        </geometry>
      <material name="dark_front">
        <color rgba="0.16 0.09 0.045 1" />
        </material>
      </visual>
    <visual name="tempo_scale">
      <origin xyz="-0.045 -0.0565 0.218" rpy="0 0 0" />
      <geometry>
        <box size="0.034 0.004 0.184" />
        </geometry>
      <material name="brass">
        <color rgba="0.86 0.62 0.23 1" />
        </material>
      </visual>
    <visual name="scale_tick_0">
      <origin xyz="-0.045 -0.0592 0.144" rpy="0 0 0" />
      <geometry>
        <box size="0.022 0.0025 0.0022" />
        </geometry>
      <material name="matte_black">
        <color rgba="0.015 0.014 0.013 1" />
        </material>
      </visual>
    <visual name="scale_tick_1">
      <origin xyz="-0.045 -0.0592 0.168" rpy="0 0 0" />
      <geometry>
        <box size="0.015 0.0025 0.0022" />
        </geometry>
      <material name="matte_black">
        <color rgba="0.015 0.014 0.013 1" />
        </material>
      </visual>
    <visual name="scale_tick_2">
      <origin xyz="-0.045 -0.0592 0.192" rpy="0 0 0" />
      <geometry>
        <box size="0.022 0.0025 0.0022" />
        </geometry>
      <material name="matte_black">
        <color rgba="0.015 0.014 0.013 1" />
        </material>
      </visual>
    <visual name="scale_tick_3">
      <origin xyz="-0.045 -0.0592 0.216" rpy="0 0 0" />
      <geometry>
        <box size="0.015 0.0025 0.0022" />
        </geometry>
      <material name="matte_black">
        <color rgba="0.015 0.014 0.013 1" />
        </material>
      </visual>
    <visual name="scale_tick_4">
      <origin xyz="-0.045 -0.0592 0.24" rpy="0 0 0" />
      <geometry>
        <box size="0.022 0.0025 0.0022" />
        </geometry>
      <material name="matte_black">
        <color rgba="0.015 0.014 0.013 1" />
        </material>
      </visual>
    <visual name="scale_tick_5">
      <origin xyz="-0.045 -0.0592 0.264" rpy="0 0 0" />
      <geometry>
        <box size="0.015 0.0025 0.0022" />
        </geometry>
      <material name="matte_black">
        <color rgba="0.015 0.014 0.013 1" />
        </material>
      </visual>
    <visual name="scale_tick_6">
      <origin xyz="-0.045 -0.0592 0.288" rpy="0 0 0" />
      <geometry>
        <box size="0.022 0.0025 0.0022" />
        </geometry>
      <material name="matte_black">
        <color rgba="0.015 0.014 0.013 1" />
        </material>
      </visual>
    <visual name="pivot_plate">
      <origin xyz="0 -0.0585 0.235" rpy="0 0 0" />
      <geometry>
        <box size="0.05 0.008 0.05" />
        </geometry>
      <material name="brass">
        <color rgba="0.86 0.62 0.23 1" />
        </material>
      </visual>
    <visual name="pivot_socket">
      <origin xyz="0 -0.064 0.235" rpy="1.5708 0 0" />
      <geometry>
        <cylinder radius="0.017" length="0.01" />
        </geometry>
      <material name="polished_steel">
        <color rgba="0.7 0.7 0.66 1" />
        </material>
      </visual>
    <visual name="side_collar">
      <origin xyz="0.094 0 0.182" rpy="0 1.5708 0" />
      <geometry>
        <cylinder radius="0.016" length="0.014" />
        </geometry>
      <material name="polished_steel">
        <color rgba="0.7 0.7 0.66 1" />
        </material>
      </visual>
    <collision name="base_plinth">
      <origin xyz="0 0 0.013" rpy="0 0 0" />
      <geometry>
        <box size="0.22 0.13 0.026" />
        </geometry>
      </collision>
    <collision name="upright_box">
      <origin xyz="0 0 0.191" rpy="0 0 0" />
      <geometry>
        <box size="0.18 0.1 0.332" />
        </geometry>
      </collision>
    <collision name="top_cap">
      <origin xyz="0 0 0.367" rpy="0 0 0" />
      <geometry>
        <box size="0.192 0.112 0.024" />
        </geometry>
      </collision>
    <collision name="flat_front_face">
      <origin xyz="0 -0.053 0.19" rpy="0 0 0" />
      <geometry>
        <box size="0.156 0.012 0.284" />
        </geometry>
      </collision>
    <collision name="tempo_scale">
      <origin xyz="-0.045 -0.0565 0.218" rpy="0 0 0" />
      <geometry>
        <box size="0.034 0.004 0.184" />
        </geometry>
      </collision>
    <collision name="scale_tick_0">
      <origin xyz="-0.045 -0.0592 0.144" rpy="0 0 0" />
      <geometry>
        <box size="0.022 0.0025 0.0022" />
        </geometry>
      </collision>
    <collision name="scale_tick_1">
      <origin xyz="-0.045 -0.0592 0.168" rpy="0 0 0" />
      <geometry>
        <box size="0.015 0.0025 0.0022" />
        </geometry>
      </collision>
    <collision name="scale_tick_2">
      <origin xyz="-0.045 -0.0592 0.192" rpy="0 0 0" />
      <geometry>
        <box size="0.022 0.0025 0.0022" />
        </geometry>
      </collision>
    <collision name="scale_tick_3">
      <origin xyz="-0.045 -0.0592 0.216" rpy="0 0 0" />
      <geometry>
        <box size="0.015 0.0025 0.0022" />
        </geometry>
      </collision>
    <collision name="scale_tick_4">
      <origin xyz="-0.045 -0.0592 0.24" rpy="0 0 0" />
      <geometry>
        <box size="0.022 0.0025 0.0022" />
        </geometry>
      </collision>
    <collision name="scale_tick_5">
      <origin xyz="-0.045 -0.0592 0.264" rpy="0 0 0" />
      <geometry>
        <box size="0.015 0.0025 0.0022" />
        </geometry>
      </collision>
    <collision name="scale_tick_6">
      <origin xyz="-0.045 -0.0592 0.288" rpy="0 0 0" />
      <geometry>
        <box size="0.022 0.0025 0.0022" />
        </geometry>
      </collision>
    <collision name="pivot_plate">
      <origin xyz="0 -0.0585 0.235" rpy="0 0 0" />
      <geometry>
        <box size="0.05 0.008 0.05" />
        </geometry>
      </collision>
    <collision name="pivot_socket">
      <origin xyz="0 -0.064 0.235" rpy="1.5708 0 0" />
      <geometry>
        <cylinder radius="0.017" length="0.01" />
        </geometry>
      </collision>
    <collision name="side_collar">
      <origin xyz="0.094 0 0.182" rpy="0 1.5708 0" />
      <geometry>
        <cylinder radius="0.016" length="0.014" />
        </geometry>
      </collision>
    </link>
  <link name="pendulum">
    <visual name="rod">
      <origin xyz="0 0 0.1125" rpy="0 0 0" />
      <geometry>
        <cylinder radius="0.0027" length="0.225" />
        </geometry>
      <material name="polished_steel">
        <color rgba="0.7 0.7 0.66 1" />
        </material>
      </visual>
    <visual name="pivot_hub">
      <origin xyz="0 0 0" rpy="1.5708 0 0" />
      <geometry>
        <cylinder radius="0.01" length="0.016" />
        </geometry>
      <material name="polished_steel">
        <color rgba="0.7 0.7 0.66 1" />
        </material>
      </visual>
    <visual name="lower_pointer">
      <origin xyz="0 0 -0.018" rpy="0 0 0" />
      <geometry>
        <box size="0.006 0.004 0.036" />
        </geometry>
      <material name="polished_steel">
        <color rgba="0.7 0.7 0.66 1" />
        </material>
      </visual>
    <collision name="rod">
      <origin xyz="0 0 0.1125" rpy="0 0 0" />
      <geometry>
        <cylinder radius="0.0027" length="0.225" />
        </geometry>
      </collision>
    <collision name="pivot_hub">
      <origin xyz="0 0 0" rpy="1.5708 0 0" />
      <geometry>
        <cylinder radius="0.01" length="0.016" />
        </geometry>
      </collision>
    <collision name="lower_pointer">
      <origin xyz="0 0 -0.018" rpy="0 0 0" />
      <geometry>
        <box size="0.006 0.004 0.036" />
        </geometry>
      </collision>
    </link>
  <link name="weight">
    <visual name="wedge">
      <geometry>
        <mesh filename="assets/meshes/sliding_wedge_weight.obj" />
        </geometry>
      <material name="brass">
        <color rgba="0.86 0.62 0.23 1" />
        </material>
      </visual>
    <visual name="rod_pad_0">
      <origin xyz="-0.00435 0 0" rpy="0 0 0" />
      <geometry>
        <box size="0.0033 0.004 0.028" />
        </geometry>
      <material name="brass">
        <color rgba="0.86 0.62 0.23 1" />
        </material>
      </visual>
    <visual name="rod_pad_1">
      <origin xyz="0.00435 0 0" rpy="0 0 0" />
      <geometry>
        <box size="0.0033 0.004 0.028" />
        </geometry>
      <material name="brass">
        <color rgba="0.86 0.62 0.23 1" />
        </material>
      </visual>
    <collision name="wedge">
      <geometry>
        <mesh filename="assets/meshes/sliding_wedge_weight.obj" />
        </geometry>
      </collision>
    <collision name="rod_pad_0">
      <origin xyz="-0.00435 0 0" rpy="0 0 0" />
      <geometry>
        <box size="0.0033 0.004 0.028" />
        </geometry>
      </collision>
    <collision name="rod_pad_1">
      <origin xyz="0.00435 0 0" rpy="0 0 0" />
      <geometry>
        <box size="0.0033 0.004 0.028" />
        </geometry>
      </collision>
    </link>
  <link name="winding_key">
    <visual name="stem">
      <origin xyz="0.014 0 0" rpy="0 1.5708 0" />
      <geometry>
        <cylinder radius="0.007" length="0.028" />
        </geometry>
      <material name="polished_steel">
        <color rgba="0.7 0.7 0.66 1" />
        </material>
      </visual>
    <visual name="round_key">
      <origin xyz="0.034 0 0" rpy="0 1.5708 0" />
      <geometry>
        <cylinder radius="0.022" length="0.016" />
        </geometry>
      <material name="brass">
        <color rgba="0.86 0.62 0.23 1" />
        </material>
      </visual>
    <visual name="grip_bar">
      <origin xyz="0.043 0 0" rpy="0 0 0" />
      <geometry>
        <box size="0.006 0.05 0.012" />
        </geometry>
      <material name="brass">
        <color rgba="0.86 0.62 0.23 1" />
        </material>
      </visual>
    <collision name="stem">
      <origin xyz="0.014 0 0" rpy="0 1.5708 0" />
      <geometry>
        <cylinder radius="0.007" length="0.028" />
        </geometry>
      </collision>
    <collision name="round_key">
      <origin xyz="0.034 0 0" rpy="0 1.5708 0" />
      <geometry>
        <cylinder radius="0.022" length="0.016" />
        </geometry>
      </collision>
    <collision name="grip_bar">
      <origin xyz="0.043 0 0" rpy="0 0 0" />
      <geometry>
        <box size="0.006 0.05 0.012" />
        </geometry>
      </collision>
    </link>
  <joint name="pendulum_pivot" type="revolute">
    <origin xyz="0 -0.077 0.235" rpy="0 0 0" />
    <parent link="housing" />
    <child link="pendulum" />
    <axis xyz="0 1 0" />
    <limit effort="1" velocity="3" lower="-0.34" upper="0.34" />
    </joint>
  <joint name="weight_slide" type="prismatic">
    <origin xyz="0 0 0.076" rpy="0 0 0" />
    <parent link="pendulum" />
    <child link="weight" />
    <axis xyz="0 0 1" />
    <limit effort="3" velocity="0.15" lower="0" upper="0.105" />
    </joint>
  <joint name="key_rotation" type="continuous">
    <origin xyz="0.101 0 0.182" rpy="0 0 0" />
    <parent link="housing" />
    <child link="winding_key" />
    <axis xyz="1 0 0" />
    <limit effort="0.5" velocity="8" />
    </joint>
  </robot>
