<robot name="car_windshield_sun_visor">
  <material name="warm_gray_roof_liner">
    <color rgba="0.66 0.62 0.54 1" />
    </material>
  <material name="padded_light_gray_fabric">
    <color rgba="0.55 0.56 0.54 1" />
    </material>
  <material name="dark_gray_seam_binding">
    <color rgba="0.23 0.24 0.23 1" />
    </material>
  <material name="satin_black_plastic">
    <color rgba="0.02 0.022 0.02 1" />
    </material>
  <material name="dark_brushed_metal">
    <color rgba="0.34 0.34 0.32 1" />
    </material>
  <material name="muted_warning_label">
    <color rgba="0.82 0.7 0.28 1" />
    </material>
  <link name="roof_bracket">
    <visual name="roof_header">
      <origin xyz="0.22 0 0.07" rpy="0 0 0" />
      <geometry>
        <box size="0.56 0.13 0.018" />
        </geometry>
      <material name="warm_gray_roof_liner">
        <color rgba="0.66 0.62 0.54 1" />
        </material>
      </visual>
    <visual name="mount_plate">
      <origin xyz="0 0 0.052" rpy="0 0 0" />
      <geometry>
        <mesh filename="assets/meshes/rounded_mount_plate.obj" />
        </geometry>
      <material name="satin_black_plastic">
        <color rgba="0.02 0.022 0.02 1" />
        </material>
      </visual>
    <visual name="upper_pivot_boss">
      <origin xyz="0 0 0.0255" rpy="0 0 0" />
      <geometry>
        <cylinder radius="0.028" length="0.035" />
        </geometry>
      <material name="satin_black_plastic">
        <color rgba="0.02 0.022 0.02 1" />
        </material>
      </visual>
    <visual name="screw_head_0">
      <origin xyz="-0.04 0 0.0415" rpy="0 0 0" />
      <geometry>
        <cylinder radius="0.0075" length="0.003" />
        </geometry>
      <material name="dark_brushed_metal">
        <color rgba="0.34 0.34 0.32 1" />
        </material>
      </visual>
    <visual name="screw_head_1">
      <origin xyz="0.04 0 0.0415" rpy="0 0 0" />
      <geometry>
        <cylinder radius="0.0075" length="0.003" />
        </geometry>
      <material name="dark_brushed_metal">
        <color rgba="0.34 0.34 0.32 1" />
        </material>
      </visual>
    <visual name="retainer_bridge">
      <origin xyz="0.425 -0.047 0.055" rpy="0 0 0" />
      <geometry>
        <box size="0.055 0.018 0.012" />
        </geometry>
      <material name="satin_black_plastic">
        <color rgba="0.02 0.022 0.02 1" />
        </material>
      </visual>
    <visual name="retainer_prong_0">
      <origin xyz="0.404 -0.047 0.032" rpy="0 0 0" />
      <geometry>
        <box size="0.01 0.012 0.034" />
        </geometry>
      <material name="satin_black_plastic">
        <color rgba="0.02 0.022 0.02 1" />
        </material>
      </visual>
    <visual name="retainer_prong_1">
      <origin xyz="0.446 -0.047 0.032" rpy="0 0 0" />
      <geometry>
        <box size="0.01 0.012 0.034" />
        </geometry>
      <material name="satin_black_plastic">
        <color rgba="0.02 0.022 0.02 1" />
        </material>
      </visual>
    <collision name="roof_header">
      <origin xyz="0.22 0 0.07" rpy="0 0 0" />
      <geometry>
        <box size="0.56 0.13 0.018" />
        </geometry>
      </collision>
    <collision name="mount_plate">
      <origin xyz="0 0 0.052" rpy="0 0 0" />
      <geometry>
        <mesh filename="assets/meshes/rounded_mount_plate.obj" />
        </geometry>
      </collision>
    <collision name="upper_pivot_boss">
      <origin xyz="0 0 0.0255" rpy="0 0 0" />
      <geometry>
        <cylinder radius="0.028" length="0.035" />
        </geometry>
      </collision>
    <collision name="screw_head_0">
      <origin xyz="-0.04 0 0.0415" rpy="0 0 0" />
      <geometry>
        <cylinder radius="0.0075" length="0.003" />
        </geometry>
      </collision>
    <collision name="screw_head_1">
      <origin xyz="0.04 0 0.0415" rpy="0 0 0" />
      <geometry>
        <cylinder radius="0.0075" length="0.003" />
        </geometry>
      </collision>
    <collision name="retainer_bridge">
      <origin xyz="0.425 -0.047 0.055" rpy="0 0 0" />
      <geometry>
        <box size="0.055 0.018 0.012" />
        </geometry>
      </collision>
    <collision name="retainer_prong_0">
      <origin xyz="0.404 -0.047 0.032" rpy="0 0 0" />
      <geometry>
        <box size="0.01 0.012 0.034" />
        </geometry>
      </collision>
    <collision name="retainer_prong_1">
      <origin xyz="0.446 -0.047 0.032" rpy="0 0 0" />
      <geometry>
        <box size="0.01 0.012 0.034" />
        </geometry>
      </collision>
    </link>
  <link name="pivot_arm">
    <visual name="vertical_pivot_pin">
      <origin xyz="0 0 -0.0175" rpy="0 0 0" />
      <geometry>
        <cylinder radius="0.019" length="0.035" />
        </geometry>
      <material name="dark_brushed_metal">
        <color rgba="0.34 0.34 0.32 1" />
        </material>
      </visual>
    <visual name="drop_post">
      <origin xyz="0 0 -0.025" rpy="0 0 0" />
      <geometry>
        <cylinder radius="0.014" length="0.05" />
        </geometry>
      <material name="satin_black_plastic">
        <color rgba="0.02 0.022 0.02 1" />
        </material>
      </visual>
    <visual name="offset_arm">
      <origin xyz="0 -0.031 -0.05" rpy="0 0 0" />
      <geometry>
        <box size="0.024 0.062 0.016" />
        </geometry>
      <material name="satin_black_plastic">
        <color rgba="0.02 0.022 0.02 1" />
        </material>
      </visual>
    <visual name="hinge_pin">
      <origin xyz="0.215 -0.055 -0.05" rpy="0 1.5708 0" />
      <geometry>
        <cylinder radius="0.008" length="0.472" />
        </geometry>
      <material name="dark_brushed_metal">
        <color rgba="0.34 0.34 0.32 1" />
        </material>
      </visual>
    <visual name="hinge_end_knuckle">
      <origin xyz="0 -0.055 -0.05" rpy="0 1.5708 0" />
      <geometry>
        <cylinder radius="0.015" length="0.03" />
        </geometry>
      <material name="satin_black_plastic">
        <color rgba="0.02 0.022 0.02 1" />
        </material>
      </visual>
    <collision name="vertical_pivot_pin">
      <origin xyz="0 0 -0.0175" rpy="0 0 0" />
      <geometry>
        <cylinder radius="0.019" length="0.035" />
        </geometry>
      </collision>
    <collision name="drop_post">
      <origin xyz="0 0 -0.025" rpy="0 0 0" />
      <geometry>
        <cylinder radius="0.014" length="0.05" />
        </geometry>
      </collision>
    <collision name="offset_arm">
      <origin xyz="0 -0.031 -0.05" rpy="0 0 0" />
      <geometry>
        <box size="0.024 0.062 0.016" />
        </geometry>
      </collision>
    <collision name="hinge_pin">
      <origin xyz="0.215 -0.055 -0.05" rpy="0 1.5708 0" />
      <geometry>
        <cylinder radius="0.008" length="0.472" />
        </geometry>
      </collision>
    <collision name="hinge_end_knuckle">
      <origin xyz="0 -0.055 -0.05" rpy="0 1.5708 0" />
      <geometry>
        <cylinder radius="0.015" length="0.03" />
        </geometry>
      </collision>
    </link>
  <link name="visor_panel">
    <visual name="padded_panel">
      <origin xyz="0.215 0.045 -0.105" rpy="0 0 0" />
      <geometry>
        <mesh filename="assets/meshes/rounded_padded_visor.obj" />
        </geometry>
      <material name="padded_light_gray_fabric">
        <color rgba="0.55 0.56 0.54 1" />
        </material>
      </visual>
    <visual name="warning_label">
      <origin xyz="0.235 0.031 -0.164" rpy="0 0 0" />
      <geometry>
        <box size="0.36 0.003 0.012" />
        </geometry>
      <material name="muted_warning_label">
        <color rgba="0.82 0.7 0.28 1" />
        </material>
      </visual>
    <visual name="top_binding">
      <origin xyz="0.215 0.031 -0.022" rpy="0 0 0" />
      <geometry>
        <box size="0.395 0.004 0.008" />
        </geometry>
      <material name="dark_gray_seam_binding">
        <color rgba="0.23 0.24 0.23 1" />
        </material>
      </visual>
    <visual name="bottom_binding">
      <origin xyz="0.215 0.031 -0.188" rpy="0 0 0" />
      <geometry>
        <box size="0.395 0.004 0.008" />
        </geometry>
      <material name="dark_gray_seam_binding">
        <color rgba="0.23 0.24 0.23 1" />
        </material>
      </visual>
    <visual name="end_binding_0">
      <origin xyz="0.018 0.031 -0.105" rpy="0 0 0" />
      <geometry>
        <box size="0.008 0.004 0.152" />
        </geometry>
      <material name="dark_gray_seam_binding">
        <color rgba="0.23 0.24 0.23 1" />
        </material>
      </visual>
    <visual name="end_binding_1">
      <origin xyz="0.412 0.031 -0.105" rpy="0 0 0" />
      <geometry>
        <box size="0.008 0.004 0.152" />
        </geometry>
      <material name="dark_gray_seam_binding">
        <color rgba="0.23 0.24 0.23 1" />
        </material>
      </visual>
    <visual name="hinge_sleeve_0">
      <origin xyz="0.058 0 0" rpy="0 1.5708 0" />
      <geometry>
        <cylinder radius="0.014" length="0.07" />
        </geometry>
      <material name="satin_black_plastic">
        <color rgba="0.02 0.022 0.02 1" />
        </material>
      </visual>
    <visual name="hinge_leaf_0">
      <origin xyz="0.058 0.027 -0.0165" rpy="0 0 0" />
      <geometry>
        <box size="0.044 0.034 0.019" />
        </geometry>
      <material name="satin_black_plastic">
        <color rgba="0.02 0.022 0.02 1" />
        </material>
      </visual>
    <visual name="hinge_sleeve_1">
      <origin xyz="0.215 0 0" rpy="0 1.5708 0" />
      <geometry>
        <cylinder radius="0.014" length="0.07" />
        </geometry>
      <material name="satin_black_plastic">
        <color rgba="0.02 0.022 0.02 1" />
        </material>
      </visual>
    <visual name="hinge_leaf_1">
      <origin xyz="0.215 0.027 -0.0165" rpy="0 0 0" />
      <geometry>
        <box size="0.044 0.034 0.019" />
        </geometry>
      <material name="satin_black_plastic">
        <color rgba="0.02 0.022 0.02 1" />
        </material>
      </visual>
    <visual name="hinge_sleeve_2">
      <origin xyz="0.372 0 0" rpy="0 1.5708 0" />
      <geometry>
        <cylinder radius="0.014" length="0.07" />
        </geometry>
      <material name="satin_black_plastic">
        <color rgba="0.02 0.022 0.02 1" />
        </material>
      </visual>
    <visual name="hinge_leaf_2">
      <origin xyz="0.372 0.027 -0.0165" rpy="0 0 0" />
      <geometry>
        <box size="0.044 0.034 0.019" />
        </geometry>
      <material name="satin_black_plastic">
        <color rgba="0.02 0.022 0.02 1" />
        </material>
      </visual>
    <collision name="padded_panel">
      <origin xyz="0.215 0.045 -0.105" rpy="0 0 0" />
      <geometry>
        <mesh filename="assets/meshes/rounded_padded_visor.obj" />
        </geometry>
      </collision>
    <collision name="warning_label">
      <origin xyz="0.235 0.031 -0.164" rpy="0 0 0" />
      <geometry>
        <box size="0.36 0.003 0.012" />
        </geometry>
      </collision>
    <collision name="top_binding">
      <origin xyz="0.215 0.031 -0.022" rpy="0 0 0" />
      <geometry>
        <box size="0.395 0.004 0.008" />
        </geometry>
      </collision>
    <collision name="bottom_binding">
      <origin xyz="0.215 0.031 -0.188" rpy="0 0 0" />
      <geometry>
        <box size="0.395 0.004 0.008" />
        </geometry>
      </collision>
    <collision name="end_binding_0">
      <origin xyz="0.018 0.031 -0.105" rpy="0 0 0" />
      <geometry>
        <box size="0.008 0.004 0.152" />
        </geometry>
      </collision>
    <collision name="end_binding_1">
      <origin xyz="0.412 0.031 -0.105" rpy="0 0 0" />
      <geometry>
        <box size="0.008 0.004 0.152" />
        </geometry>
      </collision>
    <collision name="hinge_sleeve_0">
      <origin xyz="0.058 0 0" rpy="0 1.5708 0" />
      <geometry>
        <cylinder radius="0.014" length="0.07" />
        </geometry>
      </collision>
    <collision name="hinge_leaf_0">
      <origin xyz="0.058 0.027 -0.0165" rpy="0 0 0" />
      <geometry>
        <box size="0.044 0.034 0.019" />
        </geometry>
      </collision>
    <collision name="hinge_sleeve_1">
      <origin xyz="0.215 0 0" rpy="0 1.5708 0" />
      <geometry>
        <cylinder radius="0.014" length="0.07" />
        </geometry>
      </collision>
    <collision name="hinge_leaf_1">
      <origin xyz="0.215 0.027 -0.0165" rpy="0 0 0" />
      <geometry>
        <box size="0.044 0.034 0.019" />
        </geometry>
      </collision>
    <collision name="hinge_sleeve_2">
      <origin xyz="0.372 0 0" rpy="0 1.5708 0" />
      <geometry>
        <cylinder radius="0.014" length="0.07" />
        </geometry>
      </collision>
    <collision name="hinge_leaf_2">
      <origin xyz="0.372 0.027 -0.0165" rpy="0 0 0" />
      <geometry>
        <box size="0.044 0.034 0.019" />
        </geometry>
      </collision>
    </link>
  <joint name="side_pivot" type="revolute">
    <origin xyz="0 0 0.008" rpy="0 0 0" />
    <parent link="roof_bracket" />
    <child link="pivot_arm" />
    <axis xyz="0 0 1" />
    <limit effort="8" velocity="2" lower="0" upper="1.55" />
    </joint>
  <joint name="flip_hinge" type="revolute">
    <origin xyz="0 -0.055 -0.05" rpy="0 0 0" />
    <parent link="pivot_arm" />
    <child link="visor_panel" />
    <axis xyz="1 0 0" />
    <limit effort="5" velocity="2.5" lower="0" upper="1.25" />
    </joint>
  </robot>
