<robot name="rugged_watch_winder_box">
  <material name="molded_olive_polymer">
    <color rgba="0.18 0.22 0.16 1" />
    </material>
  <material name="black_rubber_bumpers">
    <color rgba="0.015 0.016 0.014 1" />
    </material>
  <material name="matte_black_insert">
    <color rgba="0.025 0.026 0.024 1" />
    </material>
  <material name="dark_gunmetal_hardware">
    <color rgba="0.26 0.27 0.26 1" />
    </material>
  <material name="brushed_steel_fasteners">
    <color rgba="0.62 0.62 0.58 1" />
    </material>
  <material name="smoked_polycarbonate_window">
    <color rgba="0.3 0.42 0.48 0.34" />
    </material>
  <material name="black_watch_cushion">
    <color rgba="0.005 0.005 0.006 1" />
    </material>
  <material name="amber_status_lens">
    <color rgba="1 0.55 0.08 0.88" />
    </material>
  <link name="case">
    <visual name="bottom_pan">
      <origin xyz="0 0 0.009" rpy="0 0 0" />
      <geometry>
        <box size="0.36 0.26 0.018" />
        </geometry>
      <material name="molded_olive_polymer">
        <color rgba="0.18 0.22 0.16 1" />
        </material>
      </visual>
    <visual name="side_wall_0">
      <origin xyz="-0.171 0 0.06" rpy="0 0 0" />
      <geometry>
        <box size="0.018 0.26 0.12" />
        </geometry>
      <material name="molded_olive_polymer">
        <color rgba="0.18 0.22 0.16 1" />
        </material>
      </visual>
    <visual name="side_wall_1">
      <origin xyz="0.171 0 0.06" rpy="0 0 0" />
      <geometry>
        <box size="0.018 0.26 0.12" />
        </geometry>
      <material name="molded_olive_polymer">
        <color rgba="0.18 0.22 0.16 1" />
        </material>
      </visual>
    <visual name="front_wall">
      <origin xyz="0 -0.121 0.06" rpy="0 0 0" />
      <geometry>
        <box size="0.36 0.018 0.12" />
        </geometry>
      <material name="molded_olive_polymer">
        <color rgba="0.18 0.22 0.16 1" />
        </material>
      </visual>
    <visual name="rear_wall">
      <origin xyz="0 0.121 0.06" rpy="0 0 0" />
      <geometry>
        <box size="0.36 0.018 0.12" />
        </geometry>
      <material name="molded_olive_polymer">
        <color rgba="0.18 0.22 0.16 1" />
        </material>
      </visual>
    <visual name="front_top_rim">
      <origin xyz="0 -0.117 0.1275" rpy="0 0 0" />
      <geometry>
        <box size="0.36 0.026 0.015" />
        </geometry>
      <material name="molded_olive_polymer">
        <color rgba="0.18 0.22 0.16 1" />
        </material>
      </visual>
    <visual name="rear_top_rim">
      <origin xyz="0 0.117 0.1275" rpy="0 0 0" />
      <geometry>
        <box size="0.36 0.026 0.015" />
        </geometry>
      <material name="molded_olive_polymer">
        <color rgba="0.18 0.22 0.16 1" />
        </material>
      </visual>
    <visual name="side_top_rim_0">
      <origin xyz="-0.167 0 0.1275" rpy="0 0 0" />
      <geometry>
        <box size="0.026 0.26 0.015" />
        </geometry>
      <material name="molded_olive_polymer">
        <color rgba="0.18 0.22 0.16 1" />
        </material>
      </visual>
    <visual name="side_top_rim_1">
      <origin xyz="0.167 0 0.1275" rpy="0 0 0" />
      <geometry>
        <box size="0.026 0.26 0.015" />
        </geometry>
      <material name="molded_olive_polymer">
        <color rgba="0.18 0.22 0.16 1" />
        </material>
      </visual>
    <visual name="front_gasket">
      <origin xyz="0 -0.105 0.136" rpy="0 0 0" />
      <geometry>
        <box size="0.25 0.01 0.004" />
        </geometry>
      <material name="black_rubber_bumpers">
        <color rgba="0.015 0.016 0.014 1" />
        </material>
      </visual>
    <visual name="rear_gasket">
      <origin xyz="0 0.105 0.136" rpy="0 0 0" />
      <geometry>
        <box size="0.25 0.01 0.004" />
        </geometry>
      <material name="black_rubber_bumpers">
        <color rgba="0.015 0.016 0.014 1" />
        </material>
      </visual>
    <visual name="side_gasket_0">
      <origin xyz="-0.155 0 0.136" rpy="0 0 0" />
      <geometry>
        <box size="0.01 0.17 0.004" />
        </geometry>
      <material name="black_rubber_bumpers">
        <color rgba="0.015 0.016 0.014 1" />
        </material>
      </visual>
    <visual name="side_gasket_1">
      <origin xyz="0.155 0 0.136" rpy="0 0 0" />
      <geometry>
        <box size="0.01 0.17 0.004" />
        </geometry>
      <material name="black_rubber_bumpers">
        <color rgba="0.015 0.016 0.014 1" />
        </material>
      </visual>
    <visual name="corner_guard_0_0">
      <origin xyz="-0.163 -0.113 0.067" rpy="0 0 0" />
      <geometry>
        <box size="0.034 0.034 0.134" />
        </geometry>
      <material name="black_rubber_bumpers">
        <color rgba="0.015 0.016 0.014 1" />
        </material>
      </visual>
    <visual name="corner_guard_0_1">
      <origin xyz="-0.163 0.113 0.067" rpy="0 0 0" />
      <geometry>
        <box size="0.034 0.034 0.134" />
        </geometry>
      <material name="black_rubber_bumpers">
        <color rgba="0.015 0.016 0.014 1" />
        </material>
      </visual>
    <visual name="corner_guard_1_0">
      <origin xyz="0.163 -0.113 0.067" rpy="0 0 0" />
      <geometry>
        <box size="0.034 0.034 0.134" />
        </geometry>
      <material name="black_rubber_bumpers">
        <color rgba="0.015 0.016 0.014 1" />
        </material>
      </visual>
    <visual name="corner_guard_1_1">
      <origin xyz="0.163 0.113 0.067" rpy="0 0 0" />
      <geometry>
        <box size="0.034 0.034 0.134" />
        </geometry>
      <material name="black_rubber_bumpers">
        <color rgba="0.015 0.016 0.014 1" />
        </material>
      </visual>
    <visual name="floor_rail_n">
      <origin xyz="-0.095 0 0.023" rpy="0 0 0" />
      <geometry>
        <box size="0.018 0.21 0.01" />
        </geometry>
      <material name="matte_black_insert">
        <color rgba="0.025 0.026 0.024 1" />
        </material>
      </visual>
    <visual name="floor_rail_p">
      <origin xyz="0.095 0 0.023" rpy="0 0 0" />
      <geometry>
        <box size="0.018 0.21 0.01" />
        </geometry>
      <material name="matte_black_insert">
        <color rgba="0.025 0.026 0.024 1" />
        </material>
      </visual>
    <visual name="motor_stand">
      <origin xyz="0 0.025 0.047" rpy="0 0 0" />
      <geometry>
        <box size="0.115 0.045 0.058" />
        </geometry>
      <material name="matte_black_insert">
        <color rgba="0.025 0.026 0.024 1" />
        </material>
      </visual>
    <visual name="motor_pod">
      <origin xyz="0 0.01 0.078" rpy="1.5708 0 0" />
      <geometry>
        <cylinder radius="0.039" length="0.035" />
        </geometry>
      <material name="dark_gunmetal_hardware">
        <color rgba="0.26 0.27 0.26 1" />
        </material>
      </visual>
    <visual name="bearing_face">
      <origin xyz="0 -0.009 0.078" rpy="1.5708 0 0" />
      <geometry>
        <cylinder radius="0.018" length="0.006" />
        </geometry>
      <material name="brushed_steel_fasteners">
        <color rgba="0.62 0.62 0.58 1" />
        </material>
      </visual>
    <visual name="case_hinge_leaf">
      <origin xyz="0 0.133 0.112" rpy="0 0 0" />
      <geometry>
        <box size="0.31 0.006 0.04" />
        </geometry>
      <material name="dark_gunmetal_hardware">
        <color rgba="0.26 0.27 0.26 1" />
        </material>
      </visual>
    <visual name="case_knuckle_0">
      <origin xyz="-0.138 0.136 0.139" rpy="0 1.5708 0" />
      <geometry>
        <cylinder radius="0.008" length="0.068" />
        </geometry>
      <material name="dark_gunmetal_hardware">
        <color rgba="0.26 0.27 0.26 1" />
        </material>
      </visual>
    <visual name="case_knuckle_1">
      <origin xyz="0 0.136 0.139" rpy="0 1.5708 0" />
      <geometry>
        <cylinder radius="0.008" length="0.068" />
        </geometry>
      <material name="dark_gunmetal_hardware">
        <color rgba="0.26 0.27 0.26 1" />
        </material>
      </visual>
    <visual name="case_knuckle_2">
      <origin xyz="0.138 0.136 0.139" rpy="0 1.5708 0" />
      <geometry>
        <cylinder radius="0.008" length="0.068" />
        </geometry>
      <material name="dark_gunmetal_hardware">
        <color rgba="0.26 0.27 0.26 1" />
        </material>
      </visual>
    <visual name="pin_head_n">
      <origin xyz="-0.177 0.136 0.139" rpy="0 1.5708 0" />
      <geometry>
        <cylinder radius="0.01" length="0.01" />
        </geometry>
      <material name="brushed_steel_fasteners">
        <color rgba="0.62 0.62 0.58 1" />
        </material>
      </visual>
    <visual name="pin_head_p">
      <origin xyz="0.177 0.136 0.139" rpy="0 1.5708 0" />
      <geometry>
        <cylinder radius="0.01" length="0.01" />
        </geometry>
      <material name="brushed_steel_fasteners">
        <color rgba="0.62 0.62 0.58 1" />
        </material>
      </visual>
    <visual name="latch_lug_n">
      <origin xyz="-0.034 -0.136 0.076" rpy="0 1.5708 0" />
      <geometry>
        <cylinder radius="0.006" length="0.02" />
        </geometry>
      <material name="dark_gunmetal_hardware">
        <color rgba="0.26 0.27 0.26 1" />
        </material>
      </visual>
    <visual name="latch_bracket_n">
      <origin xyz="-0.034 -0.132 0.072" rpy="0 0 0" />
      <geometry>
        <box size="0.02 0.01 0.022" />
        </geometry>
      <material name="dark_gunmetal_hardware">
        <color rgba="0.26 0.27 0.26 1" />
        </material>
      </visual>
    <visual name="latch_lug_p">
      <origin xyz="0.034 -0.136 0.076" rpy="0 1.5708 0" />
      <geometry>
        <cylinder radius="0.006" length="0.02" />
        </geometry>
      <material name="dark_gunmetal_hardware">
        <color rgba="0.26 0.27 0.26 1" />
        </material>
      </visual>
    <visual name="latch_bracket_p">
      <origin xyz="0.034 -0.132 0.072" rpy="0 0 0" />
      <geometry>
        <box size="0.02 0.01 0.022" />
        </geometry>
      <material name="dark_gunmetal_hardware">
        <color rgba="0.26 0.27 0.26 1" />
        </material>
      </visual>
    <visual name="control_plate">
      <origin xyz="-0.096 -0.132 0.05" rpy="0 0 0" />
      <geometry>
        <box size="0.105 0.004 0.04" />
        </geometry>
      <material name="matte_black_insert">
        <color rgba="0.025 0.026 0.024 1" />
        </material>
      </visual>
    <visual name="status_lens">
      <origin xyz="-0.05 -0.134 0.055" rpy="1.5708 0 0" />
      <geometry>
        <cylinder radius="0.008" length="0.004" />
        </geometry>
      <material name="amber_status_lens">
        <color rgba="1 0.55 0.08 0.88" />
        </material>
      </visual>
    <visual name="knob_bushing">
      <origin xyz="-0.115 -0.1335 0.055" rpy="1.5708 0 0" />
      <geometry>
        <cylinder radius="0.02" length="0.006" />
        </geometry>
      <material name="dark_gunmetal_hardware">
        <color rgba="0.26 0.27 0.26 1" />
        </material>
      </visual>
    <visual name="front_screw_-0.14_0.04">
      <origin xyz="-0.145 -0.1308 0.04" rpy="1.5708 0 0" />
      <geometry>
        <cylinder radius="0.005" length="0.003" />
        </geometry>
      <material name="brushed_steel_fasteners">
        <color rgba="0.62 0.62 0.58 1" />
        </material>
      </visual>
    <visual name="front_screw_-0.14_0.10">
      <origin xyz="-0.145 -0.1308 0.105" rpy="1.5708 0 0" />
      <geometry>
        <cylinder radius="0.005" length="0.003" />
        </geometry>
      <material name="brushed_steel_fasteners">
        <color rgba="0.62 0.62 0.58 1" />
        </material>
      </visual>
    <visual name="front_screw_0.14_0.04">
      <origin xyz="0.145 -0.1308 0.04" rpy="1.5708 0 0" />
      <geometry>
        <cylinder radius="0.005" length="0.003" />
        </geometry>
      <material name="brushed_steel_fasteners">
        <color rgba="0.62 0.62 0.58 1" />
        </material>
      </visual>
    <visual name="front_screw_0.14_0.10">
      <origin xyz="0.145 -0.1308 0.105" rpy="1.5708 0 0" />
      <geometry>
        <cylinder radius="0.005" length="0.003" />
        </geometry>
      <material name="brushed_steel_fasteners">
        <color rgba="0.62 0.62 0.58 1" />
        </material>
      </visual>
    <collision name="bottom_pan">
      <origin xyz="0 0 0.009" rpy="0 0 0" />
      <geometry>
        <box size="0.36 0.26 0.018" />
        </geometry>
      </collision>
    <collision name="side_wall_0">
      <origin xyz="-0.171 0 0.06" rpy="0 0 0" />
      <geometry>
        <box size="0.018 0.26 0.12" />
        </geometry>
      </collision>
    <collision name="side_wall_1">
      <origin xyz="0.171 0 0.06" rpy="0 0 0" />
      <geometry>
        <box size="0.018 0.26 0.12" />
        </geometry>
      </collision>
    <collision name="front_wall">
      <origin xyz="0 -0.121 0.06" rpy="0 0 0" />
      <geometry>
        <box size="0.36 0.018 0.12" />
        </geometry>
      </collision>
    <collision name="rear_wall">
      <origin xyz="0 0.121 0.06" rpy="0 0 0" />
      <geometry>
        <box size="0.36 0.018 0.12" />
        </geometry>
      </collision>
    <collision name="front_top_rim">
      <origin xyz="0 -0.117 0.1275" rpy="0 0 0" />
      <geometry>
        <box size="0.36 0.026 0.015" />
        </geometry>
      </collision>
    <collision name="rear_top_rim">
      <origin xyz="0 0.117 0.1275" rpy="0 0 0" />
      <geometry>
        <box size="0.36 0.026 0.015" />
        </geometry>
      </collision>
    <collision name="side_top_rim_0">
      <origin xyz="-0.167 0 0.1275" rpy="0 0 0" />
      <geometry>
        <box size="0.026 0.26 0.015" />
        </geometry>
      </collision>
    <collision name="side_top_rim_1">
      <origin xyz="0.167 0 0.1275" rpy="0 0 0" />
      <geometry>
        <box size="0.026 0.26 0.015" />
        </geometry>
      </collision>
    <collision name="front_gasket">
      <origin xyz="0 -0.105 0.136" rpy="0 0 0" />
      <geometry>
        <box size="0.25 0.01 0.004" />
        </geometry>
      </collision>
    <collision name="rear_gasket">
      <origin xyz="0 0.105 0.136" rpy="0 0 0" />
      <geometry>
        <box size="0.25 0.01 0.004" />
        </geometry>
      </collision>
    <collision name="side_gasket_0">
      <origin xyz="-0.155 0 0.136" rpy="0 0 0" />
      <geometry>
        <box size="0.01 0.17 0.004" />
        </geometry>
      </collision>
    <collision name="side_gasket_1">
      <origin xyz="0.155 0 0.136" rpy="0 0 0" />
      <geometry>
        <box size="0.01 0.17 0.004" />
        </geometry>
      </collision>
    <collision name="corner_guard_0_0">
      <origin xyz="-0.163 -0.113 0.067" rpy="0 0 0" />
      <geometry>
        <box size="0.034 0.034 0.134" />
        </geometry>
      </collision>
    <collision name="corner_guard_0_1">
      <origin xyz="-0.163 0.113 0.067" rpy="0 0 0" />
      <geometry>
        <box size="0.034 0.034 0.134" />
        </geometry>
      </collision>
    <collision name="corner_guard_1_0">
      <origin xyz="0.163 -0.113 0.067" rpy="0 0 0" />
      <geometry>
        <box size="0.034 0.034 0.134" />
        </geometry>
      </collision>
    <collision name="corner_guard_1_1">
      <origin xyz="0.163 0.113 0.067" rpy="0 0 0" />
      <geometry>
        <box size="0.034 0.034 0.134" />
        </geometry>
      </collision>
    <collision name="floor_rail_n">
      <origin xyz="-0.095 0 0.023" rpy="0 0 0" />
      <geometry>
        <box size="0.018 0.21 0.01" />
        </geometry>
      </collision>
    <collision name="floor_rail_p">
      <origin xyz="0.095 0 0.023" rpy="0 0 0" />
      <geometry>
        <box size="0.018 0.21 0.01" />
        </geometry>
      </collision>
    <collision name="motor_stand">
      <origin xyz="0 0.025 0.047" rpy="0 0 0" />
      <geometry>
        <box size="0.115 0.045 0.058" />
        </geometry>
      </collision>
    <collision name="motor_pod">
      <origin xyz="0 0.01 0.078" rpy="1.5708 0 0" />
      <geometry>
        <cylinder radius="0.039" length="0.035" />
        </geometry>
      </collision>
    <collision name="bearing_face">
      <origin xyz="0 -0.009 0.078" rpy="1.5708 0 0" />
      <geometry>
        <cylinder radius="0.018" length="0.006" />
        </geometry>
      </collision>
    <collision name="case_hinge_leaf">
      <origin xyz="0 0.133 0.112" rpy="0 0 0" />
      <geometry>
        <box size="0.31 0.006 0.04" />
        </geometry>
      </collision>
    <collision name="case_knuckle_0">
      <origin xyz="-0.138 0.136 0.139" rpy="0 1.5708 0" />
      <geometry>
        <cylinder radius="0.008" length="0.068" />
        </geometry>
      </collision>
    <collision name="case_knuckle_1">
      <origin xyz="0 0.136 0.139" rpy="0 1.5708 0" />
      <geometry>
        <cylinder radius="0.008" length="0.068" />
        </geometry>
      </collision>
    <collision name="case_knuckle_2">
      <origin xyz="0.138 0.136 0.139" rpy="0 1.5708 0" />
      <geometry>
        <cylinder radius="0.008" length="0.068" />
        </geometry>
      </collision>
    <collision name="pin_head_n">
      <origin xyz="-0.177 0.136 0.139" rpy="0 1.5708 0" />
      <geometry>
        <cylinder radius="0.01" length="0.01" />
        </geometry>
      </collision>
    <collision name="pin_head_p">
      <origin xyz="0.177 0.136 0.139" rpy="0 1.5708 0" />
      <geometry>
        <cylinder radius="0.01" length="0.01" />
        </geometry>
      </collision>
    <collision name="latch_lug_n">
      <origin xyz="-0.034 -0.136 0.076" rpy="0 1.5708 0" />
      <geometry>
        <cylinder radius="0.006" length="0.02" />
        </geometry>
      </collision>
    <collision name="latch_bracket_n">
      <origin xyz="-0.034 -0.132 0.072" rpy="0 0 0" />
      <geometry>
        <box size="0.02 0.01 0.022" />
        </geometry>
      </collision>
    <collision name="latch_lug_p">
      <origin xyz="0.034 -0.136 0.076" rpy="0 1.5708 0" />
      <geometry>
        <cylinder radius="0.006" length="0.02" />
        </geometry>
      </collision>
    <collision name="latch_bracket_p">
      <origin xyz="0.034 -0.132 0.072" rpy="0 0 0" />
      <geometry>
        <box size="0.02 0.01 0.022" />
        </geometry>
      </collision>
    <collision name="control_plate">
      <origin xyz="-0.096 -0.132 0.05" rpy="0 0 0" />
      <geometry>
        <box size="0.105 0.004 0.04" />
        </geometry>
      </collision>
    <collision name="status_lens">
      <origin xyz="-0.05 -0.134 0.055" rpy="1.5708 0 0" />
      <geometry>
        <cylinder radius="0.008" length="0.004" />
        </geometry>
      </collision>
    <collision name="knob_bushing">
      <origin xyz="-0.115 -0.1335 0.055" rpy="1.5708 0 0" />
      <geometry>
        <cylinder radius="0.02" length="0.006" />
        </geometry>
      </collision>
    <collision name="front_screw_-0.14_0.04">
      <origin xyz="-0.145 -0.1308 0.04" rpy="1.5708 0 0" />
      <geometry>
        <cylinder radius="0.005" length="0.003" />
        </geometry>
      </collision>
    <collision name="front_screw_-0.14_0.10">
      <origin xyz="-0.145 -0.1308 0.105" rpy="1.5708 0 0" />
      <geometry>
        <cylinder radius="0.005" length="0.003" />
        </geometry>
      </collision>
    <collision name="front_screw_0.14_0.04">
      <origin xyz="0.145 -0.1308 0.04" rpy="1.5708 0 0" />
      <geometry>
        <cylinder radius="0.005" length="0.003" />
        </geometry>
      </collision>
    <collision name="front_screw_0.14_0.10">
      <origin xyz="0.145 -0.1308 0.105" rpy="1.5708 0 0" />
      <geometry>
        <cylinder radius="0.005" length="0.003" />
        </geometry>
      </collision>
    </link>
  <link name="lid">
    <visual name="side_frame_0">
      <origin xyz="-0.174 -0.143 0.012" rpy="0 0 0" />
      <geometry>
        <box size="0.034 0.244 0.024" />
        </geometry>
      <material name="molded_olive_polymer">
        <color rgba="0.18 0.22 0.16 1" />
        </material>
      </visual>
    <visual name="side_frame_1">
      <origin xyz="0.174 -0.143 0.012" rpy="0 0 0" />
      <geometry>
        <box size="0.034 0.244 0.024" />
        </geometry>
      <material name="molded_olive_polymer">
        <color rgba="0.18 0.22 0.16 1" />
        </material>
      </visual>
    <visual name="front_frame">
      <origin xyz="0 -0.256 0.012" rpy="0 0 0" />
      <geometry>
        <box size="0.382 0.036 0.024" />
        </geometry>
      <material name="molded_olive_polymer">
        <color rgba="0.18 0.22 0.16 1" />
        </material>
      </visual>
    <visual name="rear_frame">
      <origin xyz="0 -0.02 0.012" rpy="0 0 0" />
      <geometry>
        <box size="0.382 0.024 0.024" />
        </geometry>
      <material name="molded_olive_polymer">
        <color rgba="0.18 0.22 0.16 1" />
        </material>
      </visual>
    <visual name="window_pane">
      <origin xyz="0 -0.142 0.012" rpy="0 0 0" />
      <geometry>
        <box size="0.32 0.21 0.006" />
        </geometry>
      <material name="smoked_polycarbonate_window">
        <color rgba="0.3 0.42 0.48 0.34" />
        </material>
      </visual>
    <visual name="window_bar_-0.09">
      <origin xyz="-0.09 -0.142 0.0175" rpy="0 0 0" />
      <geometry>
        <box size="0.007 0.16 0.006" />
        </geometry>
      <material name="dark_gunmetal_hardware">
        <color rgba="0.26 0.27 0.26 1" />
        </material>
      </visual>
    <visual name="window_bar_0.00">
      <origin xyz="0 -0.142 0.0175" rpy="0 0 0" />
      <geometry>
        <box size="0.007 0.16 0.006" />
        </geometry>
      <material name="dark_gunmetal_hardware">
        <color rgba="0.26 0.27 0.26 1" />
        </material>
      </visual>
    <visual name="window_bar_0.09">
      <origin xyz="0.09 -0.142 0.0175" rpy="0 0 0" />
      <geometry>
        <box size="0.007 0.16 0.006" />
        </geometry>
      <material name="dark_gunmetal_hardware">
        <color rgba="0.26 0.27 0.26 1" />
        </material>
      </visual>
    <visual name="cross_bar_-0.20">
      <origin xyz="0 -0.195 0.0175" rpy="0 0 0" />
      <geometry>
        <box size="0.27 0.006 0.006" />
        </geometry>
      <material name="dark_gunmetal_hardware">
        <color rgba="0.26 0.27 0.26 1" />
        </material>
      </visual>
    <visual name="cross_bar_-0.09">
      <origin xyz="0 -0.09 0.0175" rpy="0 0 0" />
      <geometry>
        <box size="0.27 0.006 0.006" />
        </geometry>
      <material name="dark_gunmetal_hardware">
        <color rgba="0.26 0.27 0.26 1" />
        </material>
      </visual>
    <visual name="lid_knuckle_0">
      <origin xyz="-0.07 0 0" rpy="0 1.5708 0" />
      <geometry>
        <cylinder radius="0.008" length="0.052" />
        </geometry>
      <material name="dark_gunmetal_hardware">
        <color rgba="0.26 0.27 0.26 1" />
        </material>
      </visual>
    <visual name="lid_knuckle_0_strap">
      <origin xyz="-0.07 -0.011 0.006" rpy="0 0 0" />
      <geometry>
        <box size="0.052 0.026 0.005" />
        </geometry>
      <material name="dark_gunmetal_hardware">
        <color rgba="0.26 0.27 0.26 1" />
        </material>
      </visual>
    <visual name="lid_knuckle_1">
      <origin xyz="0.07 0 0" rpy="0 1.5708 0" />
      <geometry>
        <cylinder radius="0.008" length="0.052" />
        </geometry>
      <material name="dark_gunmetal_hardware">
        <color rgba="0.26 0.27 0.26 1" />
        </material>
      </visual>
    <visual name="lid_knuckle_1_strap">
      <origin xyz="0.07 -0.011 0.006" rpy="0 0 0" />
      <geometry>
        <box size="0.052 0.026 0.005" />
        </geometry>
      <material name="dark_gunmetal_hardware">
        <color rgba="0.26 0.27 0.26 1" />
        </material>
      </visual>
    <visual name="latch_keeper">
      <origin xyz="0 -0.276 0.01" rpy="0 0 0" />
      <geometry>
        <box size="0.074 0.012 0.02" />
        </geometry>
      <material name="dark_gunmetal_hardware">
        <color rgba="0.26 0.27 0.26 1" />
        </material>
      </visual>
    <visual name="lid_screw_-0.17_-0.25">
      <origin xyz="-0.168 -0.246 0.0245" rpy="0 0 0" />
      <geometry>
        <cylinder radius="0.0045" length="0.003" />
        </geometry>
      <material name="brushed_steel_fasteners">
        <color rgba="0.62 0.62 0.58 1" />
        </material>
      </visual>
    <visual name="lid_screw_-0.17_-0.04">
      <origin xyz="-0.168 -0.04 0.0245" rpy="0 0 0" />
      <geometry>
        <cylinder radius="0.0045" length="0.003" />
        </geometry>
      <material name="brushed_steel_fasteners">
        <color rgba="0.62 0.62 0.58 1" />
        </material>
      </visual>
    <visual name="lid_screw_0.17_-0.25">
      <origin xyz="0.168 -0.246 0.0245" rpy="0 0 0" />
      <geometry>
        <cylinder radius="0.0045" length="0.003" />
        </geometry>
      <material name="brushed_steel_fasteners">
        <color rgba="0.62 0.62 0.58 1" />
        </material>
      </visual>
    <visual name="lid_screw_0.17_-0.04">
      <origin xyz="0.168 -0.04 0.0245" rpy="0 0 0" />
      <geometry>
        <cylinder radius="0.0045" length="0.003" />
        </geometry>
      <material name="brushed_steel_fasteners">
        <color rgba="0.62 0.62 0.58 1" />
        </material>
      </visual>
    <collision name="side_frame_0">
      <origin xyz="-0.174 -0.143 0.012" rpy="0 0 0" />
      <geometry>
        <box size="0.034 0.244 0.024" />
        </geometry>
      </collision>
    <collision name="side_frame_1">
      <origin xyz="0.174 -0.143 0.012" rpy="0 0 0" />
      <geometry>
        <box size="0.034 0.244 0.024" />
        </geometry>
      </collision>
    <collision name="front_frame">
      <origin xyz="0 -0.256 0.012" rpy="0 0 0" />
      <geometry>
        <box size="0.382 0.036 0.024" />
        </geometry>
      </collision>
    <collision name="rear_frame">
      <origin xyz="0 -0.02 0.012" rpy="0 0 0" />
      <geometry>
        <box size="0.382 0.024 0.024" />
        </geometry>
      </collision>
    <collision name="window_pane">
      <origin xyz="0 -0.142 0.012" rpy="0 0 0" />
      <geometry>
        <box size="0.32 0.21 0.006" />
        </geometry>
      </collision>
    <collision name="window_bar_-0.09">
      <origin xyz="-0.09 -0.142 0.0175" rpy="0 0 0" />
      <geometry>
        <box size="0.007 0.16 0.006" />
        </geometry>
      </collision>
    <collision name="window_bar_0.00">
      <origin xyz="0 -0.142 0.0175" rpy="0 0 0" />
      <geometry>
        <box size="0.007 0.16 0.006" />
        </geometry>
      </collision>
    <collision name="window_bar_0.09">
      <origin xyz="0.09 -0.142 0.0175" rpy="0 0 0" />
      <geometry>
        <box size="0.007 0.16 0.006" />
        </geometry>
      </collision>
    <collision name="cross_bar_-0.20">
      <origin xyz="0 -0.195 0.0175" rpy="0 0 0" />
      <geometry>
        <box size="0.27 0.006 0.006" />
        </geometry>
      </collision>
    <collision name="cross_bar_-0.09">
      <origin xyz="0 -0.09 0.0175" rpy="0 0 0" />
      <geometry>
        <box size="0.27 0.006 0.006" />
        </geometry>
      </collision>
    <collision name="lid_knuckle_0">
      <origin xyz="-0.07 0 0" rpy="0 1.5708 0" />
      <geometry>
        <cylinder radius="0.008" length="0.052" />
        </geometry>
      </collision>
    <collision name="lid_knuckle_0_strap">
      <origin xyz="-0.07 -0.011 0.006" rpy="0 0 0" />
      <geometry>
        <box size="0.052 0.026 0.005" />
        </geometry>
      </collision>
    <collision name="lid_knuckle_1">
      <origin xyz="0.07 0 0" rpy="0 1.5708 0" />
      <geometry>
        <cylinder radius="0.008" length="0.052" />
        </geometry>
      </collision>
    <collision name="lid_knuckle_1_strap">
      <origin xyz="0.07 -0.011 0.006" rpy="0 0 0" />
      <geometry>
        <box size="0.052 0.026 0.005" />
        </geometry>
      </collision>
    <collision name="latch_keeper">
      <origin xyz="0 -0.276 0.01" rpy="0 0 0" />
      <geometry>
        <box size="0.074 0.012 0.02" />
        </geometry>
      </collision>
    <collision name="lid_screw_-0.17_-0.25">
      <origin xyz="-0.168 -0.246 0.0245" rpy="0 0 0" />
      <geometry>
        <cylinder radius="0.0045" length="0.003" />
        </geometry>
      </collision>
    <collision name="lid_screw_-0.17_-0.04">
      <origin xyz="-0.168 -0.04 0.0245" rpy="0 0 0" />
      <geometry>
        <cylinder radius="0.0045" length="0.003" />
        </geometry>
      </collision>
    <collision name="lid_screw_0.17_-0.25">
      <origin xyz="0.168 -0.246 0.0245" rpy="0 0 0" />
      <geometry>
        <cylinder radius="0.0045" length="0.003" />
        </geometry>
      </collision>
    <collision name="lid_screw_0.17_-0.04">
      <origin xyz="0.168 -0.04 0.0245" rpy="0 0 0" />
      <geometry>
        <cylinder radius="0.0045" length="0.003" />
        </geometry>
      </collision>
    </link>
  <link name="winder_cradle">
    <visual name="drive_plate">
      <origin xyz="0 -0.003 0" rpy="1.5708 0 0" />
      <geometry>
        <cylinder radius="0.046" length="0.012" />
        </geometry>
      <material name="dark_gunmetal_hardware">
        <color rgba="0.26 0.27 0.26 1" />
        </material>
      </visual>
    <visual name="protective_ring">
      <origin xyz="0 -0.004 0" rpy="1.5708 0 0" />
      <geometry>
        <mesh filename="assets/meshes/protective_ring.obj" />
        </geometry>
      <material name="brushed_steel_fasteners">
        <color rgba="0.62 0.62 0.58 1" />
        </material>
      </visual>
    <visual name="spoke_0">
      <origin xyz="0 -0.01 0" rpy="0 0 0" />
      <geometry>
        <box size="0.078 0.006 0.006" />
        </geometry>
      <material name="dark_gunmetal_hardware">
        <color rgba="0.26 0.27 0.26 1" />
        </material>
      </visual>
    <visual name="spoke_1">
      <origin xyz="0 -0.01 0" rpy="0 0 1.5708" />
      <geometry>
        <box size="0.078 0.006 0.006" />
        </geometry>
      <material name="dark_gunmetal_hardware">
        <color rgba="0.26 0.27 0.26 1" />
        </material>
      </visual>
    <visual name="spoke_2">
      <origin xyz="0 -0.01 0" rpy="0 0 3.14159" />
      <geometry>
        <box size="0.078 0.006 0.006" />
        </geometry>
      <material name="dark_gunmetal_hardware">
        <color rgba="0.26 0.27 0.26 1" />
        </material>
      </visual>
    <visual name="spoke_3">
      <origin xyz="0 -0.01 0" rpy="0 0 4.71239" />
      <geometry>
        <box size="0.078 0.006 0.006" />
        </geometry>
      <material name="dark_gunmetal_hardware">
        <color rgba="0.26 0.27 0.26 1" />
        </material>
      </visual>
    <visual name="cushion">
      <origin xyz="0 -0.024 0" rpy="0 1.5708 0" />
      <geometry>
        <cylinder radius="0.02" length="0.074" />
        </geometry>
      <material name="black_watch_cushion">
        <color rgba="0.005 0.005 0.006 1" />
        </material>
      </visual>
    <visual name="cushion_band_n">
      <origin xyz="-0.026 -0.046 0" rpy="0 0 0" />
      <geometry>
        <box size="0.007 0.02 0.047" />
        </geometry>
      <material name="black_rubber_bumpers">
        <color rgba="0.015 0.016 0.014 1" />
        </material>
      </visual>
    <visual name="cushion_band_p">
      <origin xyz="0.026 -0.046 0" rpy="0 0 0" />
      <geometry>
        <box size="0.007 0.02 0.047" />
        </geometry>
      <material name="black_rubber_bumpers">
        <color rgba="0.015 0.016 0.014 1" />
        </material>
      </visual>
    <visual name="watch_bezel">
      <origin xyz="0 -0.053 0" rpy="1.5708 0 0" />
      <geometry>
        <mesh filename="assets/meshes/watch_bezel.obj" />
        </geometry>
      <material name="brushed_steel_fasteners">
        <color rgba="0.62 0.62 0.58 1" />
        </material>
      </visual>
    <visual name="watch_face">
      <origin xyz="0 -0.055 0" rpy="1.5708 0 0" />
      <geometry>
        <cylinder radius="0.026" length="0.003" />
        </geometry>
      <material name="matte_black_insert">
        <color rgba="0.025 0.026 0.024 1" />
        </material>
      </visual>
    <collision name="drive_plate">
      <origin xyz="0 -0.003 0" rpy="1.5708 0 0" />
      <geometry>
        <cylinder radius="0.046" length="0.012" />
        </geometry>
      </collision>
    <collision name="protective_ring">
      <origin xyz="0 -0.004 0" rpy="1.5708 0 0" />
      <geometry>
        <mesh filename="assets/meshes/protective_ring.obj" />
        </geometry>
      </collision>
    <collision name="spoke_0">
      <origin xyz="0 -0.01 0" rpy="0 0 0" />
      <geometry>
        <box size="0.078 0.006 0.006" />
        </geometry>
      </collision>
    <collision name="spoke_1">
      <origin xyz="0 -0.01 0" rpy="0 0 1.5708" />
      <geometry>
        <box size="0.078 0.006 0.006" />
        </geometry>
      </collision>
    <collision name="spoke_2">
      <origin xyz="0 -0.01 0" rpy="0 0 3.14159" />
      <geometry>
        <box size="0.078 0.006 0.006" />
        </geometry>
      </collision>
    <collision name="spoke_3">
      <origin xyz="0 -0.01 0" rpy="0 0 4.71239" />
      <geometry>
        <box size="0.078 0.006 0.006" />
        </geometry>
      </collision>
    <collision name="cushion">
      <origin xyz="0 -0.024 0" rpy="0 1.5708 0" />
      <geometry>
        <cylinder radius="0.02" length="0.074" />
        </geometry>
      </collision>
    <collision name="cushion_band_n">
      <origin xyz="-0.026 -0.046 0" rpy="0 0 0" />
      <geometry>
        <box size="0.007 0.02 0.047" />
        </geometry>
      </collision>
    <collision name="cushion_band_p">
      <origin xyz="0.026 -0.046 0" rpy="0 0 0" />
      <geometry>
        <box size="0.007 0.02 0.047" />
        </geometry>
      </collision>
    <collision name="watch_bezel">
      <origin xyz="0 -0.053 0" rpy="1.5708 0 0" />
      <geometry>
        <mesh filename="assets/meshes/watch_bezel.obj" />
        </geometry>
      </collision>
    <collision name="watch_face">
      <origin xyz="0 -0.055 0" rpy="1.5708 0 0" />
      <geometry>
        <cylinder radius="0.026" length="0.003" />
        </geometry>
      </collision>
    </link>
  <link name="front_latch">
    <visual name="latch_barrel">
      <origin xyz="0 0 0" rpy="0 1.5708 0" />
      <geometry>
        <cylinder radius="0.006" length="0.03" />
        </geometry>
      <material name="dark_gunmetal_hardware">
        <color rgba="0.26 0.27 0.26 1" />
        </material>
      </visual>
    <visual name="hasp_plate">
      <origin xyz="0 -0.008 0.031" rpy="0 0 0" />
      <geometry>
        <box size="0.055 0.006 0.062" />
        </geometry>
      <material name="dark_gunmetal_hardware">
        <color rgba="0.26 0.27 0.26 1" />
        </material>
      </visual>
    <visual name="hasp_hook">
      <origin xyz="0 -0.009 0.06" rpy="0 0 0" />
      <geometry>
        <box size="0.065 0.01 0.012" />
        </geometry>
      <material name="brushed_steel_fasteners">
        <color rgba="0.62 0.62 0.58 1" />
        </material>
      </visual>
    <visual name="hasp_rivet_0">
      <origin xyz="-0.018 -0.013 0.034" rpy="1.5708 0 0" />
      <geometry>
        <cylinder radius="0.004" length="0.004" />
        </geometry>
      <material name="brushed_steel_fasteners">
        <color rgba="0.62 0.62 0.58 1" />
        </material>
      </visual>
    <visual name="hasp_rivet_1">
      <origin xyz="0.018 -0.013 0.034" rpy="1.5708 0 0" />
      <geometry>
        <cylinder radius="0.004" length="0.004" />
        </geometry>
      <material name="brushed_steel_fasteners">
        <color rgba="0.62 0.62 0.58 1" />
        </material>
      </visual>
    <collision name="latch_barrel">
      <origin xyz="0 0 0" rpy="0 1.5708 0" />
      <geometry>
        <cylinder radius="0.006" length="0.03" />
        </geometry>
      </collision>
    <collision name="hasp_plate">
      <origin xyz="0 -0.008 0.031" rpy="0 0 0" />
      <geometry>
        <box size="0.055 0.006 0.062" />
        </geometry>
      </collision>
    <collision name="hasp_hook">
      <origin xyz="0 -0.009 0.06" rpy="0 0 0" />
      <geometry>
        <box size="0.065 0.01 0.012" />
        </geometry>
      </collision>
    <collision name="hasp_rivet_0">
      <origin xyz="-0.018 -0.013 0.034" rpy="1.5708 0 0" />
      <geometry>
        <cylinder radius="0.004" length="0.004" />
        </geometry>
      </collision>
    <collision name="hasp_rivet_1">
      <origin xyz="0.018 -0.013 0.034" rpy="1.5708 0 0" />
      <geometry>
        <cylinder radius="0.004" length="0.004" />
        </geometry>
      </collision>
    </link>
  <link name="control_knob">
    <visual name="knob_cap">
      <origin xyz="0 -0.0095 0" rpy="1.5708 0 0" />
      <geometry>
        <mesh filename="assets/meshes/control_knob.obj" />
        </geometry>
      <material name="dark_gunmetal_hardware">
        <color rgba="0.26 0.27 0.26 1" />
        </material>
      </visual>
    <collision name="knob_cap">
      <origin xyz="0 -0.0095 0" rpy="1.5708 0 0" />
      <geometry>
        <mesh filename="assets/meshes/control_knob.obj" />
        </geometry>
      </collision>
    </link>
  <joint name="lid_hinge" type="revolute">
    <origin xyz="0 0.136 0.139" rpy="0 0 0" />
    <parent link="case" />
    <child link="lid" />
    <axis xyz="-1 0 0" />
    <limit effort="12" velocity="1.2" lower="0" upper="1.65" />
    </joint>
  <joint name="winder_spin" type="continuous">
    <origin xyz="0 -0.023 0.078" rpy="0 0 0" />
    <parent link="case" />
    <child link="winder_cradle" />
    <axis xyz="0 1 0" />
    <limit effort="1.2" velocity="0.8" />
    </joint>
  <joint name="latch_pivot" type="revolute">
    <origin xyz="0 -0.136 0.076" rpy="0 0 0" />
    <parent link="case" />
    <child link="front_latch" />
    <axis xyz="1 0 0" />
    <limit effort="3" velocity="2" lower="0" upper="1.15" />
    </joint>
  <joint name="knob_turn" type="continuous">
    <origin xyz="-0.115 -0.137 0.055" rpy="0 0 0" />
    <parent link="case" />
    <child link="control_knob" />
    <axis xyz="0 -1 0" />
    <limit effort="0.25" velocity="4" />
    </joint>
  </robot>
