<robot name="pet_door_flap_assembly">
  <link name="frame">
    <visual name="top_rail">
      <origin xyz="0 0 0.265" rpy="0 0 0" />
      <geometry>
        <box size="0.46 0.09 0.07" />
        </geometry>
      <material name="dark_textured_plastic">
        <color rgba="0.035 0.035 0.032 1" />
        </material>
      </visual>
    <visual name="bottom_rail">
      <origin xyz="0 0 -0.265" rpy="0 0 0" />
      <geometry>
        <box size="0.46 0.09 0.07" />
        </geometry>
      <material name="dark_textured_plastic">
        <color rgba="0.035 0.035 0.032 1" />
        </material>
      </visual>
    <visual name="side_rail_0">
      <origin xyz="-0.195 0 0" rpy="0 0 0" />
      <geometry>
        <box size="0.07 0.09 0.6" />
        </geometry>
      <material name="dark_textured_plastic">
        <color rgba="0.035 0.035 0.032 1" />
        </material>
      </visual>
    <visual name="side_rail_1">
      <origin xyz="0.195 0 0" rpy="0 0 0" />
      <geometry>
        <box size="0.07 0.09 0.6" />
        </geometry>
      <material name="dark_textured_plastic">
        <color rgba="0.035 0.035 0.032 1" />
        </material>
      </visual>
    <visual name="top_stop_lip">
      <origin xyz="0 0.046 0.222" rpy="0 0 0" />
      <geometry>
        <box size="0.34 0.022 0.022" />
        </geometry>
      <material name="black_rubber">
        <color rgba="0.005 0.006 0.006 1" />
        </material>
      </visual>
    <visual name="bottom_stop_lip">
      <origin xyz="0 0.046 -0.214" rpy="0 0 0" />
      <geometry>
        <box size="0.34 0.022 0.018" />
        </geometry>
      <material name="black_rubber">
        <color rgba="0.005 0.006 0.006 1" />
        </material>
      </visual>
    <visual name="side_stop_lip_0">
      <origin xyz="-0.163 0.046 0" rpy="0 0 0" />
      <geometry>
        <box size="0.02 0.022 0.41" />
        </geometry>
      <material name="black_rubber">
        <color rgba="0.005 0.006 0.006 1" />
        </material>
      </visual>
    <visual name="side_stop_lip_1">
      <origin xyz="0.163 0.046 0" rpy="0 0 0" />
      <geometry>
        <box size="0.02 0.022 0.41" />
        </geometry>
      <material name="black_rubber">
        <color rgba="0.005 0.006 0.006 1" />
        </material>
      </visual>
    <visual name="side_channel_0">
      <origin xyz="-0.182 -0.065 0.15" rpy="0 0 0" />
      <geometry>
        <box size="0.025 0.04 0.8" />
        </geometry>
      <material name="dark_textured_plastic">
        <color rgba="0.035 0.035 0.032 1" />
        </material>
      </visual>
    <visual name="front_channel_lip_0">
      <origin xyz="-0.162 -0.045 0.15" rpy="0 0 0" />
      <geometry>
        <box size="0.02 0.008 0.8" />
        </geometry>
      <material name="dark_textured_plastic">
        <color rgba="0.035 0.035 0.032 1" />
        </material>
      </visual>
    <visual name="rear_channel_lip_0">
      <origin xyz="-0.162 -0.085 0.15" rpy="0 0 0" />
      <geometry>
        <box size="0.02 0.008 0.8" />
        </geometry>
      <material name="dark_textured_plastic">
        <color rgba="0.035 0.035 0.032 1" />
        </material>
      </visual>
    <visual name="side_channel_1">
      <origin xyz="0.182 -0.065 0.15" rpy="0 0 0" />
      <geometry>
        <box size="0.025 0.04 0.8" />
        </geometry>
      <material name="dark_textured_plastic">
        <color rgba="0.035 0.035 0.032 1" />
        </material>
      </visual>
    <visual name="front_channel_lip_1">
      <origin xyz="0.162 -0.045 0.15" rpy="0 0 0" />
      <geometry>
        <box size="0.02 0.008 0.8" />
        </geometry>
      <material name="dark_textured_plastic">
        <color rgba="0.035 0.035 0.032 1" />
        </material>
      </visual>
    <visual name="rear_channel_lip_1">
      <origin xyz="0.162 -0.085 0.15" rpy="0 0 0" />
      <geometry>
        <box size="0.02 0.008 0.8" />
        </geometry>
      <material name="dark_textured_plastic">
        <color rgba="0.035 0.035 0.032 1" />
        </material>
      </visual>
    <visual name="cover_header">
      <origin xyz="0 -0.065 0.55" rpy="0 0 0" />
      <geometry>
        <box size="0.39 0.04 0.035" />
        </geometry>
      <material name="dark_textured_plastic">
        <color rgba="0.035 0.035 0.032 1" />
        </material>
      </visual>
    <visual name="hinge_ear_0">
      <origin xyz="-0.162 0.018 0.22" rpy="0 0 0" />
      <geometry>
        <box size="0.03 0.036 0.06" />
        </geometry>
      <material name="dark_textured_plastic">
        <color rgba="0.035 0.035 0.032 1" />
        </material>
      </visual>
    <visual name="hinge_ear_1">
      <origin xyz="0.162 0.018 0.22" rpy="0 0 0" />
      <geometry>
        <box size="0.03 0.036 0.06" />
        </geometry>
      <material name="dark_textured_plastic">
        <color rgba="0.035 0.035 0.032 1" />
        </material>
      </visual>
    <visual name="screw_head_0">
      <origin xyz="-0.185 0.047 0.245" rpy="1.5708 0 0" />
      <geometry>
        <cylinder radius="0.014" length="0.006" />
        </geometry>
      <material name="dull_stainless_screw_heads">
        <color rgba="0.55 0.55 0.52 1" />
        </material>
      </visual>
    <visual name="screw_head_1">
      <origin xyz="0.185 0.047 0.245" rpy="1.5708 0 0" />
      <geometry>
        <cylinder radius="0.014" length="0.006" />
        </geometry>
      <material name="dull_stainless_screw_heads">
        <color rgba="0.55 0.55 0.52 1" />
        </material>
      </visual>
    <visual name="screw_head_2">
      <origin xyz="-0.185 0.047 -0.245" rpy="1.5708 0 0" />
      <geometry>
        <cylinder radius="0.014" length="0.006" />
        </geometry>
      <material name="dull_stainless_screw_heads">
        <color rgba="0.55 0.55 0.52 1" />
        </material>
      </visual>
    <visual name="screw_head_3">
      <origin xyz="0.185 0.047 -0.245" rpy="1.5708 0 0" />
      <geometry>
        <cylinder radius="0.014" length="0.006" />
        </geometry>
      <material name="dull_stainless_screw_heads">
        <color rgba="0.55 0.55 0.52 1" />
        </material>
      </visual>
    <collision name="top_rail">
      <origin xyz="0 0 0.265" rpy="0 0 0" />
      <geometry>
        <box size="0.46 0.09 0.07" />
        </geometry>
      </collision>
    <collision name="bottom_rail">
      <origin xyz="0 0 -0.265" rpy="0 0 0" />
      <geometry>
        <box size="0.46 0.09 0.07" />
        </geometry>
      </collision>
    <collision name="side_rail_0">
      <origin xyz="-0.195 0 0" rpy="0 0 0" />
      <geometry>
        <box size="0.07 0.09 0.6" />
        </geometry>
      </collision>
    <collision name="side_rail_1">
      <origin xyz="0.195 0 0" rpy="0 0 0" />
      <geometry>
        <box size="0.07 0.09 0.6" />
        </geometry>
      </collision>
    <collision name="top_stop_lip">
      <origin xyz="0 0.046 0.222" rpy="0 0 0" />
      <geometry>
        <box size="0.34 0.022 0.022" />
        </geometry>
      </collision>
    <collision name="bottom_stop_lip">
      <origin xyz="0 0.046 -0.214" rpy="0 0 0" />
      <geometry>
        <box size="0.34 0.022 0.018" />
        </geometry>
      </collision>
    <collision name="side_stop_lip_0">
      <origin xyz="-0.163 0.046 0" rpy="0 0 0" />
      <geometry>
        <box size="0.02 0.022 0.41" />
        </geometry>
      </collision>
    <collision name="side_stop_lip_1">
      <origin xyz="0.163 0.046 0" rpy="0 0 0" />
      <geometry>
        <box size="0.02 0.022 0.41" />
        </geometry>
      </collision>
    <collision name="side_channel_0">
      <origin xyz="-0.182 -0.065 0.15" rpy="0 0 0" />
      <geometry>
        <box size="0.025 0.04 0.8" />
        </geometry>
      </collision>
    <collision name="front_channel_lip_0">
      <origin xyz="-0.162 -0.045 0.15" rpy="0 0 0" />
      <geometry>
        <box size="0.02 0.008 0.8" />
        </geometry>
      </collision>
    <collision name="rear_channel_lip_0">
      <origin xyz="-0.162 -0.085 0.15" rpy="0 0 0" />
      <geometry>
        <box size="0.02 0.008 0.8" />
        </geometry>
      </collision>
    <collision name="side_channel_1">
      <origin xyz="0.182 -0.065 0.15" rpy="0 0 0" />
      <geometry>
        <box size="0.025 0.04 0.8" />
        </geometry>
      </collision>
    <collision name="front_channel_lip_1">
      <origin xyz="0.162 -0.045 0.15" rpy="0 0 0" />
      <geometry>
        <box size="0.02 0.008 0.8" />
        </geometry>
      </collision>
    <collision name="rear_channel_lip_1">
      <origin xyz="0.162 -0.085 0.15" rpy="0 0 0" />
      <geometry>
        <box size="0.02 0.008 0.8" />
        </geometry>
      </collision>
    <collision name="cover_header">
      <origin xyz="0 -0.065 0.55" rpy="0 0 0" />
      <geometry>
        <box size="0.39 0.04 0.035" />
        </geometry>
      </collision>
    <collision name="hinge_ear_0">
      <origin xyz="-0.162 0.018 0.22" rpy="0 0 0" />
      <geometry>
        <box size="0.03 0.036 0.06" />
        </geometry>
      </collision>
    <collision name="hinge_ear_1">
      <origin xyz="0.162 0.018 0.22" rpy="0 0 0" />
      <geometry>
        <box size="0.03 0.036 0.06" />
        </geometry>
      </collision>
    <collision name="screw_head_0">
      <origin xyz="-0.185 0.047 0.245" rpy="1.5708 0 0" />
      <geometry>
        <cylinder radius="0.014" length="0.006" />
        </geometry>
      </collision>
    <collision name="screw_head_1">
      <origin xyz="0.185 0.047 0.245" rpy="1.5708 0 0" />
      <geometry>
        <cylinder radius="0.014" length="0.006" />
        </geometry>
      </collision>
    <collision name="screw_head_2">
      <origin xyz="-0.185 0.047 -0.245" rpy="1.5708 0 0" />
      <geometry>
        <cylinder radius="0.014" length="0.006" />
        </geometry>
      </collision>
    <collision name="screw_head_3">
      <origin xyz="0.185 0.047 -0.245" rpy="1.5708 0 0" />
      <geometry>
        <cylinder radius="0.014" length="0.006" />
        </geometry>
      </collision>
    </link>
  <link name="flap">
    <visual name="clear_panel">
      <origin xyz="0 0 -0.198" rpy="0 0 0" />
      <geometry>
        <box size="0.286 0.01 0.372" />
        </geometry>
      <material name="smoked_amber_polycarbonate">
        <color rgba="0.55 0.34 0.12 0.46" />
        </material>
      </visual>
    <visual name="top_gasket">
      <origin xyz="0 0 -0.012" rpy="0 0 0" />
      <geometry>
        <box size="0.286 0.018 0.026" />
        </geometry>
      <material name="black_rubber">
        <color rgba="0.005 0.006 0.006 1" />
        </material>
      </visual>
    <visual name="bottom_weight">
      <origin xyz="0 0 -0.386" rpy="0 0 0" />
      <geometry>
        <box size="0.302 0.018 0.028" />
        </geometry>
      <material name="black_rubber">
        <color rgba="0.005 0.006 0.006 1" />
        </material>
      </visual>
    <visual name="side_gasket_0">
      <origin xyz="-0.138 0 -0.198" rpy="0 0 0" />
      <geometry>
        <box size="0.01 0.018 0.372" />
        </geometry>
      <material name="black_rubber">
        <color rgba="0.005 0.006 0.006 1" />
        </material>
      </visual>
    <visual name="side_gasket_1">
      <origin xyz="0.138 0 -0.198" rpy="0 0 0" />
      <geometry>
        <box size="0.01 0.018 0.372" />
        </geometry>
      <material name="black_rubber">
        <color rgba="0.005 0.006 0.006 1" />
        </material>
      </visual>
    <visual name="hinge_barrel">
      <origin xyz="0 0 0" rpy="0 1.5708 0" />
      <geometry>
        <cylinder radius="0.01" length="0.294" />
        </geometry>
      <material name="black_rubber">
        <color rgba="0.005 0.006 0.006 1" />
        </material>
      </visual>
    <collision name="clear_panel">
      <origin xyz="0 0 -0.198" rpy="0 0 0" />
      <geometry>
        <box size="0.286 0.01 0.372" />
        </geometry>
      </collision>
    <collision name="top_gasket">
      <origin xyz="0 0 -0.012" rpy="0 0 0" />
      <geometry>
        <box size="0.286 0.018 0.026" />
        </geometry>
      </collision>
    <collision name="bottom_weight">
      <origin xyz="0 0 -0.386" rpy="0 0 0" />
      <geometry>
        <box size="0.302 0.018 0.028" />
        </geometry>
      </collision>
    <collision name="side_gasket_0">
      <origin xyz="-0.138 0 -0.198" rpy="0 0 0" />
      <geometry>
        <box size="0.01 0.018 0.372" />
        </geometry>
      </collision>
    <collision name="side_gasket_1">
      <origin xyz="0.138 0 -0.198" rpy="0 0 0" />
      <geometry>
        <box size="0.01 0.018 0.372" />
        </geometry>
      </collision>
    <collision name="hinge_barrel">
      <origin xyz="0 0 0" rpy="0 1.5708 0" />
      <geometry>
        <cylinder radius="0.01" length="0.294" />
        </geometry>
      </collision>
    </link>
  <link name="security_cover">
    <visual name="cover_panel">
      <origin xyz="0 0 0.21" rpy="0 0 0" />
      <geometry>
        <box size="0.3 0.01 0.42" />
        </geometry>
      <material name="off_white_security_panel">
        <color rgba="0.86 0.84 0.78 1" />
        </material>
      </visual>
    <visual name="side_tongue_0">
      <origin xyz="-0.157 0 0.215" rpy="0 0 0" />
      <geometry>
        <box size="0.025 0.01 0.43" />
        </geometry>
      <material name="off_white_security_panel">
        <color rgba="0.86 0.84 0.78 1" />
        </material>
      </visual>
    <visual name="side_tongue_1">
      <origin xyz="0.157 0 0.215" rpy="0 0 0" />
      <geometry>
        <box size="0.025 0.01 0.43" />
        </geometry>
      <material name="off_white_security_panel">
        <color rgba="0.86 0.84 0.78 1" />
        </material>
      </visual>
    <visual name="finger_pull">
      <origin xyz="0 -0.014 0.26" rpy="0 0 0" />
      <geometry>
        <box size="0.12 0.018 0.05" />
        </geometry>
      <material name="dark_textured_plastic">
        <color rgba="0.035 0.035 0.032 1" />
        </material>
      </visual>
    <collision name="cover_panel">
      <origin xyz="0 0 0.21" rpy="0 0 0" />
      <geometry>
        <box size="0.3 0.01 0.42" />
        </geometry>
      </collision>
    <collision name="side_tongue_0">
      <origin xyz="-0.157 0 0.215" rpy="0 0 0" />
      <geometry>
        <box size="0.025 0.01 0.43" />
        </geometry>
      </collision>
    <collision name="side_tongue_1">
      <origin xyz="0.157 0 0.215" rpy="0 0 0" />
      <geometry>
        <box size="0.025 0.01 0.43" />
        </geometry>
      </collision>
    <collision name="finger_pull">
      <origin xyz="0 -0.014 0.26" rpy="0 0 0" />
      <geometry>
        <box size="0.12 0.018 0.05" />
        </geometry>
      </collision>
    </link>
  <joint name="frame_to_flap" type="revolute">
    <origin xyz="0 0.018 0.22" rpy="0 0 0" />
    <parent link="frame" />
    <child link="flap" />
    <axis xyz="1 0 0" />
    <limit effort="4" velocity="3" lower="0" upper="1.25" />
    </joint>
  <joint name="frame_to_security_cover" type="prismatic">
    <origin xyz="0 -0.065 -0.215" rpy="0 0 0" />
    <parent link="frame" />
    <child link="security_cover" />
    <axis xyz="0 0 1" />
    <limit effort="35" velocity="0.3" lower="0" upper="0.33" />
    </joint>
  </robot>
