<robot name="premium_windshield_wiper_assembly">
  <material name="satin_black_painted_metal">
    <color rgba="0.015 0.017 0.018 1" />
    </material>
  <material name="dark_anodized_linkage">
    <color rgba="0.18 0.18 0.17 1" />
    </material>
  <material name="brushed_bearing_steel">
    <color rgba="0.46 0.45 0.42 1" />
    </material>
  <material name="fine_grain_black_polymer">
    <color rgba="0.035 0.038 0.04 1" />
    </material>
  <material name="deep_matte_elastomer">
    <color rgba="0.004 0.004 0.004 1" />
    </material>
  <material name="soft_shadow_seam">
    <color rgba="0 0 0 1" />
    </material>
  <link name="cowl">
    <visual name="cowl_skin">
      <origin xyz="0 0 0.026" rpy="0 0 0" />
      <geometry>
        <mesh filename="assets/meshes/cowl_skin_mesh.obj" />
        </geometry>
      <material name="fine_grain_black_polymer">
        <color rgba="0.035 0.038 0.04 1" />
        </material>
      </visual>
    <visual name="rear_torsion_tube">
      <origin xyz="0 -0.07 0.02" rpy="0 1.5708 0" />
      <geometry>
        <cylinder radius="0.018" length="1.08" />
        </geometry>
      <material name="satin_black_painted_metal">
        <color rgba="0.015 0.017 0.018 1" />
        </material>
      </visual>
    <visual name="motor_bearing">
      <origin xyz="0 -0.045 0.06" rpy="0 0 0" />
      <geometry>
        <cylinder radius="0.064" length="0.04" />
        </geometry>
      <material name="fine_grain_black_polymer">
        <color rgba="0.035 0.038 0.04 1" />
        </material>
      </visual>
    <visual name="drive_bearing">
      <origin xyz="-0.36 0.035 0.036" rpy="0 0 0" />
      <geometry>
        <cylinder radius="0.042" length="0.052" />
        </geometry>
      <material name="fine_grain_black_polymer">
        <color rgba="0.035 0.038 0.04 1" />
        </material>
      </visual>
    <visual name="follower_bearing">
      <origin xyz="0.36 0.035 0.036" rpy="0 0 0" />
      <geometry>
        <cylinder radius="0.042" length="0.052" />
        </geometry>
      <material name="fine_grain_black_polymer">
        <color rgba="0.035 0.038 0.04 1" />
        </material>
      </visual>
    <visual name="drive_bearing_gusset">
      <origin xyz="-0.36 -0.01 0.05" rpy="0 0 0" />
      <geometry>
        <box size="0.11 0.02 0.03" />
        </geometry>
      <material name="satin_black_painted_metal">
        <color rgba="0.015 0.017 0.018 1" />
        </material>
      </visual>
    <visual name="drive_bearing_sleeve">
      <origin xyz="-0.36 0.035 0.056" rpy="0 0 0" />
      <geometry>
        <cylinder radius="0.01" length="0.028" />
        </geometry>
      <material name="brushed_bearing_steel">
        <color rgba="0.46 0.45 0.42 1" />
        </material>
      </visual>
    <visual name="follower_bearing_gusset">
      <origin xyz="0.36 -0.01 0.05" rpy="0 0 0" />
      <geometry>
        <box size="0.11 0.02 0.03" />
        </geometry>
      <material name="satin_black_painted_metal">
        <color rgba="0.015 0.017 0.018 1" />
        </material>
      </visual>
    <visual name="follower_bearing_sleeve">
      <origin xyz="0.36 0.035 0.056" rpy="0 0 0" />
      <geometry>
        <cylinder radius="0.01" length="0.028" />
        </geometry>
      <material name="brushed_bearing_steel">
        <color rgba="0.46 0.45 0.42 1" />
        </material>
      </visual>
    <visual name="front_seam">
      <origin xyz="0 0.061 0.046" rpy="0 0 0" />
      <geometry>
        <box size="1.03 0.006 0.004" />
        </geometry>
      <material name="soft_shadow_seam">
        <color rgba="0 0 0 1" />
        </material>
      </visual>
    <visual name="end_seam_0">
      <origin xyz="-0.48 -0.004 0.043" rpy="0 0 0" />
      <geometry>
        <box size="0.006 0.122 0.006" />
        </geometry>
      <material name="soft_shadow_seam">
        <color rgba="0 0 0 1" />
        </material>
      </visual>
    <visual name="end_seam_1">
      <origin xyz="0.48 -0.004 0.043" rpy="0 0 0" />
      <geometry>
        <box size="0.006 0.122 0.006" />
        </geometry>
      <material name="soft_shadow_seam">
        <color rgba="0 0 0 1" />
        </material>
      </visual>
    <collision name="cowl_skin">
      <origin xyz="0 0 0.026" rpy="0 0 0" />
      <geometry>
        <mesh filename="assets/meshes/cowl_skin_mesh.obj" />
        </geometry>
      </collision>
    <collision name="rear_torsion_tube">
      <origin xyz="0 -0.07 0.02" rpy="0 1.5708 0" />
      <geometry>
        <cylinder radius="0.018" length="1.08" />
        </geometry>
      </collision>
    <collision name="motor_bearing">
      <origin xyz="0 -0.045 0.06" rpy="0 0 0" />
      <geometry>
        <cylinder radius="0.064" length="0.04" />
        </geometry>
      </collision>
    <collision name="drive_bearing">
      <origin xyz="-0.36 0.035 0.036" rpy="0 0 0" />
      <geometry>
        <cylinder radius="0.042" length="0.052" />
        </geometry>
      </collision>
    <collision name="follower_bearing">
      <origin xyz="0.36 0.035 0.036" rpy="0 0 0" />
      <geometry>
        <cylinder radius="0.042" length="0.052" />
        </geometry>
      </collision>
    <collision name="drive_bearing_gusset">
      <origin xyz="-0.36 -0.01 0.05" rpy="0 0 0" />
      <geometry>
        <box size="0.11 0.02 0.03" />
        </geometry>
      </collision>
    <collision name="drive_bearing_sleeve">
      <origin xyz="-0.36 0.035 0.056" rpy="0 0 0" />
      <geometry>
        <cylinder radius="0.01" length="0.028" />
        </geometry>
      </collision>
    <collision name="follower_bearing_gusset">
      <origin xyz="0.36 -0.01 0.05" rpy="0 0 0" />
      <geometry>
        <box size="0.11 0.02 0.03" />
        </geometry>
      </collision>
    <collision name="follower_bearing_sleeve">
      <origin xyz="0.36 0.035 0.056" rpy="0 0 0" />
      <geometry>
        <cylinder radius="0.01" length="0.028" />
        </geometry>
      </collision>
    <collision name="front_seam">
      <origin xyz="0 0.061 0.046" rpy="0 0 0" />
      <geometry>
        <box size="1.03 0.006 0.004" />
        </geometry>
      </collision>
    <collision name="end_seam_0">
      <origin xyz="-0.48 -0.004 0.043" rpy="0 0 0" />
      <geometry>
        <box size="0.006 0.122 0.006" />
        </geometry>
      </collision>
    <collision name="end_seam_1">
      <origin xyz="0.48 -0.004 0.043" rpy="0 0 0" />
      <geometry>
        <box size="0.006 0.122 0.006" />
        </geometry>
      </collision>
    </link>
  <link name="crank">
    <visual name="motor_shaft">
      <geometry>
        <cylinder radius="0.018" length="0.09" />
        </geometry>
      <material name="brushed_bearing_steel">
        <color rgba="0.46 0.45 0.42 1" />
        </material>
      </visual>
    <visual name="crank_disk">
      <origin xyz="0 0 0.023" rpy="0 0 0" />
      <geometry>
        <cylinder radius="0.053" length="0.016" />
        </geometry>
      <material name="dark_anodized_linkage">
        <color rgba="0.18 0.18 0.17 1" />
        </material>
      </visual>
    <visual name="crank_arm">
      <geometry>
        <mesh filename="assets/meshes/crank_arm_mesh.obj" />
        </geometry>
      <material name="dark_anodized_linkage">
        <color rgba="0.18 0.18 0.17 1" />
        </material>
      </visual>
    <visual name="crank_pin_boss">
      <origin xyz="-0.105 0 0.012" rpy="0 0 0" />
      <geometry>
        <cylinder radius="0.02" length="0.01" />
        </geometry>
      <material name="dark_anodized_linkage">
        <color rgba="0.18 0.18 0.17 1" />
        </material>
      </visual>
    <visual name="crank_pin">
      <origin xyz="-0.105 0 0.015" rpy="0 0 0" />
      <geometry>
        <cylinder radius="0.011" length="0.034" />
        </geometry>
      <material name="brushed_bearing_steel">
        <color rgba="0.46 0.45 0.42 1" />
        </material>
      </visual>
    <visual name="counterweight">
      <origin xyz="0.038 0.01 0.031" rpy="0 0 0" />
      <geometry>
        <cylinder radius="0.019" length="0.01" />
        </geometry>
      <material name="dark_anodized_linkage">
        <color rgba="0.18 0.18 0.17 1" />
        </material>
      </visual>
    <collision name="motor_shaft">
      <geometry>
        <cylinder radius="0.018" length="0.09" />
        </geometry>
      </collision>
    <collision name="crank_disk">
      <origin xyz="0 0 0.023" rpy="0 0 0" />
      <geometry>
        <cylinder radius="0.053" length="0.016" />
        </geometry>
      </collision>
    <collision name="crank_arm">
      <geometry>
        <mesh filename="assets/meshes/crank_arm_mesh.obj" />
        </geometry>
      </collision>
    <collision name="crank_pin_boss">
      <origin xyz="-0.105 0 0.012" rpy="0 0 0" />
      <geometry>
        <cylinder radius="0.02" length="0.01" />
        </geometry>
      </collision>
    <collision name="crank_pin">
      <origin xyz="-0.105 0 0.015" rpy="0 0 0" />
      <geometry>
        <cylinder radius="0.011" length="0.034" />
        </geometry>
      </collision>
    <collision name="counterweight">
      <origin xyz="0.038 0.01 0.031" rpy="0 0 0" />
      <geometry>
        <cylinder radius="0.019" length="0.01" />
        </geometry>
      </collision>
    </link>
  <link name="drive_link">
    <visual name="drive_link_rod">
      <geometry>
        <mesh filename="assets/meshes/drive_link_rod_mesh.obj" />
        </geometry>
      <material name="dark_anodized_linkage">
        <color rgba="0.18 0.18 0.17 1" />
        </material>
      </visual>
    <visual name="link_socket_0">
      <origin xyz="0 0 0.024" rpy="0 0 0" />
      <geometry>
        <sphere radius="0.019" />
        </geometry>
      <material name="brushed_bearing_steel">
        <color rgba="0.46 0.45 0.42 1" />
        </material>
      </visual>
    <visual name="link_socket_1">
      <origin xyz="-0.175 0.025 0.024" rpy="0 0 0" />
      <geometry>
        <sphere radius="0.019" />
        </geometry>
      <material name="brushed_bearing_steel">
        <color rgba="0.46 0.45 0.42 1" />
        </material>
      </visual>
    <collision name="drive_link_rod">
      <geometry>
        <mesh filename="assets/meshes/drive_link_rod_mesh.obj" />
        </geometry>
      </collision>
    <collision name="link_socket_0">
      <origin xyz="0 0 0.024" rpy="0 0 0" />
      <geometry>
        <sphere radius="0.019" />
        </geometry>
      </collision>
    <collision name="link_socket_1">
      <origin xyz="-0.175 0.025 0.024" rpy="0 0 0" />
      <geometry>
        <sphere radius="0.019" />
        </geometry>
      </collision>
    </link>
  <link name="drive_wiper">
    <visual name="drive_spindle">
      <geometry>
        <cylinder radius="0.013" length="0.1" />
        </geometry>
      <material name="brushed_bearing_steel">
        <color rgba="0.46 0.45 0.42 1" />
        </material>
      </visual>
    <visual name="drive_hub_cap">
      <origin xyz="0 0 0.058" rpy="0 0 0" />
      <geometry>
        <cylinder radius="0.032" length="0.02" />
        </geometry>
      <material name="fine_grain_black_polymer">
        <color rgba="0.035 0.038 0.04 1" />
        </material>
      </visual>
    <visual name="drive_main_arm">
      <geometry>
        <mesh filename="assets/meshes/drive_main_arm_mesh.obj" />
        </geometry>
      <material name="satin_black_painted_metal">
        <color rgba="0.015 0.017 0.018 1" />
        </material>
      </visual>
    <visual name="drive_tip_hinge">
      <origin xyz="0.11 0.53 0.075" rpy="1.5708 0 0" />
      <geometry>
        <cylinder radius="0.018" length="0.032" />
        </geometry>
      <material name="fine_grain_black_polymer">
        <color rgba="0.035 0.038 0.04 1" />
        </material>
      </visual>
    <visual name="drive_drive_lever">
      <geometry>
        <mesh filename="assets/meshes/drive_drive_lever_mesh.obj" />
        </geometry>
      <material name="satin_black_painted_metal">
        <color rgba="0.015 0.017 0.018 1" />
        </material>
      </visual>
    <visual name="drive_link_pin">
      <origin xyz="0.08 -0.055 0.015" rpy="0 0 0" />
      <geometry>
        <cylinder radius="0.011" length="0.03" />
        </geometry>
      <material name="brushed_bearing_steel">
        <color rgba="0.46 0.45 0.42 1" />
        </material>
      </visual>
    <visual name="drive_tie_lever">
      <geometry>
        <mesh filename="assets/meshes/drive_tie_lever_mesh.obj" />
        </geometry>
      <material name="satin_black_painted_metal">
        <color rgba="0.015 0.017 0.018 1" />
        </material>
      </visual>
    <visual name="drive_tie_pin">
      <origin xyz="0.11 0.025 0.01" rpy="0 0 0" />
      <geometry>
        <cylinder radius="0.01" length="0.028" />
        </geometry>
      <material name="brushed_bearing_steel">
        <color rgba="0.46 0.45 0.42 1" />
        </material>
      </visual>
    <collision name="drive_spindle">
      <geometry>
        <cylinder radius="0.013" length="0.1" />
        </geometry>
      </collision>
    <collision name="drive_hub_cap">
      <origin xyz="0 0 0.058" rpy="0 0 0" />
      <geometry>
        <cylinder radius="0.032" length="0.02" />
        </geometry>
      </collision>
    <collision name="drive_main_arm">
      <geometry>
        <mesh filename="assets/meshes/drive_main_arm_mesh.obj" />
        </geometry>
      </collision>
    <collision name="drive_tip_hinge">
      <origin xyz="0.11 0.53 0.075" rpy="1.5708 0 0" />
      <geometry>
        <cylinder radius="0.018" length="0.032" />
        </geometry>
      </collision>
    <collision name="drive_drive_lever">
      <geometry>
        <mesh filename="assets/meshes/drive_drive_lever_mesh.obj" />
        </geometry>
      </collision>
    <collision name="drive_link_pin">
      <origin xyz="0.08 -0.055 0.015" rpy="0 0 0" />
      <geometry>
        <cylinder radius="0.011" length="0.03" />
        </geometry>
      </collision>
    <collision name="drive_tie_lever">
      <geometry>
        <mesh filename="assets/meshes/drive_tie_lever_mesh.obj" />
        </geometry>
      </collision>
    <collision name="drive_tie_pin">
      <origin xyz="0.11 0.025 0.01" rpy="0 0 0" />
      <geometry>
        <cylinder radius="0.01" length="0.028" />
        </geometry>
      </collision>
    </link>
  <link name="follower_wiper">
    <visual name="follower_spindle">
      <geometry>
        <cylinder radius="0.013" length="0.1" />
        </geometry>
      <material name="brushed_bearing_steel">
        <color rgba="0.46 0.45 0.42 1" />
        </material>
      </visual>
    <visual name="follower_hub_cap">
      <origin xyz="0 0 0.058" rpy="0 0 0" />
      <geometry>
        <cylinder radius="0.032" length="0.02" />
        </geometry>
      <material name="fine_grain_black_polymer">
        <color rgba="0.035 0.038 0.04 1" />
        </material>
      </visual>
    <visual name="follower_main_arm">
      <geometry>
        <mesh filename="assets/meshes/follower_main_arm_mesh.obj" />
        </geometry>
      <material name="satin_black_painted_metal">
        <color rgba="0.015 0.017 0.018 1" />
        </material>
      </visual>
    <visual name="follower_tip_hinge">
      <origin xyz="-0.11 0.49 0.075" rpy="1.5708 0 0" />
      <geometry>
        <cylinder radius="0.018" length="0.032" />
        </geometry>
      <material name="fine_grain_black_polymer">
        <color rgba="0.035 0.038 0.04 1" />
        </material>
      </visual>
    <visual name="follower_tie_lever">
      <geometry>
        <mesh filename="assets/meshes/follower_tie_lever_mesh.obj" />
        </geometry>
      <material name="satin_black_painted_metal">
        <color rgba="0.015 0.017 0.018 1" />
        </material>
      </visual>
    <visual name="follower_tie_pin">
      <origin xyz="-0.11 0.025 0.01" rpy="0 0 0" />
      <geometry>
        <cylinder radius="0.01" length="0.028" />
        </geometry>
      <material name="brushed_bearing_steel">
        <color rgba="0.46 0.45 0.42 1" />
        </material>
      </visual>
    <collision name="follower_spindle">
      <geometry>
        <cylinder radius="0.013" length="0.1" />
        </geometry>
      </collision>
    <collision name="follower_hub_cap">
      <origin xyz="0 0 0.058" rpy="0 0 0" />
      <geometry>
        <cylinder radius="0.032" length="0.02" />
        </geometry>
      </collision>
    <collision name="follower_main_arm">
      <geometry>
        <mesh filename="assets/meshes/follower_main_arm_mesh.obj" />
        </geometry>
      </collision>
    <collision name="follower_tip_hinge">
      <origin xyz="-0.11 0.49 0.075" rpy="1.5708 0 0" />
      <geometry>
        <cylinder radius="0.018" length="0.032" />
        </geometry>
      </collision>
    <collision name="follower_tie_lever">
      <geometry>
        <mesh filename="assets/meshes/follower_tie_lever_mesh.obj" />
        </geometry>
      </collision>
    <collision name="follower_tie_pin">
      <origin xyz="-0.11 0.025 0.01" rpy="0 0 0" />
      <geometry>
        <cylinder radius="0.01" length="0.028" />
        </geometry>
      </collision>
    </link>
  <link name="tie_link">
    <visual name="tie_link_rod">
      <geometry>
        <mesh filename="assets/meshes/tie_link_rod_mesh.obj" />
        </geometry>
      <material name="dark_anodized_linkage">
        <color rgba="0.18 0.18 0.17 1" />
        </material>
      </visual>
    <visual name="tie_socket_0">
      <origin xyz="0 0 0.022" rpy="0 0 0" />
      <geometry>
        <sphere radius="0.018" />
        </geometry>
      <material name="brushed_bearing_steel">
        <color rgba="0.46 0.45 0.42 1" />
        </material>
      </visual>
    <visual name="tie_socket_1">
      <origin xyz="0.5 0 0.022" rpy="0 0 0" />
      <geometry>
        <sphere radius="0.018" />
        </geometry>
      <material name="brushed_bearing_steel">
        <color rgba="0.46 0.45 0.42 1" />
        </material>
      </visual>
    <collision name="tie_link_rod">
      <geometry>
        <mesh filename="assets/meshes/tie_link_rod_mesh.obj" />
        </geometry>
      </collision>
    <collision name="tie_socket_0">
      <origin xyz="0 0 0.022" rpy="0 0 0" />
      <geometry>
        <sphere radius="0.018" />
        </geometry>
      </collision>
    <collision name="tie_socket_1">
      <origin xyz="0.5 0 0.022" rpy="0 0 0" />
      <geometry>
        <sphere radius="0.018" />
        </geometry>
      </collision>
    </link>
  <link name="drive_blade">
    <visual name="blade_adapter">
      <geometry>
        <box size="0.06 0.04 0.024" />
        </geometry>
      <material name="fine_grain_black_polymer">
        <color rgba="0.035 0.038 0.04 1" />
        </material>
      </visual>
    <visual name="blade_spine">
      <origin xyz="0 0 -0.032" rpy="0 0 0" />
      <geometry>
        <box size="0.5 0.018 0.012" />
        </geometry>
      <material name="dark_anodized_linkage">
        <color rgba="0.18 0.18 0.17 1" />
        </material>
      </visual>
    <visual name="rubber">
      <origin xyz="0 0 -0.06" rpy="0 0 0" />
      <geometry>
        <box size="0.48 0.01 0.03" />
        </geometry>
      <material name="deep_matte_elastomer">
        <color rgba="0.004 0.004 0.004 1" />
        </material>
      </visual>
    <visual name="drive_end_cap_0">
      <origin xyz="-0.22 0 -0.042" rpy="0 0 0" />
      <geometry>
        <box size="0.028 0.026 0.038" />
        </geometry>
      <material name="fine_grain_black_polymer">
        <color rgba="0.035 0.038 0.04 1" />
        </material>
      </visual>
    <visual name="drive_end_cap_1">
      <origin xyz="0.22 0 -0.042" rpy="0 0 0" />
      <geometry>
        <box size="0.028 0.026 0.038" />
        </geometry>
      <material name="fine_grain_black_polymer">
        <color rgba="0.035 0.038 0.04 1" />
        </material>
      </visual>
    <visual name="drive_claw_0">
      <origin xyz="-0.17 0 -0.024" rpy="0 0 0" />
      <geometry>
        <box size="0.034 0.028 0.046" />
        </geometry>
      <material name="fine_grain_black_polymer">
        <color rgba="0.035 0.038 0.04 1" />
        </material>
      </visual>
    <visual name="drive_claw_1">
      <origin xyz="0 0 -0.024" rpy="0 0 0" />
      <geometry>
        <box size="0.034 0.028 0.046" />
        </geometry>
      <material name="fine_grain_black_polymer">
        <color rgba="0.035 0.038 0.04 1" />
        </material>
      </visual>
    <visual name="drive_claw_2">
      <origin xyz="0.17 0 -0.024" rpy="0 0 0" />
      <geometry>
        <box size="0.034 0.028 0.046" />
        </geometry>
      <material name="fine_grain_black_polymer">
        <color rgba="0.035 0.038 0.04 1" />
        </material>
      </visual>
    <collision name="blade_adapter">
      <geometry>
        <box size="0.06 0.04 0.024" />
        </geometry>
      </collision>
    <collision name="blade_spine">
      <origin xyz="0 0 -0.032" rpy="0 0 0" />
      <geometry>
        <box size="0.5 0.018 0.012" />
        </geometry>
      </collision>
    <collision name="rubber">
      <origin xyz="0 0 -0.06" rpy="0 0 0" />
      <geometry>
        <box size="0.48 0.01 0.03" />
        </geometry>
      </collision>
    <collision name="drive_end_cap_0">
      <origin xyz="-0.22 0 -0.042" rpy="0 0 0" />
      <geometry>
        <box size="0.028 0.026 0.038" />
        </geometry>
      </collision>
    <collision name="drive_end_cap_1">
      <origin xyz="0.22 0 -0.042" rpy="0 0 0" />
      <geometry>
        <box size="0.028 0.026 0.038" />
        </geometry>
      </collision>
    <collision name="drive_claw_0">
      <origin xyz="-0.17 0 -0.024" rpy="0 0 0" />
      <geometry>
        <box size="0.034 0.028 0.046" />
        </geometry>
      </collision>
    <collision name="drive_claw_1">
      <origin xyz="0 0 -0.024" rpy="0 0 0" />
      <geometry>
        <box size="0.034 0.028 0.046" />
        </geometry>
      </collision>
    <collision name="drive_claw_2">
      <origin xyz="0.17 0 -0.024" rpy="0 0 0" />
      <geometry>
        <box size="0.034 0.028 0.046" />
        </geometry>
      </collision>
    </link>
  <link name="follower_blade">
    <visual name="blade_adapter">
      <geometry>
        <box size="0.06 0.04 0.024" />
        </geometry>
      <material name="fine_grain_black_polymer">
        <color rgba="0.035 0.038 0.04 1" />
        </material>
      </visual>
    <visual name="blade_spine">
      <origin xyz="0 0 -0.032" rpy="0 0 0" />
      <geometry>
        <box size="0.46 0.018 0.012" />
        </geometry>
      <material name="dark_anodized_linkage">
        <color rgba="0.18 0.18 0.17 1" />
        </material>
      </visual>
    <visual name="rubber">
      <origin xyz="0 0 -0.06" rpy="0 0 0" />
      <geometry>
        <box size="0.4416 0.01 0.03" />
        </geometry>
      <material name="deep_matte_elastomer">
        <color rgba="0.004 0.004 0.004 1" />
        </material>
      </visual>
    <visual name="follower_end_cap_0">
      <origin xyz="-0.2024 0 -0.042" rpy="0 0 0" />
      <geometry>
        <box size="0.028 0.026 0.038" />
        </geometry>
      <material name="fine_grain_black_polymer">
        <color rgba="0.035 0.038 0.04 1" />
        </material>
      </visual>
    <visual name="follower_end_cap_1">
      <origin xyz="0.2024 0 -0.042" rpy="0 0 0" />
      <geometry>
        <box size="0.028 0.026 0.038" />
        </geometry>
      <material name="fine_grain_black_polymer">
        <color rgba="0.035 0.038 0.04 1" />
        </material>
      </visual>
    <visual name="follower_claw_0">
      <origin xyz="-0.17 0 -0.024" rpy="0 0 0" />
      <geometry>
        <box size="0.034 0.028 0.046" />
        </geometry>
      <material name="fine_grain_black_polymer">
        <color rgba="0.035 0.038 0.04 1" />
        </material>
      </visual>
    <visual name="follower_claw_1">
      <origin xyz="0 0 -0.024" rpy="0 0 0" />
      <geometry>
        <box size="0.034 0.028 0.046" />
        </geometry>
      <material name="fine_grain_black_polymer">
        <color rgba="0.035 0.038 0.04 1" />
        </material>
      </visual>
    <visual name="follower_claw_2">
      <origin xyz="0.17 0 -0.024" rpy="0 0 0" />
      <geometry>
        <box size="0.034 0.028 0.046" />
        </geometry>
      <material name="fine_grain_black_polymer">
        <color rgba="0.035 0.038 0.04 1" />
        </material>
      </visual>
    <collision name="blade_adapter">
      <geometry>
        <box size="0.06 0.04 0.024" />
        </geometry>
      </collision>
    <collision name="blade_spine">
      <origin xyz="0 0 -0.032" rpy="0 0 0" />
      <geometry>
        <box size="0.46 0.018 0.012" />
        </geometry>
      </collision>
    <collision name="rubber">
      <origin xyz="0 0 -0.06" rpy="0 0 0" />
      <geometry>
        <box size="0.4416 0.01 0.03" />
        </geometry>
      </collision>
    <collision name="follower_end_cap_0">
      <origin xyz="-0.2024 0 -0.042" rpy="0 0 0" />
      <geometry>
        <box size="0.028 0.026 0.038" />
        </geometry>
      </collision>
    <collision name="follower_end_cap_1">
      <origin xyz="0.2024 0 -0.042" rpy="0 0 0" />
      <geometry>
        <box size="0.028 0.026 0.038" />
        </geometry>
      </collision>
    <collision name="follower_claw_0">
      <origin xyz="-0.17 0 -0.024" rpy="0 0 0" />
      <geometry>
        <box size="0.034 0.028 0.046" />
        </geometry>
      </collision>
    <collision name="follower_claw_1">
      <origin xyz="0 0 -0.024" rpy="0 0 0" />
      <geometry>
        <box size="0.034 0.028 0.046" />
        </geometry>
      </collision>
    <collision name="follower_claw_2">
      <origin xyz="0.17 0 -0.024" rpy="0 0 0" />
      <geometry>
        <box size="0.034 0.028 0.046" />
        </geometry>
      </collision>
    </link>
  <joint name="motor_crank" type="revolute">
    <origin xyz="0 -0.045 0.092" rpy="0 0 0" />
    <parent link="cowl" />
    <child link="crank" />
    <axis xyz="0 0 1" />
    <limit effort="20" velocity="6" lower="-0.16" upper="0.16" />
    </joint>
  <joint name="crank_link_pin" type="revolute">
    <origin xyz="-0.105 0 0.015" rpy="0 0 0" />
    <parent link="crank" />
    <child link="drive_link" />
    <axis xyz="0 0 1" />
    <limit effort="8" velocity="4" lower="-0.65" upper="0.65" />
    <mimic joint="motor_crank" multiplier="-2.92" />
    </joint>
  <joint name="drive_pivot" type="revolute">
    <origin xyz="-0.36 0.035 0.092" rpy="0 0 0" />
    <parent link="cowl" />
    <child link="drive_wiper" />
    <axis xyz="0 0 1" />
    <limit effort="45" velocity="3.5" lower="-0.68" upper="0.68" />
    <mimic joint="motor_crank" multiplier="2.5" />
    </joint>
  <joint name="follower_pivot" type="revolute">
    <origin xyz="0.36 0.035 0.092" rpy="0 0 0" />
    <parent link="cowl" />
    <child link="follower_wiper" />
    <axis xyz="0 0 1" />
    <limit effort="35" velocity="3.5" lower="-0.66" upper="0.66" />
    <mimic joint="motor_crank" multiplier="1.5" />
    </joint>
  <joint name="tie_pin" type="revolute">
    <origin xyz="0.11 0.025 0.01" rpy="0 0 0" />
    <parent link="drive_wiper" />
    <child link="tie_link" />
    <axis xyz="0 0 1" />
    <limit effort="10" velocity="4" lower="-1" upper="1" />
    <mimic joint="motor_crank" multiplier="-3.33" />
    </joint>
  <joint name="drive_blade_hinge" type="revolute">
    <origin xyz="0.11 0.53 0.075" rpy="0 0 0" />
    <parent link="drive_wiper" />
    <child link="drive_blade" />
    <axis xyz="1 0 0" />
    <limit effort="6" velocity="1" lower="-0.18" upper="0.18" />
    </joint>
  <joint name="follower_blade_hinge" type="revolute">
    <origin xyz="-0.11 0.49 0.075" rpy="0 0 0" />
    <parent link="follower_wiper" />
    <child link="follower_blade" />
    <axis xyz="1 0 0" />
    <limit effort="6" velocity="1" lower="-0.18" upper="0.18" />
    </joint>
  </robot>
