<robot name="cheerful_retro_stand_mixer">
  <material name="sunny_enamel">
    <color rgba="0.96 0.27 0.18 1" />
    </material>
  <material name="warm_cream">
    <color rgba="1 0.86 0.55 1" />
    </material>
  <material name="brushed_steel">
    <color rgba="0.78 0.78 0.74 1" />
    </material>
  <material name="dark_rubber">
    <color rgba="0.05 0.045 0.04 1" />
    </material>
  <material name="polished_chrome">
    <color rgba="0.9 0.92 0.92 1" />
    </material>
  <link name="base">
    <visual name="base_plinth">
      <origin xyz="0.035 0 0.004" rpy="0 0 0" />
      <geometry>
        <mesh filename="assets/meshes/base_plinth.obj" />
        </geometry>
      <material name="sunny_enamel">
        <color rgba="0.96 0.27 0.18 1" />
        </material>
      </visual>
    <visual name="rear_column">
      <origin xyz="-0.135 0 0" rpy="0 0 0" />
      <geometry>
        <mesh filename="assets/meshes/rear_column.obj" />
        </geometry>
      <material name="sunny_enamel">
        <color rgba="0.96 0.27 0.18 1" />
        </material>
      </visual>
    <visual name="column_neck">
      <origin xyz="-0.135 0 0.075" rpy="0 0 0" />
      <geometry>
        <box size="0.135 0.15 0.038" />
        </geometry>
      <material name="sunny_enamel">
        <color rgba="0.96 0.27 0.18 1" />
        </material>
      </visual>
    <visual name="yoke_support">
      <origin xyz="-0.155 0 0.315" rpy="0 0 0" />
      <geometry>
        <box size="0.06 0.235 0.064" />
        </geometry>
      <material name="sunny_enamel">
        <color rgba="0.96 0.27 0.18 1" />
        </material>
      </visual>
    <visual name="hinge_cheek_0">
      <origin xyz="-0.13 -0.116 0.376" rpy="0 0 0" />
      <geometry>
        <box size="0.084 0.03 0.09" />
        </geometry>
      <material name="sunny_enamel">
        <color rgba="0.96 0.27 0.18 1" />
        </material>
      </visual>
    <visual name="hinge_cheek_1">
      <origin xyz="-0.13 0.116 0.376" rpy="0 0 0" />
      <geometry>
        <box size="0.084 0.03 0.09" />
        </geometry>
      <material name="sunny_enamel">
        <color rgba="0.96 0.27 0.18 1" />
        </material>
      </visual>
    <visual name="hinge_pin">
      <origin xyz="-0.13 0 0.376" rpy="-1.5708 0 0" />
      <geometry>
        <cylinder radius="0.018" length="0.232" />
        </geometry>
      <material name="polished_chrome">
        <color rgba="0.9 0.92 0.92 1" />
        </material>
      </visual>
    <visual name="slide_rail_0">
      <origin xyz="0.07 -0.11 0.069" rpy="0 0 0" />
      <geometry>
        <box size="0.29 0.023 0.012" />
        </geometry>
      <material name="warm_cream">
        <color rgba="1 0.86 0.55 1" />
        </material>
      </visual>
    <visual name="slide_rail_1">
      <origin xyz="0.07 0.11 0.069" rpy="0 0 0" />
      <geometry>
        <box size="0.29 0.023 0.012" />
        </geometry>
      <material name="warm_cream">
        <color rgba="1 0.86 0.55 1" />
        </material>
      </visual>
    <visual name="lock_socket">
      <origin xyz="0.289 0.07 0.058" rpy="0 0 0" />
      <geometry>
        <box size="0.02 0.072 0.03" />
        </geometry>
      <material name="sunny_enamel">
        <color rgba="0.96 0.27 0.18 1" />
        </material>
      </visual>
    <collision name="base_plinth">
      <origin xyz="0.035 0 0.004" rpy="0 0 0" />
      <geometry>
        <mesh filename="assets/meshes/base_plinth.obj" />
        </geometry>
      </collision>
    <collision name="rear_column">
      <origin xyz="-0.135 0 0" rpy="0 0 0" />
      <geometry>
        <mesh filename="assets/meshes/rear_column.obj" />
        </geometry>
      </collision>
    <collision name="column_neck">
      <origin xyz="-0.135 0 0.075" rpy="0 0 0" />
      <geometry>
        <box size="0.135 0.15 0.038" />
        </geometry>
      </collision>
    <collision name="yoke_support">
      <origin xyz="-0.155 0 0.315" rpy="0 0 0" />
      <geometry>
        <box size="0.06 0.235 0.064" />
        </geometry>
      </collision>
    <collision name="hinge_cheek_0">
      <origin xyz="-0.13 -0.116 0.376" rpy="0 0 0" />
      <geometry>
        <box size="0.084 0.03 0.09" />
        </geometry>
      </collision>
    <collision name="hinge_cheek_1">
      <origin xyz="-0.13 0.116 0.376" rpy="0 0 0" />
      <geometry>
        <box size="0.084 0.03 0.09" />
        </geometry>
      </collision>
    <collision name="hinge_pin">
      <origin xyz="-0.13 0 0.376" rpy="-1.5708 0 0" />
      <geometry>
        <cylinder radius="0.018" length="0.232" />
        </geometry>
      </collision>
    <collision name="slide_rail_0">
      <origin xyz="0.07 -0.11 0.069" rpy="0 0 0" />
      <geometry>
        <box size="0.29 0.023 0.012" />
        </geometry>
      </collision>
    <collision name="slide_rail_1">
      <origin xyz="0.07 0.11 0.069" rpy="0 0 0" />
      <geometry>
        <box size="0.29 0.023 0.012" />
        </geometry>
      </collision>
    <collision name="lock_socket">
      <origin xyz="0.289 0.07 0.058" rpy="0 0 0" />
      <geometry>
        <box size="0.02 0.072 0.03" />
        </geometry>
      </collision>
    </link>
  <link name="bowl_carriage">
    <visual name="carriage_plate">
      <origin xyz="0.085 0 0.008" rpy="0 0 0" />
      <geometry>
        <box size="0.235 0.185 0.016" />
        </geometry>
      <material name="warm_cream">
        <color rgba="1 0.86 0.55 1" />
        </material>
      </visual>
    <visual name="bowl_foot">
      <origin xyz="0.103 0 0.026" rpy="0 0 0" />
      <geometry>
        <cylinder radius="0.064" length="0.02" />
        </geometry>
      <material name="brushed_steel">
        <color rgba="0.78 0.78 0.74 1" />
        </material>
      </visual>
    <visual name="steel_bowl">
      <origin xyz="0.103 0 0.036" rpy="0 0 0" />
      <geometry>
        <mesh filename="assets/meshes/steel_bowl.obj" />
        </geometry>
      <material name="brushed_steel">
        <color rgba="0.78 0.78 0.74 1" />
        </material>
      </visual>
    <collision name="carriage_plate">
      <origin xyz="0.085 0 0.008" rpy="0 0 0" />
      <geometry>
        <box size="0.235 0.185 0.016" />
        </geometry>
      </collision>
    <collision name="bowl_foot">
      <origin xyz="0.103 0 0.026" rpy="0 0 0" />
      <geometry>
        <cylinder radius="0.064" length="0.02" />
        </geometry>
      </collision>
    <collision name="steel_bowl">
      <origin xyz="0.103 0 0.036" rpy="0 0 0" />
      <geometry>
        <mesh filename="assets/meshes/steel_bowl.obj" />
        </geometry>
      </collision>
    </link>
  <link name="head">
    <visual name="rounded_housing">
      <origin xyz="0.205 0 0.008" rpy="0 0 0" />
      <geometry>
        <mesh filename="assets/meshes/rounded_head_housing.obj" />
        </geometry>
      <material name="sunny_enamel">
        <color rgba="0.96 0.27 0.18 1" />
        </material>
      </visual>
    <visual name="short_nose">
      <origin xyz="0.23 0 -0.026" rpy="0 1.5708 0" />
      <geometry>
        <cylinder radius="0.04" length="0.118" />
        </geometry>
      <material name="sunny_enamel">
        <color rgba="0.96 0.27 0.18 1" />
        </material>
      </visual>
    <visual name="head_hinge_barrel">
      <origin xyz="0 0 0" rpy="-1.5708 0 0" />
      <geometry>
        <cylinder radius="0.026" length="0.205" />
        </geometry>
      <material name="polished_chrome">
        <color rgba="0.9 0.92 0.92 1" />
        </material>
      </visual>
    <visual name="hinge_boss">
      <origin xyz="0.026 0 0.036" rpy="0 0 0" />
      <geometry>
        <box size="0.052 0.15 0.024" />
        </geometry>
      <material name="sunny_enamel">
        <color rgba="0.96 0.27 0.18 1" />
        </material>
      </visual>
    <visual name="nose_trim">
      <origin xyz="0.218 0 -0.075" rpy="0 0 0" />
      <geometry>
        <box size="0.082 0.118 0.02" />
        </geometry>
      <material name="warm_cream">
        <color rgba="1 0.86 0.55 1" />
        </material>
      </visual>
    <collision name="rounded_housing">
      <origin xyz="0.205 0 0.008" rpy="0 0 0" />
      <geometry>
        <mesh filename="assets/meshes/rounded_head_housing.obj" />
        </geometry>
      </collision>
    <collision name="short_nose">
      <origin xyz="0.23 0 -0.026" rpy="0 1.5708 0" />
      <geometry>
        <cylinder radius="0.04" length="0.118" />
        </geometry>
      </collision>
    <collision name="head_hinge_barrel">
      <origin xyz="0 0 0" rpy="-1.5708 0 0" />
      <geometry>
        <cylinder radius="0.026" length="0.205" />
        </geometry>
      </collision>
    <collision name="hinge_boss">
      <origin xyz="0.026 0 0.036" rpy="0 0 0" />
      <geometry>
        <box size="0.052 0.15 0.024" />
        </geometry>
      </collision>
    <collision name="nose_trim">
      <origin xyz="0.218 0 -0.075" rpy="0 0 0" />
      <geometry>
        <box size="0.082 0.118 0.02" />
        </geometry>
      </collision>
    </link>
  <link name="tool">
    <visual name="tool_shaft">
      <origin xyz="0 0 -0.03" rpy="0 0 0" />
      <geometry>
        <cylinder radius="0.01" length="0.06" />
        </geometry>
      <material name="polished_chrome">
        <color rgba="0.9 0.92 0.92 1" />
        </material>
      </visual>
    <visual name="dough_hook">
      <geometry>
        <mesh filename="assets/meshes/dough_hook.obj" />
        </geometry>
      <material name="polished_chrome">
        <color rgba="0.9 0.92 0.92 1" />
        </material>
      </visual>
    <collision name="tool_shaft">
      <origin xyz="0 0 -0.03" rpy="0 0 0" />
      <geometry>
        <cylinder radius="0.01" length="0.06" />
        </geometry>
      </collision>
    <collision name="dough_hook">
      <geometry>
        <mesh filename="assets/meshes/dough_hook.obj" />
        </geometry>
      </collision>
    </link>
  <link name="speed_control">
    <visual name="speed_knob">
      <origin xyz="0 0 0" rpy="1.5708 0 0" />
      <geometry>
        <mesh filename="assets/meshes/speed_control_knob.obj" />
        </geometry>
      <material name="warm_cream">
        <color rgba="1 0.86 0.55 1" />
        </material>
      </visual>
    <collision name="speed_knob">
      <origin xyz="0 0 0" rpy="1.5708 0 0" />
      <geometry>
        <mesh filename="assets/meshes/speed_control_knob.obj" />
        </geometry>
      </collision>
    </link>
  <link name="head_lock">
    <visual name="lock_tab">
      <origin xyz="0.015 0 0" rpy="0 0 0" />
      <geometry>
        <box size="0.03 0.06 0.022" />
        </geometry>
      <material name="warm_cream">
        <color rgba="1 0.86 0.55 1" />
        </material>
      </visual>
    <collision name="lock_tab">
      <origin xyz="0.015 0 0" rpy="0 0 0" />
      <geometry>
        <box size="0.03 0.06 0.022" />
        </geometry>
      </collision>
    </link>
  <joint name="base_to_bowl_carriage" type="prismatic">
    <origin xyz="-0.01 0 0.082" rpy="0 0 0" />
    <parent link="base" />
    <child link="bowl_carriage" />
    <axis xyz="1 0 0" />
    <limit effort="45" velocity="0.2" lower="0" upper="0.055" />
    </joint>
  <joint name="base_to_head" type="revolute">
    <origin xyz="-0.13 0 0.376" rpy="0 0 0" />
    <parent link="base" />
    <child link="head" />
    <axis xyz="0 -1 0" />
    <limit effort="18" velocity="1.5" lower="0" upper="0.78" />
    </joint>
  <joint name="head_to_tool" type="continuous">
    <origin xyz="0.218 0 -0.085" rpy="0 0 0" />
    <parent link="head" />
    <child link="tool" />
    <axis xyz="0 0 1" />
    <limit effort="4" velocity="18" />
    </joint>
  <joint name="base_to_speed_control" type="revolute">
    <origin xyz="-0.135 -0.088 0.176" rpy="0 0 0" />
    <parent link="base" />
    <child link="speed_control" />
    <axis xyz="0 -1 0" />
    <limit effort="0.8" velocity="4" lower="-0.75" upper="0.75" />
    </joint>
  <joint name="base_to_head_lock" type="prismatic">
    <origin xyz="0.299 0.07 0.058" rpy="0 0 0" />
    <parent link="base" />
    <child link="head_lock" />
    <axis xyz="1 0 0" />
    <limit effort="8" velocity="0.08" lower="0" upper="0.018" />
    </joint>
  </robot>
