<robot name="refractor_alt_az_tripod">
  <material name="blackened_cast_iron">
    <color rgba="0.015 0.018 0.017 1" />
    </material>
  <material name="rubbed_iron_edges">
    <color rgba="0.12 0.13 0.12 1" />
    </material>
  <material name="aged_brass">
    <color rgba="0.72 0.52 0.23 1" />
    </material>
  <material name="cream_enamel">
    <color rgba="0.86 0.84 0.76 1" />
    </material>
  <material name="matte_black_trim">
    <color rgba="0.005 0.005 0.006 1" />
    </material>
  <material name="pale_coated_glass">
    <color rgba="0.35 0.62 0.78 0.45" />
    </material>
  <material name="dark_varnished_wood">
    <color rgba="0.24 0.12 0.055 1" />
    </material>
  <link name="tripod">
    <visual name="floor_boss">
      <origin xyz="0 0 0.04" rpy="0 0 0" />
      <geometry>
        <cylinder radius="0.07" length="0.08" />
        </geometry>
      <material name="blackened_cast_iron">
        <color rgba="0.015 0.018 0.017 1" />
        </material>
      </visual>
    <visual name="center_column">
      <origin xyz="0 0 0.43" rpy="0 0 0" />
      <geometry>
        <cylinder radius="0.055" length="0.78" />
        </geometry>
      <material name="blackened_cast_iron">
        <color rgba="0.015 0.018 0.017 1" />
        </material>
      </visual>
    <visual name="leg_crown">
      <origin xyz="0 0 0.77" rpy="0 0 0" />
      <geometry>
        <cylinder radius="0.105" length="0.1" />
        </geometry>
      <material name="blackened_cast_iron">
        <color rgba="0.015 0.018 0.017 1" />
        </material>
      </visual>
    <visual name="azimuth_seat">
      <origin xyz="0 0 0.845" rpy="0 0 0" />
      <geometry>
        <cylinder radius="0.095" length="0.07" />
        </geometry>
      <material name="rubbed_iron_edges">
        <color rgba="0.12 0.13 0.12 1" />
        </material>
      </visual>
    <visual name="leg_0">
      <origin xyz="2.00536e-17 0.3275 0.3825" rpy="0 2.4275 1.5708" />
      <geometry>
        <cylinder radius="0.025" length="0.893224" />
        </geometry>
      <material name="dark_varnished_wood">
        <color rgba="0.24 0.12 0.055 1" />
        </material>
      </visual>
    <visual name="leg_brace_0">
      <origin xyz="1.74512e-17 0.285 0.335" rpy="0 2.04649 1.5708" />
      <geometry>
        <cylinder radius="0.012" length="0.371214" />
        </geometry>
      <material name="blackened_cast_iron">
        <color rgba="0.015 0.018 0.017 1" />
        </material>
      </visual>
    <visual name="foot_0">
      <origin xyz="3.79641e-17 0.62 0.025" rpy="0 0 1.5708" />
      <geometry>
        <box size="0.16 0.055 0.035" />
        </geometry>
      <material name="blackened_cast_iron">
        <color rgba="0.015 0.018 0.017 1" />
        </material>
      </visual>
    <visual name="leg_1">
      <origin xyz="-0.283623 -0.16375 0.3825" rpy="0 2.4275 -2.61799" />
      <geometry>
        <cylinder radius="0.025" length="0.893224" />
        </geometry>
      <material name="dark_varnished_wood">
        <color rgba="0.24 0.12 0.055 1" />
        </material>
      </visual>
    <visual name="leg_brace_1">
      <origin xyz="-0.246817 -0.1425 0.335" rpy="0 2.04649 -2.61799" />
      <geometry>
        <cylinder radius="0.012" length="0.371214" />
        </geometry>
      <material name="blackened_cast_iron">
        <color rgba="0.015 0.018 0.017 1" />
        </material>
      </visual>
    <visual name="foot_1">
      <origin xyz="-0.536936 -0.31 0.025" rpy="0 0 3.66519" />
      <geometry>
        <box size="0.16 0.055 0.035" />
        </geometry>
      <material name="blackened_cast_iron">
        <color rgba="0.015 0.018 0.017 1" />
        </material>
      </visual>
    <visual name="leg_2">
      <origin xyz="0.283623 -0.16375 0.3825" rpy="0 2.4275 -0.523599" />
      <geometry>
        <cylinder radius="0.025" length="0.893224" />
        </geometry>
      <material name="dark_varnished_wood">
        <color rgba="0.24 0.12 0.055 1" />
        </material>
      </visual>
    <visual name="leg_brace_2">
      <origin xyz="0.246817 -0.1425 0.335" rpy="0 2.04649 -0.523599" />
      <geometry>
        <cylinder radius="0.012" length="0.371214" />
        </geometry>
      <material name="blackened_cast_iron">
        <color rgba="0.015 0.018 0.017 1" />
        </material>
      </visual>
    <visual name="foot_2">
      <origin xyz="0.536936 -0.31 0.025" rpy="0 0 5.75959" />
      <geometry>
        <box size="0.16 0.055 0.035" />
        </geometry>
      <material name="blackened_cast_iron">
        <color rgba="0.015 0.018 0.017 1" />
        </material>
      </visual>
    <collision name="floor_boss">
      <origin xyz="0 0 0.04" rpy="0 0 0" />
      <geometry>
        <cylinder radius="0.07" length="0.08" />
        </geometry>
      </collision>
    <collision name="center_column">
      <origin xyz="0 0 0.43" rpy="0 0 0" />
      <geometry>
        <cylinder radius="0.055" length="0.78" />
        </geometry>
      </collision>
    <collision name="leg_crown">
      <origin xyz="0 0 0.77" rpy="0 0 0" />
      <geometry>
        <cylinder radius="0.105" length="0.1" />
        </geometry>
      </collision>
    <collision name="azimuth_seat">
      <origin xyz="0 0 0.845" rpy="0 0 0" />
      <geometry>
        <cylinder radius="0.095" length="0.07" />
        </geometry>
      </collision>
    <collision name="leg_0">
      <origin xyz="2.00536e-17 0.3275 0.3825" rpy="0 2.4275 1.5708" />
      <geometry>
        <cylinder radius="0.025" length="0.893224" />
        </geometry>
      </collision>
    <collision name="leg_brace_0">
      <origin xyz="1.74512e-17 0.285 0.335" rpy="0 2.04649 1.5708" />
      <geometry>
        <cylinder radius="0.012" length="0.371214" />
        </geometry>
      </collision>
    <collision name="foot_0">
      <origin xyz="3.79641e-17 0.62 0.025" rpy="0 0 1.5708" />
      <geometry>
        <box size="0.16 0.055 0.035" />
        </geometry>
      </collision>
    <collision name="leg_1">
      <origin xyz="-0.283623 -0.16375 0.3825" rpy="0 2.4275 -2.61799" />
      <geometry>
        <cylinder radius="0.025" length="0.893224" />
        </geometry>
      </collision>
    <collision name="leg_brace_1">
      <origin xyz="-0.246817 -0.1425 0.335" rpy="0 2.04649 -2.61799" />
      <geometry>
        <cylinder radius="0.012" length="0.371214" />
        </geometry>
      </collision>
    <collision name="foot_1">
      <origin xyz="-0.536936 -0.31 0.025" rpy="0 0 3.66519" />
      <geometry>
        <box size="0.16 0.055 0.035" />
        </geometry>
      </collision>
    <collision name="leg_2">
      <origin xyz="0.283623 -0.16375 0.3825" rpy="0 2.4275 -0.523599" />
      <geometry>
        <cylinder radius="0.025" length="0.893224" />
        </geometry>
      </collision>
    <collision name="leg_brace_2">
      <origin xyz="0.246817 -0.1425 0.335" rpy="0 2.04649 -0.523599" />
      <geometry>
        <cylinder radius="0.012" length="0.371214" />
        </geometry>
      </collision>
    <collision name="foot_2">
      <origin xyz="0.536936 -0.31 0.025" rpy="0 0 5.75959" />
      <geometry>
        <box size="0.16 0.055 0.035" />
        </geometry>
      </collision>
    </link>
  <link name="azimuth_head">
    <visual name="turntable">
      <origin xyz="0 0 0.0275" rpy="0 0 0" />
      <geometry>
        <cylinder radius="0.115" length="0.055" />
        </geometry>
      <material name="blackened_cast_iron">
        <color rgba="0.015 0.018 0.017 1" />
        </material>
      </visual>
    <visual name="neck">
      <origin xyz="0 0 0.155" rpy="0 0 0" />
      <geometry>
        <cylinder radius="0.06" length="0.245" />
        </geometry>
      <material name="blackened_cast_iron">
        <color rgba="0.015 0.018 0.017 1" />
        </material>
      </visual>
    <visual name="yoke_bridge">
      <origin xyz="0 0 0.255" rpy="0 0 0" />
      <geometry>
        <box size="0.28 0.42 0.06" />
        </geometry>
      <material name="blackened_cast_iron">
        <color rgba="0.015 0.018 0.017 1" />
        </material>
      </visual>
    <visual name="yoke_cheek_0">
      <origin xyz="0 0.18 0.43" rpy="0 0 0" />
      <geometry>
        <box size="0.2 0.06 0.38" />
        </geometry>
      <material name="blackened_cast_iron">
        <color rgba="0.015 0.018 0.017 1" />
        </material>
      </visual>
    <visual name="bearing_cap_0">
      <origin xyz="0 0.219 0.52" rpy="1.5708 0 0" />
      <geometry>
        <cylinder radius="0.067" length="0.018" />
        </geometry>
      <material name="rubbed_iron_edges">
        <color rgba="0.12 0.13 0.12 1" />
        </material>
      </visual>
    <visual name="yoke_cheek_1">
      <origin xyz="0 -0.18 0.43" rpy="0 0 0" />
      <geometry>
        <box size="0.2 0.06 0.38" />
        </geometry>
      <material name="blackened_cast_iron">
        <color rgba="0.015 0.018 0.017 1" />
        </material>
      </visual>
    <visual name="bearing_cap_1">
      <origin xyz="0 -0.219 0.52" rpy="1.5708 0 0" />
      <geometry>
        <cylinder radius="0.067" length="0.018" />
        </geometry>
      <material name="rubbed_iron_edges">
        <color rgba="0.12 0.13 0.12 1" />
        </material>
      </visual>
    <visual name="front_rib">
      <origin xyz="0.095 0 0.35" rpy="0 0 0" />
      <geometry>
        <box size="0.04 0.34 0.11" />
        </geometry>
      <material name="blackened_cast_iron">
        <color rgba="0.015 0.018 0.017 1" />
        </material>
      </visual>
    <collision name="turntable">
      <origin xyz="0 0 0.0275" rpy="0 0 0" />
      <geometry>
        <cylinder radius="0.115" length="0.055" />
        </geometry>
      </collision>
    <collision name="neck">
      <origin xyz="0 0 0.155" rpy="0 0 0" />
      <geometry>
        <cylinder radius="0.06" length="0.245" />
        </geometry>
      </collision>
    <collision name="yoke_bridge">
      <origin xyz="0 0 0.255" rpy="0 0 0" />
      <geometry>
        <box size="0.28 0.42 0.06" />
        </geometry>
      </collision>
    <collision name="yoke_cheek_0">
      <origin xyz="0 0.18 0.43" rpy="0 0 0" />
      <geometry>
        <box size="0.2 0.06 0.38" />
        </geometry>
      </collision>
    <collision name="bearing_cap_0">
      <origin xyz="0 0.219 0.52" rpy="1.5708 0 0" />
      <geometry>
        <cylinder radius="0.067" length="0.018" />
        </geometry>
      </collision>
    <collision name="yoke_cheek_1">
      <origin xyz="0 -0.18 0.43" rpy="0 0 0" />
      <geometry>
        <box size="0.2 0.06 0.38" />
        </geometry>
      </collision>
    <collision name="bearing_cap_1">
      <origin xyz="0 -0.219 0.52" rpy="1.5708 0 0" />
      <geometry>
        <cylinder radius="0.067" length="0.018" />
        </geometry>
      </collision>
    <collision name="front_rib">
      <origin xyz="0.095 0 0.35" rpy="0 0 0" />
      <geometry>
        <box size="0.04 0.34 0.11" />
        </geometry>
      </collision>
    </link>
  <link name="telescope">
    <visual name="main_tube">
      <origin xyz="0.08 0 0" rpy="0 1.5708 0" />
      <geometry>
        <mesh filename="assets/meshes/main_open_tube.obj" />
        </geometry>
      <material name="cream_enamel">
        <color rgba="0.86 0.84 0.76 1" />
        </material>
      </visual>
    <visual name="balance_band">
      <origin xyz="0 0 0" rpy="0 1.5708 0" />
      <geometry>
        <cylinder radius="0.078" length="0.055" />
        </geometry>
      <material name="aged_brass">
        <color rgba="0.72 0.52 0.23 1" />
        </material>
      </visual>
    <visual name="trunnion_0">
      <origin xyz="0 0.108 0" rpy="1.5708 0 0" />
      <geometry>
        <cylinder radius="0.05" length="0.12" />
        </geometry>
      <material name="aged_brass">
        <color rgba="0.72 0.52 0.23 1" />
        </material>
      </visual>
    <visual name="trunnion_1">
      <origin xyz="0 -0.108 0" rpy="1.5708 0 0" />
      <geometry>
        <cylinder radius="0.05" length="0.12" />
        </geometry>
      <material name="aged_brass">
        <color rgba="0.72 0.52 0.23 1" />
        </material>
      </visual>
    <visual name="dew_shield">
      <origin xyz="0.89 0 0" rpy="0 1.5708 0" />
      <geometry>
        <cylinder radius="0.094" length="0.22" />
        </geometry>
      <material name="matte_black_trim">
        <color rgba="0.005 0.005 0.006 1" />
        </material>
      </visual>
    <visual name="objective_lens">
      <origin xyz="0.995 0 0" rpy="0 1.5708 0" />
      <geometry>
        <cylinder radius="0.07" length="0.018" />
        </geometry>
      <material name="pale_coated_glass">
        <color rgba="0.35 0.62 0.78 0.45" />
        </material>
      </visual>
    <visual name="rear_cell">
      <origin xyz="-0.665 0 0" rpy="0 1.5708 0" />
      <geometry>
        <cylinder radius="0.052" length="0.035" />
        </geometry>
      <material name="matte_black_trim">
        <color rgba="0.005 0.005 0.006 1" />
        </material>
      </visual>
    <visual name="rear_flange">
      <origin xyz="-0.655 0 0" rpy="0 1.5708 0" />
      <geometry>
        <cylinder radius="0.08" length="0.045" />
        </geometry>
      <material name="aged_brass">
        <color rgba="0.72 0.52 0.23 1" />
        </material>
      </visual>
    <visual name="focuser_block">
      <origin xyz="-0.775 0 -0.02" rpy="0 0 0" />
      <geometry>
        <box size="0.22 0.12 0.095" />
        </geometry>
      <material name="matte_black_trim">
        <color rgba="0.005 0.005 0.006 1" />
        </material>
      </visual>
    <visual name="drawtube">
      <origin xyz="-0.91 0 -0.02" rpy="0 1.5708 0" />
      <geometry>
        <cylinder radius="0.032" length="0.18" />
        </geometry>
      <material name="matte_black_trim">
        <color rgba="0.005 0.005 0.006 1" />
        </material>
      </visual>
    <visual name="eyepiece_barrel">
      <origin xyz="-1.03 0 0.015" rpy="0 -1.5708 0" />
      <geometry>
        <cylinder radius="0.022" length="0.11" />
        </geometry>
      <material name="matte_black_trim">
        <color rgba="0.005 0.005 0.006 1" />
        </material>
      </visual>
    <visual name="eyepiece_glass">
      <origin xyz="-1.092 0 0.015" rpy="0 0 0" />
      <geometry>
        <sphere radius="0.021" />
        </geometry>
      <material name="pale_coated_glass">
        <color rgba="0.35 0.62 0.78 0.45" />
        </material>
      </visual>
    <visual name="finder_tube">
      <origin xyz="0.09 0 0.132" rpy="0 1.5708 0" />
      <geometry>
        <cylinder radius="0.022" length="0.55" />
        </geometry>
      <material name="matte_black_trim">
        <color rgba="0.005 0.005 0.006 1" />
        </material>
      </visual>
    <visual name="finder_lens">
      <origin xyz="0.375 0 0.132" rpy="0 1.5708 0" />
      <geometry>
        <cylinder radius="0.026" length="0.03" />
        </geometry>
      <material name="pale_coated_glass">
        <color rgba="0.35 0.62 0.78 0.45" />
        </material>
      </visual>
    <visual name="finder_stem_0">
      <origin xyz="-0.1 0 0.094" rpy="0 0 0" />
      <geometry>
        <box size="0.03 0.018 0.08" />
        </geometry>
      <material name="aged_brass">
        <color rgba="0.72 0.52 0.23 1" />
        </material>
      </visual>
    <visual name="finder_stem_1">
      <origin xyz="0.26 0 0.094" rpy="0 0 0" />
      <geometry>
        <box size="0.03 0.018 0.08" />
        </geometry>
      <material name="aged_brass">
        <color rgba="0.72 0.52 0.23 1" />
        </material>
      </visual>
    <collision name="main_tube">
      <origin xyz="0.08 0 0" rpy="0 1.5708 0" />
      <geometry>
        <mesh filename="assets/meshes/main_open_tube.obj" />
        </geometry>
      </collision>
    <collision name="balance_band">
      <origin xyz="0 0 0" rpy="0 1.5708 0" />
      <geometry>
        <cylinder radius="0.078" length="0.055" />
        </geometry>
      </collision>
    <collision name="trunnion_0">
      <origin xyz="0 0.108 0" rpy="1.5708 0 0" />
      <geometry>
        <cylinder radius="0.05" length="0.12" />
        </geometry>
      </collision>
    <collision name="trunnion_1">
      <origin xyz="0 -0.108 0" rpy="1.5708 0 0" />
      <geometry>
        <cylinder radius="0.05" length="0.12" />
        </geometry>
      </collision>
    <collision name="dew_shield">
      <origin xyz="0.89 0 0" rpy="0 1.5708 0" />
      <geometry>
        <cylinder radius="0.094" length="0.22" />
        </geometry>
      </collision>
    <collision name="objective_lens">
      <origin xyz="0.995 0 0" rpy="0 1.5708 0" />
      <geometry>
        <cylinder radius="0.07" length="0.018" />
        </geometry>
      </collision>
    <collision name="rear_cell">
      <origin xyz="-0.665 0 0" rpy="0 1.5708 0" />
      <geometry>
        <cylinder radius="0.052" length="0.035" />
        </geometry>
      </collision>
    <collision name="rear_flange">
      <origin xyz="-0.655 0 0" rpy="0 1.5708 0" />
      <geometry>
        <cylinder radius="0.08" length="0.045" />
        </geometry>
      </collision>
    <collision name="focuser_block">
      <origin xyz="-0.775 0 -0.02" rpy="0 0 0" />
      <geometry>
        <box size="0.22 0.12 0.095" />
        </geometry>
      </collision>
    <collision name="drawtube">
      <origin xyz="-0.91 0 -0.02" rpy="0 1.5708 0" />
      <geometry>
        <cylinder radius="0.032" length="0.18" />
        </geometry>
      </collision>
    <collision name="eyepiece_barrel">
      <origin xyz="-1.03 0 0.015" rpy="0 -1.5708 0" />
      <geometry>
        <cylinder radius="0.022" length="0.11" />
        </geometry>
      </collision>
    <collision name="eyepiece_glass">
      <origin xyz="-1.092 0 0.015" rpy="0 0 0" />
      <geometry>
        <sphere radius="0.021" />
        </geometry>
      </collision>
    <collision name="finder_tube">
      <origin xyz="0.09 0 0.132" rpy="0 1.5708 0" />
      <geometry>
        <cylinder radius="0.022" length="0.55" />
        </geometry>
      </collision>
    <collision name="finder_lens">
      <origin xyz="0.375 0 0.132" rpy="0 1.5708 0" />
      <geometry>
        <cylinder radius="0.026" length="0.03" />
        </geometry>
      </collision>
    <collision name="finder_stem_0">
      <origin xyz="-0.1 0 0.094" rpy="0 0 0" />
      <geometry>
        <box size="0.03 0.018 0.08" />
        </geometry>
      </collision>
    <collision name="finder_stem_1">
      <origin xyz="0.26 0 0.094" rpy="0 0 0" />
      <geometry>
        <box size="0.03 0.018 0.08" />
        </geometry>
      </collision>
    </link>
  <link name="focus_knob">
    <visual name="shaft">
      <origin xyz="0 -0.03 0" rpy="-1.5708 0 0" />
      <geometry>
        <cylinder radius="0.01" length="0.06" />
        </geometry>
      <material name="aged_brass">
        <color rgba="0.72 0.52 0.23 1" />
        </material>
      </visual>
    <visual name="knurled_wheel">
      <origin xyz="0 -0.07 0" rpy="-1.5708 0 0" />
      <geometry>
        <mesh filename="assets/meshes/fine_focus_knob.obj" />
        </geometry>
      <material name="matte_black_trim">
        <color rgba="0.005 0.005 0.006 1" />
        </material>
      </visual>
    <collision name="shaft">
      <origin xyz="0 -0.03 0" rpy="-1.5708 0 0" />
      <geometry>
        <cylinder radius="0.01" length="0.06" />
        </geometry>
      </collision>
    <collision name="knurled_wheel">
      <origin xyz="0 -0.07 0" rpy="-1.5708 0 0" />
      <geometry>
        <mesh filename="assets/meshes/fine_focus_knob.obj" />
        </geometry>
      </collision>
    </link>
  <joint name="tripod_to_azimuth" type="revolute">
    <origin xyz="0 0 0.88" rpy="0 0 0" />
    <parent link="tripod" />
    <child link="azimuth_head" />
    <axis xyz="0 0 1" />
    <limit effort="25" velocity="0.8" lower="-3.14159" upper="3.14159" />
    </joint>
  <joint name="azimuth_to_telescope" type="revolute">
    <origin xyz="0 0 0.52" rpy="0 0 0" />
    <parent link="azimuth_head" />
    <child link="telescope" />
    <axis xyz="0 -1 0" />
    <limit effort="18" velocity="0.7" lower="-0.25" upper="1.2" />
    </joint>
  <joint name="telescope_to_focus_knob" type="revolute">
    <origin xyz="-0.79 -0.06 -0.02" rpy="0 0 0" />
    <parent link="telescope" />
    <child link="focus_knob" />
    <axis xyz="0 1 0" />
    <limit effort="0.5" velocity="8" lower="-3.14159" upper="3.14159" />
    </joint>
  </robot>
