<robot name="front_load_washer_with_add_door">
  <material name="warm_white_enamel">
    <color rgba="0.94 0.95 0.94 1" />
    </material>
  <material name="slightly_recessed_white">
    <color rgba="0.86 0.88 0.88 1" />
    </material>
  <material name="smoked_black_glass">
    <color rgba="0.02 0.025 0.03 1" />
    </material>
  <material name="blue_tinted_glass">
    <color rgba="0.36 0.62 0.82 0.45" />
    </material>
  <material name="dark_rubber_gasket">
    <color rgba="0.01 0.012 0.012 1" />
    </material>
  <material name="brushed_steel">
    <color rgba="0.58 0.6 0.62 1" />
    </material>
  <material name="charcoal_plastic">
    <color rgba="0.08 0.09 0.1 1" />
    </material>
  <link name="cabinet">
    <visual name="body_shell">
      <origin xyz="0 0 0.46" rpy="0 0 0" />
      <geometry>
        <box size="0.68 0.62 0.84" />
        </geometry>
      <material name="warm_white_enamel">
        <color rgba="0.94 0.95 0.94 1" />
        </material>
      </visual>
    <visual name="control_panel">
      <origin xyz="0 -0.325 0.815" rpy="0 0 0" />
      <geometry>
        <box size="0.64 0.03 0.125" />
        </geometry>
      <material name="slightly_recessed_white">
        <color rgba="0.86 0.88 0.88 1" />
        </material>
      </visual>
    <visual name="front_recess">
      <origin xyz="0 -0.321 0.47" rpy="0 0 0" />
      <geometry>
        <box size="0.58 0.018 0.54" />
        </geometry>
      <material name="slightly_recessed_white">
        <color rgba="0.86 0.88 0.88 1" />
        </material>
      </visual>
    <visual name="porthole_gasket">
      <origin xyz="0 -0.315 0.47" rpy="0 0 0" />
      <geometry>
        <mesh filename="assets/meshes/porthole_gasket.obj" />
        </geometry>
      <material name="dark_rubber_gasket">
        <color rgba="0.01 0.012 0.012 1" />
        </material>
      </visual>
    <visual name="door_shadow_trim">
      <origin xyz="0 -0.32 0.47" rpy="0 0 0" />
      <geometry>
        <mesh filename="assets/meshes/door_shadow_trim.obj" />
        </geometry>
      <material name="charcoal_plastic">
        <color rgba="0.08 0.09 0.1 1" />
        </material>
      </visual>
    <visual name="detergent_drawer">
      <origin xyz="-0.205 -0.343 0.825" rpy="0 0 0" />
      <geometry>
        <box size="0.205 0.012 0.046" />
        </geometry>
      <material name="warm_white_enamel">
        <color rgba="0.94 0.95 0.94 1" />
        </material>
      </visual>
    <visual name="toe_kick">
      <origin xyz="0 -0.319 0.078" rpy="0 0 0" />
      <geometry>
        <box size="0.61 0.02 0.055" />
        </geometry>
      <material name="slightly_recessed_white">
        <color rgba="0.86 0.88 0.88 1" />
        </material>
      </visual>
    <visual name="foot_0">
      <origin xyz="-0.265 -0.225 0.02" rpy="0 0 0" />
      <geometry>
        <box size="0.075 0.075 0.04" />
        </geometry>
      <material name="charcoal_plastic">
        <color rgba="0.08 0.09 0.1 1" />
        </material>
      </visual>
    <visual name="foot_1">
      <origin xyz="0.265 -0.225 0.02" rpy="0 0 0" />
      <geometry>
        <box size="0.075 0.075 0.04" />
        </geometry>
      <material name="charcoal_plastic">
        <color rgba="0.08 0.09 0.1 1" />
        </material>
      </visual>
    <visual name="foot_2">
      <origin xyz="-0.265 0.225 0.02" rpy="0 0 0" />
      <geometry>
        <box size="0.075 0.075 0.04" />
        </geometry>
      <material name="charcoal_plastic">
        <color rgba="0.08 0.09 0.1 1" />
        </material>
      </visual>
    <visual name="foot_3">
      <origin xyz="0.265 0.225 0.02" rpy="0 0 0" />
      <geometry>
        <box size="0.075 0.075 0.04" />
        </geometry>
      <material name="charcoal_plastic">
        <color rgba="0.08 0.09 0.1 1" />
        </material>
      </visual>
    <visual name="main_hinge_mount">
      <origin xyz="-0.315 -0.323 0.47" rpy="0 0 0" />
      <geometry>
        <box size="0.02 0.074 0.48" />
        </geometry>
      <material name="brushed_steel">
        <color rgba="0.58 0.6 0.62 1" />
        </material>
      </visual>
    <collision name="body_shell">
      <origin xyz="0 0 0.46" rpy="0 0 0" />
      <geometry>
        <box size="0.68 0.62 0.84" />
        </geometry>
      </collision>
    <collision name="control_panel">
      <origin xyz="0 -0.325 0.815" rpy="0 0 0" />
      <geometry>
        <box size="0.64 0.03 0.125" />
        </geometry>
      </collision>
    <collision name="front_recess">
      <origin xyz="0 -0.321 0.47" rpy="0 0 0" />
      <geometry>
        <box size="0.58 0.018 0.54" />
        </geometry>
      </collision>
    <collision name="porthole_gasket">
      <origin xyz="0 -0.315 0.47" rpy="0 0 0" />
      <geometry>
        <mesh filename="assets/meshes/porthole_gasket.obj" />
        </geometry>
      </collision>
    <collision name="door_shadow_trim">
      <origin xyz="0 -0.32 0.47" rpy="0 0 0" />
      <geometry>
        <mesh filename="assets/meshes/door_shadow_trim.obj" />
        </geometry>
      </collision>
    <collision name="detergent_drawer">
      <origin xyz="-0.205 -0.343 0.825" rpy="0 0 0" />
      <geometry>
        <box size="0.205 0.012 0.046" />
        </geometry>
      </collision>
    <collision name="toe_kick">
      <origin xyz="0 -0.319 0.078" rpy="0 0 0" />
      <geometry>
        <box size="0.61 0.02 0.055" />
        </geometry>
      </collision>
    <collision name="foot_0">
      <origin xyz="-0.265 -0.225 0.02" rpy="0 0 0" />
      <geometry>
        <box size="0.075 0.075 0.04" />
        </geometry>
      </collision>
    <collision name="foot_1">
      <origin xyz="0.265 -0.225 0.02" rpy="0 0 0" />
      <geometry>
        <box size="0.075 0.075 0.04" />
        </geometry>
      </collision>
    <collision name="foot_2">
      <origin xyz="-0.265 0.225 0.02" rpy="0 0 0" />
      <geometry>
        <box size="0.075 0.075 0.04" />
        </geometry>
      </collision>
    <collision name="foot_3">
      <origin xyz="0.265 0.225 0.02" rpy="0 0 0" />
      <geometry>
        <box size="0.075 0.075 0.04" />
        </geometry>
      </collision>
    <collision name="main_hinge_mount">
      <origin xyz="-0.315 -0.323 0.47" rpy="0 0 0" />
      <geometry>
        <box size="0.02 0.074 0.48" />
        </geometry>
      </collision>
    </link>
  <link name="main_door">
    <visual name="door_ring">
      <origin xyz="0.27 0 0" rpy="0 0 0" />
      <geometry>
        <mesh filename="assets/meshes/main_door_ring.obj" />
        </geometry>
      <material name="warm_white_enamel">
        <color rgba="0.94 0.95 0.94 1" />
        </material>
      </visual>
    <visual name="main_glass">
      <origin xyz="0.27 -0.003 0" rpy="1.5708 0 0" />
      <geometry>
        <cylinder radius="0.176" length="0.016" />
        </geometry>
      <material name="blue_tinted_glass">
        <color rgba="0.36 0.62 0.82 0.45" />
        </material>
      </visual>
    <visual name="inner_smoke_lens">
      <origin xyz="0.27 0.008 0" rpy="1.5708 0 0" />
      <geometry>
        <cylinder radius="0.132" length="0.01" />
        </geometry>
      <material name="smoked_black_glass">
        <color rgba="0.02 0.025 0.03 1" />
        </material>
      </visual>
    <visual name="add_frame">
      <origin xyz="0.27 -0.0315 0.105" rpy="0 0 0" />
      <geometry>
        <mesh filename="assets/meshes/add_door_surround.obj" />
        </geometry>
      <material name="charcoal_plastic">
        <color rgba="0.08 0.09 0.1 1" />
        </material>
      </visual>
    <visual name="hinge_leaf">
      <origin xyz="0.026 0 0" rpy="0 0 0" />
      <geometry>
        <box size="0.043 0.018 0.49" />
        </geometry>
      <material name="brushed_steel">
        <color rgba="0.58 0.6 0.62 1" />
        </material>
      </visual>
    <visual name="hinge_knuckle_0">
      <origin xyz="0 0 -0.178" rpy="0 0 0" />
      <geometry>
        <cylinder radius="0.018" length="0.102" />
        </geometry>
      <material name="brushed_steel">
        <color rgba="0.58 0.6 0.62 1" />
        </material>
      </visual>
    <visual name="hinge_knuckle_1">
      <geometry>
        <cylinder radius="0.018" length="0.102" />
        </geometry>
      <material name="brushed_steel">
        <color rgba="0.58 0.6 0.62 1" />
        </material>
      </visual>
    <visual name="hinge_knuckle_2">
      <origin xyz="0 0 0.178" rpy="0 0 0" />
      <geometry>
        <cylinder radius="0.018" length="0.102" />
        </geometry>
      <material name="brushed_steel">
        <color rgba="0.58 0.6 0.62 1" />
        </material>
      </visual>
    <visual name="pull_lip">
      <origin xyz="0.5 -0.02 0.015" rpy="0 0 0" />
      <geometry>
        <box size="0.03 0.02 0.08" />
        </geometry>
      <material name="warm_white_enamel">
        <color rgba="0.94 0.95 0.94 1" />
        </material>
      </visual>
    <collision name="door_ring">
      <origin xyz="0.27 0 0" rpy="0 0 0" />
      <geometry>
        <mesh filename="assets/meshes/main_door_ring.obj" />
        </geometry>
      </collision>
    <collision name="main_glass">
      <origin xyz="0.27 -0.003 0" rpy="1.5708 0 0" />
      <geometry>
        <cylinder radius="0.176" length="0.016" />
        </geometry>
      </collision>
    <collision name="inner_smoke_lens">
      <origin xyz="0.27 0.008 0" rpy="1.5708 0 0" />
      <geometry>
        <cylinder radius="0.132" length="0.01" />
        </geometry>
      </collision>
    <collision name="add_frame">
      <origin xyz="0.27 -0.0315 0.105" rpy="0 0 0" />
      <geometry>
        <mesh filename="assets/meshes/add_door_surround.obj" />
        </geometry>
      </collision>
    <collision name="hinge_leaf">
      <origin xyz="0.026 0 0" rpy="0 0 0" />
      <geometry>
        <box size="0.043 0.018 0.49" />
        </geometry>
      </collision>
    <collision name="hinge_knuckle_0">
      <origin xyz="0 0 -0.178" rpy="0 0 0" />
      <geometry>
        <cylinder radius="0.018" length="0.102" />
        </geometry>
      </collision>
    <collision name="hinge_knuckle_1">
      <geometry>
        <cylinder radius="0.018" length="0.102" />
        </geometry>
      </collision>
    <collision name="hinge_knuckle_2">
      <origin xyz="0 0 0.178" rpy="0 0 0" />
      <geometry>
        <cylinder radius="0.018" length="0.102" />
        </geometry>
      </collision>
    <collision name="pull_lip">
      <origin xyz="0.5 -0.02 0.015" rpy="0 0 0" />
      <geometry>
        <box size="0.03 0.02 0.08" />
        </geometry>
      </collision>
    </link>
  <link name="add_door">
    <visual name="add_panel">
      <origin xyz="0.0725 0 0" rpy="0 0 0" />
      <geometry>
        <mesh filename="assets/meshes/add_panel.obj" />
        </geometry>
      <material name="blue_tinted_glass">
        <color rgba="0.36 0.62 0.82 0.45" />
        </material>
      </visual>
    <visual name="add_trim">
      <origin xyz="0.0725 -0.006 0" rpy="0 0 0" />
      <geometry>
        <mesh filename="assets/meshes/add_trim.obj" />
        </geometry>
      <material name="warm_white_enamel">
        <color rgba="0.94 0.95 0.94 1" />
        </material>
      </visual>
    <visual name="add_hinge_barrel">
      <geometry>
        <cylinder radius="0.008" length="0.122" />
        </geometry>
      <material name="brushed_steel">
        <color rgba="0.58 0.6 0.62 1" />
        </material>
      </visual>
    <visual name="add_pull_tab">
      <origin xyz="0.146 -0.006 -0.004" rpy="0 0 0" />
      <geometry>
        <box size="0.02 0.014 0.055" />
        </geometry>
      <material name="warm_white_enamel">
        <color rgba="0.94 0.95 0.94 1" />
        </material>
      </visual>
    <collision name="add_panel">
      <origin xyz="0.0725 0 0" rpy="0 0 0" />
      <geometry>
        <mesh filename="assets/meshes/add_panel.obj" />
        </geometry>
      </collision>
    <collision name="add_trim">
      <origin xyz="0.0725 -0.006 0" rpy="0 0 0" />
      <geometry>
        <mesh filename="assets/meshes/add_trim.obj" />
        </geometry>
      </collision>
    <collision name="add_hinge_barrel">
      <geometry>
        <cylinder radius="0.008" length="0.122" />
        </geometry>
      </collision>
    <collision name="add_pull_tab">
      <origin xyz="0.146 -0.006 -0.004" rpy="0 0 0" />
      <geometry>
        <box size="0.02 0.014 0.055" />
        </geometry>
      </collision>
    </link>
  <link name="program_knob">
    <visual name="knob_cap">
      <origin xyz="0 -0.016 0" rpy="1.5708 0 0" />
      <geometry>
        <mesh filename="assets/meshes/program_knob.obj" />
        </geometry>
      <material name="warm_white_enamel">
        <color rgba="0.94 0.95 0.94 1" />
        </material>
      </visual>
    <collision name="knob_cap">
      <origin xyz="0 -0.016 0" rpy="1.5708 0 0" />
      <geometry>
        <mesh filename="assets/meshes/program_knob.obj" />
        </geometry>
      </collision>
    </link>
  <link name="button_0">
    <visual name="button_cap">
      <origin xyz="0 -0.006 0" rpy="0 0 0" />
      <geometry>
        <box size="0.03 0.012 0.02" />
        </geometry>
      <material name="charcoal_plastic">
        <color rgba="0.08 0.09 0.1 1" />
        </material>
      </visual>
    <collision name="button_cap">
      <origin xyz="0 -0.006 0" rpy="0 0 0" />
      <geometry>
        <box size="0.03 0.012 0.02" />
        </geometry>
      </collision>
    </link>
  <link name="button_1">
    <visual name="button_cap">
      <origin xyz="0 -0.006 0" rpy="0 0 0" />
      <geometry>
        <box size="0.03 0.012 0.02" />
        </geometry>
      <material name="charcoal_plastic">
        <color rgba="0.08 0.09 0.1 1" />
        </material>
      </visual>
    <collision name="button_cap">
      <origin xyz="0 -0.006 0" rpy="0 0 0" />
      <geometry>
        <box size="0.03 0.012 0.02" />
        </geometry>
      </collision>
    </link>
  <link name="button_2">
    <visual name="button_cap">
      <origin xyz="0 -0.006 0" rpy="0 0 0" />
      <geometry>
        <box size="0.03 0.012 0.02" />
        </geometry>
      <material name="charcoal_plastic">
        <color rgba="0.08 0.09 0.1 1" />
        </material>
      </visual>
    <collision name="button_cap">
      <origin xyz="0 -0.006 0" rpy="0 0 0" />
      <geometry>
        <box size="0.03 0.012 0.02" />
        </geometry>
      </collision>
    </link>
  <joint name="main_hinge" type="revolute">
    <origin xyz="-0.27 -0.355 0.47" rpy="0 0 0" />
    <parent link="cabinet" />
    <child link="main_door" />
    <axis xyz="0 0 -1" />
    <limit effort="70" velocity="1.2" lower="0" upper="1.75" />
    </joint>
  <joint name="add_hinge" type="revolute">
    <origin xyz="0.195 -0.0435 0.105" rpy="0 0 0" />
    <parent link="main_door" />
    <child link="add_door" />
    <axis xyz="0 0 -1" />
    <limit effort="8" velocity="1.5" lower="0" upper="1.35" />
    </joint>
  <joint name="knob_spin" type="revolute">
    <origin xyz="0.11 -0.34 0.825" rpy="0 0 0" />
    <parent link="cabinet" />
    <child link="program_knob" />
    <axis xyz="0 -1 0" />
    <limit effort="1.5" velocity="3" lower="-3.14159" upper="3.14159" />
    </joint>
  <joint name="button_press_0" type="prismatic">
    <origin xyz="0.215 -0.34 0.828" rpy="0 0 0" />
    <parent link="cabinet" />
    <child link="button_0" />
    <axis xyz="0 1 0" />
    <limit effort="2" velocity="0.08" lower="0" upper="0.004" />
    </joint>
  <joint name="button_press_1" type="prismatic">
    <origin xyz="0.265 -0.34 0.828" rpy="0 0 0" />
    <parent link="cabinet" />
    <child link="button_1" />
    <axis xyz="0 1 0" />
    <limit effort="2" velocity="0.08" lower="0" upper="0.004" />
    </joint>
  <joint name="button_press_2" type="prismatic">
    <origin xyz="0.315 -0.34 0.828" rpy="0 0 0" />
    <parent link="cabinet" />
    <child link="button_2" />
    <axis xyz="0 1 0" />
    <limit effort="2" velocity="0.08" lower="0" upper="0.004" />
    </joint>
  </robot>
