<robot name="secretary_desk">
  <material name="aged_walnut">
    <color rgba="0.42 0.22 0.1 1" />
    </material>
  <material name="dark_endgrain">
    <color rgba="0.25 0.12 0.055 1" />
    </material>
  <material name="warm_brass">
    <color rgba="0.86 0.62 0.24 1" />
    </material>
  <material name="shadowed_interior">
    <color rgba="0.12 0.075 0.045 1" />
    </material>
  <material name="dark_steel">
    <color rgba="0.18 0.18 0.17 1" />
    </material>
  <link name="case">
    <visual name="side_panel_0">
      <origin xyz="-0.4825 0 0.7" rpy="0 0 0" />
      <geometry>
        <box size="0.035 0.42 1.3" />
        </geometry>
      <material name="aged_walnut">
        <color rgba="0.42 0.22 0.1 1" />
        </material>
      </visual>
    <visual name="side_panel_1">
      <origin xyz="0.4825 0 0.7" rpy="0 0 0" />
      <geometry>
        <box size="0.035 0.42 1.3" />
        </geometry>
      <material name="aged_walnut">
        <color rgba="0.42 0.22 0.1 1" />
        </material>
      </visual>
    <visual name="back_panel">
      <origin xyz="0 0.1975 0.7" rpy="0 0 0" />
      <geometry>
        <box size="1 0.025 1.3" />
        </geometry>
      <material name="dark_endgrain">
        <color rgba="0.25 0.12 0.055 1" />
        </material>
      </visual>
    <visual name="bottom_deck">
      <origin xyz="0 0 0.0675" rpy="0 0 0" />
      <geometry>
        <box size="1 0.42 0.035" />
        </geometry>
      <material name="aged_walnut">
        <color rgba="0.42 0.22 0.1 1" />
        </material>
      </visual>
    <visual name="top_cap">
      <origin xyz="0 0 1.3325" rpy="0 0 0" />
      <geometry>
        <box size="1 0.42 0.035" />
        </geometry>
      <material name="aged_walnut">
        <color rgba="0.42 0.22 0.1 1" />
        </material>
      </visual>
    <visual name="writing_floor">
      <origin xyz="0 0 0.355" rpy="0 0 0" />
      <geometry>
        <box size="1 0.42 0.03" />
        </geometry>
      <material name="aged_walnut">
        <color rgba="0.42 0.22 0.1 1" />
        </material>
      </visual>
    <visual name="upper_shelf">
      <origin xyz="0 0 0.895" rpy="0 0 0" />
      <geometry>
        <box size="1 0.42 0.03" />
        </geometry>
      <material name="aged_walnut">
        <color rgba="0.42 0.22 0.1 1" />
        </material>
      </visual>
    <visual name="front_stile_0">
      <origin xyz="-0.4825 -0.225 0.7" rpy="0 0 0" />
      <geometry>
        <box size="0.035 0.03 1.3" />
        </geometry>
      <material name="dark_endgrain">
        <color rgba="0.25 0.12 0.055 1" />
        </material>
      </visual>
    <visual name="front_stile_1">
      <origin xyz="0.4825 -0.225 0.7" rpy="0 0 0" />
      <geometry>
        <box size="0.035 0.03 1.3" />
        </geometry>
      <material name="dark_endgrain">
        <color rgba="0.25 0.12 0.055 1" />
        </material>
      </visual>
    <visual name="upper_center_stile">
      <origin xyz="0 -0.225 1.105" rpy="0 0 0" />
      <geometry>
        <box size="0.035 0.03 0.4" />
        </geometry>
      <material name="dark_endgrain">
        <color rgba="0.25 0.12 0.055 1" />
        </material>
      </visual>
    <visual name="toe_rail">
      <origin xyz="0 -0.225 0.075" rpy="0 0 0" />
      <geometry>
        <box size="1 0.03 0.05" />
        </geometry>
      <material name="dark_endgrain">
        <color rgba="0.25 0.12 0.055 1" />
        </material>
      </visual>
    <visual name="drawer_top_rail">
      <origin xyz="0 -0.225 0.355" rpy="0 0 0" />
      <geometry>
        <box size="1 0.03 0.04" />
        </geometry>
      <material name="dark_endgrain">
        <color rgba="0.25 0.12 0.055 1" />
        </material>
      </visual>
    <visual name="writing_top_rail">
      <origin xyz="0 -0.225 0.895" rpy="0 0 0" />
      <geometry>
        <box size="1 0.03 0.04" />
        </geometry>
      <material name="dark_endgrain">
        <color rgba="0.25 0.12 0.055 1" />
        </material>
      </visual>
    <visual name="upper_top_rail">
      <origin xyz="0 -0.225 1.3" rpy="0 0 0" />
      <geometry>
        <box size="1 0.03 0.07" />
        </geometry>
      <material name="dark_endgrain">
        <color rgba="0.25 0.12 0.055 1" />
        </material>
      </visual>
    <visual name="writing_shadow">
      <origin xyz="0 0.182 0.62" rpy="0 0 0" />
      <geometry>
        <box size="0.86 0.006 0.47" />
        </geometry>
      <material name="shadowed_interior">
        <color rgba="0.12 0.075 0.045 1" />
        </material>
      </visual>
    <visual name="upper_shadow">
      <origin xyz="0 0.182 1.105" rpy="0 0 0" />
      <geometry>
        <box size="0.86 0.006 0.36" />
        </geometry>
      <material name="shadowed_interior">
        <color rgba="0.12 0.075 0.045 1" />
        </material>
      </visual>
    <visual name="guide_rail_0">
      <origin xyz="-0.455 -0.04 0.205" rpy="0 0 0" />
      <geometry>
        <box size="0.04 0.36 0.018" />
        </geometry>
      <material name="dark_steel">
        <color rgba="0.18 0.18 0.17 1" />
        </material>
      </visual>
    <visual name="guide_rail_1">
      <origin xyz="0.455 -0.04 0.205" rpy="0 0 0" />
      <geometry>
        <box size="0.04 0.36 0.018" />
        </geometry>
      <material name="dark_steel">
        <color rgba="0.18 0.18 0.17 1" />
        </material>
      </visual>
    <collision name="side_panel_0">
      <origin xyz="-0.4825 0 0.7" rpy="0 0 0" />
      <geometry>
        <box size="0.035 0.42 1.3" />
        </geometry>
      </collision>
    <collision name="side_panel_1">
      <origin xyz="0.4825 0 0.7" rpy="0 0 0" />
      <geometry>
        <box size="0.035 0.42 1.3" />
        </geometry>
      </collision>
    <collision name="back_panel">
      <origin xyz="0 0.1975 0.7" rpy="0 0 0" />
      <geometry>
        <box size="1 0.025 1.3" />
        </geometry>
      </collision>
    <collision name="bottom_deck">
      <origin xyz="0 0 0.0675" rpy="0 0 0" />
      <geometry>
        <box size="1 0.42 0.035" />
        </geometry>
      </collision>
    <collision name="top_cap">
      <origin xyz="0 0 1.3325" rpy="0 0 0" />
      <geometry>
        <box size="1 0.42 0.035" />
        </geometry>
      </collision>
    <collision name="writing_floor">
      <origin xyz="0 0 0.355" rpy="0 0 0" />
      <geometry>
        <box size="1 0.42 0.03" />
        </geometry>
      </collision>
    <collision name="upper_shelf">
      <origin xyz="0 0 0.895" rpy="0 0 0" />
      <geometry>
        <box size="1 0.42 0.03" />
        </geometry>
      </collision>
    <collision name="front_stile_0">
      <origin xyz="-0.4825 -0.225 0.7" rpy="0 0 0" />
      <geometry>
        <box size="0.035 0.03 1.3" />
        </geometry>
      </collision>
    <collision name="front_stile_1">
      <origin xyz="0.4825 -0.225 0.7" rpy="0 0 0" />
      <geometry>
        <box size="0.035 0.03 1.3" />
        </geometry>
      </collision>
    <collision name="upper_center_stile">
      <origin xyz="0 -0.225 1.105" rpy="0 0 0" />
      <geometry>
        <box size="0.035 0.03 0.4" />
        </geometry>
      </collision>
    <collision name="toe_rail">
      <origin xyz="0 -0.225 0.075" rpy="0 0 0" />
      <geometry>
        <box size="1 0.03 0.05" />
        </geometry>
      </collision>
    <collision name="drawer_top_rail">
      <origin xyz="0 -0.225 0.355" rpy="0 0 0" />
      <geometry>
        <box size="1 0.03 0.04" />
        </geometry>
      </collision>
    <collision name="writing_top_rail">
      <origin xyz="0 -0.225 0.895" rpy="0 0 0" />
      <geometry>
        <box size="1 0.03 0.04" />
        </geometry>
      </collision>
    <collision name="upper_top_rail">
      <origin xyz="0 -0.225 1.3" rpy="0 0 0" />
      <geometry>
        <box size="1 0.03 0.07" />
        </geometry>
      </collision>
    <collision name="writing_shadow">
      <origin xyz="0 0.182 0.62" rpy="0 0 0" />
      <geometry>
        <box size="0.86 0.006 0.47" />
        </geometry>
      </collision>
    <collision name="upper_shadow">
      <origin xyz="0 0.182 1.105" rpy="0 0 0" />
      <geometry>
        <box size="0.86 0.006 0.36" />
        </geometry>
      </collision>
    <collision name="guide_rail_0">
      <origin xyz="-0.455 -0.04 0.205" rpy="0 0 0" />
      <geometry>
        <box size="0.04 0.36 0.018" />
        </geometry>
      </collision>
    <collision name="guide_rail_1">
      <origin xyz="0.455 -0.04 0.205" rpy="0 0 0" />
      <geometry>
        <box size="0.04 0.36 0.018" />
        </geometry>
      </collision>
    </link>
  <link name="drawer">
    <visual name="drawer_front">
      <geometry>
        <box size="0.9 0.04 0.22" />
        </geometry>
      <material name="aged_walnut">
        <color rgba="0.42 0.22 0.1 1" />
        </material>
      </visual>
    <visual name="drawer_bottom">
      <origin xyz="0 0.2 -0.088" rpy="0 0 0" />
      <geometry>
        <box size="0.835 0.38 0.014" />
        </geometry>
      <material name="dark_endgrain">
        <color rgba="0.25 0.12 0.055 1" />
        </material>
      </visual>
    <visual name="drawer_side_0">
      <origin xyz="-0.425 0.2 -0.02" rpy="0 0 0" />
      <geometry>
        <box size="0.02 0.38 0.14" />
        </geometry>
      <material name="aged_walnut">
        <color rgba="0.42 0.22 0.1 1" />
        </material>
      </visual>
    <visual name="drawer_side_1">
      <origin xyz="0.425 0.2 -0.02" rpy="0 0 0" />
      <geometry>
        <box size="0.02 0.38 0.14" />
        </geometry>
      <material name="aged_walnut">
        <color rgba="0.42 0.22 0.1 1" />
        </material>
      </visual>
    <visual name="drawer_back">
      <origin xyz="0 0.386 -0.02" rpy="0 0 0" />
      <geometry>
        <box size="0.84 0.018 0.135" />
        </geometry>
      <material name="aged_walnut">
        <color rgba="0.42 0.22 0.1 1" />
        </material>
      </visual>
    <visual name="moving_rail_0">
      <origin xyz="-0.407 0.205 -0.03" rpy="0 0 0" />
      <geometry>
        <box size="0.016 0.41 0.016" />
        </geometry>
      <material name="dark_steel">
        <color rgba="0.18 0.18 0.17 1" />
        </material>
      </visual>
    <visual name="moving_rail_1">
      <origin xyz="0.407 0.205 -0.03" rpy="0 0 0" />
      <geometry>
        <box size="0.016 0.41 0.016" />
        </geometry>
      <material name="dark_steel">
        <color rgba="0.18 0.18 0.17 1" />
        </material>
      </visual>
    <visual name="pull_post_0">
      <origin xyz="-0.13 -0.036 0.018" rpy="1.5708 0 0" />
      <geometry>
        <cylinder radius="0.01" length="0.06" />
        </geometry>
      <material name="warm_brass">
        <color rgba="0.86 0.62 0.24 1" />
        </material>
      </visual>
    <visual name="pull_post_1">
      <origin xyz="0.13 -0.036 0.018" rpy="1.5708 0 0" />
      <geometry>
        <cylinder radius="0.01" length="0.06" />
        </geometry>
      <material name="warm_brass">
        <color rgba="0.86 0.62 0.24 1" />
        </material>
      </visual>
    <visual name="drawer_pull">
      <origin xyz="0 -0.07 0.018" rpy="0 1.5708 0" />
      <geometry>
        <cylinder radius="0.012" length="0.28" />
        </geometry>
      <material name="warm_brass">
        <color rgba="0.86 0.62 0.24 1" />
        </material>
      </visual>
    <collision name="drawer_front">
      <geometry>
        <box size="0.9 0.04 0.22" />
        </geometry>
      </collision>
    <collision name="drawer_bottom">
      <origin xyz="0 0.2 -0.088" rpy="0 0 0" />
      <geometry>
        <box size="0.835 0.38 0.014" />
        </geometry>
      </collision>
    <collision name="drawer_side_0">
      <origin xyz="-0.425 0.2 -0.02" rpy="0 0 0" />
      <geometry>
        <box size="0.02 0.38 0.14" />
        </geometry>
      </collision>
    <collision name="drawer_side_1">
      <origin xyz="0.425 0.2 -0.02" rpy="0 0 0" />
      <geometry>
        <box size="0.02 0.38 0.14" />
        </geometry>
      </collision>
    <collision name="drawer_back">
      <origin xyz="0 0.386 -0.02" rpy="0 0 0" />
      <geometry>
        <box size="0.84 0.018 0.135" />
        </geometry>
      </collision>
    <collision name="moving_rail_0">
      <origin xyz="-0.407 0.205 -0.03" rpy="0 0 0" />
      <geometry>
        <box size="0.016 0.41 0.016" />
        </geometry>
      </collision>
    <collision name="moving_rail_1">
      <origin xyz="0.407 0.205 -0.03" rpy="0 0 0" />
      <geometry>
        <box size="0.016 0.41 0.016" />
        </geometry>
      </collision>
    <collision name="pull_post_0">
      <origin xyz="-0.13 -0.036 0.018" rpy="1.5708 0 0" />
      <geometry>
        <cylinder radius="0.01" length="0.06" />
        </geometry>
      </collision>
    <collision name="pull_post_1">
      <origin xyz="0.13 -0.036 0.018" rpy="1.5708 0 0" />
      <geometry>
        <cylinder radius="0.01" length="0.06" />
        </geometry>
      </collision>
    <collision name="drawer_pull">
      <origin xyz="0 -0.07 0.018" rpy="0 1.5708 0" />
      <geometry>
        <cylinder radius="0.012" length="0.28" />
        </geometry>
      </collision>
    </link>
  <link name="writing_panel">
    <visual name="writing_slab">
      <origin xyz="0 -0.015 0.235" rpy="0 0 0" />
      <geometry>
        <box size="0.86 0.03 0.47" />
        </geometry>
      <material name="aged_walnut">
        <color rgba="0.42 0.22 0.1 1" />
        </material>
      </visual>
    <visual name="writing_lower_trim">
      <origin xyz="0 -0.038 0.045" rpy="0 0 0" />
      <geometry>
        <box size="0.8 0.018 0.035" />
        </geometry>
      <material name="dark_endgrain">
        <color rgba="0.25 0.12 0.055 1" />
        </material>
      </visual>
    <visual name="writing_upper_trim">
      <origin xyz="0 -0.038 0.425" rpy="0 0 0" />
      <geometry>
        <box size="0.8 0.018 0.035" />
        </geometry>
      <material name="dark_endgrain">
        <color rgba="0.25 0.12 0.055 1" />
        </material>
      </visual>
    <visual name="writing_side_trim_0">
      <origin xyz="-0.38 -0.038 0.235" rpy="0 0 0" />
      <geometry>
        <box size="0.035 0.018 0.39" />
        </geometry>
      <material name="dark_endgrain">
        <color rgba="0.25 0.12 0.055 1" />
        </material>
      </visual>
    <visual name="writing_side_trim_1">
      <origin xyz="0.38 -0.038 0.235" rpy="0 0 0" />
      <geometry>
        <box size="0.035 0.018 0.39" />
        </geometry>
      <material name="dark_endgrain">
        <color rgba="0.25 0.12 0.055 1" />
        </material>
      </visual>
    <visual name="piano_hinge">
      <origin xyz="0 -0.011 0" rpy="0 1.5708 0" />
      <geometry>
        <cylinder radius="0.015" length="0.82" />
        </geometry>
      <material name="warm_brass">
        <color rgba="0.86 0.62 0.24 1" />
        </material>
      </visual>
    <visual name="writing_pull_stem">
      <origin xyz="0 -0.043 0.37" rpy="1.5708 0 0" />
      <geometry>
        <cylinder radius="0.008" length="0.05" />
        </geometry>
      <material name="warm_brass">
        <color rgba="0.86 0.62 0.24 1" />
        </material>
      </visual>
    <visual name="writing_pull_knob">
      <origin xyz="0 -0.074 0.37" rpy="0 0 0" />
      <geometry>
        <sphere radius="0.022" />
        </geometry>
      <material name="warm_brass">
        <color rgba="0.86 0.62 0.24 1" />
        </material>
      </visual>
    <collision name="writing_slab">
      <origin xyz="0 -0.015 0.235" rpy="0 0 0" />
      <geometry>
        <box size="0.86 0.03 0.47" />
        </geometry>
      </collision>
    <collision name="writing_lower_trim">
      <origin xyz="0 -0.038 0.045" rpy="0 0 0" />
      <geometry>
        <box size="0.8 0.018 0.035" />
        </geometry>
      </collision>
    <collision name="writing_upper_trim">
      <origin xyz="0 -0.038 0.425" rpy="0 0 0" />
      <geometry>
        <box size="0.8 0.018 0.035" />
        </geometry>
      </collision>
    <collision name="writing_side_trim_0">
      <origin xyz="-0.38 -0.038 0.235" rpy="0 0 0" />
      <geometry>
        <box size="0.035 0.018 0.39" />
        </geometry>
      </collision>
    <collision name="writing_side_trim_1">
      <origin xyz="0.38 -0.038 0.235" rpy="0 0 0" />
      <geometry>
        <box size="0.035 0.018 0.39" />
        </geometry>
      </collision>
    <collision name="piano_hinge">
      <origin xyz="0 -0.011 0" rpy="0 1.5708 0" />
      <geometry>
        <cylinder radius="0.015" length="0.82" />
        </geometry>
      </collision>
    <collision name="writing_pull_stem">
      <origin xyz="0 -0.043 0.37" rpy="1.5708 0 0" />
      <geometry>
        <cylinder radius="0.008" length="0.05" />
        </geometry>
      </collision>
    <collision name="writing_pull_knob">
      <origin xyz="0 -0.074 0.37" rpy="0 0 0" />
      <geometry>
        <sphere radius="0.022" />
        </geometry>
      </collision>
    </link>
  <link name="door_0">
    <visual name="door_slab">
      <origin xyz="0.2025 -0.0125 0.17" rpy="0 0 0" />
      <geometry>
        <box size="0.405 0.025 0.34" />
        </geometry>
      <material name="aged_walnut">
        <color rgba="0.42 0.22 0.1 1" />
        </material>
      </visual>
    <visual name="hinge_barrel">
      <origin xyz="0 -0.014 0.17" rpy="0 0 0" />
      <geometry>
        <cylinder radius="0.009" length="0.33" />
        </geometry>
      <material name="warm_brass">
        <color rgba="0.86 0.62 0.24 1" />
        </material>
      </visual>
    <visual name="door_lower_trim">
      <origin xyz="0.2025 -0.032 0.04" rpy="0 0 0" />
      <geometry>
        <box size="0.33 0.016 0.03" />
        </geometry>
      <material name="dark_endgrain">
        <color rgba="0.25 0.12 0.055 1" />
        </material>
      </visual>
    <visual name="door_upper_trim">
      <origin xyz="0.2025 -0.032 0.3" rpy="0 0 0" />
      <geometry>
        <box size="0.33 0.016 0.03" />
        </geometry>
      <material name="dark_endgrain">
        <color rgba="0.25 0.12 0.055 1" />
        </material>
      </visual>
    <visual name="door_outer_trim">
      <origin xyz="0.0375 -0.032 0.17" rpy="0 0 0" />
      <geometry>
        <box size="0.028 0.016 0.27" />
        </geometry>
      <material name="dark_endgrain">
        <color rgba="0.25 0.12 0.055 1" />
        </material>
      </visual>
    <visual name="door_inner_trim">
      <origin xyz="0.3675 -0.032 0.17" rpy="0 0 0" />
      <geometry>
        <box size="0.028 0.016 0.27" />
        </geometry>
      <material name="dark_endgrain">
        <color rgba="0.25 0.12 0.055 1" />
        </material>
      </visual>
    <visual name="knob_stem">
      <origin xyz="0.355 -0.038 0.17" rpy="1.5708 0 0" />
      <geometry>
        <cylinder radius="0.007" length="0.042" />
        </geometry>
      <material name="warm_brass">
        <color rgba="0.86 0.62 0.24 1" />
        </material>
      </visual>
    <visual name="door_knob">
      <origin xyz="0.355 -0.064 0.17" rpy="0 0 0" />
      <geometry>
        <sphere radius="0.018" />
        </geometry>
      <material name="warm_brass">
        <color rgba="0.86 0.62 0.24 1" />
        </material>
      </visual>
    <collision name="door_slab">
      <origin xyz="0.2025 -0.0125 0.17" rpy="0 0 0" />
      <geometry>
        <box size="0.405 0.025 0.34" />
        </geometry>
      </collision>
    <collision name="hinge_barrel">
      <origin xyz="0 -0.014 0.17" rpy="0 0 0" />
      <geometry>
        <cylinder radius="0.009" length="0.33" />
        </geometry>
      </collision>
    <collision name="door_lower_trim">
      <origin xyz="0.2025 -0.032 0.04" rpy="0 0 0" />
      <geometry>
        <box size="0.33 0.016 0.03" />
        </geometry>
      </collision>
    <collision name="door_upper_trim">
      <origin xyz="0.2025 -0.032 0.3" rpy="0 0 0" />
      <geometry>
        <box size="0.33 0.016 0.03" />
        </geometry>
      </collision>
    <collision name="door_outer_trim">
      <origin xyz="0.0375 -0.032 0.17" rpy="0 0 0" />
      <geometry>
        <box size="0.028 0.016 0.27" />
        </geometry>
      </collision>
    <collision name="door_inner_trim">
      <origin xyz="0.3675 -0.032 0.17" rpy="0 0 0" />
      <geometry>
        <box size="0.028 0.016 0.27" />
        </geometry>
      </collision>
    <collision name="knob_stem">
      <origin xyz="0.355 -0.038 0.17" rpy="1.5708 0 0" />
      <geometry>
        <cylinder radius="0.007" length="0.042" />
        </geometry>
      </collision>
    <collision name="door_knob">
      <origin xyz="0.355 -0.064 0.17" rpy="0 0 0" />
      <geometry>
        <sphere radius="0.018" />
        </geometry>
      </collision>
    </link>
  <link name="door_1">
    <visual name="door_slab">
      <origin xyz="-0.2025 -0.0125 0.17" rpy="0 0 0" />
      <geometry>
        <box size="0.405 0.025 0.34" />
        </geometry>
      <material name="aged_walnut">
        <color rgba="0.42 0.22 0.1 1" />
        </material>
      </visual>
    <visual name="hinge_barrel">
      <origin xyz="0 -0.014 0.17" rpy="0 0 0" />
      <geometry>
        <cylinder radius="0.009" length="0.33" />
        </geometry>
      <material name="warm_brass">
        <color rgba="0.86 0.62 0.24 1" />
        </material>
      </visual>
    <visual name="door_lower_trim">
      <origin xyz="-0.2025 -0.032 0.04" rpy="0 0 0" />
      <geometry>
        <box size="0.33 0.016 0.03" />
        </geometry>
      <material name="dark_endgrain">
        <color rgba="0.25 0.12 0.055 1" />
        </material>
      </visual>
    <visual name="door_upper_trim">
      <origin xyz="-0.2025 -0.032 0.3" rpy="0 0 0" />
      <geometry>
        <box size="0.33 0.016 0.03" />
        </geometry>
      <material name="dark_endgrain">
        <color rgba="0.25 0.12 0.055 1" />
        </material>
      </visual>
    <visual name="door_outer_trim">
      <origin xyz="-0.0375 -0.032 0.17" rpy="0 0 0" />
      <geometry>
        <box size="0.028 0.016 0.27" />
        </geometry>
      <material name="dark_endgrain">
        <color rgba="0.25 0.12 0.055 1" />
        </material>
      </visual>
    <visual name="door_inner_trim">
      <origin xyz="-0.3675 -0.032 0.17" rpy="0 0 0" />
      <geometry>
        <box size="0.028 0.016 0.27" />
        </geometry>
      <material name="dark_endgrain">
        <color rgba="0.25 0.12 0.055 1" />
        </material>
      </visual>
    <visual name="knob_stem">
      <origin xyz="-0.355 -0.038 0.17" rpy="1.5708 0 0" />
      <geometry>
        <cylinder radius="0.007" length="0.042" />
        </geometry>
      <material name="warm_brass">
        <color rgba="0.86 0.62 0.24 1" />
        </material>
      </visual>
    <visual name="door_knob">
      <origin xyz="-0.355 -0.064 0.17" rpy="0 0 0" />
      <geometry>
        <sphere radius="0.018" />
        </geometry>
      <material name="warm_brass">
        <color rgba="0.86 0.62 0.24 1" />
        </material>
      </visual>
    <collision name="door_slab">
      <origin xyz="-0.2025 -0.0125 0.17" rpy="0 0 0" />
      <geometry>
        <box size="0.405 0.025 0.34" />
        </geometry>
      </collision>
    <collision name="hinge_barrel">
      <origin xyz="0 -0.014 0.17" rpy="0 0 0" />
      <geometry>
        <cylinder radius="0.009" length="0.33" />
        </geometry>
      </collision>
    <collision name="door_lower_trim">
      <origin xyz="-0.2025 -0.032 0.04" rpy="0 0 0" />
      <geometry>
        <box size="0.33 0.016 0.03" />
        </geometry>
      </collision>
    <collision name="door_upper_trim">
      <origin xyz="-0.2025 -0.032 0.3" rpy="0 0 0" />
      <geometry>
        <box size="0.33 0.016 0.03" />
        </geometry>
      </collision>
    <collision name="door_outer_trim">
      <origin xyz="-0.0375 -0.032 0.17" rpy="0 0 0" />
      <geometry>
        <box size="0.028 0.016 0.27" />
        </geometry>
      </collision>
    <collision name="door_inner_trim">
      <origin xyz="-0.3675 -0.032 0.17" rpy="0 0 0" />
      <geometry>
        <box size="0.028 0.016 0.27" />
        </geometry>
      </collision>
    <collision name="knob_stem">
      <origin xyz="-0.355 -0.038 0.17" rpy="1.5708 0 0" />
      <geometry>
        <cylinder radius="0.007" length="0.042" />
        </geometry>
      </collision>
    <collision name="door_knob">
      <origin xyz="-0.355 -0.064 0.17" rpy="0 0 0" />
      <geometry>
        <sphere radius="0.018" />
        </geometry>
      </collision>
    </link>
  <joint name="case_to_drawer" type="prismatic">
    <origin xyz="0 -0.26 0.225" rpy="0 0 0" />
    <parent link="case" />
    <child link="drawer" />
    <axis xyz="0 -1 0" />
    <limit effort="80" velocity="0.35" lower="0" upper="0.28" />
    </joint>
  <joint name="case_to_writing_panel" type="revolute">
    <origin xyz="0 -0.24 0.385" rpy="0 0 0" />
    <parent link="case" />
    <child link="writing_panel" />
    <axis xyz="1 0 0" />
    <limit effort="18" velocity="1.2" lower="0" upper="1.5708" />
    </joint>
  <joint name="case_to_door_0" type="revolute">
    <origin xyz="-0.45 -0.24 0.93" rpy="0 0 0" />
    <parent link="case" />
    <child link="door_0" />
    <axis xyz="0 0 -1" />
    <limit effort="8" velocity="1.4" lower="0" upper="1.75" />
    </joint>
  <joint name="case_to_door_1" type="revolute">
    <origin xyz="0.45 -0.24 0.93" rpy="0 0 0" />
    <parent link="case" />
    <child link="door_1" />
    <axis xyz="0 0 1" />
    <limit effort="8" velocity="1.4" lower="0" upper="1.75" />
    </joint>
  </robot>
