<robot name="premium_screw_in_bulb_socket">
  <material name="warm_clear_glass">
    <color rgba="0.88 0.96 1 0.38" />
    </material>
  <material name="polished_glass_edge">
    <color rgba="0.72 0.88 1 0.46" />
    </material>
  <material name="satin_nickel">
    <color rgba="0.72 0.7 0.64 1" />
    </material>
  <material name="thread_highlight">
    <color rgba="0.88 0.82 0.68 1" />
    </material>
  <material name="brushed_brass">
    <color rgba="0.96 0.72 0.36 1" />
    </material>
  <material name="matte_black_ceramic">
    <color rgba="0.025 0.026 0.028 1" />
    </material>
  <material name="satin_black_break">
    <color rgba="0.08 0.08 0.075 1" />
    </material>
  <material name="restrained_steel">
    <color rgba="0.56 0.57 0.58 1" />
    </material>
  <material name="warm_tungsten">
    <color rgba="1 0.58 0.18 1" />
    </material>
  <link name="socket">
    <visual name="socket_shell">
      <geometry>
        <mesh filename="assets/meshes/socket_ceramic_shell.obj" />
        </geometry>
      <material name="matte_black_ceramic">
        <color rgba="0.025 0.026 0.028 1" />
        </material>
      </visual>
    <visual name="socket_liner">
      <geometry>
        <mesh filename="assets/meshes/socket_brass_liner.obj" />
        </geometry>
      <material name="brushed_brass">
        <color rgba="0.96 0.72 0.36 1" />
        </material>
      </visual>
    <visual name="internal_thread">
      <geometry>
        <mesh filename="assets/meshes/socket_internal_thread.obj" />
        </geometry>
      <material name="brushed_brass">
        <color rgba="0.96 0.72 0.36 1" />
        </material>
      </visual>
    <visual name="lip_bead">
      <origin xyz="0 0 0.047" rpy="0 0 0" />
      <geometry>
        <mesh filename="assets/meshes/socket_lip_bead.obj" />
        </geometry>
      <material name="satin_black_break">
        <color rgba="0.08 0.08 0.075 1" />
        </material>
      </visual>
    <visual name="base_plinth">
      <origin xyz="0 0 -0.012" rpy="0 0 0" />
      <geometry>
        <cylinder radius="0.029" length="0.006" />
        </geometry>
      <material name="satin_black_break">
        <color rgba="0.08 0.08 0.075 1" />
        </material>
      </visual>
    <visual name="contact_boss">
      <origin xyz="0 0 0.0055" rpy="0 0 0" />
      <geometry>
        <cylinder radius="0.0152" length="0.002" />
        </geometry>
      <material name="satin_black_break">
        <color rgba="0.08 0.08 0.075 1" />
        </material>
      </visual>
    <visual name="center_contact">
      <origin xyz="0 0 0.007" rpy="0 0 0" />
      <geometry>
        <cylinder radius="0.006" length="0.002" />
        </geometry>
      <material name="brushed_brass">
        <color rgba="0.96 0.72 0.36 1" />
        </material>
      </visual>
    <visual name="set_screw_0">
      <origin xyz="-0.0245 0 0.021" rpy="0 1.5708 0" />
      <geometry>
        <cylinder radius="0.003" length="0.003" />
        </geometry>
      <material name="restrained_steel">
        <color rgba="0.56 0.57 0.58 1" />
        </material>
      </visual>
    <visual name="screw_slot_0">
      <origin xyz="-0.0264 0 0.021" rpy="0 0 0" />
      <geometry>
        <box size="0.0008 0.0048 0.0007" />
        </geometry>
      <material name="satin_black_break">
        <color rgba="0.08 0.08 0.075 1" />
        </material>
      </visual>
    <visual name="set_screw_1">
      <origin xyz="0.0245 0 0.021" rpy="0 1.5708 0" />
      <geometry>
        <cylinder radius="0.003" length="0.003" />
        </geometry>
      <material name="restrained_steel">
        <color rgba="0.56 0.57 0.58 1" />
        </material>
      </visual>
    <visual name="screw_slot_1">
      <origin xyz="0.0264 0 0.021" rpy="0 0 0" />
      <geometry>
        <box size="0.0008 0.0048 0.0007" />
        </geometry>
      <material name="satin_black_break">
        <color rgba="0.08 0.08 0.075 1" />
        </material>
      </visual>
    <collision name="socket_shell">
      <geometry>
        <mesh filename="assets/meshes/socket_ceramic_shell.obj" />
        </geometry>
      </collision>
    <collision name="socket_liner">
      <geometry>
        <mesh filename="assets/meshes/socket_brass_liner.obj" />
        </geometry>
      </collision>
    <collision name="internal_thread">
      <geometry>
        <mesh filename="assets/meshes/socket_internal_thread.obj" />
        </geometry>
      </collision>
    <collision name="lip_bead">
      <origin xyz="0 0 0.047" rpy="0 0 0" />
      <geometry>
        <mesh filename="assets/meshes/socket_lip_bead.obj" />
        </geometry>
      </collision>
    <collision name="base_plinth">
      <origin xyz="0 0 -0.012" rpy="0 0 0" />
      <geometry>
        <cylinder radius="0.029" length="0.006" />
        </geometry>
      </collision>
    <collision name="contact_boss">
      <origin xyz="0 0 0.0055" rpy="0 0 0" />
      <geometry>
        <cylinder radius="0.0152" length="0.002" />
        </geometry>
      </collision>
    <collision name="center_contact">
      <origin xyz="0 0 0.007" rpy="0 0 0" />
      <geometry>
        <cylinder radius="0.006" length="0.002" />
        </geometry>
      </collision>
    <collision name="set_screw_0">
      <origin xyz="-0.0245 0 0.021" rpy="0 1.5708 0" />
      <geometry>
        <cylinder radius="0.003" length="0.003" />
        </geometry>
      </collision>
    <collision name="screw_slot_0">
      <origin xyz="-0.0264 0 0.021" rpy="0 0 0" />
      <geometry>
        <box size="0.0008 0.0048 0.0007" />
        </geometry>
      </collision>
    <collision name="set_screw_1">
      <origin xyz="0.0245 0 0.021" rpy="0 1.5708 0" />
      <geometry>
        <cylinder radius="0.003" length="0.003" />
        </geometry>
      </collision>
    <collision name="screw_slot_1">
      <origin xyz="0.0264 0 0.021" rpy="0 0 0" />
      <geometry>
        <box size="0.0008 0.0048 0.0007" />
        </geometry>
      </collision>
    </link>
  <link name="thread_axis">
    <visual name="axis_bushing">
      <origin xyz="0 0 -0.001" rpy="0 0 0" />
      <geometry>
        <cylinder radius="0.002" length="0.001" />
        </geometry>
      <material name="brushed_brass">
        <color rgba="0.96 0.72 0.36 1" />
        </material>
      </visual>
    <collision name="axis_bushing">
      <origin xyz="0 0 -0.001" rpy="0 0 0" />
      <geometry>
        <cylinder radius="0.002" length="0.001" />
        </geometry>
      </collision>
    </link>
  <link name="bulb">
    <visual name="screw_sleeve">
      <origin xyz="0 0 -0.0175" rpy="0 0 0" />
      <geometry>
        <cylinder radius="0.0128" length="0.027" />
        </geometry>
      <material name="satin_nickel">
        <color rgba="0.72 0.7 0.64 1" />
        </material>
      </visual>
    <visual name="external_thread">
      <geometry>
        <mesh filename="assets/meshes/bulb_external_thread.obj" />
        </geometry>
      <material name="thread_highlight">
        <color rgba="0.88 0.82 0.68 1" />
        </material>
      </visual>
    <visual name="contact_insulator">
      <origin xyz="0 0 -0.03225" rpy="0 0 0" />
      <geometry>
        <cylinder radius="0.0072" length="0.0035" />
        </geometry>
      <material name="satin_black_break">
        <color rgba="0.08 0.08 0.075 1" />
        </material>
      </visual>
    <visual name="base_contact">
      <origin xyz="0 0 -0.0355" rpy="0 0 0" />
      <geometry>
        <cylinder radius="0.005" length="0.003" />
        </geometry>
      <material name="brushed_brass">
        <color rgba="0.96 0.72 0.36 1" />
        </material>
      </visual>
    <visual name="neck_seam_band">
      <origin xyz="0 0 -0.001" rpy="0 0 0" />
      <geometry>
        <cylinder radius="0.0142" length="0.004" />
        </geometry>
      <material name="satin_black_break">
        <color rgba="0.08 0.08 0.075 1" />
        </material>
      </visual>
    <visual name="crimp_seam">
      <origin xyz="0 0 -0.0008" rpy="0 0 0" />
      <geometry>
        <mesh filename="assets/meshes/glass_crimp_seam.obj" />
        </geometry>
      <material name="thread_highlight">
        <color rgba="0.88 0.82 0.68 1" />
        </material>
      </visual>
    <visual name="glass_envelope">
      <geometry>
        <mesh filename="assets/meshes/pear_glass_envelope.obj" />
        </geometry>
      <material name="warm_clear_glass">
        <color rgba="0.88 0.96 1 0.38" />
        </material>
      </visual>
    <visual name="equator_seam">
      <origin xyz="0 0 0.053" rpy="0 0 0" />
      <geometry>
        <mesh filename="assets/meshes/glass_equator_seam.obj" />
        </geometry>
      <material name="polished_glass_edge">
        <color rgba="0.72 0.88 1 0.46" />
        </material>
      </visual>
    <visual name="glass_stem">
      <origin xyz="0 0 0.012" rpy="0 0 0" />
      <geometry>
        <cylinder radius="0.0022" length="0.034" />
        </geometry>
      <material name="polished_glass_edge">
        <color rgba="0.72 0.88 1 0.46" />
        </material>
      </visual>
    <visual name="filament_leads">
      <geometry>
        <mesh filename="assets/meshes/filament_leads.obj" />
        </geometry>
      <material name="warm_tungsten">
        <color rgba="1 0.58 0.18 1" />
        </material>
      </visual>
    <visual name="filament_coil">
      <geometry>
        <mesh filename="assets/meshes/coiled_tungsten_filament.obj" />
        </geometry>
      <material name="warm_tungsten">
        <color rgba="1 0.58 0.18 1" />
        </material>
      </visual>
    <visual name="filament_anchor">
      <geometry>
        <mesh filename="assets/meshes/filament_anchor_bridge.obj" />
        </geometry>
      <material name="polished_glass_edge">
        <color rgba="0.72 0.88 1 0.46" />
        </material>
      </visual>
    <collision name="screw_sleeve">
      <origin xyz="0 0 -0.0175" rpy="0 0 0" />
      <geometry>
        <cylinder radius="0.0128" length="0.027" />
        </geometry>
      </collision>
    <collision name="external_thread">
      <geometry>
        <mesh filename="assets/meshes/bulb_external_thread.obj" />
        </geometry>
      </collision>
    <collision name="contact_insulator">
      <origin xyz="0 0 -0.03225" rpy="0 0 0" />
      <geometry>
        <cylinder radius="0.0072" length="0.0035" />
        </geometry>
      </collision>
    <collision name="base_contact">
      <origin xyz="0 0 -0.0355" rpy="0 0 0" />
      <geometry>
        <cylinder radius="0.005" length="0.003" />
        </geometry>
      </collision>
    <collision name="neck_seam_band">
      <origin xyz="0 0 -0.001" rpy="0 0 0" />
      <geometry>
        <cylinder radius="0.0142" length="0.004" />
        </geometry>
      </collision>
    <collision name="crimp_seam">
      <origin xyz="0 0 -0.0008" rpy="0 0 0" />
      <geometry>
        <mesh filename="assets/meshes/glass_crimp_seam.obj" />
        </geometry>
      </collision>
    <collision name="glass_envelope">
      <geometry>
        <mesh filename="assets/meshes/pear_glass_envelope.obj" />
        </geometry>
      </collision>
    <collision name="equator_seam">
      <origin xyz="0 0 0.053" rpy="0 0 0" />
      <geometry>
        <mesh filename="assets/meshes/glass_equator_seam.obj" />
        </geometry>
      </collision>
    <collision name="glass_stem">
      <origin xyz="0 0 0.012" rpy="0 0 0" />
      <geometry>
        <cylinder radius="0.0022" length="0.034" />
        </geometry>
      </collision>
    <collision name="filament_leads">
      <geometry>
        <mesh filename="assets/meshes/filament_leads.obj" />
        </geometry>
      </collision>
    <collision name="filament_coil">
      <geometry>
        <mesh filename="assets/meshes/coiled_tungsten_filament.obj" />
        </geometry>
      </collision>
    <collision name="filament_anchor">
      <geometry>
        <mesh filename="assets/meshes/filament_anchor_bridge.obj" />
        </geometry>
      </collision>
    </link>
  <joint name="screw_rotation" type="revolute">
    <origin xyz="0 0 0.045" rpy="0 0 0" />
    <parent link="socket" />
    <child link="thread_axis" />
    <axis xyz="0 0 1" />
    <limit effort="1.2" velocity="1" lower="0" upper="12.5664" />
    <dynamics damping="0.08" friction="0.04" />
    </joint>
  <joint name="thread_advance" type="prismatic">
    <parent link="thread_axis" />
    <child link="bulb" />
    <axis xyz="0 0 1" />
    <limit effort="18" velocity="0.015" lower="0" upper="0.0072" />
    <dynamics damping="0.4" friction="0.2" />
    </joint>
  </robot>
