<robot name="premium_skateboard">
  <material name="sealed_maple_edge">
    <color rgba="0.78 0.58 0.34 1" />
    </material>
  <material name="micro_grit_black">
    <color rgba="0.015 0.016 0.017 1" />
    </material>
  <material name="maple_stringer">
    <color rgba="0.88 0.7 0.43 1" />
    </material>
  <material name="satin_painted_metal">
    <color rgba="0.44 0.46 0.47 1" />
    </material>
  <material name="brushed_steel">
    <color rgba="0.78 0.78 0.74 1" />
    </material>
  <material name="black_polymer_riser">
    <color rgba="0.025 0.025 0.028 1" />
    </material>
  <material name="smoked_elastomer">
    <color rgba="0.92 0.54 0.18 0.88" />
    </material>
  <material name="translucent_urethane">
    <color rgba="0.92 0.86 0.66 0.78" />
    </material>
  <material name="warm_white_polymer">
    <color rgba="0.92 0.9 0.84 1" />
    </material>
  <link name="deck">
    <visual name="deck_shell">
      <geometry>
        <mesh filename="assets/meshes/deck_shell.obj" />
        </geometry>
      <material name="sealed_maple_edge">
        <color rgba="0.78 0.58 0.34 1" />
        </material>
      </visual>
    <visual name="grip_sheet">
      <geometry>
        <mesh filename="assets/meshes/grip_sheet.obj" />
        </geometry>
      <material name="micro_grit_black">
        <color rgba="0.015 0.016 0.017 1" />
        </material>
      </visual>
    <visual name="center_stringer">
      <origin xyz="0 0 0.096" rpy="0 0 0" />
      <geometry>
        <box size="0.565 0.007 0.001" />
        </geometry>
      <material name="maple_stringer">
        <color rgba="0.88 0.7 0.43 1" />
        </material>
      </visual>
    <visual name="bolt_head_3">
      <origin xyz="-0.301 -0.023 0.0968801" rpy="0 0 0" />
      <geometry>
        <cylinder radius="0.0042" length="0.0022" />
        </geometry>
      <material name="brushed_steel">
        <color rgba="0.78 0.78 0.74 1" />
        </material>
      </visual>
    <visual name="bolt_head_4">
      <origin xyz="-0.301 0.023 0.0968801" rpy="0 0 0" />
      <geometry>
        <cylinder radius="0.0042" length="0.0022" />
        </geometry>
      <material name="brushed_steel">
        <color rgba="0.78 0.78 0.74 1" />
        </material>
      </visual>
    <visual name="bolt_head_5">
      <origin xyz="-0.239 -0.023 0.0966443" rpy="0 0 0" />
      <geometry>
        <cylinder radius="0.0042" length="0.0022" />
        </geometry>
      <material name="brushed_steel">
        <color rgba="0.78 0.78 0.74 1" />
        </material>
      </visual>
    <visual name="bolt_head_6">
      <origin xyz="-0.239 0.023 0.0966443" rpy="0 0 0" />
      <geometry>
        <cylinder radius="0.0042" length="0.0022" />
        </geometry>
      <material name="brushed_steel">
        <color rgba="0.78 0.78 0.74 1" />
        </material>
      </visual>
    <visual name="bolt_head_7">
      <origin xyz="0.239 -0.023 0.0966443" rpy="0 0 0" />
      <geometry>
        <cylinder radius="0.0042" length="0.0022" />
        </geometry>
      <material name="brushed_steel">
        <color rgba="0.78 0.78 0.74 1" />
        </material>
      </visual>
    <visual name="bolt_head_8">
      <origin xyz="0.239 0.023 0.0966443" rpy="0 0 0" />
      <geometry>
        <cylinder radius="0.0042" length="0.0022" />
        </geometry>
      <material name="brushed_steel">
        <color rgba="0.78 0.78 0.74 1" />
        </material>
      </visual>
    <visual name="bolt_head_9">
      <origin xyz="0.301 -0.023 0.0968801" rpy="0 0 0" />
      <geometry>
        <cylinder radius="0.0042" length="0.0022" />
        </geometry>
      <material name="brushed_steel">
        <color rgba="0.78 0.78 0.74 1" />
        </material>
      </visual>
    <visual name="bolt_head_10">
      <origin xyz="0.301 0.023 0.0968801" rpy="0 0 0" />
      <geometry>
        <cylinder radius="0.0042" length="0.0022" />
        </geometry>
      <material name="brushed_steel">
        <color rgba="0.78 0.78 0.74 1" />
        </material>
      </visual>
    <collision name="deck_shell">
      <geometry>
        <mesh filename="assets/meshes/deck_shell.obj" />
        </geometry>
      </collision>
    <collision name="grip_sheet">
      <geometry>
        <mesh filename="assets/meshes/grip_sheet.obj" />
        </geometry>
      </collision>
    <collision name="center_stringer">
      <origin xyz="0 0 0.096" rpy="0 0 0" />
      <geometry>
        <box size="0.565 0.007 0.001" />
        </geometry>
      </collision>
    <collision name="bolt_head_3">
      <origin xyz="-0.301 -0.023 0.0968801" rpy="0 0 0" />
      <geometry>
        <cylinder radius="0.0042" length="0.0022" />
        </geometry>
      </collision>
    <collision name="bolt_head_4">
      <origin xyz="-0.301 0.023 0.0968801" rpy="0 0 0" />
      <geometry>
        <cylinder radius="0.0042" length="0.0022" />
        </geometry>
      </collision>
    <collision name="bolt_head_5">
      <origin xyz="-0.239 -0.023 0.0966443" rpy="0 0 0" />
      <geometry>
        <cylinder radius="0.0042" length="0.0022" />
        </geometry>
      </collision>
    <collision name="bolt_head_6">
      <origin xyz="-0.239 0.023 0.0966443" rpy="0 0 0" />
      <geometry>
        <cylinder radius="0.0042" length="0.0022" />
        </geometry>
      </collision>
    <collision name="bolt_head_7">
      <origin xyz="0.239 -0.023 0.0966443" rpy="0 0 0" />
      <geometry>
        <cylinder radius="0.0042" length="0.0022" />
        </geometry>
      </collision>
    <collision name="bolt_head_8">
      <origin xyz="0.239 0.023 0.0966443" rpy="0 0 0" />
      <geometry>
        <cylinder radius="0.0042" length="0.0022" />
        </geometry>
      </collision>
    <collision name="bolt_head_9">
      <origin xyz="0.301 -0.023 0.0968801" rpy="0 0 0" />
      <geometry>
        <cylinder radius="0.0042" length="0.0022" />
        </geometry>
      </collision>
    <collision name="bolt_head_10">
      <origin xyz="0.301 0.023 0.0968801" rpy="0 0 0" />
      <geometry>
        <cylinder radius="0.0042" length="0.0022" />
        </geometry>
      </collision>
    </link>
  <link name="front_baseplate">
    <visual name="riser_pad">
      <origin xyz="0 0 -0.002" rpy="0 0 0" />
      <geometry>
        <mesh filename="assets/meshes/front_riser_pad.obj" />
        </geometry>
      <material name="black_polymer_riser">
        <color rgba="0.025 0.025 0.028 1" />
        </material>
      </visual>
    <visual name="baseplate">
      <origin xyz="0 0 -0.008" rpy="0 0 0" />
      <geometry>
        <mesh filename="assets/meshes/front_baseplate.obj" />
        </geometry>
      <material name="satin_painted_metal">
        <color rgba="0.44 0.46 0.47 1" />
        </material>
      </visual>
    <visual name="kingpin_cup">
      <origin xyz="0 0 -0.014" rpy="0 0 0" />
      <geometry>
        <cylinder radius="0.019" length="0.004" />
        </geometry>
      <material name="satin_painted_metal">
        <color rgba="0.44 0.46 0.47 1" />
        </material>
      </visual>
    <visual name="mount_nut_3">
      <origin xyz="-0.031 -0.023 -0.0135" rpy="0 0 0" />
      <geometry>
        <cylinder radius="0.005" length="0.003" />
        </geometry>
      <material name="brushed_steel">
        <color rgba="0.78 0.78 0.74 1" />
        </material>
      </visual>
    <visual name="mount_nut_4">
      <origin xyz="-0.031 0.023 -0.0135" rpy="0 0 0" />
      <geometry>
        <cylinder radius="0.005" length="0.003" />
        </geometry>
      <material name="brushed_steel">
        <color rgba="0.78 0.78 0.74 1" />
        </material>
      </visual>
    <visual name="mount_nut_5">
      <origin xyz="0.031 -0.023 -0.0135" rpy="0 0 0" />
      <geometry>
        <cylinder radius="0.005" length="0.003" />
        </geometry>
      <material name="brushed_steel">
        <color rgba="0.78 0.78 0.74 1" />
        </material>
      </visual>
    <visual name="mount_nut_6">
      <origin xyz="0.031 0.023 -0.0135" rpy="0 0 0" />
      <geometry>
        <cylinder radius="0.005" length="0.003" />
        </geometry>
      <material name="brushed_steel">
        <color rgba="0.78 0.78 0.74 1" />
        </material>
      </visual>
    <collision name="riser_pad">
      <origin xyz="0 0 -0.002" rpy="0 0 0" />
      <geometry>
        <mesh filename="assets/meshes/front_riser_pad.obj" />
        </geometry>
      </collision>
    <collision name="baseplate">
      <origin xyz="0 0 -0.008" rpy="0 0 0" />
      <geometry>
        <mesh filename="assets/meshes/front_baseplate.obj" />
        </geometry>
      </collision>
    <collision name="kingpin_cup">
      <origin xyz="0 0 -0.014" rpy="0 0 0" />
      <geometry>
        <cylinder radius="0.019" length="0.004" />
        </geometry>
      </collision>
    <collision name="mount_nut_3">
      <origin xyz="-0.031 -0.023 -0.0135" rpy="0 0 0" />
      <geometry>
        <cylinder radius="0.005" length="0.003" />
        </geometry>
      </collision>
    <collision name="mount_nut_4">
      <origin xyz="-0.031 0.023 -0.0135" rpy="0 0 0" />
      <geometry>
        <cylinder radius="0.005" length="0.003" />
        </geometry>
      </collision>
    <collision name="mount_nut_5">
      <origin xyz="0.031 -0.023 -0.0135" rpy="0 0 0" />
      <geometry>
        <cylinder radius="0.005" length="0.003" />
        </geometry>
      </collision>
    <collision name="mount_nut_6">
      <origin xyz="0.031 0.023 -0.0135" rpy="0 0 0" />
      <geometry>
        <cylinder radius="0.005" length="0.003" />
        </geometry>
      </collision>
    </link>
  <link name="front_hanger">
    <visual name="bushing_stack">
      <origin xyz="0.00139967 -0 -0.00374712" rpy="0 -0.357484 0" />
      <geometry>
        <cylinder radius="0.016" length="0.034" />
        </geometry>
      <material name="smoked_elastomer">
        <color rgba="0.92 0.54 0.18 0.88" />
        </material>
      </visual>
    <visual name="upper_washer">
      <origin xyz="-0.00489885 0 0.0131149" rpy="0 -0.357484 0" />
      <geometry>
        <cylinder radius="0.018" length="0.003" />
        </geometry>
      <material name="brushed_steel">
        <color rgba="0.78 0.78 0.74 1" />
        </material>
      </visual>
    <visual name="lower_washer">
      <origin xyz="0.00769819 -0 -0.0206092" rpy="0 -0.357484 0" />
      <geometry>
        <cylinder radius="0.018" length="0.003" />
        </geometry>
      <material name="brushed_steel">
        <color rgba="0.78 0.78 0.74 1" />
        </material>
      </visual>
    <visual name="central_yoke">
      <origin xyz="0 0 -0.026" rpy="0 0 0" />
      <geometry>
        <box size="0.062 0.064 0.026" />
        </geometry>
      <material name="satin_painted_metal">
        <color rgba="0.44 0.46 0.47 1" />
        </material>
      </visual>
    <visual name="kingpin_neck">
      <origin xyz="0 0 -0.02" rpy="0 0 0" />
      <geometry>
        <cylinder radius="0.013" length="0.04" />
        </geometry>
      <material name="satin_painted_metal">
        <color rgba="0.44 0.46 0.47 1" />
        </material>
      </visual>
    <visual name="hanger_bar">
      <origin xyz="0 0 -0.03" rpy="1.5708 0 0" />
      <geometry>
        <cylinder radius="0.014" length="0.215" />
        </geometry>
      <material name="satin_painted_metal">
        <color rgba="0.44 0.46 0.47 1" />
        </material>
      </visual>
    <visual name="axle">
      <origin xyz="0 0 -0.03" rpy="1.5708 0 0" />
      <geometry>
        <cylinder radius="0.0045" length="0.272" />
        </geometry>
      <material name="brushed_steel">
        <color rgba="0.78 0.78 0.74 1" />
        </material>
      </visual>
    <visual name="underside_blend">
      <origin xyz="0 0 -0.04" rpy="0 0 0" />
      <geometry>
        <box size="0.05 0.07 0.014" />
        </geometry>
      <material name="satin_painted_metal">
        <color rgba="0.44 0.46 0.47 1" />
        </material>
      </visual>
    <collision name="bushing_stack">
      <origin xyz="0.00139967 -0 -0.00374712" rpy="0 -0.357484 0" />
      <geometry>
        <cylinder radius="0.016" length="0.034" />
        </geometry>
      </collision>
    <collision name="upper_washer">
      <origin xyz="-0.00489885 0 0.0131149" rpy="0 -0.357484 0" />
      <geometry>
        <cylinder radius="0.018" length="0.003" />
        </geometry>
      </collision>
    <collision name="lower_washer">
      <origin xyz="0.00769819 -0 -0.0206092" rpy="0 -0.357484 0" />
      <geometry>
        <cylinder radius="0.018" length="0.003" />
        </geometry>
      </collision>
    <collision name="central_yoke">
      <origin xyz="0 0 -0.026" rpy="0 0 0" />
      <geometry>
        <box size="0.062 0.064 0.026" />
        </geometry>
      </collision>
    <collision name="kingpin_neck">
      <origin xyz="0 0 -0.02" rpy="0 0 0" />
      <geometry>
        <cylinder radius="0.013" length="0.04" />
        </geometry>
      </collision>
    <collision name="hanger_bar">
      <origin xyz="0 0 -0.03" rpy="1.5708 0 0" />
      <geometry>
        <cylinder radius="0.014" length="0.215" />
        </geometry>
      </collision>
    <collision name="axle">
      <origin xyz="0 0 -0.03" rpy="1.5708 0 0" />
      <geometry>
        <cylinder radius="0.0045" length="0.272" />
        </geometry>
      </collision>
    <collision name="underside_blend">
      <origin xyz="0 0 -0.04" rpy="0 0 0" />
      <geometry>
        <box size="0.05 0.07 0.014" />
        </geometry>
      </collision>
    </link>
  <link name="front_wheel_0">
    <visual name="urethane_tire">
      <geometry>
        <mesh filename="assets/meshes/front_wheel_tire.obj" />
        </geometry>
      <material name="translucent_urethane">
        <color rgba="0.92 0.86 0.66 0.78" />
        </material>
      </visual>
    <visual name="polymer_core">
      <geometry>
        <mesh filename="assets/meshes/front_wheel_core.obj" />
        </geometry>
      <material name="warm_white_polymer">
        <color rgba="0.92 0.9 0.84 1" />
        </material>
      </visual>
    <collision name="urethane_tire">
      <geometry>
        <mesh filename="assets/meshes/front_wheel_tire.obj" />
        </geometry>
      </collision>
    <collision name="polymer_core">
      <geometry>
        <mesh filename="assets/meshes/front_wheel_core.obj" />
        </geometry>
      </collision>
    </link>
  <link name="front_wheel_1">
    <visual name="urethane_tire">
      <geometry>
        <mesh filename="assets/meshes/front_wheel_tire.obj" />
        </geometry>
      <material name="translucent_urethane">
        <color rgba="0.92 0.86 0.66 0.78" />
        </material>
      </visual>
    <visual name="polymer_core">
      <geometry>
        <mesh filename="assets/meshes/front_wheel_core.obj" />
        </geometry>
      <material name="warm_white_polymer">
        <color rgba="0.92 0.9 0.84 1" />
        </material>
      </visual>
    <collision name="urethane_tire">
      <geometry>
        <mesh filename="assets/meshes/front_wheel_tire.obj" />
        </geometry>
      </collision>
    <collision name="polymer_core">
      <geometry>
        <mesh filename="assets/meshes/front_wheel_core.obj" />
        </geometry>
      </collision>
    </link>
  <link name="rear_baseplate">
    <visual name="riser_pad">
      <origin xyz="0 0 -0.002" rpy="0 0 0" />
      <geometry>
        <mesh filename="assets/meshes/rear_riser_pad.obj" />
        </geometry>
      <material name="black_polymer_riser">
        <color rgba="0.025 0.025 0.028 1" />
        </material>
      </visual>
    <visual name="baseplate">
      <origin xyz="0 0 -0.008" rpy="0 0 0" />
      <geometry>
        <mesh filename="assets/meshes/rear_baseplate.obj" />
        </geometry>
      <material name="satin_painted_metal">
        <color rgba="0.44 0.46 0.47 1" />
        </material>
      </visual>
    <visual name="kingpin_cup">
      <origin xyz="0 0 -0.014" rpy="0 0 0" />
      <geometry>
        <cylinder radius="0.019" length="0.004" />
        </geometry>
      <material name="satin_painted_metal">
        <color rgba="0.44 0.46 0.47 1" />
        </material>
      </visual>
    <visual name="mount_nut_3">
      <origin xyz="-0.031 -0.023 -0.0135" rpy="0 0 0" />
      <geometry>
        <cylinder radius="0.005" length="0.003" />
        </geometry>
      <material name="brushed_steel">
        <color rgba="0.78 0.78 0.74 1" />
        </material>
      </visual>
    <visual name="mount_nut_4">
      <origin xyz="-0.031 0.023 -0.0135" rpy="0 0 0" />
      <geometry>
        <cylinder radius="0.005" length="0.003" />
        </geometry>
      <material name="brushed_steel">
        <color rgba="0.78 0.78 0.74 1" />
        </material>
      </visual>
    <visual name="mount_nut_5">
      <origin xyz="0.031 -0.023 -0.0135" rpy="0 0 0" />
      <geometry>
        <cylinder radius="0.005" length="0.003" />
        </geometry>
      <material name="brushed_steel">
        <color rgba="0.78 0.78 0.74 1" />
        </material>
      </visual>
    <visual name="mount_nut_6">
      <origin xyz="0.031 0.023 -0.0135" rpy="0 0 0" />
      <geometry>
        <cylinder radius="0.005" length="0.003" />
        </geometry>
      <material name="brushed_steel">
        <color rgba="0.78 0.78 0.74 1" />
        </material>
      </visual>
    <collision name="riser_pad">
      <origin xyz="0 0 -0.002" rpy="0 0 0" />
      <geometry>
        <mesh filename="assets/meshes/rear_riser_pad.obj" />
        </geometry>
      </collision>
    <collision name="baseplate">
      <origin xyz="0 0 -0.008" rpy="0 0 0" />
      <geometry>
        <mesh filename="assets/meshes/rear_baseplate.obj" />
        </geometry>
      </collision>
    <collision name="kingpin_cup">
      <origin xyz="0 0 -0.014" rpy="0 0 0" />
      <geometry>
        <cylinder radius="0.019" length="0.004" />
        </geometry>
      </collision>
    <collision name="mount_nut_3">
      <origin xyz="-0.031 -0.023 -0.0135" rpy="0 0 0" />
      <geometry>
        <cylinder radius="0.005" length="0.003" />
        </geometry>
      </collision>
    <collision name="mount_nut_4">
      <origin xyz="-0.031 0.023 -0.0135" rpy="0 0 0" />
      <geometry>
        <cylinder radius="0.005" length="0.003" />
        </geometry>
      </collision>
    <collision name="mount_nut_5">
      <origin xyz="0.031 -0.023 -0.0135" rpy="0 0 0" />
      <geometry>
        <cylinder radius="0.005" length="0.003" />
        </geometry>
      </collision>
    <collision name="mount_nut_6">
      <origin xyz="0.031 0.023 -0.0135" rpy="0 0 0" />
      <geometry>
        <cylinder radius="0.005" length="0.003" />
        </geometry>
      </collision>
    </link>
  <link name="rear_hanger">
    <visual name="bushing_stack">
      <origin xyz="-0.00139967 -0 -0.00374712" rpy="0 0.357484 0" />
      <geometry>
        <cylinder radius="0.016" length="0.034" />
        </geometry>
      <material name="smoked_elastomer">
        <color rgba="0.92 0.54 0.18 0.88" />
        </material>
      </visual>
    <visual name="upper_washer">
      <origin xyz="0.00489885 0 0.0131149" rpy="0 0.357484 0" />
      <geometry>
        <cylinder radius="0.018" length="0.003" />
        </geometry>
      <material name="brushed_steel">
        <color rgba="0.78 0.78 0.74 1" />
        </material>
      </visual>
    <visual name="lower_washer">
      <origin xyz="-0.00769819 -0 -0.0206092" rpy="0 0.357484 0" />
      <geometry>
        <cylinder radius="0.018" length="0.003" />
        </geometry>
      <material name="brushed_steel">
        <color rgba="0.78 0.78 0.74 1" />
        </material>
      </visual>
    <visual name="central_yoke">
      <origin xyz="0 0 -0.026" rpy="0 0 0" />
      <geometry>
        <box size="0.062 0.064 0.026" />
        </geometry>
      <material name="satin_painted_metal">
        <color rgba="0.44 0.46 0.47 1" />
        </material>
      </visual>
    <visual name="kingpin_neck">
      <origin xyz="0 0 -0.02" rpy="0 0 0" />
      <geometry>
        <cylinder radius="0.013" length="0.04" />
        </geometry>
      <material name="satin_painted_metal">
        <color rgba="0.44 0.46 0.47 1" />
        </material>
      </visual>
    <visual name="hanger_bar">
      <origin xyz="0 0 -0.03" rpy="1.5708 0 0" />
      <geometry>
        <cylinder radius="0.014" length="0.215" />
        </geometry>
      <material name="satin_painted_metal">
        <color rgba="0.44 0.46 0.47 1" />
        </material>
      </visual>
    <visual name="axle">
      <origin xyz="0 0 -0.03" rpy="1.5708 0 0" />
      <geometry>
        <cylinder radius="0.0045" length="0.272" />
        </geometry>
      <material name="brushed_steel">
        <color rgba="0.78 0.78 0.74 1" />
        </material>
      </visual>
    <visual name="underside_blend">
      <origin xyz="0 0 -0.04" rpy="0 0 0" />
      <geometry>
        <box size="0.05 0.07 0.014" />
        </geometry>
      <material name="satin_painted_metal">
        <color rgba="0.44 0.46 0.47 1" />
        </material>
      </visual>
    <collision name="bushing_stack">
      <origin xyz="-0.00139967 -0 -0.00374712" rpy="0 0.357484 0" />
      <geometry>
        <cylinder radius="0.016" length="0.034" />
        </geometry>
      </collision>
    <collision name="upper_washer">
      <origin xyz="0.00489885 0 0.0131149" rpy="0 0.357484 0" />
      <geometry>
        <cylinder radius="0.018" length="0.003" />
        </geometry>
      </collision>
    <collision name="lower_washer">
      <origin xyz="-0.00769819 -0 -0.0206092" rpy="0 0.357484 0" />
      <geometry>
        <cylinder radius="0.018" length="0.003" />
        </geometry>
      </collision>
    <collision name="central_yoke">
      <origin xyz="0 0 -0.026" rpy="0 0 0" />
      <geometry>
        <box size="0.062 0.064 0.026" />
        </geometry>
      </collision>
    <collision name="kingpin_neck">
      <origin xyz="0 0 -0.02" rpy="0 0 0" />
      <geometry>
        <cylinder radius="0.013" length="0.04" />
        </geometry>
      </collision>
    <collision name="hanger_bar">
      <origin xyz="0 0 -0.03" rpy="1.5708 0 0" />
      <geometry>
        <cylinder radius="0.014" length="0.215" />
        </geometry>
      </collision>
    <collision name="axle">
      <origin xyz="0 0 -0.03" rpy="1.5708 0 0" />
      <geometry>
        <cylinder radius="0.0045" length="0.272" />
        </geometry>
      </collision>
    <collision name="underside_blend">
      <origin xyz="0 0 -0.04" rpy="0 0 0" />
      <geometry>
        <box size="0.05 0.07 0.014" />
        </geometry>
      </collision>
    </link>
  <link name="rear_wheel_0">
    <visual name="urethane_tire">
      <geometry>
        <mesh filename="assets/meshes/rear_wheel_tire.obj" />
        </geometry>
      <material name="translucent_urethane">
        <color rgba="0.92 0.86 0.66 0.78" />
        </material>
      </visual>
    <visual name="polymer_core">
      <geometry>
        <mesh filename="assets/meshes/rear_wheel_core.obj" />
        </geometry>
      <material name="warm_white_polymer">
        <color rgba="0.92 0.9 0.84 1" />
        </material>
      </visual>
    <collision name="urethane_tire">
      <geometry>
        <mesh filename="assets/meshes/rear_wheel_tire.obj" />
        </geometry>
      </collision>
    <collision name="polymer_core">
      <geometry>
        <mesh filename="assets/meshes/rear_wheel_core.obj" />
        </geometry>
      </collision>
    </link>
  <link name="rear_wheel_1">
    <visual name="urethane_tire">
      <geometry>
        <mesh filename="assets/meshes/rear_wheel_tire.obj" />
        </geometry>
      <material name="translucent_urethane">
        <color rgba="0.92 0.86 0.66 0.78" />
        </material>
      </visual>
    <visual name="polymer_core">
      <geometry>
        <mesh filename="assets/meshes/rear_wheel_core.obj" />
        </geometry>
      <material name="warm_white_polymer">
        <color rgba="0.92 0.9 0.84 1" />
        </material>
      </visual>
    <collision name="urethane_tire">
      <geometry>
        <mesh filename="assets/meshes/rear_wheel_tire.obj" />
        </geometry>
      </collision>
    <collision name="polymer_core">
      <geometry>
        <mesh filename="assets/meshes/rear_wheel_core.obj" />
        </geometry>
      </collision>
    </link>
  <joint name="deck_to_front_baseplate" type="fixed">
    <origin xyz="0.27 0 0.083" rpy="0 0 0" />
    <parent link="deck" />
    <child link="front_baseplate" />
    </joint>
  <joint name="front_steer" type="revolute">
    <origin xyz="0 0 -0.03" rpy="0 0 0" />
    <parent link="front_baseplate" />
    <child link="front_hanger" />
    <axis xyz="-0.349918 0 0.93678" />
    <limit effort="14" velocity="2.5" lower="-0.35" upper="0.35" />
    <dynamics damping="0.18" friction="0.04" />
    </joint>
  <joint name="front_wheel_0_spin" type="continuous">
    <origin xyz="0 0.154 -0.03" rpy="0 0 1.5708" />
    <parent link="front_hanger" />
    <child link="front_wheel_0" />
    <axis xyz="1 0 0" />
    <limit effort="2" velocity="35" />
    <dynamics damping="0.03" friction="0.01" />
    </joint>
  <joint name="front_wheel_1_spin" type="continuous">
    <origin xyz="0 -0.154 -0.03" rpy="0 0 -1.5708" />
    <parent link="front_hanger" />
    <child link="front_wheel_1" />
    <axis xyz="1 0 0" />
    <limit effort="2" velocity="35" />
    <dynamics damping="0.03" friction="0.01" />
    </joint>
  <joint name="deck_to_rear_baseplate" type="fixed">
    <origin xyz="-0.27 0 0.083" rpy="0 0 0" />
    <parent link="deck" />
    <child link="rear_baseplate" />
    </joint>
  <joint name="rear_steer" type="revolute">
    <origin xyz="0 0 -0.03" rpy="0 0 0" />
    <parent link="rear_baseplate" />
    <child link="rear_hanger" />
    <axis xyz="0.349918 0 0.93678" />
    <limit effort="14" velocity="2.5" lower="-0.35" upper="0.35" />
    <dynamics damping="0.18" friction="0.04" />
    </joint>
  <joint name="rear_wheel_0_spin" type="continuous">
    <origin xyz="0 0.154 -0.03" rpy="0 0 1.5708" />
    <parent link="rear_hanger" />
    <child link="rear_wheel_0" />
    <axis xyz="1 0 0" />
    <limit effort="2" velocity="35" />
    <dynamics damping="0.03" friction="0.01" />
    </joint>
  <joint name="rear_wheel_1_spin" type="continuous">
    <origin xyz="0 -0.154 -0.03" rpy="0 0 -1.5708" />
    <parent link="rear_hanger" />
    <child link="rear_wheel_1" />
    <axis xyz="1 0 0" />
    <limit effort="2" velocity="35" />
    <dynamics damping="0.03" friction="0.01" />
    </joint>
  </robot>
