<robot name="compact_service_manipulator">
  <material name="industrial_blue">
    <color rgba="0.08 0.18 0.3 1" />
    </material>
  <material name="safety_yellow">
    <color rgba="0.92 0.64 0.1 1" />
    </material>
  <material name="dark_bearing">
    <color rgba="0.03 0.035 0.04 1" />
    </material>
  <material name="brushed_steel">
    <color rgba="0.62 0.62 0.58 1" />
    </material>
  <material name="black_rubber">
    <color rgba="0.01 0.01 0.012 1" />
    </material>
  <link name="base_column">
    <visual name="floor_plinth">
      <origin xyz="0 0 0.03" rpy="0 0 0" />
      <geometry>
        <box size="0.46 0.46 0.06" />
        </geometry>
      <material name="dark_bearing">
        <color rgba="0.03 0.035 0.04 1" />
        </material>
      </visual>
    <visual name="square_column">
      <origin xyz="0 0 0.3" rpy="0 0 0" />
      <geometry>
        <box size="0.245 0.245 0.48" />
        </geometry>
      <material name="industrial_blue">
        <color rgba="0.08 0.18 0.3 1" />
        </material>
      </visual>
    <visual name="top_flange">
      <origin xyz="0 0 0.56" rpy="0 0 0" />
      <geometry>
        <cylinder radius="0.175" length="0.04" />
        </geometry>
      <material name="brushed_steel">
        <color rgba="0.62 0.62 0.58 1" />
        </material>
      </visual>
    <visual name="top_bearing">
      <origin xyz="0 0 0.58" rpy="0 0 0" />
      <geometry>
        <cylinder radius="0.155" length="0.04" />
        </geometry>
      <material name="dark_bearing">
        <color rgba="0.03 0.035 0.04 1" />
        </material>
      </visual>
    <visual name="thrust_washer">
      <origin xyz="0 0 0.59" rpy="0 0 0" />
      <geometry>
        <cylinder radius="0.12" length="0.02" />
        </geometry>
      <material name="brushed_steel">
        <color rgba="0.62 0.62 0.58 1" />
        </material>
      </visual>
    <visual name="plinth_bolt_0">
      <origin xyz="-0.165 -0.165 0.066" rpy="0 0 0" />
      <geometry>
        <cylinder radius="0.016" length="0.012" />
        </geometry>
      <material name="brushed_steel">
        <color rgba="0.62 0.62 0.58 1" />
        </material>
      </visual>
    <visual name="plinth_bolt_1">
      <origin xyz="-0.165 0.165 0.066" rpy="0 0 0" />
      <geometry>
        <cylinder radius="0.016" length="0.012" />
        </geometry>
      <material name="brushed_steel">
        <color rgba="0.62 0.62 0.58 1" />
        </material>
      </visual>
    <visual name="plinth_bolt_2">
      <origin xyz="0.165 -0.165 0.066" rpy="0 0 0" />
      <geometry>
        <cylinder radius="0.016" length="0.012" />
        </geometry>
      <material name="brushed_steel">
        <color rgba="0.62 0.62 0.58 1" />
        </material>
      </visual>
    <visual name="plinth_bolt_3">
      <origin xyz="0.165 0.165 0.066" rpy="0 0 0" />
      <geometry>
        <cylinder radius="0.016" length="0.012" />
        </geometry>
      <material name="brushed_steel">
        <color rgba="0.62 0.62 0.58 1" />
        </material>
      </visual>
    <visual name="flange_bolt_0">
      <origin xyz="0.132 0 0.605" rpy="0 0 0" />
      <geometry>
        <cylinder radius="0.01" length="0.01" />
        </geometry>
      <material name="brushed_steel">
        <color rgba="0.62 0.62 0.58 1" />
        </material>
      </visual>
    <visual name="flange_bolt_1">
      <origin xyz="8.08267e-18 0.132 0.605" rpy="0 0 0" />
      <geometry>
        <cylinder radius="0.01" length="0.01" />
        </geometry>
      <material name="brushed_steel">
        <color rgba="0.62 0.62 0.58 1" />
        </material>
      </visual>
    <visual name="flange_bolt_2">
      <origin xyz="-0.132 1.61653e-17 0.605" rpy="0 0 0" />
      <geometry>
        <cylinder radius="0.01" length="0.01" />
        </geometry>
      <material name="brushed_steel">
        <color rgba="0.62 0.62 0.58 1" />
        </material>
      </visual>
    <visual name="flange_bolt_3">
      <origin xyz="-2.4248e-17 -0.132 0.605" rpy="0 0 0" />
      <geometry>
        <cylinder radius="0.01" length="0.01" />
        </geometry>
      <material name="brushed_steel">
        <color rgba="0.62 0.62 0.58 1" />
        </material>
      </visual>
    <collision name="floor_plinth">
      <origin xyz="0 0 0.03" rpy="0 0 0" />
      <geometry>
        <box size="0.46 0.46 0.06" />
        </geometry>
      </collision>
    <collision name="square_column">
      <origin xyz="0 0 0.3" rpy="0 0 0" />
      <geometry>
        <box size="0.245 0.245 0.48" />
        </geometry>
      </collision>
    <collision name="top_flange">
      <origin xyz="0 0 0.56" rpy="0 0 0" />
      <geometry>
        <cylinder radius="0.175" length="0.04" />
        </geometry>
      </collision>
    <collision name="top_bearing">
      <origin xyz="0 0 0.58" rpy="0 0 0" />
      <geometry>
        <cylinder radius="0.155" length="0.04" />
        </geometry>
      </collision>
    <collision name="thrust_washer">
      <origin xyz="0 0 0.59" rpy="0 0 0" />
      <geometry>
        <cylinder radius="0.12" length="0.02" />
        </geometry>
      </collision>
    <collision name="plinth_bolt_0">
      <origin xyz="-0.165 -0.165 0.066" rpy="0 0 0" />
      <geometry>
        <cylinder radius="0.016" length="0.012" />
        </geometry>
      </collision>
    <collision name="plinth_bolt_1">
      <origin xyz="-0.165 0.165 0.066" rpy="0 0 0" />
      <geometry>
        <cylinder radius="0.016" length="0.012" />
        </geometry>
      </collision>
    <collision name="plinth_bolt_2">
      <origin xyz="0.165 -0.165 0.066" rpy="0 0 0" />
      <geometry>
        <cylinder radius="0.016" length="0.012" />
        </geometry>
      </collision>
    <collision name="plinth_bolt_3">
      <origin xyz="0.165 0.165 0.066" rpy="0 0 0" />
      <geometry>
        <cylinder radius="0.016" length="0.012" />
        </geometry>
      </collision>
    <collision name="flange_bolt_0">
      <origin xyz="0.132 0 0.605" rpy="0 0 0" />
      <geometry>
        <cylinder radius="0.01" length="0.01" />
        </geometry>
      </collision>
    <collision name="flange_bolt_1">
      <origin xyz="8.08267e-18 0.132 0.605" rpy="0 0 0" />
      <geometry>
        <cylinder radius="0.01" length="0.01" />
        </geometry>
      </collision>
    <collision name="flange_bolt_2">
      <origin xyz="-0.132 1.61653e-17 0.605" rpy="0 0 0" />
      <geometry>
        <cylinder radius="0.01" length="0.01" />
        </geometry>
      </collision>
    <collision name="flange_bolt_3">
      <origin xyz="-2.4248e-17 -0.132 0.605" rpy="0 0 0" />
      <geometry>
        <cylinder radius="0.01" length="0.01" />
        </geometry>
      </collision>
    </link>
  <link name="upper_link">
    <visual name="shoulder_bearing">
      <origin xyz="0 0 0.025" rpy="0 0 0" />
      <geometry>
        <cylinder radius="0.145" length="0.05" />
        </geometry>
      <material name="dark_bearing">
        <color rgba="0.03 0.035 0.04 1" />
        </material>
      </visual>
    <visual name="shoulder_housing">
      <origin xyz="0 0 0.11" rpy="0 0 0" />
      <geometry>
        <box size="0.22 0.18 0.12" />
        </geometry>
      <material name="industrial_blue">
        <color rgba="0.08 0.18 0.3 1" />
        </material>
      </visual>
    <visual name="shoulder_neck">
      <origin xyz="0.055 0 0.175" rpy="0 0 0" />
      <geometry>
        <box size="0.16 0.135 0.05" />
        </geometry>
      <material name="industrial_blue">
        <color rgba="0.08 0.18 0.3 1" />
        </material>
      </visual>
    <visual name="upper_beam">
      <origin xyz="0.21 0 0.2375" rpy="0 -0.383284 0" />
      <geometry>
        <box size="0.334253 0.096 0.07" />
        </geometry>
      <material name="safety_yellow">
        <color rgba="0.92 0.64 0.1 1" />
        </material>
      </visual>
    <visual name="upper_rib_pos">
      <origin xyz="0.21 0.056 0.2375" rpy="0 -0.383284 0" />
      <geometry>
        <box size="0.287457 0.02 0.09" />
        </geometry>
      <material name="industrial_blue">
        <color rgba="0.08 0.18 0.3 1" />
        </material>
      </visual>
    <visual name="upper_rib_neg">
      <origin xyz="0.21 -0.056 0.2375" rpy="0 -0.383284 0" />
      <geometry>
        <box size="0.287457 0.02 0.09" />
        </geometry>
      <material name="industrial_blue">
        <color rgba="0.08 0.18 0.3 1" />
        </material>
      </visual>
    <visual name="elbow_bridge">
      <origin xyz="0.385 0 0.332" rpy="0 0 0" />
      <geometry>
        <box size="0.08 0.14 0.086" />
        </geometry>
      <material name="industrial_blue">
        <color rgba="0.08 0.18 0.3 1" />
        </material>
      </visual>
    <visual name="elbow_cheek_pos">
      <origin xyz="0.465 0.065 0.34" rpy="0 0 0" />
      <geometry>
        <box size="0.098 0.026 0.185" />
        </geometry>
      <material name="industrial_blue">
        <color rgba="0.08 0.18 0.3 1" />
        </material>
      </visual>
    <visual name="elbow_cheek_neg">
      <origin xyz="0.465 -0.065 0.34" rpy="0 0 0" />
      <geometry>
        <box size="0.098 0.026 0.185" />
        </geometry>
      <material name="industrial_blue">
        <color rgba="0.08 0.18 0.3 1" />
        </material>
      </visual>
    <visual name="elbow_cap_pos">
      <origin xyz="0.465 0.085 0.34" rpy="1.5708 0 0" />
      <geometry>
        <cylinder radius="0.058" length="0.014" />
        </geometry>
      <material name="brushed_steel">
        <color rgba="0.62 0.62 0.58 1" />
        </material>
      </visual>
    <visual name="elbow_cap_neg">
      <origin xyz="0.465 -0.085 0.34" rpy="1.5708 0 0" />
      <geometry>
        <cylinder radius="0.058" length="0.014" />
        </geometry>
      <material name="brushed_steel">
        <color rgba="0.62 0.62 0.58 1" />
        </material>
      </visual>
    <visual name="elbow_cap_bolt_pos_0">
      <origin xyz="0.465 0.095 0.378" rpy="1.5708 0 0" />
      <geometry>
        <cylinder radius="0.006" length="0.006" />
        </geometry>
      <material name="brushed_steel">
        <color rgba="0.62 0.62 0.58 1" />
        </material>
      </visual>
    <visual name="elbow_cap_bolt_neg_0">
      <origin xyz="0.465 -0.095 0.378" rpy="1.5708 0 0" />
      <geometry>
        <cylinder radius="0.006" length="0.006" />
        </geometry>
      <material name="brushed_steel">
        <color rgba="0.62 0.62 0.58 1" />
        </material>
      </visual>
    <visual name="elbow_cap_bolt_pos_1">
      <origin xyz="0.465 0.095 0.302" rpy="1.5708 0 0" />
      <geometry>
        <cylinder radius="0.006" length="0.006" />
        </geometry>
      <material name="brushed_steel">
        <color rgba="0.62 0.62 0.58 1" />
        </material>
      </visual>
    <visual name="elbow_cap_bolt_neg_1">
      <origin xyz="0.465 -0.095 0.302" rpy="1.5708 0 0" />
      <geometry>
        <cylinder radius="0.006" length="0.006" />
        </geometry>
      <material name="brushed_steel">
        <color rgba="0.62 0.62 0.58 1" />
        </material>
      </visual>
    <visual name="elbow_cap_bolt_pos_2">
      <origin xyz="0.503 0.095 0.34" rpy="1.5708 0 0" />
      <geometry>
        <cylinder radius="0.006" length="0.006" />
        </geometry>
      <material name="brushed_steel">
        <color rgba="0.62 0.62 0.58 1" />
        </material>
      </visual>
    <visual name="elbow_cap_bolt_neg_2">
      <origin xyz="0.503 -0.095 0.34" rpy="1.5708 0 0" />
      <geometry>
        <cylinder radius="0.006" length="0.006" />
        </geometry>
      <material name="brushed_steel">
        <color rgba="0.62 0.62 0.58 1" />
        </material>
      </visual>
    <visual name="elbow_cap_bolt_pos_3">
      <origin xyz="0.427 0.095 0.34" rpy="1.5708 0 0" />
      <geometry>
        <cylinder radius="0.006" length="0.006" />
        </geometry>
      <material name="brushed_steel">
        <color rgba="0.62 0.62 0.58 1" />
        </material>
      </visual>
    <visual name="elbow_cap_bolt_neg_3">
      <origin xyz="0.427 -0.095 0.34" rpy="1.5708 0 0" />
      <geometry>
        <cylinder radius="0.006" length="0.006" />
        </geometry>
      <material name="brushed_steel">
        <color rgba="0.62 0.62 0.58 1" />
        </material>
      </visual>
    <collision name="shoulder_bearing">
      <origin xyz="0 0 0.025" rpy="0 0 0" />
      <geometry>
        <cylinder radius="0.145" length="0.05" />
        </geometry>
      </collision>
    <collision name="shoulder_housing">
      <origin xyz="0 0 0.11" rpy="0 0 0" />
      <geometry>
        <box size="0.22 0.18 0.12" />
        </geometry>
      </collision>
    <collision name="shoulder_neck">
      <origin xyz="0.055 0 0.175" rpy="0 0 0" />
      <geometry>
        <box size="0.16 0.135 0.05" />
        </geometry>
      </collision>
    <collision name="upper_beam">
      <origin xyz="0.21 0 0.2375" rpy="0 -0.383284 0" />
      <geometry>
        <box size="0.334253 0.096 0.07" />
        </geometry>
      </collision>
    <collision name="upper_rib_pos">
      <origin xyz="0.21 0.056 0.2375" rpy="0 -0.383284 0" />
      <geometry>
        <box size="0.287457 0.02 0.09" />
        </geometry>
      </collision>
    <collision name="upper_rib_neg">
      <origin xyz="0.21 -0.056 0.2375" rpy="0 -0.383284 0" />
      <geometry>
        <box size="0.287457 0.02 0.09" />
        </geometry>
      </collision>
    <collision name="elbow_bridge">
      <origin xyz="0.385 0 0.332" rpy="0 0 0" />
      <geometry>
        <box size="0.08 0.14 0.086" />
        </geometry>
      </collision>
    <collision name="elbow_cheek_pos">
      <origin xyz="0.465 0.065 0.34" rpy="0 0 0" />
      <geometry>
        <box size="0.098 0.026 0.185" />
        </geometry>
      </collision>
    <collision name="elbow_cheek_neg">
      <origin xyz="0.465 -0.065 0.34" rpy="0 0 0" />
      <geometry>
        <box size="0.098 0.026 0.185" />
        </geometry>
      </collision>
    <collision name="elbow_cap_pos">
      <origin xyz="0.465 0.085 0.34" rpy="1.5708 0 0" />
      <geometry>
        <cylinder radius="0.058" length="0.014" />
        </geometry>
      </collision>
    <collision name="elbow_cap_neg">
      <origin xyz="0.465 -0.085 0.34" rpy="1.5708 0 0" />
      <geometry>
        <cylinder radius="0.058" length="0.014" />
        </geometry>
      </collision>
    <collision name="elbow_cap_bolt_pos_0">
      <origin xyz="0.465 0.095 0.378" rpy="1.5708 0 0" />
      <geometry>
        <cylinder radius="0.006" length="0.006" />
        </geometry>
      </collision>
    <collision name="elbow_cap_bolt_neg_0">
      <origin xyz="0.465 -0.095 0.378" rpy="1.5708 0 0" />
      <geometry>
        <cylinder radius="0.006" length="0.006" />
        </geometry>
      </collision>
    <collision name="elbow_cap_bolt_pos_1">
      <origin xyz="0.465 0.095 0.302" rpy="1.5708 0 0" />
      <geometry>
        <cylinder radius="0.006" length="0.006" />
        </geometry>
      </collision>
    <collision name="elbow_cap_bolt_neg_1">
      <origin xyz="0.465 -0.095 0.302" rpy="1.5708 0 0" />
      <geometry>
        <cylinder radius="0.006" length="0.006" />
        </geometry>
      </collision>
    <collision name="elbow_cap_bolt_pos_2">
      <origin xyz="0.503 0.095 0.34" rpy="1.5708 0 0" />
      <geometry>
        <cylinder radius="0.006" length="0.006" />
        </geometry>
      </collision>
    <collision name="elbow_cap_bolt_neg_2">
      <origin xyz="0.503 -0.095 0.34" rpy="1.5708 0 0" />
      <geometry>
        <cylinder radius="0.006" length="0.006" />
        </geometry>
      </collision>
    <collision name="elbow_cap_bolt_pos_3">
      <origin xyz="0.427 0.095 0.34" rpy="1.5708 0 0" />
      <geometry>
        <cylinder radius="0.006" length="0.006" />
        </geometry>
      </collision>
    <collision name="elbow_cap_bolt_neg_3">
      <origin xyz="0.427 -0.095 0.34" rpy="1.5708 0 0" />
      <geometry>
        <cylinder radius="0.006" length="0.006" />
        </geometry>
      </collision>
    </link>
  <link name="forearm">
    <visual name="elbow_hub">
      <origin xyz="0 0 0" rpy="1.5708 0 0" />
      <geometry>
        <cylinder radius="0.043" length="0.094" />
        </geometry>
      <material name="brushed_steel">
        <color rgba="0.62 0.62 0.58 1" />
        </material>
      </visual>
    <visual name="forearm_beam">
      <origin xyz="0.155 0 0" rpy="0 0 0" />
      <geometry>
        <box size="0.26 0.08 0.066" />
        </geometry>
      <material name="safety_yellow">
        <color rgba="0.92 0.64 0.1 1" />
        </material>
      </visual>
    <visual name="forearm_rib_pos">
      <origin xyz="0.165 0.046 0" rpy="0 0 0" />
      <geometry>
        <box size="0.215 0.02 0.082" />
        </geometry>
      <material name="industrial_blue">
        <color rgba="0.08 0.18 0.3 1" />
        </material>
      </visual>
    <visual name="forearm_rib_neg">
      <origin xyz="0.165 -0.046 0" rpy="0 0 0" />
      <geometry>
        <box size="0.215 0.02 0.082" />
        </geometry>
      <material name="industrial_blue">
        <color rgba="0.08 0.18 0.3 1" />
        </material>
      </visual>
    <visual name="wrist_bridge">
      <origin xyz="0.278 0 0" rpy="0 0 0" />
      <geometry>
        <box size="0.05 0.142 0.104" />
        </geometry>
      <material name="industrial_blue">
        <color rgba="0.08 0.18 0.3 1" />
        </material>
      </visual>
    <visual name="wrist_cheek_pos">
      <origin xyz="0.34 0.066 0" rpy="0 0 0" />
      <geometry>
        <box size="0.08 0.026 0.15" />
        </geometry>
      <material name="industrial_blue">
        <color rgba="0.08 0.18 0.3 1" />
        </material>
      </visual>
    <visual name="wrist_cheek_neg">
      <origin xyz="0.34 -0.066 0" rpy="0 0 0" />
      <geometry>
        <box size="0.08 0.026 0.15" />
        </geometry>
      <material name="industrial_blue">
        <color rgba="0.08 0.18 0.3 1" />
        </material>
      </visual>
    <visual name="wrist_axle">
      <origin xyz="0.34 0 0" rpy="1.5708 0 0" />
      <geometry>
        <cylinder radius="0.018" length="0.118" />
        </geometry>
      <material name="brushed_steel">
        <color rgba="0.62 0.62 0.58 1" />
        </material>
      </visual>
    <visual name="wrist_cap_pos">
      <origin xyz="0.34 0.085 0" rpy="1.5708 0 0" />
      <geometry>
        <cylinder radius="0.044" length="0.012" />
        </geometry>
      <material name="brushed_steel">
        <color rgba="0.62 0.62 0.58 1" />
        </material>
      </visual>
    <visual name="wrist_cap_neg">
      <origin xyz="0.34 -0.085 0" rpy="1.5708 0 0" />
      <geometry>
        <cylinder radius="0.044" length="0.012" />
        </geometry>
      <material name="brushed_steel">
        <color rgba="0.62 0.62 0.58 1" />
        </material>
      </visual>
    <collision name="elbow_hub">
      <origin xyz="0 0 0" rpy="1.5708 0 0" />
      <geometry>
        <cylinder radius="0.043" length="0.094" />
        </geometry>
      </collision>
    <collision name="forearm_beam">
      <origin xyz="0.155 0 0" rpy="0 0 0" />
      <geometry>
        <box size="0.26 0.08 0.066" />
        </geometry>
      </collision>
    <collision name="forearm_rib_pos">
      <origin xyz="0.165 0.046 0" rpy="0 0 0" />
      <geometry>
        <box size="0.215 0.02 0.082" />
        </geometry>
      </collision>
    <collision name="forearm_rib_neg">
      <origin xyz="0.165 -0.046 0" rpy="0 0 0" />
      <geometry>
        <box size="0.215 0.02 0.082" />
        </geometry>
      </collision>
    <collision name="wrist_bridge">
      <origin xyz="0.278 0 0" rpy="0 0 0" />
      <geometry>
        <box size="0.05 0.142 0.104" />
        </geometry>
      </collision>
    <collision name="wrist_cheek_pos">
      <origin xyz="0.34 0.066 0" rpy="0 0 0" />
      <geometry>
        <box size="0.08 0.026 0.15" />
        </geometry>
      </collision>
    <collision name="wrist_cheek_neg">
      <origin xyz="0.34 -0.066 0" rpy="0 0 0" />
      <geometry>
        <box size="0.08 0.026 0.15" />
        </geometry>
      </collision>
    <collision name="wrist_axle">
      <origin xyz="0.34 0 0" rpy="1.5708 0 0" />
      <geometry>
        <cylinder radius="0.018" length="0.118" />
        </geometry>
      </collision>
    <collision name="wrist_cap_pos">
      <origin xyz="0.34 0.085 0" rpy="1.5708 0 0" />
      <geometry>
        <cylinder radius="0.044" length="0.012" />
        </geometry>
      </collision>
    <collision name="wrist_cap_neg">
      <origin xyz="0.34 -0.085 0" rpy="1.5708 0 0" />
      <geometry>
        <cylinder radius="0.044" length="0.012" />
        </geometry>
      </collision>
    </link>
  <link name="wrist_block">
    <visual name="wrist_hub">
      <origin xyz="0 0 0" rpy="1.5708 0 0" />
      <geometry>
        <cylinder radius="0.034" length="0.082" />
        </geometry>
      <material name="brushed_steel">
        <color rgba="0.62 0.62 0.58 1" />
        </material>
      </visual>
    <visual name="nose_block">
      <origin xyz="0.082 0 0" rpy="0 0 0" />
      <geometry>
        <box size="0.124 0.088 0.074" />
        </geometry>
      <material name="industrial_blue">
        <color rgba="0.08 0.18 0.3 1" />
        </material>
      </visual>
    <visual name="tool_flange">
      <origin xyz="0.151 0 0" rpy="0 1.5708 0" />
      <geometry>
        <cylinder radius="0.046" length="0.022" />
        </geometry>
      <material name="brushed_steel">
        <color rgba="0.62 0.62 0.58 1" />
        </material>
      </visual>
    <visual name="rubber_face">
      <origin xyz="0.168 0 0" rpy="0 1.5708 0" />
      <geometry>
        <cylinder radius="0.033" length="0.01" />
        </geometry>
      <material name="black_rubber">
        <color rgba="0.01 0.01 0.012 1" />
        </material>
      </visual>
    <visual name="flange_bolt_0">
      <origin xyz="0.165 -0.027 -0.027" rpy="0 1.5708 0" />
      <geometry>
        <cylinder radius="0.0055" length="0.006" />
        </geometry>
      <material name="brushed_steel">
        <color rgba="0.62 0.62 0.58 1" />
        </material>
      </visual>
    <visual name="flange_bolt_1">
      <origin xyz="0.165 -0.027 0.027" rpy="0 1.5708 0" />
      <geometry>
        <cylinder radius="0.0055" length="0.006" />
        </geometry>
      <material name="brushed_steel">
        <color rgba="0.62 0.62 0.58 1" />
        </material>
      </visual>
    <visual name="flange_bolt_2">
      <origin xyz="0.165 0.027 -0.027" rpy="0 1.5708 0" />
      <geometry>
        <cylinder radius="0.0055" length="0.006" />
        </geometry>
      <material name="brushed_steel">
        <color rgba="0.62 0.62 0.58 1" />
        </material>
      </visual>
    <visual name="flange_bolt_3">
      <origin xyz="0.165 0.027 0.027" rpy="0 1.5708 0" />
      <geometry>
        <cylinder radius="0.0055" length="0.006" />
        </geometry>
      <material name="brushed_steel">
        <color rgba="0.62 0.62 0.58 1" />
        </material>
      </visual>
    <collision name="wrist_hub">
      <origin xyz="0 0 0" rpy="1.5708 0 0" />
      <geometry>
        <cylinder radius="0.034" length="0.082" />
        </geometry>
      </collision>
    <collision name="nose_block">
      <origin xyz="0.082 0 0" rpy="0 0 0" />
      <geometry>
        <box size="0.124 0.088 0.074" />
        </geometry>
      </collision>
    <collision name="tool_flange">
      <origin xyz="0.151 0 0" rpy="0 1.5708 0" />
      <geometry>
        <cylinder radius="0.046" length="0.022" />
        </geometry>
      </collision>
    <collision name="rubber_face">
      <origin xyz="0.168 0 0" rpy="0 1.5708 0" />
      <geometry>
        <cylinder radius="0.033" length="0.01" />
        </geometry>
      </collision>
    <collision name="flange_bolt_0">
      <origin xyz="0.165 -0.027 -0.027" rpy="0 1.5708 0" />
      <geometry>
        <cylinder radius="0.0055" length="0.006" />
        </geometry>
      </collision>
    <collision name="flange_bolt_1">
      <origin xyz="0.165 -0.027 0.027" rpy="0 1.5708 0" />
      <geometry>
        <cylinder radius="0.0055" length="0.006" />
        </geometry>
      </collision>
    <collision name="flange_bolt_2">
      <origin xyz="0.165 0.027 -0.027" rpy="0 1.5708 0" />
      <geometry>
        <cylinder radius="0.0055" length="0.006" />
        </geometry>
      </collision>
    <collision name="flange_bolt_3">
      <origin xyz="0.165 0.027 0.027" rpy="0 1.5708 0" />
      <geometry>
        <cylinder radius="0.0055" length="0.006" />
        </geometry>
      </collision>
    </link>
  <joint name="base_to_upper" type="revolute">
    <origin xyz="0 0 0.61" rpy="0 0 0" />
    <parent link="base_column" />
    <child link="upper_link" />
    <axis xyz="0 0 1" />
    <limit effort="90" velocity="1.2" lower="-2.4" upper="2.4" />
    </joint>
  <joint name="upper_to_forearm" type="revolute">
    <origin xyz="0.465 0 0.34" rpy="0 0 0" />
    <parent link="upper_link" />
    <child link="forearm" />
    <axis xyz="0 -1 0" />
    <limit effort="55" velocity="1.1" lower="-0.55" upper="0.82" />
    </joint>
  <joint name="forearm_to_wrist" type="revolute">
    <origin xyz="0.34 0 0" rpy="0 0 0" />
    <parent link="forearm" />
    <child link="wrist_block" />
    <axis xyz="0 -1 0" />
    <limit effort="18" velocity="1.8" lower="-0.85" upper="0.85" />
    </joint>
  </robot>
